File: 01_Data/Cinder_Block/STA/N2/3K_min/Cinder_Block_STA_N2_3KData_230828_R1.csv
##Temp./Â°C,Time/min,DSC/(mW/mg),Mass loss/mg
29.0,16.39389785399906,-2.266522004369717,-0.0014419785417896236
30.40000000000002,17.0729755481815,-2.2368961965726823,-0.002276355386251261
31.80000000000004,17.648095454604444,-2.22092234398921,-0.004280955501253736
33.20000000000006,18.206123041902686,-2.2148521179698726,-0.0022743222496393045
34.60000000000008,18.74102339040221,-2.2097332908658025,-0.004994567297909036
36.0000000000001,19.255117233145537,-2.2012619308441757,-0.003528092290368434
37.40000000000012,19.76855096276049,-2.1967124260933812,-0.004944241557155671
38.80000000000014,20.26687485599262,-2.192029844386868,-0.00415292438046766
40.20000000000016,20.761640147067816,-2.1872978908107488,-0.006671387968602005
41.60000000000018,21.24997340553345,-2.1826035634076844,-0.007239002671498795
43.0000000000002,21.74056339748872,-2.1782858319735454,-0.006581113911566128
44.40000000000022,22.222809750599737,-2.171612826008564,-0.007238164267727498
45.80000000000024,22.704697001065743,-2.1676739175045965,-0.008559949996846505
47.20000000000026,23.18109586174584,-2.1618710892350235,-0.008550064556181347
48.60000000000028,23.655296508559992,-2.1569567975341926,-0.009879879786498513
50.0000000000003,24.133626238102543,-2.153263347387718,-0.011177497658964697
51.40000000000032,24.604533076163946,-2.1461296730977684,-0.00988155637102306
52.80000000000034,25.082302329381985,-2.139540747986302,-0.010537743350664819
54.20000000000036,25.55394966900576,-2.135178274009699,-0.012510019987385768
55.60000000000038,26.0184621086988,-2.128850428598121,-0.012854448662870332
57.0000000000004,26.502623010607046,-2.124452120239012,-0.012322783887212196
58.40000000000042,26.9745198970204,-2.1195269278789635,-0.012760946265869322
59.80000000000044,27.445837540857756,-2.1150458003057,-0.013481234548025078
61.20000000000046,27.917014700232027,-2.110853976235359,-0.01552275095191824
62.60000000000048,28.384899985115197,-2.1065042754645167,-0.015441019283876756
64.0000000000005,28.85674431849774,-2.1029968491784112,-0.014497800962994134
65.40000000000052,29.324709149528413,-2.0981049043330606,-0.01613989500742541
66.80000000000054,29.796128776050455,-2.094800901248377,-0.017525743876207756
68.20000000000056,30.258623814215262,-2.0897165402179896,-0.016117443757049266
69.60000000000058,30.727080615779435,-2.086007363539632,-0.018770105000000648
71.0000000000006,31.19408301921664,-2.081344552589232,-0.020080072428307005
72.40000000000062,31.668340728705953,-2.076697647729188,-0.0210799355483422
73.80000000000064,32.13707125827385,-2.072381738944146,-0.02027019111877859
75.20000000000066,32.601612099107676,-2.0671934374870577,-0.02008114418505791
76.60000000000068,33.069530855876906,-2.064011142923108,-0.02009244983800418
78.0000000000007,33.53377161343663,-2.059493605060773,-0.022719840000032576
79.40000000000072,33.99815700649892,-2.055776840056956,-0.02272007013370736
80.80000000000074,34.45600465911846,-2.05178695657642,-0.023379914500570642
82.20000000000076,34.9364789534666,-2.0471132061595188,-0.024700980261186167
83.60000000000078,35.40237512660044,-2.044961793698242,-0.022060050894067373
85.0000000000008,35.87126420590952,-2.0410734569968882,-0.024700025641965162
86.40000000000082,36.33558697424616,-2.0375988853799987,-0.024674011907736215
87.80000000000084,36.800940107050934,-2.0333729465420363,-0.024689790058887162
89.20000000000086,37.26959336079456,-2.0285128857245724,-0.023827657385915302
90.60000000000088,37.73128240963808,-2.026021546441915,-0.02634987044642756
92.0000000000009,38.20028263855445,-2.0224251173150116,-0.025680166863780052
93.40000000000092,38.66011638923722,-2.01931676039413,-0.027000164999996024
94.80000000000094,39.1226795160771,-2.016113806287225,-0.026151768205269654
96.20000000000095,39.590000000000295,-2.0117299999999863,-0.028979830178946564
97.60000000000097,40.06158019955582,-2.006963872659757,-0.0276700949975881
99.000000000001,40.51735506128361,-2.0023976922212565,-0.027009767839519583
100.40000000000101,40.979697437382605,-1.99995059507923,-0.02935935911824661
101.80000000000103,41.442431516829075,-1.9969111824071097,-0.029639868736639485
103.20000000000105,41.89923927272249,-1.9911365469318456,-0.028520152418749056
104.60000000000107,42.35494174873601,-1.9880246107539747,-0.02873710239952665
106.0000000000011,42.82651127911366,-1.98553845674213,-0.02842017774742711
107.40000000000111,43.28652634050575,-1.9824389933065274,-0.02974018495404085
108.80000000000113,43.75047369065577,-1.977460527696497,-0.030390542380994923
110.20000000000115,44.207998378297326,-1.975646037524752,-0.028654837638881325
111.60000000000117,44.67174827761116,-1.9719072664317263,-0.03008020480768181
113.0000000000012,45.13069015364447,-1.9677841833059913,-0.0317808023226922
114.40000000000121,45.59314918637502,-1.964014449821853,-0.030729964852451275
115.80000000000123,46.053873591340775,-1.9608428196188457,-0.03040308673219627
117.20000000000125,46.515178927346604,-1.9582189018494005,-0.0317201106842635
118.60000000000127,46.9755668228115,-1.9555966222784142,-0.0313709915383118
120.0000000000013,47.4354034062969,-1.9517646081034092,-0.03205950310430428
121.40000000000131,47.897793553745956,-1.9477130186939702,-0.03304510298008889
122.80000000000133,48.36056494902424,-1.9449504770248578,-0.03333376402106136
124.20000000000135,48.815867476166446,-1.9413242787334741,-0.031720203860369445
125.60000000000137,49.27720877165218,-1.937744206404593,-0.03238017999999965
127.00000000000139,49.738770264773336,-1.934545589934855,-0.03510571219784531
128.4000000000014,50.19329615257503,-1.9327520815105466,-0.03370003001275279
129.80000000000143,50.65601309378872,-1.9298419831386777,-0.0337081384603275
131.20000000000147,51.115340790438076,-1.9266581172493884,-0.033700101381057834
132.60000000000147,51.57450532811846,-1.923845440645331,-0.03499197117738451
134.00000000000148,52.03474988772263,-1.920022336265907,-0.03509626380811781
135.4000000000015,52.49321152532802,-1.9187055466609375,-0.03336973975458246
136.80000000000155,52.952168409357284,-1.9168605189465862,-0.03359631881256053
138.20000000000155,53.399575040902235,-1.913212610293169,-0.03534988528952532
139.60000000000156,53.861832898072414,-1.9100065240884159,-0.035708719259208266
141.0000000000016,54.31326001095359,-1.9087849876766732,-0.03404596866073373
142.40000000000163,54.78131312652859,-1.9062400155772181,-0.03661559068845843
143.80000000000163,55.24421056102629,-1.9030006229213798,-0.037318480089567174
145.20000000000164,55.70252611695842,-1.8992798042444763,-0.036329990673661605
146.60000000000167,56.15753851115212,-1.897894597042854,-0.036297356164783245
148.0000000000017,56.615592523907885,-1.8957002899553281,-0.03703419737567781
149.4000000000017,57.072565694398975,-1.8925186330077668,-0.03711504496329088
150.80000000000172,57.5286675371587,-1.888619698718926,-0.03798001453638289
152.20000000000175,57.98672386125154,-1.887799853004853,-0.03593523640615981
153.60000000000178,58.44286942317106,-1.885949002170749,-0.037871409716129456
155.0000000000018,58.88450078282508,-1.8836113917903683,-0.036999922112447514
156.4000000000018,59.35204686256738,-1.8820414543804367,-0.0364919036103597
157.80000000000183,59.8128882632077,-1.8794734918970524,-0.03568362711126216
159.20000000000186,60.26447733045482,-1.8752488231519846,-0.03666029959822481
160.60000000000187,60.723667614041105,-1.8748206555128197,-0.03699002498050952
162.00000000000188,61.17402011179211,-1.8738643956068406,-0.03842139297232183
163.4000000000019,61.640006765896324,-1.870600123554816,-0.037760152842832184
164.80000000000194,62.094441240415996,-1.8678204366873212,-0.038089799968089366
166.20000000000195,62.55119360610317,-1.8655027830095747,-0.03890320229717936
167.60000000000196,63.00619833055761,-1.8629044087179045,-0.03732285761469445
169.000000000002,63.455555303551805,-1.8599566561253313,-0.037760054893197115
170.40000000000202,63.91782182526539,-1.8584755354877975,-0.037760159999122855
171.80000000000203,64.36765302218443,-1.8574077568361465,-0.03940421775299807
173.20000000000203,64.8244882268001,-1.8531633668174037,-0.04005768999320125
174.60000000000207,65.28262422939201,-1.8518798225667268,-0.03907016000038066
176.0000000000021,65.7385617692802,-1.8497891210464443,-0.04171327721678342
177.4000000000021,66.19030896842662,-1.847816763301767,-0.03974287103121554
178.80000000000211,66.64448253698697,-1.8464339102882315,-0.04006782699333833
180.20000000000215,67.10084068383951,-1.8429971104218117,-0.04151152019647952
181.60000000000218,67.55654638119327,-1.8409623841468308,-0.04062005000000912
183.0000000000022,68.00606511570969,-1.8417132535799665,-0.040939999999999976
184.4000000000022,68.46781869143152,-1.8409842626439585,-0.040290002618271537
185.80000000000223,68.92340200984242,-1.8388034299369156,-0.042265364506688385
187.20000000000226,69.37928884464414,-1.8360908895135684,-0.04129389063349986
188.60000000000227,69.83425302588432,-1.8341706389426187,-0.04288414346865643
190.00000000000227,70.28584291089649,-1.8318450309572654,-0.04160982500000188
191.4000000000023,70.7418738119,-1.8323694802283828,-0.04160983242053273
192.80000000000234,71.19460026639848,-1.8310065203658283,-0.0429199750541045
194.20000000000235,71.64000000000088,-1.8288600000000044,-0.04390989999999917
195.60000000000235,72.1026360035505,-1.8279710842993246,-0.04408661336864572
197.0000000000024,72.55184974515566,-1.8248912465938072,-0.04360649629175217
198.40000000000242,72.9950077502212,-1.8243534810354924,-0.043669893300049445
199.80000000000243,73.45511902360737,-1.8224742223934558,-0.04391000371631737
201.20000000000243,73.90344901423619,-1.8219190456656242,-0.044331183206767655
202.60000000000247,74.3523718569253,-1.8191661111784887,-0.04382264242866096
204.0000000000025,74.7963714345752,-1.8193341738755702,-0.04357235901005119
205.4000000000025,75.2603300092387,-1.8167628779521516,-0.0480095985758453
206.8000000000025,75.71434427289431,-1.81840287873934,-0.04621990003929355
208.20000000000255,76.16960306395889,-1.8160895644196389,-0.047200034873465135
209.60000000000258,76.62344013920695,-1.8131068588455186,-0.044568241748834225
211.0000000000026,77.06902933395735,-1.8139838045268533,-0.04587280637432478
212.4000000000026,77.51907464013384,-1.8123473864205266,-0.04589000499999418
213.80000000000263,77.9732032501291,-1.8104574026942253,-0.04588939986180929
215.20000000000266,78.42742121370419,-1.8097876895984573,-0.046870005244831425
216.60000000000267,78.87771663750091,-1.8081008680771729,-0.0472000799999126
218.00000000000267,79.33254450333794,-1.809065971898673,-0.047239515359073
219.4000000000027,79.79492432463425,-1.812047304002508,-0.04848105818700876
220.80000000000274,80.26728322425453,-1.8103880083980575,-0.046870080012832105
222.20000000000275,80.72213928850685,-1.8088473737878346,-0.04918797462974478
223.60000000000275,81.18671905010733,-1.807376202651303,-0.04819340571483899
225.00000000000279,81.64086812738388,-1.8050322873189997,-0.04753013915897508
226.40000000000282,82.09825912401749,-1.8048652764818587,-0.04859287643256227
227.80000000000283,82.54592770814723,-1.8025986676469103,-0.04852007999999852
229.20000000000283,83.00143520955407,-1.8025165322395282,-0.049839721294587136
230.60000000000286,83.45430363190482,-1.8020868782485189,-0.04852008000000119
232.0000000000029,83.9089510164332,-1.8007813643663924,-0.048521565766850294
233.4000000000029,84.36366246247441,-1.799699177421413,-0.050163246884205925
234.8000000000029,84.81869995970709,-1.7991328000138944,-0.049013072701018956
236.20000000000294,85.27214605019326,-1.7978902856261088,-0.05061659283417619
237.60000000000298,85.74724740343,-1.794976980195157,-0.04812201415066131
239.00000000000298,86.18294529888492,-1.797097050759885,-0.050610159353534634
240.400000000003,86.63835808687955,-1.7974273179763505,-0.05192998031251639
241.80000000000302,87.09610829108007,-1.7974581735092807,-0.05094008000000061
243.20000000000306,87.55314683440196,-1.7945339729673488,-0.05094008000223349
244.60000000000306,88.00664626764149,-1.7931341889858317,-0.05192008000023307
246.00000000000307,88.46020033469598,-1.7927296834338133,-0.05159989995370662
247.4000000000031,88.91459992894386,-1.793495685207463,-0.05165439184064624
248.80000000000314,89.37270584082209,-1.792406617156208,-0.05290989999999951
250.20000000000314,89.829701405996,-1.7926290212866796,-0.05225916257656138
251.60000000000315,90.28759559374853,-1.7910346050061485,-0.051589392148152946
253.00000000000318,90.7309702436553,-1.7918659595730422,-0.05225995195030464
254.40000000000322,91.19866738915694,-1.792066130091393,-0.05326964071379292
255.80000000000322,91.64966220805358,-1.791609090757075,-0.05323982498967217
257.20000000000323,92.1028760930497,-1.791164963170117,-0.05191946227466682
258.60000000000326,92.56128665966123,-1.7921601703982053,-0.053239824985277906
260.0000000000033,93.01398637602031,-1.7938672578524038,-0.05422755183371297
261.4000000000033,93.46970332113816,-1.7928670668258013,-0.054560033137971864
262.8000000000033,93.92389550892318,-1.7914167570325814,-0.053240803622733424
264.20000000000334,94.3763500708807,-1.791112022831897,-0.05456005000000852
265.6000000000034,94.83454591322405,-1.7900928885466567,-0.05260130802068508
267.0000000000034,95.29156006829446,-1.7896809157627265,-0.054218664586131116
268.4000000000034,95.74758007087853,-1.7915273660565763,-0.05332013067238517
269.8000000000034,96.20418497134838,-1.7897410954200903,-0.05400980404672584
271.20000000000346,96.65868048773633,-1.7907552698709157,-0.054669975045817054
272.60000000000343,97.11850711940653,-1.7912748073691798,-0.054532736887867195
274.00000000000347,97.57747473803657,-1.7921065931966356,-0.05433989998884847
275.4000000000035,98.0300024246228,-1.7906300645655626,-0.054474999913622035
276.80000000000354,98.48635588886768,-1.7896075375805285,-0.05632034543729292
278.20000000000357,98.94392837885418,-1.7906366036537165,-0.05444990636634506
279.60000000000355,99.40135813857418,-1.7910487425823851,-0.05542998658610809
281.0000000000036,99.85561145032538,-1.792813074263463,-0.05511049180776961
282.4000000000036,100.31675619388845,-1.793227172774275,-0.0551099749999997
283.8000000000036,100.77482251408198,-1.7892087128159249,-0.05576036928922079
285.2000000000036,101.23118337749612,-1.7913787638335446,-0.05776629569974645
286.60000000000366,101.68937382288445,-1.7908731978753905,-0.05510948892673451
288.0000000000037,102.14174522381632,-1.7908336964739957,-0.05576881155289293
289.40000000000373,102.60111873529499,-1.7904646767654429,-0.05510982499981143
290.8000000000037,103.058658441285,-1.7911127181275046,-0.05510982495571781
292.20000000000374,103.51024690102766,-1.7913585851161509,-0.053787162983671255
293.6000000000038,103.96577577438677,-1.7920895657005824,-0.05576997500042724
295.00000000000375,104.41889928785498,-1.792570549558551,-0.05610049859562771
296.4000000000038,104.87603713436766,-1.7927924466625789,-0.0561006275855882
297.8000000000038,105.33211918214387,-1.7948400970060665,-0.0570900092648583
299.20000000000385,105.79042710680444,-1.7946807420443212,-0.05748415814847174
300.6000000000039,106.2446207572794,-1.7955789159455295,-0.05707980161779913
302.00000000000387,106.70853544648641,-1.7954210427856643,-0.05839876945545619
303.4000000000039,107.16337040677448,-1.7958267490350273,-0.05707982495538255
304.80000000000393,107.61602777532448,-1.79701801262943,-0.058399819999995106
306.2000000000039,108.07800419501443,-1.7959885420633557,-0.05774006050434144
307.60000000000394,108.53801000477223,-1.797309377096874,-0.058069415402022706
309.000000000004,108.98897606907866,-1.797564436427925,-0.0596545862297031
310.400000000004,109.44674915897708,-1.7992329530912856,-0.05789226555526383
311.80000000000405,109.90202092689424,-1.7996119649050348,-0.05916997000100288
313.200000000004,110.35999625160335,-1.7994099125989536,-0.05917011999991706
314.60000000000406,110.81880649380447,-1.8011097055272862,-0.060162485106696195
316.0000000000041,111.28231959949666,-1.8006882992281052,-0.06082948944760158
317.40000000000407,111.73584517747548,-1.799785142273698,-0.060819934878460824
318.8000000000041,112.18623105020961,-1.8013512282527586,-0.0602644072948908
320.20000000000414,112.64318447476889,-1.8027640759380918,-0.06042112447970238
321.6000000000042,113.09709256345258,-1.8023335424093323,-0.0614799399999999
323.0000000000042,113.55661786261919,-1.80375374044944,-0.060819939917476695
324.4000000000042,114.01761274391843,-1.8045257505059162,-0.06148009000016508
325.8000000000042,114.47717273884712,-1.804527153826773,-0.06226947627398838
327.20000000000425,114.93580853599502,-1.8062685434631034,-0.06247045308925614
328.60000000000423,115.38941123478978,-1.806006395722733,-0.06181042941579751
330.00000000000426,115.85450115068446,-1.8085918988043412,-0.06311986009062887
331.4000000000043,116.31556517964022,-1.8092480976099636,-0.06245921257402465
332.80000000000433,116.77675019934084,-1.8115268051779096,-0.06246990999948032
334.20000000000437,117.23171483830956,-1.812140305517214,-0.06246990999931912
335.60000000000434,117.6858917874705,-1.8129743169419195,-0.06345990996131601
337.0000000000044,118.1443499389823,-1.8148286202956319,-0.062144384453067136
338.4000000000044,118.60301496099721,-1.818329595465892,-0.06312991002792456
339.8000000000044,119.06453290195654,-1.818434443380313,-0.06214018652442821
341.2000000000044,119.52172217041466,-1.8198278320084325,-0.06279023048685817
342.60000000000446,119.9861917094975,-1.8196047130950899,-0.0634073471012524
344.0000000000045,120.44220065650468,-1.8207515831731782,-0.06378008500002386
345.4000000000045,120.90520055244072,-1.8225979694739325,-0.06378008499999899
346.8000000000045,121.36421875674809,-1.8236189177489825,-0.06378008499940391
348.20000000000454,121.8269778199084,-1.824256927722242,-0.06411003869207432
349.60000000000457,122.28365295749705,-1.8277641335253496,-0.06310075078816979
351.00000000000455,122.74649821732477,-1.828505084955395,-0.06444016000677477
352.4000000000046,123.19767083668381,-1.8295016156308712,-0.06410996624948773
353.8000000000046,123.66139881683304,-1.8304944452051375,-0.06443994238495421
355.20000000000465,124.12480968915193,-1.8337880030493894,-0.06316580509226055
356.6000000000047,124.57706599083862,-1.8339801058691219,-0.06344933752381321
358.00000000000466,125.04206965026725,-1.836244603180477,-0.062461402308672476
359.4000000000047,125.50050701839454,-1.8373478584403025,-0.0651000549999976
360.80000000000473,125.96719078666003,-1.8392387721825383,-0.06609645699327604
362.2000000000047,126.43144677190422,-1.841480499846261,-0.0651000550252121
363.60000000000474,126.89274942331701,-1.8425939207741304,-0.06410983001651793
365.0000000000048,127.35501012709393,-1.8435257030065513,-0.06543117063966442
366.4000000000048,127.81398101664628,-1.8449146120863436,-0.06377970232360797
367.80000000000484,128.2731357181743,-1.848144263289974,-0.06544000510180537
369.2000000000048,128.737295290209,-1.8494915843622721,-0.06609316197639803
370.60000000000485,129.19473115999767,-1.8493399068291754,-0.06477005977346417
372.0000000000049,129.65867606574844,-1.8515837594900042,-0.0657601131557124
373.40000000000487,130.12208067128566,-1.8539919695066027,-0.06509980000009286
374.8000000000049,130.58756711316875,-1.8553392646042233,-0.06641979992002289
376.20000000000493,131.04971217924316,-1.858487817744543,-0.06707996399527616
377.60000000000497,131.51358466953022,-1.8576435990355864,-0.06509980000000626
379.000000000005,131.97394326153125,-1.8606962868087586,-0.06674891028665142
380.400000000005,132.43377158802681,-1.8618647950038327,-0.06644926747073265
381.800000000005,132.89512115968216,-1.8640726568334027,-0.06641385551192425
383.20000000000505,133.35550367399586,-1.8653657027871406,-0.06603600764984785
384.600000000005,133.82200685114253,-1.8691748617258752,-0.06839021055476868
386.00000000000506,134.2790241552725,-1.8716418093541443,-0.06609094372330437
387.4000000000051,134.7366869032404,-1.8750854661407215,-0.06748627549897313
388.8000000000051,135.19494656390947,-1.8787679087377516,-0.06737214852489659
390.20000000000516,135.6599968697216,-1.882019748807417,-0.06838986999999719
391.60000000000514,136.12820143417008,-1.883098926546527,-0.06838987766560223
393.0000000000052,136.5930926918659,-1.8876178831574018,-0.06839018853698864
394.4000000000052,137.05698563667804,-1.887538243044895,-0.06925826577085248
395.8000000000052,137.52398136136762,-1.8865443575269483,-0.06839658915009306
397.2000000000052,137.9842001087809,-1.8878249456359708,-0.06905016999910396
398.60000000000525,138.44717360928118,-1.88967337171176,-0.06938016992757268
400.0000000000053,138.91026826991876,-1.8895927619753385,-0.0680601851886129
401.4000000000053,139.37822632534295,-1.8918732671572658,-0.06904941206787019
402.8000000000053,139.83105926650572,-1.8934809955318757,-0.06905017050750661
404.20000000000533,140.29370027239747,-1.8940107912813398,-0.07037006499975185
405.60000000000537,140.7556306927313,-1.8959674729639466,-0.07004006500000193
407.00000000000534,141.22102581546955,-1.8976351529261948,-0.07140284424110543
408.4000000000054,141.68110809388202,-1.8980568392851778,-0.07069045619211511
409.8000000000054,142.14322127411205,-1.900427912110295,-0.07060605853131108
411.20000000000545,142.60819757951867,-1.9036676864619002,-0.07206242332850588
412.6000000000055,143.07427722948344,-1.9062579786108131,-0.07101982424756992
414.00000000000546,143.5363171501302,-1.9081058114082388,-0.06993783069715054
415.4000000000055,144.00142262767406,-1.911343815985083,-0.07114670124334088
416.8000000000055,144.46246285410058,-1.913964130486453,-0.07059027338762469
418.2000000000055,144.9273904393112,-1.9175661891942286,-0.07178522391130393
419.60000000000554,145.39587588013427,-1.9187429108997074,-0.07190005999998395
421.00000000000557,145.86000000000246,-1.9232900000000133,-0.07190006000000082
422.4000000000056,146.33303540843644,-1.9235667758104158,-0.0725598069732829
423.80000000000564,146.79368402778846,-1.9262913936812947,-0.07156993130420464
425.2000000000056,147.2544720043607,-1.9294636559054543,-0.07157078592337873
426.60000000000565,147.71332667413324,-1.9299547403151511,-0.07223003064714062
428.0000000000057,148.17710676835205,-1.9335740877991932,-0.07355003426130091
429.40000000000566,148.64604082203547,-1.9355692650826493,-0.07453727777391883
430.8000000000057,149.10524860497304,-1.9382935064204538,-0.07486992474261633
432.20000000000573,149.56769605679108,-1.9410100179342926,-0.07190497875381396
433.60000000000576,150.03730139613248,-1.9416015339480266,-0.07310424288295048
435.0000000000058,150.50335742740697,-1.9453125486194613,-0.07355080322571306
436.4000000000058,150.96773857052003,-1.945389134341791,-0.073879098791791
437.8000000000058,151.43517242589994,-1.9504474343200287,-0.07388007500014737
439.20000000000584,151.89772863329102,-1.9533014013500436,-0.07517607068759125
440.6000000000058,152.37125274846167,-1.9538802892696734,-0.07617991999990137
442.00000000000585,152.83034024792494,-1.957537523329776,-0.0755199555519317
443.4000000000059,153.29455296046027,-1.9604570667335846,-0.07683959046309052
444.8000000000059,153.76152158220577,-1.9621296602582328,-0.0758497761018293
446.20000000000596,154.22293706682356,-1.964109272411049,-0.07637228560363774
447.60000000000593,154.69465802373693,-1.9669768254166928,-0.07659865012504508
449.00000000000597,155.15475917705655,-1.9694650865238317,-0.07782760169236269
450.400000000006,155.6192695180116,-1.971574382389397,-0.07887674095103314
451.800000000006,156.0791840804947,-1.9753731896676325,-0.0771809002747803
453.200000000006,156.55557847462833,-1.9787946160360508,-0.07849011495554592
454.60000000000605,157.02743004797549,-1.9833563970065669,-0.07783010956459124
456.0000000000061,157.49220872942854,-1.987548904338966,-0.07859013435080087
457.4000000000061,157.96229809674813,-1.990259622848259,-0.07827001846022297
458.8000000000061,158.42654502511343,-1.9926073491998706,-0.07860002475806205
460.2000000000061,158.89270684127916,-1.993392522195845,-0.08024936116433468
461.60000000000616,159.35414598456975,-1.9957685188954346,-0.08087767027423132
463.00000000000614,159.82152518924005,-1.998108413241149,-0.0795901083248789
464.4000000000062,160.28773201696285,-2.002694787117051,-0.08057915298177765
465.8000000000062,160.75701094826144,-2.0065312783781386,-0.08024993001904068
467.20000000000624,161.22293649436006,-2.0071437526054527,-0.08029033130310781
468.6000000000063,161.69337279898073,-2.0084518260498543,-0.08020293800656164
470.00000000000625,162.15820828067748,-2.011826890139716,-0.08222997344677241
471.4000000000063,162.62392733827147,-2.015394375282588,-0.0823858125209469
472.8000000000063,163.09167332414302,-2.0181139805290274,-0.08409011160529412
474.2000000000063,163.5605832150928,-2.0199350062870858,-0.08511476861974243
475.60000000000633,164.02814599362935,-2.022756167407449,-0.08442041044892568
477.00000000000637,164.49876615921465,-2.0269166307075106,-0.08538218612434267
478.4000000000064,164.97055304532492,-2.0287684172048883,-0.08411262405268038
479.80000000000643,165.4424134258094,-2.0312313889699927,-0.08540924108490167
481.2000000000064,165.91472542114045,-2.033967608437165,-0.0857388934022758
482.60000000000645,166.37439960193188,-2.0354407282530995,-0.08631265633333207
484.0000000000065,166.8386558482721,-2.0383362706136072,-0.08672006073792637
485.40000000000646,167.30123721204944,-2.041436121299657,-0.08803993598424231
486.8000000000065,167.7678701488327,-2.0416964793369274,-0.08915948307033261
488.2000000000065,168.23531383074206,-2.0498394160661446,-0.08969041197359662
489.60000000000656,168.70897505748616,-2.0507900783496775,-0.0883700882293117
491.0000000000066,169.17538542101778,-2.052413406754126,-0.09103271228552767
492.40000000000657,169.64463383676264,-2.056212442860046,-0.08887171868150157
493.8000000000066,170.1189264463608,-2.0584930295017734,-0.09164682523354051
495.20000000000664,170.58842097171143,-2.06224065446539,-0.09099677195982592
496.6000000000066,171.05408823518565,-2.0621345036700545,-0.09100041634436717
498.00000000000665,171.5200000000023,-2.066009999999861,-0.09165994500408692
499.4000000000067,171.9844926699207,-2.068410452438627,-0.0923141983945861
500.8000000000067,172.4517993827469,-2.07170266054057,-0.09362872992744453
502.20000000000675,172.9199966429383,-2.075830063862516,-0.09363987921001904
503.60000000000673,173.38283959751132,-2.0779591677530562,-0.0942998735691094
505.00000000000676,173.85162065444217,-2.080210230273612,-0.0952784046017201
506.4000000000068,174.32493711625136,-2.082010879629115,-0.0956104261336641
507.8000000000068,174.79571398916397,-2.08614519637148,-0.09568423365198919
509.2000000000068,175.27085526982145,-2.0899246177804183,-0.09791992499995583
510.60000000000684,175.7365872741058,-2.0914711738974234,-0.09824991240644021
512.0000000000068,176.2058071739824,-2.094342150714738,-0.09726987947252619
513.4000000000069,176.6719819796596,-2.0991351482847613,-0.09890984469036646
514.8000000000069,177.14368800170647,-2.10187673121238,-0.09895613731357589
516.2000000000069,177.61145920957338,-2.1054366856981748,-0.10023017931621592
517.600000000007,178.0787301227333,-2.1099265647810808,-0.10023469546167263
519.0000000000069,178.54709917861013,-2.110806576476607,-0.10187462086480847
520.4000000000069,179.01346538163435,-2.115722011926984,-0.1006530942456969
521.800000000007,179.48257017021578,-2.117189637291692,-0.10056013067072023
523.2000000000071,179.9559662065021,-2.1217897068338196,-0.10220003489210372
524.6000000000071,180.42267482897537,-2.12573445344631,-0.10318471594257961
526.000000000007,180.89622604250576,-2.128831289457946,-0.1045104686992584
527.4000000000071,181.36467671747124,-2.1326147319461746,-0.10382251526314956
528.8000000000071,181.83758006395036,-2.135732809544275,-0.10516939781683865
530.2000000000071,182.3079831074246,-2.1421254349433747,-0.10583012500000155
531.6000000000072,182.77873669826675,-2.142898292792362,-0.10714206938142956
533.0000000000072,183.245836658769,-2.1451351117970896,-0.10714021017139119
534.4000000000071,183.72089355606477,-2.1495619296415795,-0.10782270758073942
535.8000000000072,184.19504680474603,-2.15203782757614,-0.10812980133621863
537.2000000000072,184.6653377156689,-2.154473136822086,-0.11043998510144082
538.6000000000072,185.13531870693248,-2.1567835525096384,-0.10977998499836561
540.0000000000073,185.60645712922465,-2.1608376897009123,-0.1104300289721083
541.4000000000073,186.07853250690738,-2.166410196866337,-0.1124099086277699
542.8000000000073,186.54688514628475,-2.1669160304478567,-0.11306468292153404
544.2000000000073,187.0138083428597,-2.1682582280530736,-0.11280417146719701
545.6000000000073,187.48139398776667,-2.1738360844193694,-0.1133999514702495
547.0000000000074,187.93163581651427,-2.1804783676638597,-0.11328163581630601
548.4000000000074,188.4238469349571,-2.183696649037989,-0.11471991703556395
549.8000000000075,188.89579681634967,-2.18872235470873,-0.11603009500000061
551.2000000000074,189.36412108894024,-2.1912908523348755,-0.11701993019779433
552.6000000000074,189.8364515497406,-2.1955591532576135,-0.11757032840257287
554.0000000000075,190.30585030139363,-2.1932209834459226,-0.11911572238671875
555.4000000000075,190.77417472600445,-2.198855264184029,-0.12032030582459763
556.8000000000075,191.2441488624799,-2.2020042169471417,-0.12103073582673929
558.2000000000075,191.71969075294555,-2.2055191233073876,-0.1209803598799084
559.6000000000075,192.19666226161803,-2.20977103028999,-0.12295999029143845
561.0000000000075,192.66255520590767,-2.2125546694030955,-0.1235098818093987
562.4000000000076,193.1356598930616,-2.2176494731277536,-0.12454896064594356
563.8000000000076,193.60588495883837,-2.2197591570918784,-0.12492996637060738
565.2000000000077,194.0775452065252,-2.2234578587293874,-0.12591919638783633
566.6000000000076,194.55309353881685,-2.2290927352077303,-0.12690998560401656
568.0000000000076,195.0260736344778,-2.2324256605984685,-0.12954018549491053
569.4000000000077,195.49467410414522,-2.2319479721748037,-0.1295400743420263
570.8000000000077,195.9686570184806,-2.237442105659042,-0.1321800491587437
572.2000000000078,196.4418536016744,-2.243349735892495,-0.13196003858515803
573.6000000000078,196.91563837049128,-2.245550320926452,-0.1329400284454696
575.0000000000077,197.39103785348533,-2.249129107114201,-0.13458994368399235
576.4000000000078,197.8649400427705,-2.252421900040715,-0.1355778430788499
577.8000000000078,198.33911279152798,-2.258134364521289,-0.13692301182946753
579.2000000000078,198.8072982088141,-2.261747894319672,-0.13798983018808064
580.6000000000079,199.28000677351164,-2.2661706817986937,-0.1383198057798416
582.0000000000078,199.75000000000338,-2.269059999999815,-0.14129266251743156
583.4000000000078,200.21701486612466,-2.276049449915047,-0.14127031700261483
584.8000000000079,200.69042662687144,-2.281988923470616,-0.1416229888315952
586.2000000000079,201.1629836689594,-2.2856658244178063,-0.1442501357845467
587.600000000008,201.6343260144988,-2.292297594993072,-0.14528312329947957
589.000000000008,202.1106739217006,-2.295908000406173,-0.14754003005317795
590.4000000000079,202.57446697853334,-2.3026414147013896,-0.14919485925902176
591.800000000008,203.05003270995337,-2.3072034524467195,-0.1493982835423724
593.200000000008,203.53638859979338,-2.310517844285579,-0.15412992332634667
594.6000000000081,204.00368384174766,-2.3166728693387384,-0.15412986754031133
596.0000000000081,204.47778941085835,-2.3218658550241393,-0.15741993527061826
597.400000000008,204.9537605196545,-2.3274037060258825,-0.15938862413295452
598.8000000000081,205.42788686416114,-2.3353328518227108,-0.16006001995952257
600.2000000000081,205.89838022832896,-2.341224466748883,-0.1628335979791875
601.6000000000081,206.36847740891702,-2.348935277282318,-0.16501262557481633
603.0000000000082,206.8434137498587,-2.354895893984258,-0.16892970247834693
604.4000000000082,207.3199931201579,-2.3587997868701565,-0.17158001993648186
605.8000000000081,207.79084524468786,-2.365429829422088,-0.17289753114011663
607.2000000000082,208.26787301559222,-2.3724941866429408,-0.17585789163791343
608.6000000000082,208.74293586354628,-2.3755730731582676,-0.17943682844316333
610.0000000000083,209.21041117623076,-2.3829160655295833,-0.1820814494386438
611.4000000000083,209.68936936339227,-2.3896625494626313,-0.1853561717497927
612.8000000000083,210.16204088308893,-2.396723567182994,-0.18937064920567748
614.2000000000083,210.63703461057196,-2.405913812128344,-0.19068956148063743
615.6000000000083,211.11454143353873,-2.4138067419008977,-0.19424475617812398
617.0000000000084,211.591264677991,-2.4223344493763292,-0.20011020190652085
618.4000000000084,212.06417984363364,-2.4257287364003552,-0.20426271948067942
619.8000000000084,212.53487755045995,-2.4342737588784025,-0.20747987028875903
621.2000000000085,213.0114787519234,-2.4432828699690314,-0.2087998441778418
622.6000000000084,213.4806183327776,-2.453953560976791,-0.21407784536460328
624.0000000000084,213.953511547541,-2.462508022452807,-0.21800893836320778
625.4000000000085,214.43304056189942,-2.4733993251315156,-0.22395817469899848
626.8000000000085,214.90784973944054,-2.4848797304690495,-0.2279091568893734
628.2000000000085,215.38773960521507,-2.494312449068432,-0.23251985623402582
629.6000000000085,215.86099143249768,-2.5053797564688316,-0.23775341179988763
631.0000000000085,216.3340064189,-2.5170177385903547,-0.2424000615408861
632.4000000000086,216.81316722170845,-2.5273004939602006,-0.2494971351415738
633.8000000000086,217.28357235459396,-2.5393111309694296,-0.2559062275421531
635.2000000000086,217.75820173600732,-2.5535244718637844,-0.26249126845640447
636.6000000000087,218.2334936901897,-2.566518036133007,-0.26677014663639387
638.0000000000086,218.70663764681262,-2.580066113206412,-0.27464628061956375
639.4000000000087,219.17947956128464,-2.595772300028447,-0.28059992321540506
640.8000000000087,219.6564318351868,-2.60724026552091,-0.2898430410960211
642.2000000000087,220.13039937802066,-2.624016164367066,-0.2964126072972624
643.6000000000088,220.61330967011662,-2.639847559673621,-0.30460190774494356
645.0000000000088,221.08823619669346,-2.653272341926332,-0.3132103609639061
646.4000000000087,221.56163864136906,-2.668215086628454,-0.32178011067501444
647.8000000000088,222.0368661256224,-2.6862946357135042,-0.330269585703896
649.2000000000088,222.515282419476,-2.70317397991472,-0.3400782697733775
650.6000000000088,222.98863683351223,-2.717985146732407,-0.3500698090536454
652.0000000000089,223.46308989792328,-2.7347646479440866,-0.35933132788363586
653.4000000000088,223.93977211618264,-2.7542780258054926,-0.3687590256363493
654.8000000000089,224.4184842304601,-2.771215432407374,-0.3815218850063862
656.2000000000089,224.89814218462294,-2.7910369947328353,-0.3939946769924969
657.6000000000089,225.3769855887507,-2.8097964918208747,-0.4032268255130398
659.000000000009,225.84776531193148,-2.829894520941326,-0.41668578449279314
660.400000000009,226.3215042297058,-2.849252909864569,-0.43026435745171954
661.800000000009,226.80047947787784,-2.8745802866291417,-0.44422301325710345
663.200000000009,227.27383575111705,-2.8192186678431463,-0.456837308457954
664.600000000009,227.75030096679427,-2.8334599828767497,-0.47339879852162614
666.0000000000091,228.22000000000233,-2.852999999999973,-0.48929081222879267
667.4000000000091,228.69540476066177,-2.8785369183653104,-0.5052878479757226
668.800000000009,229.17000421857875,-2.903060077923327,-0.5199303333353291
670.2000000000091,229.64734681875515,-2.9278440491254525,-0.5398929959021284
671.6000000000091,230.12602536852575,-2.954865815383324,-0.5578859667340148
673.0000000000091,230.60059277711096,-2.97998187572892,-0.57738132935842
674.4000000000092,231.07760576129277,-3.004094647899193,-0.5964550464520055
675.8000000000092,231.55462040110152,-3.033083076539101,-0.6156625766116925
677.2000000000093,232.03249449896722,-3.0612295682994013,-0.6371134119285684
678.6000000000092,232.5132272196454,-3.0912951346651814,-0.6588578815182178
680.0000000000092,232.99199221596223,-3.1246828835953053,-0.6813760019383448
681.4000000000093,233.4753349724341,-3.1569943876377096,-0.7060654711331469
682.8000000000093,233.9535643184683,-3.183553854348079,-0.72985016253919
684.2000000000094,234.42741871046172,-3.210882594028234,-0.7536068873935169
685.6000000000093,234.90206736551977,-3.2399267358623676,-0.7795438159058743
687.0000000000093,235.37424761143527,-3.2690360097941924,-0.804363797185951
688.4000000000094,235.85390125793694,-3.2993582982174003,-0.8313811012556611
689.8000000000094,236.33456028536557,-3.3294451234131834,-0.8604580487231828
691.2000000000094,236.81493917919724,-3.3562148958625935,-0.8902160512742459
692.6000000000095,237.2965556244049,-3.3827767765402554,-0.9188891458010828
694.0000000000094,237.77742963669562,-3.3996696858619426,-0.9508127891781908
695.4000000000094,238.25883797409008,-3.4207247842735065,-0.9818143292032837
696.8000000000095,238.73472913832865,-3.4362960973302785,-1.0114269247208374
698.2000000000095,239.21083643003612,-3.440034708204939,-1.041939191349274
699.6000000000096,239.68669248427207,-3.442859754433244,-1.076314089898593
701.0000000000095,240.1616019348081,-3.431110145838,-1.1059007584314933
702.4000000000095,240.63636351020256,-3.4062199284810686,-1.1363148421234621
703.8000000000096,241.11285219156696,-3.3638875397757912,-1.1666067988130764
705.2000000000096,241.5720395009463,-3.3114145276541653,-1.1927757470607645
706.6000000000097,242.04240335742946,-3.2416906051716023,-1.2197210573281945
708.0000000000097,242.51207376103397,-3.155327195496105,-1.2412799499514202
709.4000000000096,242.979409457099,-3.059026051280758,-1.2625795252836909
710.8000000000097,243.44729185137487,-2.973918487913061,-1.2791421277197768
712.2000000000097,243.91823642675507,-2.887674109040918,-1.2962197812759833
713.6000000000097,244.3846378919429,-2.7993936791028196,-1.3078073686890317
715.0000000000098,244.85321159871594,-2.717965849733734,-1.3176814695202648
716.4000000000098,245.32629373505227,-2.648293055286617,-1.3251931151543248
717.8000000000097,245.79896481500782,-2.5915831012375454,-1.3308016735523651
719.2000000000098,246.26884971228657,-2.5486499430611436,-1.3348312722826172
720.6000000000098,246.73615233775317,-2.522915656364334,-1.3374419516855447
722.0000000000099,247.2065365052034,-2.502243182698453,-1.3404473218814128
723.4000000000099,247.68446650912995,-2.4929110858746006,-1.341760191202562
724.8000000000098,248.15750745872714,-2.490768955646017,-1.3431421004208026
726.2000000000099,248.63130698002294,-2.4883707475389794,-1.3444024037194935
727.6000000000099,249.1140032850336,-2.488362360013891,-1.3453798230508816
729.00000000001,249.5861642498069,-2.486091342718374,-1.3440769541462005
730.40000000001,250.06503222470522,-2.4873452846042183,-1.3444098043685555
731.80000000001,250.54271510848957,-2.487981910171807,-1.3457058168595069
733.20000000001,251.01372250632062,-2.489114271070695,-1.3450598883438092
734.60000000001,251.4938561857702,-2.4950034167816386,-1.345720040000085
736.00000000001,251.97128343174438,-2.4970483245799153,-1.3447192481770376
737.4000000000101,252.44379172650213,-2.4987015793998593,-1.3444000400000005
738.8000000000101,252.93137005761446,-2.5005940898213463,-1.3444000604973887
740.20000000001,253.40842912689604,-2.5005868896471046,-1.3460492925907226
741.6000000000101,253.88178054949606,-2.5054472902197866,-1.3447299349998492
743.0000000000101,254.35715889855734,-2.5072124155989988,-1.3467062986618168
744.4000000000102,254.83343812257525,-2.5117182488322216,-1.3450591138149726
745.8000000000102,255.31269514411113,-2.5144675399553154,-1.3434188185564544
747.2000000000102,255.79366309988598,-2.519601739676969,-1.3453932071944137
748.6000000000103,256.27235775848334,-2.52349004435581,-1.3447301821211455
750.0000000000102,256.74679889258243,-2.525986218298697,-1.3447373650681587
751.4000000000103,257.21924335270404,-2.5305595248811006,-1.34374990496271
752.8000000000103,257.6973143649928,-2.5341330037508087,-1.3434213841104814
754.2000000000103,258.1760206169706,-2.5381844101744027,-1.3457200550000006
755.6000000000104,258.65963413415585,-2.5378925687197995,-1.3463298093102107
757.0000000000103,259.1338845306036,-2.54293967914347,-1.3438612475177796
758.4000000000103,259.6127345678169,-2.544888588425121,-1.345169902289749
759.8000000000104,260.0892417059012,-2.5448456067678906,-1.3448500849647584
761.2000000000104,260.56226735924963,-2.5485908619503572,-1.3441665920719679
762.6000000000104,261.03687777164066,-2.549160227804768,-1.3468185547600524
764.0000000000105,261.51330690571626,-2.554094532099912,-1.345172745243849
765.4000000000104,261.995711920022,-2.556891176770784,-1.3468205894564789
766.8000000000105,262.4761085528794,-2.5622909409113706,-1.3455940122484842
768.2000000000105,262.9522902789839,-2.5678888170435505,-1.349193459956327
769.6000000000105,263.43036001043384,-2.5710122095830585,-1.3481401074382204
771.0000000000106,263.90159617489513,-2.57742394525432,-1.346928530964472
772.4000000000106,264.3759631295093,-2.5791683310952775,-1.3472598399999995
773.8000000000106,264.86162972864486,-2.582034214339785,-1.3469195365772593
775.2000000000106,265.34533314536657,-2.5789178081339115,-1.3476460223147448
776.6000000000106,265.81711773191967,-2.58170558565115,-1.3475796378203433
778.0000000000107,266.2951909762775,-2.58469546902322,-1.3485701589145145
779.4000000000107,266.770650932341,-2.584982044459585,-1.3485701627773716
780.8000000000106,267.2457023055479,-2.5863381026653722,-1.3475910166017213
782.2000000000107,267.7235315703042,-2.5864482638783692,-1.346600194897654
783.6000000000107,268.1992139470507,-2.5900810974754274,-1.3469298576802062
785.0000000000107,268.6785180666369,-2.590423757551058,-1.346910619930512
786.4000000000108,269.1599926333247,-2.594178898099118,-1.348250626321744
787.8000000000108,269.6457796460504,-2.5999534361317838,-1.3475897300807653
789.2000000000108,270.12877343956467,-2.5993407455736595,-1.3485800428743513
790.6000000000108,270.59926628367793,-2.5991295508248182,-1.3472652125151452
792.0000000000108,271.07110969979044,-2.602633356616772,-1.3482500219909626
793.4000000000109,271.5499921698921,-2.604530132367967,-1.3485800280478517
794.8000000000109,272.0310021594781,-2.6077020530732327,-1.3472600299999993
796.200000000011,272.50968214076204,-2.612382503491207,-1.3462754277364208
797.6000000000109,272.99199684612466,-2.617123286001611,-1.3465065220778012
799.0000000000109,273.46765214671075,-2.620602072286329,-1.3482401218083107
800.400000000011,273.9459403879781,-2.6250578392671415,-1.345570890353847
801.800000000011,274.42413490704536,-2.627512195985954,-1.348570019119831
803.200000000011,274.89839021317715,-2.6308952931828404,-1.3495825715834573
804.600000000011,275.3756430183587,-2.6342162389396955,-1.3482360234252573
806.000000000011,275.85143789420033,-2.6370823595668687,-1.349230247890354
807.400000000011,276.3320414549937,-2.6461653243905783,-1.347911015496273
808.8000000000111,276.80432115491413,-2.6476308711011236,-1.3492404653879722
810.2000000000111,277.2855632010612,-2.653093501947353,-1.3498999761693415
811.6000000000112,277.7600072577409,-2.6553392395114375,-1.349899890914453
813.0000000000111,278.24090412182625,-2.658125904973249,-1.348579889999129
814.4000000000111,278.715340710275,-2.663906544725478,-1.3492401450051528
815.8000000000112,279.192932840461,-2.666813679516543,-1.349890072620795
817.2000000000112,279.67679761583304,-2.6687758700932185,-1.3487039545229322
818.6000000000113,280.15545233849684,-2.668938431852902,-1.3492307220205495
820.0000000000113,280.6264635163549,-2.6691227219624283,-1.348569744025549
821.4000000000112,281.10795349594883,-2.676403305027921,-1.3508799422311033
822.8000000000113,281.5900044962013,-2.682320498972828,-1.3492299504526981
824.2000000000113,282.0635396339375,-2.683121074098358,-1.3508800878433989
825.6000000000113,282.54225510061684,-2.6883808941185565,-1.3495598690170945
827.0000000000114,283.02218068021375,-2.6923308070950354,-1.3508061461437575
828.4000000000113,283.502038480942,-2.6943114437365687,-1.3495403497624117
829.8000000000113,283.9743896394005,-2.703730759568903,-1.350946966449801
831.2000000000114,284.45080237425634,-2.705390308491949,-1.349900155005873
832.6000000000114,284.93672865815654,-2.7056603281949023,-1.3515301106561273
834.0000000000115,285.4200000000054,-2.7114300000003766,-1.35055018
835.4000000000115,285.89798078899753,-2.715029412990004,-1.3505501802315845
836.8000000000114,286.3716042401818,-2.7186219015138846,-1.3502179998804045
838.2000000000115,286.8485424104364,-2.72014890632221,-1.3502208943434284
839.6000000000115,287.3212615246092,-2.723195943217937,-1.3502200000000002
841.0000000000116,287.80640341887965,-2.7259966582501534,-1.350220000000041
842.4000000000116,288.2817402867826,-2.726759887974533,-1.3512098200825573
843.8000000000116,288.76429800652045,-2.7262177342503313,-1.3501792762891518
845.2000000000116,289.2397017066882,-2.7314228465486687,-1.350549969999986
846.6000000000116,289.72230297832004,-2.731982509538665,-1.3508799960927087
848.0000000000116,290.204141242849,-2.7367283824715094,-1.3498926563759088
849.4000000000117,290.68853732766627,-2.7413607122671104,-1.3502199586429162
850.8000000000117,291.1687020775304,-2.7436568687901524,-1.3502205494046335
852.2000000000116,291.64650123991214,-2.7441494651142166,-1.349890194999933
853.6000000000117,292.12060079847936,-2.7442861142704102,-1.349890194999999
855.0000000000117,292.5954495252509,-2.7441032012776083,-1.3498898560638968
856.4000000000118,293.07673788337365,-2.745258485948383,-1.3508883355005072
857.8000000000118,293.55660297955484,-2.744860426613671,-1.3508800148068976
859.2000000000118,294.0353356731507,-2.745813707128326,-1.3508927173416696
860.6000000000118,294.51384798280304,-2.7496687729794744,-1.3505432950961782
862.0000000000118,294.994957473587,-2.7595723010729345,-1.3513927235603345
863.4000000000119,295.4718599370284,-2.7565546897715043,-1.3502201150010777
864.8000000000119,295.95457223608264,-2.759509990828003,-1.3515165780478258
866.2000000000119,296.42883437905715,-2.7608487854702672,-1.3502503893379516
867.600000000012,296.9013845025578,-2.766179088475664,-1.3505596369251704
869.0000000000119,297.3807750046426,-2.7701745541757923,-1.3521991352826332
870.4000000000119,297.85590589977176,-2.7752954108179466,-1.3508003906332644
871.800000000012,298.337111392918,-2.7806102940790716,-1.3508800588138334
873.200000000012,298.81695344877704,-2.7846148813514238,-1.3495728335792392
874.600000000012,299.2978005919067,-2.7852918578863735,-1.3508801492738343
876.000000000012,299.7745785275194,-2.7874634762862383,-1.3502301303838231
877.400000000012,300.2545652325561,-2.7980747046411247,-1.35055922323677
878.8000000000121,300.73046506551145,-2.8011835265907408,-1.3515399000000001
880.2000000000121,301.2078899980291,-2.8065029286397025,-1.351565954939094
881.6000000000121,301.6848946155898,-2.807831082974891,-1.352293196664101
883.0000000000122,302.1646297172433,-2.814531333683198,-1.3505500382808724
884.4000000000121,302.6485032768248,-2.820741141245886,-1.3515912189350838
885.8000000000122,303.13267233827906,-2.824647069770715,-1.3515413525434
887.2000000000122,303.60768973781217,-2.8281277574566794,-1.351210024224112
888.6000000000122,304.08321316147016,-2.8312428596420864,-1.3515400951867709
890.0000000000123,304.5676891869288,-2.835448590813874,-1.3514925643167568
891.4000000000123,305.0443443044885,-2.839039271998589,-1.3518698367880009
892.8000000000122,305.5215716831985,-2.841862619198446,-1.3515329622949062
894.0000000000123,305.9309696287376,-2.8433277969657853,-1.3519860441153497