File: 01_Data/Nylon_Carpet_Low_Pile/STA/N2/30K_min/Nylon_Carpet_Low_Pile_STA_N2_30KData_220107_R3.csv
##Temp./Â°C,Time/min,DSC/(mW/mg),Mass loss/mg
49.0,10.499490168168508,-0.9322822446592874,-0.012404774029595167
50.30000000000002,10.730904172306268,-0.7653264979565213,-0.010941512587255176
51.60000000000004,10.869644933941125,-0.6440113220158628,-0.011842739330877539
52.900000000000055,10.97732000854522,-0.5428087766970581,-0.010688734923140597
54.200000000000074,11.06852879504619,-0.45646949153701455,-0.012484540322412307
55.50000000000009,11.150328537423542,-0.3775125555563081,-0.012888903108530858
56.80000000000011,11.224605393551983,-0.308459456874758,-0.013811825225749974
58.10000000000013,11.294626927958253,-0.2439089824116361,-0.0134062626012601
59.40000000000015,11.359840531102384,-0.18450707681207648,-0.013306544800292919
60.700000000000166,11.422017125391966,-0.12890203665239575,-0.013083475422465352
62.000000000000185,11.482552405873587,-0.07652427828102094,-0.012545992905416359
63.3000000000002,11.540122276242608,-0.02827359405311943,-0.012061099384344853
64.60000000000022,11.596190613652286,0.018419600615677687,-0.013473048372503182
65.90000000000023,11.65089829336796,0.06138281381244962,-0.0142716792221389
67.20000000000026,11.70498749346909,0.10326038503337524,-0.014285590014630145
68.50000000000028,11.756646934429922,0.14337973798548082,-0.013202386927609222
69.8000000000003,11.809053147194145,0.18247248684109843,-0.013626926136738327
71.1000000000003,11.859391991501083,0.21682951382930848,-0.011269498849731718
72.40000000000033,11.909504257492603,0.2507903164563055,-0.006738161287255906
73.70000000000036,11.959094367199166,0.28322803388872886,-0.004063756246914352
75.00000000000037,12.008219579645132,0.31517871740997605,-0.005963412703061444
76.30000000000038,12.056866818401192,0.3443817614581663,-0.006844337454091409
77.6000000000004,12.104461094190402,0.37159539257659463,-0.012212395683364186
78.90000000000043,12.152648543056866,0.39930521608843056,-0.01526752996023717
80.20000000000044,12.199767538773203,0.4249178869927559,-0.01546089359746139
81.50000000000045,12.246856142999627,0.45208366526010346,-0.015561585307852788
82.80000000000048,12.29333360445093,0.47448366211170134,-0.01616097254617843
84.1000000000005,12.339645379650614,0.49679396778608015,-0.017160853011950028
85.40000000000052,12.385885167097602,0.5214281775453208,-0.016005984589546163
86.70000000000053,12.43150476315444,0.5435237741928609,-0.015444446807908907
88.00000000000055,12.476675793121585,0.5642780072664035,-0.014054527062667077
89.30000000000058,12.521930554468023,0.5851263250821261,-0.01294439947680992
90.60000000000059,12.567165206003667,0.6035595640817819,-0.012248485506830331
91.9000000000006,12.612069779665717,0.6249831496686513,-0.012179621799403684
93.20000000000063,12.656626488241187,0.6448030198866452,-0.01355834701569103
94.50000000000065,12.70184639882105,0.6633679526540373,-0.014802269364899256
95.80000000000067,12.745893342284411,0.6822288396622798,-0.014923290283191726
97.10000000000068,12.790388171803299,0.7015075353106001,-0.016204951130971423
98.4000000000007,12.83458806690034,0.7195790640762617,-0.01685733753985552
99.70000000000073,12.878905682249705,0.7357570451208509,-0.018618993776305715
101.00000000000074,12.922929768742483,0.7530555440920497,-0.017025163410863353
102.30000000000075,12.96693076018271,0.7696219677666891,-0.015948308250719023
103.60000000000078,13.010796733178159,0.7861933352808584,-0.0145219402294261
104.9000000000008,13.054948388458518,0.8003460970383851,-0.01364659963919257
106.20000000000081,13.0988291845324,0.8154723550579231,-0.014308533003422497
107.50000000000082,13.14226695964622,0.8294881948785796,-0.015479718095098072
108.80000000000085,13.185972282049816,0.8440838938315502,-0.016001652023666768
110.10000000000088,13.229445748235198,0.8562203835674776,-0.016382794092929753
111.40000000000089,13.273476731508795,0.8692375584550179,-0.016011445783813194
112.7000000000009,13.31736171429624,0.8833784015967981,-0.016010107921411443
114.00000000000092,13.360529219649898,0.8939239243252844,-0.01601079059078314
115.30000000000095,13.404420844564118,0.9071423796831795,-0.015645369454406755
116.60000000000096,13.447246347154191,0.9198528629866369,-0.01569943555285569
117.90000000000097,13.491453695725793,0.9305550480125789,-0.01712102192430809
119.200000000001,13.534327395815465,0.9430893213009663,-0.01711982937078327
120.50000000000102,13.577388158934635,0.9521554479256851,-0.018430459644282582
121.80000000000103,13.620689215499453,0.9653499543293221,-0.0184361344167856
123.10000000000105,13.664005247142292,0.9753531664444657,-0.017003295664436813
124.40000000000107,13.707116944873135,0.9885222635957616,-0.015863325196138423
125.7000000000011,13.75007009629454,0.9986989335348408,-0.01568186127193938
127.00000000000111,13.792579131321201,1.0121084296731346,-0.01646926765760659
128.30000000000112,13.835778229413242,1.0228137495073317,-0.01773059998851023
129.60000000000116,13.87811306915102,1.0369073009535557,-0.019412655209271712
130.90000000000117,13.921004642441424,1.0475898035838667,-0.02039513792803671
132.20000000000118,13.963327432553193,1.0595292008154342,-0.02203662828522379
133.5000000000012,14.005650346547354,1.0720012670181096,-0.020015328352823047
134.8000000000012,14.04780887340609,1.084389742407048,-0.01700332775881952
136.10000000000124,14.090170034056664,1.0987529771777604,-0.017015320008564316
137.40000000000126,14.132159793589372,1.1084181477285489,-0.017439491831194864
138.70000000000127,14.17442451732598,1.1245571629129623,-0.01700131442637165
140.0000000000013,14.21675594152808,1.1358459389675881,-0.018086178184438584
141.30000000000132,14.258650561290771,1.1510406069228094,-0.018319738541921815
142.60000000000133,14.300143502002411,1.1639188629194308,-0.018319812181191164
143.90000000000134,14.34218321092538,1.1799551544789628,-0.018319522897081164
145.20000000000135,14.383787433913195,1.1965611409648675,-0.018233247159901822
146.5000000000014,14.425555114634903,1.2107545169671245,-0.018655370372148372
147.8000000000014,14.46708073579575,1.227658477182379,-0.018923619247366297
149.10000000000142,14.508646810868422,1.245674931193025,-0.01911774511082509
150.40000000000146,14.550176658531763,1.2632126848223024,-0.020294869295446993
151.70000000000147,14.591609840934677,1.2865190189334663,-0.019439279187396075
153.00000000000148,14.632708371003586,1.3065354605532804,-0.020415938433153258
154.3000000000015,14.674365313417892,1.3302210566228745,-0.02161243230285148
155.6000000000015,14.715936298485907,1.356194864089889,-0.021609813208557593
156.90000000000154,14.756858569890227,1.3847823135152295,-0.021609372790607928
158.20000000000155,14.79802756208833,1.412349714192251,-0.0215574181489675
159.50000000000156,14.83956888506922,1.4421403842720852,-0.022930787335964542
160.8000000000016,14.88021971684856,1.4730908216101886,-0.0215278794922642
162.10000000000161,14.921653885021561,1.5011078745176718,-0.0213966372695662
163.40000000000163,14.962763344549243,1.5265981537352031,-0.020175752217382215
164.70000000000164,15.003619540891886,1.5408328034164018,-0.02017356241424917
166.00000000000165,15.044764890611729,1.5459484378109267,-0.02145419907452517
167.3000000000017,15.085594323273236,1.5425505386916174,-0.02150585968794072
168.6000000000017,15.126772277808058,1.5347178314565206,-0.02084359992954221
169.9000000000017,15.167794422478384,1.5251030611085987,-0.020838459801050035
171.20000000000175,15.208288483823347,1.5154423890343418,-0.022815502006693134
172.50000000000176,15.248430572213413,1.5049486139444532,-0.022819862004975988
173.80000000000177,15.289806901359247,1.5006847489769963,-0.022823410847189418
175.10000000000178,15.330667853800426,1.4956388952061883,-0.02248815281591643
176.4000000000018,15.37124456181371,1.494740506488052,-0.02248986946660736
177.70000000000184,15.411598413091621,1.4977519764019636,-0.022489632886300903
179.00000000000185,15.45139461274613,1.5000569639004657,-0.022434604619736565
180.30000000000186,15.492736299266765,1.5080565434192617,-0.025114591874295655
181.6000000000019,15.53320598578084,1.5140729948915506,-0.025115439667025008
182.9000000000019,15.572942123747207,1.5232423634490315,-0.023897059024521994
184.20000000000192,15.613327480309822,1.53341078170979,-0.023753204695870167
185.50000000000193,15.653796260445683,1.5433908743628748,-0.025778632041919103
186.80000000000194,15.693627497267935,1.5531306634712523,-0.02576984139352323
188.10000000000198,15.733918944277338,1.565518112820333,-0.025740135228768946
189.400000000002,15.773977442339,1.5755527754859684,-0.025634062765127474
190.700000000002,15.813938472525159,1.586288833841076,-0.025443484707170505
192.00000000000205,15.853821685536023,1.599167288451067,-0.022486931830309587
193.30000000000206,15.893865059555432,1.6104869004305071,-0.02149518548978424
194.60000000000207,15.93392858403542,1.6230190383486034,-0.020076774401944775
195.90000000000208,15.973764211348172,1.6358683055348635,-0.020490356921775366
197.2000000000021,16.01387256425014,1.6492831309726343,-0.021503329297154483
198.50000000000213,16.05350389956569,1.662080980791787,-0.02149401798380879
199.80000000000214,16.093309008663393,1.6765304156255718,-0.0226853791832462
201.10000000000215,16.133152026208563,1.690028735340369,-0.024226784982187777
202.4000000000022,16.17274758853676,1.7069793978251768,-0.024546752485000933
203.7000000000022,16.212733960627272,1.7223064761934685,-0.025494023535447052
205.00000000000222,16.252691898500206,1.7405451089221051,-0.02730368191495991
206.30000000000223,16.292153978775254,1.7604909247675136,-0.029507249304895122
207.60000000000224,16.33195662499881,1.7804731076204696,-0.030395561207434252
208.90000000000228,16.371740407810655,1.8045440729712021,-0.028923298742576264
210.2000000000023,16.411274552399842,1.833816863117558,-0.026891936586008303
211.5000000000023,16.45134084712144,1.8748180144218165,-0.02532519997994953
212.80000000000234,16.490648708772138,1.931068169763268,-0.024492865564009314
214.10000000000235,16.52978174306367,2.009475605485279,-0.024021028047173765
215.40000000000236,16.57015646925902,2.111562582344582,-0.024017963703210743
216.70000000000238,16.609720082474034,2.2335692217459284,-0.025097656707965044
218.0000000000024,16.64961741845623,2.374020454856106,-0.025988035143888588
219.30000000000243,16.689598344037186,2.5149362284869468,-0.024654972374615447
220.60000000000244,16.728884337713733,2.621902863503407,-0.02468020768364676
221.90000000000245,16.769009020558315,2.6711519786988513,-0.024680190763495702
223.2000000000025,16.80874540293563,2.6428450642184784,-0.024680183302663306
224.5000000000025,16.848599483116665,2.565728868973976,-0.02467835572957444
225.8000000000025,16.888517911893278,2.467569847461872,-0.025929074538209917
227.10000000000252,16.927966997710925,2.370573782560859,-0.025991378166873247
228.40000000000254,16.967364250565524,2.2819440984988506,-0.026736196856074645
229.70000000000258,17.007010635114714,2.2038246820749285,-0.027817487949477027
231.0000000000026,17.04633184286893,2.1420794087111985,-0.02929845924767971
232.3000000000026,17.0854944211544,2.0913755724734773,-0.029688339708018763
233.60000000000264,17.125214888056313,2.0532774874281676,-0.02926815955262274
234.90000000000265,17.164593236859023,2.023940698128069,-0.02937151869645538
236.20000000000266,17.203905815550765,2.005852818279356,-0.02928046332108636
237.50000000000267,17.243089948154037,1.9895736467637115,-0.02854925361000138
238.80000000000268,17.282269906445354,1.9822214923319612,-0.02808830657526551
240.10000000000272,17.321943052539066,1.975290156162274,-0.02939343985503662
241.40000000000273,17.36113128245325,1.9720529461379703,-0.029390016583588974
242.70000000000275,17.40043791017687,1.9729861614424697,-0.02940194938062879
244.00000000000279,17.439584591894953,1.9728717636156312,-0.02807625584158213
245.3000000000028,17.479012089318644,1.9741370198544774,-0.02938478327224381
246.6000000000028,17.51830913871371,1.9783472915396425,-0.029390978434344905
247.90000000000282,17.55746499411163,1.9817394256865872,-0.027924562336314906
249.20000000000283,17.59648390742476,1.986999454180143,-0.0263698449157328
250.50000000000287,17.63591166715502,1.9923945415719473,-0.025982967425310033
251.80000000000288,17.67549984168981,1.9963176928676956,-0.02695007345456757
253.1000000000029,17.714691835445077,2.001584623773394,-0.02764028700093224
254.40000000000293,17.75399628145262,2.0071148758323614,-0.0275867927383886
255.70000000000294,17.793490702921524,2.0125780383212306,-0.029955437789806805
257.00000000000296,17.832286749093413,2.0175150165583022,-0.030296975383192315
258.30000000000297,17.87176047798907,2.0236819372139463,-0.031595541786266335
259.600000000003,17.91103514469004,2.0288332160939437,-0.0315164825525156
260.90000000000305,17.95001057931785,2.034392464948427,-0.029848484837120548
262.200000000003,17.989473151543987,2.038955460932536,-0.029403266702273
263.50000000000307,18.028693732069087,2.04566440085667,-0.028746801828005708
264.8000000000031,18.06801910799135,2.0515551880369602,-0.030500255411858745
266.1000000000031,18.10734479448798,2.0566224326415754,-0.0320469971143269
267.4000000000031,18.14667110445029,2.061708506616622,-0.03333527759787902
268.7000000000031,18.18573930804475,2.067538681601249,-0.03335090250243011
270.0000000000031,18.224993277051993,2.0720927416383264,-0.033347116940631416
271.30000000000314,18.264385028043787,2.077677718182279,-0.03455069014767753
272.6000000000032,18.303684273163682,2.083939859569866,-0.038289581743190304
273.90000000000316,18.34272440488253,2.0897976229253548,-0.0420366864121986
275.20000000000323,18.38191473734145,2.096297845605819,-0.04341335873936769
276.50000000000324,18.42133935880997,2.099208901118149,-0.04258853145121
277.80000000000325,18.460748452161905,2.105174297666855,-0.042111011771259754
279.10000000000326,18.50008964105396,2.109110244860289,-0.042123572322675606
280.4000000000033,18.538860598926323,2.1145086781575304,-0.03922724001059441
281.70000000000334,18.578460520694755,2.117770266968963,-0.03482348038305849
283.0000000000033,18.61778193389837,2.1220375288803153,-0.03204173375997499
284.30000000000337,18.657225197088344,2.1286336773797947,-0.030710810102262176
285.6000000000034,18.69630483975372,2.1324466822623322,-0.030127998483802543
286.9000000000034,18.735856985900842,2.136255277143593,-0.029389969323474485
288.2000000000034,18.77528248944144,2.141949792131206,-0.030698411684124238
289.5000000000034,18.814142067075114,2.1461890491788886,-0.032786809424107055
290.8000000000034,18.853794512047187,2.151646005693869,-0.034786384870967524
292.10000000000343,18.89332396691146,2.1560803114610496,-0.03714067861812831
293.4000000000035,18.932383130107787,2.1598555905527506,-0.03739860273358664
294.70000000000346,18.971455585778646,2.1642273578066384,-0.038511895285205267
296.0000000000035,19.010898675905796,2.1706753947199,-0.04004138370413868
297.30000000000354,19.05063364751942,2.17376343068166,-0.04144091049221288
298.60000000000355,19.089559265254366,2.1779776879141797,-0.04146164619544512
299.90000000000356,19.129291034533153,2.182763645336971,-0.042772692190358175
301.20000000000357,19.168588773774943,2.1847998314458303,-0.04273630218443625
302.50000000000364,19.208065122691078,2.1900887040612655,-0.04276541614402918
303.8000000000036,19.24734122026365,2.193033540329371,-0.040032699057077625
305.10000000000366,19.28662897032096,2.197677987942752,-0.04004097022498421
306.4000000000037,19.32620810758312,2.2009832325106475,-0.04046169748418027
307.7000000000037,19.365283009253346,2.206361110953895,-0.041352893637818244
309.0000000000037,19.40492995382781,2.2099381829821483,-0.04135012216341938
310.3000000000037,19.444075964595253,2.214013637605265,-0.04134832574099745
311.6000000000037,19.48371793789793,2.2173820328321634,-0.04120119939623912
312.90000000000373,19.52303079113512,2.221563276948409,-0.04262607203324542
314.2000000000038,19.562533814271646,2.225048410453364,-0.04390220834533487
315.5000000000038,19.602025629685084,2.2295704180322655,-0.043266143899893805
316.8000000000038,19.64142340748574,2.2338651000941816,-0.042637008302643054
318.10000000000383,19.680638006086873,2.2391850654964522,-0.04293716788407176
319.40000000000384,19.720266017776396,2.2453395856740883,-0.04411264164931472
320.70000000000385,19.75978306335378,2.249800761347272,-0.04631428952423455
322.00000000000387,19.799048131649748,2.2549789177300394,-0.047817260386293636
323.3000000000039,19.838601159951878,2.2606928457039044,-0.049096655789491184
324.6000000000039,19.878296947851908,2.266909603600137,-0.05192083516523205
325.90000000000396,19.917812235881303,2.2731231149797644,-0.05331194873723666
327.20000000000397,19.956681381613407,2.2786138242052485,-0.0528505704484199
328.500000000004,19.996975290463,2.2825548290177156,-0.05317816212064841
329.800000000004,20.03669610437903,2.2870983174549475,-0.052180564746739044
331.100000000004,20.075940763257787,2.2933712766150984,-0.05312817410961035
332.400000000004,20.11551101734958,2.300542227425328,-0.05465459226539293
333.700000000004,20.155389185684168,2.305714113546628,-0.05473764955080407
335.0000000000041,20.195007374149643,2.3123914019735134,-0.055953752990936856
336.3000000000041,20.234777000320086,2.3200406590544693,-0.057441879124157325
337.6000000000041,20.27450111104593,2.32836505313297,-0.05980329028826592
338.9000000000041,20.31421143444713,2.3344811901003037,-0.061763421656576334
340.20000000000414,20.354067318547756,2.3427114791868697,-0.06322976964683313
341.50000000000415,20.39374031860276,2.3517036844969614,-0.06509538172984763
342.80000000000416,20.43302141544685,2.3607004492855643,-0.06722714156705578
344.1000000000042,20.473142828346077,2.370827021525405,-0.06569092530298493
345.4000000000042,20.513037737602456,2.3782329697718403,-0.0627404474394786
346.70000000000425,20.552646676020363,2.389184594764068,-0.06396174583414371
348.00000000000426,20.592585003337472,2.401419276138188,-0.0678808567867839
349.3000000000043,20.63247915750851,2.413972657714036,-0.07077953781793545
350.6000000000043,20.672112419335473,2.424907697950077,-0.07298514746616558
351.9000000000043,20.712364612898018,2.440075910590468,-0.07519153538029144
353.2000000000043,20.75224630153987,2.453332811507692,-0.07758936353381518
354.5000000000043,20.79210833360245,2.46905280395761,-0.0807289215770326
355.8000000000044,20.832146653113558,2.482729773866855,-0.08609280481978177
357.1000000000044,20.872302312350254,2.500135665309693,-0.09391909864949932
358.4000000000044,20.91205225652965,2.518109528411638,-0.10198281780732232
359.7000000000044,20.95200877959103,2.534839661459766,-0.10522283493736495
361.00000000000443,20.991972288261806,2.5547925095880246,-0.10811552318128381
362.30000000000445,21.0322926799744,2.5735188723878366,-0.11111956693587377
363.60000000000446,21.072420015457894,2.5946081334169993,-0.11454546311396197
364.90000000000447,21.112429492413288,2.6170033675220656,-0.11735507680418555
366.2000000000045,21.152162605127316,2.6392028265359713,-0.12205091290555004
367.50000000000455,21.19259922620505,2.6614672771543173,-0.12561532296809075
368.80000000000456,21.232862697502092,2.686318017313784,-0.1313651968132672
370.10000000000457,21.27209380759214,2.711901037923594,-0.13952605451652822
371.4000000000046,21.313037635549914,2.7386186593212583,-0.14633014278612544
372.7000000000046,21.353047383267032,2.7664443070858162,-0.15383897013779624
374.0000000000046,21.393287193057102,2.794237995447148,-0.163383013685225
375.3000000000046,21.433640822487916,2.824797681591194,-0.17379407846302097
376.6000000000047,21.473852751109057,2.853331293677438,-0.18474053829995984
377.9000000000047,21.514109486025472,2.884552197985296,-0.19427771556357953
379.2000000000047,21.55406746760331,2.9142467004865873,-0.20428092527302955
380.5000000000047,21.59446693830779,2.947689170333171,-0.21253156339061618
381.80000000000473,21.634954901440068,2.9776512914541287,-0.21922576307131036
383.10000000000474,21.675176285329695,3.0128020521550694,-0.22537669103126534
384.40000000000475,21.715101717671324,3.047462844326987,-0.23762424976772767
385.70000000000476,21.755957995552144,3.0819260500914316,-0.2507398461215544
387.0000000000048,21.796244373800075,3.119064376600501,-0.2620236563912708
388.30000000000484,21.83676585088366,3.153619976700524,-0.2741503889758423
389.60000000000485,21.877017033423762,3.191153173858005,-0.289831217519934
390.90000000000487,21.91735246069116,3.2303713766566786,-0.3044762251143651
392.2000000000049,21.957729320049438,3.2693992596396866,-0.32158231937947024
393.5000000000049,21.99842307400399,3.307955968273692,-0.33829944255801037
394.8000000000049,22.038790104112888,3.348167368442694,-0.35534514676621587
396.1000000000049,22.079355598932086,3.3894261188154093,-0.3714751873572517
397.400000000005,22.11954710604347,3.4327973815506465,-0.38649538925268345
398.700000000005,22.16060516199558,3.478802068474702,-0.4026519743591459
400.000000000005,22.201263334813973,3.5229989302686757,-0.4223962585716281
401.300000000005,22.241581624804656,3.5692738967263486,-0.44407123311816044
402.600000000005,22.28220849139086,3.617172204491903,-0.4650110313625606
403.90000000000504,22.322895700884335,3.664944621792443,-0.4874387763980277
405.20000000000505,22.363650172191345,3.714876169979977,-0.5106714499121039
406.50000000000506,22.40416552219274,3.7645870252692215,-0.5351740080408134
407.80000000000507,22.445030465007346,3.817060313321983,-0.559521751274592
409.10000000000514,22.485750128025707,3.865979170118713,-0.5848111405027412
410.40000000000515,22.526478697148328,3.9164533304154143,-0.6124488093417058
411.70000000000516,22.567106543554363,3.9645261055318524,-0.639209890948095
413.0000000000052,22.60800459597822,4.011960083369239,-0.6682109839350052
414.3000000000052,22.648512145186782,4.05809677631236,-0.6981338930788938
415.6000000000052,22.689418228749627,4.100189551871708,-0.7286524586115628
416.9000000000052,22.730054250838997,4.138836384593826,-0.760984268681109
418.2000000000053,22.771183092836097,4.175519394496184,-0.7946648891469037
419.5000000000053,22.811599160221547,4.204623272707119,-0.829400124888525
420.8000000000053,22.852780730960212,4.229397069699952,-0.8657923694660115
422.1000000000053,22.89388091611024,4.244897421608645,-0.9016227571039384
423.4000000000053,22.934577206657607,4.252972665970274,-0.9401715901677705
424.70000000000533,22.975477105055944,4.249710918419049,-0.978308436641826
426.00000000000534,23.016262002310448,4.235849355768976,-1.0163502688464883
427.30000000000535,23.05704720174976,4.207773703341191,-1.0520152722839855
428.60000000000537,23.09789358047582,4.165155607771183,-1.0900842437175284
429.90000000000543,23.13834779266746,4.107500092699257,-1.1267769546030975
431.20000000000545,23.17938860370335,4.031102380417405,-1.163726898816488
432.50000000000546,23.22029376456683,3.937976437336281,-1.1983818098463557
433.80000000000547,23.261299352753877,3.8324103715370597,-1.2351912144265138
435.1000000000055,23.30117762708624,3.7190241249446685,-1.2671509418457187
436.4000000000055,23.3428208158874,3.5918083854751197,-1.3017054796529104
437.7000000000055,23.383281942926924,3.4656075067868732,-1.3291982353152525
439.00000000000557,23.424231462847292,3.339806986290094,-1.3560867794535718
440.3000000000056,23.465055718921747,3.2237003686807393,-1.3795014641733467
441.6000000000056,23.50554201242496,3.1147259847711246,-1.4001453515934537
442.9000000000056,23.546384479277293,3.016784575402528,-1.4187273760999135
444.2000000000056,23.58717500356041,2.93552029356352,-1.4367927490867003
445.5000000000056,23.627779214918366,2.8658352070808975,-1.4546195556921502
446.80000000000564,23.668690832836763,2.8059007461918606,-1.470637064266613
448.10000000000565,23.709297546069806,2.7587401111616088,-1.4848556050101744
449.40000000000566,23.750201057028548,2.717535204996131,-1.498468962519857
450.70000000000573,23.79049099576818,2.6850377338762947,-1.5097302030546595
452.00000000000574,23.8320589720692,2.659308775359659,-1.5225408194165828
453.30000000000575,23.872553288754474,2.6371345004128868,-1.5350513593869168
454.60000000000576,23.91389688837046,2.620320879016057,-1.5480633471235774
455.9000000000058,23.954917961684796,2.604762489652394,-1.5603400575825646
457.2000000000058,23.995878361779912,2.595042851973089,-1.5713702538844325
458.5000000000058,24.03673860673247,2.587862894114784,-1.5833659125536856
459.80000000000587,24.078016126792583,2.579270045514784,-1.5946611027177626
461.1000000000059,24.11942920529008,2.57574324213934,-1.6068555292008355
462.4000000000059,24.16035843961949,2.5724615592629037,-1.6174860208775148
463.7000000000059,24.201368850287146,2.569316237739257,-1.6285129013816717
465.0000000000059,24.242355969333783,2.5679481855334267,-1.6423778327586955
466.3000000000059,24.283713900499674,2.566184349089004,-1.6536916882767452
467.60000000000593,24.32493026354422,2.563701700387188,-1.665739336938545
468.90000000000595,24.366167653722684,2.5643015363964032,-1.6773097633810061
470.20000000000596,24.40737399967111,2.5639085718073016,-1.6904034221306867
471.500000000006,24.448634714413192,2.5650827717776243,-1.701935944753596
472.80000000000604,24.490043320901666,2.5634628341277814,-1.71281467782189
474.10000000000605,24.531335735756933,2.5640628485932435,-1.724276520808464
475.40000000000606,24.572823222592866,2.5632516665198297,-1.7360458942982997
476.70000000000607,24.613911725750345,2.561740987725542,-1.7454581531793165
478.0000000000061,24.65522725352492,2.560150283053737,-1.7574158851985504
479.3000000000061,24.696349547513933,2.5578397216292843,-1.768449889335193
480.60000000000616,24.737898128175903,2.5556233314638215,-1.781331278375064
481.9000000000062,24.778985641270012,2.5509495464787824,-1.7907151225129305
483.2000000000062,24.820781535635877,2.5472444606447597,-1.8022074602023954
484.5000000000062,24.86216503061109,2.5405409909947574,-1.8161200679702958
485.8000000000062,24.903097079704477,2.53384472338904,-1.8293863777166566
487.1000000000062,24.944824403772785,2.5261275888103083,-1.8435489341491085
488.40000000000623,24.98644134369143,2.515223987500283,-1.8549566444161107
489.70000000000624,25.02801505941884,2.50442432709065,-1.8670080067263197
491.00000000000625,25.06949121029408,2.4874673061510113,-1.8844584954225105
492.3000000000063,25.1108156095149,2.4689553037643774,-1.8957943839491125
493.60000000000633,25.15266042439574,2.4461951711777377,-1.9060009894538466
494.90000000000634,25.193939840811577,2.4194828047335166,-1.9147384676362824
496.20000000000636,25.23571817512374,2.3837408068337345,-1.922811099953985
497.50000000000637,25.276958338221363,2.3484511100725665,-1.9319588842458884
498.8000000000064,25.318819653480414,2.3081925830252135,-1.9432882653420829
500.1000000000064,25.360357212810353,2.262128960645106,-1.9500614580938151
501.40000000000646,25.401807413383565,2.2172465956198977,-1.953213923678112
502.70000000000647,25.44306057316824,2.1739909583993815,-1.9580099268973208
504.0000000000065,25.484093950504306,2.133475887356308,-1.9653248909684335
505.3000000000065,25.52670502634284,2.094145800277862,-1.9714967814527058
506.6000000000065,25.568129493724843,2.063348475689331,-1.9755976460955407
507.9000000000065,25.610068302154666,2.0348065739429333,-1.9797314654249334
509.2000000000065,25.651335132935827,2.0118431150663785,-1.9811568882263542
510.50000000000654,25.693535613185407,1.9924377267279854,-1.9813617033445534
511.80000000000655,25.734736454824894,1.978009402403704,-1.9824623111845772
513.1000000000066,25.77671327907932,1.9657040416715523,-1.9810004608878113
514.4000000000067,25.818511210053114,1.9582096748258788,-1.9798391921933605
515.7000000000066,25.859854297773992,1.9521352107343093,-1.9798397683833646
517.0000000000066,25.9017844911678,1.9455543014466818,-1.9798248478654212
518.3000000000067,25.943624396844626,1.9405997965238357,-1.9770929737947691
519.6000000000067,25.985466121496348,1.937307864638745,-1.9782766956659765
520.9000000000067,26.027190720244356,1.9361009010620165,-1.979922927649441
522.2000000000068,26.069267124727162,1.931599634940726,-1.981235354859829
523.5000000000068,26.111026948071707,1.9317491850556638,-1.982581429005763
524.8000000000068,26.15265954205096,1.931788510029047,-1.98278363703283
526.1000000000067,26.19462843956442,1.9293143179871834,-1.980410276927476
527.4000000000068,26.236671194736324,1.928005247276628,-1.9809403864232284
528.7000000000069,26.27839657284351,1.9263033503324891,-1.9836920928685386
530.0000000000068,26.320277793790375,1.9204681330939173,-1.9855664963303123
531.3000000000068,26.362503333677747,1.920458597444859,-1.985540447844211
532.6000000000068,26.40439799939803,1.9160413688061555,-1.9855401952432605
533.9000000000069,26.446101423292692,1.9197845915573053,-1.985540194002143
535.2000000000069,26.48805163872447,1.9306005936083892,-1.9855401937854942
536.5000000000069,26.529833209360348,1.9432554014001169,-1.9855402272017484
537.800000000007,26.571434739190153,1.95704329329295,-1.9855674116675859
539.100000000007,26.613698806555337,1.9687171087708173,-1.9842332689949789
540.4000000000069,26.655568696210455,1.9770136756974686,-1.9837900375546598
541.700000000007,26.697523646565656,1.98819321675711,-1.9829032570927243
543.000000000007,26.73938496358515,1.9945330374293655,-1.9839088119290578
544.300000000007,26.781575729362903,1.9975742426403,-1.984220143207141
545.6000000000071,26.823426660612817,2.001662345791371,-1.9842212003516537
546.9000000000071,26.865674094465934,2.0051327365231066,-1.9856147961875346
548.2000000000071,26.90742412229999,2.0034292215571017,-1.985522871490776
549.500000000007,26.949650745542144,2.001371786977275,-1.9842237670413199
550.8000000000071,26.991671574339946,2.0043937077056597,-1.9843333918897357
552.1000000000072,27.033934507010482,2.0056329823258965,-1.9855436222821674
553.4000000000071,27.076101946434875,2.0077321770273797,-1.9855405839796991
554.7000000000072,27.118152196959937,2.0115159484400307,-1.987097067343004
556.0000000000073,27.160109368231613,2.0129725213230554,-1.9870392268182897
557.3000000000072,27.20236188913655,2.0151071844740707,-1.9869703661045541
558.6000000000072,27.244821401735344,2.0176636609837133,-1.9860427789333777
559.9000000000073,27.286637279700553,2.021555366460581,-1.984268307508489
561.2000000000073,27.329268896614636,2.0213773774192942,-1.9856493580003125
562.5000000000073,27.371417094206652,2.022971065096946,-1.9856506684715107
563.8000000000073,27.413469303333866,2.023706198762271,-1.9860336691834068
565.1000000000073,27.45588915666496,2.027168361738631,-1.9855281706032604
566.4000000000074,27.49806735735724,2.0265937083092704,-1.9868209088555675
567.7000000000073,27.54061519799248,2.0272674405214213,-1.9855349868125924
569.0000000000074,27.58276307023122,2.0296435559843653,-1.9857092514842387
570.3000000000075,27.62517439151336,2.0306149975414867,-1.9872384837229258
571.6000000000074,27.66769347338023,2.0368363270455787,-1.9868844597417676
572.9000000000075,27.7096161419975,2.035263728579602,-1.9881729134739743
574.2000000000074,27.7523891101823,2.0350229695291473,-1.9893887616501407
575.5000000000075,27.794415660384,2.0348014292101495,-1.989491070613031
576.8000000000075,27.836960896167255,2.034886372132015,-1.987290128557357
578.1000000000075,27.87930154295451,2.033181997815017,-1.9858496754967496
579.4000000000076,27.921847924329256,2.032120522832854,-1.9858584135268251
580.7000000000075,27.964082967680024,2.0319558869192527,-1.9869056843203188
582.0000000000076,28.00657999380635,2.0321063695862995,-1.9886206965736672
583.3000000000076,28.048935430547402,2.0330103490494307,-1.9903658704627785
584.6000000000076,28.091498281475598,2.031456508888274,-1.9882601763347925
585.9000000000076,28.133787269485076,2.033907215603977,-1.988610717834245
587.2000000000077,28.176524909878555,2.036425543828588,-1.9900965142082327
588.5000000000076,28.219102945517445,2.037714788556985,-1.9908517628600784
589.8000000000077,28.26159565341538,2.0406055492478945,-1.9897628353068288
591.1000000000078,28.304049821544442,2.044043209989382,-1.9883947134583582
592.4000000000077,28.346653586382306,2.0491765205628467,-1.9875214497281308
593.7000000000078,28.389236626759864,2.0550016202890014,-1.988389841300727
595.0000000000077,28.431927377627495,2.062477943017562,-1.988606987549609
596.3000000000078,28.474439805479005,2.069102330601677,-1.9899926313838634
597.6000000000078,28.517228386659472,2.0787729351272075,-1.9898895931301852
598.9000000000078,28.559585825992862,2.0864051941468373,-1.990067435239427
600.2000000000078,28.60245633137124,2.0986841391566653,-1.9912837786421296
601.5000000000078,28.645118312549393,2.1067995547347267,-1.992508204266767
602.8000000000079,28.68762882393095,2.1198447661303024,-1.9950884292140691
604.1000000000079,28.73075062752655,2.130079175003974,-1.9967064908374361
605.4000000000079,28.77315327682494,2.1389322450014476,-1.9967353748938952
606.7000000000079,28.81576917086334,2.151232047390414,-1.9967586139271347
608.000000000008,28.858506082529992,2.1620612138393875,-1.9973634925692436
609.3000000000079,28.901304188248705,2.173581612461861,-1.9974019931988902
610.600000000008,28.943957568635476,2.1871426955159374,-1.9960730217565539
611.900000000008,28.986773177776758,2.199076003595384,-1.99630381313274
613.200000000008,29.029567005706454,2.212208222990506,-1.9976065924948223
614.5000000000081,29.0724681226455,2.2215260395231757,-1.9976099620091592
615.800000000008,29.115343472551935,2.233434722277088,-1.9976132211834048
617.1000000000081,29.158352401368823,2.2481696235635242,-1.9976093827423131
618.400000000008,29.201106935242635,2.2616548413824886,-1.9976000712093382
619.7000000000081,29.243764243232416,2.274416836355738,-1.998460542197686
621.0000000000082,29.28671421198736,2.287474535841168,-1.9991983267147893
622.3000000000081,29.329606717087845,2.3013146350824183,-2.000339389982915
623.6000000000082,29.372157424353908,2.314042840346588,-2.0003397594970345
624.9000000000082,29.414995694958243,2.3260601442071946,-2.002089296453446
626.2000000000082,29.457696537683315,2.340811354587023,-2.004455856920103
627.5000000000082,29.50058132711806,2.354595534793194,-2.0031455180365763
628.8000000000083,29.543687084462924,2.369957198370543,-2.0029770338289947
630.1000000000082,29.586458219172883,2.379359654874575,-2.0029807696014514
631.4000000000083,29.629537461929473,2.3967483087625387,-2.0043067337409797
632.7000000000083,29.672284964068126,2.411219837636718,-2.0056202819686035
634.0000000000083,29.715260980513342,2.425388406691076,-2.0039385856325422
635.3000000000084,29.757959585530386,2.438575549089685,-2.001903219615705
636.6000000000083,29.80124747853572,2.4536591061770734,-1.9993646894414745
637.9000000000084,29.84387189307472,2.468355746414278,-1.998259338063153
639.2000000000083,29.887039558086308,2.487054845804746,-1.9982601441066539
640.5000000000084,29.929605905539187,2.50335911662505,-1.9973292380117131
641.8000000000084,29.97256795884199,2.5207343480514415,-2.000721844503906
643.1000000000084,30.015575850133065,2.5357165194766442,-2.0038999855899737
644.4000000000085,30.058614456539893,2.552064277472062,-2.006490848050193
645.7000000000085,30.101649711919144,2.571562141650679,-2.0072880509864635
647.0000000000085,30.144699756465,2.586493404439187,-2.0077132599162004
648.3000000000085,30.18742138319182,2.60823387936086,-2.0095832542378944
649.6000000000085,30.230288477108818,2.626730246085344,-2.011054964475348
650.9000000000085,30.27331300502097,2.6492584597587507,-2.0122959185584355
652.2000000000086,30.316236253927716,2.6704221034159166,-2.0147278281831094
653.5000000000086,30.35956530231873,2.6967186764709234,-2.0147100613935827
654.8000000000086,30.401939761587514,2.7238368907270027,-2.014984113983143
656.1000000000087,30.44540181682771,2.7537238852175503,-2.0126201482406865
657.4000000000086,30.48827026037414,2.7812899693858455,-2.0126668233977707
658.7000000000087,30.531583825744285,2.811777535262521,-2.0154528526454496
660.0000000000086,30.57413262918256,2.8450815112779813,-2.018140847018035
661.3000000000087,30.61732821823649,2.8742524241199514,-2.020865563574898
662.6000000000088,30.660262611766264,2.905373737979808,-2.0221623075872284
663.9000000000087,30.703384036843623,2.9391847551045918,-2.0235664004169136
665.2000000000088,30.746579766229,2.96931283803218,-2.024925566035983
666.5000000000088,30.789234198107195,2.9988553293061107,-2.027777037534199
667.8000000000088,30.83268266397328,3.0332576423549944,-2.0291426784523967
669.1000000000088,30.875453329555686,3.0707177446200724,-2.0283369889394818
670.4000000000088,30.918412906149975,3.105355841519758,-2.028468607223431
671.7000000000088,30.961364916667716,3.1443467821937747,-2.0282551836261717
673.0000000000089,31.004387710865824,3.1839469083621204,-2.030937002178831
674.3000000000089,31.04732637194613,3.2275694223145597,-2.033591282655454
675.6000000000089,31.09067012542005,3.267232732233744,-2.0356018774785607
676.900000000009,31.133422890139112,3.3077926367838413,-2.039946591322172
678.2000000000089,31.17663511000311,3.3476228503830443,-2.0437795244198007
679.500000000009,31.219661596875202,3.3887052973260743,-2.0471056196249515
680.8000000000089,31.26303867897241,3.4309869889387463,-2.049370856907225
682.100000000009,31.306144565229218,3.4718512469830616,-2.0519008490765795
683.400000000009,31.349202705543547,3.5166344437676966,-2.054521964194514
684.700000000009,31.392290046155527,3.558207955312681,-2.0557954261202296
686.0000000000091,31.435207374700948,3.6026546133735065,-2.059476427540105
687.300000000009,31.478619923085038,3.6491138727976047,-2.0608338731759397
688.6000000000091,31.52171525729051,3.696049943518282,-2.062939689499708
689.9000000000091,31.564766669174357,3.7484175687005066,-2.0645751673361206
691.2000000000091,31.607943562314517,3.801522952749905,-2.06672030433364
692.5000000000091,31.651202887868553,3.8560378207108497,-2.070743246257959
693.8000000000092,31.694615553804443,3.9104385907550125,-2.074512692336079
695.1000000000092,31.73775963273382,3.970597766716483,-2.0754103210485586
696.4000000000092,31.780830680705275,4.028374496912956,-2.079732581770349
697.7000000000093,31.82399594496171,4.090012128076421,-2.083015684058166
699.0000000000092,31.86745585723295,4.153304004051778,-2.0876107160430317
700.3000000000093,31.910749176902286,4.218838598936696,-2.090396557359956
701.6000000000092,31.953863110137647,4.287224867658676,-2.0952560911737517
702.9000000000093,31.99725990360103,4.359407010644556,-2.1037047142605108
704.2000000000094,32.04081815847429,4.4366056359389585,-2.108079690509422
705.5000000000093,32.083864605085246,4.511359772604707,-2.1107132519112426
706.8000000000094,32.127453947200564,4.588597821713816,-2.1175144981928544
708.1000000000093,32.17057784485755,4.674503909800851,-2.122162410722572
709.4000000000094,32.214057584573304,4.760292571278798,-2.1247103684980146
710.7000000000094,32.25721781179701,4.84888015819247,-2.128464750182922
712.0000000000094,32.30050034022163,4.944073808753904,-2.1362027051512045
713.3000000000094,32.34415856506237,5.041608697452895,-2.145628441542116
714.6000000000095,32.38730844958486,5.141699582713849,-2.1529504048498915
715.9000000000095,32.43027222863989,5.244973345311581,-2.162288172238851
717.2000000000095,32.47441324477668,5.353304329861796,-2.1690129530044175
718.5000000000095,32.517548504532044,5.462656737988971,-2.1730506420554807
719.8000000000095,32.560093800529074,5.573752524124659,-2.181283421317675
721.1000000000096,32.60432828857231,5.690722228303433,-2.189755951101149
722.4000000000095,32.64768213330672,5.812872445157905,-2.196889562042812
723.7000000000096,32.6911295683105,5.931596320180871,-2.202872744977141
725.0000000000095,32.73492298564191,6.055042584310662,-2.2119915615606063
726.3000000000096,32.77813675776763,6.175550927437484,-2.2227198079057757
727.6000000000097,32.82166794781718,6.293019586503681,-2.2313514792083886
728.9000000000096,32.865042366472004,6.413126540345591,-2.237597926892379
730.2000000000097,32.90853172111586,6.530057905341081,-2.2458844873424293
731.5000000000097,32.951981471825945,6.649210268701361,-2.2538994318906544
732.8000000000097,32.99553936767354,6.765658582559832,-2.264824946527468
734.1000000000097,33.03903404355599,6.883774522803398,-2.277008998209306
735.4000000000098,33.08246721048223,6.997927109883751,-2.290698910981713
736.7000000000098,33.12596682784633,7.113709703539362,-2.3045653613832067
738.0000000000098,33.169595690748565,7.230173202022319,-2.318621389723482
739.3000000000098,33.213112813289676,7.3427780453068205,-2.3295783586325043
740.6000000000098,33.25646473966323,7.458749614638268,-2.34008872504375
741.9000000000099,33.30038424394418,7.575798171575748,-2.3537147523222615
743.2000000000098,33.34357241889987,7.689236989272995,-2.365721717134128
744.5000000000099,33.38696121959999,7.805114549534282,-2.3799182272647235
745.80000000001,33.43055603008157,7.9200374431173906,-2.3933844408191822
747.1000000000099,33.474281385997436,8.031239867576971,-2.4086736882918633
748.40000000001,33.517792274926265,8.142553600168847,-2.4223502431213095
749.7000000000099,33.56126232593735,8.249646983905517,-2.435530287425486
751.00000000001,33.60460436065899,8.355793810877962,-2.4506852323974853
752.30000000001,33.6483279846945,8.458779728283636,-2.4657868482795413
753.60000000001,33.691994836692935,8.559730548841292,-2.481004689046714
754.90000000001,33.73577791761514,8.657493129713371,-2.4960672831363175
756.20000000001,33.77903708085132,8.747497108031808,-2.5126294440590717
757.5000000000101,33.82267431300082,8.832728486772863,-2.528983623881635
758.8000000000101,33.86629840952868,8.910122740074879,-2.5446548458597142
760.1000000000101,33.90985386454124,8.980055612169918,-2.5627236345473623
761.4000000000101,33.95331911775878,9.042155462963684,-2.577797952953321
762.7000000000102,33.99716325111842,9.091836901674062,-2.5930817459104136
764.0000000000101,34.040566854051946,9.133930156964649,-2.6082639081976886
765.3000000000102,34.084080117899646,9.162727134459246,-2.624513091050396
766.6000000000101,34.12781913162232,9.179633275788882,-2.645459315964272
767.9000000000102,34.17048312574916,9.181943914402883,-2.6629147005723364
769.2000000000103,34.214814353781065,9.170605737361711,-2.678519534685189
770.5000000000102,34.25838076783307,9.137727786470354,-2.695772598515375
771.8000000000103,34.30177545785531,9.081929141470141,-2.714827480498747
773.1000000000103,34.34455780390442,8.997080545361083,-2.7314123196930655
774.4000000000103,34.38790622683352,8.869825754067492,-2.74785043565516
775.7000000000103,34.43234284050618,8.671927680887528,-2.7624519436364006
777.0000000000103,34.475555065371694,8.387603595272038,-2.7764142347974436
778.3000000000104,34.51907110466354,7.94593729357693,-2.788750704040953
779.6000000000104,34.562077276651664,7.246020849763358,-2.8032114854491232
780.9000000000104,34.60524412655701,5.909154069158156,-2.8142607274414377
782.2000000000104,34.64806215326286,4.565686944556887,-2.8250519231008027
783.5000000000105,34.69092318157491,3.8238904142129346,-2.827932688987537
784.8000000000104,34.733191165644506,3.414184226721792,-2.8283430790256947
786.1000000000105,34.77654795184924,3.1727114677109753,-2.831281902940387
787.4000000000106,34.819706438802974,3.03752291976704,-2.8312229249106733
788.7000000000105,34.86279261301915,2.9624026178211187,-2.832200050398459
790.0000000000106,34.90618976029706,2.926401765480196,-2.82916895677489
791.3000000000105,34.94953626246256,2.9074447627435145,-2.8285802367607134
792.6000000000106,34.99312389759455,2.9037253706544988,-2.828579812623354
793.9000000000106,35.03673925602733,2.90596735473588,-2.829705600558
795.2000000000106,35.07990481587079,2.9107488421351215,-2.8299000763232662
796.5000000000106,35.123423337740725,2.9204961879149716,-2.829899885606899
797.8000000000106,35.166987266644966,2.934467636433227,-2.8298998835742006
799.1000000000107,35.21028502761957,2.94457424238059,-2.829899784770367
800.4000000000107,35.25419703742224,2.954138060521821,-2.8298123353937212
801.7000000000107,35.29733873836882,2.9640794369498047,-2.8306455814933376
803.0000000000107,35.34095049304732,2.976166030619652,-2.8299008903386507
804.3000000000108,35.384239579021994,2.9876128402613613,-2.8298994327706772
805.6000000000107,35.42764013327299,3.0040238151977703,-2.8312061517616396
806.9000000000108,35.47125803488368,3.016093356831815,-2.8313605897613687
808.2000000000107,35.51473842814684,3.0283286051705707,-2.8312057057055
809.5000000000108,35.55747493597917,3.041720914611602,-2.8300184591538375
810.8000000000109,35.601896752094405,3.054890913335501,-2.8311926369118696
812.1000000000108,35.64537201604974,3.0680577205748145,-2.8307213012521544
813.4000000000109,35.68870630219041,3.0831984238128824,-2.828564034779231
814.7000000000108,35.732503443118624,3.0966817740340558,-2.8272373662516133
816.0000000000109,35.776213546471446,3.1104100071729683,-2.82594178592188
817.3000000000109,35.81986607626013,3.118668026369119,-2.827031764594035
818.6000000000109,35.862725651851655,3.1323889356491987,-2.8302086960960464
819.900000000011,35.906946651689864,3.1459102471448492,-2.8307950090393277
821.200000000011,35.94983943448443,3.156776584891524,-2.8307901669783373
822.500000000011,35.99416550651956,3.1693463827072494,-2.8292893098127356
823.800000000011,36.03778645955451,3.186717451865627,-2.828028108704114
825.100000000011,36.08156252250003,3.1932008277818666,-2.8280620272715424
826.400000000011,36.12496734322664,3.2043250779455543,-2.8277084617310817
827.7000000000111,36.1687103965008,3.2184623779567296,-2.8280316035917883
829.0000000000111,36.21256642923514,3.2293779612209765,-2.828365965721779
830.3000000000111,36.25592706613494,3.2402550246963036,-2.827749020259921
831.6000000000112,36.2998100170489,3.250720140576798,-2.829027282209494
832.9000000000111,36.34355979046781,3.260441051675389,-2.830323679790795
834.2000000000112,36.386897059719914,3.2739337241087676,-2.8303401608180723
835.5000000000111,36.43099078907302,3.2856317943061475,-2.8308450689001567
836.8000000000112,36.47489760202062,3.2957835422369937,-2.830475038937335
838.1000000000112,36.51865852160488,3.3065969886387148,-2.830274487423717
839.4000000000112,36.56255903732934,3.320984330094425,-2.8284037782984552
840.7000000000113,36.60640033463038,3.3349603538964874,-2.8274799611182244
842.0000000000113,36.6501389290912,3.3449415079359768,-2.8274859322075194
843.3000000000113,36.69337041038207,3.3581021430611013,-2.828835989521547
844.6000000000113,36.73763154214938,3.3732704115753265,-2.8287997642329517
845.9000000000113,36.78149042834921,3.3852116098652654,-2.8295291690733935
847.2000000000113,36.82552431219064,3.397146509590305,-2.829460221764398
848.5000000000114,36.86917000000038,3.412470000000126,-2.8294601107580295
849.8000000000113,36.91302522332019,3.4272526039556643,-2.8298006938392364
851.1000000000114,36.95697475991642,3.4398941410159276,-2.8294545005240272
852.4000000000115,37.00095414023519,3.455998637674086,-2.8291464503155757
853.7000000000114,37.04447101224788,3.466292333844997,-2.827701902821253
855.0000000000115,37.088579511199214,3.4796222166435697,-2.826278211694226
856.3000000000114,37.1322243192905,3.4927468224790044,-2.8262247174626784
857.6000000000115,37.17616454900705,3.5055567764442706,-2.82770676359823
858.9000000000115,37.220377600203605,3.5172886181149616,-2.827707600374749
860.2000000000115,37.2639189685054,3.5301584799690833,-2.8297511151742496
861.5000000000116,37.308004364353174,3.5429529966343107,-2.8318857808616222
862.8000000000116,37.35203543370689,3.556103893027978,-2.831841925384889
864.1000000000116,37.39595727971214,3.5718576005001332,-2.834355138786806
865.4000000000116,37.439683186454346,3.5823531426539064,-2.8345132066723497
866.7000000000116,37.483669686351355,3.5995406242535744,-2.8332312397003916
868.0000000000116,37.527416072149364,3.6126441079865246,-2.83318839649149
869.3000000000117,37.571170350311455,3.625393009442625,-2.8318934797309936
870.6000000000117,37.61532298878762,3.633525446301625,-2.831857521143621
871.9000000000117,37.659136406468,3.649942223630752,-2.830561326627793
873.2000000000118,37.70308940273761,3.659861591202506,-2.8305600541351374
874.5000000000117,37.74699348623754,3.67497146610609,-2.8305609185451917
875.8000000000118,37.79105639956894,3.6894656658999696,-2.8313760910367396
877.1000000000117,37.8351478179125,3.700590132747991,-2.831869117709647
878.4000000000118,37.87887064131117,3.711725293799546,-2.831896434349394
879.7000000000118,37.922954919742004,3.7281802486491986,-2.8368910251282076
881.0000000000118,37.96689351460394,3.7410254742816567,-2.8364751135561934
882.3000000000119,38.01104368177772,3.7548991933454383,-2.833782151021373
883.6000000000118,38.05352367228414,3.7684322949479627,-2.834923165504638
884.9000000000119,38.09889775048076,3.783157045141796,-2.834950235745898
886.2000000000119,38.14263543144187,3.792100005412002,-2.836348408045355
887.5000000000119,38.18646055012132,3.810466478767978,-2.8376962849746
888.8000000000119,38.23053124220491,3.819587464019495,-2.8350880539945087
890.100000000012,38.27392529287912,3.8374307700543953,-2.8332882750938344
891.0000000000119,38.304765764422825,3.8463035634203253,-2.833186669004074