File: 01_Data/Nylon_Carpet_Low_Pile/STA/N2/30K_min/Nylon_Carpet_Low_Pile_STA_N2_30KData_220107_R2.csv
##Temp./Â°C,Time/min,DSC/(mW/mg),Mass loss/mg
49.0,10.503912977487325,-0.936360767700547,0.005432608331041866
50.30000000000002,10.73374827205202,-0.7723400898868309,0.006141031872350489
51.60000000000004,10.871641563050904,-0.6511037693949011,0.0013973826960897995
52.900000000000055,10.97957672198477,-0.5492476362678909,0.004028756366678099
54.200000000000074,11.07049068515956,-0.4620774298096626,0.004953407839464408
55.50000000000009,11.151593991922347,-0.3868354736414998,0.008410367729046353
56.80000000000011,11.226412953736126,-0.3171188374619366,0.008907195988089978
58.10000000000013,11.295794110067504,-0.25128776273507014,0.003943098841110437
59.40000000000015,11.361268998688,-0.1914068928897232,0.004002585846416995
60.700000000000166,11.42344641861993,-0.1343843199372453,0.0027186841121964456
62.000000000000185,11.483708751637039,-0.08300879824170831,0.005767486514687281
63.3000000000002,11.541521374428184,-0.0336489510217646,0.0029634710042798496
64.60000000000022,11.597277631156592,0.012747335893732937,0.0026679687758353055
65.90000000000023,11.652778973101078,0.05958978821950255,0.003820826048689163
67.20000000000026,11.70568088298868,0.10152761455208108,0.002978506563963812
68.50000000000028,11.757849716741923,0.14175771543405924,0.0022310642966627547
69.8000000000003,11.809797314258736,0.18105397035167686,-0.00021816819671371945
71.1000000000003,11.860624946645736,0.21716365086358594,0.0003915972188517358
72.40000000000033,11.9106761917464,0.25199206535230445,-0.0004827842884833622
73.70000000000036,11.960468974428276,0.28582926804367365,0.002364660185892209
75.00000000000037,12.009092799037996,0.31623547853310263,0.0033062011437792194
76.30000000000038,12.057734689967656,0.3460166933872873,0.004786879722690873
77.6000000000004,12.105301467965605,0.3744872004407251,0.006346746717207807
78.90000000000043,12.152707143825742,0.4020525580270042,0.0032211018036090167
80.20000000000044,12.200057495955626,0.4287706013818411,0.004599683600523985
81.50000000000045,12.247555488870006,0.4527961906071754,0.006157968531474101
82.80000000000048,12.293825709586052,0.4781501697809981,0.008355220491032878
84.1000000000005,12.33999288233973,0.5031595943006548,0.01056850616057714
85.40000000000052,12.38592430578824,0.5241700885253238,0.010438342916562426
86.70000000000053,12.431513444319405,0.5479420327510431,0.010432243292658239
88.00000000000055,12.4774115940847,0.5708967056933906,0.009617344489059043
89.30000000000058,12.523105243794378,0.5935213350494294,0.008348752120558522
90.60000000000059,12.567854510755772,0.6124847333579035,0.00679822382967421
91.9000000000006,12.613039556532133,0.6357342395096851,0.002623948230337181
93.20000000000063,12.657722221664462,0.6584787074243856,-0.000870078894467774
94.50000000000065,12.70263786873855,0.6790350513349771,-0.002992752500158069
95.80000000000067,12.746788569554344,0.699451201445738,-0.0016171426863968996
97.10000000000068,12.791250012008405,0.7187765044084907,0.00037828059246169943
98.4000000000007,12.835573966901748,0.7383485743943181,0.0029859537197935992
99.70000000000073,12.879570311567818,0.7566643941410911,0.005028812972881269
101.00000000000074,12.923703330017968,0.7738363203165842,0.006006527463562783
102.30000000000075,12.966895558317926,0.7912999919660536,0.005796288038355524
103.60000000000078,13.010215225780488,0.8086396973585184,0.004280311402958148
104.9000000000008,13.055487179968695,0.8256233689827349,0.004059287218414198
106.20000000000081,13.099751790936093,0.8417178332283517,0.0036802283372106004
107.50000000000082,13.143193896603394,0.8580603392373014,0.0013760884754905334
108.80000000000085,13.186778653344147,0.8743383920045656,0.0014432742132872711
110.10000000000088,13.230238315848693,0.889019716637456,0.002738958381049983
111.40000000000089,13.274351203580391,0.9035718169913597,0.0027398166815824077
112.7000000000009,13.318054896719374,0.9173601685386026,0.002721549434688608
114.00000000000092,13.361461014927697,0.9315827957296239,0.0014011683560015697
115.30000000000095,13.404751035132128,0.9457542043978212,0.0027386969814076068
116.60000000000096,13.448412181909259,0.9604168047536892,0.0027489528704212063
117.90000000000097,13.491468752755024,0.9730869413732458,0.0022869594861845144
119.200000000001,13.53539196711705,0.9859281561704203,0.0014304366239996646
120.50000000000102,13.578264472713332,0.9994771733501898,0.0006780554734775457
121.80000000000103,13.621258794039166,1.0118379010092196,0.00012728423191488147
123.10000000000105,13.664372839520919,1.0250440322745407,-0.0012006183498378675
124.40000000000107,13.707495389401933,1.0381021046910501,-0.0011993213598286978
125.7000000000011,13.750057277803036,1.051586541126859,4.409111297265511e-05
127.00000000000111,13.793097645508228,1.0658481245675995,0.003036294632555947
128.30000000000112,13.835694539021526,1.0788057681435441,0.004770264276965808
129.60000000000116,13.87849854098501,1.0900530661898074,0.004708836448921172
130.90000000000117,13.921191143791027,1.105298361477659,0.003724432875026551
132.20000000000118,13.96373938631661,1.11793566551234,0.0011342680199795119
133.5000000000012,14.00586419895473,1.1320097159670086,-0.0010492897811440471
134.8000000000012,14.048449015986515,1.146320938695734,-0.0009829345259930733
136.10000000000124,14.090563712658431,1.1598103788074436,0.00033068247666756534
137.40000000000126,14.132492190679237,1.1731508385152964,0.0015705828350385254
138.70000000000127,14.174495110314718,1.1889266837567936,0.0016545792424063066
140.0000000000013,14.216645138901653,1.2044688325885828,0.002985163988166839
141.30000000000132,14.258406952957912,1.2202680756544981,0.0029626056741509643
142.60000000000133,14.29997174839757,1.2354082131202335,0.0016917800287186147
143.90000000000134,14.341720158505867,1.2520273510902349,-0.0012553348584840585
145.20000000000135,14.383399578635427,1.2695021812542173,-0.0012100618070580715
146.5000000000014,14.424881720776384,1.2868647256985897,-0.0012099598691448499
147.8000000000014,14.46667760901836,1.3057227910598022,-0.0012099601875736887
149.10000000000142,14.507991586562975,1.3252658862283968,-0.0012100219006687674
150.40000000000146,14.549456025287967,1.3464880243690829,-0.0012252925971405482
151.70000000000147,14.59084335389396,1.3678825115269688,-0.002211698649099869
153.00000000000148,14.63175550290609,1.3926250134562188,-0.002199885906192911
154.3000000000015,14.673500649546655,1.4166223857480964,-0.0021898339358696894
155.6000000000015,14.714545803328384,1.4444169137514526,-0.0007749376475283398
156.90000000000154,14.75590215263986,1.4751265937221711,-0.0031950581392874433
158.20000000000155,14.797037186840262,1.5039973071919637,-0.005579113672224523
159.50000000000156,14.838422533628206,1.5375246886271154,-0.006801421153567411
160.8000000000016,14.879553557998136,1.5695912935060208,-0.008318772147654752
162.10000000000161,14.920481078184094,1.5985881537423663,-0.006978048132656678
163.40000000000163,14.961709414837527,1.6219058294221194,-0.00823739920510258
164.70000000000164,15.002542270010144,1.6358372399934065,-0.006970027361325126
166.00000000000165,15.043544699706109,1.6394415443802286,-0.004488784605698903
167.3000000000017,15.083992685963464,1.6356686512058163,-0.0006227271765433251
168.6000000000017,15.125108658010396,1.626135500791955,0.0005947232261065416
169.9000000000017,15.16587508257513,1.6176497306914894,0.000525248138204315
171.20000000000175,15.206557087895904,1.6095305927634658,0.0004981750331358725
172.50000000000176,15.246685118187571,1.601611654168238,-0.0007417061065124742
173.80000000000177,15.288086223839795,1.5986083679088237,0.0006458745431641155
175.10000000000178,15.328088584995449,1.598081246375159,0.0019820667563892336
176.4000000000018,15.36910946061215,1.601227028740423,0.0014713975497109288
177.70000000000184,15.409533433116216,1.6068728140235096,0.0002241866996310904
179.00000000000185,15.44972865895568,1.6136131439916737,-0.00012793637292141113
180.30000000000186,15.490410785636442,1.621598838764505,-0.0004392121872198729
181.6000000000019,15.530691666038397,1.6310215781969435,0.0009471591892249442
182.9000000000019,15.570983637515564,1.6430291080980202,0.0008800805659565647
184.20000000000192,15.611206494581761,1.6539490141073405,0.0008548584139300708
185.50000000000193,15.6519300088764,1.6680298231746071,-0.0017973201297274422
186.80000000000194,15.691641930216367,1.6812804941597856,-0.0017475321786086795
188.10000000000198,15.731713649537811,1.6939862026555361,-0.0030179004637926887
189.400000000002,15.772029815208818,1.7069110214372096,-0.004470688305296733
190.700000000002,15.811702051970018,1.7200794273343196,-0.0057489024832784175
192.00000000000205,15.851806271634228,1.734424166821954,-0.007511975644887148
193.30000000000206,15.891978004863395,1.7485926132447034,-0.00836415871676488
194.60000000000207,15.93196131760241,1.7611328696423931,-0.008439565695970153
195.90000000000208,15.971660349498391,1.7761994814062072,-0.008425717136342215
197.2000000000021,16.011552003766035,1.7904292085370268,-0.007087785943675318
198.50000000000213,16.051742832213662,1.8053139221382888,-0.007129420951510923
199.80000000000214,16.091721189313837,1.8205990770534426,-0.007082309789021135
201.10000000000215,16.131280956770873,1.835742419947862,-0.008427562185885584
202.4000000000022,16.171309733423836,1.8528230384673527,-0.008439951290327041
203.7000000000022,16.210878340504703,1.8681840103161973,-0.008481367775598159
205.00000000000222,16.250727073008665,1.8874552013938564,-0.009762913759431946
206.30000000000223,16.290765459857724,1.9077300899240845,-0.011057041315204241
207.60000000000224,16.330414508445912,1.929862842034394,-0.012404421473465987
208.90000000000228,16.37004559335124,1.9553574188962517,-0.011700840922142408
210.2000000000023,16.40992167418957,1.9863703625160398,-0.009332306318998285
211.5000000000023,16.449976509793743,2.029438482056767,-0.00943076040701829
212.80000000000234,16.48962875551458,2.0886187830775707,-0.009371955334361637
214.10000000000235,16.529264231164248,2.171875055893524,-0.00943017340917729
215.40000000000236,16.569020792511896,2.277441206176587,-0.010749422946145781
216.70000000000238,16.60889985219506,2.4023369304781936,-0.010750048982931304
218.0000000000024,16.648732710046055,2.54112510574789,-0.010750054951183419
219.30000000000243,16.68854916385306,2.677893609520204,-0.01075005499963444
220.60000000000244,16.728380173463645,2.774328876303514,-0.010750055001774061
221.90000000000245,16.768466421116653,2.8006660829173367,-0.010750055307968243
223.2000000000025,16.80796474174628,2.752881061207189,-0.010750150693485505
224.5000000000025,16.84798543795165,2.6643695547453294,-0.009244753242570347
225.8000000000025,16.887611893771165,2.5708374583200104,-0.007904331486360938
227.10000000000252,16.927028079379834,2.4837098273699647,-0.007887927983262877
228.40000000000254,16.96644174920164,2.404359502377164,-0.006554640113261456
229.70000000000258,17.005930580568286,2.333146858896429,-0.006884480341866173
231.0000000000026,17.045364605162362,2.276297109799839,-0.008116861250714091
232.3000000000026,17.084644770804818,2.2349218226182495,-0.008278145035358175
233.60000000000264,17.124125182522693,2.2014132355839617,-0.00846290968523622
234.90000000000265,17.163482298995476,2.1774698668715997,-0.009767008148949596
236.20000000000266,17.202680152662086,2.1631550295664264,-0.009729662809332407
237.50000000000267,17.24219077219992,2.1538078718928144,-0.008443667035821889
238.80000000000268,17.281420535483065,2.1475372405299464,-0.008450751698719117
240.10000000000272,17.320594628273433,2.1430842492469417,-0.00854644827836859
241.40000000000273,17.36004579477544,2.1435414685814558,-0.010276848464195076
242.70000000000275,17.399021732384515,2.1464619105291947,-0.011181686151784831
244.00000000000279,17.437638336321594,2.147677899282275,-0.012509098873398461
245.3000000000028,17.47773071471451,2.1524692734808157,-0.013719421888718664
246.6000000000028,17.517147392974096,2.1569185001029045,-0.013819049380654036
247.90000000000282,17.55615606108559,2.162234258517021,-0.013808153384477162
249.20000000000283,17.595627944756128,2.1666394404940568,-0.012477736076733414
250.50000000000287,17.634891653613874,2.1730186542499044,-0.010103973300169766
251.80000000000288,17.67431164417103,2.1789940471840956,-0.009600497379954831
253.1000000000029,17.713528462565595,2.1846153055685194,-0.008546978294133645
254.40000000000293,17.75259225476361,2.1914019299224523,-0.00861506992882477
255.70000000000294,17.791808774526537,2.1979356624553996,-0.008902290575266036
257.00000000000296,17.831506866659566,2.2042824375486836,-0.00899615497256434
258.30000000000297,17.870513210788182,2.21086894312751,-0.010252012739320193
259.600000000003,17.90974599306006,2.2178820949741356,-0.011510425535894875
260.90000000000305,17.949018846637326,2.2221070430364915,-0.013513897739263037
262.200000000003,17.988566055762732,2.2293365018594007,-0.014158422673075766
263.50000000000307,18.027632697191816,2.23720076118574,-0.015486818071619446
264.8000000000031,18.066928744459613,2.2434866542105265,-0.016218812851745312
266.1000000000031,18.106177515531627,2.2507564372208027,-0.016306716065202842
267.4000000000031,18.145016421498056,2.2559107419660123,-0.015022717593502044
268.7000000000031,18.18456368781126,2.2633552565153905,-0.015275980484897644
270.0000000000031,18.224102020020844,2.267601215115677,-0.015677928583542666
271.30000000000314,18.263298553305564,2.2742876599154607,-0.01650594667190175
272.6000000000032,18.302672575279836,2.2809908587182703,-0.017106405083205267
273.90000000000316,18.341960186676737,2.286115410641207,-0.015709985942061078
275.20000000000323,18.3812873160635,2.2908546087682784,-0.015799683342245796
276.50000000000324,18.42059411394661,2.2971249352404786,-0.01580007881634815
277.80000000000325,18.459764424832304,2.3016433274133314,-0.015800030553281275
279.10000000000326,18.499319106638595,2.3071792161031706,-0.015797795603345488
280.4000000000033,18.538809296765685,2.3121120680345064,-0.017221337690779936
281.70000000000334,18.578124900877306,2.3189561168802832,-0.017220176049599356
283.0000000000033,18.61724160416251,2.324519963732683,-0.01722190746063612
284.30000000000337,18.65681686262166,2.3289498019600763,-0.018584289775389617
285.6000000000034,18.696384322232067,2.334028934089568,-0.018540488336357352
286.9000000000034,18.735539244528784,2.3380268069575156,-0.018549448436041338
288.2000000000034,18.774972535688303,2.343671257403676,-0.01724242852659197
289.5000000000034,18.814313465242208,2.3479328963994237,-0.018094292805995504
290.8000000000034,18.85303986018315,2.353713595537753,-0.0185322944251336
292.10000000000343,18.892998909261376,2.3574812729322536,-0.0198341307763803
293.4000000000035,18.932687547380016,2.3625393580991134,-0.019167603651778276
294.70000000000346,18.97218918313161,2.3667085511634243,-0.017918892502521988
296.0000000000035,19.011742197182915,2.370690645678195,-0.018536035671703477
297.30000000000354,19.05114812410645,2.3758532127905063,-0.018525953275973617
298.60000000000355,19.090654475261015,2.382722169827954,-0.018518956112546725
299.90000000000356,19.129900262893848,2.3864523160959465,-0.01999311738816223
301.20000000000357,19.169576323268732,2.391919953905854,-0.020982306406787554
302.50000000000364,19.20910962941634,2.3959523749705074,-0.021275244837085427
303.8000000000036,19.24863478564658,2.4007046003532686,-0.022580174477214943
305.10000000000366,19.28784384997774,2.4063395858381007,-0.022527534517906567
306.4000000000037,19.327577568186744,2.4108631237173435,-0.02390709353954934
307.7000000000037,19.36705503415488,2.4165043378695383,-0.02513342661270368
309.0000000000037,19.40664693239903,2.4200990750509987,-0.025214676585454843
310.3000000000037,19.445854755587106,2.426050767922226,-0.02592730113432795
311.6000000000037,19.485447384328996,2.430128215070696,-0.02588243209667551
312.90000000000373,19.525168046446947,2.4340328696115323,-0.026504823332069716
314.2000000000038,19.56495817626549,2.4387941462678544,-0.02786199954259061
315.5000000000038,19.604235338496782,2.4436060710528906,-0.027860034343442752
316.8000000000038,19.64403623782601,2.4484508423327753,-0.027860022062032197
318.10000000000383,19.68337686879217,2.4557087898998913,-0.027860023613113682
319.40000000000384,19.72330316649851,2.459493287195537,-0.02786026684790599
320.70000000000385,19.76277931916533,2.4662920043772383,-0.02789911178406479
322.00000000000387,19.802328224216463,2.4715164025719614,-0.0279265941636897
323.3000000000039,19.84174597384478,2.4776171611165494,-0.02644722019594825
324.6000000000039,19.8814671304244,2.482863434358749,-0.02644486706880267
325.90000000000396,19.92110885336036,2.491075488020779,-0.026445064664607276
327.20000000000397,19.960737698147167,2.4947181394663627,-0.027753791372346903
328.500000000004,20.000382747476493,2.5004579050538265,-0.030127835293075833
329.800000000004,20.040142883074765,2.5058549494444495,-0.031282810543346695
331.100000000004,20.079894295112386,2.513743321757912,-0.033004955940478364
332.400000000004,20.11973387554852,2.5209629216784344,-0.03535702668668117
333.700000000004,20.15933140988178,2.52896295857927,-0.03707536031799252
335.0000000000041,20.198827051847168,2.5351373066775826,-0.0386131287240552
336.3000000000041,20.238899934675427,2.5440804868545563,-0.04004230850245438
337.6000000000041,20.278482233799732,2.5543642934126187,-0.0414432396103277
338.9000000000041,20.31849183603201,2.562486406416089,-0.04217206853833799
340.20000000000414,20.358066003298237,2.5706612974774488,-0.042879086353608376
341.50000000000415,20.397852319965313,2.5806554195176536,-0.04411030500366042
342.80000000000416,20.437737030330997,2.59035790407851,-0.044197112996597454
344.1000000000042,20.47761769794276,2.6019247642321766,-0.04546224561023671
345.4000000000042,20.517323000679596,2.6137383568543995,-0.04649654102172862
346.70000000000425,20.55740080146889,2.6256482060807564,-0.049001060023563525
348.00000000000426,20.59713745619839,2.637116201378082,-0.051567331940626904
349.3000000000043,20.636997322586527,2.6492555828893276,-0.05487605914471416
350.6000000000043,20.676810945580872,2.662897304306469,-0.05848311240253734
351.9000000000043,20.716818389303185,2.6778943042420362,-0.0613389177777286
353.2000000000043,20.7568732147606,2.6929178214621636,-0.06432879837167294
354.5000000000043,20.796518643070673,2.707949879473399,-0.06671841656750699
355.8000000000044,20.836562262174724,2.725337016085577,-0.0706630361916396
357.1000000000044,20.876195143648545,2.7416813513359237,-0.0733691545242725
358.4000000000044,20.916554875395423,2.759573579868759,-0.07756454471387775
359.7000000000044,20.956502526576983,2.7789169128874582,-0.08306428213661299
361.00000000000443,20.99639772457611,2.798320042826388,-0.08905448062083776
362.30000000000445,21.036537168829327,2.8190154844013424,-0.09454353770431911
363.60000000000446,21.076705699264558,2.840780906042739,-0.098038859279729
364.90000000000447,21.116525000309192,2.861558006774674,-0.10376041526401014
366.2000000000045,21.156718285972087,2.8871822940686274,-0.1096630139055792
367.50000000000455,21.197003570385565,2.911287470321242,-0.11585810052913592
368.80000000000456,21.23678875143327,2.937685721938992,-0.1222450930658141
370.10000000000457,21.27709593928778,2.9645136190807166,-0.12869601413645126
371.4000000000046,21.317285938463275,2.9934056729822065,-0.13647018967514057
372.7000000000046,21.35754671760571,3.020439880908998,-0.1432539306273819
374.0000000000046,21.39759898126649,3.0480673455026266,-0.15166997987653508
375.3000000000046,21.437350340848496,3.0774370753399776,-0.16104661618033012
376.6000000000047,21.477385394017244,3.1086208463107354,-0.16997321469383797
377.9000000000047,21.518383367709582,3.1408002691534946,-0.1792404832499983
379.2000000000047,21.55840640632064,3.171144631351919,-0.1907252390147085
380.5000000000047,21.598495192516616,3.2054784294688172,-0.20161972379668036
381.80000000000473,21.638765817615475,3.2354555368437077,-0.213219843933528
383.10000000000474,21.678900141367418,3.270809438692125,-0.22489475864031538
384.40000000000475,21.719073447254555,3.3053575829695476,-0.23700108718265378
385.70000000000476,21.75939141357015,3.337820034099989,-0.24960928114103043
387.0000000000048,21.79965244115838,3.3722251916549784,-0.26252324917573766
388.30000000000484,21.840345908062346,3.407725389649918,-0.27530551726088204
389.60000000000485,21.880647535754736,3.4440667350736613,-0.2898228244187102
390.90000000000487,21.921069008306862,3.480020812669071,-0.3051743570034353
392.2000000000049,21.96127003471286,3.5187922504124876,-0.3212482894512032
393.5000000000049,22.001748511865465,3.556300777324568,-0.3381623983120403
394.8000000000049,22.041906478369004,3.5942949407636466,-0.3546678229506459
396.1000000000049,22.08273600223517,3.63722626874656,-0.37294961616332767
397.400000000005,22.12315326006899,3.680529496768856,-0.3910476040911486
398.700000000005,22.163485820814593,3.7207615706205757,-0.412342692643187
400.000000000005,22.204456873555895,3.7666634516846167,-0.43316426331036606
401.300000000005,22.24466056389527,3.810493973316178,-0.45364944690839826
402.600000000005,22.285035137709983,3.8558198156636174,-0.47682289379425447
403.90000000000504,22.325934730389935,3.90097972004839,-0.4993683198623877
405.20000000000505,22.366559686202574,3.9495360358255382,-0.5234186576662894
406.50000000000506,22.407242687247482,3.993497853462045,-0.548644925154413
407.80000000000507,22.447995642021667,4.041620401968552,-0.5760422466325994
409.10000000000514,22.488604221876955,4.086423131684476,-0.6030701737609752
410.40000000000515,22.529264150382517,4.1324131039289,-0.630113303664821
411.70000000000516,22.570116821427828,4.176639407084619,-0.6620314649217942
413.0000000000052,22.610732786770445,4.219894163323759,-0.6926675237105413
414.3000000000052,22.651511818780456,4.2575763668599365,-0.7248498253649478
415.6000000000052,22.69212970828896,4.2941576722855626,-0.7567906320084208
416.9000000000052,22.733019630177083,4.324836400437288,-0.7884074490644233
418.2000000000053,22.77385910299999,4.352071119133398,-0.8221859668653599
419.5000000000053,22.814615577238875,4.371052426978398,-0.85600250957763
420.8000000000053,22.85538279052669,4.383131887779364,-0.8910250088688754
422.1000000000053,22.89639228010609,4.386831952247924,-0.9267622462665108
423.4000000000053,22.937214660086195,4.379104191822352,-0.9649999510114116
424.70000000000533,22.977645652188674,4.36235594016164,-1.0017646589225504
426.00000000000534,23.018919578007072,4.32876864919969,-1.0381629390960674
427.30000000000535,23.059654836977355,4.2816091455719185,-1.0730385460347698
428.60000000000537,23.10034893168615,4.217325465816573,-1.1093071536156867
429.90000000000543,23.141288842339886,4.137130008269697,-1.146570123773011
431.20000000000545,23.182293870399022,4.040363242719107,-1.1812217886511949
432.50000000000546,23.22300369111785,3.9338962801111688,-1.213711000028483
433.80000000000547,23.263603380484177,3.8196059060505942,-1.246598128766676
435.1000000000055,23.30446094170718,3.693619647734973,-1.2743138371674627
436.4000000000055,23.345254454745675,3.5711637023848253,-1.2999240215854364
437.7000000000055,23.385663805750696,3.4547572135953843,-1.3217957933390325
439.00000000000557,23.426555964007406,3.3431927751968837,-1.344428056233308
440.3000000000056,23.46720406516543,3.246966393265307,-1.3647329977155902
441.6000000000056,23.50813693980969,3.1591372391751644,-1.3834505778136905
442.9000000000056,23.548736434786314,3.086091563469004,-1.4011954037018848
444.2000000000056,23.58973792576049,3.025397641240015,-1.418293674964119
445.5000000000056,23.630420782362926,2.9710693861966693,-1.4319585680809883
446.80000000000564,23.671143314622945,2.930711069120115,-1.4449792185685468
448.10000000000565,23.711962206592876,2.8974249064942756,-1.4575173511605115
449.40000000000566,23.75272887634949,2.870908756798591,-1.4698489614435117
450.70000000000573,23.793644851799215,2.848736030527958,-1.480899319516169
452.00000000000574,23.834442621640186,2.8307515656891145,-1.4924090232897846
453.30000000000575,23.87550173860048,2.8171488312824096,-1.5055652473932621
454.60000000000576,23.916574694626682,2.8070303891541473,-1.5166410438602709
455.9000000000058,23.957475722281234,2.7970402331841315,-1.5272024796598607
457.2000000000058,23.998291076059473,2.7919642107630507,-1.5375754400819068
458.5000000000058,24.039607272119913,2.786272737685227,-1.54712793882035
459.80000000000587,24.080718118133618,2.7839865804716526,-1.5591960227976385
461.1000000000059,24.121754241232736,2.782247928576587,-1.570713567497299
462.4000000000059,24.162860891005,2.784125291832293,-1.582740338235539
463.7000000000059,24.203924349902678,2.7825660802609176,-1.5932600541916506
465.0000000000059,24.24492274906925,2.7832724047545323,-1.6047213487906804
466.3000000000059,24.286113902492367,2.7841933068597853,-1.6150403475390758
467.60000000000593,24.327363683314957,2.7835242588787703,-1.6256367681078334
468.90000000000595,24.368350221375685,2.786057836261171,-1.637502625452933
470.20000000000596,24.409647690640554,2.7875956167725153,-1.6468090549006922
471.500000000006,24.45090769688208,2.7896986055476107,-1.6576473878595794
472.80000000000604,24.492312241769614,2.7906284882428776,-1.6696859632828684
474.10000000000605,24.533455682345824,2.791618485036843,-1.6808821555964175
475.40000000000606,24.574850824609346,2.7922398067337504,-1.6938465919059795
476.70000000000607,24.615729915231874,2.792365953331227,-1.7052318592830233
478.0000000000061,24.65732153078769,2.7928938865714743,-1.717689952202769
479.3000000000061,24.698625527005238,2.7924207427313066,-1.7290217619882813
480.60000000000616,24.740061357243768,2.7893626572665906,-1.741570222796418
481.9000000000062,24.781177523589466,2.787698941367094,-1.755122770073117
483.2000000000062,24.822603527865024,2.7850621589449807,-1.7665855580427428
484.5000000000062,24.864259651735157,2.782704864293039,-1.7790743599536056
485.8000000000062,24.905734457152107,2.7779305850504064,-1.7916775156258704
487.1000000000062,24.94727547439465,2.770574822360926,-1.803364173525496
488.40000000000623,24.988486083860796,2.7624467535678017,-1.8153790261851168
489.70000000000624,25.03004173768551,2.754783095773318,-1.827456618956706
491.00000000000625,25.07158644278433,2.7394380511567853,-1.8390333032502229
492.3000000000063,25.113043896575782,2.721867198901432,-1.8515701972389769
493.60000000000633,25.154387313709456,2.6995328556078575,-1.8628703341081012
494.90000000000634,25.19610749979142,2.673221064504262,-1.871982716866583
496.20000000000636,25.237430997789836,2.640006711600466,-1.8807350401811411
497.50000000000637,25.27901064514402,2.6041049589435086,-1.8900781313046622
498.8000000000064,25.319860404752298,2.563875732183946,-1.8988001144459212
500.1000000000064,25.361980839091306,2.5221947918446763,-1.9058566859333967
501.40000000000646,25.403713816793523,2.4821845942585012,-1.912283088752985
502.70000000000647,25.445617675958403,2.4410685101975087,-1.9168144377980307
504.0000000000065,25.487062605897403,2.405875719492847,-1.921097897478448
505.3000000000065,25.528497914540505,2.3724102703451466,-1.9224459668554634
506.6000000000065,25.570370439466217,2.347606863986367,-1.9241206075072879
507.9000000000065,25.612024158312344,2.3272910979382275,-1.9254437511851106
509.2000000000065,25.65373973349562,2.310243985364294,-1.92680074833121
510.50000000000654,25.69538721522924,2.2975143410942125,-1.926766879099865
511.80000000000655,25.73727343267174,2.290000957703753,-1.9287245284860828
513.1000000000066,25.778820189293057,2.2844898843735826,-1.928707668347168
514.4000000000067,25.820609886407194,2.278725567557029,-1.929372531509134
515.7000000000066,25.86246132548085,2.2787832672556947,-1.9293800265830634
517.0000000000066,25.904105875487378,2.2739947865021817,-1.9293800520720592
518.3000000000067,25.946045374244935,2.2739895965981205,-1.9293788899338544
519.6000000000067,25.987875175578473,2.273240428686604,-1.9303131806036822
520.9000000000067,26.029656386955683,2.274421180883749,-1.9303548462440152
522.2000000000068,26.07158724161404,2.2752177417920643,-1.9290439963828239
523.5000000000068,26.113550797769236,2.27392655846228,-1.929049896251683
524.8000000000068,26.155303999231357,2.2772413756092944,-1.9290190258635982
526.1000000000067,26.196938793145943,2.272956297854497,-1.9307174807111047
527.4000000000068,26.239331202495144,2.2701182160923206,-1.9313730114114342
528.7000000000069,26.28123308911982,2.2640615331966223,-1.9320817491296118
530.0000000000068,26.3232302609863,2.262556302519882,-1.9346404228140819
531.3000000000068,26.364965720520356,2.265755452006958,-1.9360399648660804
532.6000000000068,26.406736992287186,2.2744596826608054,-1.9359601748119242
533.9000000000069,26.448604998541718,2.288660192483072,-1.9345747353596816
535.2000000000069,26.490395231445532,2.301501873726413,-1.9346493411865717
536.5000000000069,26.532360453252668,2.317851802603059,-1.9346497713479813
537.800000000007,26.574673756656093,2.335193891801825,-1.9346429206131974
539.100000000007,26.61626042796001,2.348532633135663,-1.935451172677353
540.4000000000069,26.658329261454064,2.360632568011072,-1.9369421278073262
541.700000000007,26.700265475735364,2.3719043015039167,-1.9382673880702828
543.000000000007,26.742209405754267,2.3822785628033154,-1.9375385624682422
544.300000000007,26.784310800512078,2.387758093984262,-1.9375299878261338
545.6000000000071,26.826194883246945,2.392545355034393,-1.9362862057119719
546.9000000000071,26.86843375505105,2.396526226163845,-1.936294393659531
548.2000000000071,26.91057003159087,2.3984337094297534,-1.9362973316085252
549.500000000007,26.952468790599827,2.402178472789406,-1.936289876537523
550.8000000000071,26.99471662250716,2.4044215924211545,-1.9362898430780127
552.1000000000072,27.036789704417487,2.4054965288585506,-1.9362898411708875
553.4000000000071,27.078968752258074,2.4094163381440623,-1.9362897971448048
554.7000000000072,27.1210445172083,2.4100335882149664,-1.937694683266761
556.0000000000073,27.16321640653482,2.4138019039364047,-1.937610313180555
557.3000000000072,27.20504332691005,2.416643939286669,-1.9376019044524142
558.6000000000072,27.247446563100105,2.418850375758676,-1.936616602938038
559.9000000000073,27.289399970529796,2.422575191631458,-1.9379308442251917
561.2000000000073,27.33149171102212,2.424147745587162,-1.9379299984150107
562.5000000000073,27.3737880711945,2.4283137690918646,-1.9379299682793225
563.8000000000073,27.415983580973865,2.4303546371562503,-1.937929994277336
565.1000000000073,27.458272177042183,2.433328938152168,-1.9379331702697096
566.4000000000074,27.500595113118372,2.433608063476045,-1.938023218662698
567.7000000000073,27.54269485693753,2.435935300046708,-1.9379200846261524
569.0000000000074,27.58509201027298,2.438496363494641,-1.936567474723292
570.3000000000075,27.627239449056393,2.4430022933368596,-1.9365784737765992
571.6000000000074,27.669170637696297,2.4506200669990132,-1.9379274730984601
572.9000000000075,27.71202309231308,2.452333770113398,-1.9375650826555955
574.2000000000074,27.754362161119598,2.452841882217806,-1.936608266008815
575.5000000000075,27.796679878144285,2.4551286688996954,-1.93587846027981
576.8000000000075,27.838818617243724,2.4548385540748807,-1.9353006232561882
578.1000000000075,27.88112440840617,2.456548296267488,-1.9366984367692361
579.4000000000076,27.923548156949018,2.4567218467227976,-1.9366386611257944
580.7000000000075,27.965983496180055,2.4594063937670274,-1.9379291320083927
582.0000000000076,28.008241702780772,2.459892617886516,-1.9379298612589486
583.3000000000076,28.050647498450623,2.4610563570960404,-1.9379298676245216
584.6000000000076,28.092986344323972,2.463966051897716,-1.9379296779532842
585.9000000000076,28.13523715660602,2.468572430729622,-1.9389779309953066
587.2000000000077,28.177874983387436,2.4712203299482733,-1.9407753866886996
588.5000000000076,28.22055029722037,2.4728641931299253,-1.9434594764075581
589.8000000000077,28.263085340217042,2.4795518319420715,-1.9434204387258216
591.1000000000078,28.305407429115807,2.484937821242023,-1.9433869234996348
592.4000000000077,28.347837374286122,2.4902162191766757,-1.9420869381465455
593.7000000000078,28.3902159104034,2.4939437888618494,-1.940817912848933
595.0000000000077,28.432788097704783,2.5036352584375385,-1.9421005271942375
596.3000000000078,28.475266021259156,2.513025917985711,-1.9421001945758976
597.6000000000078,28.517736717846198,2.519613415648609,-1.9421172787888104
598.9000000000078,28.560612042288387,2.5269193673437127,-1.9444036470250126
600.2000000000078,28.602791753608965,2.538480533648412,-1.9415292900395538
601.5000000000078,28.645523959305308,2.5455291789914667,-1.9438736549337143
602.8000000000079,28.687973484189172,2.5583857515476183,-1.9442889928731018
604.1000000000079,28.730347939939048,2.5664364541891715,-1.9441099414810061
605.4000000000079,28.773257515290897,2.578370151077584,-1.9428285850905809
606.7000000000079,28.815917616941174,2.5883811446879816,-1.9441711882262838
608.000000000008,28.85864082471,2.6031689429878306,-1.944179811867314
609.3000000000079,28.901474513695383,2.616815052559732,-1.9441766716547595
610.600000000008,28.943791805629193,2.6287983468553104,-1.9454191949482893
611.900000000008,28.986807783294136,2.6417315353326947,-1.9441736557926514
613.200000000008,29.029471094101215,2.655921724997558,-1.94417313761919
614.5000000000081,29.071788548564413,2.6699571138709297,-1.9448849806873496
615.800000000008,29.114790599611148,2.682447943867474,-1.944081879547765
617.1000000000081,29.15764365635975,2.6988905804674514,-1.9440801745103542
618.400000000008,29.199933885710337,2.715149386430543,-1.9440796811366319
619.7000000000081,29.242635667292518,2.7294593057437164,-1.945012556901121
621.0000000000082,29.28548750585965,2.7445565351819874,-1.9454043566741928
622.3000000000081,29.32847299690176,2.759923971382123,-1.9467159727388936
623.6000000000082,29.371164261825825,2.777045887037813,-1.946721669688706
624.9000000000082,29.413976080265304,2.793196907657986,-1.948026450062168
626.2000000000082,29.456583192908287,2.8079539472665194,-1.948020013853403
627.5000000000082,29.499369330515695,2.8243982061812747,-1.9480199959343132
628.8000000000083,29.54235443393604,2.842538351777643,-1.9480197695780515
630.1000000000082,29.58506561121069,2.861113859539941,-1.948976803755452
631.4000000000083,29.627749130533466,2.8786710699132882,-1.949333179230992
632.7000000000083,29.6706371766316,2.8948125993503324,-1.9514393984104799
634.0000000000083,29.713300248650672,2.911074387772864,-1.9529613896386162
635.3000000000084,29.75647473353331,2.932539959202085,-1.9534429942613354
636.6000000000083,29.799170662314445,2.9491602588779395,-1.9539799623558514
637.9000000000084,29.84219364093556,2.9688459610175593,-1.955288711778461
639.2000000000083,29.885183149909384,2.9841329110253922,-1.9560611581094762
640.5000000000084,29.92824820294699,3.0051656834999605,-1.9573758703634434
641.8000000000084,29.97116037824204,3.0244056830479935,-1.9573436738021255
643.1000000000084,30.013842441766624,3.0441382822146874,-1.9572914080661201
644.4000000000085,30.056746982983924,3.0652017068238107,-1.958665366460469
645.7000000000085,30.0996699854709,3.0872633140046424,-1.9599770434751482
647.0000000000085,30.142722482576005,3.1085109989144617,-1.960835679218099
648.3000000000085,30.185738155677758,3.132887554726925,-1.9626096376185802
649.6000000000085,30.228309487722928,3.1572325073727963,-1.9640421421063339
650.9000000000085,30.27101687316657,3.1860495852708763,-1.9653270827254756
652.2000000000086,30.314332541729456,3.2145896936059644,-1.9676902245602448
653.5000000000086,30.357110090734302,3.2438808122360734,-1.9693634211487279
654.8000000000086,30.399863573377818,3.275318307865785,-1.9706142290178472
656.1000000000087,30.44301895134968,3.308830237887746,-1.9718413803180561
657.4000000000086,30.485914568365065,3.3413794798436762,-1.972491618108955
658.7000000000087,30.529169661881852,3.376649813045216,-1.9735803533568514
660.0000000000086,30.57156243215521,3.4107425056684,-1.9749187224457736
661.3000000000087,30.61477101218515,3.443272725112506,-1.976267418286001
662.6000000000088,30.65732917745754,3.479494327883551,-1.9786522418800536
663.9000000000087,30.70061687567298,3.5180298094435645,-1.9808030210363285
665.2000000000088,30.743232546082226,3.5541190737721475,-1.982704574293391
666.5000000000088,30.78633273455716,3.59373025767331,-1.9850366338910457
667.8000000000088,30.829039304786154,3.6386264288647707,-1.985968084429685
669.1000000000088,30.87229350952165,3.682682074776497,-1.987653597817795
670.4000000000088,30.915083362541846,3.7266432973487102,-1.9881471882550517
671.7000000000088,30.95813517773734,3.7731775984772735,-1.98933669462347
673.0000000000089,31.001031614471042,3.8190907643179677,-1.989997227241099
674.3000000000089,31.04400423396055,3.861362541916287,-1.991037729492145
675.6000000000089,31.086986787247454,3.9084005100520653,-1.992995221435415
676.900000000009,31.129748063119656,3.9530878946935037,-1.9948759111416212
678.2000000000089,31.173017250074963,4.000925317884893,-1.997568474925242
679.500000000009,31.2161412244986,4.048222248536951,-2.0011375670704314
680.8000000000089,31.259301838196993,4.0952491209055415,-2.0051847368330917
682.100000000009,31.30240285739811,4.1491105858104556,-2.010224035729128
683.400000000009,31.345346755462675,4.201507814290143,-2.0146268717394613
684.700000000009,31.388348214547513,4.255259082523779,-2.0176177962564057
686.0000000000091,31.43146736221275,4.3089177994565695,-2.0192045654633946
687.300000000009,31.474745832512777,4.368031804973945,-2.019566842616422
688.6000000000091,31.517594464700576,4.427006659888256,-2.0212718050792535
689.9000000000091,31.56102324086099,4.486604017133392,-2.0231288107215555
691.2000000000091,31.604205161497315,4.548799409913088,-2.0291316900944962
692.5000000000091,31.64740527931647,4.614300776563074,-2.032930155681023
693.8000000000092,31.690685721324463,4.6817316121556205,-2.036930995429694
695.1000000000092,31.733753181416986,4.751466284209835,-2.043940708705334
696.4000000000092,31.777350470461638,4.823901008908128,-2.048666502088022
697.7000000000093,31.819391036468502,4.898094009343927,-2.053677939283997
699.0000000000092,31.863169278043195,4.974015258768883,-2.0586505646499895
700.3000000000093,31.9068764241809,5.0543857128489105,-2.063861878849279
701.6000000000092,31.950265169359188,5.137907701057442,-2.0687229402482554
702.9000000000093,31.99359579039458,5.223202691557951,-2.0738383688996738
704.2000000000094,32.03673285813694,5.313060763138015,-2.0797160329938196
705.5000000000093,32.07992727424338,5.40505407225727,-2.0852233973527063
706.8000000000094,32.12336225292932,5.502127120797833,-2.092715273286757
708.1000000000093,32.1666884220982,5.60143458940607,-2.0969953180034504
709.4000000000094,32.2098430063489,5.709198086206915,-2.10302420158252
710.7000000000094,32.25330018621817,5.814951564780139,-2.1088103564225795
712.0000000000094,32.296755451315896,5.928343075087052,-2.1163217157613614
713.3000000000094,32.33986104212191,6.041431000164893,-2.122582386127693
714.6000000000095,32.383403813291785,6.160418382948152,-2.1305604514298344
715.9000000000095,32.42668675976343,6.28645456014529,-2.1391170608171146
717.2000000000095,32.470256320058574,6.415765762277203,-2.1480884647365217
718.5000000000095,32.513577091889736,6.546711822107297,-2.1579632026376174
719.8000000000095,32.55723225496111,6.678568467374299,-2.1686979560138195
721.1000000000096,32.60071982967897,6.816634160631885,-2.1773574628790495
722.4000000000095,32.64422553266285,6.952211410875678,-2.1848814137597246
723.7000000000096,32.68756434130343,7.089652477145748,-2.195534416134772
725.0000000000095,32.731006433571466,7.223659683572424,-2.2052235192049015
726.3000000000096,32.7742630877796,7.357288953760542,-2.214423331264033
727.6000000000097,32.818036341868634,7.489601036567015,-2.2286359632786716
728.9000000000096,32.86103517455975,7.619209004219593,-2.242406120455913
730.2000000000097,32.90478802806284,7.748208011686106,-2.2556031922089983
731.5000000000097,32.948169993671684,7.8752576360275,-2.267253105578152
732.8000000000097,32.99148579246317,7.997001207255212,-2.2796213694260747
734.1000000000097,33.03501894197005,8.123528160648588,-2.2915663165144173
735.4000000000098,33.07871847264452,8.245562222734081,-2.3032016266594173
736.7000000000098,33.12223158044374,8.367103719607185,-2.3151892995031007
738.0000000000098,33.16566251878041,8.488698727277718,-2.330199810672392
739.3000000000098,33.20913594562796,8.60603462927594,-2.346186584294653
740.6000000000098,33.252245078287686,8.722781205731781,-2.3594764230035246
741.9000000000099,33.29604710448106,8.834359862736086,-2.374665912533312
743.2000000000098,33.338784677314614,8.941901552600386,-2.388203188084084
744.5000000000099,33.383111529244985,9.053524558965364,-2.4020621707435805
745.80000000001,33.426534924257034,9.154442520054701,-2.419146900678146
747.1000000000099,33.46990570684278,9.250672424523932,-2.4337072227681986
748.40000000001,33.51360468434229,9.344544969006801,-2.449149153538505
749.7000000000099,33.557317356968994,9.4310836921707,-2.4652574856610645
751.00000000001,33.600689165617226,9.512863639303669,-2.482055553441182
752.30000000001,33.64344616944743,9.585453889604189,-2.4968772323438015
753.60000000001,33.68792834752001,9.65301669736635,-2.51389739989855
754.90000000001,33.73138334974348,9.706403493929763,-2.5322016853660796
756.20000000001,33.77487879821955,9.751161612014462,-2.549089964444112
757.5000000000101,33.81829719055836,9.78134439969742,-2.5679847574043224
758.8000000000101,33.86194347134198,9.802002785818283,-2.5855730514268944
760.1000000000101,33.90529811168502,9.79920319141628,-2.6018015065553515
761.4000000000101,33.94887597478284,9.778327210785134,-2.619520661341677
762.7000000000102,33.992475744639265,9.733628199584688,-2.636727999158442
764.0000000000101,34.03598316720995,9.654323181372122,-2.6548209171298818
765.3000000000102,34.079787795314104,9.533482510676212,-2.6718280322006933
766.6000000000101,34.123026433425004,9.35813808377644,-2.6888494104193272
767.9000000000102,34.166110366309624,9.104369968897506,-2.704557857645929
769.2000000000103,34.209433272032975,8.726583648774852,-2.719762711292139
770.5000000000102,34.25276161875257,8.14342525652326,-2.733334236209609
771.8000000000103,34.295954630306966,7.174382150114847,-2.745337853164883
773.1000000000103,34.33879996014434,5.709960743678395,-2.7524157798035116
774.4000000000103,34.38146755894985,4.766904396609495,-2.7587010738907205
775.7000000000103,34.42423353198166,4.245699560260748,-2.760121953124428
777.0000000000103,34.46710052644247,3.9555233538338985,-2.762761529667714
778.3000000000104,34.510137453641384,3.7905842087291144,-2.7614161914835407
779.6000000000104,34.55243123626826,3.6934765308937427,-2.7628981288028522
780.9000000000104,34.59659515049995,3.6340242041016886,-2.762935000506435
782.2000000000104,34.64003946105112,3.597078765896132,-2.7615602037823477
783.5000000000105,34.68368607919059,3.5801302459307918,-2.7608539644621546
784.8000000000104,34.727271473857094,3.570476575994432,-2.7587825874254426
786.1000000000105,34.77108676218004,3.5688237671956955,-2.7586573745960603
787.4000000000106,34.814495166309364,3.5707319333196557,-2.7602070530962615
788.7000000000105,34.85846571531849,3.5749919121515554,-2.760140342823395
790.0000000000106,34.90184814090068,3.58213507011433,-2.7599324156503324
791.3000000000105,34.945176704373104,3.589905386611889,-2.758883980247782
792.6000000000106,34.98903316082054,3.604480283617973,-2.75884500785825
793.9000000000106,35.032772834152595,3.613082229405839,-2.7590040793299537
795.2000000000106,35.07627549888147,3.628706898819495,-2.7601413730080124
796.5000000000106,35.11981747797526,3.640427915562452,-2.760853504359417
797.8000000000106,35.16344427090175,3.6527531766069243,-2.761514638440706
799.1000000000107,35.20707535384929,3.663034889004917,-2.7628243881596246
800.4000000000107,35.250729553291315,3.673967338299156,-2.76155533914388
801.7000000000107,35.29443151705615,3.6881081889542315,-2.76277066438423
803.0000000000107,35.338019444759446,3.7039128054500665,-2.7627716970889225
804.3000000000108,35.38187204625495,3.7153426613553626,-2.7610140579130404
805.6000000000107,35.42553746965084,3.7332850681401055,-2.760803113502191
806.9000000000108,35.469203183248204,3.7449011633108897,-2.762123749795565
808.2000000000107,35.513008731538854,3.7633891019717503,-2.7634989780609724
809.5000000000108,35.556565933364794,3.775952315350658,-2.7636526732883713
810.8000000000109,35.60023026852416,3.7894207847174393,-2.7621226541799464
812.1000000000108,35.643802034874064,3.805414808369353,-2.7594306479514343
813.4000000000109,35.687446685131775,3.8188932609000985,-2.760541936446667
814.7000000000108,35.73124053172306,3.8325375423916883,-2.7620997407335395
816.0000000000109,35.77469407868626,3.842760461750486,-2.7608839846371453
817.3000000000109,35.81825214393075,3.854838154255019,-2.7594809622714
818.6000000000109,35.862207273172324,3.8727581750960036,-2.7604564724518643
819.900000000011,35.90582549610503,3.8842601782144985,-2.7648868037609473
821.200000000011,35.949505282777736,3.898127340896447,-2.7673725939941516
822.500000000011,35.993250472299366,3.910158780163809,-2.768754333951623
823.800000000011,36.037002660375606,3.9229764222770807,-2.7686984871319975
825.100000000011,36.08070541768461,3.9340598302263903,-2.767397605951219
826.400000000011,36.124597747167336,3.9474055542506634,-2.7673799210529433
827.7000000000111,36.168258487020566,3.9615476156229494,-2.767367924493617
829.0000000000111,36.21188961029832,3.970404095626012,-2.7652833942151145
830.3000000000111,36.25559685370641,3.9837293624641767,-2.7642842137607273
831.6000000000112,36.299101464263885,3.998367123735567,-2.7631673846464215
832.9000000000111,36.342855057173246,4.01273633959035,-2.7624393711276665
834.2000000000112,36.38671899025342,4.026698411710255,-2.7633806479442335
835.5000000000111,36.430345765141915,4.0393797604098225,-2.7647406653984214
836.8000000000112,36.47425243394856,4.052801555673908,-2.7643870577921175
838.1000000000112,36.518280611762144,4.065895546737133,-2.7634296873213984
839.4000000000112,36.562182549875395,4.077873318487898,-2.763429932715452
840.7000000000113,36.605901183447756,4.094441164000322,-2.7634299320294238
842.0000000000113,36.64987704948322,4.106566450140566,-2.763429929717881
843.3000000000113,36.69338906942736,4.120488366873727,-2.7634269672352882
844.6000000000113,36.73724861149088,4.134301821903615,-2.764679823934105
845.9000000000113,36.78116604379928,4.147282668622609,-2.763406685132569
847.2000000000113,36.825188043589826,4.162604891591929,-2.7647388285264034
848.5000000000114,36.86883005132868,4.176879324478195,-2.764749977912535
849.8000000000113,36.912767786337255,4.195765453037524,-2.764750080808566
851.1000000000114,36.956740868189144,4.209885733881606,-2.7647731019490127
852.4000000000115,37.00061973794882,4.223842868924832,-2.766058916944258
853.7000000000114,37.0444013649926,4.243656419728696,-2.766060074181255
855.0000000000115,37.08840953052433,4.255049531618473,-2.7660600820226238
856.3000000000114,37.13230378866334,4.268656915306964,-2.7660600257195442
857.6000000000115,37.17650148305468,4.283621590887261,-2.7660434910523217
858.9000000000115,37.220355377233616,4.297982038970735,-2.763771340957426
860.2000000000115,37.26434501625752,4.315781540615589,-2.7637601349626113
861.5000000000116,37.30824903851675,4.329939311080599,-2.7637598618666943
862.8000000000116,37.35212312595092,4.344894136517892,-2.7638889606566606
864.1000000000116,37.396156235901714,4.363168331094565,-2.7650742441461023
865.4000000000116,37.44004297814098,4.380199843435439,-2.7663784076078977
866.7000000000116,37.48414113638808,4.395511236980226,-2.7663899312303846
868.0000000000116,37.52782314617978,4.410977666021529,-2.7663838072084266
869.3000000000117,37.57171787574477,4.425779068427324,-2.7678691793680987
870.6000000000117,37.61575495854799,4.445866021133328,-2.769020294323893
871.9000000000117,37.6596790441837,4.460255596987898,-2.7690197814670348
873.2000000000118,37.70367821123642,4.47423420678327,-2.7676040549295626
874.5000000000117,37.74759884373838,4.492554673262171,-2.76769871976761
875.8000000000118,37.79153709906671,4.507932515492453,-2.7668639080276627
877.1000000000117,37.83546486507841,4.5255766708545995,-2.7658086300770575
878.4000000000118,37.87946972029311,4.542008083524996,-2.7650668089362282
879.7000000000118,37.92338641567334,4.560765842132125,-2.7660553116671047
881.0000000000118,37.96730276281587,4.575134749249842,-2.7660599191551407
882.3000000000119,38.011208720098644,4.590734898934916,-2.766059928027831
883.6000000000118,38.055019506893395,4.606917575837621,-2.7660599282604847
884.9000000000119,38.09906583318662,4.624804329734852,-2.7660599309040803
886.2000000000119,38.14297688594349,4.645335512333922,-2.7660313930072906
887.5000000000119,38.18672692669779,4.6634418717188195,-2.7663911151935205
888.8000000000119,38.230637338182895,4.679165611124163,-2.766389859740395
890.100000000012,38.274772312685315,4.697903341751907,-2.766403934643975
891.0000000000119,38.30511251100894,4.71062592196441,-2.767558533741745