File: 01_Data/Nylon_Carpet_Low_Pile/STA/N2/30K_min/Nylon_Carpet_Low_Pile_STA_N2_30KData_220107_R4.csv
##Temp./Â°C,Time/min,DSC/(mW/mg),Mass loss/mg
49.0,10.493873916403386,-0.9550849899184035,0.0021445659238121806
50.30000000000002,10.729541712888949,-0.8002804529150419,0.00321478126857766
51.60000000000004,10.865241482044864,-0.6870149558315299,0.000909705046774345
52.900000000000055,10.974405485475875,-0.5947785430216356,0.0008821151954858664
54.200000000000074,11.066688072007189,-0.5150020472474344,0.005296038187195151
55.50000000000009,11.147627157920478,-0.4433836392153802,0.006446772826933067
56.80000000000011,11.222125566841491,-0.37623949416977165,0.005733122042434591
58.10000000000013,11.29193107120713,-0.3173003400021487,0.006752468001076206
59.40000000000015,11.357248147568132,-0.2617042664652657,0.010929735361285609
60.700000000000166,11.41949993981545,-0.2091126554252867,0.007981843205014716
62.000000000000185,11.478996353435694,-0.16049083364605332,0.007926021787020954
63.3000000000002,11.536608761935895,-0.11506385667167213,0.0077888848814327005
64.60000000000022,11.593209831506345,-0.07076186346835592,0.007673347035939138
65.90000000000023,11.647728044323502,-0.029864646240542515,0.007646103287370032
67.20000000000026,11.70169000508016,0.010556099869189307,0.006445862579542272
68.50000000000028,11.753864144369205,0.04629732025242413,0.006239710589088787
69.8000000000003,11.805495921974536,0.08186479316068714,0.006517493429018639
71.1000000000003,11.855723700310321,0.11653374993525861,0.006313475327993423
72.40000000000033,11.906194075971014,0.15127464559612439,0.003939637780061567
73.70000000000036,11.955715709176468,0.18205932114055412,0.0045128143236805585
75.00000000000037,12.004454964273956,0.20965981721765756,0.0034758420366380882
76.30000000000038,12.053273884998923,0.23989461229540318,0.0016444285359833444
77.6000000000004,12.101416121154553,0.2647420197732977,-3.352877966378287e-07
78.90000000000043,12.148847451922654,0.2905215398446428,0.001489425722280835
80.20000000000044,12.196760063002351,0.3154350562990362,0.002304379683189417
81.50000000000045,12.243409194714468,0.33856674647653284,0.004597004956160777
82.80000000000048,12.289822687492526,0.3616741301556983,0.005795095045474596
84.1000000000005,12.336574250201403,0.38469150048024364,0.007360251510363458
85.40000000000052,12.382662587496228,0.40588159493457115,0.007770787324103079
86.70000000000053,12.42808233315785,0.4262795907028159,0.0065871857281467605
88.00000000000055,12.473501170796865,0.44816198135936836,0.006974878650274352
89.30000000000058,12.519030563062914,0.46917162815247504,0.005404986105902676
90.60000000000059,12.564252410296014,0.48889637221379506,0.00696194065279343
91.9000000000006,12.609241996984206,0.5084760394983299,0.007491549995074731
93.20000000000063,12.654100462345346,0.5265957963269782,0.007462043285766384
94.50000000000065,12.69869369047395,0.5467812682343122,0.006059442462922782
95.80000000000067,12.743180225647754,0.5648256317893765,0.005192443123670731
97.10000000000068,12.78746201066529,0.5825647519882179,0.0028966822938056858
98.4000000000007,12.832113415951339,0.6008365765335549,0.004286908596482952
99.70000000000073,12.875995276906975,0.6182588329349361,0.0042781159586753326
101.00000000000074,12.920378697339592,0.6352214420378101,0.004279588556887148
102.30000000000075,12.964030741440043,0.6507433164672971,0.005638503700379882
103.60000000000078,13.008192729896411,0.6685795261272839,0.005548267881913649
104.9000000000008,13.051951531038949,0.6824762705188794,0.006771886376319536
106.20000000000081,13.096093241959782,0.6973090415775912,0.006260895156654733
107.50000000000082,13.139572625666688,0.7147533083280078,0.006887495275736288
108.80000000000085,13.18364291715104,0.7277352109699141,0.0043599085893415435
110.10000000000088,13.227373134474128,0.7414362363184378,0.0036127712236622145
111.40000000000089,13.271054950563217,0.7565989494460816,0.0012889344659963164
112.7000000000009,13.314777627296754,0.7690440697228388,0.00031712131826866496
114.00000000000092,13.358277811528314,0.7802716215124393,0.0004325186913578527
115.30000000000095,13.40197988064089,0.7941343658434645,0.0005552102539496673
116.60000000000096,13.445334742229416,0.805057195199853,0.0016397121411606541
117.90000000000097,13.488902829049147,0.8180558305037714,0.0016184331084572179
119.200000000001,13.532357841867753,0.8291188210864068,0.0013170520935847918
120.50000000000102,13.575308302635905,0.8423514188917607,0.0012636469714655263
121.80000000000103,13.618435587318693,0.8549837247647858,0.0026229422238683853
123.10000000000105,13.66183155101237,0.8664873781667655,0.0026303466094850236
124.40000000000107,13.704809254316425,0.8777351468094157,0.0016754563163621228
125.7000000000011,13.74764312319212,0.8897240123297074,0.0018613681893211442
127.00000000000111,13.79055967731282,0.9016792666349582,0.0016792875677280605
128.30000000000112,13.833126774873822,0.915215667297275,0.0016351961417888639
129.60000000000116,13.876230520897236,0.9275174027353039,0.00036655152353093357
130.90000000000117,13.918431459887543,0.9386456292816212,-0.0009802583214812977
132.20000000000118,13.961452307308466,0.9516368226724788,-0.0006291449395123827
133.5000000000012,14.004000464398898,0.9647735939041333,-0.0006599261256856614
134.8000000000012,14.046179463917314,0.9777659929146644,-0.0006661083497379039
136.10000000000124,14.088327061284735,0.9898599671429182,0.0006224401767167542
137.40000000000126,14.130369432293945,1.0040159558905006,0.0016395328581793045
138.70000000000127,14.172672783259234,1.017700696343356,0.002630908138207655
140.0000000000013,14.215057625900528,1.0322067055359851,0.0026299603011175066
141.30000000000132,14.256654911137282,1.0471022903594276,0.0026185756344556665
142.60000000000133,14.29839528653095,1.0635265349817655,0.0013131662348082607
143.90000000000134,14.340573095834433,1.078191684023541,0.0011874830384548396
145.20000000000135,14.38207384117514,1.0951186845524923,0.0003257267519214402
146.5000000000014,14.423874666340664,1.112039840313498,0.0008103737386204735
147.8000000000014,14.465448852322393,1.1304024529559296,-0.0010527586597075533
149.10000000000142,14.506994997214258,1.1475765873774704,-0.0012909672159935326
150.40000000000146,14.548702729553165,1.168411289426564,0.00010003287890825163
151.70000000000147,14.589876998252548,1.1888747014938053,0.0008204933255342439
153.00000000000148,14.631439993067135,1.2115648703838082,0.0014190034691763387
154.3000000000015,14.672969191844873,1.2349637970924037,0.001419870559133507
155.6000000000015,14.71405655234884,1.2620034527373951,0.001419875972749729
156.90000000000154,14.75535277196164,1.2907506046384523,0.0014198735996351353
158.20000000000155,14.796645483311433,1.320656359129695,0.001418771806593444
159.50000000000156,14.83751595352069,1.3518160033706876,1.2409713452399274e-05
160.8000000000016,14.878752317902814,1.3816904680662065,0.0004420987402085075
162.10000000000161,14.92012583211716,1.4099234619403238,0.00044015508058947717
163.40000000000163,14.960734287268329,1.4312066543845632,0.0004533012167664552
164.70000000000164,15.002166755804366,1.4428674693630124,-0.0008656943445739529
166.00000000000165,15.0437326964883,1.4446065365344156,-0.0022873420092199837
167.3000000000017,15.084304184410701,1.4417630019197591,-0.0015954018475845544
168.6000000000017,15.125143286766216,1.4321452591838422,-0.0028562031058187998
169.9000000000017,15.166013898225069,1.4228414436794123,-0.004230638152414645
171.20000000000175,15.20704243782697,1.4145311968286287,-0.00368598901814865
172.50000000000176,15.247702233506907,1.405964769829231,-0.003429219042477172
173.80000000000177,15.288722376192341,1.4004811206973367,-0.004098851285834648
175.10000000000178,15.329169687327797,1.3985000022724163,-0.00547877656861484
176.4000000000018,15.369859127861574,1.4007234839993024,-0.0041776219649798385
177.70000000000184,15.410165932686898,1.404508425026962,-0.00417016944855364
179.00000000000185,15.450835294100802,1.4110276995783697,-0.0041680722200134745
180.30000000000186,15.491194924921084,1.4169675971414608,-0.0054558822627877035
181.6000000000019,15.531863677580366,1.427019522486685,-0.006835485919983508
182.9000000000019,15.571954422698656,1.4344940094819099,-0.00811973008640443
184.20000000000192,15.612337680772912,1.4463242410321595,-0.008125932805642666
185.50000000000193,15.652688470800214,1.4558927933474048,-0.0067399080548473655
186.80000000000194,15.693132824925382,1.4671450788607612,-0.005333195925830925
188.10000000000198,15.733280874887331,1.4797866938215076,-0.004631061705030248
189.400000000002,15.773386155175372,1.4909641191483065,-0.004061895320848663
190.700000000002,15.813293629478505,1.5039257817533802,-0.004060121719986043
192.00000000000205,15.853426778694647,1.5155969277636603,-0.004063971265067412
193.30000000000206,15.89349653185616,1.5307122046199495,-0.00277500463402669
194.60000000000207,15.933263235509589,1.5429957338931577,-0.0027424316191679843
195.90000000000208,15.972920626498333,1.5556927254001798,-0.0039703542221558585
197.2000000000021,16.0128604563539,1.571350521944221,-0.005355110447005096
198.50000000000213,16.0528391334574,1.5849914635970244,-0.004049507697772015
199.80000000000214,16.09275110838446,1.6009889082434954,-0.005386616509832631
201.10000000000215,16.132954903835532,1.6158265736398856,-0.00532997798496071
202.4000000000022,16.17259609731544,1.633771092028245,-0.006609053235224316
203.7000000000022,16.212634917209517,1.6482799943896347,-0.008007703094809138
205.00000000000222,16.252564283371466,1.665398701596272,-0.008013006524643984
206.30000000000223,16.29201793694747,1.686017510938752,-0.008840842597213516
207.60000000000224,16.332394581707664,1.7078771221969367,-0.010645724937718537
208.90000000000228,16.371862362669628,1.7338466076987153,-0.009488720398719952
210.2000000000023,16.4119592370513,1.7669442785730105,-0.009422023528401713
211.5000000000023,16.451268327984508,1.8123526813466078,-0.008005470734624431
212.80000000000234,16.49125846970199,1.8779810455357513,-0.009253199378423727
214.10000000000235,16.530648308441883,1.9644772643150072,-0.009329577496572927
215.40000000000236,16.57069618075403,2.0749642452268624,-0.009311534676155198
216.70000000000238,16.61010703012022,2.2026043734113556,-0.008001575635414149
218.0000000000024,16.649993419969803,2.343596488279941,-0.008083800931239171
219.30000000000243,16.689629967819574,2.4685506992927717,-0.007022384942930948
220.60000000000244,16.729446674675863,2.547480597508668,-0.0070297902100668885
221.90000000000245,16.76920052113667,2.554890205753742,-0.007029825418936486
223.2000000000025,16.80904711740787,2.499896604595146,-0.0070316391571743075
224.5000000000025,16.8489888266228,2.413976001198856,-0.008340430070048921
225.8000000000025,16.88861518456482,2.319881818825822,-0.008340195861276545
227.10000000000252,16.928090153960763,2.2356990396523124,-0.008340192041066175
228.40000000000254,16.96767289300104,2.1554839684420024,-0.008340192002215918
229.70000000000258,17.006944345161195,2.0874588913619174,-0.008340192493097032
231.0000000000026,17.046136021482344,2.0358824398723647,-0.008340307067601138
232.3000000000026,17.08572536317694,1.9903850971578863,-0.008456142931443367
233.60000000000264,17.12492295503999,1.9600708330948882,-0.009410311408774685
234.90000000000265,17.16458084218755,1.9360804809190775,-0.008152720202675656
236.20000000000266,17.20380485417257,1.9206550941428175,-0.0077131712323388335
237.50000000000267,17.242803471689147,1.9115288250657196,-0.007351392853940375
238.80000000000268,17.282522844803314,1.9052127835114216,-0.0073780430812546705
240.10000000000272,17.32153455146492,1.9021694090735848,-0.008670957422164172
241.40000000000273,17.360915411202924,1.900841236853015,-0.009786434336782612
242.70000000000275,17.399950729311936,1.9030772744816027,-0.010000524604602212
244.00000000000279,17.43917000000009,1.9055499999999983,-0.011341598042370116
245.3000000000028,17.47888765155148,1.9095664280590239,-0.01130048949785012
246.6000000000028,17.518099616626728,1.9123961043078457,-0.011314072488519678
247.90000000000282,17.55761885841239,1.9171022379519644,-0.009782384702428981
249.20000000000283,17.596724886072572,1.9232514384234245,-0.00845320894708701
250.50000000000287,17.635861179125154,1.9287582405842385,-0.008447524579527244
251.80000000000288,17.675216127755817,1.9338505958563994,-0.00976498257625158
253.1000000000029,17.714401838836334,1.9411288876911752,-0.009653528272499656
254.40000000000293,17.753522356194626,1.9479555003344136,-0.012848635894464167
255.70000000000294,17.792775204199177,1.9540685132577105,-0.015027336398825142
257.00000000000296,17.8321502918622,1.9596198765751014,-0.015983109466143564
258.30000000000297,17.871294528410573,1.965536090306508,-0.01603271992498234
259.600000000003,17.910589830384122,1.9731142177805414,-0.015913354131747326
260.90000000000305,17.949881720665427,1.9791996404255559,-0.016236366467451635
262.200000000003,17.989482649682724,1.9846717694918918,-0.016240019256776872
263.50000000000307,18.028479291406118,1.991128657516502,-0.016240773617526294
264.8000000000031,18.067496204222593,1.9985491328105047,-0.017625111571248464
266.1000000000031,18.106828414537485,2.0047274064807725,-0.016571640537683674
267.4000000000031,18.14627984873854,2.0110777834063986,-0.016094570732293256
268.7000000000031,18.18535486741005,2.017553735957701,-0.014702791026319328
270.0000000000031,18.224772633685134,2.022556674570732,-0.013390454266314133
271.30000000000314,18.26371877529686,2.028545217088906,-0.013380162734258239
272.6000000000032,18.30304952264878,2.032614928243831,-0.013379997933669063
273.90000000000316,18.34246368138097,2.039980474809336,-0.013379978773343737
275.20000000000323,18.381691472033285,2.046147965882009,-0.013495738096116483
276.50000000000324,18.420802030009053,2.050787903771105,-0.01528865624707132
277.80000000000325,18.460219840405557,2.057689306155643,-0.016234727572832508
279.10000000000326,18.499354550864954,2.0621633428948267,-0.01655934532295289
280.4000000000033,18.538145602867775,2.069436965829168,-0.017844391419225225
281.70000000000334,18.57739894794725,2.0760851162087537,-0.018388081020338287
283.0000000000033,18.617374786655855,2.0796146724323803,-0.019201508098229958
284.30000000000337,18.65683495770498,2.0834485463115926,-0.019200006275578385
285.6000000000034,18.696178754768503,2.089547642712702,-0.019199999114173583
286.9000000000034,18.7357072738603,2.094371941997701,-0.01920062523332966
288.2000000000034,18.77476049050653,2.1012422413726615,-0.019382634366927665
289.5000000000034,18.81420138382122,2.106802820311106,-0.0194636515680382
290.8000000000034,18.853472486018607,2.1102735128836305,-0.020506328142849473
292.10000000000343,18.892734140160584,2.115359146870604,-0.021934610566756163
293.4000000000035,18.9321239852623,2.1194209638089156,-0.02325458780521439
294.70000000000346,18.971326094064835,2.1269434363786264,-0.023256863690465757
296.0000000000035,19.010777706030858,2.1311577617963517,-0.02456261284770811
297.30000000000354,19.050389370265872,2.136802681325407,-0.02466334861291175
298.60000000000355,19.08976054010343,2.1430379252942378,-0.025890357673620024
299.90000000000356,19.128986462067402,2.146800147160681,-0.025897106992246233
301.20000000000357,19.16842413011284,2.1517626460749826,-0.024595174618164517
302.50000000000364,19.208037088494887,2.156113279633489,-0.023081102602097392
303.8000000000036,19.24721994066491,2.1606943347622423,-0.020772014905080294
305.10000000000366,19.286517360210183,2.164774886575646,-0.01973898974263033
306.4000000000037,19.32651081430774,2.1709749201708526,-0.019739985399854554
307.7000000000037,19.36543014414788,2.176508682817789,-0.019702819568342633
309.0000000000037,19.40541548107573,2.1806372392528917,-0.021743205883109518
310.3000000000037,19.444607332951445,2.186102375432832,-0.023630181398996086
311.6000000000037,19.484155846415508,2.1914672202495926,-0.025119069814171446
312.90000000000373,19.523708865591427,2.194150163894068,-0.025199545888147323
314.2000000000038,19.563245101124465,2.2008433114185886,-0.027061998034219048
315.5000000000038,19.60264276451911,2.204623978226836,-0.027417154183418724
316.8000000000038,19.64226059182436,2.2101582444475434,-0.027786796772637956
318.10000000000383,19.68178807452456,2.214942463707082,-0.02907268519090289
319.40000000000384,19.721479999166107,2.2221077557777393,-0.030481757906374085
320.70000000000385,19.76046133655848,2.227952388830477,-0.030391496546751107
322.00000000000387,19.80022890517083,2.2340279713152023,-0.03141265774771762
323.3000000000039,19.840002839632877,2.239899229934424,-0.031706261389929935
324.6000000000039,19.87943893471983,2.2457334322922256,-0.03173648236636728
325.90000000000396,19.91917031418124,2.2514200611450694,-0.03435029424842728
327.20000000000397,19.95878706923316,2.2564827217802477,-0.03528669574628163
328.500000000004,19.998549665726014,2.2620454225216893,-0.03564872587846413
329.800000000004,20.037867006691762,2.26846659173032,-0.037015068890518865
331.100000000004,20.07760000643311,2.2769318328722736,-0.039015483317403454
332.400000000004,20.117594798786204,2.28335084704567,-0.042274017655922425
333.700000000004,20.157261371193503,2.292176337453089,-0.04430046686508238
335.0000000000041,20.196674487971872,2.2994301916457074,-0.04309382984516974
336.3000000000041,20.23651274115861,2.3082728396432444,-0.041459555143938065
337.6000000000041,20.276156653943197,2.31570493657372,-0.04016714846139324
338.9000000000041,20.31599909363073,2.323188294127579,-0.04125410864699752
340.20000000000414,20.355452709443448,2.3349870173508576,-0.0425946624274216
341.50000000000415,20.3955281601947,2.34447667428519,-0.04372637721126571
342.80000000000416,20.435435497376027,2.355852951252246,-0.04584676316479763
344.1000000000042,20.475216414218185,2.3654697179531907,-0.04819291436418682
345.4000000000042,20.51495731829775,2.374675428208266,-0.05003747647459367
346.70000000000425,20.55511919259427,2.3862327956366425,-0.05453778404374843
348.00000000000426,20.59456842454459,2.397121670051302,-0.05712014622466155
349.3000000000043,20.634755305106385,2.4125847796625384,-0.06009421638814105
350.6000000000043,20.67433467312289,2.423764689144944,-0.061199682446607895
351.9000000000043,20.714366706533408,2.439157504498143,-0.06472682163821775
353.2000000000043,20.754237521014414,2.4527728582159627,-0.06813093183692098
354.5000000000043,20.79386759808361,2.4670516118257844,-0.0697990435453879
355.8000000000044,20.83425725956826,2.484091012922902,-0.0736642065676083
357.1000000000044,20.874311063794682,2.502102986164085,-0.07806005660313975
358.4000000000044,20.91455519833088,2.5200406315148305,-0.08263414769382882
359.7000000000044,20.954426307595767,2.5396948611749126,-0.08617735714538188
361.00000000000443,20.994518651491518,2.559214512349438,-0.08989980787232943
362.30000000000445,21.034350026726276,2.579401962696014,-0.09697105964528774
363.60000000000446,21.07442153966407,2.6024060355515126,-0.10199983527771384
364.90000000000447,21.114358779897394,2.6266379017645876,-0.10816179881364762
366.2000000000045,21.15451199691917,2.6480246155098883,-0.11336669730346527
367.50000000000455,21.19486139200956,2.672044144482611,-0.12051509354222079
368.80000000000456,21.234920402321354,2.700033337339481,-0.12791511537293276
370.10000000000457,21.275169049554098,2.7266649744718476,-0.13592479089464016
371.4000000000046,21.31505945879891,2.7560064737949452,-0.14165010068111128
372.7000000000046,21.35550024609811,2.7845793136142953,-0.15074884315282588
374.0000000000046,21.395550568972507,2.8124307175004013,-0.15959758387462042
375.3000000000046,21.435827005470305,2.841494130559841,-0.16794119836519084
376.6000000000047,21.476234069060077,2.8725988102400217,-0.17625872845540735
377.9000000000047,21.51650947622637,2.9047018488681347,-0.18577063299456542
379.2000000000047,21.555721507650397,2.9334625082718557,-0.19674685270643133
380.5000000000047,21.596828209357177,2.9692787591630507,-0.20725990268923988
381.80000000000473,21.636867225567457,3.0023597284354153,-0.218231847878684
383.10000000000474,21.677392006783876,3.0364257436970354,-0.23146563189555325
384.40000000000475,21.71773364212207,3.070235992772971,-0.24220195363490227
385.70000000000476,21.758333488697613,3.1039564751011888,-0.2551165678742091
387.0000000000048,21.79874258702377,3.140773460535618,-0.2687185531628975
388.30000000000484,21.839233181067236,3.177573001856264,-0.2826790486654285
389.60000000000485,21.879569893072468,3.21311730983842,-0.29815884983525676
390.90000000000487,21.919841546227854,3.2511560788329468,-0.3141120148569061
392.2000000000049,21.96047696444354,3.290055270255035,-0.328159040313464
393.5000000000049,22.000624375378916,3.3284296272779494,-0.3448201541338838
394.8000000000049,22.041551813215722,3.370464316837018,-0.3623447121688099
396.1000000000049,22.081904343390057,3.411140816941966,-0.3818079924292759
397.400000000005,22.12253899987746,3.4518629894237582,-0.4015234109532866
398.700000000005,22.163037772241786,3.4951637823989934,-0.42046176569596705
400.000000000005,22.203528567080923,3.5409609014786416,-0.4407952359602949
401.300000000005,22.2441307380705,3.5863305481689816,-0.4625019810292761
402.600000000005,22.28453237679591,3.6315612742483263,-0.48414255293338293
403.90000000000504,22.325520264032914,3.6778217604833126,-0.507111335649292
405.20000000000505,22.3660358428877,3.7271458054158866,-0.5302191797948832
406.50000000000506,22.406307795769006,3.773918452030704,-0.554572483595396
407.80000000000507,22.447434182130937,3.822907356287153,-0.5817092236025942
409.10000000000514,22.487946798268926,3.8685778167367277,-0.6103530098328793
410.40000000000515,22.528608882573316,3.9156176604891737,-0.6368106938034721
411.70000000000516,22.569551842159,3.9618326596070994,-0.665439515679993
413.0000000000052,22.610035776165017,4.003466079993048,-0.6970320871571718
414.3000000000052,22.651114214430372,4.042734357745161,-0.7290280990837239
415.6000000000052,22.691857180407194,4.078349718121677,-0.7600061341536519
416.9000000000052,22.732352027270867,4.1109113867133305,-0.7948828746721883
418.2000000000053,22.772997197632467,4.138309346062552,-0.8298432635257775
419.5000000000053,22.814118298977338,4.157112082441765,-0.8655355385881087
420.8000000000053,22.854860326358622,4.170645089205997,-0.9011551281017924
422.1000000000053,22.895464081973874,4.173668204218947,-0.9370610454441066
423.4000000000053,22.9361082826378,4.165083547791034,-0.9739999753441992
424.70000000000533,22.977028585358187,4.142407138659709,-1.0122314292761851
426.00000000000534,23.018057716509503,4.104912535766446,-1.04987326871165
427.30000000000535,23.058567461107184,4.054315154427992,-1.086344256292676
428.60000000000537,23.099663841850763,3.984671154058062,-1.1230239358558611
429.90000000000543,23.14030340177299,3.8981725098533158,-1.1554911861374588
431.20000000000545,23.1809388330441,3.799371613598346,-1.1898845529707032
432.50000000000546,23.22183440364907,3.6854671076744303,-1.2245844141738305
433.80000000000547,23.262382529316014,3.5672837283959917,-1.2549335183159878
435.1000000000055,23.303083644199262,3.44225390487777,-1.2845607163593358
436.4000000000055,23.343753786849277,3.3226091108424023,-1.309251931739936
437.7000000000055,23.384427308546588,3.2055747125632896,-1.331725000341931
439.00000000000557,23.425030987593594,3.0979140020593308,-1.3534223270432513
440.3000000000056,23.465760854338246,3.003332963339785,-1.3714307567343083
441.6000000000056,23.506372199530816,2.9194070739946265,-1.3889422061634251
442.9000000000056,23.546993563974766,2.8498855895426782,-1.4059006826957843
444.2000000000056,23.587839780938502,2.790276941828597,-1.421305814752623
445.5000000000056,23.62824798473806,2.741053204786849,-1.4367762642827806
446.80000000000564,23.669582979793105,2.701632909677929,-1.4522852001883573
448.10000000000565,23.710549691049472,2.670984295277019,-1.4662815092287604
449.40000000000566,23.75086704505222,2.6437079310355722,-1.4774800084527056
450.70000000000573,23.791800125493914,2.626120421984697,-1.488923416925311
452.00000000000574,23.832876582734393,2.6057991434195293,-1.5000542039039129
453.30000000000575,23.87353366007611,2.5962998170475022,-1.5114839494656227
454.60000000000576,23.91451724890228,2.5846841577482738,-1.522599674998962
455.9000000000058,23.955164502835746,2.5788358822470823,-1.5327977089224034
457.2000000000058,23.996452429398328,2.572935559779312,-1.5462582766897146
458.5000000000058,24.03729215327732,2.5692432864462953,-1.558166568492164
459.80000000000587,24.07824463886544,2.567008881460225,-1.5702616771520508
461.1000000000059,24.119138816208782,2.5662272346992614,-1.5823423193974686
462.4000000000059,24.160398465501686,2.562849968725587,-1.5929203993583734
463.7000000000059,24.201481136904885,2.5654605767263967,-1.605135355257549
465.0000000000059,24.24253118097813,2.565770070565514,-1.6149368247669145
466.3000000000059,24.283857676196106,2.567095462256825,-1.6248743777963672
467.60000000000593,24.324942892679083,2.5675029375335443,-1.6342167404727475
468.90000000000595,24.36640298298251,2.569204233548755,-1.6455862354254425
470.20000000000596,24.407300962644083,2.5704843601656457,-1.6578920862722577
471.500000000006,24.448349841479523,2.573189813745822,-1.6715526355246078
472.80000000000604,24.48951811331347,2.5741481298845543,-1.6821302435890346
474.10000000000605,24.53089364715354,2.5742822437089825,-1.69338562906476
475.40000000000606,24.572295613778238,2.576988303389131,-1.7055401857738546
476.70000000000607,24.613565990195646,2.5757081752857585,-1.7181081204523903
478.0000000000061,24.654865714704712,2.5756759322453213,-1.730398553914216
479.3000000000061,24.69612954807091,2.5729353701062663,-1.7411094065098314
480.60000000000616,24.737524059941077,2.57372646661143,-1.7496181409730247
481.9000000000062,24.77888542711175,2.570727787672816,-1.761678321325233
483.2000000000062,24.820318375236074,2.567807033623502,-1.7723344359533342
484.5000000000062,24.861795822666487,2.5666611479596244,-1.7857836229203325
485.8000000000062,24.90325131406742,2.5595350591580153,-1.7991787561351553
487.1000000000062,24.944592288980573,2.554851742477195,-1.8106113916061704
488.40000000000623,24.98615624770993,2.5468930626891093,-1.822543581488984
489.70000000000624,25.027666249288643,2.535802423841332,-1.8341561636546606
491.00000000000625,25.068876942177475,2.5230858801526628,-1.8456786210834126
492.3000000000063,25.110288536180004,2.5032367344806277,-1.8569616501617099
493.60000000000633,25.151941363197132,2.4815785168099507,-1.8685137936382574
494.90000000000634,25.193188743449465,2.4539733327852544,-1.8791082263949792
496.20000000000636,25.23465434742227,2.4203317256000094,-1.8890285216687013
497.50000000000637,25.276114579720222,2.3846422593728915,-1.8984366539725932
498.8000000000064,25.31761138998866,2.3441484454375394,-1.9061999228335846
500.1000000000064,25.358875760337458,2.3034246476819917,-1.913110996570487
501.40000000000646,25.400660617069487,2.2601103823465825,-1.9193495690234261
502.70000000000647,25.442478029288,2.2244708220417566,-1.9256526496005626
504.0000000000065,25.484050770018648,2.1861448347001926,-1.9283339934088546
505.3000000000065,25.525347852114155,2.1568733166964633,-1.9319168268930147
506.6000000000065,25.566983422796774,2.132764378030697,-1.9336763936382142
507.9000000000065,25.60865390584499,2.112080213934801,-1.9351965905092352
509.2000000000065,25.650269564736586,2.0953983498682196,-1.936535095908047
510.50000000000654,25.692090476204832,2.082763051104802,-1.936511434279522
511.80000000000655,25.733730319467977,2.073057553608785,-1.9369248403137367
513.1000000000066,25.775311496448467,2.0687605052923352,-1.939194100994965
514.4000000000067,25.81719803584137,2.0631772950742913,-1.9391172095300369
515.7000000000066,25.858941690387187,2.060631104920737,-1.937813008259428
517.0000000000066,25.900868111577775,2.058573343709219,-1.937637145736411
518.3000000000067,25.942783859328614,2.0573931129254484,-1.9361120441126625
519.6000000000067,25.984526878260596,2.058084294687264,-1.9373957214120447
520.9000000000067,26.026471947318672,2.0578889161288956,-1.9373894542417402
522.2000000000068,26.068309984246408,2.06038433389014,-1.9372971487731259
523.5000000000068,26.110102935695792,2.059360667553158,-1.9386988361423887
524.8000000000068,26.15192395264137,2.0605946179455037,-1.9386998280390872
526.1000000000067,26.19363202588219,2.0617585268975995,-1.9391578658231516
527.4000000000068,26.23578263178266,2.0615101225436026,-1.9402733438136432
528.7000000000069,26.277663060917753,2.0610298757763226,-1.9419777452544786
530.0000000000068,26.319529672437344,2.061017815138842,-1.942760345808916
531.3000000000068,26.361620462849494,2.063039975779907,-1.9415278281477417
532.6000000000068,26.403050077682707,2.07044359020301,-1.9414501450499664
533.9000000000069,26.445069932605037,2.084793362567189,-1.941014611348506
535.2000000000069,26.486857967456416,2.097382809223971,-1.940792218914
536.5000000000069,26.529170000000228,2.1152900000000594,-1.9417730278303797
537.800000000007,26.570758990667226,2.1260891665516017,-1.9435246426070494
539.100000000007,26.61265778320731,2.1388573747800286,-1.9435399697808164
540.4000000000069,26.654792063853495,2.1463090259261395,-1.9435400824744664
541.700000000007,26.696692018294492,2.1543221394886714,-1.94358653133764
543.000000000007,26.73887801598376,2.1578936479128004,-1.9422294072972388
544.300000000007,26.78090135350313,2.16203730343089,-1.942252898479245
545.6000000000071,26.823059886201165,2.1632269345506803,-1.9418658916758664
546.9000000000071,26.86506578228791,2.1664970895133977,-1.9422429812184188
548.2000000000071,26.907045387845354,2.1671320905947025,-1.9412341252935965
549.500000000007,26.94907237022194,2.1703419900856944,-1.9412264815967832
550.8000000000071,26.991240830974842,2.17480537005286,-1.942601155775467
552.1000000000072,27.033656342030387,2.181047542348045,-1.9440736456918724
553.4000000000071,27.07589835406221,2.187093361265295,-1.9447005922226346
554.7000000000072,27.11793548751472,2.191288670135541,-1.9447063555076953
556.0000000000073,27.160370470530175,2.19536169460637,-1.9434110576861108
557.3000000000072,27.202211408566207,2.1977995205530214,-1.9434084196789403
558.6000000000072,27.244398326449716,2.2044621813554337,-1.9434472534572325
559.9000000000073,27.28663024205192,2.206482752342792,-1.9443904027204542
561.2000000000073,27.329267475145823,2.2095884611021575,-1.9457090671481727
562.5000000000073,27.371141951069976,2.2139999779567194,-1.9457286035645307
563.8000000000073,27.41353026528423,2.2156751699943937,-1.9446768998134512
565.1000000000073,27.455676528140742,2.219125224640277,-1.9447417663429496
566.4000000000074,27.498155368363552,2.2213521494558237,-1.9457268061397297
567.7000000000073,27.539446792051553,2.2250052527863122,-1.9475135383583173
569.0000000000074,27.582268337871934,2.2266014872917568,-1.9490857770985723
570.3000000000075,27.624884317518834,2.231636310033297,-1.95042982134713
571.6000000000074,27.667348103238385,2.2381179641230258,-1.9510020441725828
572.9000000000075,27.709826313359205,2.239086377826856,-1.9511550157198472
574.2000000000074,27.752174251195758,2.2388207722769433,-1.9497847569214577
575.5000000000075,27.79438229356234,2.2386224485353203,-1.948476297952861
576.8000000000075,27.836876220784923,2.239625040239684,-1.9473278810772339
578.1000000000075,27.879233251286422,2.239861589932454,-1.947149993575707
579.4000000000076,27.92153957592929,2.24121312629769,-1.9465881995801078
580.7000000000075,27.963542893874052,2.2414953636441894,-1.9458322058111133
582.0000000000076,28.006672547891508,2.2428314426428977,-1.9458486813697724
583.3000000000076,28.04823399925683,2.2464772703693825,-1.9471557671142188
584.6000000000076,28.091687531459762,2.248598668553756,-1.9471501508054287
585.9000000000076,28.13426107892022,2.252325165581981,-1.947150140610721
587.2000000000077,28.1766063770344,2.2550292576134066,-1.9471502573922455
588.5000000000076,28.219039939951344,2.2617770969849884,-1.9474691594733176
589.8000000000077,28.26194619309095,2.268983579188716,-1.9493827610635721
591.1000000000078,28.30433583750804,2.2734184314437176,-1.9516149167253412
592.4000000000077,28.346882959579542,2.2801541993811165,-1.9530820908380635
593.7000000000078,28.389591451547446,2.2888486200853295,-1.9527414092579658
595.0000000000077,28.432569976375834,2.2974569638536564,-1.9512697787962794
596.3000000000078,28.47504296477929,2.30592290925397,-1.9493336846724647
597.6000000000078,28.51765405742207,2.3172730819483376,-1.9485800084051461
598.9000000000078,28.560292560502642,2.3252643973576324,-1.9485410203767213
600.2000000000078,28.60304227160951,2.3362665959163254,-1.9472563883677014
601.5000000000078,28.645302627232336,2.347687645740094,-1.9473693281724733
602.8000000000079,28.687958745196994,2.358987856029736,-1.9472914015538496
604.1000000000079,28.731023594120966,2.372472413316853,-1.9490835176998225
605.4000000000079,28.773591925644915,2.384208461775547,-1.9498048510685875
606.7000000000079,28.81602877245373,2.3979462471339024,-1.95115432755397
608.000000000008,28.85907243509815,2.410999557584359,-1.9525282238680042
609.3000000000079,28.901477427436284,2.4256216439906453,-1.953883815493402
610.600000000008,28.944296460645763,2.4381359017336863,-1.9543174386245763
611.900000000008,28.98712731095774,2.4535264309148683,-1.955162329879228
613.200000000008,29.02984497950064,2.4661115126098956,-1.9540376278834044
614.5000000000081,29.07270429553536,2.4826116670787433,-1.9552160324506027
615.800000000008,29.11545201827942,2.494786946935587,-1.9538373590955636
617.1000000000081,29.158267485241936,2.5093261293210194,-1.9550781623320246
618.400000000008,29.20111272628552,2.524301052894241,-1.9577264579017792
619.7000000000081,29.243896351296225,2.5376574053072463,-1.9577923206557757
621.0000000000082,29.286529621766405,2.553736402908194,-1.95648361450424
622.3000000000081,29.328429227093352,2.5692885299370776,-1.9564699434558572
623.6000000000082,29.37206555719715,2.582674653873942,-1.9562408237176627
624.9000000000082,29.41462058274922,2.5966906575940665,-1.9557920136500737
626.2000000000082,29.458118598238386,2.6128201706122285,-1.9564847983665143
627.5000000000082,29.500756327824845,2.6292100098686584,-1.9564534025595757
628.8000000000083,29.5436876451865,2.646485239816318,-1.957784854360709
630.1000000000082,29.586743158892897,2.66049491999113,-1.9581200297326218
631.4000000000083,29.629732165936552,2.6798568689657105,-1.958508348109187
632.7000000000083,29.672621356814837,2.6951866310281,-1.961254198265583
634.0000000000083,29.715546681329844,2.712160862695626,-1.9625807706432439
635.3000000000084,29.75857035820234,2.7298735621871923,-1.963270823894522
636.6000000000083,29.801298805911795,2.7475051832328856,-1.9621122253476229
637.9000000000084,29.844434126807574,2.763878185435965,-1.9619465089878756
639.2000000000083,29.887125392002776,2.7816188438549525,-1.963186099462822
640.5000000000084,29.93035948134647,2.8001471705575556,-1.9633483212860297
641.8000000000084,29.97292503935399,2.819569709371641,-1.9645852720272157
643.1000000000084,30.016198722106093,2.840946481234435,-1.9658740540897928
644.4000000000085,30.05913763804771,2.859844509529839,-1.9658998593233252
645.7000000000085,30.10211492144069,2.881638620539584,-1.9658976608284509
647.0000000000085,30.14508992545154,2.902203548989998,-1.9670158981525039
648.3000000000085,30.187794447152267,2.924563246834024,-1.9672157614746668
649.6000000000085,30.231201111077567,2.949431163832195,-1.9686409036543298
650.9000000000085,30.27364287521833,2.9739929148021393,-1.9701510384079701
652.2000000000086,30.31673050421229,3.001339550478204,-1.9714888883095827
653.5000000000086,30.359496541969623,3.028446947238995,-1.9721772866128349
654.8000000000086,30.402523851660316,3.0560251604727227,-1.9728096357384797
656.1000000000087,30.44524325787493,3.089583252928876,-1.976049845455535
657.4000000000086,30.488232537121522,3.1235069529382695,-1.980409357694847
658.7000000000087,30.531188917252578,3.1565555582606937,-1.983955534305394
660.0000000000086,30.574127861039607,3.1932170936742224,-1.9845868495078065
661.3000000000087,30.616960811881317,3.2316140163044276,-1.9855587325291122
662.6000000000088,30.660261508772518,3.268605667785449,-1.9869473962623747
663.9000000000087,30.70283205871527,3.307697052342058,-1.9876323670180616
665.2000000000088,30.74590219542567,3.346397490800365,-1.9872768046878462
666.5000000000088,30.78880895965264,3.3898002351111294,-1.9873062089853075
667.8000000000088,30.831883183948417,3.430687460087886,-1.989768184581536
669.1000000000088,30.874772588401694,3.472140547220178,-1.9916376837920569
670.4000000000088,30.917725323105277,3.5151591174710584,-1.993465847318905
671.7000000000088,30.960702891953165,3.5626277564620086,-1.9946621992906102
673.0000000000089,31.003529532302526,3.6103821015406905,-1.9976419740953568
674.3000000000089,31.046509741766478,3.6584820702871417,-1.9993959882822767
675.6000000000089,31.08946771366201,3.7097585609829693,-2.002223855879281
676.900000000009,31.132484503043734,3.7587834698347176,-2.006915213502397
678.2000000000089,31.175633452471413,3.8053722372927727,-2.0093528690873472
679.500000000009,31.218703540614502,3.855461429124621,-2.0134672812822165
680.8000000000089,31.26173925663976,3.901958366260228,-2.0168773294985507
682.100000000009,31.304548773287706,3.9536862722830115,-2.0189501070754248
683.400000000009,31.347757240457334,4.001136503750288,-2.021189395619391
684.700000000009,31.39129017338241,4.057035273056221,-2.0226730189409494
686.0000000000091,31.434090247479443,4.110954510650001,-2.02592379591134
687.300000000009,31.47728336433648,4.168845583684368,-2.0297273155083864
688.6000000000091,31.520685147006954,4.229732640539672,-2.0339310270242885
689.9000000000091,31.563444036936197,4.287830399860438,-2.037074650630119
691.2000000000091,31.606490225301528,4.3499875871054305,-2.040158117199148
692.5000000000091,31.64953797705464,4.417013306688743,-2.0435761332273916
693.8000000000092,31.693158638284423,4.482806884071255,-2.0473284489495436
695.1000000000092,31.73611981070825,4.548594250383245,-2.052133426572347
696.4000000000092,31.779370325661382,4.621265918445004,-2.055315000220663
697.7000000000093,31.822529462508225,4.694240289874369,-2.0587897182706785
699.0000000000092,31.865476082258258,4.76807539090544,-2.0642589226594685
700.3000000000093,31.909203503961535,4.8477531316479086,-2.068803068316881
701.6000000000092,31.95221097981587,4.928254003922633,-2.073472699204581
702.9000000000093,31.995516098140854,5.0109558757593,-2.0794347852817987
704.2000000000094,32.038638880366435,5.099434816765433,-2.085795949582651
705.5000000000093,32.081884032761934,5.190924717630319,-2.093047953142653
706.8000000000094,32.12528192722052,5.289332855900772,-2.0999763553567234
708.1000000000093,32.16850689193055,5.382471910027561,-2.1051461254658967
709.4000000000094,32.21186069142499,5.486910871041468,-2.1096885636474956
710.7000000000094,32.25533121904709,5.590872993877434,-2.1164059158124413
712.0000000000094,32.29876953646276,5.701066309427091,-2.1247545370698475
713.3000000000094,32.34170033158681,5.815059332105504,-2.1331147954184466
714.6000000000095,32.3854143784187,5.937614426494347,-2.1438202679009732
715.9000000000095,32.42882841153521,6.0584183907333635,-2.1513428307275224
717.2000000000095,32.47203271335555,6.181857339287658,-2.156372814938482
718.5000000000095,32.51569644769641,6.3078661282688255,-2.1602815207025055
719.8000000000095,32.55926717406765,6.442143374577244,-2.1687416007957516
721.1000000000096,32.602642310933746,6.572201764834567,-2.1770425185298747
722.4000000000095,32.64525553108699,6.703554070988554,-2.190752912068227
723.7000000000096,32.68964138109556,6.838908742434196,-2.206348999604196
725.0000000000095,32.733320655822844,6.968520516287287,-2.2178620804380964
726.3000000000096,32.7765967450923,7.09716048573109,-2.2316291571563966
727.6000000000097,32.82032219643654,7.222044242637634,-2.2437440274686757
728.9000000000096,32.86375420888915,7.347568145961113,-2.2550406072228126
730.2000000000097,32.90723735133952,7.468284476984537,-2.2677433470041137
731.5000000000097,32.951022527610114,7.58673582698559,-2.2791071676691206
732.8000000000097,32.994650565941534,7.7065178179200045,-2.288996851239507
734.1000000000097,33.03797245656572,7.820741627096545,-2.301199788007925
735.4000000000098,33.08173981579627,7.938488758854111,-2.3127920786943097
736.7000000000098,33.12519231557305,8.052431326094728,-2.3262457259840206
738.0000000000098,33.16893546728843,8.165181355129265,-2.3386473313868676
739.3000000000098,33.21233438572635,8.275304509362606,-2.3523870852310305
740.6000000000098,33.25587427375468,8.385432655276926,-2.363830455218644
741.9000000000099,33.299677031228164,8.49046814592462,-2.3759862783406582
743.2000000000098,33.34293962702873,8.595863985800063,-2.391663322182326
744.5000000000099,33.386627923640106,8.698949099077353,-2.408158363946799
745.80000000001,33.43037507526303,8.794739818747363,-2.4271469976834363
747.1000000000099,33.47368409209258,8.887083531743613,-2.4423402148850886
748.40000000001,33.51734744305045,8.972315235375019,-2.4558322091034586
749.7000000000099,33.560919142440795,9.058647996332802,-2.471557250059038
751.00000000001,33.604704901682865,9.135076980871698,-2.4892050931278886
752.30000000001,33.64801830645802,9.200449907479715,-2.5050147551221467
753.60000000001,33.691493157571976,9.26247634512222,-2.5195754640914205
754.90000000001,33.734859040658435,9.314719872780891,-2.5373431173842587
756.20000000001,33.778574482626034,9.351203662156143,-2.5546831468181708
757.5000000000101,33.82194788465057,9.377172841477817,-2.571365797076881
758.8000000000101,33.865610808778655,9.390670204306089,-2.590386678025935
760.1000000000101,33.90920402112299,9.383249718108878,-2.605819067386251
761.4000000000101,33.95285159037262,9.361144478643784,-2.620874176004813
762.7000000000102,33.99629650160301,9.314177565079259,-2.639798087092493
764.0000000000101,34.039583223903506,9.236679766788876,-2.6570700860525918
765.3000000000102,34.08332091147771,9.120977195411387,-2.67127871802141
766.6000000000101,34.12678782000767,8.960004396845369,-2.6864861398376627
767.9000000000102,34.170291915812186,8.732433915618184,-2.7024557675809575
769.2000000000103,34.213289316471304,8.424951457321328,-2.7166138733435763
770.5000000000102,34.25678799131413,7.984192726022075,-2.730756414996663
771.8000000000103,34.29963182573672,7.3492835618151275,-2.743176558900535
773.1000000000103,34.34300978954683,6.30871379331753,-2.7552121599998403
774.4000000000103,34.38594921125639,5.063832549522553,-2.7609604996114236
775.7000000000103,34.42872515751754,4.338548158359313,-2.764955500924974
777.0000000000103,34.470758095340074,3.9377913502120427,-2.766280834985397
778.3000000000104,34.51435472592845,3.6990424518924616,-2.7662801279631193
779.6000000000104,34.55698190242003,3.561805072378177,-2.7662801239274173
780.9000000000104,34.600726557816095,3.4755459464472866,-2.766280134784437
782.2000000000104,34.64411239945933,3.428084961362116,-2.766289904840902
783.5000000000105,34.687627662342756,3.4057230886054306,-2.766693491888452
784.8000000000104,34.73088036520385,3.399695670081444,-2.767698249621893
786.1000000000105,34.774361138896644,3.3964266264629517,-2.7664137464826877
787.4000000000106,34.81770451029078,3.405702737465715,-2.7663596342040195
788.7000000000105,34.8614206095689,3.411087192639222,-2.7677646782177625
790.0000000000106,34.90440802570682,3.423842625855712,-2.76771987155912
791.3000000000105,34.94776018882724,3.4357840177817276,-2.766948440568751
792.6000000000106,34.991960492011444,3.446929706481018,-2.7677116745650174
793.9000000000106,35.03523839033807,3.4578456069694314,-2.7690629041770367
795.2000000000106,35.07873749294542,3.472672293930221,-2.7677228071219897
796.5000000000106,35.12231261693199,3.4864676492895694,-2.766348786520759
797.8000000000106,35.16593586198678,3.496051228255887,-2.766399751251717
799.1000000000107,35.20949080131835,3.514846888002593,-2.7663911525283202
800.4000000000107,35.25316342888468,3.5260557867864244,-2.7657858364598793
801.7000000000107,35.29664839620293,3.540369310016588,-2.7663987895749855
803.0000000000107,35.33998227816792,3.557587458571461,-2.766454052375771
804.3000000000108,35.38369434725489,3.5729559830101745,-2.767710505388751
805.6000000000107,35.42739954754331,3.5872802314041987,-2.767710148649534
806.9000000000108,35.47053491563422,3.6022659671751227,-2.767710156373291
808.2000000000107,35.51438760867117,3.6189850239625785,-2.7677114528809423
809.5000000000108,35.55796565482112,3.6353445746086126,-2.7687997699449336
810.8000000000109,35.60140684564283,3.6497188962426965,-2.7690297913826445
812.1000000000108,35.64520916324091,3.6656194847185666,-2.7680245076437417
813.4000000000109,35.68894141123754,3.67941300620525,-2.769030483245958
814.7000000000108,35.732591046843176,3.6952108338281913,-2.7678317242231167
816.0000000000109,35.77597064848049,3.7090695567534255,-2.767705444374748
817.3000000000109,35.81981736892312,3.725583834442259,-2.7691439849248294
818.6000000000109,35.86345160523516,3.7380827188339536,-2.769241063421093
819.900000000011,35.90692149572108,3.753690465655746,-2.7691397004623957
821.200000000011,35.95040490874705,3.769648670792018,-2.769133235153066
822.500000000011,35.99438299823506,3.78028329637042,-2.767998778115746
823.800000000011,36.038054799620646,3.7961146957614673,-2.7670747486052827
825.100000000011,36.081825907110975,3.808678338738448,-2.769691211009095
826.400000000011,36.12528060848305,3.8239012171312465,-2.770031829154257
827.7000000000111,36.169235952254944,3.834745563382407,-2.7715503236570065
829.0000000000111,36.2129214722459,3.848857323924305,-2.7704986168256314
830.3000000000111,36.25636127283775,3.8641804821453016,-2.7702398741294525
831.6000000000112,36.30001136450197,3.8787068744947395,-2.7702634138800075
832.9000000000111,36.34370500484955,3.891409975977853,-2.770746226120833
834.2000000000112,36.38721480049623,3.904190739190286,-2.7702310050248453
835.5000000000111,36.43108490804688,3.916883667420143,-2.77018923932745
836.8000000000112,36.47517457343942,3.932101075429933,-2.7717622284091394
838.1000000000112,36.518789465451746,3.9435794936104553,-2.7728065075228487
839.4000000000112,36.56256736144024,3.960585891969804,-2.7703606255320077
840.7000000000113,36.60622263631862,3.9719785622941712,-2.7704521282219234
842.0000000000113,36.65010897595949,3.9834205201822392,-2.7719789942764175
843.3000000000113,36.694001009969654,3.994730053316481,-2.7731275869150513
844.6000000000113,36.73766291088122,4.008133354942249,-2.7724655498909256
845.9000000000113,36.781656664236294,4.02058350818208,-2.7702627834379454
847.2000000000113,36.82525052134284,4.032325619645805,-2.7658626435700544
848.5000000000114,36.869473475103796,4.0382570748378495,-2.7646442429056246
849.8000000000113,36.913296088724515,4.055596806059077,-2.7656300930295608
851.1000000000114,36.956937596309146,4.074301007873103,-2.7659594098631866
852.4000000000115,37.0007893611951,4.085558585416678,-2.765959578188788
853.7000000000114,37.04477528150156,4.103968237331612,-2.7658520290173594
855.0000000000115,37.08851565407394,4.1213853068936075,-2.7659622770437204
856.3000000000114,37.13224156305557,4.1383945786878575,-2.765960152725751
857.6000000000115,37.17634350037256,4.153837810362,-2.7659678842476145
858.9000000000115,37.22047462866664,4.171500130782519,-2.764638857360381
860.2000000000115,37.26384999655241,4.187668831721669,-2.764851138930831
861.5000000000116,37.30838899434577,4.20881729283262,-2.7681262813175618
862.8000000000116,37.35227070197145,4.222817546720352,-2.769810938118873
864.1000000000116,37.39614333695038,4.24055900792607,-2.772544098092146
865.4000000000116,37.440404188481395,4.255572352983749,-2.7738721234326964
866.7000000000116,37.483839530169554,4.270224518176783,-2.7738539225974117
868.0000000000116,37.52811771187875,4.284571177012242,-2.773910577571257
869.3000000000117,37.57199217590273,4.303874019665434,-2.7738531070028527
870.6000000000117,37.61597065563504,4.321337071742513,-2.775022668653285
871.9000000000117,37.66009512164612,4.3414649945087715,-2.775280387676085
873.2000000000118,37.704006243696035,4.35491947853111,-2.7749152963212653
874.5000000000117,37.74790351256671,4.370338410332788,-2.7704937793598017
875.8000000000118,37.79181598899757,4.387524534522571,-2.7684377899266606
877.1000000000117,37.83583196172872,4.4068555322516,-2.768260380570524
878.4000000000118,37.87979191787171,4.4248834102951005,-2.7682601789236863
879.7000000000118,37.923787954011985,4.43983857394167,-2.768252005318499
881.0000000000118,37.967756228607286,4.459585484745806,-2.7679324418270994
882.3000000000119,38.011698141811316,4.476646480858119,-2.769584714899354
883.6000000000118,38.055661039348834,4.495716195528166,-2.769461451617179
884.9000000000119,38.09978115066252,4.512335117061522,-2.7688019954102803
886.2000000000119,38.14358085821583,4.528697179585018,-2.7674826453919703
887.5000000000119,38.18754499263697,4.547584189111419,-2.767692738071015
888.8000000000119,38.23157290001503,4.561962185636425,-2.770223318814622
890.100000000012,38.275571421622956,4.580125704466644,-2.770236369123379
891.0000000000119,38.30601636890027,4.590554901948029,-2.7706273136913087