File: 01_Data/Nylon_Carpet_Low_Pile/STA/N2/30K_min/Nylon_Carpet_Low_Pile_STA_N2_30KData_220105_R1.csv
##Temp./Â°C,Time/min,DSC/(mW/mg),Mass loss/mg
49.0,10.516320613736367,-0.9029595372693,-0.02072733637328117
50.100000000000016,10.71619298509904,-0.7520988204956502,-0.018590648799649223
51.20000000000003,10.840791112687382,-0.6399534532735964,-0.0177844992222429
52.30000000000005,10.938670371137867,-0.5440010601824322,-0.018488480784315975
53.40000000000006,11.02287748597931,-0.4608552957004183,-0.019321927399246874
54.50000000000008,11.096881331786827,-0.38682167278992535,-0.0185983356175754
55.600000000000094,11.164254559590907,-0.32043600394055327,-0.017646514946778602
56.70000000000011,11.227292618882199,-0.2589465736541068,-0.017030525356136472
57.800000000000125,11.287069878549229,-0.20156539210425678,-0.018599513966050196
58.90000000000014,11.34328234923493,-0.1470063247076555,-0.01794361376362552
60.000000000000156,11.397234307745732,-0.09628734455079709,-0.01881509028525219
61.10000000000017,11.449133066678321,-0.048798943960008945,-0.018950265907585084
62.20000000000019,11.499001453765226,-0.002287570885318067,-0.018592075984263268
63.3000000000002,11.548320808791926,0.04128520822088172,-0.018886514321987846
64.40000000000022,11.594906316783991,0.08088284510370411,-0.017803458072743972
65.50000000000023,11.642383760215859,0.11976220458714452,-0.01956385595517407
66.60000000000025,11.688051216464038,0.1591019091398827,-0.01947982331811904
67.70000000000027,11.732588624060039,0.19394205894599145,-0.019224303679588495
68.80000000000028,11.776817056567019,0.23018951269457955,-0.018436056697263226
69.90000000000029,11.820797512616359,0.2621814423006896,-0.018856353558862615
71.00000000000031,11.863335955198433,0.2953897994015467,-0.017543336287503486
72.10000000000034,11.90622126733457,0.325379611145886,-0.019287795508796002
73.20000000000034,11.948456466617422,0.35460705465518294,-0.019554601612045808
74.30000000000035,11.990149751697443,0.38181609076063844,-0.01964104047609716
75.40000000000038,12.031205997728298,0.40887279552598926,-0.020362270621904877
76.5000000000004,12.071987174243812,0.43505316897233504,-0.019027135780831372
77.6000000000004,12.112449673222939,0.4596228940637832,-0.019504013879701354
78.70000000000041,12.15258443938643,0.4833203976593808,-0.018789830448948663
79.80000000000044,12.193217181846148,0.5074744325386011,-0.018293779572585933
80.90000000000046,12.23312961484766,0.529304621316054,-0.019271185246948264
82.00000000000047,12.272543043147122,0.551432052515351,-0.02160773529319293
83.10000000000048,12.311407652598964,0.5716859535163266,-0.021331836946961502
84.2000000000005,12.351477436842577,0.5925855654912809,-0.020219926709999392
85.30000000000052,12.389759369706711,0.6132061580075724,-0.021119151396594482
86.40000000000053,12.428824294461954,0.6323874475941502,-0.019835721296079356
87.50000000000054,12.467766295957222,0.6521060756147409,-0.019978807076500793
88.60000000000056,12.505916096727889,0.6695796061065752,-0.020420517626630108
89.70000000000059,12.544351580647973,0.6880951257214127,-0.02158096931530995
90.8000000000006,12.582485082026778,0.7061154341367171,-0.021109599740229967
91.9000000000006,12.620809829962433,0.7234482719038214,-0.02044508861382255
93.00000000000063,12.65841863794428,0.7395118990645251,-0.02159056596420239
94.10000000000065,12.696385665679335,0.7574838350629141,-0.020118992346763065
95.20000000000066,12.734282297690434,0.7743695769645781,-0.02126494502642462
96.30000000000067,12.771704172339446,0.7926831099694188,-0.02017612869104024
97.40000000000069,12.809186179748066,0.8080510007009848,-0.020205217973297884
98.50000000000071,12.846674534541187,0.8246944249465502,-0.021377952644677123
99.60000000000072,12.884003093944958,0.8405574842046777,-0.021146556885856427
100.70000000000073,12.92127563620891,0.8553448810896572,-0.020945179324601604
101.80000000000075,12.958924119922752,0.8708570329176113,-0.021593996633809454
102.90000000000077,12.995939135408388,0.8856377868735927,-0.021512955221699492
104.00000000000078,13.033103268913663,0.8995723595266674,-0.022427360221547232
105.10000000000079,13.070269359337663,0.9125194783876434,-0.022810273035765327
106.20000000000081,13.107579144161308,0.9264075616218793,-0.02141835159227501
107.30000000000084,13.144310146325092,0.9398640074958626,-0.022814936676470055
108.40000000000084,13.181814507912163,0.9520570005132485,-0.022817007892909302
109.50000000000085,13.218653528392437,0.9642530248384581,-0.023833098619976845
110.60000000000088,13.255616184372721,0.976986890292098,-0.024129553975898332
111.7000000000009,13.29284071798903,0.98893022055885,-0.024375509297139608
112.8000000000009,13.329447388421999,0.9995784733283243,-0.024131135614415378
113.90000000000092,13.36606715533996,1.0102252561751979,-0.02417757189023728
115.00000000000094,13.403195285624486,1.0219163131002806,-0.023798162065747697
116.10000000000096,13.4399647425427,1.0343742898629835,-0.023156217621439268
117.20000000000097,13.476767666751067,1.0440841118960187,-0.02414405532764352
118.30000000000098,13.513574898631376,1.0551077548487924,-0.02413028011642382
119.400000000001,13.550100361258076,1.066134936277273,-0.024457061125487733
120.50000000000102,13.586474739596357,1.0763647463457517,-0.024781430944736726
121.60000000000103,13.62310898816261,1.0864008832339545,-0.024098801244458734
122.70000000000104,13.660193424582953,1.099036715257689,-0.024130060095187922
123.80000000000106,13.696041740476533,1.108248149061873,-0.02413069822439784
124.90000000000109,13.732324422016315,1.1176310867238235,-0.024053676910098964
126.0000000000011,13.768837414637268,1.1283155706953665,-0.02544994978064441
127.1000000000011,13.80490237570605,1.1397001720053666,-0.026813399076137223
128.20000000000113,13.84036801057814,1.149921062896758,-0.02676885895142256
129.30000000000115,13.877155270392317,1.1608111703678843,-0.026770061140860335
130.40000000000117,13.913488659291978,1.174006854376172,-0.026770262913208498
131.50000000000117,13.948716795667828,1.184448274305353,-0.026762826778496063
132.6000000000012,13.985024177358998,1.1953584788757627,-0.025459978314159137
133.7000000000012,14.020552770396478,1.2076264865816415,-0.026758495130762228
134.8000000000012,14.056529432926155,1.219687335863755,-0.026757742624021752
135.90000000000123,14.092586053171075,1.2318342086502487,-0.028122771568485305
137.00000000000125,14.127778928945583,1.2429791220032727,-0.02808073742730155
138.10000000000127,14.163281440307722,1.2558542268943653,-0.028080173715033574
139.2000000000013,14.199040447501476,1.266467126976941,-0.028080174952273218
140.3000000000013,14.23480110666301,1.2797411268736874,-0.028080175000018137
141.4000000000013,14.269582520175677,1.2927460326897409,-0.028080174998917684
142.50000000000134,14.30519570657626,1.3039493469074883,-0.028080174172554706
143.60000000000133,14.340807409101641,1.3184138154696265,-0.028080150365694223
144.70000000000135,14.375245172932658,1.332645360422799,-0.028087764524825864
145.80000000000138,14.41134342053607,1.3469749693307478,-0.028403799307797684
146.9000000000014,14.446049291727352,1.3619386415156916,-0.028409983543694395
148.00000000000142,14.481312631560415,1.3763066804129562,-0.028409813336032208
149.10000000000142,14.516316576145927,1.392019698305521,-0.028407191107887364
150.20000000000144,14.55130023737817,1.4092665296817009,-0.029096218551751818
151.30000000000146,14.586497524895126,1.427926293345995,-0.029720884098559885
152.40000000000146,14.621681055640847,1.4466805056849799,-0.02967517088997962
153.50000000000148,14.656437581306326,1.4656701537805918,-0.031027931292001654
154.6000000000015,14.691122068912277,1.4875764224556272,-0.03104002027280739
155.70000000000152,14.72592416888546,1.5117955716962372,-0.03103984601881482
156.80000000000155,14.760422292340154,1.5351251448610082,-0.031039844980560893
157.90000000000154,14.795734563132399,1.5607194020486674,-0.03103984499990453
159.00000000000156,14.83049073419772,1.5880572178710368,-0.031039845000038646
160.1000000000016,14.865164131630483,1.615495944071225,-0.031039845008455913
161.20000000000158,14.900061628133798,1.6413422100077193,-0.031039844552284812
162.3000000000016,14.934687799648254,1.6635518647502847,-0.031039776448505307
163.40000000000163,14.969402650586995,1.6837835076588838,-0.031045136416568475
164.50000000000165,15.00407282586672,1.6946628195141296,-0.033072318557520575
165.60000000000167,15.038446649802525,1.6972719549201563,-0.033018593739222446
166.70000000000167,15.073212619827272,1.6980137536979396,-0.03301995244749545
167.8000000000017,15.108199416580131,1.6910715251948023,-0.03299927916615619
168.9000000000017,15.142353396546532,1.6844266286104903,-0.033345762715415894
170.0000000000017,15.176804114247606,1.6778182030512603,-0.033350026335741134
171.10000000000173,15.21115681462088,1.6705322864901408,-0.03335007080333341
172.20000000000175,15.245420764145683,1.6641819044918025,-0.03335007000011814
173.30000000000177,15.280126231102606,1.6591248902202975,-0.03335007063843065
174.4000000000018,15.31462698020815,1.6562704889580009,-0.03335006211578495
175.5000000000018,15.348804057118674,1.6576300117934855,-0.03334450004368428
176.6000000000018,15.383026574444775,1.6578995215442558,-0.034695399456770026
177.70000000000184,15.41732779220091,1.6633638366983048,-0.034660494829801713
178.80000000000183,15.451359446202275,1.6666535740060426,-0.03466006371910968
179.90000000000185,15.485231859908415,1.6730401555917607,-0.034660068758271656
181.00000000000188,15.519725974267773,1.6809014298182186,-0.03466008026431133
182.1000000000019,15.553789912115965,1.6895559801490334,-0.03466997405895267
183.20000000000192,15.587739118917847,1.6983048055679948,-0.03587516748263209
184.30000000000192,15.621727083808649,1.7071895051664838,-0.035969325040370315
185.40000000000194,15.655571312675278,1.7144386965688465,-0.035978054799714165
186.50000000000196,15.689012469502615,1.7267664370307907,-0.034606114368954444
187.60000000000196,15.723272427453402,1.735580916998082,-0.034660126442759065
188.70000000000198,15.757294973348571,1.7459706830329789,-0.0346580888897261
189.800000000002,15.791251145414382,1.75712291290799,-0.03501612711752866
190.90000000000202,15.825131896317828,1.7667006958443,-0.03596984068971043
192.00000000000205,15.858792225411023,1.7778348671927273,-0.03596976793624318
193.10000000000204,15.892514984408576,1.7891605309258796,-0.03596984064661335
194.20000000000206,15.926283621138275,1.8002945254285483,-0.03596984000322667
195.3000000000021,15.960209963493153,1.8123245738608527,-0.03596983999414416
196.40000000000208,15.993922456921997,1.8230401309311668,-0.03596984667773295
197.5000000000021,16.02776681988516,1.836788439518378,-0.03596947856628763
198.60000000000213,16.061371721361446,1.8486171944091325,-0.036428132974604566
199.70000000000215,16.09504930811326,1.8612340243115213,-0.03729681304565258
200.80000000000217,16.12862760508162,1.8736823026076235,-0.03728534392420979
201.90000000000217,16.162254973011816,1.887956264684094,-0.03799028678403982
203.0000000000022,16.195942265118806,1.9004137704749402,-0.03917025551744224
204.1000000000022,16.22974566172954,1.9153271354613361,-0.03926913536818777
205.2000000000022,16.263490048180085,1.9304948768715426,-0.03931168546205477
206.30000000000223,16.29681663938207,1.9464170121558715,-0.03795912647054411
207.40000000000225,16.330604811137043,1.965646392684761,-0.03794963454550704
208.50000000000227,16.364206930631216,1.9853308918197665,-0.03794973122945233
209.6000000000023,16.397703455621773,2.010050701110075,-0.037957885585628404
210.7000000000023,16.431401664519154,2.0425672227967486,-0.038273615233825
211.8000000000023,16.46468831262877,2.0826289862239835,-0.03827785663285166
212.90000000000234,16.498456313019936,2.14014106218885,-0.039369454752799626
214.00000000000233,16.532302668498833,2.217271641606635,-0.03926838281911316
215.10000000000235,16.565525726095018,2.3052579485939457,-0.039269962178307694
216.20000000000238,16.599305280322515,2.412105481647308,-0.03926995957041779
217.3000000000024,16.632852621685895,2.5332648796953805,-0.03927000827419658
218.40000000000242,16.666733210658276,2.6596827494165094,-0.03927080692227669
219.50000000000242,16.700000000000077,2.7692400000002126,-0.03963548582454646
220.60000000000244,16.73364775985288,2.8419266442689977,-0.03959959404543234
221.70000000000246,16.767381885713917,2.855826204039608,-0.039599958723974815
222.80000000000246,16.80142552031176,2.8099296132465756,-0.03959996048699921
223.90000000000248,16.83484888475067,2.734279011750571,-0.039599934524249925
225.0000000000025,16.868568410239497,2.6507119493681857,-0.039598879489807004
226.10000000000252,16.901890276169603,2.571895958937486,-0.03990332177533418
227.20000000000255,16.93557807121288,2.4949623685691855,-0.04026228576612123
228.30000000000254,16.9687604938517,2.427796496158392,-0.04023888918935281
229.40000000000256,17.00241992745204,2.366295877495951,-0.04059212191823924
230.5000000000026,17.035362944248597,2.3165196180274408,-0.04066183948250135
231.60000000000258,17.06908427842084,2.2753469726830127,-0.04189583106142525
232.7000000000026,17.102155818274547,2.2430822595401567,-0.041829603048194386
233.80000000000263,17.135697585680973,2.216066896233786,-0.04255242781162849
234.90000000000265,17.169009397366747,2.197540989122974,-0.0425595918347641
236.00000000000267,17.202527376885026,2.1851579432328867,-0.04253431400965635
237.10000000000267,17.235925198415373,2.1748166144801053,-0.04392845696842684
238.2000000000027,17.268678296108895,2.1675284636535643,-0.04387012947134039
239.3000000000027,17.302066009990746,2.162952791850681,-0.04258602706275827
240.4000000000027,17.33512927572504,2.160701073256852,-0.042529265743114664
241.50000000000273,17.36858023041589,2.1594062269012535,-0.043868256799791006
242.60000000000275,17.401541093888227,2.1606056387583394,-0.04388035968900006
243.70000000000277,17.434833977114547,2.162825576054887,-0.04388010363917072
244.8000000000028,17.467965024181108,2.1664703678436994,-0.043880104881320214
245.9000000000028,17.501367018712596,2.1675334880868538,-0.043880099110827686
247.0000000000028,17.534557630844656,2.1717092773625684,-0.04388119120155487
248.10000000000284,17.567896970847983,2.176181105763716,-0.04382906410232579
249.20000000000283,17.601055508779158,2.1805523170633627,-0.04486759519000039
250.30000000000285,17.634207745982046,2.185866509556633,-0.0448703184596404
251.40000000000288,17.667692893909003,2.190585333317209,-0.044394525927869743
252.5000000000029,17.70086588583032,2.1959905022508384,-0.043543118941892445
253.60000000000292,17.734173511735897,2.1998692921345318,-0.043675808423010665
254.70000000000292,17.767193959328864,2.20518553989234,-0.043871370560040646
255.80000000000294,17.80015031361646,2.2084679192131498,-0.04386987590671332
256.90000000000293,17.833507297458063,2.214735569270307,-0.04386998642426754
258.00000000000296,17.86679900034437,2.219597368336851,-0.04386255696603225
259.100000000003,17.900122110674495,2.227056580846444,-0.04482203022036746
260.200000000003,17.933244614845464,2.2313415334897355,-0.04620510144531842
261.300000000003,17.96661847893273,2.237331639112044,-0.04614796396035192
262.40000000000305,17.99951844438306,2.2409180909940454,-0.046509406543314036
263.50000000000307,18.032855900681767,2.245303472161597,-0.046510052415479564
264.6000000000031,18.0657139961609,2.250340227097048,-0.04651681170262467
265.7000000000031,18.098859810664493,2.256166617151582,-0.04714969497701205
266.8000000000031,18.13162461370238,2.261263517892326,-0.04716347692494516
267.9000000000031,18.16543632836448,2.2668897809122233,-0.04820555222979728
269.0000000000031,18.198560736199305,2.269745149563614,-0.048480343247112145
270.10000000000315,18.232103312211624,2.2756458246257343,-0.04846908631151159
271.2000000000032,18.265115681884495,2.279750133094005,-0.04916457224406212
272.30000000000314,18.298238557476562,2.284350700450148,-0.049139898015970296
273.40000000000316,18.33136452783669,2.290321050129752,-0.04914033510252214
274.5000000000032,18.364636305805696,2.293610740367746,-0.049091210857508116
275.6000000000032,18.39778954124351,2.2989138043140946,-0.05045210337638162
276.70000000000323,18.430178950059247,2.302831876398071,-0.04916806376260219
277.80000000000325,18.464121246292276,2.306417214689641,-0.04913988450022355
278.9000000000033,18.497447677107026,2.3117605127333105,-0.04913979428143023
280.0000000000033,18.530562872298592,2.316465552049195,-0.049138955431017095
281.1000000000033,18.563965184709712,2.3202754649923496,-0.05055988288892177
282.20000000000334,18.59732426086079,2.325481992000528,-0.050459162896120624
283.30000000000337,18.63041248360001,2.3301195839034206,-0.05046013779189673
284.40000000000333,18.663717510531136,2.332951475758902,-0.050460138161048995
285.50000000000335,18.697062613133546,2.3375756142109196,-0.05046027382745688
286.6000000000034,18.730267546193087,2.3409586997283323,-0.050461324951799114
287.7000000000034,18.763577559319643,2.344554129732966,-0.051672606497140006
288.8000000000034,18.79688840981873,2.3471920690816694,-0.05206033901800833
289.9000000000034,18.830091852841697,2.353999104140582,-0.05308870183845382
291.0000000000034,18.863098206976954,2.356795659310533,-0.0531184885465672
292.10000000000343,18.896741963815778,2.3611569893494786,-0.05438223190750291
293.20000000000346,18.92999968178333,2.3646199460352118,-0.05449055108435408
294.3000000000035,18.963440775918183,2.369875553116341,-0.05308991898304383
295.4000000000035,18.99652384534766,2.371665277606721,-0.0530898489909335
296.5000000000035,19.030182553847062,2.3764935738833146,-0.05308318087449315
297.60000000000355,19.063291365917813,2.3785004918457155,-0.05406798416139047
298.70000000000357,19.09654730830737,2.3833451488270074,-0.05434586636049765
299.8000000000036,19.13006000227139,2.38672494314534,-0.05571961390737323
300.9000000000036,19.163229115310717,2.3893523329894255,-0.05572034667402059
302.0000000000036,19.196752218163294,2.3932145389537043,-0.05572379694306928
303.1000000000036,19.230029637917184,2.397602409510961,-0.05525771591887718
304.2000000000036,19.263446807262707,2.401500559641822,-0.056260889295666416
305.30000000000365,19.296779759832873,2.4039111335382466,-0.05637022940280989
306.4000000000037,19.330305919819388,2.4060715719649504,-0.056371369589301334
307.5000000000037,19.363566449365447,2.410333131960636,-0.05766524563977704
308.60000000000366,19.396988270238037,2.4149196835394986,-0.057690453520933715
309.7000000000037,19.429969751765043,2.41808152489497,-0.05769017495360451
310.8000000000037,19.463436630662557,2.4216046377564098,-0.05769015222937979
311.90000000000373,19.49702893224783,2.425432637281489,-0.05769183623228402
313.00000000000375,19.530615331272227,2.4285204163241327,-0.0590416689206843
314.1000000000038,19.563875076495876,2.4341497229856266,-0.05900821649042287
315.2000000000038,19.597292349173312,2.436162413143741,-0.05901026038751134
316.3000000000038,19.6307551806679,2.439591894774072,-0.05901483914212502
317.40000000000384,19.663943308097572,2.4437797842541533,-0.06029593298708624
318.5000000000038,19.697554046678306,2.4484689794870578,-0.06032007632866998
319.60000000000383,19.731342163681244,2.453018058156934,-0.06032034763501448
320.70000000000385,19.76450550972633,2.4583992019350758,-0.06023613924078708
321.8000000000039,19.79796349697617,2.4615003053994173,-0.06270806592705958
322.9000000000039,19.83118731198621,2.465638438032439,-0.06340231203711966
324.0000000000039,19.86497890666387,2.47099471836309,-0.06428014963130257
325.10000000000394,19.89819000369697,2.474459922490928,-0.06509048490600922
326.2000000000039,19.9319862758782,2.4794237537525268,-0.0655903991324367
327.30000000000393,19.965436712347195,2.484079112937253,-0.0655860523816667
328.40000000000396,19.999115169729205,2.488212794734875,-0.06617648692654132
329.500000000004,20.03256997419436,2.4919211176011404,-0.06692686939656145
330.600000000004,20.066006229249922,2.496796862640429,-0.06818052280931841
331.700000000004,20.099627345188203,2.5011445099384044,-0.06821849958023485
332.80000000000405,20.133119278380136,2.5073281897693183,-0.06940431922668022
333.90000000000407,20.166662353636784,2.5147310259826074,-0.06993068163497007
335.0000000000041,20.200282391784054,2.519912185636018,-0.07086190375648282
336.10000000000406,20.23393563707564,2.526354567302751,-0.0722111757190671
337.2000000000041,20.26743251861219,2.533312078754047,-0.0736199152119914
338.3000000000041,20.30117642130783,2.5410166808263743,-0.07467783397056049
339.4000000000041,20.334647990185115,2.5467072092166054,-0.07537490415184323
340.50000000000415,20.368405839080914,2.553839089332321,-0.07728119462862626
341.6000000000042,20.40187557423763,2.5618201261567854,-0.07840627161306735
342.7000000000042,20.435711727796704,2.571618883968394,-0.07939422388979533
343.80000000000416,20.469345675805712,2.5794914421282646,-0.0805797042558778
344.9000000000042,20.50318579816301,2.586269202132767,-0.0828720010429107
346.0000000000042,20.536739503115797,2.5960469120408227,-0.08524920175845363
347.10000000000423,20.57081000614453,2.607691981934863,-0.08698777209784359
348.20000000000425,20.604545702988762,2.6160385379457147,-0.08841611457529996
349.3000000000043,20.637959405461512,2.624231490104161,-0.08991231213666584
350.4000000000043,20.671598317524754,2.634803954270839,-0.09161774677495416
351.5000000000043,20.705586324404422,2.645667553931784,-0.09481086282486029
352.60000000000434,20.73948558253442,2.6568426244210235,-0.09705082693301659
353.7000000000043,20.773011444538614,2.667680458106641,-0.10012844530514586
354.80000000000433,20.80674821876681,2.6803361868613154,-0.10386470906847212
355.90000000000435,20.84046443245213,2.693306889071943,-0.10646156206074009
357.0000000000044,20.87479046300644,2.7067697021123966,-0.1084601492652224
358.1000000000044,20.90826567432873,2.7197822543624217,-0.11242282313930474
359.2000000000044,20.941946138909845,2.735350270154367,-0.1159195772090027
360.30000000000445,20.97610018943156,2.751216502725014,-0.11908964496648933
361.4000000000044,21.00969468788231,2.76501271056104,-0.12262056135679256
362.50000000000443,21.04371251230316,2.781409082410942,-0.12694300086277766
363.60000000000446,21.077746115362764,2.7987577013264513,-0.13218403752461727
364.7000000000045,21.11153114260006,2.816336360541582,-0.13762636098983094
365.8000000000045,21.14551006792958,2.834244357989868,-0.14263684118659414
366.9000000000045,21.179303192429174,2.8544837885910366,-0.14691488194089874
368.00000000000455,21.21318699020024,2.874217371496763,-0.15188190845613558
369.10000000000457,21.24703005011198,2.896481751049702,-0.1571382806034891
370.2000000000046,21.28118343361047,2.9158694056141963,-0.16271051720716123
371.30000000000456,21.31526863153242,2.9381982397026984,-0.16883973136665986
372.4000000000046,21.349367571848735,2.9617617962638483,-0.17516412714974017
373.5000000000046,21.383303281479535,2.984670668685362,-0.18178612843270514
374.6000000000046,21.41710144413897,3.008036173593278,-0.1895589855842017
375.70000000000465,21.451064912467544,3.0304893289061674,-0.1951935072512212
376.8000000000047,21.485158665258687,3.057469522642247,-0.2021491215719391
377.9000000000047,21.519395735242874,3.0841956626879123,-0.21098344016223303
379.00000000000466,21.553251346592994,3.1082230865910536,-0.21854413187850819
380.1000000000047,21.587194420204465,3.1348685360433515,-0.2282444649680455
381.2000000000047,21.621368479562566,3.1639714441080358,-0.23746229388393347
382.30000000000473,21.65537128535665,3.189980733809995,-0.24705304400428663
383.40000000000475,21.689531526422293,3.2166930816842445,-0.25634115610863173
384.5000000000048,21.723657537483188,3.247575447279595,-0.26578253292577214
385.6000000000048,21.757890923436435,3.2763162115498763,-0.27611485612278397
386.7000000000048,21.791775833776715,3.303463991455464,-0.2867860928504373
387.80000000000484,21.8260651766268,3.3352700932191484,-0.298387707488728
388.9000000000048,21.860060776017765,3.366875725140421,-0.3097711714383493
390.00000000000483,21.894412471964955,3.3950647444770947,-0.32150937330630924
391.10000000000485,21.928478214212618,3.428505215360384,-0.33235696038566775
392.2000000000049,21.96271842663672,3.461440928380391,-0.3443783511980101
393.3000000000049,21.99707836630145,3.4947791432221766,-0.3581785353820113
394.4000000000049,22.031140806749498,3.5273191093455227,-0.3731897833116937
395.50000000000495,22.065375510484152,3.5629017474828077,-0.3876887116821175
396.6000000000049,22.099474375596706,3.5989414535011695,-0.40285178357824636
397.70000000000493,22.1336323251277,3.6354448645431727,-0.41720183431507873
398.80000000000496,22.168195778864195,3.6733118642228924,-0.4325589975142523
399.900000000005,22.20234351638344,3.711000946588285,-0.4491811122772402
401.000000000005,22.236592438723644,3.750726893000274,-0.46592156060450396
402.100000000005,22.271035149709313,3.789289601227864,-0.48372647452309225
403.20000000000505,22.305363229347794,3.830538847993781,-0.5021131503278271
404.30000000000507,22.339906116486446,3.871469033797215,-0.5216141465126198
405.4000000000051,22.373858721106693,3.9127385831390242,-0.5406866122144924
406.50000000000506,22.40843835395934,3.9558899454805743,-0.560723902676874
407.6000000000051,22.442769183567535,3.998778400526106,-0.5809798708751202
408.7000000000051,22.477212219536906,4.040269059735394,-0.6026993492544062
409.8000000000051,22.511422369688326,4.083270652905198,-0.6254567873374133
410.90000000000515,22.545730771329826,4.125563503162154,-0.6495916227931424
412.0000000000052,22.580126899295728,4.1670228341373,-0.6738880309136608
413.1000000000052,22.61470788525319,4.206604373646349,-0.6980166067000995
414.20000000000516,22.649428539417734,4.24539613016129,-0.7234168274150607
415.3000000000052,22.683859100207478,4.28206515051808,-0.7498615629901435
416.4000000000052,22.718246271439558,4.317829802486318,-0.7773913690628032
417.50000000000523,22.752653675168453,4.347364287557189,-0.8056956482805582
418.60000000000525,22.787446052748567,4.3757378516987595,-0.8353187649265732
419.7000000000053,22.821929217192938,4.4013929554143285,-0.8660786815962904
420.8000000000053,22.856265478497807,4.421759254189956,-0.8961804078802627
421.9000000000053,22.890652447591425,4.434693505833917,-0.9251102804982745
423.00000000000534,22.925491992918204,4.443570262427958,-0.9558092470604871
424.1000000000053,22.95999969483565,4.4457100201011865,-0.9881754737573782
425.20000000000533,22.99428159567787,4.437501322014841,-1.021455495326708
426.30000000000535,23.028867287813828,4.421107876268985,-1.0544535509309578
427.4000000000054,23.063460018818546,4.394800772631679,-1.0876234677781786
428.5000000000054,23.098053058402677,4.356240538919246,-1.121220755860545
429.6000000000054,23.13206543711404,4.309616859165824,-1.151494641484787
430.70000000000545,23.16717130617058,4.245557358403164,-1.182947872797652
431.8000000000054,23.20165035585231,4.170112320797628,-1.2140681362658783
432.90000000000543,23.236389370225787,4.086392095627682,-1.2451693147440581
434.00000000000546,23.270883923676084,3.9915595278341027,-1.274262013937006
435.1000000000055,23.305399448212523,3.8908093140084743,-1.301963605520799
436.2000000000055,23.339903524811252,3.7821421463306244,-1.3292161594658665
437.3000000000055,23.37410355854996,3.6743822531845565,-1.3530828019412624
438.40000000000555,23.409085733806954,3.564508157410359,-1.3766244233779874
439.50000000000557,23.443435889835772,3.459396688964193,-1.3984253076449726
440.6000000000056,23.47810429512902,3.358936554355164,-1.4187852371596463
441.70000000000556,23.51232150671062,3.2677581450001103,-1.4373895107746915
442.8000000000056,23.54672974383382,3.1844998510570828,-1.4547166752989655
443.9000000000056,23.58163599766577,3.110874406021219,-1.4711323744594615
445.0000000000056,23.61591297679346,3.0450462785525962,-1.4849825300656057
446.10000000000565,23.650118912692307,2.9939064963118414,-1.4981538660548366
447.2000000000057,23.684756229012965,2.9438460355649636,-1.510865689186156
448.3000000000057,23.71946679615791,2.903591317321168,-1.5227952171206383
449.40000000000566,23.754228030319688,2.8705399417927784,-1.5339512774610107
450.5000000000057,23.788456557432223,2.843416530948158,-1.5457518614828514
451.6000000000057,23.82269716512697,2.8204003760565035,-1.556295945369306
452.70000000000573,23.858034112896974,2.8015195709983827,-1.5668994424381086
453.80000000000575,23.89240172451943,2.783723757155118,-1.5763751555408176
454.9000000000058,23.927001922456448,2.7718469044300797,-1.585472436518848
456.0000000000058,23.961773301959088,2.7604697690368396,-1.5950439408284582
457.1000000000058,23.99627561522818,2.749695766011836,-1.6050006928488707
458.20000000000584,24.0310028693287,2.74207273797181,-1.6149355703077437
459.3000000000058,24.065887110356687,2.737719450972142,-1.6256676649927
460.40000000000583,24.100620153811718,2.7327304087925195,-1.6354783614458284
461.50000000000585,24.135139708843194,2.7299670904472433,-1.6448071089874592
462.6000000000059,24.170123554172914,2.7268482822417153,-1.6546567543255142
463.7000000000059,24.20490520886788,2.725639769151837,-1.66301046411643
464.8000000000059,24.239483648403024,2.725554459663389,-1.672786698132804
465.90000000000595,24.274193759087222,2.7248980107476624,-1.6825512019213722
467.0000000000059,24.309113997430295,2.7256079893860314,-1.692363341297355
468.10000000000593,24.3439616811203,2.7260356271223296,-1.7032585278839671
469.20000000000596,24.37873848181136,2.72836008578132,-1.7135872148850293
470.300000000006,24.413787633418632,2.728337338697031,-1.72277073868351
471.400000000006,24.448886325106063,2.7276344970845203,-1.732764194193182
472.500000000006,24.483477031108418,2.7308486149239815,-1.7425016452626285
473.60000000000605,24.518825317470835,2.7312775794029815,-1.7517048380546272
474.70000000000607,24.553485589535885,2.7336849109913124,-1.7620487493121781
475.8000000000061,24.588460509815025,2.7316016952406446,-1.7730127431432519
476.90000000000606,24.623465985559807,2.7326182684662137,-1.7835855261476645
478.0000000000061,24.65830578454298,2.73197643349831,-1.7935004215644756
479.1000000000061,24.693391611287577,2.7294257473842003,-1.8032938157750493
480.2000000000061,24.72847440953611,2.7298815131605174,-1.8141247226370143
481.30000000000615,24.763537516814846,2.7283921507436752,-1.825111761234926
482.4000000000062,24.79841664626985,2.724460421822486,-1.8352663864113836
483.5000000000062,24.83379661817425,2.7214182461287684,-1.8460869620515132
484.60000000000616,24.86875268988151,2.717869487773177,-1.8570190953124488
485.7000000000062,24.903586378875918,2.713817527770329,-1.866811888845508
486.8000000000062,24.938681499778184,2.7096208266148674,-1.8767674597096735
487.90000000000623,24.973628459352582,2.700224963528366,-1.8871898569840844
489.00000000000625,25.009054392933955,2.6927184511919338,-1.8971384378485894
490.1000000000063,25.043833519968363,2.6840361708325418,-1.907372204909271
491.2000000000063,25.079169249383362,2.667962397921268,-1.9169744060212022
492.3000000000063,25.11412260131243,2.654862459481602,-1.9266739568823317
493.40000000000634,25.148956771771882,2.635309230376844,-1.9363965898259496
494.5000000000063,25.184205145659377,2.615248284478396,-1.9457301619160736
495.60000000000633,25.219434280905666,2.588214051121128,-1.954894787770924
496.70000000000636,25.254603970058213,2.558673676236959,-1.9633343799248033
497.8000000000064,25.28961757745401,2.527531307450326,-1.9710634493586414
498.9000000000064,25.324967605172247,2.493108330518887,-1.978510390982699
500.0000000000064,25.360030985180302,2.4576074891031623,-1.984443714867497
501.10000000000645,25.395048592651218,2.4210829359193498,-1.9904134753787952
502.2000000000064,25.430190673286994,2.3862299993512806,-1.9952146231257832
503.30000000000643,25.46517890503537,2.351439233477011,-2.000467013875561
504.40000000000646,25.500533263070707,2.318798552503022,-2.0034260814252383
505.5000000000065,25.53584017908949,2.291396795124514,-2.0049803169292923
506.6000000000065,25.57084669408648,2.2662962091735577,-2.0075791685634483
507.7000000000065,25.60608251283064,2.2449721408764356,-2.010385629459557
508.80000000000655,25.641379301532716,2.2268225693924566,-2.0119574325957257
509.90000000000657,25.67656828366132,2.2124215289766656,-2.0133592245166803
511.0000000000066,25.711755293998674,2.201518037578424,-2.01357213564562
512.1000000000065,25.747078448725585,2.1911800999782773,-2.0145593216864235
513.2000000000066,25.782304710385233,2.186496113387363,-2.0159048018051204
514.3000000000065,25.817577494761174,2.1790152504299822,-2.0164591987966007
515.4000000000067,25.85286713466296,2.173626449793482,-2.015924431740741
516.5000000000066,25.88843239573249,2.171940143081937,-2.015919659001375
517.6000000000067,25.923670108271125,2.1687057505492313,-2.016222515406012
518.7000000000066,25.959125043636185,2.166928941037037,-2.017241262725068
519.8000000000067,25.99455076081709,2.1679167674806332,-2.0172398826861646
520.9000000000067,26.02942954033767,2.1670503761672464,-2.017240474922587
522.0000000000067,26.064980259007182,2.164709535018319,-2.01690811114767
523.1000000000067,26.10047464479962,2.1674454922135538,-2.0172394368163213
524.2000000000068,26.135895467490766,2.167035682254886,-2.0172365338151628
525.3000000000068,26.171149855530345,2.166632569546013,-2.01798596102262
526.4000000000068,26.206506683963298,2.168086142058409,-2.0185524256251886
527.5000000000068,26.24176483386442,2.1713895833769694,-2.01854992900671
528.6000000000068,26.277333797474956,2.175853868774871,-2.0185499210136557
529.7000000000069,26.31260344927734,2.1814246001798923,-2.018554173814512
530.8000000000068,26.347904512755825,2.191607697963031,-2.019560565646902
531.9000000000069,26.383562994688837,2.202656336713938,-2.019539021608643
533.0000000000068,26.418733878450475,2.212302654231173,-2.019539910931362
534.100000000007,26.454222615405936,2.2190688439664337,-2.0195399150635174
535.2000000000069,26.489314596445404,2.2287266601276468,-2.019539915139279
536.300000000007,26.525065950885324,2.2367571604809378,-2.019539983065187
537.4000000000069,26.5603195061193,2.2432413245891336,-2.019540660466199
538.5000000000069,26.59582465374608,2.251184258827229,-2.020655924813904
539.600000000007,26.631082776578115,2.260531504238937,-2.020859308051417
540.700000000007,26.666790047027494,2.2665494492076665,-2.02085982126691
541.800000000007,26.702159982993834,2.273101052773202,-2.020863579373141
542.900000000007,26.737791643548555,2.2816683800732096,-2.020089277436602
544.000000000007,26.77329478355398,2.2856032563604485,-2.0195374930718564
545.1000000000071,26.80893557707783,2.290249275395911,-2.0195379225739223
546.2000000000071,26.84459097548424,2.294850597507871,-2.0200233119317272
547.300000000007,26.879871612295474,2.2962929550023983,-2.0218429039960943
548.4000000000071,26.915509865679926,2.2973316449865715,-2.0221804463341333
549.500000000007,26.950831677467182,2.297244696902356,-2.022180110425427
550.6000000000072,26.986610053116973,2.2983684991660644,-2.0221801099739674
551.7000000000071,27.02239310290643,2.2968662814509013,-2.022180109996708
552.8000000000072,27.058179690365478,2.2950484972313396,-2.022180110266927
553.9000000000071,27.093551493055205,2.29491720442869,-2.0221801607702226
555.0000000000072,27.12948035502249,2.2930971650788665,-2.0221791263099944
556.1000000000072,27.16511441887407,2.2935246966686544,-2.0232287393371715
557.2000000000072,27.200754660141026,2.2923722974457066,-2.023489467975981
558.3000000000072,27.2364514013649,2.2950495679657763,-2.0234898947358424
559.4000000000073,27.272227312834943,2.293731936691487,-2.0234898800889987
560.5000000000073,27.307596798094774,2.2911554887724015,-2.023489879999002
561.6000000000073,27.343527672246132,2.295777979365026,-2.0234898799999894
562.7000000000073,27.379443164775513,2.298125255108031,-2.023489880000006
563.8000000000073,27.41469966064571,2.2957203764026,-2.0234898800033116
564.9000000000074,27.4498422752246,2.297003895051824,-2.023489879981621
566.0000000000074,27.485410238295273,2.298406332039065,-2.023489843786327
567.1000000000074,27.522442506349073,2.2979656131170363,-2.0234866481716876
568.2000000000073,27.55819277911144,2.2988192121321607,-2.0243074927499562
569.3000000000073,27.593699581503678,2.29929236568348,-2.0248105681492232
570.4000000000074,27.62957198600881,2.302747359472158,-2.024810179475281
571.5000000000074,27.665617809121287,2.307150504097466,-2.024810180002787
572.6000000000074,27.70135170125621,2.306420129199558,-2.0248101818247264
573.7000000000074,27.73705120337098,2.3047719357826475,-2.0248098246926602
574.8000000000075,27.77313327797956,2.307174366294243,-2.0247644565458893
575.9000000000075,27.809102078031177,2.306578957933768,-2.025467413221382
577.0000000000075,27.844874762678156,2.310885977434778,-2.025783803266733
578.1000000000075,27.880792537435944,2.3112955543460854,-2.0261193758871467
579.2000000000075,27.916955642442417,2.31047350048472,-2.026120060258768
580.3000000000076,27.95243667763673,2.3118295177595405,-2.0261053924552117
581.4000000000076,27.98849348968103,2.315594185748229,-2.025110947389771
582.5000000000076,28.024317776647415,2.318747605237633,-2.025152148553941
583.6000000000076,28.06035822903845,2.322675747095843,-2.0264515434972914
584.7000000000077,28.096155919239862,2.3240378085619895,-2.02644972224246
585.8000000000077,28.132030204296953,2.327198362120826,-2.0264498416599874
586.9000000000076,28.16817673647465,2.3314107655064285,-2.02644944430579
588.0000000000076,28.203818011615823,2.3380952635000907,-2.0267445489598517
589.1000000000076,28.23970351258678,2.342991427813305,-2.027758163307259
590.2000000000077,28.27596830958973,2.3514239838915008,-2.029079181955338
591.3000000000077,28.31221843529648,2.35660819703693,-2.027781984292092
592.4000000000077,28.34817827142004,2.3650158323618813,-2.0277759855380766
593.5000000000077,28.383995286487487,2.370662534855168,-2.026449122857608
594.6000000000078,28.42016278836274,2.3764983772146735,-2.026475325759581
595.7000000000078,28.455875072345524,2.383970109539111,-2.0277742847649947
596.8000000000078,28.49181675189143,2.3917503785956744,-2.0277701013772926
597.9000000000078,28.528076969422766,2.4003962526478753,-2.027770129402539
599.0000000000078,28.56413087202406,2.4062952435349994,-2.0277671281112286
600.1000000000079,28.60037100279276,2.4169616487096954,-2.0284526303236463
601.2000000000079,28.63640672488946,2.422933877968454,-2.0292545268536784
602.3000000000079,28.672571275064286,2.4329613335968676,-2.0300716851608014
603.4000000000078,28.708785096732022,2.4371921422711607,-2.030329672933097
604.5000000000078,28.744758867377083,2.44766434857721,-2.0310651537595135
605.6000000000079,28.781205427923798,2.4554639520862915,-2.030031815387315
606.7000000000079,28.817117812849336,2.467253208939301,-2.0303152548940786
607.8000000000079,28.85352686128947,2.475353240976484,-2.030399076045976
608.9000000000079,28.889765518559386,2.4845373942424764,-2.0304000666448645
610.000000000008,28.9258019022549,2.4944264517756536,-2.030958201863701
611.100000000008,28.96202016096562,2.5019683748053683,-2.031720367216653
612.200000000008,28.998241338268233,2.511815615719233,-2.031720107975439
613.300000000008,29.034794933715755,2.522352517280199,-2.0317201099709647
614.400000000008,29.07063959762003,2.5293035342583936,-2.0317201099809963
615.5000000000081,29.107138768965772,2.538027811239367,-2.031720108371361
616.6000000000081,29.143046024733522,2.5505510341970985,-2.031720260058435
617.7000000000081,29.179460013451006,2.5607031342941373,-2.0317515024736843
618.8000000000081,29.21578747703176,2.5711365985310715,-2.0323226075770853
619.9000000000082,29.252152936793372,2.5828693992637666,-2.032698697350988
621.0000000000082,29.288406023025257,2.5918635296250825,-2.032663714785454
622.1000000000081,29.324692637502412,2.6037173282177943,-2.0340066963770713
623.2000000000081,29.36092488889636,2.614384939986882,-2.034020030280164
624.3000000000081,29.397659369863426,2.6264179919744,-2.0341955293480027
625.4000000000082,29.43367033149013,2.6373430704826744,-2.03535897338724
626.5000000000082,29.470000000000265,2.6497200000000665,-2.034989055839225
627.6000000000082,29.506328130564828,2.659312150520484,-2.0346737210636454
628.7000000000082,29.542601610723338,2.6713603246716233,-2.0346461756232235
629.8000000000083,29.57881422702225,2.6836199705919768,-2.036112131415183
630.9000000000083,29.6151153685623,2.697650069692759,-2.0371621888627924
632.0000000000083,29.651572936314746,2.7085408125757056,-2.0374194935632524
633.1000000000083,29.68782928851656,2.7209533866183024,-2.037375468754558
634.2000000000083,29.724081999268595,2.732511875789435,-2.038716122353627
635.3000000000084,29.760500978245773,2.7446108634318507,-2.0387294596239784
636.4000000000084,29.797092284649505,2.756863621211222,-2.0394248638751025
637.5000000000084,29.833032863800938,2.7694254025512213,-2.040051533115244
638.6000000000083,29.869578875643878,2.7838417316967177,-2.040027088520403
639.7000000000083,29.905973459311323,2.7976454597421627,-2.0413550094495942
640.8000000000084,29.942250130146196,2.8118889872656494,-2.0422044894799494
641.9000000000084,29.978724779936343,2.8255686429797735,-2.042680952334269
643.0000000000084,30.01491077652809,2.8375462187933644,-2.0426798120948835
644.1000000000084,30.05081648953462,2.8520626719677247,-2.042672832762328
645.2000000000085,30.08751026771364,2.865993982563207,-2.044026784996936
646.3000000000085,30.12390312645916,2.883268858736578,-2.045411684513976
647.4000000000085,30.160323274864144,2.898393580716162,-2.044804142480687
648.5000000000085,30.19660479125689,2.913776416621201,-2.044778032120282
649.6000000000085,30.232881083823866,2.929252243509989,-2.0446944657746
650.7000000000086,30.26932997727199,2.949555555840867,-2.045976283748172
651.8000000000086,30.30567899251121,2.968270468130232,-2.0469049115740687
652.9000000000086,30.342014693100296,2.988516665694657,-2.04821949828014
654.0000000000086,30.3782568350765,3.007594194428425,-2.049837148923457
655.1000000000087,30.41442876991674,3.029508556844759,-2.0498357345599048
656.2000000000087,30.451033040001064,3.052734202419915,-2.0512196648192207
657.3000000000086,30.48740189398353,3.078381696619259,-2.052564368349514
658.4000000000086,30.523621568064446,3.103271467439113,-2.053975304124404
659.5000000000086,30.560229313835322,3.1290091393646247,-2.0538867264301324
660.6000000000087,30.596189721846766,3.153769096843159,-2.0551278711794954
661.7000000000087,30.632518478922368,3.1799082018655698,-2.05650363688891
662.8000000000087,30.668407818656632,3.2085153680165233,-2.0577650623592225
663.9000000000087,30.70558529714446,3.2362880408050776,-2.058969806609331
665.0000000000088,30.741876630423665,3.2659274564083773,-2.05908948147193
666.1000000000088,30.77841551754772,3.297254610062917,-2.060648339873185
667.2000000000088,30.81464336991192,3.3264510744662785,-2.0618071951334374
668.3000000000088,30.850730175814853,3.3567776244097045,-2.0628506087698133
669.4000000000088,30.887470733638413,3.393292388256475,-2.066138058160216
670.5000000000089,30.923811619186793,3.4259844635027727,-2.0668103624250995
671.6000000000089,30.960000642969682,3.4624205701512683,-2.067911539944558
672.7000000000089,30.99644951658584,3.4947909680721625,-2.068516668031306
673.8000000000088,31.032017624259975,3.5271504228061077,-2.070488884603363
674.9000000000088,31.069327796282863,3.5636158448885347,-2.0723132888093447
676.0000000000089,31.10564771249406,3.597771020369727,-2.0738803561561285
677.1000000000089,31.142001570049135,3.630732333748507,-2.075333083568519
678.2000000000089,31.178590134343295,3.6629743618204866,-2.0773204964218728
679.3000000000089,31.215156356305858,3.69673076953179,-2.07965919498377
680.400000000009,31.25141426577421,3.7310009121732435,-2.0815195881969935
681.500000000009,31.28776300318984,3.764355122878803,-2.083185605294477
682.600000000009,31.324263094505973,3.8008134446626403,-2.0857126344937047
683.700000000009,31.36055675588999,3.8390388123251893,-2.087884411263787
684.800000000009,31.397126547722273,3.878223555020608,-2.090270766946169
685.9000000000091,31.43377184872904,3.9162824633769815,-2.0928104903936724
687.0000000000091,31.47050040339708,3.9576276432238213,-2.095379523841156
688.1000000000091,31.5070051166532,3.998389902418906,-2.0985809966042552
689.2000000000091,31.54317321021889,4.04198426751348,-2.101327213293852
690.3000000000092,31.580281095021405,4.086360607935102,-2.1031222543413417
691.4000000000092,31.616362804821915,4.131164617544658,-2.1053808718951528
692.5000000000091,31.653067633317043,4.177037194078944,-2.108247020512385
693.6000000000091,31.689455353889134,4.22393930322874,-2.1098340934141357
694.7000000000091,31.726272164887654,4.2744666258694695,-2.1130027864874195
695.8000000000092,31.762697974160893,4.325367650856991,-2.116340475459925
696.9000000000092,31.799508113864192,4.3777963403492,-2.1210578900731254
698.0000000000092,31.835800615072802,4.431741972674265,-2.123163223676192
699.1000000000092,31.872356451245764,4.489472150459128,-2.125772882085261
700.2000000000093,31.90903349480108,4.5466827894898,-2.129874236355059
701.3000000000093,31.945521530313062,4.605562077716704,-2.13264813014044
702.4000000000093,31.981874927611617,4.666097748915132,-2.136394467615574
703.5000000000093,32.01858740457495,4.727035036268774,-2.1407382224899756
704.6000000000093,32.05552107541821,4.794416174093455,-2.1449868497601594
705.7000000000094,32.09205751074996,4.86040952476625,-2.1496641730757484
706.8000000000094,32.1288583037187,4.9293070534713745,-2.1539516232081857
707.9000000000094,32.165368507668894,5.002360617715002,-2.1574818516772463
709.0000000000093,32.20183904053037,5.075347216261303,-2.161760664218397
710.1000000000093,32.23842557602906,5.151704618767735,-2.167412014466709
711.2000000000094,32.275122264621,5.233007263828849,-2.1730138617056713
712.3000000000094,32.311702761442625,5.312252462284283,-2.177389160544588
713.4000000000094,32.34808612951282,5.395874195678926,-2.1803481375589024
714.5000000000094,32.38493612664408,5.481768374882755,-2.186428089605965
715.6000000000095,32.420777211845774,5.569770255827569,-2.19224958854442
716.7000000000095,32.45828709727526,5.664658065831275,-2.198728656757913
717.8000000000095,32.49493826951188,5.755967458043778,-2.204215572084234
718.9000000000095,32.53177265700951,5.855670119818112,-2.210203342362327
720.0000000000095,32.568400598013156,5.950370237441212,-2.2155735543475767
721.1000000000096,32.605007362735485,6.051536724113479,-2.2226222277784675
722.2000000000096,32.64187109150993,6.152609069988012,-2.229942156821918
723.3000000000096,32.678864316317956,6.259441519801651,-2.237488970948205
724.4000000000096,32.71566034034528,6.363857982453599,-2.242776178086096
725.5000000000097,32.75218561243556,6.46824316566612,-2.2502435422856673
726.6000000000097,32.78906464109296,6.576253825024342,-2.2585245181250846
727.7000000000096,32.82597163747736,6.685776498788784,-2.266966609804704
728.8000000000096,32.86252692619832,6.792834288280814,-2.273111481729585
729.9000000000096,32.899250728770106,6.901773783735354,-2.281365482258999
731.0000000000097,32.9361381449281,7.011141452000824,-2.2911217555398853
732.1000000000097,32.972970398855004,7.118186154572531,-2.3020449774898695
733.2000000000097,33.00993110425112,7.227232721524047,-2.310520330984962
734.3000000000097,33.046557719772245,7.330156828120978,-2.319830823064503
735.4000000000098,33.083167520802895,7.436200047104424,-2.3291978824651554
736.5000000000098,33.120265080192,7.543948663202564,-2.3384524759091896
737.6000000000098,33.157319047272814,7.6482351876334365,-2.3476532104080317
738.7000000000098,33.194210275194045,7.753927759668696,-2.3585737103593774
739.8000000000098,33.23091381156204,7.859929858802572,-2.368983367223798
740.9000000000099,33.26750895146808,7.961290832116958,-2.380378145888159
742.0000000000099,33.30457667361079,8.066829973304142,-2.393084355900265