File: 01_Data/Face_Shield/STA/N2/10K_min/Face_Shield_STA_N2_10KData_221116_R2.csv
##Temp./Â°C,Time/min,DSC/(mW/mg),Mass loss/mg
51.0,10.568810692945972,-1.7732836354786818,0.010394777596077542
52.100000000000016,11.063449871690409,-1.606329344762475,0.007286063681054333
53.20000000000003,11.321478660193664,-1.5094699843638888,0.008352255944476639
54.30000000000005,11.532030846844632,-1.4361152286686085,0.011209442211336906
55.40000000000006,11.721236141378096,-1.380633753605399,0.008598464002847361
56.50000000000008,11.895847854570256,-1.33231035988289,0.004272305399573018
57.600000000000094,12.05677899986655,-1.2926532270677995,0.0037397828537009126
58.70000000000011,12.211508666740803,-1.2618604431033018,0.004725755542627663
59.800000000000125,12.361812045210597,-1.2325386944229757,0.005664226544501272
60.90000000000014,12.509608929153048,-1.2095246144996803,0.008300422568220611
62.000000000000156,12.652047737999531,-1.187920348886293,0.007689076994929156
63.10000000000017,12.790143491552461,-1.168588875579171,0.005854569053206582
64.20000000000019,12.928288287645831,-1.1498182463852578,0.0074435327077617686
65.30000000000021,13.061877395816673,-1.1333411632026456,0.006021163569601029
66.40000000000022,13.19446043737626,-1.117897249531664,0.00608025637540921
67.50000000000023,13.32584792877656,-1.1047682710133604,0.006594091294557902
68.60000000000025,13.452287176934767,-1.090008693840837,0.009520875579716037
69.70000000000027,13.581844120703558,-1.074619712824557,0.008183238798953774
70.80000000000028,13.709035399371615,-1.063519127966706,0.008440951371907257
71.90000000000029,13.833207071833925,-1.0492461917757687,0.007725798062617528
73.00000000000031,13.959296648391051,-1.036142605981788,0.005820602789872176
74.10000000000034,14.080708788787401,-1.025437288554708,0.00783865396866501
75.20000000000034,14.20390357494182,-1.0115661990017832,0.007843546003133639
76.30000000000035,14.325022842925405,-1.0000524033215952,0.005159615263696793
77.40000000000038,14.443893740495737,-0.9881539166210307,0.0050262300237857716
78.5000000000004,14.566267103298443,-0.9778914231807062,0.00650789717873046
79.6000000000004,14.685593781023968,-0.9667064617018515,0.00542662262168081
80.70000000000041,14.804577493757273,-0.9550779200039199,0.005458125312261419
81.80000000000044,14.92136402058962,-0.9457112130370718,0.00518218883314292
82.90000000000046,15.037423930555091,-0.9360653175192473,0.005697736515757779
84.00000000000047,15.155507809569812,-0.9271115125203628,0.006478748332351181
85.10000000000048,15.267911537476195,-0.9179357766182932,0.0064800508946945
86.2000000000005,15.384906330712736,-0.9069859296982088,0.0065038979745377645
87.30000000000052,15.499443170394787,-0.8982827122504604,0.007786638017222458
88.40000000000053,15.6127022542714,-0.8898614551682229,0.008112496011077663
89.50000000000054,15.724878388043928,-0.8821759675375765,0.009506442706168627
90.60000000000056,15.839886463782017,-0.8721140642014505,0.00907910121226907
91.70000000000059,15.950549388668865,-0.8656206552505945,0.00746010105909134
92.8000000000006,16.061957655170062,-0.8584063900868185,0.007974767926147486
93.9000000000006,16.172631338460807,-0.8498954019674718,0.008457320436285443
95.00000000000063,16.28448953192669,-0.8405527226385938,0.008803356125401951
96.10000000000065,16.39484909410599,-0.8326858874836839,0.008835514474638817
97.20000000000066,16.505818328507203,-0.8258411385066211,0.008106764416060841
98.30000000000067,16.615947824741813,-0.8173836564537813,0.007459937136667261
99.40000000000069,16.725541449022224,-0.8095267884346528,0.008439681053125536
100.50000000000071,16.8345812631903,-0.8018631554077941,0.007416686375111059
101.60000000000072,16.94387215272774,-0.795868331278936,0.008716616434809143
102.70000000000073,17.052637840712375,-0.7883731553099653,0.008779061248589848
103.80000000000075,17.162337893137924,-0.7797325188761072,0.008379307636465327
104.90000000000077,17.269380722571878,-0.7715976503846691,0.00747188033417201
106.00000000000078,17.3784216882506,-0.7648136909148459,0.006281647183975281
107.10000000000079,17.486403247130262,-0.7572612460765779,0.006156902472551629
108.20000000000081,17.594309269070827,-0.7494150623685953,0.004829268259534114
109.30000000000084,17.701647452736005,-0.7429110732745566,0.0061397560831917275
110.40000000000084,17.808963276588493,-0.7367490630009026,0.0061499976632668485
111.50000000000085,17.916158553419915,-0.7273796112841423,0.007508644202370629
112.60000000000088,18.02553058699868,-0.7210384182505947,0.007480212075779313
113.7000000000009,18.13277920226521,-0.714897544434549,0.007090105589653284
114.8000000000009,18.240716498350903,-0.7089748222573303,0.004788715646597552
115.90000000000092,18.34707799253305,-0.7017288632960337,0.006099438955161851
117.00000000000094,18.454787223643905,-0.6954407554118128,0.008786534326065798
118.10000000000096,18.56235917038741,-0.6891389022837607,0.008387974939011222
119.20000000000097,18.667522349088784,-0.6835501157516692,0.007781541141716364
120.30000000000098,18.776326465430706,-0.677480973315407,0.007403308492091032
121.400000000001,18.882827890960954,-0.6715032700021604,0.005280139881647106
122.50000000000102,18.99034157673732,-0.6646352051725067,0.006700088849739938
123.60000000000103,19.09657741980025,-0.6589900644368282,0.008023669491862062
124.70000000000104,19.20328355718822,-0.6533643514228921,0.007043459663813145
125.80000000000106,19.31093682947613,-0.6472864349113515,0.008360808233661476
126.90000000000109,19.416715339096005,-0.6413463299864635,0.009697970126188782
128.00000000000108,19.522928302025406,-0.6371938558937638,0.008678986757620688
129.1000000000011,19.629168977979766,-0.6307899980733518,0.006699710902569489
130.20000000000113,19.734975679570457,-0.625863354467331,0.0067028104429027735
131.30000000000115,19.840448996084117,-0.6209779098399089,0.009100606945488199
132.40000000000117,19.94693348613411,-0.6138978014364154,0.011637733418916163
133.50000000000117,20.051591131230705,-0.6086115821720242,0.007679813369163568
134.6000000000012,20.156290257669397,-0.605056363266674,0.007677106571941206
135.7000000000012,20.263466039851597,-0.5980488718402084,0.0020708481561984016
136.8000000000012,20.36998427118339,-0.5918011464554435,0.0050876568399429445
137.90000000000123,20.47539979050698,-0.5886709008339113,0.00936452237239882
139.00000000000125,20.58082019256594,-0.5831771072403328,0.011978063297003239
140.10000000000127,20.686187768901764,-0.5787897051938152,0.009527838341429007
141.2000000000013,20.79220077395666,-0.5742874102417986,0.006859075649250368
142.3000000000013,20.89791005537195,-0.5691694442692934,0.006908747177802876
143.4000000000013,21.002537561666962,-0.5631179171882829,0.004297704652624912
144.50000000000134,21.10774028572094,-0.5565682286246816,0.005608967699775036
145.60000000000133,21.211957114368353,-0.5523906857984391,0.006485253676936864
146.70000000000135,21.316989637584648,-0.546520030553115,0.008166132136371296
147.80000000000138,21.421841466627633,-0.5413984386589076,0.010121823220490267
148.9000000000014,21.52609033795402,-0.5360215847772911,0.00822136834138254
150.00000000000142,21.63129690464343,-0.5318521985972227,0.005600768752731078
151.10000000000142,21.735648298251927,-0.525585269534651,0.008152039127633959
152.20000000000144,21.8407269050549,-0.5205988651711726,0.009550031661385905
153.30000000000146,21.944214227203663,-0.5170390735540604,0.009789780249452207
154.40000000000146,22.04973945195402,-0.5119309114174764,0.008867201901040733
155.50000000000148,22.154754517315244,-0.505857426688977,0.008240080202499112
156.6000000000015,22.259169035288952,-0.503630018392806,0.009550168676910165
157.70000000000152,22.362557455517397,-0.4977864494765539,0.009406027248770155
158.80000000000155,22.46758519003844,-0.494143694686411,0.009547108839214058
159.90000000000154,22.572268780287004,-0.48721409313139175,0.00954982104210167
161.00000000000156,22.67667385074545,-0.48375147137105057,0.009549757085251187
162.1000000000016,22.781706678197583,-0.48025187637664596,0.008816050611066828
163.20000000000158,22.88470173174681,-0.4755092821369453,0.010210006495237511
164.3000000000016,22.989965143033047,-0.4710933619417635,0.008554511871412984
165.40000000000163,23.09416806464927,-0.4658762518531924,0.009715674299831889
166.50000000000165,23.198334167714236,-0.4621398983806046,0.008559748929275024
167.60000000000167,23.303449940923322,-0.4585895640218375,0.009874517372507885
168.70000000000167,23.408014734350896,-0.45413366591359927,0.012510568458255822
169.8000000000017,23.512509023235094,-0.44994801699480574,0.01119684075829408
170.9000000000017,23.61742814777065,-0.44500735206019804,0.010791323017485865
172.0000000000017,23.72131877173882,-0.44086775220806845,0.00848250114979221
173.10000000000173,23.82650523177794,-0.437012946394313,0.007316036178159457
174.20000000000175,23.93094135866044,-0.43335089404393384,0.00986327612519089
175.30000000000177,24.035539135812982,-0.4280362613805595,0.011089990697872754
176.4000000000018,24.1401087853084,-0.4261003426675105,0.011741023850111887
177.5000000000018,24.245662337041352,-0.42272069326840006,0.011651666872036337
178.6000000000018,24.349281497677335,-0.4174997328219417,0.009770093408620006
179.70000000000184,24.45391142586822,-0.41257088391351315,0.009189446052725092
180.80000000000183,24.5579626733322,-0.4097160828965386,0.00846133909313318
181.90000000000185,24.660827889841034,-0.4050920209889825,0.009268304394705051
183.00000000000188,24.76734424799572,-0.4002433328363604,0.008461875538531505
184.1000000000019,24.87210443075853,-0.3973179764628887,0.00935796483242779
185.20000000000192,24.97616229025573,-0.3937897171092374,0.011086426907549907
186.30000000000192,25.078610598434523,-0.3903101801416367,0.011751277224864243
187.40000000000194,25.184937253678864,-0.38382545238396115,0.013730304342189914
188.50000000000196,25.28813586545117,-0.3782931162433128,0.01241018121341897
189.60000000000196,25.393292305862303,-0.3727681515058596,0.011658451482122967
190.70000000000198,25.497098063550997,-0.3675861084585078,0.009770235248811154
191.800000000002,25.601871087757118,-0.3610415582796072,0.011126069435523078
192.90000000000202,25.706510034912295,-0.35333538981745893,0.01108998396249783
194.00000000000205,25.810445425716104,-0.3464719608071135,0.009077289074752581
195.10000000000204,25.915052475334893,-0.3378447170211849,0.009120254273222717
196.20000000000206,26.018612342261278,-0.3311774515819428,0.010430406492431654
197.3000000000021,26.122699996776856,-0.3255889045759032,0.012468074211188451
198.40000000000208,26.227388863009082,-0.32032778146911833,0.012434237595357
199.5000000000021,26.331476556446137,-0.315985005324311,0.013729972394667112
200.60000000000213,26.43515941609207,-0.3110919270733351,0.012407759767853577
201.70000000000215,26.53878377527256,-0.3080211681458902,0.009040007332043132
202.80000000000217,26.64297153987165,-0.3035739944444951,0.007140857331668027
203.90000000000217,26.747195207728787,-0.2998474022233322,0.008608227257069334
205.0000000000022,26.85123878657915,-0.2968880129587704,0.0097635502848612
206.1000000000022,26.955959941767837,-0.29260895413283666,0.011081742960456165
207.2000000000022,27.059170000000208,-0.2890400000000013,0.01240703719498848
208.30000000000223,27.16385749579213,-0.2867168801522417,0.011092468350955897
209.40000000000225,27.266268025719384,-0.2833881651427364,0.010100244009630277
210.50000000000227,27.368247900825224,-0.2801458947713373,0.011085805108754787
211.6000000000023,27.473420931126377,-0.2773083686472819,0.009770139034259717
212.7000000000023,27.579557016535098,-0.27386565848761024,0.011113130921533543
213.8000000000023,27.683817217684364,-0.27139056988508237,0.009795374457427286
214.90000000000234,27.78814659736628,-0.26712844952092046,0.009744060022732093
216.00000000000233,27.893003586759413,-0.26320026996496604,0.011119251987873113
217.10000000000235,27.99449969884812,-0.2601544800800592,0.01109007011451224
218.20000000000238,28.100347489878715,-0.2563068485851499,0.009147890199288522
219.3000000000024,28.20512638724058,-0.2531960675315684,0.00881846469424552
220.40000000000242,28.30889562850042,-0.25115115023462853,0.011410216642795845
221.50000000000242,28.412573999647243,-0.24771116439256308,0.011399096532421993
222.60000000000244,28.518085791178343,-0.2428198353223528,0.010105453043040669
223.70000000000246,28.62020345223118,-0.24187523292052512,0.009366493607591675
224.80000000000246,28.725426253289072,-0.23723159252386808,0.012413058339281413
225.90000000000248,28.829171052422154,-0.2364900015703432,0.012681763810692193
227.0000000000025,28.932022154440787,-0.23360607291037402,0.011365863539532395
228.10000000000252,29.0365369648936,-0.2308978270810573,0.009224033011979493
229.20000000000255,29.14201458594117,-0.2281469097899771,0.011493506686380162
230.30000000000254,29.245968017925588,-0.22407529851540206,0.011409903398964971
231.40000000000256,29.35187383736561,-0.2218113692884584,0.01024184382993365
232.5000000000026,29.455274303106847,-0.21925602371618103,0.011329371591586757
233.60000000000258,29.55937130492904,-0.21631803806010935,0.014159929346993394
234.7000000000026,29.661499339719015,-0.21342443478811302,0.012845048336365128
235.80000000000263,29.76716492556417,-0.2113119448266424,0.010206249191552441
236.90000000000265,29.871445635581754,-0.20833839420428046,0.010870107220006364
238.00000000000267,29.977071370832945,-0.20500719644195847,0.01146153075778722
239.10000000000267,30.080688776819272,-0.20352999322568693,0.014282836522886644
240.2000000000027,30.185315647672596,-0.2013987761980321,0.01547759871434895
241.3000000000027,30.289988169287014,-0.19825278828669948,0.013837229928550965
242.4000000000027,30.394176948875685,-0.19635007664652346,0.010947270451895363
243.50000000000273,30.49785489474106,-0.19255537037926262,0.010979934590107376
244.60000000000275,30.601288890795388,-0.19054108405780637,0.012382138542656573
245.70000000000277,30.706719850046202,-0.18784907663372843,0.01229019953263899
246.8000000000028,30.810772959568713,-0.18615942063162536,0.012289650338287217
247.9000000000028,30.91444494675337,-0.1847397377321713,0.010979978226365983
249.0000000000028,31.018878666970515,-0.18144420712178366,0.010979362275946425
250.10000000000284,31.123544932994314,-0.17889011040881647,0.013666496399196149
251.20000000000283,31.227174870722056,-0.1775841874320438,0.013610136366050796
252.30000000000285,31.331614368055025,-0.1749865180567243,0.01257159184204637
253.40000000000288,31.435822373091035,-0.17223448861814827,0.011301235134213439
254.5000000000029,31.53797904778807,-0.1689401372799215,0.012614295592937363
255.60000000000292,31.64511424768766,-0.16841450903538893,0.012290259989799157
256.7000000000029,31.749569051456263,-0.16670979970285094,0.013727111321539809
257.8000000000029,31.853459711604383,-0.16334823818062552,0.011418416683516952
258.90000000000293,31.95838378699065,-0.16025357319798575,0.011904331910337795
260.00000000000296,32.06258874180214,-0.15917367005695923,0.012410128866673809
261.100000000003,32.16595463078692,-0.15681509647966632,0.012405294245652065
262.200000000003,32.272079001503656,-0.15718852514768322,0.013860736620318281
263.300000000003,32.375384341021494,-0.15297098120941788,0.012405823556482787
264.40000000000305,32.48006783722219,-0.15155640339896553,0.01109119892702859
265.50000000000307,32.58509216418762,-0.14849278067594912,0.012330039103728652
266.6000000000031,32.68956082810802,-0.14678809081818459,0.012400147720784904
267.7000000000031,32.793912146993385,-0.1450911890388586,0.0109802156787695
268.8000000000031,32.898144699400454,-0.1446668759056529,0.01213079109535009
269.9000000000031,33.00268551356641,-0.14174571933594385,0.013013241843170764
271.0000000000031,33.10855031719553,-0.13826923398618296,0.008999800598555652
272.10000000000315,33.212742582096396,-0.1369836766860023,0.01032353988000434
273.2000000000032,33.3182229756317,-0.13507823570727476,0.011056705965429625
274.30000000000314,33.42228335850254,-0.1338535958259535,0.01164426257177853
275.40000000000316,33.527943640545764,-0.13045320823987006,0.011322964473146957
276.5000000000032,33.63217849436415,-0.1292225385382648,0.012944681395838487
277.6000000000032,33.73656180356622,-0.1262929139536916,0.011517358241790898
278.70000000000323,33.83869507235741,-0.12432854850681099,0.012948933292597165
279.80000000000325,33.94652125751763,-0.12268496230686492,0.014307903265672994
280.9000000000033,34.050624063037034,-0.12001758922274088,0.01196986222446661
282.0000000000033,34.155854307812845,-0.11750947864369211,0.013795707828808457
283.1000000000033,34.26171545049743,-0.11608732970729663,0.011183571016118332
284.20000000000334,34.36666584777367,-0.11286364560512528,0.011516133289250607
285.30000000000337,34.471493518659045,-0.1109473198715069,0.008888194907027636
286.40000000000333,34.575670220031526,-0.10887054130289775,0.011822066408599952
287.50000000000335,34.68128803892908,-0.10771247277593851,0.014379768759174905
288.6000000000034,34.78691200147761,-0.10506801895468168,0.011597919360005982
289.7000000000034,34.89156745942509,-0.10302922551419183,0.010209850578508206
290.8000000000034,34.99688386039226,-0.10143459562292274,0.008890695629512724
291.9000000000034,35.10162349592605,-0.09871240518328894,0.012195542708686613
293.0000000000034,35.20597557859733,-0.0962765711360801,0.010867289782889422
294.10000000000343,35.3115138389411,-0.09447242845730339,0.012416107435764268
295.20000000000346,35.416987696881236,-0.0924036464783949,0.013391069061428063
296.3000000000035,35.522171133976656,-0.0912044939115301,0.012189814297707269
297.4000000000035,35.627017680104494,-0.08796454391196465,0.012189814664524512
298.5000000000035,35.732719789584195,-0.086454578155546,0.01124554779169129
299.60000000000355,35.83691495454127,-0.08437420606132609,0.011652694245783746
300.70000000000357,35.942043372150465,-0.08182327724912788,0.013516609072764751
301.8000000000036,36.046779380204256,-0.07968224924225198,0.014829876613232429
302.9000000000036,36.15307491947309,-0.0772666105166477,0.013524369848856299
304.0000000000036,36.258564809382406,-0.07363189138850745,0.01076482394704703
305.1000000000036,36.36132383856743,-0.07329518241067245,0.013402228578626385
306.2000000000036,36.4682947100819,-0.06992401025675522,0.012079840722604374
307.30000000000365,36.57279854489955,-0.06687730865206364,0.012074665724004507
308.4000000000037,36.67818134674812,-0.06432467444665307,0.01077326094824782
309.5000000000037,36.78293128430964,-0.06360299669587378,0.013069920996453543
310.60000000000366,36.88926348251645,-0.06229006764060326,0.012080204782533688
311.7000000000037,36.99487381138185,-0.060108534323119696,0.01339880320665765
312.8000000000037,37.09975699827342,-0.05819161618278404,0.01095515980166839
313.90000000000373,37.2050412708954,-0.05490074360102292,0.01075952180360984
315.00000000000375,37.30996746937337,-0.054473623514594297,0.011750104272896689
316.1000000000038,37.415998112075904,-0.05172071039249178,0.011743293201679883
317.2000000000038,37.52111953192131,-0.0509039218941588,0.01173890322735005
318.3000000000038,37.6268577483209,-0.048694480964558765,0.013069894304630125
319.40000000000384,37.731583034443105,-0.04587262342111,0.01305606454396413
320.5000000000038,37.83726483197967,-0.04376145638709235,0.013730106150922072
321.60000000000383,37.94272491231605,-0.042102603546828855,0.013426046674533065
322.70000000000385,38.04809311318562,-0.03854510108535234,0.01097705531098958
323.8000000000039,38.153869676599285,-0.0376591415063361,0.014066228628319521
324.9000000000039,38.260256564580956,-0.03434468956371174,0.011667231302656678
326.0000000000039,38.36565303724707,-0.03350071046265535,0.00924325478774568
327.10000000000394,38.47078240123711,-0.03191728605868899,0.012613144899282336
328.2000000000039,38.57634889807448,-0.029977746958965146,0.01063966793034643
329.30000000000393,38.682360921156445,-0.02811690538909793,0.010683047621643293
330.40000000000396,38.78619786560797,-0.025472124804241752,0.011969259192347703
331.500000000004,38.893198171596445,-0.023688550442587213,0.010650212420356908
332.600000000004,38.99853107050299,-0.022527248115397726,0.01129700380890819
333.700000000004,39.105544593658635,-0.0213046111813536,0.012699288479342652
334.80000000000405,39.211708406657614,-0.019206564532417602,0.011191491028527789
335.90000000000407,39.318083212012326,-0.017667470809704707,0.012630045112048904
337.0000000000041,39.423596900905366,-0.01571911899858011,0.012405653565611185
338.10000000000406,39.529416151663796,-0.014991700997526091,0.011309468391512922
339.2000000000041,39.63527022337035,-0.012257808044911181,0.008664399312753979
340.3000000000041,39.74109146953771,-0.011024286619061513,0.00867013844719855
341.4000000000041,39.847072886691365,-0.009566179874057388,0.00899999237741822
342.50000000000415,39.952646749264396,-0.007622320744630491,0.008999914841515189
343.6000000000042,40.06010213201167,-0.004438623725744128,0.007680142339541618
344.7000000000042,40.16602969577827,-0.00262310259404916,0.007685706385383018
345.80000000000416,40.27125613560286,0.00025386912748783907,0.008339994997544231
346.9000000000042,40.37745388418896,0.0025266836136159146,0.008302284204730892
348.0000000000042,40.48392189515542,0.004411139152496692,0.00968853895655375
349.10000000000423,40.59067460730468,0.00610210442316825,0.009660158307171596
350.20000000000425,40.69653070991746,0.008581130030118657,0.00811923665827985
351.3000000000043,40.802841450952556,0.010520501155787116,0.005819903016386352
352.4000000000043,40.90844552889314,0.010224492642297306,0.007130781403185349
353.5000000000043,41.014651658193536,0.013352483106491547,0.005786094039219147
354.60000000000434,41.12059220740685,0.014766034690452047,0.00844591440472442
355.7000000000043,41.22648930098749,0.01649537672576688,0.007312428392076686
356.80000000000433,41.33339935019699,0.017764715913940746,0.006032266099809558
357.90000000000435,41.43701910290996,0.019203465902090964,0.006471751656543123
359.0000000000044,41.54574836240546,0.02098001426838829,0.00551537618023934
360.1000000000044,41.65126628834538,0.022755481650752387,0.0038829555658375092
361.2000000000044,41.759349467277815,0.02428470756421534,0.00417983842182057
362.30000000000445,41.864431649939505,0.024454423634469764,0.004499921433710252
363.4000000000044,41.96985757512874,0.02629123142124599,0.004509827985198722
364.50000000000443,42.077203063045424,0.02930386706013104,0.0031893714429491737
365.60000000000446,42.1836808010389,0.030769327943276224,0.002850533040620551
366.7000000000045,42.28972921769753,0.030855228184893436,0.004180316580164156
367.8000000000045,42.395935265961796,0.030937651140950904,0.0014794617033451196
368.9000000000045,42.50284996886454,0.03266660849161048,0.003831668815200473
370.00000000000455,42.60994244676037,0.03287794759351233,0.002529908228144251
371.10000000000457,42.71628524402418,0.033135219958082655,0.0028612204153648513
372.2000000000046,42.82261792850443,0.03531400792781741,0.0019069906612485532
373.30000000000456,42.929670292010734,0.03316269028160436,0.0015217382359526965
374.4000000000046,43.0356924864237,0.03284513030919031,-0.0010993983727871637
375.5000000000046,43.14275259107436,0.035725169530354546,-2.3547117195210632e-05
376.6000000000046,43.249265677613735,0.034661600960430576,0.00022016102256028347
377.70000000000465,43.35527349108251,0.03821258471578158,0.00022016099673116685
378.8000000000047,43.4593685269639,0.040398771931953174,-0.00012749995781558
379.9000000000047,43.56827954233356,0.041407672022688385,-0.001089934530440928
381.00000000000466,43.67399782108507,0.04367775088114085,0.0002188205483495409
382.1000000000047,43.78155114745824,0.046021035261039234,-0.001066802401358924
383.2000000000047,43.8886368992701,0.04729288086104574,-0.0038397572578898753
384.30000000000473,43.99557972672729,0.049733420978269924,-0.0025182150346494403
385.40000000000475,44.10318845528403,0.05074837531183814,-0.0025199329794167724
386.5000000000048,44.21007831540227,0.05326342899088126,-0.0011451117676912759
387.6000000000048,44.315555901634916,0.05392838671724112,-0.0025239742603151427
388.7000000000048,44.42284352593922,0.0549681678433839,-0.0025206446186416542
389.80000000000484,44.52995249050596,0.05951222045071565,-0.0038399451058270806
390.9000000000048,44.636741093582316,0.05988501092691438,-0.005082592474470626
392.00000000000483,44.743511120619424,0.06180548400797279,-0.010523708236505502
393.10000000000485,44.850468408093846,0.06288029391679527,-0.009111588835088114
394.2000000000049,44.956640858083794,0.06367575292273972,-0.008120376648119265
395.3000000000049,45.0640431036302,0.06506260119474193,-0.008119987806003426
396.4000000000049,45.1700404542391,0.06639383982964013,-0.009416376492019207
397.50000000000495,45.277622237576715,0.0686688162095075,-0.010793239174005542
398.6000000000049,45.38411031835214,0.07054348392172859,-0.01336427477659008
399.70000000000493,45.491352088173024,0.07264824907642904,-0.012711089185918123
400.80000000000496,45.59822241858375,0.07354456772220866,-0.01142227971488552
401.900000000005,45.70521756391086,0.07588632744662678,-0.0114203138662754
403.000000000005,45.812339010049826,0.07791628407852245,-0.009365956784944895
404.100000000005,45.918292547913765,0.07671783688280637,-0.010760072144163413
405.20000000000505,46.02575678473043,0.08061031190433592,-0.012075474557957655
406.30000000000507,46.132994570925774,0.0835379391228146,-0.014663359725689329
407.4000000000051,46.23953710011031,0.0848723592759626,-0.014710190010808422
408.50000000000506,46.34658000241427,0.08395194249697184,-0.014728743594464522
409.6000000000051,46.454336853315795,0.08746075296189958,-0.017339896922786924
410.7000000000051,46.56149428911079,0.08954178620732059,-0.017264043678892005
411.8000000000051,46.66732834776722,0.09058174338654432,-0.018330255494318326
412.90000000000515,46.775934363696216,0.09181051239569542,-0.018174988665560665
414.0000000000052,46.88252987227624,0.0930061085063299,-0.018303535303385576
415.1000000000052,46.9889851537884,0.09589051403429696,-0.017340027507849243
416.20000000000516,47.09673942464215,0.09734326636440567,-0.018660188621831164
417.3000000000052,47.20331559115632,0.09795037434660081,-0.019982262770634307
418.4000000000052,47.31108113949681,0.10080194884817828,-0.021630283802232864
419.50000000000523,47.417254210754265,0.10254206491517755,-0.0239284584800048
420.60000000000525,47.52475836423758,0.1042688650446805,-0.023929814218971224
421.7000000000053,47.63243599159483,0.1051830032714474,-0.02287924254118101
422.8000000000053,47.73994700834954,0.1064615577639665,-0.024260129619042115
423.9000000000053,47.84752795573435,0.10884750471327383,-0.02557988654091048
425.00000000000534,47.954076760681474,0.11087445697648145,-0.02690351606636332
426.1000000000053,48.061906429548735,0.11322253253968333,-0.028884600957764572
427.20000000000533,48.16990535156918,0.1138553915129988,-0.028891760051952264
428.30000000000535,48.27616389924246,0.11503136791690026,-0.02887001872784367
429.4000000000054,48.38399446477909,0.11588247453484832,-0.02986167811903906
430.5000000000054,48.49002880736005,0.11879004002059498,-0.031730116481242465
431.6000000000054,48.59877484369995,0.12011257315649154,-0.03304010027815263
432.70000000000545,48.70553435115174,0.11990860458030272,-0.03310478619776758
433.8000000000054,48.81385893127893,0.11958851364582432,-0.0343617232495288
434.90000000000543,48.92105396796576,0.11961822896235406,-0.03703052767692361
436.00000000000546,49.028705394328725,0.121079607847214,-0.036984589942250956
437.1000000000055,49.13703717658451,0.12137879487984049,-0.039851542072524726
438.2000000000055,49.243546592779325,0.12113640422273238,-0.03921121353272694
439.3000000000055,49.34997605549537,0.12540423986699858,-0.040251066966462634
440.40000000000555,49.45990072257435,0.127118619232836,-0.04463453838371079
441.50000000000557,49.56693497323413,0.13065133724731148,-0.04458844357639391
442.6000000000056,49.67518635059161,0.1327379671282345,-0.04588960482160909
443.70000000000556,49.78306470524112,0.13427980632061176,-0.04774892703453304
444.8000000000056,49.89021124084925,0.1391601629613828,-0.050527605833299294
445.9000000000056,49.99828963713099,0.1421001594655624,-0.051810957635891164
447.0000000000056,50.10574817020107,0.14714203839360632,-0.05448800032859413
448.10000000000565,50.21356879816567,0.14875016521855255,-0.058241319205112774
449.2000000000057,50.321592868930935,0.15466286350794967,-0.06079967333274672
450.3000000000057,50.42839515535453,0.1575311930195274,-0.061266905477529665
451.40000000000566,50.53589428467954,0.16154980594801377,-0.06465925942717554
452.5000000000057,50.64340216165843,0.1640430442676191,-0.06667390975262855
453.6000000000057,50.75221671913616,0.1693059126923577,-0.06926714882047502
454.70000000000573,50.85907086314606,0.1751480626583164,-0.07321913493955501
455.80000000000575,50.96675047978537,0.18051814833515492,-0.0774612223922242
456.9000000000058,51.07440910348093,0.18720679233495727,-0.08055253514231175
458.0000000000058,51.181605730451565,0.19517199951894065,-0.08480561754678018
459.1000000000058,51.290726165329296,0.2010937973029831,-0.09038898508695592
460.20000000000584,51.39798903498224,0.20857173434823933,-0.0948476731465635
461.3000000000058,51.505486662293734,0.21720556475955283,-0.10252874895071606
462.40000000000583,51.613374287930235,0.2249592793687113,-0.10825149206353268
463.50000000000585,51.720955582664175,0.2324008855598608,-0.1147998346123944
464.6000000000059,51.82949100763201,0.24311762995936545,-0.11947963686495866
465.7000000000059,51.93788831119034,0.25438434741453125,-0.12701714670497255
466.8000000000059,52.0461044444996,0.2643786352668797,-0.13876972087266592
467.90000000000595,52.154520980697356,0.2763560504171539,-0.14642888003778243
469.0000000000059,52.262893585471275,0.28805937344499644,-0.15490572632870547
470.10000000000593,52.371313731477386,0.30183165329690037,-0.16436267007876504
471.20000000000596,52.48006410901939,0.31810233669969185,-0.17693636057324102
472.300000000006,52.58719003100242,0.33364187237007203,-0.19076019931460442
473.400000000006,52.69494062759553,0.3508347350285301,-0.20318764985776427
474.500000000006,52.80250455681883,0.3698635052260265,-0.2239135350580348
475.60000000000605,52.910875414136264,0.3871437469564083,-0.23587071087453326
476.70000000000607,53.01948293023659,0.40843708295730774,-0.25146267972521663
477.8000000000061,53.12803134720177,0.4298942932064296,-0.2733923292910361
478.90000000000606,53.236554633911396,0.4520101606206472,-0.29744732957536346
480.0000000000061,53.34468454035481,0.4778295997372997,-0.31884453059705375
481.1000000000061,53.4533326704718,0.500685635958297,-0.34116946544817406
482.2000000000061,53.56222621001152,0.5266978341915118,-0.37027019623876356
483.30000000000615,53.66998133292445,0.5579224508952949,-0.4008070030502786
484.4000000000062,53.776492215700166,0.5891134928006874,-0.43038683632818886
485.5000000000062,53.88487512896549,0.619806751102039,-0.4648402920636103
486.60000000000616,53.99374593784196,0.6509101973223208,-0.503757779031019
487.7000000000062,54.10306666587359,0.6841567979109221,-0.5456594693832164
488.8000000000062,54.21162978477853,0.7145147010886156,-0.5904186211239786
489.90000000000623,54.31946380613479,0.7477091522298075,-0.6377270241612449
491.00000000000625,54.428866300528576,0.7739610505602915,-0.6881829977323091
492.1000000000063,54.53625082502905,0.8026295418355879,-0.7388378863107481
493.2000000000063,54.644762158655084,0.8296383010935273,-0.7957403783822916
494.3000000000063,54.752944783368285,0.8475837767566039,-0.8609105061115274
495.40000000000634,54.86135855100816,0.8648633555517357,-0.9239856480042099
496.5000000000063,54.969913492500666,0.8791989177057612,-0.9865010081607695
497.60000000000633,55.07828420941513,0.8846249096476628,-1.050184233618308
498.70000000000636,55.183982467310905,0.8838208703488721,-1.1216512829721936
499.8000000000064,55.29404568966129,0.8760374340558694,-1.1963007417109055
500.9000000000064,55.403020586609166,0.8601077872655157,-1.2705534818780233
502.0000000000064,55.510846742235344,0.8354381745147682,-1.3438974557230092
503.10000000000645,55.61916901614152,0.8028802260768244,-1.4147793674706306
504.2000000000064,55.72675756085664,0.7603504356182827,-1.4857916135415938
505.30000000000643,55.83539613383592,0.7115213914707458,-1.5510519550350108
506.40000000000646,55.94403583627775,0.6567749341223111,-1.6169944837684196
507.5000000000065,56.05076948195925,0.6029751116771789,-1.6751662425742602
508.6000000000065,56.15994107269374,0.5445485741675394,-1.7332405385212803
509.7000000000065,56.26650538828136,0.48877111061501227,-1.7854558566007137
510.80000000000655,56.37509797447934,0.43900841210335656,-1.833191139922746
511.90000000000657,56.482571177236146,0.39208173380880856,-1.8841412765858156
513.0000000000066,56.590517807201536,0.3472058318101201,-1.9248807838912714
514.1000000000065,56.698658391475476,0.3098256621947955,-1.9654053428460303
515.2000000000066,56.80774624774052,0.2727082452999923,-1.9959629721598997
516.3000000000065,56.91497671621747,0.24189045599079098,-2.0280239298491005
517.4000000000067,57.023112380059175,0.2127459064102626,-2.058434909582511
518.5000000000066,57.132581450793154,0.18708595269064,-2.0845652051954815
519.6000000000067,57.24053942164143,0.16375989272486066,-2.111402630048212
520.7000000000066,57.34806188342444,0.14194975164067405,-2.136556834965669
521.8000000000067,57.45715567788072,0.12043669511448345,-2.1617785410377675
522.9000000000067,57.5644835978567,0.1045059612380982,-2.1837639381485774
524.0000000000067,57.6735296347538,0.08635066103441716,-2.202540991970235
525.1000000000067,57.780705205195616,0.068624489893587,-2.2209596962500857
526.2000000000068,57.88950230158046,0.05514503206464082,-2.2391807075810983
527.3000000000068,57.99804130279204,0.040015251914420714,-2.256812652275424
528.4000000000068,58.10628422873486,0.03044748578108661,-2.2713765981696796
529.5000000000068,58.215754449052255,0.015595323550012787,-2.2869300184122068
530.6000000000068,58.32411390719302,0.003137999872012667,-2.300067858077181
531.7000000000069,58.43168599189255,-0.005584038165669578,-2.314647134240307
532.8000000000068,58.541082220190795,-0.014181823263310536,-2.331158807577463
533.9000000000069,58.646580191694746,-0.02322934549085757,-2.34324228813173
535.0000000000068,58.757315824200475,-0.029863867012090883,-2.35662996925232
536.100000000007,58.86603134593065,-0.03633882096152127,-2.361951938299237
537.2000000000069,58.97465258889433,-0.046239621025965204,-2.376029973838489
538.300000000007,59.08397553628965,-0.052159784035639624,-2.384979959964734
539.4000000000069,59.19279865033798,-0.05752168447956221,-2.395749296643297
540.5000000000069,59.300510570959794,-0.06312540223097939,-2.40418103532673
541.600000000007,59.41015218020757,-0.06982985050442544,-2.4119288413594617
542.700000000007,59.51793832139558,-0.07471315814002481,-2.4193867893601464
543.800000000007,59.62683397427509,-0.07799804540948148,-2.42753663236919
544.900000000007,59.73546456740421,-0.0829086243396919,-2.4367392234594325
546.000000000007,59.844304077161006,-0.08554447879799146,-2.4426282697345587
547.1000000000071,59.95253360318801,-0.08768660822358232,-2.4509689904536724
548.2000000000071,60.06124710707265,-0.08984281696133006,-2.4582290277494567
549.300000000007,60.169777463903266,-0.0919314148605012,-2.468272377413591
550.4000000000071,60.278781384674076,-0.09580930165732135,-2.473402339119004
551.500000000007,60.38763022469846,-0.09511892418567981,-2.4790533307108875
552.6000000000072,60.49661258694988,-0.09748249789632792,-2.4831113798416493
553.7000000000071,60.605384285274994,-0.10094988875157766,-2.488875010755516
554.8000000000072,60.7150222454458,-0.10154265177861804,-2.4954058141555775
555.9000000000071,60.82315123111007,-0.10259912440600352,-2.501864724731263
557.0000000000072,60.932722027087074,-0.10293548626745609,-2.5084565697325574
558.1000000000072,61.04157430171217,-0.10500448429380356,-2.5142075366379224
559.2000000000072,61.15107845973426,-0.10745894975796172,-2.519973803374721
560.3000000000072,61.259269070010475,-0.10683428344792958,-2.525119949731216
561.4000000000073,61.368395893370206,-0.1085827416629733,-2.5306504136275216
562.5000000000073,61.475316077272495,-0.10960877460680189,-2.5323599338756697
563.6000000000073,61.58836324699197,-0.11051867435994944,-2.536934996955028
564.7000000000073,61.69582189968294,-0.10876260465764293,-2.5430203668892055
565.8000000000073,61.80548732404655,-0.11009393645418435,-2.545266992850499
566.9000000000074,61.91433938264129,-0.10935516849013832,-2.548394830051601
568.0000000000074,62.02458702405596,-0.10819423600651089,-2.552122612033827
569.1000000000074,62.13319402201529,-0.10847683222701411,-2.5590881637546734
570.2000000000073,62.242167120199134,-0.108844249642209,-2.564421826529312
571.3000000000073,62.35173512816801,-0.10743104465375097,-2.5670875493370686
572.4000000000074,62.46103892829737,-0.10639882151775325,-2.572840207105381
573.5000000000074,62.5700015912847,-0.10646385781638083,-2.573397944382055
574.6000000000074,62.679273513685516,-0.10537382354104848,-2.5778110538568004
575.7000000000074,62.78830384631354,-0.10429824749293627,-2.5863300411270935
576.8000000000075,62.896425256997745,-0.10243116455948512,-2.587283552057184
577.9000000000075,63.00650006191914,-0.10306972028983918,-2.5876966281620035
579.0000000000075,63.11581583303851,-0.1010729478976445,-2.590550267488096
580.1000000000075,63.2236615001771,-0.10049389133567986,-2.5919645691670508
581.2000000000075,63.33395913148978,-0.09858682139155414,-2.5959484036478897
582.3000000000076,63.44197749262659,-0.09728478045381492,-2.60656431055774
583.4000000000076,63.551686398880854,-0.09550553423991011,-2.6084495758287307
584.5000000000076,63.66069751179875,-0.09679972122746487,-2.6082725570615723
585.6000000000076,63.770232559902084,-0.09437577610502174,-2.611628850483256
586.7000000000077,63.87887193746876,-0.09275774125737905,-2.6125915149370513
587.8000000000077,63.98712077479103,-0.0898073968708947,-2.6172955313256283
588.9000000000076,64.09709788797976,-0.08818994486853392,-2.620236930315534
590.0000000000076,64.20632835460958,-0.08651564765233666,-2.6243760244287415
591.1000000000076,64.31442008392705,-0.08555104257531171,-2.626186126868171
592.2000000000077,64.42250436655031,-0.08395154986028985,-2.6299401071544093
593.3000000000077,64.53367193848317,-0.08057285079764574,-2.6285666631334483
594.4000000000077,64.64227166843995,-0.07897595923058434,-2.632235997734634
595.5000000000077,64.75033537945556,-0.07703976671369281,-2.6390753337719155
596.6000000000078,64.86160499676211,-0.07730572557037353,-2.640719861874788
597.7000000000078,64.97072577878778,-0.07436817346086179,-2.6443731852005623
598.8000000000078,65.08057102076683,-0.07352687696680689,-2.6453643769045105
599.9000000000078,65.18974343718195,-0.07036382675838358,-2.64471852403331
601.0000000000078,65.29936467357041,-0.06899988990891598,-2.648297526833236
602.1000000000079,65.40849969208942,-0.06513439891298592,-2.649607550656578
603.2000000000079,65.51825192276213,-0.06474151243815457,-2.6509259968869903
604.3000000000079,65.62836704783007,-0.06188530897673958,-2.653529229308883
605.4000000000078,65.73802079398274,-0.05979746807207098,-2.6532668218363575
606.5000000000078,65.84815882200499,-0.05794179673630294,-2.6572012226558117
607.6000000000079,65.95839184080447,-0.0525609804488939,-2.6608283896309377
608.7000000000079,66.06766482216806,-0.04918588860956217,-2.662143582708609
609.8000000000079,66.1781079846462,-0.04468228604478226,-2.6634022340346846
610.9000000000079,66.28730376550992,-0.04250257058629973,-2.665999325401299
612.000000000008,66.39849698912157,-0.039769114067819064,-2.670369330142711
613.100000000008,66.50716876671908,-0.03837217343611391,-2.672921358591287
614.200000000008,66.61743277039872,-0.03706201449951989,-2.6729999380254235
615.300000000008,66.72722604160643,-0.03632906444552653,-2.6729998660479137
616.400000000008,66.83732533044513,-0.03525872543476719,-2.674410554528829
617.5000000000081,66.94854766116264,-0.03330722044848226,-2.6770586749086265
618.6000000000081,67.05680688600198,-0.03226578471851209,-2.6787111065543625
619.7000000000081,67.16740185063959,-0.031230121795282336,-2.6810373138944845
620.8000000000081,67.27689014999363,-0.030821122234335366,-2.6824797928696604
621.9000000000082,67.38668802103132,-0.028615804946077728,-2.6836277709458756
623.0000000000082,67.49724133865112,-0.025083958985149164,-2.685957875032716
624.1000000000081,67.60667730490928,-0.02245983434689374,-2.688576535241202
625.2000000000081,67.71607954366661,-0.021175719634363523,-2.6890059563472075
626.3000000000081,67.82465231001787,-0.021510686583167096,-2.6879299678691364
627.4000000000082,67.93415810419083,-0.01816090181517958,-2.6889894792613207
628.5000000000082,68.04309039434638,-0.01467006389784998,-2.690555818316117
629.6000000000082,68.15371064476307,-0.0108380187471523,-2.6928952015515994
630.7000000000082,68.2625726602273,-0.004224469556232379,-2.6956075468937053
631.8000000000083,68.37287264236754,-0.002210665349476232,-2.6985375448751445
632.9000000000083,68.48196922186297,0.0001956293729230612,-2.6990804608569796
634.0000000000083,68.5913963433588,0.0024329769514117704,-2.699009563219005
635.1000000000083,68.7013996816629,0.006803666009972876,-2.696403544083973
636.2000000000083,68.80852138772343,0.010540521433208744,-2.6963971366815844
637.3000000000084,68.91788380328424,0.01133036568397534,-2.6989715308858475
638.4000000000084,69.02965862096082,0.011589793347445324,-2.7016609642282057
639.5000000000084,69.13777147080077,0.014493822801473438,-2.7017602338247464
640.6000000000083,69.24937281998879,0.014962233623617696,-2.704388525251014
641.7000000000083,69.35898790388545,0.015489757542984671,-2.7057102511021736
642.8000000000084,69.4680038662294,0.0181782913894304,-2.7066984879945823
643.9000000000084,69.57796777831203,0.017521625486406678,-2.7080112321059406
645.0000000000084,69.68776126391566,0.018740164745471372,-2.708351722177701
646.1000000000084,69.79753121329124,0.02026157211972919,-2.710138191591073
647.2000000000085,69.90679146468342,0.020756036890983386,-2.708306334495803
648.3000000000085,70.01596845503751,0.021798113989091487,-2.708373268699982
649.4000000000085,70.12597706979761,0.019099934166375326,-2.708340111366261
650.5000000000085,70.23485403554676,0.02265028419858414,-2.709329937000055
651.6000000000085,70.34474243805344,0.02044312502563876,-2.7083600018133334
652.7000000000086,70.45436381663453,0.02023754355181995,-2.708096427687111
653.8000000000086,70.56439483127251,0.018840730050258474,-2.707052449737429
654.9000000000086,70.67397723697547,0.021154519963113284,-2.708107957011341
656.0000000000086,70.78474322122061,0.02065991875925429,-2.7124428030664927
657.1000000000087,70.89402751025177,0.01954501437790208,-2.7163106372110644
658.2000000000087,71.00327334426456,0.01960919405762282,-2.7152602830359482
659.3000000000086,71.1136974848455,0.018377231225913615,-2.7179862424789336
660.4000000000086,71.22349278881309,0.018248662329317804,-2.718345085782757
661.5000000000086,71.33361630195832,0.017351133338707376,-2.7150031250386
662.6000000000087,71.44342988908859,0.01818667939742595,-2.718549663786983
663.7000000000087,71.55338502979349,0.01677362404549653,-2.7204418611858423
664.8000000000087,71.66274187391886,0.014918840472562412,-2.723046877408091
665.9000000000087,71.7720220307236,0.015773519146179343,-2.7257869307120313
667.0000000000088,71.88313831052277,0.013688753624708084,-2.723809447153016
668.1000000000088,71.99259614582432,0.013591989096564398,-2.7194874668339795
669.2000000000088,72.10417282269108,0.012748327210012312,-2.724422741125714
670.3000000000088,72.21236418986288,0.012729930279092127,-2.725978834724288
671.4000000000088,72.3214312296628,0.011827410353783843,-2.722105029154207
672.5000000000089,72.43349742947323,0.01169423282551255,-2.717922260381062
673.6000000000089,72.5429610918443,0.008876125372401237,-2.722700357810618
674.7000000000089,72.65398643369603,0.009772843153739113,-2.724430832010717
675.8000000000088,72.76415030566099,0.010296233297258194,-2.727010696443472
676.9000000000088,72.87402946918381,0.010854115391452706,-2.7261518467221433
678.0000000000089,72.98296069487314,0.008614107556830737,-2.7245869564832903
679.1000000000089,73.09473326061236,0.007630384051404565,-2.7273885832245504
680.2000000000089,73.20445331291292,0.007402047702363457,-2.728648297970021
681.3000000000089,73.31425760885759,0.00549956440384842,-2.7306298528810924
682.400000000009,73.42472328615663,0.004673679820061218,-2.7293155401756515
683.500000000009,73.53488249723252,0.00232551956744382,-2.729319856322893
684.600000000009,73.64502015457053,0.0045850304340957085,-2.727999796984091
685.700000000009,73.75555898070473,0.0010166383048648808,-2.7266873957050133
686.800000000009,73.86561421694779,0.001672602656369185,-2.729912354774056
687.9000000000091,73.97545449630327,-0.00013783536516913186,-2.7310704157954087
689.0000000000091,74.08567617284848,-0.0008962265734622846,-2.7348811631595833
690.1000000000091,74.19481173699502,-0.0015735187151280034,-2.7349271527142625
691.2000000000091,74.30523826949806,-0.0023860151996156565,-2.7335999698668907
692.3000000000092,74.41449669342548,-0.0016133120481970002,-2.7335995047520165
693.4000000000092,74.5247561906054,-0.0025246900597386064,-2.7347983388414017
694.5000000000091,74.6344183187967,-0.0031969540632651064,-2.7350195616535053
695.6000000000091,74.74497170010254,-0.003252362344640558,-2.736429701764594
696.7000000000091,74.8551253176752,-0.005061450692011534,-2.739054614834071
697.8000000000092,74.96517235962476,-0.007205804637278142,-2.736333521867688
698.9000000000092,75.0748130354339,-0.007253988683740505,-2.7363439534558838
700.0000000000092,75.18384144681247,-0.009284457765281138,-2.73764908869557
701.1000000000092,75.292587249037,-0.0095872688555167,-2.7376538062432143
702.2000000000093,75.40581022384455,-0.010514172545982964,-2.738981116601277
703.3000000000093,75.51592269613346,-0.012771824134032966,-2.7389798511811794
704.4000000000093,75.62618577394403,-0.013448392645815746,-2.7403000045501753
705.5000000000093,75.73628097591556,-0.012727118977359543,-2.742315562305686
706.6000000000093,75.8464574978942,-0.015141846568801959,-2.7442497703719098
707.7000000000094,75.95644426779864,-0.01649772251625109,-2.7469178407340884
708.8000000000094,76.0668135720341,-0.01977030333911188,-2.7474322253157375
709.9000000000094,76.1772235360538,-0.016262638278344805,-2.7470698287496966
711.0000000000093,76.28840495928513,-0.020817133864970562,-2.7494814798173444
712.1000000000093,76.39781138936102,-0.022056358618339697,-2.7435029168715923
713.2000000000094,76.50906448682801,-0.024906417950010622,-2.7439099166245513
714.3000000000094,76.61947673153367,-0.027200713798118576,-2.7445710125320155
715.4000000000094,76.72927188871671,-0.025284199135475475,-2.7445699893875637
716.5000000000094,76.83967855665983,-0.02939980769754391,-2.745890084591127
717.6000000000095,76.94926486072012,-0.027967299260046846,-2.7482076097918355
718.7000000000095,77.05945058631755,-0.02887530044637151,-2.7485302560616605
719.8000000000095,77.16917107333725,-0.030084262042799733,-2.749509927611557
720.9000000000095,77.28009078116182,-0.031140542616756483,-2.748085259420386
722.0000000000095,77.3904336927736,-0.03247508356005508,-2.7494898340509826
723.1000000000096,77.50032069521266,-0.03190812150751175,-2.7552995803993867
724.2000000000096,77.609895608554,-0.03282073382506785,-2.7591711009100504
725.3000000000096,77.72088433944072,-0.03325192717755272,-2.75390051845978
726.4000000000096,77.83126604074819,-0.036631719071762534,-2.7507735955647856
727.5000000000097,77.94012430835976,-0.03733064372642063,-2.7486408651004552
728.6000000000097,78.05025674322246,-0.0408702757578116,-2.7486209187516297
729.7000000000096,78.16204514931003,-0.04057468365897914,-2.7514045409882897
730.8000000000096,78.27142931033917,-0.03930438389739298,-2.75248580236277
731.9000000000096,78.38292330106998,-0.0395192113086672,-2.7557676326383516
733.0000000000097,78.49256830869228,-0.042223032990888,-2.755661569148317
734.1000000000097,78.6028339577917,-0.044457435933839856,-2.7553098256147157
735.2000000000097,78.71394651470555,-0.04502689819042624,-2.754338814399424
736.3000000000097,78.82380781856773,-0.04374627313217547,-2.7566486258701066
737.4000000000098,78.9348710417365,-0.046020590943431444,-2.7566635256068865
738.5000000000098,79.0459963891554,-0.04651207667058667,-2.7579718430595523
739.6000000000098,79.15624182260653,-0.05008419281504427,-2.757956727700718
740.7000000000098,79.2670489969454,-0.04920257640080725,-2.7605999559475607
741.8000000000098,79.37815863111119,-0.04944544595736034,-2.76059995496421
742.9000000000099,79.48877599216954,-0.05289688623252506,-2.760678455708508
744.0000000000099,79.59779460367912,-0.05090328204526119,-2.7592807124173246
745.1000000000099,79.70917200414281,-0.05278682677254205,-2.761852072673496
746.2000000000098,79.82001955286292,-0.05592823645569942,-2.7619300243532137
747.0000000000099,79.9012045467393,-0.05644547720307515,-2.7619320301899606