File: 01_Data/Face_Shield/STA/N2/10K_min/Face_Shield_STA_N2_10KData_221121_R3.csv
##Temp./Â°C,Time/min,DSC/(mW/mg),Mass loss/mg
51.0,10.445729105501561,-1.7693381226193095,0.013492845835441969
52.000000000000014,10.989170000000005,-1.6179499999999982,0.01898725231918519
53.00000000000003,11.248038296569293,-1.5257920743578541,0.017992811379045293
54.00000000000004,11.452475936054109,-1.4581679468403048,0.018734161168950436
55.00000000000006,11.631325284388156,-1.4048396740666127,0.019182422675100952
56.00000000000007,11.79293373232061,-1.3590713826224539,0.0203445586825044
57.000000000000085,11.94595532392161,-1.3235882212795176,0.020089540443247067
58.0000000000001,12.091046836477211,-1.2924585094410168,0.02047197266156875
59.000000000000114,12.232012375078021,-1.2660919295048483,0.0194875016857603
60.00000000000013,12.366457676030754,-1.2411322945348149,0.020219271167039032
61.00000000000014,12.497974556846174,-1.221107092202203,0.0201823055645578
62.000000000000156,12.627276120117163,-1.2022599094918043,0.020574954722566652
63.00000000000017,12.754322103447532,-1.1852321972924849,0.022144192847846966
64.00000000000018,12.879170000000023,-1.1689599999999987,0.02150316997218038
65.0000000000002,13.001798231793147,-1.156047812151502,0.020413580892615357
66.00000000000021,13.121133660382046,-1.1423790893809223,0.020463380960502597
67.00000000000023,13.244447751086447,-1.1304300582462143,0.02174206652533961
68.00000000000024,13.361793254110635,-1.1160693167016358,0.021764400226107483
69.00000000000026,13.479170000000028,-1.104909999999997,0.021850355404732014
70.00000000000027,13.59606161187072,-1.0925694437101456,0.02203888709031787
71.00000000000028,13.708344744650294,-1.0812199287743183,0.022060054145869756
72.0000000000003,13.825208356637146,-1.0719047316752799,0.023194440781044712
73.00000000000031,13.93694337864268,-1.0607789974235557,0.022097421258897576
74.00000000000033,14.047667665454878,-1.050262331655994,0.020788538078877927
75.00000000000034,14.1612196333021,-1.039665777275301,0.023481552690584273
76.00000000000036,14.270792394451018,-1.0287356429715149,0.02473761056248236
77.00000000000037,14.381269494008746,-1.0200644404837889,0.021630774816906673
78.00000000000038,14.491178356426062,-1.0084621611079025,0.02207217920029869
79.0000000000004,14.597300478947943,-0.999965082334997,0.024639521171901713
80.00000000000041,14.708335413819183,-0.9916965331009775,0.02327974840650615
81.00000000000043,14.81400224860581,-0.9828332270829321,0.023306297465181203
82.00000000000044,14.921256888354243,-0.9737106487600079,0.023281153040086267
83.00000000000045,15.028460397403496,-0.9662365132585589,0.022682069160592455
84.00000000000047,15.133380288402702,-0.9579902037420557,0.020682682773790262
85.00000000000048,15.237358520548193,-0.9492082754363365,0.02189124517754415
86.0000000000005,15.343510862903608,-0.942146317375967,0.02197137017214068
87.00000000000051,15.446046178387391,-0.9338396639749482,0.022629524343119378
88.00000000000053,15.551838262119585,-0.9268365301338094,0.024109579130565884
89.00000000000054,15.653911597178206,-0.9200059372035004,0.023714659832274165
90.00000000000055,15.755901841936746,-0.9131995996725514,0.023850446543959514
91.00000000000057,15.858003189857639,-0.9068970424448597,0.02323531667538603
92.00000000000058,15.959914819916385,-0.900847036563981,0.02327274821395431
93.0000000000006,16.062905793088632,-0.8940379679818163,0.023284903577799554
94.00000000000061,16.162392774681752,-0.8873649136441778,0.023362922797253383
95.00000000000063,16.265038176318516,-0.879920164009006,0.023278737311335007
96.00000000000064,16.363291908072206,-0.8742071895325716,0.023235903792336643
97.00000000000065,16.46569746510878,-0.8686029652955091,0.023243726427129907
98.00000000000067,16.56558037179217,-0.8618994200440487,0.02327984182703169
99.00000000000068,16.664019008357997,-0.8571059877616699,0.02433726969885086
100.0000000000007,16.764219501519896,-0.8484388063989884,0.024653090055464233
101.00000000000071,16.863005249774304,-0.8424839483222523,0.021960912627948304
102.00000000000072,16.962865329165098,-0.8376812595895866,0.023280101412923138
103.00000000000074,17.06253758177334,-0.830124952802429,0.02393111053395991
104.00000000000075,17.16038751084628,-0.8240410643520836,0.023270068348261397
105.00000000000077,17.258441638302365,-0.818350136608676,0.02328039609626309
106.00000000000078,17.35660277667399,-0.813175797648105,0.021859099107592428
107.0000000000008,17.45710986421925,-0.8065778719788692,0.023211944333954904
108.00000000000081,17.555004196653737,-0.7999204658130336,0.023276840615566563
109.00000000000082,17.653327362954272,-0.7949638307211981,0.023276390941492586
110.00000000000084,17.749801740133996,-0.7890576472246263,0.023633533887005065
111.00000000000085,17.84789127383639,-0.7828858387458355,0.024924024789738652
112.00000000000087,17.94617022553507,-0.7783189304350709,0.023278691236221505
113.00000000000088,18.045245209953283,-0.7732106783472716,0.02326962581522629
114.0000000000009,18.14187611059177,-0.7668098421383185,0.02459128518029363
115.00000000000091,18.239951680321226,-0.7604850723122231,0.023275273052621337
116.00000000000092,18.338061715855964,-0.7543218255030084,0.023279845058544524
117.00000000000094,18.434173037127618,-0.7502080765982957,0.0232727278473579
118.00000000000095,18.532673651792585,-0.7453481413948222,0.022954896867877217
119.00000000000097,18.629969672850255,-0.7396771703919313,0.021985209327456623
120.00000000000098,18.72501158414127,-0.7348671840675991,0.023270095682721426
121.000000000001,18.824309662345993,-0.7299249073009534,0.023270463920004758
122.00000000000101,18.921582926582875,-0.7255980776861964,0.023189451404411088
123.00000000000102,19.018051434018886,-0.7187082805921547,0.023280181406499345
124.00000000000104,19.1168306635008,-0.7137444524339399,0.024640044640973358
125.00000000000105,19.213182535170056,-0.7098081588272996,0.023675409477880827
126.00000000000107,19.31177023453372,-0.7062539616585629,0.023270593914451965
127.00000000000108,19.407827174713816,-0.7024290348408461,0.024589601071959066
128.00000000000108,19.50465978485989,-0.6976033175659189,0.024388449151439673
129.0000000000011,19.602027454070015,-0.6944619211090055,0.02324561055928598
130.00000000000114,19.697568632864392,-0.6891249082110443,0.024599567994655125
131.00000000000114,19.795187623662144,-0.6845873547870878,0.023267458083012116
132.00000000000114,19.89217594038887,-0.6808191945604358,0.023271082529889853
133.00000000000117,19.987839229974927,-0.6759188737220271,0.024589806201881892
134.0000000000012,20.084810708793267,-0.6725814867937752,0.024565785278356067
135.0000000000012,20.180620595074053,-0.6692250796961908,0.023280158376325133
136.0000000000012,20.27490631979029,-0.6635721385664747,0.02327871596989528
137.00000000000122,20.373515502592863,-0.65940883444153,0.02432199997571871
138.00000000000125,20.47018506681477,-0.6554431167018127,0.023826615259482153
139.00000000000125,20.565682330748647,-0.6507058629480945,0.02390642506667806
140.00000000000125,20.662353596161132,-0.6460785531155221,0.023260027511208925
141.00000000000128,20.758208619311308,-0.6425850612371322,0.02287249770987465
142.0000000000013,20.854537559476608,-0.6386936851147639,0.02457734513571097
143.0000000000013,20.95030269046297,-0.6340769109788692,0.023930378137577257
144.0000000000013,21.044953097508806,-0.6301473858452608,0.022641049759948295
145.00000000000134,21.14162065156606,-0.6244710425233305,0.02258731733790409
146.00000000000136,21.236869944777656,-0.6203144441778631,0.023280186517930623
147.00000000000136,21.332155975107266,-0.6157791563053432,0.02196080173260384
148.00000000000136,21.42849637707163,-0.6121774860448982,0.02194459862933762
149.0000000000014,21.52330806428792,-0.6093360200618717,0.021959031957896613
150.00000000000142,21.618056143920718,-0.6032061121975345,0.02193866197880645
151.00000000000142,21.71343590822637,-0.6006763939624676,0.021960198516847385
152.00000000000142,21.809360944979588,-0.5942230353804941,0.023291234214109835
153.00000000000145,21.90489892383696,-0.5916228933937986,0.023327585878488044
154.00000000000148,21.999714952990548,-0.5876149430309242,0.023976299074905505
155.00000000000148,22.095156105346195,-0.5834060666284665,0.024589370869903426
156.00000000000148,22.18979165721902,-0.5793436767249803,0.024256303643746868
157.0000000000015,22.28515129337064,-0.575561957196182,0.024317110259495678
158.00000000000153,22.379948232565038,-0.5726211745456429,0.022100129425779436
159.00000000000153,22.474790184075815,-0.5660382038923916,0.021960007505698265
160.00000000000153,22.569355368332786,-0.564062320288787,0.022956769565944946
161.00000000000156,22.663968798099813,-0.559142261261005,0.02426995603832527
162.0000000000016,22.760252394091744,-0.5547612797825918,0.024323292440078248
163.0000000000016,22.85469730136375,-0.5534798819710243,0.023265151437281695
164.0000000000016,22.950257265282442,-0.5498615408697995,0.02296164595242356
165.00000000000162,23.045092966203836,-0.546355233980113,0.022935783089286232
166.00000000000165,23.13973961099743,-0.5434673075013376,0.024260105880367533
167.00000000000165,23.234336600449474,-0.5408021905052381,0.02286924055938311
168.00000000000165,23.329075549646788,-0.5359465835922357,0.024269976334344356
169.00000000000168,23.42482669376559,-0.5321182494372432,0.024931529972723965
170.0000000000017,23.52017621307866,-0.5294712797205853,0.0242643896355057
171.0000000000017,23.61502754772386,-0.526483489809666,0.024271438555999225
172.0000000000017,23.710349934114348,-0.5229763370905329,0.025609685393732207
173.00000000000173,23.80500225139755,-0.5198584679636818,0.02555967315962082
174.00000000000176,23.899697569498574,-0.5156395257961166,0.02557814550440085
175.00000000000176,23.99504767474143,-0.5112458845008947,0.02295116352836679
176.00000000000176,24.090592007079934,-0.5086794363081079,0.024267521392054014
177.0000000000018,24.184268829029918,-0.5052886403212592,0.022950052300067192
178.00000000000182,24.279658327438646,-0.502162039425916,0.02383633968125487
179.00000000000182,24.37495398573769,-0.4990151138179272,0.02426086877869782
180.00000000000182,24.469441946201247,-0.4961119147444343,0.024259983084227166
181.00000000000185,24.56406468289811,-0.4924438519253318,0.022949756889426354
182.00000000000188,24.657918761430434,-0.4889448966342994,0.022939963206049185
183.00000000000188,24.753406201594334,-0.48469663416991027,0.023219440887834786
184.00000000000188,24.847877097695395,-0.48325088857291787,0.024260720543048286
185.0000000000019,24.94306323747632,-0.4787906517617352,0.024173172525014053
186.00000000000193,25.03792586814262,-0.4774727140046836,0.024270051769031298
187.00000000000193,25.13144387566123,-0.47238182836096654,0.022897654363990938
188.00000000000193,25.22709064651321,-0.4690337715534979,0.024250933159172483
189.00000000000196,25.32180202244295,-0.46203703149212244,0.02294990099976424
190.000000000002,25.416211536055346,-0.45898550287129997,0.02294994463657396
191.000000000002,25.509627477281594,-0.4544163205961155,0.023602034435473485
192.000000000002,25.607315733126747,-0.44868659192855515,0.02285231097626994
193.00000000000202,25.70001738262639,-0.4433417860782816,0.02293992823915314
194.00000000000205,25.795073591288094,-0.4371448033250596,0.022951476510587376
195.00000000000205,25.890736466990127,-0.4303041341861069,0.02226487535637034
196.00000000000205,25.985872447451854,-0.42359577345644905,0.023300673086311008
197.00000000000207,26.080294342812913,-0.41805649040849496,0.023280023092119073
198.0000000000021,26.17531936361381,-0.4132099762084181,0.02328002300000076
199.0000000000021,26.27068801250618,-0.4088448260171794,0.023280023000584293
200.0000000000021,26.365267200663663,-0.40097048315187833,0.023279637768858663
201.00000000000213,26.45896198389449,-0.39973580636908335,0.024269972449876498
202.00000000000216,26.55446401002735,-0.40097375224579507,0.024245321652148988
203.00000000000216,26.648563068069027,-0.40196435107059836,0.022940193314823
204.00000000000216,26.74350225032878,-0.401196454727004,0.022940598569825
205.0000000000022,26.838708786085803,-0.40028370421765685,0.022951115349600926
206.00000000000222,26.93334978838429,-0.39720913010431713,0.023175600613973835
207.00000000000222,27.028162349365005,-0.396977264862967,0.02395599179943897
208.00000000000222,27.122728991623717,-0.3931154879579468,0.022046619890251584
209.00000000000225,27.216818350904234,-0.3909904508788728,0.021959784243341218
210.00000000000227,27.312399039169172,-0.38811036229945767,0.02078579684719184
211.00000000000227,27.40701125714737,-0.3841478713152107,0.021960048689445344
212.00000000000227,27.501862383407982,-0.38317381862465844,0.02196005310903626
213.0000000000023,27.59642990160816,-0.3800255212476909,0.021290162255984235
214.00000000000233,27.692073879805836,-0.37701027015894695,0.021629759940765325
215.00000000000233,27.78734741668917,-0.37415835795488245,0.02063676144369886
216.00000000000233,27.88111108910033,-0.37174693935107544,0.021939141353040092
217.00000000000236,27.975699104769095,-0.3696274899836305,0.02195992211656783
218.0000000000024,28.071269898024834,-0.3669057463806587,0.021601695662964104
219.0000000000024,28.165252672475393,-0.36475675647965483,0.021644069038606162
220.0000000000024,28.26036138968368,-0.36179011811202805,0.0201785910797323
221.00000000000242,28.35418409309485,-0.360561117486284,0.0215201134685854
222.00000000000244,28.449554768991888,-0.3571475610181158,0.021520110069312537
223.00000000000244,28.543648531119747,-0.35336318484809714,0.021163886409794053
224.00000000000244,28.639727987906202,-0.3509341074811638,0.021567306889615168
225.00000000000247,28.733801557579937,-0.349817401312993,0.021849920392488897
226.0000000000025,28.827644522807173,-0.3465575297540686,0.021519615088109845
227.0000000000025,28.922945586367877,-0.3445261645835098,0.021205215983034265
228.0000000000025,29.017848125367156,-0.3420225679516157,0.021520789353550285
229.00000000000253,29.113187234069215,-0.34091533863448364,0.020180452078956357
230.00000000000256,29.206656493171852,-0.33750433370410216,0.021518938468222615
231.00000000000256,29.302473285704366,-0.3353328591046485,0.021518930339312625
232.00000000000256,29.39695228317524,-0.3315470912297008,0.022509935006450377
233.0000000000026,29.491766114972027,-0.3305865073846503,0.021183000531935114
234.00000000000261,29.5867642519933,-0.32817989978380213,0.02183919297275949
235.00000000000261,29.680743570114,-0.3271998368359553,0.021935838387836526
236.00000000000261,29.7764516251266,-0.32391946953939343,0.022515583322477717
237.00000000000264,29.869965352870754,-0.3205099692762325,0.021192923124780272
238.00000000000267,29.965976644725504,-0.3177739406600937,0.02119269054157602
239.00000000000267,30.061717792991672,-0.31500076305692815,0.021189917657969737
240.00000000000267,30.155762199001938,-0.3119507646094428,0.021385420649274955
241.0000000000027,30.250181605378387,-0.31013517804521834,0.021850061253609887
242.00000000000273,30.344062574279395,-0.3099122958092393,0.022508890267976867
243.00000000000273,30.44037279046149,-0.3064928474192747,0.022282344160950984
244.00000000000273,30.534877369686516,-0.3043973747008322,0.022508283143162444
245.00000000000276,30.62856999477973,-0.30188866790955843,0.02087789031473264
246.00000000000279,30.724438548190783,-0.300227002559587,0.02215089295916073
247.00000000000279,30.819170000000256,-0.30037999999998843,0.02217997677355843
248.00000000000279,30.91364560346855,-0.2996233350719404,0.022179976548407865
249.0000000000028,31.009357736811882,-0.29718258529662445,0.02086539695836276
250.00000000000284,31.10417482181261,-0.2952598934108401,0.019552279950335816
251.00000000000284,31.199795719480804,-0.2924489442621515,0.020848034942184235
252.00000000000284,31.294197808185878,-0.2917873744809435,0.022179821205404515
253.00000000000287,31.388884837119456,-0.28998298703391634,0.022179820000538975
254.0000000000029,31.483562280486634,-0.2881787258638559,0.02218146628876294
255.0000000000029,31.578684814046262,-0.2855025993704436,0.023489844747510702
256.0000000000029,31.673733017412776,-0.2854853857684689,0.022171470940315352
257.00000000000296,31.767525335770745,-0.2829172094461717,0.020874088880061592
258.00000000000296,31.86278684726801,-0.27998085127966144,0.021952501285605663
259.00000000000296,31.958709219090007,-0.28015241443253197,0.021152235216814752
260.00000000000296,32.05368489637112,-0.2782064268354592,0.022180106276122658
261.00000000000296,32.148064863046216,-0.27641035881488524,0.02315825518386294
262.000000000003,32.24262603091344,-0.275518555953462,0.021849862173286994
263.000000000003,32.33806601950742,-0.2738136057809133,0.02184987899999591
264.000000000003,32.432158170052254,-0.27217938381533685,0.02184987899996038
265.00000000000307,32.52817840881828,-0.2713416507199949,0.021849876002632662
266.00000000000307,32.62269162659368,-0.2703771149840836,0.02087143749094711
267.00000000000307,32.71767458988932,-0.2680840708090834,0.020859878544936983
268.00000000000307,32.81185737050893,-0.26532609011161923,0.021220533966704203
269.00000000000307,32.907419953501766,-0.26542797372293275,0.021189940676038965
270.0000000000031,33.00305181117158,-0.2627111795173989,0.022160436210922008
271.0000000000031,33.097408437524216,-0.26195229771614215,0.02217971684757991
272.0000000000031,33.1914970353803,-0.25840584911797326,0.02316895587621559
273.0000000000032,33.28888587764631,-0.2577172144420624,0.023018142774413164
274.0000000000032,33.38250871058831,-0.2564621172592994,0.021373026129649197
275.0000000000032,33.47806073267603,-0.2558921033014717,0.020530192896973887
276.0000000000032,33.57147479386224,-0.25404981075887334,0.020530200265584497
277.0000000000032,33.66808463781183,-0.25280076223658016,0.01956412578649669
278.00000000000324,33.76320018499677,-0.2501450575827105,0.02085840496186986
279.00000000000324,33.85745842234876,-0.24930428243339853,0.01955019380245382
280.00000000000324,33.95345089060857,-0.24682546745514158,0.020858706382463232
281.0000000000033,34.048382964951784,-0.24564035316598182,0.02062510574009302
282.0000000000033,34.14453688171091,-0.24509651618442072,0.01953675705572344
283.0000000000033,34.23926173020052,-0.24453377510419017,0.020527155021364152
284.0000000000033,34.33472480295829,-0.24217243863689836,0.018528473089414632
285.0000000000033,34.429737670778955,-0.2406988125489054,0.01855333188730235
286.00000000000335,34.52524933404016,-0.24160416359648074,0.019208355423653067
287.00000000000335,34.62049240408119,-0.238961355787531,0.017893665263778225
288.00000000000335,34.717013258913695,-0.2373405048948501,0.017900063987049464
289.0000000000034,34.81138325657853,-0.23819175136790954,0.01790006398640731
290.0000000000034,34.90750033828583,-0.23696242979113843,0.01790341926573724
291.0000000000034,35.00223110654623,-0.2351959850648056,0.01921994168589425
292.0000000000034,35.09822161843155,-0.2332085757706539,0.019219902945621925
293.0000000000034,35.193575123871454,-0.23097683239471847,0.01790262582903246
294.00000000000347,35.289269148016686,-0.2294763600062242,0.01790896851865842
295.00000000000347,35.384830766429566,-0.2273644429977153,0.017901131955730953
296.00000000000347,35.48064524120995,-0.2256075726261916,0.01791541218304271
297.0000000000035,35.57586428289613,-0.22553471507745554,0.017930150515883092
298.0000000000035,35.67208969515291,-0.22404315549939485,0.018890084865086365
299.0000000000035,35.76722460451545,-0.22387119058503888,0.018895793380145243
300.0000000000035,35.863893383731416,-0.22053927441891427,0.01756985289417301
301.0000000000035,35.95908100536515,-0.22127867530667072,0.017569844000723478
302.0000000000036,36.0548229802084,-0.2209761620943025,0.017570508995627065
303.0000000000036,36.151294177786596,-0.21924814700554857,0.017570270775783214
304.0000000000036,36.24649502223735,-0.2179510012251742,0.01757009599884185
305.00000000000364,36.3415815475987,-0.21672727347158832,0.017568287451162234
306.00000000000364,36.43801706597031,-0.21503112052267234,0.016250083860319897
307.00000000000364,36.53294234804037,-0.21267506478649834,0.017060023299253935
308.00000000000364,36.627869713012046,-0.21211001107565094,0.01724106691626659
309.00000000000364,36.7243983284675,-0.21136820348066615,0.018537324937086375
310.0000000000037,36.82020287918959,-0.2104460445280344,0.0160397600933031
311.0000000000037,36.916761833390794,-0.2090979437248095,0.01591885140329019
312.0000000000037,37.01290979898813,-0.20814786281393782,0.0169089971217673
313.00000000000375,37.108078375844926,-0.20789573655635135,0.015600051557711048
314.00000000000375,37.20402319788514,-0.2073235780097323,0.016909796042684277
315.00000000000375,37.29977352485004,-0.20467051813058246,0.016909875998654122
316.00000000000375,37.394546435778516,-0.20373186885842462,0.01691044927939256
317.00000000000375,37.48966950928771,-0.20246596745468315,0.015599830309126261
318.0000000000038,37.587230156375234,-0.20074110700458062,0.015599876000064405
319.0000000000038,37.68459706927257,-0.20042103219803137,0.015599912151831319
320.0000000000038,37.77927221316079,-0.19963931723370268,0.014280168246677327
321.00000000000387,37.87479990691865,-0.19649966976781288,0.015600705820002503
322.00000000000387,37.97052416267922,-0.19471291589605824,0.01592008882064544
323.00000000000387,38.06730584313931,-0.19555705544152546,0.014600567750569837
324.00000000000387,38.16345350396379,-0.19411455822416437,0.014601413185367562
325.00000000000387,38.258587310075946,-0.19292687476800394,0.016580819927550117
326.0000000000039,38.354928733421495,-0.19107330317052773,0.01526193375674012
327.0000000000039,38.4517328250859,-0.19049184411338554,0.015249067342306688
328.0000000000039,38.547093212826965,-0.18993180320487116,0.01394017087615218
329.000000000004,38.64313842332069,-0.18789758435804152,0.014269542677058489
330.000000000004,38.740118520044696,-0.18750639566829705,0.01427018590260154
331.000000000004,38.835754755548855,-0.1860895893527067,0.01435674314015678
332.000000000004,38.931155524576326,-0.18332998315451585,0.012960159370241975
333.000000000004,39.025938405697026,-0.182780061500413,0.01296015896395275
334.00000000000404,39.12450453710448,-0.18065550122303123,0.011929006355803295
335.00000000000404,39.22021238011721,-0.18107625136177094,0.011640159527486205
336.00000000000404,39.31780525052248,-0.18051533994584656,0.011640122669092534
337.0000000000041,39.413579018019426,-0.17810941855374351,0.011315458238570386
338.0000000000041,39.509769157214905,-0.17808277649406334,0.010320086482744628
339.0000000000041,39.604866310417826,-0.1764628065751465,0.0116845627602844
340.0000000000041,39.702229773366646,-0.1745428366925122,0.01032296034659641
341.0000000000041,39.79984088618458,-0.1716606308473058,0.01163973017202391
342.00000000000415,39.895888445113876,-0.17374965216708624,0.012310152583173917
343.00000000000415,39.99205831798481,-0.17233652934654767,0.012300046544464038
344.00000000000415,40.08888378788443,-0.170014278496405,0.01097987468744055
345.0000000000042,40.184807176573116,-0.16904323508234056,0.010980096023280872
346.0000000000042,40.280582986925694,-0.16686856538121028,0.01098010233198643
347.0000000000042,40.37828857523558,-0.16539015911239444,0.009666861110528835
348.0000000000042,40.47413525383373,-0.1655938336584881,0.009004270245569934
349.0000000000042,40.57130289089374,-0.16410559178498732,0.009009969238613635
350.00000000000426,40.667786405614436,-0.16117181249442955,0.009540841648978393
351.00000000000426,40.76367025305258,-0.16108052120414346,0.01098010412660777
352.00000000000426,40.860403390687665,-0.15949268211092993,0.009679991037934599
353.0000000000043,40.95675576639273,-0.15818981629797263,0.009007863993645948
354.0000000000043,41.0535629689184,-0.1559042521820523,0.009341486286684741
355.0000000000043,41.14936585579018,-0.15426491116657406,0.008679843555598588
356.0000000000043,41.24621080895199,-0.15213343871690696,0.007357585874688155
357.0000000000043,41.342742608758556,-0.1512639470128337,0.0071479261992069
358.0000000000044,41.43906342855532,-0.1499669040853307,0.006699844100849894
359.0000000000044,41.5356541945186,-0.14916698930034844,0.006700217140237719
360.0000000000044,41.63215992992,-0.1478844760413842,0.005380138028571402
361.00000000000443,41.72944765120808,-0.1468574098804022,0.006701317981396393
362.00000000000443,41.82539376611487,-0.14542169617649217,0.0077499198309896045
363.00000000000443,41.92213440005567,-0.14348707790919388,0.006700020216624303
364.00000000000443,42.01838793059388,-0.14296272903286558,0.00670000099993473
365.00000000000443,42.1148541150068,-0.1409632466274479,0.006699880239347422
366.0000000000045,42.21219940849617,-0.14004105568109937,0.005379525815528474
367.0000000000045,42.30877911773893,-0.13825877882014637,0.005373923688165583
368.0000000000045,42.40440282015118,-0.13773907052811235,0.004069971340762812
369.00000000000455,42.5027943338323,-0.13647397878020714,0.0026626656041734975
370.00000000000455,42.59945700743789,-0.13508727644112123,0.0027499740573677656
371.00000000000455,42.69494369535789,-0.13577838022421065,0.002087572615055322
372.00000000000455,42.7919521790934,-0.13454255795900583,0.001533657935436139
373.00000000000455,42.888108774223426,-0.13259310469263244,0.001430131061293416
374.0000000000046,42.98475597523386,-0.1322752522012704,0.0014227102794448498
375.0000000000046,43.082242346480996,-0.1301814095351406,7.49630299061721e-05
376.0000000000046,43.17888891762531,-0.13016562280346378,0.0006726617851269268
377.00000000000466,43.276242077781454,-0.12960639185364364,0.00011221285734386299
378.00000000000466,43.372085806859864,-0.12686306470096695,-0.0012100674899020447
379.00000000000466,43.469463108577685,-0.12663370569387783,-0.0012341711413030865
380.00000000000466,43.56680856498604,-0.12548146370193577,-0.0012099840110089133
381.00000000000466,43.662677137008664,-0.12533062029235245,-0.0028532502156251027
382.0000000000047,43.76018238706032,-0.12408570669399346,-0.0035195356917698817
383.0000000000047,43.856354125676546,-0.12296441698055716,-0.0035205697640279254
384.0000000000047,43.954192936572866,-0.12157868183947569,-0.0028612981067359655
385.0000000000048,44.050404969404205,-0.11950851285810214,-0.0029003837047563152
386.0000000000048,44.14788126959613,-0.12001867763432324,-0.0028599795759225444
387.0000000000048,44.24449193845966,-0.11826446341012023,-0.003809000218564229
388.0000000000048,44.341373180296834,-0.11752250849461421,-0.0041701533015627845
389.0000000000048,44.43822479031936,-0.11676435477847896,-0.004170216957756878
390.00000000000483,44.53547043427398,-0.11465340731949465,-0.0054899707909905615
391.00000000000483,44.63203790172653,-0.11426873799903306,-0.005489872234896609
392.00000000000483,44.72927055805317,-0.11357479462547596,-0.006810040905625314
393.0000000000049,44.82544724138223,-0.11361816874297223,-0.00681061632097002
394.0000000000049,44.92226577468081,-0.11225999142555725,-0.008120136166136938
395.0000000000049,45.020653317734556,-0.11180248031363635,-0.009444336486330585
396.0000000000049,45.11793954291233,-0.11088618619538762,-0.009440502785472482
397.0000000000049,45.2132419901459,-0.10977620364242396,-0.010750342126680579
398.00000000000495,45.31101113727947,-0.10900683679324051,-0.01075001900032202
399.00000000000495,45.408227457063454,-0.10741070992968381,-0.010750019019742041
400.00000000000495,45.505658399413306,-0.10725582945139228,-0.010858856872061118
401.000000000005,45.602063187845516,-0.10762050398643193,-0.01206653451210471
402.000000000005,45.698535461568305,-0.10722623500570111,-0.011409945076296779
403.000000000005,45.79684488263626,-0.104929280211219,-0.013056631707520694
404.000000000005,45.891741896633434,-0.10492412902774155,-0.012848595970881505
405.000000000005,45.99109751829286,-0.1038940784368542,-0.015369688201857912
406.00000000000506,46.088596901801914,-0.10363488667283648,-0.01404957720002642
407.00000000000506,46.185057053663634,-0.1019597392780181,-0.01404991342716233
408.00000000000506,46.28298372327318,-0.1004440685223004,-0.015358716925624627
409.0000000000051,46.3806193538475,-0.09929169112897608,-0.018002720454988186
410.0000000000051,46.477794394441744,-0.09865832574057457,-0.017999826994160806
411.0000000000051,46.57454126368184,-0.0983404621669806,-0.017999426677465458
412.0000000000051,46.672216047107675,-0.09598370796427937,-0.01828877427868303
413.0000000000051,46.76908340778106,-0.09519460805819246,-0.01833394186813031
414.0000000000052,46.86634190606304,-0.09403448059119311,-0.019319912813855034
415.0000000000052,46.96464220679378,-0.094523106449144,-0.019319943040380316
416.0000000000052,47.061303248780106,-0.09373063749381204,-0.021924507315462805
417.00000000000523,47.158232012739944,-0.09327614016049525,-0.022939117161310918
418.00000000000523,47.25592725163418,-0.0918182024515381,-0.023263449750784204
419.00000000000523,47.35414944037815,-0.09143152441598519,-0.025909883262266398
420.00000000000523,47.44926617149514,-0.09277067511565405,-0.024589840113020678
421.00000000000523,47.548750456976215,-0.09404969767025864,-0.026876854423264263
422.0000000000053,47.646401289000394,-0.09396027658743408,-0.028209793204429623
423.0000000000053,47.74386726840843,-0.09554914958206817,-0.0282098749836317
424.0000000000053,47.841788623097926,-0.09548293955219955,-0.028191248615012654
425.00000000000534,47.93831674484414,-0.09509365822734246,-0.028202248495007964
426.00000000000534,48.037663208843036,-0.09540960030616635,-0.029530093838125104
427.00000000000534,48.13541775633057,-0.09495273685325077,-0.03085061819276458
428.00000000000534,48.2314619736528,-0.0942160026016199,-0.032160431354514074
429.00000000000534,48.32807937443313,-0.09413541575717614,-0.030833584181538143
430.0000000000054,48.427699869942316,-0.09175130732257679,-0.03269997072094988
431.0000000000054,48.52505525648514,-0.09073758132828426,-0.03347919108862207
432.0000000000054,48.62286922552391,-0.09046432698164676,-0.03248949923843103
433.00000000000546,48.720474533056645,-0.08924176951183498,-0.035017898619836174
434.00000000000546,48.8178047483047,-0.08787347661471719,-0.03791852561817777
435.00000000000546,48.91541811735603,-0.08521881114906224,-0.03930058914660428
436.00000000000546,49.013017279207304,-0.0840066307583362,-0.03930020749103935
437.00000000000546,49.110962532471646,-0.08163793969153847,-0.040627461844369606
438.0000000000055,49.20790433288887,-0.07859975629110086,-0.04216674630861661
439.0000000000055,49.306281832121755,-0.078720585509989,-0.04324493042757904
440.0000000000055,49.40405348636669,-0.07732452618275712,-0.04574837262610565
441.00000000000557,49.50098694956838,-0.07475005486509849,-0.04588375662310451
442.00000000000557,49.598903156011524,-0.07354049299079314,-0.046487332851377516
443.00000000000557,49.696092748083075,-0.07096808363340519,-0.049831649497130925
444.00000000000557,49.79218361650612,-0.06886580571706613,-0.05114995645531817
445.00000000000557,49.892696235564955,-0.06856814132890053,-0.05286583013687096
446.0000000000056,49.99058269751046,-0.06576626167930731,-0.05571105222898609
447.0000000000056,50.088585198727394,-0.06265690569811411,-0.05927935496223746
448.0000000000056,50.18545354674557,-0.060140334378421596,-0.05968165054547825
449.0000000000057,50.2847635197795,-0.05836597561844824,-0.062112112905704286
450.0000000000057,50.38293609933566,-0.05512318078821833,-0.0648809272576969
451.0000000000057,50.48079407712937,-0.05245212202600078,-0.06751891319365466
452.0000000000057,50.57961653877969,-0.04732706059933614,-0.07325035878121255
453.0000000000057,50.67758000909098,-0.044291470769552255,-0.07561236111618364
454.00000000000574,50.77593668483136,-0.04007284929160108,-0.07788702446498608
455.00000000000574,50.874098537936106,-0.03549475343817668,-0.08216666260620809
456.00000000000574,50.97149733983812,-0.03190958431932731,-0.08633134823368138
457.0000000000058,51.07046169253739,-0.02579534145286922,-0.09090456285512838
458.0000000000058,51.169074156964506,-0.020211620734643117,-0.09605719334094243
459.0000000000058,51.26635563224408,-0.014680197707218057,-0.09865316081306608
460.0000000000058,51.364571765067566,-0.008563350653653152,-0.10513449949002407
461.0000000000058,51.462844074828325,-0.002803236858518776,-0.11046712823047322
462.00000000000585,51.56048022744069,0.0055018656066133,-0.11507343842995654
463.00000000000585,51.65685863280159,0.013551726462699368,-0.12230119268461692
464.00000000000585,51.75655715889282,0.021109885185345015,-0.1290474375309758
465.0000000000059,51.855082117451474,0.0326666769004774,-0.13574688498102994
466.0000000000059,51.95253314176777,0.04172571712366831,-0.1433767865119373
467.0000000000059,52.051467170037874,0.050578841430960565,-0.15209022887910972
468.0000000000059,52.14871642932838,0.06080171364106435,-0.16210210046327678
469.0000000000059,52.24748769568241,0.07149941324088603,-0.1717213534114519
470.00000000000597,52.34565919971668,0.08418406001474121,-0.18096359293961228
471.00000000000597,52.443857890352184,0.09778218744390474,-0.1932898982125204
472.00000000000597,52.542053929611626,0.11301034013136241,-0.20566390501229304
473.000000000006,52.63948001992857,0.12537424749398052,-0.22016410876331127
474.000000000006,52.737494532862584,0.14245427746401812,-0.233479329128226
475.000000000006,52.835288988435245,0.1597350385696848,-0.2502892012273965
476.000000000006,52.933977308745206,0.1757486594534349,-0.2648482356409625
477.000000000006,53.031939781728624,0.19503223247250417,-0.28497344936793034
478.0000000000061,53.13017789358159,0.21299498475337542,-0.304898749697589
479.0000000000061,53.22743784318379,0.23305575509686405,-0.32729299113875454
480.0000000000061,53.32570172611848,0.2535967929191475,-0.351587983671795
481.00000000000614,53.42374516767096,0.2786861503059571,-0.3750005279021509
482.00000000000614,53.52125154931556,0.30380166342413845,-0.4018345749552976
483.00000000000614,53.62084037679297,0.33334258096176655,-0.4317865830121064
484.00000000000614,53.71827725342815,0.3609903247561594,-0.4644998986353941
485.00000000000614,53.81606839330067,0.3895429886754434,-0.49783217800020374
486.0000000000062,53.914658237342834,0.4188084506743222,-0.5343032313584484
487.0000000000062,54.0133387902481,0.4489350052642835,-0.5764046893555914
488.0000000000062,54.11120287215048,0.4767568226222077,-0.6174817828908079
489.00000000000625,54.21071348526179,0.5041912990218432,-0.6633973475362116
490.00000000000625,54.3088117922316,0.530203564437206,-0.7122101635958535
491.00000000000625,54.40746498277039,0.5566141154559573,-0.764040341183926
492.00000000000625,54.50634719114234,0.5790835201510646,-0.819355300649864
493.00000000000625,54.60461943913476,0.5980050203596889,-0.8755973477336454
494.0000000000063,54.70206129281613,0.6165900832084494,-0.9317423855204261
495.0000000000063,54.80104532595399,0.6296017160856346,-0.9947945776975469
496.0000000000063,54.89917000000061,0.6394200000000593,-1.0600600872230896
497.00000000000637,54.99846128207543,0.6427768044444012,-1.1279039109795752
498.00000000000637,55.09629392488016,0.64014166792956,-1.1956645992122725
499.00000000000637,55.19510219286904,0.6291569008619804,-1.2636762949376354
500.00000000000637,55.29326987890525,0.6133504595023639,-1.3345135974573177
501.00000000000637,55.39183800466075,0.5891931364050118,-1.4051074120477929
502.0000000000064,55.48944415603158,0.5588733784808205,-1.474906806855584
503.0000000000064,55.588294504621146,0.5233103992480805,-1.5416648074142203
504.0000000000064,55.68590134895979,0.4778559716331529,-1.610088417373344
505.0000000000065,55.78397127851341,0.42824491964324496,-1.6711737461110716
506.0000000000065,55.8817784633932,0.3785731128794851,-1.7335987898989211
507.0000000000065,55.98067365801039,0.3242087748297208,-1.78980581809153
508.0000000000065,56.07861214624538,0.2712318796836994,-1.843125169579329
509.0000000000065,56.17643415078316,0.22161859222988498,-1.892232941604405
510.00000000000654,56.27563078804745,0.17155166354462545,-1.938605407003295
511.00000000000654,56.37350587997423,0.12799979909261933,-1.9817722177717476
512.0000000000066,56.47198244794823,0.08716023836399864,-2.0215212641922333
513.0000000000066,56.56973397891944,0.05156663770983623,-2.057624314245147
514.0000000000066,56.66865037593266,0.018950714286021072,-2.0899437896194892
515.0000000000066,56.766564785704745,-0.008803382702330153,-2.1225661334033807
516.0000000000066,56.86589151886226,-0.03946244285723582,-2.1492470814878253
517.0000000000066,56.96299656726898,-0.06226477710417019,-2.1771696856724376
518.0000000000066,57.06076821699854,-0.08353024680446507,-2.2015799437688974
519.0000000000066,57.159944079954954,-0.1077058895152091,-2.2251179778236585
520.0000000000066,57.25877729695859,-0.12881937920884975,-2.2501432331127407
521.0000000000067,57.35853667744395,-0.14453256486529306,-2.2713847299692116
522.0000000000067,57.456122171648374,-0.1657283786497355,-2.2894158364647277
523.0000000000067,57.55436320311618,-0.17994650529527684,-2.308273794336361
524.0000000000067,57.65330456398675,-0.19602483610826904,-2.3271263300484115
525.0000000000067,57.752262178856974,-0.21189777775922386,-2.3444549112001654
526.0000000000068,57.85030237241099,-0.226663288293996,-2.3601146383004292
527.0000000000068,57.94927400690871,-0.23981183578904297,-2.374181839374663
528.0000000000068,58.04837369663262,-0.2518683953006241,-2.388673630429011
529.0000000000068,58.14645149003115,-0.2627801836555176,-2.402453084843625
530.0000000000068,58.245991935885755,-0.2741584473263533,-2.41441229820425
531.0000000000068,58.34419359241542,-0.2817959493646759,-2.4254256730023256
532.0000000000068,58.44381076841455,-0.29268267989082275,-2.4366902531616947
533.0000000000068,58.54249937063367,-0.30098473362483186,-2.4478587767789106
534.0000000000068,58.641188248950144,-0.3093225243566765,-2.4589176684333913
535.0000000000068,58.74018461823793,-0.3137184311039726,-2.470053039674818
536.0000000000068,58.83859760051509,-0.3214932393715185,-2.4799488920022865
537.0000000000069,58.93777148808792,-0.32861932489951146,-2.48926901581173
538.0000000000069,59.03712569739541,-0.333284732464166,-2.4963113642162145
539.0000000000069,59.13565746085303,-0.3392800238106385,-2.5061096057413144
540.0000000000069,59.23502486272235,-0.34435568688622864,-2.5138249224649583
541.0000000000069,59.33383419900347,-0.34864658364192086,-2.521470987298068
542.000000000007,59.430990361927,-0.35229210037722414,-2.5286999873695217
543.000000000007,59.530841970142255,-0.3546714507593522,-2.536245506873633
544.000000000007,59.63146951265562,-0.3581122980782617,-2.543775205340147
545.000000000007,59.73027351450515,-0.3634172547826119,-2.552015734404393
546.000000000007,59.82917000000066,-0.3643900000000068,-2.5590390017752225
547.000000000007,59.92926213151481,-0.3665535562318216,-2.5644062410881037
548.000000000007,60.02908138682927,-0.36872336010256157,-2.569685361190632
549.000000000007,60.127101437405386,-0.370209344807132,-2.5766895179695575
550.000000000007,60.22705654383011,-0.37188250105647386,-2.5834771513447565
551.000000000007,60.325222208214036,-0.37298983424484294,-2.588705647846573
552.000000000007,60.42451976958217,-0.3758198735366989,-2.5944116373728368
553.0000000000072,60.52373371871392,-0.37638943501163874,-2.5994072036801903
554.0000000000072,60.62268849353094,-0.3779148376461254,-2.6040728790000034
555.0000000000072,60.720878235602285,-0.3767469956102937,-2.609379769069477
556.0000000000072,60.8205466045681,-0.37861344633416344,-2.615422346049761
557.0000000000072,60.920926204618524,-0.379186810614343,-2.619608095990882
558.0000000000073,61.01812295702732,-0.38382382404252524,-2.624266675534781
559.0000000000073,61.118863992518,-0.38510284332276773,-2.6280616921970488
560.0000000000073,61.21774506947915,-0.38473518430248826,-2.6330313936196914
561.0000000000073,61.31566062013155,-0.3851636336354,-2.6362656525052635
562.0000000000073,61.415307353202344,-0.3853982786692846,-2.641125395653885
563.0000000000073,61.514664752984054,-0.3866942900068872,-2.6471593565582436
564.0000000000073,61.61358362454445,-0.386156770101635,-2.6502571608238155
565.0000000000073,61.712216683216205,-0.3857226786668721,-2.6547597304365667
566.0000000000073,61.81197263805645,-0.38748344707641774,-2.6594489035902287
567.0000000000073,61.9107501576279,-0.38792982772327494,-2.66271131475455
568.0000000000074,62.01064574329069,-0.38848929582638575,-2.6659124253401405
569.0000000000074,62.109356542205134,-0.3870939192227857,-2.66936762907035
570.0000000000074,62.207934359548254,-0.38865929552398554,-2.674870773511236
571.0000000000074,62.30747626701196,-0.38774566664860044,-2.6765083734841526
572.0000000000074,62.40687933350188,-0.3884096049034943,-2.682262381377825
573.0000000000074,62.5065304313066,-0.38714379455398906,-2.684168201671027
574.0000000000074,62.60571335085999,-0.3861161669254959,-2.6861358296988795
575.0000000000075,62.702769434540464,-0.38622648927437014,-2.6909060438509367
576.0000000000075,62.80375157273001,-0.3855585991663949,-2.6948408126897174
577.0000000000075,62.90322020754267,-0.38564218025940744,-2.6965744347927245
578.0000000000075,63.00231636861886,-0.3863628319643304,-2.699607738292851
579.0000000000075,63.1024583330469,-0.3853376067575751,-2.701222308435889
580.0000000000075,63.20158311694995,-0.38420922546633035,-2.7050112167891145
581.0000000000075,63.30089387898082,-0.38291427988140486,-2.7077329957107885
582.0000000000075,63.398759171203764,-0.38113613588320605,-2.711276304948475
583.0000000000075,63.49906494591343,-0.3808751705172887,-2.714943274453306
584.0000000000076,63.59961762603839,-0.3829213564502155,-2.7176779702119562
585.0000000000076,63.698783034123885,-0.3799131572462789,-2.721070129745668
586.0000000000076,63.797360578481474,-0.37699006542502544,-2.7229614695950994
587.0000000000076,63.89788942248924,-0.37483686398287736,-2.725679157240276
588.0000000000076,63.99781595672741,-0.375291050154577,-2.728349401439216
589.0000000000076,64.09588987770982,-0.37352471628026285,-2.7313420451493826
590.0000000000076,64.19554177659292,-0.3719659460051259,-2.7336291572044638
591.0000000000077,64.29620199129589,-0.37147906915404705,-2.7361751334497475
592.0000000000077,64.39565180867274,-0.3713881928633019,-2.7389285893639754
593.0000000000077,64.49485500720552,-0.36946495178977184,-2.740449358087985
594.0000000000077,64.59454392829826,-0.36744533842810795,-2.7431620628522055
595.0000000000077,64.69478259728295,-0.36916552771138417,-2.745772185188881
596.0000000000077,64.79479618425088,-0.3661701219484518,-2.7511051846827224
597.0000000000077,64.89380861752686,-0.36385290992357655,-2.751038379741922
598.0000000000077,64.99332109638486,-0.3622932482994792,-2.753145663348307
599.0000000000077,65.09379210432468,-0.36324046853351005,-2.7549317556873882
600.0000000000078,65.192260006019,-0.3603217832902963,-2.7563194579670207
601.0000000000078,65.2916314625073,-0.35937252520976376,-2.759186635987292
602.0000000000078,65.39011856901695,-0.3579380134938199,-2.7617002806483932
603.0000000000078,65.49165059878351,-0.35507717625735097,-2.763057290127361
604.0000000000078,65.59034186861683,-0.35521078899167696,-2.763071268285816
605.0000000000078,65.69007998868537,-0.35268726923803007,-2.7656506180010485
606.0000000000078,65.79013585845897,-0.35222075663968677,-2.7669674878216695
607.000000000008,65.88858193176125,-0.35121244306659105,-2.7697158532338078
608.000000000008,65.98781044224621,-0.348228759768574,-2.7715748925334767
609.000000000008,66.08770571874099,-0.3474165850618383,-2.7722598619188394
610.000000000008,66.18700348826178,-0.34758596396597435,-2.7762173370437493
611.000000000008,66.28679188458474,-0.3453896301547584,-2.7776349515169576
612.000000000008,66.38647046547436,-0.34572969640229245,-2.7803110317363977
613.000000000008,66.48529195478336,-0.34282184407941074,-2.7815647300261794
614.000000000008,66.58538039197482,-0.34340854682542676,-2.7827977982391983
615.000000000008,66.68430662776194,-0.34323598037704683,-2.785578227644494
616.0000000000081,66.78192739789839,-0.3420864024269655,-2.7847907673212604
617.0000000000081,66.8830134115112,-0.34194551576271337,-2.7875733211868514
618.0000000000081,66.98354679420675,-0.3420012227042914,-2.788772037092775
619.0000000000081,67.08262590733904,-0.3427983263107515,-2.7928675214343297
620.0000000000081,67.18204942188426,-0.34275685261644384,-2.792849052836196
621.0000000000081,67.28126564218486,-0.3415488467587141,-2.794189827747781
622.0000000000081,67.3806628400849,-0.3409945816382121,-2.7955100339444945
623.0000000000082,67.48011317085317,-0.34026603824975943,-2.7968304137709805
624.0000000000082,67.57994415137773,-0.3409385529254902,-2.798144195317679
625.0000000000082,67.68013928309048,-0.3390724511833395,-2.800448536017522
626.0000000000082,67.778736120624,-0.34024903131754114,-2.801764546685335
627.0000000000082,67.8788494712598,-0.34090689557239373,-2.801774869956186
628.0000000000082,67.97677628293276,-0.34048877537665845,-2.8030792029659706
629.0000000000082,68.07686082776655,-0.3411958566406944,-2.803651722598515
630.0000000000082,68.1779231564442,-0.33859520584945296,-2.8052769479656856
631.0000000000082,68.27736557702806,-0.33881225838669027,-2.805721233163093
632.0000000000083,68.37706358351332,-0.33559446827665246,-2.807039338716569
633.0000000000083,68.47696357506172,-0.3541849921088717,-2.8083831028131305
634.0000000000083,68.57660045649527,-0.36363473053933226,-2.810016331476903
635.0000000000083,68.67626420409302,-0.37362303927407664,-2.810010117017879
636.0000000000083,68.77688944138966,-0.37359751675221936,-2.811190563706515
637.0000000000083,68.87590839971068,-0.37526035033752686,-2.81132640566776
638.0000000000083,68.9767291119877,-0.3720852944069162,-2.811246554634579
639.0000000000084,69.07406921561287,-0.37394960277958444,-2.8131556244126585
640.0000000000084,69.17553219588876,-0.37201014519102726,-2.813636999978135
641.0000000000084,69.27449622947384,-0.3733647909610895,-2.8139536738941215
642.0000000000084,69.3744370631163,-0.3727674137708319,-2.815279994996562
643.0000000000084,69.47424319429858,-0.3754720338948783,-2.8165864855589753
644.0000000000084,69.5719173274727,-0.3748558136986382,-2.81794254754305
645.0000000000084,69.67271941327772,-0.3759695096163505,-2.819230036928892
646.0000000000084,69.77264188239107,-0.37908496943567116,-2.8206594420798035
647.0000000000084,69.87219713619808,-0.37852336073281445,-2.819895969791201
648.0000000000085,69.97167762805469,-0.3792141431940081,-2.8212313054322387