File: 01_Data/Concrete_Block/STA/N2/3K_min/Concrete_Block_STA_N2_3KData_230831_R1.csv
##Temp./Â°C,Time/min,DSC/(mW/mg),Mass loss/mg
29.0,16.400751462350577,-2.2839522001447854,0.005225727456186213
30.40000000000002,17.08000000000001,-2.2495200000000004,0.004619624353383145
31.80000000000004,17.65816768857909,-2.2350742098032463,0.005938041205943101
33.20000000000006,18.205193157154348,-2.2255022207551067,0.0055881567196500725
34.60000000000008,18.732482961878418,-2.2188434487943973,0.0042813129407850425
36.0000000000001,19.267286441022843,-2.212471650611854,0.0055817257703729695
37.40000000000012,19.77193530068658,-2.2075403013283514,0.005590176529758573
38.80000000000014,20.263411087776497,-2.200839039415729,0.003721960766944754
40.20000000000016,20.764050359996386,-2.1951059086351337,0.004942322570015811
41.60000000000018,21.25227131383156,-2.1921918695668126,0.005323274204116046
43.0000000000002,21.736730538006952,-2.187101859374919,0.003945274428739154
44.40000000000022,22.216848014151985,-2.183359040426927,0.003949899988886507
45.80000000000024,22.700267977175162,-2.179031123514118,0.003958613659062138
47.20000000000026,23.18160982363648,-2.1784869491580356,0.00394386376822542
48.60000000000028,23.66039496797906,-2.1728806332464106,0.0017157163694196953
50.0000000000003,24.130000000000138,-2.1675700000000004,0.003299969995291363
51.40000000000032,24.608440379068043,-2.1625959172206697,0.0009894198479658556
52.80000000000034,25.071255774049323,-2.1571914674270647,1.7199999913231068e-07
54.20000000000036,25.546672583410754,-2.153016448946314,3.0893194553627268e-06
55.60000000000038,26.021209500478264,-2.148503440846863,-0.00026259750814983107
57.0000000000004,26.493239718384128,-2.143157576014895,-0.002190047382063298
58.40000000000042,26.951482297031905,-2.1385916419908604,-0.0035098171685348234
59.80000000000044,27.43258588846644,-2.1348453686924587,-0.0035636899829967206
61.20000000000046,27.89705528603709,-2.1314820354773265,-0.004830331777799124
62.60000000000048,28.377001036872482,-2.126565613747927,-0.0051599700256605985
64.0000000000005,28.839807519226355,-2.1227514807332852,-0.005819955355904405
65.40000000000052,29.320000000000242,-2.1176199999999956,-0.005810564967172027
66.80000000000054,29.78288469475954,-2.1128440903161607,-0.005159767303615226
68.20000000000056,30.248877913397937,-2.1076782101876317,-0.00811515202213453
69.60000000000058,30.716006063270825,-2.1029877606549197,-0.007830505547064881
71.0000000000006,31.187323541386856,-2.0978552564350545,-0.009220064286655116
72.40000000000062,31.653857737976644,-2.0940062780137194,-0.009485889103912015
73.80000000000064,32.12311742298599,-2.0883891289755527,-0.008572992316008055
75.20000000000066,32.5881345728503,-2.084455558609596,-0.011200183185557933
76.60000000000068,33.05079652718863,-2.0795477323575677,-0.012190141990793713
78.0000000000007,33.512085000693666,-2.0753873898103605,-0.013169663236941354
79.40000000000072,33.993392178748756,-2.069791376614063,-0.012179974042819453
80.80000000000074,34.459367722278856,-2.065343759071435,-0.012839932303492674
82.20000000000076,34.92805598870518,-2.0609614392384397,-0.01300029046764628
83.60000000000078,35.39497422280211,-2.0564946852880888,-0.014160046500232504
85.0000000000008,35.857166434146755,-2.051517098219657,-0.013507438366401558
86.40000000000082,36.31649033276564,-2.0473625066352277,-0.01514950502016621
87.80000000000084,36.78760014507131,-2.0455387775846274,-0.0158094825287165
89.20000000000086,37.25645666777396,-2.0400804427828643,-0.015355445059438644
90.60000000000088,37.71922567300165,-2.035462283153656,-0.016689790484990752
92.0000000000009,38.183149487961,-2.0321115694736136,-0.018003862271500637
93.40000000000092,38.64624200053822,-2.0277546675322076,-0.01767999541399856
94.80000000000094,39.11169755416564,-2.023634475319198,-0.01967890636659675
96.20000000000095,39.57000000000013,-2.0225899999999974,-0.020815927226412345
97.60000000000097,40.03751588908447,-2.0171745357610824,-0.01964982800000037
99.000000000001,40.492307193078354,-2.0139537819973645,-0.018660101483605196
100.40000000000101,40.96224909689503,-2.0105615270510655,-0.020036415547547204
101.80000000000103,41.42362466766712,-2.006160173914805,-0.021298684979586202
103.20000000000105,41.889227862309724,-2.0013261573276364,-0.022620269401848248
104.60000000000107,42.3480152649336,-1.9960964528269423,-0.021132570218610702
106.0000000000011,42.810000000000414,-1.9931699999999757,-0.02094587623111055
107.40000000000111,43.271405338190924,-1.9900842507577903,-0.023599450191198912
108.80000000000113,43.73251130095976,-1.9851087769930829,-0.022290051011701895
110.20000000000115,44.19373993282523,-1.9812182602089943,-0.023255313894788632
111.60000000000117,44.65232461367594,-1.9768569675807968,-0.022294700780570498
113.0000000000012,45.115414558820746,-1.9736418690350106,-0.024918598796420888
114.40000000000121,45.575748821089036,-1.969100778582976,-0.02510289523793441
115.80000000000123,46.040682800705056,-1.966091379864801,-0.02319962213499016
117.20000000000125,46.502197887728144,-1.9631817115861434,-0.023820159363074467
118.60000000000127,46.96265809846186,-1.9594384167888526,-0.024150392477027882
120.0000000000013,47.421893106892654,-1.9553120291131632,-0.024150034211225524
121.40000000000131,47.88472122728324,-1.951371400070302,-0.024810230371319353
122.80000000000133,48.33987195518312,-1.949355910888779,-0.024579715476559016
124.20000000000135,48.80138504334423,-1.945475229265904,-0.02316987929643144
125.60000000000137,49.261969865504874,-1.942092927666256,-0.02480991599999882
127.00000000000139,49.71957812475048,-1.9388691257319386,-0.024482606704747667
128.4000000000014,50.168862576399206,-1.9366615737438286,-0.026460192000000937
129.80000000000143,50.63629290641956,-1.932234828733747,-0.026460191973152192
131.20000000000147,51.09563011069514,-1.9300790721445444,-0.02712010801490461
132.60000000000147,51.54993296034351,-1.9277167855187307,-0.025803418834684066
134.00000000000148,52.017644330451965,-1.9239473353838126,-0.028430107999139143
135.4000000000015,52.47833808288873,-1.92085211457689,-0.02876012487341706
136.80000000000155,52.93934021528567,-1.9172566704846796,-0.026790024843751592
138.20000000000155,53.39769795963419,-1.9142869362525199,-0.02711397933462134
139.60000000000156,53.8541348243267,-1.909878833782759,-0.027439897999999463
141.0000000000016,54.30950290510147,-1.9077766844794635,-0.028599126707438582
142.40000000000163,54.764978999057206,-1.905737875970299,-0.028749012166628063
143.80000000000163,55.22305495543768,-1.9019956512209015,-0.028429852783836473
145.20000000000164,55.68000000000088,-1.9005999999999734,-0.029749855999998243
146.60000000000167,56.13976411652712,-1.8967012607626332,-0.0283518857797036
148.0000000000017,56.59664747194874,-1.8930079145743504,-0.029099491178499193
149.4000000000017,57.03255543099307,-1.8909302509450276,-0.02910069750222055
150.80000000000172,57.51128229990761,-1.8891517732742882,-0.02910006703628909
152.20000000000175,57.96227277640462,-1.8861404216214888,-0.03041005599999913
153.60000000000178,58.41754454323525,-1.8838426121311198,-0.0304110292165527
155.0000000000018,58.874329000621316,-1.8811466991945267,-0.03049885632770888
156.4000000000018,59.33137461815556,-1.8794246078438483,-0.03041029421309238
157.80000000000183,59.789571016883954,-1.8768917769138052,-0.03137959179287808
159.20000000000186,60.2518345230358,-1.8771454097150766,-0.033050090813240285
160.60000000000187,60.70474275385747,-1.8736240395516588,-0.03173017584452431
162.00000000000188,61.16106062870853,-1.869736892843888,-0.033966316130435104
163.4000000000019,61.624363361125546,-1.8678501998337909,-0.0313998576869543
164.80000000000194,62.07441793342332,-1.8653347861104999,-0.033006563245810305
166.20000000000195,62.53220834310986,-1.8636200856939513,-0.03188766736298465
167.60000000000196,62.99170436009676,-1.8601683187318039,-0.03288215461963162
169.000000000002,63.44296788195639,-1.8578911828014881,-0.03292842871592505
170.40000000000202,63.896767634008874,-1.8543275167375668,-0.03425005412368343
171.80000000000203,64.34598558602323,-1.8518521270499841,-0.03297195013476184
173.20000000000203,64.79363054086915,-1.8523400958244018,-0.031609996027501364
174.60000000000207,65.26345070171267,-1.851470939868801,-0.03424993180321412
176.0000000000021,65.7212802034293,-1.8498416047650261,-0.03457560806965354
177.4000000000021,66.17454258922463,-1.8461487750992582,-0.033260163983688695
178.80000000000211,66.63191675777159,-1.84570524726478,-0.034580672829490844
180.20000000000215,67.10624844880357,-1.8434091439086422,-0.03490981458427456
181.60000000000218,67.54117553590721,-1.8395449394867012,-0.03590007936634043
183.0000000000022,67.99882458880785,-1.8396378366481152,-0.03556933628594727
184.4000000000022,68.4513348353062,-1.8390276059122599,-0.0342501215776454
185.80000000000223,68.90940422587695,-1.8362193213226154,-0.0362311511859712
187.20000000000226,69.361117979442,-1.836156307249905,-0.03525154071852299
188.60000000000227,69.8168342254996,-1.8334261748768343,-0.03760686901110599
190.00000000000227,70.27703286577042,-1.8336342059581339,-0.03779454656041148
191.4000000000023,70.73237308136548,-1.8314298701020448,-0.03623012200049569
192.80000000000234,71.1882662208417,-1.83024468904338,-0.03882927413863824
194.20000000000235,71.64819121084773,-1.829020720183509,-0.03688980384671359
195.60000000000235,72.09825383003881,-1.8264391428357065,-0.037540668607455085
197.0000000000024,72.55633841024775,-1.8252381317511712,-0.04017989000228006
198.40000000000242,73.01162646393772,-1.8243575642210845,-0.03842048508326723
199.80000000000243,73.4693389485002,-1.822503329222238,-0.03655757306030649
201.20000000000243,73.94840120067639,-1.8213509640578405,-0.039520122131591506
202.60000000000247,74.37157794809559,-1.8209093284409386,-0.04025267436613067
204.0000000000025,74.83071146869855,-1.819685514277517,-0.03864364456052005
205.4000000000025,75.28506669450157,-1.8193974964663564,-0.04059517425600445
206.8000000000025,75.7384636460464,-1.8196209199023363,-0.038531269474977314
208.20000000000255,76.19530385931262,-1.816620522830535,-0.039299948293068265
209.60000000000258,76.64590099077319,-1.8148951985054094,-0.03963016400002095
211.0000000000026,77.10126530111538,-1.8163050341995763,-0.04095016399968543
212.4000000000026,77.55307209500214,-1.8150781995168115,-0.03990457137674852
213.80000000000263,78.0031607020463,-1.8145339911639,-0.04195608398034967
215.20000000000266,78.46472944082998,-1.8135224820183913,-0.042698525928322795
216.60000000000267,78.91999733222855,-1.8137601837065684,-0.042394339962699146
218.00000000000267,79.37380322956133,-1.8130267393500634,-0.044019972738520874
219.4000000000027,79.82958587795503,-1.811609747149154,-0.0440225578892699
220.80000000000274,80.2870936593566,-1.811317232306502,-0.043849388025334335
222.20000000000275,80.73610425719939,-1.8105232813561338,-0.04266370281877574
223.60000000000275,81.19227390852527,-1.8090928428031328,-0.04446003164088497
225.00000000000279,81.64290611143026,-1.809259430015789,-0.04381001389542005
226.40000000000282,82.10124982250613,-1.8094044516141699,-0.04412847355429994
227.80000000000283,82.55551037672069,-1.8094352515161618,-0.04564816110202363
229.20000000000283,83.01328005872706,-1.808625169797462,-0.04644013999999741
230.60000000000286,83.47123090231302,-1.807919759683114,-0.04611018076679407
232.0000000000029,83.92398854886352,-1.8068901541115716,-0.04676982199986934
233.4000000000029,84.38205503494288,-1.807103268264216,-0.045938901959144296
234.8000000000029,84.83515894233412,-1.8047045079977797,-0.047650140148078
236.20000000000294,85.28325165387852,-1.8024148542996592,-0.044904267485874616
237.60000000000298,85.73472288635057,-1.8026499691783708,-0.04831599037111811
239.00000000000298,86.18212107863246,-1.8041115287700633,-0.04730981400000056
240.400000000003,86.64061815369747,-1.8045495016798685,-0.04994973959143101
241.80000000000302,87.09492972393265,-1.8041575086095252,-0.04618729216905848
243.20000000000306,87.55000000000099,-1.8046600000000441,-0.05122811998115351
244.60000000000306,87.99876459696483,-1.8050781482629552,-0.048629902529128355
246.00000000000307,88.46241222073614,-1.8048559026373057,-0.048739313609359236
247.4000000000031,88.91910519866815,-1.8045023111371647,-0.04928998164824572
248.80000000000314,89.37301754976389,-1.8046336230948414,-0.04862956266081042
250.20000000000314,89.82691902588121,-1.804152926539452,-0.050337660920578564
251.60000000000315,90.27482729258492,-1.8040240271845602,-0.05190738885043
253.00000000000318,90.73062716059356,-1.8050572738934603,-0.050297759393912234
254.40000000000322,91.18643821649141,-1.8051474146846518,-0.05019248031856982
255.80000000000322,91.64540149676377,-1.8051566910227346,-0.052785496678182664
257.20000000000323,92.08017601835417,-1.8040850506096688,-0.05325012506420235
258.60000000000326,92.55355210095418,-1.8045658065648662,-0.05259036542206896
260.0000000000033,93.0080726891934,-1.8040524342429056,-0.051952804035094946
261.4000000000033,93.46193247363172,-1.8052627574208133,-0.052871626540875294
262.8000000000033,93.92090507620203,-1.806108422973436,-0.05292008697661332
264.20000000000334,94.37700599712856,-1.8085935584556163,-0.053579832000089755
265.6000000000034,94.83526225481167,-1.8072670924395848,-0.05423991590673394
267.0000000000034,95.28966320880365,-1.807667054758957,-0.0554596647074157
268.4000000000034,95.77222988340763,-1.8052471648778485,-0.055548056071915486
269.8000000000034,96.19655613142544,-1.8072537278078071,-0.05535842984118222
271.20000000000346,96.65742534019655,-1.8070048836846535,-0.0548999702122166
272.60000000000343,97.11034302609528,-1.8111373023679165,-0.05543998300057895
274.00000000000347,97.571099327203,-1.808869284411662,-0.056642807198048484
275.4000000000035,98.02759816647172,-1.8097413112416731,-0.05511016174502714
276.80000000000354,98.48394378796695,-1.8104464536595628,-0.056409959093718154
278.20000000000357,98.94141409566343,-1.8101285752564067,-0.05579988565453009
279.60000000000355,99.38547046896949,-1.8094114753352586,-0.056775623146120946
281.0000000000036,99.85484183215615,-1.812008465344691,-0.05708097985105898
282.4000000000036,100.31198511682106,-1.8128815860851566,-0.05742238550962808
283.8000000000036,100.77107820232807,-1.8114574324508381,-0.056437002442120576
285.2000000000036,101.22821117477261,-1.8136913999851856,-0.0574115157261903
286.60000000000366,101.679997374314,-1.814579907726412,-0.056300040274689156
288.0000000000037,102.14358402644936,-1.8141742471784867,-0.060379992022087325
289.40000000000373,102.60442863538186,-1.8166943794911266,-0.057749853111586535
290.8000000000037,103.05581779294096,-1.8169207181309477,-0.059080946513722754
292.20000000000374,103.51651285031515,-1.817566564501437,-0.058743579733128826
293.6000000000038,103.97481748280029,-1.8189905138288598,-0.05984009008475688
295.00000000000375,104.4318365444054,-1.819934422715539,-0.05874114304883582
296.4000000000038,104.89176454271303,-1.8209506870007668,-0.06166440412615737
297.8000000000038,105.34775579025897,-1.8218248658111489,-0.05994016846728556
299.20000000000385,105.78964462102167,-1.8202884762198208,-0.06059980429413514
300.6000000000039,106.26159345725014,-1.8219890786431796,-0.06356820762785231
302.00000000000387,106.7209734660089,-1.8256642525232636,-0.06132964167028465
303.4000000000039,107.17067150657287,-1.8278271950493195,-0.0625687250217899
304.80000000000393,107.63486143312853,-1.829141604205699,-0.06080161314443977
306.2000000000039,108.0926631015232,-1.8294669503979808,-0.06181742964271386
307.60000000000394,108.54969686582962,-1.8298815583306953,-0.06476965267990087
309.000000000004,109.01000000000195,-1.8323800000000898,-0.06474988890509792
310.400000000004,109.46116021689156,-1.833430513118391,-0.06160287205934445
311.80000000000405,109.91916069369562,-1.8354161439176406,-0.06165203086185844
313.200000000004,110.37760205469071,-1.83694027169639,-0.06345980448815869
314.60000000000406,110.83415920613537,-1.8373712686919614,-0.061778046704433986
316.0000000000041,111.28315422175328,-1.839017116345131,-0.06400006238412015
317.40000000000407,111.7481617068863,-1.8421090417834938,-0.06335452873994418
318.8000000000041,112.20882126631001,-1.8456637538055976,-0.0630224072367298
320.20000000000414,112.66827031256953,-1.8474729304884154,-0.06433987807263675
321.6000000000042,113.12999686371772,-1.8472697908575633,-0.06597991139198989
323.0000000000042,113.5874828285192,-1.8497612103936665,-0.06742840243703307
324.4000000000042,114.04569009463424,-1.8512661671845008,-0.06598149461238911
325.8000000000042,114.48440348315214,-1.8524675276433447,-0.06837910944098846
327.20000000000425,114.96329793943158,-1.8532282474582047,-0.06535302645958119
328.60000000000423,115.42103819423224,-1.8549918785203698,-0.06685937027080469
330.00000000000426,115.8833261394981,-1.8572206449058384,-0.06817007021799482
331.4000000000043,116.34034777503405,-1.8585891243203645,-0.06653007199995598
332.80000000000433,116.7981725158212,-1.8614349098798177,-0.06621566815859481
334.20000000000437,117.25894259262306,-1.8644640319989376,-0.06816968123268508
335.60000000000434,117.71893829077908,-1.8659809664690958,-0.0694898948940077
337.0000000000044,118.17377718245207,-1.8670455501764356,-0.06849524193833689
338.4000000000044,118.63642626188482,-1.8696483356718883,-0.06787027761324538
339.8000000000044,119.09814782434458,-1.872963170157805,-0.0681806465943251
341.2000000000044,119.5593360832628,-1.8747617478923697,-0.06916048336619518
342.60000000000446,120.02584085500828,-1.8776897362512468,-0.06913854442879286
344.0000000000045,120.48374427888928,-1.8761054113385132,-0.0687941525637199
345.4000000000045,120.94335333753936,-1.878144083300753,-0.06916914381080064
346.8000000000045,121.39491427175379,-1.8805043868050504,-0.0684620997607559
348.20000000000454,121.8547911927988,-1.8808641823274321,-0.07081050174380099
349.60000000000457,122.31194199543975,-1.8842471106169005,-0.0708100319161522
351.00000000000455,122.77092714416459,-1.8878646371121421,-0.07339781904844012
352.4000000000046,123.23487753098203,-1.8900985571651667,-0.07211989000000152
353.8000000000046,123.68917587970908,-1.8899589808533652,-0.07146901060301358
355.20000000000465,124.154713900929,-1.8925627903290065,-0.0701517690622464
356.6000000000047,124.61415862659094,-1.89524955221235,-0.0701374489150659
358.00000000000466,125.07263888507387,-1.898192836876104,-0.07243997429314941
359.4000000000047,125.52897412116074,-1.902542954130674,-0.07168646690454406
360.80000000000473,125.99061347677885,-1.9049131207455952,-0.06904993568725981
362.2000000000047,126.45758967091102,-1.9084168078316475,-0.07322855562220232
363.60000000000474,126.91964958435231,-1.9104348988857272,-0.07113538201845726
365.0000000000048,127.38111947799061,-1.910388560568569,-0.07103002651102308
366.4000000000048,127.83572841198233,-1.9135802020207813,-0.07235011365957256
367.80000000000484,128.30000282390898,-1.9162201098051646,-0.07410014140738097
369.2000000000048,128.75999547055162,-1.9175498608386818,-0.07307134256836134
370.60000000000485,129.222064308757,-1.9214892386276847,-0.07432979396315753
372.0000000000049,129.68445225565515,-1.9242691245018388,-0.072145291824814
373.40000000000487,130.14532393114712,-1.9263762140139893,-0.07190990256488883
374.8000000000049,130.60346402823154,-1.9273819253712476,-0.07320739948609356
376.20000000000493,131.0671074693939,-1.9309261235350623,-0.07353563307939215
377.60000000000497,131.52932435536422,-1.9343212478801524,-0.0748529362704895
379.000000000005,131.99519854490623,-1.9381299021502156,-0.0723644211572343
380.400000000005,132.45770678652062,-1.9424098304179895,-0.0745401099997367
381.800000000005,132.92054821796359,-1.945277120409471,-0.07321867176595731
383.20000000000505,133.38453942113796,-1.9482568421166082,-0.07441026221399172
384.600000000005,133.84628244924664,-1.9504281664249044,-0.07858837449756306
386.00000000000506,134.31191392838818,-1.9515238792990734,-0.07619692528120225
387.4000000000051,134.77628689960068,-1.956297457214706,-0.07374623349411014
388.8000000000051,135.23980908673445,-1.9601619646303232,-0.07497992033407064
390.20000000000516,135.70022933428788,-1.9607530203215633,-0.07729018032783985
391.60000000000514,136.15692002295773,-1.965074430630867,-0.07521008476224278
393.0000000000052,136.6161994022081,-1.969341227572142,-0.07661977566288458
394.4000000000052,137.08283360294698,-1.974847299082727,-0.07663011033483302
395.8000000000052,137.5492797558457,-1.981443323709954,-0.07729840709690539
397.2000000000052,138.00707991125492,-1.9846611981885647,-0.07673984320359706
398.60000000000525,138.47317152676416,-1.98820836156623,-0.07739899040303522
400.0000000000053,138.94245065538414,-1.9897326352133673,-0.0757501962221161
401.4000000000053,139.4052737866253,-1.989449358827783,-0.07698791070005218
402.8000000000053,139.86681742946504,-1.9940923267145312,-0.07761946648027118
404.20000000000533,140.32489862111944,-1.996363323991078,-0.0768500959833962
405.60000000000537,140.78260585664566,-1.9968116510852731,-0.08113013817145598
407.00000000000534,141.2539919576019,-2.001378304832734,-0.07817077626206625
408.4000000000054,141.7170106965279,-2.0057018050697026,-0.0814622600805941
409.8000000000054,142.1716091163854,-2.0099234345080648,-0.080425757830767
411.20000000000545,142.64679880853515,-2.0119958773679496,-0.08276124890461833
412.6000000000055,143.1109306320298,-2.01484798404277,-0.08111788713134693
414.00000000000546,143.57557010628872,-2.019674198651204,-0.08170812327682242
415.4000000000055,144.04077737730253,-2.022378909533839,-0.08332634805703076
416.8000000000055,144.50069754671745,-2.0244785041525786,-0.08167951803953155
418.2000000000055,144.96585419616275,-2.028274039919774,-0.08299977855032115
419.60000000000554,145.42391488753933,-2.0315807499834593,-0.08299987200009573
421.00000000000557,145.9020260249714,-2.0358697152962417,-0.08234057320062105
422.4000000000056,146.3649607174467,-2.0393579539782376,-0.0852865297663814
423.80000000000564,146.8339708653228,-2.042263348812161,-0.08497015844883382
425.2000000000056,147.2955846730906,-2.0452892890700554,-0.08497096813113147
426.60000000000565,147.75791267915884,-2.0494481615633524,-0.08562363567438513
428.0000000000057,148.21472537835632,-2.0538822930268825,-0.08726951212433809
429.40000000000566,148.68680974198713,-2.058541653215981,-0.08661992399388829
430.8000000000057,149.15164711598908,-2.0617603985729795,-0.08793998033505801
432.20000000000573,149.6183378087546,-2.06540674590716,-0.08662166684479367
433.60000000000576,150.08411851101513,-2.0672945974181043,-0.0872800092736532
435.0000000000058,150.55262496990196,-2.068629515801495,-0.08922999921443209
436.4000000000058,151.01470395237916,-2.0725148730152094,-0.08590702278591866
437.8000000000058,151.4797065238082,-2.075198855880079,-0.08926012644836634
439.20000000000584,151.94045122265996,-2.079628973467174,-0.08870994330782134
440.6000000000058,152.4079035587509,-2.0860190454132552,-0.09034993274207981
442.00000000000585,152.8800000000016,-2.0905699999999183,-0.09100791007613607
443.4000000000059,153.34252749811773,-2.0929569661096865,-0.09122455007110819
444.8000000000059,153.81115454753106,-2.096620172971954,-0.08861324076580424
446.20000000000596,154.28486881667175,-2.1049181585997925,-0.09287856961746899
447.60000000000593,154.75196817330402,-2.1072701025718357,-0.09120445889048634
449.00000000000597,155.2200000000022,-2.1101999999999483,-0.09089995199999956
450.400000000006,155.6868052734791,-2.11399595619769,-0.09090907053916153
451.800000000006,156.15242062263405,-2.1158467570579633,-0.09354009944263986
453.200000000006,156.61366925634755,-2.119247460361237,-0.09189019988585789
454.60000000000605,157.07021241015056,-2.124238498669048,-0.09221981227612552
456.0000000000061,157.54265815430034,-2.129703440096635,-0.09485252068161376
457.4000000000061,158.00410037240607,-2.134742153759377,-0.09222131693189972
458.8000000000061,158.4760451559872,-2.1374193447310486,-0.09222064941634267
460.2000000000061,158.9413375693042,-2.1420933101396007,-0.09518981413918848
461.60000000000616,159.40819961443432,-2.147776421541579,-0.0951898119999055
463.00000000000614,159.87148055427517,-2.1537456415426397,-0.09517992997297853
464.4000000000062,160.34150567579232,-2.156510504701431,-0.09782000497312815
465.8000000000062,160.80128617900192,-2.1607592029150395,-0.09823407464598333
467.20000000000624,161.27121251038602,-2.1642777542650258,-0.09890996642876448
468.6000000000063,161.73925405841536,-2.168701194365042,-0.09825993911282493
470.00000000000625,162.20662861162162,-2.1741988334051476,-0.09693965847848007
471.4000000000063,162.6726746695183,-2.177646975081398,-0.09870019603659408
472.8000000000063,163.1412654400143,-2.1826167016122753,-0.10066723324073967
474.2000000000063,163.61265134976065,-2.1859429861002098,-0.09803019205115326
475.60000000000633,164.07663066967152,-2.1877511175685025,-0.0998154621344658
477.00000000000637,164.54033694156814,-2.1929189748444275,-0.10001888053755881
478.4000000000064,165.01048673980793,-2.197728669763058,-0.10133042199918219
479.80000000000643,165.48128187972267,-2.2026669440358537,-0.10396980800898792
481.2000000000064,165.9457587592096,-2.207591768755994,-0.10395805215040044
482.60000000000645,166.41756695659163,-2.2117500212726706,-0.10317126882207761
484.0000000000065,166.88682171947406,-2.215178307263436,-0.10266309760868086
485.40000000000646,167.34196030158427,-2.2207815353601585,-0.10672879729425011
486.8000000000065,167.82513543279128,-2.225121531544164,-0.10674994168712981
488.2000000000065,168.29292359617259,-2.230685800257141,-0.1057200131600684
489.60000000000656,168.76846324437076,-2.2368408264554804,-0.106195314385094
491.0000000000066,169.23544816346336,-2.240309572704666,-0.10901283106606696
492.40000000000657,169.70143852192547,-2.2449472628097373,-0.10933993421624155
493.8000000000066,170.16823732239854,-2.2500148156540063,-0.1100099655664124
495.20000000000664,170.6422159649297,-2.2531625507555684,-0.11130212084434055
496.6000000000066,171.11321109628136,-2.2612503067296914,-0.11131976969075019
498.00000000000665,171.5961633313233,-2.267501860161601,-0.11264015278381834
499.4000000000067,172.05515772859127,-2.2696206314577974,-0.11495666184247
500.8000000000067,172.52124750196313,-2.2722287092089477,-0.11438322019487668
502.20000000000675,172.98891559177918,-2.277416980186958,-0.11368489765807333
503.60000000000673,173.4571465943686,-2.2843891904436315,-0.11615010000086423
505.00000000000676,173.91988349446007,-2.289250566707688,-0.11779991057786754
506.4000000000068,174.395031756338,-2.291614102536538,-0.11779816226068851
507.8000000000068,174.8634834347665,-2.296470481769887,-0.11788349229613271
509.2000000000068,175.33651604893475,-2.301103191370452,-0.12042845598499996
510.60000000000684,175.80259883626093,-2.307700065881021,-0.11944002461314351
512.0000000000068,176.27218775711634,-2.3119003009232086,-0.12188416019238257
513.4000000000069,176.74115289116344,-2.3171601920246654,-0.12240997799978537
514.8000000000069,177.21165932621847,-2.321230808801517,-0.12306022084170776
516.2000000000069,177.68070502482087,-2.3262633684941214,-0.12405013244479735
517.600000000007,178.15000952016763,-2.3318498133104333,-0.12422130258508846
519.0000000000069,178.615838354692,-2.337397359308574,-0.12768020304562544
520.4000000000069,179.08529013551797,-2.3435994173475287,-0.1257103003879947
521.800000000007,179.557078783162,-2.3467161684685323,-0.12966488701805012
523.2000000000071,180.0234596807233,-2.351610505483933,-0.1288219330632434
524.6000000000071,180.49623451161713,-2.3563975381992956,-0.13239997399961112
526.000000000007,180.96517835299323,-2.3607316229693205,-0.13107998313275004
527.4000000000071,181.43475805780363,-2.3690992845080863,-0.13370978533935363
528.8000000000071,181.90759647038246,-2.374568665941147,-0.13339003637678415
530.2000000000071,182.38238565719018,-2.376241915529767,-0.13536187151377677
531.6000000000072,182.85262575259404,-2.3808619483770275,-0.13667632080410375
533.0000000000072,183.3206938922512,-2.3849866345949553,-0.13669565692621521
534.4000000000071,183.78854922426223,-2.3874549863419388,-0.1380211741583346
535.8000000000072,184.25685163363406,-2.395357355545031,-0.1393320452593021
537.2000000000072,184.72501454677132,-2.401401882560783,-0.1412898117901631
538.6000000000072,185.19590240045548,-2.4044017599351664,-0.1419131477367701
540.0000000000073,185.66964003608285,-2.4101535599973163,-0.1435998730912269
541.4000000000073,186.1347839253365,-2.4157209693387274,-0.14524003199257773
542.8000000000073,186.60671933521942,-2.4213834150795157,-0.1479208596371162
544.2000000000073,187.07543161559798,-2.4273126019472744,-0.14916302522001912
545.6000000000073,187.54690327125468,-2.4340706437223583,-0.1480273395441447
547.0000000000074,188.0178991782678,-2.439437550097666,-0.15182233816982604
548.4000000000074,188.4862295769488,-2.4417355041585136,-0.15320203347984673
549.8000000000075,188.95446655258942,-2.4480472143735885,-0.1555298291053906
551.2000000000074,189.42209632461308,-2.452184679052891,-0.15429995596091794
552.6000000000074,189.89592990812204,-2.45976683167367,-0.15710001154225317
554.0000000000075,190.37892132572563,-2.4685335252212344,-0.16035511111171363
555.4000000000075,190.85623261406553,-2.4714683802551507,-0.16197127057282845
556.8000000000075,191.31941886247085,-2.478261991936112,-0.16433993999192564
558.2000000000075,191.7924817072618,-2.4827931563815864,-0.1656634998389781
559.6000000000075,192.2596876551108,-2.488924785012414,-0.166999615113109
561.0000000000075,192.72885603365484,-2.49423437379207,-0.1689501598632459
562.4000000000076,193.20363258285406,-2.5013929063919904,-0.1722491695349735
563.8000000000076,193.67298198259306,-2.507537411401815,-0.1722489622662038
565.2000000000077,194.14547723927475,-2.512785815765409,-0.1743207568236418
566.6000000000076,194.62570988501673,-2.5220493305725937,-0.17488965126263345
568.0000000000076,195.0952610710446,-2.527698422704045,-0.17845532937922437
569.4000000000077,195.56604924457372,-2.533339993923905,-0.1795000900007997
570.8000000000077,196.03616100554837,-2.5384446705034818,-0.183034318933319
572.2000000000078,196.50529813901863,-2.550067681942403,-0.1837801834602617
573.6000000000078,196.97673461875308,-2.553687066137524,-0.18773694998643853
575.0000000000077,197.44629719749,-2.5579490938852105,-0.1903700184478514
576.4000000000078,197.91925030366474,-2.5644513692419753,-0.19169009013725402
577.8000000000078,198.39364904615508,-2.570756494951509,-0.19303290419123353
579.2000000000078,198.87124089507864,-2.5777063943563774,-0.19565760277554878
580.6000000000079,199.3400114692075,-2.5818098026416787,-0.198269975790196
582.0000000000078,199.8115346753007,-2.587366259417816,-0.20090015871564493
583.4000000000078,200.2847046457717,-2.5936108684359285,-0.2022212738185587
584.8000000000079,200.75543207145208,-2.6005055953435408,-0.20454288662930242
586.2000000000079,201.22372893887615,-2.608076955119142,-0.20877888871628292
587.600000000008,201.70031553127546,-2.6160930165814937,-0.20921473356472342
589.000000000008,202.17519219641292,-2.6247361312418382,-0.21265013059422433
590.4000000000079,202.64038046888192,-2.632047212696631,-0.21744628656710496
591.800000000008,203.11738297251748,-2.6406179887662593,-0.2206701367173638
593.200000000008,203.5946581433923,-2.65047128568011,-0.21956859549752838
594.6000000000081,204.06695399449663,-2.6591784471574478,-0.22593256249977145
596.0000000000081,204.54061604205566,-2.6692804142391657,-0.23074282800395896
597.400000000008,205.0111710623402,-2.677636015733836,-0.23229989316860244
598.8000000000081,205.4883572135683,-2.6878754304085772,-0.23689546936084227
600.2000000000081,205.9619110631177,-2.694810342080838,-0.24086931435479642
601.6000000000081,206.43611214255637,-2.7060137880947983,-0.24710466508507167
603.0000000000082,206.9119063587983,-2.718119728791282,-0.25200320567410595
604.4000000000082,207.38945664165394,-2.7294158001408455,-0.2560195819563593
605.8000000000081,207.86598725451609,-2.7429645701967775,-0.2612678309429728
607.2000000000082,208.34042042229666,-2.75725833783804,-0.26535151002764934
608.6000000000082,208.81126969626104,-2.769644386820608,-0.27325212899691786
610.0000000000083,209.287862042,-2.7883547249462217,-0.2798926409001088
611.4000000000083,209.76407675931446,-2.8058008995112993,-0.28642786618086724
612.8000000000083,210.2370387830347,-2.8192628520670855,-0.2916996836562107
614.2000000000083,210.71480602414897,-2.8365727501257085,-0.3005016903661506
615.6000000000083,211.190352441805,-2.8519601676760216,-0.30489805267262504
617.0000000000084,211.661813580091,-2.8649985001441083,-0.3170545827996629
618.4000000000084,212.1380231677696,-2.880068070371948,-0.323102318268365
619.8000000000084,212.60933086394095,-2.895353619440061,-0.3325420147781939
621.2000000000085,213.0884672775352,-2.9127381851065866,-0.3404540150867015
622.6000000000084,213.5645281067811,-2.9237142805497727,-0.34975687776134823
624.0000000000084,214.03756721437838,-2.943958711843632,-0.3604097824005894
625.4000000000085,214.5133817374758,-2.960973651129591,-0.3709940407492516
626.8000000000085,214.98956115117855,-2.9792630672387164,-0.38296843570382855
628.2000000000085,215.46595117118068,-2.9951122303214195,-0.3927805210367574
629.6000000000085,215.94113649074066,-3.013529649660188,-0.40289933020391766
631.0000000000085,216.41979259122166,-3.0317585091340358,-0.41686162734053456
632.4000000000086,216.89256944766376,-3.0527212515265782,-0.43040555193066954
633.8000000000086,217.37107527970267,-3.075521661823002,-0.4419649826511787
635.2000000000086,217.84922598646983,-3.0937855675651256,-0.4575422252297763
636.6000000000087,218.32525236816787,-3.114288423525184,-0.4713158272508484
638.0000000000086,218.80186071598777,-3.1305161146283678,-0.48515967898370427
639.4000000000087,219.27765519070817,-3.1525628625565836,-0.5012920038582691
640.8000000000087,219.75000516923066,-3.1715999800485406,-0.5177410097530557
642.2000000000087,220.22322836360485,-3.1937939478516992,-0.5343475310646304
643.6000000000088,220.69810443885333,-3.2148049852367193,-0.5515675950340926
645.0000000000088,221.17780557493316,-3.2350431416088075,-0.5690850554226201
646.4000000000087,221.65114125373532,-3.2587555920179807,-0.5892002476871254
647.8000000000088,222.12941442334628,-3.279343176890794,-0.6055041270009758
649.2000000000088,222.60534542499852,-3.3037422469303266,-0.6263168270132229
650.6000000000088,223.07969329841742,-3.3276023166146604,-0.6473612377864697
652.0000000000089,223.55792190794097,-3.3504541220892414,-0.6664533497146392
653.4000000000088,224.03322198380533,-3.371403468927485,-0.6882672400695595
654.8000000000089,224.51000382616326,-3.390080299456359,-0.7095307726451745
656.2000000000089,224.98497235504877,-3.4112997414687873,-0.7333507346216215
657.6000000000089,225.4588774251418,-3.433279740269044,-0.7556853474584724
659.000000000009,225.93865040978636,-3.4544412333527212,-0.7813060407147412
660.400000000009,226.4131516982306,-3.4741152601696648,-0.8032157427480229
661.800000000009,226.88967838065636,-3.490424106255845,-0.8273063765006707
663.200000000009,227.36380686907566,-3.507348563991858,-0.8546090182461943
664.600000000009,227.83865610415572,-3.5251304645486536,-0.8797005635808448
666.0000000000091,228.30816529538055,-3.5418965886236538,-0.9081680200474169
667.4000000000091,228.78856403107193,-3.553075082103251,-0.9289409192427063
668.800000000009,229.2669445663842,-3.566428402949935,-0.9612683861468287
670.2000000000091,229.74330616116484,-3.580661528880708,-0.9850909718455676
671.6000000000091,230.21596858858345,-3.585444976984033,-1.0129858292813667
673.0000000000091,230.6884055722539,-3.5959450086810127,-1.0393148660548133
674.4000000000092,231.16547925005247,-3.6037232617687915,-1.0679606610257886
675.8000000000092,231.64150186756058,-3.613541364391686,-1.0970951571110312
677.2000000000093,232.12022983914977,-3.593906776039731,-1.120616926615782
678.6000000000092,232.5864499499165,-3.5653897248331874,-1.1498682621120104
680.0000000000092,233.06103377268073,-3.575865024906848,-1.1766091281819349
681.4000000000093,233.52865488750996,-3.590232156062049,-1.202072694501783
682.8000000000093,234.0054526182911,-3.6073206807347957,-1.2337457634133702
684.2000000000094,234.4777319211395,-3.628437665621031,-1.25950170751356
685.6000000000093,234.95034135451513,-3.647071247088423,-1.287453407569036
687.0000000000093,235.42700807761616,-3.6617973350934023,-1.3168415612137676
688.4000000000094,235.90625936284107,-3.6747334466355057,-1.3456605206130527
689.8000000000094,236.39146885182282,-3.6714991447774863,-1.3747022027198046
691.2000000000094,236.87330044255987,-3.644680099222511,-1.4009891177105938
692.6000000000095,237.34570357230282,-3.586346751516397,-1.428989480463723
694.0000000000094,237.807251679347,-3.482431859081502,-1.4509016623189792
695.4000000000094,238.26138425090775,-3.33036468767783,-1.467795841021931
696.8000000000095,238.70653602456102,-3.03175958376504,-1.4813864857917403
698.2000000000095,239.16924936498663,-2.8779932773796184,-1.4840501516391655
699.6000000000096,239.64259833941531,-2.85458410119615,-1.4853787749649774
701.0000000000095,240.12502244955715,-2.846766409094088,-1.4850404426297148
702.4000000000095,240.59880031166927,-2.8482893124957287,-1.4855321506593309
703.8000000000096,241.074567826285,-2.8519722534323817,-1.4864822492781777
705.2000000000096,241.55434726521486,-2.855922326385156,-1.487021570120811
706.6000000000097,242.02383052164257,-2.8611264203538,-1.4876801288600632
708.0000000000097,242.504377098297,-2.8663742314695737,-1.4903171412372376
709.4000000000096,242.98406653040132,-2.8710891217832875,-1.4870198315825864
710.8000000000097,243.4634217033033,-2.8754186231175134,-1.4888547248302544
712.2000000000097,243.9376600538192,-2.87913371248971,-1.4861437763281375
713.6000000000097,244.41853896619685,-2.8836737332870905,-1.4889957561692997
715.0000000000098,244.89213301758588,-2.8884394833594786,-1.4880003651976428
716.4000000000098,245.36939674031845,-2.8906845951802644,-1.4873401790160807
717.8000000000097,245.84668763448633,-2.8946597518036494,-1.4876799507316925
719.2000000000098,246.3118007829926,-2.896747287788686,-1.4889950273151533
720.6000000000098,246.79701761986277,-2.899228311089519,-1.4903095386143077
722.0000000000099,247.27129382420048,-2.9027402311908217,-1.4880361541027631
723.4000000000099,247.74886954548856,-2.908739699679966,-1.4906401124525268
724.8000000000098,248.229570026754,-2.915422443455222,-1.4909601043650471
726.2000000000099,248.70663188186666,-2.919337966939676,-1.490767825622291
727.6000000000099,249.18000933987614,-2.92170122990546,-1.4926051069112103
729.00000000001,249.65146363183314,-2.9259386444284337,-1.4896498700000005
730.40000000001,250.13205993203584,-2.92634557245817,-1.4899799120000008
731.80000000001,250.60420329967707,-2.932447240487866,-1.490640037538122
733.20000000001,251.08138065748804,-2.9330878901745763,-1.4916296501543167
734.60000000001,251.5551466673268,-2.9372304689971354,-1.491198901964566
736.00000000001,252.03366358419896,-2.9399220061050446,-1.4896510388262936
737.4000000000101,252.50918626665137,-2.9440094288812735,-1.4890879964929389
738.8000000000101,252.98926657741941,-2.9480102023820307,-1.4899352379511144
740.20000000001,253.46338575449573,-2.955144641769925,-1.4887799411452556
741.6000000000101,253.94269046407624,-2.956419931087404,-1.4910852211951195
743.0000000000101,254.42084136460676,-2.9645861034951873,-1.4915320380483181
744.4000000000102,254.901205628676,-2.969958113861193,-1.489028867590061
745.8000000000102,255.36273952256184,-2.972318757218607,-1.4903100478825273
747.2000000000102,255.84895224716095,-2.976668326339244,-1.4901983312086373
748.6000000000103,256.3343540954157,-2.9760703631810506,-1.4917194143914116
750.0000000000102,256.8093737509047,-2.980016063715018,-1.4910798100178702
751.4000000000103,257.2849377954362,-2.9825164662790544,-1.4900900985865717
752.8000000000103,257.75918965115096,-2.989850742431887,-1.491298925556153
754.2000000000103,258.2450422468967,-2.992508828466979,-1.4909704962132708
755.6000000000104,258.7231118777187,-2.9933676507826172,-1.4909707705976425
757.0000000000103,259.2000000000055,-2.9936800000002863,-1.4888799399999963
758.4000000000103,259.6686849036384,-2.996118481028595,-1.4901999419564698
759.8000000000104,260.1603286772018,-2.998719017136402,-1.4905300736958953
761.2000000000104,260.6408403185292,-2.9994849003674537,-1.490530107995062
762.6000000000104,261.1200068672334,-3.0028394282813466,-1.4931599079688942
764.0000000000105,261.5960252581685,-3.0067358027484072,-1.49315825619657
765.4000000000104,262.0688030423522,-3.010496608968407,-1.4941502264046154
766.8000000000105,262.54614924661956,-3.014385376353317,-1.4928299489593533
768.2000000000105,263.02209354143844,-3.0158647496059476,-1.4944847280429756
769.6000000000105,263.50128158716035,-3.0194726163084065,-1.493820076
771.0000000000106,263.9805357080438,-3.0228815195668295,-1.4925100760039203
772.4000000000106,264.45936734350124,-3.024932604380182,-1.4934998000074882
773.8000000000106,264.9407743391455,-3.0295866921399326,-1.493499740248562
775.2000000000106,265.42113528079955,-3.0301426910333773,-1.4928927823182443
776.6000000000106,265.8987850918448,-3.030076720660226,-1.4937870088155019
778.0000000000107,266.37447539630637,-3.03275325327457,-1.4928101527262898
779.4000000000107,266.85042944224176,-3.037798142834525,-1.4958069561884386
780.8000000000106,267.33000353300287,-3.0405300274555587,-1.494149960678211
782.2000000000107,267.8114061618079,-3.0447597595597915,-1.494150393351835
783.6000000000107,268.2928787749243,-3.0443686696074215,-1.4941524601346652
785.0000000000107,268.77491587682835,-3.0450288315236747,-1.491509692570936
786.4000000000108,269.2542437685114,-3.051599220165127,-1.4924702006039974
787.8000000000108,269.73403551178785,-3.0528938477137433,-1.4924886267320057
789.2000000000108,270.2089824779052,-3.057158247338118,-1.4938129617071816
790.6000000000108,270.6851541715259,-3.058916993215729,-1.494149279320934
792.0000000000108,271.1570681171319,-3.063285412236597,-1.4944799360000784
793.4000000000109,271.63828300506174,-3.0647916389142007,-1.4961199706511081
794.8000000000109,272.1163600378071,-3.0688034254969794,-1.4921703422056418
796.200000000011,272.5936408231375,-3.069566924678644,-1.494490062786368
797.6000000000109,273.0740368304258,-3.0684147014719074,-1.4941606250811645
799.0000000000109,273.55115419886266,-3.0665140047340556,-1.4918414549585104
800.400000000011,274.02650804193723,-3.0709063788947715,-1.4948097925854111
801.800000000011,274.5023157014059,-3.0735341273823926,-1.4928298989866602
803.200000000011,274.9778009946056,-3.075253247188417,-1.4923209076262962
804.600000000011,275.45903503460227,-3.0812924645768716,-1.493816418604665
806.000000000011,275.9300000000066,-3.0844800000000596,-1.4918499895502526
807.400000000011,276.4090842049833,-3.084013348376014,-1.4944820172588584
808.8000000000111,276.88826921461146,-3.088588999511276,-1.4954698800000004
810.2000000000111,277.3693315354179,-3.088664667688153,-1.4950399439927256
811.6000000000112,277.84409279725696,-3.089713426614449,-1.4958000231435422
813.0000000000111,278.3213694899129,-3.0894339548337753,-1.494536623085342
814.4000000000111,278.80130379213375,-3.0934068867081104,-1.4967978726681763
815.8000000000112,279.28331901952885,-3.0958283794557624,-1.4945899979023731
817.2000000000112,279.7569434679486,-3.0960667924228376,-1.4932446140804432
818.6000000000113,280.2393446784642,-3.097558585221758,-1.4959212156513573
820.0000000000113,280.71347591878936,-3.096212530732719,-1.4966789370164038
821.4000000000112,281.1950885160918,-3.098968449351926,-1.4961397528324558
822.8000000000113,281.6714135571598,-3.1012803976066396,-1.4954119060459883
824.2000000000113,282.1540744890923,-3.100869041013512,-1.4957150570363158
825.6000000000113,282.62929223964693,-3.1060436998539314,-1.4970100581520578
827.0000000000114,283.1128470540975,-3.1096091794825873,-1.4970030516634467
828.4000000000113,283.59103986226984,-3.1095583675900444,-1.495046198917632
829.8000000000113,284.0666828981549,-3.1100994622974856,-1.495690133540716
831.2000000000114,284.5428475237548,-3.114801115902302,-1.49709391713158
832.6000000000114,285.02000414377085,-3.1204604629684414,-1.4983128814386548
834.0000000000115,285.49430317682607,-3.1245618280925354,-1.497000179106693
835.4000000000115,285.97751593542466,-3.1309818739030426,-1.4943712118998325
836.8000000000114,286.4600035233953,-3.1328603347278103,-1.4959130703317807
838.2000000000115,286.9345123559785,-3.134397683153194,-1.4972119934320132
839.6000000000115,287.41784975249345,-3.139073840391652,-1.4959094801861141
841.0000000000116,287.8995869401948,-3.1392576688978746,-1.5007269443611815
842.4000000000116,288.3777833016083,-3.1440425263918623,-1.4964575693486513
843.8000000000116,288.85418341075666,-3.143630741077163,-1.4961299943112834
845.2000000000116,289.3235877277363,-3.147299398915891,-1.4984301517209118
846.6000000000116,289.8053573904191,-3.1477782627990987,-1.4981038001076725
848.0000000000116,290.28311064614326,-3.152024228190517,-1.4964513984330052
849.4000000000117,290.76362954089467,-3.1529084554700493,-1.4967167951516966
850.8000000000117,291.2434845497533,-3.1535546947665813,-1.4988667283451198
852.2000000000116,291.7243214369854,-3.15716947754042,-1.4949199853853194
853.6000000000117,292.1994731491779,-3.159420214219923,-1.4959220206115802
855.0000000000117,292.68030744694147,-3.1598930155756775,-1.4985598443167114
856.4000000000118,293.1592900818491,-3.1626185413037007,-1.4985499699488556
857.8000000000118,293.63545422765594,-3.1619171470463887,-1.4977762073726146
859.2000000000118,294.1143222864387,-3.162787821023994,-1.4988716486186044
860.6000000000118,294.59000577446136,-3.164730901138905,-1.4991992183778855
862.0000000000118,295.069130853416,-3.1697769250745225,-1.4990901395155989
863.4000000000119,295.54245762170194,-3.1710865358065163,-1.4968370405138618
864.8000000000119,296.02597604829486,-3.175645973149428,-1.4983595661077547
866.2000000000119,296.5064018012057,-3.1747935507426717,-1.4968459401330887
867.600000000012,296.984756364616,-3.176536217056945,-1.4984299380172414
869.0000000000119,297.4618691136578,-3.1795250665230452,-1.497119935951214
870.4000000000119,297.9413830631907,-3.183145198019512,-1.4971222111244078
871.800000000012,298.41745130987385,-3.184668281853691,-1.497767326552157
873.200000000012,298.89778437411854,-3.1889982029831696,-1.4977801899999998
874.600000000012,299.38340209506293,-3.2011148926305597,-1.4984398693712682
876.000000000012,299.86112110379867,-3.200178882638483,-1.496899856580479
877.400000000012,300.33959852267543,-3.202821029265049,-1.4978804456772026
878.8000000000121,300.81631383844285,-3.203118015450755,-1.4985397755840397
880.2000000000121,301.2956440644897,-3.2043595422216593,-1.498870115370769
881.6000000000121,301.77558146611,-3.2083826111059492,-1.4988701620846103
883.0000000000122,302.2532272129259,-3.2157529702618106,-1.4985494520197786
884.4000000000121,302.7260200333484,-3.220813494859583,-1.50084988200354
885.8000000000122,303.2112607751057,-3.224409116620855,-1.4969206874100371
887.2000000000122,303.6879538519777,-3.2277922168986595,-1.4985102794813239
888.6000000000122,304.17034901215874,-3.2352436875704385,-1.501510311604683
890.0000000000123,304.6446629921815,-3.2382524534861488,-1.4972221513504413
891.4000000000123,305.12861492996757,-3.2432489941306226,-1.4987601498294034
892.8000000000122,305.6079025502122,-3.2489037169611183,-1.498786558910596
893.0000000000123,305.6763031098179,-3.249704993596843,-1.4974397308060716