File: 01_Data/Polyester_Carpet_High_Pile/STA/N2/10K_min/Polyester_Carpet_High_Pile_STA_N2_10KData_220909_R2.csv
##Temp./Â°C,Time/min,DSC/(mW/mg),Mass loss/mg
51.0,10.868398702047196,-1.554940134623509,0.01447509222578347
52.100000000000016,11.19591435376985,-1.4535938505298738,0.012180941394111855
53.20000000000003,11.433263567655361,-1.3834616726257896,0.013892161775857836
54.30000000000005,11.63652686895387,-1.3299049629842798,0.01258718335137532
55.40000000000006,11.819517306068128,-1.2886824243854704,0.012841981518175505
56.50000000000008,11.989722932813493,-1.2523309124211275,0.014151019015752553
57.600000000000094,12.148680132044731,-1.2262618440489743,0.012459058595779116
58.70000000000011,12.303024639486768,-1.2005595678876484,0.013389824285679808
59.800000000000125,12.453530180237586,-1.1800839543054118,0.01266519574434044
60.90000000000014,12.599546393346381,-1.1601860482967103,0.012104765558718977
62.000000000000156,12.741047647843484,-1.143137963989416,0.011798614338554003
63.10000000000017,12.880767846321527,-1.1279446259437358,0.013849237102889767
64.20000000000019,13.017103196086893,-1.1135970988089052,0.013955788649418821
65.30000000000021,13.151174654810049,-1.0995121627994235,0.012597826409903146
66.40000000000022,13.28499086071983,-1.0862739948662032,0.013616687002809158
67.50000000000023,13.416377783807006,-1.0746056556067602,0.0139112726982904
68.60000000000025,13.543531649591621,-1.06151438139716,0.01219110062669193
69.70000000000027,13.67200061129307,-1.0497772344622107,0.013594073052049627
70.80000000000028,13.799913390447058,-1.036959285783381,0.014350461060453235
71.90000000000029,13.925974722475566,-1.0258409181585986,0.012347825847821792
73.00000000000031,14.049885474937454,-1.016027480585753,0.012181081836405205
74.10000000000034,14.173497320375693,-1.0046647965160065,0.013507830835542745
75.20000000000034,14.296301690062219,-0.9958122934243667,0.013795609560924404
76.30000000000035,14.416675370483023,-0.9898453270634118,0.013522057753658778
77.40000000000038,14.53736913774799,-0.9849113358783432,0.013596237245203646
78.5000000000004,14.657702846135512,-0.978106428807051,0.012919749933848923
79.6000000000004,14.776605561744242,-0.9713169403968153,0.012189554087098209
80.70000000000041,14.894388413589764,-0.9658175895705865,0.013508068604477952
81.80000000000044,15.01263715263964,-0.9578972472154462,0.01347715801801952
82.90000000000046,15.130252617941192,-0.9510390398450085,0.012616550262777526
84.00000000000047,15.2463429714441,-0.9446332896225182,0.013496977442771563
85.10000000000048,15.361732011913677,-0.9392977637554863,0.012195819520552043
86.2000000000005,15.476542226496855,-0.9333986491859165,0.012190357142257469
87.30000000000052,15.589550995661982,-0.9261342053446449,0.01221748992744276
88.40000000000053,15.70412466268763,-0.9201808270089523,0.01087444001347615
89.50000000000054,15.816780352532026,-0.9132635448229727,0.013533799840731664
90.60000000000056,15.92927218739301,-0.9083348461319593,0.013510456543677662
91.70000000000059,16.041954844895066,-0.904394243533531,0.01273214326051475
92.8000000000006,16.154139762946958,-0.898974704619676,0.013402136168473078
93.9000000000006,16.266385258573546,-0.8907874595259331,0.013362065398944356
95.00000000000063,16.3769528676405,-0.8868018497674476,0.012079460473390036
96.10000000000065,16.488693849011035,-0.8792137402043563,0.012962608003180609
97.20000000000066,16.59779414994432,-0.8734884613726625,0.012624923200312832
98.30000000000067,16.707752966542287,-0.8659516876102262,0.010955340417309056
99.40000000000069,16.817740183047892,-0.8601981158415146,0.011443515580374264
100.50000000000071,16.927309732046307,-0.8509000492312669,0.0133676266942242
101.60000000000072,17.035808988453944,-0.8473976388975017,0.013389141177623465
102.70000000000073,17.143938633178436,-0.8403872319223962,0.012081417959809215
103.80000000000075,17.25540203916894,-0.8339894645585976,0.01206818677623378
104.90000000000077,17.363616461439427,-0.82814952179501,0.012519539227604959
106.00000000000078,17.470306288781842,-0.8219066643756622,0.013378890041123359
107.10000000000079,17.58045725507552,-0.8145596602683172,0.013172178729780715
108.20000000000081,17.688800741460533,-0.8091288250208246,0.013377590620640145
109.30000000000084,17.793416790210674,-0.8025504160224185,0.012300763816426308
110.40000000000084,17.904326123995236,-0.7956627235604051,0.013392561640349854
111.50000000000085,18.011766394015563,-0.7894983522706205,0.013273345878815679
112.60000000000088,18.120209116740632,-0.7852127536266985,0.012496048455648445
113.7000000000009,18.226921341489994,-0.7796805059701511,0.013374569316175311
114.8000000000009,18.334215730568253,-0.7719605986778212,0.01340018897474593
115.90000000000092,18.442495240663018,-0.7664952683945655,0.01279122381748321
117.00000000000094,18.549555168998214,-0.7622965752422071,0.013389583589049625
118.10000000000096,18.658197006017797,-0.7558694435641098,0.01216217715013812
119.20000000000097,18.762978753144413,-0.7492594143776231,0.012740501403765148
120.30000000000098,18.872162671676953,-0.7452921419014211,0.012084381800652189
121.400000000001,18.97721026445068,-0.7398133930961122,0.01211705176066813
122.50000000000102,19.085385121241792,-0.7363814692785292,0.011743122686666219
123.60000000000103,19.192181359743632,-0.7307697800801907,0.01148961161714146
124.70000000000104,19.299269752828156,-0.7258894434698216,0.012070738626460908
125.80000000000106,19.404550173313236,-0.7211485086631861,0.010432583961211606
126.90000000000109,19.5122512915271,-0.7165468377141602,0.0104301257448296
128.00000000000108,19.61868914961678,-0.7100307788649781,0.011379642374738985
129.1000000000011,19.724250363318983,-0.7064776008356124,0.010759724599702647
130.20000000000113,19.831680232574385,-0.699475204155698,0.011740285030610309
131.30000000000115,19.937132769446517,-0.6949933421110128,0.012074018774682838
132.40000000000117,20.0427377239357,-0.6896471604194133,0.012199538045212677
133.50000000000117,20.14884534952222,-0.6854931107358768,0.010760119487954523
134.6000000000012,20.25360226072179,-0.6800449324740667,0.011321565542613321
135.7000000000012,20.360064228573584,-0.6760143466578528,0.010758430499361094
136.8000000000012,20.465836797787183,-0.670911333472136,0.010747082775220296
137.90000000000123,20.571739634987807,-0.664949731124556,0.012126627350105057
139.00000000000125,20.67716419404448,-0.6612342055120166,0.010786646210104056
140.10000000000127,20.782216540196995,-0.6563243007490621,0.010828506957036854
141.2000000000013,20.887685573311852,-0.6518202421541808,0.0107598065127128
142.3000000000013,20.99389963712114,-0.6471955276267531,0.012080600874611935
143.4000000000013,21.098840586413687,-0.6420880290253508,0.01075624848998169
144.50000000000134,21.204825156968663,-0.6368330991169614,0.012134841757860837
145.60000000000133,21.309264611616,-0.6323955594069994,0.010760066005235824
146.70000000000135,21.41432142593584,-0.6269601926375443,0.01061629752775195
147.80000000000138,21.518702959009065,-0.6218070024603501,0.010760122986579912
148.9000000000014,21.624473260397842,-0.6162820344440687,0.011742860580842507
150.00000000000142,21.728156522887357,-0.6096040709505243,0.010749549252079937
151.10000000000142,21.834371065396674,-0.6042006232651691,0.010687977664073589
152.20000000000144,21.93816930253658,-0.5976384090255051,0.010750960099572549
153.30000000000146,22.04462561654203,-0.5915584451856503,0.01075981400469983
154.40000000000146,22.149559773437602,-0.5836376624020855,0.010759449269279742
155.50000000000148,22.253860684407943,-0.5737160557293515,0.012053286569360555
156.6000000000015,22.358770670667187,-0.5644457729553765,0.010759862661806618
157.70000000000152,22.463940840656974,-0.5558623895735124,0.01116512193462027
158.80000000000155,22.568117281455898,-0.5465970871277736,0.01109126582218467
159.90000000000154,22.674031851183027,-0.5356685050504125,0.01076200352354073
161.00000000000156,22.77748334501007,-0.5259591602577017,0.010760043099263594
162.1000000000016,22.882008785597815,-0.5136887349771243,0.01076006395425555
163.20000000000158,22.986359656569377,-0.5035550456177461,0.012083578510336146
164.3000000000016,23.092173080964045,-0.49326534565511426,0.01208004433315546
165.40000000000163,23.19630541707794,-0.48709688370878323,0.009436227258512009
166.50000000000165,23.30207555832916,-0.4868096322917909,0.011129421434623143
167.60000000000167,23.40507430953236,-0.4940089929090573,0.0120788349384231
168.70000000000167,23.510870274955934,-0.5021712261048301,0.009442146292246711
169.8000000000017,23.614304378076184,-0.5129361519781792,0.012114402143993619
170.9000000000017,23.718091187720344,-0.5223442321282941,0.010758226447213026
172.0000000000017,23.82354285610673,-0.5276820004057711,0.010759927755182641
173.10000000000173,23.928226326103246,-0.5309596102023231,0.013530063850529572
174.20000000000175,24.032733461341696,-0.5345261118582016,0.012143302098370778
175.30000000000177,24.137175610359485,-0.5323659096807158,0.011962981660570637
176.4000000000018,24.24022008983966,-0.531338715753847,0.011960151740962655
177.5000000000018,24.346222603963565,-0.5304541899457399,0.010649806900656422
178.6000000000018,24.44989490314862,-0.5279388220717877,0.010650166569329489
179.70000000000184,24.55470296405707,-0.5252573426972342,0.010432396128343235
180.80000000000183,24.659815885801518,-0.5237532303621341,0.010650052000759747
181.90000000000185,24.763751989331215,-0.5196723725816997,0.009295790924064296
183.00000000000188,24.86907491897072,-0.5174381658616495,0.009990009092104568
184.1000000000019,24.972483134652187,-0.5145205481580101,0.009045332539497686
185.20000000000192,25.077385301364544,-0.5125951649573799,0.009522624290031256
186.30000000000192,25.182389804705895,-0.508881997123803,0.00932940989883102
187.40000000000194,25.28680071339077,-0.5065189655315161,0.009330002000146553
188.50000000000196,25.39090858489828,-0.5037390520082241,0.009330001999981352
189.60000000000196,25.495062704294828,-0.4999365885290552,0.009329998838598641
190.70000000000198,25.596810285226752,-0.4965350185960191,0.009208296071628652
191.800000000002,25.703467629661986,-0.49325327453573603,0.010625363624911621
192.90000000000202,25.808222626558887,-0.4894634477348117,0.010430221912252957
194.00000000000205,25.912737564394245,-0.48837326562871675,0.009110768915761902
195.10000000000204,26.01677446380513,-0.48468945186513424,0.010429854836546237
196.20000000000206,26.120512245158253,-0.48266544239094006,0.00911004163210638
197.3000000000021,26.22441968228508,-0.4805324341498871,0.010418202993826231
198.40000000000208,26.32956520457791,-0.4753509173997182,0.009118752640023153
199.5000000000021,26.43332656313895,-0.4729659172232743,0.007800080999255776
200.60000000000213,26.538319207799393,-0.47002803899942835,0.008443125267878937
201.70000000000215,26.64177704605867,-0.46767297341835995,0.008450128773016985
202.80000000000217,26.74557431577885,-0.4628572244641227,0.009760132456627435
203.90000000000217,26.85063200115323,-0.4602044724128394,0.009829659001130864
205.0000000000022,26.954725165637175,-0.45577187332403335,0.009110050297685302
206.1000000000022,27.060543503132934,-0.45306511940828986,0.0077606238308152165
207.2000000000022,27.163274562396346,-0.45211645011221857,0.009097156194239897
208.30000000000223,27.268143201069478,-0.4475846483499264,0.008007531037248494
209.40000000000225,27.372388178992026,-0.444728947721445,0.007808902048713318
210.50000000000227,27.475732492835473,-0.442763171996882,0.008461970952885256
211.6000000000023,27.579762999573507,-0.4378062472742948,0.007795386461677101
212.7000000000023,27.685050903574883,-0.4340592482857962,0.007164610310164576
213.8000000000023,27.789712432965178,-0.43084716064455986,0.008440533391835814
214.90000000000234,27.892933528571238,-0.4264454184632288,0.00714197489995172
216.00000000000233,27.997092033174788,-0.42339005966687054,0.007062106128047141
217.10000000000235,28.10151339177738,-0.42001803116714137,0.007129896042521899
218.20000000000238,28.205873449961732,-0.4178437378682531,0.007129896000003022
219.3000000000024,28.31047749619556,-0.41384079627728443,0.0071298981511263015
220.40000000000242,28.41600722685532,-0.4106263884189991,0.0072117231783965785
221.50000000000242,28.519369056901343,-0.40786090053796,0.00712668418542961
222.60000000000244,28.623540022726356,-0.40397589495604425,0.005162137747807716
223.70000000000246,28.72667754032515,-0.40133651097792056,0.006301803211237633
224.80000000000246,28.833469346962904,-0.39705206437486623,0.006478178440974869
225.90000000000248,28.936926219497018,-0.3945238058618153,0.006149967075009144
227.0000000000025,29.041637574900445,-0.3911154691876979,0.006149968255606986
228.10000000000252,29.146014923136935,-0.3867425873053132,0.005740203614272854
229.20000000000255,29.250876624537632,-0.38263168224586164,0.005793009258602044
230.30000000000254,29.35284919847559,-0.37886910669590274,0.005320644462300184
231.40000000000256,29.46018955919112,-0.3746671535000927,0.005820058505800585
232.5000000000026,29.563126751231255,-0.36660191426736577,0.0061500240197145395
233.60000000000258,29.668424619377213,-0.36331693332917936,0.004833107813083881
234.7000000000026,29.769835912285163,-0.3573619031412002,0.005489807901401189
235.80000000000263,29.87650162582457,-0.3511325255005394,0.004118674074976791
236.90000000000265,29.981310771483532,-0.3453163169564674,0.004182332708823289
238.00000000000267,30.085133580539214,-0.33735328723490776,0.004098385508759517
239.10000000000267,30.187406414306643,-0.32927963966699225,0.003520054530694594
240.2000000000027,30.295095271412706,-0.318779537082467,0.0045002748744789045
241.3000000000027,30.398962072999794,-0.3091942265708274,0.0045000444641520865
242.4000000000027,30.501771770917877,-0.29575296510462273,0.001907677648009365
243.50000000000273,30.606364009042135,-0.27655794245302173,0.0031802650659549236
244.60000000000275,30.71319554579763,-0.2538485285321372,0.003180039999767015
245.70000000000277,30.817310248240094,-0.2242598007801895,0.0031800400108168425
246.8000000000028,30.920556775948587,-0.18444751690556324,0.0034801514746916062
247.9000000000028,31.026569635557344,-0.13696714184759315,0.0042645880530578495
249.0000000000028,31.132099166283826,-0.08503730305702982,0.0032084211045493305
250.10000000000284,31.236316311244046,-0.054281192981000696,0.0031799400010674717
251.20000000000283,31.341733151859824,-0.04870266889913149,0.003178527968427769
252.30000000000285,31.445636284610345,-0.07641475776843254,0.001869942443526007
253.40000000000288,31.551263791407273,-0.12251496938411086,0.0018699399999948518
254.5000000000029,31.65655932813264,-0.17627762716255424,0.0018699400000024013
255.60000000000292,31.76053271847383,-0.22119056889727665,0.0018699380177826797
256.7000000000029,31.86450938349303,-0.25555658086483063,0.0005200369304860786
257.8000000000029,31.969170916837893,-0.2803402179530811,0.000561117467091865
258.90000000000293,32.073344607888814,-0.2979346081195372,-0.000770059609593865
260.00000000000296,32.17760869631634,-0.30889875560011404,-0.0007700598845525874
261.100000000003,32.28171459867621,-0.3190332239668246,-0.0004230662929560758
262.200000000003,32.38692484821893,-0.3241112226712612,-0.0004418603269482624
263.300000000003,32.49123187797554,-0.32594251311520256,-0.0010300387253159293
264.40000000000305,32.596084145160624,-0.328432926994736,0.00022038292176551622
265.50000000000307,32.70033617309169,-0.32960594433172097,-0.0004432786928370014
266.6000000000031,32.80507237623392,-0.3293771377906519,-0.0004401100004010061
267.7000000000031,32.91033037202275,-0.32829655311592204,-0.0004400611561279355
268.8000000000031,33.014031299916425,-0.3284261740965088,-0.0027507863798867938
269.9000000000031,33.11917104635629,-0.32578989594203905,-0.0027498379982957566
271.0000000000031,33.22407463869743,-0.32626308579102375,-0.0027475613786602793
272.10000000000315,33.32801269177005,-0.3231979226723797,-0.0014299064327958355
273.2000000000032,33.43325442955414,-0.3222408647289953,-0.002739881449134174
274.30000000000314,33.53775215651404,-0.3212214720233213,-0.0037297755786585007
275.40000000000316,33.64268514044106,-0.3194020064599706,-0.003730060000589841
276.5000000000032,33.746788143288065,-0.3183403511485452,-0.003730059995625812
277.6000000000032,33.852212166255,-0.3160665021631194,-0.0037281290683806034
278.70000000000323,33.956780399527176,-0.3147511890829831,-0.005050077720410329
279.80000000000325,34.062647166878925,-0.3116915663724121,-0.005050059999987422
280.9000000000033,34.16655738689709,-0.31073030132182644,-0.005050046863381841
282.0000000000033,34.27238127716968,-0.30867196319760193,-0.005379120464346965
283.1000000000033,34.3767496898076,-0.3076197901917373,-0.005379837999333947
284.20000000000334,34.481475385252175,-0.3052444560615092,-0.005379837999993864
285.30000000000337,34.586814341806885,-0.3037130400930204,-0.005403461672436105
286.40000000000333,34.69165423263103,-0.3009953102757588,-0.006699837834119204
287.50000000000335,34.79488167785723,-0.3005529001132303,-0.006699837999998959
288.6000000000034,34.90180582337768,-0.2979843495994588,-0.006699837999775138
289.7000000000034,35.00711764893083,-0.2975368102278434,-0.006699663588970228
290.8000000000034,35.112617719437246,-0.29431475425952924,-0.009323825772611372
291.9000000000034,35.21678267737103,-0.29151116544255795,-0.00808270997461813
293.0000000000034,35.322689495909984,-0.2899428515599919,-0.008680168168447189
294.10000000000343,35.42834771007073,-0.2877651100210581,-0.009722680089553126
295.20000000000346,35.53355913020416,-0.2856498025797223,-0.01031388139422118
296.3000000000035,35.63843718838586,-0.2820350886082558,-0.011300182914798285
297.4000000000035,35.744543875650955,-0.2788868823556984,-0.011300181999996273
298.5000000000035,35.850268135928765,-0.27669873300642234,-0.011300182000009151
299.60000000000355,35.95460314548435,-0.2722898050490783,-0.011300168191005433
300.70000000000357,36.060311994717495,-0.2689530816562477,-0.013808047669729984
301.8000000000036,36.16468876438835,-0.2646705252885904,-0.014050006951761507
302.9000000000036,36.27029390826019,-0.2624473688057568,-0.013720110917608608
304.0000000000036,36.37587838741989,-0.2578098218787015,-0.015091943128294538
305.1000000000036,36.481089663788445,-0.25313427087309653,-0.015019078806682629
306.2000000000036,36.58615689096822,-0.2500381466167109,-0.01636209682775691
307.30000000000365,36.69137841138399,-0.2449319050374474,-0.017690730296581858
308.4000000000037,36.79680033554792,-0.24027086884698118,-0.016604848268694017
309.5000000000037,36.90306053490555,-0.23566657338184352,-0.019319753087424285
310.60000000000366,37.00825686244586,-0.2329242929340162,-0.020639716009621
311.7000000000037,37.11334344213868,-0.22713455630872068,-0.020639594153812446
312.8000000000037,37.2180944680101,-0.22300501102578352,-0.02327995185341658
313.90000000000373,37.325365883868095,-0.22026205714592795,-0.023272163138952973
315.00000000000375,37.43138271056408,-0.2177906500567303,-0.02459004917873875
316.1000000000038,37.53750456990852,-0.21539360511221617,-0.02590735527549093
317.2000000000038,37.6421871289312,-0.21479098180593723,-0.02722462369781775
318.3000000000038,37.74773459526507,-0.21584366472686514,-0.029521820760988415
319.40000000000384,37.854265712676145,-0.21412389194337303,-0.0308409192476371
320.5000000000038,37.9595274525009,-0.2171367772463312,-0.03249947280844667
321.60000000000383,38.06564692096811,-0.21753937071540108,-0.03512913414931029
322.70000000000385,38.1724689451883,-0.2195423472798289,-0.03643788915075419
323.8000000000039,38.2794575784023,-0.2213760616129028,-0.03776067245107573
324.9000000000039,38.383931645641155,-0.2225699561515736,-0.04037582284142527
326.0000000000039,38.490965707657516,-0.22431345806736003,-0.04303375256997777
327.10000000000394,38.59726160428725,-0.22468440075806506,-0.04644078275740071
328.2000000000039,38.703459897213364,-0.22561533429085576,-0.04828085389412706
329.30000000000393,38.808171244277,-0.22810831132122686,-0.04992306989601181
330.40000000000396,38.91466345819872,-0.22734278070164915,-0.052581109235426915
331.500000000004,39.02114241096063,-0.22768426509223919,-0.05539578198292183
332.600000000004,39.126462887661475,-0.22861093522678677,-0.05942051292900841
333.700000000004,39.233375073713965,-0.22764167198267402,-0.06376754832638953
334.80000000000405,39.338980274205106,-0.22706296125201442,-0.06784961100652032
335.90000000000407,39.44574405110562,-0.22761207626729796,-0.07195403884503415
337.0000000000041,39.55150794626362,-0.23025051234197172,-0.07486560760885341
338.10000000000406,39.658149246299395,-0.23110471374697655,-0.08081013624337219
339.2000000000041,39.76423766148719,-0.23115501739145983,-0.08810601018907738
340.3000000000041,39.870920847610066,-0.23115312144576108,-0.09073551318612072
341.4000000000041,39.97533401686806,-0.23198255542414167,-0.09400757880146227
342.50000000000415,40.082979513399245,-0.22933429798171498,-0.09815298241625703
343.6000000000042,40.18926982048535,-0.22940084208064943,-0.1038591979054364
344.7000000000042,40.29526505553493,-0.22897349345134718,-0.108512419456825
345.80000000000416,40.39866547992288,-0.22696737862487443,-0.1141673167100361
346.9000000000042,40.507370344277206,-0.22592846917496665,-0.12032633862061326
348.0000000000042,40.61364238390358,-0.22640929435417464,-0.12584452656444833
349.10000000000423,40.720310391427134,-0.2269418729060953,-0.13051290888136924
350.20000000000425,40.82665612923323,-0.22499854828769875,-0.13720061268483752
351.3000000000043,40.93366492812743,-0.22355397060352,-0.1464169046313053
352.4000000000043,41.03936038608984,-0.22242722729115375,-0.15204712439225299
353.5000000000043,41.144974847796725,-0.21970651427095886,-0.15659135617233844
354.60000000000434,41.25151912276292,-0.21805699633972223,-0.15943649627480116
355.7000000000043,41.359070479615696,-0.21629691811823062,-0.16402615417376598
356.80000000000433,41.462195641177026,-0.2142037949229211,-0.1714388047208324
357.90000000000435,41.5705034416075,-0.2138805311130839,-0.17677523516546545
359.0000000000044,41.67720046808467,-0.21242775039765116,-0.18381571803769603
360.1000000000044,41.781244497717175,-0.21140236282167654,-0.18856785169363377
361.2000000000044,41.88925970689423,-0.2093239575734214,-0.19463784725575506
362.30000000000445,41.995876416677945,-0.20980272261048938,-0.19932680186560736
363.4000000000044,42.10179841673811,-0.20867709500858503,-0.20662572789702915
364.50000000000443,42.208813910020545,-0.20559735617389957,-0.21358951133358106
365.60000000000446,42.31471552268813,-0.20568140889743353,-0.22128684624064565
366.7000000000045,42.422326071582006,-0.20485657644696117,-0.2284557526861355
367.8000000000045,42.528228138593434,-0.2039302452347437,-0.233085367755673
368.9000000000045,42.63406675946802,-0.20367745360843278,-0.23438730928119034
370.00000000000455,42.74106764132745,-0.20402410316194283,-0.2356998756000137
371.10000000000457,42.84749184553707,-0.20541866514910204,-0.23910671656894644
372.2000000000046,42.95407577392711,-0.20451467573473017,-0.24469759159757443
373.30000000000456,43.06029720630367,-0.20410904873693686,-0.25435740361684633
374.4000000000046,43.16782521434866,-0.20378061687341703,-0.2625009070406987
375.5000000000046,43.27404871470966,-0.20392189426905213,-0.2711255318636536
376.6000000000046,43.38136767551278,-0.20367680638786814,-0.2798409226868661
377.70000000000465,43.48824462774953,-0.20333171592509608,-0.286105103346173
378.8000000000047,43.59476633573956,-0.20265667697302991,-0.2914162376083409
379.9000000000047,43.7010654057475,-0.20325714874129377,-0.29765382867651224
381.00000000000466,43.80867011036518,-0.20325299521039364,-0.30308810308993994
382.1000000000047,43.91542771492744,-0.20360399119063124,-0.30964246664624007
383.2000000000047,44.02149923554257,-0.20390262784383736,-0.3176594692670007
384.30000000000473,44.128367269114946,-0.20386337292543752,-0.3242618250306335
385.40000000000475,44.23507454331629,-0.20482348316514146,-0.33132292063470503
386.5000000000048,44.34072636768635,-0.20434697063581456,-0.33895186788566
387.6000000000048,44.45002544784126,-0.205154943897566,-0.34580038415632774
388.7000000000048,44.556982556451786,-0.20287883791143202,-0.3527536264423179
389.80000000000484,44.664481393295254,-0.20328017918510435,-0.36063150328717075
390.9000000000048,44.77174674083114,-0.20386531150267587,-0.36870519246431277
392.00000000000483,44.878188020664716,-0.20288241485490704,-0.3765711042533044
393.10000000000485,44.9857272146287,-0.20191683531328847,-0.3852932736489323
394.2000000000049,45.09006276903945,-0.2015847894950214,-0.3942701112385234
395.3000000000049,45.198548364400665,-0.20013344257139407,-0.4022976156164497
396.4000000000049,45.3052044186598,-0.20058647069559837,-0.4105403061917312
397.50000000000495,45.4124987838792,-0.1987964207943777,-0.4213371337083385
398.6000000000049,45.51926731001987,-0.19780462674938398,-0.4312354126473781
399.70000000000493,45.62446961403994,-0.1946126582813904,-0.43917464126076
400.80000000000496,45.7335316120286,-0.19483373132689022,-0.44941624647154965
401.900000000005,45.84114811983905,-0.194336526843429,-0.46072677054874456
403.000000000005,45.947910552044924,-0.19190034855548888,-0.47151358023151246
404.100000000005,46.05552142474312,-0.18844584677588277,-0.4823939448593051
405.20000000000505,46.16209789040984,-0.18781521252904676,-0.4949075898596935
406.30000000000507,46.269570557371516,-0.18575318310739006,-0.5060429899829666
407.4000000000051,46.376228142011705,-0.18280309550502138,-0.5183755404705392
408.50000000000506,46.483807383150236,-0.17791189283889627,-0.5308654389270822
409.6000000000051,46.59105764836124,-0.17361497129737538,-0.54572193567761
410.7000000000051,46.69705063731156,-0.16845554284544653,-0.557595888580595
411.8000000000051,46.80652460073806,-0.16141596719790102,-0.5718461367132561
412.90000000000515,46.91352256121183,-0.15621858316400627,-0.5867477915225403
414.0000000000052,47.02005881545672,-0.14778635920302205,-0.6036206379730884
415.1000000000052,47.12757737667468,-0.1417070245887918,-0.6192441009550462
416.20000000000516,47.23428578217385,-0.13429069339176145,-0.6360304915738122
417.3000000000052,47.34121306891801,-0.12823325220692636,-0.6536438222948266
418.4000000000052,47.44887550378357,-0.11896666720025884,-0.671288456717313
419.50000000000523,47.556259059210504,-0.11211892181229352,-0.6895921356673727
420.60000000000525,47.66402904994603,-0.1056848293388197,-0.7086002290803348
421.7000000000053,47.7715195884224,-0.09882243383288372,-0.7295509228046142
422.8000000000053,47.8796409774099,-0.09281400034858953,-0.7487251783946625
423.9000000000053,47.985081571914286,-0.08834984130249772,-0.7706167080055524
425.00000000000534,48.0945385132245,-0.0827315355026361,-0.7927412801695666
426.1000000000053,48.20109019998954,-0.07696876464320108,-0.814030086252008
427.20000000000533,48.30907186784228,-0.07113898273824877,-0.8372927670389045
428.30000000000535,48.417003725726666,-0.06627979294443262,-0.8615444958825798
429.4000000000054,48.521467208932286,-0.06095678380578188,-0.8862272716558639
430.5000000000054,48.63222253567199,-0.05615854266505242,-0.9126497153976971
431.6000000000054,48.739576555346595,-0.053033464819292074,-0.93861074889276
432.70000000000545,48.84800077278958,-0.047477042462985466,-0.9667180838841953
433.8000000000054,48.9556686599241,-0.046057380432981014,-0.9924576881846194
434.90000000000543,49.063832182492085,-0.044658918084381626,-1.019091818347019
436.00000000000546,49.17052425807348,-0.04220282544593042,-1.0467503365794806
437.1000000000055,49.27928016378153,-0.04218935256217078,-1.0754702941530367
438.2000000000055,49.386386259791465,-0.0422274000891354,-1.1023332348621357
439.3000000000055,49.49403353754687,-0.04490932987863723,-1.128874267453643
440.40000000000555,49.601725571330384,-0.047045554184936104,-1.1559731507921676
441.50000000000557,49.709488072400234,-0.0525952578375751,-1.1797159469379923
442.6000000000056,49.81725050236729,-0.05791938012886175,-1.203916830501854
443.70000000000556,49.924307102954856,-0.06570975020552502,-1.2267716511666151
444.8000000000056,50.03205336120906,-0.07198776634125817,-1.24779647392152
445.9000000000056,50.14014246247741,-0.08374397560587189,-1.2661253307340297
447.0000000000056,50.24698349594145,-0.09428895984224665,-1.2825758924376491
448.10000000000565,50.35431566073497,-0.10868745108745144,-1.299452602931579
449.2000000000057,50.46174216334906,-0.12283768739152366,-1.3129475059564588
450.3000000000057,50.57002782266397,-0.13563749219246574,-1.3259926109388975
451.40000000000566,50.676808781454575,-0.1489657825173655,-1.3395183747261732
452.5000000000057,50.784859604652496,-0.15867851073880263,-1.3502027546728335
453.6000000000057,50.891948327315085,-0.1689654568609014,-1.3605356085323863
454.70000000000573,51.00045470971648,-0.17455701716451089,-1.3702840396936136
455.80000000000575,51.10821442312378,-0.17963815080128093,-1.3803059161827878
456.9000000000058,51.2162050332393,-0.185160272197651,-1.3909395600315477
458.0000000000058,51.32469073329003,-0.1871915819130559,-1.4012642863059885
459.1000000000058,51.431919748434225,-0.18807323408754806,-1.4103835141391552
460.20000000000584,51.54017330205409,-0.18781754996152297,-1.420765786966589
461.3000000000058,51.64714704925795,-0.18554285396577422,-1.4315836828003143
462.40000000000583,51.756591029490934,-0.1847552789068232,-1.4415644338329128
463.50000000000585,51.863593528940086,-0.18072308027103107,-1.4521661593082422
464.6000000000059,51.97157922187386,-0.17979068049451974,-1.4635007418989874
465.7000000000059,52.078352168560976,-0.17646613242492795,-1.4755127678197386
466.8000000000059,52.187729195461294,-0.17490662310616248,-1.4860973084253577
467.90000000000595,52.29524068915617,-0.172366366998839,-1.4995406490339436
469.0000000000059,52.40298417995712,-0.1708251661677554,-1.5128449339748191
470.10000000000593,52.51098384771648,-0.1706870899877909,-1.5260412285055205
471.20000000000596,52.6188757840208,-0.17120885324381302,-1.5388919258376208
472.300000000006,52.727454016052256,-0.17538784943248897,-1.5510445460015636
473.400000000006,52.835834255667685,-0.1823244781923534,-1.5644952060706703
474.500000000006,52.94315179966259,-0.19143330384669063,-1.578352223918683
475.60000000000605,53.051277553336185,-0.20216883137213448,-1.5888544772555164
476.70000000000607,53.15906651617308,-0.216044199059886,-1.5983190506552112
477.8000000000061,53.26685697960019,-0.23586602228959475,-1.6048415712779978
478.90000000000606,53.374763319618246,-0.2555324526399095,-1.6112850826327483
480.0000000000061,53.48323414236802,-0.2744760305683826,-1.6167748632563432
481.1000000000061,53.59087219055011,-0.29340648626387655,-1.6210611255940006
482.2000000000061,53.69866785740177,-0.3088384215747986,-1.623895959013284
483.30000000000615,53.80726153473061,-0.3197934991291385,-1.6280748693998897
484.4000000000062,53.913505153814214,-0.32601463984820367,-1.6280727390444363
485.5000000000062,54.022650769886006,-0.3308617235228131,-1.6302780248593116
486.60000000000616,54.13027460828678,-0.3331195940555307,-1.6330253618634551
487.7000000000062,54.2379384610614,-0.3335272554796395,-1.6343428739870784
488.8000000000062,54.345501898403526,-0.33506040842891316,-1.6344733641273277
489.90000000000623,54.453464168262165,-0.3353524119846551,-1.6377499288289443
491.00000000000625,54.56195316536848,-0.33490065227605625,-1.638568815250931
492.1000000000063,54.669266109849325,-0.32891126727016146,-1.6395833882844908
493.2000000000063,54.77534087256915,-0.3204552242463193,-1.6408376254476669
494.3000000000063,54.88551818498873,-0.3163982799511804,-1.6435595154411549
495.40000000000634,54.993388033383546,-0.31426112636924664,-1.6432294128283487
496.5000000000063,55.10090354665615,-0.31271986248522515,-1.6445501416875787
497.60000000000633,55.20874893903283,-0.31257658109359804,-1.6448830419271077
498.70000000000636,55.31783781349746,-0.31136183473396006,-1.6461892950635266
499.8000000000064,55.42643583535675,-0.3101190480769892,-1.6475099377503413
500.9000000000064,55.53461617187333,-0.308094248479856,-1.6475246513116466
502.0000000000064,55.643473921125626,-0.30756363349366295,-1.6492247244169662
503.10000000000645,55.75169397131628,-0.3064617369768397,-1.6501462457234894
504.2000000000064,55.85971882178006,-0.3055963737734156,-1.651017879487238
505.30000000000643,55.968977440635946,-0.30476049925818344,-1.6521202853269807
506.40000000000646,56.0777644247488,-0.30306788390272055,-1.6534391939727109
507.5000000000065,56.18407435056021,-0.3003907004329113,-1.6561141818887157
508.6000000000065,56.293935194136424,-0.3005767862135668,-1.6560848166027102
509.7000000000065,56.4027204748515,-0.29894216166253734,-1.6571685991401441
510.80000000000655,56.51215204324626,-0.29835653798901013,-1.6582874784414563
511.90000000000657,56.62004864789795,-0.29450218336234374,-1.6591208804835627
513.0000000000066,56.72821610665782,-0.2931711303843798,-1.660023055221981
514.1000000000065,56.83659859608909,-0.2918512107471384,-1.6604725582575037
515.2000000000066,56.94535540864654,-0.2898605281919128,-1.6613685967916094
516.3000000000065,57.054293716411955,-0.288620896489894,-1.6626707754353176
517.4000000000067,57.1623720615946,-0.28690977769879455,-1.6642747215363922
518.5000000000066,57.272156724219144,-0.28622646553232595,-1.6669534254809837
519.6000000000067,57.38058135210726,-0.2857018704006598,-1.6672705120896159
520.7000000000066,57.48967381146607,-0.28505030494326145,-1.6685900710642585
521.8000000000067,57.5991710681759,-0.2846499276788193,-1.6699001464688936
522.9000000000067,57.70647820493683,-0.28404823439087806,-1.671393335637783
524.0000000000067,57.816617333859526,-0.28389968500437046,-1.6737432406016688
525.1000000000067,57.92457691666731,-0.28488150169092197,-1.6725498608139238
526.2000000000068,58.03165459821137,-0.28322453725720065,-1.6739498190848443
527.3000000000068,58.14304771990236,-0.28254560404454454,-1.676490140442081
528.4000000000068,58.25220187212136,-0.2842095222477587,-1.6765159218224972
529.5000000000068,58.36148534902137,-0.2831303065546268,-1.6791280864480953
530.6000000000068,58.47016740088142,-0.2835588279515571,-1.6804406062272172
531.7000000000069,58.578975804186015,-0.2833755037790931,-1.6804502727519672
532.8000000000068,58.68765661787769,-0.28474846763220135,-1.6817616011732452
533.9000000000069,58.79746472965311,-0.28487286285858676,-1.683604303278993
535.0000000000068,58.905996310103504,-0.28630024234332335,-1.685757822708228
536.100000000007,59.01510435227637,-0.2866068612273489,-1.6870480702847739
537.2000000000069,59.12405705081531,-0.2861904527612788,-1.6870037547519088
538.300000000007,59.232819667211665,-0.28825145655001316,-1.6884582035825368
539.4000000000069,59.34273813954634,-0.28764130209076755,-1.6890199921681188
540.5000000000069,59.44997124212827,-0.2881042085148936,-1.6922934394963867
541.600000000007,59.56000176991171,-0.28691948915439075,-1.6936319976707597
542.700000000007,59.666178510600744,-0.28643157403248154,-1.6953174037528522
543.800000000007,59.77732706946625,-0.2869348145345564,-1.6966176681101088
544.900000000007,59.886463097860755,-0.2884643528942276,-1.69703917273165
546.000000000007,59.995942089714035,-0.28720901727767356,-1.6993490030189604
547.1000000000071,60.10385798479761,-0.28704908774788324,-1.7019621436253027
548.2000000000071,60.21300719029262,-0.2881211873990862,-1.7028099513458002
549.300000000007,60.32154836103254,-0.28796302358628106,-1.7041562489567812
550.4000000000071,60.43109303057164,-0.2879223422721167,-1.7068067972828427
551.500000000007,60.54056963487062,-0.28695892198110134,-1.7080937581485447
552.6000000000072,60.6490728660017,-0.2878041495077122,-1.709432772120227
553.7000000000071,60.7582309455124,-0.28603914572120026,-1.7120317401742775
554.8000000000072,60.86738949852481,-0.2868869644651976,-1.7137008247421366
555.9000000000071,60.97668092598511,-0.2882876849749977,-1.71581168737098
557.0000000000072,61.084045217662506,-0.2877131996014619,-1.719080918788769
558.1000000000072,61.194137990130365,-0.2878801339323474,-1.7221437826892996
559.2000000000072,61.303743953092294,-0.2903248629606411,-1.7244978981839445
560.3000000000072,61.413134874254645,-0.2914174864049032,-1.7254978973209991
561.4000000000073,61.5218291479768,-0.290693840943312,-1.7288385894810019
562.5000000000073,61.63078505780587,-0.2926024856640143,-1.7316623312751385
563.6000000000073,61.73936864388354,-0.29390696568962954,-1.7333567666896799
564.7000000000073,61.84838653168195,-0.2937377337331621,-1.7353653780645555
565.8000000000073,61.956987919335695,-0.2929355376173184,-1.7390915247582308
566.9000000000074,62.067307149097914,-0.29349397103379,-1.743889234835124
568.0000000000074,62.17623684423054,-0.290248953320821,-1.7462972561108732
569.1000000000074,62.28492064633928,-0.285396247436026,-1.7506008582347259
570.2000000000073,62.39553938042002,-0.28325896110664983,-1.7546178732078563
571.3000000000073,62.504283202294246,-0.28006910814973185,-1.757893989496186
572.4000000000074,62.613037774112165,-0.27662964868712825,-1.76228598236496
573.5000000000074,62.72281622462599,-0.272075105323573,-1.767415454857519
574.6000000000074,62.83211464446965,-0.2675485375887629,-1.7725139728459176
575.7000000000074,62.942015331874885,-0.2651844798479562,-1.7770501214460457
576.8000000000075,63.05147633539113,-0.2605853566685903,-1.7824528983352947
577.9000000000075,63.16040468087596,-0.2575873844106261,-1.7865027760977217
579.0000000000075,63.267833577895146,-0.25487806497665044,-1.7929754298164635
580.1000000000075,63.38034351727707,-0.25370483267466143,-1.7996570358298265
581.2000000000075,63.48584325122776,-0.25432052147812595,-1.805125543055016
582.3000000000076,63.598774895760656,-0.2545574142294735,-1.8140160517601762
583.4000000000076,63.70800615700827,-0.2541900107810746,-1.8199615603285721
584.5000000000076,63.818632342349545,-0.2529693738079445,-1.8266593451093138
585.6000000000076,63.92702042410839,-0.25626839577821375,-1.834047004824789
586.7000000000077,64.03688040734271,-0.25505799404793017,-1.8407536591248368
587.8000000000077,64.14550697329344,-0.2560865052805316,-1.8480987120673693
588.9000000000076,64.25487609051348,-0.25385275502720744,-1.8559344539716922
590.0000000000076,64.36437165914157,-0.25403234252739687,-1.8631664101660355
591.1000000000076,64.47338367402457,-0.25338129849279467,-1.8720662116864122
592.2000000000077,64.58297866466573,-0.2541112653281188,-1.880520640631116
593.3000000000077,64.69199000182155,-0.25332743309587213,-1.8883397160442872
594.4000000000077,64.80137755608088,-0.2532534671249571,-1.8969857922144335
595.5000000000077,64.90961838869113,-0.2529534366697365,-1.9071755037411373
596.6000000000078,65.01951494281057,-0.2555308537041953,-1.9141051962907727
597.7000000000078,65.1292777563745,-0.255345860928166,-1.9244941459234686
598.8000000000078,65.23852018849016,-0.2589389890157464,-1.9332134752757755
599.9000000000078,65.3471711745027,-0.26048080333168544,-1.9417798615713358
601.0000000000078,65.45676605558249,-0.2600736267283387,-1.951923787003537
602.1000000000079,65.56653056169351,-0.26343802388565934,-1.9609141925855225
603.2000000000079,65.67564071184015,-0.2673013772420117,-1.9701625460633219
604.3000000000079,65.78544791883245,-0.26978298200672196,-1.9776051514924928
605.4000000000078,65.89404181131555,-0.27246273580837355,-1.9864672471509532
606.5000000000078,66.00389992548219,-0.2771926572939152,-1.9937788791784836
607.6000000000079,66.11321394817072,-0.28178800205651733,-1.9996156178054743
608.7000000000079,66.22316104507352,-0.28268059133767476,-2.005395231798415
609.8000000000079,66.33362374085549,-0.28041275647219155,-2.00957948661767
610.9000000000079,66.44260264388515,-0.27828213961004644,-2.0128980514549033
612.000000000008,66.55148002663209,-0.2725093706261866,-2.014233841224169
613.100000000008,66.66130987780781,-0.2697635993192696,-2.0155129635961178
614.200000000008,66.76990902549403,-0.2613098474231105,-2.0168311772573206
615.300000000008,66.87964772871986,-0.2571232543209122,-2.017777072905476
616.400000000008,66.98770198969915,-0.2529136770785689,-2.019138668315363
617.5000000000081,67.09844073872534,-0.24699783787328472,-2.0191326965834735
618.6000000000081,67.20758218144105,-0.24457066228252308,-2.0217693518946374
619.7000000000081,67.31692121182355,-0.24317869319417948,-2.023079212736429
620.8000000000081,67.42562642280366,-0.2383377975557489,-2.024116923125379
621.9000000000082,67.53693197001664,-0.2339628636245824,-2.0244004603206003
623.0000000000082,67.645090430626,-0.23152692949802153,-2.0257138249842415
624.1000000000081,67.75442967239975,-0.2246935740590085,-2.027029623514238
625.2000000000081,67.86415157650619,-0.22074174732664242,-2.028779394992082
626.3000000000081,67.97431383632849,-0.21483776269656502,-2.0309677418701506
627.4000000000082,68.08295434820579,-0.2095258969400524,-2.032299602903171
628.5000000000082,68.19343959859954,-0.2060236574603245,-2.0326292517946536
629.6000000000082,68.30280813626389,-0.20004364034062416,-2.033960078874844
630.7000000000082,68.41308194588913,-0.19611707443500212,-2.0365738502957518
631.8000000000083,68.52274067343669,-0.19189938736376863,-2.0379006329028924
632.9000000000083,68.6327348737561,-0.18630702788884856,-2.0391441931637493
634.0000000000083,68.74217385596042,-0.17980249433493867,-2.0414388654848947
635.1000000000083,68.85178537636884,-0.17305739717739804,-2.0431271902734567
636.2000000000083,68.96209478000023,-0.16638662999988915,-2.0458042987419507
637.3000000000084,69.07200851505809,-0.15900911373787233,-2.047143100215794
638.4000000000084,69.1818206679477,-0.1509489776883636,-2.0485646565000097
639.5000000000084,69.29184913607658,-0.14144136201188692,-2.0519851276047705
640.6000000000083,69.4020851663742,-0.13078571331652405,-2.0520190581057367
641.7000000000083,69.51208888513949,-0.12037283946017473,-2.054701101629833
642.8000000000084,69.62205359627812,-0.10767186815256555,-2.0574256090430936
643.9000000000084,69.73160624139639,-0.0962945781156821,-2.06065332181443
645.0000000000084,69.84178101484532,-0.08400256476900043,-2.062745438412854
646.1000000000084,69.94938503572175,-0.07193656717092824,-2.0637170177334117
647.2000000000085,70.06253268563,-0.05801807646055182,-2.066755343508969
648.3000000000085,70.17232430422216,-0.04568292207563981,-2.070355710415155
649.4000000000085,70.28168967691349,-0.029473186858001744,-2.0734615811854398
650.5000000000085,70.39212066449974,-0.01705952800515987,-2.076071755403
651.6000000000085,70.50212222853744,-0.00015524042164348443,-2.080245838043704
652.7000000000086,70.61261560918824,0.01438812454987347,-2.082926215848587
653.8000000000086,70.72215227607701,0.031402229833597875,-2.0870744786428146
654.9000000000086,70.83304386696551,0.04924065674998448,-2.091785858446473
656.0000000000086,70.94079557710812,0.06674536629899075,-2.0931146968699412
657.1000000000087,71.05307810887281,0.08389564272763687,-2.098896635251437
658.2000000000087,71.16280316805266,0.10459574718459089,-2.102147333079851
659.3000000000086,71.27284222794786,0.12659130665269022,-2.1077993354478313
660.4000000000086,71.38256490568048,0.14440590062803563,-2.1111623462009383
661.5000000000086,71.49232441784896,0.16577709200729662,-2.116061325466155
662.6000000000087,71.60273541670426,0.18652529762284045,-2.12005947194317
663.7000000000087,71.71277477483382,0.2075784804779771,-2.1245527592557845
664.8000000000087,71.82265832765519,0.22859441821933552,-2.1298239367914116
665.9000000000087,71.9330318783135,0.24655746034606074,-2.1356627152222747
667.0000000000088,72.04250246090888,0.26938935018783877,-2.141633667780293
668.1000000000088,72.15238775525754,0.29303717484674696,-2.146030373621624
669.2000000000088,72.26281857746882,0.31274625289476266,-2.151009004789822
670.3000000000088,72.37276769270994,0.33832955227169004,-2.158395894879302
671.4000000000088,72.48203274143687,0.36067517415306405,-2.1634621856866563
672.5000000000089,72.59005679857675,0.3830066174357145,-2.168969195105568
673.6000000000089,72.70277174983076,0.40974652465245714,-2.17480299347332
674.7000000000089,72.81260408885517,0.43609530207866737,-2.18054771234117
675.8000000000088,72.92344967498637,0.45897616350316284,-2.1878146775060046
676.9000000000088,73.03248342410967,0.4823491512141794,-2.1948928999501396
678.0000000000089,73.14403559173172,0.5060171182187355,-2.20306088733092
679.1000000000089,73.25268836215261,0.5348589023293464,-2.2110229338503
680.2000000000089,73.36310643571079,0.5594681062629788,-2.2177745362824313
681.3000000000089,73.47364286424339,0.5852655085565504,-2.225588920028242
682.400000000009,73.58257214984607,0.6099097198868338,-2.2334895197962834
683.500000000009,73.69375966862776,0.6357419132226582,-2.2415202081225076
684.600000000009,73.80101028473933,0.6632300234045877,-2.248919952818853
685.700000000009,73.91336393787842,0.6863681023545488,-2.256172098767489
686.800000000009,74.02298492078744,0.7113989158572385,-2.264528586065758
687.9000000000091,74.13317733916192,0.7368863740902364,-2.2739158949772724
689.0000000000091,74.24238412489143,0.7601473986962001,-2.283169630623691
690.1000000000091,74.35303151087635,0.7893914341600702,-2.291895333613671
691.2000000000091,74.46247506537966,0.8153312246561042,-2.30032569514622
692.3000000000092,74.57377903074716,0.8447361494766625,-2.3101823463859015
693.4000000000092,74.68293536153844,0.8735459685317187,-2.319658658018472
694.5000000000091,74.79225064965942,0.9065382994354645,-2.3288300730329494
695.6000000000091,74.90325231289609,0.9371773837140097,-2.338895231075912
696.7000000000091,75.01274650267251,0.9691083374011227,-2.348766243587955
697.8000000000092,75.12235998560946,1.0031570280630606,-2.357632443903956
698.9000000000092,75.23379929075408,1.035786070435986,-2.3687719515862113
700.0000000000092,75.34415278500325,1.0717111254303542,-2.380701121480738
701.1000000000092,75.45451786140315,1.1059633281909733,-2.3900402871945707
702.2000000000093,75.5641158559133,1.1404120594868075,-2.4019730824259575
703.3000000000093,75.67576816301394,1.1775512784156748,-2.4121232931909917
704.4000000000093,75.78625554092031,1.2114683771714543,-2.423756179154236
705.5000000000093,75.89483193230411,1.2446657649239665,-2.435510466890994
706.6000000000093,76.00449637022678,1.272878895856492,-2.447922372106645
707.7000000000094,76.11639387503953,1.3044180153169407,-2.4599535685986442
708.8000000000094,76.22637967513663,1.3291601992114366,-2.4730486762227915
709.9000000000094,76.33695264376719,1.351228129707599,-2.4857686856807284
711.0000000000093,76.44755677512273,1.3668719146107626,-2.4959079380843665
712.1000000000093,76.55701223464887,1.3830769243041405,-2.5097683585832273
713.2000000000094,76.66718324988618,1.3898316161976305,-2.5223816289072394
714.3000000000094,76.77547338754243,1.394934959134572,-2.5348686254833908
715.4000000000094,76.88737746461949,1.392951348557085,-2.5472152545731674
716.5000000000094,76.99860504846878,1.381360272125566,-2.559197521277267
717.6000000000095,77.10897888134194,1.3668916752318485,-2.5731758052679217
718.7000000000095,77.21896093138035,1.3480868754729707,-2.5855908287742633
719.8000000000095,77.32936833705193,1.3165071864113924,-2.596284357377435
720.9000000000095,77.439460322254,1.27556173597997,-2.607718020127746
722.0000000000095,77.54997005150567,1.2242073088205294,-2.6221120761940337
723.1000000000096,77.66005126845192,1.1497363478670384,-2.632673461431399
724.2000000000096,77.76981315750781,1.0565263277529036,-2.6415378522038364
725.3000000000096,77.8794956896875,0.9306355579260044,-2.652607252073425
726.4000000000096,77.98995165231076,0.755218112663536,-2.6624831934543076
727.5000000000097,78.09867453989172,0.5111577901570739,-2.6704241068307626
728.6000000000097,78.20888773223012,0.17874429738738914,-2.675045408262754
729.7000000000096,78.31842462789376,-0.20002290299795256,-2.6795195431495924
730.8000000000096,78.42395196387578,-0.37607756481672056,-2.680618104134701
731.9000000000096,78.53793219608048,-0.4569988892500433,-2.681887069240721
733.0000000000097,78.6480538248444,-0.49385402927062816,-2.6832101927637586
734.1000000000097,78.75811106469101,-0.5153836945947373,-2.6832000382647596
735.2000000000097,78.86799249181028,-0.5254921439024899,-2.683805145775392
736.3000000000097,78.97917107566505,-0.5339300685639216,-2.6841965470602847
737.4000000000098,79.08673494334076,-0.5434898662258483,-2.686419293777583
738.5000000000098,79.19946802328224,-0.548837811251468,-2.6863530708447296
739.6000000000098,79.31028890255627,-0.55527080476045,-2.6858368020589207
740.7000000000098,79.419951053826,-0.5577859546402778,-2.6858399611580195
741.8000000000098,79.53037609576143,-0.5594333629622257,-2.686499940643088
742.9000000000099,79.64106882585811,-0.5644428584759733,-2.687810179876818
744.0000000000099,79.75116112497237,-0.5642609360423294,-2.687797281726464
745.1000000000099,79.86284766117011,-0.5649906890102011,-2.6891533208795035
746.0000000000099,79.9538013028466,-0.567947175709693,-2.6897898694832527