File: 01_Data/Polyester_Carpet_High_Pile/STA/N2/10K_min/Polyester_Carpet_High_Pile_STA_N2_10KData_220912_R3.csv
##Temp./Â°C,Time/min,DSC/(mW/mg),Mass loss/mg
51.0,10.856630592501688,-1.5004339784908474,0.030262498244026936
52.100000000000016,11.185466163047026,-1.3930040064242575,0.02977958290238014
53.20000000000003,11.428455330780217,-1.3160268634553407,0.02840874039570629
54.30000000000005,11.630518627898589,-1.2604050364062354,0.029941483257912793
55.40000000000006,11.81240495708732,-1.2170160042290377,0.029664907550219333
56.50000000000008,11.984427384178504,-1.1800220222318112,0.030493894371373287
57.600000000000094,12.145679902385629,-1.1500926545937786,0.02916361289735203
58.70000000000011,12.300196501472191,-1.1252446537096306,0.03069037825918386
59.800000000000125,12.449170000000015,-1.1026999999999991,0.03056788055253623
60.90000000000014,12.594696963867156,-1.082585526480359,0.030781127332437208
62.000000000000156,12.738032210279634,-1.0657998488566358,0.029117473451452547
63.10000000000017,12.876559186753559,-1.0480505619901086,0.029208590407360013
64.20000000000019,13.014189464291716,-1.0332857998340095,0.030537421804943676
65.30000000000021,13.14795799896448,-1.0192385272006397,0.03128731479351021
66.40000000000022,13.27999621671319,-1.0045504034024526,0.03063965281629155
67.50000000000023,13.41180621420276,-0.9902895017870139,0.030603575136352035
68.60000000000025,13.541456139370837,-0.9769827379333258,0.030617569290138924
69.70000000000027,13.67038984259793,-0.9665846515370906,0.031720008957395684
70.80000000000028,13.796791480231326,-0.9540468935565309,0.03070370415835022
71.90000000000029,13.9212019976733,-0.9432612560755854,0.030607806358161405
73.00000000000031,14.045742463076149,-0.9299390205372338,0.03077443235081745
74.10000000000034,14.168234229682696,-0.9210384823108622,0.030721057805341623
75.20000000000034,14.292349019478017,-0.9118409121760265,0.031930633498372885
76.30000000000035,14.415157291099167,-0.9022680341280986,0.03115724865490943
77.40000000000038,14.53540619711314,-0.8955672639518316,0.032182856662101855
78.5000000000004,14.654776436464868,-0.8887749512773088,0.030630402663929246
79.6000000000004,14.77301923359176,-0.8824768875886634,0.03203745387938994
80.70000000000041,14.892802632589754,-0.875682112127464,0.032104577277509705
81.80000000000044,15.010182716045096,-0.8692238289444679,0.03062868286764342
82.90000000000046,15.126067098595808,-0.8635537857997535,0.03169286575668551
84.00000000000047,15.2416786341842,-0.8556340870158424,0.03194983255065509
85.10000000000048,15.357085575132958,-0.8486131590345636,0.032117045449429504
86.2000000000005,15.472984612488602,-0.8415949757155838,0.03331118254963705
87.30000000000052,15.586016644308607,-0.8352586650748467,0.033258608645728494
88.40000000000053,15.701430592853526,-0.8278115128848392,0.03252590613054007
89.50000000000054,15.815219010339433,-0.8223761610754499,0.03091957411502655
90.60000000000056,15.928662158942721,-0.8165052231346128,0.03250065548194403
91.70000000000059,16.040875304777497,-0.8099084829749057,0.03259965219800698
92.8000000000006,16.152071094562988,-0.8026266398777085,0.03378755322070237
93.9000000000006,16.263529003284347,-0.7974373910550382,0.03331097253365378
95.00000000000063,16.376171319528364,-0.7918062061052945,0.03282999995499658
96.10000000000065,16.484804144022714,-0.783827377794594,0.03328239742724648
97.20000000000066,16.594637942752325,-0.7780407134571061,0.033274931546737996
98.30000000000067,16.70550165981895,-0.7695511180444787,0.032423430476695714
99.40000000000069,16.81475637392567,-0.7622292118831875,0.03338080017852629
100.50000000000071,16.924101571964393,-0.7545786902388485,0.03337705819628933
101.60000000000072,17.034279196693642,-0.7482755710210723,0.03467430709072694
102.70000000000073,17.1410186824209,-0.7418788928889161,0.034659580797200995
103.80000000000075,17.25058465226661,-0.7346804362845172,0.03465550696710995
104.90000000000077,17.359639135096234,-0.726053846886936,0.03468973681416898
106.00000000000078,17.467637879289736,-0.7210853792254779,0.03468893752847446
107.10000000000079,17.575323920844575,-0.7144371023152014,0.033450495090602494
108.20000000000081,17.6831224980356,-0.7078417202764622,0.034698602577858395
109.30000000000084,17.792398120570397,-0.7005151886733134,0.0335708990585184
110.40000000000084,17.89863025744384,-0.6945073043906436,0.03336163168185369
111.50000000000085,18.006113481443876,-0.688322059933365,0.03427765639615998
112.60000000000088,18.114781861095707,-0.68165880288175,0.034689773270320856
113.7000000000009,18.221908825565396,-0.6757241371109305,0.034704657268221695
114.8000000000009,18.32570858436602,-0.6700009769934361,0.03542552231273799
115.90000000000092,18.436982551654694,-0.6643917935797146,0.03600573520120065
117.00000000000094,18.54354544582268,-0.658891615870121,0.03469679209176402
118.10000000000096,18.651927901074504,-0.6533172892547203,0.036043738445698636
119.20000000000097,18.758597982229478,-0.6479053682699062,0.03334338270286441
120.30000000000098,18.865529008626325,-0.6434911164476566,0.03470005238343443
121.400000000001,18.97317668205838,-0.638406439565891,0.03577953614165175
122.50000000000102,19.07917000000011,-0.6320399999999964,0.03469010827582153
123.60000000000103,19.186718689651915,-0.6274190040851948,0.03600876254262353
124.70000000000104,19.294284452936548,-0.6216983767038649,0.03601200543008076
125.80000000000106,19.400327930552155,-0.617871749094864,0.036082977371560965
126.90000000000109,19.505572818558413,-0.6118374041123216,0.03567980853820263
128.00000000000108,19.614307110377517,-0.6079967777797681,0.034678514141225136
129.1000000000011,19.71938416249269,-0.6020028905416525,0.03469005477653475
130.20000000000113,19.824855117947138,-0.5972207964396372,0.03600215711963983
131.30000000000115,19.93129629862836,-0.5915103024924148,0.036174357308374816
132.40000000000117,20.03824164007237,-0.5861690168529383,0.03601116645955038
133.50000000000117,20.142609026741503,-0.5808585326538683,0.03600725974675267
134.6000000000012,20.24972617555175,-0.57550195677838,0.03593673777257855
135.7000000000012,20.355249337486363,-0.5701749631468589,0.036010059924277193
136.8000000000012,20.461084789380628,-0.5644266678787266,0.03690821393614119
137.90000000000123,20.567792358705468,-0.5602889015186188,0.036187550350459396
139.00000000000125,20.673705175618384,-0.5558826106925382,0.03533860396488642
140.10000000000127,20.77898082941227,-0.5514317859206075,0.03743101325820408
141.2000000000013,20.883866030997495,-0.5464665749666292,0.03743965687316475
142.3000000000013,20.98874774965263,-0.5409790067920803,0.03801290775958499
143.4000000000013,21.094525125979555,-0.5362742839011323,0.037440271155712246
144.50000000000134,21.199755786333693,-0.531402157435661,0.03611998659142923
145.60000000000133,21.30435387832809,-0.5258032480123007,0.03612082405706207
146.70000000000135,21.408302240758676,-0.520927869232875,0.03612083112938258
147.80000000000138,21.514368716228127,-0.5154616700712628,0.037440444381179105
148.9000000000014,21.617745906994518,-0.5105154266367998,0.03714719352946538
150.00000000000142,21.72419361469529,-0.5038632266685737,0.03611964531671852
151.10000000000142,21.829350818316673,-0.49741178547666015,0.03710985934985711
152.20000000000144,21.934981686032174,-0.490082707908399,0.037164411235480976
153.30000000000146,22.038770312060503,-0.48416101875214196,0.03609668997900428
154.40000000000146,22.143782466817093,-0.4762873751429912,0.03742996215389027
155.50000000000148,22.248601515109165,-0.4676492912690985,0.03631103279348391
156.6000000000015,22.352824284348614,-0.4581870885463691,0.03743982192109829
157.70000000000152,22.456770619994654,-0.4481418361807776,0.0387421462933375
158.80000000000155,22.56195516347477,-0.4367028503380163,0.037435732289560875
159.90000000000154,22.667165341000356,-0.42644166930185423,0.036778213559044204
161.00000000000156,22.77115517302963,-0.41201537061595966,0.037372150560849526
162.1000000000016,22.87650501354704,-0.4017102015137549,0.03742453717727656
163.20000000000158,22.98096066296665,-0.39032196658218915,0.03742992800194944
164.3000000000016,23.085745479686896,-0.38141319271692264,0.0374273650059056
165.40000000000163,23.190123864719308,-0.3752778139634199,0.038751796916217884
166.50000000000165,23.29461525303071,-0.372943055303041,0.03744021547191689
167.60000000000167,23.400045382438613,-0.37912567545224257,0.03749681389531201
168.70000000000167,23.505007912669278,-0.3915114758455807,0.038760076729157156
169.8000000000017,23.606992901048066,-0.4042881107041301,0.03879413300403378
170.9000000000017,23.71263521710419,-0.41395113037272135,0.03841898224592377
172.0000000000017,23.817055343295035,-0.42028401036529006,0.03743012518257949
173.10000000000173,23.92232606173848,-0.4237237309328105,0.03875066085503409
174.20000000000175,24.026586111064184,-0.4256479188328856,0.038749893325707774
175.30000000000177,24.130303552669506,-0.4271380880010965,0.0373795130880854
176.4000000000018,24.235490886043767,-0.42385302721348717,0.037421272392831995
177.5000000000018,24.34054470861087,-0.42247906881977154,0.03744027399214289
178.6000000000018,24.441734187120673,-0.41942702743911753,0.03876345195033082
179.70000000000184,24.549616494852252,-0.4156952062622798,0.03876117275634794
180.80000000000183,24.651378315019972,-0.41150599991433123,0.0374361531020142
181.90000000000185,24.757915459667842,-0.40845073409147337,0.038756613238543736
183.00000000000188,24.86354687606739,-0.40555669368035785,0.037430018890254324
184.1000000000019,24.966931234757162,-0.40307565702463183,0.03742443886041258
185.20000000000192,25.072067280805594,-0.3999062189689844,0.03808946312932271
186.30000000000192,25.175935321977217,-0.39750470293598755,0.038084526710806976
187.40000000000194,25.277876750767618,-0.39475809540688395,0.03885999390560624
188.50000000000196,25.385098361716448,-0.3920005615578301,0.03775176040492223
189.60000000000196,25.48962353980668,-0.38783075562387864,0.036745571885854034
190.70000000000198,25.593967895895698,-0.3861783548736262,0.038179932669391015
191.800000000002,25.697716604106148,-0.38213359759486054,0.03765245326680233
192.90000000000202,25.80337592911615,-0.37918215640841685,0.03710982877076052
194.00000000000205,25.907123472127854,-0.37702331355408786,0.03813463357346514
195.10000000000204,26.01056502520648,-0.37396798470562576,0.03676989111581541
196.20000000000206,26.114937103574494,-0.3696897543577783,0.03676565060825698
197.3000000000021,26.22011578328445,-0.36599750249790364,0.038090112603994086
198.40000000000208,26.32460388694736,-0.36433112402350404,0.03743903418637551
199.5000000000021,26.42926485007563,-0.3600722666744749,0.03677547471828646
200.60000000000213,26.532314059437425,-0.356719894948946,0.03678144688044149
201.70000000000215,26.637684216884757,-0.35243526845315964,0.038099290838908395
202.80000000000217,26.741803199912752,-0.3487277970495975,0.036780164411401195
203.90000000000217,26.84660531712478,-0.3462053466010722,0.03546015485121501
205.0000000000022,26.949986011090807,-0.34288683952979926,0.03578894425849466
206.1000000000022,27.054637126154972,-0.33986783041133045,0.03578513333924693
207.2000000000022,27.159941062121224,-0.337320195678493,0.03711034195102503
208.30000000000223,27.262683444927717,-0.33464816710537404,0.036805806812826525
209.40000000000225,27.36844311829458,-0.33112221950178927,0.03546019968166991
210.50000000000227,27.473149810818533,-0.3276460383146017,0.03546902797656415
211.6000000000023,27.576459651615867,-0.32435472797957526,0.03538153516330844
212.7000000000023,27.681593223927827,-0.3206606191121828,0.035472400178243824
213.8000000000023,27.784916422873277,-0.31900251530515766,0.03546009443497766
214.90000000000234,27.88982713816459,-0.31471665206790783,0.03413575300901606
216.00000000000233,27.994011540217166,-0.3107547344302021,0.03551281530280459
217.10000000000235,28.098137367817458,-0.3057009898383301,0.03546007100877002
218.20000000000238,28.20345215453919,-0.30231944093588214,0.035447297301485214
219.3000000000024,28.307552830278194,-0.29948499653013094,0.034470071230097155
220.40000000000242,28.41144979794195,-0.294995613037697,0.03441776220220216
221.50000000000242,28.516707029397857,-0.2928092324580631,0.03545990726489645
222.60000000000244,28.620597380930775,-0.2880187760935748,0.03413995174991946
223.70000000000246,28.725299012754075,-0.284883284599426,0.034139914009664984
224.80000000000246,28.83004036960902,-0.28057667244775086,0.03412846054193164
225.90000000000248,28.934411166166445,-0.27741607483111336,0.03348991303386217
227.0000000000025,29.038198632760505,-0.2738070522008845,0.034805827302963444
228.10000000000252,29.142751535503038,-0.27112130616896135,0.03415101414378796
229.20000000000255,29.248003712067625,-0.2664724447392857,0.03415022263769174
230.30000000000254,29.352230388111735,-0.26199489028586315,0.033196119119345724
231.40000000000256,29.45648389410959,-0.2573901441589784,0.03315982005016238
232.5000000000026,29.56045771217908,-0.2518421864443152,0.03314991766110875
233.60000000000258,29.66573005854815,-0.24546200249446398,0.03411277454656947
234.7000000000026,29.770208757791448,-0.2387750173579701,0.03282019294580696
235.80000000000263,29.875041830964875,-0.23432574240158802,0.032820192999999165
236.90000000000265,29.978365391651344,-0.2270576446633718,0.032820193028474165
238.00000000000267,30.083792620429954,-0.21760682539952522,0.032861341105913766
239.10000000000267,30.187881846317175,-0.2071841317188578,0.032489655053045574
240.2000000000027,30.293195637459647,-0.19997577906957,0.03149443387731665
241.3000000000027,30.396176599040572,-0.18749413583679955,0.03281559863077188
242.4000000000027,30.501181075897218,-0.17528042080269007,0.032818849342762135
243.50000000000273,30.60536355396067,-0.15540828954649788,0.03150283661874376
244.60000000000275,30.71134096893099,-0.13353778664775107,0.031510047965181975
245.70000000000277,30.815647658453507,-0.10280807279592392,0.031510051469844313
246.8000000000028,30.92017032628624,-0.06252518315890826,0.03051943468337104
247.9000000000028,31.02484392533755,-0.011828843248813106,0.02952992446683389
249.0000000000028,31.129524936363662,0.04042376177942688,0.03085149437401391
250.10000000000284,31.23462543489037,0.07497176665812924,0.030317033811155802
251.20000000000283,31.340555525778225,0.08029882003695459,0.030522640966118786
252.30000000000285,31.44487580591563,0.04865579637676002,0.030614758559017297
253.40000000000288,31.55007218945968,-0.0006790082839527175,0.02924147894667506
254.5000000000029,31.653321320632884,-0.05467565461504065,0.03021497534288553
255.60000000000292,31.758868047677694,-0.1002745846304841,0.03018987900479786
256.7000000000029,31.862619940850283,-0.1345153239292558,0.030175805891689222
257.8000000000029,31.967654480800256,-0.1590435425530369,0.02919987899933396
258.90000000000293,32.07146467849404,-0.1766659859810784,0.029201581019242973
260.00000000000296,32.17656448545714,-0.18899759282930617,0.02803880854706442
261.100000000003,32.28090095778504,-0.1954715804227762,0.029192419222373367
262.200000000003,32.38517486099535,-0.20232362311919988,0.029531548530542295
263.300000000003,32.490321257045714,-0.20395598842718551,0.028776258919410935
264.40000000000305,32.59467822472625,-0.20609020681128595,0.02718402238913953
265.50000000000307,32.69926625556715,-0.20629213025284118,0.02722981600169394
266.6000000000031,32.80304104879482,-0.20678050539261167,0.027229815999999296
267.7000000000031,32.907956587900976,-0.2076742391633548,0.027229816000000184
268.8000000000031,33.01268738396461,-0.20544275613506016,0.02722981599578933
269.9000000000031,33.118625134013506,-0.20432132636878322,0.027239523505183882
271.0000000000031,33.222433050404895,-0.20209284476319392,0.025923012810596724
272.10000000000315,33.327860589576254,-0.2015418938019608,0.026900027779394264
273.2000000000032,33.43240602467361,-0.20087060113785227,0.025579528857591072
274.30000000000314,33.53782785093508,-0.19972186361974642,0.02558015488171339
275.40000000000316,33.643094876361936,-0.19700937824292442,0.02425985593498048
276.5000000000032,33.747971214579266,-0.19623779899756383,0.02426016200051606
277.6000000000032,33.85281172142611,-0.19465002748401272,0.02426016199999914
278.70000000000323,33.957701992021924,-0.19343579538340877,0.0242601620808518
279.80000000000325,34.06232559289451,-0.19144510274011867,0.02309058161257216
280.9000000000033,34.16896843907247,-0.1891321822745307,0.022950151572069366
282.0000000000033,34.27446703903546,-0.18682442391100815,0.02229403426826071
283.1000000000033,34.37855936200524,-0.18510274276059946,0.022610036728907268
284.20000000000334,34.483375810111355,-0.18449564420730452,0.02261004540771605
285.30000000000337,34.587364105074414,-0.1826084819439902,0.021952056453606872
286.40000000000333,34.69357471673096,-0.1805999558950024,0.021942398245616168
287.50000000000335,34.79917000000037,-0.17945999999999784,0.02063990999993237
288.6000000000034,34.9048322982509,-0.17707814019368778,0.020639909965771253
289.7000000000034,35.00898461757617,-0.1761709947576848,0.02063991000001053
290.8000000000034,35.11424505633355,-0.1722121695524237,0.02063977097582903
291.9000000000034,35.219866533238296,-0.17062318264933982,0.018040623802841438
293.0000000000034,35.32544909115433,-0.16817157646473127,0.01800988537324777
294.10000000000343,35.43041861358462,-0.1651568729611646,0.020318094493525507
295.20000000000346,35.536119068333086,-0.16291548793273253,0.02007945511116027
296.3000000000035,35.641715875449734,-0.16074102432314677,0.017676709921280676
297.4000000000035,35.74705809459905,-0.15757720236790382,0.01767463833502969
298.5000000000035,35.8524705533108,-0.15588806679550163,0.016192710287851853
299.60000000000355,35.95750617488409,-0.15167338482628254,0.015217738727594465
300.70000000000357,36.06277748069397,-0.14815906740664317,0.01539589889863624
301.8000000000036,36.16797626230967,-0.1459710956046944,0.015039976773290498
302.9000000000036,36.27296830316772,-0.14372747319999934,0.015039822262813196
304.0000000000036,36.37935822898841,-0.13941166288255732,0.013720136453371445
305.1000000000036,36.48208652527119,-0.13751012333573284,0.012401461672565617
306.2000000000036,36.589079839484995,-0.1337689315644752,0.012399914208604201
307.30000000000365,36.6947957252559,-0.1310052801408636,0.011079881729492591
308.4000000000037,36.79917094039816,-0.12774000026401555,0.011079882065988755
309.5000000000037,36.9057352134174,-0.12491507200825919,0.009769967472320396
310.60000000000366,37.01041531124432,-0.1217443831937867,0.009722075132263974
311.7000000000037,37.11573293836453,-0.11858009665931772,0.008582030987550837
312.8000000000037,37.22102901513513,-0.11555021167970449,0.006198839280695978
313.90000000000373,37.32635015386469,-0.11385020662794167,0.005810616680165914
315.00000000000375,37.42959185350469,-0.11249278076527108,0.0045003600820203715
316.1000000000038,37.5370920488538,-0.11121603326099395,0.0031868063552611403
317.2000000000038,37.64378704727753,-0.11018619150515951,0.002838719966542058
318.3000000000038,37.7502329280079,-0.10896075863740083,9.059960176660553e-05
319.40000000000384,37.85523465352444,-0.10851993089899196,-0.0011947441106947565
320.5000000000038,37.96105686948019,-0.1087342220386658,-0.002414696297075025
321.60000000000383,38.06538392150257,-0.10757467244453135,-0.0036641359465283685
322.70000000000385,38.1728238772585,-0.10575729760572106,-0.0077409712580589485
323.8000000000039,38.27907293394839,-0.10596067725349959,-0.008995496857081342
324.9000000000039,38.38361771741133,-0.10495164271907148,-0.010229891165709937
326.0000000000039,38.48969318796109,-0.10334756003713233,-0.012948123539306522
327.10000000000394,38.595890950360236,-0.10301267353473376,-0.016787426145213225
328.2000000000039,38.702396480266955,-0.10222335584637582,-0.019570578069521005
329.30000000000393,38.807922498425874,-0.10103569798899176,-0.022090648965797932
330.40000000000396,38.913746088198586,-0.10050185392508074,-0.024894719495064166
331.500000000004,39.01906702799263,-0.09952644632089859,-0.028312506531111836
332.600000000004,39.126086824428725,-0.09773960926680954,-0.031094488002834098
333.700000000004,39.23187773882743,-0.09824005222072817,-0.03621978012737692
334.80000000000405,39.33466855185151,-0.09812002689021254,-0.0373609122406906
335.90000000000407,39.44365351490226,-0.09846920753292415,-0.04171837095112885
337.0000000000041,39.549263881646326,-0.09802553585449673,-0.04731882857139347
338.10000000000406,39.655742986259305,-0.0987541749021185,-0.05162602310905218
339.2000000000041,39.76135766399417,-0.09959352859674724,-0.05598535398574089
340.3000000000041,39.867823205148916,-0.09905364347600461,-0.059492967901838334
341.4000000000041,39.97387389166084,-0.09975119360172277,-0.06609985902780835
342.50000000000415,40.07964912280332,-0.09960683334917314,-0.07047078842177346
343.6000000000042,40.18624548484604,-0.09949237233652271,-0.07476753123356605
344.7000000000042,40.29298347312498,-0.09850938280533716,-0.08006326242415618
345.80000000000416,40.39947787410797,-0.09686751701206048,-0.08477014462878962
346.9000000000042,40.50563883582956,-0.09589648589863466,-0.09193234787603854
348.0000000000042,40.61176641833108,-0.09554575117049505,-0.09665614763944674
349.10000000000423,40.717240903335124,-0.09406708746969207,-0.10172014298395027
350.20000000000425,40.823878219744124,-0.09345310299535643,-0.10736808181078361
351.3000000000043,40.93043189103645,-0.09086179490544019,-0.11289266888049587
352.4000000000043,41.036235669119215,-0.0897604308479243,-0.11806369278707063
353.5000000000043,41.14367186781612,-0.08871031699993223,-0.12465305888725631
354.60000000000434,41.24878460869822,-0.0859254416917829,-0.1292099285893702
355.7000000000043,41.35498862129233,-0.0832011670730708,-0.13562417003615845
356.80000000000433,41.462432253721104,-0.08434849413956502,-0.1416806216074189
357.90000000000435,41.569070747432505,-0.08410280663881836,-0.14798654503193331
359.0000000000044,41.67493581320312,-0.0813698967641991,-0.15526435472189304
360.1000000000044,41.782259751288706,-0.0803579047164183,-0.15985031887753776
361.2000000000044,41.88916904489391,-0.07795269107189773,-0.166431840657566
362.30000000000445,41.995691350061506,-0.07540631102287455,-0.1727910277683704
363.4000000000044,42.101528130137844,-0.07331145667690214,-0.17758003900272845
364.50000000000443,42.20795731904816,-0.07257965648593555,-0.18546629790746794
365.60000000000446,42.31533875799915,-0.07199203074225416,-0.18950501907337713
366.7000000000045,42.42173787258795,-0.07021756926073063,-0.19532205733283892
367.8000000000045,42.52888248272825,-0.0685376923562715,-0.20264613968314737
368.9000000000045,42.63564957422656,-0.06801058109952561,-0.20934583932125594
370.00000000000455,42.74155123861627,-0.06841436751512601,-0.21522091665844378
371.10000000000457,42.847919903258074,-0.06769223027734614,-0.2208668018584845
372.2000000000046,42.955377488305494,-0.06823203347666158,-0.22691692417899567
373.30000000000456,43.06188059541771,-0.06782896203202927,-0.23303015107107816
374.4000000000046,43.16860669274273,-0.06841672334178943,-0.2395870767721271
375.5000000000046,43.27554791730029,-0.067225960241319,-0.24680438320677522
376.6000000000046,43.38205903325041,-0.06785847634152302,-0.2546136884319594
377.70000000000465,43.48899100040599,-0.06674967191252265,-0.2608343673893301
378.8000000000047,43.59575901396187,-0.06593903711812499,-0.26605889116747905
379.9000000000047,43.70127317212385,-0.06854238472270428,-0.2724433754180784
381.00000000000466,43.809066571183074,-0.06825440601407813,-0.27948897934309747
382.1000000000047,43.91697896209983,-0.06658305851055403,-0.28706494252548875
383.2000000000047,44.023364829402794,-0.0667472997399767,-0.2916770851620436
384.30000000000473,44.12967384622887,-0.06577760141203745,-0.3006899466071111
385.40000000000475,44.23640028428519,-0.06581163157363705,-0.30743682159513686
386.5000000000048,44.342688113174965,-0.06644761094279396,-0.31483374105340634
387.6000000000048,44.450481684452505,-0.06555660258576752,-0.3213751513894123
388.7000000000048,44.55640997997939,-0.06666894947533089,-0.3286597959203883
389.80000000000484,44.664111074895736,-0.06559543750808648,-0.3369851106378614
390.9000000000048,44.77095913656759,-0.06504930820778519,-0.34552637419317556
392.00000000000483,44.877870946630125,-0.06540006769633966,-0.3540409703366709
393.10000000000485,44.98477647766523,-0.06408600064919354,-0.362648216782004
394.2000000000049,45.0914623747084,-0.06396172166324446,-0.3710703197888252
395.3000000000049,45.19856265716108,-0.06350572371126882,-0.3795772041318686
396.4000000000049,45.30509902340212,-0.06301531878524264,-0.388255702673181
397.50000000000495,45.412445164395784,-0.061232963460907376,-0.398022859578107
398.6000000000049,45.51946058654679,-0.060704152504695436,-0.4078729671007064
399.70000000000493,45.626475744429996,-0.0596137845020178,-0.4189568753172459
400.80000000000496,45.733660066776054,-0.05761072192118625,-0.4290323064889119
401.900000000005,45.840112987328965,-0.05522845885911163,-0.4391480335054263
403.000000000005,45.94694993125525,-0.05334301388308909,-0.4502123676691183
404.100000000005,46.05522607888636,-0.05097685209582554,-0.4607718089398469
405.20000000000505,46.161212336721526,-0.04908309882545368,-0.4739167213149398
406.30000000000507,46.26701734820525,-0.04678993692647695,-0.4855674656361755
407.4000000000051,46.37524816430477,-0.04386003915668261,-0.49892804187367634
408.50000000000506,46.482565208115574,-0.039033525088416114,-0.5128931256710154
409.6000000000051,46.589718331326104,-0.034686015916622896,-0.5245873164738946
410.7000000000051,46.69773893181968,-0.029087992931604592,-0.540057252445667
411.8000000000051,46.8033587638993,-0.024105107169098874,-0.553596951490706
412.90000000000515,46.911664117963944,-0.017134134606220923,-0.5692493883172802
414.0000000000052,47.01839367468326,-0.009908879020774454,-0.5855594509570841
415.1000000000052,47.12659083058962,-0.0011793946502840714,-0.602105226588745
416.20000000000516,47.232919405108646,0.005205761588030259,-0.6198887695436355
417.3000000000052,47.340602297063946,0.012560624942925133,-0.6375022054514514
418.4000000000052,47.4475398179927,0.019927010979924577,-0.6559184362112891
419.50000000000523,47.554866215976936,0.02827598161628894,-0.6742656434106964
420.60000000000525,47.662476640165465,0.035931945700321495,-0.6948040631777506
421.7000000000053,47.76907662566887,0.04023125354270786,-0.714769508141829
422.8000000000053,47.87664563649181,0.04765364344291898,-0.7377415316926466
423.9000000000053,47.983654756601275,0.052899061084434,-0.758072069211349
425.00000000000534,48.092132079250874,0.05979140112261153,-0.7803951224561709
426.1000000000053,48.1989880253481,0.06541584462971764,-0.8042359835813295
427.20000000000533,48.305020412477745,0.07136478790187721,-0.8294753762577383
428.30000000000535,48.413544723018255,0.07626770996258203,-0.8541611228513846
429.4000000000054,48.520281145189614,0.08280193993553847,-0.8785892773030706
430.5000000000054,48.62842362787116,0.08725625063914372,-0.9061805855412763
431.6000000000054,48.73536524094062,0.09245840160328975,-0.9339028838538481
432.70000000000545,48.843119776785606,0.09667016794497903,-0.9617573238126225
433.8000000000054,48.95033376889145,0.09890106865465298,-0.9878759981948084
434.90000000000543,49.05702044605394,0.10255510668080597,-1.0157785946861253
436.00000000000546,49.16629047367576,0.10490242333606124,-1.0480362021072436
437.1000000000055,49.27200023794487,0.10515946927496271,-1.0764411770742779
438.2000000000055,49.38068420294026,0.10371120413153262,-1.1032298309525763
439.3000000000055,49.48766615489193,0.1034545140401817,-1.1318560789046583
440.40000000000555,49.59547182163341,0.10035896245312542,-1.1591666696547112
441.50000000000557,49.70366436049905,0.09627797153655704,-1.186300410380956
442.6000000000056,49.811142911679,0.0896898242194013,-1.210466223323463
443.70000000000556,49.918875839401,0.08397712419011251,-1.235203080550352
444.8000000000056,50.02547005321271,0.07469943644407812,-1.2567046317502837
445.9000000000056,50.133610036363955,0.06568484426096018,-1.2787740104418686
447.0000000000056,50.24046562152374,0.05392672971873576,-1.2963702861933801
448.10000000000565,50.34907143736544,0.03869287943589096,-1.313431149159392
449.2000000000057,50.457098802976276,0.027634784434457684,-1.3283267159437289
450.3000000000057,50.56379645734226,0.01264380929310876,-1.3419675575546566
451.40000000000566,50.67146013720699,-0.000496350481677787,-1.3545741282421466
452.5000000000057,50.778066642341656,-0.012809006395823845,-1.3681062248491074
453.6000000000057,50.885146216762095,-0.02108168908999978,-1.3792456167391487
454.70000000000573,50.99521168074445,-0.028874046153196713,-1.389066361498398
455.80000000000575,51.10227165038814,-0.03696297194098191,-1.4002313173235565
456.9000000000058,51.2095710262968,-0.0408216190891615,-1.4114044078558283
458.0000000000058,51.317534702482995,-0.044160080189808944,-1.4217000986407218
459.1000000000058,51.42404503734937,-0.04483447825791353,-1.431523471158655
460.20000000000584,51.533109756579606,-0.04538434474490022,-1.442078944846838
461.3000000000058,51.640579959220766,-0.04541579019742357,-1.451972934110874
462.40000000000583,51.7500097675016,-0.042423236740755155,-1.463718508358899
463.50000000000585,51.85717404459378,-0.04063148541336428,-1.4747170567592751
464.6000000000059,51.965830234333,-0.036648941830753665,-1.4865714631382336
465.7000000000059,52.073517519813045,-0.035345990795770776,-1.4973098793459862
466.8000000000059,52.18211258138328,-0.031192960825187827,-1.5100626790368978
467.90000000000595,52.28989508987727,-0.026855689078252698,-1.524916503958449
469.0000000000059,52.40025705077837,-0.025449309735143543,-1.5367707399105308
470.10000000000593,52.5069376469986,-0.023680877404155823,-1.551125310520253
471.20000000000596,52.61583178311277,-0.024292188959868972,-1.5653761553932384
472.300000000006,52.723486655964365,-0.024955676147259312,-1.5796026800229992
473.400000000006,52.83177553180342,-0.02866781281733032,-1.5939153836877709
474.500000000006,52.939852557905716,-0.03635388226822275,-1.6089493763473723
475.60000000000605,53.04828923854713,-0.048666459873982375,-1.620419661409429
476.70000000000607,53.15668171706515,-0.06286196811016753,-1.6321548521379832
477.8000000000061,53.264289293871435,-0.08069519288145556,-1.6412415843104609
478.90000000000606,53.37221899846603,-0.10208631218005357,-1.6472535752117712
480.0000000000061,53.479562869747,-0.12439444620825453,-1.6543157168708253
481.1000000000061,53.588649667764216,-0.14784280146886022,-1.6591009270002264
482.2000000000061,53.69630753221042,-0.16345466479976214,-1.6634820784309503
483.30000000000615,53.80474269236647,-0.17946648317308914,-1.6647513415036959
484.4000000000062,53.91342217563892,-0.1901049886628365,-1.6676545785375514
485.5000000000062,54.02094748709155,-0.19825808034523346,-1.6703554196260604
486.60000000000616,54.130480316422805,-0.20063285896041078,-1.671672573961088
487.7000000000062,54.23886200521875,-0.202098826249537,-1.6739440187836285
488.8000000000062,54.34749156656249,-0.20334198714212692,-1.6756113142268716
489.90000000000623,54.455156746151395,-0.20326717830750887,-1.6769310844548997
491.00000000000625,54.56351653836531,-0.2024815896403103,-1.6782499802002238
492.1000000000063,54.67179690892419,-0.20155765659558278,-1.6795775890115436
493.2000000000063,54.78131346844891,-0.2009673135964191,-1.6795721060308337
494.3000000000063,54.88732489566852,-0.19978586115203997,-1.6822329136264509
495.40000000000634,54.99657781277669,-0.19764806671500823,-1.682853263897539
496.5000000000063,55.104513463595374,-0.19670327918190184,-1.684180551021536
497.60000000000633,55.21486242245292,-0.19530777359357718,-1.6841808678926187
498.70000000000636,55.321703643013294,-0.19554524440053928,-1.6854898601361166
499.8000000000064,55.43012458907685,-0.1934113192151499,-1.6868137403384793
500.9000000000064,55.53868128001055,-0.19205567785728822,-1.686538387304052
502.0000000000064,55.647396861478654,-0.19065053167827806,-1.6876950349881907
503.10000000000645,55.754992515696905,-0.18891797744671807,-1.6904191413790817
504.2000000000064,55.86241961532995,-0.18772197597915044,-1.6917588311821339
505.30000000000643,55.969403758577776,-0.1856006592197996,-1.6930799697623904
506.40000000000646,56.07972336982501,-0.18495771579779652,-1.6943926408650412
507.5000000000065,56.18713198185854,-0.1839219278241046,-1.6953741551622885
508.6000000000065,56.294025634927586,-0.18174704944749345,-1.6957576008052206
509.7000000000065,56.4036182472458,-0.1784651646898885,-1.6977271895904416
510.80000000000655,56.511756602694184,-0.1719522203965716,-1.6969209381958064
511.90000000000657,56.61841908966419,-0.17123894502509654,-1.6984567726257485
513.0000000000066,56.72817612851215,-0.16742645489467864,-1.7004298372493052
514.1000000000065,56.837046040777444,-0.1666781326413438,-1.7017510817139518
515.2000000000066,56.94479165798926,-0.16589794949813252,-1.7021293540427633
516.3000000000065,57.053064123381596,-0.16525193933595905,-1.7033999528487112
517.4000000000067,57.161599866142225,-0.16375101605680378,-1.704710666812637
518.5000000000066,57.26956369092623,-0.1628662550174424,-1.7060446706632924
519.6000000000067,57.3785008553756,-0.16200884862658865,-1.7070072988226532
520.7000000000066,57.487442232095546,-0.16019611826181138,-1.7083277087379911
521.8000000000067,57.59579731403121,-0.15902731823825006,-1.7096515595903696
522.9000000000067,57.70370087462696,-0.15827871631331147,-1.709637083140776
524.0000000000067,57.81295686951833,-0.16015150982772447,-1.7109304333559798
525.1000000000067,57.9212181964512,-0.15762149535251224,-1.7149246733939107
526.2000000000068,58.030740226520514,-0.15665506746540298,-1.7139298589962757
527.3000000000068,58.13800791030449,-0.15782233155833333,-1.7165822512875146
528.4000000000068,58.24779861422212,-0.15471950448703306,-1.7177968593945039
529.5000000000068,58.35712943280788,-0.1533502811615003,-1.7191865321945352
530.6000000000068,58.46594450848315,-0.15355323845405677,-1.7202233621402279
531.7000000000069,58.57475919011377,-0.15245979369244783,-1.7215105316161932
532.8000000000068,58.683917347793006,-0.1531882793540299,-1.7214810312610878
533.9000000000069,58.792826874171155,-0.15151920585204737,-1.7241396527903965
535.0000000000068,58.901608890808724,-0.1518109186245012,-1.7241528248060303
536.100000000007,59.010410520980564,-0.1507646439778191,-1.7254628113783186
537.2000000000069,59.119377177921656,-0.15103049312523342,-1.72677548206586
538.300000000007,59.228338723190994,-0.15267528067992414,-1.7280885346945047
539.4000000000069,59.337421988878454,-0.1511462723945349,-1.7294293984278428
540.5000000000069,59.446609491631754,-0.15049338759176434,-1.7307582158558943
541.600000000007,59.55523556595437,-0.14924597409918983,-1.7326124565158545
542.700000000007,59.66481414729693,-0.14991968262474312,-1.734703153013136
543.800000000007,59.77407295653032,-0.15030758891889634,-1.7359716630169322
544.900000000007,59.88398516069644,-0.14953886579878778,-1.7368148206947454
546.000000000007,59.99175880182896,-0.15012411801883793,-1.7389686292868762
547.1000000000071,60.10112066027338,-0.14826586138266015,-1.7402921816647767
548.2000000000071,60.210864283494146,-0.14787373645419472,-1.742924335239385
549.300000000007,60.31926537571114,-0.14762374429652905,-1.7449079915088013
550.4000000000071,60.427656963900496,-0.1451645063503468,-1.7468914087893586
551.500000000007,60.5373873194674,-0.144545462737667,-1.747522404433861
552.6000000000072,60.64622285689361,-0.14480919743726334,-1.7501360352553657
553.7000000000071,60.75558124155683,-0.14409478093491673,-1.7519751781407584
554.8000000000072,60.86497330348959,-0.14351118570889165,-1.753456505415715
555.9000000000071,60.97333463444205,-0.14311298251847848,-1.7561616043152934
557.0000000000072,61.08404970735931,-0.14126729956684764,-1.7584516744368774
558.1000000000072,61.19169145574587,-0.14128455653604846,-1.7601548427326823
559.2000000000072,61.300761866875234,-0.13862375907034988,-1.7639964489329802
560.3000000000072,61.41030235437599,-0.13724772538169966,-1.7666575413408667
561.4000000000073,61.51967817499781,-0.13553485803898802,-1.7673077698473376
562.5000000000073,61.628665532906496,-0.13521040730942446,-1.770864853615576
563.6000000000073,61.73683371305858,-0.13448697048730066,-1.7738724658394531
564.7000000000073,61.84755111120947,-0.13284336011530623,-1.776644890706081
565.8000000000073,61.9560180225779,-0.13074609718274913,-1.7800402370038633
566.9000000000074,62.065551377317774,-0.1289541179912801,-1.7826294345333795
568.0000000000074,62.17454973575643,-0.12647017772969407,-1.786747571899891
569.1000000000074,62.284303183102,-0.12156638462416175,-1.7894983179221238
570.2000000000073,62.392929093237036,-0.11841876040714507,-1.7907832994509034
571.3000000000073,62.502866682875165,-0.11429863290626886,-1.7964944129317209
572.4000000000074,62.612131679486716,-0.1102722591637731,-1.7993660456110074
573.5000000000074,62.72252792335506,-0.10468744075163876,-1.803754023359594
574.6000000000074,62.83124701239044,-0.09916010966998591,-1.8083486380616254
575.7000000000074,62.939557706714524,-0.09452371130447415,-1.8118124600459384
576.8000000000075,63.049263179414204,-0.09021822137685213,-1.8171467568822943
577.9000000000075,63.15886105918788,-0.08572475412743748,-1.823270436329378
579.0000000000075,63.267914342591816,-0.08204490604793839,-1.8293015753331443
580.1000000000075,63.37733816633731,-0.07910577678564447,-1.8347019371337692
581.2000000000075,63.48642415452677,-0.07789579051291515,-1.8397522322067439
582.3000000000076,63.59583796154182,-0.07619029869861636,-1.8477967181964603
583.4000000000076,63.70624799900025,-0.07439468052837603,-1.8548065847000719
584.5000000000076,63.815393729262325,-0.07477796705683726,-1.8602367214268227
585.6000000000076,63.923951069215505,-0.07321532187254584,-1.8678828743303204
586.7000000000077,64.03372503432705,-0.07259893380989373,-1.8751451209936976
587.8000000000077,64.1427597430294,-0.07322299522432027,-1.883149664347906
588.9000000000076,64.25204866510705,-0.07088264017593486,-1.890246833078519
590.0000000000076,64.36114870577099,-0.06946592147680991,-1.8980356970977956
591.1000000000076,64.4710273086666,-0.06835830257559343,-1.9054365810409166
592.2000000000077,64.57994175122269,-0.0670480191682094,-1.9144466516769665
593.3000000000077,64.68907215954673,-0.06755501303603983,-1.9228400360331621
594.4000000000077,64.7985765707962,-0.06504364835374588,-1.930914128824086
595.5000000000077,64.90628728333607,-0.06525470515845558,-1.9403746607664845
596.6000000000078,65.01650259557405,-0.06526255593973089,-1.9490780479463585
597.7000000000078,65.12636109564848,-0.06441658569073624,-1.9581386708294897
598.8000000000078,65.23561969151528,-0.06467641127844274,-1.966967244545121
599.9000000000078,65.34587944916329,-0.06506171493679776,-1.9769356113654326
601.0000000000078,65.45506158026781,-0.06552008285838862,-1.9865376138674873
602.1000000000079,65.5639646940355,-0.06687491143182321,-1.9969230328984002
603.2000000000079,65.67360394081935,-0.06817514190452,-2.005385524207266
604.3000000000079,65.78393078269562,-0.07029321690172978,-2.012124010334036
605.4000000000078,65.89295698290162,-0.07292875497321574,-2.0219531313746812
606.5000000000078,66.00292815161963,-0.07455488175370054,-2.0304014960789187
607.6000000000079,66.1116886862072,-0.07847321951221803,-2.036872812374609
608.7000000000079,66.22225645565338,-0.08099280769387725,-2.0412876455850157
609.8000000000079,66.33126275061193,-0.08107122702501765,-2.046476604918931
610.9000000000079,66.43905994865918,-0.07741052671272916,-2.051291897029419
612.000000000008,66.55103071734128,-0.07840509631866134,-2.053940265803978
613.100000000008,66.66012180452812,-0.08049759017991824,-2.054271183481576
614.200000000008,66.76980528089025,-0.08188522267420895,-2.055578947855002
615.300000000008,66.8789775329408,-0.08026003835855289,-2.056569476868553
616.400000000008,66.98866491127401,-0.07360831415719118,-2.0578660407300435
617.5000000000081,67.09815881514866,-0.06635309684420097,-2.0592000614264188
618.6000000000081,67.20556954234576,-0.0611022210008785,-2.0605543544777123
619.7000000000081,67.31715354157323,-0.05204504747978754,-2.062816556804832
620.8000000000081,67.42651940916255,-0.04794651048097902,-2.062477559304927
621.9000000000082,67.53655344329685,-0.0430560096428893,-2.064528978568706
623.0000000000082,67.64656595906612,-0.03868915699855074,-2.0643892477670214
624.1000000000081,67.75685293573669,-0.0362174976706887,-2.067087867281145
625.2000000000081,67.86635016508899,-0.03137089897826433,-2.0684200786538476
626.3000000000081,67.97605079090116,-0.026402670740175986,-2.0697342810245773
627.4000000000082,68.08549295275125,-0.02318021244115407,-2.072482638117093
628.5000000000082,68.19623847551549,-0.019645798197781845,-2.0724835863362254
629.6000000000082,68.30566690282154,-0.01601526882146406,-2.0748414161264463
630.7000000000082,68.41546377730893,-0.011767114716127439,-2.076710550152844
631.8000000000083,68.52453853484718,-0.006286470192415617,-2.0774284473340954
632.9000000000083,68.63352554033189,-0.00033332994433773685,-2.0787415991264004
634.0000000000083,68.74445260412418,0.004438081086618991,-2.0799799968276105
635.1000000000083,68.85375585189696,0.011607938516109279,-2.082688050385674
636.2000000000083,68.96478228444123,0.017972680926821843,-2.0840098629316595
637.3000000000084,69.07386183922394,0.023429461935799013,-2.0853773109749842
638.4000000000084,69.18145480758685,0.030207767634123806,-2.0878831630979664
639.5000000000084,69.29380122198683,0.0392511996760573,-2.089938580230893
640.6000000000083,69.40313511056097,0.04894633404507194,-2.092634609101408
641.7000000000083,69.51330924527261,0.05873927448914122,-2.0932826162985343
642.8000000000084,69.62170346869841,0.0699925057668384,-2.0951421804554973
643.9000000000084,69.73250802476856,0.08101286209450301,-2.099203826630885
645.0000000000084,69.84289961857924,0.09163245540244422,-2.10162507224072
646.1000000000084,69.95256563343497,0.10534460556051381,-2.105846811367215
647.2000000000085,70.06255803828948,0.11830825689709067,-2.108119689749015
648.3000000000085,70.17234493772122,0.1338159578712221,-2.1099598712169665
649.4000000000085,70.28255989522447,0.14775089553884252,-2.1138577997562624
650.5000000000085,70.39221554932499,0.16028460622514207,-2.1153205123441428
651.6000000000085,70.50248685696393,0.1767079737310514,-2.1195053860929116
652.7000000000086,70.61268359827652,0.19720048874541143,-2.120711992869806
653.8000000000086,70.7230173254445,0.21614056167712156,-2.1248290603386852
654.9000000000086,70.83159527037954,0.23466508058612107,-2.128576964935074
656.0000000000086,70.94211606916245,0.2517347865505238,-2.132676635386624
657.1000000000087,71.05354034051167,0.2688141960844118,-2.1371213647410814
658.2000000000087,71.16293768839829,0.2888757488784989,-2.1421001171204437
659.3000000000086,71.27357360526707,0.3068908243776242,-2.1451616049385733
660.4000000000086,71.38444808232867,0.32724984919014544,-2.150560316625941
661.5000000000086,71.49298049363846,0.3485702682282303,-2.154806853042686
662.6000000000087,71.60436671778977,0.37027676481153915,-2.159586017038668
663.7000000000087,71.71400475449909,0.39301588927685915,-2.164431068506885
664.8000000000087,71.82508238751905,0.41485868589386043,-2.169580263516158
665.9000000000087,71.9339845621551,0.4356942287648093,-2.1741315614232084
667.0000000000088,72.04486044782982,0.4586619087971187,-2.180582907574628
668.1000000000088,72.15550985728089,0.4815378236691539,-2.185142033651075
669.2000000000088,72.26462035329519,0.5040226832470561,-2.190930588655026
670.3000000000088,72.37542636194381,0.5294015978115012,-2.1957676658776784
671.4000000000088,72.4847972517333,0.5520140795044941,-2.2023770835992966
672.5000000000089,72.59489302955352,0.57813080206304,-2.209202422749639
673.6000000000089,72.70621663016304,0.602909820455977,-2.215660890417704
674.7000000000089,72.81590915736908,0.6270200742795818,-2.2209122951689655
675.8000000000088,72.92560867979583,0.6510754497601868,-2.2288479868898383
676.9000000000088,73.03620595038088,0.6795857048645583,-2.235689030626806
678.0000000000089,73.14639139722352,0.7093636038647221,-2.242999289941022
679.1000000000089,73.25652056227288,0.7356667273041644,-2.2502585113154607
680.2000000000089,73.36709699429419,0.7585700612588497,-2.2574202150104465
681.3000000000089,73.47744815667399,0.785938311248102,-2.2659816321024966
682.400000000009,73.58748112110675,0.8149050973068311,-2.273027458068845
683.500000000009,73.69714234139529,0.8401384660044876,-2.2824357205224013
684.600000000009,73.80703963343308,0.8684971524529231,-2.291179762788753
685.700000000009,73.9166465279386,0.8945748012359163,-2.2991455235692957
686.800000000009,74.02788400827906,0.9205831461616417,-2.3072886568569757
687.9000000000091,74.13813398713643,0.9468012243547542,-2.3161179523837587
689.0000000000091,74.24676267850468,0.9759269670121425,-2.3258346448870855
690.1000000000091,74.35644918294398,0.9991726609114332,-2.334857713045559
691.2000000000091,74.46702218509604,1.0260068464981573,-2.3433867803071196
692.3000000000092,74.57647070875788,1.057306469218661,-2.3537511296995346
693.4000000000092,74.68614116601012,1.0859692466720288,-2.3638517645239996
694.5000000000091,74.79723773715938,1.115345261399135,-2.3737962374364185
695.6000000000091,74.90633086751535,1.144782010587996,-2.3842888932697863
696.7000000000091,75.01618980117931,1.177290877008422,-2.3957441951657077
697.8000000000092,75.12692352102515,1.2097266032335035,-2.4054438633470236
698.9000000000092,75.23717362163418,1.2450626296617704,-2.4155143605600538
700.0000000000092,75.34754319758747,1.2806327889960156,-2.4269682542699584
701.1000000000092,75.45805197585456,1.3169076365317425,-2.436535451724803
702.2000000000093,75.56798267570488,1.356368225352866,-2.4491502219807666
703.3000000000093,75.678882648264,1.3933878482698634,-2.4597752524617884
704.4000000000093,75.78896261090783,1.434879585479356,-2.4726125874386016
705.5000000000093,75.89917000000094,1.470100000000509,-2.4843900650000927
706.6000000000093,76.01030872656153,1.5125316594317828,-2.4966751763680692
707.7000000000094,76.12056229001696,1.5465370002884,-2.509351390862088
708.8000000000094,76.23126078925871,1.5767301361517696,-2.521960726822336
709.9000000000094,76.34152776353632,1.6064865759581086,-2.5350822053002147
711.0000000000093,76.45023154750714,1.6341997592311799,-2.5479948724554387
712.1000000000093,76.56174531453878,1.661233783717645,-2.560723424808661
713.2000000000094,76.67260592552623,1.6761665085128798,-2.573647751161624
714.3000000000094,76.7815621294349,1.6854590441063602,-2.5871772268055944
715.4000000000094,76.89220196736618,1.6877406881967547,-2.600951307594716
716.5000000000094,77.00313346325498,1.6819474526476652,-2.6149427924332262
717.6000000000095,77.11379195636694,1.6625796518723774,-2.6277719430042215
718.7000000000095,77.22287061760541,1.63429688050079,-2.640585709374921
719.8000000000095,77.33327466881332,1.5949772724130802,-2.6528194359186834
720.9000000000095,77.44335796250758,1.5445656344287328,-2.6664338297564285
722.0000000000095,77.55333482539412,1.477094896329331,-2.6781479257616816
723.1000000000096,77.66284198177276,1.3908689493891968,-2.689045907898012
724.2000000000096,77.77228933807177,1.2815487653176105,-2.699819192233932
725.3000000000096,77.88242889732255,1.1381973469439768,-2.710553186076481
726.4000000000096,77.99247919009531,0.9257791155902002,-2.7199138867258057
727.5000000000097,78.10190702130387,0.5327993830766308,-2.727869491655987
728.6000000000097,78.21069077045907,0.09016414537581152,-2.7318345579845893
729.7000000000096,78.3204364374437,-0.12937110288554274,-2.733144098656983
730.8000000000096,78.43019034951831,-0.2261809082543975,-2.7344698013786206
731.9000000000096,78.53970202508127,-0.27037878993621195,-2.7357902272341823
733.0000000000097,78.64926631764794,-0.29839497797491293,-2.737109962551565
734.1000000000097,78.75957351597961,-0.31363679811918393,-2.7378128899656424
735.2000000000097,78.8699223596132,-0.3248189836434763,-2.7371198080923644
736.3000000000097,78.9801686584753,-0.33235521392783585,-2.737759798420112
737.4000000000098,79.09135512143018,-0.34048187629788357,-2.738429514467045
738.5000000000098,79.2011260069711,-0.34621172346223533,-2.7383500948508397
739.6000000000098,79.31197220098767,-0.34780477741848354,-2.738751637858531
740.7000000000098,79.42252673214702,-0.3488944503483614,-2.7387707736072064
741.8000000000098,79.53256097170865,-0.35168480964862575,-2.739389509222474
742.9000000000099,79.64405066892346,-0.3516799441815719,-2.7401025723262746
744.0000000000099,79.75453311825677,-0.35358076756389845,-2.7400596331817946
745.1000000000099,79.86418252176902,-0.35655521149322206,-2.740392095331219
746.0000000000099,79.95535266246877,-0.35436381604468975,-2.740347958928398