File: 01_Data/Polyester_Carpet_High_Pile/STA/N2/10K_min/Polyester_Carpet_High_Pile_STA_N2_10KData_220907_R1.csv
##Temp./Â°C,Time/min,DSC/(mW/mg),Mass loss/mg
51.0,10.844870410139501,-1.5278305697451173,-0.006238001475406207
52.100000000000016,11.186170941633602,-1.4186758370004433,-0.007169266910659999
53.20000000000003,11.428308743625747,-1.343027815469306,-0.00691448961119967
54.30000000000005,11.631369371294689,-1.2898099162398353,-0.007035679604758371
55.40000000000006,11.816758464492617,-1.2436613807615133,-0.006354623777585999
56.50000000000008,11.986857609805545,-1.2095934793328011,-0.006993917793237436
57.600000000000094,12.14695040041938,-1.179504898212887,-0.005234751138661231
58.70000000000011,12.300825123904737,-1.1534206950373476,-0.00549496682968087
59.800000000000125,12.446871337063682,-1.1321120275082857,-0.005832103918823606
60.90000000000014,12.598151999492016,-1.1121507154485988,-0.005983200049165305
62.000000000000156,12.739862843993205,-1.0943401341459755,-0.0057388771925648285
63.10000000000017,12.879747451992749,-1.0771953707760693,-0.005731654345657589
64.20000000000019,13.016714145616318,-1.0619936248119304,-0.005759306996020008
65.30000000000021,13.151000098306719,-1.0492144496129467,-0.007759235750528504
66.40000000000022,13.285850487729473,-1.0355876508470072,-0.006473359106928811
67.50000000000023,13.416270197392521,-1.022213787056159,-0.007282215217103705
68.60000000000025,13.54204817718195,-1.0093350268834032,-0.007914898340959375
69.70000000000027,13.673638090931382,-0.9967999116552911,-0.007335854138057485
70.80000000000028,13.799076343132644,-0.9859550207532083,-0.007349644058753491
71.90000000000029,13.9258052630774,-0.9725665472926265,-0.007365444604411131
73.00000000000031,14.04963020432398,-0.9625296682825057,-0.005997017243667635
74.10000000000034,14.174316662220372,-0.9512993594882279,-0.0066995585068090335
75.20000000000034,14.296923947990548,-0.9426025173490725,-0.007414780260284637
76.30000000000035,14.416699405286963,-0.9351856223198606,-0.0074702806032336255
77.40000000000038,14.538497279621454,-0.9284567105182735,-0.007491472091333939
78.5000000000004,14.657837606291764,-0.920820054537865,-0.008607278174191713
79.6000000000004,14.776895334543658,-0.9144721251995857,-0.007503099360520515
80.70000000000041,14.894440949830535,-0.9074161882238113,-0.008816363519601467
81.80000000000044,15.012917107092381,-0.8999804319671905,-0.010090215548817838
82.90000000000046,15.130142905986357,-0.8937783430376137,-0.008782422030181536
84.00000000000047,15.24574762005602,-0.8861881228558748,-0.009183475106426364
85.10000000000048,15.361723866427685,-0.880320812367478,-0.010127641455591974
86.2000000000005,15.477134767370188,-0.8730463920471331,-0.009708716887980806
87.30000000000052,15.591637801908453,-0.8669818698935698,-0.009314192021256495
88.40000000000053,15.705166144194592,-0.861421565722653,-0.010848848018562673
89.50000000000054,15.817708879111866,-0.8536981110008679,-0.008789552916960375
90.60000000000056,15.93010761434151,-0.849135023775605,-0.01117605342200445
91.70000000000059,16.042790653485767,-0.8424695251743111,-0.009445081662811994
92.8000000000006,16.155589495555315,-0.8361335865378642,-0.010205022138241926
93.9000000000006,16.266038739405854,-0.8308452977417264,-0.010531902128725346
95.00000000000063,16.37788342556013,-0.8230278076387354,-0.011450517834581397
96.10000000000065,16.487392040373194,-0.8176812581905992,-0.010104060589104069
97.20000000000066,16.596021885852885,-0.8110635394517348,-0.010200478450014483
98.30000000000067,16.706295669157935,-0.8045414075388299,-0.008849320306617336
99.40000000000069,16.81865509885866,-0.797539766448321,-0.01142319894317989
100.50000000000071,16.92768769954109,-0.792267473992754,-0.011565214773235688
101.60000000000072,17.03633966969671,-0.7859256380620727,-0.0114043131721977
102.70000000000073,17.145876945414653,-0.7783119470317119,-0.01142136586918685
103.80000000000075,17.25476291491063,-0.773383698424566,-0.011793050343248623
104.90000000000077,17.364320337771787,-0.7658111469144732,-0.012680815262321232
106.00000000000078,17.472032958942986,-0.7595303668355122,-0.010269968598935808
107.10000000000079,17.580000000000073,-0.7525699999999937,-0.011421213429998467
108.20000000000081,17.688130598221907,-0.745532321472698,-0.011422814317661789
109.30000000000084,17.795790660956882,-0.738114556367645,-0.012729421171272293
110.40000000000084,17.9047348517409,-0.7339816347361846,-0.011421375797758593
111.50000000000085,18.01133234798796,-0.7262697333028464,-0.011432776376887333
112.60000000000088,18.120386057599198,-0.722104946077201,-0.012746701615614864
113.7000000000009,18.228235122778113,-0.7172804453426972,-0.011424714078532627
114.8000000000009,18.335288306786993,-0.7105750989607746,-0.011420895013340981
115.90000000000092,18.442607691150165,-0.7034206978856666,-0.011420112770553992
117.00000000000094,18.550966870205635,-0.698202660080309,-0.011425759556975112
118.10000000000096,18.657254440318304,-0.6936880663657017,-0.012209952538153601
119.20000000000097,18.76461093937761,-0.6872612474183496,-0.01141668960513087
120.30000000000098,18.871771037183528,-0.6815249503369456,-0.012731902958770025
121.400000000001,18.979796171472145,-0.6775995830335151,-0.012738264280375056
122.50000000000102,19.0872366011826,-0.6712496628317993,-0.012745626797704634
123.60000000000103,19.19340871741549,-0.6663639883686183,-0.01153355469316697
124.70000000000104,19.297699626550106,-0.6617957440454796,-0.01404370873067462
125.80000000000106,19.407898867379917,-0.6572994792209816,-0.014060590451986599
126.90000000000109,19.514536050787804,-0.6510091464043842,-0.012738180959042555
128.00000000000108,19.62136320162549,-0.6446190895790297,-0.014165845960722123
129.1000000000011,19.727523364175802,-0.6404482882466159,-0.014059760419108613
130.20000000000113,19.83341768512662,-0.6348355970509352,-0.012749684207179257
131.30000000000115,19.94080221091575,-0.6300300007675141,-0.014060007817461084
132.40000000000117,20.045481586764346,-0.6242216869558386,-0.014060291526107882
133.50000000000117,20.15258259935905,-0.6198900042514336,-0.01277041914702215
134.6000000000012,20.258472416761634,-0.6138230862360375,-0.0140388617806817
135.7000000000012,20.36451468179048,-0.6087622539816783,-0.014039762507653819
136.8000000000012,20.470202132656432,-0.6034912897620744,-0.014048741241670992
137.90000000000123,20.575391756736614,-0.59809031340442,-0.01406016965095791
139.00000000000125,20.680976131785037,-0.5944447657198753,-0.014973571901531813
140.10000000000127,20.787206261529185,-0.588364885844975,-0.014057613525868096
141.2000000000013,20.892322196142036,-0.5837189455758449,-0.015365249088692412
142.3000000000013,20.997941799887975,-0.5800177117317235,-0.014060027021636667
143.4000000000013,21.102170907475006,-0.5747602396133691,-0.014061046736383087
144.50000000000134,21.20749677638899,-0.5690388735680344,-0.014050100024273426
145.60000000000133,21.312327164810878,-0.5629649542855678,-0.012702632213133835
146.70000000000135,21.41828211102352,-0.5581235224623957,-0.013964463470453214
147.80000000000138,21.523081665084256,-0.553612588146572,-0.014059909899634793
148.9000000000014,21.627559573894878,-0.5463397285552374,-0.014059322527852025
150.00000000000142,21.731980499080827,-0.5410809735986324,-0.012740890984072273
151.10000000000142,21.836778465839426,-0.5335238760407258,-0.014060074958106128
152.20000000000144,21.94137178754897,-0.5267021206129898,-0.013967924062888049
153.30000000000146,22.04684329892146,-0.5198531025148855,-0.014050547216475806
154.40000000000146,22.150688054441932,-0.510048772534416,-0.015367156595324172
155.50000000000148,22.256336214454464,-0.5025474316026584,-0.01405992123708133
156.6000000000015,22.360313699346964,-0.4946201519707805,-0.013291782669700325
157.70000000000152,22.464342933507744,-0.4826561398474998,-0.014390137539643355
158.80000000000155,22.570000000000164,-0.4713699999999823,-0.015479210265000987
159.90000000000154,22.673737741086224,-0.45943003180046493,-0.01408421978217067
161.00000000000156,22.77971248506744,-0.44676901753112147,-0.015367204165628756
162.1000000000016,22.882978596836626,-0.43566434267878384,-0.01405058685678684
163.20000000000158,22.987957480780715,-0.42650147495708274,-0.015370042265880457
164.3000000000016,23.093596325848097,-0.4170344247502116,-0.01555053472599921
165.40000000000163,23.196631303999727,-0.41076624866346445,-0.015379972454507396
166.50000000000165,23.302001824795926,-0.4113606213900228,-0.0166073493791572
167.60000000000167,23.40694447075379,-0.4194503226785842,-0.015379891703169779
168.70000000000167,23.510189485974806,-0.43253612773313216,-0.01537985919220608
169.8000000000017,23.61587711075827,-0.44434137878470803,-0.015369274336435979
170.9000000000017,23.720190591900344,-0.4532115238430963,-0.01541895690283912
172.0000000000017,23.824109844642095,-0.46015799122260326,-0.01630526507484431
173.10000000000173,23.929907493317597,-0.4622397012255022,-0.01537057435143696
174.20000000000175,24.031841847199114,-0.4635703138628739,-0.016030506909322728
175.30000000000177,24.137962169467837,-0.46337933038016765,-0.01537314520937727
176.4000000000018,24.242526307661148,-0.4621954887940853,-0.016370039683045068
177.5000000000018,24.34621003415099,-0.45904694681994296,-0.01563561551554038
178.6000000000018,24.452733597634385,-0.45711453966542054,-0.01669036028886195
179.70000000000184,24.556298987006908,-0.45417336033306394,-0.01674356340537342
180.80000000000183,24.66214909427056,-0.4512561825254042,-0.015699881641653146
181.90000000000185,24.765491897698755,-0.44777619506958477,-0.01571285794864208
183.00000000000188,24.869570158855456,-0.4444768101882502,-0.01740291397139959
184.1000000000019,24.972836992689324,-0.44155154837007804,-0.016699764339477063
185.20000000000192,25.07778619335573,-0.4372479706720309,-0.016700192999461017
186.30000000000192,25.1817918830416,-0.43505286632443346,-0.016699783401767476
187.40000000000194,25.286234149309198,-0.43188673129046024,-0.016713348459702182
188.50000000000196,25.390407694946614,-0.4286869734934495,-0.016647946824246862
189.60000000000196,25.495141932228215,-0.42617603198181164,-0.017677463829626205
190.70000000000198,25.599401012299687,-0.42404292950610323,-0.016354151693909635
191.800000000002,25.703163929183138,-0.4217138062888258,-0.017672807266692736
192.90000000000202,25.808359830534073,-0.41856617234866056,-0.017677719821348692
194.00000000000205,25.912981278325805,-0.41575902250901214,-0.01767957080022553
195.10000000000204,26.01596180615851,-0.41122366571024815,-0.01774866905897854
196.20000000000206,26.122693036091405,-0.40823456524594937,-0.017683481665260015
197.3000000000021,26.224667027338427,-0.4057591546769341,-0.01863785618071212
198.40000000000208,26.32971864509666,-0.40274735016473484,-0.018659873878755118
199.5000000000021,26.433328516823252,-0.39853441826046065,-0.01763551415359288
200.60000000000213,26.537443627787756,-0.39575072597077093,-0.017679664336349266
201.70000000000215,26.642800455837687,-0.3923187025923196,-0.019000127568158387
202.80000000000217,26.747406403244437,-0.3890341524870255,-0.017651571442770297
203.90000000000217,26.851777031570844,-0.3851035771235727,-0.017677472314362674
205.0000000000022,26.95626299180118,-0.38176440181831206,-0.019000128745231493
206.1000000000022,27.059361196483014,-0.378082204918223,-0.0189996680313671
207.2000000000022,27.163963504204045,-0.37517264587367466,-0.01899994382023662
208.30000000000223,27.26856058194008,-0.37268283985652495,-0.019590358574071765
209.40000000000225,27.37301901496748,-0.370010522212464,-0.019660090192370916
210.50000000000227,27.476417794557484,-0.36585241175641886,-0.019968483254916958
211.6000000000023,27.582267080362147,-0.3621149680693333,-0.01964996893323878
212.7000000000023,27.685643384746182,-0.3569490673083533,-0.019317814482560536
213.8000000000023,27.789823077439465,-0.3548021616868243,-0.019319927501788126
214.90000000000234,27.89470744121418,-0.35109704421931165,-0.020598402052273368
216.00000000000233,27.998912961262455,-0.34803728736603107,-0.020711446952544232
217.10000000000235,28.10327439202573,-0.34426064667909906,-0.02064993094461487
218.20000000000238,28.207792881273306,-0.3417267792832071,-0.020648213722633812
219.3000000000024,28.312035358596294,-0.33766212146173047,-0.02064983856159408
220.40000000000242,28.41549620458333,-0.33548767365464643,-0.020649797950957005
221.50000000000242,28.52109521578243,-0.33236366084979146,-0.021959814207362705
222.60000000000244,28.625334007665266,-0.32871441733274626,-0.02196005460778494
223.70000000000246,28.730695007827773,-0.3247977638054536,-0.020640029496292733
224.80000000000246,28.834646733112738,-0.32204826766472877,-0.02064014799952174
225.90000000000248,28.938845136419726,-0.3183365155585092,-0.02064014647610035
227.0000000000025,29.04274458198458,-0.31495042489386815,-0.021288300999059206
228.10000000000252,29.147864827376146,-0.3100394556634633,-0.02130026588503542
229.20000000000255,29.25296667687733,-0.3060841845263239,-0.02261995121501137
230.30000000000254,29.35727969697182,-0.3025025948775773,-0.021960133992392716
231.40000000000256,29.461313237600866,-0.29867641142400675,-0.0227323657821481
232.5000000000026,29.56750464482175,-0.29325533053688113,-0.022585917799283983
233.60000000000258,29.67050375195597,-0.28858452258857975,-0.020968835678495612
234.7000000000026,29.775806000878667,-0.2827333536144866,-0.022619672585289408
235.80000000000263,29.880093305611346,-0.27693987469246956,-0.02393985982397906
236.90000000000265,29.985486763539118,-0.26961529086100366,-0.02263180676897747
238.00000000000267,30.09000000000027,-0.26278999999997127,-0.022545550105346646
239.10000000000267,30.195124092709367,-0.2537767304393367,-0.02393998891999294
240.2000000000027,30.300204625091936,-0.24306874513407348,-0.023939988999999606
241.3000000000027,30.403984715613248,-0.23256476235555593,-0.023939988999980066
242.4000000000027,30.509689787860946,-0.21779571464537137,-0.023939961847792013
243.50000000000273,30.61344275091996,-0.19897974619539843,-0.023939083232052294
244.60000000000275,30.718476896815346,-0.17863812008211077,-0.023939897018434575
245.70000000000277,30.82380870243502,-0.1454422183285869,-0.023947670082018035
246.8000000000028,30.928770933858686,-0.10449711641379857,-0.025259896944595628
247.9000000000028,31.034291901521758,-0.05333095286872555,-0.025259896999999754
249.0000000000028,31.138217486828744,-0.005891929287889005,-0.025259896999600517
250.10000000000284,31.243452399129175,0.022405631810233247,-0.025259629605027367
251.20000000000283,31.348997848115662,0.018886708815912333,-0.026570222381939956
252.30000000000285,31.450787456392412,-0.013159026923880011,-0.025911898481319806
253.40000000000288,31.55650261587846,-0.06106842990399595,-0.02499795639238167
254.5000000000029,31.66291265124063,-0.10992504461784923,-0.025909855705045448
255.60000000000292,31.766807369509227,-0.15056977038909516,-0.025254120271720915
256.7000000000029,31.87132562418934,-0.1807513690438255,-0.026239811930458323
257.8000000000029,31.975065327728867,-0.2044642024370616,-0.02659119346426131
258.90000000000293,32.08057594846465,-0.21952324334032078,-0.026569805051140705
260.00000000000296,32.18508265459199,-0.231068636045609,-0.02656980499048478
261.100000000003,32.290618940005515,-0.24017080644312905,-0.026504950211847067
262.200000000003,32.394273435900324,-0.24386558987467336,-0.027796384039662225
263.300000000003,32.499405583013186,-0.24684969822904762,-0.028596288082979093
264.40000000000305,32.60379777345615,-0.24848172704445884,-0.02920471666130897
265.50000000000307,32.70898712300277,-0.24702997763683665,-0.029540035205968707
266.6000000000031,32.81383092584519,-0.24745749589669463,-0.02936024651784619
267.7000000000031,32.91860980932289,-0.2472483687939272,-0.029539844748598387
268.8000000000031,33.023883060710254,-0.24528328950881267,-0.030268673566855586
269.9000000000031,33.12799333109025,-0.24422160899489936,-0.03216822511512252
271.0000000000031,33.23296965357944,-0.24124737214424005,-0.030861621121162308
272.10000000000315,33.338531834668416,-0.23917653354294574,-0.030863419376354617
273.2000000000032,33.44371801454057,-0.23687789908514886,-0.032169894140089195
274.30000000000314,33.54836315072074,-0.23444201264106426,-0.031147198118141706
275.40000000000316,33.652784268971665,-0.23265116351845386,-0.03248308327267457
276.5000000000032,33.75896102744359,-0.23026270352184888,-0.033486670059828416
277.6000000000032,33.86434038898513,-0.2290657990373205,-0.03348989699787985
278.70000000000323,33.96909485123793,-0.22759875080842157,-0.03349675741273028
279.80000000000325,34.074502377623666,-0.22498725655190804,-0.03480989820450109
280.9000000000033,34.179456582427704,-0.2248699546601367,-0.03480989699999926
282.0000000000033,34.28226715477315,-0.22196393804971465,-0.03480989700020176
283.1000000000033,34.389705900883875,-0.22096010876452188,-0.034809670717824925
284.20000000000334,34.49455448310811,-0.21746989634727654,-0.03612988494876568
285.30000000000337,34.600174265052594,-0.21470250537630045,-0.03613019130560646
286.40000000000333,34.70544855535029,-0.21212849463644587,-0.03645991727948816
287.50000000000335,34.811091295977086,-0.2111725614146929,-0.037213203240085146
288.6000000000034,34.91602503967471,-0.2087393003824414,-0.037780195154986984
289.7000000000034,35.021048278000066,-0.20681840311835298,-0.038765114345088225
290.8000000000034,35.12749752006171,-0.20438249825358154,-0.03739530633567556
291.9000000000034,35.231878851192455,-0.20090658742124243,-0.03973869953371523
293.0000000000034,35.337741908213474,-0.1990068738484699,-0.0397400329979658
294.10000000000343,35.4406122665914,-0.19669152597069484,-0.03974003299999973
295.20000000000346,35.54652501371025,-0.19194172455665798,-0.039740033051249846
296.3000000000035,35.65203389336395,-0.19013702443866612,-0.03968984256184882
297.4000000000035,35.75679515041889,-0.18507298101495456,-0.0410575167397611
298.5000000000035,35.86377336260609,-0.1807286029976671,-0.041389451225920304
299.60000000000355,35.97009039998717,-0.17858487046171403,-0.042380126987811906
300.70000000000357,36.074218217011286,-0.17507863394473927,-0.04362570067568772
301.8000000000036,36.18062609493363,-0.17188592425909757,-0.045015712644098205
302.9000000000036,36.285136102174064,-0.16797905207520789,-0.045019838977430116
304.0000000000036,36.39008589512797,-0.16384945581188776,-0.045019843861228814
305.1000000000036,36.49539626756785,-0.15860247799981828,-0.04661799826312807
306.2000000000036,36.601531363452246,-0.15440502930864164,-0.04666993097941985
307.30000000000365,36.704372960295366,-0.15008127905933885,-0.046625471922913775
308.4000000000037,36.81154317834537,-0.14566018074521628,-0.04798723677021588
309.5000000000037,36.91768144354715,-0.14089102048654498,-0.050436477536679014
310.60000000000366,37.02353495916599,-0.13570342005553546,-0.050620075480253934
311.7000000000037,37.128156808551694,-0.13124249631065876,-0.051284444857222056
312.8000000000037,37.2344447698768,-0.12526358562141512,-0.051273999329626285
313.90000000000373,37.33938449958893,-0.12295986049153011,-0.05392593353253394
315.00000000000375,37.44499981539738,-0.11924583410472445,-0.055219875229329585
316.1000000000038,37.55056887095761,-0.1184749692319004,-0.056540198154962695
317.2000000000038,37.656239173208746,-0.11810705190988774,-0.05755771547356403
318.3000000000038,37.762045286023984,-0.118085759312922,-0.05916805198828268
319.40000000000384,37.8681805853026,-0.11889846372383381,-0.06048934235942749
320.5000000000038,37.97381719814337,-0.1183904593027086,-0.06182443075654076
321.60000000000383,38.08009631016383,-0.11977193719840218,-0.06543038903500387
322.70000000000385,38.186570409269336,-0.12045303854615334,-0.06674795645687537
323.8000000000039,38.292663462391474,-0.12165795494102902,-0.06865669238879057
324.9000000000039,38.39809479104275,-0.12378681430412974,-0.0706932988941853
326.0000000000039,38.50415921835345,-0.12396002793292184,-0.0730013759077508
327.10000000000394,38.608247657281396,-0.12424580078488012,-0.07467120823188722
328.2000000000039,38.71328123389283,-0.12426888470584793,-0.07729162193373806
329.30000000000393,38.8192859159892,-0.12371676870058791,-0.08025833104904168
330.40000000000396,38.929122642662854,-0.1235401174064236,-0.08288465901641873
331.500000000004,39.03430040773363,-0.12254452258291018,-0.08600335134602943
332.600000000004,39.1394205830472,-0.12216564222941838,-0.08958596929523122
333.700000000004,39.243938166717896,-0.12210299919881197,-0.09440744851611882
334.80000000000405,39.35156316054179,-0.12182515458680719,-0.09771952781466853
335.90000000000407,39.4572011549403,-0.12196347161166145,-0.10177865361430571
337.0000000000041,39.56344317313858,-0.11904903245383221,-0.10602276125008236
338.10000000000406,39.6702138082137,-0.11983744734098005,-0.11023249410589875
339.2000000000041,39.77339890663199,-0.11966162443706341,-0.1135860850213839
340.3000000000041,39.88175561167953,-0.11782912413752894,-0.11906227581754969
341.4000000000041,39.988338268345444,-0.11785782421494165,-0.12298511869000706
342.50000000000415,40.0934315994082,-0.11653822537358241,-0.12943081088330244
343.6000000000042,40.19894047424237,-0.11557164132309339,-0.13241606978258602
344.7000000000042,40.30471990026801,-0.11513242414448903,-0.13727590879128693
345.80000000000416,40.41073236887551,-0.11508508698384168,-0.14369921009918185
346.9000000000042,40.51727743126092,-0.1117758361966457,-0.14775679403436914
348.0000000000042,40.62366110459957,-0.11070758522232955,-0.15291476177984897
349.10000000000423,40.73019817453458,-0.1092903585886092,-0.15963590301590935
350.20000000000425,40.8363160828776,-0.10555509994302616,-0.1639228135583517
351.3000000000043,40.942395444397,-0.10318187845697319,-0.17035210331548534
352.4000000000043,41.04833101364695,-0.10151737865096383,-0.17656897440138275
353.5000000000043,41.15478300904706,-0.09950261725731838,-0.181275714102485
354.60000000000434,41.26176030268935,-0.09872953823470235,-0.18691170187436645
355.7000000000043,41.36656632143663,-0.09771358360827712,-0.19332828866223206
356.80000000000433,41.47442338196029,-0.0946942382918369,-0.19790080276984812
357.90000000000435,41.58052693440161,-0.09190772738550615,-0.20447014461017865
359.0000000000044,41.68690063940408,-0.09126650120909244,-0.20946933642548204
360.1000000000044,41.79243860403312,-0.08943919661970982,-0.2165898995515465
361.2000000000044,41.9012074991999,-0.08845981302055261,-0.22297882568777316
362.30000000000445,42.00698253031912,-0.08693000854889536,-0.22836068803020382
363.4000000000044,42.11368225159117,-0.08527507088468907,-0.23416249348324802
364.50000000000443,42.219592757276715,-0.08465725007750624,-0.23918464484216173
365.60000000000446,42.32728617869485,-0.08355828216354154,-0.24627915063139527
366.7000000000045,42.43312624005228,-0.08185719174177226,-0.2512127735002436
367.8000000000045,42.540364347563255,-0.08038921300742033,-0.25755149259751287
368.9000000000045,42.646513993117914,-0.0797414467363193,-0.2637495957115088
370.00000000000455,42.75373325903224,-0.07870969624369299,-0.2704700769005415
371.10000000000457,42.85937253956901,-0.07835266967026738,-0.2755038844024198
372.2000000000046,42.96648996176735,-0.07762601805440719,-0.2823272238678949
373.30000000000456,43.07306775293958,-0.07829975100668708,-0.2862015088550929
374.4000000000046,43.1793859262329,-0.07617437126167188,-0.2953174318877392
375.5000000000046,43.286833418770144,-0.0760466172717833,-0.29990878440495816
376.6000000000046,43.39267655892083,-0.07557571781593432,-0.30678726244354193
377.70000000000465,43.50029656686692,-0.07433928252657723,-0.3132125665739163
378.8000000000047,43.60590577155149,-0.07400407443985446,-0.31930680942855405
379.9000000000047,43.71323186156086,-0.07565421825919386,-0.32550727957405945
381.00000000000466,43.8194626749216,-0.07446951953970579,-0.3334955042049481
382.1000000000047,43.92761110587719,-0.07404445860510588,-0.3399129423002183
383.2000000000047,44.03464354838922,-0.07419466058700169,-0.3468164207554114
384.30000000000473,44.14141440617122,-0.07340529761317693,-0.35217404590499646
385.40000000000475,44.247692583030734,-0.07148700224184489,-0.3587933500380731
386.5000000000048,44.354731630498335,-0.07244000291813929,-0.36710756339903305
387.6000000000048,44.46225106249238,-0.07165709801431969,-0.37370493866972865
388.7000000000048,44.5686319885584,-0.07107573793701337,-0.3824941822127972
389.80000000000484,44.6756218616693,-0.06881741671475028,-0.38982309693718786
390.9000000000048,44.78218222086777,-0.06937218969347268,-0.3982091924921365
392.00000000000483,44.88957755697257,-0.06758791288311018,-0.4059347957785602
393.10000000000485,44.99621175823886,-0.06597172934966704,-0.4135246703930675
394.2000000000049,45.10310569201245,-0.06529468255483989,-0.4232850296054047
395.3000000000049,45.2097973300576,-0.06364060076965533,-0.4312065367398654
396.4000000000049,45.317206209625574,-0.061426918488253074,-0.4409014963734039
397.50000000000495,45.42392545361919,-0.0601164665180109,-0.44818570820597703
398.6000000000049,45.53010474503414,-0.05988098522602948,-0.4590214474285932
399.70000000000493,45.637398318292014,-0.05864795960686341,-0.4686115853515429
400.80000000000496,45.74464662938309,-0.056865950353237195,-0.4807959190417379
401.900000000005,45.85221868763677,-0.05393427318204254,-0.4912536316906442
403.000000000005,45.9585061884413,-0.05093656336162421,-0.5027967438486711
404.100000000005,46.066182218326006,-0.04928094122397433,-0.5129317377554323
405.20000000000505,46.17372700264276,-0.04644800462157105,-0.524603599155097
406.30000000000507,46.27970606763534,-0.0429023004976243,-0.5373655007215783
407.4000000000051,46.386557404250105,-0.03954643707400174,-0.5511955534402113
408.50000000000506,46.493842052844364,-0.03346714988272996,-0.5631985609734622
409.6000000000051,46.60079776433497,-0.03038537572373326,-0.5769993019621444
410.7000000000051,46.708261289133134,-0.02534537888190316,-0.5906532164455802
411.8000000000051,46.81443677706396,-0.017914352827410985,-0.6052494008537921
412.90000000000515,46.92178573179133,-0.010932256399976702,-0.6202322142583432
414.0000000000052,47.030094610484255,-0.004525434186805732,-0.6372247979972441
415.1000000000052,47.13588498519589,0.003775044442831406,-0.6528212897792005
416.20000000000516,47.24292020765515,0.010755885571628416,-0.6702221584461028
417.3000000000052,47.349692312009516,0.017744909031757277,-0.6877415916571712
418.4000000000052,47.45588889918161,0.025531000291550403,-0.704975888627386
419.50000000000523,47.56194147222287,0.0344080191591025,-0.7255038335180783
420.60000000000525,47.67129376709114,0.040268139407691216,-0.7448206472473857
421.7000000000053,47.77832554156701,0.04584211971589516,-0.7639693132838192
422.8000000000053,47.88624979271647,0.0513433362126058,-0.7842434856429792
423.9000000000053,47.993759636469846,0.05896724182353683,-0.806232415717322
425.00000000000534,48.100635760552315,0.06364216499253798,-0.8308140047031616
426.1000000000053,48.20727837907991,0.06878418051103811,-0.8532572144132464
427.20000000000533,48.31577430928751,0.07529477261983071,-0.8756025536219378
428.30000000000535,48.42251099060121,0.08057432021742121,-0.9020602558213984
429.4000000000054,48.53123536523519,0.08586368835892409,-0.9282922045566773
430.5000000000054,48.63899837168089,0.09087724089220928,-0.9527258487957893
431.6000000000054,48.74661899645127,0.09622751244619825,-0.9808545306914147
432.70000000000545,48.854919980333875,0.09924119399471097,-1.0076087434993153
433.8000000000054,48.962123005289435,0.10151287538651514,-1.0345796694788612
434.90000000000543,49.06947121215835,0.10449875363165809,-1.0644000218811627
436.00000000000546,49.179124506698166,0.10683947585915103,-1.091740452680165
437.1000000000055,49.286621000316785,0.10663500659630025,-1.1206192945324496
438.2000000000055,49.39244271843762,0.10696898980587409,-1.1487140188834624
439.3000000000055,49.503389999151665,0.10700040787183421,-1.1764535900367514
440.40000000000555,49.608516286178364,0.10356556434247732,-1.2031164412276545
441.50000000000557,49.716550035850666,0.10049908975842746,-1.229550976151308
442.6000000000056,49.82454330176887,0.09541064861390541,-1.2551618051510793
443.70000000000556,49.933279477082664,0.08802196642188481,-1.2783562302688223
444.8000000000056,50.04065924958831,0.08077478064439687,-1.2994923801568112
445.9000000000056,50.14886602487277,0.07122727841240409,-1.319434122079032
447.0000000000056,50.25793228350145,0.06232817270033367,-1.3385468284362112
448.10000000000565,50.366534399867874,0.048231592174251936,-1.3544076773979272
449.2000000000057,50.47314464431391,0.034791701772914185,-1.3684086151148507
450.3000000000057,50.582059462610886,0.022031399386698968,-1.382370803566678
451.40000000000566,50.689898922693814,0.009741631779477917,-1.3962172097098393
452.5000000000057,50.79787441113697,0.0008425032884158375,-1.4069224460979974
453.6000000000057,50.90597059722024,-0.009499726773342777,-1.417881833152248
454.70000000000573,51.01323527359915,-0.015851450403735423,-1.4296935209492
455.80000000000575,51.119699912894006,-0.020352277709458542,-1.4388003433837082
456.9000000000058,51.228839068347256,-0.02634474702489423,-1.4498150784345034
458.0000000000058,51.33896737872759,-0.02559385816116461,-1.4606908387829742
459.1000000000058,51.445621877263484,-0.028034536077394437,-1.471788018649021
460.20000000000584,51.551869314266604,-0.02760635700544967,-1.4808123587102964
461.3000000000058,51.66234015722057,-0.024643206997719425,-1.4922553051507195
462.40000000000583,51.7687481025656,-0.023657302565578117,-1.50325774771038
463.50000000000585,51.87820156925187,-0.021962595921166717,-1.5129939012236289
464.6000000000059,51.98648739300384,-0.01664679200555023,-1.5264693438796284
465.7000000000059,52.0949113712866,-0.01207153302256166,-1.5383476724189138
466.8000000000059,52.201983477435476,-0.010226143259664599,-1.5513670222176126
467.90000000000595,52.30971416124122,-0.007927052978522713,-1.563736530131655
469.0000000000059,52.41897756636598,-0.0050985709040223875,-1.575635160097832
470.10000000000593,52.5257682413115,-0.0028566890417950287,-1.590255522061514
471.20000000000596,52.6340877307729,-0.002817398040192808,-1.6044933911951125
472.300000000006,52.74165143536419,-0.006759962206711327,-1.619286874572004
473.400000000006,52.84947787296007,-0.0092366799654426,-1.631566702955228
474.500000000006,52.95727861242772,-0.018345956098911254,-1.6448440057080127
475.60000000000605,53.06607399974922,-0.030012496824988324,-1.659148647747846
476.70000000000607,53.17450840219408,-0.03972207955082855,-1.6682956759011724
477.8000000000061,53.282862883938336,-0.05434308087460004,-1.678575527366994
478.90000000000606,53.390509584999606,-0.07243580410078916,-1.6848438491560542
480.0000000000061,53.49870035109295,-0.09240066785534767,-1.691285578369854
481.1000000000061,53.606115986887275,-0.11153595814154652,-1.697008821997903
482.2000000000061,53.71452186858244,-0.1283446173130353,-1.7002563958499097
483.30000000000615,53.82239238245872,-0.14243888610720368,-1.7049266595362624
484.4000000000062,53.93019547026471,-0.15421766817788865,-1.7065802088528574
485.5000000000062,54.03839892575832,-0.1613687769597707,-1.7091032058580087
486.60000000000616,54.145653361617704,-0.16718989160861736,-1.7105158728979108
487.7000000000062,54.254318758081794,-0.1679400539923359,-1.7118457354119285
488.8000000000062,54.36322364336411,-0.16762516557188406,-1.7131701796675824
489.90000000000623,54.47193770218747,-0.16861861579292262,-1.7135900217566977
491.00000000000625,54.580287689590286,-0.16657826027551195,-1.715477296539674
492.1000000000063,54.6886609008854,-0.1645855204629925,-1.7161399823081869
493.2000000000063,54.79747764644955,-0.1635565751688296,-1.7174617492066857
494.3000000000063,54.90473153919645,-0.15657062019245718,-1.718732916750652
495.40000000000634,55.012984440695995,-0.1505159472509663,-1.7200897937216046
496.5000000000063,55.12156847598712,-0.1455929025608678,-1.7214113701147822
497.60000000000633,55.230093697370705,-0.14336982573194518,-1.7227302114181788
498.70000000000636,55.33748814374904,-0.14119417966444836,-1.724040076193306
499.8000000000064,55.446224234729996,-0.13852198565653648,-1.725340475342045
500.9000000000064,55.55447892047223,-0.13495120511104264,-1.7253815113620137
502.0000000000064,55.66270005778904,-0.13340517672015526,-1.7281082955958853
503.10000000000645,55.77052700693388,-0.13124874886677837,-1.729128245079738
504.2000000000064,55.87885268177296,-0.13003411437522852,-1.729429842935403
505.30000000000643,55.98650738552992,-0.12727138293463147,-1.7307399695641017
506.40000000000646,56.096579472055005,-0.1251096728767468,-1.7309326797143454
507.5000000000065,56.203585982374214,-0.12139753768075515,-1.7321239390637344
508.6000000000065,56.31305033730186,-0.12016142085362083,-1.7333683257324282
509.7000000000065,56.42142148680962,-0.11832605710036848,-1.733358196654882
510.80000000000655,56.53000084201532,-0.11529995590429665,-1.7346899131537472
511.90000000000657,56.638254477049095,-0.11283517604747724,-1.7360076855312325
513.0000000000066,56.74724684236563,-0.11109200415296495,-1.7374665944533256
514.1000000000065,56.855936786078665,-0.1085838983979854,-1.7386368502192648
515.2000000000066,56.96410208904875,-0.10546422255570664,-1.7398912905402226
516.3000000000065,57.07239564745212,-0.10459160331256545,-1.7412807811490585
517.4000000000067,57.180699392185254,-0.10412337592349036,-1.74259020133697
518.5000000000066,57.28927547837836,-0.10180792468777441,-1.7439104764631987
519.6000000000067,57.399096647056744,-0.09880400776884941,-1.7439161660840687
520.7000000000066,57.507615563367345,-0.09743059531240757,-1.7452290790715344
521.8000000000067,57.61629513643,-0.09840034937527237,-1.746540812434966
522.9000000000067,57.7245786970508,-0.09607761669768591,-1.747859045098492
524.0000000000067,57.833430685538325,-0.09570904057623143,-1.749463626192468
525.1000000000067,57.94282402415955,-0.09451535499350898,-1.750493463850698
526.2000000000068,58.048286608163245,-0.09219939792651521,-1.7526805515846409
527.3000000000068,58.15715245601533,-0.09094811820165213,-1.7531316230512122
528.4000000000068,58.26855439873709,-0.09094970228300914,-1.7544500940363346
529.5000000000068,58.37722404168857,-0.09114400709419643,-1.7558000076477298
530.6000000000068,58.48651089955392,-0.08923868076611367,-1.7574670593967072
531.7000000000069,58.5958506943255,-0.0894896415975936,-1.7587305177245467
532.8000000000068,58.70478863076149,-0.0897337265449288,-1.759338229788312
533.9000000000069,58.81331058798112,-0.08774937166268863,-1.760930459812673
535.0000000000068,58.92223013868147,-0.0890109810779611,-1.7623520867576268
536.100000000007,59.03061130338075,-0.08942151242316206,-1.7643279942512287
537.2000000000069,59.139894261594016,-0.0872445807674378,-1.7656500576732914
538.300000000007,59.24979986356827,-0.08711509103761264,-1.765640318118975
539.4000000000069,59.35756327384236,-0.08379717596709298,-1.7669558390244289
540.5000000000069,59.46742910620726,-0.08353083426689202,-1.7682955635206783
541.600000000007,59.57725286277912,-0.08370863721678116,-1.7695920463533747
542.700000000007,59.68644690530846,-0.08154541462941217,-1.7715381918595674
543.800000000007,59.795583070837566,-0.07992102285464163,-1.773553777260899
544.900000000007,59.904165657176094,-0.08052697547612558,-1.7748720446659294
546.000000000007,60.014234070365475,-0.07856062330126551,-1.7774750715701657
547.1000000000071,60.12304368749523,-0.07798245626231384,-1.7788215817409592
548.2000000000071,60.23130720041926,-0.07555483553813672,-1.7788753608532266
549.300000000007,60.34050254839021,-0.07631925360546267,-1.7814612320466927
550.4000000000071,60.45010661375699,-0.07365191268664721,-1.7831187210588166
551.500000000007,60.559700461902125,-0.07257572392773841,-1.7853889474858002
552.6000000000072,60.66793498965491,-0.07156578823276574,-1.7868916652190734
553.7000000000071,60.77733506670238,-0.07063784084650022,-1.7902427477683398
554.8000000000072,60.88605683928916,-0.06877634024747309,-1.791766792959196
555.9000000000071,60.995159964345866,-0.06779043904120409,-1.7943074086788915
557.0000000000072,61.104342964038565,-0.06618423915571406,-1.7969517126247911
558.1000000000072,61.21200072177331,-0.06600256283850431,-1.799129048208644
559.2000000000072,61.32328980509412,-0.06658341993564221,-1.8019215578627992
560.3000000000072,61.43225674109444,-0.06694726758350293,-1.803802450854143
561.4000000000073,61.54078257560983,-0.06580840093332817,-1.805787570144818
562.5000000000073,61.65039976225962,-0.0673474173666384,-1.808019750858568
563.6000000000073,61.75937456026245,-0.06697744513131723,-1.8130159421313614
564.7000000000073,61.86867659121877,-0.06724154978679923,-1.8159862030007745
565.8000000000073,61.977280807282455,-0.06839543481034378,-1.8198598048006907
566.9000000000074,62.086716561998976,-0.06638472345467394,-1.8234538726335492
568.0000000000074,62.19504424336627,-0.06313577171493272,-1.8273789552617843
569.1000000000074,62.30374587361338,-0.06148904454072088,-1.8315996169933055
570.2000000000073,62.412346784645266,-0.0562432819519285,-1.8330425963002188
571.3000000000073,62.521881159555434,-0.05290885899176069,-1.837565774894363
572.4000000000074,62.63088560531208,-0.0481734512278883,-1.8437713085058163
573.5000000000074,62.73945191262962,-0.04259727811696312,-1.8473931254328484
574.6000000000074,62.847884471305484,-0.03744813812942726,-1.8515614041057171
575.7000000000074,62.95769325412238,-0.031735899066283234,-1.8559460164078616
576.8000000000075,63.06682804254577,-0.02743820242912547,-1.861859602013567
577.9000000000075,63.17606637812812,-0.022789569017303373,-1.8682300519129482
579.0000000000075,63.28537442506157,-0.019462245533668,-1.8755184306207058
580.1000000000075,63.39492826730581,-0.019656313097946906,-1.8818504243495195
581.2000000000075,63.5040141612334,-0.019214375023888446,-1.8890115407078576
582.3000000000076,63.61293140053367,-0.018702383320016225,-1.8958016353306033
583.4000000000076,63.72360019968576,-0.017675310247315786,-1.901839076495318
584.5000000000076,63.83216816073516,-0.01608735096383415,-1.909970362406368
585.6000000000076,63.94226740618468,-0.01577796643726457,-1.9178890817022571
586.7000000000077,64.05176877194604,-0.013572940584902863,-1.9267919916431664
587.8000000000077,64.16072651630338,-0.010527759769970418,-1.9335840229824246
588.9000000000076,64.27060908045348,-0.008453402810987649,-1.9418808664501634
590.0000000000076,64.37978768346369,-0.0110434497788311,-1.9489872836216793
591.1000000000076,64.48990076906202,-0.009620338742057423,-1.957760300208335
592.2000000000077,64.59977377852742,-0.009393226538676603,-1.9673042463684562
593.3000000000077,64.70788669081401,-0.009640826841114848,-1.9739906671342502
594.4000000000077,64.81727313656428,-0.007179415342443126,-1.9837278966019118
595.5000000000077,64.92663300750807,-0.00657936600308236,-1.9929796502144175
596.6000000000078,65.03717340097278,-0.00865291297231512,-2.0019434895083954
597.7000000000078,65.14732384120053,-0.007203296336773997,-2.011622585514611
598.8000000000078,65.25621235430228,-0.00561185972530166,-2.0216377453582552
599.9000000000078,65.36619988840089,-0.005955138897922668,-2.0318410809863368
601.0000000000078,65.47470261593477,-0.004875663694510388,-2.0380653938239908
602.1000000000079,65.58536765373313,-0.004914982365259728,-2.047839884727247
603.2000000000079,65.69380662032589,-0.007103828609113407,-2.0568527301118147
604.3000000000079,65.80384413442707,-0.010765279847050408,-2.0644581912050772
605.4000000000078,65.91315443732894,-0.012539051664259993,-2.073919483448221
606.5000000000078,66.02280161436218,-0.017254924786845212,-2.0805912297609477
607.6000000000079,66.13030328685109,-0.020343322599989257,-2.0851137652974416
608.7000000000079,66.24226241137671,-0.01925389857523566,-2.0913276786037858
609.8000000000079,66.35000117855606,-0.013756073896972896,-2.093900140115157
610.9000000000079,66.46096884827821,-0.009525693004386954,-2.09528115995258
612.000000000008,66.57143756528482,-0.008263718774088493,-2.0968584566726722
613.100000000008,66.68010082640753,-0.005420714043810656,-2.0968706261049475
614.200000000008,66.78999885167642,0.000740754570399179,-2.0995001555029034
615.300000000008,66.89959027660241,0.006410190855518971,-2.0997958245405153
616.400000000008,67.00801631513426,0.008637567633569987,-2.101787240567341
617.5000000000081,67.11981977968614,0.015105349573368627,-2.1022943257716817
618.6000000000081,67.23009970926765,0.020854986989935417,-2.1034501289951537
619.7000000000081,67.33942894997925,0.023591843627019347,-2.104770191845838
620.8000000000081,67.44941531392101,0.028098576105086086,-2.105734380636833
621.9000000000082,67.55978983836646,0.033129546185556136,-2.10706834826082
623.0000000000082,67.66940729487433,0.03634815217146416,-2.107400107126123
624.1000000000081,67.77902907555911,0.04142867983965369,-2.108982000495183
625.2000000000081,67.88924034156206,0.04828042717311458,-2.1109492964867607
626.3000000000081,67.99878098999605,0.052024058482308164,-2.112667459512291
627.4000000000082,68.10978217098899,0.055983277322112425,-2.1139901122800455
628.5000000000082,68.21796826187952,0.06354674001970273,-2.1152953290276577
629.6000000000082,68.32942102571106,0.06720075907991441,-2.118217843129398
630.7000000000082,68.43932382457572,0.07360909498245836,-2.118239940933961
631.8000000000083,68.54969142086328,0.0820436587768384,-2.1199038879236936
632.9000000000083,68.65902842764393,0.08508496567250223,-2.1214802579708545
634.0000000000083,68.76881032219453,0.09418517863964973,-2.122904032439652
635.1000000000083,68.87941612283194,0.10387687494817512,-2.1251254415201513
636.2000000000083,68.98874496266808,0.11242481953310408,-2.1268260744427647
637.3000000000084,69.09836697082889,0.12138920778636333,-2.129237398572567
638.4000000000084,69.20768467797876,0.13051765180496244,-2.12990321890048
639.5000000000084,69.31774578219196,0.1411002153976365,-2.1330962818400003
640.6000000000083,69.42710211641459,0.15009744122120436,-2.135779159818031
641.7000000000083,69.53736242364818,0.16136980926157116,-2.138495500226078
642.8000000000084,69.64769255136929,0.17500611818075384,-2.1397690817193578
643.9000000000084,69.7563080392308,0.18767122842242648,-2.14113029556912
645.0000000000084,69.8663235563023,0.2011848431147116,-2.1452580645935826
646.1000000000084,69.97639434154979,0.21580443051179224,-2.148932532964612
647.2000000000085,70.08636426881112,0.2332559636413014,-2.1506305854183143
648.3000000000085,70.19568722447057,0.24803522528149044,-2.154466454730381
649.4000000000085,70.30599109071996,0.26625801784551845,-2.157622434775932
650.5000000000085,70.41634326245101,0.28308106399337996,-2.160161585706669
651.6000000000085,70.5253869325845,0.29994205139087593,-2.163702675050887
652.7000000000086,70.63603966331162,0.31870660248243204,-2.1672321722156296
653.8000000000086,70.74583307642789,0.33583335356734906,-2.170074454603838
654.9000000000086,70.85585251393313,0.35540949740190697,-2.173975436959378
656.0000000000086,70.96396299180283,0.3767106069182245,-2.1806858470901695
657.1000000000087,71.07489955338117,0.3959510440725693,-2.1830146665160735
658.2000000000087,71.1846413246789,0.4210056655915307,-2.18602791366786
659.3000000000086,71.29491906842398,0.4375139855869676,-2.1901389290397946
660.4000000000086,71.4050364519048,0.45940538948029885,-2.1946677490382562
661.5000000000086,71.51482923047075,0.4799069238740379,-2.2010067581744686
662.6000000000087,71.62503859159482,0.5018998907176616,-2.204477017705088
663.7000000000087,71.73529643943183,0.5230925916495708,-2.210585698146191
664.8000000000087,71.84538028856129,0.5467123843393883,-2.2161101253631834
665.9000000000087,71.95468840660165,0.568702038901956,-2.2208133874672438
667.0000000000088,72.06621827744927,0.5921558454095409,-2.2269108653284944
668.1000000000088,72.1760262661772,0.6125921135686307,-2.231851271483193
669.2000000000088,72.28711315091368,0.6398191542680263,-2.238216642537049
670.3000000000088,72.39546144305554,0.6641704829128756,-2.2444911317460785
671.4000000000088,72.50726592697912,0.6853588922113061,-2.24952370773463
672.5000000000089,72.61670892507503,0.707887419012194,-2.256640086179064
673.6000000000089,72.72710443973492,0.7342721251923287,-2.263570798426376
674.7000000000089,72.8381736726119,0.758314820403965,-2.27052073955263
675.8000000000088,72.9477611615583,0.78248035642017,-2.276277372278823
676.9000000000088,73.05774524037048,0.8051972106032286,-2.2835309481922406
678.0000000000089,73.16625280141562,0.8288852403324087,-2.2910766829802816
679.1000000000089,73.27505281006131,0.8556078934727411,-2.2989157679707866
680.2000000000089,73.38565300405529,0.87869451759926,-2.305345742565846
681.3000000000089,73.49631553118397,0.9070749667480842,-2.314041066842903
682.400000000009,73.60585902067767,0.9306831744927985,-2.3223610854058627
683.500000000009,73.71650089393945,0.9566737799785326,-2.3307722404856737
684.600000000009,73.82620821789645,0.9812762091134857,-2.3401602684212017
685.700000000009,73.93656796289996,1.0078358912633174,-2.347992200232382
686.800000000009,74.04624869625972,1.027169172149586,-2.357225907386552
687.9000000000091,74.15728258563307,1.0539333850056636,-2.3662384785680386
689.0000000000091,74.26678996005714,1.0814593291967882,-2.374899472481499
690.1000000000091,74.37721738931785,1.1043977719709617,-2.3831253003733455
691.2000000000091,74.48754453225929,1.1301361995403436,-2.3929751960278223
692.3000000000092,74.5976087119337,1.1585270275803052,-2.40300635964627
693.4000000000092,74.70789303949852,1.188278964096517,-2.4111515058496464
694.5000000000091,74.81758545895796,1.2176512521436695,-2.4216557595942128
695.6000000000091,74.92914173289674,1.2480298901796145,-2.4317039535178058
696.7000000000091,75.03906333835378,1.2811867366312202,-2.4431377640176053
697.8000000000092,75.1493084966843,1.3170534032628227,-2.4520538086282215
698.9000000000092,75.26030101450459,1.3524923981009476,-2.4631322431979354
700.0000000000092,75.37067528504745,1.386578721519421,-2.4738245833340646
701.1000000000092,75.4807789346565,1.4270789685021164,-2.4860001452391467
702.2000000000093,75.58968736307612,1.466660246352869,-2.498308262339504
703.3000000000093,75.70192427483057,1.5042275821777105,-2.5100761905168856
704.4000000000093,75.8118961564418,1.5404278028497949,-2.521261509707782
705.5000000000093,75.92271892254395,1.57269958848968,-2.5343292834552584
706.6000000000093,76.03333202545022,1.604081219874845,-2.5468889532121155
707.7000000000094,76.14414745625055,1.633329119533959,-2.559508645312839
708.8000000000094,76.25401767689323,1.6599476756961686,-2.5708697387717194
709.9000000000094,76.36332603611912,1.687078669059852,-2.5840288211694595
711.0000000000093,76.47453016516582,1.705438558778513,-2.597116874662485
712.1000000000093,76.58520924660958,1.7159165569872883,-2.611152099073551
713.2000000000094,76.69569346947254,1.7185773578868286,-2.623585405663741
714.3000000000094,76.80576007106693,1.7130163500270768,-2.6375791843101783
715.4000000000094,76.91674573915863,1.6995681914469811,-2.6506510255757227
716.5000000000094,77.02660365908825,1.6789058204065066,-2.664238670757431
717.6000000000095,77.1369885654809,1.6503955000388384,-2.6746476275601068
718.7000000000095,77.24801397875775,1.6111932026010163,-2.68722718403712
719.8000000000095,77.35861498482807,1.5625604566825333,-2.69899003051557
720.9000000000095,77.46822105545509,1.5033300203584816,-2.7107448008604567
722.0000000000095,77.57826468598496,1.4246864940993313,-2.7209350910596743
723.1000000000096,77.68888628781752,1.3175809342606377,-2.7320734490957643
724.2000000000096,77.79857536888736,1.171116073694736,-2.742904605285302
725.3000000000096,77.90835273503426,0.9326781953911406,-2.7515051734208864
726.4000000000096,78.01847484214169,0.5202011851285558,-2.7574161288889436
727.5000000000097,78.12498338631406,0.15442832674304144,-2.761390743577249
728.6000000000097,78.23606037065629,-0.008254842433254706,-2.7627593944384654
729.7000000000096,78.34588013650627,-0.07673345487353196,-2.7631162385765857
730.8000000000096,78.45584961248778,-0.1092166534121777,-2.765769737022557
731.9000000000096,78.56529381303436,-0.1272045823975145,-2.765742119305857
733.0000000000097,78.6753064671191,-0.1360392669819749,-2.7660915380485678
734.1000000000097,78.78607884448566,-0.1427030396369203,-2.7670898938532225
735.2000000000097,78.8959393064131,-0.14644799714169549,-2.767840019758468
736.3000000000097,79.00592549071415,-0.1498676245444585,-2.7674200290271624
737.4000000000098,79.11714939566286,-0.15188220855850548,-2.767090008285119
738.5000000000098,79.22713699484528,-0.15624346195372463,-2.7682812404081245
739.6000000000098,79.3366441846357,-0.1570124323580566,-2.7669774311930926
740.7000000000098,79.44763865838027,-0.15929941778324389,-2.767086512908822
741.8000000000098,79.55746419369557,-0.15850669017234034,-2.769719166472906
742.9000000000099,79.66820713459947,-0.16087846467153544,-2.7691790782192274
744.0000000000099,79.77764421783631,-0.15736612847846004,-2.7697201519953847
745.1000000000099,79.8887652699684,-0.15862003554153614,-2.7697179600699116
746.0000000000099,79.97819478018754,-0.1587966259701399,-2.771039936420931