File: 01_Data/Plastic_Laminate_Countertop_Particle_Board/STA/N2/10K_min/Plastic_Laminate_Countertop_Particle_Board_STA_N2_10KData_221004_R1.csv
##Temp./Â°C,Time/min,DSC/(mW/mg),Mass loss/mg
51.0,10.776525012274757,-1.5837986294964597,0.0012827638039603073
52.100000000000016,11.137959806543327,-1.4548928995834363,-0.0009626503731867686
53.20000000000003,11.383509849831164,-1.3699558179369473,-0.0021855956266918497
54.30000000000005,11.594240432782179,-1.302033022967837,-0.004283250532221672
55.40000000000006,11.777483422505636,-1.2517278387717568,-0.0018951339577997217
56.50000000000008,11.954181016452427,-1.2093220400228988,-0.0023262724313175553
57.600000000000094,12.114372231992983,-1.1723291955193313,-0.00429165650302199
58.70000000000011,12.268221661552777,-1.1419216892848403,-0.001958193148907661
59.800000000000125,12.416101297547865,-1.1165856042614315,-0.0005253000078306869
60.90000000000014,12.564726267717775,-1.0919476792011518,-0.0035751617077117714
62.000000000000156,12.708416196638785,-1.070989355433766,-0.004458414838852676
63.10000000000017,12.846272227021354,-1.0511563854108066,-0.0032679171660410233
64.20000000000019,12.981761560814542,-1.0330784409197662,-0.005252069980575591
65.30000000000021,13.117527800735544,-1.0159057485609129,-0.004602576242347389
66.40000000000022,13.251266555602434,-0.9984304149135163,-0.002067292349495986
67.50000000000023,13.382121843788347,-0.9835720373581456,-0.0032478565634033174
68.60000000000025,13.512619709689899,-0.9671998967582799,-0.003986253372689319
69.70000000000027,13.641851851737913,-0.9519172192247252,-0.004617787207246593
70.80000000000028,13.767001040333632,-0.9378045652275169,-0.007578869160531632
71.90000000000029,13.893838844367444,-0.9231119996238273,-0.0073887690824747665
73.00000000000031,14.015528726531338,-0.9092348199689033,-0.005983253110184883
74.10000000000034,14.14114637581948,-0.8956401755945215,-0.006329045070210704
75.20000000000034,14.265233940464327,-0.881730097325094,-0.006370179373723417
76.30000000000035,14.38528268752785,-0.8683098495209016,-0.007692441271185402
77.40000000000038,14.50811019826853,-0.8557642599909134,-0.006372243095746022
78.5000000000004,14.626284076106973,-0.8418392923519107,-0.0063472258987591346
79.6000000000004,14.745459146813964,-0.8290910463217419,-0.007681576762756492
80.70000000000041,14.865139168450185,-0.8176871633805645,-0.009007638147442876
81.80000000000044,14.981765275241939,-0.808018969646178,-0.009010114454083507
82.90000000000046,15.099580059709911,-0.7965919093343385,-0.009279206252736039
84.00000000000047,15.216005329489482,-0.7881721257113795,-0.010356267900642813
85.10000000000048,15.331863770979362,-0.7776677689034236,-0.010508151119840825
86.2000000000005,15.446230852621598,-0.7690295932066785,-0.010318300024112936
87.30000000000052,15.561771811620527,-0.7605941084657611,-0.010265659415096273
88.40000000000053,15.675085118691335,-0.7535069330417107,-0.011552313378745183
89.50000000000054,15.787702706564168,-0.7440773788021307,-0.010534437070394809
90.60000000000056,15.899796606907094,-0.735855947192041,-0.011546982570690645
91.70000000000059,16.013257309391847,-0.7298749098991002,-0.014168992119015122
92.8000000000006,16.125750066432694,-0.7233736677692398,-0.014138572380636205
93.9000000000006,16.235551765359048,-0.7168380270879912,-0.014166521602323456
95.00000000000063,16.347927113595073,-0.7106456642996943,-0.012768132803502752
96.10000000000065,16.459170000000064,-0.7064499999999941,-0.012852691170600394
97.20000000000066,16.56791806096559,-0.6999885380421249,-0.013774048969143138
98.30000000000067,16.678677425126576,-0.6942147128980173,-0.015517153034892317
99.40000000000069,16.786711785119337,-0.6882497984138091,-0.013499492886731801
100.50000000000071,16.898919704369817,-0.6828606681116426,-0.016289739360662026
101.60000000000072,17.00863219677393,-0.677946089598001,-0.014936260853719574
102.70000000000073,17.11628379680892,-0.6716133099494443,-0.01626348837002567
103.80000000000075,17.2257820101082,-0.667959650295833,-0.018215012672297526
104.90000000000077,17.33378897255497,-0.6612193094370514,-0.016962149709023322
106.00000000000078,17.443063690541045,-0.6561436959948571,-0.01856453009754766
107.10000000000079,17.55081424912575,-0.6522243359945505,-0.01856017246079844
108.20000000000081,17.65974560065667,-0.646459833178137,-0.016579038291489212
109.30000000000084,17.768008818115728,-0.6402575605902241,-0.016570234671253736
110.40000000000084,17.875537095909007,-0.6358374553925161,-0.01657914939374283
111.50000000000085,17.982934810731127,-0.6305455715265981,-0.015745691235028225
112.60000000000088,18.0908933665872,-0.6258364670874719,-0.01789793653139249
113.7000000000009,18.19917000000009,-0.6208900000000043,-0.01808369881971217
114.8000000000009,18.306127333266407,-0.6144594599953094,-0.01921827624766692
115.90000000000092,18.413969935919763,-0.6099289137257644,-0.016829540484900818
117.00000000000094,18.521204980805916,-0.6050304395053987,-0.01664132918506045
118.10000000000096,18.6283388720004,-0.6012665689356632,-0.01691258090453296
119.20000000000097,18.736210526548525,-0.5961568664349716,-0.016927137951294746
120.30000000000098,18.843021282559118,-0.5905741860025077,-0.017800458813356457
121.400000000001,18.952650334596907,-0.5845187661283232,-0.01693166295316928
122.50000000000102,19.057516080456605,-0.5806056777099087,-0.019009571536068748
123.60000000000103,19.164799917916174,-0.5746172318686886,-0.01927304743539171
124.70000000000104,19.272214061272837,-0.5684223373452542,-0.019219974530764183
125.80000000000106,19.37787182818629,-0.5612029737951792,-0.017900458889180015
126.90000000000109,19.484858393850246,-0.5576599401955142,-0.017923610481013874
128.00000000000108,19.59316486390268,-0.5520554818928748,-0.01787224651163477
129.1000000000011,19.700391293137333,-0.546679166976382,-0.017900150709920126
130.20000000000113,19.80599497716399,-0.5423359032935728,-0.016567424319856805
131.30000000000115,19.91196010628735,-0.5369053351219624,-0.01922040344956244
132.40000000000117,20.01670071681835,-0.5313163674681362,-0.018228844723568116
133.50000000000117,20.122444534575084,-0.5261864799657855,-0.01822981600055673
134.6000000000012,20.228382418978093,-0.519176171082869,-0.01822980825533449
135.7000000000012,20.33415825302558,-0.5142852375353286,-0.016911124591261206
136.8000000000012,20.442994713978415,-0.507326089967889,-0.017879994408732003
137.90000000000123,20.547654647487207,-0.501777534236144,-0.017899929697284378
139.00000000000125,20.65326143428338,-0.49738048070870555,-0.01652377608940636
140.10000000000127,20.758928668253937,-0.49156400754236906,-0.017900024779567758
141.2000000000013,20.864291256653612,-0.4872179937286583,-0.01789988699203171
142.3000000000013,20.970116923344506,-0.48237176267807563,-0.01789990928139229
143.4000000000013,21.075279550923902,-0.47609268599624627,-0.01922034783078974
144.50000000000134,21.17958445615718,-0.4698521422655051,-0.019206071528675928
145.60000000000133,21.28521381189129,-0.46463968234716985,-0.019219887930226776
146.70000000000135,21.38994158015799,-0.4594636159474236,-0.019220417597703765
147.80000000000138,21.496433354347033,-0.4531868692240141,-0.018801327789408795
148.9000000000014,21.600773722544098,-0.44898973638367795,-0.020012424248025518
150.00000000000142,21.705724317082307,-0.4434549076413049,-0.020540087913126115
151.10000000000142,21.81091310213783,-0.437121089465055,-0.019550791049749883
152.20000000000144,21.915407306983735,-0.43093181286697146,-0.019329502180726266
153.30000000000146,22.020351111849482,-0.4254893012160267,-0.01921884355136605
154.40000000000146,22.122565706686622,-0.4189608570450731,-0.02161195920746195
155.50000000000148,22.229804902306263,-0.413741675704234,-0.022954248018150825
156.6000000000015,22.332680350013458,-0.40874400684467455,-0.021625390901113928
157.70000000000152,22.43727035403706,-0.4011328665275699,-0.02029206574459197
158.80000000000155,22.54126733573179,-0.3969531877199095,-0.02165231258549305
159.90000000000154,22.6472175840414,-0.38863000282195376,-0.020319921324386314
161.00000000000156,22.752866481471813,-0.38283554408781156,-0.020319398617397955
162.1000000000016,22.85651824291375,-0.3775939788852318,-0.02015131830080019
163.20000000000158,22.960535665533968,-0.3707706583141839,-0.020310384085082678
164.3000000000016,23.06599223202667,-0.3646266439922873,-0.022948903844741242
165.40000000000163,23.17027368411148,-0.358527935369867,-0.022946866373078745
166.50000000000165,23.274013169649145,-0.3526426252860205,-0.021630069195071933
167.60000000000167,23.379721996510153,-0.3459516178177751,-0.021628418902547963
168.70000000000167,23.48269261137768,-0.3391708267840338,-0.021949314729034164
169.8000000000017,23.587027030989645,-0.3331355872295497,-0.022949767026684942
170.9000000000017,23.69169491591813,-0.3266595955394872,-0.023748365546157224
172.0000000000017,23.795335182585795,-0.32094048295347166,-0.024589959378495507
173.10000000000173,23.899960267492666,-0.3133658272457624,-0.02458814226127437
174.20000000000175,24.004409634065993,-0.3060445104875903,-0.02590994872653729
175.30000000000177,24.108729864453277,-0.3018000536664061,-0.02590995999632595
176.4000000000018,24.21384859980523,-0.29475035276303035,-0.025936755080598672
177.5000000000018,24.318424552693465,-0.2865213521730126,-0.027230128529188935
178.6000000000018,24.42203907018858,-0.28034979681937755,-0.028549842152284732
179.70000000000184,24.52598483950698,-0.2724778195733534,-0.02724363290089915
180.80000000000183,24.62956511865236,-0.2672001481844338,-0.028532951211202473
181.90000000000185,24.73546364976868,-0.26127403613681355,-0.029860127501978972
183.00000000000188,24.83906449973278,-0.2531127803749017,-0.029860227465745126
184.1000000000019,24.945635966972517,-0.24571958203968472,-0.031187777950196782
185.20000000000192,25.048786312594853,-0.23952069408936108,-0.030732708236782535
186.30000000000192,25.153722157706618,-0.23269104800079832,-0.031760438022372384
187.40000000000194,25.259072503963843,-0.22338494247756008,-0.03283662344677207
188.50000000000196,25.36240621770105,-0.2159998832814614,-0.03514031599488909
189.60000000000196,25.46688603546643,-0.2087151021754487,-0.035140627741980346
190.70000000000198,25.570748942975374,-0.20267615486351953,-0.03678833244117685
191.800000000002,25.676648493540533,-0.19393975759891577,-0.03777018274965993
192.90000000000202,25.781341881051755,-0.18794617020659657,-0.03907746977804649
194.00000000000205,25.883817889819547,-0.181251947272834,-0.040399934349387934
195.10000000000204,25.98837268913428,-0.1738157728142382,-0.04246421964865377
196.20000000000206,26.092408260515416,-0.16812488211524756,-0.043039010159804825
197.3000000000021,26.19811617569914,-0.16193787666047976,-0.04532666486832637
198.40000000000208,26.301319551923388,-0.15533817611429157,-0.045349832661131906
199.5000000000021,26.406696216302922,-0.15077091836866316,-0.045680907058177844
200.60000000000213,26.510276356993124,-0.14635032227980466,-0.04574729495659913
201.70000000000215,26.61470076432696,-0.1397652557450319,-0.04699894304039187
202.80000000000217,26.717802616092243,-0.1349553778690423,-0.05018321488563959
203.90000000000217,26.82284865964376,-0.1298512979827367,-0.051276440125047174
205.0000000000022,26.927482767253885,-0.1246253078082626,-0.053793348280545494
206.1000000000022,27.031520452310556,-0.12006409425393821,-0.054968861011921444
207.2000000000022,27.136404769201626,-0.11534075870660433,-0.05625409279468885
208.30000000000223,27.241036675971156,-0.1108889506189514,-0.057530024226337684
209.40000000000225,27.344562664251104,-0.1080746240050731,-0.057507908722400636
210.50000000000227,27.448353279105994,-0.10277661572312559,-0.06007297130823552
211.6000000000023,27.552609308606993,-0.10034274983869963,-0.06147723684521322
212.7000000000023,27.658320571765916,-0.0964751273641434,-0.06280091829009216
213.8000000000023,27.761050480362666,-0.0921892312996616,-0.06507969861611551
214.90000000000234,27.864322595906966,-0.08757714355268682,-0.06594046599203063
216.00000000000233,27.96906587285653,-0.08246633566023306,-0.06806995080978995
217.10000000000235,28.07337414083524,-0.07739111037934206,-0.06827906854754717
218.20000000000238,28.177489863560986,-0.07345766537561069,-0.07202338591783919
219.3000000000024,28.282333026069615,-0.06793012188034085,-0.07465026801225116
220.40000000000242,28.386403108965077,-0.06391998081932558,-0.07834158482936004
221.50000000000242,28.490027709593296,-0.058412895558021094,-0.0799324733036686
222.60000000000244,28.593995147825357,-0.05488307202731915,-0.07860719466768762
223.70000000000246,28.698078952667434,-0.04946056862236408,-0.08125500035321753
224.80000000000246,28.802010892041338,-0.04565192573946157,-0.08268960767231226
225.90000000000248,28.90694760738391,-0.044254120101504466,-0.08532843249357658
227.0000000000025,29.00990482283231,-0.03914792945160182,-0.08925292886669567
228.10000000000252,29.11569452543931,-0.03560122740766817,-0.09254091309885437
229.20000000000255,29.220347893082668,-0.030317808008221644,-0.09628864522690694
230.30000000000254,29.325327967172367,-0.028284460350228552,-0.09988012935154789
231.40000000000256,29.42898525035695,-0.026065945493160703,-0.10166449158329272
232.5000000000026,29.534452562429152,-0.02430997290723947,-0.10386251524815604
233.60000000000258,29.63749621272983,-0.0221283285579506,-0.10398681880128002
234.7000000000026,29.742533789673697,-0.02012523617720479,-0.10641439554361698
235.80000000000263,29.846313636050446,-0.017063953279684036,-0.11107840172024241
236.90000000000265,29.95027185828396,-0.014871513511858264,-0.11487748053095004
238.00000000000267,30.05544475176624,-0.012395241416810865,-0.12039303338609209
239.10000000000267,30.1597061361278,-0.010706042462392077,-0.1216332200066974
240.2000000000027,30.26419467645933,-0.008556715944824139,-0.12484315319899775
241.3000000000027,30.369262722627262,-0.0068700611863544755,-0.12966479730861957
242.4000000000027,30.472937715510103,-0.004609338797716725,-0.1333388364074244
243.50000000000273,30.576305241805795,-0.002122197720322012,-0.13689457724148513
244.60000000000275,30.68113169109083,0.00045158076988910845,-0.14087068783105794
245.70000000000277,30.7840108976979,0.0037368506673506417,-0.14497470213245967
246.8000000000028,30.88964854493316,0.005541268109048718,-0.15056671073573513
247.9000000000028,30.994150440864296,0.007348435899848826,-0.155624074125305
249.0000000000028,31.099504563744883,0.011128810701327305,-0.15952971247794068
250.10000000000284,31.203328314982667,0.013702629492834639,-0.16445618064156475
251.20000000000283,31.307545999266814,0.015448773666692929,-0.16964750217075153
252.30000000000285,31.412755534718816,0.01792682494714221,-0.1748798805215932
253.40000000000288,31.51649981997337,0.020119132500309445,-0.18001919423115265
254.5000000000029,31.62126136839374,0.02089632564066604,-0.185969524643955
255.60000000000292,31.725141727626625,0.023237292933321527,-0.19065509598928942
256.7000000000029,31.82946049681349,0.02472048771334707,-0.19619493888024264
257.8000000000029,31.934968059928632,0.02623242113132361,-0.20302556263646387
258.90000000000293,32.03985599686853,0.028179776483768574,-0.20960261039710337
260.00000000000296,32.14420034188332,0.028700345945895805,-0.21621056498423696
261.100000000003,32.248630312392315,0.03143022003719341,-0.22275722122258612
262.200000000003,32.354189774946185,0.032454737208522294,-0.22799229365082052
263.300000000003,32.458785827061895,0.032637778145040874,-0.23346882713024764
264.40000000000305,32.563134749808825,0.0345294920009539,-0.24044591987993202
265.50000000000307,32.66665010408169,0.03491576588506588,-0.24643508931168867
266.6000000000031,32.7727126990383,0.03566140766873176,-0.2563737649832598
267.7000000000031,32.87727501890766,0.03672985291427148,-0.26546548156616634
268.8000000000031,32.981341615766425,0.03592040132995779,-0.27446540362268035
269.9000000000031,33.086170298175844,0.035376420079983546,-0.28363003398082975
271.0000000000031,33.19164474746254,0.03399937288235073,-0.29399981604226655
272.10000000000315,33.295959458110396,0.0346100974553639,-0.30308022707892857
273.2000000000032,33.40029077808336,0.03217303228761471,-0.31203973096079984
274.30000000000314,33.50392336075885,0.03205706736295277,-0.3250366746467175
275.40000000000316,33.609429800294734,0.030259315446222946,-0.33312561432640075
276.5000000000032,33.71419773859033,0.026462245191078274,-0.3432698321352752
277.6000000000032,33.81871737315039,0.02509932106714122,-0.3546628573259172
278.70000000000323,33.92414208628622,0.02257250866168313,-0.3672456941830462
279.80000000000325,34.02814336712015,0.02014979290552116,-0.3789677042828137
280.9000000000033,34.133788357842,0.016334141985077506,-0.3921950260965077
282.0000000000033,34.239663358708675,0.013296337693511222,-0.40318549793545433
283.1000000000033,34.343813785013,0.009412916526733364,-0.4141179559924293
284.20000000000334,34.449665910850996,0.0036951017551458735,-0.4288309691979917
285.30000000000337,34.55397280864075,0.0005702951752246262,-0.4407175096138314
286.40000000000333,34.65866631303706,-0.004048740636480587,-0.45410256974096574
287.50000000000335,34.76381452543776,-0.0091811730331376,-0.4690822439330713
288.6000000000034,34.86845016957341,-0.011445154399120975,-0.48338046544243385
289.7000000000034,34.97414799232784,-0.014359328261472367,-0.4980938454910402
290.8000000000034,35.079466796606916,-0.01743145382641211,-0.5143865072590703
291.9000000000034,35.18408665354144,-0.020231165487913604,-0.5291076831535655
293.0000000000034,35.288870908643446,-0.023280132612254298,-0.5441777982919533
294.10000000000343,35.39465987834223,-0.028003082027766326,-0.5589117713659055
295.20000000000346,35.49859095824208,-0.02931758372089301,-0.576829691661251
296.3000000000035,35.60392147039161,-0.03204485381778585,-0.5919969360375572
297.4000000000035,35.71025999484763,-0.03385141036666143,-0.6108529163380716
298.5000000000035,35.81503829404321,-0.034631645852816466,-0.6268102868523822
299.60000000000355,35.91994124108012,-0.036935655395880805,-0.6431148967556002
300.70000000000357,36.02295746133127,-0.03644524187260264,-0.6601901764097291
301.8000000000036,36.13106731138938,-0.03740882433384539,-0.677430990243947
302.9000000000036,36.23648970562467,-0.040063539538784755,-0.6980342668207196
304.0000000000036,36.34059537177048,-0.03985129953398188,-0.7175669016368964
305.1000000000036,36.44691923004955,-0.03868178031789648,-0.7365712571559384
306.2000000000036,36.55196877313612,-0.03995601795991556,-0.7556653852342619
307.30000000000365,36.65855132449384,-0.03941746033723087,-0.7756102569409995
308.4000000000037,36.763426544266856,-0.03748260082877638,-0.7940071830639646
309.5000000000037,36.86877180814673,-0.03667543534585183,-0.8157035268337056
310.60000000000366,36.97533206838396,-0.03596223021690599,-0.8371582927797512
311.7000000000037,37.08095879131876,-0.03373328801348348,-0.8547915431161588
312.8000000000037,37.18604021745607,-0.03180017239593486,-0.8766877117951588
313.90000000000373,37.29094210179233,-0.02723731062651251,-0.8984677956734282
315.00000000000375,37.39637627571654,-0.025291088541628117,-0.9206645274794036
316.1000000000038,37.502513658607505,-0.020639198607279564,-0.9439072144495735
317.2000000000038,37.60897599955701,-0.018231333343714535,-0.9674809268556612
318.3000000000038,37.71390030831714,-0.013357740186565027,-0.9911452443887372
319.40000000000384,37.82062624511773,-0.009274671275851428,-1.0150053786727478
320.5000000000038,37.925928530792575,-0.004819542400168096,-1.0384863803701219
321.60000000000383,38.03208183258635,-0.0007863542449349261,-1.0610401881174818
322.70000000000385,38.13766661579971,0.004139085006393501,-1.0868653275063656
323.8000000000039,38.244745254701,0.010745430818820609,-1.1104411468188982
324.9000000000039,38.3515381134827,0.016961638929029514,-1.1377393040347683
326.0000000000039,38.456507834240924,0.02107630464147354,-1.1632054739091293
327.10000000000394,38.56289489837404,0.027799932912279283,-1.1888435974612297
328.2000000000039,38.669269121692416,0.034430325107717305,-1.2154380166450776
329.30000000000393,38.774994954335874,0.04008069819519417,-1.2430228432344288
330.40000000000396,38.88115059139009,0.04686366469132029,-1.2695892438114145
331.500000000004,38.98698142024628,0.05383521650788181,-1.297669977961088
332.600000000004,39.09301300978406,0.06073780431147896,-1.3278982414984655
333.700000000004,39.19964430030349,0.06707109328565455,-1.355326362285754
334.80000000000405,39.30533876599442,0.07296780985803036,-1.383901553057047
335.90000000000407,39.41101256312425,0.07994395695160257,-1.4141791326227344
337.0000000000041,39.51760897216701,0.08715154644648025,-1.4428431499947032
338.10000000000406,39.62441582343193,0.09345993313257829,-1.4749280496764912
339.2000000000041,39.73183836206346,0.10034115691991927,-1.5071420667006747
340.3000000000041,39.83698792919401,0.10895711013180188,-1.5368127787286125
341.4000000000041,39.944135982821905,0.11621689902650571,-1.56965335771506
342.50000000000415,40.04980246906671,0.12282757978623636,-1.6033589890238433
343.6000000000042,40.15629583016889,0.12977426583844437,-1.6382291233207273
344.7000000000042,40.26216309214671,0.1394325674511745,-1.671253031159221
345.80000000000416,40.369070572661634,0.1465326536845412,-1.7066768334046798
346.9000000000042,40.474810452843585,0.1530809844624382,-1.7420182637331054
348.0000000000042,40.582450561574134,0.16016337905774417,-1.7771595528477104
349.10000000000423,40.688352938278115,0.16635329177855807,-1.814204840463633
350.20000000000425,40.795808348600936,0.17213663601177956,-1.8531409328566841
351.3000000000043,40.8999280088811,0.17999719297794142,-1.8891480199737205
352.4000000000043,41.00775296618805,0.1845319392204986,-1.9294323520484413
353.5000000000043,41.11490034727215,0.1899990432412823,-1.9667510408125453
354.60000000000434,41.2213996380409,0.19511386651112533,-2.005691102875533
355.7000000000043,41.328175555872505,0.19599060829932496,-2.046091346616428
356.80000000000433,41.43460678878695,0.19784702481762684,-2.0849293416030443
357.90000000000435,41.54021767199684,0.1982748916492997,-2.124191849342739
359.0000000000044,41.64733605786689,0.19587121355264778,-2.165721309159095
360.1000000000044,41.75440330945356,0.1913835536058533,-2.20376652507881
361.2000000000044,41.86145419697692,0.18433771350760791,-2.244192174702283
362.30000000000445,41.9672277011019,0.17668402212805234,-2.283239401445749
363.4000000000044,42.07303625078289,0.16671095279152426,-2.319276069266309
364.50000000000443,42.179939198451756,0.15343702000054565,-2.356491517918946
365.60000000000446,42.28517616329226,0.136250959508627,-2.3927593947554504
366.7000000000045,42.393835684068435,0.11827663936023873,-2.4260896147352864
367.8000000000045,42.50045602922933,0.09512393889469989,-2.459541221749143
368.9000000000045,42.60545114468447,0.06956195995659138,-2.4903455482483148
370.00000000000455,42.71377270030416,0.04455892162579396,-2.5215182199547455
371.10000000000457,42.82045503269149,0.017885575595710072,-2.546675954278598
372.2000000000046,42.92490279593085,-0.008545142787289519,-2.5713839760165187
373.30000000000456,43.03389623962043,-0.039329445371290725,-2.593348166240649
374.4000000000046,43.13945301250033,-0.06678822497046294,-2.6099213336893006
375.5000000000046,43.248171674946796,-0.0941389234232412,-2.625159937632035
376.6000000000046,43.35542895309935,-0.11762979394752114,-2.638435372217816
377.70000000000465,43.46177522061776,-0.13813999779897834,-2.6497554610099265
378.8000000000047,43.56925958500874,-0.15605160997782036,-2.660052448287043
379.9000000000047,43.67568298866467,-0.16929711381501567,-2.6675304253388434
381.00000000000466,43.78330707671975,-0.18087695151496863,-2.675744137519729
382.1000000000047,43.89004627651703,-0.1894183375951676,-2.6811649481673694
383.2000000000047,43.997107946645414,-0.19632021552966453,-2.68917191749435
384.30000000000473,44.10475846597012,-0.2015566937883431,-2.6917709627341835
385.40000000000475,44.21248601378378,-0.20497079719327474,-2.6951204321182587
386.5000000000048,44.31896232240451,-0.20810436957221418,-2.70055212013177
387.6000000000048,44.426249758067236,-0.21025721262856278,-2.703915001489158
388.7000000000048,44.53223229145298,-0.21222204718402443,-2.7093098885656746
389.80000000000484,44.64086702875378,-0.21333005856927695,-2.7133212297934097
390.9000000000048,44.74754057420759,-0.21516951218474314,-2.716619646881764
392.00000000000483,44.85659075964978,-0.21494179008772757,-2.7207440673775896
393.10000000000485,44.961270304312926,-0.21534413032032537,-2.7235771074237425
394.2000000000049,45.06979723153413,-0.21654696089332945,-2.725810690490036
395.3000000000049,45.17663651166605,-0.2158343021948438,-2.730550307711818
396.4000000000049,45.28330758977618,-0.21619200225668514,-2.7351000512623056
397.50000000000495,45.391233184830966,-0.21637994336698455,-2.7388557825617865
398.6000000000049,45.49784317029872,-0.2168870170846058,-2.743234013496473
399.70000000000493,45.604712695179124,-0.21718181483509408,-2.7470480124661507
400.80000000000496,45.7119868503516,-0.2180923810425415,-2.7504416349827014
401.900000000005,45.81724291134241,-0.21766865821675221,-2.7523904092599434
403.000000000005,45.92675178253068,-0.2181451340577972,-2.755885206786619
404.100000000005,46.0338774894829,-0.21918092606567005,-2.7585550907628997
405.20000000000505,46.140147796124246,-0.21904664476838018,-2.761431250919749
406.30000000000507,46.24623478540552,-0.2182016723973335,-2.7656237968111284
407.4000000000051,46.35410461297625,-0.21864086746262099,-2.7684156563642546
408.50000000000506,46.462705141755926,-0.21893429143454027,-2.7712392481064114
409.6000000000051,46.56947842343201,-0.22059459282274688,-2.7751116465124417
410.7000000000051,46.67720624344652,-0.21894481742635863,-2.7793086194614034
411.8000000000051,46.78457591868325,-0.21933763260076167,-2.7820799961994718
412.90000000000515,46.89288664563533,-0.2196258020878218,-2.7856795245108903
414.0000000000052,47.0000337046037,-0.2178753564683389,-2.790098869038051
415.1000000000052,47.10674114934473,-0.21739094272649673,-2.7934367581433173
416.20000000000516,47.21436423017986,-0.21454457180544437,-2.796134009978082
417.3000000000052,47.32172442998759,-0.21449411968891458,-2.7978123239913937
418.4000000000052,47.42699585662908,-0.2137705401558088,-2.801268268156284
419.50000000000523,47.53507479569811,-0.21298340415022474,-2.8046288123917797
420.60000000000525,47.644350389708514,-0.2102536294014672,-2.808185535177828
421.7000000000053,47.75217357612438,-0.20868553822002875,-2.8102935106809355
422.8000000000053,47.859270503757564,-0.2064801437214565,-2.8145153263206786
423.9000000000053,47.96783941593206,-0.20269544521342547,-2.8171360010088886
425.00000000000534,48.075503801973845,-0.20206314704843664,-2.8199399348787617
426.1000000000053,48.18285513195607,-0.19830923176202056,-2.8227777914307457
427.20000000000533,48.29072859396789,-0.1975018858865473,-2.825556918639603
428.30000000000535,48.39861908617727,-0.19412188950892095,-2.829776454807229
429.4000000000054,48.506431202309905,-0.19138290001740985,-2.8311301392324104
430.5000000000054,48.61512888962165,-0.18854014406957234,-2.8337201465541244
431.6000000000054,48.72373713017573,-0.18529331527395287,-2.836604626114352
432.70000000000545,48.831357533872826,-0.18203501625060992,-2.8400509344735565
433.8000000000054,48.938772971594794,-0.17754807401387132,-2.8418381619849105
434.90000000000543,49.046233058985365,-0.17295244264398157,-2.8446141270187058
436.00000000000546,49.15484209086232,-0.17048987035210283,-2.8471837584409125
437.1000000000055,49.26328705330696,-0.16499959361806896,-2.8488042322050635
438.2000000000055,49.37128906792713,-0.16271577603664616,-2.8511823461810537
439.3000000000055,49.47951275878532,-0.15956306587589433,-2.8538126030461335
440.40000000000555,49.587409769387214,-0.15533628910041974,-2.858282254974957
441.50000000000557,49.69514754287997,-0.15245255282144635,-2.860347473391546
442.6000000000056,49.80178102460615,-0.14872800608198006,-2.8629372509053166
443.70000000000556,49.91173532096745,-0.14487073034342304,-2.8656893927667944
444.8000000000056,50.01992515770592,-0.14065812628139954,-2.8687752969385434
445.9000000000056,50.12821763143848,-0.1372345692872963,-2.871381264469936
447.0000000000056,50.235567487010194,-0.1342470186275832,-2.8730493270633706
448.10000000000565,50.342197651833764,-0.13085122471177552,-2.8767082827872152
449.2000000000057,50.45270673124031,-0.1274012434212852,-2.8779595637049704
450.3000000000057,50.5607259314973,-0.12411334779639477,-2.880665223499114
451.40000000000566,50.66877784958685,-0.12003282582091063,-2.8815930624841073
452.5000000000057,50.776689950489875,-0.11837077669299442,-2.884207387586961
453.6000000000057,50.88506469678707,-0.11474980744875636,-2.8855457968706726
454.70000000000573,50.993580207217406,-0.11022918377960098,-2.88808846849047
455.80000000000575,51.101468702749095,-0.10754170571758896,-2.8909953610893084
456.9000000000058,51.20994016661643,-0.10525470056541428,-2.893457938670848
458.0000000000058,51.31928261397339,-0.10067279914912446,-2.8960813915861183
459.1000000000058,51.42598489591932,-0.09875096757395273,-2.8973827485149917
460.20000000000584,51.53561785049421,-0.09611349276836378,-2.900003612218878
461.3000000000058,51.644040556612424,-0.09266487693054111,-2.900034058241209
462.40000000000583,51.753163116671416,-0.09116657161951278,-2.90341620401838
463.50000000000585,51.8595148306573,-0.08788168456469872,-2.9049800364715623
464.6000000000059,51.96994353204067,-0.08646001533101388,-2.906303110732602
465.7000000000059,52.07937540108517,-0.08442464220341406,-2.9076147934616197
466.8000000000059,52.18786925352645,-0.08261630340413405,-2.9103307613967684
467.90000000000595,52.296701483020726,-0.07873462314712704,-2.9122055143267827
469.0000000000059,52.40601974656,-0.07751813083770946,-2.913564676401747
470.10000000000593,52.51430134507803,-0.07618827780561084,-2.916127751052865
471.20000000000596,52.623738470279825,-0.07243837484891688,-2.9162040057269936
472.300000000006,52.73247229805959,-0.07005956663309457,-2.918811903040753
473.400000000006,52.840580047732615,-0.06794422158044751,-2.9209093931861827
474.500000000006,52.94976079435269,-0.06479860543126627,-2.9224330723513408
475.60000000000605,53.05829969440725,-0.06248537308571548,-2.923034354375374
476.70000000000607,53.166969085456124,-0.061865199484939994,-2.9251310801138075
477.8000000000061,53.27586143332798,-0.05840815929078872,-2.9254409070015
478.90000000000606,53.38480541578002,-0.057555488431167166,-2.9277016515519856
480.0000000000061,53.49335826312524,-0.05569774098466818,-2.9301690446607314
481.1000000000061,53.60249317078268,-0.052734306780788186,-2.9322182263422834
482.2000000000061,53.71106749447137,-0.051186751771254806,-2.934956069478331
483.30000000000615,53.8195804512841,-0.04905413138461405,-2.9362690230855106
484.4000000000062,53.9288618230339,-0.045440159053553766,-2.936260909578371
485.5000000000062,54.037045225162295,-0.04515487579700898,-2.937580028581434
486.60000000000616,54.146636650922176,-0.040326075260321864,-2.937927177478179
487.7000000000062,54.25541447046167,-0.03337693209149151,-2.9391739137838853
488.8000000000062,54.36102416315924,-0.029409007174925426,-2.9410562240540368
489.90000000000623,54.47204835009612,-0.026516775547705207,-2.943155891223957
491.00000000000625,54.58032611757266,-0.021472322225930703,-2.94448292144674
492.1000000000063,54.690255561830426,-0.01813730638397307,-2.947132676286893
493.2000000000063,54.798261711661475,-0.017006119391407594,-2.94949928740556
494.3000000000063,54.90839155516249,-0.012461505454824556,-2.9507552310459815
495.40000000000634,55.01555589639066,-0.008078458971210274,-2.95075276162509
496.5000000000063,55.12555400579656,-0.005081661981113734,-2.951118708769101
497.60000000000633,55.23529082929322,-0.0020616227589982257,-2.9533888032600446
498.70000000000636,55.34416994903911,0.0006603112891740207,-2.9547038944534787
499.8000000000064,55.45282084771271,0.004717380366104692,-2.9560205615831907
500.9000000000064,55.56249494392336,0.006606828371953756,-2.9572814434277417
502.0000000000064,55.671201168362316,0.00923839809724676,-2.959970273342181
503.10000000000645,55.77996887781962,0.010603739610951936,-2.960564347639532
504.2000000000064,55.890179346212214,0.013291748294507754,-2.960278577493348
505.30000000000643,55.999371113806276,0.014737658294991124,-2.9616198304696564
506.40000000000646,56.10789561683551,0.017076976577902102,-2.964258333546609
507.5000000000065,56.21831047193499,0.0180493599700437,-2.9642518631367105
508.6000000000065,56.327314958872705,0.020039312909581195,-2.9655708752398873
509.7000000000065,56.436441349162095,0.02117599190822428,-2.965579527869888
510.80000000000655,56.54552050062619,0.023338844772964835,-2.9668996286070115
511.90000000000657,56.6556010138868,0.02527467120609801,-2.9682101949457325
513.0000000000066,56.76442062484905,0.026662018811048484,-2.972111275344451
514.1000000000065,56.87130057232818,0.028961946934750266,-2.9721649743387233
515.2000000000066,56.983634245309666,0.03149022493188796,-2.974797945258181
516.3000000000065,57.092920297010465,0.03303153088134783,-2.973480072310025
517.4000000000067,57.201402499386376,0.035219961510094176,-2.9748093654252337
518.5000000000066,57.31106654195316,0.03728544498037096,-2.9761181802082612
519.6000000000067,57.42058096835637,0.03852134710714857,-2.9774411460105403
520.7000000000066,57.52952273138684,0.04035565562117629,-2.9787496600366787
521.8000000000067,57.637952602047584,0.04092967529322349,-2.9787360586826743
522.9000000000067,57.748464288876,0.04248804876237554,-2.9800707111225933
524.0000000000067,57.85788953541375,0.04382880776662947,-2.9806277319837875
525.1000000000067,57.96769751789244,0.04599664805392036,-2.984016825518266
526.2000000000068,58.07661179548387,0.0439111393629187,-2.9853358388737274
527.3000000000068,58.186318740681074,0.04478386797884636,-2.9867338151980602
528.4000000000068,58.29597924871585,0.04548387984259703,-2.986659696840668
529.5000000000068,58.40533539929454,0.04623684602837157,-2.986650274370053
530.6000000000068,58.514711204242744,0.04731036038654286,-2.9879086542085815
531.7000000000069,58.62419225823888,0.04825741278925935,-2.987868144475553
532.8000000000068,58.73320740398956,0.04790884356640084,-2.9894290624299975
533.9000000000069,58.841640890921205,0.047161654942411396,-2.991588089121051
535.0000000000068,58.95157623228456,0.04600142867256581,-2.991663947635413
536.100000000007,59.06089021521011,0.0457417345943827,-2.993300483290773
537.2000000000069,59.16992760903253,0.044199908315819866,-2.993899967429699
538.300000000007,59.27926431284905,0.042637446672798,-2.995220171128765
539.4000000000069,59.3892784770305,0.042235728600170504,-2.996530563620995
540.5000000000069,59.49896780378539,0.04069748775843995,-2.996864254890659
541.600000000007,59.60896332286328,0.04119416740391637,-2.996199051495093
542.700000000007,59.718086983239814,0.040696851547502855,-2.9977780764851176
543.800000000007,59.82811180337463,0.03925091260379894,-3.001390652615947
544.900000000007,59.937017487397185,0.038831580520968204,-3.001484092979598
546.000000000007,60.046770933640396,0.03784692089489841,-3.0014820565114
547.1000000000071,60.15667950523806,0.0374236934076592,-3.004109761733778
548.2000000000071,60.26644305450275,0.03887393167576863,-3.0041109321951387
549.300000000007,60.375650154020065,0.038735959889282884,-3.0043954810637032
550.4000000000071,60.48588195465389,0.036267714311670626,-3.0064116905682012
551.500000000007,60.596344553199096,0.03796812552087934,-3.0077298660881366
552.6000000000072,60.704270386394704,0.03670004843758024,-3.009038864887697
553.7000000000071,60.814154525703515,0.0392609564302576,-3.0090506772198955
554.8000000000072,60.92389445890574,0.03799611915053042,-3.0090501215988192
555.9000000000071,61.03357070650653,0.037651656800475886,-3.0102759760856266
557.0000000000072,61.14288524121889,0.039215047820689714,-3.0113508220593945
558.1000000000072,61.25429302422342,0.040625566357649946,-3.0126700281528986
559.2000000000072,61.36325212888884,0.040236449440019924,-3.0126707295730286
560.3000000000072,61.4728073388772,0.03792141801696885,-3.012638842402745
561.4000000000073,61.582539164351196,0.03930366088052287,-3.014028840932986
562.5000000000073,61.69149209664627,0.03872440950216789,-3.0139901131007316
563.6000000000073,61.80130907994022,0.0397177131394473,-3.015319622105163
564.7000000000073,61.909833407148064,0.039104853033568164,-3.016957415499016
565.8000000000073,62.02105983612361,0.04038817497005216,-3.018128500358744
566.9000000000074,62.131028051963014,0.04031994360419247,-3.0187316273930755
568.0000000000074,62.23944675019949,0.03973584705362613,-3.0189298129352995
569.1000000000074,62.34730638931244,0.04055953980163792,-3.0215711019803004
570.2000000000073,62.45916900230928,0.04170780600081525,-3.0215667851253825
571.3000000000073,62.56898225426508,0.0422444270387775,-3.0202500489745145
572.4000000000074,62.67762107139397,0.04171757944948821,-3.020834477500821
573.5000000000074,62.78766602770068,0.0417087409933989,-3.0231005468123837
574.6000000000074,62.89792511577762,0.04306508312728561,-3.024080791733428
575.7000000000074,63.00660023205851,0.04182379415744803,-3.025793064663175
576.8000000000075,63.116153051800914,0.0415481427704105,-3.0245331765435504
577.9000000000075,63.2254837551531,0.04356798297489935,-3.0258433825116944
579.0000000000075,63.336132120097524,0.041735047382689454,-3.0271598032290985
580.1000000000075,63.44592144060837,0.04072160248202127,-3.028470632003562
581.2000000000075,63.555362349766675,0.04261216773815946,-3.0294596377516863
582.3000000000076,63.66546127458089,0.04363174733610329,-3.029732620546675
583.4000000000076,63.77405931867869,0.04380453402357561,-3.0297898610554315
584.5000000000076,63.88362479313568,0.04342460241061404,-3.031096129178861
585.6000000000076,63.99373237846622,0.043040638146374925,-3.031440126265906
586.7000000000077,64.10391116295132,0.04313399420685848,-3.031892229940201
587.8000000000077,64.21419166315418,0.04583172699134453,-3.032586237170504
588.9000000000076,64.32352552841498,0.04455058581809808,-3.0340722814229832
590.0000000000076,64.4338378782851,0.043838733635026404,-3.034079720884978
591.1000000000076,64.543640316014,0.04482968148876356,-3.0340736494136618
592.2000000000077,64.65474255253423,0.04259991154335772,-3.035497047690747
593.3000000000077,64.7640962696453,0.04160420635798342,-3.036806147732459
594.4000000000077,64.87473540565819,0.040450282863201764,-3.038031058048237
595.5000000000077,64.98353007353822,0.041942930788794054,-3.039349884403946
596.6000000000078,65.09328215865169,0.04295417288569614,-3.0393498080704227
597.7000000000078,65.20337729829618,0.04326513276407843,-3.0386894054242317
598.8000000000078,65.31357486473819,0.04405796479998467,-3.0400105650819986
599.9000000000078,65.42119433147674,0.045260962512428955,-3.040945684075661
601.0000000000078,65.53305234371199,0.04561253347562181,-3.041001183522847
602.1000000000079,65.64279953187621,0.04592861700357354,-3.042683911651798
603.2000000000079,65.75146522420083,0.04532140629448233,-3.0439572724831425
604.3000000000079,65.86171910708333,0.04546763177040219,-3.042970154294824
605.4000000000078,65.97218346088954,0.046917600326942775,-3.0426401963813055
606.5000000000078,66.08222816054526,0.04702767351306359,-3.044971561927516
607.6000000000079,66.19224674032758,0.04900118510505397,-3.045282578621727
608.7000000000079,66.3015173804565,0.04825270353046583,-3.0452965485227406
609.8000000000079,66.41180995447003,0.048200528537158824,-3.048505724035901
610.9000000000079,66.52083743931651,0.048400247636708096,-3.0479105428374234
612.000000000008,66.63057089707293,0.04842670133505561,-3.0479094745643995
613.100000000008,66.7405369771867,0.05036207703927258,-3.0485650208678505
614.200000000008,66.85115405529133,0.0493234991765286,-3.0492301795456602
615.300000000008,66.95833085380627,0.05055918633137411,-3.049562287149967
616.400000000008,67.07008553467098,0.0518777441123883,-3.0495498980061133
617.5000000000081,67.18042755025817,0.05167446828234492,-3.049550178978513
618.6000000000081,67.29047696967073,0.05353657659222231,-3.0508701146125854
619.7000000000081,67.3999491251355,0.053525747465837034,-3.051897116881513
620.8000000000081,67.51085890460341,0.053623621075770615,-3.0505489869773426
621.9000000000082,67.62091001745526,0.05423999698353314,-3.052985492933985
623.0000000000082,67.73123236904449,0.05358663167168662,-3.052190268011424
624.1000000000081,67.84053022891327,0.05301221779364505,-3.053509840762284
625.2000000000081,67.95086804939822,0.0535425558990474,-3.0548263217661216
626.3000000000081,68.06016865541059,0.05345840085382213,-3.054830051516986
627.4000000000082,68.17154093613335,0.05239477397760247,-3.0552639220327764
628.5000000000082,68.28178148687192,0.054309631082366715,-3.056479768424603
629.6000000000082,68.3926534818751,0.053974580527138535,-3.055170001349443
630.7000000000082,68.50207697800914,0.053156938955814394,-3.0567098694815438
631.8000000000083,68.6125856070094,0.05410268812316981,-3.0580715045707962
632.9000000000083,68.72222740120954,0.05238648874178207,-3.05911621933977
634.0000000000083,68.8331597170672,0.05194922537548257,-3.059835330404179
635.1000000000083,68.94383423425684,0.05378803525247929,-3.0605954559099
636.2000000000083,69.05306493432809,0.053848829567237265,-3.0604194613192677
637.3000000000084,69.16340279376314,0.05636218432200111,-3.0630605477247395
638.4000000000084,69.27344803166628,0.054464768244232915,-3.0620232322093943
639.5000000000084,69.38312970567266,0.0550795045117656,-3.0617387555407785
640.6000000000083,69.49460648006168,0.05641247364223272,-3.0641464557093006
641.7000000000083,69.60398083989007,0.05580477746994111,-3.0640496471507594
642.8000000000084,69.71466994995961,0.055884420059825086,-3.065369901144418
643.9000000000084,69.82432518591177,0.05355900039904,-3.0653018072098677
645.0000000000084,69.93402281258996,0.05466597241655601,-3.0640468873916866
646.1000000000084,70.04438237002523,0.052782724919858165,-3.064049974001028
647.2000000000085,70.15490264614161,0.0541556555778274,-3.0640499750980563
648.3000000000085,70.26437073385152,0.052622809313350734,-3.0653628288617476
649.4000000000085,70.3730692728804,0.05217244218261547,-3.06539104695435
650.5000000000085,70.48451694708234,0.053034552665135376,-3.066688900805191
651.6000000000085,70.59521417778814,0.05563242734231637,-3.065370458682813
652.7000000000086,70.70614019514794,0.053700938497274205,-3.066685815758001
653.8000000000086,70.8148348050203,0.053590944087523,-3.0679969330190753
654.9000000000086,70.92492288428373,0.05196196856685527,-3.067881170199916
656.0000000000086,71.03518824373667,0.052632499585436775,-3.067999894970494
657.1000000000087,71.14566832395099,0.0528438399138981,-3.0679999177537827
658.2000000000087,71.25496696895246,0.05316379875678251,-3.0676266439438313
659.3000000000086,71.36629158736542,0.053545663383005156,-3.0676706743697877
660.4000000000086,71.4768335403913,0.05268891999662602,-3.0693224504869825
661.5000000000086,71.58703404839646,0.05186607903263301,-3.0693201260098872
662.6000000000087,71.69754973467062,0.050044405298707934,-3.0706344673553043
663.7000000000087,71.80781568776347,0.05036523298668841,-3.0719495003557578
664.8000000000087,71.91926537601248,0.0505089404155106,-3.071950012149861
665.9000000000087,72.02926677699877,0.0508555255528439,-3.0719191155819328
667.0000000000088,72.13856089581816,0.04960369944147702,-3.070640716830649
668.1000000000088,72.24958011008934,0.05022410529174035,-3.071971501413909
669.2000000000088,72.36000227423499,0.05224182892880159,-3.071959945971047
670.3000000000088,72.4697739672335,0.05164889965460581,-3.0719812602487115
671.4000000000088,72.58099160652756,0.05099632084479471,-3.0732664510232537
672.5000000000089,72.69022114486847,0.052177885106513715,-3.0732612959895143
673.6000000000089,72.80205111578842,0.05322454379742253,-3.074255359060221
674.7000000000089,72.91311087203178,0.051947752222866544,-3.0745882099045954
675.8000000000088,73.02313646964856,0.05268076516172429,-3.0746123536008128
676.9000000000088,73.13364466687277,0.05221214815256251,-3.075910165886844
678.0000000000089,73.2431119293275,0.0509781729258155,-3.0759102334624204
679.1000000000089,73.35409589856242,0.05246268606021693,-3.0772191827564157
680.2000000000089,73.46422621604934,0.0509524862773171,-3.078543581768611
681.3000000000089,73.5735345821235,0.05319595662052341,-3.077550282306045
682.400000000009,73.68369520601044,0.05371803237278257,-3.078569148680659
683.500000000009,73.79438533769017,0.052695655218757055,-3.0788698157832393
684.600000000009,73.905676684312,0.04982086861728906,-3.0787367945745636
685.700000000009,74.01584464375256,0.051907359746986875,-3.078467653075664
686.800000000009,74.12706552472565,0.05113128794329963,-3.0795794149498494
687.9000000000091,74.23771619343862,0.051400279049210275,-3.079860158990366
689.0000000000091,74.34756799533292,0.04922685085492487,-3.080849363065345
690.1000000000091,74.45851785274623,0.05014859315304308,-3.0798598409789246
691.2000000000091,74.56867506083327,0.04919830510459807,-3.0811848989443202
692.3000000000092,74.6797144300919,0.04793278778395284,-3.0824982550537547
693.4000000000092,74.78966703123493,0.05015966074124677,-3.0822081062985114
694.5000000000091,74.90036118611029,0.04722595125712138,-3.0824998021542496
695.6000000000091,75.01105528359282,0.04787220333555046,-3.0836008331691014
696.7000000000091,75.12151072253917,0.047155841297146145,-3.0846642628980994
697.8000000000092,75.23223205849,0.04748473323251368,-3.083809827030973
698.9000000000092,75.34282314305716,0.045394938513851936,-3.085238335380513
700.0000000000092,75.45366304320133,0.047970090954328554,-3.0846074405397808
701.1000000000092,75.56404950816598,0.046980472353640855,-3.0856995698972396
702.2000000000093,75.67497903777014,0.047586167822031594,-3.0864393023084666
703.3000000000093,75.78453368715336,0.04820792895279754,-3.0890863244038456
704.4000000000093,75.89470553894745,0.05092010087682121,-3.086536349147449
705.5000000000093,76.0055120944131,0.050357091316950896,-3.0891101369619807
706.6000000000093,76.11549600594773,0.05170966920680646,-3.0880139141300686
707.7000000000094,76.22609611152956,0.05095525407572081,-3.087422313619626
708.8000000000094,76.33626270547508,0.05174055340226707,-3.088750118489081
709.9000000000094,76.4458333526269,0.0515687538421206,-3.0899030483496106
711.0000000000093,76.55816719580841,0.0498455471674336,-3.0894155261659852
712.1000000000093,76.66744457417226,0.05094002949123942,-3.0907300016354626
713.2000000000094,76.77788369150018,0.05062070230366064,-3.0897399998842756
714.3000000000094,76.88800382037816,0.05164063818058742,-3.0896720305214305
715.4000000000094,76.99815286354838,0.05131771547559374,-3.0907399551526114
716.5000000000094,77.10786434744479,0.051185933761025565,-3.0920499333782905
717.6000000000095,77.2191720976604,0.05124043989246962,-3.0907235449013517
718.7000000000095,77.3294762508805,0.05079436410838519,-3.0920377730778927
719.8000000000095,77.44021403226415,0.05083097030343383,-3.092040054190746
720.9000000000095,77.55028386293945,0.05009791420179832,-3.0933600819086533
722.0000000000095,77.66096025059535,0.049143536192840565,-3.0946799811535035
723.1000000000096,77.7725537733397,0.048406865625833614,-3.093352534791649
724.2000000000096,77.88257984120227,0.04957323635015336,-3.0946800027496932
725.3000000000096,77.99297458289293,0.04774105700441472,-3.094679986002209
726.4000000000096,78.10436486477224,0.04738798804066183,-3.094673957371763
727.5000000000097,78.21452593703368,0.045358349819515406,-3.0959836795840596
728.6000000000097,78.32480269459049,0.04356513568253419,-3.0971038904443655
729.7000000000096,78.4357288141503,0.04371054610791317,-3.094998954355294
730.8000000000096,78.54629052766185,0.044370198887127565,-3.0963416943722333
731.9000000000096,78.6565050938836,0.04501947982743972,-3.0960000380179564
733.0000000000097,78.76760152884047,0.04336933217382494,-3.096000711714807
734.1000000000097,78.87841129077253,0.04624263883037253,-3.097319794450255
735.2000000000097,78.99007681964359,0.043944686727784024,-3.096673874647332
736.3000000000097,79.10015321745831,0.043509858654891514,-3.0963297255575175
737.4000000000098,79.21163885468911,0.04509065691566094,-3.0989677370624045
738.5000000000098,79.32196790593984,0.04580706480588711,-3.0989699671089856
739.6000000000098,79.43208176994787,0.04576041850417891,-3.097696874375962
740.7000000000098,79.54280100904663,0.04352262054138246,-3.0976326206701703
741.8000000000098,79.65362498820004,0.042788711186283086,-3.097640089955882
742.9000000000099,79.76399033151932,0.04112168192989668,-3.097736395769677
744.0000000000099,79.87472034721118,0.041821186116557434,-3.0979697610504884
745.0000000000099,79.97504177169378,0.042587932895186954,-3.097969855999836