File: 01_Data/Plastic_Laminate_Countertop_Particle_Board/STA/N2/10K_min/Plastic_Laminate_Countertop_Particle_Board_STA_N2_10KData_221004_R2.csv
##Temp./Â°C,Time/min,DSC/(mW/mg),Mass loss/mg
51.0,10.723141508650759,-1.601155218044304,-0.06376830955039647
52.100000000000016,11.112661496661184,-1.4735376985548498,-0.06389332360419164
53.20000000000003,11.368163541030295,-1.391314276588219,-0.06541555052466741
54.30000000000005,11.5775491210659,-1.3283675704254927,-0.06559934905730724
55.40000000000006,11.7614171560994,-1.2830004255095926,-0.06641594345874013
56.50000000000008,11.938660851535282,-1.2405650422216548,-0.0670745016839045
57.600000000000094,12.100684311132882,-1.2064480563007114,-0.06798169246961461
58.70000000000011,12.254228068103966,-1.1797947972904768,-0.06937955196081047
59.800000000000125,12.406583173504876,-1.1534194177824648,-0.067456814744276
60.90000000000014,12.552396733138487,-1.1332933349314251,-0.0671015567129305
62.000000000000156,12.696351742821427,-1.1122776381742394,-0.06881821987855563
63.10000000000017,12.835893584578857,-1.0938365516916737,-0.06849480395495622
64.20000000000019,12.972355638486336,-1.0771991745453084,-0.06844703944939567
65.30000000000021,13.108680998984976,-1.0606073439851742,-0.07100584920788444
66.40000000000022,13.241014809142326,-1.045954763876631,-0.07134558106241862
67.50000000000023,13.37254236515415,-1.029614196907746,-0.07196738823863313
68.60000000000025,13.502729633844368,-1.0153615262529792,-0.07277866218650164
69.70000000000027,13.632358943516603,-0.9995207971054128,-0.07277888353914674
70.80000000000028,13.759467906746197,-0.9859325444913566,-0.0714848950929663
71.90000000000029,13.884899476949224,-0.9730599309466175,-0.07340182225684666
73.00000000000031,14.009288088872085,-0.9592154575565854,-0.07417131490542728
74.10000000000034,14.13371487719498,-0.9454429780815321,-0.07552907533521713
75.20000000000034,14.254296605269351,-0.9339246348196898,-0.075523971699051
76.30000000000035,14.376827086593597,-0.9212058512706708,-0.07603280086419062
77.40000000000038,14.497475783939791,-0.9103873647284807,-0.07815840232600291
78.5000000000004,14.617588891650502,-0.8981548060935075,-0.0794586487506046
79.6000000000004,14.736499600471898,-0.8873053004212919,-0.08063391303641376
80.70000000000041,14.855228123181536,-0.8782055315539515,-0.0808501241557118
81.80000000000044,14.972665563246801,-0.8693029761470209,-0.08086193566373412
82.90000000000046,15.089787587464011,-0.8596678403396892,-0.08222942178641457
84.00000000000047,15.20630379735201,-0.8497024767740843,-0.08223890558242841
85.10000000000048,15.320973559606546,-0.8402572107950905,-0.08354053867787048
86.2000000000005,15.437425209937368,-0.8334432865320701,-0.08222756064397085
87.30000000000052,15.552036951052784,-0.8258137560473088,-0.0848724217950001
88.40000000000053,15.665863154436504,-0.8187119029497092,-0.08616320601117122
89.50000000000054,15.779616922617342,-0.8114278103703946,-0.08663910055024893
90.60000000000056,15.893773970080142,-0.8049281892357018,-0.08734784175903654
91.70000000000059,16.005026591410985,-0.8000975307684832,-0.08738859564603185
92.8000000000006,16.118005091383573,-0.7938871480158953,-0.08811403655008876
93.9000000000006,16.2288738636682,-0.78695996109673,-0.08884618643007913
95.00000000000063,16.339906528017032,-0.7839491792471042,-0.09002999922332089
96.10000000000065,16.44773108175886,-0.7793572694663846,-0.09002487574543139
97.20000000000066,16.561550303635425,-0.7724939387761175,-0.09002137746026273
98.30000000000067,16.67169507618323,-0.768155274342382,-0.09063742653671003
99.40000000000069,16.781765112372142,-0.764117836309098,-0.0919500842078862
100.50000000000071,16.892037744771788,-0.7613335897270571,-0.09239989387620007
101.60000000000072,17.000291328332732,-0.7545518513695858,-0.09180557656714061
102.70000000000073,17.109639227594915,-0.74915257603912,-0.09266039650931202
103.80000000000075,17.219164316059693,-0.7457883611895655,-0.09509658982313729
104.90000000000077,17.327071364523462,-0.7419206480318952,-0.09397550196882865
106.00000000000078,17.437132392123274,-0.7356129462421366,-0.09397020905854037
107.10000000000079,17.543564303708393,-0.7323519940692904,-0.09397930282884559
108.20000000000081,17.651087819350536,-0.7278924122599617,-0.09288528126768414
109.30000000000084,17.76142991083056,-0.724466980919022,-0.09269463305069836
110.40000000000084,17.869484382753427,-0.7195378962255289,-0.09561803510900813
111.50000000000085,17.977855154535778,-0.7147750280572444,-0.09694529747692426
112.60000000000088,18.084141189315197,-0.7099805696502808,-0.09694006305934799
113.7000000000009,18.19294674489766,-0.7061867622143273,-0.09825329744177136
114.8000000000009,18.3009337102161,-0.7013774910871785,-0.0969398614081265
115.90000000000092,18.40800457679837,-0.6981132306711754,-0.09693953498284014
117.00000000000094,18.51731983560014,-0.6931554237791817,-0.09692972934126232
118.10000000000096,18.623626793471967,-0.6876313441378703,-0.09693803000653389
119.20000000000097,18.731829081306795,-0.6844310418874516,-0.0969398686271905
120.30000000000098,18.838722092115113,-0.6784275487706004,-0.09691180435092228
121.400000000001,18.94548642759284,-0.6746910626866387,-0.09731844109312471
122.50000000000102,19.05269607285454,-0.6699505466001765,-0.09828500935501205
123.60000000000103,19.15971193175944,-0.6650330220099765,-0.0982602188653221
124.70000000000104,19.266398620296602,-0.6601895691946288,-0.09827889226625741
125.80000000000106,19.373259104822573,-0.6555705551636061,-0.0995698802726741
126.90000000000109,19.481222359273268,-0.6503402919841598,-0.09956981659908415
128.00000000000108,19.586414111157367,-0.6468715482975251,-0.09890714032235559
129.1000000000011,19.692535773650246,-0.6418811348691887,-0.09957351430667227
130.20000000000113,19.800198633483454,-0.6353192105218612,-0.0995800185423188
131.30000000000115,19.9059582292306,-0.6304903759993177,-0.10090018709528303
132.40000000000117,20.01054144420664,-0.6259399980108367,-0.10183275678878623
133.50000000000117,20.11812467752922,-0.6214264726940585,-0.09953293825646847
134.6000000000012,20.224119165719525,-0.6175286272429417,-0.10089024822005799
135.7000000000012,20.3295881589818,-0.6122527732194853,-0.10192120323196008
136.8000000000012,20.435819885615004,-0.6069314118975728,-0.10150448100081366
137.90000000000123,20.54067900901824,-0.6020508623333483,-0.10221078016533935
139.00000000000125,20.64637601543864,-0.5981789341974412,-0.10089989767878382
140.10000000000127,20.751302630055573,-0.5925396988912675,-0.1021899220135647
141.2000000000013,20.856327493912527,-0.5881609517804498,-0.1028399899312209
142.3000000000013,20.9621845446945,-0.5825800357552946,-0.10256269842181354
143.4000000000013,21.06715394323427,-0.579101241328219,-0.10254598998366582
144.50000000000134,21.172284117441347,-0.5744925136600849,-0.10386080573095136
145.60000000000133,21.278730664049213,-0.5688390506513054,-0.1051750739884385
146.70000000000135,21.383559777882116,-0.5630648844131664,-0.1048556408549528
147.80000000000138,21.487884850247095,-0.5574011943220579,-0.10483112966669506
148.9000000000014,21.5934485672,-0.5523874539889388,-0.1048399171613017
150.00000000000142,21.698849379856764,-0.5469979061682868,-0.1045095358540249
151.10000000000142,21.80188857422609,-0.5420559332076854,-0.10353089664181692
152.20000000000144,21.90662891735237,-0.5372972355056207,-0.1048505508648887
153.30000000000146,22.01145208255545,-0.5327870982340978,-0.10483151801455026
154.40000000000146,22.11692356506465,-0.5269338435775462,-0.10484104057974264
155.50000000000148,22.221957395840978,-0.5213611621523091,-0.10616096968348598
156.6000000000015,22.325472507371288,-0.5158148233728317,-0.10844770578865148
157.70000000000152,22.431921215941582,-0.5104496057857727,-0.1071539219305917
158.80000000000155,22.535394552171734,-0.5042144499279096,-0.10715002846114263
159.90000000000154,22.64046950821943,-0.49863120998184574,-0.10846858367941437
161.00000000000156,22.74557364771507,-0.49402776211027766,-0.10714984368297298
162.1000000000016,22.84928713775669,-0.48772660453018246,-0.1084379726768594
163.20000000000158,22.953852927791193,-0.48332549025601,-0.10978011483675632
164.3000000000016,23.05689577014935,-0.47670709684658036,-0.10978673803465622
165.40000000000163,23.16273116410626,-0.47109063085685726,-0.11077012376920559
166.50000000000165,23.266791296884506,-0.4657754630957601,-0.11005785107007071
167.60000000000167,23.37026977726048,-0.45997372657608937,-0.11010988736193461
168.70000000000167,23.47662554360992,-0.45316592428725044,-0.10983011275347465
169.8000000000017,23.582113709875042,-0.44618345582266344,-0.11241840403975134
170.9000000000017,23.685620784868124,-0.4402875768666688,-0.11241993226836033
172.0000000000017,23.790089567561918,-0.4341299508376218,-0.11374035056462084
173.10000000000173,23.89381729809053,-0.42904750181932216,-0.11340002484045941
174.20000000000175,23.997837984094094,-0.422051977883991,-0.11242004994303612
175.30000000000177,24.103194062732978,-0.41596461808921836,-0.1137168900554828
176.4000000000018,24.20837746993285,-0.4098671990436616,-0.11505950091205097
177.5000000000018,24.310000000000187,-0.40165999999997143,-0.11509776841442276
178.6000000000018,24.416954889235736,-0.39606990851055385,-0.11636181060867568
179.70000000000184,24.522374940587344,-0.3888026111606039,-0.1171103582838775
180.80000000000183,24.626610290781393,-0.3815946914481897,-0.11722609917852189
181.90000000000185,24.729043466998778,-0.3748549268150223,-0.11901525097036103
183.00000000000188,24.835547992629,-0.36737796138138246,-0.12032997717282257
184.1000000000019,24.940776193998154,-0.3607363795409449,-0.12032990822077672
185.20000000000192,25.044562332408162,-0.35472583408600195,-0.12227654286755252
186.30000000000192,25.14846724836672,-0.34715698526639793,-0.12361986568153016
187.40000000000194,25.252763219814156,-0.34006338312844114,-0.12361989906546622
188.50000000000196,25.35762717857834,-0.33458805463851826,-0.12494205610282805
189.60000000000196,25.461866301557635,-0.3280771785069183,-0.12625017839141162
190.70000000000198,25.56677764234085,-0.31952202876005054,-0.12624668907394776
191.800000000002,25.671271487939787,-0.31400825963269696,-0.12757018252784347
192.90000000000202,25.775701777695843,-0.30668919815643403,-0.127568994703942
194.00000000000205,25.88069362508343,-0.29970496353458004,-0.12889456490885554
195.10000000000204,25.984990913432835,-0.29462590992716786,-0.13284178637591992
196.20000000000206,26.088103894114212,-0.2865090986117676,-0.13284015399908222
197.3000000000021,26.192857239879242,-0.28235207477659613,-0.13284013870321276
198.40000000000208,26.297122284418112,-0.27624969631266116,-0.13428414469916072
199.5000000000021,26.402285739425732,-0.2720233353213782,-0.13675704901889363
200.60000000000213,26.507264664548906,-0.2670277294248084,-0.13942190947260302
201.70000000000215,26.610989694660006,-0.26246909004850943,-0.14008231513759917
202.80000000000217,26.715669288810517,-0.25708813462972957,-0.13999549514862863
203.90000000000217,26.820295341132926,-0.2530179673511292,-0.14206009628153415
205.0000000000022,26.924956371063086,-0.25017732303325685,-0.14335803011085524
206.1000000000022,27.030086305991873,-0.24567952050470218,-0.1446996701362555
207.2000000000022,27.13273675974087,-0.24183528755874195,-0.14713993965795913
208.30000000000223,27.237817475710713,-0.23764962727524644,-0.14855885210799524
209.40000000000225,27.342740870354454,-0.23235820450377248,-0.1515483218539253
210.50000000000227,27.446571234119,-0.2296766447644656,-0.15370055559527618
211.6000000000023,27.55117537505331,-0.22610469452297566,-0.15533948381827445
212.7000000000023,27.65529823487508,-0.22228508809615655,-0.15643667802228567
213.8000000000023,27.760814740728513,-0.21885843700207405,-0.15806049613232265
214.90000000000234,27.865608416339963,-0.215852363486523,-0.16022078488855573
216.00000000000233,27.970848315986334,-0.20984329000898688,-0.1613049716463042
217.10000000000235,28.07311972103569,-0.20686501310758218,-0.16456058539216656
218.20000000000238,28.178307380981565,-0.20142688658609167,-0.16837981515768297
219.3000000000024,28.28435812879748,-0.19859747691180718,-0.16851023443935764
220.40000000000242,28.389708566856093,-0.19336625165736032,-0.16854203542905832
221.50000000000242,28.492557225030364,-0.18925577711857094,-0.17128758694100554
222.60000000000244,28.59720169885553,-0.18504691470587398,-0.17378081655704536
223.70000000000246,28.70156634283647,-0.18105415969406977,-0.1753974691023683
224.80000000000246,28.80590318794002,-0.17732933970190443,-0.17916842532490262
225.90000000000248,28.910713390691203,-0.17384802361946045,-0.18021621409788624
227.0000000000025,29.015568458129533,-0.17093812342908501,-0.1824650511790189
228.10000000000252,29.11990030787905,-0.1673755302802772,-0.18663041176221862
229.20000000000255,29.223954685710407,-0.16346204762577118,-0.19063375387936654
230.30000000000254,29.329296057892986,-0.1633617234139912,-0.19201509033317432
231.40000000000256,29.434016603262044,-0.16047397499062838,-0.1956164507296001
232.5000000000026,29.538760038381728,-0.15701013989113458,-0.1973034825485973
233.60000000000258,29.643734163333825,-0.15521685417649192,-0.20033363792616665
234.7000000000026,29.7484635733785,-0.15335902378791377,-0.20258313817096774
235.80000000000263,29.85199196608497,-0.15080560851614871,-0.20648045531652537
236.90000000000265,29.95761658263693,-0.1503098268410128,-0.2104976593104233
238.00000000000267,30.062279699373704,-0.14924102639318104,-0.2130880709602354
239.10000000000267,30.167872001386215,-0.1466020169169663,-0.21569920397891673
240.2000000000027,30.270670777627444,-0.14715022830487243,-0.21870629934213603
241.3000000000027,30.37641804236347,-0.14452740690243934,-0.22428749191584885
242.4000000000027,30.481827600848423,-0.14413156004499839,-0.22900401276303972
243.50000000000273,30.58617348522831,-0.1423290196818366,-0.23194030617671935
244.60000000000275,30.690662655281137,-0.13992114347104367,-0.23604611360586025
245.70000000000277,30.794965723213277,-0.13821353376642556,-0.2405790553521756
246.8000000000028,30.9003990566249,-0.13548379454465456,-0.2455169253023537
247.9000000000028,31.005006690087708,-0.13309306898560735,-0.24956187979083522
249.0000000000028,31.10990423497713,-0.13236995939188015,-0.25666985036391443
250.10000000000284,31.21454631374038,-0.13071837957028085,-0.26138301914419815
251.20000000000283,31.318796721490642,-0.12855199610130172,-0.26621184663468345
252.30000000000285,31.424657725674425,-0.12593414596819721,-0.2718634134898772
253.40000000000288,31.52906167612795,-0.12366025182975522,-0.2795214263747301
254.5000000000029,31.633765350504902,-0.12173529695594873,-0.2830715055549522
255.60000000000292,31.739298917276752,-0.1189642660485869,-0.28768161009362414
256.7000000000029,31.84276428178081,-0.11660919834055598,-0.29440800019755997
257.8000000000029,31.948035816942994,-0.11448838829250223,-0.3019021479535473
258.90000000000293,32.05361264400664,-0.11429568047219167,-0.3065192049051606
260.00000000000296,32.156849169844804,-0.11202599379065178,-0.31369530595639317
261.100000000003,32.262422511639585,-0.11198062557110218,-0.3188769768242028
262.200000000003,32.36820355233514,-0.1100454372805902,-0.3274332726937983
263.300000000003,32.47156316636372,-0.10941267654341129,-0.33420366294221004
264.40000000000305,32.57728796470032,-0.10749123466058198,-0.34207971663684766
265.50000000000307,32.68224323447985,-0.10730356406141414,-0.3499393109244968
266.6000000000031,32.786407021404706,-0.10701306084789021,-0.3571137977348089
267.7000000000031,32.891172139459705,-0.10628576576623819,-0.36460790463258563
268.8000000000031,32.99544236292488,-0.10678747464006914,-0.3725840415301618
269.9000000000031,33.10167192536947,-0.10560722086503906,-0.38338870897360433
271.0000000000031,33.20695165089171,-0.10965980012341821,-0.39414195104530414
272.10000000000315,33.31132054360568,-0.11028196069340235,-0.4021103166347202
273.2000000000032,33.41593778091729,-0.11105032801086137,-0.41226851340197257
274.30000000000314,33.521851717685834,-0.11314182070833013,-0.42248648302917013
275.40000000000316,33.62636444418876,-0.11354338767758468,-0.43295038287166676
276.5000000000032,33.73207315344083,-0.11597652986043103,-0.44272881026276023
277.6000000000032,33.837072954808846,-0.11858900499977888,-0.4562389043806543
278.70000000000323,33.94214454706321,-0.12239486196256036,-0.4682373139483782
279.80000000000325,34.04730512514009,-0.12622246847449586,-0.47962852910635334
280.9000000000033,34.151992137454144,-0.12969558642451443,-0.4910576814991945
282.0000000000033,34.2542127202887,-0.1321800901609807,-0.5033990730984121
283.1000000000033,34.36134781599392,-0.13616942970143858,-0.5164551859738986
284.20000000000334,34.466814076006976,-0.14201997305956116,-0.5289220130797099
285.30000000000337,34.572178665142225,-0.14471172932856738,-0.5439689416551454
286.40000000000333,34.67748041350304,-0.14952734256257508,-0.5566212050450225
287.50000000000335,34.78247588056203,-0.15226614984028494,-0.571921552123515
288.6000000000034,34.88720592217377,-0.15780661564691553,-0.5852321333149995
289.7000000000034,34.993876862604154,-0.1622080723540886,-0.6006480657722824
290.8000000000034,35.0986378441317,-0.16458313680964243,-0.6148738221792276
291.9000000000034,35.20427699665911,-0.16823439066580406,-0.6322331327870128
293.0000000000034,35.30920695895003,-0.1712611679382796,-0.646433126997715
294.10000000000343,35.41580189042849,-0.1747318922160821,-0.661735288604425
295.20000000000346,35.520277740660326,-0.17842645716599007,-0.6777482272715125
296.3000000000035,35.6261045158754,-0.18044077358519195,-0.6950729298954932
297.4000000000035,35.73145724233652,-0.18271276283301793,-0.7119422534492394
298.5000000000035,35.8380738226341,-0.18593279284290973,-0.728463422560262
299.60000000000355,35.94301498167666,-0.18687278405094282,-0.7462850041690143
300.70000000000357,36.0478936936091,-0.18818125589864754,-0.7649384663337582
301.8000000000036,36.15454949284663,-0.18803712953980828,-0.7825203647730654
302.9000000000036,36.25991150127968,-0.18932904902359687,-0.8014071088006665
304.0000000000036,36.36468164762793,-0.19038800410531292,-0.8198299610352131
305.1000000000036,36.470871695971205,-0.1902360379618996,-0.8397283092765013
306.2000000000036,36.57592783591498,-0.19056319728530963,-0.8586524746417954
307.30000000000365,36.68181247362081,-0.19009808461403213,-0.8790139161940562
308.4000000000037,36.78795923850517,-0.1876150817683138,-0.8980763183236387
309.5000000000037,36.89267589637111,-0.18824628582594138,-0.9189936062658077
310.60000000000366,36.999696977551636,-0.18682666430461323,-0.9398944259641402
311.7000000000037,37.10450794223406,-0.18455127404932864,-0.9612145974515034
312.8000000000037,37.21098524854441,-0.182862013930319,-0.9815354641500509
313.90000000000373,37.31717516025602,-0.18131493323041747,-1.0053656634705588
315.00000000000375,37.42267537015848,-0.17807793628972501,-1.0286997953171628
316.1000000000038,37.52882710742055,-0.17447861684025373,-1.0516245245871851
317.2000000000038,37.63531881527525,-0.1706578984511239,-1.0757119967975979
318.3000000000038,37.74028899771606,-0.16661307614294998,-1.0978909945904514
319.40000000000384,37.846562992818235,-0.16355158342494416,-1.122198913899926
320.5000000000038,37.953660433351295,-0.1603467899130264,-1.145869010482182
321.60000000000383,38.05868425928014,-0.15567790822014935,-1.1692599986341534
322.70000000000385,38.1657727553766,-0.14996661265412117,-1.1957635187447186
323.8000000000039,38.271049702532096,-0.14734113686155006,-1.2212243744679987
324.9000000000039,38.376933205941434,-0.1406282360370277,-1.2459449195525165
326.0000000000039,38.4838991048848,-0.13452096102853617,-1.2719914082987667
327.10000000000394,38.589163564560586,-0.12961237364181669,-1.2983184409241604
328.2000000000039,38.69578025269058,-0.12384961129308106,-1.3238345976203352
329.30000000000393,38.80182104527212,-0.11743996858143055,-1.351833317988337
330.40000000000396,38.90744946639285,-0.11128124721115407,-1.3794546185905951
331.500000000004,39.012835545086915,-0.10466389609321279,-1.408014687359005
332.600000000004,39.12084428507618,-0.09740149910468436,-1.4404427158998905
333.700000000004,39.22662350405363,-0.09088502582322705,-1.4685439563418656
334.80000000000405,39.33165936744063,-0.08426792400669546,-1.4979525171117767
335.90000000000407,39.43804184887024,-0.07750895079547646,-1.5271869147416988
337.0000000000041,39.54482087148514,-0.07044339615465706,-1.5569740870153113
338.10000000000406,39.65129376709518,-0.0636862208338533,-1.5878273791266841
339.2000000000041,39.758620852649365,-0.05511005231803422,-1.6207398728826847
340.3000000000041,39.8647760337778,-0.04920865328497605,-1.6539875563457116
341.4000000000041,39.970270148015864,-0.04093396118407518,-1.685800296135508
342.50000000000415,40.074014698409066,-0.035498819279619544,-1.7180816038094684
343.6000000000042,40.18307888322098,-0.028630647183687494,-1.753761461086603
344.7000000000042,40.289240800474566,-0.021596205503392932,-1.7877914690720944
345.80000000000416,40.39668800898511,-0.014066216866503035,-1.8242250050045747
346.9000000000042,40.50304603037178,-0.008031246304148674,-1.859944106667299
348.0000000000042,40.608200782427986,-0.0016201432846802248,-1.8954460473888082
349.10000000000423,40.71456017627625,0.004713369497001839,-1.9333761715603273
350.20000000000425,40.82255128258636,0.010512726727183787,-1.9712496342740526
351.3000000000043,40.928158701877855,0.017349767442917427,-2.007814535773952
352.4000000000043,41.034685261649656,0.02249426961774645,-2.047489001929451
353.5000000000043,41.14137726973342,0.026879433192549703,-2.085919041285025
354.60000000000434,41.24797094368169,0.029240883718240393,-2.125945754620328
355.7000000000043,41.35264007915112,0.0317386899122948,-2.1657453847256924
356.80000000000433,41.461979841849946,0.03132521786802076,-2.206139806953669
357.90000000000435,41.56676007811903,0.03132590587907125,-2.2451076738828633
359.0000000000044,41.671456697077645,0.02918726661064589,-2.285425772783249
360.1000000000044,41.78048650006471,0.02393744092720895,-2.3247424010256164
361.2000000000044,41.8885524770526,0.017080814186792567,-2.3633627711843754
362.30000000000445,41.99214146700055,0.008142804609764718,-2.4029632286782046
363.4000000000044,42.101104822329,-0.003164047350552854,-2.44241331465409
364.50000000000443,42.20704709613057,-0.016436176427238287,-2.4792340072633525
365.60000000000446,42.31387780561597,-0.034513596718702896,-2.514525892880096
366.7000000000045,42.42034776313241,-0.05401058555833029,-2.5487580622560584
367.8000000000045,42.52535934934833,-0.07645774782669924,-2.5825863249067305
368.9000000000045,42.63369475621512,-0.10104944344311259,-2.6143754272443207
370.00000000000455,42.73974544503758,-0.12727696207874345,-2.6424010811089236
371.10000000000457,42.84726549258057,-0.15766457863041025,-2.6693873687311194
372.2000000000046,42.95404053330062,-0.1855267536999547,-2.693214626127969
373.30000000000456,43.060288104465606,-0.21480133782391342,-2.7124717721771496
374.4000000000046,43.16731433219106,-0.24305819555119548,-2.7304959847169723
375.5000000000046,43.27338325520352,-0.26803407789295164,-2.7471934712349997
376.6000000000046,43.38145829481783,-0.2919065276543968,-2.759511792496196
377.70000000000465,43.48690332474495,-0.310136317960944,-2.769924889874744
378.8000000000047,43.59412638807606,-0.32925044324939007,-2.7793788962902592
379.9000000000047,43.700466276846946,-0.34243354186874697,-2.7883403840072507
381.00000000000466,43.808105104028925,-0.3535217028535315,-2.797160068074174
382.1000000000047,43.91511505254981,-0.3602906016228737,-2.8025644901058753
383.2000000000047,44.021380915434904,-0.36602623751311747,-2.8072386792369763
384.30000000000473,44.129133197716165,-0.3710340568964612,-2.8147367127822402
385.40000000000475,44.23567589164646,-0.3749462813596835,-2.818779822930573
386.5000000000048,44.34302624977669,-0.3785570063265177,-2.823367399012929
387.6000000000048,44.448081777587134,-0.38019726517440156,-2.8259791606677505
388.7000000000048,44.55497008699128,-0.38288918790485327,-2.8295326136155405
389.80000000000484,44.661648733394074,-0.38450895211469277,-2.833482437813407
390.9000000000048,44.769020468437795,-0.38508088721980194,-2.8378956663174733
392.00000000000483,44.876104240180375,-0.3869702887514191,-2.841213081652402
393.10000000000485,44.983565049694654,-0.38815716287778473,-2.8448360221416715
394.2000000000049,45.09188133896034,-0.3904570224702807,-2.84757471975043
395.3000000000049,45.19859808810908,-0.391031945006482,-2.8527816771688714
396.4000000000049,45.30669646485753,-0.39116090497251915,-2.856319364854979
397.50000000000495,45.41274563935328,-0.39426708552044476,-2.8605966103298663
398.6000000000049,45.5218014549584,-0.3946790972253349,-2.8632530650990344
399.70000000000493,45.629184517351156,-0.39504557177422744,-2.867490990363527
400.80000000000496,45.736761508034505,-0.39809213261216003,-2.870167721776792
401.900000000005,45.84519320852602,-0.3988834813795908,-2.873188948427722
403.000000000005,45.95239570305567,-0.39980911616331033,-2.8764435782203917
404.100000000005,46.06028534139103,-0.39993344366821987,-2.8798302535508387
405.20000000000505,46.16729814737071,-0.4005113547137818,-2.8837752048409993
406.30000000000507,46.27527658439511,-0.4006476892305882,-2.8867753625499204
407.4000000000051,46.38344205893832,-0.39989899327181844,-2.8930584335055265
408.50000000000506,46.491244525316034,-0.4021231833029843,-2.895536652610838
409.6000000000051,46.59910346393352,-0.4005169156014654,-2.897896908952191
410.7000000000051,46.70641320187292,-0.40141540167287615,-2.9005792705196365
411.8000000000051,46.814380156295734,-0.40015336955419156,-2.901273725039329
412.90000000000515,46.92208667524377,-0.400681178107959,-2.905261860453817
414.0000000000052,47.03000000000049,-0.3976699999999748,-2.911206560568311
415.1000000000052,47.136508839204566,-0.39804268665791964,-2.916653316404839
416.20000000000516,47.243923151752995,-0.39563754014371005,-2.919478757349292
417.3000000000052,47.351632807165586,-0.393101556665459,-2.9222968737652453
418.4000000000052,47.458316493292294,-0.39280444046555446,-2.9229646539851486
419.50000000000523,47.56577802012097,-0.3899916358019305,-2.9263897482927055
420.60000000000525,47.67358803690834,-0.3898948580171922,-2.930768021964838
421.7000000000053,47.779999023949834,-0.38732005800630753,-2.9343910052687914
422.8000000000053,47.88868604288,-0.38528394433748137,-2.9383472957391654
423.9000000000053,47.99444184384966,-0.38465433693618745,-2.941068453452739
425.00000000000534,48.10317568474993,-0.3822557925915337,-2.943976764516267
426.1000000000053,48.21105441122019,-0.381206649716578,-2.949256280863834
427.20000000000533,48.31795705386945,-0.3782089261481067,-2.9508487556808083
428.30000000000535,48.425368827569805,-0.3763961011962784,-2.9519200832179
429.4000000000054,48.53373736705284,-0.3723950736910761,-2.954609684806165
430.5000000000054,48.64028662785133,-0.3714371660837967,-2.958544388239397
431.6000000000054,48.74735004306362,-0.3708552237381413,-2.9611690251450717
432.70000000000545,48.85579226863619,-0.36931639818201883,-2.963860940407689
433.8000000000054,48.96311788126011,-0.3650080384353927,-2.967472865151676
434.90000000000543,49.071414611524496,-0.363379791781318,-2.969296678348352
436.00000000000546,49.18000000000051,-0.36040000000003497,-2.971830074578559
437.1000000000055,49.2877131084159,-0.35739643864266984,-2.9730566854807856
438.2000000000055,49.39612759204132,-0.3544224043863868,-2.9771023179007945
439.3000000000055,49.50391679975357,-0.35102985453791363,-2.9797631047043414
440.40000000000555,49.61140239727609,-0.3473725808643761,-2.9814788171225164
441.50000000000557,49.71707154482289,-0.3422537856409823,-2.985530678380168
442.6000000000056,49.82811027026061,-0.3388266379432827,-2.9881931182872075
443.70000000000556,49.93553534882542,-0.3363182818592654,-2.9900181677911344
444.8000000000056,50.043799565677126,-0.333765056181704,-2.993106959785425
445.9000000000056,50.15185527035265,-0.332115114714656,-2.994787931960955
447.0000000000056,50.260762094506816,-0.327110901239216,-2.997567960866114
448.10000000000565,50.367685829788776,-0.32497776548719337,-3.001608254487467
449.2000000000057,50.475704451400716,-0.3212089732945213,-3.0026825982603693
450.3000000000057,50.58508780607548,-0.3175499679310722,-3.0041917599769192
451.40000000000566,50.693220504277654,-0.31432936719250765,-3.0056841633330613
452.5000000000057,50.80103321373812,-0.31144522943011504,-3.0108249392719917
453.6000000000057,50.90854316564162,-0.31021577621219215,-3.012766696798337
454.70000000000573,51.0179932246116,-0.30550418385409944,-3.0146759043035525
455.80000000000575,51.126111396641676,-0.3024970077502635,-3.015814240790626
456.9000000000058,51.23441381809215,-0.2994128217534281,-3.017165775454499
458.0000000000058,51.342513021053946,-0.2977073223661998,-3.0198645812515155
459.1000000000058,51.45068729231875,-0.2951331090146493,-3.021119502720451
460.20000000000584,51.55919426091846,-0.29308449629357675,-3.0237689030016504
461.3000000000058,51.66783219463171,-0.2902364808877282,-3.025042123672811
462.40000000000583,51.77605215833806,-0.28885235562002237,-3.0271640377357287
463.50000000000585,51.88343953327701,-0.28809264668943946,-3.029466230965165
464.6000000000059,51.99033706418854,-0.2836468081407282,-3.030674495902375
465.7000000000059,52.10049351816372,-0.28074604897950206,-3.0347019212096944
466.8000000000059,52.20971321568359,-0.27824633578700364,-3.035939335183085
467.90000000000595,52.31769643266536,-0.2771051374488542,-3.0375997514731274
469.0000000000059,52.42633772723399,-0.2738569370854262,-3.039874994149998
470.10000000000593,52.5345354507161,-0.2731678713558042,-3.0398792110053656
471.20000000000596,52.64294304290911,-0.27078679391647453,-3.041355036966074
472.300000000006,52.75093388578882,-0.26923189717610396,-3.0438382497610874
473.400000000006,52.860956298228785,-0.2679202818988033,-3.0451623436917528
474.500000000006,52.9669205614356,-0.2659788646883605,-3.0476962511330274
475.60000000000605,53.076469890446845,-0.2644481732320678,-3.049112069749835
476.70000000000607,53.18599118453615,-0.26306185450007974,-3.0504421886707633
477.8000000000061,53.29248236006731,-0.262353456027192,-3.052116750371722
478.90000000000606,53.40246871730547,-0.2591937934264393,-3.0540787181653997
480.0000000000061,53.51159671024947,-0.2577094141229912,-3.056676609803028
481.1000000000061,53.61907183905132,-0.25638402208943945,-3.057025159027021
482.2000000000061,53.72779665657132,-0.25478700067493537,-3.05964461142191
483.30000000000615,53.835665125859826,-0.25307281909736007,-3.059651452418165
484.4000000000062,53.94488635446295,-0.2525629617655822,-3.06234497526434
485.5000000000062,54.051983643123535,-0.2488210582024129,-3.0650227915693593
486.60000000000616,54.16179337111471,-0.24850371046926645,-3.0648908868000193
487.7000000000062,54.26944319614618,-0.24744441797018113,-3.0675657515583037
488.8000000000062,54.37801291448268,-0.24532569151291103,-3.068912977946281
489.90000000000623,54.48714584764791,-0.24251852602202545,-3.0700731496707476
491.00000000000625,54.59532196397669,-0.23522048628639278,-3.071603140545931
492.1000000000063,54.70489245831649,-0.23057624290086734,-3.0731609693089963
493.2000000000063,54.81289272438455,-0.22830222140951176,-3.0747484493410298
494.3000000000063,54.922966177827355,-0.22255422018303478,-3.0740864653262547
495.40000000000634,55.03037418859714,-0.22066619156583742,-3.078099881653539
496.5000000000063,55.139700190691414,-0.2176414196919359,-3.078433019952924
497.60000000000633,55.24837005869197,-0.21505250131933276,-3.0797414812509727
498.70000000000636,55.35757021078901,-0.21056409603102347,-3.082039803222785
499.8000000000064,55.465989176814325,-0.2089639880694819,-3.0827061047007636
500.9000000000064,55.57457711986605,-0.20586829622753533,-3.0826718429792095
502.0000000000064,55.68391418260353,-0.20385078456916078,-3.0867489911772443
503.10000000000645,55.79259948020307,-0.2005034894570705,-3.0866695504243666
504.2000000000064,55.90136987782859,-0.2000452764412859,-3.0886161142759896
505.30000000000643,56.011055654955044,-0.19700834417979504,-3.0886385530339013
506.40000000000646,56.1195894568717,-0.1948158824774141,-3.0885886520781742
507.5000000000065,56.229044437862534,-0.19302067988233879,-3.0899579551487713
508.6000000000065,56.33751933134442,-0.19090638426316384,-3.0932750122100687
509.7000000000065,56.443841155170745,-0.18906867785506842,-3.094248462303933
510.80000000000655,56.555342341666176,-0.18780935975229246,-3.0946056293020656
511.90000000000657,56.66381474969912,-0.1857763783504384,-3.094923808717087
513.0000000000066,56.7734920702404,-0.18375431932050915,-3.0981903843485936
514.1000000000065,56.88051510214793,-0.18272661244568372,-3.0995286662231294
515.2000000000066,56.99149619550432,-0.1813122260384324,-3.0995097610504074
516.3000000000065,57.10104806547977,-0.18004221967755227,-3.102197761979595
517.4000000000067,57.210302356292665,-0.17733237308516558,-3.1011854380210715
518.5000000000066,57.319500569054554,-0.17620258378029202,-3.103594711235403
519.6000000000067,57.427848711022094,-0.17498825236773566,-3.1049992843934326
520.7000000000066,57.53782592605263,-0.17421909410941844,-3.1063098732657783
521.8000000000067,57.64680417179605,-0.17345717986203665,-3.1056087288419727
522.9000000000067,57.755577482280735,-0.17177675463053707,-3.1069699424328
524.0000000000067,57.86399061101496,-0.17240310370290343,-3.1082900805429876
525.1000000000067,57.974568369495984,-0.17098190923889642,-3.110459726908159
526.2000000000068,58.08358769017952,-0.17023882115004255,-3.1125181251658622
527.3000000000068,58.19337161976541,-0.17031203947516005,-3.1150390666090635
528.4000000000068,58.303354605879775,-0.1685201635959439,-3.1136695620499024
529.5000000000068,58.412097066647256,-0.16914328414645471,-3.1136693843081544
530.6000000000068,58.52108521897247,-0.1672584831430882,-3.114978504450323
531.7000000000069,58.63109235379067,-0.16662296385946906,-3.116293457197821
532.8000000000068,58.740000989755266,-0.16713998045547732,-3.1162999926748967
533.9000000000069,58.849618787932684,-0.16576978190835698,-3.1179183662173333
535.0000000000068,58.95947078446241,-0.16701460286425432,-3.118859692753034
536.100000000007,59.06885987730699,-0.1670313431372036,-3.1189394330092735
537.2000000000069,59.17660674729335,-0.16637889768059508,-3.120259849851927
538.300000000007,59.28638356076395,-0.16799988970846927,-3.1215803727423688
539.4000000000069,59.39638822258503,-0.1672408804667906,-3.1239678578402117
540.5000000000069,59.50611925294525,-0.16680919565007615,-3.124786873209736
541.600000000007,59.61505450004342,-0.16739192316919094,-3.123879742508574
542.700000000007,59.72340955493055,-0.16990741827347897,-3.1259069061026556
543.800000000007,59.832683326431074,-0.1695734147141116,-3.1258580695800444
544.900000000007,59.93999828013738,-0.1713601412167284,-3.1284898363778755
546.000000000007,60.05082260902887,-0.17289110758459478,-3.1298032928299513
547.1000000000071,60.15886682266569,-0.17419265426866992,-3.13078066190174
548.2000000000071,60.268083906259115,-0.17481964911694392,-3.13112994700722
549.300000000007,60.37770742279999,-0.17608776997124065,-3.1311299502309033
550.4000000000071,60.48738676668339,-0.1782970422695002,-3.132440543116642
551.500000000007,60.595836592528826,-0.1775303095387123,-3.1324542958490826
552.6000000000072,60.704927179406575,-0.17879534762900473,-3.13376000825629
553.7000000000071,60.814213241782305,-0.1799112767063608,-3.1349675976069613
554.8000000000072,60.92307417640472,-0.1795543585633468,-3.136398562192487
555.9000000000071,61.03218418313062,-0.18122220881747436,-3.136411011667226
557.0000000000072,61.14222670921078,-0.18110187081808315,-3.137371951613572
558.1000000000072,61.25177638245357,-0.18130665737742663,-3.138700204850731
559.2000000000072,61.36066377123094,-0.1821365215697951,-3.1400197779558883
560.3000000000072,61.46918799707313,-0.1818178990929476,-3.1403403654899296
561.4000000000073,61.579076908589286,-0.1811554508759153,-3.1416743844546664
562.5000000000073,61.689074860144636,-0.18359989913375274,-3.141625076090751
563.6000000000073,61.798143249353345,-0.18432940219783325,-3.142988221773525
564.7000000000073,61.907347388305894,-0.18512459587947142,-3.1449599691535672
565.8000000000073,62.01657863614881,-0.18416388180621832,-3.144747124413793
566.9000000000074,62.125932959942766,-0.18649293112323984,-3.147674829075056
568.0000000000074,62.235187173627025,-0.1864162571515825,-3.147773405376539
569.1000000000074,62.34527024653605,-0.18801562688313164,-3.1481490348833416
570.2000000000073,62.454491451094675,-0.1878192957927798,-3.1493583174797397
571.3000000000073,62.564292230642764,-0.18782245872147044,-3.1506556457297914
572.4000000000074,62.67391583920483,-0.1892401234922404,-3.15131960699998
573.5000000000074,62.784137318579425,-0.18930023761299455,-3.1516473847707505
574.6000000000074,62.89239981680435,-0.1890246628845323,-3.1511826033150228
575.7000000000074,63.00296045193635,-0.188912485952999,-3.1529315601445482
576.8000000000075,63.11256055454372,-0.19004457838887215,-3.153577196101149
577.9000000000075,63.221397567867676,-0.19165534408853355,-3.15494003221618
579.0000000000075,63.33136533568407,-0.1903214056937318,-3.156025225599553
580.1000000000075,63.441053787125526,-0.19038456587572206,-3.155615699826605
581.2000000000075,63.55021365401524,-0.19017436535247423,-3.157936581461186
582.3000000000076,63.660806627673956,-0.18893856121705402,-3.158250156007381
583.4000000000076,63.77028762734617,-0.19017795185726516,-3.1582501564521
584.5000000000076,63.87971301690845,-0.19039861012888207,-3.1595593042989853
585.6000000000076,63.98808491360053,-0.19264826416436842,-3.160879819112367
586.7000000000077,64.09932751679624,-0.19258503949440092,-3.161807523548613
587.8000000000077,64.20861952833995,-0.1938514159658203,-3.1621636803720996
588.9000000000076,64.31899816756018,-0.19536144776264722,-3.1621486084038755
590.0000000000076,64.42785623210837,-0.19402775163019548,-3.1635135490547235
591.1000000000076,64.53825812709783,-0.19648506390041973,-3.164793336520871
592.2000000000077,64.64750389783808,-0.1945229122075201,-3.165159734026117
593.3000000000077,64.75708987490817,-0.1965255771647377,-3.1651595827744075
594.4000000000077,64.8667181778092,-0.1958922571677565,-3.1664718490501587
595.5000000000077,64.97759947729273,-0.1953663983840366,-3.1677900712777163
596.6000000000078,65.08705563577668,-0.1959824994792044,-3.1676616601327985
597.7000000000078,65.19686441791147,-0.19576867078149485,-3.168625992075949
598.8000000000078,65.30619560835714,-0.195596071186236,-3.168779984117723
599.9000000000078,65.41507013351641,-0.19473186355642266,-3.1686664931071986
601.0000000000078,65.52566747188133,-0.1967302962065928,-3.1691100050931933
602.1000000000079,65.63522113578117,-0.1969149526879813,-3.170015584575806
603.2000000000079,65.74468266995503,-0.19577027538985778,-3.171402364351113
604.3000000000079,65.85513420582488,-0.1971431556735026,-3.1720706657393407
605.4000000000078,65.96499221225123,-0.19712051477233053,-3.1733899804814003
606.5000000000078,66.07422046575242,-0.19599510445236445,-3.174678565928315
607.6000000000079,66.18452565270124,-0.19663240978029337,-3.1758297261852277
608.7000000000079,66.29496586685518,-0.1986454394994326,-3.1763496776295885
609.8000000000079,66.40378836109217,-0.19887793606708293,-3.1763598198195675
610.9000000000079,66.51287236941023,-0.19830849240753043,-3.175354410283532
612.000000000008,66.62415348242611,-0.19906066928469,-3.1753839087519036
613.100000000008,66.73370874937368,-0.19933518902335226,-3.1769868836080253
614.200000000008,66.84159157594284,-0.19998734099508225,-3.1793372024027486
615.300000000008,66.95139761014941,-0.19986142972398707,-3.1789850478235864
616.400000000008,67.06265800551127,-0.20041909024758717,-3.1799800134363347
617.5000000000081,67.17328838828551,-0.20104673389427657,-3.1799798739935072
618.6000000000081,67.28181845487373,-0.20019462544185268,-3.1799978012408388
619.7000000000081,67.38990669608347,-0.20036283254546244,-3.180970170427984
620.8000000000081,67.50247401252388,-0.20005519482375128,-3.181613749250128
621.9000000000082,67.61190144669247,-0.19885696077125828,-3.1829433161329432
623.0000000000082,67.72123146843111,-0.2019219176875878,-3.182939835040577
624.1000000000081,67.83115062645359,-0.20295793948297494,-3.182282707274266
625.2000000000081,67.94065350414795,-0.20245281548274704,-3.183600310923524
626.3000000000081,68.05216047793913,-0.2023930761296816,-3.1836004774088518
627.4000000000082,68.16125946255282,-0.20519858721852371,-3.184577691462606
628.5000000000082,68.2708069486053,-0.204349831666118,-3.1829317859175665
629.6000000000082,68.38079807612952,-0.20675098373254513,-3.1842628083615248
630.7000000000082,68.4908348348862,-0.20569267707931133,-3.1865624919822815
631.8000000000083,68.60030661735686,-0.20567502122297135,-3.1852499604610927
632.9000000000083,68.70990249592495,-0.20621572084684525,-3.1865705078834257
634.0000000000083,68.82019561485201,-0.2079994766016265,-3.1868995314122355
635.1000000000083,68.92703525694384,-0.20875001132670767,-3.188544646019969
636.2000000000083,69.03914599070794,-0.20985170491297284,-3.1878220673454107
637.3000000000084,69.14899721684377,-0.20842481620073228,-3.19018095901066
638.4000000000084,69.25938436017331,-0.20897287978449866,-3.191495384592608
639.5000000000084,69.36583906547904,-0.21111555390938594,-3.191579941516787
640.6000000000083,69.47876082888499,-0.21179947117162978,-3.194141930904744
641.7000000000083,69.58814833738343,-0.21073322904379005,-3.1942245293965392
642.8000000000084,69.69869626157242,-0.2124345692063554,-3.194140040417195
643.9000000000084,69.80890403670026,-0.21401850649558204,-3.192202267089145
645.0000000000084,69.91887279893082,-0.2138945529880215,-3.1934930739936442
646.1000000000084,70.02911260144482,-0.2155726104204279,-3.195137668634649
647.2000000000085,70.14009292194878,-0.2184838384129312,-3.1938104036473405
648.3000000000085,70.2493609608295,-0.21875864675429071,-3.195129799935779
649.4000000000085,70.35989904181682,-0.21886258594816102,-3.196128819561395
650.5000000000085,70.470817569181,-0.22000736951907796,-3.1958460573406233
651.6000000000085,70.58000212654191,-0.2225799472441297,-3.197429979491957
652.7000000000086,70.69052513338357,-0.22137155675228598,-3.1974262851295636
653.8000000000086,70.79980934671057,-0.22221257680962106,-3.1987501797919897
654.9000000000086,70.91082888519091,-0.22492268444978633,-3.1987501801149185
656.0000000000086,71.02087632608341,-0.22422448025525393,-3.2000591790543558
657.1000000000087,71.13151081181803,-0.22777432296407046,-3.201388575131856
658.2000000000087,71.24216372610546,-0.22586031988979538,-3.2024504486763847
659.3000000000086,71.35052868065068,-0.22642997335418477,-3.2021050927489583
660.4000000000086,71.46321652337262,-0.22787228937199938,-3.2027003101896327
661.5000000000086,71.57280938931666,-0.2290466673816619,-3.204018857222865
662.6000000000087,71.68268844871633,-0.2275900013512756,-3.203992152792997
663.7000000000087,71.79340410095756,-0.22730222490782317,-3.2026985875616796
664.8000000000087,71.90335361206262,-0.22871170936298613,-3.2027288347254284
665.9000000000087,72.01333343765657,-0.22851551175649612,-3.202709965991177
667.0000000000088,72.12495763267961,-0.228123886487082,-3.202709775015737
668.1000000000088,72.23459594368163,-0.2273469192591718,-3.203879290698084
669.2000000000088,72.3462062751681,-0.2311844180761081,-3.2047289570520836
670.3000000000088,72.45549073929517,-0.23114572923721505,-3.204126648178671
671.4000000000088,72.56664481821146,-0.23223751631225908,-3.202396773496882
672.5000000000089,72.67639516812504,-0.23381136197239377,-3.2027000014433487
673.6000000000089,72.78638690368332,-0.23377988624772675,-3.205037309579381
674.7000000000089,72.89719990355549,-0.23321023484564857,-3.206660109664818
675.8000000000088,73.00697263953609,-0.23392372070619424,-3.2079716016061535
676.9000000000088,73.11776367736593,-0.23469093125755416,-3.207970113237506
678.0000000000089,73.22682071657208,-0.2348291636951976,-3.2092768134987204
679.1000000000089,73.3382804127604,-0.23528412623559425,-3.2092897458088343
680.2000000000089,73.44804302851887,-0.23572650636382156,-3.20951593306724
681.3000000000089,73.56021335356546,-0.2349560786433343,-3.2092901320012976
682.400000000009,73.66960338940555,-0.2321611816610683,-3.2093684523250148
683.500000000009,73.77926358691468,-0.23516644537007952,-3.210609150519044
684.600000000009,73.89010433327694,-0.23608768505306138,-3.2105999498871824
685.700000000009,74.00021237604152,-0.23514526845047665,-3.2119197934710573
686.800000000009,74.109714922085,-0.23603802497444656,-3.2119198875363435
687.9000000000091,74.21909592703875,-0.23567517758169662,-3.2106182752847072
689.0000000000091,74.32888586369327,-0.23687811883326726,-3.211781303850768
690.1000000000091,74.4393433634668,-0.23609377720101796,-3.2102979928914714
691.2000000000091,74.5480308983689,-0.23305778902439991,-3.211260123088514
692.3000000000092,74.65785199701988,-0.2345633307049667,-3.212571290648345
693.4000000000092,74.76808557359954,-0.23370450470916948,-3.2138610309444204
694.5000000000091,74.87839800686896,-0.23529541690588673,-3.212572408950619
695.6000000000091,74.9880611003297,-0.2349535516250015,-3.212531441083268
696.7000000000091,75.09826020142108,-0.23531884218658633,-3.2143808389256563
697.8000000000092,75.20946132055418,-0.24016684628535884,-3.2165128060978185
698.9000000000092,75.31716420531637,-0.23925400200606867,-3.216553044281996
700.0000000000092,75.4292529674382,-0.24054656587823794,-3.215219925866387
701.1000000000092,75.5399028596598,-0.24089900278069182,-3.216540358025407
702.2000000000093,75.64989456716697,-0.24213980225568632,-3.2178597867147696
703.3000000000093,75.76048506627157,-0.24203182465938092,-3.217229218066252
704.4000000000093,75.87123034372429,-0.24231324045743624,-3.216539814086447
705.5000000000093,75.98123218735667,-0.24279409025805088,-3.21653977496571
706.6000000000093,76.09237208105546,-0.2426753323789283,-3.216530395246736
707.7000000000094,76.20158430614927,-0.2436195529842792,-3.2165301021775403
708.8000000000094,76.31302609997444,-0.24320943921682064,-3.217518262368031
709.9000000000094,76.42249421871267,-0.24340809263799199,-3.216525604504134
711.0000000000093,76.53446170817753,-0.2455856239275575,-3.218182145951095
712.1000000000093,76.64536819865548,-0.24709341359913894,-3.2191706130537825
713.2000000000094,76.75614943368733,-0.24691683003470516,-3.219127322737778
714.3000000000094,76.86623429324253,-0.2485569874091899,-3.2191700790727813
715.4000000000094,76.97766959819705,-0.2479100389791001,-3.21936249737693
716.5000000000094,77.08785070778276,-0.2477316879816898,-3.219357594813587
717.6000000000095,77.19755064759855,-0.2507935712666979,-3.220122504357076
718.7000000000095,77.30825657482048,-0.2501120668340664,-3.21944052337253
719.8000000000095,77.4192450930058,-0.2542540533371576,-3.220304565442473
720.9000000000095,77.5294905801136,-0.2535847673242219,-3.220490112074395
722.0000000000095,77.6412546028535,-0.25487950571491513,-3.2204898927705727
723.1000000000096,77.75174214824105,-0.2574184039770555,-3.2231343370291548
724.2000000000096,77.85974765385521,-0.2600926820331106,-3.221810004327315
725.3000000000096,77.97320363227652,-0.2607387527226333,-3.2231200647693186
726.4000000000096,78.08385817028828,-0.2620209298968637,-3.221466539659316
727.5000000000097,78.19436517262133,-0.26340538700949595,-3.220397844462233
728.6000000000097,78.30502908649882,-0.26443740750438,-3.222483564377351
729.7000000000096,78.4158109248048,-0.2656034489575438,-3.2236250915143487
730.8000000000096,78.52435410682145,-0.2689425620309502,-3.2244396600128327
731.9000000000096,78.63796015382027,-0.2697582050111981,-3.2244557493717565
733.0000000000097,78.74865356889417,-0.26834034105074966,-3.2244490948159408
734.1000000000097,78.85753170962828,-0.2674789736826233,-3.2244498600000666
735.2000000000097,78.97062349540651,-0.26565645150751177,-3.2244504965578384
736.3000000000097,79.08096676079656,-0.26750480538352855,-3.2261591485204315
737.4000000000098,79.19097994881369,-0.27019563687056464,-3.225760018011874
738.5000000000098,79.3020388118355,-0.27282006279398857,-3.224441666682213
739.6000000000098,79.4124899987451,-0.27163794045361545,-3.225749954528087
740.7000000000098,79.52414425824973,-0.27272772723550726,-3.2272690457002304
741.8000000000098,79.63518337223701,-0.27496473637969526,-3.2284847353375627
742.9000000000099,79.74498780109644,-0.2790798927984198,-3.2257438685422506
744.0000000000099,79.8555943208849,-0.2804964468161136,-3.2270798392199045
745.0000000000099,79.95604675049073,-0.27997934833413946,-3.2281099061801295