File: 01_Data/Plastic_Laminate_Countertop_Particle_Board/STA/N2/10K_min/Plastic_Laminate_Countertop_Particle_Board_STA_N2_10KData_221004_R3.csv
##Temp./Â°C,Time/min,DSC/(mW/mg),Mass loss/mg
51.0,10.657513256794646,-1.6680797296629375,-0.03802459571309802
52.100000000000016,11.065100866763373,-1.5424294254473858,-0.04083253305724721
53.20000000000003,11.349676131987884,-1.4426303167116556,-0.03891496250502735
54.30000000000005,11.562213866796025,-1.378294948347883,-0.039660211250562405
55.40000000000006,11.74880534753452,-1.3288499886806666,-0.03938403789136613
56.50000000000008,11.920000000000021,-1.2874899999999991,-0.03995852808622358
57.600000000000094,12.08652781020911,-1.2516367612324837,-0.04031402563982578
58.70000000000011,12.243091643970377,-1.2219443713641571,-0.040000857282809665
59.800000000000125,12.394395286801975,-1.1958314155548748,-0.04109495105882033
60.90000000000014,12.539592210082532,-1.1743572172548224,-0.04132801889310311
62.000000000000156,12.682144362977319,-1.155009577432689,-0.04063285789372584
63.10000000000017,12.819915767318514,-1.1347852844651327,-0.04275655331234507
64.20000000000019,12.963450060198818,-1.1167832002675797,-0.040807326038990954
65.30000000000021,13.096595501146613,-1.1006301741269864,-0.042104510843567144
66.40000000000022,13.23035100705425,-1.0838784973091355,-0.04305546328723686
67.50000000000023,13.361867086801057,-1.0678189804423883,-0.04356795370594835
68.60000000000025,13.491807652584594,-1.0520574750241507,-0.044792226078703035
69.70000000000027,13.62011367405198,-1.0386044366190366,-0.046228066936837564
70.80000000000028,13.747117730984819,-1.0247149987998752,-0.0462293725626326
71.90000000000029,13.873731200758407,-1.0095546580616284,-0.04736974801447902
73.00000000000031,13.998009601461401,-0.9971720941061696,-0.04739428969545534
74.10000000000034,14.12057407962026,-0.9845393416923806,-0.04906256784458485
75.20000000000034,14.241743624052187,-0.9737262568698125,-0.05024877822571838
76.30000000000035,14.363023502883593,-0.9608807701044972,-0.05049110420475644
77.40000000000038,14.487655212284936,-0.9488013884243821,-0.04962167229144576
78.5000000000004,14.606990456015026,-0.9378482103653799,-0.049058811651510936
79.6000000000004,14.727360219478962,-0.9265814543585369,-0.051680921060250906
80.70000000000041,14.845321735687152,-0.9170230658720222,-0.05174475656158517
81.80000000000044,14.9637008310347,-0.9067941219248514,-0.05434850251731316
82.90000000000046,15.081728864675462,-0.898144212509564,-0.053020009946911806
84.00000000000047,15.194255402093159,-0.8896476069906815,-0.053023917203977255
85.10000000000048,15.31371278023937,-0.8788133271917995,-0.05311961890557537
86.2000000000005,15.429290292479894,-0.869580631314902,-0.05514088573621745
87.30000000000052,15.543863680224856,-0.8612842849746617,-0.05565582075396858
88.40000000000053,15.658126907419474,-0.8542293801597565,-0.05573008907036048
89.50000000000054,15.77176680617196,-0.8489243968937591,-0.056985787087197703
90.60000000000056,15.88281512127098,-0.8423092141040254,-0.05698974518697453
91.70000000000059,15.996273093572738,-0.8339716109537284,-0.058285935780687304
92.8000000000006,16.10923226449686,-0.8295723334838252,-0.05696833122276601
93.9000000000006,16.218191286262513,-0.8241761692833823,-0.05974972946539481
95.00000000000063,16.332060825361022,-0.8187299291177469,-0.05961008331121764
96.10000000000065,16.442871381798494,-0.8128924807776525,-0.05951375589809249
97.20000000000066,16.554053561909058,-0.8084416546465507,-0.05950238673379804
98.30000000000067,16.664008995151924,-0.8024343943723901,-0.06083353380171408
99.40000000000069,16.77328014548172,-0.7974592033097617,-0.05959176049236614
100.50000000000071,16.883107034288212,-0.7914957473914656,-0.06085274816907704
101.60000000000072,16.992350846767128,-0.7866676300920135,-0.0595099399481569
102.70000000000073,17.102262328733083,-0.7807805459385351,-0.05951018776058792
103.80000000000075,17.209814916425245,-0.7769376524378802,-0.05811325465281625
104.90000000000077,17.316766872984118,-0.7735387221316508,-0.06081834232238714
106.00000000000078,17.42718967566253,-0.7673466121987147,-0.06082841220783708
107.10000000000079,17.535803525039945,-0.7620476672460487,-0.06081063788980101
108.20000000000081,17.64405652673911,-0.7581120015394818,-0.06184996258481945
109.30000000000084,17.751578901988868,-0.7530705418716024,-0.06212444122678429
110.40000000000084,17.86072040237274,-0.7485835089254561,-0.06214007425133028
111.50000000000085,17.967418454990025,-0.7417385772600994,-0.062139653093591374
112.60000000000088,18.075181652483064,-0.737405672465073,-0.06211911445840901
113.7000000000009,18.18272194687205,-0.7328615483295794,-0.06219486130461105
114.8000000000009,18.2907477604702,-0.7287285912497159,-0.06214368830027528
115.90000000000092,18.3986508835736,-0.7236315208656666,-0.062147487685439984
117.00000000000094,18.505845390706885,-0.718306650937977,-0.06346000767438831
118.10000000000096,18.612741792326343,-0.7131680689281694,-0.06476531822596021
119.20000000000097,18.718749587189272,-0.7104008347019649,-0.06474394295013752
120.30000000000098,18.828353678866932,-0.7056117336978419,-0.06345682516380036
121.400000000001,18.93487697439335,-0.7000315471636724,-0.06345662313549338
122.50000000000102,19.0418249998353,-0.6946432950624415,-0.06286085353139947
123.60000000000103,19.148359989729652,-0.6891713580151272,-0.06477025699701011
124.70000000000104,19.25538388914308,-0.684570165074242,-0.0641907935502295
125.80000000000106,19.36263336712172,-0.680636995688292,-0.06208013163911641
126.90000000000109,19.469287390449452,-0.6751967139560197,-0.06214176447761499
128.00000000000108,19.57563067802372,-0.6706514481522406,-0.06415996132795909
129.1000000000011,19.68301412977491,-0.6657677705159913,-0.0648129165719733
130.20000000000113,19.789356249859207,-0.6597392394853265,-0.06510060058020128
131.30000000000115,19.89518706249871,-0.6549300268354078,-0.0662347860706296
132.40000000000117,20.00072953012622,-0.6503886959808455,-0.06474080118626135
133.50000000000117,20.10741126690339,-0.6448119321446395,-0.06608977892779144
134.6000000000012,20.21371195127363,-0.6380986118588642,-0.06575991522953828
135.7000000000012,20.31915426262838,-0.6334687867013254,-0.06477506983701797
136.8000000000012,20.424896358376806,-0.628583614414834,-0.06708339978720268
137.90000000000123,20.530745051054122,-0.62378101740952,-0.0670690822231883
139.00000000000125,20.636898378136404,-0.6196157638216886,-0.06639226523325403
140.10000000000127,20.742211077542844,-0.6148362122865336,-0.06673689882909928
141.2000000000013,20.846649567114998,-0.6093968660047384,-0.06608969775647067
142.3000000000013,20.953077524603934,-0.6041685778785278,-0.06477025934612968
143.4000000000013,21.058769355101596,-0.5993164849912765,-0.06579315257979879
144.50000000000134,21.163079486438043,-0.5950697779701534,-0.06576005229511317
145.60000000000133,21.26660150709283,-0.5899008986065539,-0.06575987992692989
146.70000000000135,21.37300897298981,-0.5833023914957826,-0.06576013315426854
147.80000000000138,21.47841378108809,-0.5765650003587333,-0.0683907569821609
148.9000000000014,21.583636349565616,-0.5744702050485511,-0.06839004499983092
150.00000000000142,21.68880400072465,-0.5689189406760028,-0.068389983768252
151.10000000000142,21.792778093377294,-0.5634530106666095,-0.06707028688392525
152.20000000000144,21.89880006365785,-0.5588236664050522,-0.0670810361094496
153.30000000000146,22.00236579576497,-0.5542470774606976,-0.06707942706194103
154.40000000000146,22.10686094500692,-0.5489559136393619,-0.06669501483820461
155.50000000000148,22.212834765267253,-0.5444379679861951,-0.06840365373312718
156.6000000000015,22.317265757665844,-0.5383505922345221,-0.06840004575662828
157.70000000000152,22.42226765561861,-0.5329925238627995,-0.06974219072963095
158.80000000000155,22.527205817300324,-0.5286771153657532,-0.07103017752805663
159.90000000000154,22.632514535613254,-0.5235172108418006,-0.07102698612137459
161.00000000000156,22.736814937066047,-0.5169055912495156,-0.07102995512073917
162.1000000000016,22.837518546881938,-0.5094797841597163,-0.07107647874250533
163.20000000000158,22.9460585273315,-0.505837993234598,-0.0707011944652578
164.3000000000016,23.051818284680795,-0.49901906766850174,-0.07101926309555573
165.40000000000163,23.155774647202236,-0.49372331277596276,-0.07233993624930513
166.50000000000165,23.260385830815522,-0.4873719678449828,-0.07233986251196933
167.60000000000167,23.363134533202718,-0.4807529651394255,-0.07365986080074194
168.70000000000167,23.470662078493916,-0.4763211434935239,-0.07365986501301602
169.8000000000017,23.57483587684147,-0.4692291436432817,-0.07365986499999977
170.9000000000017,23.67919239972986,-0.46376057482894767,-0.07497886909321894
172.0000000000017,23.783911108755227,-0.4565753391264984,-0.0749709815412456
173.10000000000173,23.888124337150554,-0.45040380128060575,-0.07362613193035328
174.20000000000175,23.993887876150772,-0.44314011742137543,-0.07497663841536006
175.30000000000177,24.099581124676533,-0.4388725479766509,-0.07628962478553225
176.4000000000018,24.203601448609668,-0.4313841554754725,-0.07562979987286456
177.5000000000018,24.30856073381865,-0.42429245474539146,-0.07563758584000801
178.6000000000018,24.41210325366398,-0.417380241000238,-0.07826988486054054
179.70000000000184,24.518916278128742,-0.4096680760078736,-0.07958848126374285
180.80000000000183,24.622505728254733,-0.40398364590390584,-0.07958990988233072
181.90000000000185,24.72747840685507,-0.3958150824118494,-0.07960739932980321
183.00000000000188,24.83141816431778,-0.3901467557501655,-0.07925982286187105
184.1000000000019,24.936792104828918,-0.38246834554434095,-0.07926500724691543
185.20000000000192,25.04074510867453,-0.37502250533523296,-0.08227431389389483
186.30000000000192,25.144914327464665,-0.36797009658497243,-0.08364792889108053
187.40000000000194,25.249495174846658,-0.36001129130013704,-0.08486000206697186
188.50000000000196,25.353597862370346,-0.3549734936112335,-0.08486000379437364
189.60000000000196,25.458194976018277,-0.3467907411178739,-0.08619805835145655
190.70000000000198,25.563093679493033,-0.3408412423039248,-0.08617236773573422
191.800000000002,25.66716990628295,-0.3337675942437141,-0.08749237930924858
192.90000000000202,25.77173361793178,-0.3274043042032932,-0.08877043765060799
194.00000000000205,25.875557643958587,-0.32054271843633214,-0.08980022379858532
195.10000000000204,25.97841076728578,-0.3155156529351123,-0.0914492543918417
196.20000000000206,26.08452576731066,-0.30901943593781234,-0.09204928616426189
197.3000000000021,26.188779608141807,-0.30178364477411457,-0.09274248145659714
198.40000000000208,26.293261823991262,-0.29677940689668525,-0.0950662427753457
199.5000000000021,26.398025046788685,-0.29186657132385724,-0.09540014021911425
200.60000000000213,26.501969419069365,-0.2851396727761635,-0.09682963896627239
201.70000000000215,26.606342853784973,-0.2813485468908672,-0.10069097462391063
202.80000000000217,26.70828894330588,-0.2756650405692535,-0.10066926859527126
203.90000000000217,26.813443562609223,-0.27245478710527526,-0.10067037594511596
205.0000000000022,26.91681008043896,-0.2662468689978851,-0.1033330050749246
206.1000000000022,27.01936851645483,-0.2633198138947032,-0.10594280038375414
207.2000000000022,27.1271301364345,-0.25938757369434834,-0.10725863269023472
208.30000000000223,27.23152490726204,-0.25587546282497325,-0.10857334982080102
209.40000000000225,27.335640870134437,-0.2538769149424459,-0.1111783658449772
210.50000000000227,27.44026777421895,-0.24988492632743262,-0.11220408781725189
211.6000000000023,27.544926145349063,-0.24644151505866868,-0.11351051054799344
212.7000000000023,27.64990857259938,-0.24366053262010287,-0.113840248563577
213.8000000000023,27.753873804036598,-0.23956622447319287,-0.11659649690922347
214.90000000000234,27.85784896916845,-0.2364305661646627,-0.11790307221576102
216.00000000000233,27.962421897078332,-0.23229919927132406,-0.11922008243264903
217.10000000000235,28.06712091739704,-0.2274792772519644,-0.12179959198938217
218.20000000000238,28.17126961753479,-0.2239264966203602,-0.12329009628741883
219.3000000000024,28.275673523679384,-0.2185251381227446,-0.12459339224359312
220.40000000000242,28.38059800070398,-0.21547782246851363,-0.1269588495135876
221.50000000000242,28.485043142917895,-0.2115351823863459,-0.12994460071141845
222.60000000000244,28.58891992905687,-0.20738231483407052,-0.12988016948508685
223.70000000000246,28.69361067182354,-0.2033079196727338,-0.13244720519220676
224.80000000000246,28.797868089424068,-0.1986640999875802,-0.13514682207728956
225.90000000000248,28.901878943466972,-0.19567220771039628,-0.13907727733545272
227.0000000000025,29.00696120115218,-0.1909111645243242,-0.14109405001923214
228.10000000000252,29.111781834487342,-0.18746760381750552,-0.1436835883266152
229.20000000000255,29.216387536242653,-0.18671491775773374,-0.14616426877579247
230.30000000000254,29.32072230072339,-0.18274216258655476,-0.14961019355024696
231.40000000000256,29.423674194206097,-0.17906122129467947,-0.15106039085665568
232.5000000000026,29.529611363030877,-0.17823021314044446,-0.15540665575170332
233.60000000000258,29.63503944901526,-0.175875777492527,-0.1578794221822335
234.7000000000026,29.74000000000025,-0.1750399999999951,-0.1590801400000008
235.80000000000263,29.84247818509684,-0.1718013402944689,-0.16231860864868608
236.90000000000265,29.94963672475664,-0.17071061989830588,-0.16588292012083894
238.00000000000267,30.054713342266474,-0.16864328972985182,-0.16852640491977722
239.10000000000267,30.158840741854195,-0.16670409253337526,-0.17257878667130644
240.2000000000027,30.263091159643757,-0.1647672045273348,-0.17645742032821898
241.3000000000027,30.36637476451172,-0.16392637744472877,-0.18066825406708897
242.4000000000027,30.472345509104276,-0.16164745168728958,-0.1861477484827141
243.50000000000273,30.57817042747896,-0.16145878364093774,-0.18884330014704176
244.60000000000275,30.68207146642861,-0.15766525985416674,-0.19299864975258618
245.70000000000277,30.78704325870784,-0.15538229400694573,-0.19626935900479214
246.8000000000028,30.892765190876062,-0.15418579999092516,-0.19992751440379086
247.9000000000028,30.996547094698386,-0.15294966662319523,-0.2043686738631596
249.0000000000028,31.101689738432828,-0.1510567394543607,-0.21009777768102733
250.10000000000284,31.20585221539986,-0.14850665836541802,-0.21548375859650282
251.20000000000283,31.309090185981894,-0.14713840954421514,-0.22194698465701368
252.30000000000285,31.41556298013164,-0.14334194789137608,-0.22646926930142763
253.40000000000288,31.52125932433422,-0.14059557069740491,-0.231558889272645
254.5000000000029,31.626271101519436,-0.1409361337390967,-0.23669969728672813
255.60000000000292,31.73035063964317,-0.1388357112379771,-0.24095929997386412
256.7000000000029,31.83307818351669,-0.13558924571501105,-0.24683537972665714
257.8000000000029,31.939618914945548,-0.13446434512984098,-0.2556322182980346
258.90000000000293,32.04379301567722,-0.13219358500171022,-0.25972646147523504
260.00000000000296,32.14864598110762,-0.1301790889831718,-0.2657879189960801
261.100000000003,32.254449073490306,-0.12931414469887362,-0.2733549330889824
262.200000000003,32.35844580578734,-0.12818880278555797,-0.28038894353785304
263.300000000003,32.463229136146396,-0.12602427492764745,-0.28537464627643017
264.40000000000305,32.567787192634725,-0.12504727404274463,-0.29338762125969575
265.50000000000307,32.67263022036201,-0.1239109525705097,-0.30103145912133256
266.6000000000031,32.7769703561246,-0.12292415131836247,-0.3077824050432456
267.7000000000031,32.88248185332878,-0.12208597794031953,-0.31486647056279704
268.8000000000031,32.98385610821189,-0.12391377196316868,-0.32332925311078053
269.9000000000031,33.092424919761584,-0.12267018047302741,-0.33330000612171906
271.0000000000031,33.197258435099755,-0.12244196713357414,-0.34419852739743373
272.10000000000315,33.30122642928931,-0.12574279678502198,-0.3524628519585806
273.2000000000032,33.40392189842867,-0.12565348665852233,-0.36228020372968883
274.30000000000314,33.51131252141574,-0.1263375102670587,-0.37343295479325933
275.40000000000316,33.61646460094245,-0.12736950248354378,-0.38449568509369936
276.5000000000032,33.72131661986503,-0.1288738469608817,-0.3941418404834196
277.6000000000032,33.82659038901519,-0.130739812718183,-0.4041590089669542
278.70000000000323,33.93093869419925,-0.13554589962446312,-0.41545892925602423
279.80000000000325,34.036044392576436,-0.13899703638973337,-0.42829825255706133
280.9000000000033,34.14097652189457,-0.14253768018782645,-0.4410300258607416
282.0000000000033,34.24629707744509,-0.147830801789922,-0.452633497633534
283.1000000000033,34.35031058481857,-0.15110937660537846,-0.46749907497276855
284.20000000000334,34.45630712083979,-0.15513292832413872,-0.4796254729292415
285.30000000000337,34.561419955945034,-0.15744110753390098,-0.49303719896235876
286.40000000000333,34.666877942998056,-0.16190939386119532,-0.5063393165942491
287.50000000000335,34.771898060144686,-0.16625910712919884,-0.5194776276507391
288.6000000000034,34.87691491954958,-0.16846066768573179,-0.5329848997978024
289.7000000000034,34.982336469377124,-0.1715410403356007,-0.5465440394622392
290.8000000000034,35.08778184157286,-0.17582870752697277,-0.5598989907646663
291.9000000000034,35.192320780369535,-0.17807894788389872,-0.5779917749200489
293.0000000000034,35.297928856560624,-0.1811524599285748,-0.5925862025786359
294.10000000000343,35.40223138533865,-0.18341052536354532,-0.6086668839210292
295.20000000000346,35.50734836067747,-0.18761119112426072,-0.623815610052822
296.3000000000035,35.61191922118883,-0.18975250845306194,-0.641535581802545
297.4000000000035,35.717490932372066,-0.19281998715926396,-0.6575402332122047
298.5000000000035,35.82468611641195,-0.1947595878341114,-0.6743024494523571
299.60000000000355,35.930821111528,-0.1955240674013913,-0.6916580524214955
300.70000000000357,36.03593221490859,-0.19794667106848918,-0.7088722873251809
301.8000000000036,36.140717609444856,-0.19829827588302718,-0.7260359791694069
302.9000000000036,36.246948371746676,-0.19742835720938584,-0.7432545964705066
304.0000000000036,36.351947678335,-0.1970664002563406,-0.7621561473175844
305.1000000000036,36.45742158978109,-0.19791036351405727,-0.7795574161279251
306.2000000000036,36.562277049884585,-0.19786590424260717,-0.8005273119386449
307.30000000000365,36.668595479708756,-0.19684030543696296,-0.8209689861769549
308.4000000000037,36.773884895251264,-0.1960111218802038,-0.8380478613602604
309.5000000000037,36.880364677170114,-0.19529143879007024,-0.8585374389837619
310.60000000000366,36.986060561580445,-0.19322393406600058,-0.8802518580705092
311.7000000000037,37.09109465309314,-0.19106067514652067,-0.9012309129021996
312.8000000000037,37.19715329624333,-0.18918289875841243,-0.9222188212619273
313.90000000000373,37.302615891904985,-0.18756487382990825,-0.9441770149383055
315.00000000000375,37.408422605962365,-0.1847708567977223,-0.9667443930571489
316.1000000000038,37.513480381669986,-0.1803951838173938,-0.98899666752272
317.2000000000038,37.619999004362484,-0.1767800745934125,-1.010769788443488
318.3000000000038,37.72646587377935,-0.17243710931453168,-1.033201705026432
319.40000000000384,37.83237400064816,-0.16887467735269193,-1.058238615452435
320.5000000000038,37.9385878324655,-0.16433179880721227,-1.0804030733728927
321.60000000000383,38.044804480792195,-0.15977042848099532,-1.1055087439215403
322.70000000000385,38.15059238070279,-0.1549946381961559,-1.1284944279433073
323.8000000000039,38.256463903139284,-0.15138355319079844,-1.1519311210516991
324.9000000000039,38.36162181681555,-0.14703722295691515,-1.177971665169097
326.0000000000039,38.46694734520868,-0.13961441890328932,-1.2021330883583627
327.10000000000394,38.575308764094984,-0.13532300691742827,-1.2290311482870293
328.2000000000039,38.680704917519215,-0.12911026566240347,-1.2549025498626474
329.30000000000393,38.78734692701443,-0.12410824389654304,-1.281674248590765
330.40000000000396,38.89308291495105,-0.11809630770001055,-1.3078589462942292
331.500000000004,38.999816631381584,-0.11129318865673368,-1.3363302641825334
332.600000000004,39.10508065855791,-0.1066066458502822,-1.3634878661813663
333.700000000004,39.209998787523205,-0.09914727185201747,-1.3927094832441629
334.80000000000405,39.318559426028685,-0.09282616813871913,-1.421209242997683
335.90000000000407,39.42535716059103,-0.0852315945421113,-1.452308725639674
337.0000000000041,39.53030990925746,-0.07877541121544598,-1.4794137180018732
338.10000000000406,39.637467391228164,-0.07111928895749949,-1.509817117114964
339.2000000000041,39.74351337048143,-0.06450961099706762,-1.5432466264193008
340.3000000000041,39.851263097678256,-0.05777563290745759,-1.5769319248486626
341.4000000000041,39.9573621408607,-0.049588724559141,-1.6082506846050517
342.50000000000415,40.06370838211912,-0.041487889305257465,-1.639323456914561
343.6000000000042,40.169614334927445,-0.034496817391253064,-1.6720864809390212
344.7000000000042,40.27692006520625,-0.02734740764403107,-1.70533860384992
345.80000000000416,40.384461768723156,-0.019018722673484624,-1.7410843372133749
346.9000000000042,40.49019703279099,-0.014321123739641851,-1.776138644767387
348.0000000000042,40.59657072086371,-0.008000758059323347,-1.8119854707046725
349.10000000000423,40.703019412866524,-0.0006903709515764691,-1.8462665557086315
350.20000000000425,40.810817033774654,0.007161054019452896,-1.8852335992407854
351.3000000000043,40.91725965194454,0.011765499751035222,-1.920201602854375
352.4000000000043,41.02295129927125,0.017972927943557506,-1.9579664456311554
353.5000000000043,41.13009601356151,0.02126975289686514,-1.9965203916068759
354.60000000000434,41.23656801218204,0.025872688990451812,-2.0351489914597565
355.7000000000043,41.343523089653125,0.027337948724970786,-2.073180767492601
356.80000000000433,41.449485308562885,0.02801310311053145,-2.1133450259529054
357.90000000000435,41.556596437653596,0.027297842904485524,-2.151033526104425
359.0000000000044,41.66409558762447,0.02445624422814896,-2.1903393707668615
360.1000000000044,41.76939144046118,0.020368247561727712,-2.2321881235167647
361.2000000000044,41.87715606220019,0.01402266254210048,-2.269658915606433
362.30000000000445,41.98359706596715,0.004920603286461441,-2.307674746432318
363.4000000000044,42.088094814576216,-0.007822073316272833,-2.345850025767297
364.50000000000443,42.19598432837659,-0.02213283760158193,-2.381293775279425
365.60000000000446,42.30265126990117,-0.04047257442317337,-2.4176715680261305
366.7000000000045,42.41009765496228,-0.059554980764831955,-2.4517031938723433
367.8000000000045,42.51667877549222,-0.08395330145179265,-2.4821327387940393
368.9000000000045,42.6230134694555,-0.11135412295179997,-2.512608815930185
370.00000000000455,42.72958795511947,-0.13792900944369274,-2.541549966390787
371.10000000000457,42.83538844569705,-0.1672943042810885,-2.5675270102044614
372.2000000000046,42.94293761582598,-0.1977306499680918,-2.591182957620285
373.30000000000456,43.04950473156679,-0.2285902651515408,-2.610868207971622
374.4000000000046,43.15605638322139,-0.25748124376313847,-2.6290474891126885
375.5000000000046,43.26160247295876,-0.28569035649083496,-2.6447602300180266
376.6000000000046,43.36920157733199,-0.3113703033075403,-2.656449655294866
377.70000000000465,43.476147364915235,-0.3308579094546696,-2.6683655546866785
378.8000000000047,43.58293597737193,-0.3489108301781966,-2.6766669711875655
379.9000000000047,43.68965111951304,-0.36439826864296604,-2.6854784657758
381.00000000000466,43.79537010339789,-0.37514628278102075,-2.6928473318903405
382.1000000000047,43.90309743964225,-0.3843094759960364,-2.698568784540787
383.2000000000047,44.010495313278575,-0.3920381754154562,-2.7039983140564408
384.30000000000473,44.116697114597486,-0.3961509444003548,-2.7080175402997195
385.40000000000475,44.224645057593314,-0.3989650296258293,-2.711188322309961
386.5000000000048,44.331883041903936,-0.40161816731218064,-2.7167506668067043
387.6000000000048,44.43961583617666,-0.40384830475854183,-2.723101122992709
388.7000000000048,44.546725051681435,-0.40630509322251745,-2.7265013878193374
389.80000000000484,44.654087793698835,-0.40777087651325167,-2.729101840006331
390.9000000000048,44.759197603393126,-0.4081625135409477,-2.7325321203928725
392.00000000000483,44.86822206512682,-0.40990677694826244,-2.734718617580156
393.10000000000485,44.975650293124964,-0.41191794676963256,-2.740505391860484
394.2000000000049,45.082389240686034,-0.4106501070289289,-2.744908335840686
395.3000000000049,45.18607145209678,-0.4122151083962897,-2.7473341087035843
396.4000000000049,45.296121567131124,-0.41394699878439883,-2.7499857854888012
397.50000000000495,45.40389188179508,-0.4154743033434486,-2.7541925664792783
398.6000000000049,45.51066600971045,-0.41706171007892906,-2.7583478125084797
399.70000000000493,45.618202636487766,-0.4179064172748067,-2.76189186691363
400.80000000000496,45.72585998388107,-0.4180086494239317,-2.765739149767053
401.900000000005,45.83317278883676,-0.4172143348993652,-2.769180452086646
403.000000000005,45.939446317903595,-0.4189636904549454,-2.770497632090101
404.100000000005,46.04598090042046,-0.41916163111894295,-2.7730589957058833
405.20000000000505,46.155318027147395,-0.4196687618883273,-2.778382289677005
406.30000000000507,46.26234506252971,-0.4192809399976572,-2.782571672595255
407.4000000000051,46.37120460377712,-0.42065016917361897,-2.784631753515651
408.50000000000506,46.47805662477617,-0.41879100299844463,-2.787382947670972
409.6000000000051,46.58520041659651,-0.419828917947318,-2.79068272429454
410.7000000000051,46.69180749894431,-0.4194580410267283,-2.794136402240211
411.8000000000051,46.80029411848023,-0.4199143759104952,-2.7972619191130974
412.90000000000515,46.90800331291222,-0.4203967042899903,-2.801276926309362
414.0000000000052,47.01483560399318,-0.4185082388814136,-2.8042323467910317
415.1000000000052,47.12211084602972,-0.4195902779499658,-2.8075298280142347
416.20000000000516,47.23055783286077,-0.4197925394149663,-2.81033815882837
417.3000000000052,47.337029014022136,-0.417525829028061,-2.812861482852311
418.4000000000052,47.445444633773945,-0.41569278414731764,-2.8156168565610535
419.50000000000523,47.5506515264785,-0.41521059120799436,-2.8197680126866915
420.60000000000525,47.65920926092494,-0.4142467855855795,-2.8224209449138575
421.7000000000053,47.766208846280705,-0.4131511457214036,-2.825046554458121
422.8000000000053,47.87444690822576,-0.4115618500055388,-2.8276774732217045
423.9000000000053,47.98241297076325,-0.4090600671906185,-2.830315790607119
425.00000000000534,48.08948310925768,-0.407368753598627,-2.8342757416306377
426.1000000000053,48.197246613145474,-0.4048678268896307,-2.8356984309399786
427.20000000000533,48.30557897005825,-0.4030152615167395,-2.8401705871949
428.30000000000535,48.41444453182581,-0.4016988849468653,-2.844111080215087
429.4000000000054,48.518386986942964,-0.39849750149619323,-2.8476478762833723
430.5000000000054,48.629117419037115,-0.3955464376566723,-2.8489955864525305
431.6000000000054,48.73636012802633,-0.39312255091917075,-2.8507378050698122
432.70000000000545,48.84486794170767,-0.39092829310264327,-2.8547323825749538
433.8000000000054,48.95239480270578,-0.38792221078451294,-2.8573590360409487
434.90000000000543,49.06037250540242,-0.38522630988223333,-2.8593009236680667
436.00000000000546,49.168840721706175,-0.383040091269516,-2.860620856266748
437.1000000000055,49.27687689781251,-0.37930608849787845,-2.862445727990565
438.2000000000055,49.38537529999409,-0.3762174512340741,-2.862567737372232
439.3000000000055,49.492104183185525,-0.3710232165468742,-2.8684623154519366
440.40000000000555,49.59930309004865,-0.3683792451292847,-2.872038979483268
441.50000000000557,49.70759359136543,-0.36391056773104435,-2.8746729633500108
442.6000000000056,49.81586441859541,-0.3610692856634154,-2.8774093396622367
443.70000000000556,49.92480846122658,-0.35782770251582796,-2.87920393468658
444.8000000000056,50.03030550200861,-0.35385209140288393,-2.8813796587156717
445.9000000000056,50.138726723128556,-0.3495147939873376,-2.8839173215413583
447.0000000000056,50.2470085648781,-0.3468544925601126,-2.8842587381507094
448.10000000000565,50.35463002206815,-0.34294863601055564,-2.885343434349177
449.2000000000057,50.46337148762826,-0.3404844869106808,-2.888879521066193
450.3000000000057,50.57116460879838,-0.33875727071193185,-2.8920080029289297
451.40000000000566,50.68021685393856,-0.3366216778443048,-2.8946502839222914
452.5000000000057,50.78835197032885,-0.33248730370699225,-2.8959764233371996
453.6000000000057,50.89611217074311,-0.3307033115966413,-2.897366014621058
454.70000000000573,51.00489682355169,-0.32834098786683263,-2.9010900935159505
455.80000000000575,51.11262346323564,-0.3247011926176637,-2.903979124597099
456.9000000000058,51.22051815494087,-0.32137078436713995,-2.9053001779623053
458.0000000000058,51.328823513008444,-0.31880893351260314,-2.9066074625483287
459.1000000000058,51.438346235253654,-0.3163339974433745,-2.909267795420245
460.20000000000584,51.54679545985501,-0.3133618704242144,-2.9120646445887717
461.3000000000058,51.65449423138142,-0.3101057040969545,-2.9133220420992094
462.40000000000583,51.76266791373389,-0.3094023468042138,-2.913520719978177
463.50000000000585,51.86898407245382,-0.30609272759600326,-2.9143327420268115
464.6000000000059,51.98020672831057,-0.3026071409542835,-2.917369884650312
465.7000000000059,52.08707188913276,-0.3007442901617894,-2.918575811966239
466.8000000000059,52.1964514367082,-0.2987845298105374,-2.9196796761767745
467.90000000000595,52.303659682702204,-0.2964990871323269,-2.921198263027468
469.0000000000059,52.41277525672015,-0.29456330993271795,-2.9228295206350547
470.10000000000593,52.52194338435952,-0.2933030702266108,-2.9245577656428132
471.20000000000596,52.63087905923212,-0.28902887386302717,-2.9259931843311513
472.300000000006,52.738978213736445,-0.28942477683610013,-2.926906097665431
473.400000000006,52.84693369986637,-0.2870342693043911,-2.9295594852362585
474.500000000006,52.95569211441925,-0.28477661655293407,-2.9316357995295705
475.60000000000605,53.06443924337975,-0.2834868102125316,-2.932879381945161
476.70000000000607,53.17288929324832,-0.28164287369663665,-2.9348179795348095
477.8000000000061,53.28127257072745,-0.27891532774757066,-2.9348799412976416
478.90000000000606,53.39030716701994,-0.27837529623351054,-2.936165741012138
480.0000000000061,53.49822130162764,-0.27672200632913163,-2.936484927036602
481.1000000000061,53.60562916282496,-0.27379285263317166,-2.9398890097610946
482.2000000000061,53.71516083848768,-0.2732731167788403,-2.9417750422563294
483.30000000000615,53.82342147162277,-0.2711166367579112,-2.94325958030179
484.4000000000062,53.93159681746735,-0.26838796610368715,-2.9443229807950138
485.5000000000062,54.04000000000065,-0.26638999999996316,-2.945699845064565
486.60000000000616,54.14822732150653,-0.26374063013221305,-2.9478264788835005
487.7000000000062,54.255820636603765,-0.2625882017735717,-2.9483531135177814
488.8000000000062,54.365369231170135,-0.258959249067246,-2.949649806598467
489.90000000000623,54.47342395793137,-0.25131112753420703,-2.9496507326245096
491.00000000000625,54.58173046136735,-0.24637650453466825,-2.9522834171828904
492.1000000000063,54.68865398358342,-0.24085574220735176,-2.952279844174473
493.2000000000063,54.798493013662906,-0.23784318516408653,-2.9536128349511634
494.3000000000063,54.907434406029296,-0.2339048028765723,-2.9549205795277285
495.40000000000634,55.01605818572531,-0.2309140676051532,-2.956252031797191
496.5000000000063,55.12541893483599,-0.22792547518433628,-2.957188577661963
497.60000000000633,55.23408024073418,-0.22373317738965223,-2.960177796695766
498.70000000000636,55.34340007211228,-0.21964565764577873,-2.961847185726333
499.8000000000064,55.449913647422306,-0.2158294356499802,-2.963800786542584
500.9000000000064,55.56000114673932,-0.21446988225978672,-2.9624900112460173
502.0000000000064,55.66971333579495,-0.21334341920802016,-2.9638105694631194
503.10000000000645,55.77857716914182,-0.21070248050486678,-2.9634825119225736
504.2000000000064,55.887342229479785,-0.2086938488678434,-2.9637577516133273
505.30000000000643,55.996210350821784,-0.206882475966836,-2.967757361591361
506.40000000000646,56.10520453928389,-0.20592280857038348,-2.969063960160138
507.5000000000065,56.21408596886487,-0.2035074624115109,-2.970393038409175
508.6000000000065,56.32387859067276,-0.2001407087103703,-2.9713552284918725
509.7000000000065,56.43309569874367,-0.1975684741635111,-2.9717196537566326
510.80000000000655,56.54179387400409,-0.1974127032437265,-2.9730188712962966
511.90000000000657,56.65065640202411,-0.19509361350898957,-2.973537611061367
513.0000000000066,56.75971296579963,-0.19371384521744733,-2.9743498099187575
514.1000000000065,56.86904761801519,-0.1930696868785114,-2.9756710728247464
515.2000000000066,56.97739855783701,-0.19173243672963797,-2.9770020463493436
516.3000000000065,57.08679241229404,-0.19012403881252518,-2.978312006537193
517.4000000000067,57.195149999974184,-0.18857353950203623,-2.9793729011123817
518.5000000000066,57.3043563380345,-0.18902631668147407,-2.981916739586098
519.6000000000067,57.41376448898769,-0.1859834505080326,-2.983144988780622
520.7000000000066,57.5225063431641,-0.18536686549761747,-2.980939154721141
521.8000000000067,57.63146420394969,-0.18493971881111873,-2.9823098663544014
522.9000000000067,57.740714775297896,-0.18248804015518952,-2.9848900147509485
524.0000000000067,57.84916566275453,-0.18276413047230472,-2.986213759088031
525.1000000000067,57.959692737444364,-0.1831043366088752,-2.987200175819257
526.2000000000068,58.06574812234416,-0.18203745319646356,-2.9871882961433895
527.3000000000068,58.1769986754108,-0.18234438087306803,-2.9898329320664816
528.4000000000068,58.285089538141,-0.181131275628231,-2.990564106572175
529.5000000000068,58.395528350586936,-0.18079337747661048,-2.990489816721297
530.6000000000068,58.505295033692114,-0.18041419721239932,-2.9918328631058073
531.7000000000069,58.61484714709267,-0.1803528134701199,-2.9928290831059017
532.8000000000068,58.72407792520535,-0.18054392963929367,-2.9931341761442987
533.9000000000069,58.83404410108944,-0.18095491988220627,-2.9965324137509146
535.0000000000068,58.94304712660977,-0.17996290157043782,-2.9950604318401965
536.100000000007,59.04989156276364,-0.18224875455108155,-2.9950999462800745
537.2000000000069,59.16194961553482,-0.18368137757403047,-2.995759967332174
538.300000000007,59.26982862218482,-0.18539689044655577,-2.9970695020203064
539.4000000000069,59.381110496115596,-0.1845615845081471,-2.9983604165869244
540.5000000000069,59.49065870904671,-0.18674518564935585,-2.9997190361556108
541.600000000007,59.59847995705947,-0.1880445032507334,-3.000247043375306
542.700000000007,59.70904993371896,-0.18892065464433164,-2.9997117954867702
543.800000000007,59.81807276643607,-0.18959700576810243,-3.000699854740807
544.900000000007,59.92784241559109,-0.19198615880174694,-3.002022399326216
546.000000000007,60.036827404108124,-0.19384273368687455,-3.0032937510109488
547.1000000000071,60.14649428955978,-0.19326023068574083,-3.00334245595534
548.2000000000071,60.254540901869845,-0.1942498531414087,-3.003339884778055
549.300000000007,60.36343334721813,-0.1942678588700469,-3.0046185335397317
550.4000000000071,60.47286154095518,-0.19451528309105792,-3.0079082345961936
551.500000000007,60.583182356141315,-0.195074278367698,-3.0086101351962684
552.6000000000072,60.692920685460926,-0.19280457356933203,-3.0086113385969746
553.7000000000071,60.80031629045283,-0.19387348393927056,-3.0099296804440874
554.8000000000072,60.91230515952215,-0.19451192190401687,-3.01036460799011
555.9000000000071,61.021171207324194,-0.19191344839728816,-3.0125990170321666
557.0000000000072,61.130935467412606,-0.1924170630385635,-3.014216507307782
558.1000000000072,61.24028971054253,-0.1921608914187876,-3.012348042017713
559.2000000000072,61.34879310047909,-0.19474723114913892,-3.011573687468383
560.3000000000072,61.45894669529093,-0.19210118655869776,-3.012803199717448
561.4000000000073,61.56725513066843,-0.19196125218733553,-3.015519859478941
562.5000000000073,61.67633251725373,-0.1942219135168665,-3.015582177402288
563.6000000000073,61.78645001012177,-0.19416648961989427,-3.0158498351940684
564.7000000000073,61.897055967415014,-0.19390704812159848,-3.0184763378567836
565.8000000000073,62.0061758530853,-0.19344045065079551,-3.021108673794795
566.9000000000074,62.11450188273987,-0.19413203060189674,-3.0224390110247956
568.0000000000074,62.22466627066943,-0.19245912854544794,-3.0214489105721585
569.1000000000074,62.3344535789113,-0.19344271828455695,-3.0214498980376057
570.2000000000073,62.4432719410529,-0.19210486292854773,-3.0224300346614505
571.3000000000073,62.55443535251368,-0.19099586645027852,-3.0250699229282074
572.4000000000074,62.66372148256964,-0.192275180233011,-3.025068834043622
573.5000000000074,62.772619768843406,-0.19086458998267666,-3.025070010000495
574.6000000000074,62.883500281275246,-0.19149912165988767,-3.0250700168205706
575.7000000000074,62.99270317341433,-0.19362771760276007,-3.0250765758354365
576.8000000000075,63.1026869884855,-0.1961241934854826,-3.026389921996279
577.9000000000075,63.21061719705608,-0.19642719432854533,-3.0271070184724995
579.0000000000075,63.322361318142676,-0.19649849579704712,-3.027744795267771
580.1000000000075,63.43260354942527,-0.19593320574975315,-3.0290653709437594
581.2000000000075,63.541644746289855,-0.19903238563070474,-3.0303501920676275
582.3000000000076,63.65146313709911,-0.19690477905169393,-3.0316599428397217
583.4000000000076,63.75999796695663,-0.19594994920776448,-3.03165990643762
584.5000000000076,63.87156597312302,-0.19764283648974806,-3.032320629610503
585.6000000000076,63.98102539312049,-0.19789451408243927,-3.031653873972431
586.7000000000077,64.09093073160969,-0.19902494614621102,-3.03166027198306
587.8000000000077,64.20091898206113,-0.19865381993639536,-3.0329748910378096
588.9000000000076,64.31087543162694,-0.19737524287312638,-3.035280117855133
590.0000000000076,64.42131467013122,-0.19763173309303123,-3.0369302719385445
591.1000000000076,64.53000189404479,-0.19667004983364397,-3.036930179984609
592.2000000000077,64.63999892299003,-0.19715996005803355,-3.036930454696879
593.3000000000077,64.74784324590922,-0.19681308133266562,-3.0379189396870316
594.4000000000077,64.85622972637745,-0.19876816168706776,-3.0379198676630557
595.5000000000077,64.96824073876887,-0.19757283896503003,-3.0392284370131737
596.6000000000078,65.07795148829086,-0.1977080240443692,-3.0405688034265896
597.7000000000078,65.18677407906068,-0.1982459262828937,-3.039231904700459
598.8000000000078,65.29788854822142,-0.19813757706553783,-3.0419263171456077
599.9000000000078,65.40710634583593,-0.1982748762841739,-3.043016759839782
601.0000000000078,65.51617156314856,-0.19945590234116298,-3.042630212044492
602.1000000000079,65.62591470904262,-0.19974231261641726,-3.041919978357966
603.2000000000079,65.73557219639727,-0.20005081127305716,-3.0445837570185916
604.3000000000079,65.84505511027984,-0.2015668690277204,-3.044619951539743
605.4000000000078,65.95454934052,-0.20161043043725888,-3.0453353783321475
606.5000000000078,66.06380354172882,-0.2033222657923205,-3.045269899702983
607.6000000000079,66.17405878348612,-0.2039187934553853,-3.045265352432423
608.7000000000079,66.28370704614318,-0.20471120175575414,-3.0465899777569088
609.8000000000079,66.39335875083894,-0.2030813771988957,-3.0465899750002996
610.9000000000079,66.50299273440916,-0.2044728715066664,-3.046589278551602
612.000000000008,66.61343539585067,-0.20281433871662313,-3.04675339474262
613.100000000008,66.72237705259364,-0.20446402280609155,-3.0492051243006744
614.200000000008,66.83258138459088,-0.20406233331094817,-3.0505399695728053
615.300000000008,66.94269688427777,-0.204672911489167,-3.051859236570244
616.400000000008,67.05200578521142,-0.2041222921080769,-3.0505396857341176
617.5000000000081,67.16272031432545,-0.2059744570789828,-3.0505398179215626
618.6000000000081,67.27320510789427,-0.20822118396228284,-3.050537152066906
619.7000000000081,67.3821988021204,-0.20706226862567154,-3.0518604526777158
620.8000000000081,67.4930790646161,-0.20808933146248923,-3.0518598498976077
621.9000000000082,67.60045982149985,-0.208777116742777,-3.0518949482105326
623.0000000000082,67.71194758554046,-0.20947452101269415,-3.0545785325287387
624.1000000000081,67.8233656506529,-0.21021381721285554,-3.0567413341106744
625.2000000000081,67.93277384468227,-0.21050209257372446,-3.0573641944076604
626.3000000000081,68.04312499112045,-0.2127384469916701,-3.057130949138325
627.4000000000082,68.15310897806388,-0.21426046047801647,-3.057097073951635
628.5000000000082,68.2624089008255,-0.2129244389230174,-3.057240644525737
629.6000000000082,68.37372407911879,-0.21356970683349313,-3.058440138281445
630.7000000000082,68.48338475661939,-0.21481755184176174,-3.0584472144015433
631.8000000000083,68.59130717359243,-0.2137980346529199,-3.0584498815671717
632.9000000000083,68.70332506120519,-0.21381925798833162,-3.059769802402514
634.0000000000083,68.81299285111405,-0.21478609567040371,-3.0587803003888796
635.1000000000083,68.922131838003,-0.21526484379846056,-3.0600898602696773
636.2000000000083,69.0314905909219,-0.2134551656473328,-3.0600902480045127
637.3000000000084,69.1422982006893,-0.21610757934266553,-3.0597053220929546
638.4000000000084,69.25296417363295,-0.21527242701647836,-3.059225114551605
639.5000000000084,69.36146265414585,-0.2166807063077042,-3.0597384728303694
640.6000000000083,69.46969227748792,-0.2169167885795843,-3.0610802424699646
641.7000000000083,69.5823771050649,-0.214565201466238,-3.062397122977446
642.8000000000084,69.69081972753412,-0.21600313230256948,-3.063060732412193
643.9000000000084,69.8015035329276,-0.21763778575965106,-3.065690950877535
645.0000000000084,69.9126918439859,-0.21941201245243955,-3.0655699344690666
646.1000000000084,70.0226951301923,-0.2178125144323945,-3.0643700809454115
647.2000000000085,70.13207036236903,-0.21963346591994407,-3.0643699845265076
648.3000000000085,70.24217767775,-0.22027972962544803,-3.0646989348918368
649.4000000000085,70.35228995024103,-0.22236511540581158,-3.066019532439943
650.5000000000085,70.46261835318894,-0.2218719432298265,-3.0646957482036377
651.6000000000085,70.57362271723348,-0.22382288888879143,-3.064700156248845
652.7000000000086,70.68282090393316,-0.22477838933758962,-3.0673269571412223
653.8000000000086,70.79244472302108,-0.22600066926420467,-3.06718254330463
654.9000000000086,70.90317979982704,-0.22672367402759894,-3.0646666043839508
656.0000000000086,71.01326185818078,-0.22565713895450162,-3.0669344117093886
657.1000000000087,71.1225937784562,-0.2276349737068725,-3.0666918812031057
658.2000000000087,71.2328668988614,-0.22722645764090169,-3.069319462247342
659.3000000000086,71.343043370602,-0.22760403431200693,-3.069320165002196
660.4000000000086,71.45301097986135,-0.22780296106388448,-3.0693171772705954
661.5000000000086,71.5635948849352,-0.22798017230586307,-3.0706323255357044
662.6000000000087,71.67270503999413,-0.2256256436494278,-3.0693100777518567
663.7000000000087,71.78347875535916,-0.22787766354749073,-3.0706187563270717
664.8000000000087,71.89449174646057,-0.2285046371245953,-3.071950104814868
665.9000000000087,72.00494674208528,-0.22749453405500375,-3.071868116219452
667.0000000000088,72.11459196634283,-0.22939941825789406,-3.073269866270085
668.1000000000088,72.22449827234746,-0.2294310909775598,-3.07390843112083
669.2000000000088,72.33576493825962,-0.23180865987512006,-3.073594799728722
670.3000000000088,72.44588522380641,-0.2331541674257047,-3.074910529806409
671.4000000000088,72.55670609530924,-0.23440273480400287,-3.07626299420345
672.5000000000089,72.66687747975159,-0.23553040525147306,-3.0735840666799668
673.6000000000089,72.77659567461708,-0.23504247990566124,-3.0742466148182093
674.7000000000089,72.88727479174116,-0.23494194893648104,-3.071607717497255
675.8000000000088,72.99773592713558,-0.23613604743078628,-3.074250115383389
676.9000000000088,73.10875935994237,-0.23644345375156003,-3.0731730802351853
678.0000000000089,73.21843103678975,-0.23518330162072007,-3.0742553493659877
679.1000000000089,73.32980040039268,-0.23691539526791072,-3.0755751293350237
680.2000000000089,73.43871171629678,-0.2351136201701861,-3.074817520782805
681.3000000000089,73.5494040763213,-0.23713453347485422,-3.074909944211507
682.400000000009,73.65937376070228,-0.23581603309644925,-3.077240107380854
683.500000000009,73.77009894067079,-0.23816218731193575,-3.076692067106539
684.600000000009,73.88093561402485,-0.23822351303349057,-3.0752441886504744
685.700000000009,73.98955996699036,-0.23838664352032551,-3.076559642320926
686.800000000009,74.10208721979025,-0.23798125941482948,-3.075249679091316
687.9000000000091,74.21227797139218,-0.23777474935908288,-3.076563862587964
689.0000000000091,74.3200000000009,-0.24064000000002395,-3.0765599432741504
690.1000000000091,74.43289658921091,-0.240641104472209,-3.077879879257385
691.2000000000091,74.54358017648316,-0.2418814158403258,-3.079190058090219
692.3000000000092,74.65460106514904,-0.24115168095301381,-3.0805103914934664
693.4000000000092,74.76423554570707,-0.24434746951551892,-3.0790819162741734
694.5000000000091,74.87483463034924,-0.243678584641936,-3.0805956250958744
695.6000000000091,74.98595055710369,-0.24395685889582164,-3.081828668194108
696.7000000000091,75.09581332649543,-0.2438724427962801,-3.081830130000748
697.8000000000092,75.20776121844459,-0.24718084480417385,-3.0818301299999997
698.9000000000092,75.3180842352196,-0.24680140524131897,-3.08183013
700.0000000000092,75.42841203945966,-0.2454515257865113,-3.08183013
701.1000000000092,75.53724268138781,-0.24620805825581615,-3.0818301299977406
702.2000000000093,75.6481724408254,-0.2476782602065727,-3.0818362292360857
703.3000000000093,75.76029538727045,-0.24673403573338465,-3.081736893313124
704.4000000000093,75.86970943863821,-0.2460295809958818,-3.084103155551952
705.5000000000093,75.980283741516,-0.2472830133945789,-3.0831584487773624
706.6000000000093,76.09061524492401,-0.24745484377167265,-3.083202904658866
707.7000000000094,76.20066295567098,-0.24725596189462748,-3.08182503269982
708.8000000000094,76.31150854315766,-0.24871276546485965,-3.081725471762468
709.9000000000094,76.420843794625,-0.2486554642279725,-3.0840132002812197
711.0000000000093,76.53045770839725,-0.24855231759032234,-3.08435082899664
712.1000000000093,76.64079638275652,-0.24692666206321498,-3.0869755054887364
713.2000000000094,76.75154219519287,-0.25005803271661986,-3.086990129695418
714.3000000000094,76.86299667840021,-0.24979490473522617,-3.08567012427223
715.4000000000094,76.97275793991474,-0.2509910888950855,-3.085670130000002
716.5000000000094,77.0833317509722,-0.2507362745750169,-3.085670129999418
717.6000000000095,77.1941701071219,-0.2516295682693333,-3.085671675073577
718.7000000000095,77.30361228523805,-0.25261955763224087,-3.0856248647089934
719.8000000000095,77.41570179371347,-0.2527318949466064,-3.086990199643226
720.9000000000095,77.5259460215939,-0.2513225184168263,-3.086989861488882
722.0000000000095,77.63732273696614,-0.2536925670873937,-3.0870264964576126
723.1000000000096,77.74806549475807,-0.2515452950047169,-3.0869901414770053
724.2000000000096,77.85802592537054,-0.2539889063080899,-3.087986652931987
725.3000000000096,77.96944681322685,-0.2551802307837317,-3.0896312730349837
726.4000000000096,78.08041532611787,-0.2565204923006405,-3.0909401874124955
727.5000000000097,78.18928670805131,-0.2599368054597385,-3.0886843675952793
728.6000000000097,78.30204332250061,-0.2615344414699633,-3.0883099149679287
729.7000000000096,78.41368175832048,-0.26446845236715033,-3.088304424571348
730.8000000000096,78.52411613214835,-0.2656094480047435,-3.0896201303647692
731.9000000000096,78.63468229896293,-0.265951656306431,-3.089629153142396
733.0000000000097,78.7457948722858,-0.26870021353662604,-3.0896772203979292
734.1000000000097,78.85618308829915,-0.2699671244195157,-3.0893006081224925
735.2000000000097,78.96710198147267,-0.2718804003699373,-3.089619825130355
736.3000000000097,79.07825409758794,-0.27235686072309473,-3.089554369573469
737.4000000000098,79.1878346447751,-0.2736716597009551,-3.089619880727284
738.5000000000098,79.29932110827382,-0.27673722450760957,-3.0906107104481757
739.6000000000098,79.40981017456693,-0.27723526120427516,-3.0896315703614317
740.7000000000098,79.52089277887086,-0.27713651457339133,-3.0900053051378227
741.8000000000098,79.63091086568933,-0.2788143846799688,-3.090613356985158
742.9000000000099,79.74147694706471,-0.279326874253588,-3.091964242207837
744.0000000000099,79.85309158319954,-0.2818099596873781,-3.0892860233209207
745.0000000000099,79.95323822503696,-0.28434568366580726,-3.0906099419303037