File: 01_Data/Rebond_Foam_Carpet_Pad/STA/N2/10K_min/Rebond_Foam_Carpet_Pad_STA_N2_10KData_221017_R2.csv
##Temp./Â°C,Time/min,DSC/(mW/mg),Mass loss/mg
51.0,10.812600397215954,-1.6119830164846851,0.05040151694872197
51.90000000000001,11.113100041909739,-1.517229664324729,0.049774143505109336
52.800000000000026,11.322389418060613,-1.4512924712759903,0.0479563740799378
53.70000000000004,11.500260369197475,-1.397648647702525,0.049164641369540796
54.60000000000005,11.662938676436776,-1.353572276400515,0.04866133366092562
55.500000000000064,11.811039876869565,-1.3186093700000177,0.04893699734693335
56.40000000000008,11.951763281443041,-1.2904723423007816,0.049737341897842846
57.30000000000009,12.085274376633835,-1.2634060614672828,0.04813443045110777
58.2000000000001,12.21321189625115,-1.242086521900227,0.04987039444812069
59.100000000000115,12.334432777790777,-1.2229911817432193,0.04889771224665829
60.00000000000013,12.458744212313077,-1.2069969624762853,0.05014146711429568
60.90000000000014,12.576603899174417,-1.1923304565777368,0.049228517523239645
61.80000000000015,12.695162288549852,-1.1773039221429762,0.04919282169601136
62.700000000000166,12.807590634783818,-1.1639687455176417,0.050594386751239284
63.60000000000018,12.921277813127494,-1.1534976516674025,0.050553710100993854
64.5000000000002,13.032831748559543,-1.1418349147634759,0.048888073359935724
65.4000000000002,13.142515585329114,-1.1313121882504946,0.04989729319925473
66.30000000000021,13.249017171389223,-1.120108239204528,0.050275618992386306
67.20000000000023,13.36015816112966,-1.109893505659702,0.05263013429162999
68.10000000000025,13.463568294855865,-1.1011015594008167,0.05107382970621188
69.00000000000026,13.570899845250834,-1.0907353768396666,0.05082369197242276
69.90000000000026,13.675911678975734,-1.0816754569571132,0.052783247324520666
70.80000000000028,13.780211549861587,-1.0735311567237769,0.05071365099319092
71.7000000000003,13.882595487479888,-1.063791614728156,0.05047038005131732
72.6000000000003,13.98330314738374,-1.0558481118899048,0.05151256145585226
73.50000000000031,14.085898245411517,-1.045940807556863,0.051487770189099
74.40000000000033,14.18753086180445,-1.0366031380503542,0.05201111994571672
75.30000000000035,14.284636204277934,-1.029851276730355,0.052946974035858574
76.20000000000036,14.386344292858679,-1.0211294611099377,0.051596351835621945
77.10000000000036,14.486230095426235,-1.0146708729937208,0.05319228697329592
78.00000000000038,14.581425664127728,-1.0077050388221336,0.0524872820465454
78.9000000000004,14.680944785089313,-1.001969705103925,0.05183504279327256
79.80000000000041,14.778505557647708,-0.9941420660928499,0.05316571842931772
80.70000000000041,14.87489110114342,-0.9892593641306918,0.0531690080121523
81.60000000000043,14.971066434527295,-0.9816840796205967,0.05314700780328696
82.50000000000045,15.066362375576773,-0.9758447291754075,0.05194755003303442
83.40000000000046,15.16217671407956,-0.9708270418544886,0.053013810448115706
84.30000000000047,15.257145761740595,-0.964802211046804,0.054496119158419454
85.20000000000049,15.349170000000072,-0.958319999999997,0.05443873109734021
86.1000000000005,15.445191729730501,-0.9549879732649612,0.0544503647085719
87.00000000000051,15.537795146400885,-0.9489023614539629,0.05443637662202683
87.90000000000052,15.632328787218922,-0.9443903106683442,0.05616941907852446
88.80000000000054,15.724719780499926,-0.9384123504860464,0.05570213398083812
89.70000000000056,15.818244494737591,-0.9323161450091804,0.05553630460604708
90.60000000000056,15.909598493731812,-0.9255664385482568,0.05574169916735361
91.50000000000057,16.00321068443741,-0.9198137509999229,0.05576410872573767
92.40000000000059,16.092208854756393,-0.9139984563431728,0.055767144967799
93.30000000000061,16.184816380598207,-0.9081565844555387,0.05582796827237857
94.20000000000061,16.275267994826503,-0.9020090635452336,0.056391370272364405
95.10000000000062,16.36608304923958,-0.8977235791414802,0.05568412673591272
96.00000000000064,16.45507161588152,-0.8912358539122306,0.05577975882119368
96.90000000000066,16.546236231896074,-0.8848638261506896,0.05633487275151161
97.80000000000067,16.635649454106748,-0.8807022902462612,0.05680800057570501
98.70000000000067,16.7244569782239,-0.8746860093380635,0.057425830580228876
99.60000000000069,16.81589062140972,-0.8711753647932611,0.05839924346028624
100.50000000000071,16.905512425449626,-0.866136133128065,0.05709075650749451
101.40000000000072,16.99375852527752,-0.8605065674047716,0.058419194566914356
102.30000000000072,17.082694027459766,-0.8567192139331001,0.057088836437388935
103.20000000000074,17.172158213888057,-0.8518734493729414,0.05797767835044443
104.10000000000076,17.260549492667053,-0.8473390478757478,0.058396215257882744
105.00000000000077,17.348890167897178,-0.8429352807660837,0.05771414889784943
105.90000000000077,17.439170000000118,-0.8395399999999928,0.058409844922088006
106.8000000000008,17.525570917795587,-0.8347432279412346,0.0583719817407129
107.70000000000081,17.615643670851917,-0.8325800684519182,0.05983266308961532
108.60000000000082,17.70047228780405,-0.8274691631009862,0.05850974086566829
109.50000000000082,17.79183329766914,-0.8240135238481285,0.05718410769849047
110.40000000000084,17.880541984822596,-0.8198069461638535,0.05587952982756761
111.30000000000086,17.968986112282845,-0.8162873658934521,0.05851330537699173
112.20000000000087,18.057864500880818,-0.8119715389385762,0.05851365786628726
113.10000000000088,18.14521096287921,-0.8087792787928272,0.05986837153830926
114.0000000000009,18.233221406946598,-0.8043454347428771,0.05918488625803153
114.90000000000092,18.321431641601635,-0.8008242547229624,0.059214141828479505
115.80000000000092,18.408401520476065,-0.7964353129806645,0.05686410824465682
116.70000000000093,18.496020784191803,-0.7918926182347451,0.05787225082551206
117.60000000000095,18.584608998706635,-0.7875313708277221,0.05830563812190359
118.50000000000097,18.672757138430775,-0.783849036894148,0.05760692965710312
119.40000000000097,18.75801707234189,-0.7803487166090273,0.05825351753573571
120.30000000000098,18.84687185136496,-0.7768505856860854,0.058301944869484146
121.200000000001,18.933981268250932,-0.774050481150646,0.058290382943472
122.10000000000102,19.02192377443242,-0.7717933919582599,0.05937464640389045
123.00000000000102,19.11064450510475,-0.7699429927649215,0.059608566814915775
123.90000000000103,19.19861638193133,-0.7677467746945758,0.0582843644886184
124.80000000000105,19.284990360339577,-0.7661397027980933,0.05829015975212215
125.70000000000107,19.371630077837505,-0.7627101175112199,0.05989555271991431
126.60000000000107,19.459933580185204,-0.7600970009236443,0.06049171592349101
127.50000000000108,19.547293533805274,-0.7588747920587534,0.061150476521715014
128.4000000000011,19.633414263636393,-0.7559253182281537,0.06015923605900486
129.30000000000112,19.720662997797,-0.7534791325393756,0.0599031939391832
130.20000000000113,19.806545185293068,-0.7502766181621532,0.05791480706354957
131.10000000000113,19.893947434522442,-0.7469990248201955,0.05752992865461426
132.00000000000114,19.980155343583498,-0.7442672540706787,0.057529927272645054
132.90000000000117,20.06770078668246,-0.7423569483265158,0.05793950456537367
133.80000000000118,20.15456613660161,-0.7394718799730224,0.05883916901993658
134.70000000000118,20.240200873939,-0.7359583308991554,0.058840013805828484
135.60000000000122,20.327050714161015,-0.732591022729061,0.057519752878720354
136.50000000000122,20.412881089215183,-0.7283405406564026,0.05887464351282912
137.40000000000123,20.500640923945927,-0.7269540368469438,0.05753008498574541
138.30000000000123,20.585628668778885,-0.7241958797112559,0.058883297871436646
139.20000000000124,20.672882710849542,-0.7217023667225382,0.057821856080155776
140.10000000000127,20.758864578796075,-0.7195113946356211,0.057359909998196734
141.00000000000128,20.84547657230801,-0.7156757982422741,0.05873566026538857
141.90000000000128,20.931000410811365,-0.7120704660163066,0.05873003558739587
142.80000000000132,21.01755209833123,-0.7096627826093981,0.05956657221850925
143.70000000000132,21.10309410307192,-0.7078444829609851,0.06004991005386273
144.60000000000133,21.19003437231509,-0.7046721003587016,0.05874950307010973
145.50000000000134,21.275299754551682,-0.7018573810360671,0.05835023397107175
146.40000000000134,21.360643582574102,-0.6970754480743426,0.0598299878109243
147.30000000000138,21.44744197263895,-0.6948820372980445,0.06108487847059685
148.20000000000138,21.532142830141648,-0.6922420857866733,0.0598445071246676
149.1000000000014,21.618616352648196,-0.689793353362924,0.05982764656322903
150.00000000000142,21.70364419062022,-0.6865557343115571,0.05851946439573208
150.90000000000143,21.787356495989304,-0.6822412868417911,0.057101185003673116
151.80000000000143,21.873924038108072,-0.6790584621677596,0.05720008031128998
152.70000000000144,21.959903760866716,-0.6754400260182787,0.05669352936562433
153.60000000000144,22.04615766623587,-0.6724158977148863,0.05585095281321539
154.50000000000148,22.132451506834336,-0.6689096161036312,0.05730016493224799
155.40000000000148,22.21701350476696,-0.6667323780550284,0.057300223270631
156.3000000000015,22.302740818298663,-0.6630973576815313,0.05730508838296622
157.20000000000152,22.38793915139803,-0.6605026889618066,0.05863004005008943
158.10000000000153,22.473247761827018,-0.6573994809956129,0.057639926847248724
159.00000000000153,22.55858861940945,-0.6552729099967244,0.05763992893643355
159.90000000000154,22.644152721296454,-0.6534326708458994,0.05762931984919728
160.80000000000155,22.729930828531838,-0.6518089813676899,0.055670702751262624
161.70000000000158,22.815537251475902,-0.6486247925419937,0.05494654253769227
162.6000000000016,22.90038869505378,-0.6482336803412193,0.054999849794478806
163.5000000000016,22.98490911373353,-0.6458580835174754,0.05427454910519458
164.40000000000163,23.071786698680075,-0.6446733109924403,0.055660051471936534
165.30000000000163,23.156501089915466,-0.6424022362223101,0.05435298873264749
166.20000000000164,23.241572816080804,-0.6401640364104751,0.05565964177538607
167.10000000000164,23.327428080604644,-0.6379714167336997,0.05565981234267259
168.00000000000165,23.412587796760643,-0.6358863460170263,0.054571874725804825
168.90000000000168,23.498501834554215,-0.6342905987320345,0.05302451497519378
169.8000000000017,23.585313795274402,-0.6307127370966092,0.0530198239529609
170.7000000000017,23.66972079250706,-0.6290879473353916,0.05301981708615511
171.60000000000173,23.755037612152098,-0.6261322370847346,0.05165660079574064
172.50000000000173,23.840739726565257,-0.6238160750308456,0.05301056642486035
173.40000000000174,23.92716906220594,-0.6215294044895455,0.05301982277299455
174.30000000000175,24.011000774880426,-0.6199221856348384,0.05219210264651952
175.20000000000175,24.09562208317055,-0.617770491961442,0.05045780065722205
176.10000000000178,24.182957373481194,-0.6145746954826367,0.051000409916630574
177.0000000000018,24.267726139188373,-0.6130101350467251,0.05038827815940028
177.9000000000018,24.35382196959938,-0.609329578015052,0.048661954266615126
178.80000000000183,24.438143487611747,-0.6093033455563721,0.048420145296134365
179.70000000000184,24.52465640417011,-0.6070457611633185,0.048420143999425846
180.60000000000184,24.610287795401202,-0.6041597784626631,0.048420129602905426
181.50000000000185,24.695058255498132,-0.6005822244410525,0.04776856216166259
182.40000000000185,24.77816076638674,-0.5988630344383279,0.046440493872551336
183.3000000000019,24.865881394860956,-0.5965758569893245,0.045119956583901555
184.2000000000019,24.951124082423267,-0.594920547850829,0.04513092014550235
185.1000000000019,25.037357467163016,-0.5924143141453793,0.04381127087398262
186.00000000000193,25.12193806399346,-0.5918468666005233,0.04478982415581889
186.90000000000194,25.20813629620892,-0.5890474495481116,0.043469246682933615
187.80000000000194,25.29276069969224,-0.5845395971086301,0.042052310175431096
188.70000000000195,25.377695192449085,-0.5832542850919296,0.04216388896162648
189.60000000000196,25.463550417991154,-0.5802101742314749,0.040839725167726826
190.500000000002,25.548521943619747,-0.5786435305776406,0.040839975972849274
191.400000000002,25.633464895818218,-0.5768428296055329,0.04084644326364728
192.300000000002,25.71637977969348,-0.5743952285015502,0.0385298768200979
193.20000000000203,25.80454363028063,-0.5721134228045659,0.03820079346799776
194.10000000000204,25.887839209374548,-0.5700198127329043,0.03820014485396417
195.00000000000205,25.97393363997724,-0.56729793320797,0.03721476673088997
195.90000000000205,26.059586013098826,-0.5653626218741603,0.0355821052375731
196.80000000000206,26.1451696357468,-0.5632720742558246,0.035641615301951646
197.7000000000021,26.229535795659924,-0.5611422228060401,0.031616931369345735
198.6000000000021,26.313824219738134,-0.5592596589312917,0.032612912999053556
199.5000000000021,26.399359487222025,-0.5566844050306622,0.0326249209804681
200.40000000000214,26.485071800552557,-0.5531360061295024,0.03303252680685187
201.30000000000214,26.570037315945438,-0.5510757424013442,0.0302609130124587
202.20000000000215,26.656538466845547,-0.5480592382068662,0.028981304399223973
203.10000000000215,26.740310966226353,-0.544824031763565,0.027683868749383223
204.00000000000216,26.82603922923591,-0.5432071443549128,0.025046601217066033
204.9000000000022,26.911983629102373,-0.5403832910173164,0.023703891857738135
205.8000000000022,26.997642420298913,-0.5377917516422026,0.02261027475735844
206.7000000000022,27.081972585033327,-0.5346805685444893,0.021069948659078186
207.60000000000224,27.16749218167388,-0.5298108815664291,0.02056258875249828
208.50000000000225,27.25346159590703,-0.5271350298304132,0.018770672636073904
209.40000000000225,27.338044658549418,-0.5236521294123289,0.018437846114816026
210.30000000000226,27.423583296221647,-0.5199030540325179,0.01625770016184358
211.20000000000226,27.50846548964728,-0.5182519298733533,0.014490572677237523
212.1000000000023,27.594814160921604,-0.5147360351023278,0.013153140137931452
213.0000000000023,27.679059063099935,-0.5089565351631974,0.012511232608026113
213.9000000000023,27.765086055743556,-0.5071693558607423,0.01073243208278285
214.80000000000234,27.848642329159947,-0.5034241112779246,0.009220503702361604
215.70000000000235,27.935072157871414,-0.5000698777809871,0.007900427074269523
216.60000000000235,28.019168960384434,-0.4972599502529983,0.006589875217080987
217.50000000000236,28.105771665301457,-0.4933930660489258,0.005273141169532813
218.40000000000236,28.19089906986481,-0.4897003595311504,0.002633747080778903
219.3000000000024,28.276559141197954,-0.4862078253964006,0.0001003183328158741
220.2000000000024,28.36226031066795,-0.48326184179717896,-0.0016611715884629064
221.1000000000024,28.446882002663575,-0.47843534116713354,-0.00402697191994239
222.00000000000244,28.532486895579147,-0.4744357040847163,-0.006677081740731339
222.90000000000245,28.618959601952728,-0.4705447802697927,-0.006689007829474569
223.80000000000246,28.703792644092136,-0.46614771536591426,-0.010539866778911389
224.70000000000246,28.7894639182532,-0.4619165173038787,-0.01197035131379831
225.60000000000247,28.873395064739857,-0.45730168730410764,-0.013312644792983441
226.5000000000025,28.96006075843283,-0.45253387948779034,-0.016026427944860977
227.4000000000025,29.04495476455542,-0.4483615753503682,-0.01734680071733763
228.3000000000025,29.13036945504332,-0.44418109902904157,-0.021431023404057115
229.20000000000255,29.215158353046338,-0.4378009029908434,-0.025241863502634132
230.10000000000255,29.301667833772278,-0.4336107035889714,-0.026792248697558918
231.00000000000256,29.387656920957614,-0.4285321125145517,-0.02964158964861241
231.90000000000256,29.472739342129433,-0.424248286378833,-0.03247578527387596
232.80000000000257,29.55841685782358,-0.41906555096924925,-0.03370413957575291
233.7000000000026,29.643336550755432,-0.4130137640384073,-0.03647403091838797
234.6000000000026,29.728610705681508,-0.40896276170918355,-0.04073493915563908
235.50000000000261,29.81430577099385,-0.40305690424287927,-0.04397295817623181
236.40000000000265,29.89961936406082,-0.39825572809707893,-0.047579653693266444
237.30000000000265,29.98522137311615,-0.39431555084832537,-0.05075692416387856
238.20000000000266,30.070954143219677,-0.3876799655992552,-0.05220052657167429
239.10000000000267,30.15656473383025,-0.38230462113966557,-0.056483947448678684
240.00000000000267,30.24213723868679,-0.37600594305991486,-0.05997926069028203
240.9000000000027,30.326770235901144,-0.36890911141308724,-0.06232303521261162
241.8000000000027,30.412357417174807,-0.3636158360348168,-0.06509624322974794
242.70000000000272,30.497956842797972,-0.354902476460472,-0.07101939577265348
243.60000000000275,30.583961422202016,-0.3494435035323608,-0.07389170075768536
244.50000000000276,30.666345708752424,-0.34075861956909154,-0.07682349704642011
245.40000000000276,30.754672500972305,-0.32790774650600796,-0.08084265375663335
246.30000000000277,30.84008324320575,-0.3141123610611538,-0.08453556767053083
247.20000000000277,30.926265104795384,-0.30484341707603335,-0.08953963062595882
248.1000000000028,31.011235599060125,-0.2896281507354674,-0.09433592309574923
249.0000000000028,31.096730906981527,-0.2831774866410264,-0.09709333704600276
249.90000000000282,31.182967383662987,-0.28793768430335515,-0.10165093992092711
250.80000000000285,31.269068659604763,-0.2946513736070825,-0.1057083941595911
251.70000000000286,31.354291589253442,-0.29803959859529333,-0.11267758882859935
252.60000000000286,31.438901297487945,-0.29987978398297216,-0.11614082745954635
253.50000000000287,31.524708893542382,-0.30156785044402407,-0.12191898049080363
254.40000000000288,31.61143467265243,-0.3027263806443136,-0.1268213564231302
255.3000000000029,31.696584927230358,-0.30171529489902005,-0.1314428423172438
256.2000000000029,31.781309461006128,-0.2991651088293882,-0.13638095751573376
257.1000000000029,31.86776995190361,-0.29498466773199633,-0.14235522559928837
258.00000000000296,31.953371632356564,-0.2908319543858251,-0.14831847372733487
258.90000000000293,32.03906641891588,-0.28612020859724147,-0.1540282026572215
259.80000000000297,32.124161286818875,-0.27867638343933987,-0.15852378453605054
260.700000000003,32.21103056833825,-0.2739824841800842,-0.1645524376598444
261.600000000003,32.29541532870774,-0.2670739731646027,-0.17082941139823138
262.500000000003,32.38212677532102,-0.26170582530537,-0.17953812915748246
263.40000000000305,32.46726536265783,-0.2533256338147814,-0.18650364242228035
264.300000000003,32.554535958790346,-0.24669702763597753,-0.192329649134666
265.20000000000306,32.637797887389546,-0.23843766197414257,-0.19937228904413162
266.1000000000031,32.72602926469752,-0.23007793735845739,-0.2077731849676927
267.00000000000307,32.81074514205175,-0.2216095622200104,-0.21515559839892173
267.90000000000305,32.89779553189799,-0.21317809437560212,-0.2225288313330127
268.8000000000031,32.98275911412916,-0.2058859623592768,-0.23062579642604408
269.7000000000031,33.06864994574703,-0.19613346172315,-0.2386726453039274
270.6000000000031,33.15490798776472,-0.18377559642159866,-0.24924839588561332
271.5000000000031,33.24063220799099,-0.17260408918429268,-0.2584712841325625
272.40000000000316,33.32551564294908,-0.16315580508948335,-0.26695819699345513
273.30000000000314,33.4119828655823,-0.14940927841002835,-0.2763781030946202
274.2000000000032,33.49802133940293,-0.13729737385415658,-0.28698991807870744
275.1000000000032,33.584616248453656,-0.12549639087639333,-0.29663164925017727
276.0000000000032,33.669817310879395,-0.11229418410514112,-0.3080140438956751
276.9000000000032,33.75684216140862,-0.09911078443434296,-0.3191960373556437
277.80000000000325,33.84156581353986,-0.08596793888932254,-0.33132746067139784
278.70000000000323,33.9281383438327,-0.07248164237165766,-0.3431427611062041
279.60000000000326,34.01402183404866,-0.05654512940149843,-0.3559856445196079
280.5000000000033,34.099925244522844,-0.045027702445768245,-0.3652633029010288
281.4000000000033,34.186069489617594,-0.031253016360182344,-0.38042643342174287
282.30000000000325,34.271921323289,-0.019692856029315368,-0.39250237299377577
283.2000000000033,34.35862413926266,-0.008873315841659613,-0.40545974855106204
284.1000000000033,34.44408417105728,0.0035937998334028,-0.4175900221289961
285.0000000000033,34.531502880402314,0.014718242517431833,-0.4305480673777917
285.90000000000333,34.6167435287905,0.023914244299538874,-0.44630336733591314
286.80000000000337,34.70315947964815,0.03274015304540254,-0.4603671322301399
287.70000000000334,34.79090711744533,0.0408994140796949,-0.4741999288505587
288.6000000000034,34.876299920900045,0.04954627994271816,-0.48753100780696323
289.5000000000034,34.962295045600435,0.05383702525683947,-0.5019436958405556
290.4000000000034,35.048453393998884,0.058787140808726907,-0.5164848130364392
291.3000000000034,35.135425378805714,0.05911623684077237,-0.5311422014285645
292.20000000000346,35.22101289541395,0.05707184221376163,-0.5456725373103994
293.10000000000343,35.30732506562246,0.05179988564406786,-0.5615146302031588
294.00000000000347,35.39465156370722,0.04137191939592634,-0.5741492303734872
294.9000000000035,35.47976691848897,0.02867161820279275,-0.5873829759387403
295.8000000000035,35.56722655833855,0.008719675460511719,-0.604695425027864
296.70000000000346,35.652276307973196,-0.011763696527620542,-0.6180870790719988
297.6000000000035,35.7385807333109,-0.03654236757994517,-0.6342026836122558
298.5000000000035,35.824809159519184,-0.06110593413939509,-0.6471465350917409
299.4000000000035,35.91111864269705,-0.08475589102127773,-0.6598943332674159
300.30000000000354,35.99680914397166,-0.10728664238970596,-0.6713458976568214
301.20000000000357,36.08249457165904,-0.1271937862495542,-0.6832516522029319
302.10000000000355,36.16865838738277,-0.1462129282903709,-0.6960779424659287
303.0000000000036,36.2544853703556,-0.16436842672167234,-0.7075172109606123
303.9000000000036,36.34041149168105,-0.18018766229501265,-0.7190209988209117
304.8000000000036,36.42723204159363,-0.19518067366488134,-0.7315068075753812
305.7000000000036,36.512494536037785,-0.2071034042828334,-0.7429125184519307
306.60000000000366,36.598769390835834,-0.22093556704628775,-0.752840675204264
307.50000000000364,36.68347225794694,-0.23240122671410957,-0.7631963488733966
308.4000000000037,36.77141927510011,-0.24384813475087397,-0.7744319683926437
309.30000000000365,36.85725541850547,-0.25416535967371084,-0.7836167612852214
310.2000000000037,36.94382436519663,-0.2631685080921042,-0.7912529741772092
311.1000000000037,37.02998203464776,-0.2737992528975272,-0.8005121707205705
312.0000000000037,37.11585294513438,-0.2838158939494543,-0.8096353771140601
312.90000000000373,37.20200759150503,-0.29525193729227445,-0.8186221924744554
313.8000000000037,37.287437150835665,-0.30405402221351235,-0.8262312112144632
314.70000000000374,37.374710680957875,-0.3139460657219411,-0.8357576258191455
315.6000000000038,37.459859531659184,-0.3247367946979778,-0.8425274665546394
316.50000000000375,37.54645096802647,-0.3345461361795231,-0.8520117036523955
317.4000000000038,37.6332476903281,-0.343819084187781,-0.860365356334237
318.3000000000038,37.719356184079764,-0.35173352558172616,-0.8675173058276044
319.2000000000038,37.8054689363988,-0.3617136295735282,-0.8751426497928834
320.10000000000383,37.89240519467389,-0.37094156412769974,-0.8827240286774924
321.00000000000387,37.97786983126062,-0.3787843247883433,-0.8893954301309499
321.90000000000384,38.06579961662948,-0.38608399152100836,-0.8953934980436551
322.8000000000039,38.151381459261394,-0.3942737956833964,-0.9031290156187444
323.70000000000385,38.237343358120256,-0.3994761536112984,-0.908957409269556
324.6000000000039,38.325025200000674,-0.40694544703844077,-0.9175770535268017
325.5000000000039,38.411467969283386,-0.41434703074618406,-0.9242207588921145
326.4000000000039,38.498213777589385,-0.42090078108600504,-0.9318990266111076
327.30000000000393,38.58421305437243,-0.42732423069809167,-0.9367306163222757
328.2000000000039,38.67116182917462,-0.4323813269876582,-0.945510448652688
329.10000000000394,38.75737340909619,-0.43938242407523626,-0.9516020596197405
330.000000000004,38.844011560090145,-0.4420038280114278,-0.9584504528181825
330.90000000000396,38.92815062337808,-0.4475601240730213,-0.9658867277559939
331.800000000004,39.01727086395906,-0.4509578900467331,-0.9727073643102386
332.700000000004,39.10302850521227,-0.45530746287131163,-0.9803975316001612
333.600000000004,39.19122492739885,-0.46035921682631903,-0.9881578214512352
334.50000000000404,39.27714964750081,-0.463669420751634,-0.9944930675197003
335.40000000000407,39.36356754377993,-0.46800278473826723,-1.0011534541738212
336.30000000000405,39.450757145731444,-0.47242386785851276,-1.0086318299408337
337.2000000000041,39.53816786128402,-0.476766520958747,-1.016715712784971
338.10000000000406,39.62527616914528,-0.4798035326180992,-1.0267432225203303
339.0000000000041,39.71149090921567,-0.4821354065142552,-1.0317549171826874
339.9000000000041,39.79814747544653,-0.48396161301246776,-1.0389263257733714
340.8000000000041,39.88593496449335,-0.4853121389165965,-1.04536605534991
341.70000000000414,39.970235782311605,-0.48648132575534575,-1.0535396625756284
342.6000000000041,40.059359602652954,-0.4887109437156984,-1.0617367495470376
343.50000000000415,40.146414951133686,-0.48794058865148293,-1.0674417785872463
344.4000000000042,40.23377890524873,-0.48856107601664445,-1.0737416209378505
345.30000000000416,40.321353372687554,-0.48765290049733484,-1.081603958657741
346.2000000000042,40.40861243754164,-0.4896272459897417,-1.0874132431314525
347.10000000000423,40.494422011459605,-0.49040245498949514,-1.0934159872014444
348.0000000000042,40.581730585616064,-0.49070347450431345,-1.1003513120627764
348.90000000000424,40.66679265288119,-0.4895939399260195,-1.108505397595045
349.8000000000043,40.75563473930547,-0.4904164457464239,-1.1150854116395217
350.70000000000425,40.84221459650218,-0.488658236361761,-1.1217292287093774
351.6000000000043,40.93034502291518,-0.4833006189468836,-1.1267049384341132
352.50000000000426,41.01654159083692,-0.4782001283402997,-1.135395075725282
353.4000000000043,41.10378681936295,-0.475614135806517,-1.1422969348145267
354.30000000000433,41.189871064054074,-0.4722585212214904,-1.1499201410152984
355.2000000000043,41.27735739765189,-0.4668835503635306,-1.1573897511897298
356.10000000000434,41.36346766386874,-0.46162328016755694,-1.166839112699912
357.0000000000043,41.450434163143306,-0.4581416949323156,-1.175083173562221
357.90000000000435,41.53751510295868,-0.4539420516638037,-1.1828651609363274
358.8000000000044,41.62602354863447,-0.44924077610898255,-1.1903046514743174
359.70000000000437,41.712797229851105,-0.4437414938311609,-1.198515741738547
360.6000000000044,41.79999078114521,-0.4387789915435086,-1.2071412207652203
361.50000000000443,41.886801216702985,-0.4320720174719459,-1.217870373590194
362.4000000000044,41.97490101575715,-0.4277320811223674,-1.2287757915859263
363.30000000000445,42.06125979637782,-0.4222005818116919,-1.2393921120602478
364.2000000000045,42.14787452491385,-0.41674362037696033,-1.2495043403405948
365.10000000000446,42.233925407555695,-0.4100800687219443,-1.2604861243297383
366.0000000000045,42.32000737162049,-0.4048635990131775,-1.2707475381950704
366.90000000000447,42.40888417811058,-0.4003421083412364,-1.2842035781567551
367.8000000000045,42.496400271508705,-0.3934680456273269,-1.2965313318993315
368.70000000000454,42.583633334055,-0.386470836809617,-1.308913244012746
369.6000000000045,42.67068751627327,-0.379162914422087,-1.322972430724353
370.50000000000455,42.75626282715842,-0.3715518889874846,-1.3374441987441186
371.4000000000045,42.84452731437389,-0.364512889191513,-1.351911852459751
372.30000000000456,42.930526801360536,-0.3532599507931415,-1.3678603652678434
373.2000000000046,43.0189667090701,-0.3438195410249092,-1.3828899489425832
374.10000000000457,43.10614937556453,-0.3350740154774451,-1.4019109778571064
375.0000000000046,43.193657347264505,-0.324073923657665,-1.4185094860871161
375.90000000000464,43.28063794211586,-0.3126911308059096,-1.4381189767832812
376.8000000000046,43.368209956578326,-0.3027058763584578,-1.456685013578435
377.70000000000465,43.45624301615077,-0.2913654639876409,-1.4784216575984197
378.6000000000047,43.54430837431784,-0.27789344245988973,-1.4999534819994067
379.50000000000466,43.63026210735694,-0.2675352032595025,-1.521108637411316
380.4000000000047,43.718857790337196,-0.25393425410246795,-1.5457332273593072
381.3000000000047,43.805603126661964,-0.24356125908170786,-1.5709001433465621
382.2000000000047,43.89322892168624,-0.23141902439345657,-1.596350770887835
383.10000000000474,43.98036811223388,-0.21886514475353142,-1.6233511142793327
384.0000000000047,44.06878950023642,-0.2070188059931862,-1.6490382797758945
384.90000000000475,44.15608651119436,-0.19290108004374792,-1.6784523509322793
385.80000000000473,44.2436193333623,-0.18239362375026044,-1.709821442242284
386.70000000000476,44.33108705783491,-0.16864533828272374,-1.7420666479738602
387.6000000000048,44.41916907868156,-0.15549021954703535,-1.7729996321196153
388.5000000000048,44.507031838051056,-0.1446975027450337,-1.8066440560898944
389.4000000000048,44.5924367254663,-0.13178718039803916,-1.8403693966583248
390.30000000000484,44.68269765371602,-0.12099712136267278,-1.8788020004028105
391.2000000000048,44.76927115405603,-0.11018747890679365,-1.9148861381970574
392.10000000000485,44.85767617243225,-0.10169086681685131,-1.95371702355801
393.0000000000049,44.945355973391614,-0.09172306841073279,-1.9924395908729475
393.90000000000487,45.03281756449962,-0.0850997046025637,-2.033573898809146
394.8000000000049,45.12030896693606,-0.07789179995041733,-2.0740331074001266
395.7000000000049,45.209266407086545,-0.07198154398874465,-2.115234193711987
396.6000000000049,45.295924625072246,-0.06858517412807763,-2.156380072474012
397.50000000000495,45.38401850480544,-0.06903465910738006,-2.1973692027343175
398.4000000000049,45.47191983169359,-0.06794862208757942,-2.2369618526867825
399.30000000000496,45.55987749433659,-0.07010189893899117,-2.278633767113051
400.20000000000493,45.64760282634006,-0.07382325427926895,-2.3206375613077
401.10000000000497,45.7353336733062,-0.08260186220974845,-2.3613722747548467
402.000000000005,45.823072248921505,-0.08920412825998966,-2.4027001290518286
402.900000000005,45.910830156296534,-0.10020957865301845,-2.442529992737653
403.800000000005,45.99696824000791,-0.1108013570040614,-2.4820514380945013
404.70000000000505,46.08572501951946,-0.12348189191566093,-2.521173613274406
405.600000000005,46.17316264168114,-0.13489797269085485,-2.5585186682134538
406.50000000000506,46.260414293823985,-0.15133667622014965,-2.5937253399390157
407.4000000000051,46.34668441334471,-0.16478026170318366,-2.6285459065202827
408.30000000000507,46.43510099568359,-0.1802193855418879,-2.6641677928161087
409.2000000000051,46.5225757196847,-0.1961952061279932,-2.6999239707259974
410.1000000000051,46.609839615377545,-0.21161427050259252,-2.7325197226738265
411.0000000000051,46.698542543323995,-0.22887695998357935,-2.7651545574011527
411.90000000000515,46.78559381270778,-0.24577438828587225,-2.7953577109373224
412.8000000000051,46.873212812598176,-0.2625013090829322,-2.825577134096645
413.70000000000516,46.96005478477372,-0.27910427768430457,-2.8537357666359853
414.60000000000514,47.04877078394305,-0.29639070807506784,-2.8824752019864492
415.5000000000052,47.13596965970535,-0.3131551157017634,-2.9089341404343623
416.4000000000052,47.223066347303615,-0.33017650412313365,-2.9327512872107335
417.3000000000052,47.31153719861825,-0.3460898396490687,-2.9596296683718295
418.2000000000052,47.39916898102659,-0.36098999956203026,-2.9825973896314024
419.10000000000525,47.48658482883071,-0.3775999785556556,-3.0041745917440714
420.00000000000523,47.574597260178805,-0.3922471618489061,-3.0248197407327106
420.90000000000526,47.66235609325884,-0.4073075856373633,-3.045476897050842
421.8000000000053,47.75035307152708,-0.4193601399626848,-3.064248518461328
422.7000000000053,47.83773490162682,-0.43237221497977574,-3.082770936786275
423.6000000000053,47.9264194695629,-0.444779485699672,-3.1000388767432483
424.5000000000053,48.01259596697451,-0.4558011628735871,-3.1167105768903736
425.4000000000053,48.101375627777514,-0.46752623370920293,-3.131610500316274
426.30000000000535,48.18886687705757,-0.4786910872554446,-3.1453465747208424
427.20000000000533,48.27732204596671,-0.4885122992783656,-3.1599882394493064
428.10000000000537,48.3651674563644,-0.5013004258716088,-3.173204667518189
429.00000000000534,48.452826086998236,-0.5100873052698401,-3.1843870327544597
429.9000000000054,48.54011839693635,-0.5186311380305331,-3.19567781102124
430.8000000000054,48.628244341925665,-0.5263120541574511,-3.204484976329075
431.7000000000054,48.716790698987054,-0.5348481499542497,-3.215299084589927
432.6000000000054,48.80422466433782,-0.5413800355713448,-3.226035340814968
433.50000000000546,48.89128206007263,-0.5497597755045113,-3.234987865776087
434.40000000000543,48.9793419028388,-0.5554601284097466,-3.241575934634035
435.30000000000547,49.06666115863351,-0.5611856739393659,-3.2491862914983547
436.2000000000055,49.15508343883932,-0.5651084960381192,-3.2566314039454936
437.1000000000055,49.24175068280288,-0.5702941098371027,-3.261826014120904
438.0000000000055,49.33060087011981,-0.5752468472227317,-3.2688668026261456
438.9000000000055,49.41934653769488,-0.5787733358492071,-3.276043516996674
439.8000000000055,49.50769785012815,-0.5813855286544052,-3.280214361280087
440.70000000000556,49.596114211093564,-0.5839026308038314,-3.2854296019909697
441.60000000000554,49.68448812938464,-0.5866704677364762,-3.2912781029866034
442.50000000000557,49.772789611735206,-0.5898253967325973,-3.296274369622424
443.40000000000555,49.86189934629492,-0.5906924815589697,-3.2995277360548574
444.3000000000056,49.950820359346174,-0.5933048673577911,-3.303552500796096
445.2000000000056,50.039825723449134,-0.5947505693179783,-3.30819717457304
446.1000000000056,50.12679341783609,-0.5962637024425579,-3.3135057884925176
447.0000000000056,50.21603048770288,-0.5970044518435671,-3.3165738309320627
447.90000000000566,50.304510509704706,-0.5975477899354642,-3.3228559173005134
448.80000000000564,50.392680660051255,-0.5988678502867295,-3.324204461640853
449.7000000000057,50.48134679148698,-0.5996045337258076,-3.327530278011398
450.6000000000057,50.56999405143785,-0.5990999809812869,-3.33028632070885
451.5000000000057,50.65850261512208,-0.5998561393003562,-3.333530020199871
452.4000000000057,50.74682866825529,-0.5991556832524694,-3.336310745149122
453.3000000000057,50.83423355535101,-0.5985065142658597,-3.3418488976850305
454.20000000000573,50.923089637069964,-0.5984030142666298,-3.3453748987615524
455.10000000000576,51.01196237626735,-0.5979756199147883,-3.3505869423185293
456.00000000000574,51.099550935064016,-0.5978819015809274,-3.3534313580627195
456.9000000000058,51.18787288098352,-0.5974958839513894,-3.3567232491285837
457.80000000000575,51.27615478776528,-0.595685677954752,-3.358555574457027
458.7000000000058,51.36511756927037,-0.596404244144985,-3.3623623868278916
459.6000000000058,51.453421473330636,-0.5940823857074831,-3.366898709877683
460.5000000000058,51.54132376810657,-0.5952659671332076,-3.3697464175664003
461.40000000000583,51.63052437568817,-0.5933157564189744,-3.3724083299976657
462.30000000000587,51.71897709679263,-0.5937562284306052,-3.37516816266442
463.20000000000584,51.80854841691556,-0.5923536056944552,-3.3790566027480153
464.1000000000059,51.896369416923896,-0.5927786634287698,-3.3827891241605164
465.0000000000059,51.98455763353219,-0.5930830963748772,-3.384246045598747
465.9000000000059,52.07258260268202,-0.5932367406689658,-3.3891243909248634
466.8000000000059,52.16168542919004,-0.5922818120674886,-3.393739259284942
467.7000000000059,52.25026534108571,-0.5921623127965286,-3.397238348709502
468.60000000000593,52.33916897991304,-0.5923600786343906,-3.4012897683133216
469.50000000000597,52.42809918011208,-0.5924152965999901,-3.4045641631548147
470.40000000000595,52.51563963280617,-0.5917866139784996,-3.4071578680894907
471.300000000006,52.60630264123974,-0.5919014237590546,-3.4119004597234444
472.20000000000596,52.69456957257514,-0.5922191125665187,-3.413198223653351
473.100000000006,52.78286903335311,-0.5938981549086086,-3.4160384115392386
474.000000000006,52.871331010877505,-0.5940004218035335,-3.4202475904686276
474.900000000006,52.96136228457011,-0.5934022618324609,-3.4229840426222893
475.80000000000604,53.05009066998782,-0.594413600889967,-3.4258940132543616
476.70000000000607,53.13878713520348,-0.5950107092303295,-3.429744454363888
477.60000000000605,53.22789237885753,-0.5974047395067991,-3.431043313121502
478.5000000000061,53.31586355322501,-0.5967148201383544,-3.4349820593610403
479.4000000000061,53.404209904869894,-0.5985438933396029,-3.436822325993554
480.3000000000061,53.49263029800215,-0.6000955677581039,-3.4407001117101093
481.2000000000061,53.58213614439624,-0.6008806772891933,-3.4437415586323867
482.1000000000061,53.67080019202904,-0.6015108196101967,-3.4449722568595487
483.00000000000614,53.75959215644178,-0.601809821457679,-3.447652639037547
483.9000000000062,53.84793532545655,-0.6039015613540369,-3.4489689628838542
484.80000000000615,53.93608585639798,-0.6058033879143309,-3.4514270605068216
485.7000000000062,54.02490269075609,-0.6061880911824709,-3.453555423873367
486.60000000000616,54.11446500690366,-0.6062274891044646,-3.4575594141596224
487.5000000000062,54.200030275144734,-0.6070145394222436,-3.4605130449731245
488.40000000000623,54.2911292989351,-0.6069412958677816,-3.4604690004061345
489.3000000000062,54.380280705589094,-0.6081654762719108,-3.460889911936001
490.20000000000624,54.46916906675569,-0.6092200574354331,-3.4643971450453015
491.1000000000063,54.558241341323246,-0.6090259526695267,-3.4644209677424485
492.00000000000625,54.64664846214853,-0.6116416977968495,-3.4670598566248554
492.9000000000063,54.73447599011066,-0.6106588517702974,-3.469060269097936
493.8000000000063,54.823424348317864,-0.6128620059947879,-3.4697587498675517
494.7000000000063,54.91217079195598,-0.6112201728955977,-3.471915482737707
495.60000000000633,55.001901027415926,-0.6108306805254939,-3.471335049590821
496.5000000000063,55.08966787533395,-0.6123176057409733,-3.4730922041243293
497.40000000000634,55.17897923390994,-0.6105204389397788,-3.474412978971894
498.3000000000064,55.26865032165303,-0.6103166014843058,-3.4757309043325018
499.20000000000636,55.35588603290634,-0.6102024987442252,-3.48151064818593
500.1000000000064,55.445751811081706,-0.6119693078419727,-3.4804639059780724
501.00000000000637,55.53296686947895,-0.6118480443468401,-3.480452172520886
501.9000000000064,55.62413307844109,-0.6122280148166621,-3.4814550407976426
502.80000000000643,55.711800520694915,-0.6113855728872905,-3.4814454299186135
503.7000000000064,55.80198505158793,-0.6118599858525887,-3.484060155812317
504.60000000000645,55.8904863279964,-0.6100106286184875,-3.4853941991174477
505.5000000000065,55.97917000000067,-0.6121400000000592,-3.4863762714061988
506.40000000000646,56.06854482154225,-0.6110981229047672,-3.487699411253236
507.3000000000065,56.15831941856705,-0.6119874847817388,-3.4864562650850806
508.2000000000065,56.246904258100656,-0.6104573748375829,-3.4877474079104847
509.1000000000065,56.33575267343572,-0.60938201508573,-3.489096093738307
510.00000000000654,56.42455909390509,-0.6100903130424392,-3.4827513552194986
510.9000000000065,56.51335899843713,-0.6095889109077467,-3.4895001947513604
511.80000000000655,56.60139825865358,-0.6093006266534362,-3.4912145741084193
512.7000000000066,56.69115364347062,-0.60905275616772,-3.48989063500655
513.6000000000065,56.780211629976776,-0.6084047155736607,-3.4911865777025644
514.5000000000066,56.869264144252,-0.6082530566853438,-3.4938403277929697
515.4000000000066,56.95875842826263,-0.6091935627683551,-3.4925174600830857
516.3000000000065,57.04695424094995,-0.6091703437838453,-3.492520084591754
517.2000000000066,57.13597823070512,-0.609552608946425,-3.4938371568704962
518.1000000000066,57.225200705148055,-0.6080498126316881,-3.4938490493134076
519.0000000000066,57.313296189280926,-0.6074833410398759,-3.4978926277685036
519.9000000000067,57.40201119219886,-0.6074686345385732,-3.4993490844240855
520.8000000000067,57.49214286291902,-0.6080576747444272,-3.500516663962639
521.7000000000066,57.58052044534275,-0.6074074595551006,-3.49945875672358
522.6000000000067,57.67008489802058,-0.6070063597376314,-3.4994400488243667
523.5000000000067,57.758773900131374,-0.6068606408843106,-3.49936942922327
524.4000000000067,57.84804683240083,-0.6069137033518319,-3.4983973446904013
525.3000000000068,57.93489048045711,-0.6054540944623634,-3.5017484496690914
526.2000000000068,58.02594018414217,-0.6048017192522883,-3.500438458422021
527.1000000000067,58.115226576119206,-0.6076864853793285,-3.500441463170805
528.0000000000068,58.20401060187238,-0.6067846230311125,-3.501746755186299
528.9000000000068,58.29370182892515,-0.6064450674133695,-3.5051804876569745
529.8000000000068,58.381410876272355,-0.6067310132017625,-3.507026037002192
530.7000000000069,58.471525365057,-0.6056483410201892,-3.50718887683
531.6000000000068,58.56034599452891,-0.6057444907530136,-3.509665517757699
532.5000000000068,58.64866901049589,-0.6042194287455565,-3.5083399040915086
533.4000000000069,58.73839014395597,-0.6057847357573223,-3.510149068967147
534.3000000000069,58.82768008051851,-0.6040778731345582,-3.5119778180174723
535.2000000000069,58.91737297912799,-0.6040822153785469,-3.5119600990730557
536.100000000007,59.00552370534059,-0.6035416272159879,-3.5132689429937223
537.0000000000069,59.09453007087208,-0.6022354545784372,-3.5132694372354347
537.9000000000069,59.18348364721216,-0.6029561205343139,-3.513279978999
538.800000000007,59.272335811590025,-0.6024238521734889,-3.5159041493135463
539.7000000000069,59.36221511263041,-0.602034964755903,-3.515959630412279
540.600000000007,59.45172441957676,-0.6020410005815537,-3.5149311266035284
541.500000000007,59.541737109105114,-0.6004126708473061,-3.5162500078166987
542.4000000000069,59.630757286664256,-0.6018137683852809,-3.5162418676648355
543.300000000007,59.72019929882127,-0.6019939463511386,-3.517228982662858
544.200000000007,59.80916906346799,-0.6002400316708504,-3.517559815530035
545.100000000007,59.89814040961531,-0.5998970062255202,-3.5187982225272108
546.000000000007,59.987578352902155,-0.5996648885050246,-3.5198666128512492
546.900000000007,60.07693429425836,-0.600517741371686,-3.5211906732190887
547.800000000007,60.16594378665435,-0.5971494563499776,-3.5211786999831522
548.7000000000071,60.25593814394245,-0.5987635922682485,-3.5224999839935114
549.6000000000071,60.3450123992951,-0.59857454132807,-3.523815424588883
550.500000000007,60.43465244699869,-0.5980058371409995,-3.522513766403468
551.4000000000071,60.52415969552051,-0.5991936852957002,-3.5236517520672517
552.3000000000071,60.61292954133403,-0.5996544374591384,-3.523820129187196
553.2000000000071,60.702585817198376,-0.5979786512042861,-3.5238202123859903
554.1000000000072,60.79158396715929,-0.5987241178625935,-3.5251273541079913
555.0000000000072,60.88096940501066,-0.5992490073902437,-3.5264439413558746
555.9000000000071,60.971031012928655,-0.5987221219165771,-3.527905388338498
556.8000000000072,61.060214169521764,-0.5999315540820466,-3.5304340037460125
557.7000000000072,61.14980714839531,-0.599077265784324,-3.5290899895849206
558.6000000000072,61.239266976424105,-0.6014487798966086,-3.5300707589016165
559.5000000000073,61.32896645127603,-0.6004336762589259,-3.530069849583417
560.4000000000073,61.41867164694362,-0.6004884668753863,-3.5303727418456567
561.3000000000072,61.5079840307031,-0.6025238850814947,-3.5317198922730353
562.2000000000073,61.598046916655555,-0.6032458830514694,-3.530397582524066
563.1000000000073,61.68701903718087,-0.6054841944685324,-3.530355045773336
564.0000000000073,61.776636550693574,-0.6050821797660726,-3.5335014655493246
564.9000000000073,61.86341566532146,-0.6047686509624417,-3.5357796295130957
565.8000000000073,61.954877069208344,-0.6057952641357036,-3.5347522452326645
566.7000000000073,62.043441400911604,-0.6056634696241932,-3.5361114428546343
567.6000000000073,62.1340907528922,-0.605405472697684,-3.53742979631434
568.5000000000074,62.22281252391295,-0.6077863012875666,-3.537732407990168
569.4000000000074,62.310766969692345,-0.6077697582498176,-3.5387491793250603
570.3000000000073,62.40105384921313,-0.6099497353234806,-3.5384246795017207
571.2000000000074,62.49096098638186,-0.6111988427687987,-3.5374299364621464
572.1000000000074,62.57935455889819,-0.6107340249471321,-3.536786177794526
573.0000000000074,62.669170000000705,-0.6113199999999785,-3.5374299361039223
573.9000000000075,62.75835281051871,-0.6108340461802718,-3.5387561952114424
574.8000000000075,62.84834558134268,-0.6101926772604136,-3.540004819985519
575.7000000000074,62.93606795813079,-0.6091289575959062,-3.5386730209218427
576.6000000000074,63.02645044377384,-0.6066812892301826,-3.5399745818128823
577.5000000000075,63.11506412141804,-0.6068315328549693,-3.5413863038187587
578.4000000000075,63.20417306406814,-0.6050571313218249,-3.540059824022926
579.3000000000075,63.29344447560781,-0.6035868509979758,-3.5413809306664787
580.2000000000075,63.38235541452929,-0.6029172899475749,-3.5417104776144663
581.1000000000075,63.473235648316134,-0.6039401479126304,-3.5420455582451336
582.0000000000075,63.56238484820155,-0.6020873509809265,-3.5426898951894676
582.9000000000076,63.6511715177568,-0.601629275683865,-3.541724320838953
583.8000000000076,63.74149863171614,-0.6016611636038335,-3.5418705773149832
584.7000000000075,63.82980533126096,-0.600228736494928,-3.543054427535952
585.6000000000076,63.920739848979466,-0.5996413902318006,-3.54434062664683
586.5000000000076,64.00864998272426,-0.5988223189091831,-3.5443381296079233
587.4000000000076,64.09916804979895,-0.5977600503910352,-3.545010171495515
588.3000000000077,64.18879094339198,-0.596016702487752,-3.5450102000451835
589.2000000000077,64.2774308461125,-0.5962758059646713,-3.5450102962262964
590.1000000000076,64.36654488880755,-0.5947010228751575,-3.5443454515692214
591.0000000000077,64.45590816145143,-0.59400709920084,-3.545141765461674
591.9000000000077,64.54526110964305,-0.5928308116255357,-3.5453299524075863
592.8000000000077,64.63483040580813,-0.5923122941582416,-3.54550717573459
593.7000000000077,64.72440483209326,-0.592318090954392,-3.5464796391784974
594.6000000000078,64.81388771506296,-0.592343744063105,-3.5456955741155483
595.5000000000077,64.90296988288672,-0.5911994148519518,-3.545645583230937
596.0000000000077,64.95325252583164,-0.5918633531209693,-3.5466625901227653