File: 01_Data/Rebond_Foam_Carpet_Pad/STA/N2/10K_min/Rebond_Foam_Carpet_Pad_STA_N2_10KData_221017_R3.csv
##Temp./Â°C,Time/min,DSC/(mW/mg),Mass loss/mg
51.0,10.77,-1.65137,-0.01139131627402401
51.90000000000001,11.08554270800177,-1.5403819204486475,-0.012271544662853184
52.800000000000026,11.303693118860037,-1.460619136147835,-0.010550382875835318
53.70000000000004,11.48418387264117,-1.4014958700715383,-0.010867276974091844
54.60000000000005,11.645313080070114,-1.351971747191834,-0.011377654599317832
55.500000000000064,11.795213197966728,-1.3110774664448857,-0.010509429266743808
56.40000000000008,11.935165373218679,-1.2779962662238522,-0.011495649515484985
57.30000000000009,12.06958175442014,-1.2490240862207331,-0.01129630368529222
58.2000000000001,12.19966701695042,-1.2230118849732483,-0.011059972793775241
59.100000000000115,12.323229328013326,-1.20081960513864,-0.009684075095008904
60.00000000000013,12.44598579712655,-1.1824806246102233,-0.011018260554196413
60.90000000000014,12.56599028737946,-1.163279204575469,-0.011294277383224749
61.80000000000015,12.681867274666326,-1.1468004543369017,-0.009845754267685969
62.700000000000166,12.792490918701603,-1.1341950014635929,-0.01075791780811608
63.60000000000018,12.910000000000023,-1.1204899999999987,-0.009921133366366686
64.5000000000002,13.022505583822133,-1.107012446361075,-0.010277226334661993
65.4000000000002,13.13261974653915,-1.0938931868214283,-0.011956177989878913
66.30000000000021,13.241855441887637,-1.082065702570655,-0.010921361809959507
67.20000000000023,13.349080094996765,-1.0714785647855773,-0.011657895591683953
68.10000000000025,13.456243010147466,-1.060826966593976,-0.011970508377754818
69.00000000000026,13.56156813629171,-1.0497787303986272,-0.011117638390777618
69.90000000000026,13.665554391177183,-1.038606194355223,-0.009738240121348607
70.80000000000028,13.770374890749832,-1.0270537904937975,-0.01238630292720222
71.7000000000003,13.872965556900432,-1.0186050772468642,-0.013737974655360308
72.6000000000003,13.974844137905501,-1.0086644653587051,-0.012369604143679602
73.50000000000031,14.073694265507005,-0.9995286056810571,-0.012252596035862595
74.40000000000033,14.176146607602165,-0.9891586244520538,-0.012346615731051003
75.30000000000035,14.276240315195823,-0.9809746868243253,-0.014913820941761635
76.20000000000036,14.377749304673937,-0.9719782211492942,-0.013761091257980418
77.10000000000036,14.47404461885665,-0.9635447318175918,-0.013331482754365798
78.00000000000038,14.57336402621453,-0.9561825098460398,-0.012404090810170132
78.9000000000004,14.67307564537153,-0.948158824686126,-0.012424778534961156
79.80000000000041,14.769508983034797,-0.9410030469596524,-0.013774775514349802
80.70000000000041,14.865911711439006,-0.9324550224300535,-0.01372854452844452
81.60000000000043,14.962100647759954,-0.9260390857732701,-0.01375834237831386
82.50000000000045,15.058557447605372,-0.9202616936028983,-0.013718946492176531
83.40000000000046,15.1538974811073,-0.9137550177782301,-0.013719647874530061
84.30000000000047,15.247954805163975,-0.9075717266422503,-0.013695445719105859
85.20000000000049,15.34223398539809,-0.9013125598976188,-0.013997663598158905
86.1000000000005,15.436962248312334,-0.8957288555858804,-0.014888310186660814
87.00000000000051,15.52971426014013,-0.8883624224039535,-0.015021227943765147
87.90000000000052,15.624410273922251,-0.8823855065053748,-0.01514548093624235
88.80000000000054,15.71850369856109,-0.8760946827298113,-0.016365731656473148
89.70000000000056,15.81091184835081,-0.8681499091247519,-0.015966667168197723
90.60000000000056,15.902336408572978,-0.8617755782672938,-0.014595325316047791
91.50000000000057,15.994158199188796,-0.8543696412343552,-0.013773909632115888
92.40000000000059,16.08598855899586,-0.8480005788347602,-0.01546794228623316
93.30000000000061,16.177161558121576,-0.8414340457292545,-0.015231746144432456
94.20000000000061,16.26910381014903,-0.8338857930104834,-0.015074494369562874
95.10000000000062,16.360000000000067,-0.8280499999999889,-0.016038205241855064
96.00000000000064,16.450881165026424,-0.8202867000601632,-0.01576944207398423
96.90000000000066,16.539469487965427,-0.8141847433720044,-0.015032459077819027
97.80000000000067,16.630505163993444,-0.8092468041989965,-0.01503876045766983
98.70000000000067,16.719073560637778,-0.8042300740221786,-0.015039287253320932
99.60000000000069,16.81127245135898,-0.7957189491989985,-0.01499880618949545
100.50000000000071,16.898997053456863,-0.7891610593418027,-0.015049961729325378
101.40000000000072,16.989513629102767,-0.7850707712878993,-0.01507691572260228
102.30000000000072,17.077883478109,-0.7784133622995426,-0.01503984615686571
103.20000000000074,17.166953361783595,-0.7739273695255445,-0.016476197631571488
104.10000000000076,17.25621095154931,-0.7694430620719854,-0.01636616823165271
105.00000000000077,17.345496443089743,-0.7642574524125589,-0.016359260937005793
105.90000000000077,17.434364335247576,-0.758507385211274,-0.01765980639387088
106.8000000000008,17.522959189086926,-0.7542748254253929,-0.016360167040551765
107.70000000000081,17.610197692014456,-0.7481600665361854,-0.01504488611342758
108.60000000000082,17.70043334919262,-0.744828556324389,-0.016361562651396877
109.50000000000082,17.788362479406445,-0.7396504711395777,-0.01632244868042365
110.40000000000084,17.878184587041417,-0.7329438112961315,-0.016360150844584975
111.30000000000086,17.964584795482757,-0.727849291459766,-0.016608857293064716
112.20000000000087,18.05341416170491,-0.72398682868108,-0.01774666672336611
113.10000000000088,18.140370487396208,-0.718899033308032,-0.01635903087952295
114.0000000000009,18.229476990682656,-0.714851157932845,-0.017681046937374933
114.90000000000092,18.317804305163435,-0.7103302851858408,-0.01635306753793131
115.80000000000092,18.40526376601341,-0.7048117376333715,-0.01767127444619554
116.70000000000093,18.49346618375778,-0.7007059930698453,-0.018060976164747
117.60000000000095,18.581434173351095,-0.6943570925071468,-0.01871577024651172
118.50000000000097,18.669275992038408,-0.6887123624870941,-0.017683371281651095
119.40000000000097,18.756609981778247,-0.6830553088527737,-0.018999412770304147
120.30000000000098,18.843649352360046,-0.6777510259372765,-0.018981818134750306
121.200000000001,18.930415234311344,-0.6749576339528809,-0.01832629420626608
122.10000000000102,19.01979636401214,-0.6707255666288409,-0.018990734130285514
123.00000000000102,19.10560289389727,-0.6674091913986328,-0.017725359080076775
123.90000000000103,19.19306745536099,-0.6670808362911959,-0.017682357495184764
124.80000000000105,19.2800948446272,-0.6624707804456836,-0.01767909634883935
125.70000000000107,19.368041077655736,-0.6589622048356621,-0.019031908036258205
126.60000000000107,19.45502857288738,-0.6573012010969923,-0.017680038406830523
127.50000000000108,19.541259436382198,-0.6562267273390537,-0.01768006591421134
128.4000000000011,19.628880487013028,-0.6523029073532803,-0.018604296928416364
129.30000000000112,19.71604544461934,-0.6490589133107928,-0.019990886399518626
130.20000000000113,19.802624016753953,-0.6462427494232839,-0.01898226432921879
131.10000000000113,19.88895870036476,-0.6421814120020455,-0.01898984691785799
132.00000000000114,19.975911939731684,-0.6388353190844318,-0.018909290121313038
132.90000000000117,20.063947179660957,-0.634386310685922,-0.019617114574585592
133.80000000000118,20.148881627455808,-0.6324068328980625,-0.018999394721565643
134.70000000000118,20.236125005704217,-0.6283638209106945,-0.020309485735885424
135.60000000000122,20.3225033241065,-0.6253128344576089,-0.021047985863083873
136.50000000000122,20.409687274281364,-0.6214442858422795,-0.020309890494277116
137.40000000000123,20.49639885928909,-0.6164778997751901,-0.02028934842453456
138.30000000000123,20.581261133250162,-0.6137027333512202,-0.020299993277468342
139.20000000000124,20.667953526114637,-0.6106693195179458,-0.021613281286473107
140.10000000000127,20.754024340408126,-0.6069241513096776,-0.022620032099943455
141.00000000000128,20.840261147030255,-0.6042948729432794,-0.02261998301019119
141.90000000000128,20.926922540226947,-0.5995427526056799,-0.02262763011663438
142.80000000000132,21.012252477686424,-0.5957258010340518,-0.021325874633737474
143.70000000000132,21.0998998149114,-0.5911268168511812,-0.021299786340869264
144.60000000000133,21.184808022041846,-0.5895761120478773,-0.02262844824757826
145.50000000000134,21.26958521928924,-0.5858237206497217,-0.022666752784322952
146.40000000000134,21.356029762437107,-0.5816177504082556,-0.02360989965341176
147.30000000000138,21.441852022737535,-0.578793807845718,-0.02394783043122617
148.20000000000138,21.527308183960788,-0.5759078889954483,-0.02393981486128638
149.1000000000014,21.613464770258613,-0.5710046057485644,-0.025272565162675953
150.00000000000142,21.699321858363827,-0.5673819502618633,-0.025249832852457743
150.90000000000143,21.784847989174356,-0.5635135328523773,-0.025308834602484342
151.80000000000143,21.87165273100234,-0.5590627980953107,-0.02557992978404311
152.70000000000144,21.956290807840276,-0.5545159981592407,-0.025250259581413026
153.60000000000144,22.041985038283745,-0.5516501695433224,-0.025156791019516955
154.50000000000148,22.12646339868517,-0.5465340389751512,-0.02393100864958253
155.40000000000148,22.21346428108748,-0.5430885094388376,-0.025249241215639984
156.3000000000015,22.298844032230786,-0.5388039167589652,-0.0255786880293023
157.20000000000152,22.38429255666287,-0.5355924098433869,-0.02655592059573708
158.10000000000153,22.47009534550491,-0.532018093429423,-0.026570191026270784
159.00000000000153,22.553836449519093,-0.5293699054595232,-0.0278864963503187
159.90000000000154,22.640001047146686,-0.5268699988564653,-0.027880180002608057
160.80000000000155,22.72626831017353,-0.5240861263991581,-0.02657171943677339
161.70000000000158,22.812519071344482,-0.5231811404278697,-0.02656989404077592
162.6000000000016,22.896521459062956,-0.5203358023436374,-0.027885970668894533
163.5000000000016,22.98382536510873,-0.517015759880107,-0.027884880939953227
164.40000000000163,23.067213967586095,-0.5162987996241694,-0.027556989865188175
165.30000000000163,23.15327450256511,-0.5133096239924719,-0.028879525015458096
166.20000000000164,23.23824801052551,-0.5108425646535756,-0.029251181785788116
167.10000000000164,23.325221970141754,-0.5076456181733706,-0.02986663150460167
168.00000000000165,23.40959615707563,-0.5050541332976843,-0.029931915756157945
168.90000000000168,23.496005090130804,-0.5009796579972442,-0.03117987667702682
169.8000000000017,23.58040453511433,-0.4973801558057975,-0.031178033100696112
170.7000000000017,23.667134701445452,-0.49651431190557865,-0.03377956590230413
171.60000000000173,23.753639766809975,-0.49291090731096737,-0.03251761130127706
172.50000000000173,23.83768917637146,-0.48902979632707577,-0.032507788867662146
173.40000000000174,23.923986731834034,-0.4856980244671373,-0.033930233396666676
174.30000000000175,24.008378201550535,-0.48177840030400515,-0.0339433161814382
175.20000000000175,24.09356171377855,-0.48054252983482293,-0.03395102924853166
176.10000000000178,24.17982433026775,-0.4772679440402082,-0.03525044505851094
177.0000000000018,24.265165470796454,-0.4739662712100632,-0.03555260201653487
177.9000000000018,24.349797348230787,-0.47097284340379253,-0.03556986813013108
178.80000000000183,24.43582103651816,-0.46840986265101636,-0.03559693308028633
179.70000000000184,24.52180756012562,-0.46650951008169733,-0.0378704937639216
180.60000000000184,24.604650382187533,-0.46217238149300416,-0.03852887599178034
181.50000000000185,24.692035711076635,-0.4596250033834609,-0.03852756900237919
182.40000000000185,24.778752735886947,-0.45733339876232615,-0.03885839784163192
183.3000000000019,24.86265657704154,-0.4542811105823662,-0.04018020078809492
184.2000000000019,24.94827323718092,-0.45145310457607185,-0.04018017995150691
185.1000000000019,25.031689130371422,-0.4493532344011524,-0.04035462464474193
186.00000000000193,25.11971245559098,-0.44807884657526903,-0.04346907406630507
186.90000000000194,25.205307878461472,-0.4437311957199936,-0.04348002058299105
187.80000000000194,25.28906340838018,-0.44116199675046736,-0.0436425415873809
188.70000000000195,25.37525505169549,-0.43873147193906853,-0.04420373727856175
189.60000000000196,25.459744838567456,-0.43695831438933264,-0.045789211443488576
190.500000000002,25.545153270479673,-0.4339143535924664,-0.04764999200393172
191.400000000002,25.630914178495054,-0.43055426549318515,-0.047649981999914104
192.300000000002,25.716152264500373,-0.4284339947097952,-0.047649981929991814
193.20000000000203,25.802841309856298,-0.4237081745765814,-0.04765870478508294
194.10000000000204,25.886137321743917,-0.42255660887755614,-0.048970107725144096
195.00000000000205,25.972549051187347,-0.4200552804194967,-0.048965709673675306
195.90000000000205,26.056243838065686,-0.4169811234002075,-0.05153331164829167
196.80000000000206,26.14250612998627,-0.4144404092418738,-0.051600082422325944
197.7000000000021,26.227193353239667,-0.4112797455296583,-0.05158932486787293
198.6000000000021,26.311809788063947,-0.40779822546088346,-0.054228265722475744
199.5000000000021,26.39723930203617,-0.4051137462482517,-0.05423003684454386
200.40000000000214,26.482740664591464,-0.4005091670256899,-0.05524682335247055
201.30000000000214,26.568315888660667,-0.39862439179579123,-0.05687100200232109
202.20000000000215,26.653511204700596,-0.3953541976967247,-0.05781825274050689
203.10000000000215,26.73889764548705,-0.390768189736982,-0.05819016955215428
204.00000000000216,26.82430133001773,-0.3886559144348694,-0.05953058374871523
204.9000000000022,26.905607953107747,-0.3866709159614884,-0.060834296315622094
205.8000000000022,26.993984258378983,-0.38191493333474624,-0.0621506427056997
206.7000000000022,27.080093378886595,-0.37999120419573296,-0.0634599053822158
207.60000000000224,27.164549211384607,-0.37523098881192407,-0.06344970390583837
208.50000000000225,27.25000000000024,-0.3722899999999747,-0.06609013127516361
209.40000000000225,27.33590436676824,-0.3683064909170058,-0.068697658919739
210.30000000000226,27.421481162249883,-0.3643178974593318,-0.06982179932695809
211.20000000000226,27.50661541985942,-0.36134633240169345,-0.07003713752469265
212.1000000000023,27.59108679885847,-0.35673817026350296,-0.07134793441816978
213.0000000000023,27.676523609711,-0.35412415177789275,-0.07333921747024208
213.9000000000023,27.76058074979544,-0.3493586609140029,-0.07464997747214053
214.80000000000234,27.846245908180002,-0.34558228998071877,-0.075965586965693
215.70000000000235,27.93368517070645,-0.34146905422288404,-0.07728979759963428
216.60000000000235,28.019250837515372,-0.3371308597471114,-0.07856881232097646
217.50000000000236,28.105075333853623,-0.3350788983175747,-0.08059244283769251
218.40000000000236,28.190303392789126,-0.33015594954436556,-0.0842362693257468
219.3000000000024,28.274533290614148,-0.3253261635072934,-0.08578350020653591
220.2000000000024,28.3597088544786,-0.3224315576775343,-0.0858084831962187
221.1000000000024,28.445959704366366,-0.3172126500905686,-0.08915286346262041
222.00000000000244,28.53216412759316,-0.3126770305001834,-0.09130910507485046
222.90000000000245,28.61735662984288,-0.30929085814882895,-0.09329620441869846
223.80000000000246,28.702148790355768,-0.3043703025785212,-0.09573693531341032
224.70000000000246,28.787675113417507,-0.3001534739603898,-0.09781221618655733
225.60000000000247,28.873705581204796,-0.29634499762211136,-0.10047352914841179
226.5000000000025,28.958247057379545,-0.2920319861251057,-0.10375110893748918
227.4000000000025,29.044156357361743,-0.2862390249077551,-0.10526267058124983
228.3000000000025,29.129640872241012,-0.28117642640862234,-0.10869631593596507
229.20000000000255,29.21549916625841,-0.27474981117252884,-0.11139613038571872
230.10000000000255,29.30077613264463,-0.27020558979918785,-0.11408882480351412
231.00000000000256,29.38624406317721,-0.2645178612850148,-0.11543709392499935
231.90000000000256,29.472500754054277,-0.2588159252683461,-0.12147338307266553
232.80000000000257,29.55739131815979,-0.25297997980095466,-0.12329697384830451
233.7000000000026,29.644471763822786,-0.24624605464969387,-0.12640312117767882
234.6000000000026,29.728246146574723,-0.24191150560594113,-0.12768613106806148
235.50000000000261,29.814143096666086,-0.23543279910274584,-0.130563972080747
236.40000000000265,29.900983771346205,-0.22891197950952347,-0.13486864247394914
237.30000000000265,29.98617699348978,-0.22479487746963084,-0.13863575198993017
238.20000000000266,30.071687188170845,-0.21921602901265383,-0.14149695897425296
239.10000000000267,30.158154439101054,-0.2117749142819425,-0.14461813554455416
240.00000000000267,30.243008752154743,-0.2059676604815713,-0.14915979156969916
240.9000000000027,30.327795139421802,-0.19954306113550085,-0.1544937895390226
241.8000000000027,30.41424953576109,-0.19254115096616137,-0.15755881750945466
242.70000000000272,30.499330711259542,-0.18616161705702336,-0.1602979841847625
243.60000000000275,30.583344046219207,-0.17705004535617944,-0.16467368450878483
244.50000000000276,30.67159599680556,-0.16788377349186862,-0.16797543251809843
245.40000000000276,30.757618980769323,-0.1557179131495966,-0.17281127970101595
246.30000000000277,30.84160031519345,-0.14237859102009048,-0.17716985437960853
247.20000000000277,30.928308232928632,-0.13052504877134857,-0.18106102514733013
248.1000000000028,31.0136285505206,-0.1154993849972014,-0.18478984427645884
249.0000000000028,31.099263859992345,-0.10801918296997047,-0.18846512069708687
249.90000000000282,31.185948669694792,-0.11012404555519709,-0.1928031259588585
250.80000000000285,31.270611733129456,-0.11468913267473395,-0.1975364877594612
251.70000000000286,31.356560571135144,-0.11941984041963655,-0.20257663801492942
252.60000000000286,31.440429800536382,-0.12236592519061981,-0.2074267827214693
253.50000000000287,31.527171955425743,-0.12262456423312984,-0.211386176483356
254.40000000000288,31.61246513605447,-0.12091066614839317,-0.2158029398441017
255.3000000000029,31.699172294960984,-0.11973283434104465,-0.22053301505520784
256.2000000000029,31.784044577793026,-0.11704160848197458,-0.22764362934194482
257.1000000000029,31.86972859206849,-0.11398255479871768,-0.23260490904676123
258.00000000000296,31.95699286721762,-0.11004263410992826,-0.2384949867682189
258.90000000000293,32.041036104320305,-0.10329425957028436,-0.24471752107558453
259.80000000000297,32.12708337150042,-0.09870450131700342,-0.24957748528228718
260.700000000003,32.21380201686438,-0.09306878205309034,-0.2573887643466839
261.600000000003,32.298435273128725,-0.0862226700074694,-0.26199056976415624
262.500000000003,32.38468155212696,-0.07664351217846277,-0.2691594205574881
263.40000000000305,32.47131545573935,-0.07100519759890683,-0.27573291243863807
264.300000000003,32.55486780884664,-0.06366378528345809,-0.28343862092891836
265.20000000000306,32.64269184099768,-0.0550818585320641,-0.2913791685471234
266.1000000000031,32.72475476506061,-0.048790807521164,-0.29558850725624275
267.00000000000307,32.81399586263151,-0.03985573901767297,-0.30452349464445927
267.90000000000305,32.90035510200033,-0.033308369589247266,-0.3121458165217499
268.8000000000031,32.98568884214228,-0.025315444721016878,-0.31992278761214177
269.7000000000031,33.071468862491265,-0.014844097778197953,-0.3283036297902169
270.6000000000031,33.1575349508297,-0.004356748418019603,-0.3363800954837046
271.5000000000031,33.243371801813126,0.005027897454132682,-0.34432889850651316
272.40000000000316,33.329484827466615,0.016659682420908088,-0.3542592030459537
273.30000000000314,33.41466138601489,0.028561654203772914,-0.3633243229732406
274.2000000000032,33.50130765130867,0.04270894157084748,-0.37232485491805845
275.1000000000032,33.587629380879115,0.05429779439488347,-0.38265276641484336
276.0000000000032,33.67319973981324,0.06692658273925772,-0.3947356326935574
276.9000000000032,33.75848460875105,0.08109389733649923,-0.4050523488300275
277.80000000000325,33.84501326111552,0.09549394830401904,-0.41596311251706286
278.70000000000323,33.931666758202944,0.1087235892598492,-0.42885266016727286
279.60000000000326,34.01607581502816,0.1237893643393929,-0.4398969360840925
280.5000000000033,34.10341364429414,0.13635140390721892,-0.4518477141302757
281.4000000000033,34.18952572248409,0.14993120002303176,-0.46334699549617175
282.30000000000325,34.27534300153785,0.1625351761984164,-0.4753097850532697
283.2000000000033,34.36202524745106,0.17694791902474188,-0.49045474850653514
284.1000000000033,34.446879002181646,0.1855628062782705,-0.5020855527084107
285.0000000000033,34.53416063327632,0.19613197903227378,-0.5162363283164626
285.90000000000333,34.6191565916219,0.20725141666900854,-0.5283115354835504
286.80000000000337,34.70544818799275,0.21605108387269945,-0.5432193444862317
287.70000000000334,34.7924589825699,0.22493639726287318,-0.5539786806355935
288.6000000000034,34.87847205234105,0.23190816676535875,-0.5683476919783534
289.5000000000034,34.96447306052719,0.23564944022469383,-0.582083867061221
290.4000000000034,35.050335804551544,0.24049117109786516,-0.597089270878854
291.3000000000034,35.13614234389386,0.24051250721939427,-0.6118075509305503
292.20000000000346,35.222200508108436,0.2384999463532836,-0.6254984834040065
293.10000000000343,35.30828666143825,0.2342969479062338,-0.6409003000028979
294.00000000000347,35.39503146642463,0.22382423442126137,-0.6542414820037417
294.9000000000035,35.48051195249163,0.20769917959934844,-0.6695329194278679
295.8000000000035,35.5670421091301,0.18969471902395885,-0.6817443248199933
296.70000000000346,35.65246992740537,0.16698757920248725,-0.6965235012096884
297.6000000000035,35.739713804618795,0.14157620526981937,-0.7105546495357626
298.5000000000035,35.825790781000926,0.1166830155490019,-0.7239983148678157
299.4000000000035,35.911793363173445,0.09393685321884744,-0.7353346476094544
300.30000000000354,35.997975181387766,0.07213774429168834,-0.7466069014168881
301.20000000000357,36.08384957020542,0.05370072391042801,-0.7605993151534096
302.10000000000355,36.17010222424434,0.035859423483445826,-0.7715943714168105
303.0000000000036,36.25658587227621,0.018193087877109698,-0.7838848165718626
303.9000000000036,36.3423092797271,0.0045543003395267624,-0.7946967178078865
304.8000000000036,36.42777207381301,-0.008149765194647413,-0.8047925921850085
305.7000000000036,36.51391407681907,-0.01987139230974162,-0.8144573452221153
306.60000000000366,36.600526076671166,-0.03249046576707724,-0.8247405976460604
307.50000000000364,36.686865280810096,-0.04387881711230834,-0.8351268002305061
308.4000000000037,36.772036724996404,-0.05552139542351579,-0.8437907429231957
309.30000000000365,36.85779013116342,-0.06506830259614281,-0.8534662046069141
310.2000000000037,36.94555366867989,-0.07612478766353534,-0.8636254150129972
311.1000000000037,37.03090120147447,-0.08597644283082868,-0.8736054032849245
312.0000000000037,37.117439908985645,-0.09560090935955046,-0.8825497256129489
312.90000000000373,37.20360830230216,-0.10576306194771821,-0.8895377139104026
313.8000000000037,37.291046930311396,-0.11653489941565008,-0.8973649271574922
314.70000000000374,37.376894696509936,-0.12653759072964396,-0.906177300173066
315.6000000000038,37.462006286070086,-0.1357927366046706,-0.9138729297721442
316.50000000000375,37.54841426715744,-0.14491856973772296,-0.9207878452947456
317.4000000000038,37.63605798392071,-0.15388737751946754,-0.9294380037781287
318.3000000000038,37.721182360213454,-0.16463113535451757,-0.9370897738044168
319.2000000000038,37.80810838544292,-0.17184423014796332,-0.9454837403892493
320.10000000000383,37.89341465296557,-0.17864458582887283,-0.9508222759006304
321.00000000000387,37.980779236839055,-0.18884026755325267,-0.9583898471403862
321.90000000000384,38.06608508637076,-0.1968042856328098,-0.9647918809050671
322.8000000000039,38.154190740325504,-0.20290390694363458,-0.9734333624432967
323.70000000000385,38.2399039388111,-0.20975844574969854,-0.9798090078491901
324.6000000000039,38.32546859099124,-0.21589673208241966,-0.9863755584889398
325.5000000000039,38.41246377090369,-0.22337449044033578,-0.9934620202234345
326.4000000000039,38.498841654636266,-0.22743352115252224,-0.9999409154377727
327.30000000000393,38.58547881449611,-0.23508035750667117,-1.0066613204649237
328.2000000000039,38.67159967161942,-0.23954465839360756,-1.0130925883288642
329.10000000000394,38.75787692227916,-0.2442257145633793,-1.019658194312826
330.000000000004,38.84510683141171,-0.24852261609505402,-1.029019376044681
330.90000000000396,38.932070490526975,-0.2519406685227873,-1.0358381695534455
331.800000000004,39.01827533970469,-0.25529617657256487,-1.0422575472719555
332.700000000004,39.10538871629047,-0.2602881790611096,-1.0496750031645732
333.600000000004,39.19191664588455,-0.26434904630928885,-1.0559056064243006
334.50000000000404,39.279111400800424,-0.26912395352337437,-1.0620537262150322
335.40000000000407,39.366314170479164,-0.2723282113495726,-1.0686800822144376
336.30000000000405,39.45261434594045,-0.27338821233515204,-1.0759570216826781
337.2000000000041,39.53980678243776,-0.277393130955738,-1.0835533159511876
338.10000000000406,39.62577024601139,-0.2795470076776335,-1.0907020752295629
339.0000000000041,39.713379083390286,-0.28139609063182175,-1.0976991491831973
339.9000000000041,39.799905058960576,-0.28455124709722807,-1.1056267016812575
340.8000000000041,39.884315700704754,-0.2856660134484634,-1.1111616242563827
341.70000000000414,39.97336458473271,-0.289503945327353,-1.1188523052726178
342.6000000000041,40.06036432830305,-0.2903371554755991,-1.1248359534466355
343.50000000000415,40.14686786581178,-0.2923993479331195,-1.131454593352068
344.4000000000042,40.234373081227005,-0.2925342881984027,-1.138726590369827
345.30000000000416,40.31976338059547,-0.2946860186429461,-1.1445778682584167
346.2000000000042,40.40729252015637,-0.2956404706560808,-1.1525059278194396
347.10000000000423,40.49238405980213,-0.2948044003783058,-1.15843061264474
348.0000000000042,40.58081278051058,-0.296397360759189,-1.1663260582938197
348.90000000000424,40.669259885804564,-0.29598634627187254,-1.1723443402927867
349.8000000000043,40.75534303342791,-0.29560243801316555,-1.1789750701064081
350.70000000000425,40.84266270222183,-0.2944570823810735,-1.186093080637706
351.6000000000043,40.927590140498815,-0.2945139853366726,-1.1931442226592384
352.50000000000426,41.01638218645056,-0.29228509591808866,-1.1998192566257617
353.4000000000043,41.10367678369419,-0.28948209368974154,-1.2063416468576311
354.30000000000433,41.18789675594563,-0.28743901649247666,-1.2157756046358497
355.2000000000043,41.27778548414031,-0.28553932264148707,-1.2235789043994285
356.10000000000434,41.364326635041124,-0.2828424089815199,-1.2299262372090491
357.0000000000043,41.45080461667267,-0.27917684199291665,-1.2366207898802979
357.90000000000435,41.53889555916794,-0.27778514567019974,-1.246183736690206
358.8000000000044,41.625922976025905,-0.27200066855260224,-1.2543817904732304
359.70000000000437,41.71373803945043,-0.2703650392199919,-1.2652672790500228
360.6000000000044,41.801060947974044,-0.26556906402193253,-1.2731440017967524
361.50000000000443,41.88765645689466,-0.2598554060134907,-1.2822638047644208
362.4000000000044,41.97509398526733,-0.2573757330793584,-1.2907376517432314
363.30000000000445,42.06177071966682,-0.2522562343417468,-1.2996916068899127
364.2000000000045,42.14846848567244,-0.24824214339667938,-1.3105175913820255
365.10000000000446,42.23696891182664,-0.2420324938380832,-1.3219259835623514
366.0000000000045,42.32050065623506,-0.23782928785778742,-1.3328249050154635
366.90000000000447,42.410394490001465,-0.2322490642316719,-1.3448691038166891
367.8000000000045,42.49701537954992,-0.22446009981333984,-1.3579160840188136
368.70000000000454,42.58448473817071,-0.219122992187903,-1.3714337074331708
369.6000000000045,42.67227577678366,-0.21206137873380645,-1.3860031979660952
370.50000000000455,42.75933004239727,-0.20596833327479008,-1.3988350206993116
371.4000000000045,42.84624765373462,-0.19804486028838258,-1.413965851469837
372.30000000000456,42.9340195989615,-0.18922896730822528,-1.4290222449021406
373.2000000000046,43.02156066761851,-0.1824637691986739,-1.4471045819707924
374.10000000000457,43.10792508050419,-0.17382959034015022,-1.4627639810386954
375.0000000000046,43.19503402523882,-0.16449276131133042,-1.4796291779503106
375.90000000000464,43.28293840963956,-0.1557018010958328,-1.4977891808480348
376.8000000000046,43.370842703766534,-0.14634478389094233,-1.5163914944538948
377.70000000000465,43.45775781842786,-0.1380218848695638,-1.5341546946733966
378.6000000000047,43.54590331804478,-0.1266881832518948,-1.5540664194904177
379.50000000000466,43.63294760328758,-0.1171096863314166,-1.577353028367646
380.4000000000047,43.72058435477949,-0.10474349899414033,-1.5998116349798934
381.3000000000047,43.80860415060275,-0.0948035425942789,-1.6254387913739996
382.2000000000047,43.89587496555335,-0.08415906917030527,-1.6509542538447488
383.10000000000474,43.98393816351373,-0.07177689518482015,-1.675888210354251
384.0000000000047,44.07047768026411,-0.06176379605902939,-1.7040992908087116
384.90000000000475,44.15838600395696,-0.052008501161384474,-1.7307821977892788
385.80000000000473,44.24601116267377,-0.040357189993816524,-1.7586369411561846
386.70000000000476,44.33246901995846,-0.028557932175841377,-1.7872063204347302
387.6000000000048,44.42178423758101,-0.017861165680891,-1.8184984793073626
388.5000000000048,44.50594336476186,-0.006802801313482294,-1.8494537760093186
389.4000000000048,44.5967026889163,0.003864508848736102,-1.8843400169084825
390.30000000000484,44.684108338624036,0.014015651830817566,-1.919626862480285
391.2000000000048,44.77263994939427,0.023141733660320577,-1.9547699883930378
392.10000000000485,44.860609348775675,0.03194582179862018,-1.9912963070534782
393.0000000000049,44.9481704900927,0.0426968709305415,-2.0286597233939627
393.90000000000487,45.03491683819526,0.050340766001959206,-2.066911239934224
394.8000000000049,45.12359717353115,0.0563587821489604,-2.106105874618919
395.7000000000049,45.21159154462559,0.0609392221028792,-2.144613672824595
396.6000000000049,45.298752156156894,0.06471455971970812,-2.183460524778065
397.50000000000495,45.384934586434156,0.06574728023723947,-2.222008762055986
398.4000000000049,45.47351808410593,0.06531256511659664,-2.263262395374228
399.30000000000496,45.5604811856056,0.06108980896973265,-2.301048155038546
400.20000000000493,45.64924335998494,0.05665511741260361,-2.340211434294969
401.10000000000497,45.736970175029086,0.05106016614036141,-2.3792796460518453
402.000000000005,45.82398165093549,0.0441509481637693,-2.416680449358678
402.900000000005,45.913446066745855,0.0332770305478822,-2.4556820284893877
403.800000000005,45.99810819926183,0.02438652443202634,-2.4932601074008476
404.70000000000505,46.08790194357846,0.011074508966692372,-2.5315123686041594
405.600000000005,46.175864257845795,-0.0009621370369020993,-2.5651914212814217
406.50000000000506,46.26355438872094,-0.015975172645538088,-2.601309099879424
407.4000000000051,46.35172253417122,-0.03040991677370167,-2.6366802309658603
408.30000000000507,46.43810287713562,-0.04556432536767183,-2.6696232087120446
409.2000000000051,46.52800082836468,-0.06021423915883168,-2.704129453918598
410.1000000000051,46.61544016192395,-0.07595684932418,-2.733760176170846
411.0000000000051,46.70257292893728,-0.09230839816456372,-2.7646493856841907
411.90000000000515,46.791254151477816,-0.11280080883320721,-2.795893894438179
412.8000000000051,46.87854478126822,-0.12811346423621345,-2.8243583357404063
413.70000000000516,46.966637731164504,-0.14275338858300812,-2.8524398828212485
414.60000000000514,47.054489889717445,-0.16144658827964878,-2.8789848548590427
415.5000000000052,47.14162249663895,-0.17508795482155015,-2.903746674857455
416.4000000000052,47.22899549069462,-0.19292381072632334,-2.927493888042757
417.3000000000052,47.31733748398758,-0.20727806033052623,-2.951932207331995
418.2000000000052,47.40568164268096,-0.2246558256955005,-2.9735796745867047
419.10000000000525,47.492925560410164,-0.23935218405090083,-2.99457055949841
420.00000000000523,47.58066444323996,-0.2540517158342722,-3.0143677141197567
420.90000000000526,47.668997513416095,-0.2673436700789776,-3.033386165378338
421.8000000000053,47.75602089795877,-0.2810833625141642,-3.0516889772031845
422.7000000000053,47.844396111633245,-0.2936405935810144,-3.0686311787863234
423.6000000000053,47.93188853171755,-0.3059459358268631,-3.0858876560580004
424.5000000000053,48.020414794675986,-0.31928276777897335,-3.1018965466191544
425.4000000000053,48.107527953074026,-0.3294394959040057,-3.117320673481193
426.30000000000535,48.19536568771502,-0.34092943324170183,-3.128606518126891
427.20000000000533,48.28382342733986,-0.35239888898543864,-3.1408721479726838
428.10000000000537,48.37144920739615,-0.3633499252705725,-3.1538698968726604
429.00000000000534,48.45916898956766,-0.37222489984132684,-3.166173242595211
429.9000000000054,48.547022092677835,-0.38110984433504946,-3.178943350629036
430.8000000000054,48.635186019486135,-0.3896458115666745,-3.1892627052737472
431.7000000000054,48.72313372198702,-0.40017572672397306,-3.1977103848024857
432.6000000000054,48.812138022990624,-0.4077276248728071,-3.2062974262027186
433.50000000000546,48.89980070211786,-0.41351059506218635,-3.214210801604641
434.40000000000543,48.98766818018898,-0.4195504186806308,-3.2217481118577505
435.30000000000547,49.075806980946474,-0.42639209317158466,-3.2300989502698254
436.2000000000055,49.16367278829443,-0.4316625510874808,-3.2354109989388515
437.1000000000055,49.25201834134527,-0.43563165406690324,-3.242984162391596
438.0000000000055,49.33959859774215,-0.44161682923238377,-3.2480218806503123
438.9000000000055,49.427200464149706,-0.4451708511897314,-3.2512870875038713
439.8000000000055,49.51577051181849,-0.44687672587635907,-3.256346895747023
440.70000000000556,49.6035890584345,-0.45183000248556504,-3.2603366997205367
441.60000000000554,49.69209647257587,-0.4535767098564609,-3.264852397327284
442.50000000000557,49.78009927880401,-0.45596708396668967,-3.2689025712391664
443.40000000000555,49.8680260282405,-0.45897167591967614,-3.272985375684358
444.3000000000056,49.956035507599566,-0.4611164202151255,-3.2788650148590013
445.2000000000056,50.04438703547991,-0.46178628021819584,-3.2841415152647846
446.1000000000056,50.1324489897794,-0.4630711142898596,-3.2887695815161635
447.0000000000056,50.22010221325242,-0.46463815071235703,-3.2910906471496655
447.90000000000566,50.308073434644314,-0.4656787496743435,-3.2947078069025793
448.80000000000564,50.3970547619025,-0.4684557027591645,-3.2976278175082228
449.7000000000057,50.48472174184649,-0.46753816119810143,-3.3010455903755354
450.6000000000057,50.57389558131505,-0.4668592227938573,-3.3067611080330455
451.5000000000057,50.66222018451157,-0.46932001869942463,-3.3102145160208916
452.4000000000057,50.749173879223534,-0.46944702903605257,-3.313925590923603
453.3000000000057,50.83854969830329,-0.46934062208129096,-3.318247058466733
454.20000000000573,50.927468984682775,-0.470364047041403,-3.322431928856455
455.10000000000576,51.01521124090026,-0.4690162684562575,-3.327328467425667
456.00000000000574,51.1038890475069,-0.46927767724198827,-3.3326407225206163
456.9000000000058,51.19231260689905,-0.4704388782182502,-3.3352206835386706
457.80000000000575,51.28010407269943,-0.47062055589509133,-3.3379588942803173
458.7000000000058,51.36990592488453,-0.4700702099666518,-3.342236972330146
459.6000000000058,51.45737380642108,-0.47148290699923034,-3.3447985550027153
460.5000000000058,51.54515147083072,-0.4699613635662876,-3.3483803233327496
461.40000000000583,51.63429559485944,-0.47063098116293006,-3.354197065107558
462.30000000000587,51.723129241424004,-0.47006720165521926,-3.357917330099156
463.20000000000584,51.811153523733125,-0.4700194986776366,-3.3623916170198482
464.1000000000059,51.89908642377203,-0.47045290017246766,-3.3654361940451727
465.0000000000059,51.98767045348296,-0.4699372878154163,-3.368893023757008
465.9000000000059,52.07586425157176,-0.4702349591624222,-3.372510158118793
466.8000000000059,52.16409066486161,-0.4701631334783177,-3.37566583831601
467.7000000000059,52.25315189299991,-0.47065164703028023,-3.38019203300375
468.60000000000593,52.342170504872904,-0.4702344706248742,-3.383337701159843
469.50000000000597,52.43000000000063,-0.47215999999996927,-3.3872499187879623
470.40000000000595,52.5182277588743,-0.4729570011523484,-3.3920445737472664
471.300000000006,52.606809077524396,-0.4727724294701315,-3.3957513788626943
472.20000000000596,52.69558262482758,-0.4737637960606764,-3.3972683395496235
473.100000000006,52.78414437190607,-0.47378166456776,-3.4011402929816685
474.000000000006,52.87266501179921,-0.47516822219042026,-3.4036647779627645
474.900000000006,52.961832424288424,-0.4747685762116143,-3.407315095442732
475.80000000000604,53.048926866922685,-0.4767779397773594,-3.411089375853929
476.70000000000607,53.13780017514113,-0.4780811878501486,-3.414190138341441
477.60000000000605,53.22661858112484,-0.47833568339882077,-3.418750619490762
478.5000000000061,53.3144515600993,-0.47902583372568047,-3.42228509801451
479.4000000000061,53.40325764573266,-0.4812249156171273,-3.424108771765263
480.3000000000061,53.49223852649586,-0.48052877508748804,-3.426312801763828
481.2000000000061,53.58061669675094,-0.48319693445158163,-3.4288589847747026
482.1000000000061,53.66809677758239,-0.4847445220705483,-3.43151486935373
483.00000000000614,53.75748556839292,-0.4881691287469111,-3.4315472405629586
483.9000000000062,53.846309614501685,-0.48910100354206343,-3.4328299793799832
484.80000000000615,53.934321329984485,-0.49046084843961346,-3.4368927537794587
485.7000000000062,54.02364816707784,-0.4923605349368078,-3.440726482149216
486.60000000000616,54.11183619012197,-0.494887935369862,-3.441335728356611
487.5000000000062,54.200209030421675,-0.493849294824657,-3.4434560003273647
488.40000000000623,54.286679175793196,-0.49610877098414086,-3.443446764547293
489.3000000000062,54.37766846102709,-0.4953979256607066,-3.444769172013574
490.20000000000624,54.465487755577705,-0.49795420590998424,-3.4447720203115613
491.1000000000063,54.55442336243922,-0.49814564157619357,-3.447403456874393
492.00000000000625,54.64332797976458,-0.5013591895227637,-3.450061027779371
492.9000000000063,54.731641687047535,-0.5015118862556013,-3.4500448677191335
493.8000000000063,54.820823132985815,-0.499900994221488,-3.4513545463608217
494.7000000000063,54.909373367646644,-0.5016935604194767,-3.4526793912157876
495.60000000000633,54.99579821853849,-0.5014564918333301,-3.4528629948351766
496.5000000000063,55.0859287679923,-0.5017805196573825,-3.4544137819192207
497.40000000000634,55.175938520070886,-0.5025983809111991,-3.4556286901911095
498.3000000000064,55.26242968954002,-0.5055818990914224,-3.455665489584549
499.20000000000636,55.35346819259562,-0.5047380842327736,-3.459671161350824
500.1000000000064,55.438434057237565,-0.5017657835277265,-3.46091035544581
501.00000000000637,55.53090709454117,-0.5031212903310562,-3.4609489947914773
501.9000000000064,55.6177292528247,-0.503403619888437,-3.461690725491672
502.80000000000643,55.708394696176995,-0.5039082151247717,-3.4649676008522605
503.7000000000064,55.79709336436395,-0.5018402871149112,-3.466290116754765
504.60000000000645,55.884937446082446,-0.5031285368702644,-3.46628994402348
505.5000000000065,55.97437829581628,-0.5035051726074102,-3.4662865930116844
506.40000000000646,56.06265210219149,-0.5034982177077233,-3.469035072670176
507.3000000000065,56.15107262252832,-0.503307870712312,-3.470350477673784
508.2000000000065,56.24020797371041,-0.5027756077927111,-3.4716888405731394
509.1000000000065,56.32904104578486,-0.5032142224718609,-3.472330212142202
510.00000000000654,56.41771415140642,-0.5033510055818708,-3.4729283283688837
510.9000000000065,56.50642809493891,-0.5028334271558701,-3.474309925967195
511.80000000000655,56.59558788119808,-0.5040048050251377,-3.473692392057133
512.7000000000066,56.68303845981658,-0.504633169976325,-3.4741243413291616
513.6000000000065,56.77191974219136,-0.5048682336854691,-3.476287580180448
514.5000000000066,56.86180936275676,-0.5048884649050965,-3.4749553188772726
515.4000000000066,56.950827341667726,-0.5048121307216445,-3.4769384021447047
516.3000000000065,57.0396947286315,-0.5066316394363028,-3.4782508602987687
517.2000000000066,57.128563117955856,-0.5060707375039257,-3.4796328646193873
518.1000000000066,57.21763052618447,-0.5054128242631226,-3.479623432936837
519.0000000000066,57.30772124011668,-0.5068007564635977,-3.4808902230847054
519.9000000000067,57.39637981309759,-0.5062225500404256,-3.480890041020378
520.8000000000067,57.48432399857228,-0.5080472512221228,-3.480887221744539
521.7000000000066,57.57391927026177,-0.5085169392093762,-3.482210460857275
522.6000000000067,57.662888613064155,-0.5084242915278063,-3.4822176846868187
523.5000000000067,57.751130133478505,-0.509026957476524,-3.484507845210355
524.4000000000067,57.840870529377035,-0.507620465963264,-3.4858144450427138
525.3000000000068,57.930436791218106,-0.5089160539315613,-3.487162271319057
526.2000000000068,58.01689691017886,-0.5078281143901963,-3.4884788998924754
527.1000000000067,58.10823062255326,-0.5084856679512378,-3.489841292483561
528.0000000000068,58.19673157095145,-0.5092517389090403,-3.488478406602802
528.9000000000068,58.285124473701195,-0.5090498290325185,-3.4897878212663462
529.8000000000068,58.37521345420473,-0.509849755649148,-3.4904337949450923
530.7000000000069,58.46383765070748,-0.5111987347686563,-3.491760047858583
531.6000000000068,58.55399008828818,-0.5106751315914801,-3.4914583868883287
532.5000000000068,58.64316450845606,-0.5113401231095239,-3.4924212680369155
533.4000000000069,58.730885587115964,-0.5094194487402441,-3.493740090256729
534.3000000000069,58.82103936318045,-0.5103151226083189,-3.4937445276682038
535.2000000000069,58.91071927443682,-0.5112510942803721,-3.4924222580299658
536.100000000007,59.0005825135335,-0.5107313558447671,-3.495439409160582
537.0000000000069,59.0895012074254,-0.511371263474686,-3.497691241564987
537.9000000000069,59.179232192398494,-0.5107205564766069,-3.498603964101209
538.800000000007,59.26739814055532,-0.5121060258472969,-3.499009922024413
539.7000000000069,59.35714236344828,-0.5111329142329539,-3.4990117581380793
540.600000000007,59.44627733543064,-0.5111580446071847,-3.500338480628407
541.500000000007,59.53554297336697,-0.5121105716220554,-3.499669899962612
542.4000000000069,59.62526973633116,-0.5112595701654403,-3.5009901252868807
543.300000000007,59.713639075239094,-0.5082039021944751,-3.502300463484479
544.200000000007,59.80281144086655,-0.5089271756706553,-3.50081914555958
545.100000000007,59.893183042906045,-0.5091426312295744,-3.5018529941487104
546.000000000007,59.982796914294454,-0.5064306881833209,-3.5043601910265463
546.900000000007,60.071003695691886,-0.5056756118277418,-3.505710148691554
547.800000000007,60.16144394984405,-0.5071577118720141,-3.507029995028771
548.7000000000071,60.250199525483396,-0.5096305812112542,-3.5070221097148675
549.6000000000071,60.33905257978569,-0.5073651210477883,-3.508342244273448
550.500000000007,60.428213013136784,-0.5081203339823425,-3.508911693455484
551.4000000000071,60.517907958530415,-0.506462994083289,-3.509329364632324
552.3000000000071,60.60698150986092,-0.5071312011437838,-3.508010066073855
553.2000000000071,60.69684245553215,-0.5074796901180173,-3.5080178240012128
554.1000000000072,60.786184169047786,-0.5063642387006546,-3.5083532417956715
555.0000000000072,60.87521596042173,-0.507210629952391,-3.5096542688016994
555.9000000000071,60.96498932765135,-0.507991030949768,-3.5119598329116855
556.8000000000072,61.05356221218793,-0.5090622017586395,-3.5119600016367296
557.7000000000072,61.14313345671303,-0.5116368877934615,-3.5131482057909116
558.6000000000072,61.2322499007633,-0.512503544938889,-3.5126171645645705
559.5000000000073,61.32165860636082,-0.5138501726531377,-3.5127358368331416
560.4000000000073,61.41124901938921,-0.5142843861718136,-3.5139400625642736
561.3000000000072,61.50019730759993,-0.5164189195886939,-3.514723472724828
562.2000000000073,61.5908314044499,-0.5168975487354782,-3.514643396127419
563.1000000000073,61.6782867646256,-0.519828639999945,-3.5141075334985667
564.0000000000073,61.76786382621295,-0.5190595035161563,-3.514318398649956
564.9000000000073,61.85719659382883,-0.5212575921387057,-3.5142592575170006
565.8000000000073,61.94662649358977,-0.5206038443430554,-3.5155798724446505
566.7000000000073,62.03579328022174,-0.52118537988594,-3.5162795072859128
567.6000000000073,62.12489046477231,-0.5212253175035715,-3.5178665469280985
568.5000000000074,62.21438461163114,-0.5235733190625538,-3.52061849806181
569.4000000000074,62.30341058335014,-0.5229843797691672,-3.520520082936243
570.3000000000073,62.39371966876477,-0.5233184867349144,-3.5206247986459855
571.2000000000074,62.48246150879798,-0.5243139260473924,-3.5218394610602117
572.1000000000074,62.57124722828002,-0.525885607853242,-3.521842749919114
573.0000000000074,62.66018710383303,-0.5259334383305823,-3.5231592056977066
573.9000000000075,62.750206077326105,-0.5264376954279635,-3.5216759001790705
574.8000000000075,62.839550209090774,-0.5269333787231333,-3.520259867475844
575.7000000000074,62.92867330042826,-0.5273065862072198,-3.5203271355204557
576.6000000000074,63.017830630252455,-0.5278077062448949,-3.521578537480988
577.5000000000075,63.107918811863776,-0.5257896440366954,-3.526168413452964
578.4000000000075,63.196943696241625,-0.5225894170840756,-3.5264495740748942
579.3000000000075,63.28595716279209,-0.5186283318345788,-3.5245898199113497
580.2000000000075,63.37516929096306,-0.5190400675966077,-3.524563188262305
581.1000000000075,63.464632763431965,-0.5161428444045569,-3.5245881843905638
582.0000000000075,63.55363803030426,-0.5161446723545408,-3.5231881697394845
582.9000000000076,63.64329258380119,-0.5150989352967701,-3.5246302004661434
583.8000000000076,63.7327709999698,-0.5148785862187772,-3.5283010406753887
584.7000000000075,63.82275875559779,-0.5132358700995373,-3.5285400536493787
585.6000000000076,63.91160289976435,-0.513023997067665,-3.5282103389572725
586.5000000000076,64.00028801797637,-0.5117571648645806,-3.5285654261831945
587.4000000000076,64.089562732934,-0.50984755637595,-3.529530044231845
588.3000000000077,64.17934339581855,-0.5089522835262096,-3.5308439900379582
589.2000000000077,64.26933910391554,-0.5089776388131259,-3.530850919049928
590.1000000000076,64.3585964116231,-0.5076846697481954,-3.530882818680211
591.0000000000077,64.44829029498898,-0.5048587258032078,-3.5282092644728826
591.9000000000077,64.53715323794262,-0.5034394516984827,-3.528352890480176
592.8000000000077,64.62629912460257,-0.5040994142833441,-3.5308363891180505
593.7000000000077,64.71563850143494,-0.5004768662511013,-3.5319338470059027
594.6000000000078,64.80531597692556,-0.5007677756820137,-3.5334750134776103
595.5000000000077,64.89457799347839,-0.4977769022397708,-3.534272965641329
596.0000000000077,64.94488376797919,-0.4982744042052535,-3.533789577213507