File: 01_Data/PU_Aerogel/STA/N2/10K_min/PU_Aerogel_STA_N2_10KData_230201_R1.csv
##Temp./Â°C,Time/min,DSC/(mW/mg),Mass loss/mg
50.0,10.873179885092936,-1.8199658797403278,0.024361338850902747
51.100000000000016,11.188359617866396,-1.7048164312589458,0.022322579835086565
52.20000000000003,11.417355830195534,-1.6225330239852935,0.021470748962497233
53.30000000000005,11.61577833993147,-1.559205060495065,0.020285259759046603
54.40000000000006,11.79187675525564,-1.5104102353538553,0.02030500546106584
55.50000000000008,11.963023824221326,-1.4661716866563625,0.02082186567520594
56.600000000000094,12.118777835736728,-1.4327236057098847,0.022435910142024618
57.70000000000011,12.270106359055266,-1.4018797943333836,0.024043442977093044
58.800000000000125,12.416418616934047,-1.3773099044164472,0.022852099494003575
59.90000000000014,12.559287043311869,-1.3522321846454068,0.021633493325335706
61.000000000000156,12.699653733572084,-1.3343945108983248,0.021349201171122267
62.10000000000017,12.83353723203239,-1.314670966997476,0.021068954008216068
63.20000000000019,12.968987563150044,-1.2974237582522359,0.02305108217109275
64.30000000000021,13.101795409080777,-1.2797698046764816,0.02205029999985264
65.40000000000022,13.231169825600661,-1.264915976572701,0.0221681283735089
66.50000000000023,13.361955440319495,-1.2524849670939049,0.022171635839418613
67.60000000000025,13.490114912148602,-1.2391330764623185,0.022031784151133493
68.70000000000027,13.61548137777475,-1.2250048054212672,0.01967860550281575
69.80000000000028,13.739677271652793,-1.213653807342783,0.020373059351030953
70.90000000000029,13.863997589943388,-1.199872668135432,0.02087209476946228
72.00000000000031,13.988275949372952,-1.1881277738996323,0.02084556233738244
73.10000000000034,14.108628149454324,-1.1764172306992924,0.021741447467328534
74.20000000000034,14.229656012125261,-1.1658323426779753,0.020855176429493305
75.30000000000035,14.350000000000037,-1.1553999999999967,0.0222809497934211
76.40000000000038,14.469493407177108,-1.143775899494639,0.021589847331272338
77.5000000000004,14.587483266020056,-1.135439211173225,0.020961354061217463
78.6000000000004,14.706422273538122,-1.1254045347874218,0.020966196219359468
79.70000000000041,14.822082101715015,-1.1178818347398563,0.021504055640403585
80.80000000000044,14.939544810346927,-1.1077525521469247,0.02279370327149266
81.90000000000046,15.054835733205554,-1.0997130941136468,0.022302627547603926
83.00000000000047,15.167751743849458,-1.091554251046201,0.022311832778227902
84.10000000000048,15.284473970822864,-1.082714735581926,0.0208729067329676
85.2000000000005,15.396472669565252,-1.073142659302203,0.02095828083404072
86.30000000000052,15.51088616680774,-1.064600028537911,0.02093224146581729
87.40000000000053,15.623458998081022,-1.0567113296581385,0.02227386595563008
88.50000000000054,15.735139341184986,-1.0496291325399298,0.02233614108059534
89.60000000000056,15.846233897134782,-1.0409428169370987,0.023599609451707693
90.70000000000059,15.95696551592145,-1.033357246148436,0.02360021563717929
91.8000000000006,16.06845433552218,-1.0237556935872851,0.023538607925903676
92.9000000000006,16.17642514932872,-1.0174678077579364,0.02492006684441872
94.00000000000063,16.287300980960197,-1.010349375328146,0.024910115668877353
95.10000000000065,16.397810365625,-1.003888066033594,0.02301606758494934
96.20000000000066,16.505880028034902,-0.9964476877158578,0.022837069041895752
97.30000000000067,16.614501901735164,-0.9881795590232069,0.02468522553532093
98.40000000000069,16.722869773847645,-0.9817905668343212,0.026850022895904324
99.50000000000071,16.831101594240945,-0.9750665261386183,0.025576063607459787
100.60000000000072,16.938977395395362,-0.9684804903058969,0.02694983332478973
101.70000000000073,17.046933953310333,-0.961196011879654,0.02556654416991755
102.80000000000075,17.154694076989728,-0.9547016588377134,0.024204292174951014
103.90000000000077,17.2627379360332,-0.9463360998062834,0.024251064613616258
105.00000000000078,17.36855771163901,-0.9393007273950411,0.02425996328460922
106.10000000000079,17.477156881145,-0.9319718387778604,0.02422440885576993
107.20000000000081,17.580590353665983,-0.9265550277785954,0.022910569907825362
108.30000000000084,17.69018956118783,-0.9186214407273544,0.02295998261480303
109.40000000000084,17.796176055835733,-0.9123452017350234,0.02333127679632785
110.50000000000085,17.904376144130428,-0.9062875524414803,0.024183303586357674
111.60000000000088,18.010102275096287,-0.8996938971409639,0.02450264673133784
112.7000000000009,18.11762138945391,-0.8926755024167443,0.022934794159458427
113.8000000000009,18.221555046973613,-0.8878877083131254,0.025579669210381795
114.90000000000092,18.32701002217893,-0.8811827635029598,0.026036154621472463
116.00000000000094,18.435938408962738,-0.8739479517072505,0.024261687245588526
117.10000000000096,18.54191557628479,-0.8694815978357169,0.022610392407104385
118.20000000000097,18.646546911477028,-0.8628007290838282,0.02261072034687661
119.30000000000098,18.754995577810163,-0.8575938352353482,0.022615472438112683
120.400000000001,18.86030713071485,-0.8526854943087219,0.023929954092953842
121.50000000000102,18.966653618964536,-0.8470441113595334,0.023793331794925265
122.60000000000103,19.072559062865547,-0.8420086468971492,0.02386849654326273
123.70000000000104,19.178999221686773,-0.8367938860774333,0.023962097667440396
124.80000000000106,19.284788583891928,-0.8306052995474277,0.02392997995732493
125.90000000000109,19.390180569746708,-0.8242107989011064,0.024143109222951153
127.0000000000011,19.495528767346713,-0.8180661929368704,0.025254116113097247
128.1000000000011,19.602086615048258,-0.8121742234864788,0.024850404351417055
129.20000000000113,19.706077421232774,-0.8081254925611557,0.023598521031750863
130.30000000000115,19.810945044220382,-0.8032817825282405,0.025580689325865436
131.40000000000117,19.916057940293435,-0.7965913329908826,0.025579625302879272
132.50000000000117,20.020852556071407,-0.790129119099391,0.02494961183038935
133.6000000000012,20.12675300907316,-0.7869371734218753,0.02363367688481599
134.7000000000012,20.229229039982542,-0.780910110447764,0.02445760948356046
135.8000000000012,20.335210582224526,-0.7758084155768434,0.02623980041380669
136.90000000000123,20.44063573311742,-0.7710168378487512,0.02755028437543139
138.00000000000125,20.54419400260128,-0.7663647800751681,0.026344918386013383
139.10000000000127,20.648715518182176,-0.760944841266586,0.024917552346698457
140.2000000000013,20.753651310550133,-0.7566428655535525,0.023574798832278532
141.3000000000013,20.858821650200348,-0.7513114216111195,0.022280079419878973
142.4000000000013,20.961616400329863,-0.7450207960155382,0.02360560385044863
143.50000000000134,21.06630731413861,-0.7410348404589779,0.023598567174444973
144.60000000000133,21.170180181532416,-0.7358384059801324,0.022279860002094587
145.70000000000135,21.27435997163279,-0.7303887452001258,0.022876032968546234
146.80000000000138,21.379312610872706,-0.7252624013273471,0.023067684808971478
147.9000000000014,21.48391602300961,-0.7223264759835807,0.02359571038957231
149.00000000000142,21.586646737142118,-0.7164938662921629,0.02486930515192931
150.10000000000142,21.69077808049246,-0.7106572067479103,0.023586778962860322
151.20000000000144,21.7940956572834,-0.7068703616862286,0.022279594518695767
152.30000000000146,21.898293992068805,-0.7019955539250182,0.020958261691269797
153.40000000000146,22.002071139608613,-0.69642888789261,0.02228047267821953
154.50000000000148,22.10562516554247,-0.6918895297244796,0.021294450387988384
155.6000000000015,22.20999905088397,-0.6857099471977566,0.020309863172384368
156.70000000000152,22.312844112967884,-0.6814670351400512,0.01999989122274215
157.80000000000155,22.416505372752955,-0.6775512155554473,0.01998010860343058
158.90000000000154,22.520683024942947,-0.6713425308152514,0.019980652273669186
160.00000000000156,22.62329896969221,-0.6668658976250514,0.019980025767075027
161.1000000000016,22.72739138647502,-0.6631609982302102,0.01900824705308679
162.20000000000158,22.830663318307863,-0.6585753370434274,0.018010065982340784
163.3000000000016,22.934565714287764,-0.6543973295139051,0.01929718197502428
164.40000000000163,23.038750741055196,-0.6491277147398109,0.01887417567621963
165.50000000000165,23.1411488585531,-0.6452263284370713,0.01756021591915502
166.60000000000167,23.24451704074158,-0.6417096781055205,0.018880425909459042
167.70000000000167,23.348653811442134,-0.6370256347322363,0.01974599219300721
168.8000000000017,23.4530625435555,-0.6314113098084986,0.02133444004031304
169.9000000000017,23.556698588599122,-0.6275385644760971,0.020861692459812176
171.0000000000017,23.66000000000017,-0.6239399999999679,0.020196729366466215
172.10000000000173,23.76506433824487,-0.6178455158961307,0.018880196188139742
173.20000000000175,23.86736640793596,-0.6144652823972139,0.01691307920314422
174.30000000000177,23.970276678879618,-0.6099431127994802,0.01693809827671977
175.4000000000018,24.07267814567289,-0.6072643840444282,0.01723020031935718
176.5000000000018,24.18020234755823,-0.6022519512355877,0.01723079298045871
177.6000000000018,24.282872546318966,-0.5965082614812628,0.01854875125757438
178.70000000000184,24.38742903857494,-0.594513995461803,0.016427344672054645
179.80000000000183,24.49050125097948,-0.5903524495438409,0.01725451844250081
180.90000000000185,24.593569815561583,-0.5849491505217899,0.01788931526012938
182.00000000000188,24.69395716630369,-0.5825664719253295,0.019209589383315517
183.1000000000019,24.800820069046264,-0.5780297361470038,0.018284045646075775
184.20000000000192,24.903600881459813,-0.5733483455829727,0.016789867067219966
185.30000000000192,25.007261479051053,-0.5706981792382599,0.014774099776072802
186.40000000000194,25.110803502635886,-0.5662428400931495,0.01416000001801443
187.50000000000196,25.21360631231466,-0.5638596873514827,0.014160000000042139
188.60000000000196,25.316932811220116,-0.5600957572472042,0.014159954484124881
189.70000000000198,25.421549399713964,-0.5558782907419613,0.013169331234471393
190.800000000002,25.523548146672482,-0.5518638749742734,0.012839959637259923
191.90000000000202,25.627355655706783,-0.5469675164231422,0.012839256558190293
193.00000000000205,25.731134849062155,-0.5419309976501311,0.011519829638414691
194.10000000000204,25.835242198814257,-0.5374876988255924,0.011520000000053265
195.20000000000206,25.937603902063568,-0.534554127086793,0.011519938198419233
196.3000000000021,26.04112320703949,-0.5290318335254793,0.010198693029261463
197.40000000000208,26.144887373793566,-0.5222458147782436,0.008895919676271014
198.5000000000021,26.247270120988173,-0.5189892587330786,0.007580240821607909
199.60000000000213,26.348892980582843,-0.5122443185261871,0.006557188730510255
200.70000000000215,26.454163622658236,-0.5076981146738211,0.008876937383749173
201.80000000000217,26.557836572933684,-0.5039083784246651,0.007611818950189253
202.90000000000217,26.66131940440431,-0.49804354852554544,0.006580181055662493
204.0000000000022,26.764696537668268,-0.49235732340606564,0.006145703419928594
205.1000000000022,26.867180540359012,-0.487522269097217,0.006259292552502238
206.2000000000022,26.971760110516016,-0.48019560530752203,0.004940220040156262
207.30000000000223,27.074745402728976,-0.47457600273925304,0.0036161824072182824
208.40000000000225,27.17562996342585,-0.4681670453520365,0.0009815024481234502
209.50000000000227,27.280920886006584,-0.46037012723090126,0.002306445322739492
210.6000000000023,27.385283162415167,-0.4526697758146818,0.0022998771383679895
211.7000000000023,27.486708981872336,-0.4433254280041866,0.0008421245893437401
212.8000000000023,27.59315020084148,-0.4336475460462179,-0.0003078666504583438
213.90000000000234,27.696244054702397,-0.4218479739515712,-0.003056573732415302
215.00000000000233,27.799338750095593,-0.4105432526606271,-0.004390139752874056
216.10000000000235,27.903424120943033,-0.39510678409842404,-0.005711369152590073
217.20000000000238,28.007051844270123,-0.38006609801005065,-0.006462207274138265
218.3000000000024,28.10963789633655,-0.3603569207159357,-0.009701463124002885
219.40000000000242,28.214844274324765,-0.34193904587009016,-0.01130398957480594
220.50000000000242,28.317820318415905,-0.31920912008270963,-0.013291395077290602
221.60000000000244,28.422036249075592,-0.29712432397285304,-0.014598812722198318
222.70000000000246,28.525635319126657,-0.2695370709988768,-0.017890025018506783
223.80000000000246,28.629186054246176,-0.24361474070286307,-0.023258361155869878
224.90000000000248,28.732657100770627,-0.2140594589019912,-0.02328622859218843
226.0000000000025,28.837406088245032,-0.18529085251944832,-0.02622618092959783
227.10000000000252,28.941213480691058,-0.1574311112553834,-0.029103019856871803
228.20000000000255,29.044738353026858,-0.1299248758091758,-0.032959786763054666
229.30000000000254,29.149749287618345,-0.10034708350565819,-0.03643521285241835
230.40000000000256,29.254104682512953,-0.075839354173717,-0.042358361811953404
231.5000000000026,29.357136075525112,-0.053891131238502726,-0.04651084297466568
232.60000000000258,29.46178684272005,-0.03480964513345853,-0.05282286516874857
233.7000000000026,29.564902478786266,-0.015171317940462167,-0.060531146049076945
234.80000000000263,29.6692104125036,-0.002132768211277372,-0.06679339211989355
235.90000000000265,29.772938924097314,0.012033461126350243,-0.07186109616643499
237.00000000000267,29.877519513037555,0.02057748784840399,-0.07736287608253711
238.10000000000267,29.981655815003432,0.029458542523739646,-0.08349526970684407
239.2000000000027,30.08569364234799,0.035767802335429755,-0.09169016232380889
240.3000000000027,30.189810093490504,0.04030220748186756,-0.09934998253806837
241.4000000000027,30.293380246569008,0.04662188799375392,-0.10652248266441644
242.50000000000273,30.398400257352876,0.0500647073573636,-0.1155970680895444
243.60000000000275,30.502103140180076,0.055998783180738095,-0.1266449383009456
244.70000000000277,30.60698894062482,0.06082947176137082,-0.136352632403538
245.8000000000028,30.710487573843043,0.06542083587822646,-0.14731628441088995
246.9000000000028,30.814826371141134,0.0706638260551617,-0.160266465435702
248.0000000000028,30.919441498749634,0.07865590403878338,-0.17030770241274862
249.10000000000284,31.02363798841976,0.08480468336520587,-0.18423200355590108
250.20000000000283,31.127922855189777,0.09214138208187347,-0.19714991803081627
251.30000000000285,31.23246244932356,0.09877865020168433,-0.21004119705102875
252.40000000000288,31.337452148794675,0.10497982103817631,-0.22473723898346076
253.5000000000029,31.440763945586518,0.11366777278732725,-0.23936883954996624
254.60000000000292,31.545317317045594,0.12105807493670201,-0.25514893056596755
255.70000000000292,31.649511414679466,0.12655127544366646,-0.2703430231691928
256.8000000000029,31.753543955607327,0.13249297193552864,-0.2880361275275387
257.90000000000293,31.857939860023862,0.13631440376352244,-0.3041475654690009
259.00000000000296,31.961002408678272,0.14097816215573492,-0.32299783808622395
260.100000000003,32.06510968123021,0.14256936098354067,-0.3415659955230037
261.200000000003,32.169125556387186,0.14217246359336727,-0.3606678570748403
262.300000000003,32.27401578841516,0.14173390246742915,-0.38127845720392406
263.40000000000305,32.3782351909547,0.13803688254873575,-0.3996556844471546
264.50000000000307,32.482259457430025,0.13423127251170125,-0.4201197822278533
265.6000000000031,32.58640947460903,0.12759864903372947,-0.4386131648817351
266.7000000000031,32.690470515814354,0.12085560227900934,-0.4607675993366023
267.8000000000031,32.79465569307426,0.11105185976447578,-0.4826262530967216
268.9000000000031,32.89875446291166,0.09935010091374102,-0.5046750601610621
270.0000000000031,33.00271710869623,0.0849104568437416,-0.5224193016984882
271.10000000000315,33.106775010397534,0.07108574048299128,-0.5398057787173212
272.2000000000032,33.21207086027827,0.05515983329961492,-0.5609191801634594
273.30000000000314,33.31688715177821,0.03663396500495133,-0.5813502428644841
274.40000000000316,33.42103541976149,0.019243465252088143,-0.5994944694659021
275.5000000000032,33.5243845690094,-0.002375132211387808,-0.6177856802564334
276.6000000000032,33.62999894491182,-0.022635465076712977,-0.6370696515942504
277.70000000000323,33.73239732543757,-0.04128859543338591,-0.6524607772679545
278.80000000000325,33.83706777829258,-0.06073121516887486,-0.6689400503189407
279.9000000000033,33.94114528890206,-0.07928965774939542,-0.6812382712275511
281.0000000000033,34.04364223422965,-0.09411784665219447,-0.6933039516019459
282.1000000000033,34.15008443854777,-0.1098685580968612,-0.7061373957457739
283.20000000000334,34.254024427979985,-0.12109093046394966,-0.7177873701576951
284.30000000000337,34.356005642002444,-0.13153676894116656,-0.7295232719943381
285.40000000000333,34.463038008366404,-0.13969203534666208,-0.7399584226512519
286.50000000000335,34.568082733012446,-0.14426079203452055,-0.750443591372
287.6000000000034,34.67085879414809,-0.14818403713991998,-0.7591445256293836
288.7000000000034,34.775736587049806,-0.15066527593996967,-0.7694708572150781
289.8000000000034,34.88037664482751,-0.1528964083424684,-0.7771824863255512
290.9000000000034,34.98416147258181,-0.15189428533419322,-0.7858297979366329
292.0000000000034,35.08833639885938,-0.1530267511052204,-0.7952396623905367
293.10000000000343,35.19323400892221,-0.14872301504555632,-0.806135095579803
294.20000000000346,35.2982612090855,-0.1460607200226693,-0.8135203623942178
295.3000000000035,35.40098249930263,-0.14380694339149952,-0.8227593708918124
296.4000000000035,35.50693039666459,-0.13897230203309113,-0.8313830421807036
297.5000000000035,35.61107168550916,-0.13488918146093473,-0.8376718528805362
298.60000000000355,35.7165519208909,-0.13016862277140404,-0.8456332480697251
299.70000000000357,35.821702863031696,-0.1256365951897828,-0.8519652301339296
300.8000000000036,35.92638588162839,-0.11916631584084825,-0.8601663144868317
301.9000000000036,36.03062868615272,-0.11304580954961353,-0.8640391718835585
303.0000000000036,36.136114772849716,-0.1052862452106967,-0.8706524052676881
304.1000000000036,36.24074278046868,-0.09850285963789654,-0.8773142602385011
305.2000000000036,36.3466459860715,-0.08990573678717294,-0.884238797953639
306.30000000000365,36.45128072678129,-0.08377498323906146,-0.8918658502701788
307.4000000000037,36.5560035733824,-0.0758144109137111,-0.8995755772922305
308.5000000000037,36.66090465573705,-0.06917017506599442,-0.9078069067993111
309.60000000000366,36.766671503084865,-0.05980994052164762,-0.913607155005546
310.7000000000037,36.871158308540004,-0.053458212455706665,-0.9199587433163425
311.8000000000037,36.97585559994133,-0.04626585109344162,-0.9288599737964471
312.90000000000373,37.080946365254405,-0.0385277542718297,-0.9356905343615214
314.00000000000375,37.18696629620747,-0.03098227592302614,-0.9415527197358635
315.1000000000038,37.29124213683579,-0.024839286174609294,-0.9516460402508278
316.2000000000038,37.3967401623233,-0.015683498718573344,-0.9612883718481386
317.3000000000038,37.50180324142282,-0.008602250711544775,-0.9698539702185238
318.40000000000384,37.60665963152335,-0.002123905866265425,-0.9795691927465606
319.5000000000038,37.71158109499696,0.003098217525953035,-0.9876137705529278
320.60000000000383,37.81835316321307,0.010152358370611694,-0.9960429328475673
321.70000000000385,37.92349739435506,0.01586149232532396,-1.0082337746877452
322.8000000000039,38.02804055175122,0.019999080595837444,-1.0177204018040165
323.9000000000039,38.13279977676277,0.023759958645002955,-1.0271286633610504
325.0000000000039,38.238603142924376,0.028157681396662877,-1.0359013580945127
326.10000000000394,38.34403357375347,0.029925211807265883,-1.0444702503988985
327.2000000000039,38.44952600647734,0.03307678068982602,-1.0560749095371373
328.30000000000393,38.55504976466604,0.03523321428566869,-1.0683773985934684
329.40000000000396,38.65944524734499,0.036252916268500295,-1.0784704320185199
330.500000000004,38.76608029893511,0.0383830673260698,-1.0901022139274397
331.600000000004,38.87008179125803,0.040069241441592844,-1.1003454976770053
332.700000000004,38.974086374548286,0.03765075954307559,-1.110954943898553
333.80000000000405,39.081079398931905,0.034485941511643886,-1.1241924897886886
334.90000000000407,39.1868868912813,0.029309827413325544,-1.1378588672839554
336.0000000000041,39.29220874082455,0.022406454862318292,-1.1500078425198992
337.10000000000406,39.39849854976622,0.015890680621168805,-1.1613551258727433
338.2000000000041,39.50472788801425,0.008578002337925569,-1.1721687189685484
339.3000000000041,39.610595383665824,0.0035089013319241614,-1.1854026394180002
340.4000000000041,39.71577775375624,-0.0007730886459288625,-1.197795158305218
341.50000000000415,39.821598643833724,-0.005903866613664249,-1.2089188938274016
342.6000000000042,39.92763213666835,-0.009746662893164948,-1.2220981128144301
343.7000000000042,40.030758203650976,-0.01258655842582177,-1.2335149212704568
344.80000000000416,40.13776488720095,-0.01960410963478872,-1.2454779514828291
345.9000000000042,40.24276556583048,-0.025846366479366042,-1.26064238788052
347.0000000000042,40.35081068644235,-0.03380659479144378,-1.274335927118321
348.10000000000423,40.45717080361506,-0.038479381869674825,-1.2849037506485934
349.20000000000425,40.56292041304983,-0.045377659315722386,-1.2967393703835546
350.3000000000043,40.666436935738275,-0.05341384274949811,-1.3094823703307825
351.4000000000043,40.77375572803569,-0.06253847415769426,-1.3216261515337715
352.5000000000043,40.881220422807296,-0.07206156230541219,-1.334324976397911
353.60000000000434,40.98639386018222,-0.08079942004518854,-1.3426291410204239
354.7000000000043,41.09135953618191,-0.08999641380678086,-1.3552290595031344
355.80000000000433,41.198663865948475,-0.10083694377688371,-1.3679658056314263
356.90000000000435,41.30383766264934,-0.11145345213178133,-1.3785728505000705
358.0000000000044,41.41037996611928,-0.12284426082941947,-1.3911990423708849
359.1000000000044,41.51761500910857,-0.13261459921870206,-1.4011412950581885
360.2000000000044,41.62283707202574,-0.14426409373395063,-1.4107363411057952
361.30000000000445,41.728945265208175,-0.15488687926036945,-1.4204901903932812
362.4000000000044,41.834697696789455,-0.1644326965041314,-1.4312530673723702
363.50000000000443,41.94045731353931,-0.17446828228838357,-1.4389739937055412
364.60000000000446,42.046300299213044,-0.18405269602639332,-1.4487671276015766
365.7000000000045,42.15300122925877,-0.19288792590337034,-1.457675467861527
366.8000000000045,42.25865189930576,-0.2021305896150591,-1.4660481440389792
367.9000000000045,42.3646942064112,-0.21094504772409808,-1.4744644253612496
369.00000000000455,42.47081856996934,-0.2166620235165982,-1.4795196133170343
370.10000000000457,42.577208972647256,-0.22583317765444966,-1.4878309356254267
371.2000000000046,42.68319415164535,-0.22986244305376652,-1.4973180932395058
372.30000000000456,42.78945036889481,-0.23751165165970162,-1.504556348393482
373.4000000000046,42.89518294100557,-0.24278486295530735,-1.511564801272283
374.5000000000046,43.00109202392591,-0.24868271856240684,-1.517741964119041
375.6000000000046,43.10723052300185,-0.2557533984785145,-1.5251052040204653
376.70000000000465,43.214851061098734,-0.26008160900353755,-1.5322260220222863
377.8000000000047,43.32019373416216,-0.2649920311917373,-1.5381879472652975
378.9000000000047,43.4260740346006,-0.26825115273031963,-1.5456532809869792
380.00000000000466,43.53282629380893,-0.2744009218951977,-1.5513405140024537
381.1000000000047,43.63873865312676,-0.27818948531297855,-1.5592545442289985
382.2000000000047,43.744378486997576,-0.28296542382893886,-1.5673529183037802
383.30000000000473,43.85047174633026,-0.28577124146665833,-1.5744426572417214
384.40000000000475,43.95674414237228,-0.28919886415898727,-1.5811024185606173
385.5000000000048,44.063525051934924,-0.2919802338844905,-1.5880215067259322
386.6000000000048,44.169398075839254,-0.29509523284861827,-1.5967834716070453
387.7000000000048,44.27698955544612,-0.29910471094189295,-1.603229178260548
388.80000000000484,44.38236882111751,-0.30231885984515683,-1.6101431081760937
389.9000000000048,44.48959059745071,-0.30561866990584824,-1.618373610684639
391.00000000000483,44.59549891249961,-0.30729202582069787,-1.6274977584611974
392.10000000000485,44.70277772461785,-0.3087956446470769,-1.6342633176235672
393.2000000000049,44.8087663724901,-0.3091757758264095,-1.6427736197642022
394.3000000000049,44.91444570459467,-0.3087505188686468,-1.6502031737174057
395.4000000000049,45.021561035082094,-0.3105734157462517,-1.6568270438634545
396.50000000000495,45.12904595396557,-0.3076330480243475,-1.6669554822892665
397.6000000000049,45.235142128447656,-0.30451703730891894,-1.676513160325758
398.70000000000493,45.34025687025817,-0.30283043629273876,-1.6860523039009285
399.80000000000496,45.448303179919215,-0.29990372497504697,-1.6915564715249207
400.900000000005,45.55404701139523,-0.29627188303846896,-1.6986235568022807
402.000000000005,45.66200560004851,-0.2931191526905351,-1.707395804808225
403.100000000005,45.76788051305499,-0.2893943473257083,-1.7155012900254563
404.20000000000505,45.87542469119545,-0.281912437556348,-1.725421831943501
405.30000000000507,45.98248064245624,-0.2748724043518074,-1.733759885221283
406.4000000000051,46.09010163840075,-0.2701076125407132,-1.7452393566819908
407.50000000000506,46.19598366357301,-0.2624857862298201,-1.7525443486029029
408.6000000000051,46.30393924361038,-0.25543713419417824,-1.7620128294958017
409.7000000000051,46.40920476180162,-0.2484495607735403,-1.7719496130862886
410.8000000000051,46.51839617156455,-0.24212554295167876,-1.7784615487815167
411.90000000000515,46.62575833620708,-0.2357307112163905,-1.7891822984609003
413.0000000000052,46.73031982910587,-0.23055931353296683,-1.7973882500819354
414.1000000000052,46.83905885510657,-0.22249486378235314,-1.8078642996798422
415.20000000000516,46.94692854743701,-0.21634667421383563,-1.8164022451953201
416.3000000000052,47.054640524502304,-0.208459283576358,-1.8254658491340994
417.4000000000052,47.16236420794408,-0.20339270827052383,-1.8300404411570277
418.50000000000523,47.26883384708287,-0.1960829946935016,-1.8386260344311434
419.60000000000525,47.3766924008015,-0.19138286825292522,-1.8491809678134352
420.7000000000053,47.484443558583095,-0.1874586937534141,-1.8601514443706542
421.8000000000053,47.59307527061728,-0.18009187118437758,-1.8694712883101543
422.9000000000053,47.70018591697515,-0.17396822490776076,-1.8780789112396876
424.00000000000534,47.808116269206636,-0.1689216499338115,-1.8883721497331556
425.1000000000053,47.91574708515006,-0.16409706690295117,-1.8955705287532223
426.20000000000533,48.023714348416085,-0.15795154054782137,-1.9019570195652733
427.30000000000535,48.13115585436787,-0.15510203896876334,-1.91037161791392
428.4000000000054,48.237933872151,-0.1503500469498858,-1.9198651664558821
429.5000000000054,48.34612569060914,-0.1450483069271237,-1.929974245337431
430.6000000000054,48.45428328178567,-0.1424016190264772,-1.93895964423626
431.70000000000545,48.56065752972032,-0.13796941544049404,-1.9461937664524163
432.8000000000054,48.66931726028778,-0.13492604423122004,-1.954613127511157
433.90000000000543,48.77555704536919,-0.132013115722125,-1.9642400495786987
435.00000000000546,48.8846513677588,-0.1276526728439024,-1.9722851038889888
436.1000000000055,48.992650388648485,-0.12550220214943528,-1.9778172368230424
437.2000000000055,49.09873638721889,-0.1221370292698672,-1.9847607677478627
438.3000000000055,49.206692022441004,-0.11978950074681417,-1.992514890235726
439.40000000000555,49.314566450878125,-0.11733295640535553,-2.0003250205886642
440.50000000000557,49.42212158961976,-0.11448195499873669,-2.010609548058367
441.6000000000056,49.52952660497612,-0.11285286229448217,-2.0176558863582605
442.70000000000556,49.63715705096057,-0.1102073540451464,-2.0261166297976456
443.8000000000056,49.74572372173967,-0.10903233131728829,-2.033198104195046
444.9000000000056,49.85357371203551,-0.1054666844923498,-2.0409612484640505
446.0000000000056,49.96104601471048,-0.10373391067658377,-2.0494159506390477
447.10000000000565,50.06934304916519,-0.10070929647765431,-2.057279691872208
448.2000000000057,50.1779095567717,-0.10044868137357164,-2.0650180733182086
449.3000000000057,50.28598695913643,-0.09954868017567613,-2.070555388972013
450.40000000000566,50.394000392535496,-0.09755060413540326,-2.0761298308412766
451.5000000000057,50.501677269110395,-0.09586628121180679,-2.082172077875395
452.6000000000057,50.60980731315621,-0.09400406437412327,-2.0922391992452023
453.70000000000573,50.717361694150746,-0.09235109082097724,-2.0979042753537493
454.80000000000575,50.82568028540345,-0.09069008110286214,-2.104691267753291
455.9000000000058,50.933609327545575,-0.08843312881335132,-2.1111286882329523
457.0000000000058,51.0405230804497,-0.08703067890180681,-2.117549315751198
458.1000000000058,51.14770833875323,-0.08583225236465826,-2.124212037606215
459.20000000000584,51.2580444853542,-0.08365650405186258,-2.1324915474050608
460.3000000000058,51.36590229772255,-0.08267186863205579,-2.141463803216662
461.40000000000583,51.474954058935786,-0.08108004668141248,-2.1493534364331452
462.50000000000585,51.583441209385796,-0.07934034422377344,-2.1543353640748046
463.6000000000059,51.69056761876984,-0.07779699048475373,-2.1597234615390315
464.7000000000059,51.79897712740201,-0.07500425398843616,-2.1651706529046164
465.8000000000059,51.907412814247856,-0.07228821137168141,-2.171929378226643
466.90000000000595,52.015071198985794,-0.07052653086743114,-2.1789855561735174
468.0000000000059,52.12319366844845,-0.06893075696040366,-2.185313036498038
469.10000000000593,52.23108067689219,-0.0679678136165196,-2.1915579480956993
470.20000000000596,52.339285711377364,-0.06460876463663531,-2.1976766131269945
471.300000000006,52.446880956319305,-0.06470517375065764,-2.205611527869953
472.400000000006,52.554933892735775,-0.06122197241462886,-2.2132603389229337
473.500000000006,52.66252852856314,-0.05922197560594928,-2.2196856856603437
474.60000000000605,52.771579156169445,-0.05732820280960152,-2.226326024662071
475.70000000000607,52.879708462943825,-0.05463877152589061,-2.232987754005642
476.8000000000061,52.986995045082466,-0.05426219313702758,-2.2409369219470485
477.90000000000606,53.09533407877015,-0.05462862017353577,-2.2482948239434886
479.0000000000061,53.20368646470937,-0.052601885186489124,-2.253745563267759
480.1000000000061,53.31066264916974,-0.05282428489884905,-2.2594959223458475
481.2000000000061,53.41891249014387,-0.05113532037737508,-2.2686739068542257
482.30000000000615,53.52681115397328,-0.05004439463735207,-2.2747305925538344
483.4000000000062,53.635092634513086,-0.05044160054725607,-2.282041996012413
484.5000000000062,53.74324097429053,-0.0480471987742285,-2.291645083789699
485.60000000000616,53.85186797144035,-0.04890980789718325,-2.2985754930989577
486.7000000000062,53.96057501143842,-0.046773586420695394,-2.3046878559876176
487.8000000000062,54.069477617778,-0.04747164601891351,-2.314108658589951
488.90000000000623,54.17777540826307,-0.046821297789767846,-2.321939125560454
490.00000000000625,54.2865729151989,-0.04691666539264819,-2.329294419335791
491.1000000000063,54.395623240408,-0.048050469878954234,-2.337713978268563
492.2000000000063,54.50227149206963,-0.04744689821220588,-2.3457280963563596
493.3000000000063,54.61233342047913,-0.047715421764524306,-2.352698259289811
494.40000000000634,54.720001005457014,-0.046092821279096564,-2.3605623626016032
495.5000000000063,54.82791203984613,-0.04625176761839192,-2.3661042997290043
496.60000000000633,54.93766804988975,-0.04560676133808533,-2.3750344670939953
497.70000000000636,55.04234912297826,-0.0451695913188296,-2.3826294582795766
498.8000000000064,55.15193417326652,-0.04465700205683922,-2.390081511675382
499.9000000000064,55.262064619674916,-0.044729046905969176,-2.3971665325197966
501.0000000000064,55.371320957291125,-0.043754698585209084,-2.4078021200532
502.10000000000645,55.47882986061788,-0.04262872242159487,-2.415581040978932
503.2000000000064,55.58792973138427,-0.041854152826093505,-2.4223957551122712
504.30000000000643,55.69538239697434,-0.04068212103559001,-2.429302275358829
505.40000000000646,55.80480643328196,-0.041028161662936984,-2.4349564061102473
506.5000000000065,55.91305087225542,-0.041020748562691514,-2.4415976790532197
507.6000000000065,56.021164334516214,-0.03896569375771386,-2.4515489527559584
508.7000000000065,56.13010138412952,-0.039015354934860205,-2.4559873613238716
509.80000000000655,56.237216905640814,-0.03869580431046882,-2.4610275353115667
510.90000000000657,56.347894327290845,-0.03781097183717082,-2.4705203707543535
512.0000000000066,56.45628293232839,-0.03636253060492492,-2.478221660330987
513.1000000000065,56.565417309603,-0.03617713324912505,-2.483974265538198
514.2000000000066,56.673461344787164,-0.03617192760333054,-2.4905192667362637
515.3000000000065,56.78143299354994,-0.0366368798527624,-2.498348301156291
516.4000000000067,56.891343007267174,-0.035405107725277565,-2.504721273109777
517.5000000000066,56.999580267659574,-0.034743632304183,-2.510511681045582
518.6000000000067,57.10761936266131,-0.03540256190633799,-2.5149015654935147
519.7000000000066,57.21570743060463,-0.034968518287477594,-2.5212606686198527
520.8000000000067,57.32601626036062,-0.03439280990682163,-2.5278001588520422
521.9000000000067,57.435810243668634,-0.03399007418750468,-2.5333786986989724
523.0000000000067,57.54456159885171,-0.031514046806400936,-2.539353654732354
524.1000000000067,57.65258349436125,-0.029810317529008968,-2.5442977362046353
525.2000000000068,57.761944621283945,-0.028990251826426297,-2.551018047911124
526.3000000000068,57.87097038310226,-0.027843420876070453,-2.5567711547058165
527.4000000000068,57.979556154517866,-0.027196858666645403,-2.563229008521856
528.5000000000068,58.08879425368424,-0.02797260329152261,-2.5676610166895824
529.6000000000068,58.19842119222325,-0.026103622001490585,-2.572222351488692
530.7000000000069,58.30728185313781,-0.02553924265162913,-2.5792126431035802
531.8000000000068,58.415781314344976,-0.02555167494292957,-2.5855782014751156
532.9000000000069,58.52310393838936,-0.0240416767676404,-2.588647758181688
534.0000000000068,58.63362467259192,-0.024628381465569286,-2.596255070543752
535.100000000007,58.74258929033299,-0.022914126528791545,-2.601700312301337
536.2000000000069,58.851275704005225,-0.024004560542882393,-2.605470546425132
537.300000000007,58.960411511184844,-0.02377370134544512,-2.609485883258405
538.4000000000069,59.0684548087022,-0.02350920160706651,-2.6144085197403255
539.5000000000069,59.179009888430166,-0.022109874331150803,-2.6184687459813594
540.600000000007,59.28828705296329,-0.02360898951566922,-2.622976769860905
541.700000000007,59.396270015543216,-0.02192372087562538,-2.628628926058955
542.800000000007,59.505569843296634,-0.02321635815683134,-2.6317158277273194
543.900000000007,59.61519794387116,-0.022844689311071285,-2.63516629927238
545.000000000007,59.72397052116283,-0.022561447215346097,-2.640357080708683
546.1000000000071,59.83437484779747,-0.02261430313514012,-2.644934716406167
547.2000000000071,59.94398316175409,-0.02160348336019211,-2.649073715451838
548.300000000007,60.05185245436097,-0.022673360284272203,-2.6533373839228593
549.4000000000071,60.161433309896125,-0.022125960972975506,-2.656203976082434
550.500000000007,60.271108649795494,-0.019217578886493617,-2.6575712709085035
551.6000000000072,60.380001928367776,-0.01963000287295123,-2.6618101318321403
552.7000000000071,60.48881437241134,-0.01945207181332396,-2.6678360084573396
553.8000000000072,60.598643843772784,-0.018185792141147274,-2.671818527508341
554.9000000000071,60.708262131507134,-0.020326903275093847,-2.6741927810014205
556.0000000000072,60.817180570543414,-0.01984620297418563,-2.676410634335455
557.1000000000072,60.927453946987015,-0.020264685373144808,-2.6787857851176584
558.2000000000072,61.037044096465806,-0.017540411681388472,-2.682262295301053
559.3000000000072,61.14600092506669,-0.01885338751112025,-2.6863802310461042
560.4000000000073,61.25464218014717,-0.01867907520949512,-2.688240353949642
561.5000000000073,61.36443084437133,-0.016856916758831175,-2.689794697951448
562.6000000000073,61.47375896570172,-0.017007115577168698,-2.693420679911666
563.7000000000073,61.58290652791314,-0.018418946545608935,-2.695864569868414
564.8000000000073,61.69191989141143,-0.01748498059777663,-2.698006227935692
565.9000000000074,61.80173342481708,-0.014441669061378826,-2.7032843830706077
567.0000000000074,61.91145704250977,-0.014582818751801143,-2.7088885675558254
568.1000000000074,62.020110307411194,-0.011011859483624958,-2.7109888704861103
569.2000000000073,62.12940377753688,-0.011566495711265326,-2.7142900258994445
570.3000000000073,62.238301962714374,-0.008975286291425967,-2.7169306440833756
571.4000000000074,62.34783846580896,-0.008993293833333147,-2.721270702077424
572.5000000000074,62.45606397708335,-0.0067593503337542655,-2.7225296934326515
573.6000000000074,62.566089513903755,-0.006086632139676565,-2.7265091671450676
574.7000000000074,62.67545250552721,-0.0057966297912782775,-2.7278506791549377
575.8000000000075,62.78488548971585,-0.004391990354301555,-2.7305958206548273
576.9000000000075,62.89429822237283,-0.004301685162492614,-2.7321762388299167
578.0000000000075,63.00398799224511,-0.004393479340571618,-2.736226615050395
579.1000000000075,63.113232683505615,-0.0035248993105466866,-2.7361633661085447
580.2000000000075,63.22242597271366,-0.002342795639158257,-2.7390933560115993
581.3000000000076,63.332429408864016,-0.001350413484034842,-2.7431540384783992
582.4000000000076,63.442097323989906,-0.0019402500934334185,-2.745944191668631
583.5000000000076,63.55141698946434,-3.7620778849314594e-05,-2.7485379196137627
584.6000000000076,63.66174173497334,0.0002343927067381775,-2.7498471029525455
585.7000000000077,63.77119532368182,0.0035114034202548203,-2.7525989648813693
586.8000000000077,63.8802233062018,0.0039184632379862605,-2.7539265481676836
587.9000000000076,63.98981828256203,0.006548994796289054,-2.757194144386967
589.0000000000076,64.0985300058794,0.009237141474841039,-2.757870924417713
590.1000000000076,64.20881309369047,0.009171037016798285,-2.7581995529603773
591.2000000000077,64.319289769337,0.01157767006196522,-2.760781760518822
592.3000000000077,64.4280022040439,0.013878313016779104,-2.760904630707301
593.4000000000077,64.53776433893238,0.014582710568118143,-2.7647853216870253
594.5000000000077,64.64767254934728,0.014853896240775565,-2.76477964589727
595.6000000000078,64.75761220615948,0.01815535524896272,-2.7660001157851823
596.7000000000078,64.86828797334458,0.0192774329256681,-2.767420279616906
597.8000000000078,64.97785132255842,0.021019947470542293,-2.768213349462841
598.9000000000078,65.08753917979433,0.02320140085384671,-2.7698691773441064
600.0000000000078,65.19799304166257,0.024137116126700317,-2.7726041972982802
601.1000000000079,65.3077472276441,0.024611211536031644,-2.7740503554813456
602.2000000000079,65.41658647792997,0.02798095345822568,-2.7761946747576465
603.3000000000079,65.52470566319239,0.02942537725744184,-2.777412391640979
604.4000000000078,65.63629612197562,0.031154194395248063,-2.778876547970494
605.5000000000078,65.74507539223754,0.030908983238458292,-2.779755385285893
606.6000000000079,65.85334314662506,0.034519553269574794,-2.778176742787144
607.7000000000079,65.96416868458317,0.032364204865301525,-2.780858308120997
608.8000000000079,66.07439686015299,0.03486254029278465,-2.7821398752386273
609.9000000000079,66.18328822960085,0.03644924089527945,-2.7808558004833426
611.000000000008,66.2924662665654,0.038490198739179665,-2.783447973645628
612.100000000008,66.40162447988155,0.0409445950119523,-2.7834646322726346
613.200000000008,66.51098750423364,0.04370472158867713,-2.786235466279136
614.300000000008,66.61980604851647,0.044827641978435105,-2.787504166004773
615.400000000008,66.73021173366138,0.04625436826329582,-2.78883006362426
616.5000000000081,66.8369405104276,0.04851882812204835,-2.790150232787023
617.6000000000081,66.94825041638417,0.04756134503997179,-2.790149926565688
618.7000000000081,67.05754299465607,0.050588219274256885,-2.7898333133881823
619.8000000000081,67.16790301759006,0.05166404637743869,-2.7904803064491577
620.9000000000082,67.27727592227441,0.053825212215578934,-2.7917838935239714
622.0000000000082,67.38736834293776,0.05569047796353255,-2.794102456722638
623.1000000000081,67.49642765832664,0.055391090714472416,-2.794104247103275
624.2000000000081,67.60725357062637,0.05854950614622593,-2.796730136933035
625.3000000000081,67.7146455833418,0.06118075382659571,-2.798108824097358
626.4000000000082,67.82487548824503,0.06298485655805451,-2.798034593590868
627.5000000000082,67.9367981724352,0.06514300181077455,-2.798006572278549
628.6000000000082,68.04635129371205,0.06617024185955023,-2.7980596008812975
629.7000000000082,68.15600428250542,0.06916265406937747,-2.8014742511880852
630.8000000000083,68.26610292486217,0.07289864667640925,-2.8020002756769067
631.9000000000083,68.37519707955809,0.0752730582849915,-2.8034305970200055
633.0000000000083,68.48431580710455,0.07449238533905114,-2.8047495741027344
634.1000000000083,68.59500788994168,0.07787215481866915,-2.804417659847976
635.2000000000083,68.70534442140061,0.07832608844725537,-2.8031112054384293
636.3000000000084,68.81608338855067,0.08054227401875308,-2.803271846810879
637.4000000000084,68.92621350730491,0.08252849877935955,-2.803078207642404
638.5000000000084,69.03669851994368,0.08168466032858336,-2.805745687775127
639.6000000000083,69.14635240145574,0.0839904655007244,-2.8057392596507698
640.7000000000083,69.25672779027526,0.08559175917931677,-2.8067206541206016
641.8000000000084,69.36642611877558,0.08751273552178065,-2.808394122571402
642.9000000000084,69.4765636068353,0.09103723887499073,-2.808697037006641
644.0000000000084,69.58743937382383,0.0923964332902674,-2.8100228126302795
645.1000000000084,69.69633676276823,0.09295739182994289,-2.8109642563886523
646.2000000000085,69.80600447444544,0.09245954908215331,-2.8126299929181653
647.3000000000085,69.91656635982183,0.09303425637468507,-2.8119562363231236
648.4000000000085,70.02626344971901,0.09424738444818234,-2.8126499479691986
649.5000000000085,70.13662766179567,0.09380640591579487,-2.8126499490447276
650.6000000000085,70.24561345009138,0.09456298384908067,-2.8128596642301407
651.7000000000086,70.35652071665844,0.09430287896195441,-2.814244066824025
652.8000000000086,70.46666163784346,0.09414574331498511,-2.816920402995239
653.9000000000086,70.57705886186321,0.09474652574591845,-2.818560323430578
655.0000000000086,70.68699444934856,0.09372062844303071,-2.817261020944334
656.1000000000087,70.79602724095601,0.09104359624645145,-2.8185799112869523
657.2000000000087,70.90751458669934,0.0907588980514967,-2.8178802422621585
658.3000000000086,71.01824846104589,0.08986432537231234,-2.8172686231056896
659.4000000000086,71.12743902813125,0.09022012090747512,-2.817266698425248
660.5000000000086,71.23684463197195,0.09017889176615745,-2.818558136445471
661.6000000000087,71.34818116771471,0.09090351081670027,-2.8212198979929717
662.7000000000087,71.45880460438349,0.09202916615763329,-2.8225349339825585
663.8000000000087,71.56877103266955,0.09267514556192345,-2.8225401760025965
664.9000000000087,71.67900379875327,0.08787177539779649,-2.8225401817604494
666.0000000000088,71.7885245847156,0.09027612029482182,-2.822537365331285
667.1000000000088,71.90020152502946,0.09108217466088639,-2.825171764100757
668.2000000000088,72.01010446800537,0.09119605549075065,-2.823859256657391
669.3000000000088,72.1201018889448,0.0901694753797949,-2.8238498158336154
670.4000000000088,72.2305677516406,0.08737296162438908,-2.8225456157254247
671.5000000000089,72.34107481733177,0.08699981844376503,-2.8215403375174013
672.6000000000089,72.45210241774538,0.08536295516101472,-2.824056928457888
673.7000000000089,72.56103117520188,0.08553329957363581,-2.8271844546438576
674.8000000000088,72.67172316014086,0.08510068084759116,-2.8278098005788017
675.9000000000088,72.78212989805569,0.08518538461745143,-2.828369488661841
677.0000000000089,72.89249853058777,0.08461794667391728,-2.8291198395946027
678.1000000000089,73.002852899985,0.08450322382071321,-2.8304405735909715
679.2000000000089,73.11324576003719,0.08412621956809717,-2.8316578190921264
680.3000000000089,73.22456901618813,0.08233605170289907,-2.831429931937249
681.400000000009,73.33493410515747,0.08303163689824908,-2.8314300637627614
682.500000000009,73.44556912501578,0.08205810497522403,-2.8320539511024188
683.600000000009,73.55627423566847,0.08099605358912965,-2.833345167268692
684.700000000009,73.66716810350411,0.08131138983551947,-2.834723201685037
685.800000000009,73.77783044884377,0.07906389646990584,-2.836041393764374
686.9000000000091,73.88856272510955,0.07884411326075821,-2.836680633040041
688.0000000000091,73.99925390396089,0.07582410933495272,-2.8380066959633865
689.1000000000091,74.11066543585079,0.07745504873377992,-2.839330054475527
690.2000000000091,74.22134561691423,0.07677571647573428,-2.839330019999972
691.3000000000092,74.33185128957953,0.0739160364528388,-2.839330020441522
692.4000000000092,74.44312469677435,0.07361635322909672,-2.840530747102278
693.5000000000091,74.55360167219006,0.0721041391250623,-2.841453618815439
694.6000000000091,74.66406126054028,0.06800247292103746,-2.8419597554979896
695.7000000000091,74.77429167188728,0.06915483144383837,-2.8402756633972075
696.8000000000092,74.88592987466768,0.06804623025019867,-2.8415698471759585
697.9000000000092,74.99709057556868,0.0651735378075245,-2.8433465178694926
699.0000000000092,75.10652705201133,0.06281946996390111,-2.8419714193601404
700.1000000000092,75.2181979096152,0.06166867571296574,-2.8445992149095733
701.2000000000093,75.3295110411178,0.057826293959055045,-2.844600245846231
702.3000000000093,75.44030044797326,0.0576421961827353,-2.84459945901084
703.4000000000093,75.55183186077052,0.05694230200929043,-2.8446002185973507
704.5000000000093,75.66211231476272,0.05346605517630112,-2.845910186582336
705.6000000000093,75.77120501424503,0.05200650245455344,-2.848550075129822
706.7000000000094,75.8813397310133,0.049316323635413946,-2.8472512120139752
707.8000000000094,75.99289320353287,0.047015105322278976,-2.8459227604715442
708.9000000000094,76.1039232760674,0.044858762562670136,-2.8482200678719525
710.0000000000093,76.21452756619829,0.04272458858620824,-2.84953805146924
711.1000000000093,76.32650779300027,0.04085435020123465,-2.84954006160393
712.2000000000094,76.43658222646238,0.03967449158437682,-2.8495241304399266
713.3000000000094,76.54713751679516,0.03879170260372118,-2.8507370421567377
714.4000000000094,76.65920126583109,0.03288494090976513,-2.850906922078733
715.5000000000094,76.76980292732603,0.034124024959825965,-2.8508595495718634
716.6000000000095,76.88144657799452,0.030474621416707617,-2.8502044047013455
717.7000000000095,76.99284843850431,0.027350706251962835,-2.8495449077380455
718.8000000000095,77.1033189381292,0.024198903344405897,-2.8521881144369408
719.9000000000095,77.21362181086079,0.02076978276456668,-2.853490743638334
721.0000000000095,77.32485959817627,0.018774463683384108,-2.856129697571184
722.1000000000096,77.43685164210493,0.01608603695868205,-2.8568021291821646
723.2000000000096,77.54845921666868,0.014343156972511397,-2.8574612257453116
724.3000000000096,77.66057484264675,0.007203067323060067,-2.8587597859435268
725.4000000000096,77.7716820011679,0.004347658838938049,-2.8574477730918675
726.5000000000097,77.88263651991878,0.0022931343988900057,-2.860164759477663
727.6000000000097,77.99255715904818,-0.004285722136251389,-2.8627202393555216
728.7000000000096,78.10744684212905,-0.006100278720884941,-2.8640392755543855
729.8000000000096,78.21764268747111,-0.011475860333910813,-2.8642038520144597
730.9000000000096,78.3292663397845,-0.014980236904724971,-2.8653437637220747
732.0000000000097,78.44135101712496,-0.019144986913703716,-2.8662322744505544
733.1000000000097,78.55155806306809,-0.02024428190350034,-2.8654496969100958
734.2000000000097,78.66300602097631,-0.025849653020236847,-2.863865202768307
735.3000000000097,78.77167594346102,-0.02666797362728956,-2.864587395632156
736.4000000000098,78.88458887322744,-0.032493003342600864,-2.8666119199733435
737.5000000000098,78.99680192018359,-0.033580976165966586,-2.867879927464637
738.6000000000098,79.10908620284911,-0.035553364263880616,-2.8691900399763504
739.7000000000098,79.22079523480878,-0.03881991315277277,-2.870178826188881
740.8000000000098,79.33111935162569,-0.042976779265260674,-2.868870095870686
741.9000000000099,79.44392746164031,-0.04748825700885303,-2.8682019752632946
743.0000000000099,79.55591529541431,-0.04890601064477349,-2.870840054767349
744.1000000000099,79.66676815614281,-0.05118588120854812,-2.872160514578708
745.2000000000098,79.77867538198966,-0.05259355015087467,-2.8721521254395057
746.3000000000098,79.89055339724091,-0.057882742203693334,-2.873470082689327
746.7000000000099,79.93094114740799,-0.058827544095473264,-2.8734699250486937