File: 01_Data/PU_Aerogel/STA/N2/10K_min/PU_Aerogel_STA_N2_10KData_230201_R2.csv
##Temp./Â°C,Time/min,DSC/(mW/mg),Mass loss/mg
50.0,10.8649625621252,-1.8926479414425879,0.01968182735548929
51.100000000000016,11.177103817455267,-1.7786629842324437,0.019775042866962966
52.20000000000003,11.407312784797433,-1.701744900013781,0.018943120978605954
53.30000000000005,11.604826477723806,-1.6409180223853763,0.01961915409510162
54.40000000000006,11.784577625253963,-1.5916325648218117,0.01992666776664276
55.50000000000008,11.950830000000012,-1.5515099999999977,0.019747544324703714
56.600000000000094,12.105509659328192,-1.519505359842807,0.01754561970088675
57.70000000000011,12.261533526392014,-1.4921498591852578,0.019550373328665493
58.800000000000125,12.40788234130253,-1.4653978044676141,0.02000384843616665
59.90000000000014,12.546757822935417,-1.4449297084359436,0.018755466400780296
61.000000000000156,12.691418673357033,-1.424245728516577,0.019537554147375236
62.10000000000017,12.828761311972738,-1.4092391737501118,0.019915717165372993
63.20000000000019,12.962241359251188,-1.3906253562844084,0.019619373193894507
64.30000000000021,13.095208175423457,-1.3781723657848506,0.01951676270447722
65.40000000000022,13.225969939661562,-1.362557272794269,0.020285712144104906
66.50000000000023,13.356437700095709,-1.350020209301069,0.021222604957467528
67.60000000000025,13.482563491974522,-1.335754177755898,0.021272585701506586
68.70000000000027,13.610382976561091,-1.323397582184458,0.020669696710951868
69.80000000000028,13.735031788070934,-1.3112301457476636,0.021211360753834896
70.90000000000029,13.859158221805258,-1.2997841746203214,0.020742598275603985
72.00000000000031,13.98224044358067,-1.290277443864483,0.019871943683553273
73.10000000000034,14.104010894470328,-1.2794243896022222,0.021534657989826123
74.20000000000034,14.225118253553262,-1.2707502199351617,0.02002254396317049
75.30000000000035,14.34582061025616,-1.2606572399226543,0.021650152808484258
76.40000000000038,14.465365838146596,-1.2495638873259933,0.022438116957831156
77.5000000000004,14.584192576415273,-1.242104600897449,0.02182678942987959
78.6000000000004,14.702337102148704,-1.2332478331600252,0.0223025721970056
79.70000000000041,14.81679625614535,-1.2249170357246588,0.02250782689776676
80.80000000000044,14.935346915004397,-1.216015520744275,0.02247938553809181
81.90000000000046,15.051187247362689,-1.2068991129309663,0.022504218580794877
83.00000000000047,15.16575880614922,-1.1996481690920704,0.022474544644792704
84.10000000000048,15.279003397616803,-1.191488922318211,0.021708341680561904
85.2000000000005,15.391918027451487,-1.1838477529863043,0.022493141918826787
86.30000000000052,15.50501199595909,-1.174807315039846,0.022510200835086813
87.40000000000053,15.617324022949616,-1.1678910291218023,0.021564605208489684
88.50000000000054,15.72510958708256,-1.1599633155077125,0.022464303559986742
89.60000000000056,15.839033148023173,-1.1517277694645354,0.022499477082137176
90.70000000000059,15.9507230064401,-1.1444221727623245,0.021526464151541802
91.8000000000006,16.06046127810007,-1.1383929661813204,0.023821035635639642
92.9000000000006,16.167873972150492,-1.1333234153434082,0.022501275738135984
94.00000000000063,16.27787130865461,-1.1254134503579474,0.023578516093979207
95.10000000000065,16.388971862177993,-1.1169732531464809,0.02387918370562181
96.20000000000066,16.49713117577652,-1.1118200313644544,0.023934011920698772
97.30000000000067,16.606293217596278,-1.1045483429491791,0.02428835266737961
98.40000000000069,16.71610381671518,-1.098659914510087,0.02450253795438595
99.50000000000071,16.8245747019179,-1.093071985568812,0.02392085003044464
100.60000000000072,16.931484249907893,-1.0863281674077165,0.02381157960090574
101.70000000000073,17.039387594241536,-1.0795246166305899,0.02379275843897588
102.80000000000075,17.14696986773365,-1.0748870128383199,0.023809702562838098
103.90000000000077,17.25484227433649,-1.0676602144296974,0.024536732643369863
105.00000000000078,17.36148694689148,-1.062506944524742,0.026434838439236774
106.10000000000079,17.469036344901262,-1.0565905457600815,0.025131584697457132
107.20000000000081,17.574175321909404,-1.049798632061068,0.023827532781275362
108.30000000000084,17.682146537360328,-1.0445258242157742,0.023828012688224653
109.40000000000084,17.787150492675043,-1.0379115680747857,0.02511785979215375
110.50000000000085,17.89515100796586,-1.0328645816439133,0.02514995610287496
111.60000000000088,18.003079789517493,-1.0279376457258285,0.02497458783768547
112.7000000000009,18.10980586790247,-1.0217159934781335,0.02538817007214389
113.8000000000009,18.21516754435275,-1.0162819317262368,0.025135653126176383
114.90000000000092,18.322174092465865,-1.0100688168771814,0.023816199137139282
116.00000000000094,18.42976819734384,-1.0064285371240353,0.024703564773985942
117.10000000000096,18.535221048944194,-0.9999020824992343,0.024221674336246224
118.20000000000097,18.641006193177585,-0.9954326865147233,0.025130032004349268
119.30000000000098,18.74651570436209,-0.9898996075104209,0.0251299287430502
120.400000000001,18.85299485794807,-0.9831256595300367,0.02512847682375785
121.50000000000102,18.958712459471904,-0.979029974859523,0.02514311222427379
122.60000000000103,19.06501236958895,-0.9729707325971074,0.02382028781959633
123.70000000000104,19.170380594808226,-0.9686602800565633,0.023820345032451673
124.80000000000106,19.276004548542975,-0.9632951602792723,0.023819725544517834
125.90000000000109,19.382078810718323,-0.9583026277034397,0.025137012788348123
127.0000000000011,19.48679086414308,-0.9549038385779544,0.02381005821182436
128.1000000000011,19.593091373322245,-0.9487666189534739,0.023828886165516483
129.20000000000113,19.697192202221334,-0.9446211921098041,0.023819952665312893
130.30000000000115,19.80154645614157,-0.9406366545850693,0.022487227768372087
131.40000000000117,19.90739556977564,-0.9343599673792393,0.022831594592711557
132.50000000000117,20.01250979487126,-0.9294510891423086,0.022551178451843956
133.6000000000012,20.118475058305172,-0.9266084648761247,0.023818068201936438
134.7000000000012,20.223327655593106,-0.9213447182149397,0.023656702832488552
135.8000000000012,20.327823631503172,-0.9174208573213898,0.022500230999552784
136.90000000000123,20.432595652157413,-0.912722717811193,0.0225092404090268
138.00000000000125,20.53726048414763,-0.9093392481515673,0.023819992756163533
139.10000000000127,20.64091646139142,-0.9060922952924274,0.02354537593932271
140.2000000000013,20.746360346021945,-0.8995430685107686,0.02354419861634094
141.3000000000013,20.848828581520156,-0.895816636740665,0.023721494385943398
142.4000000000013,20.95300266876437,-0.8911751637060994,0.023802477472130157
143.50000000000134,21.058506491808227,-0.8872182236516,0.023861745175760785
144.60000000000133,21.162595284950697,-0.8824185460188305,0.024140467252651288
145.70000000000135,21.26696557820962,-0.8777676120076617,0.025135519007790208
146.80000000000138,21.37092661734625,-0.8724288879735259,0.025130090370829805
147.9000000000014,21.47338819403443,-0.8685077315807569,0.023818121597629194
149.00000000000142,21.578215211944894,-0.8640755026840262,0.02428936499508705
150.10000000000142,21.682215964843888,-0.8601388094220013,0.025129672032357053
151.20000000000144,21.787103504368595,-0.8563123019964916,0.023809918658810325
152.30000000000146,21.890435243773922,-0.8524437238891291,0.023810233018869198
153.40000000000146,21.993472803621682,-0.8493921689423671,0.023809808800950183
154.50000000000148,22.097731034367502,-0.8442239927641538,0.025129106828266412
155.6000000000015,22.200725198361695,-0.8417837016265115,0.023843888814890857
156.70000000000152,22.30454208837946,-0.8365354311381485,0.023820138898979604
157.80000000000155,22.409339678317068,-0.8328491054825986,0.025143272754401202
158.90000000000154,22.51192572504098,-0.8282828812123925,0.023819951673455186
160.00000000000156,22.61607644707636,-0.8254746573563333,0.025127221466586747
161.1000000000016,22.718893920043648,-0.82083911598694,0.023808302531066694
162.20000000000158,22.822608450997304,-0.8172565847881098,0.02281936292198994
163.3000000000016,22.927150287257266,-0.8139148195925365,0.02281953745651588
164.40000000000163,23.031394493750316,-0.8106827528906656,0.023819761530908146
165.50000000000165,23.135716746569756,-0.80491453769892,0.022499840694433004
166.60000000000167,23.238636377163306,-0.8027500040516464,0.02249898362534397
167.70000000000167,23.34244060495608,-0.7992638160503439,0.02117988696222506
168.8000000000017,23.446441229224916,-0.7933733347917356,0.021179812505527362
169.9000000000017,23.551194879778986,-0.7896272848986159,0.019859734633100423
171.0000000000017,23.65374001495611,-0.7863156053453673,0.02084995883882712
172.10000000000173,23.75717056506417,-0.7815493522245635,0.021231109244262303
173.20000000000175,23.860926483728505,-0.7767464494090747,0.019870140240616507
174.30000000000177,23.96392729361064,-0.772256921219974,0.019870226777506605
175.4000000000018,24.066117486818552,-0.7697230751725342,0.01982497590848764
176.5000000000018,24.171449261110517,-0.7664462228969993,0.01886757355704427
177.6000000000018,24.27447725256263,-0.762326298856476,0.018879809116166157
178.70000000000184,24.37921727217966,-0.7581777199343197,0.017541032680902013
179.80000000000183,24.482730347049884,-0.7564629605830032,0.018748534807579098
180.90000000000185,24.585257440652597,-0.7525470295330534,0.01755433596667766
182.00000000000188,24.689133029688804,-0.7500777474061708,0.017890009047420552
183.1000000000019,24.79322513219165,-0.7459930143113828,0.01789005022350798
184.20000000000192,24.89484047615904,-0.7431415379852145,0.017227952927988177
185.30000000000192,24.998820277316952,-0.7399265469380373,0.016898491275437966
186.40000000000194,25.10252800881904,-0.7370131996308772,0.015498481546249998
187.50000000000196,25.206285700493158,-0.7340078628087713,0.01493057515128049
188.60000000000196,25.308975024574476,-0.7313434139644599,0.014929991095776085
189.70000000000198,25.41245444582291,-0.7261595765337434,0.01492997145568875
190.800000000002,25.515137868095515,-0.7241356498913005,0.012290580161354647
191.90000000000202,25.618889079464534,-0.7200141254553621,0.013609127545133326
193.00000000000205,25.71949489753473,-0.7167720046482197,0.012289871453187828
194.10000000000204,25.82646147426718,-0.714284076476423,0.012289804474266308
195.20000000000206,25.929988367180393,-0.7108116088083412,0.010970094967169164
196.3000000000021,26.032396021825665,-0.7062297471140757,0.01031007373424675
197.40000000000208,26.13713839557272,-0.7021389868645946,0.01030495400362641
198.5000000000021,26.240045772845477,-0.6976305368982707,0.008362483613700622
199.60000000000213,26.343873061259906,-0.6929699016053383,0.008339944037055513
200.70000000000215,26.44664571886862,-0.6903727681540475,0.008339940136450785
201.80000000000217,26.550557847892403,-0.6839848478023836,0.00703393680303277
202.90000000000217,26.655273646736056,-0.679038409467032,0.006978775496759848
204.0000000000022,26.758163634134746,-0.6744673188731456,0.005700078516507112
205.1000000000022,26.862769700270242,-0.6678329318247854,0.005699547023148899
206.2000000000022,26.96588373452617,-0.6635050827815157,0.003718192324059455
207.30000000000223,27.06971968804135,-0.6577835830020113,0.003730141669702647
208.40000000000225,27.173185376354542,-0.6470641982059995,0.0017502981398869188
209.50000000000227,27.27768983752962,-0.6416017937424552,0.0004302297476024286
210.6000000000023,27.38064326182928,-0.6320983998882785,0.00043015199981866203
211.7000000000023,27.485165549971807,-0.6243475904524094,0.000433093743169799
212.8000000000023,27.58714019033929,-0.6146392454845772,-0.0008903321859996538
213.90000000000234,27.691874108468554,-0.6013876840291809,-0.0035670547131099184
215.00000000000233,27.79515953040247,-0.5887508321019405,-0.0035199682408757482
216.10000000000235,27.89908674301713,-0.5764195432416641,-0.0035463811478617657
217.20000000000238,28.003027264765052,-0.5603423554379501,-0.00497391912158518
218.3000000000024,28.10600517812235,-0.5425195142380937,-0.00877427102574746
219.40000000000242,28.2089527320527,-0.5233407399779113,-0.009952290971379174
220.50000000000242,28.313196325299728,-0.5000187385957919,-0.012044390804835992
221.60000000000244,28.416668831446383,-0.4764314401118301,-0.013304227158814186
222.70000000000246,28.521179139949,-0.4514912545388502,-0.017050718363349482
223.80000000000246,28.624709020601706,-0.42445052448457027,-0.018963926700053424
224.90000000000248,28.72857811399248,-0.39453270803625484,-0.021920480217580973
226.0000000000025,28.831210205800446,-0.3679600203020991,-0.025929827257128224
227.10000000000252,28.934885201478732,-0.3379577835558631,-0.028705030216326755
228.20000000000255,29.03890365142138,-0.31009660125888927,-0.03244206811682515
229.30000000000254,29.143703113930542,-0.2811502513914388,-0.03619264089708185
230.40000000000256,29.246526654071282,-0.25608399749095473,-0.04117752124192897
231.5000000000026,29.35065369073696,-0.2343379637084924,-0.045675362957279475
232.60000000000258,29.45476653786015,-0.21582363923505565,-0.0500645949012557
233.7000000000026,29.55829027346106,-0.19870375899202444,-0.05579399152343045
234.80000000000263,29.66272541693796,-0.1835202327870623,-0.06129890592185694
235.90000000000265,29.765784620388576,-0.1719854326240297,-0.06621892379676453
237.00000000000267,29.86890904544949,-0.16197631157317322,-0.07326567034762288
238.10000000000267,29.97394069295511,-0.1534798029061065,-0.08196629363643515
239.2000000000027,30.076399746249983,-0.14607123701188351,-0.09117112893491175
240.3000000000027,30.181300328128124,-0.14152384884607208,-0.09853552436312274
241.4000000000027,30.285292878281673,-0.13442496025977818,-0.10715839033739183
242.50000000000273,30.389611908094018,-0.12877795139758383,-0.11787574500852482
243.60000000000275,30.493415283719045,-0.12497685928216637,-0.1260984163843224
244.70000000000277,30.596530822911113,-0.11884167758198656,-0.13688222128037975
245.8000000000028,30.701633379761322,-0.11191508002458984,-0.1482965991248988
246.9000000000028,30.805558035599915,-0.10427567253872648,-0.15859425941203265
248.0000000000028,30.91026123503361,-0.0967239512457396,-0.17143475444644718
249.10000000000284,31.012812141263833,-0.08961867427715164,-0.18398425842042299
250.20000000000283,31.118503696985293,-0.08133306156996654,-0.1960463341324492
251.30000000000285,31.221584184869734,-0.07282185793800136,-0.20960820264682312
252.40000000000288,31.32657679338407,-0.06447813761611618,-0.22331057400669874
253.5000000000029,31.43017296290486,-0.05814228626341753,-0.23760229382775044
254.60000000000292,31.53418772309541,-0.050106986220010336,-0.2538781115993536
255.70000000000292,31.638865141170765,-0.04422894126449457,-0.2692107600713314
256.8000000000029,31.74263499728908,-0.03841586291254149,-0.28523179915132957
257.90000000000293,31.84698040115809,-0.03397794302566243,-0.3013754739311878
259.00000000000296,31.95147574250625,-0.02893697194291124,-0.31872484915602994
260.100000000003,32.05615667670868,-0.027821147072737615,-0.3362556916380086
261.200000000003,32.160553752973286,-0.02662752272600346,-0.35499403964352405
262.300000000003,32.26505458963894,-0.02727157318656962,-0.3721751987065405
263.40000000000305,32.368861872676575,-0.0290757274264907,-0.3907606496685676
264.50000000000307,32.47125633444532,-0.03250440346068041,-0.4096579880222082
265.6000000000031,32.57757861807043,-0.037039538560990966,-0.43005773266750147
266.7000000000031,32.68227834679353,-0.04486321570950937,-0.44950047657679715
267.8000000000031,32.78767896716777,-0.05236580862306275,-0.47032813691035136
268.9000000000031,32.89110229260847,-0.06310863378171198,-0.4899325322624688
270.0000000000031,32.99495122765975,-0.07585581378371144,-0.5096298303527722
271.10000000000315,33.09892412051569,-0.09014565746174924,-0.5287458655356141
272.2000000000032,33.20487677067795,-0.1046822814433132,-0.5485524721143769
273.30000000000314,33.309588784439754,-0.12204178585627774,-0.5676635369501115
274.40000000000316,33.411663162725574,-0.14063675332440295,-0.5850403314330315
275.5000000000032,33.51840285841362,-0.15869243327410834,-0.6037552970913245
276.6000000000032,33.62346594552327,-0.1796999742757947,-0.6192332339308928
277.70000000000323,33.72839619181058,-0.19657837632410974,-0.6345421364902015
278.80000000000325,33.83177210251732,-0.21620220509823465,-0.6491043214296921
279.9000000000033,33.93551503642379,-0.23279773653057362,-0.662392325752938
281.0000000000033,34.041278937071674,-0.24905805731503758,-0.6753305217025125
282.1000000000033,34.14569924135663,-0.2611439271726378,-0.687389466944571
283.20000000000334,34.24963490332814,-0.2739391185530261,-0.7006055639988049
284.30000000000337,34.35390810422751,-0.28245227932361183,-0.7102219011210238
285.40000000000333,34.458795447281844,-0.2913817900651244,-0.7220841595261551
286.50000000000335,34.561917403442926,-0.29525117300434117,-0.7315091027518683
287.6000000000034,34.66775721606067,-0.2995818080827797,-0.7417137337065984
288.7000000000034,34.77065406324878,-0.30193593412004394,-0.749911741227161
289.8000000000034,34.8763235546298,-0.3024679125471094,-0.7593835030963811
290.9000000000034,34.97831944419861,-0.3019258906826856,-0.7692105650086432
292.0000000000034,35.08458655808702,-0.30040389320000604,-0.7756522471096998
293.10000000000343,35.19037268106111,-0.29826877007329017,-0.7833971491273188
294.20000000000346,35.294481090076786,-0.29512415514407153,-0.7907147527138574
295.3000000000035,35.39822064220315,-0.29184588290161323,-0.8010113045786214
296.4000000000035,35.5024137147432,-0.28652682732104473,-0.8080727915570463
297.5000000000035,35.60935913822149,-0.2810346890092526,-0.8171535230553117
298.60000000000355,35.71391205936071,-0.2750957533243832,-0.823068819223137
299.70000000000357,35.8179899209111,-0.26855479980468144,-0.8298506574513009
300.8000000000036,35.92356477800405,-0.2594280787366739,-0.8381692093022952
301.9000000000036,36.028587926494396,-0.25435540249576594,-0.8458386076091111
303.0000000000036,36.13367577941114,-0.24915907119295658,-0.8529922174541555
304.1000000000036,36.23867323515485,-0.24331056121841613,-0.8576814389939176
305.2000000000036,36.34359111349489,-0.2345924575119358,-0.8646771210761446
306.30000000000365,36.44827872764947,-0.22784262059718555,-0.871635110366757
307.4000000000037,36.55396204751843,-0.21899423026690804,-0.879177052705884
308.5000000000037,36.65821673717921,-0.2083637629000525,-0.8847692813074972
309.60000000000366,36.764151417813046,-0.20234596138596864,-0.893653725770096
310.7000000000037,36.869174975875175,-0.19422152802070247,-0.8997622043369544
311.8000000000037,36.973923374798005,-0.18646176770846948,-0.9069702666152688
312.90000000000373,37.07700550750008,-0.17819711242613795,-0.9133851305608878
314.00000000000375,37.18487234987005,-0.17107614797287732,-0.9227139389508143
315.1000000000038,37.28928810114869,-0.16217256595963514,-0.9303040869726522
316.2000000000038,37.39411106382953,-0.1565678838577095,-0.9383898546141816
317.3000000000038,37.4999631845281,-0.15118676047008278,-0.9448828381546934
318.40000000000384,37.605645626678744,-0.14131555040533686,-0.953244207935382
319.5000000000038,37.71053226373451,-0.13536661800642055,-0.96310816823495
320.60000000000383,37.81732402039087,-0.12938197360484105,-0.9720938604647267
321.70000000000385,37.92242696429373,-0.12259978634722311,-0.9807122883589598
322.8000000000039,38.02700050722805,-0.11689959676980026,-0.9903236060833525
323.9000000000039,38.13214971075218,-0.11146368324324323,-0.9990370119252665
325.0000000000039,38.237403076504364,-0.10850240699799213,-1.009022121982925
326.10000000000394,38.34082902875039,-0.10483009199558961,-1.0197799419573026
327.2000000000039,38.44786462300067,-0.10066058974043049,-1.030546148126291
328.30000000000393,38.553172789465705,-0.09632815138361055,-1.0388920524595893
329.40000000000396,38.658898946455906,-0.09428312335373974,-1.0498123118538247
330.500000000004,38.76457901687017,-0.0907760585357514,-1.0598526162936275
331.600000000004,38.869414595446514,-0.08784117501874937,-1.0721035155015475
332.700000000004,38.9743700472948,-0.08760436632293367,-1.08210349110312
333.80000000000405,39.0796549564158,-0.08993657562817252,-1.0925670980126228
334.90000000000407,39.18680845219629,-0.0942515089115762,-1.1052400967457499
336.0000000000041,39.29202346963085,-0.09929687162164996,-1.1172598024603602
337.10000000000406,39.39711715650648,-0.10337675284290768,-1.1290616888236151
338.2000000000041,39.502854656344915,-0.10919109661308715,-1.1398114305540479
339.3000000000041,39.61016344511975,-0.11432631695610414,-1.1529400191433083
340.4000000000041,39.71364671571038,-0.11821626906937743,-1.1654612262042763
341.50000000000415,39.81989727038313,-0.1216613475117177,-1.1766181241734812
342.6000000000042,39.92524539374996,-0.12669518023451268,-1.1888230145220344
343.7000000000042,40.03118920723186,-0.1287567454640549,-1.2028259156896128
344.80000000000416,40.136737025747394,-0.13175912692136163,-1.21452007635787
345.9000000000042,40.24236350965469,-0.1376558249020555,-1.226253747385253
347.0000000000042,40.34917748625399,-0.1418025847754505,-1.2396036330638953
348.10000000000423,40.455381359936425,-0.1455908296560719,-1.2508854051839817
349.20000000000425,40.5610201714338,-0.15278103840042764,-1.2624184589188268
350.3000000000043,40.665972273262916,-0.16135259372574393,-1.2750412116772423
351.4000000000043,40.77229215430382,-0.16857958167967194,-1.2879554035245229
352.5000000000043,40.87868011395906,-0.1730812699819606,-1.3000066929010172
353.60000000000434,40.98445652376594,-0.181322167690792,-1.3119051340974064
354.7000000000043,41.090328342979205,-0.1895616585590717,-1.3226217024618996
355.80000000000433,41.19667738892287,-0.199896207009731,-1.3339262609660736
356.90000000000435,41.30048387463851,-0.2101942481490856,-1.344168043751381
358.0000000000044,41.407943322802055,-0.21902093484449095,-1.3550396164666334
359.1000000000044,41.51410999964225,-0.227413202956502,-1.3659425308908273
360.2000000000044,41.62042416045584,-0.2385000692402173,-1.374468659441122
361.30000000000445,41.72641821267321,-0.24940474988806008,-1.383462279398847
362.4000000000044,41.83146841670069,-0.25695114168554045,-1.3928595197143347
363.50000000000443,41.937072794527346,-0.2673456452157723,-1.4028411504714757
364.60000000000446,42.04399475418312,-0.2742012290092861,-1.410567232234743
365.7000000000045,42.15027075922234,-0.2845710708263861,-1.4191438527557478
366.8000000000045,42.257027765959876,-0.29084190884815203,-1.4275067069072351
367.9000000000045,42.363357295235424,-0.2996663921957476,-1.4347164251238493
369.00000000000455,42.469766313615935,-0.30636246304327164,-1.4418191713349784
370.10000000000457,42.57492781068605,-0.3120867954361228,-1.4467882917124237
371.2000000000046,42.68194739119773,-0.3194657233722698,-1.4545392205505268
372.30000000000456,42.787651633424794,-0.32320110940744967,-1.4623547953155045
373.4000000000046,42.89378947225846,-0.3296694068037692,-1.4701005441350357
374.5000000000046,43.00092897152198,-0.33557161283208514,-1.4749599696537712
375.6000000000046,43.106441477678764,-0.33948077594524395,-1.4825808617965186
376.70000000000465,43.2123172590754,-0.3442773804751257,-1.4897546057687654
377.8000000000047,43.318757951175314,-0.3484344101129691,-1.4960713034827866
378.9000000000047,43.42453449627344,-0.3543613322764794,-1.5031251076035517
380.00000000000466,43.53093266967854,-0.3562656400342896,-1.509978683430984
381.1000000000047,43.63747543648329,-0.36110088817290353,-1.5166133652347193
382.2000000000047,43.74362671445121,-0.3639956898576597,-1.5232562308216324
383.30000000000473,43.850255388257025,-0.3662520533268239,-1.5304287802525498
384.40000000000475,43.95581148619036,-0.3700815774419787,-1.537087963232084
385.5000000000048,44.06367511131414,-0.37249318570309947,-1.5447517153478376
386.6000000000048,44.17064113955958,-0.37699920612091,-1.5516694606684136
387.7000000000048,44.277239499971685,-0.37888845770898427,-1.5584238782960118
388.80000000000484,44.383710627245655,-0.3810874790959552,-1.5661932492836321
389.9000000000048,44.49083092233508,-0.3815100069419636,-1.573540016247636
391.00000000000483,44.597165368567424,-0.3825192255528541,-1.5805135586539447
392.10000000000485,44.704442857685166,-0.3816579691479023,-1.588589817560571
393.2000000000049,44.81004824710324,-0.3822801261696023,-1.59543267098302
394.3000000000049,44.91749996040302,-0.38060221936598004,-1.6050718413514313
395.4000000000049,45.02554606438751,-0.37883082496797493,-1.6105076420920543
396.50000000000495,45.132011923311886,-0.37580896956695115,-1.6179651817716865
397.6000000000049,45.23922200479947,-0.3741473951794789,-1.6272699848968886
398.70000000000493,45.34638914301979,-0.3702376222043622,-1.6350926370442629
399.80000000000496,45.45337809456203,-0.36748608770355395,-1.6434376174762497
400.900000000005,45.559083565402304,-0.3632707153924544,-1.6529568708139224
402.000000000005,45.66681076893239,-0.358705361866414,-1.6617071010743238
403.100000000005,45.77499565907458,-0.3517426202296447,-1.6695934846893774
404.20000000000505,45.88216306558324,-0.3438903060638023,-1.6774348846082843
405.30000000000507,45.989694493417204,-0.3386930741194569,-1.6862347092121546
406.4000000000051,46.09696942288949,-0.3297377810345839,-1.6945837502713528
407.50000000000506,46.20348433531445,-0.3237949979859928,-1.7021423955137616
408.6000000000051,46.31043729908339,-0.3154672523644278,-1.7111696373655492
409.7000000000051,46.4178327814313,-0.30649396542146795,-1.7185730393441947
410.8000000000051,46.524570101266946,-0.29909743876880074,-1.728046853129369
411.90000000000515,46.63186447651828,-0.29050309992173984,-1.7348893190995605
413.0000000000052,46.740309704889754,-0.2817341042071846,-1.74411957127304
414.1000000000052,46.84647540814995,-0.27379881150480495,-1.7512882914473065
415.20000000000516,46.95388229220666,-0.2662443024793681,-1.7589010971488865
416.3000000000052,47.059145522979335,-0.2584686096391098,-1.7675637656193839
417.4000000000052,47.16742217086916,-0.25048344325917976,-1.7773663049575075
418.50000000000523,47.276179023004296,-0.24292496473105019,-1.7847939671149242
419.60000000000525,47.3812976504091,-0.2368182466723979,-1.792489574605896
420.7000000000053,47.489296318371665,-0.2314291259075014,-1.8006808113393897
421.8000000000053,47.59541240612373,-0.22291074129925528,-1.8103471370991842
422.9000000000053,47.703179015931916,-0.21806551021979367,-1.816628676665124
424.00000000000534,47.8092516898161,-0.21196748959030706,-1.8231505423165046
425.1000000000053,47.91833585057237,-0.20493756688971965,-1.8316647726050972
426.20000000000533,48.026285609846674,-0.19855579587485958,-1.8404955111632408
427.30000000000535,48.13334095189543,-0.19569545582282002,-1.8470278169398449
428.4000000000054,48.240552091633106,-0.18845951264130612,-1.8544128798186366
429.5000000000054,48.34709903246988,-0.18226427284515628,-1.863706408860287
430.6000000000054,48.45569338617146,-0.17936500267832628,-1.8730017034454618
431.70000000000545,48.56347731828021,-0.17447739003468526,-1.8795598942144571
432.8000000000054,48.672308786758116,-0.17035395929943667,-1.8873502921342995
433.90000000000543,48.779308814731806,-0.1648583765681474,-1.8955356148978089
435.00000000000546,48.88639093042442,-0.16115564468507776,-1.9043391154368816
436.1000000000055,48.99471038677722,-0.15719789472560616,-1.9127672159346907
437.2000000000055,49.103000291361994,-0.1547377128914855,-1.9190124817493137
438.3000000000055,49.211868504284425,-0.15133659096364316,-1.9263577700865262
439.40000000000555,49.31882615734886,-0.14974261051945362,-1.9343472225553136
440.50000000000557,49.42625638543687,-0.14826402116333304,-1.94149958475716
441.6000000000056,49.53416754366496,-0.1445496020734046,-1.9498818149457422
442.70000000000556,49.64273160592111,-0.14227615588710302,-1.9582033824863574
443.8000000000056,49.751413401422894,-0.13782692386515447,-1.9666898234802108
444.9000000000056,49.85889048674331,-0.13584873079017365,-1.9744606600178376
446.0000000000056,49.96770033511943,-0.1310442097532314,-1.9828330218940569
447.10000000000565,50.07518220726695,-0.12985722734475444,-1.9887634431731724
448.2000000000057,50.1817213330234,-0.12682853087462717,-1.996614421497057
449.3000000000057,50.290611518197444,-0.12528409188069883,-2.004310267470239
450.40000000000566,50.39701045466532,-0.12090770457050637,-2.0123933130098735
451.5000000000057,50.50532920354167,-0.11729815229534031,-2.02068287533213
452.6000000000057,50.61271160305798,-0.11493065563512739,-2.026319256083367
453.70000000000573,50.72023608273668,-0.11257383980606837,-2.0342189185961193
454.80000000000575,50.82787943654207,-0.10978645119211893,-2.0406509412801537
455.9000000000058,50.935850018496964,-0.10538663466151875,-2.0488914489299743
457.0000000000058,51.04331614190992,-0.10540585366879703,-2.0558785993149202
458.1000000000058,51.15113868367778,-0.10277270945092218,-2.0622145848317794
459.20000000000584,51.25820466049674,-0.10172863733418619,-2.070151768906757
460.3000000000058,51.36590348055082,-0.09966200910337734,-2.0773090394132736
461.40000000000583,51.471942609343046,-0.09928570303596623,-2.084168060611419
462.50000000000585,51.58231303093673,-0.09608381958931851,-2.0930034147785173
463.6000000000059,51.68926965578107,-0.09233369216771663,-2.097854083965383
464.7000000000059,51.79797010732909,-0.09164014354197945,-2.1043743244647333
465.8000000000059,51.90414509883069,-0.08899418860086847,-2.1108352690632106
466.90000000000595,52.012862091535474,-0.08613583375037707,-2.117889339032933
468.0000000000059,52.11913796025311,-0.08574357866831307,-2.125308362061662
469.10000000000593,52.226578184314896,-0.08512976563110887,-2.1304615292592066
470.20000000000596,52.33617574036748,-0.08306624516681764,-2.1371825774105595
471.300000000006,52.444482158366164,-0.0816851853308905,-2.1447452014428134
472.400000000006,52.55169745862979,-0.07991380416844332,-2.1520502098241057
473.500000000006,52.66012167975475,-0.07953192077406453,-2.157245729861142
474.60000000000605,52.769091074062686,-0.07703969178234389,-2.1634980501607384
475.70000000000607,52.877168001253914,-0.07701564351582142,-2.1708287849199506
476.8000000000061,52.984183391456554,-0.076310305686592,-2.17717615212847
477.90000000000606,53.09243135922493,-0.07313945685688941,-2.183675622333816
479.0000000000061,53.199240237115994,-0.07247856651672496,-2.189501971554365
480.1000000000061,53.308963948441836,-0.06978206308873243,-2.1954705315406224
481.2000000000061,53.417250126513906,-0.06959938040412664,-2.2028718890108894
482.30000000000615,53.52409136140539,-0.06733824473897558,-2.209979019702553
483.4000000000062,53.63307229150338,-0.06654466486266836,-2.217227444041238
484.5000000000062,53.74167039227199,-0.06647543519079104,-2.2235969297422598
485.60000000000616,53.849681897859725,-0.06595243297702323,-2.230202971643056
486.7000000000062,53.95815826914659,-0.065693074826503,-2.2356835471205505
487.8000000000062,54.066467382099816,-0.06372503730523975,-2.243976923581287
488.90000000000623,54.174627986817654,-0.06246754489896106,-2.2511619970788783
490.00000000000625,54.2827525847942,-0.06269705855360978,-2.256987485492737
491.1000000000063,54.39113006391575,-0.060516503399741954,-2.263742920901925
492.2000000000063,54.49837741864311,-0.059721471681026685,-2.2706649689799474
493.3000000000063,54.60752455008977,-0.05775976594735582,-2.279912363780207
494.40000000000634,54.71562692709384,-0.057493680440372785,-2.2856240673791204
495.5000000000063,54.82429723968171,-0.055076799257339194,-2.2927990383695054
496.60000000000633,54.93215295362512,-0.05469825782900727,-2.299853377966378
497.70000000000636,55.041030024403604,-0.05479008400988989,-2.307121874191775
498.8000000000064,55.14952783817761,-0.05372930787758469,-2.313994092962169
499.9000000000064,55.256517276877766,-0.052555617188830756,-2.3190817614670296
501.0000000000064,55.36747527048894,-0.05031062353688299,-2.3266660714346483
502.10000000000645,55.47401367315403,-0.05014009841102065,-2.3337670879253283
503.2000000000064,55.58336786011257,-0.04907577607010649,-2.341517172355167
504.30000000000643,55.6912276756247,-0.04698160627680699,-2.3477721174759516
505.40000000000646,55.800162484194665,-0.046498049075937645,-2.3545656200014817
506.5000000000065,55.908760956597966,-0.04522362430993131,-2.3618219476194
507.6000000000065,56.01785093490361,-0.0439185958587393,-2.368559896837633
508.7000000000065,56.12583920249171,-0.042230852494170065,-2.374060972561287
509.80000000000655,56.23343391464875,-0.04200906768426943,-2.3814405197102158
510.90000000000657,56.34253133738016,-0.041031509852032196,-2.387657363256879
512.0000000000066,56.45153985788823,-0.041360763137883186,-2.3948991414124663
513.1000000000065,56.559866538564556,-0.03992191766842301,-2.4005299339717796
514.2000000000066,56.66759472980143,-0.03683228263289617,-2.405414187150208
515.3000000000065,56.77702600984199,-0.036503332319349824,-2.411961813498521
516.4000000000067,56.886063942065235,-0.034886899725713454,-2.4187397696258834
517.5000000000066,56.99490224638606,-0.03342617770725638,-2.4249284289210324
518.6000000000067,57.10353575832175,-0.03248296234211588,-2.4289050000989167
519.7000000000066,57.21143651016747,-0.03161392199073141,-2.436177066860678
520.8000000000067,57.32125404337501,-0.030889860683505223,-2.4419107160181297
521.9000000000067,57.430081607727054,-0.030190607659779854,-2.4466721097444264
523.0000000000067,57.53935802016431,-0.02854876453234972,-2.4525532010753404
524.1000000000067,57.649166288234426,-0.02823172450157578,-2.45845910524421
525.2000000000068,57.75869100835058,-0.026207002753286912,-2.4641014401724872
526.3000000000068,57.867800962250485,-0.02409305031265769,-2.4695048300005578
527.4000000000068,57.97663011875912,-0.024192551110396792,-2.472038854714068
528.5000000000068,58.08594839746254,-0.023334231678441984,-2.4778066331550233
529.6000000000068,58.19493645376694,-0.020626877646139855,-2.482744577366463
530.7000000000069,58.304191265411255,-0.020851581804282843,-2.4868151332500155
531.8000000000068,58.41469045871358,-0.02014179220800777,-2.49405119201505
532.9000000000069,58.52160578812959,-0.021603071669616062,-2.4983734923400016
534.0000000000068,58.63185371633361,-0.017024328747703137,-2.5035943778000647
535.100000000007,58.74172117236204,-0.01581369337680504,-2.5085339671977795
536.2000000000069,58.849833758078915,-0.017289909489769086,-2.512020916997325
537.300000000007,58.96020926916105,-0.014563083758472798,-2.516862353859178
538.4000000000069,59.06871809766278,-0.014413396982844265,-2.5237946727192693
539.5000000000069,59.176444378133425,-0.0121155453095151,-2.526897924148249
540.600000000007,59.28567496106087,-0.011212190209865339,-2.5313374664719097
541.700000000007,59.39422322725769,-0.009920806338216459,-2.536983141237148
542.800000000007,59.50315456603095,-0.008985614913549399,-2.539837969464931
543.900000000007,59.61196467043254,-0.008519961727835937,-2.542886839810406
545.000000000007,59.721385036165834,-0.00667051784117105,-2.5474755492353522
546.1000000000071,59.83131608166976,-0.007264554820297784,-2.5533946346968253
547.2000000000071,59.94061546723441,-0.0059328068661780075,-2.5569644962508953
548.300000000007,60.04935015183654,-0.006841025578116254,-2.5602951833155676
549.4000000000071,60.158583238807495,-0.004423855102006798,-2.5656830567264866
550.500000000007,60.26887749704888,-0.00745070164685949,-2.570010992760874
551.6000000000072,60.37788401878693,-0.004576888714520873,-2.572858418091056
552.7000000000071,60.48680866785375,-0.005967586591029375,-2.5772436495965216
553.8000000000072,60.59573754180192,-0.004269612050448611,-2.5800069169598236
554.9000000000071,60.70561148590306,-0.004529730429413275,-2.583861111380906
556.0000000000072,60.815277820659496,-0.002946998839339193,-2.586844311318993
557.1000000000072,60.92452806481486,-0.003518033290368076,-2.5907315696341273
558.2000000000072,61.03427577378985,-0.0007290172714818906,-2.5933021648026267
559.3000000000072,61.1432117378719,-0.0015553146065300442,-2.5945669086249743
560.4000000000073,61.25259883896346,0.0011694919477309418,-2.5990961462870352
561.5000000000073,61.36199311287688,0.0008289698956453273,-2.6031405044479445
562.6000000000073,61.471021067465514,0.0013215801264796442,-2.6070411760429226
563.7000000000073,61.58026427711329,0.003687112118780796,-2.6086852967049703
564.8000000000073,61.690058284941976,0.0029367183422928256,-2.6113009101499522
565.9000000000074,61.79930688836467,0.005289591368581032,-2.614058577903653
567.0000000000074,61.90873650925908,0.0049477851924936,-2.617173724043676
568.1000000000074,62.01778541529064,0.006127466136095502,-2.6193563831847033
569.2000000000073,62.12703974697628,0.008131689090879283,-2.6232025354579718
570.3000000000073,62.23607184262821,0.011576370428056596,-2.6259652858097793
571.4000000000074,62.344226942120684,0.014105773737749416,-2.6281569258830957
572.5000000000074,62.452480666986894,0.01671599839804489,-2.6328338360700987
573.6000000000074,62.562246695100015,0.017254149959968705,-2.635546163194782
574.7000000000074,62.670928552426126,0.018357381499979748,-2.6369005413081865
575.8000000000075,62.778856057594865,0.020150839144743804,-2.63952248890199
576.9000000000075,62.88921051689296,0.020413355836762355,-2.643505290229636
578.0000000000075,62.99738900706986,0.019951106777500862,-2.6447923016858006
579.1000000000075,63.106751178603915,0.021621887253287123,-2.6460449724313087
580.2000000000075,63.21592358780052,0.02387726067047458,-2.650178632759636
581.3000000000076,63.323796802041485,0.024835057560818146,-2.6528165725620605
582.4000000000076,63.43292967530894,0.02670419054451113,-2.655490659550831
583.5000000000076,63.54182704643932,0.02804026972287566,-2.656739079782992
584.6000000000076,63.651459818288096,0.02936037015104913,-2.658796177208157
585.7000000000077,63.761366371610514,0.029910381693668203,-2.6607189487983756
586.8000000000077,63.87018936271724,0.027959483688773212,-2.6623606918305565
587.9000000000076,63.97985481484135,0.029909214042097586,-2.6659556837531637
589.0000000000076,64.08992027391561,0.03111332890561617,-2.6686179365550253
590.1000000000076,64.1994347024886,0.0325485401706191,-2.670790367693745
591.2000000000077,64.3090743219607,0.03347131035433824,-2.6726338376606043
592.3000000000077,64.4179059004885,0.03343163815579706,-2.6738877060155914
593.4000000000077,64.52873698329789,0.036000018146001775,-2.675137497271823
594.5000000000077,64.63911502063888,0.03677670187908995,-2.6778424393435696
595.6000000000078,64.74920062758704,0.0382969554991212,-2.679172523036246
596.7000000000078,64.85853396845978,0.04224548409641696,-2.6804548296670747
597.8000000000078,64.96875865204635,0.04126586030138922,-2.6842956109609117
598.9000000000078,65.08014285031466,0.04012051636622772,-2.6844300420009297
600.0000000000078,65.19023413804102,0.04161434666945215,-2.685741248096931
601.1000000000079,65.29931237077297,0.04258298511020469,-2.6870697483832986
602.2000000000079,65.40965184834018,0.04439283763991471,-2.688373694638474
603.3000000000079,65.520622786278,0.048062291486172366,-2.688379760660225
604.4000000000078,65.63013369271113,0.0481369892850377,-2.6897003601502147
605.5000000000078,65.73806399981437,0.04943553016935049,-2.6910201337282618
606.6000000000079,65.84847296010878,0.05175966827716967,-2.6923398771650167
607.7000000000079,65.95946634467545,0.05157574889495051,-2.6910258952614003
608.8000000000079,66.06955714801867,0.053463127633811384,-2.692991077141489
609.9000000000079,66.17927857361148,0.05483653968977993,-2.6943101286113844
611.000000000008,66.28941341922796,0.05571877859543712,-2.6949698492745213
612.100000000008,66.39903517883405,0.058450919524061465,-2.6949696214505785
613.200000000008,66.50841638699194,0.057615632250427325,-2.696290217473336
614.300000000008,66.61764954098773,0.05745892106157573,-2.6965221500640797
615.400000000008,66.72903114573084,0.05771959617504343,-2.697331565366403
616.5000000000081,66.8369967480938,0.057398502361711796,-2.6979299886035593
617.6000000000081,66.94885689662411,0.05996904257255469,-2.69792982661659
618.7000000000081,67.05819371329953,0.06050322233942243,-2.699249643275346
619.8000000000081,67.16743148359171,0.0603419291622045,-2.70057024255118
620.9000000000082,67.27783957521726,0.06367494610764082,-2.701253844066549
622.0000000000082,67.3888728134269,0.06345622611923966,-2.7017594525575617
623.1000000000081,67.49869763731823,0.06656793012214962,-2.703109073576215
624.2000000000081,67.60765598488216,0.06710926895907825,-2.704516934192326
625.3000000000081,67.71836775887168,0.06954285040432837,-2.7068310863671394
626.4000000000082,67.82804659451551,0.07019866592346467,-2.707951713268728
627.5000000000082,67.93838854950488,0.0715780834184991,-2.7094903039045177
628.6000000000082,68.04808287483331,0.07294752713056275,-2.712152582156571
629.7000000000082,68.15771099017527,0.07446064623952829,-2.713926564744229
630.8000000000083,68.26642050869623,0.07531827044108277,-2.7136675261537615
631.9000000000083,68.37779538242319,0.07769817177023858,-2.7139345745529524
633.0000000000083,68.48734399804148,0.08153568127255677,-2.716700438156643
634.1000000000083,68.59721241578748,0.08325616982633836,-2.7177962462666443
635.2000000000083,68.70714659890416,0.08394754387902457,-2.719009681427923
636.3000000000084,68.81657373484197,0.08559056699982201,-2.7203197437392195
637.4000000000084,68.92632922424566,0.08780361303119133,-2.7193151767194266
638.5000000000084,69.03625123415343,0.09006471072853373,-2.722036555591728
639.6000000000083,69.14503468609894,0.0892540031224751,-2.7219801816001152
640.7000000000083,69.25529761221637,0.08957283625732251,-2.723299858685353
641.8000000000084,69.36479740339765,0.09024979376693555,-2.7233000000000835
642.9000000000084,69.47498255044495,0.09036516042617268,-2.723299997840634
644.0000000000084,69.58441893277445,0.09338701636263011,-2.724617579559869
645.1000000000084,69.6942363022828,0.09343260495767639,-2.7246585085512223
646.2000000000085,69.8038937045506,0.09395434491903427,-2.724609927930319
647.3000000000085,69.9153732077768,0.09289210318366356,-2.7238987292050627
648.4000000000085,70.02411776173153,0.09255737738180042,-2.723633337042207
649.5000000000085,70.13487062643813,0.09302333781506825,-2.723290184214292
650.6000000000085,70.24448278715424,0.09224386469361315,-2.7242660557071536
651.7000000000086,70.35468484526878,0.09188450553130785,-2.7245290356712286
652.8000000000086,70.46538153893697,0.09138158466815695,-2.7259154650217936
653.9000000000086,70.57523564055707,0.08925834719806318,-2.727287004456535
655.0000000000086,70.68626071132681,0.0888922591688504,-2.728560876760529
656.1000000000087,70.7946310528366,0.08761659970475903,-2.7313404687689204
657.2000000000087,70.906514000718,0.08250275023447606,-2.730206314699867
658.3000000000086,71.01517793890008,0.08354476693883033,-2.731520177146411
659.4000000000086,71.12780314869195,0.08281388860401707,-2.732573534185336
660.5000000000086,71.23745900039972,0.08056685579009355,-2.7340024577922524
661.6000000000087,71.346145596394,0.08220102819802881,-2.733647694189979
662.7000000000087,71.45809757393667,0.07868078509183374,-2.733835344386468
663.8000000000087,71.56867475868603,0.07740636058756499,-2.7338266272008553
664.9000000000087,71.67890212481116,0.07752043300830207,-2.735109605531736
666.0000000000088,71.79051976928086,0.07651553926513044,-2.743354038903474
667.1000000000088,71.90072637105325,0.07305881066404332,-2.742288244853936
668.2000000000088,72.0094814756438,0.07167055437522662,-2.741630140698927
669.3000000000088,72.11964822402138,0.071739152487076,-2.7410078057077905
670.4000000000088,72.2287747798278,0.06966858322936517,-2.7403099682083196
671.5000000000089,72.34093265944168,0.06809570403029144,-2.740309967903261
672.6000000000089,72.45157297458668,0.06364688562384921,-2.7416071762721947
673.7000000000089,72.56082895365789,0.0643997645569444,-2.7422898318713167
674.8000000000088,72.67263653570727,0.06158368960976393,-2.7436083708739467
675.9000000000088,72.78274088203419,0.05828612041372612,-2.7435663268401456
677.0000000000089,72.89379468203536,0.05740605152248584,-2.746216760236379
678.1000000000089,73.00366039182921,0.0561874174033189,-2.748961408504293
679.2000000000089,73.115147820616,0.05254210531917119,-2.750190994223377
680.3000000000089,73.22612129808451,0.05260301630646111,-2.750190079527443
681.400000000009,73.33644517061688,0.0462506634371567,-2.7488652260953432
682.500000000009,73.44764578603288,0.0436076552576958,-2.74500034353058
683.600000000009,73.5576285190858,0.04084483338194919,-2.742180161503809
684.700000000009,73.66772208430429,0.035914015730239605,-2.7404674431123426
685.800000000009,73.77806524740883,0.03238273030886267,-2.7364680840643727
686.9000000000091,73.88795418580834,0.029846585326825614,-2.741008235462809
688.0000000000091,73.99862450141656,0.02647413399200159,-2.745300072475265
689.1000000000091,74.1083820819516,0.024073619167419204,-2.748531423110867
690.2000000000091,74.2190213433406,0.0217912740554145,-2.750769414261279
691.3000000000092,74.32950308085712,0.0209607169246205,-2.752060549274513
692.4000000000092,74.44029642097198,0.015044764367178913,-2.7520601587353224
693.5000000000091,74.55013242608423,0.011552071619851214,-2.7520708074635127
694.6000000000091,74.6614404243406,0.007663802375864769,-2.7533711259091973
695.7000000000091,74.77230323509536,0.004641842021510837,-2.75468893368018
696.8000000000092,74.88311734452611,0.0016628204119504204,-2.7560099712040698
697.9000000000092,74.99379421094008,-0.003889777408830585,-2.7573338923995765
699.0000000000092,75.10366322602543,-0.009259069109922583,-2.756010110316046
700.1000000000092,75.21539423465167,-0.012162733790636012,-2.757149640876266
701.2000000000093,75.32665107316363,-0.01836411033180872,-2.7576281925010964
702.3000000000093,75.43809131198682,-0.02365029668335134,-2.757650063912215
703.4000000000093,75.54850962106714,-0.026788934346314342,-2.7581127247827535
704.5000000000093,75.65935562745524,-0.03397164478707369,-2.7571671393112336
705.6000000000093,75.77092867603169,-0.03875868214075026,-2.7586501854244774
706.7000000000094,75.87937232267592,-0.04584415455672679,-2.7596406776428113
707.8000000000094,75.99188595896311,-0.04833196463010181,-2.759962509907135
708.9000000000094,76.10319474708402,-0.054729073821271866,-2.7612801053601386
710.0000000000093,76.21441941759963,-0.06225551131229544,-2.7621502315761752
711.1000000000093,76.32512388829775,-0.06417057948765424,-2.76127998069226
712.2000000000094,76.43643832222679,-0.07034530575338685,-2.7625863443908085
713.3000000000094,76.54729754303742,-0.07933384583975918,-2.7639091276416643
714.4000000000094,76.65848311231973,-0.08374479764401434,-2.764382872347277
715.5000000000094,76.76920086769243,-0.08936840348336748,-2.764431345153416
716.6000000000095,76.8813410413342,-0.0945392440405971,-2.765229998195702
717.7000000000095,76.99218793999341,-0.10043694892383893,-2.7678685766141715
718.8000000000095,77.10414561912557,-0.10635925560028973,-2.7673017878575195
719.9000000000095,77.21463753584466,-0.11315537073669224,-2.767177877194905
721.0000000000095,77.32616957342877,-0.11873909118756958,-2.7678916757705734
722.1000000000096,77.43695631025872,-0.1246864109438508,-2.7695386721181126
723.2000000000096,77.54874823052418,-0.13064316444526652,-2.7714899415079612
724.3000000000096,77.65967064144306,-0.13595314245643833,-2.7724712690616737
725.4000000000096,77.77136050616585,-0.14327397574130038,-2.772867241261073
726.5000000000097,77.88165244224015,-0.14953135269331214,-2.774161758523528
727.6000000000097,77.993285430925,-0.15436737331011224,-2.7751101054928387
728.7000000000096,78.1044072988215,-0.1617359143284982,-2.7759735367343135
729.8000000000096,78.2161998343308,-0.16814848580309177,-2.776702793650644
730.9000000000096,78.32614969533846,-0.1730706018468196,-2.7764299922006064
732.0000000000097,78.43800562774678,-0.17798523481382078,-2.7755921423111407
733.1000000000097,78.54897599524308,-0.18432627115720182,-2.7764299118931537
734.2000000000097,78.65932644747342,-0.19216555403681712,-2.7763875738265944
735.3000000000097,78.76905892470782,-0.19633931574808888,-2.777751843403029
736.4000000000098,78.8823135228976,-0.2013667704544479,-2.7790624614227286
737.5000000000098,78.99350179078895,-0.20741174221434658,-2.779060130364614
738.6000000000098,79.10546370699655,-0.21265664144387472,-2.7790600971695207
739.7000000000098,79.21790570775781,-0.2146592148232341,-2.778087253247698
740.8000000000098,79.32784056315073,-0.2214786067811837,-2.779059460787391
741.9000000000099,79.43977809019766,-0.22714214730977988,-2.780379864530832
743.0000000000099,79.55289116546588,-0.23089696484574496,-2.780354318374518
744.1000000000099,79.6634443191858,-0.23882584187903683,-2.7804828741373973
745.2000000000098,79.77498415699705,-0.24144498119320634,-2.783075135455468
746.3000000000098,79.88670124194921,-0.2454198368259322,-2.7816974547628988
746.7000000000099,79.92703067611248,-0.24738250930415773,-2.7829976298106947