File: 01_Data/Air_Fryer/STA/N2/10K_min/Air_Fryer_STA_N2_10KData_221116_R3.csv
##Temp./Â°C,Time/min,DSC/(mW/mg),Mass loss/mg
51.0,10.51,-1.75593,0.017492359897107512
51.80000000000001,10.935301271750653,-1.6212094513367266,0.012085421302191257
52.60000000000002,11.163068015258075,-1.5279329032426738,0.012469878159897974
53.400000000000034,11.343247015429142,-1.4581041526940703,0.013188676617307493
54.200000000000045,11.499154872223112,-1.4004410680232942,0.012899487342246552
55.00000000000006,11.63728852175825,-1.357548950331982,0.01520571695867634
55.80000000000007,11.772768002602819,-1.3150210267293336,0.013626880391553797
56.60000000000008,11.898329871827197,-1.2788880682989432,0.013375238147901314
57.40000000000009,12.017212350195134,-1.2483626285989144,0.01268663254304947
58.2000000000001,12.131658057562024,-1.2197864851835631,0.013578692355586064
59.000000000000114,12.24493399804421,-1.1969843502904491,0.018159734831494134
59.800000000000125,12.355797709280317,-1.1730422204259447,0.01714983084449173
60.600000000000136,12.461240336913685,-1.1548465768485467,0.014672145206872322
61.40000000000015,12.564918689810968,-1.1365787656251845,0.01624298463588225
62.20000000000016,12.670149731673169,-1.1207645107701487,0.01641709344568998
63.00000000000017,12.771714489514038,-1.104690080539693,0.016473565124112355
63.80000000000018,12.866342529948394,-1.087554135114101,0.01594586728581593
64.6000000000002,12.969291790186405,-1.075364174566234,0.014824880992839518
65.4000000000002,13.068555193711445,-1.0636725474459714,0.016840690668316505
66.20000000000022,13.165409445192063,-1.0519485002174835,0.018397015001339057
67.00000000000023,13.261088380318476,-1.0411268432981169,0.018050065288862882
67.80000000000024,13.355658944190212,-1.030183593870139,0.018875434731294938
68.60000000000025,13.449312270529267,-1.0197712307035331,0.017541003895081175
69.40000000000026,13.543123425079555,-1.0096924040378827,0.01777102418217602
70.20000000000027,13.635216091026825,-1.0000933569312882,0.016259916218723802
71.00000000000028,13.728740849341701,-0.9924920382007366,0.016781993328202738
71.8000000000003,13.819760268906128,-0.9859215147567504,0.01624853382275049
72.6000000000003,13.909370890983913,-0.9759497337613343,0.017051463191989136
73.40000000000032,13.998789802569105,-0.9683221766451586,0.016275950856339705
74.20000000000033,14.085561752334112,-0.9622762688418448,0.016266775771363484
75.00000000000034,14.178219371174027,-0.9526786405342962,0.016255939895710725
75.80000000000035,14.268232517463556,-0.944953590871481,0.01607556630081497
76.60000000000036,14.355642034592757,-0.9373535350752144,0.015225043762402635
77.40000000000038,14.442125235138272,-0.9296167601702842,0.017528118583519436
78.20000000000039,14.530746931814308,-0.9219056782290628,0.019449380922756276
79.0000000000004,14.61782240777714,-0.9164540734038695,0.01934054418809872
79.80000000000041,14.702934755851107,-0.9070905225428547,0.018008022837559423
80.60000000000042,14.786774001068022,-0.9004060229130774,0.015309022432196784
81.40000000000043,14.875001290147448,-0.8938047297124052,0.014138440308482991
82.20000000000044,14.960487733261493,-0.8852503607741768,0.015592219781591865
83.00000000000045,15.044854063858278,-0.8794628054919897,0.016019075681171557
83.80000000000047,15.130984131468205,-0.8734842344622514,0.016593323030829943
84.60000000000048,15.214893377724366,-0.8663609287137732,0.015278050189299286
85.40000000000049,15.299503533968764,-0.8603449524405349,0.016536492278804715
86.2000000000005,15.380715994711878,-0.8549510677891226,0.016540372928748326
87.00000000000051,15.464399176704454,-0.8487294660620767,0.017857495867479756
87.80000000000052,15.54873367837926,-0.8411167235946638,0.01682025495797035
88.60000000000053,15.630998324585649,-0.8347518676950465,0.01791071099510777
89.40000000000055,15.71476485895897,-0.828109340173078,0.01790349607785746
90.20000000000056,15.796276272292836,-0.8206991734977636,0.0192218229287775
91.00000000000057,15.879465389342762,-0.8148201918638196,0.020368556675000704
91.80000000000058,15.961581517813302,-0.8081930218557468,0.01923312756234896
92.60000000000059,16.041114228453928,-0.8039890269081773,0.019229644127486623
93.4000000000006,16.122654322336174,-0.7971033157858692,0.01922379954443798
94.20000000000061,16.203760143191886,-0.7927921077415617,0.020848616471806025
95.00000000000063,16.28231533563949,-0.7862725436701016,0.01956064953246983
95.80000000000064,16.36420372304803,-0.7789153029182385,0.016814612577908505
96.60000000000065,16.44404915009178,-0.7740892074002605,0.017605270168912668
97.40000000000066,16.522709524328647,-0.7697014989395049,0.018089786920603146
98.20000000000067,16.60102709381364,-0.7647262648829157,0.018007967203938158
99.00000000000068,16.684548541847906,-0.7578766019272906,0.01974494055485465
99.8000000000007,16.764350268753283,-0.7537975922059289,0.02054737971442755
100.6000000000007,16.84379511654392,-0.7473355693324142,0.017880555109539564
101.40000000000072,16.922766491660703,-0.741204916527024,0.016689068227586645
102.20000000000073,17.003173175357993,-0.7350292062784757,0.017898375709478387
103.00000000000074,17.080968189663512,-0.7314423496306637,0.01796553011962132
103.80000000000075,17.162047670582773,-0.7255832612568921,0.01791394535361679
104.60000000000076,17.240363025072977,-0.7201322027942803,0.016565896477057862
105.40000000000077,17.31819878756318,-0.7171992794808472,0.0166017185267906
106.20000000000078,17.39735326818131,-0.7116572728501483,0.016553914709895423
107.0000000000008,17.475642240285545,-0.7054678059055793,0.01691974823536757
107.80000000000081,17.55559473063875,-0.7014070894930643,0.017922936947295298
108.60000000000082,17.632913140550443,-0.6957913897133827,0.019244672932459572
109.40000000000083,17.711768789120267,-0.692352624869305,0.020024384651769367
110.20000000000084,17.790334526092245,-0.6869952974215189,0.020529989254026937
111.00000000000085,17.869700830576512,-0.6817577222302597,0.020511150994451555
111.80000000000086,17.947954515953345,-0.6778500232499107,0.020212568882003623
112.60000000000088,18.024772658026343,-0.6724811046645249,0.021202793121333663
113.40000000000089,18.104284498244073,-0.6676824428731895,0.019662008056607228
114.2000000000009,18.18255284150392,-0.6637411974982722,0.0183169177532454
115.00000000000091,18.26105053099757,-0.6576155473249056,0.01867013990285482
115.80000000000092,18.337774471369325,-0.6547795484457539,0.01884473974894796
116.60000000000093,18.416754916672353,-0.6496881721152754,0.018670010877018584
117.40000000000094,18.495120718297912,-0.645288453222531,0.019721084712263526
118.20000000000095,18.572968366683252,-0.6398594393741743,0.018679738561553805
119.00000000000097,18.650423178583676,-0.6366736146380978,0.01802129457622037
119.80000000000098,18.727325642957922,-0.6307622810359389,0.01897459594148465
120.60000000000099,18.805580804526844,-0.6272600020983414,0.018670045944905844
121.400000000001,18.88310090240193,-0.6211026406051241,0.019174759053992574
122.20000000000101,18.96019785920631,-0.6174661695561687,0.018985664539717284
123.00000000000102,19.039066811009114,-0.6143361899056274,0.018670489353732833
123.80000000000103,19.116991800515894,-0.6104440181360533,0.018659498207550307
124.60000000000105,19.194222330142015,-0.6041591362782647,0.018302870149049966
125.40000000000106,19.27140862072291,-0.5998983213835225,0.01767971615688957
126.20000000000107,19.348239536895242,-0.5937206863123664,0.017680049544586574
127.00000000000108,19.427418603193008,-0.5898834410515241,0.018228147213701362
127.80000000000109,19.50381548736097,-0.5869295403904305,0.017287799291460182
128.6000000000011,19.581101874988793,-0.5808450650257025,0.018668089795171205
129.4000000000011,19.658518037646388,-0.5779806482303806,0.018670117011443388
130.20000000000113,19.734651859458243,-0.5704617541499517,0.018788232254848936
131.00000000000114,19.811979772017185,-0.5665670172457069,0.018669333961141454
131.80000000000115,19.88973082699352,-0.5608388407685072,0.01801970427133881
132.60000000000116,19.963898777682907,-0.5562513055344563,0.018047096460721335
133.40000000000117,20.043107034543596,-0.5501551562216039,0.019309301305279192
134.20000000000118,20.119905966140053,-0.5431422932431427,0.018009953443006488
135.0000000000012,20.197385872839973,-0.5388237613761143,0.016860485276190218
135.8000000000012,20.273810007455133,-0.5321512588717332,0.018056770545923584
136.60000000000122,20.350800733669757,-0.5259346441300916,0.016693443463213775
137.40000000000123,20.427205593152838,-0.5204759675535608,0.018010175178027055
138.20000000000124,20.5048024210777,-0.5142550414592614,0.017984321535078784
139.00000000000125,20.58000000000011,-0.5066399999999835,0.018018217774142364
139.80000000000126,20.656200611394063,-0.49968484772598737,0.01801830996637932
140.60000000000127,20.73351239736826,-0.49098589412636917,0.01864908183648417
141.40000000000128,20.810657793641102,-0.4843683763820124,0.019329288154509072
142.2000000000013,20.886632777836528,-0.4744943458603605,0.019336266956606174
143.0000000000013,20.963069666544374,-0.4661968087055372,0.02032666164902075
143.80000000000132,21.03929859422321,-0.4559416085991796,0.01902311356362496
144.60000000000133,21.11615342996749,-0.44741363626394276,0.018967649431099076
145.40000000000134,21.192465996631373,-0.4360746867669953,0.016343728539752078
146.20000000000135,21.269029585029504,-0.42407693808770436,0.01504986874622638
147.00000000000136,21.345725136144175,-0.4135352054689956,0.016392660023445416
147.80000000000138,21.42038356490118,-0.4012816221832417,0.016503702409838006
148.6000000000014,21.498535813417845,-0.3865639442831497,0.017679792363648694
149.4000000000014,21.573127461455037,-0.37145892957249976,0.017680228446967483
150.2000000000014,21.65125479281086,-0.35563382493314843,0.0176244165072168
151.00000000000142,21.72720390015951,-0.3368804596020546,0.017680071198009628
151.80000000000143,21.80323717605414,-0.3181997195515734,0.01747963100349903
152.60000000000144,21.880335732825888,-0.29805985884699615,0.01635992565269273
153.40000000000146,21.956487675416366,-0.27373648147123014,0.016314396012632848
154.20000000000147,22.032276740820713,-0.24766197071962398,0.016542150447942383
155.00000000000148,22.110536597201726,-0.21976800969877985,0.01899710217727879
155.8000000000015,22.184863563123987,-0.18829954032445081,0.020312395793282256
156.6000000000015,22.261297683665966,-0.15364328651147835,0.018997811202865478
157.4000000000015,22.338296984503714,-0.11326178122595996,0.017650249132429963
158.20000000000152,22.414253907213354,-0.06820956574581255,0.018337462040800112
159.00000000000153,22.490788197369348,-0.01865274502858646,0.019000061768626786
159.80000000000155,22.568062382377136,0.035621510316973255,0.01899984617488215
160.60000000000156,22.644677528581155,0.09645581307334569,0.0176711187975247
161.40000000000157,22.72126125075732,0.16307264376594952,0.01866870320222702
162.20000000000158,22.79806770943221,0.2331239981258398,0.018670419557789586
163.0000000000016,22.875298418669963,0.30581432769660416,0.017710474270421273
163.8000000000016,22.95135185967515,0.38067931809446254,0.020396702561927604
164.60000000000161,23.027868694563914,0.45486527755946893,0.02030712182998684
165.40000000000163,23.10511817843545,0.5265411937406802,0.020308382720010343
166.20000000000164,23.182234574601804,0.5915160657236904,0.018903872033149582
167.00000000000165,23.258989324338312,0.6513036085324919,0.01899984239086283
167.80000000000166,23.33554095793713,0.7064683424364424,0.018822179540149087
168.60000000000167,23.41269353213401,0.7456488038386837,0.018981839212379725
169.40000000000168,23.489899685371377,0.7608159865123294,0.020320056762172634
170.2000000000017,23.565398617116415,0.737270499389388,0.0203194131357467
171.0000000000017,23.642693156482355,0.6623437394847372,0.021319835993672598
171.80000000000172,23.71909974188947,0.5302778543291841,0.017198747774469503
172.60000000000173,23.793862912805583,0.35336898137163764,0.0171471502091336
173.40000000000174,23.870001025469268,0.16455748668141415,0.015809826502892754
174.20000000000175,23.944995782639495,0.0053203626420601806,0.014512017964453783
175.00000000000176,24.021455656760775,-0.10759509156257936,0.015810059420561018
175.80000000000177,24.0944650029458,-0.17961837247260842,0.016210196195897808
176.60000000000178,24.169912151078243,-0.22754337717870343,0.015819720975062346
177.4000000000018,24.2464181535473,-0.2586436487342966,0.017141258090537015
178.2000000000018,24.320186091579345,-0.27987001527718863,0.01857478636560117
179.00000000000182,24.39618661419724,-0.2928084536782981,0.021883637393035116
179.80000000000183,24.470558038424873,-0.3007525026503981,0.021525351645221846
180.60000000000184,24.547613099045407,-0.3058393442849513,0.020208836690946974
181.40000000000185,24.622521187173746,-0.3091426433740172,0.017370790963083138
182.20000000000186,24.699061453790176,-0.3097631203338464,0.016838324493157586
183.00000000000188,24.77424355270993,-0.30967461006295205,0.017617139219748168
183.8000000000019,24.849901372315543,-0.30972254136641675,0.016254626688885665
184.6000000000019,24.926212999688694,-0.3088308523611224,0.014968811373054614
185.4000000000019,25.001416725904964,-0.30648192839824545,0.013623141766061053
186.20000000000192,25.07735763380404,-0.3041543697167492,0.013947289151178488
187.00000000000193,25.151131629930163,-0.30331601926362856,0.016292930768570635
187.80000000000194,25.22861018934207,-0.3013154514911237,0.016327205996407912
188.60000000000196,25.303678401827334,-0.29939904715123716,0.016253838340531068
189.40000000000197,25.380183072452667,-0.2966539187471267,0.017579892954475262
190.20000000000198,25.456761823525895,-0.29661971632497536,0.017582352504674326
191.000000000002,25.531852348435983,-0.2935644836858427,0.017564813201946805
191.800000000002,25.60700166067601,-0.29255830320421206,0.01789225060231292
192.600000000002,25.681172206713025,-0.290189675375153,0.01789112467395615
193.40000000000202,25.758256526497743,-0.28744966417895984,0.017920991384782425
194.20000000000203,25.834191449067806,-0.28457036095078103,0.019220465520553454
195.00000000000205,25.910608023292724,-0.28324881483794784,0.01921998586247664
195.80000000000206,25.986035553083042,-0.281539384105807,0.01818897245073181
196.60000000000207,26.060274803993146,-0.2766013785696779,0.016584788421631025
197.40000000000208,26.135673976865576,-0.27667902141171424,0.01658020919351877
198.2000000000021,26.210098978123227,-0.2716791608116603,0.01658923481840091
199.0000000000021,26.286501375349523,-0.26968832938157733,0.017909256720701094
199.80000000000211,26.362221423971096,-0.2663810272655466,0.017893670268660955
200.60000000000213,26.435775049433552,-0.2659345724866391,0.017590129316252145
201.40000000000214,26.515750031167794,-0.2648808725448205,0.017271208873602895
202.20000000000215,26.591723667081965,-0.2629212263143123,0.01691160645101064
203.00000000000216,26.666721960623164,-0.2598052139154945,0.01658976923826483
203.80000000000217,26.742985630213052,-0.2548861577003042,0.01658988726815913
204.60000000000218,26.815914323389094,-0.25346993387400807,0.01786653742339972
205.4000000000022,26.893352924154986,-0.2525316144001415,0.017991863961333898
206.2000000000022,26.969918424663565,-0.24808123939798007,0.016579951381505253
207.00000000000222,27.044902818602985,-0.2454463541111413,0.01788129694875007
207.80000000000223,27.120751055123215,-0.2441823191585564,0.016559333335485427
208.60000000000224,27.194613007104977,-0.24224810140452316,0.01526995637641626
209.40000000000225,27.273064208247337,-0.2395237961247281,0.015201889148189096
210.20000000000226,27.347748930481757,-0.23817705184491011,0.016589845916304746
211.00000000000227,27.424324449939828,-0.23620128572674984,0.016589967248066273
211.80000000000229,27.499907740421566,-0.23379147798986846,0.015287907939566914
212.6000000000023,27.57571441895602,-0.23022565813340043,0.01658862054018062
213.4000000000023,27.651690782708037,-0.22988824300842672,0.016585939415015183
214.20000000000232,27.724958872561583,-0.22514000191611463,0.016593135226775857
215.00000000000233,27.80301588846446,-0.22249290790510295,0.01657986499150521
215.80000000000234,27.878975684585217,-0.22161349168075,0.01525713979808252
216.60000000000235,27.95428680729683,-0.21969613406219224,0.015259885151378327
217.40000000000236,28.029818142878813,-0.21913279122957097,0.015237994355011608
218.20000000000238,28.105903398617134,-0.21666087298165987,0.015589892421377094
219.0000000000024,28.180857648498847,-0.21402489778145886,0.01562566170520263
219.8000000000024,28.257588436613176,-0.2105176206894903,0.016893666994207912
220.6000000000024,28.33275138238447,-0.21102989371276004,0.015599383676405232
221.40000000000242,28.406764231666205,-0.2094720478558445,0.01592479358357224
222.20000000000243,28.485141549728993,-0.20725638935899449,0.015930088642002183
223.00000000000244,28.560579969837484,-0.20598278679132856,0.015930089351039456
223.80000000000246,28.63462588839786,-0.20362914220658246,0.015914190427022135
224.60000000000247,28.711815503204246,-0.20251690124012972,0.016260853422678245
225.40000000000248,28.788328652781036,-0.19915709667667067,0.015930630358459652
226.2000000000025,28.86363985628382,-0.19798688668693296,0.014786006404311713
227.0000000000025,28.938446880140354,-0.196230732469613,0.015597278559795313
227.8000000000025,29.015249364822505,-0.19321071279114144,0.015606003584593076
228.60000000000252,29.09163185256008,-0.19168800388315813,0.014280396293615105
229.40000000000254,29.167379325587522,-0.19056403592759089,0.01558900803267349
230.20000000000255,29.243144108314326,-0.18815975698247375,0.014882426224576584
231.00000000000256,29.31818051712176,-0.1862793752342964,0.014609826007731641
231.80000000000257,29.394246250311202,-0.18395079266918876,0.014237948636096398
232.60000000000258,29.47077736154966,-0.18117434333557722,0.011427902896024023
233.4000000000026,29.546895714569615,-0.17849995733251103,0.010103663926421369
234.2000000000026,29.621518368543033,-0.17813709399881172,0.010542184870294236
235.00000000000261,29.697140810330307,-0.1765693934417976,0.011097479903738439
235.80000000000263,29.77220416907153,-0.17528600637535077,0.011549092422056262
236.60000000000264,29.84928377828255,-0.17104904117813938,0.013703254706795676
237.40000000000265,29.92416392915225,-0.17215599367205178,0.015173230239499347
238.20000000000266,30.00089162910483,-0.1706397702810033,0.015143675675943769
239.00000000000267,30.074054267758445,-0.16734343995402276,0.016417477417855153
239.80000000000268,30.151643718707636,-0.1660735275249311,0.013859882856902317
240.6000000000027,30.226742495254072,-0.1638447280072713,0.01227752300168028
241.4000000000027,30.302919001801122,-0.1636091816142062,0.01196982491377696
242.20000000000272,30.3792454409432,-0.16312113280361232,0.01197003661185203
243.00000000000273,30.455370425537254,-0.15925183633270165,0.01306739897190301
243.80000000000274,30.531120104066773,-0.15810191095206674,0.012286078947769674
244.60000000000275,30.606239933797042,-0.15835847798813837,0.011970881710148262
245.40000000000276,30.682589302153847,-0.15508822147212978,0.013388779902941295
246.20000000000277,30.757597011711255,-0.15282248154481165,0.01462285077182024
247.00000000000279,30.834470162808984,-0.15235465752111885,0.01592375897969145
247.8000000000028,30.90970754974094,-0.14898780844210532,0.01320679430025784
248.6000000000028,30.985123886806416,-0.1484567620064752,0.010492571123823069
249.40000000000282,31.061309547527557,-0.14588503058974706,0.011869777340566934
250.20000000000283,31.13687170165477,-0.14506759072466788,0.011869938333822994
251.00000000000284,31.21188660068612,-0.14309727973375172,0.013206799048820272
251.80000000000285,31.289169706986662,-0.1422117584057619,0.013180027159441998
252.60000000000286,31.362971278830848,-0.14036909153706495,0.014545982689805115
253.40000000000288,31.441293823963804,-0.13909597393680695,0.015850934450064358
254.2000000000029,31.517343279312975,-0.1370216705119111,0.013883614240474351
255.0000000000029,31.592646101895337,-0.13433394353129877,0.011861021643499114
255.8000000000029,31.665260047907996,-0.13439754765082945,0.011893670683759794
256.6000000000029,31.74394185362393,-0.13215000556460477,0.01165984349520599
257.40000000000293,31.82055040554548,-0.12967058398368478,0.01187880932026264
258.20000000000294,31.895741246699515,-0.13068642396383048,0.011867654900039604
259.00000000000296,31.97025669330054,-0.1301815646679251,0.010540039179475436
259.80000000000297,32.049243985719116,-0.12643395301643542,0.010539992155420563
260.600000000003,32.12347525468916,-0.12618761698116251,0.010552815622370204
261.400000000003,32.199282671626776,-0.12612376847178514,0.011854514659169979
262.200000000003,32.27560231270014,-0.12372115214807836,0.013179320042922882
263.000000000003,32.35125426300078,-0.123303300286885,0.011830664360704901
263.800000000003,32.428243888649554,-0.12143648872331325,0.011956798722134288
264.60000000000304,32.50453723923713,-0.1209257412078736,0.011941686683397457
265.40000000000305,32.58050001389379,-0.11883385042953708,0.009995787169022385
266.20000000000306,32.65661487428462,-0.11818791028187847,0.010658838826173245
267.00000000000307,32.73274431180197,-0.11852297644213404,0.0113220462686634
267.8000000000031,32.80831068434376,-0.11430420367715512,0.010005133020443147
268.6000000000031,32.88427484758607,-0.11491684986759845,0.007978976810223415
269.4000000000031,32.960249081568506,-0.11172071117309333,0.00934028261743336
270.2000000000031,33.03663853713002,-0.10979191691221339,0.010658327764174302
271.0000000000031,33.11260471337396,-0.10844520181423349,0.010055102198628596
271.80000000000314,33.18862574029131,-0.10609950919238562,0.008352720496657362
272.60000000000315,33.26543993349847,-0.1054404081762928,0.009662599549999484
273.40000000000316,33.341510280021694,-0.10393131822445753,0.011099750647131756
274.2000000000032,33.41761110382882,-0.10216402854066582,0.011070229144407584
275.0000000000032,33.49334418616956,-0.10035482106906152,0.008453406182678869
275.8000000000032,33.569237461400945,-0.09918983181762282,0.008130087178511936
276.6000000000032,33.64486808338517,-0.09757157404614436,0.008374245804116498
277.4000000000032,33.72171564446797,-0.09548976204331563,0.010236794348236877
278.20000000000323,33.79699850261578,-0.09456164281309766,0.010867482472699308
279.00000000000324,33.87321554292346,-0.0948717341339452,0.009561803206334929
279.80000000000325,33.95059066762148,-0.09316853856868801,0.009560179291779214
280.60000000000326,34.02610229240817,-0.09178341589698316,0.009543144839523343
281.4000000000033,34.10263561985922,-0.09145206556105966,0.009888419664799919
282.2000000000033,34.17853917668243,-0.0895393834479372,0.00988990504759446
283.0000000000033,34.254601778208325,-0.08799033626791386,0.009889905003796606
283.8000000000033,34.331023303998485,-0.08726810823161786,0.009889924891959723
284.6000000000033,34.407090763489926,-0.0851808609663028,0.009561518065761554
285.40000000000333,34.48303078362963,-0.08575757668054801,0.00956264190312428
286.20000000000334,34.55979182228182,-0.08392948259861678,0.006949100372011685
287.00000000000335,34.63546988427014,-0.0832766944193106,0.006930177143564364
287.80000000000337,34.71255526081392,-0.0825300639127217,0.006901072078895787
288.6000000000034,34.78817374026898,-0.08184874147159654,0.00824001443386635
289.4000000000034,34.86507364676283,-0.07882732808095944,0.009668425101120981
290.2000000000034,34.941779962484105,-0.07952265764428036,0.010556985066017432
291.0000000000034,35.0188163517964,-0.07687434111021464,0.010536033070053463
291.8000000000034,35.09440492317356,-0.07697594966135833,0.007153592900813521
292.60000000000343,35.17064899749632,-0.07450990112789237,0.006095794701956869
293.40000000000344,35.24709719545227,-0.07448714780422962,0.007370142940431812
294.20000000000346,35.3236486324302,-0.07231106026087278,0.007370164271444324
295.00000000000347,35.40088290459154,-0.07260765071895878,0.006678479593568376
295.8000000000035,35.476480924611636,-0.0709787874791018,0.004729829570742972
296.6000000000035,35.55397061514976,-0.06918130687151308,0.004696598558320275
297.4000000000035,35.630872612383506,-0.06787327939804809,0.006050724363998228
298.2000000000035,35.70688121441691,-0.06794979949464469,0.0047269749600404865
299.0000000000035,35.78301233686413,-0.06459779278707187,0.004742744006764887
299.80000000000354,35.86091721939411,-0.06571880193214524,0.0060501682985627525
300.60000000000355,35.937007588996885,-0.06325932338613148,0.006050145928833572
301.40000000000356,36.01282959238622,-0.06221118712385531,0.006034429802821428
302.20000000000357,36.08981940621102,-0.05921565700499927,0.004741287076448941
303.0000000000036,36.16541460689611,-0.057212106705814274,0.0037818180456401507
303.8000000000036,36.24154523890917,-0.055644902466691924,0.003867083033025409
304.6000000000036,36.317757025474634,-0.054900332647224485,0.004900351345458631
305.4000000000036,36.3956772293985,-0.05366820525168893,0.00342133491857588
306.2000000000036,36.46967251351374,-0.05046722079913431,0.004392029161719435
307.00000000000364,36.54889310586287,-0.05094648040571763,0.004729875011572737
307.80000000000365,36.6243869337193,-0.050324904719528774,0.004729870406102066
308.60000000000366,36.70140797017929,-0.04958545022566625,0.004710072928668652
309.4000000000037,36.7777066635799,-0.0489830934974269,0.005389976856513101
310.2000000000037,36.85424331013132,-0.048297474179644376,0.005390025997280112
311.0000000000037,36.93112415578513,-0.04637464634753139,0.005390024378507441
311.8000000000037,37.00710786532021,-0.04612032350722573,0.005365199312757696
312.6000000000037,37.08318185644663,-0.04248967158964947,0.005375668475092077
313.40000000000373,37.15924931538996,-0.04314093093651992,0.005059426390586985
314.20000000000374,37.2359025905753,-0.042063471099791916,0.003761520039732069
315.00000000000375,37.31241615673222,-0.040833223876229036,0.003739948533454829
315.80000000000376,37.389234103528004,-0.04151822886950491,0.0037399491867509127
316.6000000000038,37.468532586346896,-0.041685195653503204,0.003742179017659275
317.4000000000038,37.5455775514649,-0.03922097109951442,0.002752048083504377
318.2000000000038,37.62199943230347,-0.03855562823562191,0.0027503092286442765
319.0000000000038,37.6991270732411,-0.03596901581390853,0.0014288551765515578
319.8000000000038,37.774735536827215,-0.036471088201889386,0.0014301248189578786
320.60000000000383,37.852556711889726,-0.03338892496867857,0.0014301249999943977
321.40000000000384,37.930095124045735,-0.031200205956449553,0.0014301250000272603
322.20000000000385,38.00619046124037,-0.03237310333253621,0.001430107309301043
323.00000000000387,38.08243231295583,-0.030449625223571027,0.0022882241183257435
323.8000000000039,38.159721611965075,-0.028511143603549755,0.0027500380610883113
324.6000000000039,38.23682050220464,-0.02699018420132959,0.003994377008476491
325.4000000000039,38.31316371804676,-0.02638314755232374,0.0032462707021148063
326.2000000000039,38.39142142423285,-0.027527630096086664,0.0013839016164993723
327.0000000000039,38.46751221889165,-0.02474758694463328,0.0013829064620196618
327.80000000000393,38.54411974325471,-0.025178436490680006,0.002749788198564751
328.60000000000394,38.621605803914,-0.023194134944538265,0.0014297407700247788
329.40000000000396,38.69828434826522,-0.020570011035734977,0.0006045937134100399
330.20000000000397,38.775491101480306,-0.02175883133644312,-0.001260029838410226
331.000000000004,38.85296943843233,-0.01819787543424974,-0.0008698669545363913
331.800000000004,38.93009321532879,-0.01537633005890941,-0.0011907598330367364
332.600000000004,39.00699067754349,-0.015202676076907673,-0.0011653073871977782
333.400000000004,39.0841040802916,-0.014646532286027605,-0.0002110349941535361
334.200000000004,39.1611447972874,-0.012405887160736258,0.00011530025568706748
335.00000000000404,39.23867097318259,-0.010478531946485124,-0.0013603866502869266
335.80000000000405,39.315770814429456,-0.01056299488788743,-0.00273098182661613
336.60000000000406,39.392220690383155,-0.00834225181449061,-0.0027301945099473812
337.40000000000407,39.46973689284262,-0.006836479493027613,-0.002727077741255357
338.2000000000041,39.548136031781986,-0.005022188852956619,-0.0014204097949059857
339.0000000000041,39.62467054490974,-0.003870165614525454,-0.0020517163380811
339.8000000000041,39.70244895593926,-0.003125255692959864,-0.003389002822804521
340.6000000000041,39.77999908245757,-0.004298613523205449,-0.003364683484446296
341.4000000000041,39.8566224194922,-0.0024106666952598862,-0.0038609161658573754
342.20000000000414,39.93393225510901,-1.0066242929828072e-05,-0.0027861085771272442
343.00000000000415,40.01103056539668,0.0006840011619843949,-0.002072578120905
343.80000000000416,40.088237737406494,0.0029225220372707094,-0.004050191067461739
344.6000000000042,40.16501249876739,0.004878743232942649,-0.0032283293075252573
345.4000000000042,40.242322322623,0.003970092407646298,-0.0027302008780321074
346.2000000000042,40.31850429193543,0.006329440236113315,-0.0027320957941414648
347.0000000000042,40.39532335873111,0.009194070241924486,-0.004051095504810753
347.8000000000042,40.47303216070149,0.00965944531033563,-0.002729614035343886
348.60000000000423,40.54891747733125,0.009760263572407947,-0.002717885117323071
349.40000000000424,40.62639039432099,0.012215472730447926,-0.00613697852155326
350.20000000000425,40.7037680070381,0.013217411061654083,-0.005993406055070594
351.00000000000426,40.78079597895384,0.017796788644106616,-0.0054633891981819005
351.8000000000043,40.85853985819944,0.017121081308048,-0.00679795711339537
352.6000000000043,40.93568714021499,0.01745415937974963,-0.00801701707098701
353.4000000000043,41.01282958107723,0.018697288838849045,-0.0068001225335745374
354.2000000000043,41.0921602217127,0.02097797933383728,-0.00686182059507523
355.0000000000043,41.169344817599956,0.02154936585600503,-0.008120784975363726
355.80000000000433,41.245314602701455,0.021408492361555596,-0.010817168728748605
356.60000000000434,41.32250119652044,0.02306322218346421,-0.010281985227187818
357.40000000000435,41.40085434966183,0.024607735091137332,-0.009555176133523524
358.20000000000437,41.47811939739277,0.025494298884017687,-0.010860027257633575
359.0000000000044,41.55543795245183,0.02785723789804449,-0.009937785813710853
359.8000000000044,41.63316910082942,0.028597425298651964,-0.009549460564304724
360.6000000000044,41.710582298400624,0.02995329658292327,-0.009220087209079963
361.4000000000044,41.78754035389958,0.03246697794042598,-0.010417653821808592
362.2000000000044,41.864830399055776,0.032142168307874,-0.011246636117065556
363.00000000000443,41.94215343309926,0.032553833043701026,-0.010860179257766944
363.80000000000445,42.01863824668572,0.03361337924055548,-0.0108601409977096
364.60000000000446,42.09774164195218,0.03486575740161278,-0.010860140999998436
365.40000000000447,42.17447937881652,0.037074801901859744,-0.010860141000000212
366.2000000000045,42.251445524422124,0.038122094455882445,-0.010860141000047285
367.0000000000045,42.33009948277771,0.04058867411023551,-0.01086014111359912
367.8000000000045,42.40674302302152,0.0409855917086019,-0.010792556880435455
368.6000000000045,42.48450431713441,0.04299287845325687,-0.011520032294156657
369.4000000000045,42.56174337158289,0.044407005462683564,-0.012845294343160063
370.20000000000454,42.63862580522834,0.046185492609891264,-0.014063043543106168
371.00000000000455,42.71523565027143,0.04799900680416775,-0.015469137960104185
371.80000000000456,42.7938472509168,0.04891142274916631,-0.015480368130679878
372.60000000000457,42.87110312380121,0.04802462072987112,-0.0167907000057248
373.4000000000046,42.948629272970095,0.052217217012727316,-0.016757004303020295
374.2000000000046,43.026164562332106,0.05165228541974134,-0.01677672390340934
375.0000000000046,43.10340493111184,0.05070472957194152,-0.0141168214586882
375.8000000000046,43.180559909302815,0.05365317599680075,-0.014148714353388492
376.6000000000046,43.258527098990896,0.054116746457771016,-0.013490839765524676
377.40000000000464,43.33584987778567,0.055992090858427136,-0.014814804611679833
378.20000000000465,43.41367523887052,0.05593532997360792,-0.016966177309011954
379.00000000000466,43.491135670384814,0.05510588136200896,-0.020551105980649353
379.8000000000047,43.56943884786927,0.05578489565397851,-0.021503572362209233
380.6000000000047,43.64600950868996,0.057721797737618596,-0.021391117859014486
381.4000000000047,43.72314404555184,0.05599821748358525,-0.021512796746959495
382.2000000000047,43.800928849056646,0.05950256872130031,-0.027704550799475314
383.0000000000047,43.87930356992892,0.059711755902242585,-0.029199967594746745
383.80000000000473,43.956510255497605,0.062265334161765065,-0.028123310155073966
384.60000000000474,44.035063167107545,0.0648032277216293,-0.026755988539354014
385.40000000000475,44.11191279675355,0.06740542433819605,-0.02547195502682076
386.20000000000476,44.18943608342358,0.07005566473661833,-0.026780114859893622
387.0000000000048,44.26699797245182,0.06897066883576937,-0.02810318536193801
387.8000000000048,44.344196559967706,0.07078235734166785,-0.028012932455062867
388.6000000000048,44.422795081840896,0.07192741255972208,-0.02802479296329352
389.4000000000048,44.50073861130345,0.07539383515260287,-0.02930012760508749
390.2000000000048,44.57786052906888,0.07625840881077994,-0.029300122001436613
391.00000000000483,44.65614589921341,0.07529199088671172,-0.029300205832937465
391.80000000000484,44.733834436313344,0.07820382597517721,-0.03067003077539887
392.60000000000485,44.8117090863006,0.07717558662216224,-0.030536296241276517
393.40000000000487,44.88952761000743,0.07992558277646639,-0.029089657269111058
394.2000000000049,44.96718173866321,0.08050021542954847,-0.029392676253735317
395.0000000000049,45.045364963806705,0.07951083031877881,-0.03504623445002508
395.8000000000049,45.12356239493418,0.07938244562533729,-0.03673399376448838
396.6000000000049,45.20269949088387,0.08091591496669819,-0.03897007575069722
397.4000000000049,45.27893537064989,0.08330115583677963,-0.040281898446093756
398.20000000000493,45.35725249048754,0.087604838234855,-0.04217969195076421
399.00000000000495,45.434751729635835,0.09160019714524117,-0.04406766275953444
399.80000000000496,45.51230710594044,0.09435726122581288,-0.04642919476389107
400.60000000000497,45.59068941682763,0.09577890444180898,-0.04643000527097829
401.400000000005,45.66911809844021,0.09639831819242015,-0.04775934284885608
402.200000000005,45.747195467451824,0.0981395806263969,-0.048442286149854574
403.000000000005,45.824834605043286,0.09707201335001757,-0.05168362252224057
403.800000000005,45.902820487306165,0.09995289600838933,-0.058096739392971664
404.600000000005,45.980202033764805,0.09843387960037821,-0.059169958192746286
405.40000000000504,46.058161073731924,0.09792656458315334,-0.05783318101220214
406.20000000000505,46.13611030584875,0.09767688683129445,-0.05813892043039459
407.00000000000506,46.21364633362927,0.10043485179490388,-0.06080891362806007
407.80000000000507,46.291746303975174,0.1014436144946251,-0.06076232693952832
408.6000000000051,46.369531797838334,0.10180369524980515,-0.061470177082545874
409.4000000000051,46.44735928055269,0.10163463465206084,-0.0614710700836234
410.2000000000051,46.525944058245244,0.1034790938858022,-0.06540898406031737
411.0000000000051,46.60348852307406,0.10220975333198012,-0.0680994467332301
411.8000000000051,46.681612224995334,0.10507955852896841,-0.07085622287842863
412.60000000000514,46.759444801570595,0.10820438622402125,-0.07441365493297214
413.40000000000515,46.83873480322159,0.10948338004941074,-0.07570680594986712
414.20000000000516,46.91499415777916,0.11216557444479068,-0.07705993046737802
415.0000000000052,46.9943278462315,0.11508788900427892,-0.07870235274681825
415.8000000000052,47.07156786383454,0.11716563647377534,-0.08082950155691826
416.6000000000052,47.14990429692606,0.12150376611093525,-0.083209920985015
417.4000000000052,47.22854753407862,0.12644906352796056,-0.08601036978389409
418.2000000000052,47.306409697215706,0.13087572338991185,-0.09143417284031496
419.00000000000523,47.38422773054896,0.1352975965171917,-0.09144981241730488
419.80000000000524,47.46245171267178,0.14414511058989965,-0.0904579966584933
420.60000000000525,47.5403814535629,0.14884104994436537,-0.09477928622615117
421.40000000000526,47.61913573140007,0.15643999303038836,-0.10380748206084744
422.2000000000053,47.69719282249141,0.16446372279942612,-0.10800751797960073
423.0000000000053,47.77538904919428,0.17392748702044145,-0.10888616668647089
423.8000000000053,47.85337353588606,0.18566835370235066,-0.1128844234248807
424.6000000000053,47.93123563961799,0.19743297985478886,-0.11925437113833359
425.4000000000053,48.00960378943816,0.20912179146402401,-0.12151722874169968
426.20000000000533,48.08731477396177,0.22185808191689668,-0.12700256233518514
427.00000000000534,48.16675606275687,0.23891746605147182,-0.13521937170668474
427.80000000000535,48.24469162156238,0.2532558052650159,-0.14022432460398937
428.60000000000537,48.32227561017948,0.2704674814492458,-0.14745262560712424
429.4000000000054,48.40160016909482,0.28814347177829325,-0.15472692784875042
430.2000000000054,48.47886359612265,0.30667011765317115,-0.1610606029494166
431.0000000000054,48.55848928183171,0.33197003389582097,-0.16873738235203373
431.8000000000054,48.63608499148818,0.3535349015510892,-0.17534018934535434
432.6000000000054,48.71469760943581,0.379557252250923,-0.18568326445437844
433.40000000000543,48.79211704182067,0.4042377064435916,-0.19814681255787514
434.20000000000545,48.870763488119465,0.43434623603802386,-0.2068396812168185
435.00000000000546,48.947987162015295,0.4637659477644573,-0.21658349761527873
435.80000000000547,49.027745571240146,0.4947636929771708,-0.22898199233061378
436.6000000000055,49.103892054309675,0.5284166392337842,-0.24346333127420827
437.4000000000055,49.184567150696616,0.5612401691942409,-0.26001343404843924
438.2000000000055,49.26249773707423,0.6006073298921386,-0.2748026518883995
439.0000000000055,49.34162948901327,0.6416672955888066,-0.29281391915238064
439.8000000000055,49.41969459723108,0.6855908513501083,-0.3101848327722463
440.60000000000554,49.49798769901886,0.7278419941460144,-0.3296115644519788
441.40000000000555,49.57644908664376,0.7729564509054059,-0.35405219173931535
442.20000000000556,49.65646922582163,0.82115577519932,-0.38126656984420393
443.00000000000557,49.73361302206547,0.8729608015319476,-0.4117023169070402
443.8000000000056,49.812061738745825,0.9260474281893546,-0.4414963016303184
444.6000000000056,49.89040718207842,0.9756712185373337,-0.46723650433501396
445.4000000000056,49.9697154718761,1.031607283790409,-0.4963377555232755
446.2000000000056,50.04874702870557,1.0815590996762465,-0.5310960134281135
447.0000000000056,50.12704403361286,1.1392317883851928,-0.5721978618752765
447.80000000000564,50.20655940104653,1.194004257623207,-0.6138551230877187
448.60000000000565,50.285295164834096,1.2478800396613368,-0.656419002417389
449.40000000000566,50.36268411212695,1.2981688383746877,-0.7000011005658786
450.2000000000057,50.443255374559676,1.3614766108851375,-0.7496201050926707
451.0000000000057,50.51876890952556,1.4113320835061032,-0.8044869730515796
451.8000000000057,50.60043935429888,1.4566281569032904,-0.863513954739175
452.6000000000057,50.67932356494919,1.4806792823144945,-0.9253461198850665
453.4000000000057,50.75916237245414,1.5276766746926485,-0.9840802646245512
454.20000000000573,50.836748912358516,1.566963553271419,-1.046153638899852
455.00000000000574,50.915999972002325,1.6076057579714924,-1.1125828782001395
455.80000000000575,50.99491619855713,1.6626600374702005,-1.1788603815392467
456.60000000000576,51.07319374634619,1.7280537751198182,-1.2553698040192387
457.4000000000058,51.15245277096659,1.773364847122486,-1.3375828237815668
458.2000000000058,51.23121599548466,1.8209309263313918,-1.4251166902613304
459.0000000000058,51.310294778035406,1.8293954421367087,-1.5120864908170493
459.8000000000058,51.38893280795203,1.8581512285768964,-1.6009018953159653
460.6000000000058,51.46711501227445,1.8599564091773848,-1.6961032528609774
461.40000000000583,51.546098175520584,1.8700155118307304,-1.796439436114464
462.20000000000584,51.62455409212206,1.871761435626747,-1.9024871708335596
463.00000000000585,51.70390390031137,1.8593822577775763,-2.009406262029821
463.80000000000587,51.78193004170062,1.8405905878165225,-2.1198278709628635
464.6000000000059,51.860194127416776,1.8077540428349799,-2.2297426123457216
465.4000000000059,51.9393408245202,1.759563624017353,-2.345667478247689
466.2000000000059,52.01772880801362,1.6971684743819238,-2.459239558563934
467.0000000000059,52.09660206555977,1.6201748942482364,-2.577846498110979
467.8000000000059,52.175339058920954,1.529857959714814,-2.6920084607601824
468.60000000000593,52.253425185629546,1.4219244477187098,-2.8069279134355503
469.40000000000595,52.332109739142375,1.3009718682024896,-2.9155970917744005
470.20000000000596,52.409607763877915,1.1739485291992826,-3.022983176930002
471.00000000000597,52.488488298168214,1.0370686174288541,-3.129318400899989
471.800000000006,52.566471768448245,0.8907943232162483,-3.2339847958791275
472.600000000006,52.64460660344688,0.7411953673006667,-3.329583559068881
473.400000000006,52.72182082858359,0.58714110802705,-3.415857584767825
474.200000000006,52.79939459674877,0.43477444941244453,-3.4949855599308775
475.000000000006,52.876668558041686,0.2867456814985245,-3.564193916719173
475.80000000000604,52.95591965714957,0.15347532289189902,-3.6333769235239313
476.60000000000605,53.03429469050616,0.03298352815300735,-3.6920651850155806
477.40000000000606,53.1125625892264,-0.07174557303498924,-3.7409766321669364
478.20000000000607,53.18980422686274,-0.15030473435351457,-3.7853402453112963
479.0000000000061,53.26798814715946,-0.2171708680617275,-3.824658505902746
479.8000000000061,53.345316473271076,-0.2693988164266132,-3.8577087908487018
480.6000000000061,53.42405547826128,-0.30965712048578686,-3.886767393042777
481.4000000000061,53.50156003897392,-0.3375714085538454,-3.909682728967394
482.2000000000061,53.580446618520455,-0.3502503800500282,-3.93375243841352
483.00000000000614,53.658277031886946,-0.3622420803938248,-3.9526091122986555
483.80000000000615,53.73767694499425,-0.3756417195776538,-3.9726189158474163
484.60000000000616,53.81568031149593,-0.38180448137737827,-3.986135009746355
485.4000000000062,53.893467239880906,-0.38626041840480924,-3.9959778693969947
486.2000000000062,53.971734644123984,-0.3881968246991793,-4.00054447362618
487.0000000000062,54.05116727265665,-0.39415494459482464,-4.009585761552381
487.8000000000062,54.13084454937463,-0.4017445720250361,-4.014499450987477
488.6000000000062,54.207891790696145,-0.40718056282402715,-4.017513285273484
489.40000000000623,54.286470598946565,-0.41134722208662955,-4.020991640354938
490.20000000000624,54.364918180567514,-0.4146321367241014,-4.023520735235621
491.00000000000625,54.44480231035811,-0.4137324582467439,-4.022159462731971
491.80000000000626,54.522916987749895,-0.4160008069973437,-4.025725024639146
492.6000000000063,54.60120993458077,-0.4172664947185357,-4.0248584806027115
493.4000000000063,54.68051846471471,-0.41928618046959537,-4.023512567294034
494.2000000000063,54.75921809621387,-0.4196803783510728,-4.023541226229014
495.0000000000063,54.8377009151046,-0.41665764362632884,-4.022215053997326
495.8000000000063,54.91597795941551,-0.41400495292831874,-4.0235399536440974
496.60000000000633,54.99393729893581,-0.4090950600908823,-4.022249666388471
497.40000000000634,55.07211954103883,-0.4057243044257176,-4.022247308321317
498.20000000000636,55.15148597415509,-0.4085280534643264,-4.024203372054603
499.00000000000637,55.2303967576925,-0.4126005217480636,-4.025520163497015
499.8000000000064,55.309905813692765,-0.4180634444193174,-4.026830081492275
500.6000000000064,55.3870435405273,-0.41966944946331824,-4.028161822234207
501.4000000000064,55.467742226979325,-0.4186132836966783,-4.026866418488716
502.2000000000064,55.54574669913615,-0.4181279619850675,-4.026950211339504
503.0000000000064,55.6254344121597,-0.41716993229029425,-4.024201963038536
503.80000000000643,55.704407710623364,-0.41379106208203237,-4.025203882392563
504.60000000000645,55.78321225202942,-0.4124181590755059,-4.025510095237675
505.40000000000646,55.8619411647039,-0.40964415612247407,-4.025596498244824
506.20000000000647,55.9409767354752,-0.4102813220275841,-4.028151571149752
507.0000000000065,56.019217402542125,-0.40791757003794044,-4.030065787361868
507.8000000000065,56.0972899494782,-0.40649651661650765,-4.030778097145044
508.6000000000065,56.17837739570983,-0.4040424329724876,-4.028537967841349
509.4000000000065,56.256971155562674,-0.4020694272305471,-4.026821190910872
510.2000000000065,56.33623343924367,-0.402847088005047,-4.025480137598149
511.00000000000654,56.41290144535493,-0.40175779346605545,-4.024199952247357
511.80000000000655,56.49412586700156,-0.40030305840475505,-4.024201372525967
512.6000000000065,56.57172684672496,-0.3972587039495591,-4.025583727235496
513.4000000000066,56.65240671827292,-0.3970265555767092,-4.028132498439552
514.2000000000066,56.729059977425166,-0.394586194297466,-4.026830431079212
515.0000000000066,56.8072504751627,-0.39531436998230207,-4.0255110705044785
515.8000000000065,56.88730484604879,-0.3942191902295953,-4.025510372323215
516.6000000000066,56.965280219167624,-0.39302679851859956,-4.0241260495956075
517.4000000000067,57.044378763996875,-0.3919540577278134,-4.026361744372886
518.2000000000066,57.12289868696443,-0.3908953255213292,-4.0289876767142045
519.0000000000066,57.203029854328626,-0.38922961122366284,-4.031909997714183
519.8000000000067,57.28051430633947,-0.3919926139250193,-4.029124653939693
520.6000000000067,57.36149099257529,-0.39282097560709595,-4.026838920871855
521.4000000000067,57.438881363306116,-0.3929375530329336,-4.0255108394955705
522.2000000000066,57.51893552219877,-0.39445000221689186,-4.025520173645113
523.0000000000067,57.598235497637745,-0.39530816933221957,-4.025514929107979
523.8000000000068,57.67722319993494,-0.39357465537036923,-4.027708106147401
524.6000000000067,57.7565787985527,-0.39421191494504937,-4.0271856559786325
525.4000000000067,57.83554255879987,-0.3949661284479147,-4.0265042725300795
526.2000000000068,57.914170849871056,-0.39319600511042563,-4.0271619447447184
527.0000000000068,57.99346526557237,-0.3933945203107419,-4.026500488067417
527.8000000000068,58.07314862902909,-0.3919052400937808,-4.026500720497438
528.6000000000067,58.1517174018625,-0.39062350549990543,-4.0278222340243275
529.4000000000068,58.23055978712478,-0.3921302357305288,-4.029157952228227
530.2000000000069,58.30989055879205,-0.3919882392543528,-4.029142637906432
531.0000000000068,58.388833271057834,-0.39090856018527964,-4.027830182296002
531.8000000000068,58.468376837382664,-0.3885737441180721,-4.027830121006458
532.6000000000068,58.54519974062442,-0.39155809425996707,-4.028851867446416
533.4000000000069,58.62493751122148,-0.3889354138607861,-4.027819802267673
534.2000000000069,58.703949820185194,-0.38993645380483843,-4.0278198219995165
535.0000000000068,58.78273402870997,-0.3879593326778495,-4.027819821608195
535.8000000000069,58.86341745220025,-0.38951493634245016,-4.027859894304567
536.600000000007,58.94239719896008,-0.38722743962895745,-4.027829497275508
537.4000000000069,59.018881460523104,-0.3900141209103596,-4.026513900048847
538.2000000000069,59.100103738857584,-0.3885234131097752,-4.025190534992802
539.0000000000069,59.17888852406561,-0.3863978975486971,-4.026631959903771
539.800000000007,59.258135665339644,-0.38642833915188896,-4.027490041133034
540.600000000007,59.33774387481345,-0.38737897532511123,-4.0274927657761985
541.4000000000069,59.41616009583111,-0.3859494438490255,-4.027541471841723
542.200000000007,59.49605574952097,-0.3864410091585825,-4.027958606094107
543.000000000007,59.5749953303235,-0.3844291604539627,-4.0274815040902
543.800000000007,59.65153330943555,-0.3845196476501657,-4.029911748784902
544.600000000007,59.73280205488397,-0.3832748868499756,-4.031452668041256
545.400000000007,59.811926363626036,-0.38413582660794887,-4.030141785651175
546.2000000000071,59.891068475854745,-0.38355825362339735,-4.029780444845676
547.000000000007,59.97000000000069,-0.3823599999999819,-4.030851773685905