File: 01_Data/Concrete_Block/STA/N2/30K_min/Concrete_Block_STA_N2_30KData_230830_R3.csv
##Temp./Â°C,Time/min,DSC/(mW/mg),Mass loss/mg
28.0,10.277811153643906,-2.306873482168898,-0.015198851278045211
29.40000000000002,10.715641403981255,-2.2185008248780975,-0.014832411303431492
30.80000000000004,10.880022514474042,-2.1641640518696947,-0.013479755084072842
32.20000000000006,11.000575060455416,-2.121033963392,-0.013917258330502058
33.60000000000008,11.101626933300498,-2.0812737093112843,-0.013049620499979042
35.0000000000001,11.18928423760498,-2.0431160954902436,-0.013690823521960382
36.40000000000012,11.270023539187383,-2.0092584319771953,-0.01394399194671525
37.80000000000014,11.34391192983698,-1.9765270983092187,-0.013826005170760602
39.20000000000016,11.415236808120637,-1.9464618951761188,-0.014596537855394942
40.60000000000018,11.48225975409061,-1.9174201009635738,-0.013794630479107006
42.0000000000002,11.546205798130098,-1.8910131310793767,-0.01395355222004735
43.40000000000022,11.60865618024501,-1.865649157636048,-0.012158520018958008
44.80000000000024,11.66900610399253,-1.8402948997013886,-0.013119726597904169
46.20000000000026,11.728003360407978,-1.817643506080584,-0.015989727623358263
47.60000000000028,11.784789695936283,-1.7951239683260574,-0.016864689929056098
49.0000000000003,11.840998743962949,-1.7753095873818252,-0.016572407017533486
50.40000000000032,11.897748668505107,-1.754917321220628,-0.01678099381847087
51.80000000000034,11.95188448340958,-1.7380947189892568,-0.015119319543464904
53.20000000000036,12.006311492371646,-1.7199529495457462,-0.01586058675739377
54.60000000000038,12.059670915305611,-1.7044485086546457,-0.01638728532554179
56.0000000000004,12.11203045081774,-1.6907530326790476,-0.01624349006979564
57.40000000000042,12.16477550153953,-1.676802055761328,-0.01607408570991975
58.80000000000044,12.215704289828004,-1.6646700556139626,-0.017594653718362885
60.20000000000046,12.267617284752788,-1.6543416323381632,-0.01869867465788122
61.60000000000048,12.318343260064859,-1.6421283149540344,-0.01936233812780941
63.0000000000005,12.368363843330696,-1.6318227437035817,-0.020290793042007316
64.40000000000052,12.41920472268286,-1.6184592320872684,-0.02050928095724469
65.80000000000054,12.468664162163968,-1.6072971645373855,-0.020420474523021426
67.20000000000056,12.517098833246337,-1.5956851333225803,-0.021809275975001263
68.60000000000058,12.567879245053696,-1.584245657970513,-0.021325433850694964
70.0000000000006,12.617358010899897,-1.5699776414318236,-0.020887295331727174
71.40000000000062,12.66654313746586,-1.5584838996107644,-0.021066350991198135
72.80000000000064,12.715040173023095,-1.5461606873569715,-0.02201519034404864
74.20000000000066,12.764306327133294,-1.534482874390499,-0.023001419491361474
75.60000000000068,12.812299589559569,-1.52354141850844,-0.02395504181962238
77.0000000000007,12.861857925139418,-1.510138907319637,-0.02504893051071022
78.40000000000072,12.910473036387467,-1.5003316920224201,-0.0238323237056699
79.80000000000074,12.95847173274318,-1.4890436615074343,-0.02515401561296038
81.20000000000076,13.007376184475165,-1.4780199456628318,-0.026447691441567223
82.60000000000078,13.055593852247082,-1.4673786943272984,-0.026448610699608466
84.0000000000008,13.103613071464752,-1.4582505844716618,-0.027770619624166493
85.40000000000082,13.15140076407772,-1.4496456208458497,-0.02772410715223117
86.80000000000084,13.198699400695496,-1.4384005743508093,-0.027771063042673738
88.20000000000086,13.246242491699885,-1.4287235981294046,-0.029005684455074565
89.60000000000088,13.29410316591189,-1.4190676001531675,-0.027766547452126922
91.0000000000009,13.3403517023718,-1.4090100529136627,-0.027726597823176213
92.40000000000092,13.388166431640409,-1.3993949103276948,-0.02748495095876624
93.80000000000094,13.435339786954689,-1.3903527831611766,-0.028869286079878265
95.20000000000095,13.48216723106245,-1.379080351392297,-0.030404501916090787
96.60000000000097,13.528797188627204,-1.370005239389204,-0.03170788730517238
98.000000000001,13.57606730750839,-1.3587161869427757,-0.03172034675992297
99.40000000000101,13.62221236873045,-1.3499578876792433,-0.03148934161264538
100.80000000000103,13.66883542594057,-1.3385661855192184,-0.03172781738585595
102.20000000000105,13.715071774008837,-1.3283909708433015,-0.03173451020376028
103.60000000000107,13.761707698304738,-1.3170914564786325,-0.03306257438168991
105.0000000000011,13.807593407036116,-1.308062409833486,-0.03303919709385461
106.40000000000111,13.853716021949461,-1.2987735269274416,-0.0321612088779597
107.80000000000113,13.899369597769052,-1.287971698606608,-0.03204925343847709
109.20000000000115,13.945328243705791,-1.2769514453661657,-0.03344997321411558
110.60000000000117,13.991954702355013,-1.2684050789315933,-0.03336053698256514
112.0000000000012,14.038425781204111,-1.2595389916974828,-0.033059792079772166
113.40000000000121,14.084103628929707,-1.2484569390001372,-0.03335148731320725
114.80000000000123,14.130065941660972,-1.2388708804772812,-0.03406688033101357
116.20000000000125,14.175590077492751,-1.2305387923663842,-0.03462182096393196
117.60000000000127,14.221512439001001,-1.2227143536853529,-0.03602621143904283
119.0000000000013,14.267110436466657,-1.213426735785297,-0.038641111023348884
120.40000000000131,14.31172259487132,-1.2039024442277932,-0.03863989804532064
121.80000000000133,14.3583911462895,-1.1942896686506443,-0.038639860945853144
123.20000000000135,14.40369150462049,-1.184251247717404,-0.03783760720942109
124.60000000000137,14.449137711019974,-1.1746559297435735,-0.03732007728927744
126.00000000000139,14.495093454119448,-1.1633014952988219,-0.03731307091651104
127.40000000000141,14.540211385382744,-1.1515205618615667,-0.03861682669975952
128.80000000000143,14.58490217035053,-1.1398586301745175,-0.038642522663665524
130.20000000000147,14.630051062699525,-1.1285962030374663,-0.04124796631579386
131.60000000000147,14.675016582707817,-1.117168223000134,-0.0412698607829558
133.00000000000148,14.719448399074512,-1.1063188413043237,-0.04126990806443853
134.4000000000015,14.764433959350516,-1.094501520131292,-0.04126990827731358
135.80000000000155,14.809138614801808,-1.0834275157170628,-0.04127004764056519
137.20000000000155,14.853565114017615,-1.0755820549124986,-0.041676994478986096
138.60000000000156,14.898016570716024,-1.063165274059304,-0.04258819631762112
140.0000000000016,14.941743437743765,-1.053811103473895,-0.04258990687146724
141.40000000000163,14.986811443532115,-1.0427032415318882,-0.04259001675320473
142.80000000000163,15.030656392267169,-1.0333851002609984,-0.04261322568302184
144.20000000000164,15.074443554159876,-1.0233819134558866,-0.043908826996781336
145.60000000000167,15.117721936007333,-1.0119183196238657,-0.04391084509874954
147.0000000000017,15.162402153031644,-1.0015474277696867,-0.04519992674206019
148.4000000000017,15.20594305421819,-0.9934664944295456,-0.04523167285634422
149.80000000000172,15.2500157162069,-0.9846497340645284,-0.04628716170892311
151.20000000000175,15.29293751738883,-0.975354869946791,-0.04655003940863356
152.60000000000178,15.33767443142773,-0.9656316779109617,-0.0465504737362048
154.0000000000018,15.38160649633683,-0.9557800105554606,-0.0463418864697438
155.4000000000018,15.42536897484781,-0.9477554697562283,-0.04658406143043514
156.80000000000183,15.469079397824435,-0.9381690558795438,-0.04654000895519861
158.20000000000186,15.512463664818107,-0.9302020869826229,-0.04791553995519582
159.60000000000187,15.555907124644737,-0.9216972923761058,-0.04786030752538917
161.00000000000188,15.599326448733771,-0.9130843280842528,-0.04786012596518496
162.4000000000019,15.64280740837301,-0.9036240220978072,-0.04786012599797562
163.80000000000194,15.686282385749628,-0.8958556226610676,-0.04786012600240941
165.20000000000195,15.729864098720112,-0.8876954265911969,-0.04786012661189343
166.60000000000196,15.773357201760318,-0.8801109718809154,-0.047860031458311525
168.000000000002,15.816675149365803,-0.870134222989849,-0.04773834240247954
169.40000000000202,15.859042572744807,-0.8646702648121474,-0.04654717011850362
170.80000000000203,15.9033357819413,-0.8542739956400732,-0.04621034832643023
172.20000000000203,15.946634138149635,-0.8471546856985461,-0.0462402146296883
173.60000000000207,15.989916079230758,-0.8379750091177244,-0.04584140915563051
175.0000000000021,16.032980236677705,-0.8302799282672669,-0.04849507266507125
176.4000000000021,16.076323722769704,-0.823804881118263,-0.048520471298716394
177.80000000000211,16.119479341420558,-0.8162859046839459,-0.04860094720270958
179.20000000000215,16.16197912877528,-0.809038637607078,-0.04719486424962227
180.60000000000218,16.204760005315705,-0.8026437273902434,-0.048590759171857734
182.0000000000022,16.248522664856914,-0.7944983237433412,-0.04983062985209408
183.4000000000022,16.291126332415274,-0.7863083198503757,-0.049829874589471856
184.80000000000223,16.334114877526687,-0.7803946416664435,-0.04982986359077035
186.20000000000226,16.37703305209688,-0.7726445913801299,-0.049822939553634704
187.60000000000227,16.41956622149381,-0.7670746852642012,-0.051142321101869115
189.00000000000227,16.462527108124448,-0.7623844798956537,-0.05114989828181482
190.4000000000023,16.505240424162594,-0.7563111297311127,-0.0511478683263773
191.80000000000234,16.547408519693413,-0.7479690398906674,-0.04976560630772475
193.20000000000235,16.5911379130849,-0.7418147208002884,-0.04983052104228314
194.60000000000235,16.633429760924262,-0.7353986742500519,-0.05021125625710443
196.0000000000024,16.67612021146083,-0.7298077069926212,-0.050829496504137595
197.40000000000242,16.719018436927033,-0.7248402861620978,-0.05082020622982952
198.80000000000243,16.761395671160482,-0.7190075878325942,-0.05088391681255455
200.20000000000243,16.804095945602853,-0.713268685984464,-0.05114920074292506
201.60000000000247,16.846622172095497,-0.7094997840053965,-0.05114986412874423
203.0000000000025,16.888476232854615,-0.7035886088619757,-0.05114986400730093
204.4000000000025,16.931976046024634,-0.6997899103577434,-0.05114989839452644
205.8000000000025,16.974559718821812,-0.6931805707742384,-0.05256244095842799
207.20000000000255,17.017563431487314,-0.690015299992346,-0.05248090966512908
208.60000000000258,17.059955017149683,-0.6837998598903905,-0.05404328978816597
210.0000000000026,17.10238204571846,-0.6818208944437276,-0.05400877640086588
211.4000000000026,17.145064578552727,-0.675961557834665,-0.05282109901864285
212.80000000000263,17.187720719919188,-0.672537427619016,-0.051317185527519626
214.20000000000266,17.230366314364705,-0.6679572661187593,-0.051397560114117447
215.60000000000267,17.272568495976717,-0.6651274215343326,-0.05136973403350442
217.00000000000267,17.315313563585317,-0.6618931320616105,-0.052340890555950814
218.4000000000027,17.35801034716343,-0.6567983368007749,-0.053996862539824164
219.80000000000274,17.400130406382875,-0.6520465743594093,-0.054010134688236455
221.20000000000275,17.442795559710333,-0.6486214785905492,-0.054010168532227176
222.60000000000275,17.485457521545868,-0.6461372204138297,-0.05400763730962055
224.00000000000279,17.527927062178186,-0.6414908367793773,-0.054348066437078124
225.40000000000282,17.5700874637229,-0.6390171420249853,-0.054339836868075864
226.80000000000283,17.613175103117758,-0.6359812870832774,-0.05434524492815296
228.20000000000283,17.65534496753319,-0.6344485742539372,-0.053660296101000426
229.60000000000286,17.697694350388236,-0.6307271131249611,-0.05367959702336211
231.0000000000029,17.740287882500056,-0.6276308190901934,-0.05368000341794854
232.4000000000029,17.782613936515094,-0.6253060420292739,-0.05368000599425393
233.8000000000029,17.82491426160894,-0.6227510263905162,-0.053680006187883045
235.20000000000294,17.867225894453323,-0.6212674267038854,-0.05367993357064993
236.60000000000298,17.908787213038387,-0.6180403777224861,-0.053634485061466286
238.00000000000298,17.951902604641166,-0.6153329077729197,-0.054989373025834176
239.400000000003,17.994110504213896,-0.612284559109889,-0.05535195813366034
240.80000000000302,18.03664104154354,-0.6098827953560734,-0.05401104991687955
242.20000000000306,18.0792309555951,-0.605121092679087,-0.05401121665371722
243.60000000000306,18.121321495995726,-0.6014432817658917,-0.05545841835709897
245.00000000000307,18.163422722199023,-0.5992239066921816,-0.05631032141294412
246.4000000000031,18.205965327057584,-0.5954136749245285,-0.056310246766607897
247.80000000000314,18.248268240226842,-0.5923179369217798,-0.056227700340221176
249.20000000000314,18.290636404308117,-0.5877877118812681,-0.05498654547730286
250.60000000000315,18.333020579324568,-0.5871355267851752,-0.05499015721690714
252.00000000000318,18.375167427534684,-0.5847934530564641,-0.05499090409225893
253.40000000000322,18.41592698471927,-0.582098715279057,-0.05523071403313029
254.80000000000322,18.458875893368834,-0.5784638992805116,-0.0552903518735528
256.20000000000323,18.501151406593834,-0.5775570382119379,-0.056627158870968586
257.60000000000326,18.543810879074787,-0.5756012290281612,-0.05664106772569877
259.0000000000033,18.58640847879899,-0.5732703333817665,-0.05713821442185729
260.4000000000033,18.628525432977888,-0.5713787436185558,-0.057299831696886905
261.8000000000033,18.670964184864598,-0.5671486774344351,-0.05730120510626069
263.20000000000334,18.712896427156497,-0.566095744238552,-0.05633197146563518
264.6000000000034,18.755491284140973,-0.5640916568285397,-0.05598057460976413
266.0000000000034,18.797716351563793,-0.5617141740407562,-0.05594796672777402
267.4000000000034,18.839801725425485,-0.5603296119939215,-0.05730056737304601
268.8000000000034,18.882053513033483,-0.5572935401676566,-0.05850929930429416
270.20000000000346,18.924221711682552,-0.5575164666523968,-0.05920093784858338
271.60000000000343,18.966349003494653,-0.5550587813061291,-0.06005013233022005
273.00000000000347,19.00859990885701,-0.5522368468150635,-0.060049524986582004
274.4000000000035,19.0509469551347,-0.5514939005833669,-0.05924227543392391
275.80000000000354,19.092986141257207,-0.5508005584584731,-0.058731035141714294
277.20000000000357,19.135415616583195,-0.54970407835838,-0.05875576399107363
278.60000000000355,19.17755769928618,-0.5483994934609594,-0.06005144641725613
280.0000000000036,19.219649034157626,-0.5463713420148292,-0.05897377427574657
281.4000000000036,19.26207402607059,-0.5447155525817705,-0.05849216063502016
282.8000000000036,19.30451176066522,-0.5440069792479597,-0.05740970582780758
284.2000000000036,19.34670153410437,-0.543525101300098,-0.057432921702607054
285.60000000000366,19.389376313520074,-0.5435057871378939,-0.05872958660315941
287.0000000000037,19.431461341432474,-0.5418732993810663,-0.058728292142770755
288.40000000000373,19.47345143041667,-0.5402615195955828,-0.059854767241480644
289.8000000000037,19.51637600654808,-0.5404521301068757,-0.06134833668776052
291.20000000000374,19.55854857224513,-0.5392551785015752,-0.06135998214324978
292.6000000000038,19.600962332853037,-0.537680160915875,-0.06135999608610376
294.00000000000375,19.643116661044722,-0.5369259311177403,-0.06135999548885884
295.4000000000038,19.685928493672883,-0.536284882652776,-0.06135987736667037
296.8000000000038,19.728001641677942,-0.5360794065769355,-0.06134640093040833
298.20000000000385,19.770648740109003,-0.5370007067446199,-0.06005149693824574
299.6000000000039,19.812836181778817,-0.5375650426834712,-0.060049832927731916
301.00000000000387,19.85531251565984,-0.5361164180099154,-0.06004609236985914
302.4000000000039,19.897817313474455,-0.5358764871931834,-0.061311031111676684
303.80000000000393,19.94018283494655,-0.5352978546451912,-0.06135961169354687
305.2000000000039,19.982582769490005,-0.5357665774742284,-0.060036758662026735
306.60000000000394,20.0250509142091,-0.535159970240365,-0.05905293412466772
308.000000000004,20.067989786232566,-0.5353688654062523,-0.06004127926953684
309.400000000004,20.110456287071784,-0.5350892039422968,-0.060048751542407075
310.80000000000405,20.152004978381083,-0.5356136521433292,-0.061053093202181774
312.200000000004,20.194679560333526,-0.5367099129547039,-0.06103965707793613
313.60000000000406,20.23721879838838,-0.536078065104048,-0.060999373260104406
315.0000000000041,20.28008042435247,-0.5354246182963561,-0.06235184498575297
316.40000000000407,20.322706469740215,-0.5350247420712696,-0.06234998358681931
317.8000000000041,20.364920778329726,-0.5348589781586002,-0.06234097075826561
319.20000000000414,20.40734056045572,-0.5341536309890508,-0.06366117697443885
320.6000000000042,20.450016959562284,-0.5346422897491125,-0.06366250260221573
322.0000000000042,20.492744163100568,-0.5352848489807244,-0.06497465582912243
323.4000000000042,20.535254078535893,-0.534876886342703,-0.06477958437751097
324.8000000000042,20.57783533924256,-0.5361848739131582,-0.06235304283726473
326.20000000000425,20.620556157710762,-0.5354264206794053,-0.061712786225414984
327.60000000000423,20.66353504163834,-0.5346271171845662,-0.061030743458118764
329.00000000000426,20.705971082964073,-0.5356670173528889,-0.061029911333551734
330.4000000000043,20.748529338283753,-0.5359757444314216,-0.06103081737334737
331.80000000000433,20.791762655199523,-0.5377796673773503,-0.061710458547060476
333.20000000000437,20.834131021426906,-0.5378239631869675,-0.062348963400824076
334.60000000000434,20.877046915821733,-0.5389082508743588,-0.06234974819984895
336.0000000000044,20.91976598096669,-0.5396256712965645,-0.062136326094405
337.4000000000044,20.962721707415234,-0.5392107077389289,-0.06103078124212491
338.8000000000044,21.00530750421393,-0.5404846223111007,-0.06104918046557595
340.2000000000044,21.048223104070512,-0.5406780021914159,-0.06305666607834937
341.60000000000446,21.09084432981948,-0.5425161471045611,-0.06377907147166839
343.0000000000045,21.134120610954902,-0.543607628850334,-0.06380663214020998
344.4000000000045,21.1770637451692,-0.5438404384675789,-0.0627717395984142
345.8000000000045,21.219888381093767,-0.5452393714114333,-0.0614704465532987
347.20000000000454,21.262494627054632,-0.5472857782293112,-0.06146990937975616
348.60000000000457,21.305242202726113,-0.5477786177404725,-0.061469901987065256
350.00000000000455,21.34833506165465,-0.5483834729025141,-0.061469896810901314
351.4000000000046,21.391422482082806,-0.5495976299301972,-0.061471535258228904
352.8000000000046,21.434488917015177,-0.5502835192641574,-0.06272866593828264
354.20000000000465,21.47767003535485,-0.5526579877248364,-0.06378062710586274
355.6000000000047,21.520293792071204,-0.5532142925408271,-0.06378053962641994
357.00000000000466,21.563597428841337,-0.5555757692806461,-0.06366782548960126
358.4000000000047,21.605871888283847,-0.5563142464497877,-0.06278204077562943
359.80000000000473,21.64926532029811,-0.5581974173053711,-0.06279263001089097
361.2000000000047,21.692523060488178,-0.558751212921127,-0.06411401210918344
362.60000000000474,21.735647478419438,-0.5598072937792848,-0.06419068310575593
364.0000000000048,21.778833988350804,-0.5618335669649173,-0.06279080503383705
365.4000000000048,21.821888547971938,-0.5645923648965882,-0.06279010180764555
366.80000000000484,21.864341728760223,-0.5655026443572848,-0.06346474233979338
368.2000000000048,21.90805175130585,-0.56547508902061,-0.06282907826014039
369.60000000000485,21.95118275516321,-0.566326099909611,-0.06278964042040602
371.0000000000049,21.994708086493898,-0.5662332264964741,-0.06293840786593208
372.40000000000487,22.037773529878425,-0.5675365713900324,-0.06544650388963458
373.8000000000049,22.080864613198173,-0.5684256736975039,-0.06543006384170091
375.20000000000493,22.12353739563396,-0.5691899920346031,-0.06543011948392019
376.60000000000497,22.16786571242623,-0.5695907628819044,-0.06543010297958407
378.000000000005,22.21087544621842,-0.5706984891504102,-0.06543843969292373
379.400000000005,22.25383839736996,-0.5724627096516909,-0.06674663759598376
380.800000000005,22.2974548135253,-0.5730335120760311,-0.06674515650482027
382.20000000000505,22.340749431540054,-0.5735392110919453,-0.0654179082073525
383.600000000005,22.383974762025534,-0.5746681309066966,-0.06410342411496339
385.00000000000506,22.427124176680103,-0.5761455833652069,-0.06410419556634972
386.4000000000051,22.470745806412406,-0.5788678022410458,-0.06543577139953483
387.8000000000051,22.514261697893538,-0.5800340023933137,-0.06543019239375925
389.20000000000516,22.55775199282496,-0.5818921716521219,-0.06543441199888678
390.60000000000514,22.60111567189068,-0.5818730407955126,-0.06410409061155553
392.0000000000052,22.644427736089778,-0.5821045043202053,-0.06410977474001145
393.4000000000052,22.688225265121158,-0.5844406926287113,-0.064109799097253
394.8000000000052,22.731405301085587,-0.5859173818453428,-0.06411593265865889
396.2000000000052,22.774647887626767,-0.5887096973983759,-0.06547576839665581
397.60000000000525,22.818461575961194,-0.5892989547076003,-0.06543070852405375
399.0000000000053,22.86189743081518,-0.5909856484414885,-0.06671461856921024
400.4000000000053,22.905623586773395,-0.593521027784376,-0.06675856696507276
401.8000000000053,22.949233456381272,-0.5952734537332466,-0.06839667877072797
403.20000000000533,22.992594446718012,-0.5969947759105942,-0.0690523216488983
404.60000000000537,23.03642035577833,-0.5992544324008506,-0.06905019709083415
406.00000000000534,23.07995836357544,-0.6014584674062466,-0.06905022708663822
407.4000000000054,23.123637601181812,-0.6040250946344136,-0.06909973514447199
408.8000000000054,23.167507114786876,-0.6074958428844002,-0.06773419526582414
410.20000000000545,23.21099615098593,-0.6107079760157293,-0.06772975995389574
411.6000000000055,23.254762313904315,-0.6137564831434315,-0.06761565476902698
413.00000000000546,23.29860857149699,-0.6201047187803531,-0.06674976229152563
414.4000000000055,23.3426019184245,-0.6253158170759289,-0.06674764520612442
415.8000000000055,23.386257721653678,-0.6316545525272245,-0.06792780449636426
417.2000000000055,23.430218268269048,-0.6364140097065303,-0.06806010387316297
418.60000000000554,23.474018776441355,-0.6445306850588712,-0.06805995537628906
420.00000000000557,23.517839481885893,-0.649949727890975,-0.06805995401952547
421.4000000000056,23.56193273885448,-0.6567687901060687,-0.06805995313290047
422.80000000000564,23.605901094030433,-0.6646139951017918,-0.06805785363737638
424.2000000000056,23.64999028483021,-0.6697419255470626,-0.06840444552671565
425.60000000000565,23.693840448976815,-0.6743616020601503,-0.06963994906343496
427.0000000000057,23.73763537367773,-0.6783807932457697,-0.07043437913741624
428.40000000000566,23.781605534404186,-0.6796352131788473,-0.07141152573441989
429.8000000000057,23.82553238070147,-0.6775785419289925,-0.07134991120059908
431.20000000000573,23.86963385950776,-0.6756385629851592,-0.07137122702450815
432.60000000000576,23.913543159087357,-0.671923453865456,-0.07200894606230879
434.0000000000058,23.957512807204193,-0.6669541699825967,-0.0720200598305456
435.4000000000058,24.001610886468928,-0.6628989178563981,-0.0733188260485953
436.8000000000058,24.045640153816265,-0.6598929585170449,-0.07332043806731825
438.20000000000584,24.089817720651958,-0.6568221708479687,-0.07127123851051786
439.6000000000058,24.13369741364287,-0.6557197423021016,-0.07070117717751767
441.00000000000585,24.17771523307982,-0.6550883878702153,-0.0707001589963383
442.4000000000059,24.222034377132747,-0.6553854298520809,-0.07070923788315664
443.8000000000059,24.26623527987927,-0.6550995083375374,-0.07170051218328943
445.20000000000596,24.31017670146597,-0.6571324271082334,-0.07168998810873317
446.60000000000593,24.354135424299884,-0.6592237226831792,-0.071689999953644
448.00000000000597,24.3985687433787,-0.660617579484996,-0.07169000433576933
449.400000000006,24.44286982193377,-0.6623252026026907,-0.0716826381139688
450.800000000006,24.487061903484427,-0.6640188316603268,-0.0713996422631955
452.200000000006,24.53158877245317,-0.6667700526398371,-0.0726756501480823
453.60000000000605,24.575782312061754,-0.6673136806244724,-0.07131866445556678
455.0000000000061,24.619823600875986,-0.670440903774028,-0.07136264145155158
456.4000000000061,24.66458987469789,-0.6726563222206975,-0.0726757869972805
457.8000000000061,24.708793486381566,-0.676749069979526,-0.07267008614913184
459.2000000000061,24.752998327570367,-0.6777460542346126,-0.07267008623800253
460.60000000000616,24.797432012068608,-0.6790436059997388,-0.07267175138898319
462.00000000000614,24.841549270932813,-0.6830176312812435,-0.0748873885194481
463.4000000000062,24.88591411252774,-0.6848935117380174,-0.07529916712936569
464.8000000000062,24.93042657151747,-0.6877928736285026,-0.07529999028847678
466.20000000000624,24.974891591313032,-0.6912427133798087,-0.07529999001604315
467.6000000000063,25.01939654527568,-0.6954914980895359,-0.0752999895794173
469.00000000000625,25.06404867346401,-0.6963115860974631,-0.07529878067419249
470.4000000000063,25.10841706389774,-0.7003876057437436,-0.0746935759423093
471.8000000000063,25.15287843740774,-0.704305188002481,-0.07596170308005767
473.2000000000063,25.197677863624868,-0.7090300034174994,-0.07595987356637357
474.60000000000633,25.24197542496392,-0.7142318023564797,-0.07593115299316233
476.00000000000637,25.286790643033473,-0.7178955726710619,-0.0772736381186423
477.4000000000064,25.33125141211481,-0.7231807763840122,-0.0772800145389172
478.80000000000643,25.376115822065724,-0.7280771321324405,-0.07729721055606653
480.2000000000064,25.42067592241581,-0.7342765802322245,-0.07594166647556255
481.60000000000645,25.4649213709952,-0.7405694708628182,-0.07662354998578369
483.0000000000065,25.509673280289423,-0.7457359299484941,-0.07661927914673683
484.40000000000646,25.554513045472113,-0.7491767825253076,-0.07630259325942745
485.8000000000065,25.599006658659874,-0.7580786426407145,-0.07696152470852935
487.2000000000065,25.64375366816856,-0.7641683958134313,-0.07694456304590958
488.60000000000656,25.688551229849697,-0.7697638214969352,-0.0759626325767
490.0000000000066,25.733107103377346,-0.7755446974345925,-0.07599327689895219
491.40000000000657,25.778012224808542,-0.7799334046597781,-0.07696228581745945
492.8000000000066,25.82270868382642,-0.7846435013030748,-0.07829130202885004
494.20000000000664,25.867629791514897,-0.7912561980691277,-0.07826984530428849
495.6000000000066,25.91213889097965,-0.7952941084361506,-0.07827907189471794
497.00000000000665,25.95731775476868,-0.7993829087617833,-0.0786019300325207
498.4000000000067,26.002072484185234,-0.8044131850090499,-0.0785998888880064
499.8000000000067,26.046478766418115,-0.8080501291814272,-0.07859987909740473
501.20000000000675,26.091370035642882,-0.8152525912063214,-0.07860016184333407
502.60000000000673,26.136177876023787,-0.81869156819072,-0.07883427209090943
504.00000000000676,26.18114776574536,-0.8225869852089234,-0.0789176317021778
505.4000000000068,26.225940433198787,-0.8265537169764792,-0.08022376793483055
506.8000000000068,26.270881562447034,-0.8305632367406028,-0.07914463903748814
508.2000000000068,26.315774472803966,-0.8353169600259819,-0.07893000304114306
509.60000000000684,26.360917596735884,-0.8405665082423903,-0.07893634660600979
511.0000000000069,26.404729019832843,-0.8446703681611232,-0.0795736416691426
512.4000000000069,26.45046760403191,-0.8488594628733948,-0.0795899061641121
513.8000000000069,26.495473181979058,-0.8517175958338286,-0.07959629267036394
515.2000000000069,26.540479142292362,-0.8570665752098992,-0.08153418196738249
516.600000000007,26.58562338077889,-0.8600682317258146,-0.08271618915397472
518.0000000000069,26.63084533813282,-0.8647871963995386,-0.08288011222437541
519.4000000000069,26.675952667837095,-0.8703237746423086,-0.08288006679283377
520.800000000007,26.721155316432434,-0.8728493001032083,-0.08326400970448367
522.2000000000071,26.765992863012116,-0.8782934909860426,-0.08354009289622866
523.6000000000071,26.811404623783133,-0.8840648467359233,-0.08353974075646597
525.000000000007,26.85659572728592,-0.8873426637344605,-0.08344792687276126
526.4000000000071,26.902056717229136,-0.8913639986985961,-0.0835026868149491
527.8000000000071,26.9471238129394,-0.8944017554562332,-0.08342488945675175
529.2000000000071,26.992508196168313,-0.8986534528279434,-0.08221987499618999
530.6000000000072,27.03751627776012,-0.9035492074464235,-0.08222009485268478
532.0000000000072,27.08247611529168,-0.9094194707672667,-0.08221974055999048
533.4000000000071,27.127760281605113,-0.912848739488889,-0.08343819764728355
534.8000000000072,27.17281529541047,-0.917247583824642,-0.08354049628934179
536.2000000000072,27.218052607977608,-0.9211030654299371,-0.0835400052095685
537.6000000000072,27.263380637631137,-0.9243615632965225,-0.08353478755271881
539.0000000000073,27.308946278333845,-0.9277354032174725,-0.08485889178101891
540.4000000000073,27.35431475782645,-0.9362075029728255,-0.08485411043494606
541.8000000000073,27.399271612088267,-0.9383463960558572,-0.08618017169176717
543.2000000000073,27.445067067390966,-0.9432887176251312,-0.08617820445323332
544.6000000000073,27.49032752210949,-0.9476616283757359,-0.08750591495271998
546.0000000000074,27.535912335166707,-0.95261273215625,-0.08749980984852312
547.4000000000074,27.581401687592663,-0.9588320519405489,-0.08749981423336095
548.8000000000075,27.62670672028664,-0.9624952718838667,-0.08750072081587845
550.2000000000074,27.671410791804576,-0.9684786562233396,-0.0883422828468925
551.6000000000074,27.71751127991039,-0.9730112552279285,-0.08879131806683738
553.0000000000075,27.762756241112175,-0.9788914033072759,-0.09033723750824096
554.4000000000075,27.80820348469927,-0.9835343936825085,-0.0887864201813664
555.8000000000075,27.853695391925662,-0.9878848832107711,-0.08747640277222812
557.2000000000075,27.899232744501063,-0.993624194284497,-0.08881012196230031
558.6000000000075,27.944538458073577,-0.9978960202148768,-0.08880987262652207
560.0000000000075,27.99051647753975,-1.0034475943574923,-0.08881594979555496
561.4000000000076,28.035891759969306,-1.0097870647249505,-0.09013497783143576
562.8000000000076,28.081518727723594,-1.0156652306265874,-0.0901301825759444
564.2000000000077,28.12699890169067,-1.0230681938754425,-0.09012999672894617
565.6000000000076,28.173308844909123,-1.0285222902165958,-0.0903312340407969
567.0000000000076,28.21891651564811,-1.0358094659767014,-0.09080488837538603
568.4000000000077,28.264413802030962,-1.0424561250569806,-0.09168246255502277
569.8000000000077,28.310144808133096,-1.050009279589398,-0.0917946221266015
571.2000000000078,28.35592109568529,-1.063456981640874,-0.09276432837127357
572.6000000000078,28.401508241112793,-1.0833400731998664,-0.09413825225352479
574.0000000000077,28.446908546595182,-1.1029695515943976,-0.0947361226388086
575.4000000000078,28.49283618268833,-1.0999724574420773,-0.09615417896295853
576.8000000000078,28.538109570381053,-1.0918100634410832,-0.09540233853046542
578.2000000000078,28.58443926764018,-1.090386946608869,-0.09605100707559044
579.6000000000079,28.6299530974255,-1.087805978842316,-0.09606022426560967
581.0000000000078,28.675713202277684,-1.085558605891957,-0.09669103466923223
582.4000000000078,28.72063740649029,-1.0867187571275934,-0.09737037834205609
583.8000000000079,28.767479117268287,-1.0897314609167281,-0.09788368226127941
585.2000000000079,28.813187716829507,-1.0927478802625528,-0.0980367375202813
586.600000000008,28.859071426015426,-1.096446211511304,-0.09803149888592522
588.000000000008,28.904853902595633,-1.1002018471924977,-0.09934822165449608
589.4000000000079,28.950589034763848,-1.1042646585221862,-0.099349945861404
590.800000000008,28.996143990572214,-1.1097884232530537,-0.09934425998500496
592.200000000008,29.042792118312992,-1.1150711835293785,-0.10067422176586494
593.6000000000081,29.08862440648907,-1.1230754699724206,-0.10147731714002095
595.0000000000081,29.134523186465707,-1.1274066006780041,-0.10132053656436701
596.400000000008,29.18061131223886,-1.1371646907037487,-0.10209760041685367
597.8000000000081,29.22662173690677,-1.143494975290522,-0.10263618404857278
599.2000000000081,29.272726766839245,-1.1477478540537345,-0.10401478032198996
600.6000000000081,29.318712336177526,-1.156429276045359,-0.1039458694925921
602.0000000000082,29.36505968264245,-1.1646972932503226,-0.10527441279327254
603.4000000000082,29.410634613401,-1.1713305143372512,-0.10635918250303833
604.8000000000081,29.457644412999148,-1.179421893954516,-0.10743429207783883
606.2000000000082,29.50363060235685,-1.1844142534088784,-0.10790597493606446
607.6000000000082,29.55000229991602,-1.1906399216872476,-0.10923310258879981
609.0000000000083,29.59612208908792,-1.1980731349449845,-0.10920629405032978
610.4000000000083,29.64216483098125,-1.205887037280255,-0.10961655063154963
611.8000000000083,29.688412530220084,-1.210739339598227,-0.10921703648771963
613.2000000000083,29.734824569751254,-1.218623827236095,-0.11054617875330841
614.6000000000083,29.781346548784523,-1.2245501966604362,-0.11058303284779925
616.0000000000084,29.82713862649631,-1.2314440936148914,-0.11321748112812369
617.4000000000084,29.87389963709666,-1.2375009525427445,-0.11323958459838135
618.8000000000084,29.919761121583647,-1.2435651181532665,-0.11388774846425642
620.2000000000085,29.96635731021671,-1.25194174015992,-0.11448081062406112
621.6000000000084,30.012444387600908,-1.2591715495989761,-0.11583481089364733
623.0000000000084,30.058940080058957,-1.2660612005748433,-0.11713010424302883
624.4000000000085,30.10520009828499,-1.2723017324921557,-0.1170434655537802
625.8000000000085,30.151758901705904,-1.2833718795316797,-0.11846641318852935
627.2000000000085,30.198263758761293,-1.2889196974504293,-0.11977693717640969
628.6000000000085,30.244294591838347,-1.2971247932283385,-0.120969908037873
630.0000000000085,30.29065917691111,-1.3039639056561625,-0.1225702725501212
631.4000000000086,30.336815543255234,-1.311817920142987,-0.123819255803582
632.8000000000086,30.383438603466345,-1.3229478324326747,-0.12270805320580935
634.2000000000086,30.42997530010998,-1.3304799979394026,-0.12539708974010688
635.6000000000087,30.476459407145484,-1.3393060879509786,-0.12673740643380826
637.0000000000086,30.52278070413384,-1.3487575597109662,-0.12811357045427485
638.4000000000087,30.569300173854156,-1.3556273716500624,-0.1294240384839065
639.8000000000087,30.615878777976818,-1.3670819600509094,-0.12941694457942488
641.2000000000087,30.662199370138946,-1.3748675881897094,-0.1307464473298987
642.6000000000088,30.708270635447676,-1.3839752989026362,-0.1320072564103496
644.0000000000088,30.755429094678902,-1.396606056344996,-0.13172949045819804
645.4000000000087,30.801829256688116,-1.4085339036485418,-0.13322554202040582
646.8000000000088,30.848499536874424,-1.4221713510578262,-0.13467599450827228
648.2000000000088,30.894383190404618,-1.437871636788809,-0.13596009577876256
649.6000000000088,30.941508964635577,-1.453091992831711,-0.13601886110392547
651.0000000000089,30.98781001412353,-1.471546972922944,-0.1369892294049504
652.4000000000088,31.034326714552105,-1.484341789278414,-0.13773603676445223
653.8000000000089,31.081079736066485,-1.5043560985554048,-0.1407109912285618
655.2000000000089,31.127566973492073,-1.5234171045477056,-0.14234055645568677
656.6000000000089,31.174072977835156,-1.540460898745882,-0.1450269090603551
658.000000000009,31.220693580512542,-1.5621917138045172,-0.14645520864891637
659.400000000009,31.267380420694455,-1.5887091405382519,-0.1478217307128995
660.800000000009,31.313835677238096,-1.615865507721639,-0.14954833634795062
662.200000000009,31.360640420575162,-1.643382649526861,-0.15140066952427755
663.600000000009,31.407372110496226,-1.6712983917179587,-0.15335945004404739
665.0000000000091,31.454000530194314,-1.7012626849758619,-0.15510669070464544
666.4000000000091,31.50088678039562,-1.7356922392283454,-0.15660509071564643
667.800000000009,31.547772981936667,-1.7712881991451823,-0.15956160378271456
669.2000000000091,31.594282156644645,-1.8041979485516753,-0.16033566123921084
670.6000000000091,31.641003211146238,-1.838234868417403,-0.16272887263578628
672.0000000000091,31.687884813550948,-1.8751206593750507,-0.16746287204171484
673.4000000000092,31.734800111837004,-1.9149116583349794,-0.1706144992030021
674.8000000000092,31.781749884780815,-1.9585327862105488,-0.17267528624478956
676.2000000000093,31.82873097559929,-2.001572487299369,-0.17499838318492067
677.6000000000092,31.875946289798673,-2.0412753430063013,-0.17694167102028047
679.0000000000092,31.922533824187592,-2.0883298920987143,-0.180934113225252
680.4000000000093,31.969634481806953,-2.136072996585551,-0.184591887331921
681.8000000000093,32.016702702202025,-2.183080118440291,-0.18777356244974763
683.2000000000094,32.0637684524272,-2.2336910093163036,-0.19222400890073033
684.6000000000093,32.1107654800532,-2.286353728109253,-0.19658105538085913
686.0000000000093,32.15755208655943,-2.3376184897584027,-0.2000372663552521
687.4000000000094,32.204884503436844,-2.3961758781790397,-0.203626884799621
688.8000000000094,32.25195003145484,-2.4578489641666783,-0.2074133608839306
690.2000000000094,32.29907110608944,-2.5147028487248053,-0.21075951848295738
691.6000000000095,32.34644784953756,-2.577761387539755,-0.21717235054147688
693.0000000000094,32.39375124824722,-2.6441337857017513,-0.22218552085945564
694.4000000000094,32.44112799617127,-2.71193326286603,-0.22709978545809228
695.8000000000095,32.488639573092655,-2.782772485894796,-0.23146279762674915
697.2000000000095,32.53567495943518,-2.8503806746328775,-0.23582158261679576
698.6000000000096,32.58316983148749,-2.9256308502841475,-0.24247133319302883
700.0000000000095,32.630575881856075,-2.9989046077127433,-0.24846621236857036
701.4000000000095,32.678026672904075,-3.0806556353656025,-0.2547324723708648
702.8000000000096,32.725379926612256,-3.1588076799404363,-0.2628510696329731
704.2000000000096,32.77279476971714,-3.2415569155489483,-0.2694903884287938
705.6000000000097,32.82053403809979,-3.326068979797446,-0.27650003107907173
707.0000000000097,32.867856304592486,-3.405621011600043,-0.2850798381045303
708.4000000000096,32.915479931692225,-3.496443320707383,-0.29097187227704113
709.8000000000097,32.962998841352416,-3.5878272869985333,-0.29799651117124704
711.2000000000097,33.010557003828374,-3.6794277777331743,-0.30617980168825865
712.6000000000097,33.05811085453398,-3.7742903286345864,-0.31477886124780907
714.0000000000098,33.10617409368094,-3.8743257904962087,-0.32361942264635024
715.4000000000098,33.15335884909265,-3.97120525638645,-0.3335927537460375
716.8000000000097,33.20116430331936,-4.071878630580795,-0.344419846742273
718.2000000000098,33.248764404233086,-4.17213923914427,-0.3567059283431857
719.6000000000098,33.29673646803588,-4.275909957944257,-0.3682305221610047
721.0000000000099,33.344365959363074,-4.382491115428678,-0.3784670560013499
722.4000000000099,33.392190871074455,-4.488107420370065,-0.3892485240245134
723.8000000000098,33.44009685136334,-4.596023558362092,-0.39936699750587845
725.2000000000099,33.48793368516943,-4.705023916510831,-0.4106803491780089
726.6000000000099,33.535193504905806,-4.815706811651729,-0.4217156633254553
728.00000000001,33.58341552352655,-4.93096386437455,-0.4348133097394258
729.40000000001,33.63114874800089,-5.042610789034982,-0.44738543586998647
730.80000000001,33.67881997098026,-5.153507887838368,-0.4607376037296591
732.20000000001,33.72691770437265,-5.268445262050647,-0.4761470394228762
733.60000000001,33.774820297813534,-5.3825948595127295,-0.48880977914090407
735.00000000001,33.82252648049759,-5.494136642976672,-0.5025905381311992
736.4000000000101,33.87050893236761,-5.608233797174021,-0.5183716875677815
737.8000000000101,33.91816069388338,-5.719373195174244,-0.5335965998128245
739.20000000001,33.9658512342398,-5.832099849426664,-0.5496974889886759
740.6000000000101,34.01379775973028,-5.946458035630304,-0.5639527421957884
742.0000000000101,34.06158063223614,-6.055907370592848,-0.5791716956327368
743.4000000000102,34.109136136931475,-6.167307500288847,-0.5955479781245963
744.8000000000102,34.15748232156915,-6.278485476052886,-0.6133458168813286
746.2000000000102,34.2050006223031,-6.388674506840701,-0.6306351393691356
747.6000000000103,34.25276530963845,-6.4992568146841085,-0.647070622979844
749.0000000000102,34.300615227675664,-6.609732805026527,-0.6645451016523332
750.4000000000103,34.3481957328886,-6.719966648606388,-0.6857175403969737
751.8000000000103,34.39632155066711,-6.83108480707395,-0.7051155715804636
753.2000000000103,34.44386948259805,-6.943886503483669,-0.7246372324183898
754.6000000000104,34.491959770239006,-7.057377661475608,-0.7438555714016304
756.0000000000103,34.540047553295274,-7.170885167598774,-0.7630911253646167
757.4000000000103,34.58776059223516,-7.290662808446192,-0.7850550393370788
758.8000000000104,34.63523428285647,-7.40941475330565,-0.8080566513761824
760.2000000000104,34.683861878953216,-7.534458668056887,-0.8314101019942126
761.6000000000104,34.732060075778605,-7.6664745013452364,-0.8539827487499525
763.0000000000105,34.779772494934875,-7.7991549953469415,-0.8768749203612645
764.4000000000104,34.82796422001147,-7.935792799565503,-0.8991731071061433
765.8000000000105,34.876234300026724,-8.075245894627605,-0.9236122126999464
767.2000000000105,34.92450776799066,-8.219684781364668,-0.9492415789098603
768.6000000000105,34.9727249428393,-8.37118247528189,-0.9726317075861877
770.0000000000106,35.02105857150088,-8.521137226340127,-0.9975741498921198
771.4000000000106,35.068747326651206,-8.668089700416637,-1.0230467624732502
772.8000000000106,35.11741412678619,-8.81678831604122,-1.0501720017502367
774.2000000000106,35.16579207672932,-8.959947050815272,-1.0765094752684221
775.6000000000106,35.213989549966506,-9.095788899318322,-1.1029641419617304
777.0000000000107,35.26205769131613,-9.222860913567704,-1.1306655664540881
778.4000000000107,35.309897303267086,-9.342108261923347,-1.1579598297402498
779.8000000000106,35.35790014802954,-9.458891197074358,-1.1855788850085336
781.2000000000107,35.405733612426225,-9.564289587781456,-1.2148340567625833
782.6000000000107,35.45329141035892,-9.654482945185903,-1.241188066500674
784.0000000000107,35.501000318732984,-9.717871065868577,-1.2669015399831798
785.4000000000108,35.548359830084976,-9.725951055517564,-1.2944379682054787
786.8000000000108,35.594547223619685,-9.634499534987784,-1.320909659144538
788.2000000000108,35.63981802407446,-9.417919238828203,-1.3470339567455851
789.6000000000108,35.68392634900048,-9.0299044351034,-1.370823477489345
791.0000000000108,35.726234017465146,-8.439304299409908,-1.3933703899291046
792.4000000000109,35.76686879264406,-7.631213944911425,-1.411988904982839
793.8000000000109,35.80574720110777,-6.613834367445727,-1.427648163829386
795.200000000011,35.84377097474807,-5.469675364748575,-1.442089143793896
796.6000000000109,35.88197699878629,-4.378962229956993,-1.4523168961575434
798.0000000000109,35.9218319680359,-3.4702214217784433,-1.4601534048268898
799.400000000011,35.96304617331485,-2.772716875725503,-1.46552337084941
800.800000000011,36.00504954030875,-2.2673900024773377,-1.4681887181480429
802.200000000011,36.04941461355955,-1.8956371988547278,-1.471315676500716
803.600000000011,36.09427988279982,-1.6562566347747831,-1.472943117895964
805.000000000011,36.13970513174503,-1.4955943226206851,-1.4738393525386622
806.400000000011,36.18582481153522,-1.3940337024991365,-1.4741953535793564
807.8000000000111,36.23197426118608,-1.3288073838059369,-1.4742940106760631
809.2000000000111,36.27846060904659,-1.289802741746414,-1.4754910313529317
810.6000000000112,36.32567357971081,-1.265172714640913,-1.4767760793954827
812.0000000000111,36.372516975371326,-1.2563034844198797,-1.4767290517672635
813.4000000000111,36.41986083534539,-1.2541415587961064,-1.4758259683679436
814.8000000000112,36.46676321737394,-1.2532463324345222,-1.476439516473251
816.2000000000112,36.513583542832265,-1.2568648436673346,-1.475810350877711
817.6000000000113,36.560932223073216,-1.260243573143788,-1.4758081498905797
819.0000000000113,36.608094379342944,-1.263052754284583,-1.4745349606611677
820.4000000000112,36.65526314692239,-1.2658118583337719,-1.4751642191221022
821.8000000000113,36.70247149826781,-1.2686135585778129,-1.4751600307089774
823.2000000000113,36.7496838330892,-1.2727448640207566,-1.4751600380466026
824.6000000000113,36.79674701724141,-1.276281787624629,-1.4751601265139245
826.0000000000114,36.844073003744704,-1.277719733733892,-1.4750940073455965
827.4000000000113,36.89145482750346,-1.283300858629901,-1.4758443637237253
828.8000000000113,36.93850350747857,-1.2854540569906,-1.478640996751667
830.2000000000114,36.98599575694187,-1.2907558297474955,-1.4786220045154104
831.6000000000114,37.03322099549039,-1.2925775256496674,-1.4783384596657507
833.0000000000115,37.080743447261575,-1.2951895061240417,-1.4772415186814611
834.4000000000115,37.12787633781827,-1.2987193941302029,-1.4772398536363691
835.8000000000114,37.17535438989896,-1.3043559981054087,-1.4772398548784693
837.2000000000115,37.22264116439197,-1.305510922235075,-1.477228386160374
838.6000000000115,37.27020933486814,-1.3132538787851247,-1.4759331442241614
840.0000000000116,37.31737013293622,-1.3194448880338205,-1.4759249590034127
841.4000000000116,37.364887594968266,-1.3221783898880823,-1.4745890145271923
842.8000000000116,37.412132872044104,-1.3252143741404347,-1.475967132972221
844.2000000000116,37.45964702257336,-1.3307840925575969,-1.4759198340412558
845.6000000000116,37.50714233429006,-1.3339137886808263,-1.4759214890194805
847.0000000000116,37.55454736409825,-1.3396695473213553,-1.4745974784996823
848.4000000000117,37.602397796316616,-1.3419290567922617,-1.475842322866035
849.8000000000117,37.64956210736353,-1.34698547530101,-1.4773498489604386
851.2000000000116,37.697161179317234,-1.354716581362696,-1.4762040542834054
852.6000000000117,37.744714090532426,-1.360583597163828,-1.4762168520208272
854.0000000000117,37.79219235490306,-1.3667791281024229,-1.4775730806985607
855.4000000000118,37.83982838066421,-1.3698562740790987,-1.477558965254937
856.8000000000118,37.887103432441585,-1.3739782382611212,-1.4788894129114905
858.2000000000118,37.9345816469029,-1.3809674100843476,-1.4788901440920341
859.6000000000118,37.982307851842506,-1.3841066280151155,-1.478890140495344
861.0000000000118,38.02961652199632,-1.3888212193863583,-1.4788902662157537
862.4000000000119,38.07737008236774,-1.3908170344038697,-1.480245731111717
863.8000000000119,38.125004514854496,-1.3960432007384787,-1.481277987117536
865.2000000000119,38.172526618377915,-1.3994101493031246,-1.481198892468902
866.600000000012,38.219952151516324,-1.4060351690451174,-1.4802895322684404
868.0000000000119,38.267631108640465,-1.411283404093214,-1.4802099805175253
869.4000000000119,38.314900011026644,-1.4138045512776067,-1.4801917039730994
870.800000000012,38.36247916224305,-1.4187368970610816,-1.4798711056455627
872.200000000012,38.4093032604987,-1.4226940800985102,-1.4785703686421625
873.600000000012,38.45738886737332,-1.4296650514841844,-1.4798648599581394
875.000000000012,38.504561800011274,-1.4326365021387526,-1.4798701324231431
876.400000000012,38.552257970720596,-1.4383015704011963,-1.4798711103434758
877.8000000000121,38.599440470571814,-1.441884738991492,-1.481185681635361
879.2000000000121,38.64714103749637,-1.4466914051855546,-1.4824968741917441
880.6000000000121,38.6943274575185,-1.4528273249306403,-1.4825235527694502
882.0000000000122,38.74145154656744,-1.4566038410312023,-1.4838088639821647
883.4000000000121,38.7892049703246,-1.4578644705175121,-1.4838168773575866
884.8000000000122,38.83690834079243,-1.4645301430300328,-1.4853140563289173
886.2000000000122,38.88391730651967,-1.4713964300162636,-1.48525717899861
887.6000000000122,38.93182238804151,-1.47420372202565,-1.483888463789893
889.0000000000123,38.979203388669355,-1.4776077149086875,-1.4824992947184072
890.4000000000123,39.02654461311482,-1.4805143862364862,-1.4833945450461186
891.8000000000122,39.074210681509804,-1.4846405377662097,-1.484024472829962
892.0000000000123,39.080791450735035,-1.4845713925080724,-1.4845649316215206