File: 01_Data/Concrete_Block/STA/N2/30K_min/Concrete_Block_STA_N2_30KData_230830_R2.csv
##Temp./Â°C,Time/min,DSC/(mW/mg),Mass loss/mg
29.0,10.634809190176131,-0.03771822491285172,0.008413402118520708
30.40000000000002,10.828574169247029,-0.03667667908826871,0.008549197867864677
31.80000000000004,10.960462162000606,-0.03582000420009531,0.009165351887418183
33.20000000000006,11.067084809524673,-0.03508027451487199,0.01027847986352981
34.60000000000008,11.159050817203683,-0.03437538226021885,0.009169095333476207
36.0000000000001,11.242816896816972,-0.033764834526532644,0.01255368541259827
37.40000000000012,11.318907709167416,-0.033168959020906504,0.009140484430929519
38.80000000000014,11.391203357826857,-0.03258782861116052,0.009637157882963265
40.20000000000016,11.459415302616486,-0.032046708304281815,0.009021465022271968
41.60000000000018,11.524353384358799,-0.03156605079581247,0.009123978628821305
43.0000000000002,11.587371232282136,-0.031081687727848722,0.008597333727976775
44.40000000000022,11.648863490954003,-0.030637181987388136,0.008300365255649922
45.80000000000024,11.707714449056894,-0.030177986617027575,0.008502820671282052
47.20000000000026,11.765875795961357,-0.029791899873699998,0.007926471010279101
48.60000000000028,11.82310431326242,-0.029409845592230678,0.007016748183929167
50.0000000000003,11.87932561528824,-0.029050069008207627,0.007044449828754296
51.40000000000032,11.933496327193307,-0.028725879756333936,0.00731267810317604
52.80000000000034,11.98826384747238,-0.028431529231879214,0.006344792724121362
54.20000000000036,12.041796326115518,-0.028133683996227947,0.0060422562574160565
55.60000000000038,12.09479583901339,-0.02787273124413916,0.006220095528249203
57.0000000000004,12.147377869830914,-0.02762563716613419,0.0049439196005778285
58.40000000000042,12.199058514875302,-0.027379427544297945,0.006507696505622107
59.80000000000044,12.250298394888272,-0.027177242742637997,0.006284917156932579
61.20000000000046,12.301292149067464,-0.026952978333756268,0.005017718614254818
62.60000000000048,12.351888871289187,-0.026754235791817568,0.004630909747959322
64.0000000000005,12.402216709163815,-0.02651590691713043,0.004622185769477483
65.40000000000052,12.451946655680686,-0.026316674326316944,0.004818516415667773
66.80000000000054,12.502044922603284,-0.026078715030155606,0.0034386140561082357
68.20000000000056,12.551863132822994,-0.02584268997703757,0.003371519686055535
69.60000000000058,12.600463608820359,-0.025650271855077417,0.0039017977018431793
71.0000000000006,12.650428394347855,-0.02540334260533852,0.0026316495964806563
72.40000000000062,12.699103365664532,-0.025214219512787114,0.0005331059032869234
73.80000000000064,12.748449583575928,-0.02500608025826763,0.000362293564819538
75.20000000000066,12.796895229062073,-0.02479093410800307,0.0002522791043588768
76.60000000000068,12.846265607033976,-0.024596221386004664,0.0004226451528097641
78.0000000000007,12.894521744919118,-0.024413563490964206,0.0012156481846261613
79.40000000000072,12.94309218918439,-0.02422965888647817,0.00033341911074558084
80.80000000000074,12.991332361405755,-0.02402919743206269,0.00041112948309773856
82.20000000000076,13.03971959043506,-0.023846422750204696,0.0003876298177658555
83.60000000000078,13.08793069511581,-0.02368453362230079,0.00031415603874052067
85.0000000000008,13.135734336578949,-0.023473099451754433,-0.001012699289702823
86.40000000000082,13.183353976771633,-0.023311927564974903,-0.0018615548433160711
87.80000000000084,13.231655016122087,-0.023148110551731195,-0.00238800715331422
89.20000000000086,13.277981835733105,-0.022960071211842938,-0.002320242959655161
90.60000000000088,13.325853631700118,-0.022777760802656286,-0.00392397251189891
92.0000000000009,13.372979008897312,-0.022617051269769508,-0.003949628372652114
93.40000000000092,13.420429137400854,-0.02245222437286827,-0.002666191744452817
94.80000000000094,13.467450082730322,-0.022244708005896213,-0.002636570010537298
96.20000000000095,13.514143542021843,-0.02208778131343061,-0.004033697599908237
97.60000000000097,13.560648616430624,-0.021898550453996902,-0.0036719951221186875
99.000000000001,13.607037064086425,-0.02172625527891654,-0.00412304333590896
100.40000000000101,13.65390531670917,-0.02154497529278279,-0.0065781884293585335
101.80000000000103,13.700439815236464,-0.021344066558442006,-0.0065876062219274445
103.20000000000105,13.747227623171206,-0.0211638444609758,-0.006596858832637054
104.60000000000107,13.793035130563734,-0.020964139921761635,-0.007910559451204335
106.0000000000011,13.839268323426587,-0.020799990664957444,-0.006575864892312211
107.40000000000111,13.885779420674256,-0.02063294399572758,-0.006580640365200452
108.80000000000113,13.93176380273879,-0.020439146125673307,-0.007739904652282803
110.20000000000115,13.978056837125223,-0.020279191554772688,-0.007901693465811377
111.60000000000117,14.023750592375821,-0.020102635795222937,-0.007908492729370664
113.0000000000012,14.069945707753314,-0.019959659529695944,-0.009200256366170834
114.40000000000121,14.116099082124286,-0.019765308436382346,-0.009211435834600934
115.80000000000123,14.161983512103482,-0.019614015695199348,-0.009209255613683354
117.20000000000125,14.207569347194296,-0.019455846364103375,-0.010500381543266712
118.60000000000127,14.252405174867649,-0.019290997849978012,-0.011859478270054069
120.0000000000013,14.29894355151467,-0.01914127309881937,-0.011857644605555606
121.40000000000131,14.344836336783057,-0.018927175245929594,-0.011293833825561705
122.80000000000133,14.390310645357644,-0.018748437419237686,-0.010868692787425971
124.20000000000135,14.435534698961055,-0.01857476169450418,-0.01086901087313663
125.60000000000137,14.481257070949813,-0.0183679796732294,-0.010879944514982753
127.00000000000139,14.526144220837953,-0.018193905968493518,-0.013360002791955594
128.4000000000014,14.571150200969635,-0.017977009463542193,-0.013515343066558216
129.80000000000143,14.615975031040076,-0.01777142450376724,-0.013515204306287387
131.20000000000147,14.66071745773688,-0.01758810517287116,-0.01353741191863378
132.60000000000147,14.706058700161163,-0.017386785755657504,-0.014833151523077959
134.00000000000148,14.750531558705543,-0.017190709042935855,-0.014835146184054793
135.4000000000015,14.795072942797312,-0.016980046639545183,-0.014836214812675053
136.80000000000155,14.83938886290171,-0.016788381720890113,-0.016157836201870168
138.20000000000155,14.88333173650477,-0.016618286150109796,-0.016168190798282467
139.60000000000156,14.927678168904265,-0.01641829916525531,-0.014842070744890634
141.0000000000016,14.972952295067564,-0.01624657929121458,-0.014835118151751203
142.40000000000163,15.01662088062788,-0.016070288769754124,-0.014831303528239914
143.80000000000163,15.060993614848286,-0.015893089054923898,-0.015504470820673077
145.20000000000164,15.105011488333862,-0.015722051581767368,-0.015806700589479306
146.60000000000167,15.148797300419552,-0.01554126295545332,-0.01681154387634365
148.0000000000017,15.192792919723534,-0.015400271281877364,-0.016811882552872248
149.4000000000017,15.236848128814101,-0.015231310143614453,-0.017498741895650483
150.80000000000172,15.280829755311142,-0.015069575626134252,-0.018316762097214223
152.20000000000175,15.324805456118174,-0.014901540118225576,-0.018901091410270965
153.60000000000178,15.368535908972522,-0.014766003257872026,-0.01890554115337295
155.0000000000018,15.41206856930992,-0.014572808093416167,-0.01791260161130026
156.4000000000018,15.4556245449197,-0.014400598882507495,-0.0179112260163663
157.80000000000183,15.499295426185627,-0.01428117851588174,-0.017911311805931973
159.20000000000186,15.543329619427109,-0.014132420963083318,-0.0179113035613625
160.60000000000187,15.586578809440585,-0.013973468611497104,-0.017902914175834894
162.00000000000188,15.63010715969839,-0.013830714347035039,-0.017584545752526992
163.4000000000019,15.673720940912023,-0.013689734449680194,-0.017581302904801532
164.80000000000194,15.717400356799352,-0.013520161945913529,-0.017581309743775364
166.20000000000195,15.760652617795111,-0.013381696245202237,-0.017581124381479185
167.60000000000196,15.80405597768754,-0.013258023414522051,-0.019109009257078924
169.000000000002,15.847658886953125,-0.013086253973696817,-0.02034201678080194
170.40000000000202,15.890270017655991,-0.012960261832491793,-0.019686360594732832
171.80000000000203,15.934343221772243,-0.01280975040103298,-0.020249786506212786
173.20000000000203,15.977480956656802,-0.012661348903929216,-0.018884836537608862
174.60000000000207,16.02068719241074,-0.012548959612695892,-0.018881824095501543
176.0000000000021,16.063819527843982,-0.012396900213170576,-0.02108922342972619
177.4000000000021,16.107407704847652,-0.012282958330831706,-0.021529099627912274
178.80000000000211,16.15050165733003,-0.012119888118248151,-0.021529521579850552
180.20000000000215,16.192689382768894,-0.012010491975517946,-0.021529520010204806
181.60000000000218,16.23676475336128,-0.011880027688626208,-0.021529519999518243
183.0000000000022,16.2795104980865,-0.011756041743873452,-0.021529519937217856
184.4000000000022,16.322356430391338,-0.011637124054615556,-0.02152954807084484
185.80000000000223,16.365109074416,-0.011492070999043452,-0.021541657063352204
187.20000000000226,16.408058572943265,-0.011368373412697875,-0.022874548220784163
188.60000000000227,16.450998254896465,-0.01126967124591832,-0.022888166954629696
190.00000000000227,16.4935641475195,-0.011149498431625092,-0.021823954994317774
191.4000000000023,16.53664379467324,-0.011026944442833173,-0.020535356085076728
192.80000000000234,16.57891940616114,-0.010930850866428773,-0.02054088352508643
194.20000000000235,16.62138353366162,-0.010845126591724858,-0.02063394914105743
195.60000000000235,16.664457815699933,-0.010739592751826506,-0.02184568302524781
197.0000000000024,16.707025743813432,-0.010622214096580821,-0.021426377444527134
198.40000000000242,16.7499937325724,-0.010539896975095645,-0.021266520127539934
199.80000000000243,16.79239968037391,-0.010453640722093035,-0.023247885541934465
201.20000000000243,16.835027071774817,-0.01036307452277883,-0.023443938006096232
202.60000000000247,16.877878618079922,-0.010274300373057902,-0.024467906205359213
204.0000000000025,16.920637012820492,-0.01016863412840542,-0.02316906760356119
205.4000000000025,16.962906479054833,-0.010068975701951682,-0.023168372873527687
206.8000000000025,17.00559982080914,-0.009980933411363625,-0.02280293282558432
208.20000000000255,17.047909628292466,-0.009920370684124376,-0.021842120124517805
209.60000000000258,17.0901108963316,-0.009838276229766666,-0.02184297826107695
211.0000000000026,17.13302533392767,-0.00974184437185499,-0.02184296196600144
212.4000000000026,17.175234399645895,-0.009652650577458304,-0.021839235186973838
213.80000000000263,17.218169716643807,-0.009582607009164633,-0.023133949697751177
215.20000000000266,17.260526682878396,-0.00951433030340131,-0.023169291212212784
216.60000000000267,17.303115262412554,-0.00943792807446817,-0.023162229484455565
218.00000000000267,17.34520391267278,-0.009346038225223355,-0.024476991189345654
219.4000000000027,17.388248080848346,-0.009308328632718141,-0.024495272941095436
220.80000000000274,17.43049600028842,-0.009207644144887641,-0.0244952961127467
222.20000000000275,17.47302315648859,-0.009158832414431961,-0.02449529589677013
223.60000000000275,17.515073770925884,-0.009077405261769306,-0.02449527226926307
225.00000000000279,17.557586879447936,-0.009018238136434816,-0.024492010000841447
226.40000000000282,17.600063510073568,-0.00898728871361259,-0.025143357268348154
227.80000000000283,17.642454694632583,-0.008929196868425627,-0.026464329537930098
229.20000000000283,17.685056832580756,-0.008885079029957976,-0.02646630814936657
230.60000000000286,17.727353193417798,-0.008829130746722029,-0.026466319952021422
232.0000000000029,17.769877317981493,-0.008804810603828258,-0.0264663196181516
233.4000000000029,17.811982785351773,-0.008762867851828017,-0.02646618436034487
234.8000000000029,17.854351940996583,-0.008684683370764546,-0.02643657695392676
236.20000000000294,17.89655388189478,-0.008660542175962894,-0.02580958809031131
237.60000000000298,17.938840195512903,-0.008596461018926757,-0.025797364705056225
239.00000000000298,17.981210854131163,-0.008531735375431027,-0.025797124063103638
240.400000000003,18.02359967968535,-0.00847339317044019,-0.02570032139206546
241.80000000000302,18.065882859746225,-0.008425503663829341,-0.027041829151130514
243.20000000000306,18.10841694236311,-0.008380005305792547,-0.023855592867391806
244.60000000000306,18.150329713930148,-0.008288168599928144,-0.02561285368247468
246.00000000000307,18.192819357014226,-0.008246234303589105,-0.02710402054051997
247.4000000000031,18.23468832739484,-0.008177320928209558,-0.027123441110887825
248.80000000000314,18.277677926767545,-0.008141396092255533,-0.02712574417753899
250.20000000000314,18.31966278678863,-0.00807280375338841,-0.025683338767407804
251.60000000000315,18.361422070601087,-0.008021910630222248,-0.026250270200961268
253.00000000000318,18.404228486160225,-0.007981879856007186,-0.027132116614552615
254.40000000000322,18.446617022075642,-0.00792597942916036,-0.02797118598510906
255.80000000000322,18.488704536257373,-0.007868043961469517,-0.02844884465804398
257.20000000000323,18.53130289633208,-0.007823483582071114,-0.028452586100456756
258.60000000000326,18.572968647153157,-0.007776567565835454,-0.027148972063798738
260.0000000000033,18.615452766213416,-0.00773554201894696,-0.027123599471536863
261.4000000000033,18.65705251841997,-0.007675896795654662,-0.02712350379789541
262.8000000000033,18.69986059756913,-0.007682468205935163,-0.027123478642408827
264.20000000000334,18.7420703960697,-0.0076186607661355476,-0.027145303951584765
265.6000000000034,18.78464498889362,-0.007581636268653992,-0.026458468277638758
267.0000000000034,18.82636858139069,-0.007536286138721902,-0.02646442171899821
268.4000000000034,18.868844162396393,-0.0075112510458344205,-0.027087003784259878
269.8000000000034,18.91087255568807,-0.007487784763657705,-0.027788909924083782
271.20000000000346,18.95302766238655,-0.007443195184034898,-0.027789659113778953
272.60000000000343,18.995299071306928,-0.007415220414343999,-0.027789790361794076
274.00000000000347,19.037400058118095,-0.007403751510320946,-0.027809686757052532
275.4000000000035,19.07983753754436,-0.007341219740105583,-0.02909111102087536
276.80000000000354,19.12188626284777,-0.007305977401530132,-0.029087546124998198
278.20000000000357,19.16410959355713,-0.007297476702426525,-0.030064310142137174
279.60000000000355,19.20627635551345,-0.00726246691065075,-0.030081642958009525
281.0000000000036,19.247709940350028,-0.007228344886910615,-0.030081717825339638
282.4000000000036,19.29069561843624,-0.007213508448732132,-0.03007986745353719
283.8000000000036,19.33274162989618,-0.007194888332537536,-0.03128621149349442
285.2000000000036,19.375302787209485,-0.007159024029821343,-0.03137976862589653
286.60000000000366,19.417887244408092,-0.007150057398369235,-0.03043220616785902
288.0000000000037,19.459685129937295,-0.007123967695805467,-0.030417869843915923
289.40000000000373,19.501494400382473,-0.007096286941287633,-0.030417871813853026
290.8000000000037,19.54424099556368,-0.007065547351046969,-0.030417871998935198
292.20000000000374,19.586496860234664,-0.007063413920550608,-0.030417872000015223
293.6000000000038,19.62871439865742,-0.007067129350273983,-0.030417872000015223
295.00000000000375,19.670793287111866,-0.007060171499439252,-0.03041787199995838
296.4000000000038,19.7129363493619,-0.007044454890110423,-0.030417871979153688
297.8000000000038,19.755842052129463,-0.007023990809323326,-0.030417866127407933
299.20000000000385,19.79809293928657,-0.007002676961350546,-0.030417261317751354
300.6000000000039,19.840832241840776,-0.007010965152996269,-0.02960679471195249
302.00000000000387,19.88292060361738,-0.007017922082364095,-0.02908851890018127
303.4000000000039,19.925196223985093,-0.006992280335904807,-0.030396680672765797
304.80000000000393,19.9676852621342,-0.006979591603974522,-0.030417832061090166
306.2000000000039,20.01032966104439,-0.006983253691460898,-0.030417872104521848
307.60000000000394,20.052536036670663,-0.006969935789239142,-0.030417872001038404
309.000000000004,20.09509732471522,-0.006985495644897282,-0.03041787200714907
310.400000000004,20.13754255896009,-0.0069855537533898785,-0.030417872993808714
311.80000000000405,20.179958604018815,-0.00696907419530077,-0.030417736632671222
313.200000000004,20.222224124325866,-0.0069867059676162625,-0.030954178706508628
314.60000000000406,20.264864303925165,-0.006977260570758339,-0.0314053869133204
316.0000000000041,20.30731016684404,-0.0069701322883874905,-0.03140646185968876
317.40000000000407,20.349763932204567,-0.006984887125557463,-0.03140646400677838
318.8000000000041,20.392184704126773,-0.006959062691185263,-0.031406468701192125
320.20000000000414,20.43479262810936,-0.006973831808586355,-0.03140780347050054
321.6000000000042,20.47739280245649,-0.006978932803797205,-0.032011094083770786
323.0000000000042,20.520061947207147,-0.0069923028282565265,-0.032066681027060895
324.4000000000042,20.562739592456232,-0.006980469765525666,-0.03206460190500593
325.8000000000042,20.60546296417274,-0.006995635304771699,-0.03240465608843124
327.20000000000425,20.64765797337015,-0.007002938509510403,-0.03237986495346945
328.60000000000423,20.690375443240505,-0.007011494732541937,-0.03241302718643624
330.00000000000426,20.73325206423247,-0.007005836607228176,-0.03138236646023529
331.4000000000043,20.77610648601668,-0.007037671463278844,-0.03138989897527722
332.80000000000433,20.81877335360586,-0.007065412216919845,-0.03138991998878282
334.20000000000437,20.861277372818225,-0.007061483362512024,-0.03138993163287296
335.60000000000434,20.903422212484486,-0.007054791757048917,-0.031394452646452464
337.0000000000044,20.947024594859208,-0.00704541862924306,-0.03201691598906109
338.4000000000044,20.989559802380615,-0.007056895156402265,-0.033808177615156865
339.8000000000044,21.032209398615855,-0.0070743337048163445,-0.03212507392882458
341.2000000000044,21.075159113459616,-0.0070612074322579195,-0.03073172986910322
342.60000000000446,21.11819557930507,-0.007066640676243289,-0.03171985283793788
344.0000000000045,21.160911248777715,-0.007075641523553321,-0.0330670967279616
345.4000000000045,21.203923856900786,-0.007119615310633734,-0.03306125445843122
346.8000000000045,21.246298547204002,-0.007130022030598505,-0.03306121693060504
348.20000000000454,21.289573474052606,-0.007175085622142123,-0.03306118105638234
349.60000000000457,21.33255710623552,-0.007172619823469025,-0.031378249090778354
351.00000000000455,21.37548623261915,-0.0071736813615712325,-0.032174157682334226
352.4000000000046,21.41853744583603,-0.007196537371078369,-0.033198985479657495
353.8000000000046,21.461323574131956,-0.007230627289244575,-0.035104894583639634
355.20000000000465,21.504166928340076,-0.007264216805841867,-0.03519465960224011
356.6000000000047,21.547384808100777,-0.007289799990167157,-0.03567801454235564
358.00000000000466,21.59028775784208,-0.007305999884741234,-0.0346030291125885
359.4000000000047,21.633516933190446,-0.007312412016382823,-0.03426568151954257
360.80000000000473,21.676775255783056,-0.007373189510543902,-0.03357512660116413
362.2000000000047,21.719972158185218,-0.007370162788000021,-0.03360967452238128
363.60000000000474,21.76263267191447,-0.00741323458882774,-0.03361093888136679
365.0000000000048,21.80616325014968,-0.0074143963260111774,-0.034293946582039325
366.4000000000048,21.84910824230018,-0.007438081860235148,-0.03491168226733521
367.80000000000484,21.892286683297428,-0.007438688256150115,-0.0349116700790546
369.2000000000048,21.93524401182747,-0.007467579563247537,-0.034908068289723815
370.60000000000485,21.978710093650438,-0.0074611880395842375,-0.03638667638881543
372.0000000000049,22.021823256557845,-0.007457685411596336,-0.03895769739915522
373.40000000000487,22.06512167122079,-0.007474818254465845,-0.03748802810542884
374.8000000000049,22.108587619426068,-0.007484344679979426,-0.03623618966142317
376.20000000000493,22.15165507142419,-0.007490129767614392,-0.03702331907382472
377.60000000000497,22.195025137854902,-0.00753901478633629,-0.03722614137643632
379.000000000005,22.238323820708164,-0.007544113651356075,-0.03722643172983453
380.400000000005,22.281760058681346,-0.007551941479028257,-0.037226432010044164
381.800000000005,22.32486876747888,-0.0075821075589787516,-0.03722643487009236
383.20000000000505,22.36812375002166,-0.007599305711240946,-0.03722672019196693
384.600000000005,22.41181402079981,-0.007617399506741595,-0.036998463451283214
386.00000000000506,22.454646830098486,-0.007612406800156104,-0.03567407916347065
387.4000000000051,22.498528225978518,-0.007613151668349047,-0.037218680529406356
388.8000000000051,22.541545939988072,-0.0076560387954125965,-0.03736008741867636
390.20000000000516,22.585136226271565,-0.007674819630234389,-0.03824453439790432
391.60000000000514,22.62885861360633,-0.007674251155063799,-0.038214613436906575
393.0000000000052,22.67212089458176,-0.007687744692777501,-0.03834718938270498
394.4000000000052,22.71556820412795,-0.007726493653872027,-0.04086897076530249
395.8000000000052,22.75917030852007,-0.007753629067150169,-0.0393068201338167
397.2000000000052,22.80275076516825,-0.007771397654394376,-0.03798212570200121
398.60000000000525,22.84598852247381,-0.0077935180936271635,-0.036633515401348404
400.0000000000053,22.889490075629276,-0.007815831129228644,-0.036674996538522464
401.4000000000053,22.933230501236306,-0.007838810713370694,-0.03667506509785312
402.8000000000053,22.976496631476643,-0.007901825990207383,-0.03668662924877708
404.20000000000533,23.02027249330458,-0.007920492988459779,-0.037986809752368345
405.60000000000537,23.064164997327364,-0.007930552251084544,-0.037380566475405885
407.00000000000534,23.107519002160114,-0.007997989751864599,-0.03799109519155763
408.4000000000054,23.15115354839364,-0.008037580912525004,-0.037798088402013263
409.8000000000054,23.195062165329503,-0.008120641449093602,-0.037983433397812405
411.20000000000545,23.238614741848174,-0.008167640304104365,-0.03799501704747854
412.6000000000055,23.2823880058788,-0.008248816183518881,-0.03799502409790989
414.00000000000546,23.326011500645233,-0.008319266062481769,-0.037995023609482814
415.4000000000055,23.369797250836807,-0.008421359858286499,-0.0379950807513012
416.8000000000055,23.41380982769439,-0.008532744005187397,-0.03808082899897158
418.2000000000055,23.457324648033776,-0.008692254737860249,-0.03948630288905974
419.60000000000554,23.501502183520795,-0.0088638428324755,-0.04031020269493979
421.00000000000557,23.54524362099003,-0.009015467185816703,-0.04031143494646017
422.4000000000056,23.589480583718636,-0.009170369072615784,-0.040301529538197656
423.80000000000564,23.633232280463844,-0.009388563834474306,-0.03898584877464373
425.2000000000056,23.677028571735164,-0.009533832317896163,-0.03836147503557186
426.60000000000565,23.720624048627545,-0.009650149123558802,-0.03898371742644713
428.0000000000057,23.76493992969424,-0.009722311826948847,-0.0389424867192929
429.40000000000566,23.808287484209668,-0.009790530469487932,-0.040267592306804545
430.8000000000057,23.852979251636125,-0.00980370965591891,-0.04161369605759546
432.20000000000573,23.89666968307833,-0.009702957009816665,-0.04161323299572928
433.60000000000576,23.940224894273143,-0.00963348619634617,-0.04161323211380363
435.0000000000058,23.98431152123936,-0.009516037427416859,-0.04161333610767315
436.4000000000058,24.028449570563907,-0.00944133339805268,-0.041893060573244156
437.8000000000058,24.072251666992923,-0.0093334968293302,-0.04293752135893669
439.20000000000584,24.116348986163224,-0.009263064811982396,-0.042921527291042594
440.6000000000058,24.160241293933318,-0.00925253062221478,-0.04162150339436721
442.00000000000585,24.20411126226783,-0.009206559089296674,-0.04161940011326237
443.4000000000059,24.2481986438084,-0.009230438222804437,-0.041619375152549765
444.8000000000059,24.29143682176837,-0.00926740955523313,-0.04160215703035419
446.20000000000596,24.335990919652758,-0.009291218036641374,-0.04260747875238735
447.60000000000593,24.38022193792337,-0.009311552843703719,-0.04260941449555844
449.00000000000597,24.424051209394253,-0.009332806873164106,-0.042609392053776673
450.400000000006,24.468299403967713,-0.009391197490152804,-0.04260939199966174
451.800000000006,24.512305617485616,-0.009411087048227178,-0.042609391938242425
453.200000000006,24.556678976199926,-0.009474853368522097,-0.042609397550307904
454.60000000000605,24.59993663443457,-0.009507780713879794,-0.04261822262853343
456.0000000000061,24.64469316457464,-0.009575786757389593,-0.042938600310606034
457.4000000000061,24.688436566285667,-0.00962337527562632,-0.04294091536272049
458.8000000000061,24.733029091920876,-0.009678717833649155,-0.04377668323166972
460.2000000000061,24.777011060687602,-0.009725957354397428,-0.044259276109443135
461.60000000000616,24.82126893792753,-0.009775627476872167,-0.04425767004099157
463.00000000000614,24.865615724549833,-0.009839309943784054,-0.04313591816148232
464.4000000000062,24.90986325708989,-0.009891237061976865,-0.04293948861814556
465.8000000000062,24.95399041152773,-0.009940482422748668,-0.04293939196105612
467.20000000000624,24.998467577202383,-0.009971469442923977,-0.042939392262638876
468.6000000000063,25.04259067394393,-0.010025445289973546,-0.0429390271947625
470.00000000000625,25.086958875997595,-0.01008987865879616,-0.044073638459877884
471.4000000000063,25.131479319616965,-0.01016973561524691,-0.04419287038408015
472.8000000000063,25.175571721236373,-0.010267335672128343,-0.04556059247008193
474.2000000000063,25.219785753454982,-0.010306231467165748,-0.04476088059396943
475.60000000000633,25.264127288587815,-0.010374822690482573,-0.04510371599388918
477.00000000000637,25.308562475236013,-0.010464765284146058,-0.045567407662218784
478.4000000000064,25.353070150244093,-0.010551790296182681,-0.045567471010400595
479.80000000000643,25.397458662254383,-0.010631123844730705,-0.04535067897958811
481.2000000000064,25.441580237996252,-0.010723496886003006,-0.04283490245180133
482.60000000000645,25.4860447445733,-0.010789110720224353,-0.042630489942467875
484.0000000000065,25.530489076181347,-0.010855782003168777,-0.04411788164085806
485.40000000000646,25.57479870377609,-0.010923405859839653,-0.045469167102851316
486.8000000000065,25.618741930612106,-0.011001643188550432,-0.04545596650697803
488.2000000000065,25.663839640325506,-0.01106885157513414,-0.046764095610484446
489.60000000000656,25.708367740333056,-0.01111820236281042,-0.04677319266235713
491.0000000000066,25.75287154006359,-0.01117519398049277,-0.04677324111534631
492.40000000000657,25.797451777661827,-0.011271863864108085,-0.046780753474962466
493.8000000000066,25.841687905557638,-0.011308427973686806,-0.04743774861967154
495.20000000000664,25.886326295409546,-0.01138360203334481,-0.04776395330628702
496.6000000000066,25.930629602861817,-0.011449856191194303,-0.04765928184593804
498.00000000000665,25.974567306819573,-0.011511043637342414,-0.04633747829339541
499.4000000000067,26.01988205653091,-0.01155978658176514,-0.04767747954480228
500.8000000000067,26.064400210586218,-0.011664497909336118,-0.04764122516996849
502.20000000000675,26.109046764240155,-0.011741488299541632,-0.04763454716416504
503.60000000000673,26.15384358947542,-0.011797733428663429,-0.04896806690950939
505.00000000000676,26.198663761285328,-0.01187021648841523,-0.0497713171964449
506.4000000000068,26.243193426758587,-0.01195649508966529,-0.05028723787191325
507.8000000000068,26.288026948237608,-0.0120302208427287,-0.050290095131742873
509.2000000000068,26.333066799412965,-0.012090082158669566,-0.048973835376330044
510.60000000000684,26.37701091054461,-0.012147892663271405,-0.048991115887332626
512.0000000000068,26.422561454025022,-0.012228486625377715,-0.050291683854453595
513.4000000000069,26.4673984938647,-0.012288789448949075,-0.050293548206610694
514.8000000000069,26.51226250804111,-0.012383354993315339,-0.050293541012393916
516.2000000000069,26.557253957794618,-0.01246146998210907,-0.05041993887755325
517.600000000007,26.60272884660173,-0.012533986099740511,-0.050953551800262176
519.0000000000069,26.647444094160356,-0.012622825353106968,-0.05095354954457321
520.4000000000069,26.692630395529623,-0.012679872963167863,-0.050953550607829357
521.800000000007,26.73789324500381,-0.012783269255274371,-0.050941143029461955
523.2000000000071,26.783067981219297,-0.012894384967731955,-0.04963825949511147
524.6000000000071,26.828336385004846,-0.012982348747880925,-0.04865880578716997
526.000000000007,26.873141207021067,-0.013089889407170307,-0.04689720708256573
527.4000000000071,26.91933195011209,-0.013173099034171151,-0.05006032221467649
528.8000000000071,26.964619956302165,-0.013290072768694912,-0.05005389268461613
530.2000000000071,27.009959074190068,-0.01339751879126334,-0.05215188298825524
531.6000000000072,27.055393787885997,-0.013485928898494523,-0.05269500457711729
533.0000000000072,27.10092250808973,-0.013562936642152754,-0.05269295884451708
534.4000000000071,27.146627711839336,-0.013652491676526789,-0.05400914693004211
535.8000000000072,27.19249496069226,-0.013779358475909931,-0.05402197015865795
537.2000000000072,27.23811616447262,-0.013857281192777775,-0.054021942143691604
538.6000000000072,27.283599066663076,-0.01390945115912327,-0.05401400132492995
540.0000000000073,27.329265609603247,-0.014036097044600147,-0.055348470960638
541.4000000000073,27.375293676210706,-0.0141098637318025,-0.05534756500247795
542.8000000000073,27.42121446039294,-0.014212416867021863,-0.054924223591683585
544.2000000000073,27.466756985986244,-0.014297157031429872,-0.05506436961951522
545.6000000000073,27.5124038810523,-0.014369942537583667,-0.05599830086435986
547.0000000000074,27.558451279352564,-0.01447718602698155,-0.054668006536758185
548.4000000000074,27.604255846244257,-0.014572061529734663,-0.054672939232546014
549.8000000000075,27.64985210720517,-0.014671676601684683,-0.05467296061240745
551.2000000000074,27.695267221128987,-0.014726375557965736,-0.05467389464234884
552.6000000000074,27.741688263430312,-0.014833943702592008,-0.0562454335135385
554.0000000000075,27.787398052726562,-0.014922570948300138,-0.057422484167148014
555.4000000000075,27.83348332591369,-0.015013047934745657,-0.05738602362973211
556.8000000000075,27.879238818934624,-0.015061732219924106,-0.05608943597792404
558.2000000000075,27.924915417172027,-0.015153446488178311,-0.05739625149740846
559.6000000000075,27.97031206523716,-0.015271132417061802,-0.057420259264063134
561.0000000000075,28.016383171274654,-0.015386335502485986,-0.05877506227488993
562.4000000000076,28.062158521824838,-0.015462155632443351,-0.0587428996205972
563.8000000000076,28.107957478632635,-0.01551506607033977,-0.05865387671758526
565.2000000000077,28.15371337821528,-0.015672766218938292,-0.06070468689495101
566.6000000000076,28.19956420675518,-0.015775227665113217,-0.06070553621722752
568.0000000000076,28.24509275428225,-0.015861265304748327,-0.06070565656258964
569.4000000000077,28.290706201822594,-0.0160079817134271,-0.06118892058208303
570.8000000000077,28.336519427588893,-0.01618487727784457,-0.06203081238044206
572.2000000000078,28.38221445009782,-0.016457333548409663,-0.06197473153824262
573.6000000000078,28.428187644990874,-0.01688138217434241,-0.06335714194509023
575.0000000000077,28.473669033086328,-0.01689644092583151,-0.06472451060622575
576.4000000000078,28.519434507177717,-0.016745350224877057,-0.06334020983263144
577.8000000000078,28.564966073114192,-0.01667220136694209,-0.06444546509035831
579.2000000000078,28.610251623577682,-0.016626268771222193,-0.06466516430432989
580.6000000000079,28.655964246702055,-0.01662513819144337,-0.06595905270867775
582.0000000000078,28.701655919477968,-0.016648134243348225,-0.0662496031291937
583.4000000000078,28.747347778227567,-0.016689789387422743,-0.06762280182044833
584.8000000000079,28.793027046988392,-0.016738897535762038,-0.06862707055609008
586.2000000000079,28.838782994459777,-0.01682223015565536,-0.06860718817807765
587.600000000008,28.88384542128595,-0.016925386760068422,-0.0672944462993712
589.000000000008,28.92976537134458,-0.016980817225749033,-0.06599843821513218
590.4000000000079,28.975154716608323,-0.017111845318231747,-0.06731508796059416
591.800000000008,29.02137804586118,-0.017205980766310445,-0.06858914210303624
593.200000000008,29.06674396447004,-0.017282993201219368,-0.06863721423394509
594.6000000000081,29.112317175585805,-0.017340897953626002,-0.07044192371233748
596.0000000000081,29.157842544808815,-0.017438126591026358,-0.0716386287074613
597.400000000008,29.203769992929576,-0.017566895747390582,-0.07359196661556666
598.8000000000081,29.24967379037724,-0.01765899404293834,-0.07398056605291004
600.2000000000081,29.29475365139104,-0.01771994929028639,-0.07402910250223727
601.6000000000081,29.341248156421006,-0.017858368846214907,-0.07267098432959074
603.0000000000082,29.386517401967208,-0.017975882096523548,-0.07288259868508362
604.4000000000082,29.432491184328107,-0.01805735826516483,-0.07452675220895344
605.8000000000081,29.47821980815683,-0.018171019925005673,-0.07575570590915959
607.2000000000082,29.52394309227136,-0.01830634327868779,-0.07852478580164757
608.6000000000082,29.569460559016512,-0.018414705450159313,-0.07982435935571175
610.0000000000083,29.61543448096539,-0.018506369992050267,-0.07980184975977522
611.4000000000083,29.66117644484768,-0.01866507602670538,-0.08113931958757803
612.8000000000083,29.707061657666223,-0.018760661536705855,-0.08105670499182338
614.2000000000083,29.75248967570312,-0.018907898113434046,-0.08241186531896005
615.6000000000083,29.79875609561288,-0.019052898355452083,-0.0811490585470267
617.0000000000084,29.84447222208615,-0.019173951673811643,-0.08115567281177505
618.4000000000084,29.890311117941227,-0.019261816670441127,-0.07987252326893213
619.8000000000084,29.936262406427502,-0.019378382815789786,-0.08104540204934096
621.2000000000085,29.981750903773005,-0.019506226208529792,-0.0830560381820078
622.6000000000084,30.027077822423298,-0.01964801194167825,-0.08641405732177532
624.0000000000084,30.07377773542918,-0.019819902155770903,-0.08643928641814114
625.4000000000085,30.119653245708758,-0.01995708957837123,-0.08783199952199539
626.8000000000085,30.165891427406876,-0.020051226437038428,-0.08915560506429188
628.2000000000085,30.211877693310658,-0.02025392047530209,-0.09041244504777524
629.6000000000085,30.257084412130165,-0.0203721591965551,-0.09170403481840594
631.0000000000085,30.303481360482333,-0.020549261480966193,-0.09333345786671998
632.4000000000086,30.349838243513346,-0.020690281666002088,-0.09437393067992161
633.8000000000086,30.396106085430148,-0.02090009261179489,-0.09462796995899225
635.2000000000086,30.44244093666878,-0.021034958939444695,-0.09603599364905335
636.6000000000087,30.48825355548886,-0.02119668906334077,-0.09530792973964708
638.0000000000086,30.5346669768323,-0.02135161309823901,-0.09658676725462101
639.4000000000087,30.580156332714434,-0.021533309713771404,-0.09795147978377372
640.8000000000087,30.62732177421021,-0.021768507352047214,-0.09911422160374173
642.2000000000087,30.673366732396914,-0.021994044649315408,-0.09927702132515037
643.6000000000088,30.71959614241125,-0.022168838656011512,-0.1007039262474052
645.0000000000088,30.765900171001338,-0.02237831104826017,-0.10276051793374563
646.4000000000087,30.812271165380224,-0.022635591782807326,-0.10416946583029585
647.8000000000088,30.858577133231393,-0.02288749570446543,-0.1069815318874987
649.2000000000088,30.905034533879086,-0.02318640368200673,-0.10889281294166153
650.6000000000088,30.951591940411102,-0.023505361401434173,-0.10919048712324297
652.0000000000089,30.997976284680558,-0.02385155371220845,-0.11197302360810113
653.4000000000088,31.044571364798657,-0.024261643038337246,-0.11305469070850904
654.8000000000089,31.090841458363677,-0.024587076667182236,-0.11410423676568371
656.2000000000089,31.13732787044683,-0.02500451348495528,-0.11708976870582433
657.6000000000089,31.184103177146948,-0.025478649575817077,-0.11867344057284868
659.000000000009,31.230746516266613,-0.025950496064102227,-0.12097255217534553
660.400000000009,31.277252433176358,-0.026423741048794535,-0.12194918641901609
661.800000000009,31.323722658979026,-0.026965107971903015,-0.12447266461890649
663.200000000009,31.37040676280024,-0.02748220451118186,-0.12470865623532745
664.600000000009,31.417450097771106,-0.028061509698515133,-0.12777316870929667
666.0000000000091,31.464387895894934,-0.028655586267893086,-0.13062817969944263
667.4000000000091,31.510647453469453,-0.029295050093275724,-0.1344656047720605
668.800000000009,31.557588442179338,-0.02988106703460304,-0.13770236440041117
670.2000000000091,31.603859154202908,-0.03052631425935256,-0.13797743186810862
671.6000000000091,31.651410078423442,-0.031207523501885544,-0.1414810639371069
673.0000000000091,31.698211179093285,-0.03186735688075165,-0.14306296911794902
674.4000000000092,31.74514738055059,-0.03268154644830728,-0.14663577080318646
675.8000000000092,31.79207143031282,-0.03340054990685419,-0.14870255443770475
677.2000000000093,31.83890775957173,-0.03415809525747737,-0.1521596275957222
678.6000000000092,31.88583510913995,-0.034952515384710316,-0.1553947708226815
680.0000000000092,31.93267780156932,-0.03576981680026348,-0.1586631792338551
681.4000000000093,31.97943023034775,-0.03662162912315833,-0.161739611495193
682.8000000000093,32.026272557941176,-0.03756000974757302,-0.16592449084672012
684.2000000000094,32.07306402770953,-0.03844941524745925,-0.17030235032800078
685.6000000000093,32.12066812655289,-0.03941565059900155,-0.17458983867791744
687.0000000000093,32.16764646678978,-0.0403864174198468,-0.17980961839847964
688.4000000000094,32.214680479010596,-0.041379426061457635,-0.18535234754708085
689.8000000000094,32.261968869164065,-0.042512994768702204,-0.19113696807804104
691.2000000000094,32.30880538450905,-0.043551099458856865,-0.19671584980488888
692.6000000000095,32.35511891217186,-0.04472020346074971,-0.19937747445635523
694.0000000000094,32.403262512523675,-0.04590434466988738,-0.20514162288503712
695.4000000000094,32.45002925110255,-0.047098445945693096,-0.21120743895724559
696.8000000000095,32.49691092296177,-0.048319730221496514,-0.21723790736209025
698.2000000000095,32.544561082240236,-0.049575657457886196,-0.22279969800703725
699.6000000000096,32.591777715885854,-0.05090966383965787,-0.2289021211467741
701.0000000000095,32.638929625915516,-0.052270047157285504,-0.23567458072167824
702.4000000000095,32.686602024124284,-0.053683243827120565,-0.2406183837254332
703.8000000000096,32.733790615991936,-0.05511854421005961,-0.24816636692710858
705.2000000000096,32.781160816582485,-0.05657968069111017,-0.256237960342645
706.6000000000097,32.828477988441136,-0.058068976331795565,-0.2640337436597804
708.0000000000097,32.875664452543155,-0.05960897537478739,-0.2730668202731579
709.4000000000096,32.923570830386595,-0.06121330741451837,-0.28191303037968396
710.8000000000097,32.97107367183962,-0.06283444663995091,-0.2894744925818884
712.2000000000097,33.018406281198715,-0.06449714352773166,-0.29864449287157413
713.6000000000097,33.06612086842491,-0.0661499982279832,-0.30792004428965924
715.0000000000098,33.11358497587762,-0.06792410909057281,-0.31950504227464194
716.4000000000098,33.16090763450139,-0.06970957974667431,-0.32954679935537
717.8000000000097,33.2086979955118,-0.07149847631090625,-0.33913369439795815
719.2000000000098,33.256452212063195,-0.07334999726802374,-0.3506514968732404
720.6000000000098,33.30399591787601,-0.07519112953090208,-0.3611523068425413
722.0000000000099,33.3519196338138,-0.07706659211767475,-0.3720455260605604
723.4000000000099,33.3993721630911,-0.07903472845485623,-0.3832631031502558
724.8000000000098,33.446829448039935,-0.08089474363361196,-0.3959918597166734
726.2000000000099,33.495457471375985,-0.08292756804899172,-0.41037748559026
727.6000000000099,33.543028241151205,-0.08487941420762961,-0.42343954566916864
729.00000000001,33.59020689509454,-0.08678888613363943,-0.43555966949747926
730.40000000001,33.63865655009526,-0.08881209667109774,-0.4507001610766679
731.80000000001,33.68667939308497,-0.09082700760980314,-0.46584872774641894
733.20000000001,33.73424166964226,-0.09277773374467584,-0.48097406859946545
734.60000000001,33.78249985755991,-0.09477524010292952,-0.49560481332025574
736.00000000001,33.830069271091254,-0.09677724344249625,-0.5105517176980925
737.4000000000101,33.87848532195404,-0.09879009946812792,-0.5271425182116332
738.8000000000101,33.92643993848466,-0.10070325261230956,-0.5428638775115928
740.20000000001,33.97432151629556,-0.10263891659001553,-0.5601217538337551
741.6000000000101,34.02211755468638,-0.10454052197577873,-0.5771135733635049
743.0000000000101,34.07023239609703,-0.10640293435424339,-0.5950823542331136
744.4000000000102,34.11821310559991,-0.10827553627536754,-0.6123910826429153
745.8000000000102,34.16549948431436,-0.11012575424706494,-0.631436597590664
747.2000000000102,34.213900391928895,-0.11192093042600013,-0.6504424178517354
748.6000000000103,34.26200163099873,-0.11372672334928181,-0.6691768893405481
750.0000000000102,34.30992682194897,-0.11564886679127287,-0.6889918113970452
751.4000000000103,34.35788802056408,-0.11748047955167112,-0.7093612744053814
752.8000000000103,34.40567496750469,-0.11931888846963151,-0.727266850507192
754.2000000000103,34.45411632624886,-0.12121025893593469,-0.7457247126240532
755.6000000000104,34.502216751347284,-0.12316405050134,-0.7719783130095266
757.0000000000103,34.549807848727546,-0.12511729114625098,-0.7935247944269577
758.4000000000103,34.59805081261815,-0.127161924040771,-0.8130324783345486
759.8000000000104,34.646744315256,-0.1293224396176757,-0.8375306956851034
761.2000000000104,34.69459177410883,-0.1315150555115762,-0.8627147560972332
762.6000000000104,34.742669374286805,-0.1337447858959281,-0.8857199725397322
764.0000000000105,34.79089093493162,-0.13609762868920433,-0.9086784955647147
765.4000000000104,34.839405523015,-0.1385213715593678,-0.9331870976614596
766.8000000000105,34.88782046042635,-0.14100245507909864,-0.9596450600591879
768.2000000000105,34.93612568457411,-0.14348005879676112,-0.9840304604287553
769.6000000000105,34.98432910487387,-0.1459815057261567,-1.0086767288204328
771.0000000000106,35.032849498792544,-0.14852113687268148,-1.0345865559831395
772.4000000000106,35.08123665985604,-0.15100579538949147,-1.063928618289026
773.8000000000106,35.12945640449429,-0.15346553595553433,-1.090167862734603
775.2000000000106,35.1776931485625,-0.1559043983368619,-1.1142694569848288
776.6000000000106,35.22598411074854,-0.15836709542400837,-1.1467213509241674
778.0000000000107,35.27465817433306,-0.1607606792473628,-1.1760136300875956
779.4000000000107,35.32255910060759,-0.1628710406513347,-1.2053389159202368
780.8000000000106,35.370534439075506,-0.16439300786616176,-1.234609436101124
782.2000000000107,35.418171043171526,-0.16504047744044584,-1.260681058139852
783.6000000000107,35.464791549939,-0.1639828223096467,-1.2875956945500207
785.0000000000107,35.50998744278782,-0.1603886989433291,-1.3108156453696722
786.4000000000108,35.55400254109033,-0.15344754523265755,-1.33471162797224
787.8000000000108,35.59608907206577,-0.14273049330429938,-1.357204906581643
789.2000000000108,35.636449329969146,-0.12790853421407222,-1.3771354096409425
790.6000000000108,35.674483956475626,-0.10915197614374678,-1.3932919370494403
792.0000000000108,35.71179676802993,-0.088445971571299,-1.405624951473328
793.4000000000109,35.74998060204333,-0.06928302043939016,-1.4159473251688723
794.8000000000109,35.789663046360445,-0.05383366732319536,-1.4233189296398905
796.200000000011,35.83102994366585,-0.042470990234106,-1.4276218821043756
797.6000000000109,35.87372317353312,-0.03454367035776803,-1.4313722380069862
799.0000000000109,35.918158033990906,-0.029261860833574346,-1.4325774536456777
800.400000000011,35.96300722923875,-0.025883911589561607,-1.4312640250730908
801.800000000011,36.00890840074621,-0.023723698179876154,-1.4325613426144912
803.200000000011,36.05475935723105,-0.022355839614762296,-1.4330960912893431
804.600000000011,36.10143651859438,-0.021458814660622393,-1.4338913625659586
806.000000000011,36.147979824291404,-0.02093286211725635,-1.4352226491818385
807.400000000011,36.19502554654788,-0.02066442525179602,-1.4351163555269864
808.8000000000111,36.24219214707384,-0.02057299259075268,-1.4365136065219986
810.2000000000111,36.2891696567041,-0.020570089751031882,-1.4378397415044901
811.6000000000112,36.33641717410009,-0.02060538966389691,-1.437840013219045
813.0000000000111,36.38355746789641,-0.02066261020612151,-1.4378429016323935
814.4000000000111,36.43097832779192,-0.02078360957443912,-1.4365316230141332
815.8000000000112,36.477715477523944,-0.02084970052676237,-1.4365297253661993
817.2000000000112,36.52540030445674,-0.020914039626064612,-1.4365309061306846
818.6000000000113,36.572810932595196,-0.020973011399899502,-1.4378031629214831
820.0000000000113,36.6200831639527,-0.021104396570232005,-1.4378318255523936
821.4000000000112,36.66746830476747,-0.021189368474431935,-1.43783161283352
822.8000000000113,36.714424990235045,-0.02128720112597377,-1.438122277026764
824.2000000000113,36.761654364831635,-0.02134815855387388,-1.4378344500119056
825.6000000000113,36.80937483138354,-0.021474305393384397,-1.4378392158553197
827.0000000000114,36.85714682057623,-0.02153601415705022,-1.4391667566523267
828.4000000000113,36.90469545821968,-0.021579608443793776,-1.4391641158932202
829.8000000000113,36.95193400535414,-0.02169748357871479,-1.4391637372276023
831.2000000000114,36.99957696797689,-0.021720778620766355,-1.4378656000379806
832.6000000000114,37.046719910635176,-0.021802421622664107,-1.4378441077166713
834.0000000000115,37.093713596761944,-0.02181547330711145,-1.4378419359851478
835.4000000000115,37.141829688702074,-0.021886262592893765,-1.4371898240359542
836.8000000000114,37.1893450900193,-0.021974644992099807,-1.4365229403912565
838.2000000000115,37.23706574616621,-0.02209734313517686,-1.4365236078581347
839.6000000000115,37.28406525006763,-0.022143150167979422,-1.4379188425832012
841.0000000000116,37.33217384909494,-0.022256254451758495,-1.437826121653302
842.4000000000116,37.37954063046333,-0.022351347462001323,-1.4376365047280046
843.8000000000116,37.42713833671936,-0.02241651628914828,-1.4371666271290735
845.2000000000116,37.474860333739784,-0.02248785310761697,-1.4371681050980385
846.6000000000116,37.5220501501688,-0.022588053410898774,-1.4384684912986643
848.0000000000116,37.56993178286343,-0.022635307022694482,-1.4384923512251078
849.4000000000117,37.61691875594059,-0.022687459951217168,-1.438490726970599
850.8000000000117,37.66541984775963,-0.022761152276575377,-1.4391911809154294
852.2000000000116,37.712917811467534,-0.02282326938873055,-1.4395189211312527
853.6000000000117,37.76085202049898,-0.02292482801212897,-1.4401573500637141
855.0000000000117,37.80835241547041,-0.022968468694502663,-1.4402301086315674
856.4000000000118,37.85595617957625,-0.023018049512847756,-1.4388364471606678
857.8000000000118,37.90356816024907,-0.023041347141992078,-1.4389655463148472
859.2000000000118,37.95116693834589,-0.023169891263885297,-1.4378403566397253
860.6000000000118,37.99910413557549,-0.023226700366514426,-1.4378305457630631
862.0000000000118,38.04686624614152,-0.023309479363105425,-1.438282115992422
863.4000000000119,38.09442899386858,-0.023431559795017695,-1.4378352956015874
864.8000000000119,38.14218947078479,-0.02350262710039362,-1.4378378493360913
866.2000000000119,38.18990705998593,-0.023558380821687284,-1.4391298209857837
867.600000000012,38.23761663929218,-0.02368195923034614,-1.439138717142498
869.0000000000119,38.28519639820586,-0.02373126054142309,-1.4391388295258025
870.4000000000119,38.33320047687287,-0.02384640583612189,-1.439097884844756
871.800000000012,38.381076512364025,-0.023927565052877315,-1.4404677492626092
873.200000000012,38.42846224252385,-0.02399386747875515,-1.4404653407306967
874.600000000012,38.476453688728306,-0.024059260756008886,-1.4416803748862037
876.000000000012,38.52435951264507,-0.024140407662519243,-1.4408016621883348
877.400000000012,38.57185683332554,-0.024174729777519038,-1.4408110941515702
878.8000000000121,38.61968431388581,-0.024295639831163108,-1.4408110282859639
880.2000000000121,38.667388852189134,-0.024321994083980582,-1.4407370872081344
881.6000000000121,38.715249053436196,-0.02438192756447644,-1.4421159131530317
883.0000000000122,38.76281085331706,-0.024462120883598313,-1.441792817300751
884.4000000000121,38.81063386827899,-0.024472970403818156,-1.4417182136641884
885.8000000000122,38.85841717362352,-0.02448513981362717,-1.4404625004306695
887.2000000000122,38.90622530051239,-0.02454659548634687,-1.440463123762271
888.6000000000122,38.95382568199149,-0.024594774771413648,-1.4404631205820806
890.0000000000123,39.001648423906595,-0.024612622768224554,-1.4404628894875486
891.4000000000123,39.04899740266276,-0.02448477522409572,-1.4417789292430996
892.0000000000123,39.06954447544549,-0.02445188417395981,-1.441790776996271