File: 01_Data/Concrete_Block/STA/N2/30K_min/Concrete_Block_STA_N2_30KData_230829_R1.csv
##Temp./Â°C,Time/min,DSC/(mW/mg),Mass loss/mg
29.0,15.620206311863006,-2.290515471697487,-0.0033288750696560676
30.40000000000002,15.81672837039408,-2.2223162505525993,-0.001803467658184843
31.80000000000004,15.951614237397774,-2.166877077597693,-0.0020464756603169043
33.20000000000006,16.060279550667655,-2.118863002461622,-0.0018949809156287856
34.60000000000008,16.15266209610513,-2.074884665190078,-0.0020210893323899803
36.0000000000001,16.235053936569024,-2.0355740462737417,-0.0011452663243147754
37.40000000000012,16.313392342043556,-1.9972410101826263,-0.0007818653676232579
38.80000000000014,16.38569713507536,-1.963368655349211,-0.002076041325661304
40.20000000000016,16.4537123511028,-1.9318848209633954,-0.002089194362828728
41.60000000000018,16.518590499419794,-1.9001120938813725,-0.0023848394170160603
43.0000000000002,16.581085564188715,-1.870757573632938,-0.0026476522090757015
44.40000000000022,16.643704888624395,-1.8413297443570367,-0.0015561470008531586
45.80000000000024,16.70259254823804,-1.8156882720493295,-0.003217895468666132
47.20000000000026,16.761430523527437,-1.7907014154343128,-0.0028469128139501088
48.60000000000028,16.818180263912517,-1.7682990126823626,-0.00356728390578942
50.0000000000003,16.874093983997604,-1.7451619524628155,-0.0029777623482254434
51.40000000000032,16.929591375514978,-1.7264329457970176,-0.0033009040286660074
52.80000000000034,16.98326361101125,-1.7084329718202917,-0.005274421405930596
54.20000000000036,17.036719769035184,-1.6908637512264109,-0.005764657668196893
55.60000000000038,17.08987764451039,-1.6750644782597606,-0.0035180132268974873
57.0000000000004,17.142059950766676,-1.6587442080383157,-0.00500889959185935
58.40000000000042,17.19424403808876,-1.6468735970737072,-0.004367031131619292
59.80000000000044,17.245437195053164,-1.634220480970984,-0.006540844113068989
61.20000000000046,17.296930365226757,-1.622290754183152,-0.0060974937823252695
62.60000000000048,17.34778328083013,-1.611214367360067,-0.005554934709284254
64.0000000000005,17.39661256575587,-1.5982615637752828,-0.006531947620866951
65.40000000000052,17.44794503491727,-1.5860787467828787,-0.007689318157063418
66.80000000000054,17.497721014165535,-1.576171132180754,-0.008140358246750079
68.20000000000056,17.546939886355243,-1.5634706078314051,-0.008098570648720216
69.60000000000058,17.596729608771497,-1.5521520634460821,-0.007885702784178328
71.0000000000006,17.64637098062289,-1.5376390752480689,-0.007797253393606152
72.40000000000062,17.69517009668985,-1.5265789802926701,-0.00778680820719746
73.80000000000064,17.744305655906178,-1.512625615793091,-0.009130348383986853
75.20000000000066,17.793490083354595,-1.502656626352042,-0.010417088666092145
76.60000000000068,17.84223740577337,-1.4889089354141571,-0.010443000684331682
78.0000000000007,17.890936336547636,-1.4786963885432627,-0.01069457657903028
79.40000000000072,17.939376368635248,-1.467522183917132,-0.010450918334062642
80.80000000000074,17.987703206802735,-1.4576926652470714,-0.011743888338922925
82.20000000000076,18.036399689918397,-1.448028621940588,-0.012408676089798565
83.60000000000078,18.083424544987306,-1.439245730131757,-0.011746620265857377
85.0000000000008,18.1323191907307,-1.4303327648965711,-0.011782627874150187
86.40000000000082,18.18008985027761,-1.4196689919859853,-0.013131006414935698
87.80000000000084,18.227533890392653,-1.4095965000710422,-0.013117739228901026
89.20000000000086,18.275221191486075,-1.401167590728758,-0.013068853561003735
90.60000000000088,18.322827154298153,-1.3901022222640558,-0.014366562372253977
92.0000000000009,18.37011024317279,-1.3799927517963608,-0.014390431002591075
93.40000000000092,18.417175003188728,-1.3719195209439154,-0.014353632565215158
94.80000000000094,18.464395154984096,-1.3615842829096083,-0.015710841461885394
96.20000000000095,18.511295463356113,-1.3519158970631773,-0.01700822326591167
97.60000000000097,18.557569780307123,-1.3433720051403297,-0.017020207552617794
99.000000000001,18.6047486490573,-1.3323605867849586,-0.017020706040374645
100.40000000000101,18.651827970883073,-1.32497344018371,-0.018374532036029123
101.80000000000103,18.697836660701753,-1.31475517614943,-0.017473659905439476
103.20000000000105,18.744455255187336,-1.3033290012151644,-0.01834101862735471
104.60000000000107,18.790936613617376,-1.2931110538129083,-0.018339936056945394
106.0000000000011,18.837038653615526,-1.2854836077367833,-0.018340620446674283
107.40000000000111,18.883598172502587,-1.2758310740766972,-0.018913237583482623
108.80000000000113,18.92998120367735,-1.263328287771582,-0.019659103274878742
110.20000000000115,18.976010529004313,-1.2554608033373755,-0.019660021082029466
111.60000000000117,19.02237728538564,-1.2474940434113195,-0.01966001733515288
113.0000000000012,19.068529023481503,-1.2387215619573382,-0.019661750156084068
114.40000000000121,19.114463114735145,-1.2288833876335052,-0.020971522326700853
115.80000000000123,19.160310208443256,-1.2205327235880736,-0.02096993709097905
117.20000000000125,19.206010905723314,-1.2130165399235053,-0.020996007185712706
118.60000000000127,19.252222598374857,-1.2042418817849305,-0.022290538540376215
120.0000000000013,19.298195337789362,-1.1962755099223237,-0.023475966935404546
121.40000000000131,19.343618385805478,-1.188013164948975,-0.02219798751218649
122.80000000000133,19.389658081619967,-1.1779829247074673,-0.022291569732292515
124.20000000000135,19.434493061413303,-1.1699384135090234,-0.023260678837595083
125.60000000000137,19.48034256836896,-1.1584095008452167,-0.023609910097561304
127.00000000000139,19.525422713745662,-1.1480129899529026,-0.023610019942492233
128.4000000000014,19.57032986620206,-1.1365796582062242,-0.023610020001064047
129.80000000000143,19.615928297882544,-1.125561053477629,-0.023610019965529805
131.20000000000147,19.660797948361232,-1.1157978171333018,-0.023609972995502382
132.60000000000147,19.70558696794209,-1.105135428083429,-0.02361577849588148
134.00000000000148,19.75016205908527,-1.0955736149799429,-0.024919154731604554
135.4000000000015,19.795062914651265,-1.083729572507082,-0.026248612360516344
136.80000000000155,19.839526657695085,-1.0738594107287527,-0.02625018679043256
138.20000000000155,19.884142795691492,-1.0625662892572953,-0.02625018821480829
139.60000000000156,19.928835068253687,-1.0536138866412874,-0.026209461198031025
141.0000000000016,19.973036797879825,-1.0432416982772519,-0.027071253455646094
142.40000000000163,20.017437979141697,-1.0335694583980344,-0.02690009675811611
143.80000000000163,20.061324529646935,-1.0238377715707543,-0.026899902640367568
145.20000000000164,20.10537513707748,-1.0159172793346638,-0.026899518269775324
146.60000000000167,20.14962556857682,-1.0061295289558385,-0.02824386863435091
148.0000000000017,20.193779408340234,-0.9959590800320021,-0.02822058745474143
149.4000000000017,20.237660906023393,-0.9883300264433174,-0.028220527568962428
150.80000000000172,20.28135180303162,-0.9779304873483238,-0.028073993033158384
152.20000000000175,20.324526720196136,-0.9713663203762399,-0.02821808634805656
153.60000000000178,20.368982475431896,-0.9618982375473422,-0.0282199022392704
155.0000000000018,20.412677865762255,-0.953198435157552,-0.028911268399025136
156.4000000000018,20.45648979588264,-0.9457285603638446,-0.028610382505884324
157.80000000000183,20.499669076606196,-0.9355816172794135,-0.02822068942033118
159.20000000000186,20.543755888317804,-0.9270980585506847,-0.028220089618204547
160.60000000000187,20.587413744534658,-0.9212163869178267,-0.02826389198935164
162.00000000000188,20.630612346036774,-0.9131907747666416,-0.029539771267463433
163.4000000000019,20.674217688134522,-0.9036624193685168,-0.030836189331846953
164.80000000000194,20.717958549055677,-0.8942542004263508,-0.03085926402856387
166.20000000000195,20.761055233090588,-0.8879306664582233,-0.03004446617951606
167.60000000000196,20.804934894927452,-0.8795049962761136,-0.02954022266693812
169.000000000002,20.84828992586691,-0.8708230152547557,-0.03201894480247658
170.40000000000202,20.891619515595295,-0.8643356041528458,-0.0321902269278449
171.80000000000203,20.93495554435856,-0.8568336183819262,-0.03085643741910049
173.20000000000203,20.978202510568167,-0.8481348313675021,-0.03100720059319606
174.60000000000207,21.02174882328195,-0.8410753731801355,-0.03184992829919375
176.0000000000021,21.064513883127074,-0.8326457882994334,-0.031849947020083924
177.4000000000021,21.107801241302077,-0.8245258546062756,-0.0320767381141982
178.80000000000211,21.1509931097757,-0.8179861000837426,-0.03315867968914965
180.20000000000215,21.19396919805153,-0.8107502112003627,-0.03322465300375699
181.60000000000218,21.236572888726492,-0.8040727996047988,-0.031147117531107327
183.0000000000022,21.279939692557672,-0.7973560867388506,-0.031186590222735955
184.4000000000022,21.322475147271287,-0.7887715337139387,-0.03248693036243866
185.80000000000223,21.365567528360025,-0.783368260590938,-0.03250107585858997
187.20000000000226,21.40818860957638,-0.7767183743200828,-0.03307657278246179
188.60000000000227,21.450926804012926,-0.7709258015430789,-0.03381921112308195
190.00000000000227,21.4934495082093,-0.7665228711034281,-0.033819956864226786
191.4000000000023,21.536352011269276,-0.7587087450674826,-0.03382510884058787
192.80000000000234,21.578741189348293,-0.754001132133037,-0.03250215109012844
194.20000000000235,21.62172011941693,-0.7486258786663111,-0.03307826054614438
195.60000000000235,21.663962612975826,-0.7423723610189216,-0.033818186623885804
197.0000000000024,21.706586767110732,-0.7369238524890888,-0.03381994403054778
198.40000000000242,21.74907742456006,-0.7316933585484896,-0.03381917000313628
199.80000000000243,21.79147275416111,-0.7264257296068477,-0.0334990076350512
201.20000000000243,21.833898727213466,-0.7222512649262407,-0.033496266051858736
202.60000000000247,21.876210343378908,-0.7176180938792724,-0.03416223143426178
204.0000000000025,21.918567583295367,-0.7125242135517461,-0.034483780592893254
205.4000000000025,21.960953791617047,-0.7073803787400172,-0.03448012456129135
206.8000000000025,22.00340309952901,-0.7035758629871377,-0.03447989559522391
208.20000000000255,22.045940618060325,-0.6973410912672628,-0.03444732416420093
209.60000000000258,22.087819028367004,-0.6938818864425481,-0.035802303349633746
211.0000000000026,22.13033118415548,-0.6885886293494257,-0.03580020541163442
212.4000000000026,22.172382050938957,-0.6844945220878744,-0.035807541191918535
213.80000000000263,22.214956628055823,-0.6793194878414915,-0.03468389855525089
215.20000000000266,22.25730736251236,-0.6774603291632937,-0.0348098514832853
216.60000000000267,22.299437030652037,-0.6725508753478878,-0.03481010395396611
218.00000000000267,22.341638061593336,-0.6689253773530689,-0.03481010399642237
219.4000000000027,22.384185953346986,-0.6648601539651086,-0.03481010156032882
220.80000000000274,22.426118452097707,-0.6609808374936191,-0.034809612943763835
222.20000000000275,22.46811767566971,-0.6573711914393061,-0.03475557775441951
223.60000000000275,22.510965904897102,-0.6548070565737611,-0.03613184080167864
225.00000000000279,22.552921832260107,-0.6510597412014815,-0.03688634819575265
226.40000000000282,22.59428766976895,-0.6483143004803464,-0.03744987474145889
227.80000000000283,22.63736873787627,-0.6459103129994288,-0.03744987138282774
229.20000000000283,22.679434735605525,-0.6415710196807201,-0.03744990350312749
230.60000000000286,22.721547648223197,-0.63838826939148,-0.03745652031378732
232.0000000000029,22.763851978332177,-0.6369591607544988,-0.036132792687765036
233.4000000000029,22.806404408805324,-0.6353199208096254,-0.03612962225676286
234.8000000000029,22.848096190122384,-0.63344560527333,-0.03610307535301471
236.20000000000294,22.8907124003439,-0.6324599047245134,-0.03746919175055741
237.60000000000298,22.933024173274067,-0.6296224632233238,-0.038761958645464833
239.00000000000298,22.975225314211034,-0.6269399876219895,-0.03876008439112111
240.400000000003,23.01789408591066,-0.6240946869097086,-0.03875896820098346
241.80000000000302,23.060119729196252,-0.6209863499889535,-0.03828957729679372
243.20000000000306,23.102316758681415,-0.6175188457378339,-0.03743980521255885
244.60000000000306,23.14445943447392,-0.616038742361773,-0.037440229261751945
246.00000000000307,23.186401143960794,-0.6141245233508817,-0.037467987561607075
247.4000000000031,23.228817211439207,-0.6118537837430339,-0.03843010517557177
248.80000000000314,23.272304584697387,-0.609454749018437,-0.038755842892127745
250.20000000000314,23.314295105415933,-0.6067318655398066,-0.040066865866233314
251.60000000000315,23.35667015692594,-0.6043565992582081,-0.04007844812328676
253.00000000000318,23.39944938964332,-0.6011321998592627,-0.038709048684193004
254.40000000000322,23.44184856360708,-0.6002995203803245,-0.03875959898993919
255.80000000000322,23.483982763894133,-0.5990150583964902,-0.038761855496516784
257.20000000000323,23.526285510562627,-0.5960213283119642,-0.03970677724922789
258.60000000000326,23.56902043351225,-0.5944995704147916,-0.04073474702154556
260.0000000000033,23.6114061811372,-0.5930801605309882,-0.04074035428773426
261.4000000000033,23.65395900434178,-0.5923996343113195,-0.04074008188330058
262.8000000000033,23.6963438904715,-0.5894127978511899,-0.0407401271315897
264.20000000000334,23.739019421113937,-0.5889949562072975,-0.0407404972624148
265.6000000000034,23.781313652432857,-0.5867213443060263,-0.041431327437857046
267.0000000000034,23.82374740185529,-0.5857713836652171,-0.041399815623130554
268.4000000000034,23.866076476571045,-0.5842977130601701,-0.04246695091758035
269.8000000000034,23.90842634133808,-0.582922373266418,-0.042714415065840505
271.20000000000346,23.95103897976218,-0.5825443420464763,-0.041411605330659906
272.60000000000343,23.993677973033076,-0.5805808044620112,-0.041400095833552975
274.00000000000347,24.03596868068085,-0.578674944779337,-0.04140003291666128
275.4000000000035,24.078334435715583,-0.5784948614342805,-0.04140095386767184
276.80000000000354,24.12076043488297,-0.5760736575818994,-0.04270120630283314
278.20000000000357,24.162430313584462,-0.5751784454782612,-0.04274599905884502
279.60000000000355,24.205662431470177,-0.5743917277347999,-0.04370479388392434
281.0000000000036,24.247717007297773,-0.5719038207238352,-0.04370020560241672
282.4000000000036,24.290224022178545,-0.5701638090322168,-0.04370005010954614
283.8000000000036,24.33289749108816,-0.567998500236693,-0.04358462776875083
285.2000000000036,24.375137702556135,-0.5679911810861094,-0.04336460218802429
286.60000000000366,24.417609691514933,-0.567474326237943,-0.04251055432565165
288.0000000000037,24.46016625721534,-0.565885780036686,-0.04212000606710875
289.40000000000373,24.502577566871544,-0.5648780967038479,-0.04205983921390244
290.8000000000037,24.544304449191113,-0.5641577780193582,-0.04206016124511214
292.20000000000374,24.587459894290507,-0.5630869217366153,-0.042292741337863315
293.6000000000038,24.62989432450565,-0.561402010876272,-0.043049627943750224
295.00000000000375,24.672393028831646,-0.5609401400966408,-0.043055126918515096
296.4000000000038,24.71487205777742,-0.5609176078666902,-0.04206066635449268
297.8000000000038,24.75702594001607,-0.5599039086228662,-0.04205016790861915
299.20000000000385,24.7995470674768,-0.5587121810085578,-0.042050062577703606
300.6000000000039,24.842160930708815,-0.5584578717606665,-0.04204986930781063
302.00000000000387,24.88464205107925,-0.5588463829536607,-0.043430850973091406
303.4000000000039,24.92719044396554,-0.5573776040180355,-0.0433708046490362
304.80000000000393,24.969629007441036,-0.5574456868601113,-0.043421591482650346
306.2000000000039,25.01218307121829,-0.5574361412313142,-0.04205252438218254
307.60000000000394,25.054858241076182,-0.556682925236331,-0.041999805477294316
309.000000000004,25.097241040294325,-0.5567098446292176,-0.044692505930576054
310.400000000004,25.139817109472755,-0.5560521221479596,-0.04468986518576257
311.80000000000405,25.18253138370278,-0.556878534194602,-0.04468983252885428
313.200000000004,25.224758269616515,-0.556261961704068,-0.044689693229458705
314.60000000000406,25.26741318974241,-0.5565981478736437,-0.04531911025814539
316.0000000000041,25.30997682381291,-0.5569448496759365,-0.04600573016968079
317.40000000000407,25.352565150271666,-0.5572718254520463,-0.044695831845771306
318.8000000000041,25.395307032801032,-0.55661643230867,-0.04468981848900455
320.20000000000414,25.437412437513107,-0.5572812066098788,-0.0446898318947464
321.6000000000042,25.48021887123999,-0.5552005665075308,-0.04468983330409637
323.0000000000042,25.522837629745947,-0.5574521540043028,-0.04469078089752099
324.4000000000042,25.56534130710204,-0.5572724559890462,-0.045111871816239546
325.8000000000042,25.608023403541438,-0.5573756773318836,-0.045349834240310916
327.20000000000425,25.650398794778628,-0.557434862644518,-0.045350164875473276
328.60000000000423,25.693141311553017,-0.5574859785350061,-0.04535228637920197
330.00000000000426,25.73559591476407,-0.557262984173483,-0.04568257014350641
331.4000000000043,25.778340974978693,-0.5589408965493734,-0.04568012706796942
332.80000000000433,25.820965238632464,-0.5594450192009978,-0.04568011403322236
334.20000000000437,25.863078885913428,-0.5603719424434117,-0.04568011399941696
335.60000000000434,25.906081038578606,-0.5621308358672492,-0.04568011387280091
337.0000000000044,25.949501432320446,-0.5626971294402082,-0.045680119414994724
338.4000000000044,25.99181419297647,-0.562952546260194,-0.04569043249792282
339.8000000000044,26.034537528808425,-0.5631039222769706,-0.0463228684936543
341.2000000000044,26.077279438321533,-0.5626177189953728,-0.046339962111884514
342.60000000000446,26.120182059121092,-0.5637633060203912,-0.04633999703739944
344.0000000000045,26.16308541745494,-0.5657743860657434,-0.0463391374064801
345.4000000000045,26.205507499636706,-0.5660350756295686,-0.045934689655348304
346.8000000000045,26.248561932356605,-0.5662793580379984,-0.04457932738155401
348.20000000000454,26.29144024082384,-0.5680654312762856,-0.0462220414367045
349.60000000000457,26.334387743498283,-0.5691552286771859,-0.04639541528756963
351.00000000000455,26.37752094677704,-0.5683170282333666,-0.047441269060942926
352.4000000000046,26.42026890108833,-0.5704892229764424,-0.04744006712753368
353.8000000000046,26.462841058450582,-0.5726708737051908,-0.04744006997286254
355.20000000000465,26.50627025271072,-0.5759441976523018,-0.047440070038903936
356.6000000000047,26.549110643352716,-0.576481408800932,-0.04744008107597919
358.00000000000466,26.591912757464147,-0.5784395475321116,-0.04744102644182302
359.4000000000047,26.635249052101454,-0.5814751038707378,-0.04852134395947294
360.80000000000473,26.678403605248647,-0.5835960721791562,-0.048420525632542066
362.2000000000047,26.7210572300399,-0.5856858375251498,-0.048420070541242755
363.60000000000474,26.76396032437613,-0.5863994174429256,-0.048420069997062054
365.0000000000048,26.806707471457443,-0.5870510599076719,-0.04842006999998327
366.4000000000048,26.850150504306235,-0.589290560995712,-0.04842007000000015
367.80000000000484,26.89341661971499,-0.5911061049500226,-0.04842006999998327
369.2000000000048,26.936553720887122,-0.5922154613627064,-0.048420069996286674
370.60000000000485,26.97983580395454,-0.5946338440256279,-0.04842007032094342
372.0000000000049,27.022885016612943,-0.5934974031478298,-0.048420465983736616
373.40000000000487,27.06601573504721,-0.5950172736219344,-0.04852239908760536
374.8000000000049,27.10938546369222,-0.5957643953259938,-0.04710711886657171
376.20000000000493,27.152698237994453,-0.5965187429533596,-0.049801707272071116
377.60000000000497,27.195966516099546,-0.5976749827758623,-0.05016944048506522
379.000000000005,27.23929242512603,-0.6003709650765232,-0.05017007609421986
380.400000000005,27.282562190268866,-0.6016486172272524,-0.05017007600672363
381.800000000005,27.32558846307492,-0.604568365283497,-0.05017007600389567
383.20000000000505,27.369169689368576,-0.6047899892967215,-0.05017007600012802
384.600000000005,27.412539734898676,-0.6053843449327438,-0.05016972708528966
386.00000000000506,27.45585407553792,-0.6072174096123552,-0.05121593357536103
387.4000000000051,27.499358162155776,-0.6092775809497687,-0.05148989510430413
388.8000000000051,27.542677897530357,-0.6099133634726264,-0.05148979632998918
390.20000000000516,27.586564299723246,-0.6117688319619878,-0.05166015180952899
391.60000000000514,27.63010778688213,-0.6136315218048985,-0.052148817128443437
393.0000000000052,27.67276887991772,-0.6177894183376675,-0.05214984364623909
394.4000000000052,27.71673811587971,-0.6188666757339655,-0.05214984400953604
395.8000000000052,27.7604755034341,-0.6205676286675871,-0.05214984400003253
397.2000000000052,27.803781893106347,-0.6220445922239474,-0.05214984400001299
398.60000000000525,27.847547564448035,-0.6232942208927819,-0.05214984395572442
400.0000000000053,27.890985950197376,-0.6261381166026182,-0.052149831070626984
401.4000000000053,27.934724082647875,-0.6276725431255376,-0.05215051806793314
402.8000000000053,27.978129263054615,-0.6306648246941567,-0.05247089164621821
404.20000000000533,28.022135489297266,-0.6319264505215907,-0.05247981469408414
405.60000000000537,28.06509938373812,-0.6333641214256244,-0.05247980975237976
407.00000000000534,28.109264429346535,-0.635339550126833,-0.05248022133235564
408.4000000000054,28.152848996371425,-0.6384721453886809,-0.05380750101747145
409.8000000000054,28.196405819568827,-0.6412040196916641,-0.05379985118648145
411.20000000000545,28.24053739117145,-0.6452297962070203,-0.05334730667437393
412.6000000000055,28.284117845894126,-0.6479674513953927,-0.05248104429694278
414.00000000000546,28.327996526274415,-0.6526572108522045,-0.053718740488511774
415.4000000000055,28.37167832088894,-0.6557679709267465,-0.0538004613911629
416.8000000000055,28.415422999017,-0.6604795115520692,-0.05380001193042494
418.2000000000055,28.459298396422575,-0.6657028634122117,-0.05380001000717494
419.60000000000554,28.50343477962285,-0.6725176855885558,-0.05380006741808385
421.00000000000557,28.547121373877587,-0.680831094248435,-0.05381141003339218
422.4000000000056,28.59102521885591,-0.6888200850445256,-0.055110033339574205
423.80000000000564,28.63504319991499,-0.6953200963512176,-0.05512011745628209
425.2000000000056,28.678980299901053,-0.7050603734651144,-0.05512017595913088
426.60000000000565,28.722838849216938,-0.7134475851511465,-0.055120336133853254
428.0000000000057,28.766388425309025,-0.7212003263212519,-0.05515711756019703
429.40000000000566,28.81112292224968,-0.7287624027880589,-0.05479042181280791
430.8000000000057,28.85499322724602,-0.7320386739407552,-0.05478983913184399
432.20000000000573,28.899139386773903,-0.73383968476502,-0.054789836035693984
433.60000000000576,28.942752402099682,-0.7349585405828207,-0.054789853246177245
435.0000000000058,28.986895391837283,-0.7306746436618423,-0.0547894396380717
436.4000000000058,29.030793770350115,-0.7288224444399471,-0.05643507704375539
437.8000000000058,29.074968018354813,-0.7264306703084827,-0.05643007954902757
439.20000000000584,29.118823589704167,-0.7236245609776486,-0.056430039042376645
440.6000000000058,29.16336445775605,-0.7212205249708669,-0.05647107712291399
442.00000000000585,29.207056112919673,-0.7195045410265815,-0.055127316323759334
443.4000000000059,29.251164600062697,-0.7178756493254159,-0.056236657248804445
444.8000000000059,29.295303350634672,-0.718691866708174,-0.05769969859348034
446.20000000000596,29.339480488710237,-0.7198767387674057,-0.057750020468322116
447.60000000000593,29.38384761537987,-0.7210919215910968,-0.05766374300804067
449.00000000000597,29.42808281120331,-0.7231575972250234,-0.05907090861010955
450.400000000006,29.472414603904273,-0.7241538228617234,-0.05838897176755031
451.800000000006,29.51663341251475,-0.7287452072624456,-0.05840972360858743
453.200000000006,29.560823823825427,-0.73051178533206,-0.058409854843362474
454.60000000000605,29.605106198824792,-0.7348442587142087,-0.05854857603213626
456.0000000000061,29.649633649353227,-0.7388598510356528,-0.058739637770433006
457.4000000000061,29.69439015872719,-0.7401384530388242,-0.05873982172304304
458.8000000000061,29.738399268489392,-0.7449119941215104,-0.05873988595522528
460.2000000000061,29.782270960251218,-0.7470576895403932,-0.05938222634887813
461.60000000000616,29.826370679817067,-0.7493056684868419,-0.06005906059254995
463.00000000000614,29.871580861091434,-0.75412195263557,-0.060061289425028086
464.4000000000062,29.91629197328859,-0.7559294082547441,-0.059709040068574026
465.8000000000062,29.96076719421465,-0.7592060935833974,-0.05905221459463572
467.20000000000624,30.00533849452019,-0.7630985403703159,-0.05907005424877898
468.6000000000063,30.049719184892194,-0.7685964785872333,-0.05907016049062097
470.00000000000625,30.094171877155873,-0.7723509518718586,-0.05907100444476088
471.4000000000063,30.13870277692399,-0.7772405968164355,-0.05969048817505129
472.8000000000063,30.183194386740116,-0.7813979518250642,-0.060389215729778734
474.2000000000063,30.227918829036184,-0.7854782556520353,-0.06042367286902106
475.60000000000633,30.272459755881414,-0.7875044106994383,-0.0587267233602522
477.00000000000637,30.317093569071126,-0.7912833197778406,-0.05958562358088493
478.4000000000064,30.361714666002353,-0.795885095130182,-0.061897947854333335
479.80000000000643,30.40622837198241,-0.7995620671849217,-0.06322724524464318
481.2000000000064,30.450779703740672,-0.8054752717889444,-0.062041919308115645
482.60000000000645,30.495783124930494,-0.8104139281543908,-0.06308266444935562
484.0000000000065,30.540144458423622,-0.8141812847481245,-0.06323975472692744
485.40000000000646,30.584958347798523,-0.8207532375821256,-0.06268901166417606
486.8000000000065,30.629734177378886,-0.824106184967774,-0.06192022307787903
488.2000000000065,30.674351055728366,-0.8287953480439835,-0.061920180673399994
489.60000000000656,30.719328315562127,-0.8333227730692178,-0.06192017999905408
491.0000000000066,30.763505112660287,-0.8382005402519979,-0.061920178732794096
492.40000000000657,30.808307500904366,-0.8421419341613751,-0.061920141776698134
493.8000000000066,30.85327023479642,-0.8467101529253954,-0.06213282374651952
495.20000000000664,30.89804591324297,-0.8500214797573971,-0.06390562381293208
496.6000000000066,30.942843376214498,-0.852257399424731,-0.06389995672699067
498.00000000000665,30.986828429596862,-0.8582468652235351,-0.06390165304472273
499.4000000000067,31.032122027412314,-0.860960777633499,-0.06498455507189949
500.8000000000067,31.0765193565239,-0.8650008305711985,-0.06489048615123982
502.20000000000675,31.12181510677022,-0.8696264106417491,-0.06487182399355262
503.60000000000673,31.166822885552055,-0.8723783638079953,-0.06522129637771545
505.00000000000676,31.21137653123059,-0.8771105364815814,-0.06522011524076543
506.4000000000068,31.25636592936907,-0.8801252487206442,-0.06522186698945998
507.8000000000068,31.30136475990313,-0.88503105171725,-0.06636393547079766
509.2000000000068,31.34592607352005,-0.8868871699180826,-0.06653980719036312
510.60000000000684,31.391076035413075,-0.8922870777109051,-0.06653988212749162
512.0000000000068,31.435733282359813,-0.8948464681824716,-0.0665398820005727
513.4000000000069,31.480601940173273,-0.8994877923983521,-0.06653988199969518
514.8000000000069,31.525941325223382,-0.9048114049890811,-0.0665398817867624
516.2000000000069,31.570568736581368,-0.9091915358664688,-0.06653992326944547
517.600000000007,31.615393258136304,-0.9137681954136344,-0.06664897105410184
519.0000000000069,31.660407347573237,-0.9189870770989113,-0.0678490313038278
520.4000000000069,31.70498041553327,-0.9235127649148747,-0.06785009019622557
521.800000000007,31.750399016912382,-0.9302712372849441,-0.06785009800752295
523.2000000000071,31.79561944879489,-0.933597391465454,-0.06785009798679908
524.6000000000071,31.84045059641559,-0.9410940335074444,-0.06785010037034223
526.000000000007,31.88544214377265,-0.9460808419652326,-0.06785196078488465
527.4000000000071,31.930532408177722,-0.9518719782325198,-0.06894052083741897
528.8000000000071,31.975684658127335,-0.9586582162061001,-0.06916976761828941
530.2000000000071,32.0207241138146,-0.9631914378351861,-0.06917017355229049
531.6000000000072,32.0660078390052,-0.9692472743896847,-0.06957171911685123
533.0000000000072,32.111282011741736,-0.9741086015547383,-0.07048934655227512
534.4000000000071,32.156397110550685,-0.9778186621850601,-0.0699137744503866
535.8000000000072,32.20144892125252,-0.9831532456745797,-0.0692666921889673
537.2000000000072,32.2467907778318,-0.9900153158405858,-0.07049176183929795
538.6000000000072,32.29214626704595,-0.9947922867632838,-0.07062302826476818
540.0000000000073,32.33759364814184,-1.001053459097398,-0.07180118468305974
541.4000000000073,32.38228809603281,-1.007302579633052,-0.07180007333648186
542.8000000000073,32.428130011302386,-1.0146659702244203,-0.07198150430762196
544.2000000000073,32.47408805183606,-1.0176463924931989,-0.07311819479461734
545.6000000000073,32.51957676696846,-1.0251110756610784,-0.0731197037207032
547.0000000000074,32.56489251324115,-1.0298516864174625,-0.07427563530687253
548.4000000000074,32.610550046779935,-1.0342205960667057,-0.07312109494200669
549.8000000000075,32.65625471109485,-1.039828639403201,-0.07420717318174619
551.2000000000074,32.70206256049028,-1.0465315091567151,-0.074440386648297
552.6000000000074,32.747125670917484,-1.053441019235077,-0.07443995124171376
554.0000000000075,32.79331336513859,-1.056745145023718,-0.07443974643523488
555.4000000000075,32.83923314849218,-1.0622776252711101,-0.07444184591043124
556.8000000000075,32.884747306179825,-1.0707299370203838,-0.0757636215829467
558.2000000000075,32.930868041905654,-1.0781262935106268,-0.07576010549983758
559.6000000000075,32.976437931544325,-1.0816834867381468,-0.07575653176689334
561.0000000000075,33.02226027266088,-1.0903953126710724,-0.0771178821044125
562.4000000000076,33.06824005029006,-1.098588268327135,-0.07706974618754048
563.8000000000076,33.1132459933342,-1.1043939374058693,-0.07743908028835023
565.2000000000077,33.160046349652674,-1.1110402758730544,-0.07839000736720658
566.6000000000076,33.20603036131698,-1.1216030327828455,-0.078384486573424
568.0000000000076,33.251902873602965,-1.127925507729057,-0.07976074039100922
569.4000000000077,33.297794373881146,-1.1385790026974756,-0.08236268324537166
570.8000000000077,33.343691457158286,-1.149446755503171,-0.08104251674797114
572.2000000000078,33.39003854862435,-1.1680192400743863,-0.0810300545202085
573.6000000000078,33.43601498934549,-1.1981664194017958,-0.0810317428899534
575.0000000000077,33.48225316827703,-1.1989938678979895,-0.08220894418134828
576.4000000000078,33.528013168771864,-1.191303455127518,-0.08135563261339573
577.8000000000078,33.57404043439417,-1.1858411002554186,-0.08267648106035219
579.2000000000078,33.619881399420024,-1.1845085816584253,-0.08265772942946059
580.6000000000079,33.665687381609416,-1.1857324674669283,-0.08398826665493297
582.0000000000078,33.71169257898136,-1.1846492428617486,-0.0853895525417041
583.4000000000078,33.75758426990192,-1.1902527124878557,-0.08530025779394323
584.8000000000079,33.80353018595113,-1.1940720553744755,-0.08521389194926243
586.2000000000079,33.84936363285454,-1.1981914441446586,-0.08662028210975192
587.600000000008,33.89556838643326,-1.2043445611313273,-0.08723557142140148
589.000000000008,33.94103302087893,-1.2092337194543177,-0.08930367692428476
590.4000000000079,33.98715010132303,-1.2154591545938223,-0.08925608249965711
591.800000000008,34.03337191008192,-1.2219007977982412,-0.0893395395169807
593.200000000008,34.07959280268756,-1.2263140134970612,-0.08926021810696039
594.6000000000081,34.125103892025805,-1.2336976435366547,-0.08984041631743445
596.0000000000081,34.17125301419689,-1.2405666262999042,-0.09054612760842717
597.400000000008,34.21765147914452,-1.2494114720738865,-0.0918860123885179
598.8000000000081,34.26329177095392,-1.2542301772995588,-0.09189089285877294
600.2000000000081,34.309584364032816,-1.2636378343174859,-0.09258517232115304
601.6000000000081,34.355324324541705,-1.2701276418175513,-0.09320135059556778
603.0000000000082,34.40146498917317,-1.2776724221751063,-0.09454014718019099
604.4000000000082,34.44717217676762,-1.2849781091687413,-0.09454331686763195
605.8000000000081,34.493580266787234,-1.2925196512428825,-0.09590134519027282
607.2000000000082,34.539401195923176,-1.3024904230098986,-0.09584289352157604
608.6000000000082,34.58566343505986,-1.308875407295351,-0.09847127867842298
610.0000000000083,34.63151372469034,-1.318533640967933,-0.09847782882197409
611.4000000000083,34.67695743931674,-1.3288361732880076,-0.09978883159610019
612.8000000000083,34.72369433416241,-1.3345833651112258,-0.09925716410420504
614.2000000000083,34.769928763719484,-1.3440048481959397,-0.09980387349551956
615.6000000000083,34.81594431330127,-1.3520163780763255,-0.10112125067805078
617.0000000000084,34.86196455853514,-1.3593927874058234,-0.10240235082227711
618.4000000000084,34.907806610905105,-1.3662428164881624,-0.10371064359587567
619.8000000000084,34.953833570284004,-1.375023307471719,-0.10398649369935997
621.2000000000085,35.0001374659995,-1.3834508413215256,-0.10624673779908944
622.6000000000084,35.04610641782962,-1.39392412742055,-0.10517810327993526
624.0000000000084,35.09256565446577,-1.3996986079502503,-0.10650822711273111
625.4000000000085,35.13834733012488,-1.4114333543001631,-0.10741645182706483
626.8000000000085,35.18442868486415,-1.4187291664445694,-0.1078145350779467
628.2000000000085,35.23040380339961,-1.4282148038348956,-0.10948157482868615
629.6000000000085,35.27663875362585,-1.4374205271358824,-0.1096254012022504
631.0000000000085,35.32291976322766,-1.4473521123416824,-0.11070201078453135
632.4000000000086,35.36906893486968,-1.4549040261482453,-0.11209429987074104
633.8000000000086,35.41476121856221,-1.46467091949578,-0.11371360550039533
635.2000000000086,35.460848889673116,-1.4777639928343569,-0.1147305679355588
636.6000000000087,35.50686077538358,-1.484601688552527,-0.11491894209747322
638.0000000000086,35.553222532726444,-1.4955201230006407,-0.11764553738354122
639.4000000000087,35.59947271856876,-1.5046219770601927,-0.11889602789474552
640.8000000000087,35.64550848496949,-1.5132197596637975,-0.11950248153974208
642.2000000000087,35.69151986000557,-1.522888933747748,-0.1190877730119273
643.6000000000088,35.737734433623416,-1.5341450909679073,-0.12075872084251182
645.0000000000088,35.784089159478626,-1.546621174277045,-0.12269174564643315
646.4000000000087,35.830211082078044,-1.5564929944184958,-0.12492169137459497
647.8000000000088,35.87671240610995,-1.5712618944663472,-0.12689041180230465
649.2000000000088,35.92301565576217,-1.5811611005653674,-0.12695905778725303
650.6000000000088,35.96891014983551,-1.5932270996372901,-0.12833818698648436
652.0000000000089,36.01558317172629,-1.6060485332939165,-0.1296779240155299
653.4000000000088,36.06165539872993,-1.6222187027036243,-0.13096372989687266
654.8000000000089,36.10825435534368,-1.6350032728931014,-0.1326195972647115
656.2000000000089,36.15440069006776,-1.65147009110949,-0.13494560978889814
657.6000000000089,36.20079186163876,-1.671319876492926,-0.1365754011278857
659.000000000009,36.247140738700296,-1.6869264695689778,-0.13825676831383138
660.400000000009,36.29360084997538,-1.709357786675082,-0.13959277088113398
661.800000000009,36.34020873584479,-1.7335327390934803,-0.14104423549058653
663.200000000009,36.38651026488272,-1.7589298795730672,-0.14251031049612317
664.600000000009,36.432876816606786,-1.785882901902387,-0.14514745335480983
666.0000000000091,36.479655505577,-1.8159594527823983,-0.14645320551793262
667.4000000000091,36.52610863514386,-1.846987965946982,-0.14797037284309011
668.800000000009,36.57286335273035,-1.8778254198078823,-0.15043515904072846
670.2000000000091,36.61933684414398,-1.913788632298684,-0.15204723221581773
671.6000000000091,36.66628043285019,-1.9492086572989435,-0.15465435396930705
673.0000000000091,36.71217530807687,-1.9849256082273192,-0.1575619034382476
674.4000000000092,36.75991600691603,-2.0229436953908664,-0.160793927631107
675.8000000000092,36.80594172583213,-2.064419830273907,-0.16331889113542397
677.2000000000093,36.853445818940386,-2.106785780593459,-0.16567846825055899
678.6000000000092,36.90032363940849,-2.148844470031684,-0.16747780891993047
680.0000000000092,36.94728512942113,-2.1931634286987047,-0.171403999639395
681.4000000000093,36.9941923740933,-2.2360547681865772,-0.17392505906436062
682.8000000000093,37.04110594729415,-2.2824526916015415,-0.177915463097436
684.2000000000094,37.087668015872715,-2.3317729038768653,-0.18166613327258085
685.6000000000093,37.13526438641801,-2.3804090230323247,-0.18569718979835814
687.0000000000093,37.182411214879636,-2.4337417221496196,-0.1891029584264432
688.4000000000094,37.22948026084492,-2.48858649516212,-0.19149268265207953
689.8000000000094,37.276946716049544,-2.549842355424996,-0.19648010242344727
691.2000000000094,37.3239542479491,-2.6051928072863486,-0.20232691826140448
692.6000000000095,37.37130411381852,-2.6606034091812174,-0.2065209560230139
694.0000000000094,37.41871640820003,-2.722673426736827,-0.2106295368137312
695.4000000000094,37.46604053042044,-2.790388148808946,-0.2167456614485248
696.8000000000095,37.51340270214532,-2.8547774274924453,-0.2215027162838381
698.2000000000095,37.56069875234076,-2.9246835187882554,-0.22641714070339924
699.6000000000096,37.60813849491081,-2.992776008429519,-0.23288780100725015
701.0000000000095,37.655967126093074,-3.0695953222684467,-0.23837860367627117
702.4000000000095,37.70306593494995,-3.14365138831314,-0.24331316102801237
703.8000000000096,37.75076593803835,-3.22420314822719,-0.24992824772848854
705.2000000000096,37.79825733041311,-3.300692429561898,-0.2566076992036779
706.6000000000097,37.84587358880929,-3.3843791967762185,-0.26401774928923727
708.0000000000097,37.89341111619175,-3.466771035886276,-0.2717625480620254
709.4000000000096,37.941198736601976,-3.5511677929378647,-0.27751181785918533
710.8000000000097,37.98849703484924,-3.641400039714592,-0.2859649850921966
712.2000000000097,38.036300062121,-3.731598778796752,-0.2941997269725549
713.6000000000097,38.08389158267701,-3.8259428485442823,-0.3024882004496119
715.0000000000098,38.13104984919523,-3.9166261751054066,-0.3095566056564363
716.4000000000098,38.179306672666584,-4.018080041743027,-0.3184154716071985
717.8000000000097,38.2269779548351,-4.11933245427715,-0.3290153580692965
719.2000000000098,38.27437900070038,-4.22007717666284,-0.3364665241700009
720.6000000000098,38.32234522781493,-4.326990199542001,-0.342783123358656
722.0000000000099,38.37022142346031,-4.431108427979769,-0.35676633778452604
723.4000000000099,38.41824522708173,-4.5434728407291685,-0.3708285336312813
724.8000000000098,38.46583982609302,-4.655291592466448,-0.3813138040618633
726.2000000000099,38.51358957529404,-4.769948877430361,-0.39262931184285277
727.6000000000099,38.561369112510675,-4.88534198991988,-0.4028134699913051
729.00000000001,38.60944267225873,-4.998521037913562,-0.4144983025065274
730.40000000001,38.65708205831218,-5.118110022491744,-0.4275531044676524
731.80000000001,38.70505243721711,-5.236321903931644,-0.44058106185868207
733.20000000001,38.753114159552915,-5.35189082344327,-0.45336268307477257
734.60000000001,38.80108699893547,-5.476421431212967,-0.46759760044588106
736.00000000001,38.848640608438544,-5.59442175768605,-0.48150269491160724
737.4000000000101,38.896504217917865,-5.715777619982776,-0.49543399946885636
738.8000000000101,38.944718522681164,-5.842607489412766,-0.5102046644053315
740.20000000001,38.992247634730575,-5.960873231675294,-0.52251619244513
741.6000000000101,39.03957906037614,-6.084470487246878,-0.5431813592045436
743.0000000000101,39.088047923084815,-6.204921176823968,-0.5589285456696564
744.4000000000102,39.136059223129905,-6.327095897839023,-0.5747951436435512
745.8000000000102,39.183699937242466,-6.449170383108244,-0.5914261507523371
747.2000000000102,39.23154146940017,-6.567968180201546,-0.6087719147432096
748.6000000000103,39.279540258850844,-6.682318517897555,-0.6269021223803914
750.0000000000102,39.327423428233075,-6.801420023188341,-0.6446989596707975
751.4000000000103,39.37535142851034,-6.913418159154393,-0.6637229898979222
752.8000000000103,39.423081289257716,-7.028050939221689,-0.6815623294958146
754.2000000000103,39.470809277915485,-7.135468217001519,-0.7025943742108658
755.6000000000104,39.5189300468702,-7.249085217779022,-0.7222792511552636
757.0000000000103,39.56663292634115,-7.356561104408717,-0.7403802182061159
758.4000000000103,39.614626186588254,-7.4647683867819,-0.7602205988602377
759.8000000000104,39.66242602080102,-7.572447634705391,-0.7818418809011947
761.2000000000104,39.710322765602974,-7.679706470548535,-0.8039341066214987
762.6000000000104,39.7583104377244,-7.79475164929462,-0.8264945097652636
764.0000000000105,39.80608028296807,-7.909399972099449,-0.8488675174432858
765.4000000000104,39.854355686240396,-8.02479142215611,-0.8713741612646921
766.8000000000105,39.90230354693381,-8.145363524199798,-0.8936330009607198
768.2000000000105,39.950264923812874,-8.278075021121243,-0.9178442178545732
769.6000000000105,39.99853364423167,-8.41076682872675,-0.9443573805882397
771.0000000000106,40.046904678915396,-8.543751993829085,-0.968385476143184
772.4000000000106,40.09488335045152,-8.684795953942597,-0.9920706089648883
773.8000000000106,40.14276146354991,-8.824627561964427,-1.0164807680276464
775.2000000000106,40.19099022542328,-8.956952854655345,-1.042758591550494
776.6000000000106,40.23917068108023,-9.078611696616404,-1.0704002864158069
778.0000000000107,40.28683969032656,-9.188127533835164,-1.095023351922368
779.4000000000107,40.334989949562676,-9.286741048190857,-1.1198056771326148
780.8000000000106,40.38284640695673,-9.370868168899321,-1.147095433416697
782.2000000000107,40.43054528219442,-9.446584974861237,-1.1732563993493375
783.6000000000107,40.47861118897876,-9.539236676305318,-1.19861649067049
785.0000000000107,40.52612349937023,-9.644828545831267,-1.2229512166207002
786.4000000000108,40.57450906320168,-9.761070456189934,-1.2491262003837589
787.8000000000108,40.6221726771717,-9.835929095180589,-1.2758110073343008
789.2000000000108,40.66916965949802,-9.849330348584463,-1.304019834383379
790.6000000000108,40.71528825151753,-9.710242641026843,-1.3285851879681325
792.0000000000108,40.75986345618759,-9.395443874083847,-1.3498354303644016
793.4000000000109,40.80306238325678,-8.83218245052878,-1.3725968873796202
794.8000000000109,40.84352115457182,-7.9896398695534465,-1.3922720545217961
796.200000000011,40.88106174987428,-6.754942992444212,-1.408836618955001
797.6000000000109,40.91781778060303,-5.363177888974505,-1.4217059201544155
799.0000000000109,40.95579190365785,-4.157963396778417,-1.432182470457089
800.400000000011,40.99507004905452,-3.241266553206929,-1.4385624295026118
801.800000000011,41.03688020605573,-2.569659053612216,-1.441587646548406
803.200000000011,41.080104375162826,-2.124158281160888,-1.4440519873339102
804.600000000011,41.124605562750254,-1.8321506807827879,-1.4440367433244723
806.000000000011,41.170247580212326,-1.6776116098659963,-1.4455085448271654
807.400000000011,41.21627349787073,-1.5988317839654518,-1.4468242647534235
808.8000000000111,41.26311948671809,-1.5330098291223262,-1.4468399167976576
810.2000000000111,41.309651504745474,-1.513776661287981,-1.446839839931418
811.6000000000112,41.356665418458874,-1.497738005886739,-1.4467503939082516
813.0000000000111,41.40393976327098,-1.4949131102039277,-1.4478389276703676
814.4000000000111,41.45090690527377,-1.4951485322964286,-1.4468512308643682
815.8000000000112,41.49806542379144,-1.50050841959244,-1.4468500341811072
817.2000000000112,41.545069708615465,-1.5052090588112397,-1.446862713982469
818.6000000000113,41.5922461726916,-1.5096964188465725,-1.4481451924260145
820.0000000000113,41.639435207007864,-1.5146175667635504,-1.4468760587586513
821.4000000000112,41.68709233048691,-1.5201155494316583,-1.4468398259073334
822.8000000000113,41.73429832608744,-1.524548298416281,-1.4468398640571318
824.2000000000113,41.7814698619024,-1.5321091589709657,-1.4468398542767367
825.6000000000113,41.82809368170767,-1.5376728377856554,-1.4468376494482178
827.0000000000114,41.87623436119845,-1.542855768476291,-1.4481644905039688
828.4000000000113,41.9232171373604,-1.5492484709598873,-1.4481600377160015
829.8000000000113,41.97094527688979,-1.555076903627365,-1.4482536444965426
831.2000000000114,42.01763987974698,-1.5595127723544082,-1.4473839048328694
832.6000000000114,42.06579699238434,-1.5629622705431703,-1.4481594737366552
834.0000000000115,42.11317802744714,-1.5705772279618175,-1.448159996130745
835.4000000000115,42.16050619590906,-1.5752422552624765,-1.448208670525311
836.8000000000114,42.20800348280953,-1.5798442333205016,-1.448229754450567
838.2000000000115,42.25523599588783,-1.582676384597245,-1.4494762526365386
839.6000000000115,42.302758380078146,-1.5840395483629377,-1.4494701687808895
841.0000000000116,42.35013673469907,-1.5890106272220812,-1.4494700584106872
842.4000000000116,42.39755356163771,-1.5937842472653605,-1.4495518254386193
843.8000000000116,42.4450274797018,-1.5964390974238079,-1.4481599461532344
845.2000000000116,42.49236272834649,-1.6011553587609775,-1.4480915533420102
846.6000000000116,42.540155697970675,-1.6065770109004525,-1.4494801298229647
848.0000000000116,42.58771691290712,-1.6120984617174134,-1.4494799653197261
849.4000000000117,42.6352069225291,-1.6186818060721802,-1.449474549170049
850.8000000000117,42.68249356556773,-1.6217447482167888,-1.4495673211328564
852.2000000000116,42.73010574100086,-1.625187206074658,-1.4494800997478339
853.6000000000117,42.777598600531626,-1.6313727353450023,-1.4494801141687792
855.0000000000117,42.82514438852556,-1.6348449662358233,-1.4494795902901143
856.4000000000118,42.87266419665318,-1.6405283693648673,-1.4497749626693017
857.8000000000118,42.91985501285313,-1.6467823745889107,-1.4507898861998085
859.2000000000118,42.96731660935961,-1.651644232000541,-1.4507899311449712
860.6000000000118,43.01514967612154,-1.655551403218999,-1.4507901245501489
862.0000000000118,43.06280964257595,-1.660370574499522,-1.4508061819252451
863.4000000000119,43.110340706111764,-1.663320204923139,-1.4494696735686436
864.8000000000119,43.15761456959439,-1.667166115041134,-1.4508229287878622
866.2000000000119,43.20503050142554,-1.6735309861513075,-1.4507472541893764
867.600000000012,43.252693053039415,-1.673765451190271,-1.4518676864531876
869.0000000000119,43.30021816676881,-1.677588734667383,-1.4520824164289885
870.4000000000119,43.34739837644454,-1.6828500847655936,-1.4507923153465891
871.800000000012,43.39496500550798,-1.6875164482603613,-1.4511110683835517
873.200000000012,43.44232741977031,-1.6920383372472392,-1.4521090754931576
874.600000000012,43.48999267418797,-1.6965488797245178,-1.4521020980286452
876.000000000012,43.53760428569976,-1.7013608758238157,-1.453415539205817
877.400000000012,43.58482018583017,-1.7069765622971265,-1.4529111574628888
878.8000000000121,43.63218323406203,-1.7105918735192809,-1.452110101857449
880.2000000000121,43.67973377669572,-1.7151418442090969,-1.4521100599941419
881.6000000000121,43.72683950391229,-1.719952096423877,-1.453469517426532
883.0000000000122,43.774608995102554,-1.7256049997949618,-1.4534548805051033
884.4000000000121,43.82212206923051,-1.7304046160068844,-1.4547486786321198
885.8000000000122,43.86957101759336,-1.733296180895883,-1.4547357802757301
887.2000000000122,43.916893117073386,-1.7392589218802232,-1.4537675375334458
888.6000000000122,43.96435325272131,-1.7424521897503462,-1.4534368306704386
890.0000000000123,44.01179740175381,-1.7468589724961456,-1.4534455673929711
891.4000000000123,44.05903380303401,-1.7488212554068694,-1.4524266300888566
892.0000000000123,44.07937619173314,-1.7498512804625537,-1.4534266341826139