File: 01_Data/Nylon_Carpet_Low_Pile/STA/N2/10K_min/Nylon_Carpet_Low_Pile_STA_N2_10KData_220105_R1.csv
##Temp./Â°C,Time/min,DSC/(mW/mg),Mass loss/mg
50.0,10.751940566985862,-0.9014694202627324,0.018909619333385308
51.100000000000016,11.052388548175802,-0.7944064451646088,0.020212798472747373
52.20000000000003,11.262705805261593,-0.7195122340253107,0.019047430040984636
53.30000000000005,11.440145920858319,-0.6650645526024135,0.020480409729706217
54.40000000000006,11.598402791621021,-0.6178509691922639,0.020060372795792425
55.50000000000008,11.744322412379338,-0.5833901830271586,0.01978350647931304
56.600000000000094,11.886176677864096,-0.5535232845861429,0.01964654569633595
57.70000000000011,12.021535400848977,-0.5281739078583552,0.02089096942462465
58.800000000000125,12.152492637000167,-0.5072465972529474,0.022179434354770322
59.90000000000014,12.277551519415708,-0.4890901249010288,0.02076763186696695
61.000000000000156,12.40500709963445,-0.4724041824451147,0.021091963042498385
62.10000000000017,12.52475350590593,-0.45763482370387465,0.02242604322866182
63.20000000000019,12.653908622334752,-0.44374607289391194,0.020951973924120182
64.30000000000021,12.772605166659215,-0.4310281818237528,0.021172685633880306
65.40000000000022,12.89395816453306,-0.41881339691403074,0.022293958378623024
66.50000000000023,13.014280266131117,-0.4071551997547603,0.021285147103232482
67.60000000000025,13.133179850958564,-0.39695979716648905,0.0209858909521623
68.70000000000027,13.250499717960187,-0.3860859088050936,0.02184866063305435
69.80000000000028,13.36851922031019,-0.3762855344459849,0.023542082314036428
70.90000000000029,13.48751648293467,-0.36582318274420966,0.022139336014666
72.00000000000031,13.604632653862819,-0.3587073318024633,0.02358995558054744
73.10000000000034,13.720188471648129,-0.34673851698844466,0.023591731106648695
74.20000000000034,13.832759665249764,-0.3379006192235902,0.022871075666862417
75.30000000000035,13.950883661603662,-0.3284602277141871,0.023589167523778265
76.40000000000038,14.06718491089024,-0.3181599106081392,0.023591872081507148
77.5000000000004,14.18185821023838,-0.30971438367827897,0.023559771044103783
78.6000000000004,14.296817411878916,-0.30135576313828466,0.02259005708347317
79.70000000000041,14.4081864755781,-0.29154214821576063,0.022277145185055858
80.80000000000044,14.521061174179447,-0.28354090693551215,0.02226983035849006
81.90000000000046,14.63521343800043,-0.2758370855138406,0.022284583203616926
83.00000000000047,14.747249885431826,-0.2667808181440845,0.020300113666987585
84.10000000000048,14.86111852193417,-0.25823932189450105,0.020299021620288293
85.2000000000005,14.972629190713196,-0.2492544209503493,0.019086339442715428
86.30000000000052,15.084696912434145,-0.2414306406185964,0.020300010246629085
87.40000000000053,15.195871973723756,-0.2348646835790165,0.02161521222989382
88.50000000000054,15.306761888181066,-0.22687303276895246,0.02294011770375448
89.60000000000056,15.415634165062336,-0.219610025257819,0.02284515490138439
90.70000000000059,15.52756746697671,-0.211142054025579,0.022927664909334844
91.8000000000006,15.637219456879155,-0.20372678224553198,0.0227326199933362
92.9000000000006,15.748392227243352,-0.19593380677218108,0.02161716679870551
94.00000000000063,15.858196957509623,-0.1894840627845765,0.0229124335010642
95.10000000000065,15.96559638194593,-0.18200023782277217,0.02164814730002007
96.20000000000066,16.075290676216014,-0.17526978371686824,0.02227669009250377
97.30000000000067,16.18454002959381,-0.1665056382469963,0.023622063230100743
98.40000000000069,16.29353106180342,-0.16057537172402447,0.022280115025963276
99.50000000000071,16.402413157882606,-0.1530369656791456,0.0235673970603143
100.60000000000072,16.51104847226179,-0.14651876476584125,0.02096752998831697
101.70000000000073,16.619441010479452,-0.13973640920910288,0.02095932599493544
102.80000000000075,16.728522647771733,-0.13311436272022278,0.01963810428237256
103.90000000000077,16.835868984892603,-0.1273230305832652,0.020959743628700345
105.00000000000078,16.944107314438856,-0.1192074990702158,0.019837861529725664
106.10000000000079,17.052584898543095,-0.1127640682912548,0.020953603449100022
107.20000000000081,17.160948026155914,-0.10603637503068,0.022269920617662642
108.30000000000084,17.26799491409052,-0.1011622786865551,0.023160048643660502
109.40000000000084,17.37703907784661,-0.09643043221012261,0.02358068017993098
110.50000000000085,17.48349068562604,-0.08976921731084282,0.02226712428658928
111.60000000000088,17.592367653566757,-0.08279396277804177,0.01970817335135777
112.7000000000009,17.700108275696596,-0.07820466483246238,0.019640190862353357
113.8000000000009,17.80672653347019,-0.07230547745336964,0.019673382962920094
114.90000000000092,17.914232206349702,-0.06750785077515788,0.018372746573954046
116.00000000000094,18.02308859654727,-0.06054602750968039,0.018607457567260788
117.10000000000096,18.12930018614157,-0.05366215385689967,0.01996911945879898
118.20000000000097,18.236192814259805,-0.04972319460470447,0.020623503434508805
119.30000000000098,18.344819860285174,-0.04354161482912649,0.02029989026076162
120.400000000001,18.452812074519525,-0.0367420454941869,0.021152417118999622
121.50000000000102,18.5596931108526,-0.03401060012065789,0.0186650553952461
122.60000000000103,18.666880620648826,-0.028316403222770233,0.01894970333115431
123.70000000000104,18.774932456575343,-0.02511101021780319,0.019113316604432384
124.80000000000106,18.880547652233748,-0.015951931718542665,0.019970132995311474
125.90000000000109,18.98864978476091,-0.013647091590962793,0.019970132104035976
127.0000000000011,19.095694730365953,-0.008070685105677551,0.021295077621850567
128.1000000000011,19.20288611588082,-0.002098149529810274,0.01996243221388383
129.20000000000113,19.309148101291292,0.0031237996791620114,0.01780415674543523
130.30000000000115,19.415277062467684,0.009107722914444462,0.018677270936019674
131.40000000000117,19.524021696091783,0.01375604123103517,0.0187080893933258
132.50000000000117,19.630857004580267,0.01892945384631416,0.018649807894883352
133.6000000000012,19.736638859764398,0.02448399202532483,0.01997666132084941
134.7000000000012,19.842989578762367,0.030689303934969665,0.018678758917087812
135.8000000000012,19.949812722704287,0.035522833821326184,0.020095863907263478
136.90000000000123,20.055781927745706,0.04141121768472705,0.018638036658537693
138.00000000000125,20.161404703342217,0.046247499743147444,0.01734046126999811
139.10000000000127,20.268864101706317,0.052649851235825,0.018720120912488092
140.2000000000013,20.375276684719672,0.05890337588229142,0.016679888680533494
141.3000000000013,20.481261806132352,0.06622626980782384,0.017664235348800794
142.4000000000013,20.58781959908472,0.0697203288260823,0.016233140130529122
143.50000000000134,20.693587106546598,0.07676166753986358,0.016326075111028793
144.60000000000133,20.798879580911155,0.08324897980449926,0.015326822321236833
145.70000000000135,20.90545208141527,0.08829502482187156,0.01668019096959128
146.80000000000138,21.011585640383952,0.09565626227247707,0.017005275836119438
147.9000000000014,21.117887199792015,0.10264838526303456,0.01692395635188504
149.00000000000142,21.223960900557437,0.1087006604911066,0.018312253303744086
150.10000000000142,21.329450324569276,0.1170106856955096,0.01734009530312175
151.20000000000144,21.436383586333378,0.1251779309779641,0.017339878991231572
152.30000000000146,21.54214031013078,0.13294498840235636,0.01734811029886263
153.40000000000146,21.64642699070766,0.13953368541478423,0.017989894465034517
154.50000000000148,21.754104167618184,0.14990539138890627,0.0179912170647496
155.6000000000015,21.858056756686107,0.15905425956350308,0.016417300016557945
156.70000000000152,21.966134854085226,0.1679261501212006,0.016355146186280756
157.80000000000155,22.071026407651793,0.17818440803207225,0.01568994620521824
158.90000000000154,22.17387485047555,0.1909189662003131,0.0156899459999984
160.00000000000156,22.28197261295519,0.20551452500247563,0.015689946000010835
161.1000000000016,22.386585457955995,0.21815823015996538,0.01568998085625406
162.20000000000158,22.493846817509507,0.23152670951299895,0.015076439843050515
163.3000000000016,22.598932782446976,0.2441201367860436,0.014377102359639515
164.40000000000163,22.70476303288515,0.25456857308988445,0.015040411693741262
165.50000000000165,22.80873186830171,0.2609135455447443,0.015040018662946686
166.60000000000167,22.915847915943598,0.2624181625268221,0.013720049666972045
167.70000000000167,23.020942628625942,0.25796445486693964,0.013720060937252754
168.8000000000017,23.12746363020042,0.2515668589865736,0.014369864916268682
169.9000000000017,23.23345098791637,0.24441091891858752,0.01460855315934051
171.0000000000017,23.338455621965604,0.2372060989666061,0.014386082829108915
172.10000000000173,23.443859810890128,0.23368765064438812,0.013150226739491622
173.20000000000175,23.54874051815045,0.23126204911201326,0.01234444774041954
174.30000000000177,23.654535157120065,0.22925486558684482,0.014220348098739954
175.4000000000018,23.760098751627083,0.23208221568293683,0.013391040056796477
176.5000000000018,23.865544550473814,0.23369407359011038,0.013592623614591126
177.6000000000018,23.970911010599714,0.2381404061826414,0.015118577629364083
178.70000000000184,24.07701017470853,0.24161952293218408,0.015699887551479108
179.80000000000183,24.18130385424471,0.24685811654896997,0.015699887989556238
180.90000000000185,24.28693707597783,0.25104869762065196,0.015692700722342856
182.00000000000188,24.39469319140392,0.25657704956197064,0.01436360568870576
183.1000000000019,24.498184669879997,0.2622487055817829,0.013059827354908293
184.20000000000192,24.600257993450054,0.2685005515226854,0.011751412579186216
185.30000000000192,24.70784197385396,0.27338433546604124,0.011827192338638604
186.40000000000194,24.81380454327643,0.2787899479380957,0.011751610157228143
187.50000000000196,24.91829068852307,0.2833687446062888,0.0142997465482404
188.60000000000196,25.024658553549912,0.28766665508689465,0.014376602521783965
189.70000000000198,25.128780880850368,0.29264886626121656,0.014017884405440384
190.800000000002,25.234756423641358,0.2968971413483287,0.01405001868757072
191.90000000000202,25.340527548871247,0.30302715459124446,0.012731963770978183
193.00000000000205,25.444769423559155,0.30717641924451067,0.011502466577316461
194.10000000000204,25.55080496620707,0.3125331907130017,0.010100014864638851
195.20000000000206,25.6560607207444,0.3173748128913741,0.011403271532767434
196.3000000000021,25.760935635146424,0.32326442468301275,0.011410024007606268
197.40000000000208,25.867393306568033,0.32831381352466177,0.01141002399999902
198.5000000000021,25.97229579902594,0.3320810080500028,0.01141002399999902
199.60000000000213,26.078481989367425,0.3371433602669168,0.011410023999999908
200.70000000000215,26.184432171171487,0.3428392472249434,0.011410025387658784
201.80000000000217,26.28847975301932,0.35078301267145623,0.01010884488630115
202.90000000000217,26.39433872892784,0.3555931636436303,0.01010665611007866
204.0000000000022,26.50036442511625,0.36214669489364915,0.009765503899430428
205.1000000000022,26.60561629631956,0.3682321489722014,0.011640804227564416
206.2000000000022,26.710274839733472,0.37485737270197356,0.011740113983895739
207.30000000000223,26.816497082176447,0.3828537313456764,0.011745796923136709
208.40000000000225,26.921396078316,0.3898626996159123,0.010420115095217675
209.50000000000227,27.026731009990016,0.3981339795695673,0.009303076486316009
210.6000000000023,27.132173865134927,0.40768848553984177,0.009110113955674848
211.7000000000023,27.23698762284417,0.4194830710279716,0.009110114000030478
212.8000000000023,27.342508628434455,0.43494147586377974,0.009110099252916726
213.90000000000234,27.44653762369868,0.4575710625145561,0.007786334604998224
215.00000000000233,27.551308667394323,0.4919108794478321,0.009164355318137751
216.10000000000235,27.656189876496818,0.5414609847318284,0.009109831966261694
217.20000000000238,27.762723269824104,0.6055728331983777,0.009460032131180185
218.3000000000024,27.867292626905147,0.6728389977827203,0.009440103256374677
219.40000000000242,27.972599479780776,0.7368693517006054,0.010760247966059566
220.50000000000242,28.078165305882912,0.7865045177104242,0.010734717942233019
221.60000000000244,28.18470804595639,0.8089615127268625,0.010099849241168357
222.70000000000246,28.288657057815534,0.7915226910391052,0.010099850999996995
223.80000000000246,28.39605884146004,0.7349370742942206,0.010099851000313187
224.90000000000248,28.501329343344988,0.6658475644756507,0.010100110844393662
226.0000000000025,28.606336770355366,0.6032006437393005,0.009428296044662332
227.10000000000252,28.711750816413822,0.5585909670196153,0.008119851993352079
228.20000000000255,28.8165797755871,0.525836173018898,0.009452888565043338
229.30000000000254,28.92041766921768,0.5022063341828231,0.00811984502136287
230.40000000000256,29.02483479209682,0.48742640748119215,0.008174508827570648
231.5000000000026,29.12781516137891,0.48049543216110224,0.0074633613854429015
232.60000000000258,29.235633381450153,0.47461770256729524,0.008888169667534918
233.7000000000026,29.33947991953667,0.4753767191220694,0.007140489559501972
234.80000000000263,29.444721239389672,0.4753203079033566,0.007139874000087865
235.90000000000265,29.549904745989796,0.4771995475883112,0.007140376238387702
237.00000000000267,29.654866148932676,0.48088174905217657,0.005819850536742166
238.10000000000267,29.76018693462505,0.48158013764848273,0.005819873992566116
239.2000000000027,29.8646958543481,0.4874923313577971,0.005667376223802201
240.3000000000027,29.97029945123804,0.4912527062840291,0.0041802109363375806
241.4000000000027,30.074649642599976,0.49439399895895675,0.0028601600702140573
242.50000000000273,30.179716971663556,0.4976953874837796,0.004170862132221842
243.60000000000275,30.283732697293594,0.5023821078278671,0.004179851063998541
244.70000000000277,30.39026213123586,0.5050009876852146,0.004179851490760278
245.8000000000028,30.49429287045809,0.5073483715001043,0.005501106520806154
246.9000000000028,30.599897777938143,0.5124265732224135,0.005499943000017993
248.0000000000028,30.70494007590748,0.5149298996698116,0.005499938151126038
249.10000000000284,30.810913581156978,0.5176081239289617,0.004182783913618593
250.20000000000283,30.91513831845217,0.5216741845352556,0.004179944868538676
251.30000000000285,31.02117152454188,0.5240696030919373,0.0028553185122612845
252.40000000000288,31.12536669185257,0.5290650449714391,0.004169457486661976
253.5000000000029,31.231783847393466,0.5304753275732502,0.004179948818101131
254.60000000000292,31.336825715739167,0.534909134676608,0.0016869594706641067
255.70000000000292,31.44199822141947,0.5379952360928238,0.0028554666817273144
256.8000000000029,31.54666151841692,0.5422927983066144,0.003860004877449086
257.90000000000293,31.65286601815977,0.5458752183354533,0.0038499429966281085
259.00000000000296,31.757104205032306,0.5495367245984636,0.0038499429999978574
260.100000000003,31.861762326028344,0.5531597166036631,0.003849944382219306
261.200000000003,31.967617824723618,0.5568025432129544,0.0028601664995937526
262.300000000003,32.073044807067284,0.5602685306460364,0.0025299203319395502
263.40000000000305,32.17788933071575,0.5634405122747109,0.002529919999997965
264.50000000000307,32.283130967965874,0.565799227532121,0.002529921253923817
265.6000000000031,32.388035921752994,0.5684353045964041,0.0012410651030627662
266.7000000000031,32.492980013007795,0.5725507170002284,0.0013343540024539635
267.8000000000031,32.59796353806257,0.5749084613990749,0.002538029170172429
268.9000000000031,32.704862156176134,0.5796312503866954,0.0008898732218609595
270.0000000000031,32.81069020577724,0.5840269657801208,0.0008898740020324425
271.10000000000315,32.915721640942074,0.5849952161124491,0.0008780715277598716
272.2000000000032,33.020284089786514,0.587747021629394,0.0018694307649314013
273.30000000000314,33.1255745330857,0.5910021491554825,0.0015398533282429128
274.40000000000316,33.23131157408314,0.59392821963945,0.0015398509999977605
275.5000000000032,33.337058977403714,0.5952098080922215,0.0015398510074398075
276.6000000000032,33.44194713637503,0.602008122680625,0.0015362969696175455
277.70000000000323,33.54682889920224,0.6056799723511884,0.00022988328915651834
278.80000000000325,33.65349288556249,0.6074313755785462,-0.001091022026816546
279.9000000000033,33.75732750283749,0.6128956782571771,-0.001093587884115621
281.0000000000033,33.86388292790128,0.6163416431448898,0.0003053904538585783
282.1000000000033,33.969506201616795,0.6200058716103204,-0.0024098451960572476
283.20000000000334,34.07371062662285,0.6224326350438915,-0.002409839999983454
284.30000000000337,34.17907603680073,0.6261572670614483,-0.0024098399999994413
285.40000000000333,34.28507268173887,0.6292095021901337,-0.0024098699897470155
286.50000000000335,34.38979637494705,0.632282106806417,-0.0033994944830730844
287.6000000000034,34.49553019796462,0.636099127702567,-0.004820214597850203
288.7000000000034,34.59999895698779,0.6401599090439278,-0.0035101690143717335
289.8000000000034,34.70604077214952,0.6418644543715516,-0.003511791707783374
290.9000000000034,34.81122253808024,0.6462740065066155,-0.004820172477583817
292.0000000000034,34.91667833549832,0.6465067130775585,-0.004820183900804409
293.10000000000343,35.022353979211985,0.6501682628835035,-0.00579740804025608
294.20000000000346,35.127296362020026,0.6552554676353641,-0.005809849985585203
295.3000000000035,35.23377396582955,0.6560542370929618,-0.005809849999998562
296.4000000000035,35.33900494340386,0.6604327418471638,-0.0058098509394399755
297.5000000000035,35.44503165229034,0.6637289176247066,-0.006135689095821739
298.60000000000355,35.5509534230044,0.6685106174321913,-0.006141032430231341
299.70000000000357,35.65687908816175,0.6711162739359774,-0.007775450923086957
300.8000000000036,35.76178657451495,0.6748742964912323,-0.007790706932556013
301.9000000000036,35.8693900178165,0.6794508118846344,-0.01041048675884415
303.0000000000036,35.97460561253601,0.6830502480533338,-0.009099555058086573
304.1000000000036,36.08030158648106,0.6897977743526253,-0.010404962963847186
305.2000000000036,36.1866782329438,0.6930465459239961,-0.010341092940383323
306.30000000000365,36.29318007146482,0.6980855803935287,-0.012401740628422253
307.4000000000037,36.39853103747743,0.6998647320123371,-0.01431975493993054
308.5000000000037,36.50444810085623,0.7052535920062663,-0.013699966732828806
309.60000000000366,36.610697830842504,0.7083553404393658,-0.014360058233074735
310.7000000000037,36.71598712065119,0.7147071606975411,-0.01712659979269482
311.8000000000037,36.819891835637435,0.7184340873561194,-0.017297113929916286
312.90000000000373,36.92829582847396,0.723707234901758,-0.018309523958166096
314.00000000000375,37.035174691913234,0.7287840661027155,-0.01830972890478666
315.1000000000038,37.14063775347668,0.7332227380324756,-0.019630104877840893
316.2000000000038,37.24624133185134,0.7363975421885404,-0.02093357252348582
317.3000000000038,37.3527724503137,0.7410907811752885,-0.02357033347823112
318.40000000000384,37.457884141315446,0.7448101449437685,-0.024840000198155465
319.5000000000038,37.56459290899538,0.7489728183449538,-0.027577940685834523
320.60000000000383,37.67165257528455,0.7542385569490294,-0.028841488607564525
321.70000000000385,37.77671194291346,0.7604230573647628,-0.031499542104409084
322.8000000000039,37.882976294532995,0.7667728841549138,-0.03369805289728012
323.9000000000039,37.98830074434594,0.7715456800737266,-0.03541180037947722
325.0000000000039,38.09380437743435,0.7771313996094108,-0.03690206959539122
326.10000000000394,38.20119003090883,0.7819330671418061,-0.04074844119879195
327.2000000000039,38.305806021822164,0.7877202181054,-0.04333177349328787
328.30000000000393,38.41373999087914,0.7944478777686548,-0.04596645387290543
329.40000000000396,38.52038552332524,0.8021417823832351,-0.048684157130797434
330.500000000004,38.62568195023096,0.8077971782223512,-0.05225094680363984
331.600000000004,38.73224056585248,0.8152289120908345,-0.053969045352265876
332.700000000004,38.83793495424404,0.8237261668445588,-0.05789236968704303
333.80000000000405,38.94489280117364,0.8306776177975217,-0.06208900686940799
334.90000000000407,39.05098213142686,0.8392868834432692,-0.0665657692765409
336.0000000000041,39.157856609622655,0.8477055185952598,-0.07092974513251082
337.10000000000406,39.262881403984316,0.8563160919239046,-0.07523616399415278
338.2000000000041,39.36770672913019,0.8648361904661049,-0.07962032491424242
339.3000000000041,39.47726569454838,0.8736761538677894,-0.08386503302502657
340.4000000000041,39.58377226091052,0.8821874243171868,-0.08993786243501933
341.50000000000415,39.69078093025227,0.8915415133287317,-0.09658500103406586
342.6000000000042,39.79796171066397,0.9025340961306727,-0.10118159612405364
343.7000000000042,39.903791004970735,0.912969778149037,-0.11107728223823976
344.80000000000416,40.01144192848645,0.924971380236179,-0.11820137528787189
345.9000000000042,40.11721925037729,0.9364116930154264,-0.12504554746056584
347.0000000000042,40.223353707878815,0.949061401664512,-0.13304060263771023
348.10000000000423,40.33139040186735,0.9614181088049009,-0.1403266570245174
349.20000000000425,40.43801624547595,0.9741151926691373,-0.14839352481011758
350.3000000000043,40.54369392941996,0.9843804818698818,-0.15764370879532708
351.4000000000043,40.65120047017083,0.9986720384879951,-0.1674764799564481
352.5000000000043,40.75864041685328,1.010934117032491,-0.17589910751976
353.60000000000434,40.86372572575572,1.0253736270566496,-0.1865886265230845
354.7000000000043,40.97233596202452,1.0379032926386924,-0.19728900224587687
355.80000000000433,41.077708079162406,1.0499043031885655,-0.2092026903777957
356.90000000000435,41.18394854676256,1.0625060188962516,-0.2199070207685958
358.0000000000044,41.29109872130247,1.0747522707179495,-0.23198092436927098
359.1000000000044,41.3981548040009,1.0880880869535994,-0.24571949433942386
360.2000000000044,41.50461772580118,1.1005756822468555,-0.259888350452532
361.30000000000445,41.61038755522542,1.1129151165365265,-0.2721762118359048
362.4000000000044,41.71773696541562,1.12683519244673,-0.28555092125213477
363.50000000000443,41.82313081170384,1.139064763104848,-0.30168083889929154
364.60000000000446,41.9318509358035,1.1531617658958262,-0.3163080679812529
365.7000000000045,42.03749489869172,1.1628585965025826,-0.33299239983561524
366.8000000000045,42.14468925401257,1.1766886279636875,-0.348379580617153
367.9000000000045,42.25179662525705,1.1898241889008325,-0.3642297454904839
369.00000000000455,42.35979016645139,1.2035750366832856,-0.38142867799279934
370.10000000000457,42.465469685961395,1.2157925169863013,-0.3970139784181832
371.2000000000046,42.5729916497975,1.2306965942402976,-0.41591495145377166
372.30000000000456,42.6804629469476,1.2455566882351892,-0.4322680038716795
373.4000000000046,42.78682179729178,1.2575170721462599,-0.4517354996221341
374.5000000000046,42.892932765453,1.271600190736792,-0.47116251191687164
375.6000000000046,43.00070750835508,1.286717098131436,-0.49000894795898775
376.70000000000465,43.107938183717,1.303936962537389,-0.5100218343709204
377.8000000000047,43.21457505593066,1.3176774441588153,-0.5320216094772112
378.9000000000047,43.3214293557668,1.3315624308447471,-0.5520697330199624
380.00000000000466,43.428751073198185,1.3483728261030263,-0.5771494278971914
381.1000000000047,43.535075308230134,1.3634350008675462,-0.6013776231788008
382.2000000000047,43.64378852737884,1.3774985015018575,-0.6269737924383953
383.30000000000473,43.75067518616873,1.392605380275229,-0.6526491109229315
384.40000000000475,43.85799880619029,1.407408539945316,-0.6766164939897057
385.5000000000048,43.964795561831885,1.421931187519249,-0.7034870872364225
386.6000000000048,44.07235174684719,1.4356084644314615,-0.732807499958533
387.7000000000048,44.180212821603995,1.4488767349120366,-0.7605155360588931
388.80000000000484,44.288244569041254,1.4592245130427466,-0.7892501367437434
389.9000000000048,44.39562372242219,1.4693286492433717,-0.8184175504191158
391.00000000000483,44.50317221727134,1.475351689105647,-0.8478361136130657
392.10000000000485,44.610534771002584,1.4812097795771204,-0.8785052077645625
393.2000000000049,44.71714720871618,1.4868485825272098,-0.909668810321012
394.3000000000049,44.82511188808245,1.4865257031667176,-0.9415175730860286
395.4000000000049,44.932308924713574,1.48515316146237,-0.9717303186222819
396.50000000000495,45.04000000000051,1.476189999999998,-1.0043911055598245
397.6000000000049,45.14743228887144,1.4685249540928202,-1.0372895035771248
398.70000000000493,45.25544037901439,1.4523303366215707,-1.0664003686449437
399.80000000000496,45.36102406955494,1.430624421943179,-1.0971880664882248
400.900000000005,45.468526821717816,1.4050639446340099,-1.12944902743883
402.000000000005,45.576300466979546,1.3757841086184124,-1.1559776389075913
403.100000000005,45.68400557936567,1.3398166000191754,-1.1848674891322046
404.20000000000505,45.79088634963599,1.3033829734246183,-1.2099567293116889
405.30000000000507,45.898446783865126,1.2609102888012431,-1.2354752339696873
406.4000000000051,46.005079655614274,1.2228366253730145,-1.2569491954020524
407.50000000000506,46.112517691806694,1.1827329686793036,-1.279253505719883
408.6000000000051,46.220565777709766,1.1446818219272052,-1.2981792651633697
409.7000000000051,46.32781477951868,1.1096164912229345,-1.315580449063214
410.8000000000051,46.435173417424885,1.0810430158405193,-1.3292954392165166
411.90000000000515,46.54250804977169,1.0554588969075571,-1.3438356139511272
413.0000000000052,46.65091206349002,1.037208607180451,-1.358208619099853
414.1000000000052,46.75731588854622,1.0216343772359282,-1.3704621211851564
415.20000000000516,46.86490086266119,1.0098115873636877,-1.3850136805862188
416.3000000000052,46.97187224228313,0.9992742288193267,-1.394765307788151
417.4000000000052,47.080382665900885,0.9937343882314524,-1.405334294569911
418.50000000000523,47.18632063330768,0.9912734472344188,-1.4157954879517325
419.60000000000525,47.294767874896124,0.9875992618261489,-1.4245163793689968
420.7000000000053,47.40179797432008,0.9876389356665626,-1.4331930570304356
421.8000000000053,47.51009173734732,0.9861351358381991,-1.442610765033442
422.9000000000053,47.6178523959173,0.9859552228057801,-1.4516064423352426
424.00000000000534,47.723803008154086,0.9859376309100826,-1.4591789156537711
425.1000000000053,47.83324922286658,0.989014076128076,-1.4701510722056934
426.20000000000533,47.94094586902287,0.9910667305576057,-1.4780437217775262
427.30000000000535,48.04654687300624,0.9913995454707952,-1.4873095413614044
428.4000000000054,48.15446243935527,0.994659448591223,-1.4952647400971233
429.5000000000054,48.26191001944695,0.9977438822173791,-1.5038435205336746
430.6000000000054,48.369998944751245,1.0011900414489343,-1.5126597555675283
431.70000000000545,48.477584756581514,1.0041623039118488,-1.5196324478089398
432.8000000000054,48.58372028087118,1.0061849560109248,-1.5292856283249057
433.90000000000543,48.69342609414514,1.0080488488188772,-1.5382610559103638
435.00000000000546,48.80042729704948,1.0141313725398071,-1.5463933142283706
436.1000000000055,48.90869459560797,1.0189068238892776,-1.5574633804499345
437.2000000000055,49.01547695007564,1.0222791204512833,-1.5662870342429809
438.3000000000055,49.12369473360052,1.0245886523717591,-1.575438684854693
439.40000000000555,49.2314769513755,1.0297492805767707,-1.5845891638194365
440.50000000000557,49.33818574620772,1.031669667960273,-1.592966078768924
441.6000000000056,49.44626783358995,1.0357437765906359,-1.6029976460414495
442.70000000000556,49.55539159816069,1.0407622370651004,-1.6129711013175383
443.8000000000056,49.66239457116139,1.0434548180392302,-1.6225553329132323
444.9000000000056,49.770902588960425,1.0475917554533811,-1.6314455155969148
446.0000000000056,49.87900953832088,1.0520879915790569,-1.6420117116519144
447.10000000000565,49.98675897478596,1.0547688450529284,-1.652313646158348
448.2000000000057,50.09504336767639,1.057921168835652,-1.661655767063313
449.3000000000057,50.20279853495139,1.0621882259308661,-1.6728263656597537
450.40000000000566,50.31150160926336,1.0671546711148894,-1.684868255607443
451.5000000000057,50.41990424090143,1.0704855881369602,-1.6923311852845742
452.6000000000057,50.5295667121927,1.0747768193042675,-1.7031419806382107
453.70000000000573,50.63688957760861,1.0775161725701976,-1.7127355127523867
454.80000000000575,50.74542145836066,1.080545982599506,-1.7243604244044595
455.9000000000058,50.853304715997076,1.0829995767510185,-1.735554869645926
457.0000000000058,50.96287573692753,1.0860999648707197,-1.747795130780402
458.1000000000058,51.070778996264785,1.088098681603756,-1.7575642731527417
459.20000000000584,51.17924839651612,1.0907109978493792,-1.7666441596967695
460.3000000000058,51.28761122515474,1.0945152058240328,-1.7784615761093536
461.40000000000583,51.395085806553844,1.0975546241136775,-1.790104508630566
462.50000000000585,51.50327855753291,1.1004366193914947,-1.8024097020012366
463.6000000000059,51.60999903722695,1.101599946658845,-1.8128900357877056
464.7000000000059,51.72060343696764,1.104565748472915,-1.823247574268752
465.8000000000059,51.82909106772202,1.1038279023743895,-1.836369725586179
466.90000000000595,51.93742056260241,1.104134590468927,-1.8466961627273877
468.0000000000059,52.04552800972561,1.1029329991742465,-1.8570606681332587
469.10000000000593,52.15462450139849,1.0997704411816362,-1.8681105048704403
470.20000000000596,52.26340490826324,1.0955141023846457,-1.878641960414241
471.300000000006,52.37231451017682,1.0878111351897903,-1.8890705826654917
472.400000000006,52.480363060511095,1.0765939523565473,-1.8985838523182252
473.500000000006,52.58875174864068,1.0658599957799078,-1.9092734385691275
474.60000000000605,52.6979475282799,1.0503280876958265,-1.9153278887251997
475.70000000000607,52.80598558784048,1.0371251881809604,-1.9226401206168307
476.8000000000061,52.913565775785656,1.0244597508448574,-1.9275346836036684
477.90000000000606,53.02290145519861,1.012251319889125,-1.9327037530035653
479.0000000000061,53.13146853108204,1.000533828100566,-1.9353606832306407
480.1000000000061,53.24060356190987,0.9911460574288008,-1.9388028146712024
481.2000000000061,53.34893157893562,0.9816786192690701,-1.9410297485290706
482.30000000000615,53.457767517164896,0.9810941683285296,-1.9401197786087452
483.4000000000062,53.565833044683494,0.9799796689666872,-1.9415455392041316
484.5000000000062,53.67513652309657,0.9811683643596544,-1.9427925368197072
485.60000000000616,53.78322704951802,0.9820349195517273,-1.9427661275409696
486.7000000000062,53.89183955895843,0.9879408115371225,-1.9440523713845397
487.8000000000062,54.000745338098966,0.9941768519098801,-1.9440723077888005
488.90000000000623,54.10806522414242,1.0118075403145101,-1.9453899319529335
490.00000000000625,54.21671718012834,1.0244250706422071,-1.9452883671433994
491.1000000000063,54.325398731801,1.0300942792280445,-1.9467224240670404
492.2000000000063,54.434928159234765,1.039269801441544,-1.9480100012350485
493.3000000000063,54.543677018468955,1.0429747217010985,-1.948347798999856
494.40000000000634,54.652450178606564,1.0508411330583853,-1.949330038747723
495.5000000000063,54.75990142705747,1.0584499285964657,-1.9493300899999983
496.60000000000633,54.869789262719024,1.0602880820432887,-1.9493300899783401
497.70000000000636,54.97764491138284,1.0640841585098257,-1.9506920231931058
498.8000000000064,55.08603689751479,1.0656166357719543,-1.950650181962252
499.9000000000064,55.195592849064646,1.0627422835051996,-1.9506673230093843
501.0000000000064,55.30486540058304,1.0599268129486084,-1.9493401827350292
502.10000000000645,55.41419239380625,1.0542004110503969,-1.9506218483594657
503.2000000000064,55.52333529619051,1.0522419867335502,-1.9519802799349906
504.30000000000643,55.63178202912831,1.0475467955189226,-1.951970919297672
505.40000000000646,55.74218742428967,1.0441332859700188,-1.9524674514941758
506.5000000000065,55.8486110281853,1.044351708889822,-1.9510627791350696
507.6000000000065,55.959894934499566,1.0428958456222335,-1.95097994014864
508.7000000000065,56.06926404087474,1.0414806267590482,-1.9534346668048128
509.80000000000655,56.17876789917875,1.0436242956780106,-1.9535752203128323
510.90000000000657,56.28852039102539,1.036803807399374,-1.9536094131344326
512.0000000000066,56.39781666189587,1.0364963127474789,-1.9526200464154768
513.1000000000065,56.50814178365488,1.0303285569708578,-1.9539247855008006
514.2000000000066,56.617036608825906,1.028789234847395,-1.9552603570699825
515.3000000000065,56.72745848344603,1.0301404880983553,-1.9541670826222717
516.4000000000067,56.836065590628905,1.0302002925480758,-1.9546001678604448
517.5000000000066,56.94523672810118,1.034686894298831,-1.9545999834917738
518.6000000000067,57.05569569355688,1.039588277401435,-1.9532801445304573
519.7000000000066,57.16404397219491,1.0407735648497152,-1.9546006608149051
520.8000000000067,57.27383366099686,1.0464870534967525,-1.954267397918084
521.9000000000067,57.38255851545092,1.051999265100858,-1.9564053968160078
523.0000000000067,57.49289287461609,1.0588037991139143,-1.9565797745255034
524.1000000000067,57.60144375209348,1.0635880646264246,-1.955256689197816
525.2000000000068,57.7116465983549,1.0707727149237998,-1.9565610974690806
526.3000000000068,57.821808211216485,1.0783231964331406,-1.9565696806909503
527.4000000000068,57.93009734857135,1.0848862852137593,-1.9559102421176622
528.5000000000068,58.04019808426287,1.0933238885503818,-1.9558208139679696
529.6000000000068,58.15000210656136,1.0985802296628977,-1.9572299030754254
530.7000000000069,58.259518195763114,1.1066334977181467,-1.9572299030009086
531.8000000000068,58.36873614801498,1.1125848261609261,-1.957225839486859
532.9000000000069,58.47812235444648,1.120499173979095,-1.9595498417464952
534.0000000000068,58.58784724052891,1.1238409873817696,-1.9582199856107336
535.100000000007,58.697733296079655,1.1332692059298473,-1.9580400112048024
536.2000000000069,58.80673411119888,1.1380337684115145,-1.9592105930983439
537.300000000007,58.91641041816481,1.1436649054864532,-1.9585459502572666
538.4000000000069,59.02543479203534,1.1511906856616472,-1.957228460230219
539.5000000000069,59.13626261336953,1.1559691849090443,-1.9572299497025045
540.600000000007,59.24572694535753,1.1625434070977263,-1.9584805841118782
541.700000000007,59.354919989543056,1.168456257727834,-1.9578984240750241
542.800000000007,59.4650492431282,1.1745746517591862,-1.958550027656552
543.900000000007,59.57434139738438,1.1789108005493345,-1.9572331120615178
545.000000000007,59.683625215811375,1.1852421813333063,-1.95985943383929
546.1000000000071,59.79366830859688,1.1911555233466948,-1.9585382358078318
547.2000000000071,59.902385446315016,1.196921170578664,-1.9585294709130148
548.300000000007,60.01312238909778,1.2040412973964456,-1.9571836859884932
549.4000000000071,60.12353531565454,1.2072188097101686,-1.9598738814416468
550.500000000007,60.2335095477918,1.2081726563789514,-1.9609590723237793
551.6000000000072,60.34382948083807,1.2162090816683349,-1.9585376532200955
552.7000000000071,60.453858842010824,1.22009776486748,-1.959860221900613
553.8000000000072,60.56318823484063,1.2245820498751667,-1.9585419554297552
554.9000000000071,60.673440848905145,1.2291867905939053,-1.9598602393478224
556.0000000000072,60.782943403826636,1.2354883737382423,-1.9598601999999823
557.1000000000072,60.89256595200364,1.2400805212378572,-1.9598601999934533
558.2000000000072,61.00161350654393,1.2464667021734863,-1.9598678039167545
559.3000000000072,61.11229643636093,1.2526323206641314,-1.963874137953209
560.4000000000073,61.22181768364545,1.2574965002386336,-1.9624806667478993
561.5000000000073,61.33153335979429,1.2614826784294366,-1.9616470296207034
562.6000000000073,61.441806717119455,1.2678122111636105,-1.9624900427949195
563.7000000000073,61.55128352429676,1.2721885346230637,-1.9638082193473503
564.8000000000073,61.66008846674551,1.2780174105575237,-1.9638104430244328
565.9000000000074,61.770915153424674,1.2840458604902998,-1.9638101392853118
567.0000000000074,61.880314310815315,1.2894001343872088,-1.961259257397367
568.1000000000074,61.9897050557521,1.2937341300506786,-1.9621700268365618
569.2000000000073,62.0995151096991,1.2996581259725912,-1.9624744892680805
570.3000000000073,62.21031610206191,1.3037582782275177,-1.962686944177884
571.4000000000074,62.32019875845039,1.3077939220444113,-1.9624902400340791
572.5000000000074,62.4306267995937,1.3155713558708861,-1.963809889271198
573.6000000000074,62.54018917689083,1.3186744155481833,-1.9638101173716271
574.7000000000074,62.6511613292576,1.326086645542348,-1.9651296800321072
575.8000000000075,62.761309589302584,1.3303678676996562,-1.9651298079965258
576.9000000000075,62.87100786944143,1.3344348217670507,-1.9651356946574428
578.0000000000075,62.9813993216518,1.3377653476249807,-1.9648026615064182
579.1000000000075,63.09206722672294,1.3473899012829815,-1.9665105245592813
580.2000000000075,63.20118489033231,1.3512086221661326,-1.9651321722892163
581.3000000000076,63.31258763212944,1.3573899326379324,-1.9664410360901474
582.4000000000076,63.420123899802206,1.3631682325376586,-1.965139940181718
583.5000000000076,63.53354636129904,1.3689041368958834,-1.966440139031696
584.6000000000076,63.64335404376972,1.3744104964672177,-1.9651296084685885
585.7000000000077,63.753713315555586,1.3817425564275592,-1.9637545817146909
586.8000000000077,63.86360046282789,1.3897417642726582,-1.965129831118872
587.9000000000076,63.97355020549222,1.395821312100438,-1.9651299670001392
589.0000000000076,64.08373042286757,1.403553446935643,-1.9651298289513641
590.1000000000076,64.19399868316754,1.4089342971060612,-1.9661505004121103
591.2000000000077,64.30369956238142,1.4173091719226878,-1.9667471821404598
592.3000000000077,64.41293469784996,1.4228522672252653,-1.9669903617636573
593.4000000000077,64.5242422171496,1.4311567664137934,-1.9671100898635516
594.5000000000077,64.63390878032719,1.4374455561964299,-1.9697306019367802
595.6000000000078,64.74467265573377,1.4456717132267063,-1.9697298169979605
596.7000000000078,64.8538149889038,1.4517323607038162,-1.9697336653534077
597.8000000000078,64.9651710521979,1.4606725732472574,-1.968883592177118
598.9000000000078,65.07536085318891,1.467658025839756,-1.9707299454319367
600.0000000000078,65.18516130788002,1.4731396828381607,-1.972017189433421
601.1000000000079,65.2954335761837,1.481935093354713,-1.9720399759136522
602.2000000000079,65.40520864631108,1.4920227749208832,-1.9723446140167042
603.3000000000079,65.51606843939841,1.5002174705738673,-1.9724717007267962
604.4000000000078,65.62659415886414,1.5072376840789319,-1.9736860898020558
605.5000000000078,65.73605809157488,1.5156750487028483,-1.9750007336355346
606.6000000000079,65.84667169564545,1.5233108674784133,-1.9759899121125022
607.7000000000079,65.95698819257174,1.5318020148306286,-1.9769226809857186
608.8000000000079,66.06875578737875,1.5409318361157747,-1.9766498595632025
609.9000000000079,66.17922058240957,1.5475583895549274,-1.976650009608718
611.000000000008,66.28894427471167,1.55470611380794,-1.9779706142874938
612.100000000008,66.39989736741643,1.5611424697321352,-1.9779595889796844
613.200000000008,66.51060366369981,1.571980098336546,-1.9788055503890467
614.300000000008,66.62147864876495,1.5804914809208277,-1.9799284516005473
615.400000000008,66.7319350572223,1.5880941387904322,-1.9799889781776314
616.5000000000081,66.84288456141489,1.6000491302022104,-1.9816514735366395
617.6000000000081,66.95265489473755,1.6073046341305857,-1.981579881462169
618.7000000000081,67.06337341243564,1.6181769815763916,-1.982339096564837
619.8000000000081,67.17405932462691,1.6282594279620486,-1.9826056154460145
620.9000000000082,67.2831351255455,1.6370528722433453,-1.9838880018649534
622.0000000000082,67.39458437211456,1.6451081141728108,-1.9854434410383512
623.1000000000081,67.50509683184264,1.657106209189039,-1.98651967609312
624.2000000000081,67.61554440919889,1.6675499521092223,-1.9878410959470902
625.3000000000081,67.72646675476933,1.6759471952210756,-1.9878493744148775
626.4000000000082,67.83667843404338,1.6893649800204236,-1.989084843286188
627.5000000000082,67.94800656323812,1.6977372080117032,-1.9904692248380735
628.6000000000082,68.05894706135769,1.7103867982659355,-1.9930994228779517
629.7000000000082,68.17038203933132,1.7203190613761368,-1.9944211650968615
630.8000000000083,68.28097820246845,1.7292579587499581,-1.9957408460585744
631.9000000000083,68.39154804818467,1.7426344754724952,-1.995730205084978
633.0000000000083,68.5026616636271,1.7528917058225344,-1.998028460182459
634.1000000000083,68.61311387280782,1.7669958973079227,-2.001050654550502
635.2000000000083,68.72447691920708,1.778280795359378,-2.0027148712201317
636.3000000000084,68.83497584643133,1.789627393720287,-2.0035818978086994
637.4000000000084,68.94671479787588,1.8048928918771912,-2.0049680432403942
638.5000000000084,69.05677180147293,1.8158731856927397,-2.0069304746286245
639.6000000000083,69.16702830670692,1.8295248055847018,-2.0094147531023783
640.7000000000083,69.27822596574902,1.8403682056997,-2.010902848284821
641.8000000000084,69.38907961992695,1.8563637450487982,-2.014937933069901
642.9000000000084,69.49919963361035,1.8662386085118778,-2.0168965007700668
644.0000000000084,69.6091810802411,1.8819643411333202,-2.0189512549196715
645.1000000000084,69.72053104928142,1.898210044309722,-2.020331163151447
646.2000000000085,69.83094428630865,1.9116358739620385,-2.0229219651713004
647.3000000000085,69.94187017199633,1.9246088755185202,-2.025570186573945
648.4000000000085,70.05240708318136,1.9393271805514478,-2.028309898954441
649.5000000000085,70.16344194120931,1.9563679460736239,-2.0298855013319352
650.6000000000085,70.27405668244154,1.972152425860703,-2.0334637846530415
651.7000000000086,70.38417136064261,1.9898318734786817,-2.036331802584667
652.8000000000086,70.4958971702828,2.0113599100462474,-2.040655227061116
653.9000000000086,70.60616009082968,2.0319707989228655,-2.0431777145757772
655.0000000000086,70.71682991252956,2.0559955899935995,-2.044743669778414
656.1000000000087,70.82742942601567,2.0827078786539417,-2.048159150026893
657.2000000000087,70.93869836351412,2.1062044440086765,-2.0500395145466914
658.3000000000086,71.0498953928259,2.1367522103050116,-2.054074609315524
659.4000000000086,71.16010605717571,2.1651015235549202,-2.0586005135338405
660.5000000000086,71.27100467853235,2.1954534047946312,-2.0612534974370784
661.6000000000087,71.38284865681892,2.2247055246801613,-2.0653843035069595
662.7000000000087,71.49279156200365,2.256847677513946,-2.0682395763333896
663.8000000000087,71.60315076093895,2.292006929161506,-2.0742302445469636
664.9000000000087,71.71591699657314,2.326993311437944,-2.0792274507210333
666.0000000000088,71.82537006401559,2.359914147265377,-2.0836325959283224
667.1000000000088,71.93601920589973,2.3943660648213516,-2.0866900923727494
668.2000000000088,72.04761527816416,2.4342743721172955,-2.0918817857002274
669.3000000000088,72.15803167320419,2.468831073360557,-2.096668978824744
670.4000000000088,72.26937655062865,2.5077108634763796,-2.1016362138055573
671.5000000000089,72.38009293420092,2.5429026543311086,-2.107438794082456
672.6000000000089,72.49104024177295,2.581897271248803,-2.113875266825988
673.7000000000089,72.60173484890889,2.6194888420635105,-2.1189199882878698
674.8000000000088,72.71207845567305,2.65862417583949,-2.1217391593060526
675.9000000000088,72.8225733892309,2.702034103731286,-2.1276349748174157
677.0000000000089,72.93192560100475,2.741261299281428,-2.135394135894831
678.1000000000089,73.04501512636517,2.7795365900306876,-2.140901286692455
679.2000000000089,73.15701726462434,2.8203010476011863,-2.148068424490249
680.3000000000089,73.26771352220076,2.858364070364658,-2.154209243188351
681.400000000009,73.37928640782994,2.8954895917909944,-2.159936133574833
682.500000000009,73.49009168198108,2.932945936364949,-2.166394564236084
683.600000000009,73.60137823428022,2.969926149623418,-2.175430195046472
684.700000000009,73.71303810822249,3.011638411039201,-2.1827757540107413
685.800000000009,73.82437706581403,3.0509247308548177,-2.191383511112679
686.9000000000091,73.93560699457107,3.0931588212460994,-2.19874508431992
688.0000000000091,74.04656536962474,3.136213952591997,-2.205771949602318
689.1000000000091,74.15944850727746,3.183032414457311,-2.214169280051116
690.2000000000091,74.2718160632572,3.2279014167732396,-2.22421233703123
691.3000000000092,74.3828929615161,3.2740029057619884,-2.234490478315119
692.4000000000092,74.49423816214517,3.316701136316729,-2.244024564574902
693.5000000000091,74.60616254832917,3.362082311195032,-2.2540352936216603
694.6000000000091,74.71757346138857,3.4079132923403175,-2.264366883704486
695.7000000000091,74.82678230076209,3.4520765635935584,-2.2747941622787877
696.8000000000092,74.94019632312413,3.5003352900649367,-2.2846563371421906
697.9000000000092,75.05174179715766,3.546412180512156,-2.297625946819413
699.0000000000092,75.1618636071125,3.5948474973401168,-2.3076564913254454
700.1000000000092,75.27476521017763,3.6444224275037387,-2.3215805349935463
701.2000000000093,75.38527565428826,3.6904857098764614,-2.334001436069615
702.3000000000093,75.49723862696285,3.7376270666942255,-2.3442437424960083
703.4000000000093,75.60797645018332,3.7806471155455452,-2.3570715410095127
704.5000000000093,75.71917956757194,3.826806327727232,-2.3690899184367193
705.6000000000093,75.83087158104814,3.870284184384552,-2.383819385897254
706.7000000000094,75.94162742306256,3.9137792755255405,-2.3970163616879168
707.8000000000094,76.05258715978479,3.9541091622454525,-2.4090857999080657
708.9000000000094,76.16302358806189,3.9943827390691293,-2.4236865191424455
710.0000000000093,76.27451316885457,4.031612292774255,-2.4346324412956886
711.1000000000093,76.38654213599821,4.073472021331911,-2.452238999857749
712.2000000000094,76.49628460999863,4.109237483287872,-2.466560086919703
713.3000000000094,76.60750840690035,4.147477453900291,-2.4818593926168164
714.4000000000094,76.71860389559293,4.1837861306816,-2.494684391437999
715.5000000000094,76.8296910355192,4.219959806640478,-2.509249344536426
716.6000000000095,76.93872027851364,4.255271452722095,-2.523860892772733
717.7000000000095,77.0538865068248,4.291034611456161,-2.5402262814682994
718.8000000000095,77.16444082368531,4.324075148084441,-2.5562498103173423
719.9000000000095,77.27681011599105,4.355334322139132,-2.571510700988884
721.0000000000095,77.38782345715005,4.380223041900428,-2.586059363694468
722.1000000000096,77.49852267479412,4.404615926810333,-2.6053468881993322
723.2000000000096,77.61060818165582,4.42744905487572,-2.6217411674653857
724.3000000000096,77.72162484334412,4.4473489627474345,-2.636904217021355
725.4000000000096,77.83203875022595,4.454179620795236,-2.651615291123518
726.5000000000097,77.94402848587336,4.451594169200651,-2.6683475062352566
727.6000000000097,78.05583454114544,4.4420735300390515,-2.6841503301845737
728.7000000000096,78.1663698378891,4.417241986416198,-2.7007462301658656
729.8000000000096,78.27712625238722,4.371226754528483,-2.7164103783643796
730.9000000000096,78.38925429118463,4.301517223898876,-2.7336882918301546
732.0000000000097,78.49991518608608,4.1890644293655255,-2.750356866006241
733.1000000000097,78.61139810402312,4.011364312146739,-2.761929222266164
734.2000000000097,78.72203594131967,3.721397418390507,-2.77456232788452
735.3000000000097,78.833559155366,3.1926334115737793,-2.783588200105531
736.4000000000098,78.94403064866452,2.4518524711101746,-2.787050004854895
737.5000000000098,79.05413142052838,2.1807441400578256,-2.7880996860455944
738.6000000000098,79.16552877873836,2.1044403637650544,-2.7894187055499913
739.7000000000098,79.27660032795102,2.0878925797568253,-2.7907351397902893
740.8000000000098,79.38849320514338,2.0833024826315065,-2.7920487574063184
741.9000000000099,79.49834067385406,2.0855454691009903,-2.7907400316832467
743.0000000000099,79.6105108793056,2.090768236129214,-2.7907400280406383
744.1000000000099,79.72152165808086,2.0979242309088577,-2.7914340203610726
745.2000000000098,79.83295342435002,2.1064093588120203,-2.792048558214426
746.0000000000099,79.91402698092764,2.1081754253744505,-2.7920395481294635