File: 01_Data/Nylon_Carpet_Low_Pile/STA/N2/10K_min/Nylon_Carpet_Low_Pile_STA_N2_10KData_220106_R3.csv
##Temp./Â°C,Time/min,DSC/(mW/mg),Mass loss/mg
50.0,10.752393019960929,-0.8908748372815589,-0.0035850855313084296
51.20000000000002,11.074444944332761,-0.7792413348249749,-0.001959065978222263
52.400000000000034,11.297504506435228,-0.7064846764296259,-0.0022846231936339834
53.60000000000005,11.481040282243676,-0.6531696231740914,-0.0002755185431855267
54.80000000000007,11.648353478928637,-0.6091707023720776,-0.0025442159008690624
56.000000000000085,11.803956186178906,-0.5755773750230766,-0.00262728449561056
57.2000000000001,11.952651115694794,-0.5470644233987503,-0.0010437004621088875
58.40000000000012,12.09511469615543,-0.52259104497046,-0.001265383462305536
59.600000000000136,12.234489521219404,-0.5039884484038306,-0.0011659230495268957
60.80000000000015,12.37174829502005,-0.48637325680244875,-0.0009648436021505447
62.00000000000017,12.50698080825284,-0.4700219600771315,-0.0028504318117041905
63.20000000000019,12.641169151900243,-0.45588138873231215,-0.0036147225731157917
64.4000000000002,12.773431533917694,-0.4422400176693387,-0.002916617654922682
65.60000000000022,12.90381419821443,-0.4315010930710562,-0.0022957549767488317
66.80000000000024,13.034374701192418,-0.4202477679748046,-0.001821573461646686
68.00000000000026,13.163171438127382,-0.40941762510496094,-0.002737294523398326
69.20000000000027,13.291511412203075,-0.39739244568657595,-0.002290197652604853
70.40000000000029,13.421814973996083,-0.3879295151016199,-0.0022999400497649702
71.6000000000003,13.548962559868393,-0.37652120536522315,-0.0036097945840047885
72.80000000000032,13.675726676777753,-0.3658519943566957,-0.003928081664089866
74.00000000000034,13.80270184227458,-0.35458417091205846,-0.003621054597743978
75.20000000000036,13.928257069193236,-0.34458268225243277,-0.003610373948198742
76.40000000000038,14.054732284714078,-0.33402861798755584,-0.0036032135477883642
77.60000000000039,14.178831737454399,-0.3265072114016005,-0.0036094139719011764
78.80000000000041,14.30399473752248,-0.31619095673221487,-0.003591796427528493
80.00000000000043,14.427505043215774,-0.30790487383589493,-0.0036147263763828263
81.20000000000044,14.552263706625503,-0.29683360862342206,-0.0049298748511619195
82.40000000000046,14.675178614450697,-0.28780677901549184,-0.005000672165444087
83.60000000000048,14.798023082070996,-0.2781608820958952,-0.007445877249755206
84.8000000000005,14.921483307853633,-0.2704872795646689,-0.007482409565803927
86.00000000000051,15.041917869759763,-0.26215589636513215,-0.006240087740554401
87.20000000000053,15.16305845042376,-0.2527914231595276,-0.004918551852002295
88.40000000000055,15.282209361042982,-0.24499899274631365,-0.004929501171009321
89.60000000000056,15.405345304267751,-0.23618012314049286,-0.00493662260032135
90.80000000000058,15.526230047391083,-0.22809083287703774,-0.006240199378209965
92.0000000000006,15.645109212019062,-0.221508542317339,-0.007560073690457081
93.20000000000061,15.765338185948465,-0.21265716820343786,-0.006249653521604337
94.40000000000063,15.88703755496061,-0.2047960189632265,-0.007559954962576221
95.60000000000065,16.00573768595039,-0.19519394605543422,-0.007555370856713317
96.80000000000067,16.12511662844216,-0.18761346963280917,-0.007564475797632753
98.00000000000068,16.244189241467758,-0.17986885523328988,-0.007800239942121756
99.2000000000007,16.36265570523602,-0.1721376916066463,-0.007575794380407785
100.40000000000072,16.48168908439792,-0.16329837836117317,-0.007559563233749067
101.60000000000073,16.599903198462282,-0.1566746683583328,-0.008211581467878482
102.80000000000075,16.718229933340282,-0.14874437839946775,-0.008220086155732886
104.00000000000077,16.836482439883486,-0.14171065437714397,-0.008219736340910444
105.20000000000078,16.95486949671801,-0.13372567105721037,-0.008868998670685357
106.4000000000008,17.072485513129386,-0.12764580405893478,-0.0088799636154695
107.60000000000082,17.191349847327007,-0.12098352041883766,-0.010201513211749003
108.80000000000084,17.309082981626744,-0.11398639140167448,-0.00888001872672195
110.00000000000085,17.42681131555442,-0.10741884038005144,-0.009859589569039429
111.20000000000087,17.545362489628733,-0.10122382174038824,-0.008902649043262656
112.40000000000089,17.662631007246183,-0.09321041789535096,-0.010190146414258194
113.6000000000009,17.781116528033166,-0.08853912200180653,-0.011510587527273408
114.80000000000092,17.896843799852576,-0.0816172122557825,-0.010199620851786051
116.00000000000094,18.014108216201627,-0.07519931083576137,-0.010199951188498702
117.20000000000095,18.13227949389895,-0.07041788092364759,-0.009338593886392133
118.40000000000097,18.24878807044988,-0.0627630030823355,-0.010190117244511576
119.60000000000099,18.3660771384606,-0.05658315922050945,-0.011180110681690891
120.800000000001,18.484171423617877,-0.05119993998177066,-0.009869900842025103
122.00000000000102,18.600846789054042,-0.04672432570002284,-0.010201254123279213
123.20000000000104,18.71830879650202,-0.039044780864095054,-0.010262316969512852
124.40000000000106,18.834736024874463,-0.03409635797764654,-0.011458738870213203
125.60000000000107,18.95157897098136,-0.02658272584326085,-0.01184006002867477
126.80000000000109,19.06860935162112,-0.021119520925086347,-0.013195171863610966
128.0000000000011,19.185838072055155,-0.016861847826662946,-0.011840166661673202
129.20000000000113,19.303161232102763,-0.01048494258066771,-0.013147441333175358
130.40000000000114,19.41901045299457,-0.0035345288428582375,-0.011839990353315955
131.60000000000116,19.536289646815657,0.002180416917300619,-0.012629000395523171
132.80000000000118,19.653268791764994,0.007349132309850505,-0.013159990002657551
134.0000000000012,19.769146528080427,0.013584319673015238,-0.011766364615565905
135.2000000000012,19.885195651714604,0.01942703843822201,-0.013160094685658486
136.40000000000123,20.002835342339857,0.026317540040604798,-0.013160094999997263
137.60000000000124,20.119254786235025,0.03185559324997077,-0.013160083382318888
138.80000000000126,20.234951029755205,0.0374210963516518,-0.013083986480344478
140.00000000000128,20.350373386842513,0.043420612448451905,-0.01315020000271172
141.2000000000013,20.467423166171002,0.051766715481586546,-0.013145020644699912
142.4000000000013,20.583576076945477,0.057337834785833736,-0.01579014315251559
143.60000000000133,20.699552227086464,0.06494402227134363,-0.015129379499478013
144.80000000000135,20.81519425284086,0.07271946905867181,-0.015785819693904912
146.00000000000136,20.930696960421656,0.07864073077913011,-0.014469835187787439
147.20000000000138,21.046588350161585,0.08629850194735768,-0.014470024999662101
148.4000000000014,21.16219196769748,0.09225987352054318,-0.014470828010705539
149.60000000000142,21.27813667079056,0.09969469672793027,-0.015790022516895874
150.80000000000143,21.394283928318227,0.10933355970391395,-0.014801634770922334
152.00000000000145,21.510451049228944,0.11806288534233364,-0.015777918782844402
153.20000000000147,21.62482740315415,0.12758981728846705,-0.015790129995690627
154.40000000000148,21.740489587977077,0.13867153981013755,-0.015790130000455704
155.6000000000015,21.85576178233319,0.14885127614884625,-0.01579034432482551
156.80000000000152,21.971764699850436,0.15957588134868989,-0.014967528173784217
158.00000000000153,22.087427106741824,0.1747391551777695,-0.0144700578658421
159.20000000000155,22.201956085094047,0.18660715042038606,-0.01443984982481794
160.40000000000157,22.317805044094044,0.20254202419819375,-0.015790059534100287
161.6000000000016,22.433287482600676,0.21529347969167406,-0.01579006717323761
162.8000000000016,22.54866598833836,0.2302855511048955,-0.01846041934091236
164.00000000000162,22.66315376874707,0.24331533178053105,-0.01664840068276252
165.20000000000164,22.779694320989556,0.2536101097453862,-0.017100317966862733
166.40000000000165,22.894538564741516,0.25501651817548465,-0.018407558969025573
167.60000000000167,23.009811755111297,0.2511267986300511,-0.017426106742088443
168.8000000000017,23.12457054181116,0.24261964897505833,-0.01754531654617164
170.0000000000017,23.240663706748098,0.23374371231427193,-0.01804011879747769
171.20000000000172,23.35493573767141,0.2288376285340675,-0.018090084845678867
172.40000000000174,23.47009534810367,0.22328127761111824,-0.01809008999936257
173.60000000000176,23.58417515877731,0.22273814685191856,-0.018148630168749236
174.80000000000177,23.70000000000016,0.22273999999998614,-0.017422729557946326
176.0000000000018,23.81533524008019,0.22257661268957807,-0.018424755021670514
177.2000000000018,23.930612524464212,0.22685554556072995,-0.017759914735925975
178.40000000000182,24.046119836602042,0.23003700539998426,-0.018088763263921948
179.60000000000184,24.1610889172675,0.23528945900838655,-0.018082371043992573
180.80000000000186,24.276603560350814,0.24141392729624753,-0.017758355061370246
182.00000000000188,24.390284553493146,0.24656046539912657,-0.01907421964835443
183.2000000000019,24.504494801764956,0.25187393639781247,-0.019081045570490396
184.4000000000019,24.619724635339477,0.25825973402884084,-0.019079944999973897
185.60000000000193,24.73393902818913,0.2627086075986951,-0.019079911591452614
186.80000000000194,24.847827999803158,0.26937598974512156,-0.018420360295362315
188.00000000000196,24.964269953216153,0.27393763274180477,-0.018433309427650535
189.20000000000198,25.079638913381388,0.28056756375350056,-0.019080151419743174
190.400000000002,25.194276551235273,0.28451462549471335,-0.019080174999824173
191.600000000002,25.308295206157126,0.290651929389656,-0.019080242213930454
192.80000000000203,25.422938181772235,0.29751998039065275,-0.01874792469472375
194.00000000000205,25.538430275930647,0.30318977363399763,-0.020433377543567666
195.20000000000206,25.65160877934671,0.3079347209137725,-0.01907987521457155
196.40000000000208,25.76729321189856,0.31326786921702343,-0.019077073716787574
197.6000000000021,25.881853447178205,0.31907668772900005,-0.020398935247394334
198.80000000000211,25.99664704206524,0.3241054255197819,-0.020389731964748137
200.00000000000213,26.111110953217363,0.32990099082085617,-0.020071399854414196
201.20000000000215,26.226409996049476,0.33699589807617913,-0.022042698025700247
202.40000000000217,26.33972344824379,0.34208484242590914,-0.02336854462213278
203.60000000000218,26.45516557644043,0.35078525503073643,-0.02072925063358344
204.8000000000022,26.570529898916586,0.35611213951026877,-0.020721196891353877
206.00000000000222,26.68485246076066,0.3647327927718378,-0.022040705995744148
207.20000000000223,26.79885758094153,0.37230729037485244,-0.02204245394562676
208.40000000000225,26.91506278185769,0.3794271704273324,-0.0207225296295519
209.60000000000227,27.029999052684,0.38879995704961606,-0.02334968671773119
210.80000000000229,27.143569765037732,0.3996200998666819,-0.024771689566854604
212.0000000000023,27.259520325418215,0.4118723822971691,-0.023464305463489765
213.20000000000232,27.37432699810502,0.4316152106950796,-0.02246990088076295
214.40000000000234,27.489802856304976,0.46157987960620095,-0.0237897951236139
215.60000000000235,27.603558550060548,0.508330763137163,-0.023789800000104222
216.80000000000237,27.718152565121656,0.5710818168348649,-0.023789584767885508
218.0000000000024,27.83428315808869,0.6446805266684209,-0.02378962062571599
219.2000000000024,27.94971543062241,0.7136700740189397,-0.023490803337088195
220.40000000000242,28.064164326681027,0.7697782323128124,-0.023580967121756835
221.60000000000244,28.17895881583978,0.7949717962356609,-0.023720820074481175
222.80000000000246,28.29402457105279,0.7676509637221549,-0.024450090423380644
224.00000000000247,28.410000000000235,0.702469999999812,-0.023799274418881744
225.2000000000025,28.524192757788775,0.6294089216108671,-0.023799732898074133
226.4000000000025,28.638683306876267,0.5704930722783005,-0.025110029643797382
227.60000000000252,28.752563457516903,0.5270953057285188,-0.025439806170136414
228.80000000000254,28.86646424016199,0.4988451095413775,-0.025412037559616074
230.00000000000256,28.98055351046927,0.48055369940393183,-0.02511994936917361
231.20000000000258,29.094739621338597,0.46930805842670104,-0.02511995319838256
232.4000000000026,29.2087673263337,0.46371402042511367,-0.026428001246994626
233.6000000000026,29.323348731766853,0.46273246087702,-0.025121837245671408
234.80000000000263,29.4385519854327,0.4624969448201952,-0.02511004501532188
236.00000000000264,29.55203124440069,0.46564786678731684,-0.026430218219261725
237.20000000000266,29.66586475177377,0.4682402796330172,-0.027856379680933685
238.40000000000268,29.780284022930473,0.4723253631219063,-0.027771977235672374
239.6000000000027,29.894881910019095,0.4764998297316448,-0.029302030415875535
240.8000000000027,30.01009183290709,0.48076064601270097,-0.030369915284405913
242.00000000000273,30.123630643570188,0.48507797824956583,-0.027599680911220226
243.20000000000275,30.24000000000029,0.487610000000049,-0.028410020513391032
244.40000000000276,30.353094778058487,0.4894688363294237,-0.030369941673672685
245.60000000000278,30.46503040766783,0.49459123360555224,-0.03048888603933353
246.8000000000028,30.581755867942146,0.4979054708994004,-0.029387382500930315
248.0000000000028,30.69657269962276,0.5009863325835817,-0.029059608386798885
249.20000000000283,30.81156832119199,0.5060127043305912,-0.03179575553539493
250.40000000000285,30.927179388458725,0.5106106333137792,-0.0325288738947096
251.60000000000286,31.041752909191892,0.5136451128714884,-0.03279262220975365
252.80000000000288,31.155751076957735,0.5182213900111213,-0.031000490750647813
254.0000000000029,31.27000000000026,0.5217900000000187,-0.030489367284022073
255.20000000000292,31.385028414086687,0.5267445802622351,-0.03113969722038057
256.40000000000293,31.499811179555675,0.5300513830403125,-0.029838957258697896
257.600000000003,31.613286606902808,0.53438628180335,-0.031139749701357466
258.80000000000297,31.728369266220064,0.5383619343752304,-0.03280111383612461
260.00000000000296,31.843541033665172,0.5412259782544833,-0.03506573801726098
261.200000000003,31.95795413951691,0.546047523797069,-0.03378793112507772
262.40000000000305,32.073182139091806,0.5500693647344272,-0.03376981000257473
263.60000000000304,32.18702635483531,0.5540351660949485,-0.03376980992062695
264.800000000003,32.30234344743169,0.5585297440783176,-0.03455440339267746
266.00000000000307,32.41674008647285,0.5602158063824527,-0.03508981008398315
267.2000000000031,32.530630391531645,0.5640534298874113,-0.03469702198032998
268.4000000000031,32.646930830677405,0.5680428913855627,-0.035053681927313285
269.6000000000031,32.760255773856926,0.5724858815123626,-0.03619016898516936
270.80000000000314,32.875205924274056,0.5757038823966468,-0.03483371454365525
272.0000000000032,32.990706605057284,0.5790420051180198,-0.036646027125374125
273.2000000000032,33.106086206063125,0.581418575340434,-0.03795478321699264
274.40000000000316,33.220577347261134,0.5848685601713671,-0.036959800518413743
275.6000000000032,33.33476422436204,0.5876692870395143,-0.0369598000000817
276.80000000000325,33.45134457036088,0.5921051444755596,-0.036959688156342096
278.00000000000324,33.56679154511044,0.5955300376421436,-0.03841303160314524
279.20000000000323,33.681136206472274,0.5988034063580115,-0.038390094910869976
280.4000000000033,33.796353083957015,0.604274294359205,-0.03839009999997334
281.6000000000033,33.9111328290517,0.6092176031187321,-0.03839014578615263
282.8000000000033,34.026319734137935,0.6103432569999357,-0.04100998013403512
284.0000000000033,34.14139839244069,0.612903907990756,-0.04166960523422869
285.20000000000334,34.256137419352896,0.6177310907066673,-0.041669870369450024
286.4000000000034,34.372155630567455,0.6213285284632925,-0.04066057165726633
287.6000000000034,34.48719751002827,0.6255780388010213,-0.040680325404697015
288.80000000000337,34.60107525379471,0.6298948979213986,-0.041339867350506765
290.0000000000034,34.71727376497961,0.6338931665105468,-0.04263518906440655
291.20000000000346,34.832765183088625,0.6384011183873431,-0.04266065709028943
292.40000000000344,34.947719827717144,0.6425910695831325,-0.043978619557140775
293.60000000000343,35.06377131812758,0.6490329369679402,-0.041096946162460846
294.8000000000035,35.17750811471482,0.6508745527372596,-0.040313421898088286
296.0000000000035,35.29301188047815,0.6550747967770502,-0.046172461390864505
297.2000000000035,35.408569180849256,0.6607485507742088,-0.04366898265859209
298.4000000000035,35.52390765119549,0.6643394136282905,-0.04496813412815648
299.60000000000355,35.63944915244701,0.6669356177913147,-0.044970080998608886
300.8000000000036,35.75365588903175,0.6730634214721061,-0.04627982512122131
302.0000000000036,35.86932358192002,0.6759880512799009,-0.0489103002122766
303.20000000000357,35.981328169269666,0.6824728030331708,-0.0499628731218591
304.4000000000036,36.09980339476688,0.6852095330352423,-0.04912971731929616
305.60000000000366,36.21512666139448,0.6884333792921631,-0.05049975213764135
306.80000000000365,36.330828564393656,0.6944710572510076,-0.05043213344435893
308.00000000000364,36.44584342654882,0.6996107208997175,-0.05175986650679043
309.2000000000037,36.56009198532554,0.7056072570660158,-0.05308235434945585
310.40000000000373,36.675952986510765,0.7120344490633836,-0.05439053968025176
311.6000000000037,36.79276863940643,0.7165621142336615,-0.055713443093518666
312.8000000000037,36.90840127027279,0.7188745249215792,-0.0565356224187048
314.00000000000375,37.02304848831052,0.7236895088504163,-0.05835891143309002
315.2000000000038,37.139243745819,0.7273026047548368,-0.06097357816325566
316.4000000000038,37.25384535902965,0.7332384090488319,-0.060912761051374886
317.6000000000038,37.370258980945735,0.7385701907127908,-0.06228994558201295
318.8000000000038,37.48585850206786,0.7413455183465629,-0.06360978870508482
320.00000000000387,37.60285090240447,0.7482588861268161,-0.06761031271149998
321.20000000000385,37.71809130304867,0.754135375834149,-0.07017637512687402
322.40000000000384,37.83284995312618,0.759818992077379,-0.07150718246220622
323.6000000000039,37.94913451883358,0.7665565996554435,-0.07413687737037522
324.80000000000393,38.06379152946255,0.7737281646658072,-0.07676570460716592
326.0000000000039,38.180354249584155,0.7817178862489801,-0.080093418629132
327.2000000000039,38.29534401837096,0.7881505633646825,-0.08201242348179827
328.40000000000396,38.41083463658977,0.7954091512847304,-0.08547606038335864
329.600000000004,38.526654437530524,0.8024371743878678,-0.08941055098926087
330.800000000004,38.64302494670832,0.8101172270786815,-0.093670458938933
332.000000000004,38.75817015446962,0.8184978695725943,-0.09594694096842415
333.200000000004,38.8749484878008,0.8256912960715006,-0.10050166522191128
334.40000000000407,38.990928428130644,0.8373584524071157,-0.10456047974010696
335.60000000000406,39.105995552147846,0.8444280833604376,-0.11045205315159556
336.80000000000405,39.22281550026949,0.8548816144648537,-0.11450689167720896
338.0000000000041,39.338700124926056,0.8657480904931052,-0.1190019015841437
339.20000000000414,39.45421994606638,0.8753799333904018,-0.1263511501579906
340.4000000000041,39.570802273145084,0.885871578223837,-0.13133098540717114
341.6000000000041,39.68720369866706,0.8952380915944866,-0.14008087778877254
342.80000000000416,39.802858969870066,0.9083716224437086,-0.14638270928677422
344.0000000000042,39.92028038517439,0.9194492434305249,-0.15479021053857078
345.2000000000042,40.035856991384364,0.9322500172114075,-0.16347851637594335
346.4000000000042,40.152895483494866,0.945683341150691,-0.17265016664676924
347.60000000000423,40.26926373091476,0.9595231750635732,-0.18005910007782155
348.8000000000043,40.385576248339035,0.9731155606567707,-0.18981655887803717
350.00000000000426,40.502708301110445,0.9865122252167352,-0.19810427064533442
351.20000000000425,40.61840839103013,1.000833885538902,-0.20850431598510122
352.4000000000043,40.735551082061974,1.0146927849416867,-0.22156474513705504
353.60000000000434,40.85116329374235,1.0291351873196348,-0.23373633679656303
354.80000000000433,40.965416120827264,1.0433990287080748,-0.24545988212587266
356.0000000000043,41.08456059178829,1.057235536849238,-0.2582002814963089
357.20000000000437,41.20068735538166,1.0705837951574129,-0.2716411798245182
358.4000000000044,41.317005130004915,1.0838714637025564,-0.2864627075624413
359.6000000000044,41.434731996404444,1.099655657472344,-0.3010342905237806
360.8000000000044,41.55075156840919,1.1144167838116914,-0.3166635483348421
362.00000000000443,41.66822691291332,1.1282817162301308,-0.33181287147853356
363.2000000000045,41.78394860020639,1.141094123029804,-0.34899163980821823
364.40000000000447,41.90039956016294,1.1535568634007687,-0.36627546808025047
365.60000000000446,42.016613594663454,1.16830541813071,-0.3805973528429618
366.8000000000045,42.13389968971543,1.1837809211058556,-0.4014132501386789
368.00000000000455,42.250653640984204,1.197528130949393,-0.41900087434427835
369.20000000000454,42.36689990137693,1.2121842408901387,-0.4388338840373125
370.4000000000045,42.48257819054483,1.225996893174149,-0.4579509305674132
371.60000000000457,42.600635411568184,1.2417012130291964,-0.4796689939667096
372.8000000000046,42.716884060293495,1.2572370823813983,-0.5004657933878449
374.0000000000046,42.833782698405116,1.2726001050382074,-0.5215797974176892
375.2000000000046,42.950688613603155,1.287468684622774,-0.5458004375994614
376.40000000000464,43.06703528774591,1.3054462047189686,-0.5676857939156545
377.6000000000047,43.184394372754106,1.3208669196834348,-0.5909273840735478
378.8000000000047,43.300769289086034,1.3350993670278613,-0.6169516001018231
380.00000000000466,43.41892878376125,1.3518066845124785,-0.6440883268507087
381.2000000000047,43.53472013656669,1.367844810396229,-0.6698785764810742
382.40000000000475,43.65212567808629,1.3816028059008798,-0.6981935495953815
383.60000000000474,43.769330228823264,1.3985951863020423,-0.7281296977553633
384.80000000000473,43.88646417630603,1.4109166993539657,-0.7579447665829901
386.0000000000048,44.00323063730417,1.4244563896995666,-0.7881457622423644
387.2000000000048,44.11999904025912,1.4346098712557567,-0.8204497731481215
388.4000000000048,44.23760706267978,1.4485241168161793,-0.8500964793988781
389.6000000000048,44.35508328891673,1.4557799547446484,-0.8822199209541952
390.80000000000484,44.47115569351238,1.4612672436811769,-0.9163910260820414
392.0000000000049,44.58944751349459,1.4641629443046285,-0.9502576521788906
393.2000000000049,44.70620933946464,1.4656580506227395,-0.9859947177887238
394.40000000000487,44.82180980065859,1.4595933363039677,-1.0157587854033507
395.6000000000049,44.939438819326774,1.450787005160313,-1.0527346742903867
396.80000000000496,45.05635202655358,1.4372563006995427,-1.08892054685329
398.00000000000495,45.17345615661436,1.4185624964537216,-1.1188521679272476
399.20000000000493,45.29075332936658,1.3945799243517218,-1.1516968546305164
400.400000000005,45.40687790548292,1.3618783372770458,-1.1831068192566825
401.600000000005,45.52223657258414,1.3278608263797942,-1.2127932399564743
402.800000000005,45.64026984776931,1.2888490831448869,-1.2407802156408647
404.000000000005,45.756925010664034,1.2471618131291842,-1.2686799279316476
405.20000000000505,45.8733902531083,1.2051644857551846,-1.2926292414555602
406.4000000000051,45.99054772485211,1.1668208239721485,-1.3135431544683493
407.6000000000051,46.10722222727749,1.127795756360449,-1.3337605035299522
408.80000000000507,46.22347016190854,1.0947638332076564,-1.3521973757852552
410.0000000000051,46.34000000000048,1.0674099999998852,-1.369437058035528
411.20000000000516,46.4567165239167,1.045789073980317,-1.3840553303094971
412.40000000000515,46.57441182977531,1.0265355169582557,-1.3989789563138348
413.60000000000514,46.690999258484865,1.0160604086264522,-1.4116918886248357
414.8000000000052,46.80812282255944,1.0071670597990499,-1.4225187653848312
416.00000000000523,46.926039886020284,1.0012819410207352,-1.4330232440642043
417.2000000000052,47.04237974398084,0.9972501748599515,-1.4451211025638107
418.4000000000052,47.16030389147565,0.9960195888670936,-1.4544623732166815
419.60000000000525,47.27791439491622,0.9949105515438191,-1.4644904045241551
420.8000000000053,47.39486760283902,0.9947912607737774,-1.4751966329386677
422.0000000000053,47.5124189442634,0.9952234611001723,-1.4851193602811064
423.2000000000053,47.63019166668763,0.9977931358729208,-1.4973310511939006
424.4000000000053,47.74695885339906,0.9990287922353953,-1.5056855334446784
425.60000000000537,47.86468909368011,1.002370200803768,-1.5135747293084476
426.80000000000535,47.9825655387405,1.0043608519691776,-1.525494362023875
428.00000000000534,48.09980503999565,1.0062505411952294,-1.533936361843244
429.2000000000054,48.21706706149147,1.0100563549575914,-1.5439112400876294
430.40000000000543,48.33475030916222,1.0125686202286983,-1.5530967950081247
431.6000000000054,48.453009471583684,1.0165036603337823,-1.5613299202306141
432.8000000000054,48.569138384748406,1.0204931540643727,-1.571096579045824
434.00000000000546,48.68792551840895,1.0241106220956109,-1.5826498516628105
435.2000000000055,48.80585265397487,1.0266904434270752,-1.5929299335417122
436.4000000000055,48.924136474034846,1.0314746329838151,-1.6009792721138743
437.6000000000055,49.04149582376787,1.0351641264909643,-1.6116811883499969
438.8000000000055,49.15912824914217,1.0383066176424471,-1.6216177686656557
440.00000000000557,49.27762080682349,1.0440772459335415,-1.6330619516402956
441.20000000000556,49.394714804974534,1.048784881924427,-1.6438439019503366
442.40000000000555,49.51359910238877,1.0536809703485672,-1.6534495759500292
443.6000000000056,49.63220472443545,1.0594937000057272,-1.6643747630093677
444.80000000000564,49.74584253513482,1.0623050667571443,-1.6756945479571552
446.0000000000056,49.867506387926355,1.0683547195013634,-1.6867414928177453
447.2000000000056,49.98630881257592,1.072647869657319,-1.6994681595473873
448.40000000000566,50.10423873155526,1.0764247840082704,-1.708625849978854
449.6000000000057,50.22198172220595,1.081195258142917,-1.7204357228754557
450.8000000000057,50.34058331892897,1.086016796836381,-1.7332959973903783
452.0000000000057,50.45617487278265,1.089506013924038,-1.7439729582906196
453.20000000000573,50.575932353431035,1.094226379493788,-1.7573672768835964
454.4000000000058,50.69484426380595,1.0991101221124255,-1.7673408866572182
455.60000000000576,50.81234480770506,1.1051929041641615,-1.781085004110218
456.80000000000575,50.93000100024559,1.1077300915509485,-1.7941300070284503
458.0000000000058,51.048988661723314,1.112295295038887,-1.8061022124768233
459.20000000000584,51.16668898605404,1.1166439933725683,-1.8178938918820222
460.40000000000583,51.284218625747,1.1212393399878813,-1.8294513913567623
461.6000000000058,51.4027497221555,1.1238279770636914,-1.8426868524591327
462.80000000000587,51.520342953589186,1.126148770889684,-1.8573523238000336
464.0000000000059,51.63969176400578,1.128292965800497,-1.8684418653189088
465.2000000000059,51.75693136371532,1.131348897514367,-1.8779466283304918
466.4000000000059,51.875526734516654,1.1294569181595724,-1.8933860002810556
467.60000000000593,51.99420892940218,1.129054420440422,-1.9056325317483411
468.800000000006,52.112603157136824,1.1248422364885926,-1.9199528441705018
470.00000000000597,52.23124138838066,1.1198733285113478,-1.9283774917119327
471.20000000000596,52.34838671622369,1.1100287634943646,-1.9396530213381946
472.400000000006,52.467205348661416,1.1013857030174885,-1.9508620030227921
473.60000000000605,52.58513131968119,1.0880496381087745,-1.961381286771024
474.80000000000604,52.70392878689074,1.0737584109714227,-1.9700347950245418
476.000000000006,52.82229245175977,1.057326452697209,-1.9774102877084427
477.20000000000607,52.93979472178209,1.0450561157118017,-1.9798333605521585
478.4000000000061,53.05854688156397,1.0315519840845886,-1.983979782107955
479.6000000000061,53.17593969400391,1.022563357198044,-1.9860759620183437
480.8000000000061,53.29570758845952,1.014719282601697,-1.9884971037707277
482.00000000000614,53.41433259349896,1.010844823419977,-1.9913398344332722
483.2000000000062,53.53322329153144,1.0091088917412625,-1.9913276214254658
484.4000000000062,53.651646599808146,1.0113456235019591,-1.992656219627956
485.60000000000616,53.76909226572047,1.0146740874447997,-1.9936501152682315
486.8000000000062,53.88900611539951,1.0188395141732576,-1.9933787939247152
488.00000000000625,54.007314799999,1.0261541904108877,-1.9927982916682527
489.20000000000624,54.12562863082098,1.0433452531978298,-1.9947569641803984
490.40000000000623,54.24417115426203,1.0568203702495362,-1.9940875210530913
491.6000000000063,54.362365372188414,1.0656300753824002,-1.9952877495368462
492.8000000000063,54.47959557657063,1.0711041538706523,-1.995377025223219
494.0000000000063,54.59877856383357,1.0802203250965379,-1.9965773772605298
495.2000000000063,54.71762561168326,1.0824752514233404,-1.99738351530161
496.40000000000634,54.83564552833153,1.0838772195855981,-1.9973799350001302
497.6000000000064,54.95462706299351,1.08221242731204,-1.9973799350000014
498.8000000000064,55.07428098940692,1.081558441895248,-1.9973799556906284
500.00000000000637,55.19167595312885,1.0820566591366063,-1.9980303525098635
501.2000000000064,55.31144462178641,1.0805267230923499,-1.9993494641568779
502.40000000000646,55.43057115912339,1.0796748246534107,-1.998029934171929
503.60000000000645,55.549080811397516,1.0810019141402951,-1.9980249372766719
504.80000000000643,55.66788513524197,1.0814296652275233,-1.9993499765598055
506.0000000000065,55.78737504953078,1.0864215553774172,-1.9990223685621182
507.2000000000065,55.906223171287564,1.088913574778987,-1.9993496694693706
508.4000000000065,56.025015963892706,1.089676595127812,-2.0006699218159447
509.6000000000065,56.14429663747474,1.0874104254096457,-1.9993494792936928
510.80000000000655,56.26302930645509,1.0898722526857498,-2.0006582029186872
512.0000000000066,56.38226230434491,1.089898626857295,-1.9996834182663137
513.2000000000066,56.501808049670586,1.09142945601257,-1.9997601020302165
514.4000000000066,56.62010403026504,1.0897109780933902,-2.0000099901428854
515.6000000000066,56.740001988102144,1.0910496951475035,-2.0000099749937466
516.8000000000067,56.85929006276818,1.092166512923556,-1.9999399897252133
518.0000000000066,56.97805732491736,1.100147064028853,-2.0026401493985917
519.2000000000066,57.098280072171285,1.1024174258356203,-2.0027512947046255
520.4000000000067,57.217985741105444,1.1056509732586772,-2.0013201503951805
521.6000000000067,57.33654485587586,1.1109639339831214,-2.003750981148173
522.8000000000068,57.457284207873585,1.1193486125862713,-2.0039600449744137
524.0000000000067,57.57732300016681,1.1244808137568896,-2.003882944451518
525.2000000000068,57.69525568561811,1.1308482414892387,-2.004341028442051
526.4000000000068,57.81587061650551,1.1408696767217972,-2.0042901921777174
527.6000000000067,57.93386477304659,1.1492738737114987,-2.0042951910144353
528.8000000000068,58.053904712898856,1.1560270109744688,-2.003792820739937
530.0000000000068,58.174503956477515,1.16073510975172,-2.0036301950123
531.2000000000069,58.29404258288387,1.1708694411385956,-2.0036301801496332
532.4000000000069,58.41231158812656,1.1753411549863058,-2.0049492825893274
533.6000000000068,58.53152537919725,1.183484744627609,-2.004581924335464
534.8000000000069,58.65201243923299,1.1889103862635744,-2.0046200899956514
536.0000000000069,58.77101915449869,1.197721864409926,-2.00462009
537.2000000000069,58.890716420828745,1.2032918780234068,-2.004620090104539
538.4000000000069,59.00968860458584,1.2108582780542692,-2.005928551503786
539.600000000007,59.1289088895062,1.2186642304003021,-2.0059298599808217
540.800000000007,59.24886578547207,1.2246969814120485,-2.005325448674585
542.000000000007,59.36887938710332,1.2302421804128727,-2.004609575043733
543.200000000007,59.48787702095522,1.2376343516978778,-2.0039379086428966
544.400000000007,59.60738044537897,1.2431471039802826,-2.0052706527783677
545.6000000000071,59.72710977068799,1.2493146755777116,-2.005930006817192
546.800000000007,59.84649533748373,1.2574814294975134,-2.0059300099999997
548.000000000007,59.96641980228573,1.2626108492836499,-2.0059300100000006
549.2000000000071,60.08695583732712,1.2655116643901492,-2.0059300100633237
550.4000000000071,60.20620702824802,1.270843258754817,-2.006048511694046
551.6000000000072,60.32606690674214,1.2770959835583153,-2.005939905381379
552.8000000000071,60.44602874698825,1.2832534532224547,-2.0072937878901502
554.0000000000072,60.56598425947519,1.291174163513036,-2.0082300805328153
555.2000000000072,60.68555656863372,1.2958868090187996,-2.0069204935826304
556.4000000000071,60.80516429470436,1.3042326275799334,-2.0069200585649605
557.6000000000072,60.92572604268724,1.3085296430031221,-2.0082363850064016
558.8000000000072,61.04637391404089,1.3157581809245529,-2.0092272645257863
560.0000000000073,61.165751692479674,1.3221847329572776,-2.008570416254108
561.2000000000073,61.28647211810417,1.326785550382518,-2.008570125000033
562.4000000000073,61.40564912914275,1.332615622355248,-2.0085701249992565
563.6000000000073,61.52576945839576,1.3399719298853878,-2.008564410535418
564.8000000000073,61.64664767989221,1.346113633703097,-2.0092199524186367
566.0000000000073,61.766112678529915,1.3493813044607184,-2.0092142302769673
567.2000000000073,61.886728827012085,1.3577237886241227,-2.009234645628766
568.4000000000074,62.00642476275709,1.365523720947294,-2.010539918708294
569.6000000000074,62.12826331222584,1.3721208097275919,-2.011530059023978
570.8000000000075,62.24789622062209,1.3787075708376397,-2.0115299400000475
572.0000000000074,62.36839025154979,1.3869426261801652,-2.0115302406630824
573.2000000000074,62.48770617877139,1.3924968175876518,-2.0102101296845287
574.4000000000075,62.60832968223245,1.3986379563978715,-2.010206229106993
575.6000000000074,62.72779734516903,1.4038160625897458,-2.010210331704472
576.8000000000075,62.84744287593023,1.4111108441603553,-2.010538326142107
578.0000000000075,62.968070100282276,1.4199599127722868,-2.013172523306582
579.2000000000075,63.088826351501254,1.4261629013456882,-2.0131696358418116
580.4000000000076,63.20865405150883,1.4333663741684635,-2.0115207932485752
581.6000000000075,63.329060506531874,1.4424214468182475,-2.012468329486113
582.8000000000076,63.44909589028756,1.4494389483943189,-2.01283892656469
584.0000000000076,63.568968373551385,1.4589198791167637,-2.012816540183527
585.2000000000075,63.688384247447246,1.465581883396288,-2.0141599607256926
586.4000000000076,63.809090220938906,1.4740658668063917,-2.015470083350141
587.6000000000076,63.92939515286285,1.4810809762078083,-2.014159829392633
588.8000000000077,64.04923583652355,1.4908488508440905,-2.014138298553618
590.0000000000077,64.16960792050313,1.4980932067430053,-2.0153758790765646
591.2000000000077,64.28930124544556,1.5056068471823638,-2.015479975291132
592.4000000000077,64.40962305817048,1.5151197581543587,-2.0164707014215293
593.6000000000078,64.52912210849638,1.5256007402723066,-2.015150187593698
594.8000000000077,64.64990831253829,1.532328833928077,-2.0158104719278134
596.0000000000077,64.77019217047527,1.543219473828359,-2.0158149077867993
597.2000000000078,64.89084472914487,1.5490390415992628,-2.017461813586519
598.4000000000078,65.00879688835465,1.5583504401583084,-2.0181100444424858
599.6000000000079,65.13216422155732,1.5690011344438215,-2.0180581216289535
600.8000000000078,65.2517327149496,1.5790345886209405,-2.019266290696739
602.0000000000078,65.37200795120886,1.5897790717726423,-2.0214262640556244
603.2000000000079,65.49265830390483,1.5996649378206393,-2.02060050562485
604.4000000000078,65.611650934896,1.6067412529889997,-2.020410190008957
605.6000000000079,65.73254633010367,1.619939476700197,-2.0204111062445334
606.8000000000079,65.85259575917398,1.6294662234807333,-2.0219414654737053
608.000000000008,65.97278977311232,1.6416345172955953,-2.0236765483907146
609.200000000008,66.09436133908581,1.651223667834491,-2.025024279271766
610.4000000000079,66.2140079645621,1.6651899170437054,-2.026330130620238
611.600000000008,66.33521641948596,1.6762221861337796,-2.0273185426285183
612.800000000008,66.4553199380626,1.6885391948848145,-2.027317690044751
614.000000000008,66.57668628008406,1.6961437301318723,-2.028328541045028
615.200000000008,66.69563883809778,1.7102329259282796,-2.0299500447616183
616.400000000008,66.81707389648562,1.720658223023953,-2.0318238177513734
617.6000000000081,66.93900253084131,1.7330275410327236,-2.0329100770483737
618.8000000000081,67.05845693059237,1.7445932726484514,-2.0315722176101807
620.0000000000081,67.17882960373193,1.7577885732282539,-2.0345522000380125
621.2000000000081,67.3001104618595,1.7703873504783723,-2.035895258665626
622.4000000000082,67.42139815594521,1.7838923616611544,-2.036869160418513
623.6000000000081,67.54133058732877,1.7970658752316873,-2.038234361338738
624.8000000000081,67.6627760182285,1.8114870807031753,-2.041660994531475
626.0000000000082,67.7834137468153,1.8260634375200084,-2.0446860810372964
627.2000000000082,67.903943486676,1.8452846364812956,-2.047417428627296
628.4000000000083,68.02524811554413,1.8556018617228878,-2.0488193249751245
629.6000000000082,68.1453650917617,1.8700095276583761,-2.0488236995198803
630.8000000000083,68.26682106020453,1.8868770332273044,-2.0514713514071463
632.0000000000083,68.38740867311934,1.9038704220201972,-2.0538906421995136
633.2000000000082,68.50823492800485,1.919969262419476,-2.053918007083828
634.4000000000083,68.62999794131126,1.9329600167187817,-2.054089867598202
635.6000000000083,68.7500944258093,1.948381437847657,-2.057628194371323
636.8000000000084,68.87213307588505,1.9649188125055732,-2.0605475118399927
638.0000000000084,68.99211674380734,1.9790933894282718,-2.062639567355476
639.2000000000083,69.11443613822088,1.9964510639608448,-2.0639878167016903
640.4000000000084,69.23499214666447,2.012888605272666,-2.0651826203632044
641.6000000000084,69.35607739245842,2.0331930633085435,-2.068483794084111
642.8000000000084,69.47721530442473,2.050517085772959,-2.072069908641173
644.0000000000084,69.59766447426962,2.0677654495077475,-2.07514891478683
645.2000000000085,69.71889235821298,2.087888352594751,-2.0780986517091717
646.4000000000085,69.83946932016012,2.106524242328636,-2.079820077778331
647.6000000000085,69.96135389201872,2.125210580816763,-2.0835926803486835
648.8000000000085,70.08115533917052,2.14711162332652,-2.0890719543134697
650.0000000000085,70.20274127872895,2.168223569256841,-2.0923236445056235
651.2000000000086,70.32352897260358,2.192720722347453,-2.0983996077289926
652.4000000000085,70.44445327905285,2.2156215274138082,-2.1004871260644356
653.6000000000085,70.56508011425109,2.2416649186335897,-2.103505355342347
654.8000000000086,70.68590723364997,2.2692679228644224,-2.107287584404914
656.0000000000086,70.80655718324061,2.297956912895239,-2.1108128137259845
657.2000000000087,70.92694576299522,2.3259478245731464,-2.1154988350785233
658.4000000000086,71.0463766826918,2.3588338029853704,-2.1203940824142102
659.6000000000087,71.16858474548883,2.3915462321871233,-2.1266379806124465
660.8000000000087,71.28856897359836,2.4247884182279664,-2.130073395089471
662.0000000000086,71.40990456435539,2.461572576678015,-2.1357974544034075
663.2000000000087,71.53051299125583,2.4980931140523506,-2.1391830408879
664.4000000000087,71.65047664042454,2.5317088880781076,-2.143051478135671
665.6000000000088,71.77238195427772,2.5717428095933674,-2.1481632058743747
666.8000000000088,71.89300665965153,2.6088344446033407,-2.156194060452294
668.0000000000088,72.01321553374802,2.650190156452855,-2.1627150833119764
669.2000000000088,72.1336263018275,2.6913341533403163,-2.1680620905622545
670.4000000000088,72.25574227140076,2.7367420232093944,-2.175130933023876
671.6000000000088,72.37647173297512,2.7816824798373094,-2.1826118974886084
672.8000000000088,72.49745766235631,2.8249278963261024,-2.1903042452608066
674.0000000000089,72.61808628525448,2.8737015253379186,-2.1962254802141645
675.2000000000089,72.73942614040233,2.918598206676109,-2.2029001528579526
676.400000000009,72.86066285747815,2.965402987126129,-2.2115452483246347
677.6000000000089,72.98106223256617,3.0140336384333044,-2.2188621628455287
678.8000000000089,73.10259682122023,3.0602264725489974,-2.225949395520961
680.000000000009,73.2223045469513,3.109078911568688,-2.234014293111146
681.2000000000089,73.34563347058364,3.1612726958166406,-2.2431975157918647
682.400000000009,73.46605179072137,3.209599240732678,-2.2518732265423913
683.600000000009,73.58804763700846,3.2602058656430226,-2.2612877981085475
684.800000000009,73.70879466971806,3.3066783714766803,-2.2702126574116095
686.0000000000091,73.82962265056766,3.3602694691572084,-2.283069436795656
687.200000000009,73.95084971463719,3.410303896411995,-2.2917607241256555
688.4000000000091,74.06957139905249,3.460762042195276,-2.301953137060247
689.6000000000091,74.1933283848665,3.516334763867611,-2.314106065077295
690.800000000009,74.31487832463806,3.5692768999402187,-2.3255575363195944
692.0000000000091,74.43589789228751,3.6238241370391573,-2.3369420118016855
693.2000000000091,74.55698744110467,3.6780510553923986,-2.350474587853207
694.4000000000092,74.67911937540916,3.7333342179047633,-2.3616688019901018
695.6000000000092,74.79980543763524,3.784874872108818,-2.3748953105240846
696.8000000000092,74.92130155829437,3.835842483620819,-2.385850083751027
698.0000000000092,75.04309817323124,3.887253930936164,-2.4024326920468515
699.2000000000093,75.16515908326328,3.9392392037146804,-2.4172037315479615
700.4000000000092,75.28689833612219,3.994196362241965,-2.431458325592751
701.6000000000092,75.40882591301721,4.043026550561195,-2.446185568582495
702.8000000000093,75.52970258030008,4.089574298956799,-2.462903732141001
704.0000000000093,75.65137128845265,4.141577473446805,-2.4772521333013944
705.2000000000094,75.77266997334964,4.189891001222382,-2.4931184718957877
706.4000000000093,75.8946471150608,4.237882871271507,-2.5069813095694347
707.6000000000093,76.01593195270657,4.283169901215668,-2.524329454371808
708.8000000000094,76.13761359100792,4.328759652471025,-2.5429962015510537
710.0000000000093,76.25925097930109,4.3723812101055675,-2.5610173117015664
711.2000000000094,76.37990029874207,4.414836787340768,-2.5782614994606305
712.4000000000094,76.50111929190625,4.456348655957697,-2.595588262019905
713.6000000000095,76.6233911925343,4.497481039812368,-2.611170149970001
714.8000000000095,76.74419736048945,4.532055826967326,-2.629935024430539
716.0000000000094,76.86667548907985,4.570818623958089,-2.647531330718482
717.2000000000095,76.98792012889707,4.604149849678917,-2.6658079357640823
718.4000000000095,77.10980897186822,4.6279239587387275,-2.6848604275043493
719.6000000000095,77.23097446683823,4.653145289091983,-2.7058527253796036
720.8000000000095,77.35197572474746,4.663947909400843,-2.722655898022992
722.0000000000095,77.4734749018825,4.658677063723732,-2.7411365571911177
723.2000000000096,77.59524030794685,4.636256734857699,-2.7599042933146554
724.4000000000096,77.71648683055442,4.588901115333168,-2.7801058632229063
725.6000000000096,77.83748977101354,4.49555679098371,-2.79468144030553
726.8000000000096,77.95899895275835,4.328279733194534,-2.8116832792985678
728.0000000000097,78.07970057750188,4.007755640555364,-2.82712885424659
729.2000000000096,78.19970424912589,3.3054586893875038,-2.840300026550696
730.4000000000096,78.32064210814406,2.5385420932359124,-2.845495835914406
731.6000000000097,78.4416548396986,2.3392210785910894,-2.846460136785298
732.8000000000097,78.56137758455358,2.2940361490181287,-2.84646012389926
734.0000000000098,78.6832998772325,2.2852264318845554,-2.847789727189973
735.2000000000097,78.80426594025911,2.2902552345419096,-2.8480435667008743
736.4000000000098,78.9262422420584,2.2974959446759655,-2.847780025016899
737.6000000000098,79.04678184174699,2.304815918828381,-2.847777851637776
738.8000000000097,79.16850519083903,2.313857973892968,-2.845796002775323
740.0000000000098,79.28931657569137,2.322602308175649,-2.8471002541510977
741.2000000000098,79.41090630783043,2.334383334542672,-2.847109972308181
742.4000000000099,79.53205896378024,2.346346941757959,-2.8484299377151108
743.6000000000099,79.65426406708988,2.3550158054193338,-2.8484301224717896
744.8000000000098,79.77545331831783,2.366359000794324,-2.849419876520738
746.0000000000099,79.8961290419455,2.3768017971614817,-2.848432573054689
747.2000000000099,80.01678139826772,2.3884298397686567,-2.8497490627746216
748.4000000000099,80.13806198364807,2.399889873590649,-2.849749839999944
749.6000000000099,80.25890925307942,2.410024240055778,-2.8497498382746063
750.80000000001,80.37989534687367,2.419295408392764,-2.851050700033351
752.00000000001,80.5021468668087,2.4282035060492833,-2.850097545835995
753.20000000001,80.62394632682864,2.436742959919352,-2.850409836667066
754.40000000001,80.74553882188776,2.448871907702466,-2.850409835000011
755.60000000001,80.8678020832652,2.45823742576953,-2.850409347175003
756.8000000000101,80.98844082309073,2.468980082368596,-2.8507110243217784
758.00000000001,81.11188481777043,2.475223688156236,-2.851200663093176
759.20000000001,81.23162012728801,2.4871175337858613,-2.851390199396174
760.4000000000101,81.35437422381732,2.4981936846404884,-2.851390084999929
761.6000000000101,81.47490289544061,2.508357040873264,-2.8513895224558867
762.8000000000102,81.59866650276089,2.5210394662179887,-2.8510600858305484
764.0000000000101,81.71913078711715,2.5283337905519083,-2.8510741804344857
765.2000000000102,81.84078518257833,2.542656405904141,-2.8510599664033984
766.4000000000102,81.9634747004262,2.549846480025911,-2.8517254693964107
767.6000000000101,82.08526346754232,2.563484740308998,-2.851719980000712
768.8000000000102,82.20687448160047,2.573992475338914,-2.851720218524873
770.0000000000102,82.32799320404524,2.5840481042090895,-2.853594748152405
771.2000000000103,82.45020584944318,2.597789606181324,-2.852374095877997
772.4000000000103,82.57190169360126,2.607886179271705,-2.852380129994602
773.6000000000103,82.69289141813644,2.6192238104413144,-2.852380130003232
774.8000000000103,82.81438353924493,2.6329950582228467,-2.85209824823149
776.0000000000103,82.93606344042526,2.643060672220856,-2.8523799616667285
777.2000000000103,83.0573131605743,2.6556476018340076,-2.85187494639544
778.4000000000103,83.17928961748653,2.666170650987236,-2.853052427279227
779.6000000000104,83.30085808706633,2.6779132085708635,-2.8530328132172453
780.8000000000104,83.42209474080944,2.688131799466434,-2.853029442825759
782.0000000000105,83.54370857653295,2.6989551046845546,-2.851720034320488
783.2000000000104,83.66565657870012,2.71462034233676,-2.852606163426665
784.4000000000104,83.78659324938032,2.7240766749404677,-2.8527100500067717
785.6000000000105,83.90847792460856,2.7376758400247643,-2.852953272108161
786.8000000000104,84.03062926093219,2.7496200878735544,-2.8524067904041854
788.0000000000105,84.15152011956903,2.7627601258630814,-2.853752571085395
789.2000000000105,84.27339347988375,2.7749618112715075,-2.8527288040083203
790.4000000000106,84.39579498720735,2.7887903471526694,-2.853632926145187
791.6000000000106,84.5174514137619,2.801237114793668,-2.8527102877161106
792.8000000000105,84.64000113278699,2.812269941750097,-2.8544322145354752
794.0000000000106,84.76213251246962,2.8289830353451344,-2.855669832803538
795.2000000000106,84.88359758637763,2.8376106903914526,-2.856100360240872
796.0000000000106,84.96525040512248,2.8489426310287764,-2.8556700248832456