File: 01_Data/Laminate_Flooring/STA/N2/10K_min/Laminate_Flooring_STA_N2_10KData_221205_R2.csv
##Temp./Â°C,Time/min,DSC/(mW/mg),Mass loss/mg
51.0,10.586923690809035,-1.8135676956149749,0.007606939714928984
52.20000000000002,11.049864121142614,-1.6862624085866562,0.004224532790233937
53.400000000000034,11.332157786220506,-1.6048537367672981,0.0038946867262552587
54.60000000000005,11.558324856917261,-1.545878366762635,0.00249150451163338
55.80000000000007,11.76013698624934,-1.501849427643734,0.003741500863344349
57.000000000000085,11.940980793428178,-1.4658051618460175,0.0038187790501780228
58.2000000000001,12.114462644712365,-1.4362642163128168,0.0020199658477499938
59.40000000000012,12.285577460493938,-1.4123724031888223,0.0039652542740373775
60.600000000000136,12.444011863981022,-1.3894467622233726,0.003099390714703887
61.80000000000015,12.601302317066102,-1.371731316442936,0.002664654119109322
63.00000000000017,12.753613309068124,-1.35536627959519,0.0020546758989157254
64.20000000000019,12.90220831402826,-1.341430992862803,0.0030566011333670318
65.4000000000002,13.049591051414154,-1.324705324390919,0.002910546345773035
66.60000000000022,13.193156436585829,-1.3151547683933131,0.003337881549708044
67.80000000000024,13.335867925763253,-1.3056989641184058,0.003105755905090213
69.00000000000026,13.476652444318463,-1.2962808226049287,0.0016594372992999595
70.20000000000027,13.616028382661039,-1.283759926465667,0.0016857295996999255
71.40000000000029,13.75277017097314,-1.2717490939874168,0.0021101106527483537
72.6000000000003,13.889139419809135,-1.2611918009429104,0.0016826538846173023
73.80000000000032,14.02048205108301,-1.2496167028167289,0.0016282146049988455
75.00000000000034,14.15753180185819,-1.2394851072065027,0.0016323594553311338
76.20000000000036,14.292231758205526,-1.2273977497031676,0.0016606316208083172
77.40000000000038,14.422372004759891,-1.2178125971806955,0.002949767063492814
78.60000000000039,14.553461280457364,-1.2067874094781548,0.0016585767950578756
79.80000000000041,14.68317892378897,-1.1975348470277758,0.0016824977179634715
81.00000000000043,14.81214447875802,-1.1865493661959154,0.001117031035408722
82.20000000000044,14.93946333623957,-1.1757810990719728,0.0018254806546549318
83.40000000000046,15.066009869476773,-1.1672584909212886,0.0015204736158889176
84.60000000000048,15.193434618020985,-1.1591922227500597,0.0015934506362640377
85.8000000000005,15.317621860161315,-1.1511032177489111,0.0003301325582780734
87.00000000000051,15.444436932952792,-1.1436309891111374,-4.783161928800794e-05
88.20000000000053,15.569037496018229,-1.1370115323067704,0.0003502052878543438
89.40000000000055,15.691314647451337,-1.1294754512083067,0.001577631634717136
90.60000000000056,15.815003550698819,-1.1221679675349476,0.0003314023815184086
91.80000000000058,15.936770050316763,-1.114606833158901,0.00036874958343435793
93.0000000000006,16.05928443645739,-1.107538319331298,0.00033823251687170597
94.20000000000061,16.180929026669002,-1.0970991656021598,0.000660503989776906
95.40000000000063,16.302270229967657,-1.0910928217141498,0.0003303387920672307
96.60000000000065,16.424045572651764,-1.0833672790503581,0.0003415047034920349
97.80000000000067,16.543101922701457,-1.0760984577120325,-0.00022925709230481317
99.00000000000068,16.663034376695705,-1.0685777943353723,0.00032982201203601846
100.2000000000007,16.78243047204464,-1.0609559566212667,0.000343949784801012
101.40000000000072,16.901590760185847,-1.0523765319531744,0.00035071395481711676
102.60000000000073,17.020725469321,-1.0464760024382453,0.0003636327212630519
103.80000000000075,17.140191359380616,-1.0382436433542401,-0.00019403301053610988
105.00000000000077,17.258385686718718,-1.030680637501805,0.0003327149158307563
106.20000000000078,17.37647125179752,-1.024237660369755,0.0003392009674811902
107.4000000000008,17.49486136267038,-1.0173225976671934,0.00032778935830002354
108.60000000000082,17.612664054661252,-1.0106895850964746,-0.0009926150144221602
109.80000000000084,17.73074070828635,-1.0038432677170164,0.0003207628630503834
111.00000000000085,17.847462577577993,-0.9986640795429887,0.0002455589703505012
112.20000000000087,17.965096540084314,-0.9918482764875748,9.633958635291151e-06
113.40000000000089,18.08281883070057,-0.9867868863346506,0.001714730762038208
114.6000000000009,18.200229587866932,-0.9794780140353284,0.00034194850974333946
115.80000000000092,18.31599876382555,-0.9737287859743791,0.0016669211045226007
117.00000000000094,18.432875526974332,-0.9694527540153042,0.0003389568937812726
118.20000000000095,18.551643673398015,-0.96368264503441,0.00033637426525423564
119.40000000000097,18.6675834600318,-0.9570934181396301,0.0013375628434992848
120.60000000000099,18.78518824367168,-0.9517953941717884,0.0003265767165920863
121.800000000001,18.901639957790284,-0.9460590769979004,0.000330001032027738
123.00000000000102,19.018569830520832,-0.9408367069664344,-0.0009699943140843992
124.20000000000104,19.134958564195927,-0.9352943973713576,-0.0013484503699876527
125.40000000000106,19.251716313505682,-0.930456561854007,0.0003907279045556322
126.60000000000107,19.367250472631497,-0.9239041245362122,-0.0008963365991987438
127.80000000000109,19.484353978386245,-0.9198345305462191,-0.00067168807370388
129.0000000000011,19.598647140836366,-0.9136064750680384,-0.00045865261002919766
130.20000000000113,19.71590284254768,-0.9099770171727181,-0.0009570069861388752
131.40000000000114,19.83034747842875,-0.9052224457292731,0.0003096428284834474
132.60000000000116,19.945389175765673,-0.8996123659881199,0.0003371494164357003
133.80000000000118,20.06293722436479,-0.8943873490380682,-0.0006373853238379468
135.0000000000012,20.178697246062878,-0.8911761273480309,0.00033087052279423546
136.2000000000012,20.29358211865893,-0.8856510372423015,-0.0010031084748094443
137.40000000000123,20.409576429087743,-0.8816710283121498,0.0003481168267578383
138.60000000000124,20.52337642606777,-0.877599180345992,-0.00039398447253935487
139.80000000000126,20.63763618228189,-0.8716702920930044,-0.0009176251064855201
141.00000000000128,20.75281058824424,-0.8685189473908813,0.000340000580965949
142.2000000000013,20.86852544732876,-0.8630865966599979,-0.000992576452314875
143.4000000000013,20.98324432762577,-0.8589982912495757,0.00033517092922075165
144.60000000000133,21.09789214132527,-0.8533399294638487,-0.0018064580810621678
145.80000000000135,21.210010339518483,-0.8487648060845544,0.0003256336777583968
147.00000000000136,21.32700095768355,-0.8458283044671503,-5.1123632706318034e-05
148.20000000000138,21.44226209145334,-0.840378586388382,0.0001812158014704579
149.4000000000014,21.557587939963245,-0.8355199752845988,0.0002287639949019038
150.60000000000142,21.67131935310058,-0.8321061083549064,0.00022989147960394973
151.80000000000143,21.78569417566695,-0.828555113488605,-0.0011917928366593777
153.00000000000145,21.90055409684958,-0.8232613115545674,-0.0010899341379499994
154.20000000000147,22.013942806497194,-0.8189876453706104,-0.0010884114625602237
155.40000000000148,22.129082276036534,-0.8148028201147864,-0.0010933952270142377
156.6000000000015,22.241211937886813,-0.8107048606510475,-0.0005046939932373817
157.80000000000152,22.357579228748683,-0.8045943476927817,0.000365607581687577
159.00000000000153,22.471203355094463,-0.8003577119147114,-0.0009898684801630253
160.20000000000155,22.58564699035304,-0.795067956736742,-0.0009908297778569164
161.40000000000157,22.697902755456674,-0.7918969611036524,-0.0006613932314745163
162.6000000000016,22.813459751391292,-0.7866424020324277,-0.0006525571136486441
163.8000000000016,22.927234399552095,-0.7829962947132033,-0.0006500054756299889
165.00000000000162,23.042262746742647,-0.7785544061676639,-0.0009793590833666599
166.20000000000164,23.153558918176742,-0.775412661424366,-0.0016408664927500816
167.40000000000165,23.26978567216357,-0.7708439948760518,-0.0019691339208880443
168.60000000000167,23.384024332314404,-0.7672708121001288,-0.0010005746657517633
169.8000000000017,23.496803620051832,-0.7629351781809485,-0.0016296236713815304
171.0000000000017,23.611133021766644,-0.7607662247217509,-0.0032806464766217402
172.20000000000172,23.725874521869002,-0.7573421839850825,-0.000612076676365092
173.40000000000174,23.83870297726956,-0.7521840035287556,-0.003289195162605729
174.60000000000176,23.950540883202287,-0.7491879461098387,-0.001969993968702788
175.80000000000177,24.066796422797026,-0.7449969650100681,-0.0019688754475870596
177.0000000000018,24.181215287200377,-0.7425708265239056,-0.0016191935429756832
178.2000000000018,24.294653919372383,-0.7383599942168889,-0.002300173985310572
179.40000000000182,24.409088525075887,-0.7350963761001583,-0.0019703208289238994
180.60000000000184,24.522379584681403,-0.7313558037770541,-0.001969711528839291
181.80000000000186,24.636006030962186,-0.7288393490622016,-0.00196999987445734
183.00000000000188,24.750410943412337,-0.7269981035940585,-0.002613854435077556
184.2000000000019,24.864265281208645,-0.7228815066196523,-0.0026399532208083443
185.4000000000019,24.9780099672815,-0.7198174971121603,-0.0029598628178328923
186.60000000000193,25.092848899400682,-0.71739979134197,-0.003950740486788895
187.80000000000194,25.20561210802759,-0.7135561562182442,-0.0029592617169691415
189.00000000000196,25.32036354991186,-0.7104615066716812,-0.0029601143111444017
190.20000000000198,25.433539239616806,-0.7084858807725859,-0.003937020230174504
191.400000000002,25.54652476290092,-0.705031212333252,-0.0027268073718409447
192.600000000002,25.660360307236672,-0.701555992730585,-0.0026192848966415383
193.80000000000203,25.77483363294852,-0.6989097903621236,-0.00394000323494792
195.00000000000205,25.888603502410692,-0.6958382519082874,-0.003998437265974708
196.20000000000206,26.001109072401995,-0.6934992617669307,-0.0039644979934116975
197.40000000000208,26.11520632564491,-0.6902677026274916,-0.003950063114208646
198.6000000000021,26.228639534822214,-0.6868193961156088,-0.005270012862264473
199.80000000000211,26.343532005573923,-0.6845432206826942,-0.005269933882931621
201.00000000000213,26.45605745676975,-0.6805188642981587,-0.003950211830953343
202.20000000000215,26.570629854039097,-0.6773734419447093,-0.00468566032195028
203.40000000000217,26.684377630678718,-0.6753462322024455,-0.005260082422610779
204.60000000000218,26.79800886962252,-0.6722895161271862,-0.0065798874839195776
205.8000000000022,26.911488793922928,-0.6689280950473069,-0.0065800000647451284
207.00000000000222,27.026493923077396,-0.6657859878101188,-0.007564170176191709
208.20000000000223,27.138317259960818,-0.6614496448714756,-0.006579999974751338
209.40000000000225,27.252978934832644,-0.6597687035673279,-0.00657999998144998
210.60000000000227,27.367427864121325,-0.6563887660094501,-0.006897700221289327
211.80000000000229,27.480494355864444,-0.653736867368982,-0.009220067031106893
213.0000000000023,27.595290100043677,-0.6505547276606702,-0.007900007652810626
214.20000000000232,27.70916165608236,-0.646407563007346,-0.00818514597549358
215.40000000000234,27.822455302130376,-0.6449261888747785,-0.00954001230449908
216.60000000000235,27.93724065350042,-0.6427337193403582,-0.010077459659481036
217.80000000000237,28.051206858302695,-0.6393965093160479,-0.010859997414804923
219.0000000000024,28.165292827861936,-0.6383898170980128,-0.010860000116384771
220.2000000000024,28.27881789484386,-0.6364886353522183,-0.010297902273358694
221.40000000000242,28.39304518438696,-0.633772723316815,-0.011520000755445903
222.60000000000244,28.507259583193843,-0.6318739179942034,-0.011644116845235253
223.80000000000246,28.621099446695034,-0.6289327418901663,-0.012156984084057854
225.00000000000247,28.7357557519059,-0.626682802049644,-0.0129311760171813
226.2000000000025,28.849734890385445,-0.6244659957997046,-0.01318132765594271
227.4000000000025,28.963691313909116,-0.6222164937797693,-0.013169999569687896
228.60000000000252,29.07854356795039,-0.6194883937713814,-0.013726605891037469
229.80000000000254,29.191483830916436,-0.6170817603821666,-0.016140059843570587
231.00000000000256,29.30721828869436,-0.6142164484578374,-0.017284780449365655
232.20000000000258,29.4202988145689,-0.6131580324497978,-0.017451127314357606
233.4000000000026,29.535179999567063,-0.6101642270804895,-0.01844000416103375
234.6000000000026,29.64903217243377,-0.6072316969293634,-0.01979053533387276
235.80000000000263,29.763038998748787,-0.603593120866008,-0.01975063192093751
237.00000000000264,29.877755074647908,-0.6020195064149981,-0.021448158251816007
238.20000000000266,29.991571114200212,-0.5987759326943278,-0.024009553023503827
239.40000000000268,30.106104424736962,-0.5967251750567512,-0.024024682288934063
240.6000000000027,30.218657374719207,-0.5932449869788116,-0.024036219986153462
241.8000000000027,30.33351382183476,-0.5916590422117838,-0.02667279566607972
243.00000000000273,30.448087187971936,-0.5902864979807751,-0.026670010655871934
244.20000000000275,30.562046518153256,-0.5870573692880646,-0.02930072268146855
245.40000000000276,30.676457733233573,-0.5849273112319617,-0.02797969490674701
246.60000000000278,30.789264237711826,-0.5827644635150505,-0.029711414079784948
247.8000000000028,30.902465557218736,-0.5800391432271339,-0.03029353559037329
249.0000000000028,31.0172013762376,-0.577666084143928,-0.03161029080056421
250.20000000000283,31.132759683129873,-0.5750150393099275,-0.03326090631765943
251.40000000000285,31.245200971834816,-0.574264578910406,-0.03591437058590774
252.60000000000286,31.360433695256333,-0.5723686210743958,-0.03687928780626093
253.80000000000288,31.4752808142514,-0.5700842979610484,-0.039336102646250204
255.0000000000029,31.588541162658174,-0.570333879087407,-0.04227389291492667
256.2000000000029,31.701357569012934,-0.5689159595029591,-0.044715989569816816
257.40000000000293,31.81552329751527,-0.5697055801406481,-0.04556383723119373
258.600000000003,31.93012699044486,-0.5695604006458694,-0.0477987474112358
259.80000000000297,32.04405529338263,-0.5696621516440711,-0.04910820566148688
261.00000000000296,32.158030005018624,-0.5685068839639895,-0.05324831212688297
262.200000000003,32.27149265677256,-0.5633974272336449,-0.05547655994489098
263.40000000000305,32.386857962926776,-0.5576227184294938,-0.057440259055937304
264.60000000000304,32.500643293575514,-0.5493867455462793,-0.06060831170254177
265.800000000003,32.61538529689948,-0.539430331308159,-0.06632424628044031
267.00000000000307,32.72925936191209,-0.5332046262255953,-0.06942681865264744
268.2000000000031,32.8418296818892,-0.528119973263498,-0.07409244404482296
269.4000000000031,32.9572844095024,-0.5229131143880679,-0.07991509809839625
270.6000000000031,33.071532699421766,-0.516114673960019,-0.08678050736154219
271.80000000000314,33.18630901181471,-0.508927939155062,-0.09389883800526633
273.0000000000032,33.30073892521253,-0.5040126355779552,-0.10252026069377118
274.2000000000032,33.41435866339587,-0.4987185621276208,-0.11119268817589756
275.40000000000316,33.52864999147187,-0.49289273724310234,-0.12146620462745927
276.6000000000032,33.64334241753775,-0.4873197823270307,-0.13422616149352606
277.80000000000325,33.75708581313774,-0.4847222150618437,-0.1461464463801887
279.00000000000324,33.872860536204875,-0.4801119832284227,-0.16006529464570818
280.20000000000323,33.986946299882774,-0.47400961803659114,-0.1764016912961215
281.4000000000033,34.100610810776345,-0.46740208786316945,-0.19054444113142965
282.6000000000033,34.2167419987978,-0.4568349337568277,-0.2067548731278679
283.8000000000033,34.33100370455452,-0.44268000509901745,-0.2233208471715038
285.0000000000033,34.44505888285267,-0.4257733431934073,-0.24117908284955503
286.20000000000334,34.56047992776066,-0.40887024710264086,-0.2594917737582989
287.4000000000034,34.674450836466576,-0.3871048623069082,-0.2772090397179068
288.6000000000034,34.78850361603153,-0.37011033490058504,-0.29686373984014924
289.80000000000337,34.90415682545432,-0.35399956788071846,-0.3146399385066099
291.0000000000034,35.01895503217779,-0.33990836164661536,-0.3344842601764464
292.20000000000346,35.13430063172173,-0.3295907952600326,-0.35336701117970737
293.40000000000344,35.24878239326108,-0.32248903858486466,-0.37360891466522883
294.60000000000343,35.3622916082001,-0.31843065154342876,-0.39080508362034205
295.8000000000035,35.4781442693501,-0.31742358008355837,-0.408197394484056
297.0000000000035,35.593269905050235,-0.32025047704923265,-0.4242166280500599
298.2000000000035,35.707885225967,-0.32482443429426916,-0.44088257202523806
299.4000000000035,35.82260879898232,-0.33043244586576953,-0.4560290149978261
300.60000000000355,35.938248242907775,-0.33854520007995226,-0.4706989216929278
301.8000000000036,36.052232498473536,-0.34830857754239597,-0.4828225655179761
303.0000000000036,36.16755089740089,-0.35747810136585584,-0.49700408048691225
304.20000000000357,36.28228146950879,-0.36919005785628006,-0.507671916397455
305.4000000000036,36.39499004949736,-0.3785265627351046,-0.5188729331697708
306.60000000000366,36.51173226665508,-0.3894557596940508,-0.5290093019999009
307.80000000000365,36.62669016563019,-0.39927989542098197,-0.5382953162090338
309.00000000000364,36.74179394803617,-0.4108856609958379,-0.5480774875793366
310.2000000000037,36.85696103025494,-0.4198047056576225,-0.55616156696711
311.40000000000373,36.97200098083654,-0.4273928903549954,-0.5630532519018789
312.6000000000037,37.08780104507306,-0.4360965334572201,-0.5706754098191191
313.8000000000037,37.20168584709216,-0.44321035573335127,-0.5789052057842556
315.00000000000375,37.31766423096947,-0.4514651125485747,-0.5853466617546297
316.2000000000038,37.430929360009245,-0.4595625917686205,-0.5901815218158619
317.4000000000038,37.544988743080125,-0.4670913201649442,-0.5958774902786086
318.6000000000038,37.66150886772791,-0.4734319879895076,-0.6037273061627539
319.8000000000038,37.77726898533512,-0.47939937593306625,-0.6078701228471104
321.00000000000387,37.89222824223747,-0.48829156761067305,-0.612343182765283
322.20000000000385,38.00668408859273,-0.4938705704903441,-0.6166164455406187
323.40000000000384,38.123280901463694,-0.4989608496344006,-0.6226693644045831
324.6000000000039,38.238079040051225,-0.5056708802395437,-0.6265038997332937
325.80000000000393,38.352975023176796,-0.5101747661580436,-0.6297738971637141
327.0000000000039,38.46896653170482,-0.5170911771653894,-0.6336579274325995
328.2000000000039,38.58479122690951,-0.5223002237418723,-0.6363558441299553
329.40000000000396,38.70011376224949,-0.5261808632992873,-0.6403572379180664
330.600000000004,38.8122639453789,-0.5327245014250009,-0.6424607333728796
331.800000000004,38.93048395269208,-0.5346793109320238,-0.6457401185342349
333.000000000004,39.045392348281474,-0.5386787706656978,-0.648343903827385
334.200000000004,39.16111831715328,-0.5427780293309352,-0.6509953494600857
335.40000000000407,39.27602007075148,-0.545135476890662,-0.6542974634858676
336.60000000000406,39.3914936860266,-0.5489385346880049,-0.6576427125510063
337.80000000000405,39.50645619589944,-0.5517487047735656,-0.6588154551995653
339.0000000000041,39.622604340484514,-0.552865259164806,-0.6615536244180555
340.20000000000414,39.73791717388091,-0.5555769048064436,-0.6628700913623913
341.4000000000041,39.85227868365837,-0.5577519944479287,-0.6641836848172749
342.6000000000041,39.96635227918852,-0.5588552075539842,-0.6655280524139853
343.80000000000416,40.0837105930191,-0.5611831637499815,-0.6668229974483313
345.0000000000042,40.200045531554025,-0.563876453245346,-0.6681400497072563
346.2000000000042,40.315749266791336,-0.563531445872968,-0.6705063834331759
347.4000000000042,40.43039833590011,-0.563609487506179,-0.6704219026495517
348.60000000000423,40.54643299645864,-0.5651152848599632,-0.6730692606438646
349.8000000000043,40.66267032046826,-0.5649269038078093,-0.67309111298463
351.00000000000426,40.778484537657334,-0.5645352484457418,-0.6751648158154548
352.20000000000425,40.89445491277358,-0.5643159669538887,-0.6756627758093159
353.4000000000043,41.008152058817885,-0.563969630467323,-0.6783376907644314
354.60000000000434,41.12717334607668,-0.5615242602985601,-0.6783305342632602
355.80000000000433,41.243368996695565,-0.5609276024552399,-0.6783400108085149
357.0000000000043,41.35944688561639,-0.5610381047409932,-0.6792126472399045
358.20000000000437,41.47563863660257,-0.5592545041847103,-0.6806500002179376
359.4000000000044,41.59052969135401,-0.5556396761990591,-0.680652580857446
360.6000000000044,41.70691499217832,-0.5551557271838984,-0.6809700080716388
361.8000000000044,41.82372555718144,-0.5541227748246654,-0.6809699991280542
363.00000000000443,41.93959452723816,-0.5529958560574997,-0.6829466169362743
364.2000000000045,42.0544759117041,-0.5508135061103687,-0.683643036556846
365.40000000000447,42.17148722582174,-0.549469758152898,-0.6836099936013764
366.60000000000446,42.28789419972102,-0.5475741876599881,-0.6836141485728158
367.8000000000045,42.40406316317727,-0.5470500391854513,-0.6849302653744531
369.00000000000455,42.521505340759795,-0.5464443713989103,-0.6849422175536506
370.20000000000454,42.63586660941158,-0.5455124653188282,-0.685930197977231
371.4000000000045,42.752690403855524,-0.5432687764410647,-0.6869282989869614
372.60000000000457,42.86857957885089,-0.5402418829102874,-0.6875599691030323
373.8000000000046,42.98470328393105,-0.5396923190255423,-0.6885183337701255
375.0000000000046,43.10153122549107,-0.5390540379322573,-0.6885568712597583
376.2000000000046,43.21668300162532,-0.5390002219192597,-0.6898110469565819
377.40000000000464,43.33231983061566,-0.537198667370115,-0.6885565075141011
378.6000000000047,43.45013153915477,-0.5366788678509129,-0.6892170526197527
379.8000000000047,43.56635534685857,-0.5346621267448339,-0.6898700062655991
381.00000000000466,43.68073282240792,-0.5341134515328769,-0.6911899707719211
382.2000000000047,43.79921819614384,-0.5334040974052563,-0.6911900002833669
383.40000000000475,43.91497881444782,-0.5315675148781107,-0.6930234514657183
384.60000000000474,44.03233612725266,-0.531284438205662,-0.6938200000112964
385.80000000000473,44.149588897881756,-0.5304611024068526,-0.6938200940532666
387.0000000000048,44.26615271350121,-0.5290659210869679,-0.6937682403676453
388.2000000000048,44.38173785547162,-0.5271115162800161,-0.6944798987161773
389.4000000000048,44.499723169046604,-0.5256211994705342,-0.6958000066314165
390.6000000000048,44.616677397787605,-0.5257795523567002,-0.6962882495708915
391.80000000000484,44.732332041429046,-0.5240669645678071,-0.6958056892109545
393.0000000000049,44.84982742756093,-0.5238484600827906,-0.697119876107839
394.2000000000049,44.96749167263608,-0.5220300212402338,-0.6990898521494402
395.40000000000487,45.084084197997065,-0.5204236735120908,-0.6990900003849143
396.6000000000049,45.19988945353772,-0.5185375872468008,-0.7004010866149457
397.80000000000496,45.31706881892252,-0.5180151157004951,-0.7017399554428825
399.00000000000495,45.43377608830287,-0.5161672959676836,-0.7017299999037583
400.20000000000493,45.549900671507906,-0.5153509273185457,-0.7026368531735709
401.400000000005,45.66628183064733,-0.5155290311075311,-0.7030512848403938
402.600000000005,45.78296427990994,-0.5135749669972645,-0.7040300035462446
403.800000000005,45.900144889665626,-0.5120582482254277,-0.7040171982351873
405.000000000005,46.01716298826977,-0.5113738278302509,-0.7056858918672044
406.20000000000505,46.13102841071947,-0.5101793112151515,-0.7056797790219629
407.4000000000051,46.250727200475865,-0.50951748654879,-0.7060014523138927
408.6000000000051,46.36737960918931,-0.5085808807977136,-0.7083107875223904
409.80000000000507,46.48429472969266,-0.5094145300163921,-0.7096304910224407
411.0000000000051,46.601968144134354,-0.5074666656695843,-0.7109499411516236
412.20000000000516,46.71787595652465,-0.507176213452931,-0.713293578225008
413.40000000000515,46.83515356789901,-0.5055763342773734,-0.71193417445033
414.60000000000514,46.95191350585494,-0.5057092081876458,-0.7132869430173185
415.8000000000052,47.06923352989202,-0.5043542023742152,-0.7159187045604476
417.00000000000523,47.185896582097214,-0.5029917777279426,-0.71813047537779
418.2000000000052,47.303499698230375,-0.5026218272638711,-0.7195585157071407
419.4000000000052,47.41992226400434,-0.5035843191098988,-0.7208304303147015
420.60000000000525,47.53713039818527,-0.5011892602003273,-0.7221061810547251
421.8000000000053,47.65359614775968,-0.5012683500122345,-0.7234522902251737
423.0000000000053,47.770932255450155,-0.5013867812057581,-0.7261017717482945
424.2000000000053,47.886140937473286,-0.49923750209012985,-0.7274604694684563
425.4000000000053,48.00585546896101,-0.49751726326126144,-0.7300591238618552
426.60000000000537,48.122285163998775,-0.4955579286262279,-0.7314312818669282
427.80000000000535,48.23987759656772,-0.4944581446352584,-0.7339936610453024
429.00000000000534,48.35656147921921,-0.4931340991843433,-0.7369673404054331
430.2000000000054,48.474778721997566,-0.49193849923216476,-0.7389061143310691
431.40000000000543,48.5919992767588,-0.49118787725885227,-0.7395976947259362
432.6000000000054,48.708129742886264,-0.4880400599844675,-0.7432039044995049
433.8000000000054,48.82548313688441,-0.48800687509595764,-0.7458669256397199
435.00000000000546,48.94319163592367,-0.48302574666296466,-0.749825362147984
436.2000000000055,49.059901061370674,-0.4821054274067297,-0.7529072253601541
437.4000000000055,49.17704624219995,-0.4799522762661927,-0.7552261884289013
438.6000000000055,49.293761226044595,-0.47732954320161397,-0.7593398330059653
439.8000000000055,49.41092603616652,-0.4742010584276338,-0.7628873111702621
441.00000000000557,49.52890290366107,-0.46963009863795524,-0.7673896450673632
442.20000000000556,49.64619121547375,-0.46937513762155275,-0.7702721092670788
443.40000000000555,49.76316966483311,-0.4651467038469988,-0.7744074862144767
444.6000000000056,49.88073968652277,-0.4597532759739858,-0.7792231808191623
445.80000000000564,49.99729640619904,-0.45632081764985577,-0.784484676010901
447.0000000000056,50.114151434197964,-0.45214037585333133,-0.7889439833797307
448.2000000000056,50.23111570138892,-0.4462890591440613,-0.7946222767492763
449.40000000000566,50.34852023832712,-0.4423046466941587,-0.7999214281420102
450.6000000000057,50.46545757742358,-0.43611227007384973,-0.8046956316162035
451.8000000000057,50.582118394408596,-0.4318577894318327,-0.8097466896782177
453.0000000000057,50.700320468207735,-0.42704873765923657,-0.8161763278772618
454.20000000000573,50.81761889771206,-0.42079520007845067,-0.821675222767456
455.4000000000058,50.93510922963513,-0.413863495819935,-0.8276024594025095
456.60000000000576,51.05183246975309,-0.4108037432015079,-0.8329698615939565
457.80000000000575,51.16948693871026,-0.40495333495605246,-0.8392069344265836
459.0000000000058,51.286910010183455,-0.3998772480657691,-0.8455995932883522
460.20000000000584,51.403324589525965,-0.3941119588180499,-0.8516296392519904
461.40000000000583,51.5204532193462,-0.38763733367515196,-0.8579534753261813
462.6000000000058,51.63794153371137,-0.38210127616056666,-0.8636912410324875
463.80000000000587,51.75555974055594,-0.3785519591261831,-0.8699605727981505
465.0000000000059,51.872446300655994,-0.37399101506920696,-0.8766442325363775
466.2000000000059,51.990021633607874,-0.37213627500323937,-0.8814420688369986
467.4000000000059,52.10709852714441,-0.3685192164194126,-0.8888583211788683
468.60000000000593,52.2248910567479,-0.3656631817564101,-0.8933411461817862
469.800000000006,52.34232302050451,-0.36014340451316956,-0.8969932273592605
471.00000000000597,52.45916853559664,-0.3601389244104387,-0.9041876818311172
472.20000000000596,52.57729982792573,-0.3567798796987509,-0.9083778750293963
473.400000000006,52.69366538109454,-0.3562290188225596,-0.9146769685846232
474.60000000000605,52.81330535643689,-0.3553074447057333,-0.9186119452653525
475.80000000000604,52.93025672073601,-0.35218902981240446,-0.9232252591134591
477.000000000006,53.04864596827588,-0.35036934512828827,-0.9274194647115848
478.20000000000607,53.16389494817578,-0.34947042375496024,-0.9327302239260913
479.4000000000061,53.28403515585856,-0.3477609471459491,-0.9369118191688433
480.6000000000061,53.40268992458194,-0.3466716563401183,-0.9418618235201204
481.8000000000061,53.51869621980171,-0.3448529337199175,-0.9464182496006215
483.00000000000614,53.63924275976102,-0.34311609584703423,-0.9477855566691091
484.2000000000062,53.75604259251199,-0.34047840524345574,-0.951270856910905
485.4000000000062,53.87458868188602,-0.3389270021747338,-0.9546640134346633
486.60000000000616,53.99275731085264,-0.3387422731672059,-0.9582667266354274
487.8000000000062,54.11052718325392,-0.33634309596024414,-0.9609290819748435
489.00000000000625,54.22883478121638,-0.3347600219802769,-0.9635626412113769
490.20000000000624,54.3457675720444,-0.333715047303936,-0.9675153921162338
491.40000000000623,54.4642633629412,-0.331431836964855,-0.9701959279570618
492.6000000000063,54.58151982725864,-0.3303077544155522,-0.971792522223982
493.8000000000063,54.70063029790828,-0.326866575872984,-0.9728185724199321
495.0000000000063,54.81777642236919,-0.32542992203776,-0.9755205729751615
496.2000000000063,54.935086942181705,-0.32445815407500056,-0.9780006362414753
497.40000000000634,55.05481968253527,-0.32352215862140116,-0.9800933919982673
498.6000000000064,55.17316425777755,-0.3208428682000988,-0.9820782612668455
499.8000000000064,55.28995490369997,-0.32188818683644244,-0.9834299886053142
501.00000000000637,55.408224011344046,-0.32187572717683116,-0.9847514970844595
502.2000000000064,55.527538772208686,-0.31947089189266153,-0.9860696524222972
503.40000000000646,55.64438586514979,-0.31844861696104926,-0.9873900688707988
504.60000000000645,55.76241343510928,-0.31723667868621647,-0.9887072762683253
505.80000000000643,55.88063344935876,-0.31648839780683236,-0.99002004877496
507.0000000000065,55.997909312091544,-0.3141016613038872,-0.9903499725205558
508.2000000000065,56.11618288306859,-0.3136084190851099,-0.9926543118084754
509.4000000000065,56.23235061872895,-0.31405275670869315,-0.9933548455161594
510.6000000000065,56.35298891855568,-0.31195346734394824,-0.9939699997006173
511.80000000000655,56.47031688634682,-0.3116903463499251,-0.9939736552754188
513.0000000000066,56.58759288610793,-0.31039097398491666,-0.9966100030798475
514.2000000000066,56.70649289722259,-0.30806310791063407,-0.9958302621744148
515.4000000000066,56.82515053554062,-0.30738690837414867,-0.9979199739324947
516.6000000000066,56.94186836758136,-0.30691516656708834,-0.9991813164944143
517.8000000000067,57.06045481544646,-0.3064316816852303,-1.0003270404881563
519.0000000000066,57.17864315291858,-0.3018915056595675,-0.9992415809498643
520.2000000000066,57.29616009141219,-0.29856529005173543,-1.001879881887711
521.4000000000067,57.415124160553056,-0.29387359406202196,-1.0032422049439207
522.6000000000067,57.53239523785405,-0.28899307785059225,-1.003185282930254
523.8000000000068,57.651044149355236,-0.2849596712023996,-1.0045112075656757
525.0000000000067,57.76947768147263,-0.2828951118603156,-1.0049817854294871
526.2000000000068,57.88731100018276,-0.27916762045110677,-1.0045100007006686
527.4000000000068,58.00675165838879,-0.2772874244834629,-1.0054859807113443
528.6000000000067,58.12507147987651,-0.2740705600949837,-1.0068139851887716
529.8000000000068,58.24301569242793,-0.27129661572908625,-1.0073586438766409
531.0000000000068,58.36249837825517,-0.2659155818527603,-1.008129999961655
532.2000000000069,58.48122802700023,-0.26178606457551773,-1.008131622687884
533.4000000000069,58.5996358439364,-0.25784041553354875,-1.010766157388208
534.6000000000068,58.717467968444296,-0.24941544372797853,-1.0117500629673422
535.8000000000069,58.836531686404896,-0.2476453928201947,-1.0122484705753783
537.0000000000069,58.955466615536736,-0.24252942225742272,-1.012080009143895
538.2000000000069,59.07438487948931,-0.23642741415291335,-1.0134017142853353
539.4000000000069,59.19245217963443,-0.23105238242610904,-1.0155162497566614
540.600000000007,59.31164040380063,-0.22553144560954938,-1.0160300007577203
541.800000000007,59.42997754423314,-0.21945668694365614,-1.0173474068731823
543.000000000007,59.547959019001354,-0.21355935538198556,-1.0186706718591325
544.200000000007,59.667976455433156,-0.2063826876986105,-1.0178340862374458
545.400000000007,59.787346740688115,-0.19862015702643357,-1.020010936707127
546.6000000000071,59.9070449456687,-0.18728129434724175,-1.022989272339779
547.800000000007,60.02422596776245,-0.17903272251088084,-1.0244078029874912
549.000000000007,60.143349346273276,-0.16739971257984934,-1.0242637680749556
550.2000000000071,60.26231352796373,-0.15521342914980862,-1.0269400171648457
551.4000000000071,60.38146851880657,-0.14028664509220357,-1.028217194941642
552.6000000000072,60.500731219180466,-0.12602732535026748,-1.0298643873225468
553.8000000000071,60.62017313036001,-0.11297816462674748,-1.031190006456844
555.0000000000072,60.73958935007988,-0.09585880155453108,-1.032505663230943
556.2000000000072,60.85700941816226,-0.08139585178830716,-1.0350706121453674
557.4000000000071,60.97787255054518,-0.06373393791256589,-1.0391840468015094
558.6000000000072,61.09716955373225,-0.047612981821300804,-1.0418182824763238
559.8000000000072,61.21637025390288,-0.029978163888988583,-1.0430989208777346
561.0000000000073,61.33534135811077,-0.012993080411190034,-1.0458525701168946
562.2000000000073,61.45197665710589,0.0021957781410895617,-1.0495208556471343
563.4000000000073,61.57331812652522,0.01724547930255921,-1.0531853101189568
564.6000000000073,61.69185729467834,0.03340479024646269,-1.05520490821552
565.8000000000073,61.811225930955715,0.04739026905327884,-1.0589912320890766
567.0000000000073,61.93016464323528,0.0595534999218426,-1.0626953820407548
568.2000000000073,62.04960176895336,0.07017861983321266,-1.066819484600979
569.4000000000074,62.167975308406,0.07483770230122358,-1.068828158125113
570.6000000000074,62.28817331728094,0.07234325496287049,-1.0723724744833354
571.8000000000075,62.40685219054337,0.060348356371761,-1.0776369013632539
573.0000000000074,62.52662379594205,0.03543038902920382,-1.0816893111884305
574.2000000000074,62.64591598679881,-0.01382815435153393,-1.0850570246103466
575.4000000000075,62.765897900825884,-0.09510896630923454,-1.0894300882500123
576.6000000000074,62.883809627716836,-0.17170003263183498,-1.0906881104318549
577.8000000000075,63.00393885676731,-0.2204024420041953,-1.0933207746391922
579.0000000000075,63.123721705159895,-0.2469928355914951,-1.0920000373871592
580.2000000000075,63.24320983674198,-0.2645026569467758,-1.0933200924188706
581.4000000000076,63.36281189529417,-0.27377688697213504,-1.0946452833595584
582.6000000000075,63.48257332631718,-0.28129343197256557,-1.093664797728875
583.8000000000076,63.60150773241286,-0.28609313813573567,-1.09497089068513
585.0000000000076,63.721237935949,-0.29151127355400974,-1.094970638883932
586.2000000000075,63.840932516447765,-0.29283362166048227,-1.0972699691698504
587.4000000000076,63.960509868613485,-0.29219156770886673,-1.09726796505133
588.6000000000076,64.08083217769291,-0.2928996368150119,-1.0972700002937423
589.8000000000077,64.20018099962617,-0.28966210287297367,-1.0985899914194115
591.0000000000077,64.3190145611445,-0.28152100238227223,-1.098587549366516
592.2000000000077,64.4389021166029,-0.27971975836815316,-1.0998991925381123
593.4000000000077,64.55850876283571,-0.2709372946840455,-1.1012200093806963
594.6000000000078,64.67777447802861,-0.2637736865606941,-1.0999072858201666
595.8000000000077,64.79715168938327,-0.254858010055504,-1.1012542223053003
597.0000000000077,64.91650737641517,-0.24648314904853308,-1.102549957153132
598.2000000000078,65.03675369052021,-0.23840016363773056,-1.103860742855633
599.4000000000078,65.15637687442384,-0.22883220312585073,-1.105179619709956
600.6000000000079,65.27538044368177,-0.21771160690647717,-1.1065000061530434
601.8000000000078,65.39369586391612,-0.20803658234592212,-1.106498049002881
603.0000000000078,65.51444335014367,-0.1962207256191312,-1.1083080308865942
604.2000000000079,65.63425096622682,-0.18906250133066885,-1.109130888221606
605.4000000000078,65.75249349875055,-0.18025506064565608,-1.110450023178942
606.6000000000079,65.873072985546,-0.1725154479912318,-1.1115957834626178
607.8000000000079,65.99238623741714,-0.16408485420107186,-1.114400063269343
609.000000000008,66.11167609794896,-0.15611379712889442,-1.1157194185417612
610.200000000008,66.23113567401896,-0.14952581912998153,-1.1167265060904628
611.4000000000079,66.3508279786315,-0.14064017403527673,-1.1180198315942627
612.600000000008,66.46932596709426,-0.13152042701762504,-1.1199869304312622
613.800000000008,66.58766828611104,-0.1228122885224824,-1.1223742638741543
615.000000000008,66.70852749280185,-0.11175096503599617,-1.1236196002468954
616.200000000008,66.82772889589646,-0.10072827168710398,-1.1236223296515595
617.400000000008,66.94769794958606,-0.09066712932039403,-1.126253406344305
618.6000000000081,67.06538005394967,-0.0817282269866818,-1.1302115654543528
619.8000000000081,67.18682719386845,-0.07099088131994483,-1.1302126100397287
621.0000000000081,67.30733010238805,-0.056062445550514865,-1.1328478722663728
622.2000000000081,67.4272939246183,-0.04407964332928719,-1.134161669581454
623.4000000000082,67.54721019863379,-0.029029783541323607,-1.136611118099741
624.6000000000081,67.66670029972937,-0.014248069501834063,-1.1382116551661574
625.8000000000081,67.78567601226487,-0.0009901344717686438,-1.1408097230425711
627.0000000000082,67.90541701105715,0.01702532745307175,-1.143813821621456
628.2000000000082,68.02575369260822,0.034028357554689075,-1.1460025619993561
629.4000000000083,68.14631480443384,0.052354042810160616,-1.1489247684294694
630.6000000000082,68.26527866233167,0.07512248118674299,-1.1523504950488812
631.8000000000083,68.38522294447843,0.09299540427723386,-1.154374163709651
633.0000000000083,68.50623952727,0.11542295199762782,-1.1576448333953202
634.2000000000082,68.62405643403027,0.1375262531443788,-1.1606961097243618
635.4000000000083,68.74464077836569,0.1611292660795105,-1.164429981355465
636.6000000000083,68.86358051302258,0.1833473851704265,-1.1686481972288805
637.8000000000084,68.98331461671026,0.20707978672449734,-1.1711479350768483
639.0000000000084,69.10257768743371,0.23256691167832086,-1.175368779098966
640.2000000000083,69.22276505059313,0.25612552054258597,-1.1795869260827931
641.4000000000084,69.34145433041836,0.28039757078820476,-1.1836908751198512
642.6000000000084,69.4617038034049,0.3076019286839362,-1.1888470806771982
643.8000000000084,69.58091660221324,0.3333469884647356,-1.1925694424604134
645.0000000000084,69.70044328981405,0.3605463340167183,-1.1980333253722106
646.2000000000085,69.82072886796237,0.3877426210233612,-1.2036398917893507
647.4000000000085,69.94092507108533,0.415514022286844,-1.2071710250936665
648.6000000000085,70.06083192590782,0.44305044277524624,-1.2140764065894891
649.8000000000085,70.18034459039471,0.4732275433225035,-1.2202407765440357
651.0000000000085,70.30034947483404,0.5069662759417699,-1.226352130381179
652.2000000000086,70.42024552912154,0.5373607783587695,-1.2324010681962578
653.4000000000085,70.53884614864897,0.569611670247207,-1.2373736831106177
654.6000000000085,70.65927678003513,0.6034978123907881,-1.2443253039393274
655.8000000000086,70.7788100441894,0.6368593622915792,-1.2505464422673662
657.0000000000086,70.89851338480996,0.6739736896710714,-1.2568045357715376
658.2000000000087,71.01764722334843,0.7080807443584907,-1.2647037148100964
659.4000000000086,71.13950152769804,0.7442861248896836,-1.2732371538156015
660.6000000000087,71.25826526339937,0.7829035576367991,-1.2817315463190626
661.8000000000087,71.37688386181318,0.8225503285303915,-1.2886988330703861
663.0000000000086,71.4968317826445,0.8636996604768608,-1.2963675984282386
664.2000000000087,71.61645595153416,0.9029885480750208,-1.3064350559868552
665.4000000000087,71.73708973687216,0.9462946559718911,-1.3131870028539652
666.6000000000088,71.8565577039384,0.9908023925303323,-1.3232885613016236
667.8000000000088,71.9748954887755,1.034895949012929,-1.3330299024136085
669.0000000000088,72.09664659097675,1.085722142963476,-1.342210485874459
670.2000000000088,72.21639090167355,1.1335900324530608,-1.3516538149297634
671.4000000000088,72.33653605995586,1.1852179359444486,-1.3628057547757515
672.6000000000088,72.45689770310007,1.239418907401948,-1.3719615427668028
673.8000000000088,72.57731171277118,1.2990054688451569,-1.384186661777424
675.0000000000089,72.69770718089185,1.360300027593315,-1.3961527999366727
676.2000000000089,72.8184011098782,1.4273032352621107,-1.4070971733122768
677.400000000009,72.93716132068073,1.4984022229060825,-1.4196983096821065
678.6000000000089,73.05797984966536,1.5829836243037887,-1.4326103834636363
679.8000000000089,73.17938718746163,1.672537436038618,-1.4467564848561176
681.000000000009,73.30092692689695,1.7699341752972177,-1.4606680204132916
682.2000000000089,73.42063837432221,1.8689871553060557,-1.4757960880510437
683.400000000009,73.54114264438188,1.9763745816305622,-1.4898133148526647
684.600000000009,73.66250821863736,2.092030047183053,-1.5066208119063336
685.800000000009,73.78226798524562,2.204715328554373,-1.5223742800244997
687.0000000000091,73.9043886971413,2.325197059353259,-1.5397831119387546
688.200000000009,74.02409773012326,2.4326621867751554,-1.5550971736348624
689.4000000000091,74.14561682388174,2.5211244196211875,-1.5757396635226901
690.6000000000091,74.2653875211115,2.5718467441591737,-1.5924576377253827
691.800000000009,74.38624622858438,2.583498747979018,-1.612779176480672
693.0000000000091,74.50716116585703,2.5499281834525176,-1.6340171980958593
694.2000000000091,74.62550091190906,2.512846952379824,-1.653377854568498
695.4000000000092,74.74488576432283,2.499777015140458,-1.675382969718401
696.6000000000092,74.86714589754288,2.5015556627351043,-1.6941352183636575
697.8000000000092,74.98726715033251,2.512199282331982,-1.716059178182383
699.0000000000092,75.10636040695367,2.5213230211825013,-1.7378929818354534
700.2000000000093,75.22745479636517,2.522671588122212,-1.7595418898846842
701.4000000000092,75.3474277605973,2.5157122068057296,-1.7800849183705556
702.6000000000092,75.46763706656455,2.494701351385896,-1.8020769061588053
703.8000000000093,75.58738858436004,2.4505857732220178,-1.8236902211382646
705.0000000000093,75.70807149032679,2.379683344887545,-1.8466657360022416
706.2000000000094,75.82843622295262,2.2774127512390865,-1.8679042192580049
707.4000000000093,75.94872403493396,2.1376876758262626,-1.8883527404749985
708.6000000000093,76.06729535888826,1.9755828334402756,-1.9072875617141767
709.8000000000094,76.18777960528868,1.7909214713732087,-1.9257187719319542
711.0000000000093,76.3083134782755,1.5694638180237677,-1.9422076838131925
712.2000000000094,76.42677182362125,1.3717475052809671,-1.9566301378099982
713.4000000000094,76.54733619780329,1.2345080393067018,-1.970391396609338
714.6000000000095,76.66711396420396,1.058545118307914,-1.9868520318241956
715.8000000000095,76.78705183448227,0.7843605353987583,-1.9982244374690463
717.0000000000094,76.90625146910334,0.4121075089747496,-2.010471995808082
718.2000000000095,77.02574496108656,0.04367515322698512,-2.0165343963846727
719.4000000000095,77.14556808306776,-0.17392596442758523,-2.0206050934797473
720.6000000000095,77.26570727969293,-0.24483480997324414,-2.0205500082904253
721.8000000000095,77.3864070074277,-0.25966032106973924,-2.0205500033737094
723.0000000000095,77.50763966099666,-0.2546774148428011,-2.021613349156888
724.2000000000096,77.62805056458288,-0.24894790249066812,-2.0205505193225575
725.4000000000096,77.74976799357623,-0.2451192400248729,-2.0205412872312154
726.6000000000096,77.8706215211758,-0.24355127905561583,-2.021870001115211
727.8000000000096,77.99011006849949,-0.2379362333830166,-2.0218699999999936
729.0000000000097,78.1110369171192,-0.23633508385222526,-2.021869973734822
730.2000000000096,78.23271055619936,-0.2355414495243639,-2.0205170402065225
731.4000000000096,78.35201726510407,-0.2345605205499268,-2.021938520651685
732.6000000000097,78.4743895035625,-0.23213794316819625,-2.0208800090099834
733.8000000000097,78.59439798726665,-0.23078806866737556,-2.022189514670044
735.0000000000098,78.71586915311775,-0.2284208966246178,-2.023186731884071
736.2000000000097,78.8375582220804,-0.22834074458092965,-2.0218600007003023
737.4000000000098,78.95803107490515,-0.22565020370609815,-2.020713834324832
738.6000000000098,79.07899175410694,-0.22368901788144918,-2.023040423067221
739.8000000000097,79.20023721989556,-0.22252814547320277,-2.0218700040068676
741.0000000000098,79.31975618071992,-0.21942973012964842,-2.023198479645991
742.2000000000098,79.44054296198196,-0.21985902449889852,-2.0218678701602
743.4000000000099,79.5609374720995,-0.21969941844647936,-2.023190046766651
744.6000000000099,79.68154325502258,-0.216518261408393,-2.0232017952247707
745.8000000000098,79.80197256512578,-0.21364873547851,-2.0245140911105937
747.0000000000099,79.92244880162762,-0.21344964915099124,-2.023190006494358
748.2000000000099,80.04192923117374,-0.21158795400546812,-2.022530586985518
749.4000000000099,80.16364149017475,-0.20943843973872595,-2.023840007029966
750.6000000000099,80.28335734079756,-0.20603125742362402,-2.023836646707655
751.80000000001,80.40388314657925,-0.20630245705626205,-2.0251599994114406
753.00000000001,80.52371866857683,-0.20306305860090504,-2.0251599936715388
754.20000000001,80.64438094236768,-0.20566660764246256,-2.026484052268951
755.40000000001,80.76508855695221,-0.20145979687990687,-2.024463763435566
756.60000000001,80.88628275001975,-0.20121721385897204,-2.024499999994979
757.8000000000101,81.00613592054992,-0.1979175164167668,-2.0245000006504625
759.00000000001,81.12682588421866,-0.19619775684622565,-2.025823077278308
760.20000000001,81.24663527647382,-0.19091890459331462,-2.02450102296838
761.4000000000101,81.36749770079375,-0.18769082444760463,-2.024475504682737
762.6000000000101,81.48818745157776,-0.18723728565458034,-2.0269334097752223
763.8000000000102,81.60939547570999,-0.18536608213606404,-2.025851850189407
765.0000000000101,81.73003498730799,-0.1813531571502456,-2.0244788510977125
766.2000000000102,81.85072683899101,-0.1786176536906729,-2.024825456987206
767.4000000000102,81.97189156542804,-0.1773546573477533,-2.026149716289561
768.6000000000101,82.09159925632947,-0.17412108942023408,-2.026150104671453
769.8000000000102,82.21349629857501,-0.17050210261077892,-2.0274437751892753
771.0000000000102,82.33492975309444,-0.1669489738257857,-2.0274608209244316
772.2000000000103,82.45588869769583,-0.16283864109396384,-2.0274635245965253
773.4000000000103,82.5768997020698,-0.162706166996875,-2.0282434205532223
774.6000000000103,82.69799619280386,-0.15971653311394787,-2.0278000019212126
775.8000000000103,82.81813876198214,-0.15496274019943854,-2.027800000049982
777.0000000000103,82.9390070369058,-0.15220510901318277,-2.0286360841043916
778.2000000000103,83.05906641531388,-0.14605092188388408,-2.0287869874766993
779.4000000000103,83.18051875903804,-0.14226697090868445,-2.028775807030788
780.6000000000104,83.30045767104158,-0.13650578480313746,-2.0274666146677385
781.8000000000104,83.42008438087326,-0.13115104142625178,-2.0287800036865997
783.0000000000105,83.54150166698112,-0.12841321288643687,-2.0297619679463437
784.2000000000104,83.66142246299836,-0.12002659405921746,-2.0294507827645494
785.4000000000104,83.7810897500928,-0.11321813392736634,-2.0301000003842744
786.6000000000105,83.90093590970153,-0.10254163047069259,-2.030123242959376
787.8000000000104,84.02146638590938,-0.09466022993185153,-2.030100011334553
789.0000000000105,84.14150116679268,-0.08262317079698936,-2.0301000067311756
790.2000000000105,84.2614197113346,-0.06802079931577139,-2.030429982166657
791.4000000000106,84.3821180679849,-0.054588055382092986,-2.0314218750607687
792.6000000000106,84.5023200986045,-0.03741437016343824,-2.0301707201585426
793.8000000000105,84.62151262938566,-0.022496616370442393,-2.0294440887716076
795.0000000000106,84.74173532240134,0.001599896768090893,-2.0300901734896026
796.2000000000106,84.86210386579853,0.02575937932725055,-2.030757079165447
797.0000000000106,84.94314509413495,0.045336825190155604,-2.0327171892884923