File: 01_Data/Laminate_Flooring/STA/N2/10K_min/Laminate_Flooring_STA_N2_10KData_221206_R3.csv
##Temp./Â°C,Time/min,DSC/(mW/mg),Mass loss/mg
51.1,10.624594975385458,-1.7925943467694596,0.02270193560549849
52.30000000000002,11.071596884427764,-1.6671973376660982,0.012278144939283031
53.500000000000036,11.346170631456618,-1.587151243193866,0.010239941549303744
54.70000000000005,11.572231741719891,-1.5292847480100362,0.009036873837059645
55.90000000000007,11.769027931329969,-1.4855879552841136,0.011417935465074969
57.10000000000009,11.95014235583217,-1.4516981287688069,0.008885345680275769
58.300000000000104,12.12368493967175,-1.4242008662768273,0.009087949583385324
59.50000000000012,12.291828625914144,-1.3975231840239923,0.009278578089418232
60.70000000000014,12.451400057474721,-1.3785115999588107,0.008065162787129765
61.900000000000155,12.606848074066328,-1.3604047301532736,0.008739035992864075
63.10000000000017,12.760138029066923,-1.3431313188785545,0.008809972286610623
64.30000000000018,12.909850332625792,-1.327468519221623,0.008852892871206386
65.5000000000002,13.056398440738029,-1.3143350799740596,0.009663838163388228
66.70000000000022,13.202003824302581,-1.3049661892563706,0.008926212503305386
67.90000000000023,13.345399459679253,-1.2969583797918134,0.00853004193562601
69.10000000000025,13.485214702812964,-1.2867762147243411,0.009034529050992113
70.30000000000027,13.624249513818194,-1.2738611081776476,0.008930600149991363
71.50000000000028,13.7628025473079,-1.2625409804202308,0.008899800320696372
72.7000000000003,13.898382680435548,-1.2506305097317456,0.009545617511144577
73.90000000000032,14.03407925275635,-1.2382997384364032,0.008909143163227107
75.10000000000034,14.166661375087054,-1.2292628361850348,0.00886626381184108
76.30000000000035,14.299077570635589,-1.215217509481319,0.009795983990318113
77.50000000000037,14.43060267751783,-1.207389037581422,0.00888346411122587
78.70000000000039,14.561248283662323,-1.1969750441053568,0.009018117261620162
79.9000000000004,14.6889356455287,-1.1850155301273368,0.009899485851165402
81.10000000000042,14.820091974274835,-1.1756257825719183,0.008934962876265828
82.30000000000044,14.946155309159614,-1.1665237603890335,0.009000232018616217
83.50000000000045,15.074614956622282,-1.1584042923553808,0.01030920324272877
84.70000000000047,15.19850481116911,-1.1512446568655128,0.008999286496996994
85.90000000000049,15.325246750964991,-1.1427171201411532,0.009452080094649595
87.1000000000005,15.449590535492941,-1.1350892706541387,0.00899274083045043
88.30000000000052,15.573233126930253,-1.1273886812241747,0.010406817530071777
89.50000000000054,15.696036846358329,-1.1203170355879521,0.010312940049397312
90.70000000000056,15.818944030429897,-1.1110154607637057,0.009590948121847909
91.90000000000057,15.941354685258032,-1.1038549418355963,0.010319023686890638
93.10000000000059,16.063316137169966,-1.096479157180494,0.010010465774822563
94.30000000000061,16.183103516923712,-1.0885004968814285,0.008916164589316544
95.50000000000063,16.304350941801246,-1.0801500709621388,0.008972360761054787
96.70000000000064,16.425611813144727,-1.0723502942520386,0.009006153561082364
97.90000000000066,16.5453691856328,-1.0648435708701727,0.008926281843768535
99.10000000000068,16.664874910357,-1.0585771164467528,0.007737595918831275
100.3000000000007,16.78508590966451,-1.0497760044967868,0.008997991064171096
101.50000000000071,16.903289504884253,-1.0431790209771887,0.00900299969419649
102.70000000000073,17.021702354272417,-1.0361744454651216,0.007663166714277914
103.90000000000074,17.13811237680228,-1.029211196496643,0.008975739672081318
105.10000000000076,17.258888341942953,-1.0214973764867077,0.007611410003226737
106.30000000000078,17.37742007454144,-1.0151015840848885,0.00900332905370238
107.5000000000008,17.494946706363905,-1.008250698794099,0.009036087545127636
108.70000000000081,17.613060836686245,-1.0024636355013818,0.008891807810033292
109.90000000000083,17.731337722255976,-0.9959244719295702,0.007680422325865521
111.10000000000085,17.848674707630085,-0.9899191061606475,0.007680498572303129
112.30000000000086,17.962833113173563,-0.9819549139610364,0.009000785808042977
113.50000000000088,18.083312642209663,-0.9771163827517261,0.008990020881489258
114.7000000000009,18.20064553051487,-0.9727866700400234,0.008928996826597313
115.90000000000092,18.317669775484813,-0.9663279328093968,0.008956764285393604
117.10000000000093,18.434306722758013,-0.9609856838815413,0.009019544015288261
118.30000000000095,18.549269118413235,-0.9541079600836261,0.009000158125923363
119.50000000000097,18.669803829411403,-0.9501488791711314,0.009979807349054681
120.70000000000098,18.785829609489205,-0.9447095285491127,0.008981860687961252
121.900000000001,18.902356303812336,-0.9393040432702765,0.009000339849611905
123.10000000000102,19.018973194213938,-0.9353699175115787,0.009001286884447346
124.30000000000103,19.13709359152825,-0.9292459964426927,0.010312953719086693
125.50000000000105,19.252962106871824,-0.923035173129883,0.009001001052728164
126.70000000000107,19.369472973832526,-0.917158153114317,0.010319488125993814
127.90000000000109,19.484966546556212,-0.9147122053925928,0.008990298896299542
129.1000000000011,19.599999245775948,-0.9104000306600173,0.008996513966446074
130.30000000000112,19.71731475733794,-0.9039980178433156,0.008999810575667233
131.50000000000114,19.832854906423332,-0.8994289742643805,0.008483154542318516
132.70000000000115,19.949356800989005,-0.8936311546274465,0.007672191745295542
133.90000000000117,20.064336216249217,-0.8884778649789479,0.009553908342161854
135.1000000000012,20.179999027334585,-0.8818601123918243,0.010970116349498404
136.3000000000012,20.293992289496373,-0.877986484512492,0.009644179355692728
137.50000000000122,20.410943441884694,-0.8748532664273744,0.010964609467572828
138.70000000000124,20.524880756081465,-0.8683490769934294,0.009655626657467664
139.90000000000126,20.639819447944713,-0.8642893044620727,0.010980048098108597
141.10000000000127,20.754491467488034,-0.8586593443112566,0.009672128515910927
142.3000000000013,20.869339252114738,-0.8540773476868945,0.010969817250794378
143.5000000000013,20.984857698445552,-0.8501092806187639,0.010976271099141677
144.70000000000132,21.09935306096029,-0.8463690806613156,0.010970009897680377
145.90000000000134,21.213968965895592,-0.842325702688833,0.010968781815469342
147.10000000000136,21.327445824528397,-0.8363195024037947,0.012291974541621009
148.30000000000138,21.442539077048593,-0.8331700643665004,0.010978676742843696
149.5000000000014,21.557003645772028,-0.8275151516666989,0.010932244231195654
150.7000000000014,21.671290963962484,-0.8252163913285525,0.010964954613959854
151.90000000000143,21.78574736964999,-0.819562353111728,0.010972729986503893
153.10000000000144,21.90030520177867,-0.8139827129502997,0.012291016134175159
154.30000000000146,22.014663079779258,-0.8092315498735642,0.013612879383048337
155.50000000000148,22.127862516454236,-0.8048158348404599,0.012175675992827095
156.7000000000015,22.241089288134127,-0.8003584294166043,0.01256398270093495
157.9000000000015,22.35654466956193,-0.7955260455532633,0.01228919925563332
159.10000000000153,22.46970889630004,-0.7911480280072297,0.010980074441099497
160.30000000000155,22.581890739603416,-0.7879605583756375,0.012290396266712023
161.50000000000156,22.696989053041236,-0.7835215253034518,0.011282133053700072
162.70000000000158,22.813918717510695,-0.7797384679960937,0.012290738351392605
163.9000000000016,22.92667023898767,-0.7767076381405466,0.012289262018294167
165.10000000000161,23.04009748317919,-0.7718286796272484,0.010970391465747298
166.30000000000163,23.155142760530563,-0.7679830856132083,0.01229126783034129
167.50000000000165,23.267406000798186,-0.7634091731193965,0.01228571529214939
168.70000000000167,23.382242388058906,-0.7624439681401876,0.01230159150856025
169.90000000000168,23.49596905446457,-0.7567507264598134,0.01359988932890488
171.1000000000017,23.60961574017006,-0.7545665724117842,0.012288528372693008
172.30000000000172,23.723611041529484,-0.751256929066146,0.013609819355873576
173.50000000000173,23.837912271462308,-0.7465186627783522,0.013612592530836132
174.70000000000175,23.951162668033895,-0.7421509554447434,0.01229468435778891
175.90000000000177,24.062862262559914,-0.7396512973981938,0.01098697775560531
177.10000000000178,24.17941903541862,-0.7352692596459379,0.012290089139950666
178.3000000000018,24.288537675178382,-0.7337533357660584,0.012300529488067369
179.50000000000182,24.404751578934242,-0.7312045398552662,0.012289960011007572
180.70000000000184,24.520737941377437,-0.7267448206511671,0.01228996092522916
181.90000000000185,24.634505307053015,-0.7231922076894371,0.013661605737843807
183.10000000000187,24.74810452462116,-0.7217004264913005,0.011630448980749719
184.3000000000019,24.862674533333564,-0.7185300458148717,0.011627087769595867
185.5000000000019,24.975741731645495,-0.7138773899879944,0.011625090288299056
186.70000000000192,25.089900640280685,-0.7105816389929476,0.010309845149319763
187.90000000000194,25.202887308131782,-0.7082161719369604,0.01162949991941531
189.10000000000196,25.31701711887366,-0.706188835838847,0.010287214399053113
190.30000000000197,25.43194940862665,-0.7027157107934826,0.01031852767207031
191.500000000002,25.54464303478248,-0.7002897513753249,0.011313828778002133
192.700000000002,25.658910160694965,-0.6979870440077676,0.011942419910837998
193.90000000000202,25.772050916273603,-0.6926189706021231,0.011172038960689079
195.10000000000204,25.88569403908062,-0.6904017886529392,0.011251779308275367
196.30000000000206,26.001276598877954,-0.6881459241609766,0.010861985996062806
197.50000000000207,26.114229764870068,-0.6829325152409199,0.011356570962582246
198.7000000000021,26.227207482123436,-0.6801299636326988,0.012619970003732384
199.9000000000021,26.34176486474193,-0.6786185377815075,0.01262433454676426
201.10000000000213,26.455155091142714,-0.6743110756900594,0.011291046804672966
202.30000000000214,26.56870760257035,-0.6705687912759086,0.009333432000061315
203.50000000000216,26.68213426408131,-0.6679312292150612,0.009319907680712447
204.70000000000218,26.79505534953595,-0.6648455521955723,0.010647932123112547
205.9000000000022,26.90990421755153,-0.6636868382744737,0.011299907245712504
207.1000000000022,27.023254507134,-0.6595847109916109,0.010639989710269582
208.30000000000223,27.137027716142427,-0.6566104515133354,0.010971148631558236
209.50000000000225,27.250304053657107,-0.6532924001242857,0.0106500479749716
210.70000000000226,27.36356137603794,-0.6506105881954104,0.01064997842158899
211.90000000000228,27.47761934455833,-0.648909742280647,0.009330128859220466
213.1000000000023,27.59209571061756,-0.6436143146845316,0.009330047982047063
214.3000000000023,27.70516439537621,-0.6429189782943215,0.00925141804425511
215.50000000000233,27.81933769196294,-0.6397892070760184,0.008008531307747369
216.70000000000235,27.932993183330336,-0.6361205206412355,0.008694613736721202
217.90000000000236,28.04498200735143,-0.6347796112658455,0.009330183913331958
219.10000000000238,28.160273952348,-0.6319525022227312,0.00844540330961685
220.3000000000024,28.273632674976973,-0.6295757274196055,0.008403662870250628
221.50000000000242,28.38707133281253,-0.6276013087382528,0.00745325963219301
222.70000000000243,28.500176438775263,-0.6263170284488476,0.007679843931759578
223.90000000000245,28.615189443616558,-0.6231947937604062,0.005013777296071886
225.10000000000247,28.72873265251342,-0.6214469967946583,0.00534760759881614
226.30000000000248,28.83962655375305,-0.619542902746711,0.006040183958942791
227.5000000000025,28.955363971773064,-0.6153267138944362,0.006040183955367873
228.70000000000252,29.06918680714534,-0.6138239321163422,0.005952445864608968
229.90000000000254,29.18254431670389,-0.6108751441833944,0.004720169353197079
231.10000000000255,29.296377222478235,-0.6088970543880986,0.0037207111928800884
232.30000000000257,29.409271607316324,-0.6055379315460296,0.0033999119056105087
233.5000000000026,29.52419258878519,-0.6031550584118762,0.002110372415314643
234.7000000000026,29.635953009134386,-0.6008023568981453,0.0018024460634675776
235.90000000000262,29.75107632524794,-0.5981278308631832,0.0017498445372678972
237.10000000000264,29.864726741065198,-0.5963899370787068,0.0007883287362018265
238.30000000000265,29.978181017201166,-0.5940208561595632,-0.000890058663698845
239.50000000000267,30.093198149483182,-0.5935096084044543,-0.002193653902978099
240.7000000000027,30.207089868970268,-0.591519020775711,-0.002209604306051993
241.9000000000027,30.320292528859,-0.5889047254215389,-0.00352012127612511
243.10000000000272,30.43463983181328,-0.586663218389548,-0.00565121114518341
244.30000000000274,30.548951826515413,-0.5843254062290786,-0.0061499245331004815
245.50000000000276,30.662724245266652,-0.5809904673194229,-0.008339877313988886
246.70000000000277,30.776709891702605,-0.5796369050616728,-0.008786095788656745
247.9000000000028,30.89160335908877,-0.5776819987945989,-0.009780073182349192
249.1000000000028,31.00563466171802,-0.5772123320195394,-0.012361472678331431
250.30000000000283,31.119809853343313,-0.5762252908530783,-0.013729692076163147
251.50000000000284,31.232812438368057,-0.5748778988026936,-0.015026170201198674
252.70000000000286,31.347353780649897,-0.5727887912351889,-0.01711455980109644
253.90000000000288,31.46129607751007,-0.5705708211943805,-0.01768075934155533
255.1000000000029,31.57555430648665,-0.5716441303632316,-0.02042290812353187
256.3000000000029,31.68959144733486,-0.5690632717453912,-0.02193596445202406
257.50000000000296,31.804140680178104,-0.5707785289118489,-0.02420582342966071
258.70000000000294,31.9185238357297,-0.5705921620247314,-0.025585333525627973
259.90000000000293,32.032934424603255,-0.5708582385611436,-0.02807630842360176
261.100000000003,32.147435514319874,-0.5690171086856208,-0.030806220223166036
262.300000000003,32.26065934889657,-0.5669984637422093,-0.03348953054372927
263.500000000003,32.3757993157133,-0.5593166701172778,-0.035997370411746665
264.700000000003,32.48999895834849,-0.5496901238426403,-0.039420078428944016
265.90000000000305,32.604879643256595,-0.5427574921258567,-0.04275126638188098
267.1000000000031,32.71948550419121,-0.5363837459559238,-0.04698922215349821
268.3000000000031,32.83435547404705,-0.5302067664545463,-0.05026857224892467
269.50000000000307,32.94850199716497,-0.5245352282258057,-0.05705072489877816
270.7000000000031,33.06313991699684,-0.5183324729294311,-0.06338114687324525
271.90000000000316,33.1778805474089,-0.5122349285536546,-0.07129925183050734
273.10000000000315,33.29289172430282,-0.5032294129805215,-0.08099198246617245
274.30000000000314,33.40794303851589,-0.4988400049304921,-0.08952260634287468
275.5000000000032,33.520978880048084,-0.4921238956327123,-0.10176354989943714
276.70000000000323,33.63570121303935,-0.48661181985457036,-0.11403243682346265
277.9000000000032,33.751221150946456,-0.4817545651790384,-0.1260421376616212
279.1000000000032,33.864967204290814,-0.47597940793023297,-0.1410210570969319
280.30000000000325,33.979908160099626,-0.46796819635357456,-0.1554382585038354
281.5000000000033,34.093436797854146,-0.45929018783620496,-0.17001648634283395
282.7000000000033,34.2078615374114,-0.44882502738457397,-0.1861781898775745
283.9000000000033,34.32236992211104,-0.4324837996375953,-0.20406490607447436
285.1000000000033,34.43514158912276,-0.41742232112077066,-0.2198797325177413
286.30000000000337,34.55143504135233,-0.3989343609963524,-0.2390549723729456
287.50000000000335,34.66644565005846,-0.37989015751878263,-0.2566935009369189
288.70000000000334,34.78042900513523,-0.3609260453912229,-0.27583040070388254
289.9000000000034,34.8953645370262,-0.3453655147255772,-0.2945174788490057
291.10000000000343,35.0103697097314,-0.3350509491123633,-0.31308191715692946
292.3000000000034,35.12548862203427,-0.3258752752137356,-0.33390638615307866
293.5000000000034,35.2400871516392,-0.31992795505649796,-0.3519882867851347
294.70000000000346,35.353560442404955,-0.3160550890335158,-0.3683386808953122
295.9000000000035,35.469076514493665,-0.3171629972023128,-0.38755430077612774
297.1000000000035,35.58369065776855,-0.31862961269700935,-0.4045962357897608
298.3000000000035,35.69916300308707,-0.32198696616520933,-0.4199757751496924
299.5000000000035,35.81437032181032,-0.3305370131496952,-0.43634630265957197
300.70000000000357,35.92884565284021,-0.3370324308823947,-0.45078824570611475
301.90000000000356,36.04343560163196,-0.3474434450719076,-0.4633898042899167
303.10000000000355,36.158570484189376,-0.357190867364827,-0.4757349786705918
304.3000000000036,36.27355495768478,-0.36852300359680445,-0.4880489134098127
305.50000000000364,36.38841612053708,-0.3793050304017488,-0.4974899713940877
306.7000000000036,36.503117342788784,-0.39131499092446115,-0.5095243954396307
307.9000000000037,36.61968586708226,-0.4030249148134187,-0.51783613596991
309.10000000000366,36.7338306937886,-0.41168195391819484,-0.5271840640227161
310.3000000000037,36.848833438684586,-0.4227129440070756,-0.5358970874744688
311.5000000000037,36.96452475709916,-0.43111461950262137,-0.5423024279745148
312.70000000000374,37.07990167299308,-0.4397656427334073,-0.5508835513109944
313.90000000000373,37.19393013902698,-0.4477869768728825,-0.557182002173159
315.1000000000038,37.30869927456922,-0.45470698031812207,-0.5616609573639018
316.30000000000376,37.4242391029555,-0.4620190838482057,-0.5687596237424288
317.5000000000038,37.538921736191256,-0.47039531790936884,-0.5759614730623328
318.7000000000038,37.65449139526402,-0.4761530083389031,-0.579702946237894
319.90000000000384,37.76979521368771,-0.48512934465487173,-0.5843885573599463
321.10000000000383,37.88551202624539,-0.49102504439910283,-0.590786794634834
322.3000000000039,37.999491299309646,-0.49689369726677207,-0.5959744434411443
323.50000000000387,38.11442711956071,-0.5027400605660369,-0.5992445154174275
324.7000000000039,38.228904437754515,-0.5100816176172026,-0.6044242900375156
325.9000000000039,38.34378882575584,-0.5161926706374473,-0.6082704254049327
327.10000000000394,38.461059450638395,-0.5211206378457571,-0.6106555627655403
328.30000000000393,38.57564124328035,-0.5263468086492884,-0.6124697306223919
329.500000000004,38.69142493683912,-0.5316300299879765,-0.6151374359660169
330.70000000000397,38.80719264763221,-0.5356949630382778,-0.6205225423363996
331.900000000004,38.92317001612587,-0.5419869288297517,-0.6232966646788869
333.100000000004,39.03819912392641,-0.5477102036471735,-0.6258966862325623
334.30000000000405,39.151294691290396,-0.5492026928471939,-0.6259437207587424
335.50000000000404,39.269382011494685,-0.5527761962110112,-0.630434926919694
336.7000000000041,39.38416528431805,-0.5566960562020864,-0.632476439683693
337.90000000000407,39.50146563788952,-0.5600557566799637,-0.6363934500563837
339.1000000000041,39.61701199267996,-0.5626265497632408,-0.6377415131804112
340.3000000000041,39.730176042771106,-0.5636733126834359,-0.6390613152410896
341.50000000000415,39.84765588274914,-0.5662179681496162,-0.641686206588572
342.70000000000414,39.96408763398564,-0.5677515388242627,-0.6426869262351795
343.9000000000042,40.08009363354729,-0.5695312950423265,-0.6440030036237943
345.1000000000042,40.194847593569776,-0.5707542715636897,-0.6453100264232923
346.3000000000042,40.31059356970479,-0.5707467211412646,-0.6459885123645619
347.5000000000042,40.426316293920756,-0.572476158309747,-0.6473750235726774
348.70000000000425,40.542959652914014,-0.5732835095355167,-0.6486098537297278
349.90000000000424,40.659066079812625,-0.5721814016946298,-0.6499199365360626
351.1000000000043,40.77384065957469,-0.5722004968342066,-0.6512410348292414
352.3000000000043,40.890671595820216,-0.5723740536682225,-0.6518998592196392
353.5000000000043,41.00590952159905,-0.5715574797300831,-0.6545122993880392
354.7000000000043,41.12225793417534,-0.570022751195133,-0.6540707473480398
355.90000000000435,41.23954350922452,-0.5702246220074064,-0.6545400859853423
357.10000000000434,41.35420791797619,-0.5695875053385837,-0.6559015314707453
358.3000000000044,41.47018742049402,-0.567309108139488,-0.6571601999503285
359.5000000000044,41.58645948841023,-0.5664709922672752,-0.6557891033774488
360.7000000000044,41.70299254959283,-0.5654050986513109,-0.6558511778440193
361.9000000000044,41.81927770358612,-0.5631591991794949,-0.6571635095846426
363.10000000000446,41.93546638871559,-0.5614767641216137,-0.6584822525812886
364.30000000000445,42.050402073521504,-0.5588789786912114,-0.6591724482752905
365.5000000000045,42.16493824159267,-0.5584903797967228,-0.6597999360976221
366.7000000000045,42.28244537769797,-0.5556788979131875,-0.6597999242861872
367.9000000000045,42.399316239975064,-0.5541080410035373,-0.6611203147588811
369.1000000000045,42.51605711047372,-0.5541945048187035,-0.6611198040003816
370.30000000000456,42.63009555881348,-0.551393269588802,-0.6611198039999988
371.50000000000455,42.74629271521058,-0.5498212365221938,-0.6611198768773159
372.7000000000046,42.86291234474109,-0.5481651906847589,-0.6624302224194167
373.9000000000046,42.97884005362943,-0.5470748246539293,-0.6624306199279526
375.1000000000046,43.09463593986251,-0.5468080010016287,-0.6637498579695902
376.3000000000046,43.21029445629975,-0.5451143517760706,-0.6637619287774483
377.50000000000466,43.32707537196295,-0.5431560946220411,-0.6645072190412793
378.70000000000465,43.44229343851975,-0.5422652228214346,-0.6653376066354855
379.9000000000047,43.55894479841205,-0.5404870087362411,-0.6660540950080032
381.1000000000047,43.67531991583118,-0.5404590448576602,-0.6650639692066846
382.30000000000473,43.79180322175157,-0.5412720301562814,-0.6663898153870429
383.5000000000047,43.90888895316084,-0.5395514635652714,-0.6677001443755333
384.70000000000476,44.02567410531697,-0.5385223885391918,-0.6677000406090161
385.90000000000475,44.14110650643864,-0.5389280729995519,-0.6707579705042521
387.1000000000048,44.25821576327999,-0.5365996808110355,-0.6721006288475047
388.3000000000048,44.37467026278443,-0.5377478386382605,-0.673485239358691
389.50000000000483,44.49150981682629,-0.5344960472479755,-0.6714400937592337
390.7000000000048,44.60764924175404,-0.5340924735469047,-0.6720984615353589
391.90000000000487,44.724540056658995,-0.5328786146682002,-0.6727548144009265
393.10000000000485,44.840816623428346,-0.5291191094306366,-0.6723804801397049
394.3000000000049,44.95874855003765,-0.5298709360532879,-0.6727734369517133
395.5000000000049,45.073441882515624,-0.5286451917439725,-0.6753902839732593
396.70000000000493,45.19089837674334,-0.5272046952558949,-0.6764548210093229
397.9000000000049,45.30818962536079,-0.5277971241449244,-0.6754100889419354
399.10000000000497,45.42398416189519,-0.5262460194883307,-0.6767101390534536
400.30000000000496,45.54083546148329,-0.5254461474207631,-0.677042374726093
401.500000000005,45.6576649483661,-0.5246045965394175,-0.6769898314719835
402.700000000005,45.77359703962649,-0.5238121172724974,-0.6783506930264274
403.90000000000504,45.89099955882618,-0.5239040507764918,-0.6796817215015882
405.100000000005,46.00703226329724,-0.5225781984413379,-0.6816542524553948
406.30000000000507,46.12523843695882,-0.521952902361522,-0.6816501076188386
407.50000000000506,46.242863097130076,-0.5211079677448617,-0.6829701798308556
408.7000000000051,46.35939199672632,-0.5213861894917444,-0.6842901360071818
409.9000000000051,46.47561923694654,-0.5212858991477333,-0.685587495039623
411.10000000000514,46.59298788125465,-0.520583362257776,-0.6866470883156239
412.3000000000051,46.7104957895424,-0.5186566570271409,-0.6866316330730471
413.5000000000052,46.826879754893824,-0.5186934114522976,-0.6885983836646998
414.70000000000516,46.94443177052232,-0.516515682975313,-0.6887084344980687
415.9000000000052,47.06143942102559,-0.5170165299380582,-0.6902079323915347
417.1000000000052,47.17826299539844,-0.5141675737399853,-0.6928449903348848
418.30000000000524,47.29468327999276,-0.5128756626971219,-0.6931338111524359
419.50000000000523,47.41221664891618,-0.5123366487966469,-0.6955623303420797
420.7000000000053,47.5289807686823,-0.5103245634288005,-0.696800239474288
421.90000000000526,47.64497942691183,-0.5094378947273113,-0.6981238955077607
423.1000000000053,47.76230343154369,-0.5076757156784276,-0.6986668318573859
424.3000000000053,47.87914688261617,-0.5058880189284775,-0.7008235052533891
425.50000000000534,47.996103824923914,-0.5051280578940283,-0.7034989696128604
426.70000000000533,48.11375401887135,-0.5041521696888634,-0.703975403330495
427.9000000000054,48.231271935747465,-0.5030793411218141,-0.7061273716660663
429.10000000000537,48.34808528827305,-0.5014765408757398,-0.7087495091504952
430.3000000000054,48.464255414937405,-0.49874335286493915,-0.7113722510258764
431.5000000000054,48.58178516140264,-0.49834112964916577,-0.7135258008240069
432.70000000000545,48.698066152783035,-0.4978708821166114,-0.7167103854804919
433.90000000000543,48.81555145478311,-0.49547521895931046,-0.7194030248044236
435.1000000000055,48.9335213592991,-0.49409040514348623,-0.7221333711956075
436.30000000000547,49.050435082363315,-0.4914336688427943,-0.7248042267374841
437.5000000000055,49.16761962204146,-0.4897528537501303,-0.7287746393846422
438.7000000000055,49.28558868047058,-0.48569507346034685,-0.73261990992357
439.90000000000555,49.403702150147986,-0.48407412968605845,-0.735760936781872
441.10000000000554,49.51930765965129,-0.4814064894495925,-0.7398848554397923
442.3000000000056,49.637885875409864,-0.47670334478926013,-0.7438328246025812
443.50000000000557,49.755817757955164,-0.47339980207219146,-0.7481946594588549
444.7000000000056,49.87309275920792,-0.47122818980694164,-0.7523509918446338
445.9000000000056,49.990822112124285,-0.46668054919045115,-0.7564996659308241
447.10000000000565,50.10887746349036,-0.4622729627714485,-0.762409244348536
448.30000000000564,50.2255553221116,-0.4584283743567683,-0.766652816187511
449.5000000000057,50.343357944993926,-0.4535645583580402,-0.7715011458851615
450.7000000000057,50.46143425297174,-0.4476941837464709,-0.7762990034429618
451.9000000000057,50.57868983172199,-0.4423385273098721,-0.7816072306878494
453.1000000000057,50.696044573887136,-0.43616338806226995,-0.7879816166927811
454.30000000000575,50.8129588724381,-0.42987883651086967,-0.795515066578965
455.50000000000574,50.930000000000526,-0.4250599999998864,-0.8003198000041896
456.7000000000058,51.04532496150061,-0.4174397434843597,-0.806287217847057
457.9000000000058,51.164579184351986,-0.4107864592485019,-0.8132261448154705
459.1000000000058,51.280572637128394,-0.4046320967374536,-0.8182811186300532
460.3000000000058,51.39777462064773,-0.3991779029821415,-0.8248812108372583
461.50000000000585,51.513961002134494,-0.3936223564504361,-0.8310543019141203
462.70000000000584,51.63167319462656,-0.38949615792180703,-0.837404590281821
463.9000000000059,51.74908566895208,-0.38502258387704924,-0.8432317990473472
465.1000000000059,51.86721183263369,-0.38199952823623223,-0.8491207272210222
466.3000000000059,51.98468932873319,-0.37760110858357315,-0.8539360944499195
467.5000000000059,52.10289009079207,-0.3748421125335507,-0.8588714477770711
468.70000000000596,52.219907805020405,-0.37249225103452654,-0.8672873671934047
469.90000000000595,52.33750336810911,-0.3694649856261806,-0.8710270847826207
471.100000000006,52.455938461738,-0.3661671542469927,-0.8750127579916125
472.300000000006,52.572874434091325,-0.36589540966409523,-0.8806408670833155
473.500000000006,52.69097311962397,-0.361878961796754,-0.886768743140562
474.700000000006,52.807164284822136,-0.36117293076887985,-0.891103211771902
475.90000000000606,52.92670587570673,-0.3597532324861247,-0.8956628238011004
477.10000000000605,53.044270295775355,-0.35672957025295793,-0.9004955886324737
478.3000000000061,53.16268697103794,-0.3556327008322427,-0.9036399003552402
479.5000000000061,53.27979729421973,-0.3520440790956231,-0.9094409431160431
480.7000000000061,53.397640738362185,-0.3503154131209454,-0.91198440498257
481.9000000000061,53.51515237140604,-0.3493899895756693,-0.9163447245585159
483.10000000000616,53.63271926052636,-0.3486125308641419,-0.920171596078053
484.30000000000615,53.75090562233442,-0.3454873285133772,-0.9230410287942403
485.5000000000062,53.869135709214554,-0.3432045401985868,-0.9270274517367656
486.7000000000062,53.98680208888012,-0.34134163857417066,-0.9296496301658435
487.90000000000623,54.104190423614284,-0.3404543831177891,-0.932271239804586
489.1000000000062,54.2224068355574,-0.3391821839401472,-0.9348771028311598
490.30000000000626,54.3403108315983,-0.33716914170304674,-0.9392001728066521
491.50000000000625,54.45822581523311,-0.3371007629407336,-0.940737787952143
492.7000000000063,54.5763637679808,-0.3347324727748843,-0.943168160560675
493.9000000000063,54.69446698357719,-0.3337026158332845,-0.9457982283208879
495.10000000000633,54.81153245352369,-0.3328187655032794,-0.9470851575941799
496.3000000000063,54.93075542356544,-0.33161324580966395,-0.949402311176355
497.50000000000637,55.048811548339884,-0.33078857707866566,-0.9520328031664125
498.70000000000636,55.16624960491788,-0.32965572393766646,-0.9530312732398256
499.9000000000064,55.28523714145555,-0.32884634124895823,-0.9536875363061275
501.1000000000064,55.403257223418066,-0.32729109258629674,-0.9550841345232532
502.30000000000643,55.52196730639482,-0.32715858588589697,-0.9566272513421237
503.5000000000064,55.640096359341754,-0.3286934721087092,-0.9589679010317309
504.70000000000647,55.757836957731755,-0.3264431022772264,-0.9597885673658233
505.90000000000646,55.87576136735617,-0.3270104253487646,-0.9599510571799348
507.1000000000065,55.99502571415461,-0.32594135381151296,-0.9612700900833087
508.3000000000065,56.11208619021911,-0.3239655863162007,-0.9625803950220422
509.50000000000654,56.23086147790034,-0.3229549144142046,-0.9624155604912121
510.7000000000065,56.34893861058494,-0.3223939258606648,-0.9639456772412163
511.90000000000657,56.466365618106835,-0.32093453158006063,-0.9652193883452922
513.1000000000065,56.584329620103716,-0.32012098734524286,-0.9652201793951258
514.3000000000065,56.70276812195813,-0.31608941396983997,-0.9665450490078791
515.5000000000066,56.82199197176027,-0.31739334175945694,-0.9665358412507277
516.7000000000066,56.93961501258559,-0.31769963943073476,-0.9678466869596849
517.9000000000067,57.05886361942977,-0.3160268865116215,-0.9691698415284749
519.1000000000067,57.17735873003066,-0.313593071093901,-0.970489958280532
520.3000000000067,57.2952974788513,-0.3110261599349134,-0.970550886113148
521.5000000000067,57.41409003946673,-0.3101857684129908,-0.9718001366328428
522.7000000000066,57.53292975468585,-0.3058373494177229,-0.9731321970677049
523.9000000000067,57.65040065642118,-0.3006021837525892,-0.9738656981267213
525.1000000000067,57.769170955234806,-0.2942568240039806,-0.9718098871586514
526.3000000000068,57.88697358779814,-0.2912844336779197,-0.9727391995867758
527.5000000000068,58.0058636875148,-0.28708139298683083,-0.9757031931405935
528.7000000000069,58.12541944295585,-0.2847572871880972,-0.9770701816906384
529.9000000000068,58.2449963340138,-0.2807748302505215,-0.9783207385789594
531.1000000000068,58.362748816458485,-0.27683678433078673,-0.9783603280956403
532.3000000000068,58.480602625653816,-0.27155796396531945,-0.9796977452657814
533.5000000000068,58.599455044670826,-0.2651901660137461,-0.9823300687799499
534.7000000000069,58.71853365067264,-0.2595361455105103,-0.9813536284751438
535.9000000000069,58.83709361949315,-0.2528399799653389,-0.982654120311441
537.100000000007,58.95424323533548,-0.24684280669628703,-0.9838929268250451
538.300000000007,59.07398424850606,-0.24132989964820922,-0.9839842749416614
539.5000000000069,59.191828047115344,-0.23447641906344813,-0.9852999994722582
540.700000000007,59.30990121131407,-0.2287561069228932,-0.9856060419935169
541.9000000000069,59.429063365969704,-0.22049022044104521,-0.9869605499494467
543.100000000007,59.547080810809064,-0.21398137918336374,-0.9882799664115467
544.300000000007,59.66461365223675,-0.20504858342013396,-0.9896077603989335
545.500000000007,59.784702387135056,-0.19601110744515612,-0.9909869670219766
546.7000000000071,59.9039963331598,-0.18580056484848248,-0.9922286147097266
547.9000000000071,60.02234481059124,-0.1733899101662507,-0.9945157585685758
549.1000000000071,60.141697148071955,-0.15909462787929055,-0.9945354456349689
550.3000000000071,60.26133040046523,-0.1436459757777547,-0.9945325713027606
551.500000000007,60.37922362092029,-0.13047384127795464,-0.9981605480910609
552.7000000000071,60.497952037023744,-0.11479160746356007,-0.9995081626655375
553.9000000000071,60.61685952704333,-0.09923674478928138,-1.0008141371068313
555.1000000000072,60.73632656454035,-0.08138371436523475,-1.003416080429333
556.3000000000072,60.85427014254848,-0.06441173336976268,-1.0060270708654917
557.5000000000073,60.97361872750732,-0.049009733145224624,-1.0100933521201854
558.7000000000072,61.09200331747542,-0.033549503727181296,-1.0107755681687616
559.9000000000073,61.20945423659587,-0.01641697401326704,-1.0162207083277628
561.1000000000072,61.3308997387907,0.00018954232981720768,-1.0190682591879034
562.3000000000072,61.449392253865774,0.017499925088476278,-1.021639043298233
563.5000000000073,61.56746809429725,0.033212274356170315,-1.0256630863334624
564.7000000000073,61.688623243176615,0.04578185372847796,-1.02701562486565
565.9000000000074,61.80849926269292,0.05954135950999539,-1.032505964975174
567.1000000000073,61.92755085530249,0.06996873586151688,-1.0356510546055535
568.3000000000073,62.04724047334479,0.07311955274579991,-1.0400887586228125
569.5000000000074,62.16694975348338,0.072933413716386,-1.0435641120862762
570.7000000000074,62.28686890610204,0.06140224033692883,-1.047523406394046
571.9000000000074,62.40665299927507,0.0331488906701122,-1.050983863257997
573.1000000000074,62.52470689487562,-0.02243346212501983,-1.0551242356066197
574.3000000000075,62.64472401495474,-0.10654717367510316,-1.0589222672569676
575.5000000000075,62.76294478412659,-0.18415638231640097,-1.059369325151311
576.7000000000074,62.88045598945528,-0.22954744014486414,-1.0609809844121183
577.9000000000075,63.001249959086095,-0.2591431207658586,-1.061942248212473
579.1000000000075,63.120973102341786,-0.27455104577882944,-1.0619399562127239
580.3000000000076,63.239503541769366,-0.28384845330942904,-1.0619401639966255
581.5000000000075,63.35817034350883,-0.2923191387463719,-1.0618610218018842
582.7000000000075,63.4784004187047,-0.2963069892314468,-1.0655598438410125
583.9000000000076,63.59669819683341,-0.2963380970663559,-1.065924907250368
585.1000000000076,63.715849589614905,-0.2965866109576582,-1.0655600721080742
586.3000000000076,63.834741705106815,-0.29624777120965967,-1.0666108599926512
587.5000000000076,63.95405047490682,-0.292090197043883,-1.0665579713456586
588.7000000000077,64.07389540925709,-0.28746228896572096,-1.065890613587566
589.9000000000077,64.19265568194646,-0.2808059068172739,-1.0672001180071988
591.1000000000076,64.31175630010429,-0.2750919492511002,-1.067226693448521
592.3000000000077,64.43150556439159,-0.2689142874196194,-1.068189979570088
593.5000000000077,64.55060945922905,-0.2614661822029468,-1.0695520093796884
594.7000000000078,64.67010972957281,-0.2548800680360787,-1.0695098481591656
595.9000000000077,64.78961154491623,-0.24402320031182054,-1.070830012592105
597.1000000000078,64.9087785505791,-0.23510693004712374,-1.0721399021797682
598.3000000000078,65.03000105769013,-0.22682985319326981,-1.0725138080168333
599.5000000000078,65.14862033277201,-0.21729258489983483,-1.0734712725633613
600.7000000000078,65.26949398570852,-0.20840888038753347,-1.0747896731635684
601.9000000000078,65.38873833489433,-0.19778881392257686,-1.0760939534970824
603.1000000000079,65.50834091801357,-0.1892585877958502,-1.077739722021279
604.3000000000079,65.62910634735657,-0.18032233484542304,-1.0796296285746196
605.5000000000078,65.7472429515745,-0.17074989113325154,-1.0801777350652784
606.7000000000079,65.86675414312188,-0.1609570730770126,-1.0816910794100631
607.9000000000079,65.98640869204242,-0.1535651295301774,-1.0830198203761645
609.100000000008,66.10642841104315,-0.1440269012848161,-1.0845657577994459
610.3000000000079,66.22606784462498,-0.13448467752908186,-1.085670911617242
611.500000000008,66.3456184547978,-0.12547236375654913,-1.086894425628052
612.700000000008,66.4644320701681,-0.11674661762895737,-1.0895043804207032
613.900000000008,66.58384063631027,-0.10805622307176949,-1.092340634326165
615.100000000008,66.70478327302133,-0.09695752050041351,-1.0935476767680514
616.300000000008,66.82324457054325,-0.08610431777320707,-1.0937958053687118
617.5000000000081,66.94306195538454,-0.07683147528982051,-1.0965239971182532
618.7000000000081,67.06233970719981,-0.06557038493474354,-1.099139060555994
619.900000000008,67.18192136001447,-0.05213062020972598,-1.1004687567676341
621.1000000000081,67.30042219825847,-0.039264560847495356,-1.1041252460409208
622.3000000000081,67.41863487541696,-0.02347162396563956,-1.104408908024178
623.5000000000082,67.53839625987631,-0.00867081638486018,-1.1084556748177907
624.7000000000081,67.65815914478652,0.004681395430398121,-1.1098103987919021
625.9000000000082,67.77640489549835,0.02150350812419107,-1.1111860996054292
627.1000000000082,67.89594527190818,0.038711622413789254,-1.1148206247638934
628.3000000000083,68.01516700745783,0.05694695597165197,-1.1181931863516752
629.5000000000082,68.13486010627057,0.07415304507869726,-1.1216139552299054
630.7000000000082,68.25365314487564,0.0920375997246216,-1.1243142675036144
631.9000000000083,68.374122168555,0.1142857153943871,-1.1272830028701497
633.1000000000083,68.49308130828818,0.13458460125892518,-1.1309822072986604
634.3000000000083,68.61264042751294,0.15522770361304764,-1.133682136494445
635.5000000000083,68.73214453370514,0.1766267898984341,-1.1377375272333716
636.7000000000083,68.8519035074437,0.2006469920591716,-1.1406416851009427
637.9000000000084,68.97211013536662,0.22450525987309508,-1.1456456742768704
639.1000000000083,69.09033259783885,0.2476623760775598,-1.150319141836825
640.3000000000084,69.21040505905286,0.2748837897271275,-1.1546035323273576
641.5000000000084,69.32960667770081,0.299537050813938,-1.158777603924853
642.7000000000085,69.44906153203783,0.326977964878419,-1.1617972663817557
643.9000000000084,69.56878663952561,0.35170662089173677,-1.1674132373993293
645.1000000000084,69.6891727411537,0.38335290150572643,-1.1727763622394405
646.3000000000085,69.80842458855874,0.41304500788261755,-1.1797058824335345
647.5000000000085,69.92786537753202,0.44163879565031555,-1.1844394528515325
648.7000000000085,70.04888945798463,0.4706652116633666,-1.1897450901578668
649.9000000000085,70.16707967405893,0.5028014610722037,-1.1951773064254363
651.1000000000085,70.28469155557511,0.5342861774928949,-1.2031738825367748
652.3000000000086,70.40702875022505,0.5668882487130563,-1.2082371325720018
653.5000000000085,70.5269015069586,0.602549430258791,-1.2163145444263588
654.7000000000086,70.64794907405029,0.6389780313080282,-1.2226565790238473
655.9000000000086,70.76939077482992,0.6724225643241393,-1.2296672305526237
657.1000000000087,70.88883618016317,0.710260154531957,-1.2362883284031354
658.3000000000086,71.00880534712026,0.7440151181982536,-1.2449646578655118
659.5000000000086,71.12949598784691,0.7846063329056027,-1.252696390802285
660.7000000000087,71.25042494166215,0.8224547881511053,-1.2620131380190243
661.9000000000087,71.3683230824905,0.8588489231456744,-1.2680088193659245
663.1000000000087,71.4904904838278,0.9002300146155741,-1.2776076422834044
664.3000000000087,71.61086280625905,0.9429790700421783,-1.287635126033296
665.5000000000088,71.73138869158856,0.9884918973433243,-1.296957445719829
666.7000000000088,71.84894248766429,1.030505471973865,-1.3064680309858305
667.9000000000087,71.97078804057048,1.076709948245171,-1.3144153972650798
669.1000000000088,72.09087742127468,1.1274885808660533,-1.325668813712496
670.3000000000088,72.21137390496305,1.1753292820799817,-1.336749557778583
671.5000000000089,72.33147821637036,1.2286023914888051,-1.3466205423804856
672.7000000000088,72.45068441395325,1.2884887653459345,-1.3584246659766492
673.9000000000088,72.57108135289158,1.3502845266443073,-1.3699787014346194
675.1000000000089,72.690202298495,1.416976039685327,-1.3802205548934041
676.3000000000089,72.81046789733227,1.4882876430063148,-1.3940826240869924
677.5000000000089,72.93148091129872,1.566741382379562,-1.407114477903738
678.7000000000089,73.05211680042679,1.6532647266265332,-1.4202653586878746
679.900000000009,73.1728218422218,1.7460353556463706,-1.4347200525822852
681.100000000009,73.29188757365277,1.840313793383602,-1.449990593707641
682.3000000000089,73.41250330500195,1.9462384691604393,-1.4638362384057553
683.500000000009,73.53276850017734,2.056402517727438,-1.4801730524560215
684.700000000009,73.65296453366808,2.1699022919523334,-1.4962503098717246
685.9000000000091,73.77435600142681,2.2834989248215765,-1.5135813214525053
687.100000000009,73.89491326755662,2.3952856087882326,-1.5309211297188727
688.300000000009,74.01524381403576,2.496088223074602,-1.5496909454847914
689.5000000000091,74.13678990743554,2.5719257932928263,-1.5683158025983035
690.7000000000091,74.25746529971396,2.6126703828189926,-1.5877077675105302
691.9000000000091,74.37849185002122,2.6060456554048406,-1.6089515707521382
693.1000000000091,74.49591556573215,2.5741342549247967,-1.6296668662369984
694.3000000000092,74.61808827451098,2.544296489456649,-1.6505837689377034
695.5000000000092,74.73842354846168,2.528317661424552,-1.6723824646078849
696.7000000000091,74.8585189454391,2.5207533228264505,-1.6936365432911304
697.9000000000092,74.97926337387321,2.513784822591946,-1.715000087437442
699.1000000000092,75.09959302340116,2.5036200257808656,-1.7352404464963636
700.3000000000093,75.22021247732582,2.4833217602970836,-1.7580021752823436
701.5000000000092,75.34020746078895,2.4461267712514054,-1.7791933643634699
702.7000000000093,75.460637416415,2.388475539784218,-1.8015843822411495
703.9000000000093,75.57979294434946,2.3076385890950952,-1.8224790257361954
705.1000000000093,75.69882767146223,2.188569537033545,-1.843139160458636
706.3000000000093,75.82100458417949,2.035726761438696,-1.8622704308344602
707.5000000000093,75.94088736599939,1.8670830441206332,-1.8815096486493528
708.7000000000094,76.06041613369278,1.6798975417315705,-1.8995544578411114
709.9000000000094,76.18073062211364,1.486181319927411,-1.9142983019229978
711.1000000000093,76.30009915859493,1.3515439865606977,-1.930335233854355
712.3000000000094,76.42087984534373,1.2058366496756936,-1.9441807750875113
713.5000000000094,76.54019302212997,0.9754813329699898,-1.9586588525094322
714.7000000000095,76.66020278818696,0.6199079248260464,-1.9704156159742632
715.9000000000094,76.77841475950562,0.21187692587699436,-1.9794743785244608
717.1000000000095,76.89906173776237,-0.11650903890246996,-1.9838018674829967
718.3000000000095,77.01858392920445,-0.25853341482915126,-1.987206425840228
719.5000000000095,77.13989921435318,-0.2940616860167596,-1.9877598723397658
720.7000000000095,77.26054395823549,-0.2960785446724869,-1.9883980587740897
721.9000000000095,77.38218117510391,-0.293121323860345,-1.9870796613747563
723.1000000000096,77.49966690391302,-0.29063475152919843,-1.9870798559999292
724.3000000000096,77.62195985559532,-0.2873928101465521,-1.98707985869948
725.5000000000095,77.74236844259242,-0.2834049682218057,-1.9883921204382222
726.7000000000096,77.86389195596102,-0.2826643446681036,-1.987949635455125
727.9000000000096,77.98426067085998,-0.2822751605909811,-1.9890659791327399
729.1000000000097,78.10443440672073,-0.2785362004245423,-1.987369177319354
730.3000000000096,78.22557328859291,-0.2768758991313642,-1.9883997785657757
731.5000000000097,78.34447331017162,-0.2735049349502481,-1.9883494415655387
732.7000000000097,78.46540265342968,-0.27223589884795935,-1.9885929043077843
733.9000000000098,78.58494249681634,-0.2731144493892644,-1.9887301667682995
735.1000000000097,78.7071565156084,-0.27131389421746005,-1.9900438843753268
736.3000000000097,78.82852396400936,-0.2690533480128696,-1.9887301797062191
737.5000000000098,78.94861222221896,-0.26806947776995854,-1.990053722469053
738.7000000000098,79.06880360857085,-0.2667260953494107,-1.9887379167688417
739.9000000000098,79.19118306990913,-0.2658244194607145,-1.9900398038126301
741.1000000000098,79.31138244863308,-0.26606511750760964,-1.9900398040650416
742.3000000000098,79.43178386041964,-0.2657974523483703,-1.9887505982301539
743.5000000000099,79.5510008687081,-0.26575178441584213,-1.988437479140437
744.7000000000098,79.67439935916988,-0.2641069299505541,-1.989380125090472
745.9000000000099,79.79532624403072,-0.26494705424435316,-1.9896273498908044
747.1000000000099,79.91688108345124,-0.26271434894747564,-1.990049943970308
748.30000000001,80.03763273820925,-0.260689738543531,-1.9900499440011323
749.5000000000099,80.15789496785432,-0.2601163403718786,-1.9900587067800237
750.7000000000099,80.27870887080041,-0.2582143660559347,-1.991361870905068
751.90000000001,80.39892738113092,-0.2563990955103959,-1.9900401378336605
753.10000000001,80.51968665983813,-0.25363681801512405,-1.990952143800084
754.30000000001,80.64021535326347,-0.25325415544761654,-1.9903699159448442
755.50000000001,80.7609450658349,-0.25227520244004925,-1.9903699160000006
756.70000000001,80.88164573613089,-0.24914328008310493,-1.9903699160058292
757.9000000000101,81.0022092439656,-0.2472335148098669,-1.9903104203563866
759.10000000001,81.12188807299506,-0.24660059996794953,-1.9900376491289524
760.3000000000101,81.24283140952562,-0.24510387871697928,-1.9913598510836907
761.5000000000101,81.36176887250372,-0.24525247507571146,-1.991358498256469
762.7000000000102,81.48423310912031,-0.2425427697552685,-1.9926800450066762
763.9000000000101,81.60491940707519,-0.24309555535793465,-1.9908924615539565
765.1000000000101,81.72583503766471,-0.23794563683699418,-1.9890311743362696
766.3000000000102,81.84534529354417,-0.23849727215111793,-1.9907085701901175
767.5000000000102,81.96542219509973,-0.23776612192601157,-1.990264806195888
768.7000000000102,82.08510193523455,-0.23223636371597367,-1.9904124524025284
769.9000000000102,82.20507460435721,-0.23011076092411606,-1.9906998917507392
771.1000000000103,82.3253236840492,-0.22888871092307506,-1.990673359963476
772.3000000000103,82.44577926285774,-0.22492833496571263,-1.9916890791018687
773.5000000000102,82.56528707419676,-0.22181233105739892,-1.9920504140003334
774.7000000000103,82.68657956680504,-0.21470799264125978,-1.9910475173381426
775.9000000000103,82.80492730375163,-0.21099302201276293,-1.9910298933875201
777.1000000000104,82.92716866313503,-0.21100646183405514,-1.992024836595244
778.3000000000103,83.04742293826493,-0.20775680254854836,-1.9921758062813186
779.5000000000103,83.1690228348783,-0.20200626785055198,-1.9933399680802837
780.7000000000104,83.28901089252784,-0.20114735344195708,-1.9920543418236036
781.9000000000104,83.41065639052346,-0.1942764818811268,-1.9933424188989255
783.1000000000104,83.53149652525738,-0.19038984902486397,-1.9942946577773428
784.3000000000104,83.6521838542961,-0.18559804723647763,-1.9946504426278682
785.5000000000105,83.7725459421666,-0.1766107017160146,-1.9933416302044207
786.7000000000105,83.89251694888543,-0.16803194543538166,-1.9933400080002417
787.9000000000104,84.0112618474795,-0.1636682654510875,-1.9933400079999997
789.1000000000105,84.13436788099843,-0.15353470782510564,-1.9933399925095192
790.3000000000105,84.25527696945055,-0.14360734145499338,-1.9946590110788915
791.5000000000106,84.37646792971127,-0.1285794305729061,-1.9933413878364918
792.7000000000105,84.49743678656276,-0.11405984580823343,-1.9946572729030931
793.9000000000106,84.61802776786605,-0.09665498938388062,-1.9953100243056805
795.1000000000106,84.73705420991625,-0.07707248071595804,-1.9939886117138426
796.3000000000106,84.85868381688812,-0.0498105786149573,-1.9946499153254185
797.0000000000106,84.92916830213414,-0.035553807132568144,-1.9946499160000415