File: 01_Data/CPVC_Pipe/STA/N2/10K_min/CPVC_Pipe_STA_N2_10KData_221024_R2.csv
##Temp./Â°C,Time/min,DSC/(mW/mg),Mass loss/mg
51.0,10.708550234319306,-1.7063755976861075,-0.024115095422251986
51.80000000000001,11.009914589649945,-1.6193679107452448,-0.021777879229042174
52.60000000000002,11.218975439207394,-1.5548866779072572,-0.020256903686373118
53.400000000000034,11.393257499730606,-1.5049246531684768,-0.021100528905277915
54.200000000000045,11.545557171737892,-1.4628392489984345,-0.01889621734327651
55.00000000000006,11.683957462465184,-1.42947272309524,-0.02007517528944458
55.80000000000007,11.814971877871466,-1.4006206954962785,-0.01915685637647746
56.60000000000008,11.94055712558173,-1.3772294161939593,-0.018671285156691475
57.40000000000009,12.057001272686119,-1.3530004424424371,-0.018906418755751275
58.2000000000001,12.171851022728845,-1.336619966223861,-0.01945010719063811
59.000000000000114,12.282677566485741,-1.3178738520057356,-0.018333917836421687
59.800000000000125,12.391644521154937,-1.302286561568147,-0.01973316585180873
60.600000000000136,12.49879046936496,-1.2894491450510235,-0.018435565729462144
61.40000000000015,12.603141318916048,-1.2740543772762736,-0.018942401103823503
62.20000000000016,12.705784828810014,-1.2624202560589215,-0.019987200118317006
63.00000000000017,12.808045502016613,-1.2518847601598573,-0.02009200689790891
63.80000000000018,12.910051190686751,-1.2398474717991055,-0.019778065797648736
64.6000000000002,13.005963350296517,-1.2313199323857764,-0.020095949450073203
65.4000000000002,13.102869517964756,-1.2205148026377974,-0.02115735360230886
66.20000000000022,13.20063666317741,-1.21124773924414,-0.021143001573376452
67.00000000000023,13.297583621205874,-1.20116966731609,-0.021093369410138507
67.80000000000024,13.389917601952261,-1.191564623331333,-0.020531634852710035
68.60000000000025,13.486349186706928,-1.1835224811435368,-0.020495420299493805
69.40000000000026,13.580222044984366,-1.1747575433986737,-0.01977413716117571
70.20000000000027,13.673410110410193,-1.1666066640931056,-0.021282595798701287
71.00000000000028,13.767723587490368,-1.1583838744362667,-0.021189561679549662
71.8000000000003,13.857052650089061,-1.1500829910253212,-0.021093382210760403
72.6000000000003,13.946543934162978,-1.1424694546531993,-0.01990435676299418
73.40000000000032,14.03861856004458,-1.134308666564934,-0.019900505580486172
74.20000000000033,14.12763288737661,-1.1280166127253124,-0.02147153315234185
75.00000000000034,14.21503741128482,-1.1197618784900216,-0.02118295962825556
75.80000000000035,14.304509447657544,-1.1140648028218825,-0.021181417693967752
76.60000000000036,14.394352174086151,-1.1099231624836696,-0.021189319911000037
77.40000000000038,14.481077359357904,-1.1042671563532191,-0.021240911059791756
78.20000000000039,14.569051530663504,-1.1001270388025226,-0.021392281262561763
79.0000000000004,14.65568131232058,-1.0947319095862749,-0.022423361795967267
79.80000000000041,14.741847569385852,-1.0891376023119117,-0.02252949515870828
80.60000000000042,14.82727541532836,-1.0852109658963836,-0.02119865916291186
81.40000000000043,14.91435905837055,-1.0809021045541627,-0.021573436095996712
82.20000000000044,14.998960376565629,-1.075425492450077,-0.022339046144910224
83.00000000000045,15.083100747982014,-1.0724449235407438,-0.02383661952417304
83.80000000000047,15.168842296126911,-1.0662301776385623,-0.022828373005186364
84.60000000000048,15.251866629774137,-1.0603839078704942,-0.022565306329582313
85.40000000000049,15.33709912380424,-1.054172803594223,-0.022495085617032284
86.2000000000005,15.420731368165761,-1.0504170410834384,-0.02257233787892199
87.00000000000051,15.504565938538242,-1.0429571890983835,-0.022543682373519225
87.80000000000052,15.585299078464942,-1.0384721923771139,-0.022525522393093134
88.60000000000053,15.669624742055536,-1.032164435896971,-0.023881831643862927
89.40000000000055,15.751981308678284,-1.0254925497397998,-0.023884827503414474
90.20000000000056,15.833826772171873,-1.0221450290469138,-0.02250348583136219
91.00000000000057,15.916522687103287,-1.017459841967839,-0.023819757495317617
91.80000000000058,15.996617356275777,-1.0111593998578183,-0.02378409098167067
92.60000000000059,16.07872066878246,-1.0054623954448547,-0.025063599227010958
93.4000000000006,16.16065620092851,-1.0004234500087168,-0.023825552041019993
94.20000000000061,16.2416807480532,-0.996615201782225,-0.023842853630450023
95.00000000000063,16.320383320945666,-0.9906137137185765,-0.02383989407216136
95.80000000000064,16.4021491334171,-0.986583755175651,-0.02381946215274766
96.60000000000065,16.482662412102492,-0.9802984830102777,-0.02518806124703099
97.40000000000066,16.56252276305003,-0.9755837807227489,-0.023766131119329348
98.20000000000067,16.64249300660375,-0.9714985652159028,-0.02381900434444484
99.00000000000068,16.723262551807572,-0.9657302227290376,-0.025136556918586628
99.8000000000007,16.803172847747295,-0.963323029533941,-0.025140211331845297
100.6000000000007,16.88165707174958,-0.957020599525618,-0.023830150072135403
101.40000000000072,16.96156923682502,-0.9525056692453405,-0.02512995932523099
102.20000000000073,17.041645523765407,-0.9477876787770578,-0.025137847335948482
103.00000000000074,17.120637285405834,-0.9422198094163317,-0.02500814496587367
103.80000000000075,17.199890562315026,-0.9374493247089558,-0.026288301318604823
104.60000000000076,17.278260871912373,-0.9327268831873027,-0.025388328175481867
105.40000000000077,17.35670449344568,-0.9288243281207662,-0.02531790041521198
106.20000000000078,17.43726413464245,-0.9238628960856885,-0.026460230498263737
107.0000000000008,17.516570670986255,-0.9192047831323942,-0.026822412040706567
107.80000000000081,17.594179873046556,-0.9153921445605201,-0.02646253560476186
108.60000000000082,17.673163872456815,-0.9112350264060745,-0.026462393972574105
109.40000000000083,17.751953342332147,-0.9070550558410122,-0.026460148584879217
110.20000000000084,17.830575001733557,-0.9027690249531986,-0.026474129521173673
111.00000000000085,17.908961768679514,-0.897664392781529,-0.026450298328681843
111.80000000000086,17.98757709061191,-0.8940267650555677,-0.026441679744523494
112.60000000000088,18.06563710724166,-0.8910697343798974,-0.0264567932030495
113.40000000000089,18.143574603369473,-0.8862312335336004,-0.02646022361870326
114.2000000000009,18.220780585214893,-0.8821019338210283,-0.026455324545995307
115.00000000000091,18.30039892516965,-0.8781109568184209,-0.026461750131395068
115.80000000000092,18.378137803106384,-0.8720334361684727,-0.027772133387266695
116.60000000000093,18.45571448726717,-0.8673494248070494,-0.027780759053884108
117.40000000000094,18.53503314497259,-0.8642553386080271,-0.0274998573087486
118.20000000000095,18.613315327792947,-0.8599565041938704,-0.02778394192556899
119.00000000000097,18.689972307104785,-0.8536616934519922,-0.0277695952627921
119.80000000000098,18.769274007332516,-0.8498171759686942,-0.02908788601476342
120.60000000000099,18.84727185799303,-0.8443511530304051,-0.028100089035398845
121.400000000001,18.92555863960461,-0.8404113042031928,-0.028100304294470302
122.20000000000101,19.002146589652984,-0.836138306637305,-0.02902003540457887
123.00000000000102,19.08018635896358,-0.8310817684521842,-0.029097562235143037
123.80000000000103,19.157805972006972,-0.8274929813558718,-0.029079492349879388
124.60000000000105,19.235147189855407,-0.8236153896922395,-0.029089683437865776
125.40000000000106,19.31073357269435,-0.8196482000164733,-0.02909320670457216
126.20000000000107,19.390553844384357,-0.8150057961596616,-0.03050493173679092
127.00000000000108,19.46785117670882,-0.8119195880763425,-0.029128418534694944
127.80000000000109,19.544384764826372,-0.808382467539198,-0.028102773822741955
128.6000000000011,19.62252106554642,-0.8024731431636076,-0.029419792569905123
129.4000000000011,19.700296206758114,-0.7988576774371812,-0.030737484246866398
130.20000000000113,19.7778792430735,-0.7957475796243875,-0.03046046056385565
131.00000000000114,19.85519780883574,-0.7919773102817564,-0.03039997407257289
131.80000000000115,19.93231532211688,-0.7882259913093818,-0.030399981590353065
132.60000000000116,20.00926095405844,-0.7852467287539141,-0.030719126707824174
133.40000000000117,20.08634296775564,-0.782322682455529,-0.031307468702877816
134.20000000000118,20.162411690555555,-0.7796841732084201,-0.03040985369693905
135.0000000000012,20.23917000000013,-0.7783499999999928,-0.030089831182447124
135.8000000000012,20.31678028310192,-0.7742912380664664,-0.030408710389342897
136.60000000000122,20.39341982792147,-0.7714910418311659,-0.03174675599769161
137.40000000000123,20.470625449086167,-0.7672518107014242,-0.033039860488102146
138.20000000000124,20.547596226064332,-0.7651617569319511,-0.03172665343360448
139.00000000000125,20.62361141544018,-0.7600387339245017,-0.03039971803061725
139.80000000000126,20.69957887565314,-0.7580803783055726,-0.030393608304462916
140.60000000000127,20.777860886328895,-0.7565037112259528,-0.03305695170130951
141.40000000000128,20.853841456609256,-0.7525923075449393,-0.03303043541599093
142.2000000000013,20.9301891503315,-0.749912264463099,-0.0330417738482045
143.0000000000013,21.0073254373031,-0.7451728542425574,-0.03173050412216716
143.80000000000132,21.08288886298684,-0.7439679104842758,-0.033053179859823256
144.60000000000133,21.160171812792143,-0.7417456795338815,-0.03168052265288246
145.40000000000134,21.2360742183167,-0.7379110245769326,-0.03303992572039549
146.20000000000135,21.309372404875223,-0.7342627470711903,-0.03172201939015418
147.00000000000136,21.38574258581029,-0.7318928738078581,-0.033040113351667344
147.80000000000138,21.463858668909126,-0.7285517759003931,-0.03304004699521235
148.6000000000014,21.540217021317925,-0.7258322704512638,-0.0330401017171158
149.4000000000014,21.616617047389283,-0.7231188242428862,-0.031706730208826084
150.2000000000014,21.69270515719893,-0.7210951370567799,-0.03268101460398398
151.00000000000142,21.7666544046996,-0.7183117872075994,-0.03305099469835149
151.80000000000143,21.84510465823058,-0.7158394979176689,-0.03435213052165942
152.60000000000144,21.92210351831215,-0.713784915117032,-0.0343600802288031
153.40000000000146,21.997877690424133,-0.7101993286355176,-0.03568028000261281
154.20000000000147,22.074393887331617,-0.707104718849975,-0.036126479688662894
155.00000000000148,22.15155133246293,-0.702895864143721,-0.034356829063119765
155.8000000000015,22.226041589989702,-0.7014568930338937,-0.03566663101808265
156.6000000000015,22.30168422719099,-0.6995649078237491,-0.03431405482523919
157.4000000000015,22.37907062644752,-0.6961935442990574,-0.035679881673607916
158.20000000000152,22.454070291156448,-0.6939504077044295,-0.03567987199982037
159.00000000000153,22.530617322545897,-0.6903156135063652,-0.03567985851742028
159.80000000000155,22.60681440152986,-0.6867733349994656,-0.03434060346437651
160.60000000000156,22.683257632516227,-0.6836865202341882,-0.03568016769564286
161.40000000000157,22.758420031151076,-0.6815173554087968,-0.03568022695278872
162.20000000000158,22.83416527812433,-0.6787698374787313,-0.037045024389409154
163.0000000000016,22.910564432183723,-0.675605360846396,-0.03700016788823568
163.8000000000016,22.986965975310213,-0.6749812675522969,-0.037395132390569685
164.60000000000161,23.062017268558765,-0.6712167678716697,-0.037002140612106604
165.40000000000163,23.138679951054417,-0.6683152268348673,-0.03700479268415924
166.20000000000164,23.21383179759055,-0.66645158340832,-0.03799041329427588
167.00000000000165,23.289940111272156,-0.6629141958653683,-0.03829780013662365
167.80000000000166,23.366205860316626,-0.660266064912957,-0.038969893681569445
168.60000000000167,23.441574671805622,-0.65822759571183,-0.03853841665273361
169.40000000000168,23.518196570780624,-0.6562641924704821,-0.0396268078204991
170.2000000000017,23.594585598297318,-0.6539695445608892,-0.038635245958356546
171.0000000000017,23.670429158636555,-0.650670806026788,-0.03831012237148235
171.80000000000172,23.746442663023775,-0.6494804082381752,-0.03831005911466345
172.60000000000173,23.82276287263416,-0.6464171409740975,-0.03957488391857478
173.40000000000174,23.897786400402115,-0.6458156883416597,-0.03962845165109785
174.20000000000175,23.974436280053002,-0.642680563154722,-0.03962337455935616
175.00000000000176,24.050951408806384,-0.6401118709875017,-0.03962999386141863
175.80000000000177,24.126600198693964,-0.6396639741545018,-0.03963003353194772
176.60000000000178,24.202194399989516,-0.6359351544217775,-0.041005111050432586
177.4000000000018,24.27881736691965,-0.6347677310311781,-0.04094999400087529
178.2000000000018,24.355182977847576,-0.6309522896177611,-0.040950012248211376
179.00000000000182,24.430030705236096,-0.6318849520916683,-0.040212870098127684
179.80000000000183,24.504069071758888,-0.6282519829695813,-0.04095000234371282
180.60000000000184,24.583741945654886,-0.6255761349674243,-0.04094994968142629
181.40000000000185,24.657390333811815,-0.62446923335499,-0.04168943359369193
182.20000000000186,24.734249651645754,-0.6217014577873317,-0.04161153335118861
183.00000000000188,24.810453616174634,-0.621324112863785,-0.04161015836126447
183.8000000000019,24.88610848267348,-0.6178986411342607,-0.04158817885205757
184.6000000000019,24.962221964523543,-0.6175364828645562,-0.04291910770350116
185.4000000000019,25.03800529662195,-0.614867522676906,-0.04292039263545222
186.20000000000192,25.11462539239991,-0.6135027796472611,-0.04421701213818663
187.00000000000193,25.190321317064747,-0.6110329376191068,-0.043579997266021575
187.80000000000194,25.26672223400973,-0.6097756840824406,-0.04358543097661416
188.60000000000196,25.342560662774325,-0.607606344332328,-0.04390720188046959
189.40000000000197,25.418301296296384,-0.6060036851269647,-0.04390982601225657
190.20000000000198,25.493686871754324,-0.603706754459208,-0.043911782495434704
191.000000000002,25.569472570433444,-0.6025453166576895,-0.04523009686759938
191.800000000002,25.645516992609437,-0.6005838562457417,-0.04522562457950752
192.600000000002,25.721807323477144,-0.5974548767733647,-0.046209571531781624
193.40000000000202,25.796524485025234,-0.5968383393094661,-0.04620982600363188
194.20000000000203,25.87317534676461,-0.5954442653771809,-0.04620969601641711
195.00000000000205,25.9490644918984,-0.5939076152931915,-0.04653970848396538
195.80000000000206,26.024446556136695,-0.5914613755462694,-0.04747752288281859
196.60000000000207,26.10041013367316,-0.5903111596265457,-0.0475381440700402
197.40000000000208,26.17674068724636,-0.5874437314379332,-0.04709663278120191
198.2000000000021,26.25158192854201,-0.5862769862716478,-0.04852027301569084
199.0000000000021,26.328465962645332,-0.5835134291147585,-0.049832326664493554
199.80000000000211,26.40440447442893,-0.5817479943145092,-0.0498328052864192
200.60000000000213,26.47973831179182,-0.5812155850198321,-0.049167234285004024
201.40000000000214,26.555129752527787,-0.5779733734073577,-0.04885981167986486
202.20000000000215,26.628312616091936,-0.5767656045797751,-0.04885981899568481
203.00000000000216,26.70675652758493,-0.5750447591116099,-0.04885996402489079
203.80000000000217,26.780100737952463,-0.5721493413958643,-0.05017603539924931
204.60000000000218,26.85896031072492,-0.5718001768800749,-0.050169799263188875
205.4000000000022,26.93421227055807,-0.5707456756697087,-0.051393442078856655
206.2000000000022,27.00968057583562,-0.5689444864738046,-0.0514891440829226
207.00000000000222,27.085958921738353,-0.5665142740745069,-0.0537892773881401
207.80000000000223,27.162210455991406,-0.5655057155482995,-0.05378212805019045
208.60000000000224,27.237413905668742,-0.5662346901013761,-0.05248017250748083
209.40000000000225,27.313618718423573,-0.5633778829055166,-0.05283201754287736
210.20000000000226,27.389744922215076,-0.5621525806945202,-0.05280974542741612
211.00000000000227,27.464570253265435,-0.5612953292044548,-0.05451556298887361
211.80000000000229,27.541036529576242,-0.5589462501601183,-0.05511002108733054
212.6000000000023,27.616442619839233,-0.5585810393692927,-0.05511001200222321
213.4000000000023,27.6913283711439,-0.5551561624141621,-0.05511002712728885
214.20000000000232,27.768031365501834,-0.555358579079821,-0.05544752946384435
215.00000000000233,27.84481774499014,-0.5538757825594773,-0.05675728791255086
215.80000000000234,27.920900278004602,-0.552356302775284,-0.056735161551720203
216.60000000000235,27.99619068306882,-0.550772416787199,-0.05805954143695269
217.40000000000236,28.07277049478253,-0.5497978748895348,-0.05939333339183106
218.20000000000238,28.14806157394989,-0.5479305783569469,-0.0587304031216167
219.0000000000024,28.224046663770554,-0.5477175781004049,-0.058730130302003136
219.8000000000024,28.300803681296788,-0.5450715816054897,-0.05873391436370223
220.6000000000024,28.37571251406739,-0.5450130438689189,-0.061018680057155716
221.40000000000242,28.451787089662382,-0.5428551879744511,-0.061040578198890305
222.20000000000243,28.528789577839415,-0.5421524433501077,-0.06136933529278821
223.00000000000244,28.604212217726428,-0.5408951606212389,-0.06137025596388357
223.80000000000246,28.679953452216154,-0.5381260849916518,-0.06403453709690643
224.60000000000247,28.755795611066226,-0.5374271482293592,-0.06400018052779721
225.40000000000248,28.832209724968457,-0.536801237249221,-0.06399979369157638
226.2000000000025,28.908979409391755,-0.5361398297636191,-0.0653176987615911
227.0000000000025,28.984307459629132,-0.5341931272918171,-0.06663025720440441
227.8000000000025,29.061521930468736,-0.5327858567469504,-0.06665736615114293
228.60000000000252,29.136727712627902,-0.5316947710904567,-0.06794990419805513
229.40000000000254,29.213076693536674,-0.528816659612413,-0.0679456738550277
230.20000000000255,29.2893993979211,-0.5285890228036133,-0.06926988960714597
231.00000000000256,29.36433859824895,-0.5260760809559148,-0.0705428433721993
231.80000000000257,29.44069780056689,-0.5257482398385225,-0.07186698388004631
232.60000000000258,29.51761254851617,-0.5247881267133917,-0.07125022967985029
233.4000000000026,29.593780534814705,-0.522577006720344,-0.07257087462207279
234.2000000000026,29.669548991189576,-0.5214205167635348,-0.07256293276067671
235.00000000000261,29.742751358766363,-0.520938947549072,-0.07388544096197824
235.80000000000263,29.82215245365882,-0.5182043671677107,-0.07517661188226343
236.60000000000264,29.89672500156766,-0.5168639054007301,-0.07718401512850592
237.40000000000265,29.973874455801475,-0.5149063509171202,-0.07842732944749953
238.20000000000266,30.05012633222667,-0.5121331236718198,-0.07850013367457898
239.00000000000267,30.124710268473002,-0.511120799099459,-0.08047827114538153
239.80000000000268,30.201263120091077,-0.5100901453022745,-0.08234208215308625
240.6000000000027,30.277627539527433,-0.5087212601294819,-0.08430742583083672
241.4000000000027,30.354914551826873,-0.5064697218040057,-0.08444184878182304
242.20000000000272,30.43069344715934,-0.5045992990299798,-0.08619584311007245
243.00000000000273,30.50573294055655,-0.5027907711217361,-0.0888430591162388
243.80000000000274,30.582634825352102,-0.503332428075827,-0.09043831441021455
244.60000000000275,30.658410997261196,-0.5018395148956694,-0.09233228162842488
245.40000000000276,30.73440679211174,-0.4999929261872654,-0.09495876995218833
246.20000000000277,30.8103576394569,-0.49975513477891403,-0.09777125836703648
247.00000000000279,30.885422998004078,-0.4986000267494459,-0.09764533384250784
247.8000000000028,30.96224996596782,-0.49919685784600987,-0.09903225393198012
248.6000000000028,31.037132620375573,-0.5003045095023592,-0.1006997067974833
249.40000000000282,31.114029226077303,-0.4994316135606585,-0.10382281738569876
250.20000000000283,31.188914795779056,-0.49918314746423736,-0.10581184998949711
251.00000000000284,31.26574108613822,-0.4986424281470928,-0.10846424080714812
251.80000000000285,31.342182924857266,-0.49478111758281557,-0.10987223917623767
252.60000000000286,31.418058269625732,-0.49016660068822626,-0.1124115674700219
253.40000000000288,31.49437936964888,-0.48372009412406575,-0.11371880450787764
254.2000000000029,31.570159321335247,-0.4789908290389526,-0.11505266265090652
255.0000000000029,31.64620920624217,-0.4743459526893158,-0.11638053766442402
255.8000000000029,31.722223129511182,-0.4692031351489217,-0.11902301049173492
256.6000000000029,31.798530515526892,-0.4648281591518771,-0.1203000765954707
257.40000000000293,31.874903365118765,-0.46310917140560354,-0.12201736704327892
258.20000000000294,31.95117460378666,-0.4586179763771589,-0.12335575060476822
259.00000000000296,32.02675259703324,-0.45334238675076505,-0.12467970338751977
259.80000000000297,32.10285828220781,-0.4515622542501535,-0.1285792017410783
260.600000000003,32.179582293121804,-0.4473070805660554,-0.129975013150065
261.400000000003,32.256102178758624,-0.44346763555851776,-0.13239006522974073
262.200000000003,32.33254211002605,-0.44026280604767115,-0.13454897892025297
263.000000000003,32.40806168545416,-0.4378551598206645,-0.1358025358670063
263.800000000003,32.48464492322633,-0.4335250736874109,-0.1380537767425012
264.60000000000304,32.56105767438174,-0.4288535491538413,-0.14177313469716202
265.40000000000305,32.6374108132092,-0.4258910262346889,-0.14418346865585496
266.20000000000306,32.712655262960034,-0.42099521961588987,-0.14831682180238115
267.00000000000307,32.789266845575355,-0.4170617649924964,-0.1504001274102449
267.8000000000031,32.865936015254455,-0.4131853349210095,-0.15315782252169674
268.6000000000031,32.941191512123666,-0.409416163956568,-0.155940424619188
269.4000000000031,33.01818523887394,-0.4039464843446568,-0.1606253773819457
270.2000000000031,33.09425612380078,-0.3992349346698348,-0.1646807146553506
271.0000000000031,33.17037507904646,-0.394476668025358,-0.16853718952026364
271.80000000000314,33.24643473164521,-0.38904780813613005,-0.1725887640160022
272.60000000000315,33.323409556464306,-0.38469896801988773,-0.17746552591945974
273.40000000000316,33.39926593378862,-0.3806652208063355,-0.18245896808547135
274.2000000000032,33.475937472524336,-0.3767263417445475,-0.18628283434156057
275.0000000000032,33.55261322700495,-0.37155768931073785,-0.19263855423541631
275.8000000000032,33.628435891207225,-0.36703012611939895,-0.19797526984935354
276.6000000000032,33.704103346215156,-0.3620007711714748,-0.20310082505040716
277.4000000000032,33.78191850432147,-0.3587849191499004,-0.21014127938907157
278.20000000000323,33.85837400689246,-0.3530935530025685,-0.21752348821222034
279.00000000000324,33.93441590110655,-0.3490643045231199,-0.223842798869752
279.80000000000325,34.01110011148911,-0.34322915888520944,-0.22982710092784142
280.60000000000326,34.08649432001659,-0.33746006271481865,-0.23801613043946412
281.4000000000033,34.16234415463609,-0.33299456580596465,-0.24721393356513088
282.2000000000033,34.23987603570815,-0.32775213741330655,-0.25541595971671605
283.0000000000033,34.31720523772216,-0.32237707452343706,-0.26372871780964324
283.8000000000033,34.39337881306819,-0.31750630333887425,-0.27378323466354715
284.6000000000033,34.46861340714524,-0.3125986280522368,-0.2844405270504362
285.40000000000333,34.54537631700838,-0.3080917679242452,-0.29484264013005834
286.20000000000334,34.62072849814033,-0.3038473481855721,-0.30568791655120275
287.00000000000335,34.69896407468469,-0.29875984021035207,-0.3179997281885507
287.80000000000337,34.77577384205624,-0.29271245790661643,-0.3298683667374074
288.6000000000034,34.85256111564329,-0.29055583421770537,-0.34444927765475164
289.4000000000034,34.92955459839425,-0.28602215216354554,-0.3572951380185736
290.2000000000034,35.0059687016731,-0.28122449052318405,-0.37122273294271535
291.0000000000034,35.08225658423679,-0.27684668763322906,-0.3874232368749757
291.8000000000034,35.160065282414664,-0.2746664175767154,-0.4037932046064956
292.60000000000343,35.23514921680937,-0.27147030293798624,-0.4205949486912335
293.40000000000344,35.31247027557075,-0.2679858675704294,-0.43925481549048895
294.20000000000346,35.389090190996015,-0.265523899549843,-0.45745178116033314
295.00000000000347,35.466016623747805,-0.26511381408448187,-0.47602415304304024
295.8000000000035,35.54219417735999,-0.26281627289236326,-0.49908159131307483
296.6000000000035,35.618382271243604,-0.2614401187899258,-0.5187574165154736
297.4000000000035,35.695787828147715,-0.260084234620737,-0.542355961884454
298.2000000000035,35.77223017354356,-0.2583729049575659,-0.5657873115041467
299.0000000000035,35.847481818201935,-0.2596441933247884,-0.5899946532470857
299.80000000000354,35.92645045721856,-0.2592196111505768,-0.6156135208762019
300.60000000000355,36.00248622528099,-0.25914393499006,-0.6404690931255406
301.40000000000356,36.078999319514956,-0.26051591612742075,-0.6685015323562222
302.20000000000357,36.15535005593355,-0.2608024779918657,-0.6976300600640024
303.0000000000036,36.23270105656365,-0.26234533999529497,-0.7275335087664279
303.8000000000036,36.30956990132897,-0.26485572492351384,-0.7590759542063359
304.6000000000036,36.38604918523474,-0.2679402344135733,-0.7909451314297642
305.4000000000036,36.4620561755237,-0.2716314771508627,-0.8243720794586538
306.2000000000036,36.539364310413134,-0.2758208015515017,-0.8603309141100706
307.00000000000364,36.61585188076352,-0.2786773576541881,-0.8967246197798118
307.80000000000365,36.69170327430614,-0.2824897213210837,-0.9331731254862916
308.60000000000366,36.769066887528325,-0.28928959350090916,-0.9731629661862282
309.4000000000037,36.84304661861735,-0.2932946969047951,-1.0094270074700922
310.2000000000037,36.92263561686783,-0.298545924779971,-1.0516736525291006
311.0000000000037,36.998690594259116,-0.30556203185128056,-1.093018587778471
311.8000000000037,37.07626605502971,-0.3110422849103109,-1.1362672908722677
312.6000000000037,37.150925615579524,-0.3194150412045055,-1.179326936934976
313.40000000000373,37.2268484664489,-0.3271429171528774,-1.2229593215669494
314.20000000000374,37.305414941075696,-0.3356974176084497,-1.2704999789669444
315.00000000000375,37.38166998897121,-0.34522743074961326,-1.3172665579987686
315.80000000000376,37.45774083756495,-0.35482726347222615,-1.3635475198653095
316.6000000000038,37.5335330398564,-0.36752780412940866,-1.4128339081760068
317.4000000000038,37.610664660070334,-0.37646884410145637,-1.4614406397157085
318.2000000000038,37.6887679436533,-0.38912454002997543,-1.509912689720451
319.0000000000038,37.76417712257355,-0.40033156832195504,-1.5558894696811127
319.8000000000038,37.8398864623953,-0.41158250490801845,-1.601958970000815
320.60000000000383,37.917275595038156,-0.4245281947669563,-1.6481490091041398
321.40000000000384,37.99329041809178,-0.43598091424001767,-1.6918979459549006
322.20000000000385,38.0703236988277,-0.4478182412900759,-1.7367559611623156
323.00000000000387,38.14742183493496,-0.45905959111904054,-1.780539122188343
323.8000000000039,38.22369385036078,-0.4700487336524472,-1.8203531081466036
324.6000000000039,38.30174179055622,-0.48070553796758,-1.8598979157906523
325.4000000000039,38.378797677683025,-0.49123343030849487,-1.8959355734776464
326.2000000000039,38.45548364901671,-0.49926546070627276,-1.9309500232277044
327.0000000000039,38.5314699508843,-0.5072663584725566,-1.9640556581033377
327.80000000000393,38.60935097925331,-0.5148811889083301,-1.994864800515229
328.60000000000394,38.682807200243374,-0.5204332209277535,-2.0209907500677833
329.40000000000396,38.76212632967466,-0.5266289778000978,-2.046486780809172
330.20000000000397,38.83896454797646,-0.5319658631415659,-2.0708848153004076
331.000000000004,38.91669522242493,-0.5385456608886101,-2.0943932399451146
331.800000000004,38.99339604939291,-0.5420579879558605,-2.1158230395207953
332.600000000004,39.07045583484131,-0.5451325434548467,-2.136303275297627
333.400000000004,39.14482534926455,-0.5477880215705381,-2.155266007532562
334.200000000004,39.22444209264241,-0.5508972359822272,-2.1735868828062275
335.00000000000404,39.30255416679565,-0.5521206489783681,-2.1906154260041175
335.80000000000405,39.37947444530615,-0.5548726123169843,-2.207018156089697
336.60000000000406,39.456011958622284,-0.5566783173528532,-2.221141655792723
337.40000000000407,39.53307399837383,-0.5603083324525477,-2.2360570118090086
338.2000000000041,39.61034670473927,-0.562312907246528,-2.249486562149265
339.0000000000041,39.68806348864826,-0.5670778508298665,-2.262096033280763
339.8000000000041,39.76330571023295,-0.5715377898177081,-2.272906898673268
340.6000000000041,39.840998818465934,-0.5749693690316107,-2.285591571487517
341.4000000000041,39.918772817829485,-0.5787438310488884,-2.2956063748201503
342.20000000000414,39.99628472720422,-0.5830292097895069,-2.305439993123403
343.00000000000415,40.07081220358893,-0.5852856339270397,-2.3144956060084176
343.80000000000416,40.151001396888894,-0.5890264939284593,-2.3239273517912737
344.6000000000042,40.22826359162388,-0.5924001259380838,-2.334761440664165
345.4000000000042,40.30394832621132,-0.5952385509189021,-2.3427405685505462
346.2000000000042,40.381723723985104,-0.5977461865747759,-2.3501507670712125
347.0000000000042,40.45917000000045,-0.6015099999999896,-2.3577001640000406
347.8000000000042,40.53620609535279,-0.6050180729086395,-2.3649208903098726
348.60000000000423,40.614529984854215,-0.608116318447255,-2.3725295344833706
349.40000000000424,40.69141097992826,-0.6101114020603293,-2.3787052058354865
350.20000000000425,40.769371698608744,-0.6144838110457427,-2.3856982841083885
351.00000000000426,40.84598670169551,-0.6146356230291157,-2.3929116891047135
351.8000000000043,40.92311815811325,-0.6185527578579736,-2.3978555738811185
352.6000000000043,41.00082216481772,-0.6219816705188398,-2.405003345828729
353.4000000000043,41.07608792569952,-0.6231459927107597,-2.410569573023353
354.2000000000043,41.15548221397746,-0.6250306036775977,-2.415634088899494
355.0000000000043,41.23280566847,-0.6274144752789511,-2.4193632628031447
355.80000000000433,41.31015369094862,-0.6292322999824487,-2.423327786168345
356.60000000000434,41.388405350065064,-0.6311199115134264,-2.428324694927772
357.40000000000435,41.46530806927062,-0.6322528305113386,-2.433259094432704
358.20000000000437,41.54201932411522,-0.6339165538290715,-2.4376652655795072
359.0000000000044,41.619916410852284,-0.6344829971517413,-2.4397871309574715
359.8000000000044,41.69624134736171,-0.6342944969143474,-2.44530696222781
360.6000000000044,41.7736205234527,-0.635287118394587,-2.4488085883260977
361.4000000000044,41.85250436155256,-0.6348199216508635,-2.452806933905049
362.2000000000044,41.928783571650214,-0.6357324420694378,-2.4569015190175048
363.00000000000443,42.00591932952589,-0.6365056173575421,-2.4604205909359687
363.80000000000445,42.084057269015624,-0.6372464126126212,-2.4632924521343007
364.60000000000446,42.159783053278666,-0.6364039765032035,-2.466262587658063
365.40000000000447,42.23950640848229,-0.6375457926117878,-2.4692396847770928
366.2000000000045,42.31610216522418,-0.637462974769484,-2.4719885840633404
367.0000000000045,42.39361938815813,-0.6377215598105263,-2.474957672033968
367.8000000000045,42.470108746734404,-0.6366613696348261,-2.4778314525570977
368.6000000000045,42.54844383269737,-0.6376161079314338,-2.479132505311661
369.4000000000045,42.625865172089604,-0.6362170925398581,-2.483365049350387
370.20000000000454,42.70374247018223,-0.6358440076104791,-2.4853494869832136
371.00000000000455,42.78131746133612,-0.6359425363860478,-2.488653090097593
371.80000000000456,42.85854272879854,-0.6343951610414188,-2.491363024731691
372.60000000000457,42.93638578317616,-0.6350433671964355,-2.493400418155327
373.4000000000046,43.01458861025731,-0.6338821251454073,-2.4952331739755644
374.2000000000046,43.09147199484647,-0.6338029507900061,-2.4973960799336874
375.0000000000046,43.16897193762004,-0.633199865604547,-2.500188965628886
375.8000000000046,43.24758040139601,-0.6324423334648437,-2.5015297513954016
376.6000000000046,43.32416564140032,-0.6311423943793424,-2.5043126428898335
377.40000000000464,43.40159134185915,-0.631136328135776,-2.5055367212493698
378.20000000000465,43.478885087836304,-0.6311966899152561,-2.508224418558136
379.00000000000466,43.5568938786457,-0.630491232227283,-2.5095427099950744
379.8000000000047,43.63434147602957,-0.6285570660390013,-2.5107943028425046
380.6000000000047,43.71264788347009,-0.6283217379686539,-2.5121808411890307
381.4000000000047,43.79005103775789,-0.6277684076227967,-2.5142141023120637
382.2000000000047,43.8677322087205,-0.6279541515342468,-2.5161116179928142
383.0000000000047,43.94524659689862,-0.6263506816550668,-2.5173187036665556
383.80000000000473,44.02161641775561,-0.6274402193499222,-2.5200830232893874
384.60000000000474,44.1012920955021,-0.62557295794807,-2.522480130785934
385.40000000000475,44.17781124312355,-0.6263202613292584,-2.525059981425609
386.20000000000476,44.25700666648724,-0.6258208111129867,-2.5264724290681433
387.0000000000048,44.3325727991094,-0.6268438598695734,-2.527706180409184
387.8000000000048,44.41109655392447,-0.6268714473829476,-2.5304219796885508
388.6000000000048,44.48862234314204,-0.6260059737984973,-2.531674258694019
389.4000000000048,44.5660893898371,-0.626467241602393,-2.5343295699222144
390.2000000000048,44.64464158688248,-0.6264293918527173,-2.5343332634926843
391.00000000000483,44.72235179383937,-0.6271246761450888,-2.53657540745898
391.80000000000484,44.79984386275187,-0.6275228729063462,-2.538285148833304
392.60000000000485,44.87775602912729,-0.6280429445201542,-2.539145618901971
393.40000000000487,44.95542874099064,-0.6287729717086689,-2.54147618064583
394.2000000000049,45.03306610904463,-0.6295326245986285,-2.5440027881076923
395.0000000000049,45.11114837624495,-0.6326729305459725,-2.5454652940286815
395.8000000000049,45.1881263599765,-0.6351941080289738,-2.5467248324008214
396.6000000000049,45.2660349316937,-0.6349861574515002,-2.5475893934414584
397.4000000000049,45.34430524859004,-0.6361721143090892,-2.5490806729683078
398.20000000000493,45.42203738707969,-0.6373993893046823,-2.551318893770378
399.00000000000495,45.50032388165429,-0.6363655364457006,-2.552746327643796
399.80000000000496,45.57836457275876,-0.637455235681712,-2.5553275997572698
400.60000000000497,45.654607868803716,-0.6375821112436668,-2.556228832508319
401.400000000005,45.73255301765414,-0.637557103408936,-2.5567389589059566
402.200000000005,45.81059144797375,-0.6376763467937856,-2.559530499637159
403.000000000005,45.888053658324694,-0.6376116425573177,-2.5606317109039276
403.800000000005,45.96565556722878,-0.6366320106319511,-2.5630241853083024
404.600000000005,46.0435877299434,-0.6353803453196737,-2.56467283365968
405.40000000000504,46.12173304527537,-0.6341469119032374,-2.565961162421327
406.20000000000505,46.199168983516486,-0.6332599888511292,-2.568231978705345
407.00000000000506,46.27669697848821,-0.6334187592360807,-2.569919198338919
407.80000000000507,46.354440688536116,-0.6328019167321512,-2.5699958318058482
408.6000000000051,46.43226452460033,-0.6321319612936894,-2.5712523656137223
409.4000000000051,46.511117507712385,-0.6304244610936554,-2.573914988497309
410.2000000000051,46.588700043137536,-0.631474489298606,-2.575154559490403
411.0000000000051,46.66561201235262,-0.6292826236720923,-2.5775298359141994
411.8000000000051,46.74389961913934,-0.627952921760159,-2.577732446139697
412.60000000000514,46.82222972084838,-0.6284721468428046,-2.5797405372536293
413.40000000000515,46.90003810739585,-0.6287656163697228,-2.5811154984069566
414.20000000000516,46.9783994312909,-0.6271547591857201,-2.582396085328204
415.0000000000052,47.05675632530295,-0.6272770855657454,-2.583661619542662
415.8000000000052,47.13444861177101,-0.6277769740081004,-2.585715238790417
416.6000000000052,47.21272598025772,-0.6263647767316467,-2.587211481843393
417.4000000000052,47.28788788562071,-0.6271970563091672,-2.5876724393208765
418.2000000000052,47.368692862401986,-0.6266714997694633,-2.589982159288422
419.00000000000523,47.44720590094621,-0.6272038181723818,-2.589933432230345
419.80000000000524,47.525346773620214,-0.6269034394225862,-2.591662412396136
420.60000000000525,47.603510064633916,-0.6250996376932245,-2.5939841989699004
421.40000000000526,47.68170352163107,-0.626579845379306,-2.5962598332198614
422.2000000000053,47.75916905777744,-0.6270099047231629,-2.5975801859300667
423.0000000000053,47.83775704745783,-0.6275256555408618,-2.598896217371492
423.8000000000053,47.915204166510556,-0.6288941718617327,-2.6012091321570368
424.6000000000053,47.99398692029305,-0.6282016397161169,-2.6025694430502067
425.4000000000053,48.07175079158848,-0.6293131450473038,-2.604213359169922
426.20000000000533,48.15032182886207,-0.6308126828946066,-2.605464608633585
427.00000000000534,48.228701596269566,-0.6291984459699846,-2.606800793846557
427.80000000000535,48.306580784691555,-0.6309510341063114,-2.608111330233138
428.60000000000537,48.38402981235766,-0.63060651058932,-2.6094574513989017
429.4000000000054,48.46269951060142,-0.6295964925356851,-2.6114437055408484
430.2000000000054,48.54058992500425,-0.6310185317773778,-2.613364055461478
431.0000000000054,48.618393208660265,-0.629955480600179,-2.6146998155372305
431.8000000000054,48.697680224286366,-0.6312746586961284,-2.6147070204170175
432.6000000000054,48.775075874334824,-0.6302646409011387,-2.617138962088323
433.40000000000543,48.85368847720986,-0.6321867490767138,-2.6186264865315687
434.20000000000545,48.93226121808693,-0.6300740504034482,-2.6213463315683727
435.00000000000546,49.01046651015881,-0.6292454234313895,-2.6226274216630103
435.80000000000547,49.08801329262339,-0.6291363409809648,-2.623282711938764
436.6000000000055,49.167010573088184,-0.6290583548766522,-2.624537279881973
437.4000000000055,49.244363076328234,-0.6281641328649121,-2.6272893662819192
438.2000000000055,49.32239376631092,-0.6281149438146127,-2.6285055610785295
439.0000000000055,49.4009023096003,-0.6277879860558028,-2.6307996294295677
439.8000000000055,49.47875506623363,-0.6282435946897579,-2.6324981738656508
440.60000000000554,49.5578561119309,-0.6271630343932058,-2.633824534947988
441.40000000000555,49.63576085721084,-0.626876274165056,-2.635779882299481
442.20000000000556,49.71425633028476,-0.6257256315959908,-2.6374897858912645
443.00000000000557,49.7917023491505,-0.6240008504388778,-2.6391559960835806
443.8000000000056,49.86936387627064,-0.6256940989319265,-2.639746249782516
444.6000000000056,49.94868146979021,-0.6237138612719871,-2.6427628113257855
445.4000000000056,50.02699769533605,-0.6230453356870479,-2.6445588693639897
446.2000000000056,50.10482854746835,-0.6219957924712484,-2.648314469724694
447.0000000000056,50.18346501802793,-0.6208877876398391,-2.649740729135652
447.80000000000564,50.26186472421847,-0.6210642343144291,-2.651144117173081
448.60000000000565,50.34076726368024,-0.619531420510935,-2.6515448708536615
449.40000000000566,50.41810403882889,-0.619896373941618,-2.6524406799881843
450.2000000000057,50.49488698324009,-0.6177686779459918,-2.6561423337875816
451.0000000000057,50.57609955673131,-0.6166882744145873,-2.6588360816039227
451.8000000000057,50.654075324122736,-0.6171939482602021,-2.6614157841866497
452.6000000000057,50.73223270122924,-0.6145025096281352,-2.66341965175212
453.4000000000057,50.81152093935938,-0.6147710211932838,-2.666519657268382
454.20000000000573,50.88926162685554,-0.6130088619565103,-2.6680619892666337
455.00000000000574,50.96800727735896,-0.6115488545517718,-2.6689393867701203
455.80000000000575,51.0472465153108,-0.6101646184036503,-2.671346046940084
456.60000000000576,51.125913774078946,-0.6099710471694515,-2.673190309845853
457.4000000000058,51.20340193393623,-0.609013073138985,-2.6776844024134907
458.2000000000058,51.28245207864453,-0.6082368796081689,-2.6798024803041223
459.0000000000058,51.35956319310251,-0.6074062812055228,-2.680936279879341
459.8000000000058,51.43936204235592,-0.6051994547816953,-2.6834567996702967
460.6000000000058,51.51773017523867,-0.6034274990207948,-2.686982146925695
461.40000000000583,51.596178024829705,-0.6037230526447321,-2.6900409265208656
462.20000000000584,51.67540377538897,-0.5999548822643753,-2.6914733380028686
463.00000000000585,51.75382856737026,-0.5990535187826957,-2.6928218931389
463.80000000000587,51.83232941795606,-0.5969251793172912,-2.695691083412422
464.6000000000059,51.91018539798404,-0.594877970686449,-2.698102950166496
465.4000000000059,51.98927010141292,-0.5934848269784879,-2.7008891890221984
466.2000000000059,52.06779479626552,-0.5924866990516265,-2.7029793047912163
467.0000000000059,52.14565406128834,-0.5906976362223418,-2.70613121976583
467.8000000000059,52.22292152270483,-0.5895222602784805,-2.708320957178787
468.60000000000593,52.30123358398643,-0.586984826957797,-2.7110573672358513
469.40000000000595,52.381862435260494,-0.5854885634898692,-2.7138110244925193
470.20000000000596,52.46047877517132,-0.5847078220857326,-2.7158076972791987
471.00000000000597,52.539170000000624,-0.5836700000000279,-2.7191001120000085
471.800000000006,52.617141617408905,-0.5815591851974241,-2.7218294827001497
472.600000000006,52.695484805257266,-0.5814817513707563,-2.7247344982959687
473.400000000006,52.77566932196854,-0.5806563777870046,-2.726142854259624
474.200000000006,52.85437424057244,-0.5787237022938114,-2.7291354187499013
475.000000000006,52.93326560658647,-0.578615679600568,-2.731681151214363
475.80000000000604,53.01168365795364,-0.5774162712448896,-2.734574959133608
476.60000000000605,53.08991221779334,-0.575680089981388,-2.735890046153396
477.40000000000606,53.16847465075314,-0.5753447560556476,-2.738054138276408
478.20000000000607,53.24816869708031,-0.576474380188821,-2.740823169685725
479.0000000000061,53.327119790503616,-0.5752108320104973,-2.743522287772186
479.8000000000061,53.406127221377005,-0.574376690514636,-2.7446757074397654
480.6000000000061,53.48551522922664,-0.5749940131584768,-2.7473928374261853
481.4000000000061,53.564642987681054,-0.5745378167390662,-2.7485388549200582
482.2000000000061,53.64360078486199,-0.57384329421585,-2.7516206039313023
483.00000000000614,53.72214199219585,-0.5730435691466365,-2.754372173098011
483.80000000000615,53.80180479190681,-0.5717278296550331,-2.755726208137633
484.60000000000616,53.88064207675767,-0.5727681280191713,-2.7592610669358844
485.4000000000062,53.959074232763896,-0.5710283753022569,-2.7592812074536335
486.2000000000062,54.03877054629406,-0.5705341307397541,-2.7619172107159264
487.0000000000062,54.11687697543411,-0.5688057434309239,-2.7632447462595096
487.8000000000062,54.19609914970928,-0.567642837235297,-2.764456527463304
488.6000000000062,54.27223040338243,-0.5664903628131864,-2.7646911838267267
489.40000000000623,54.353835346550966,-0.565592414033777,-2.768484787930141
490.20000000000624,54.43207362665526,-0.5658026071876898,-2.769843958732086
491.00000000000625,54.510832397369796,-0.5646206498428429,-2.7719657773322584
491.80000000000626,54.59019894885626,-0.5622788403022196,-2.773830040898199
492.6000000000063,54.668782329156215,-0.5627212184404238,-2.774023460508966
493.4000000000063,54.74718402370878,-0.5623059973106748,-2.776421048458234
494.2000000000063,54.82420725657539,-0.5602472848835429,-2.7791290557927297
495.0000000000063,54.90448250961048,-0.5593646984820728,-2.7790501148797215
495.8000000000063,54.98148412291417,-0.5587951124409491,-2.7797495434829993
496.60000000000633,55.063631997013445,-0.5575304920163237,-2.7835753689252583
497.40000000000634,55.14213009102731,-0.5578393663941987,-2.7836635515300365
498.20000000000636,55.2209262991703,-0.5571805966062343,-2.785132410803719
499.00000000000637,55.30103873600504,-0.5574275170053417,-2.786705617985908
499.8000000000064,55.3800676294545,-0.5568350336918252,-2.788052225245556
500.6000000000064,55.45864220127465,-0.556989571696433,-2.7893682020497224
501.4000000000064,55.538059411377674,-0.5575164983000762,-2.7913448838679655
502.2000000000064,55.61836717456842,-0.5564276197262303,-2.7926576489995516
503.0000000000064,55.697404559532146,-0.5555670433330941,-2.7952408744215558
503.80000000000643,55.77749709129894,-0.5552165078824196,-2.796614631127412
504.60000000000645,55.85671240072789,-0.5520991218845909,-2.796939477890974
505.40000000000646,55.93383529725761,-0.5508230517812867,-2.797909732318735
506.20000000000647,56.0148642878533,-0.5500705055284015,-2.79925040555257
507.0000000000065,56.09393977727694,-0.548177906299773,-2.801901135356328
507.8000000000065,56.17425120895662,-0.5464498745605072,-2.8018845306619298
508.6000000000065,56.2531857771054,-0.5464802572211948,-2.803287017193571
509.4000000000065,56.332184487523236,-0.5455878406712524,-2.8055105814143166
510.2000000000065,56.41178180248746,-0.5454907660400405,-2.806828214651965
511.00000000000654,56.49124233970548,-0.544791107025325,-2.806818170429561
511.80000000000655,56.57057747634312,-0.5423299636276616,-2.8069141343709947
512.6000000000065,56.64937300150651,-0.541949391228847,-2.8081406050237696
513.4000000000066,56.72957375310432,-0.5414213816450755,-2.8104829147474977
514.2000000000066,56.8074512547601,-0.540701565318511,-2.8107996108375297
515.0000000000066,56.887401752818164,-0.540834362428778,-2.8123016740847184
515.8000000000065,56.96656027534494,-0.5403421848080874,-2.8145088225430612
516.6000000000066,57.04504938058119,-0.5401021107125868,-2.8147323085316946
517.4000000000067,57.124024631422,-0.5380573284906812,-2.8160727988168848
518.2000000000066,57.20290606930148,-0.5374692956165013,-2.817359901092054
519.0000000000066,57.28122641963908,-0.5357763557818116,-2.8181844541724326
519.8000000000067,57.360279293244886,-0.5355327146414465,-2.820072227566607
520.6000000000067,57.43948236237453,-0.533871983364529,-2.820005785103154
521.4000000000067,57.51765057320045,-0.5341193517391903,-2.8214111006091223
522.2000000000066,57.59789041013971,-0.5331145711389399,-2.8214200390234927
523.0000000000067,57.67617902983192,-0.5336637291081221,-2.82293260959235
523.8000000000068,57.75592910828636,-0.532155057284733,-2.825035861052375
524.6000000000067,57.834903345198086,-0.5325756077183266,-2.826126243392202
525.4000000000067,57.91345782901851,-0.5307229526021935,-2.824965156128103
526.2000000000068,57.9924436535233,-0.5309633551261314,-2.8288858666670875
527.0000000000068,58.071663837093574,-0.5294423077067207,-2.829000228546848
527.8000000000068,58.15042618290185,-0.5284954436316938,-2.8299994032244618
528.6000000000067,58.2291720429331,-0.5273697195874572,-2.831293622716376
529.4000000000068,58.308667025605075,-0.5279821667133705,-2.830309779157438
530.2000000000069,58.38731745471095,-0.5266829429556681,-2.8316294799254202
531.0000000000068,58.46715307518741,-0.5263898975794863,-2.8329503581917512
531.8000000000068,58.545866624598716,-0.5257207527969144,-2.834263134120098
532.6000000000068,58.62441415941933,-0.5259501286567598,-2.835579890654074
533.4000000000069,58.70170656635431,-0.5262294109920478,-2.8355800857100495
534.2000000000069,58.78328423407682,-0.5236605044206469,-2.8363127144356213
535.0000000000068,58.861436015294515,-0.5232914804534208,-2.838222889408896
535.8000000000069,58.94110224347183,-0.5214180769546569,-2.8391988411320233
536.600000000007,59.01974565655158,-0.52111161385547,-2.839210112747278
537.4000000000069,59.099580429294384,-0.5187032312885773,-2.8405195539349806
538.2000000000069,59.178191890630416,-0.5164458416347335,-2.8418418873095184
539.0000000000069,59.25775840036472,-0.5147185047475206,-2.841839500093931
539.800000000007,59.337060301880385,-0.5120025396438035,-2.8429637661728737
540.600000000007,59.41561007758468,-0.5111523449294999,-2.8436656162614304
541.4000000000069,59.49587554813953,-0.508232662339857,-2.846009699234629
542.200000000007,59.574332522324696,-0.5088361671785614,-2.8446895751437893
543.000000000007,59.654016866791586,-0.5079157386996216,-2.8457327433735733
543.800000000007,59.732883211303886,-0.5059990602676533,-2.84730729705864
544.600000000007,59.812602389101535,-0.5055000047178261,-2.847267586186374
545.400000000007,59.890925896450504,-0.5037697361190818,-2.849442956505615
546.000000000007,59.95076953620562,-0.5040260829226773,-2.849959793306135