File: 01_Data/CPVC_Pipe/STA/N2/10K_min/CPVC_Pipe_STA_N2_10KData_221024_R3.csv
##Temp./Â°C,Time/min,DSC/(mW/mg),Mass loss/mg
51.0,10.68359894502658,-1.6714473359803508,-0.019128844572287917
51.80000000000001,11.010367865372032,-1.5831014918953143,-0.01622624936743744
52.60000000000002,11.22271953168834,-1.5177313383341342,-0.016303424645849773
53.400000000000034,11.391643016048343,-1.4713694052987898,-0.016873966654076256
54.200000000000045,11.547085424945884,-1.4302080649086106,-0.016081743380184754
55.00000000000006,11.686718544639477,-1.3974143358452038,-0.017037777835215095
55.80000000000007,11.814654498629151,-1.368910599360385,-0.01670081321930983
56.60000000000008,11.93838275328345,-1.3460478041522193,-0.016274704446685995
57.40000000000009,12.0595494719208,-1.3228337960052792,-0.015843866922055305
58.2000000000001,12.173604141999842,-1.3036435899100518,-0.01665751214219835
59.000000000000114,12.28466964140155,-1.2876453218209405,-0.018925822929205083
59.800000000000125,12.393811965639673,-1.2736743129361339,-0.017489443138138938
60.600000000000136,12.49986151214199,-1.2595063315702104,-0.017399137797709407
61.40000000000015,12.605023110527775,-1.2455015735076014,-0.017259551958032304
62.20000000000016,12.70792235125155,-1.2344760419842906,-0.01744275761031666
63.00000000000017,12.810681929390812,-1.2236932258434463,-0.017466249998488337
63.80000000000018,12.91125437880084,-1.2122362778536047,-0.01689318670864992
64.6000000000002,13.009100366555119,-1.2031625555914505,-0.01706845301174109
65.4000000000002,13.107627307816264,-1.1937285393903623,-0.017365811490616778
66.20000000000022,13.203717623690116,-1.1828590965973305,-0.018595841349188014
67.00000000000023,13.30000000000003,-1.1755799999999996,-0.01906566228516393
67.80000000000024,13.395598428259449,-1.167126603374104,-0.01873093912042023
68.60000000000025,13.489390118470983,-1.1595592795873357,-0.017451866203018973
69.40000000000026,13.58265268459704,-1.1511943632786679,-0.018659605725900974
70.20000000000027,13.674920599982888,-1.141102810910357,-0.017746264553649027
71.00000000000028,13.767388736681713,-1.1351236777920382,-0.018838278985356283
71.8000000000003,13.859777718746532,-1.1274962870546152,-0.018562139750263107
72.6000000000003,13.948876789884196,-1.1199944703232614,-0.018787704184208387
73.40000000000032,14.040544245368029,-1.1113437451057822,-0.018706399135469454
74.20000000000033,14.129732458585767,-1.1035990492002727,-0.019792780875005356
75.00000000000034,14.218942957084435,-1.096206284248606,-0.018781956972978797
75.80000000000035,14.307358727917853,-1.091975703590667,-0.018765724122820515
76.60000000000036,14.396046571774116,-1.0867812260073921,-0.018914267589861034
77.40000000000038,14.482973099147761,-1.082186523400119,-0.02013682802968031
78.20000000000039,14.569009522256342,-1.0788260664543543,-0.018809878918747636
79.0000000000004,14.658698426625527,-1.0734912820019467,-0.01876000208894446
79.80000000000041,14.743421803437094,-1.0703201578414465,-0.019069666845945576
80.60000000000042,14.828846143089642,-1.0658105262421305,-0.019084451815368553
81.40000000000043,14.913659529944622,-1.060876260728578,-0.02007549665040287
82.20000000000044,15.001706061015193,-1.056403048574331,-0.01975219932044414
83.00000000000045,15.086278276323311,-1.0525605160420832,-0.01973431353863031
83.80000000000047,15.167699731512485,-1.0455076181441738,-0.020030994127308688
84.60000000000048,15.255783422917895,-1.0421846260776328,-0.020101786176791592
85.40000000000049,15.338850641664282,-1.0356811280022191,-0.020137506625202306
86.2000000000005,15.422679835286452,-1.0315376893817068,-0.02142748490513746
87.00000000000051,15.506249879662189,-1.0246762403131902,-0.021455838994394405
87.80000000000052,15.589795566647314,-1.0190167157058234,-0.021522790179580475
88.60000000000053,15.672821695546615,-1.0137205824985533,-0.022712090773124416
89.40000000000055,15.754692400602025,-1.0088136882209904,-0.022729120713010253
90.20000000000056,15.833848698409186,-1.0043963029952832,-0.021755766235811436
91.00000000000057,15.919185438528281,-0.9986083979677363,-0.021411968435154805
91.80000000000058,16.00027020026893,-0.9938052958157195,-0.021411428503670393
92.60000000000059,16.082704966227887,-0.9877749439041242,-0.021423182572922528
93.4000000000006,16.163295216322194,-0.9836987415424762,-0.021430793511078683
94.20000000000061,16.244786272499404,-0.978211107742428,-0.021410847356563067
95.00000000000063,16.3264117214592,-0.9737964378343328,-0.02145423667273949
95.80000000000064,16.40513396254228,-0.9690565546523496,-0.02272897724630596
96.60000000000065,16.485612455389504,-0.9645590525249889,-0.021410528721542477
97.40000000000066,16.567228158497016,-0.9587698214404274,-0.021376198533704205
98.20000000000067,16.646409682255136,-0.9547191314093904,-0.02140858892829023
99.00000000000068,16.72524554705825,-0.9500680697407236,-0.022729941133952103
99.8000000000007,16.803876145553968,-0.9450202503679795,-0.023000454031670614
100.6000000000007,16.88598709975297,-0.9402760392270001,-0.022722786346975
101.40000000000072,16.964072183576775,-0.9364069280143521,-0.022720033999719114
102.20000000000073,17.043715650462126,-0.9320179170131605,-0.021869472259576028
103.00000000000074,17.122758834785174,-0.9276034992852494,-0.021413098030158118
103.80000000000075,17.204934028906543,-0.9213486415384592,-0.022508016014273657
104.60000000000076,17.27959195928264,-0.9180720253949224,-0.022620839781058777
105.40000000000077,17.361781674276767,-0.9136010166681461,-0.022667084381606806
106.20000000000078,17.43960167627207,-0.9105181749788134,-0.02273005663325467
107.0000000000008,17.518449302046665,-0.9065752612499122,-0.024038972902449274
107.80000000000081,17.597154959655935,-0.9011003523098515,-0.02401410758406719
108.60000000000082,17.676385696844648,-0.8984467794022652,-0.024050230107006243
109.40000000000083,17.755307744639467,-0.8936381583640368,-0.024046338348559182
110.20000000000084,17.833510295431253,-0.888459550387508,-0.024049933560458925
111.00000000000085,17.91260854937224,-0.8849493383960702,-0.022607137302822267
111.80000000000086,17.991177497383024,-0.881042735800027,-0.023980634607650764
112.60000000000088,18.06961211576821,-0.877445308713894,-0.024040310847698976
113.40000000000089,18.148363639475654,-0.8743705294385309,-0.02306035310174437
114.2000000000009,18.22633222414218,-0.8680678472978938,-0.024379139829315832
115.00000000000091,18.304571989234972,-0.8643143726422833,-0.025378742392518916
115.80000000000092,18.382219286396662,-0.8609437358393893,-0.023694373399135493
116.60000000000093,18.461005760826083,-0.856737777911104,-0.02527825553443286
117.40000000000094,18.539712326153783,-0.8524278907962775,-0.025249901960193277
118.20000000000095,18.617898011008187,-0.8471274636505879,-0.023941523193730774
119.00000000000097,18.695006176778186,-0.8436247451214997,-0.023929818319316176
119.80000000000098,18.774291250681905,-0.8382249192510092,-0.025216323692398568
120.60000000000099,18.848183258862683,-0.8344187853403064,-0.023939644310467578
121.400000000001,18.92870649264125,-0.8286533071615996,-0.025259416930777157
122.20000000000101,19.007310846051272,-0.823421761834172,-0.023956129027723705
123.00000000000102,19.084117003203936,-0.8187383950452488,-0.025259926576603142
123.80000000000103,19.162105263657644,-0.8145947991418909,-0.023779705116838912
124.60000000000105,19.24000000000011,-0.8094399999999973,-0.024259830485904743
125.40000000000106,19.31761508545377,-0.806035487406863,-0.02500002713693661
126.20000000000107,19.393886728870086,-0.8012724921812114,-0.02557374760886777
127.00000000000108,19.472493376334814,-0.7986509013812206,-0.02640209132280802
127.80000000000109,19.547689718955983,-0.7932722885663094,-0.02729820460452359
128.6000000000011,19.62560150620475,-0.7890040035267123,-0.027470319873808435
129.4000000000011,19.703239458497375,-0.7845550552976425,-0.024928549299952252
130.20000000000113,19.78000000000011,-0.7817200000000055,-0.025617603657045684
131.00000000000114,19.857971232574716,-0.7791570785777232,-0.025620883964631247
131.80000000000115,19.93387502864028,-0.7754418105399963,-0.025623594956180717
132.60000000000116,20.011720645260546,-0.7722669292228669,-0.027636473609861767
133.40000000000117,20.088190082849316,-0.7691102291710564,-0.026899542486500394
134.20000000000118,20.16435185444616,-0.7665667554025883,-0.026954813072329387
135.0000000000012,20.24306553697928,-0.7621622606800426,-0.02690794980688871
135.8000000000012,20.318929654230583,-0.7611862932488682,-0.026910084036040338
136.60000000000122,20.396003106270147,-0.7577158189640628,-0.02552406062678081
137.40000000000123,20.47332524089804,-0.7558653380756682,-0.026884664528459723
138.20000000000124,20.54980578619823,-0.7514807648100416,-0.02700906196164876
139.00000000000125,20.625797609033206,-0.7512222219430931,-0.026899950089106284
139.80000000000126,20.70335327108153,-0.7470477980913154,-0.026892642147354984
140.60000000000127,20.77951998524919,-0.7449802816767406,-0.028219855359048474
141.40000000000128,20.85569033894947,-0.7429697666279501,-0.026960185887980437
142.2000000000013,20.93182912333446,-0.7389861197802989,-0.02817070120152465
143.0000000000013,21.009285526083353,-0.7359592550635525,-0.02821873718467227
143.80000000000132,21.086165646706352,-0.7324312034439775,-0.028230492683397834
144.60000000000133,21.160614318467214,-0.7298647943141391,-0.029526553384410015
145.40000000000134,21.23839417146239,-0.7263006206723744,-0.028262705783781428
146.20000000000135,21.314077010409946,-0.7249025751014949,-0.028235392195810505
147.00000000000136,21.39028766244041,-0.7211350604242246,-0.028201614308005496
147.80000000000138,21.466750774734408,-0.7189201358752659,-0.02756008571263102
148.6000000000014,21.543053088921166,-0.7166520280058145,-0.02918749089854611
149.4000000000014,21.619196001399573,-0.7136720146111392,-0.028219610512763005
150.2000000000014,21.695170528198307,-0.710626629132388,-0.02824040039127329
151.00000000000142,21.7720406018966,-0.7075644495708798,-0.02955793819872632
151.80000000000143,21.848678311502034,-0.7053258033571592,-0.029529937199521683
152.60000000000144,21.92454072170501,-0.7036427163709307,-0.029530148037135717
153.40000000000146,22.000595032033704,-0.699666639744716,-0.02953145662037482
154.20000000000147,22.076650656186228,-0.6980833063047425,-0.029576927641183914
155.00000000000148,22.15319879218716,-0.6952522457446825,-0.029540005657427315
155.8000000000015,22.22747852898034,-0.6915941444929026,-0.03082726990707574
156.6000000000015,22.3046427497526,-0.6900880183329461,-0.029895986286273768
157.4000000000015,22.380905024673364,-0.6868472816608842,-0.031190233956982283
158.20000000000152,22.45665122507748,-0.6827949150927187,-0.031190190998300338
159.00000000000153,22.532882665371897,-0.680581997728034,-0.031190197965490718
159.80000000000155,22.60960147574098,-0.6789965006186066,-0.030868618972282214
160.60000000000156,22.685288042345256,-0.6773372556250135,-0.03059516229500492
161.40000000000157,22.76184201318598,-0.6743746531166384,-0.03170696549244223
162.20000000000158,22.83577167583816,-0.6724339187736356,-0.032169811854654284
163.0000000000016,22.91283582690314,-0.6702143548564615,-0.03212745090386093
163.8000000000016,22.98879273752953,-0.6675517853899693,-0.030849777928598776
164.60000000000161,23.06398759542739,-0.6642413475547811,-0.03219592870926924
165.40000000000163,23.140096789536578,-0.6624441605099106,-0.032169903663104016
166.20000000000164,23.21631642032526,-0.6607195042121145,-0.03104626325744686
167.00000000000165,23.292239472866736,-0.657259397021467,-0.03217034857092216
167.80000000000166,23.368485530891114,-0.653858265398918,-0.03349070637987506
168.60000000000167,23.444679891582204,-0.6520872333698934,-0.03349017889599981
169.40000000000168,23.520810365430513,-0.648429726161408,-0.03349017546341937
170.2000000000017,23.596230466615378,-0.6461528728456473,-0.03270619731379831
171.0000000000017,23.670843806318793,-0.6428010614629818,-0.032500060681369014
171.80000000000172,23.749095176243724,-0.6413363644075619,-0.0338192544360032
172.60000000000173,23.823857810223057,-0.6391920552266247,-0.03345633448206353
173.40000000000174,23.899788542844533,-0.6365272068718871,-0.033490338082505566
174.20000000000175,23.977958893927504,-0.63496346701407,-0.033481197498778315
175.00000000000176,24.051776450504406,-0.6338722141950796,-0.03425642720982314
175.80000000000177,24.129199863504663,-0.6313266299046225,-0.03611987328993305
176.60000000000178,24.205232042014675,-0.6290444984114245,-0.03611000655487917
177.4000000000018,24.27880843426179,-0.6268142321028024,-0.034800936063838606
178.2000000000018,24.35749830799815,-0.626888578462647,-0.03611939357783189
179.00000000000182,24.432510960884606,-0.6241377547030807,-0.0361199735822888
179.80000000000183,24.510319845528105,-0.6224600581108898,-0.03612558742778482
180.60000000000184,24.5851315769439,-0.6200680631956137,-0.038759971737857946
181.40000000000185,24.66180242079502,-0.6171708385818795,-0.037620722625738345
182.20000000000186,24.738057579993963,-0.616962730877518,-0.03800261064693622
183.00000000000188,24.81369761476645,-0.6138305230735791,-0.03842997658206748
183.8000000000019,24.89051176605668,-0.611425253393636,-0.03842995888290979
184.6000000000019,24.965438686671764,-0.6089061836068459,-0.03729253206540051
185.4000000000019,25.042901066759093,-0.6064485163176034,-0.03776951530649786
186.20000000000192,25.11804973909011,-0.6052912506548392,-0.039079031876759984
187.00000000000193,25.194199181447235,-0.6034980191373657,-0.039080139687875715
187.80000000000194,25.268824065960995,-0.6025657205281383,-0.03936382060281929
188.60000000000196,25.34456158320997,-0.6001887102170091,-0.04171903500433771
189.40000000000197,25.421415635248202,-0.5990260618763714,-0.040362996625432856
190.20000000000198,25.49715383770157,-0.5966879717638053,-0.04039994356055221
191.000000000002,25.57368677022213,-0.5945485763784236,-0.041689036011914204
191.800000000002,25.648219371701842,-0.5939228607119447,-0.04040987307860089
192.600000000002,25.724231858821334,-0.5901594632978457,-0.0417053066000328
193.40000000000202,25.799544823924297,-0.5893577516205012,-0.04172033567718447
194.20000000000203,25.875329706608323,-0.5870665041534399,-0.04270502719676195
195.00000000000205,25.95138349179284,-0.5847461893828263,-0.04300030435040014
195.80000000000206,26.026357293583267,-0.5827038189263876,-0.044350232350827135
196.60000000000207,26.102432468013667,-0.5810617065839865,-0.04435110614752613
197.40000000000208,26.178178598198084,-0.5807167228501742,-0.04335701375601175
198.2000000000021,26.25509775528413,-0.5782714506111758,-0.04336931716521519
199.0000000000021,26.329907729353,-0.5768350455324152,-0.044359111653792915
199.80000000000211,26.40567775295455,-0.5736821419471939,-0.044356343619284644
200.60000000000213,26.481707374175034,-0.5752017159726153,-0.04560114070505783
201.40000000000214,26.558330770661986,-0.5719442461585056,-0.047036046050220826
202.20000000000215,26.634427471238784,-0.571324409250463,-0.046340141568233406
203.00000000000216,26.708513314343254,-0.5684893022183567,-0.046340167062629334
203.80000000000217,26.78539850148268,-0.5668369290225646,-0.04633504912874109
204.60000000000218,26.86060814305279,-0.5644614787968337,-0.047000586543955336
205.4000000000022,26.937466968669632,-0.5641724214480803,-0.04700014595309998
206.2000000000022,27.013033894342566,-0.562563215406831,-0.04773771616912548
207.00000000000222,27.087910851243986,-0.5612562169821081,-0.04766026536275003
207.80000000000223,27.16412387508472,-0.5593728165250261,-0.048958611156742826
208.60000000000224,27.241310634339655,-0.5583580545414121,-0.04897016665667753
209.40000000000225,27.315872438189963,-0.5562817585508953,-0.04897016700169221
210.20000000000226,27.39121254468258,-0.5528986444015508,-0.04897021151167902
211.00000000000227,27.46798726888841,-0.5530440336441266,-0.05024428500487055
211.80000000000229,27.54396927504006,-0.5527599519644133,-0.050310938409327655
212.6000000000023,27.62070152322551,-0.5512834213751052,-0.05160061334697641
213.4000000000023,27.69610329175618,-0.5488735698964319,-0.05160694220576989
214.20000000000232,27.77087834985557,-0.5471883815358727,-0.05160630578444714
215.00000000000233,27.846966406143565,-0.5460970867908229,-0.05391256746249162
215.80000000000234,27.923667952096388,-0.5440164098337273,-0.05259280777243003
216.60000000000235,27.999467673685977,-0.5434592295374723,-0.053910631844825474
217.40000000000236,28.075283184159122,-0.5415094542160184,-0.05424236337987409
218.20000000000238,28.150771789399236,-0.540022881318911,-0.054208665685500534
219.0000000000024,28.227585228686007,-0.539641853179539,-0.05522354313324929
219.8000000000024,28.303316245453214,-0.5375936304316837,-0.056548730109518885
220.6000000000024,28.378914892735626,-0.5359513898362862,-0.05687028609945699
221.40000000000242,28.45422782402789,-0.5340823886636191,-0.05719711997603749
222.20000000000243,28.531008317235592,-0.5327147981257797,-0.05918340807529354
223.00000000000244,28.60614962963508,-0.5312494293653103,-0.05917754573565137
223.80000000000246,28.682111067888243,-0.5289687214603753,-0.05951064392152361
224.60000000000247,28.75769361925175,-0.525658221783054,-0.06050246112639801
225.40000000000248,28.83344627624553,-0.5263995772131521,-0.06182013772952999
226.2000000000025,28.909348047513774,-0.5237125603814398,-0.06181986594156896
227.0000000000025,28.985724543927496,-0.5231400585072594,-0.06214175517413523
227.8000000000025,29.060679102536675,-0.5222164384049408,-0.06253400260105657
228.60000000000252,29.13418970805666,-0.5194028605173655,-0.06345996007966637
229.40000000000254,29.210505298956257,-0.51736805002845,-0.0647771247295541
230.20000000000255,29.288235837002485,-0.516482295329705,-0.06530854888477755
231.00000000000256,29.36478952680527,-0.5148960947188028,-0.06741990705171208
231.80000000000257,29.440669021088215,-0.5133710580914066,-0.06744448441512585
232.60000000000258,29.516049865523478,-0.5133504163472331,-0.06872732037332874
233.4000000000026,29.592320173549673,-0.5105320018205951,-0.07005030728249029
234.2000000000026,29.66832899001934,-0.5086757766219632,-0.0709152154271031
235.00000000000261,29.74455078261034,-0.5074982812600505,-0.07196060518163039
235.80000000000263,29.820500450094432,-0.5064179609727866,-0.07399477599523019
236.60000000000264,29.895681073542235,-0.5043516439278425,-0.075308900927606
237.40000000000265,29.971319781085132,-0.5030183116755199,-0.0765708852223379
238.20000000000266,30.047793442769667,-0.5014699704036361,-0.07795061247712809
239.00000000000267,30.12294491231424,-0.49971548311333075,-0.07927326171141402
239.80000000000268,30.19918875778224,-0.4983195079437368,-0.08059269076656594
240.6000000000027,30.27485265142577,-0.4979729465837215,-0.08190024609591884
241.4000000000027,30.351219562532943,-0.4961898437274976,-0.08451178599462272
242.20000000000272,30.42798282958305,-0.49532154726711225,-0.08634529023000281
243.00000000000273,30.502647774421657,-0.49536603448127975,-0.08855385119835013
243.80000000000274,30.579467972391054,-0.4935933056392929,-0.0898172468244236
244.60000000000275,30.65559592207536,-0.49352021977642113,-0.09168288758152432
245.40000000000276,30.731684334062177,-0.49361722455343554,-0.09486705261426831
246.20000000000277,30.80818761162733,-0.49324747381926864,-0.09635160448984559
247.00000000000279,30.883385262266337,-0.4930604848959784,-0.09771879306215636
247.8000000000028,30.957075155785404,-0.49181568296851214,-0.1002473048783572
248.6000000000028,31.036805204685734,-0.49233296376196173,-0.101720848123243
249.40000000000282,31.11319160098042,-0.49131102654849024,-0.1030901754675062
250.20000000000283,31.188999774954063,-0.4903939674438724,-0.10562749687196638
251.00000000000284,31.26480210924323,-0.48787250368958607,-0.10624729620176243
251.80000000000285,31.341240132762728,-0.48278702131229523,-0.10842983657854699
252.60000000000286,31.41663556262528,-0.4788386858082804,-0.11033164261312578
253.40000000000288,31.493734016339957,-0.47313625597199027,-0.11293741453178185
254.2000000000029,31.57110948337382,-0.4670676497160063,-0.1142988069456008
255.0000000000029,31.645913905685482,-0.462973082390192,-0.11622141134407604
255.8000000000029,31.722830147971735,-0.4593550211307671,-0.11849397087404645
256.6000000000029,31.79835144496154,-0.4553818243972926,-0.12023379366573916
257.40000000000293,31.875279254865106,-0.45207635609998353,-0.12048931438903088
258.20000000000294,31.951694651040555,-0.44841992421165766,-0.12286639092102902
259.00000000000296,32.02789641896624,-0.44483832413620233,-0.12532657831422123
259.80000000000297,32.103888722428074,-0.4410839861135397,-0.12740700197896304
260.600000000003,32.18094472409451,-0.43799072720872845,-0.12943895221454138
261.400000000003,32.257295010022446,-0.4328736531664949,-0.1318536446499503
262.200000000003,32.33325937771254,-0.43233420548591284,-0.13458538526278696
263.000000000003,32.407367091906714,-0.42781550399315904,-0.13635932134881923
263.800000000003,32.484122367537175,-0.4232122734335185,-0.13846803854785383
264.60000000000304,32.562085360697516,-0.41764058114565505,-0.14138508610813494
265.40000000000305,32.63560708285782,-0.415830720563463,-0.1445065183008154
266.20000000000306,32.713940448855176,-0.4107119157090511,-0.1472411079824223
267.00000000000307,32.79085936344242,-0.40563969666243,-0.15180776997118706
267.8000000000031,32.86622284717607,-0.4017948091248673,-0.1555038601562746
268.6000000000031,32.94268437073729,-0.3964165790382702,-0.15881282370268357
269.4000000000031,33.0199054023125,-0.39041908041451273,-0.16335155401658996
270.2000000000031,33.09512375189413,-0.3871243198885977,-0.1661687703990804
271.0000000000031,33.1721116865447,-0.38256293508174916,-0.16973875223132584
271.80000000000314,33.24822236326615,-0.3773105002945967,-0.17428047083603815
272.60000000000315,33.326771342902376,-0.37194169627265733,-0.18039365145226016
273.40000000000316,33.40192171823024,-0.36919286502618914,-0.18559441610192273
274.2000000000032,33.47891814745369,-0.36358179374687494,-0.19029692547978838
275.0000000000032,33.55486585680024,-0.35853338288254394,-0.19610349302289887
275.8000000000032,33.62974218851961,-0.3539417403426824,-0.20146004566589149
276.6000000000032,33.707548638803345,-0.349771909189776,-0.20667831321788777
277.4000000000032,33.78460537842926,-0.34420896482022156,-0.21435741041523748
278.20000000000323,33.86172411200485,-0.33756317574132155,-0.2210560017571317
279.00000000000324,33.93721481004229,-0.3336420712219907,-0.2287972442530517
279.80000000000325,34.014111546842095,-0.3273678209105874,-0.23698471182318048
280.60000000000326,34.090093620277216,-0.321844717239547,-0.24515895648472208
281.4000000000033,34.16795199601941,-0.3159163122773445,-0.25402859222177465
282.2000000000033,34.24399786858795,-0.3106059370966879,-0.2634765840567912
283.0000000000033,34.31989791286132,-0.3047401680005759,-0.27432113471355013
283.8000000000033,34.396233138806515,-0.29962189641336984,-0.2850042049956345
284.6000000000033,34.4729592350405,-0.2935222677806263,-0.29485864710301257
285.40000000000333,34.54909682799481,-0.28766315319908703,-0.30690437374351287
286.20000000000334,34.62647321742862,-0.2814884258515482,-0.3201010822854591
287.00000000000335,34.70170887992445,-0.2773875916781386,-0.332290838296736
287.80000000000337,34.77952720506577,-0.2712349965135292,-0.34682987858163106
288.6000000000034,34.85493771721638,-0.268383066718464,-0.3617005391592083
289.4000000000034,34.93163861163526,-0.2626807018578021,-0.37514768386006736
290.2000000000034,35.00822526149841,-0.25889239057079577,-0.3917481155620832
291.0000000000034,35.0831833315807,-0.2540140331927104,-0.4082840021738203
291.8000000000034,35.161043108365604,-0.2492649397936667,-0.4261511902001338
292.60000000000343,35.23685179713906,-0.24573532099790932,-0.4440105353091308
293.40000000000344,35.31314220794404,-0.24285586775614007,-0.46336529140229965
294.20000000000346,35.39105481781515,-0.24018043409592738,-0.48398958948048776
295.00000000000347,35.46671409325996,-0.2371159457046846,-0.5060302063408537
295.8000000000035,35.5426185662537,-0.23510940923030085,-0.5287923797844307
296.6000000000035,35.61848918249583,-0.232972791078439,-0.5518219194937202
297.4000000000035,35.69533733483765,-0.23185561732432286,-0.5766716047379012
298.2000000000035,35.77249052725162,-0.23046669660622804,-0.60173101955036
299.0000000000035,35.84917613422979,-0.2304548266611591,-0.6280480411512968
299.80000000000354,35.92558548205095,-0.23063382077085576,-0.6549542982643652
300.60000000000355,36.00107672509983,-0.23136356501276298,-0.6846579270294364
301.40000000000356,36.07779243227014,-0.23310678678380647,-0.7136104566286052
302.20000000000357,36.15425722727879,-0.233748625072437,-0.7449224120889908
303.0000000000036,36.230677866076626,-0.23639051699893227,-0.7774689560124783
303.8000000000036,36.30831833306892,-0.2393747961545352,-0.8124954605118573
304.6000000000036,36.38453337933466,-0.24307531435207094,-0.8456545842937775
305.4000000000036,36.46134702587199,-0.24562633820524188,-0.882848396024674
306.2000000000036,36.53780968009147,-0.2507957336203447,-0.9196849976414283
307.00000000000364,36.614283714281015,-0.25543542623210724,-0.9577536994378928
307.80000000000365,36.69164675194705,-0.2610574601363274,-0.9982995573391937
308.60000000000366,36.76771681110215,-0.26782152667541664,-1.0382276031478161
309.4000000000037,36.84501141175641,-0.27511851499559736,-1.0805576034284932
310.2000000000037,36.92154780752721,-0.2807292562809931,-1.1230881784049584
311.0000000000037,36.99904790089857,-0.28838361779631827,-1.1663802047559653
311.8000000000037,37.07441232347162,-0.29655848027770065,-1.209714576305215
312.6000000000037,37.151362824363495,-0.303149016280041,-1.2537459051145272
313.40000000000373,37.227595350857236,-0.3126041632241479,-1.2988775915722335
314.20000000000374,37.30586887374878,-0.3217365047298661,-1.3452377183110258
315.00000000000375,37.38120966100929,-0.3301821717618257,-1.3907911801033173
315.80000000000376,37.45930393864443,-0.34100031963291294,-1.4393596531698782
316.6000000000038,37.53579655483305,-0.34987334125550534,-1.4890508575210628
317.4000000000038,37.61197077271167,-0.35981693174102936,-1.5349285516377855
318.2000000000038,37.688843686965214,-0.3713564363933419,-1.5824372909017579
319.0000000000038,37.76534119450934,-0.3831148813653522,-1.6286467544650014
319.8000000000038,37.84212595875676,-0.3945293539803022,-1.673491431852277
320.60000000000383,37.91816686627398,-0.40675030547707186,-1.7170811812942537
321.40000000000384,37.995301549904454,-0.4175113930813066,-1.760991373306569
322.20000000000385,38.071949306521944,-0.4278125658887705,-1.8044703788061303
323.00000000000387,38.148810118832145,-0.4378075130194115,-1.8447427777589547
323.8000000000039,38.22449772109111,-0.44824787482803874,-1.8833202054976077
324.6000000000039,38.302201008145595,-0.4557723167405499,-1.9204264537440108
325.4000000000039,38.37658334854225,-0.46636308542396465,-1.9544861931920456
326.2000000000039,38.45440908496815,-0.47445330625396687,-1.9889212880961624
327.0000000000039,38.532025816950316,-0.4823308716134761,-2.019932432272933
327.80000000000393,38.609004886116,-0.4896811208595989,-2.050042458789867
328.60000000000394,38.6856134203844,-0.4972229446492527,-2.077835593817549
329.40000000000396,38.76265381651364,-0.5044450915285457,-2.1034054707646965
330.20000000000397,38.84037408019677,-0.508616330239408,-2.127621988076844
331.000000000004,38.91643541574374,-0.5144755612697701,-2.1495837563471607
331.800000000004,38.9931091025385,-0.518536468909873,-2.170839063672408
332.600000000004,39.070569120863674,-0.5235422992210108,-2.1902073058034848
333.400000000004,39.14732281133014,-0.5256903176825375,-2.2085968045714415
334.200000000004,39.22347335373413,-0.5277851499606164,-2.2263854596660337
335.00000000000404,39.30220723460835,-0.530576125749128,-2.2442196026154764
335.80000000000405,39.378234044438365,-0.5333688585587419,-2.2589674126981865
336.60000000000406,39.455492356836714,-0.5343764769946372,-2.2737501204040376
337.40000000000407,39.53191939692403,-0.5394668945090288,-2.28741276211324
338.2000000000041,39.609090452381785,-0.5436707112424123,-2.3018755542700715
339.0000000000041,39.68647709932542,-0.5461186007843615,-2.313507302950956
339.8000000000041,39.76353176206686,-0.5490933916971747,-2.3263486773940336
340.6000000000041,39.840390719545496,-0.5535593347405486,-2.337753596985169
341.4000000000041,39.91776727631031,-0.5566227537201092,-2.3473331891153375
342.20000000000414,39.994812215699774,-0.5604406448219968,-2.358042785069236
343.00000000000415,40.07209046948302,-0.5639873155997595,-2.368684495138233
343.80000000000416,40.14683632043321,-0.5698620123657054,-2.377148267663144
344.6000000000042,40.226971213231494,-0.5712375348571175,-2.3857549155666815
345.4000000000042,40.304267568372474,-0.5747968360367861,-2.3952356582470724
346.2000000000042,40.381450836129474,-0.5760823186172893,-2.4030574527193345
347.0000000000042,40.458790395446265,-0.580434271194893,-2.410952728279659
347.8000000000042,40.536008974865744,-0.5829938476396271,-2.4185444133775933
348.60000000000423,40.61445990982402,-0.5865069850562709,-2.4251151018672092
349.40000000000424,40.69195378059024,-0.5898869601314849,-2.433157005184987
350.20000000000425,40.76663118494991,-0.592128765660225,-2.4385771242832153
351.00000000000426,40.84607714567488,-0.5948145265033336,-2.44458629387388
351.8000000000043,40.92365681313278,-0.5956097410660233,-2.45050491301639
352.6000000000043,41.00177030692632,-0.5989078641941954,-2.4566315623121318
353.4000000000043,41.07981378670825,-0.6009038590515858,-2.460998130811453
354.2000000000043,41.15615426154215,-0.6008940035609714,-2.4659379709290468
355.0000000000043,41.23363117908773,-0.6034987534595784,-2.4722203991992817
355.80000000000433,41.311806293241574,-0.6051727278221372,-2.4765914448485553
356.60000000000434,41.38946970941085,-0.6067738893755767,-2.4813808469704286
357.40000000000435,41.46694123819119,-0.6084790772634421,-2.4860197805596784
358.20000000000437,41.54488977642875,-0.608474404696489,-2.489657150140605
359.0000000000044,41.62193166497981,-0.6093391303756908,-2.4940596074690022
359.8000000000044,41.69969155606713,-0.6102925232098829,-2.497428562405274
360.6000000000044,41.77625577394794,-0.6097951959972424,-2.501668509892828
361.4000000000044,41.855208750636386,-0.6106480833732484,-2.506696784178472
362.2000000000044,41.93247881743082,-0.6115548720738644,-2.509349249761614
363.00000000000443,42.009898652186,-0.6102765914701187,-2.5130399677778814
363.80000000000445,42.086122381224484,-0.6113173387249274,-2.515260562364862
364.60000000000446,42.16449850909728,-0.6110265490123132,-2.518424527446801
365.40000000000447,42.24181029500999,-0.6096933795797554,-2.5230019572923017
366.2000000000045,42.31999900388774,-0.6090799864386748,-2.524579845277767
367.0000000000045,42.39696776753812,-0.6101992030915865,-2.5269571194587286
367.8000000000045,42.47412544185941,-0.61027218448044,-2.5298555629741886
368.6000000000045,42.55228674604781,-0.6086254098733704,-2.5326651042339448
369.4000000000045,42.62953809301203,-0.6092972499775902,-2.5361085364832734
370.20000000000454,42.70705724608264,-0.6076935510018082,-2.5375572959113395
371.00000000000455,42.78465991246788,-0.6070535526313217,-2.5401796239106753
371.80000000000456,42.86239494951706,-0.6072003819585862,-2.5425959488873744
372.60000000000457,42.93980856827124,-0.6037637994288942,-2.545215255293817
373.4000000000046,43.01757773239893,-0.6041083651884831,-2.547291267949248
374.2000000000046,43.0955023572841,-0.6030834948285865,-2.549945657916343
375.0000000000046,43.172883516214974,-0.6031421621105545,-2.5513870881350194
375.8000000000046,43.24990761938262,-0.6019919052979077,-2.5534425191549825
376.6000000000046,43.327472874905695,-0.601273429056184,-2.5559568594549473
377.40000000000464,43.40628621612648,-0.6001286686202739,-2.5578110722143697
378.20000000000465,43.48311810483027,-0.6006708333523678,-2.5594123271765765
379.00000000000466,43.5617672374446,-0.5994222025070207,-2.5619142220678186
379.8000000000047,43.6386332634632,-0.6002151696834281,-2.5647732445298237
380.6000000000047,43.71606198317658,-0.598272863606481,-2.56611301629275
381.4000000000047,43.79394236233011,-0.5989266237194457,-2.5684925372270113
382.2000000000047,43.87143458413732,-0.5975776229968838,-2.5692808427920157
383.0000000000047,43.94901592768022,-0.5971853548830441,-2.571423562131903
383.80000000000473,44.02768315879602,-0.5960040072850378,-2.574073055590614
384.60000000000474,44.10290812855606,-0.5962631464489473,-2.575391147238843
385.40000000000475,44.18207820821628,-0.5959010264992067,-2.5781827193557003
386.20000000000476,44.2613182609199,-0.5959476785227235,-2.5789176109259735
387.0000000000048,44.33866778561085,-0.5943973942132812,-2.580790095595532
387.8000000000048,44.41594908346141,-0.5960701355533755,-2.5821366946384394
388.6000000000048,44.49376579681359,-0.5961697113275497,-2.5847562027534945
389.4000000000048,44.572136436746945,-0.5964840790773223,-2.5855609527519885
390.2000000000048,44.64869386845925,-0.5946300802767289,-2.5873799833200373
391.00000000000483,44.72554455075849,-0.5951547659000159,-2.590287927967148
391.80000000000484,44.804435881416936,-0.5952951989126631,-2.5919768576366193
392.60000000000485,44.88173121924295,-0.5959097265792802,-2.5919920821220885
393.40000000000487,44.95950617296399,-0.5952355363872733,-2.593299038828116
394.2000000000049,45.03652288946619,-0.5963997999130789,-2.597356522366487
395.0000000000049,45.114175045082575,-0.5962570087716065,-2.6000314555008743
395.8000000000049,45.191933694902815,-0.596260332048779,-2.6002478468709134
396.6000000000049,45.26981938547922,-0.5967043868070275,-2.6024049077629874
397.4000000000049,45.34745102168724,-0.5960324342086637,-2.6040435556240085
398.20000000000493,45.4231764482342,-0.5968417751859088,-2.6054519978711377
399.00000000000495,45.50352481788355,-0.5972090328738631,-2.6082609418139233
399.80000000000496,45.58130749909231,-0.598169935126404,-2.6095577332219593
400.60000000000497,45.65913447117356,-0.5981017896362615,-2.612133032195531
401.400000000005,45.7360462796277,-0.5984436765908663,-2.6133254655955653
402.200000000005,45.812841725379315,-0.5983549083421966,-2.6147995236358423
403.000000000005,45.89262505392278,-0.5996958116057338,-2.6174697009041497
403.800000000005,45.97019336531624,-0.5998370585537725,-2.6177899293223046
404.600000000005,46.0484861261204,-0.5997444660619085,-2.619089496475685
405.40000000000504,46.12688452141355,-0.5999327326255994,-2.620421072046611
406.20000000000505,46.204405242611244,-0.6002240841538876,-2.6232184456938974
407.00000000000506,46.282494341932654,-0.600811647264773,-2.624144713461064
407.80000000000507,46.36084530289078,-0.6000950859238867,-2.625963253804914
408.6000000000051,46.43757509304956,-0.5997660037515673,-2.6272229809170935
409.4000000000051,46.51609539389739,-0.6007939946903177,-2.628547638687156
410.2000000000051,46.59444232319953,-0.6007438215386984,-2.6308399731800605
411.0000000000051,46.67205188407778,-0.6010043906269774,-2.6330577854605117
411.8000000000051,46.74963121278076,-0.6003025711608123,-2.6331502711562416
412.60000000000514,46.828575618520325,-0.6012383588973821,-2.6347025925042518
413.40000000000515,46.90628500135683,-0.5994938641304458,-2.6362146618440603
414.20000000000516,46.98506374973553,-0.6006152961402903,-2.637885356869891
415.0000000000052,47.06308897502726,-0.6010325282951566,-2.638756353593494
415.8000000000052,47.14010146260824,-0.6016122952511814,-2.640069847110964
416.6000000000052,47.217258078456425,-0.6009064448322075,-2.6412833473578483
417.4000000000052,47.29673546372858,-0.6016204344639471,-2.6438717722172185
418.2000000000052,47.37208502638312,-0.6010255850193449,-2.6463052791152197
419.00000000000523,47.45233251550033,-0.6019063549325663,-2.6476959591756564
419.80000000000524,47.53019058101155,-0.6012858656240521,-2.6489608028490137
420.60000000000525,47.60795999163105,-0.6026824852589747,-2.6502620209745427
421.40000000000526,47.686073665721366,-0.6030167242398332,-2.650501151838556
422.2000000000053,47.76352835664067,-0.6011245608980348,-2.6516001793794715
423.0000000000053,47.84201174731741,-0.6034595322914981,-2.652893358444121
423.8000000000053,47.92136860113717,-0.6029058859141506,-2.6555389346053775
424.6000000000053,47.99875803862161,-0.6033395502037193,-2.657101552477131
425.4000000000053,48.077716062921,-0.6034613012013545,-2.659488819717324
426.20000000000533,48.155661718145346,-0.6040542500277515,-2.660810122443203
427.00000000000534,48.23135614028543,-0.6041527909001216,-2.6610054105101146
427.80000000000535,48.31099659352382,-0.6043819132191475,-2.6624563970787163
428.60000000000537,48.389808930803,-0.6043210254179295,-2.6637915412106894
429.4000000000054,48.46788618175583,-0.6049857160620186,-2.6664155530087514
430.2000000000054,48.54525596690898,-0.6060185734743191,-2.667731112404309
431.0000000000054,48.624749413460734,-0.6043298910990799,-2.6703355007282408
431.8000000000054,48.70184259330948,-0.6059597982779638,-2.671751867847536
432.6000000000054,48.78163880222728,-0.6052827314345313,-2.6731479645059584
433.40000000000543,48.85747029629966,-0.6058850491366063,-2.673752040242494
434.20000000000545,48.93856365734201,-0.6063641445615396,-2.6756130888163385
435.00000000000546,49.01652856985848,-0.6075737539424497,-2.678612171013783
435.80000000000547,49.09554529740342,-0.6063272058439388,-2.6792159775125377
436.6000000000055,49.173274092343,-0.6060999849329658,-2.6815330427460133
437.4000000000055,49.24950262200255,-0.607050991261445,-2.682853305868165
438.2000000000055,49.329766186340045,-0.6063444062316565,-2.6856199780232477
439.0000000000055,49.40674912240503,-0.6071850000545225,-2.686938725554142
439.8000000000055,49.48681311559642,-0.606214034140484,-2.688277556060338
440.60000000000554,49.5651948630745,-0.6057470874166379,-2.689597648736253
441.40000000000555,49.644023237782775,-0.6052171646324622,-2.6923745193989808
442.20000000000556,49.72212631382329,-0.604278053409667,-2.6942990840226586
443.00000000000557,49.800843965767015,-0.6036143387247112,-2.6969649810498217
443.8000000000056,49.8786450733706,-0.605534512147458,-2.69761960724078
444.6000000000056,49.957451554887925,-0.6054806128357362,-2.6996544255016377
445.4000000000056,50.03592065716362,-0.6042191528551363,-2.7013470364946692
446.2000000000056,50.114510300573755,-0.6048306375103717,-2.7028577194096393
447.0000000000056,50.19289476402234,-0.6052659214757838,-2.705656565618204
447.80000000000564,50.27118388756897,-0.6050385247496262,-2.7062482416418914
448.60000000000565,50.34922673492984,-0.6051253110851859,-2.708906344230143
449.40000000000566,50.42617978846369,-0.6029301490880391,-2.710178405907814
450.2000000000057,50.50725401544758,-0.6015797729023504,-2.712963275154281
451.0000000000057,50.58556014927786,-0.6019986271274723,-2.7144987617186915
451.8000000000057,50.663171624380034,-0.602008984363633,-2.7157878132509925
452.6000000000057,50.74181743495909,-0.5995360852897954,-2.718257030619128
453.4000000000057,50.819674624251206,-0.5965608195601524,-2.722399374905134
454.20000000000573,50.897933833307015,-0.5959106415648979,-2.7236617959479066
455.00000000000574,50.97645836131753,-0.5945485013171926,-2.7249971590294346
455.80000000000575,51.05435621260691,-0.5933367510547537,-2.727884150910353
456.60000000000576,51.13435502279572,-0.5919953351183923,-2.7306357482342962
457.4000000000058,51.21216857165597,-0.5908288447237259,-2.7331288250392625
458.2000000000058,51.290833191925806,-0.586661707567517,-2.7352590368682326
459.0000000000058,51.36881889154781,-0.5849549958257461,-2.736468391976259
459.8000000000058,51.447440847187316,-0.5851637595618498,-2.7399133662373654
460.6000000000058,51.52593352375294,-0.582403482751935,-2.742682082688093
461.40000000000583,51.602170287720064,-0.5797506683088083,-2.7453045167242545
462.20000000000584,51.683897030338656,-0.5788731615321563,-2.7479069709080344
463.00000000000585,51.762615936006355,-0.5751065049484231,-2.7511784832869104
463.80000000000587,51.841058246684135,-0.5739656105834019,-2.752767367647259
464.6000000000059,51.91896701942321,-0.5707963167578421,-2.7555774769781767
465.4000000000059,51.99718835564487,-0.569288187572428,-2.7599599234582053
466.2000000000059,52.076693574531575,-0.5668867405320065,-2.7597267169960737
467.0000000000059,52.15518963532589,-0.5658048385995336,-2.7632842477762782
467.8000000000059,52.2334800985268,-0.5635810487943764,-2.766557293740804
468.60000000000593,52.31251654562757,-0.5625511838369012,-2.7693532640406273
469.40000000000595,52.39073727567019,-0.5599624227364912,-2.771761050815459
470.20000000000596,52.46924922433978,-0.5582283533537693,-2.7734858378122085
471.00000000000597,52.54771332134804,-0.5581707981145757,-2.7750448851625222
471.800000000006,52.6275527077553,-0.555999075212126,-2.778517612331581
472.600000000006,52.70483917969366,-0.5551453522301326,-2.7812565305139305
473.400000000006,52.78457969391081,-0.5552992250582884,-2.7843846978351343
474.200000000006,52.863923477864915,-0.5542845028871494,-2.7866246810978517
475.000000000006,52.942375995989266,-0.5522581046693872,-2.789661521970524
475.80000000000604,53.021654166279866,-0.552873328368664,-2.792036894164772
476.60000000000605,53.09990447295005,-0.5524883405394503,-2.7938828205951705
477.40000000000606,53.175932686501056,-0.5512910574118326,-2.796751412175934
478.20000000000607,53.25788755667892,-0.5507597895480169,-2.798355602884068
479.0000000000061,53.33685444813629,-0.5521043777847497,-2.799802042321266
479.8000000000061,53.41519874949821,-0.5513679618142043,-2.802470160367045
480.6000000000061,53.49429454693592,-0.5505037263729216,-2.8060019114880492
481.4000000000061,53.57376569471544,-0.5507747410148776,-2.8095682394865236
482.2000000000061,53.65292660235475,-0.5510670765903848,-2.809597684133755
483.00000000000614,53.73107216599838,-0.5501526346216888,-2.8131597417636645
483.80000000000615,53.810472397830175,-0.5484076360549205,-2.815547695738501
484.60000000000616,53.88831123026633,-0.5489695475356313,-2.8167471239194124
485.4000000000062,53.96843707467919,-0.5482034211802923,-2.818354648761025
486.2000000000062,54.0443302898017,-0.5479246401240989,-2.819519834798249
487.0000000000062,54.12641886100246,-0.5481383033467668,-2.8217674167587163
487.8000000000062,54.2050372279012,-0.5478062405184929,-2.8244478539642737
488.6000000000062,54.28371607284885,-0.5455362015142817,-2.8264139847754937
489.40000000000623,54.36243709009988,-0.5452108071709129,-2.8283220295413507
490.20000000000624,54.44193030559865,-0.5452477360457633,-2.831179996159555
491.00000000000625,54.520000000000564,-0.5453899999999924,-2.831089864282501
491.80000000000626,54.59988788213062,-0.5446684102755583,-2.832732304196547
492.6000000000063,54.67809461183238,-0.5428538827787156,-2.834060965973218
493.4000000000063,54.757797674487556,-0.5431204679845726,-2.836140747967248
494.2000000000063,54.836788789194564,-0.5442667003322023,-2.8376845106501336
495.0000000000063,54.914905006884716,-0.5427003043285438,-2.839066166438517
495.8000000000063,54.99407570419072,-0.543728191861029,-2.8403096397412453
496.60000000000633,55.07314798708444,-0.5420254449873324,-2.8418923690487894
497.40000000000634,55.151665355901486,-0.5425232096709727,-2.844379666078403
498.20000000000636,55.229542952082454,-0.5415506929756775,-2.8450391325853537
499.00000000000637,55.30881234117561,-0.5424174270091218,-2.846368987127195
499.8000000000064,55.38824693852297,-0.5402978077912551,-2.8476645774399865
500.6000000000064,55.46798388695713,-0.5395747625468549,-2.8491844993623627
501.4000000000064,55.546624942890645,-0.539345298016973,-2.8519186766965934
502.2000000000064,55.62494567573876,-0.5402839996476673,-2.852482893395482
503.0000000000064,55.70386815928772,-0.5387584768166448,-2.853920284231485
503.80000000000643,55.783152950616426,-0.5381969940367013,-2.855224789876574
504.60000000000645,55.8626033436758,-0.5386291189854325,-2.8577577747335594
505.40000000000646,55.94170392600574,-0.5391605018820045,-2.859195248314281
506.20000000000647,56.02051682227904,-0.5396120952604906,-2.85956541385875
507.0000000000065,56.0991309632357,-0.539152643261647,-2.8607691877048853
507.8000000000065,56.178310679519896,-0.5386983137792424,-2.8630268761604736
508.6000000000065,56.25839024225021,-0.5387116313950656,-2.8631623057218745
509.4000000000065,56.33624233986196,-0.5371146865498234,-2.8631415084436234
510.2000000000065,56.41633064671306,-0.5380470744970747,-2.8657786832017877
511.00000000000654,56.49287488866197,-0.5376662110821583,-2.8671317213665297
511.80000000000655,56.57386020731239,-0.5377222563020193,-2.867084503025001
512.6000000000065,56.65234291314137,-0.536167511224369,-2.8684086591326117
513.4000000000066,56.73135610356591,-0.5370940091987776,-2.871020642681505
514.2000000000066,56.810973747753394,-0.535740757326768,-2.871558920679025
515.0000000000066,56.88921064461725,-0.5359284415415085,-2.872370907047675
515.8000000000065,56.969387507734446,-0.5357078305199132,-2.873679987006613
516.6000000000066,57.04935034742614,-0.5352224231467242,-2.874998748493466
517.4000000000067,57.127475041264475,-0.5340422777674615,-2.876315906144601
518.2000000000066,57.206503945220945,-0.5351047129868398,-2.877735775948678
519.0000000000066,57.2871385742997,-0.5332323688373156,-2.8789112950766746
519.8000000000067,57.36592678187173,-0.5334203570865151,-2.880293583288375
520.6000000000067,57.444811134687015,-0.5329049923047596,-2.881590125197274
521.4000000000067,57.524038031672184,-0.5335100111857004,-2.8815915063696975
522.2000000000066,57.60288870605528,-0.5318052776165892,-2.8829103781547785
523.0000000000067,57.682086491892164,-0.5309794131154076,-2.884373312986729
523.8000000000068,57.761085316556105,-0.5315300671498626,-2.8862866879492
524.6000000000067,57.84019593627997,-0.5304230546083583,-2.885543037096144
525.4000000000067,57.91999789459066,-0.5274900328951887,-2.88685199273833
526.2000000000068,57.999292771195336,-0.5281248774558052,-2.889490020391167
527.0000000000068,58.07877354099729,-0.5265567739980248,-2.8903634562779827
527.8000000000068,58.15785180698754,-0.5264095494996822,-2.890822783213104
528.6000000000067,58.23686032636506,-0.5256036084968234,-2.8914927072634136
529.4000000000068,58.31579990269514,-0.5261220470327816,-2.892132297285506
530.2000000000069,58.39539611316064,-0.5228620568888045,-2.8935317894265555
531.0000000000068,58.47443309656109,-0.5232707198626522,-2.8955114119831586
531.8000000000068,58.553930996983134,-0.5231162606947407,-2.8957091683779854
532.6000000000068,58.63306304889989,-0.5223734349859146,-2.896082786182015
533.4000000000069,58.71235995751813,-0.5221863071960047,-2.897413939898406
534.2000000000069,58.792217724747175,-0.5194454572153215,-2.8986752807183933
535.0000000000068,58.870389707078544,-0.5195792139563186,-2.900040176368556
535.8000000000069,58.94964747157577,-0.5199190720253956,-2.901349969751421
536.600000000007,59.02925840369524,-0.5189953907151285,-2.902623043360738
537.4000000000069,59.10749851695688,-0.5176978116397607,-2.9038463540642674
538.2000000000069,59.188070194429976,-0.5190374389882072,-2.9026641228497136
539.0000000000069,59.26617338850529,-0.5180371605610145,-2.9053316217879797
539.800000000007,59.346159528148625,-0.5153515583774002,-2.905270072238957
540.600000000007,59.42620312104152,-0.5168642141518062,-2.9066727482768284
541.4000000000069,59.50499483210501,-0.5159315864285093,-2.907122631158841
542.200000000007,59.58429171452384,-0.5152134283532065,-2.9092552021125972
543.000000000007,59.66121754264294,-0.51416529374084,-2.9092593465113823
543.800000000007,59.741890716815725,-0.5151236913500417,-2.911627815317464
544.600000000007,59.823069394573736,-0.5124293172563557,-2.9115779296046487
545.400000000007,59.901533252294,-0.5141646773226483,-2.911557868121154
546.000000000007,59.961919046035135,-0.5136211079826954,-2.912869444926274