File: 01_Data/CPVC_Pipe/STA/N2/10K_min/CPVC_Pipe_STA_N2_10KData_221024_R1.csv
##Temp./Â°C,Time/min,DSC/(mW/mg),Mass loss/mg
51.0,10.672906223080041,-1.6931049327357408,-0.005502230481986281
52.100000000000016,11.072262860980866,-1.5900753486356152,-0.0052580657547665055
53.20000000000003,11.346265815098478,-1.5171719755127988,-0.007207830363411105
54.30000000000005,11.554871283330309,-1.468497623475458,-0.005141620290817883
55.40000000000006,11.745598484291236,-1.4270074054575734,-0.007266048537434955
56.50000000000008,11.917789619236492,-1.394200180170638,-0.007196249534037413
57.600000000000094,12.080929032049083,-1.3684313924697669,-0.0066422902108733695
58.70000000000011,12.237680469187008,-1.3447109937756836,-0.006238057191441548
59.800000000000125,12.387956316415817,-1.3262765501166536,-0.006516745894324494
60.90000000000014,12.532310915025834,-1.3095979356062344,-0.006726275286255579
62.000000000000156,12.676987134980111,-1.29384490482978,-0.006797071254912801
63.10000000000017,12.815220653352915,-1.2801145157494613,-0.005109140925632971
64.20000000000019,12.954034537644633,-1.2676955402244539,-0.006448842605569105
65.30000000000021,13.087009742686968,-1.2554802649886894,-0.005364085413732234
66.40000000000022,13.221877906739591,-1.2449881511826264,-0.006698206099225779
67.50000000000023,13.352507388206538,-1.2338488213581846,-0.008311319199306944
68.60000000000025,13.482149149915664,-1.2238258078581334,-0.0067628348458823595
69.70000000000027,13.610862881197882,-1.2130620209557241,-0.008111893250096536
70.80000000000028,13.737326888943755,-1.2037922436485773,-0.00811918499027442
71.90000000000029,13.862091306021776,-1.193889284696872,-0.008220527353204332
73.00000000000031,13.98650598254297,-1.185261069613366,-0.006639225381683822
74.10000000000034,14.109581433955134,-1.1755433479561157,-0.007077528482652973
75.20000000000034,14.233137195565064,-1.1674298639607095,-0.006930047504590142
76.30000000000035,14.354577165326734,-1.1597344164843286,-0.008122623017356112
77.40000000000038,14.47550348072123,-1.1556172546588523,-0.008114338365018625
78.5000000000004,14.594604217183822,-1.1502704329103985,-0.007216113761608689
79.6000000000004,14.713523198411295,-1.1459425994525443,-0.009529779835204089
80.70000000000041,14.832959107205964,-1.1408314794457013,-0.009238853758880339
81.80000000000044,14.951386977236888,-1.1354473277948864,-0.00877740493117507
82.90000000000046,15.06767803651658,-1.1293851339012806,-0.00868172779755394
84.00000000000047,15.184576257490553,-1.1230812067802285,-0.009271827647232556
85.10000000000048,15.296239542131278,-1.1164969357647165,-0.008544266390182464
86.2000000000005,15.413880332817099,-1.1090520747434076,-0.009880110705593914
87.30000000000052,15.529402820078985,-1.1022095833634502,-0.009860715421403654
88.40000000000053,15.643572651798301,-1.0961041318333198,-0.008871807833470413
89.50000000000054,15.75617712610862,-1.0895580125063313,-0.009521010304336386
90.60000000000056,15.869005331800086,-1.084235311700542,-0.0092806984878262
91.70000000000059,15.980962521429657,-1.0772716623727507,-0.00857206024393875
92.8000000000006,16.093716949185314,-1.072197247197111,-0.008572542163099328
93.9000000000006,16.20533699963068,-1.0667277857995985,-0.009881403776286213
95.00000000000063,16.316735818858987,-1.0605935279633525,-0.009884975214905722
96.10000000000065,16.427449144463502,-1.0533991320826988,-0.00987133538050955
97.20000000000066,16.53676136578464,-1.047411069510341,-0.009869044416131345
98.30000000000067,16.64759781569478,-1.042149605580765,-0.009878352220900055
99.40000000000069,16.75755260758158,-1.036759604722542,-0.009879850074398178
100.50000000000071,16.866978455993962,-1.0302584429338926,-0.01016976591755725
101.60000000000072,16.976397848678065,-1.025096655724174,-0.009857795712560957
102.70000000000073,17.083726695668314,-1.0203130572534922,-0.009870198161070043
103.80000000000075,17.195464243328132,-1.014605048156065,-0.01119724365697472
104.90000000000077,17.303757651871617,-1.0086238176415674,-0.00980491347108714
106.00000000000078,17.41241098287905,-1.0028350549183862,-0.010635284686508761
107.10000000000079,17.519799797558427,-0.9989457723221966,-0.012208649620640166
108.20000000000081,17.6275638905392,-0.9941252326948523,-0.01117053300970916
109.30000000000084,17.736667651374304,-0.9876141739471377,-0.01119836672476282
110.40000000000084,17.844731842454127,-0.9831068035164264,-0.011480525115576512
111.50000000000085,17.95222809874751,-0.9752367088129916,-0.012535452196615005
112.60000000000088,18.060090545189237,-0.9725993004973095,-0.011189785110478745
113.7000000000009,18.167106983504247,-0.9654573733297092,-0.011285226237534474
114.8000000000009,18.275114355027494,-0.9627502587978498,-0.012499999087625113
115.90000000000092,18.382244889054125,-0.9558971568886631,-0.013801576455417575
117.00000000000094,18.490000000000094,-0.950379999999996,-0.012509844007975168
118.10000000000096,18.59705975116662,-0.9447975947209039,-0.011189976963506432
119.20000000000097,18.703888340016512,-0.939186024199207,-0.011120913990615655
120.30000000000098,18.81176937554312,-0.9318277146071547,-0.012510962357664468
121.400000000001,18.918078560992996,-0.9272654003427251,-0.01224780257104019
122.50000000000102,19.02538386542559,-0.9210015074723471,-0.013881993429170514
123.60000000000103,19.13116048981256,-0.9152198606762312,-0.013829950095073151
124.70000000000104,19.237797625124674,-0.9088742839582031,-0.013830065768289934
125.80000000000106,19.342683362841782,-0.9044719632518221,-0.013186054746505249
126.90000000000109,19.45148646407255,-0.9004669176862116,-0.013165373916812939
128.00000000000108,19.556623806722712,-0.8949475986810083,-0.013162115318599454
129.1000000000011,19.663663336483047,-0.8900553384813928,-0.013819947951291489
130.20000000000113,19.769131431926045,-0.8864525216674412,-0.01323108865970024
131.30000000000115,19.875431356219185,-0.8830396915789342,-0.013830249447670973
132.40000000000117,19.98187270258841,-0.877320090446164,-0.013825803899406353
133.50000000000117,20.089193494435033,-0.873664454714086,-0.013169888347099423
134.6000000000012,20.194366989756695,-0.8710374347025222,-0.014489889894486296
135.7000000000012,20.29981275323922,-0.8659690709787529,-0.015799746839042506
136.8000000000012,20.405368113351756,-0.8632852478071887,-0.015587644497877307
137.90000000000123,20.511759909645647,-0.8596834571828331,-0.014379578414715155
139.00000000000125,20.616526670763193,-0.8548254600459163,-0.014480151801003593
140.10000000000127,20.721688490577545,-0.8524970084766248,-0.015110129274642503
141.2000000000013,20.82701950886343,-0.8486029568256142,-0.01448969089502139
142.3000000000013,20.93253531110928,-0.8450918584439172,-0.01581034799201575
143.4000000000013,21.038781445507997,-0.8421664299267058,-0.015807136870423122
144.50000000000134,21.14212868356978,-0.8397084087707714,-0.015800130799011214
145.60000000000133,21.244743669190537,-0.837160280879786,-0.01580018250140469
146.70000000000135,21.351760326870615,-0.832189448551308,-0.017120082947483795
147.80000000000138,21.457908146320484,-0.8286324394856674,-0.017070797574878505
148.9000000000014,21.56307013167734,-0.8253501433642342,-0.017168443023124702
150.00000000000142,21.664807761474627,-0.8225669687776557,-0.017119607298296202
151.10000000000142,21.772080017293188,-0.8179567173754902,-0.01712133786029657
152.20000000000144,21.877773162458624,-0.8141193983674185,-0.0184354114812999
153.30000000000146,21.981482286751888,-0.8125406203724994,-0.01711979969413857
154.40000000000146,22.086883629773386,-0.807460879097705,-0.017119798558258736
155.50000000000148,22.19153034007402,-0.8037441858221126,-0.01614045931069974
156.6000000000015,22.29526207595595,-0.8005053754258972,-0.01745003586462346
157.70000000000152,22.400575278102743,-0.7978277501593879,-0.01797516066572058
158.80000000000155,22.504450196438317,-0.7927992555965261,-0.019406876570259968
159.90000000000154,22.609710101942436,-0.7912634371856067,-0.016690129481520266
161.00000000000156,22.714901922707448,-0.7871960118179607,-0.01799424363916824
162.1000000000016,22.818445729603653,-0.7849529181456841,-0.0190622141929655
163.20000000000158,22.922699226248106,-0.7813496742395035,-0.017991084804207524
164.3000000000016,23.02683972265673,-0.7778096679138685,-0.017987833982179957
165.40000000000163,23.13014951689002,-0.7752289175600215,-0.01931019944701351
166.50000000000165,23.237288954945218,-0.771777183632995,-0.01983130182647752
167.60000000000167,23.341090364615628,-0.7692973532796434,-0.018951540436296987
168.70000000000167,23.44572710535842,-0.7661146556974586,-0.01931945131244106
169.8000000000017,23.54990745418616,-0.7633408693375174,-0.020971219859834633
170.9000000000017,23.653112089835123,-0.7595799636057531,-0.022014843570129727
172.0000000000017,23.758716659778198,-0.7575350213932143,-0.02374669274943031
173.10000000000173,23.862730691035473,-0.7543865366305098,-0.020744044194633382
174.20000000000175,23.96792821825282,-0.7509979954251537,-0.02206923810421202
175.30000000000177,24.072315801771552,-0.7481685904971095,-0.022273282557606855
176.4000000000018,24.17630226219055,-0.7467548914022519,-0.022060087343882095
177.5000000000018,24.27901781075166,-0.7439597106610217,-0.024717945186667478
178.6000000000018,24.385062931977764,-0.7402126311892816,-0.023273560458998865
179.70000000000184,24.489617845576166,-0.7387625375886671,-0.023380087997884935
180.80000000000183,24.594982002818046,-0.7379730279958662,-0.023393349287731624
181.90000000000185,24.698800448914064,-0.7348858824158336,-0.024700083495444503
183.00000000000188,24.80391447186382,-0.7311941512778566,-0.026087011537421212
184.1000000000019,24.907748836653166,-0.729102611496484,-0.025226563647991362
185.20000000000192,25.01326373155004,-0.7285680530311865,-0.024716477676083315
186.30000000000192,25.116558164505797,-0.7270427244699943,-0.027329662308446245
187.40000000000194,25.221067821910978,-0.7233554106001309,-0.027330088145260945
188.50000000000196,25.325301290600343,-0.7213368745508737,-0.027800011106954514
189.60000000000196,25.429272388200076,-0.7190093338360932,-0.028649865343349568
190.70000000000198,25.5339535740435,-0.7164626835781948,-0.027873435726364804
191.800000000002,25.63593766831157,-0.7146758113028591,-0.029309952041572274
192.90000000000202,25.743020231630304,-0.7118036726660205,-0.029309808653063207
194.00000000000205,25.847388520519672,-0.7088781817640429,-0.030687160976384575
195.10000000000204,25.952284362547854,-0.7048735909212328,-0.02996057016799103
196.20000000000206,26.055700157326253,-0.7042685501709217,-0.03127877145519342
197.3000000000021,26.159490865232566,-0.7016740575737227,-0.029960220976559704
198.40000000000208,26.265157435883506,-0.6984439673722541,-0.032599821968040565
199.5000000000021,26.367964278295595,-0.6973071271507878,-0.031279728490563485
200.60000000000213,26.471978395425136,-0.6948128869140677,-0.0339002500157628
201.70000000000215,26.57448198131443,-0.6933165060780253,-0.03259529278119633
202.80000000000217,26.680762567833277,-0.6901193516088007,-0.033920478121467035
203.90000000000217,26.784714816539832,-0.6870248616467365,-0.03294411798956798
205.0000000000022,26.88947985982995,-0.6849937031976953,-0.03424368638542852
206.1000000000022,26.994037442924082,-0.6832763283345648,-0.03423989790693671
207.2000000000022,27.098782283732962,-0.6804729497587089,-0.0355599028479574
208.30000000000223,27.20144906451591,-0.6775131273891987,-0.03687915810905551
209.40000000000225,27.305854605086612,-0.6765686500258961,-0.038182578509666776
210.50000000000227,27.40970038964683,-0.6730644273187888,-0.038200156185496326
211.6000000000023,27.515142865422224,-0.67179692295028,-0.03820016289031347
212.7000000000023,27.61826907679876,-0.6698969978082852,-0.03885293831553849
213.8000000000023,27.72365064338717,-0.6684877211728748,-0.040601736037796154
214.90000000000234,27.827946378868365,-0.6674491166416592,-0.04074666687723827
216.00000000000233,27.93205903316474,-0.6651419607683214,-0.04247329098725938
217.10000000000235,28.03699623928537,-0.6633349277257763,-0.043139887834706236
218.20000000000238,28.140744316310876,-0.6602924421898794,-0.042808582946639806
219.3000000000024,28.245796170985905,-0.6583484949041001,-0.04374657285999728
220.40000000000242,28.351240957577172,-0.6563520123326416,-0.04484319661623459
221.50000000000242,28.454992745148015,-0.6546415368617653,-0.04610067916309735
222.60000000000244,28.559230330621354,-0.6526134180703955,-0.04610006410252332
223.70000000000246,28.663106801538323,-0.6494675032941558,-0.0466159712512324
224.80000000000246,28.76752539073096,-0.6467543682309017,-0.04873994872612064
225.90000000000248,28.87269197240636,-0.6438115236273062,-0.04873991477152728
227.0000000000025,28.97719802005322,-0.6425173068646339,-0.05005851157094732
228.10000000000252,29.081969749607612,-0.6401983299730626,-0.051068404358357355
229.20000000000255,29.185069946579592,-0.6384066686233809,-0.05235637338401533
230.30000000000254,29.28964940824861,-0.6353302782638752,-0.054012119598552566
231.40000000000256,29.393033533411312,-0.6343361692884574,-0.056011078367273814
232.5000000000026,29.49796105050455,-0.6315671929530619,-0.05712441464722229
233.60000000000258,29.602695383020368,-0.629400056522573,-0.05948510288202291
234.7000000000026,29.708099341258816,-0.6275186785056163,-0.06190962157425517
235.80000000000263,29.811543549296644,-0.6256804377270111,-0.06323057855111358
236.90000000000265,29.916941896503115,-0.6229726134232381,-0.06457943067998073
238.00000000000267,30.021125047856582,-0.62194431225988,-0.0659374204733445
239.10000000000267,30.125063556982553,-0.6183825709628601,-0.06822755343559583
240.2000000000027,30.22961063749355,-0.6165249655735804,-0.07113845979872613
241.3000000000027,30.334810330954245,-0.6149057103623552,-0.07244964235109252
242.4000000000027,30.439148233714448,-0.6129265078416537,-0.0739841636366072
243.50000000000273,30.543374577976017,-0.610485702844851,-0.07905088903072466
244.60000000000275,30.648606784255023,-0.610855358082368,-0.08030199670691118
245.70000000000277,30.75310903152114,-0.6108126566237442,-0.08294997729059972
246.8000000000028,30.85693676394144,-0.6094984115870096,-0.08636571127372772
247.9000000000028,30.962663736370295,-0.6084028442771411,-0.08851116891037236
249.0000000000028,31.066574148715805,-0.6077802054352878,-0.09094561925195155
250.10000000000284,31.170758741022908,-0.6061124125150852,-0.09227908794101047
251.20000000000283,31.276304414201448,-0.6024329994583034,-0.09485861122963435
252.30000000000285,31.380000000000262,-0.5933199999999925,-0.09879987599183293
253.40000000000288,31.484829666929926,-0.5864660635917002,-0.10011958519189301
254.5000000000029,31.590603127867507,-0.577878594217148,-0.10181326255920409
255.60000000000292,31.694389093190704,-0.5713140319810897,-0.10406916738627059
256.7000000000029,31.799219299480725,-0.5668264576970917,-0.10538996908956788
257.8000000000029,31.903805890507357,-0.5622768854908606,-0.10810077512535221
258.90000000000293,32.00915944980694,-0.5561908053430289,-0.11208146292480237
260.00000000000296,32.11338910345519,-0.5508615983401807,-0.11472008200172112
261.100000000003,32.21884712553159,-0.5462579624277661,-0.11604644486026361
262.200000000003,32.32328981260796,-0.5392523896065275,-0.12015295857845576
263.300000000003,32.42799458178211,-0.5349685027824775,-0.12434386689843935
264.40000000000305,32.53251006679679,-0.5287609229340716,-0.12701514025564764
265.50000000000307,32.637878394972155,-0.5233097023125719,-0.12964151419825765
266.6000000000031,32.74206683711833,-0.5169454306082119,-0.13416474245494747
267.7000000000031,32.846750071119246,-0.5120382008941631,-0.13839347620030162
268.8000000000031,32.9510005955221,-0.5032880663569045,-0.1441650139775379
269.9000000000031,33.05612998493027,-0.4978485375708082,-0.14917020223053123
271.0000000000031,33.16240762960614,-0.49039352085884474,-0.15523798882643547
272.10000000000315,33.26740653526621,-0.4829581299896677,-0.15962295826822803
273.2000000000032,33.37224699649069,-0.4777790997904281,-0.16815972549116642
274.30000000000314,33.477114839275075,-0.47167238658468624,-0.17433998175563392
275.40000000000316,33.58303639910505,-0.4644311315072832,-0.18091390941961238
276.5000000000032,33.6876012173624,-0.45779868326915996,-0.1907930513278311
277.6000000000032,33.792366552820596,-0.44973409954493476,-0.19962350059787726
278.70000000000323,33.89843392126597,-0.44353223562121113,-0.20605149564481628
279.80000000000325,34.00272080893276,-0.4348083339078057,-0.21605036772895314
280.9000000000033,34.10759022249548,-0.4275325998874971,-0.22801106563650286
282.0000000000033,34.21244024423947,-0.42008821754548115,-0.24026403586090606
283.1000000000033,34.317287877884745,-0.41149182149017943,-0.25158421492829586
284.20000000000334,34.42305319369869,-0.4058982026270131,-0.26589364436438334
285.30000000000337,34.52827259743533,-0.39622100046251524,-0.28130126842409453
286.40000000000333,34.63357021072632,-0.39022107179680504,-0.29710706633675166
287.50000000000335,34.73857393000192,-0.38365747847194615,-0.3132646486224431
288.6000000000034,34.843524981182256,-0.37726074183857716,-0.3309574863261249
289.7000000000034,34.94832121232553,-0.3710686978924479,-0.3497659214525193
290.8000000000034,35.0534633740315,-0.3646060834755848,-0.3706745944372605
291.9000000000034,35.15795290731031,-0.3588226021056953,-0.3923367258331427
293.0000000000034,35.263860423457615,-0.35447488573020397,-0.41719766707118744
294.10000000000343,35.368960478928614,-0.35014121083086835,-0.4426173117449177
295.20000000000346,35.473686950053114,-0.3464954328059935,-0.4684833582431258
296.3000000000035,35.57940283050426,-0.3444476301737459,-0.4975681777124472
297.4000000000035,35.685427146938494,-0.3422676951460897,-0.5293767829057221
298.5000000000035,35.79025752891946,-0.3416115500036021,-0.5608507929196791
299.60000000000355,35.89584476658141,-0.34109903515963935,-0.5936474711151205
300.70000000000357,36.000758726593816,-0.3412865726762214,-0.6290695549134715
301.8000000000036,36.10665798400523,-0.34230050799417816,-0.6672510213226941
302.9000000000036,36.21313768455045,-0.3451627648105661,-0.707687328864679
304.0000000000036,36.31800450081488,-0.3472570100588128,-0.7493037874145987
305.1000000000036,36.423056031729715,-0.35134322679474234,-0.7929742339960413
306.2000000000036,36.52870564122566,-0.3566767592229127,-0.8388414095623986
307.30000000000365,36.63356507442777,-0.3618321590959736,-0.8876356509843744
308.4000000000037,36.73941913929302,-0.3671381483292041,-0.9363276678076882
309.5000000000037,36.844309182616875,-0.3727042830088217,-0.9892501585108966
310.60000000000366,36.94944323358157,-0.3831705161588279,-1.0447277674407842
311.7000000000037,37.05543007853478,-0.39201910295202635,-1.0991229678399925
312.8000000000037,37.16135431089252,-0.39917520334972717,-1.1583676310283177
313.90000000000373,37.26660040219633,-0.4033325526228931,-1.2187243220941757
315.00000000000375,37.36968634802283,-0.41292018896511745,-1.278020340506263
316.1000000000038,37.47628599472269,-0.42578444733437104,-1.3414911025225207
317.2000000000038,37.582107794506506,-0.4387665137358647,-1.4055352913775612
318.3000000000038,37.688008082107395,-0.4505562923934614,-1.4677378077826653
319.40000000000384,37.792884843287304,-0.4642867385152041,-1.5325235669916522
320.5000000000038,37.899493670405285,-0.477989265314821,-1.5952738887915054
321.60000000000383,38.005123132302465,-0.49352501415288963,-1.6574934126687788
322.70000000000385,38.109999091261805,-0.5075997930763432,-1.7152493459185223
323.8000000000039,38.21496287574986,-0.5221417498054757,-1.7683417951042766
324.9000000000039,38.32144091272727,-0.5363417599250492,-1.8258347177435859
326.0000000000039,38.42743931442481,-0.5499093957122874,-1.8761255048389653
327.10000000000394,38.53268498377096,-0.560755122739867,-1.9193122009457828
328.2000000000039,38.63990488669643,-0.5706363444010477,-1.961349634888082
329.30000000000393,38.74523937919678,-0.5799989208186583,-2.0013148436381054
330.40000000000396,38.8511953470068,-0.5870857391787466,-2.0370660674328063
331.500000000004,38.95658049807302,-0.595020047202667,-2.0707427867043218
332.600000000004,39.062399390490626,-0.600541512277873,-2.100355838509888
333.700000000004,39.168623666905866,-0.6041223635751862,-2.1265619821327317
334.80000000000405,39.27449900399352,-0.6076499812950188,-2.151465223662856
335.90000000000407,39.379778355989416,-0.6108604267168075,-2.174739516601387
337.0000000000041,39.4860048895707,-0.6155040874360012,-2.195661755868847
338.10000000000406,39.59211579410888,-0.6198144865411451,-2.2168848026831
339.2000000000041,39.69722426825166,-0.6236770072008494,-2.2356738238479084
340.3000000000041,39.80413941482497,-0.6289746342392867,-2.2505842635006834
341.4000000000041,39.91082921389557,-0.6340864817975438,-2.2697836942399183
342.50000000000415,40.016276478782785,-0.6399804835806707,-2.283237897185753
343.6000000000042,40.122657404245444,-0.644593578661828,-2.296910513177366
344.7000000000042,40.22937161152858,-0.6487897557131649,-2.3102076931720794
345.80000000000416,40.33255886361868,-0.6538326512334741,-2.321996870215082
346.9000000000042,40.4418179587667,-0.657978308667916,-2.3342501047136945
348.0000000000042,40.54790978314256,-0.6610305094992818,-2.344907288111054
349.10000000000423,40.6534874502923,-0.6650706780626408,-2.3562162599143734
350.20000000000425,40.75929943478488,-0.6682695171534438,-2.365192268407963
351.3000000000043,40.866060116405286,-0.6709597729544748,-2.373240199888774
352.4000000000043,40.97237419122794,-0.6731017008593442,-2.3829198382585575
353.5000000000043,41.07942612985204,-0.6753287413628923,-2.391989076640021
354.60000000000434,41.185583222005,-0.6780906022944941,-2.399679268815188
355.7000000000043,41.29220824139752,-0.6812282887882122,-2.406939018825675
356.80000000000433,41.39772568853671,-0.6827151809400905,-2.413517259717677
357.90000000000435,41.50489003341085,-0.6858928552588439,-2.4203385729602322
359.0000000000044,41.61158061604554,-0.6868234219687329,-2.4259093829745275
360.1000000000044,41.71569544397738,-0.6885491146707731,-2.42978652086297
361.2000000000044,41.824283562359234,-0.6898348644993648,-2.436943603415422
362.30000000000445,41.93000089136722,-0.689170103988788,-2.4421239289877477
363.4000000000044,42.0370121660561,-0.6895839414280718,-2.447345809992342
364.50000000000443,42.144456683778536,-0.6900285453210696,-2.4540554915932384
365.60000000000446,42.250217352868646,-0.6907172097257241,-2.458704085532532
366.7000000000045,42.358046051645935,-0.6894518726694839,-2.463003844841274
367.8000000000045,42.46355070090022,-0.6902087587292491,-2.465811260029863
368.9000000000045,42.56980423584473,-0.6894962552149935,-2.469774171787467
370.00000000000455,42.67614855110527,-0.6896908079652203,-2.4751534271205755
371.10000000000457,42.78380629779932,-0.6900536660663422,-2.4780845438684747
372.2000000000046,42.89041117377547,-0.6874467727650169,-2.482075243818212
373.30000000000456,42.99651206285499,-0.6856788050716798,-2.486226954036764
374.4000000000046,43.10367701382661,-0.6837627777823119,-2.4894822369266345
375.5000000000046,43.209109387666246,-0.6822975822679076,-2.492676054381465
376.6000000000046,43.316906055747005,-0.6804654055782937,-2.4951690191529714
377.70000000000465,43.423308715930716,-0.6790468926944755,-2.498442571573196
378.8000000000047,43.53048998084571,-0.6783448914712605,-2.5010763130134386
379.9000000000047,43.63491546117022,-0.6781957289030487,-2.5054134371733414
381.00000000000466,43.74453487226202,-0.67797915249103,-2.5092535622468444
382.1000000000047,43.85034755748599,-0.6768495133537381,-2.512159745596042
383.2000000000047,43.95729812774582,-0.6768515274134506,-2.514774610742514
384.30000000000473,44.063904957784025,-0.6754184428945119,-2.5173236040719456
385.40000000000475,44.170263425621435,-0.6740414884893827,-2.5195212378035015
386.5000000000048,44.27748961121513,-0.6739790972191135,-2.5221802731552065
387.6000000000048,44.38423848390902,-0.6727071841305249,-2.5252684006159796
388.7000000000048,44.49088164673325,-0.6728760148942421,-2.5288477270925176
389.80000000000484,44.59748284798488,-0.6729877947968771,-2.5301776956670796
390.9000000000048,44.70380363724107,-0.6716330033368899,-2.5314422916719157
392.00000000000483,44.81165206038983,-0.672976660160068,-2.5355515342273445
393.10000000000485,44.918004599465775,-0.6717973081707413,-2.5382120517434648
394.2000000000049,45.02568161489903,-0.6718248820799217,-2.5410657089311384
395.3000000000049,45.132481992643775,-0.6717690744645743,-2.543495550969546
396.4000000000049,45.24019150222456,-0.6719760918169201,-2.5449946164925366
397.50000000000495,45.345372577853176,-0.6737802640826975,-2.5488324070551016
398.6000000000049,45.453587347280724,-0.6720950595721795,-2.550563530799284
399.70000000000493,45.56039172013076,-0.67489454879364,-2.5528901005776823
400.80000000000496,45.667834968163646,-0.6744658461611872,-2.554981984891752
401.900000000005,45.77549936848687,-0.6750627660293328,-2.5581387937828497
403.000000000005,45.882540222508844,-0.6756659782185702,-2.5608552730923853
404.100000000005,45.9895463389741,-0.6754418159296269,-2.56232687681619
405.20000000000505,46.09703304041566,-0.6748380524517519,-2.5658810951933293
406.30000000000507,46.20429538325809,-0.6754954933491473,-2.5662087342768594
407.4000000000051,46.31239247319257,-0.6755509929042945,-2.570238528477772
408.50000000000506,46.41948349579797,-0.675779221038053,-2.5718470852390416
409.6000000000051,46.52729893091656,-0.6760075110130002,-2.5741996634189968
410.7000000000051,46.634980281358544,-0.6764455803828033,-2.5768189561050945
411.8000000000051,46.74199378889478,-0.6763648786502261,-2.5781371748444597
412.90000000000515,46.849209063981434,-0.6763496959974208,-2.5807191268917666
414.0000000000052,46.95667857229695,-0.6761145894489569,-2.58248352214371
415.1000000000052,47.06421365657849,-0.6764942246482024,-2.58472392830749
416.20000000000516,47.17148951696252,-0.6784638031452169,-2.587444309636258
417.3000000000052,47.27850722398834,-0.6780578727716524,-2.5886589911625872
418.4000000000052,47.385646696564244,-0.6784901652029854,-2.5902798830363287
419.50000000000523,47.49290150073829,-0.679789764396492,-2.5916487022830714
420.60000000000525,47.600856873867,-0.6785869487305843,-2.5942531568729343
421.7000000000053,47.707996972324224,-0.6800883106843468,-2.596005108425354
422.8000000000053,47.81512606743233,-0.6814483999061843,-2.5986770130290444
423.9000000000053,47.922780965767224,-0.6820561331368243,-2.5999971695070148
425.00000000000534,48.030203706623674,-0.682011325291707,-2.602627175169956
426.1000000000053,48.137074891990345,-0.6825173622262319,-2.6052529752153175
427.20000000000533,48.245161963270796,-0.6831474044107954,-2.608093404736951
428.30000000000535,48.35049454489935,-0.6826634096572197,-2.610630778353188
429.4000000000054,48.46082441359965,-0.6835639446407482,-2.6119514919621745
430.5000000000054,48.567252442214915,-0.6850241742791835,-2.614390476432985
431.6000000000054,48.675071102103814,-0.6852050931704103,-2.61597215615548
432.70000000000545,48.78292697855772,-0.6856209373618435,-2.6185854319553847
433.8000000000054,48.89062853490168,-0.685967994139871,-2.6198628642482293
434.90000000000543,48.998710030362844,-0.6856206606419274,-2.6224991755736156
436.00000000000546,49.10380025538442,-0.6857681040982406,-2.6239952896926253
437.1000000000055,49.21389232821346,-0.6862482724190208,-2.6282159436075587
438.2000000000055,49.32238605607857,-0.684461346984161,-2.6298143049539395
439.3000000000055,49.42952511718229,-0.6852286558179761,-2.6328905828180855
440.40000000000555,49.53817218749427,-0.6843063034881621,-2.634947333249027
441.50000000000557,49.645479836214044,-0.6836745265578628,-2.6368789918999145
442.6000000000056,49.75360821871891,-0.6821044204331693,-2.6391356989026225
443.70000000000556,49.86119409400244,-0.6839119926537807,-2.6422024274300977
444.8000000000056,49.96902491376717,-0.6832635450347037,-2.645706488053735
445.9000000000056,50.07667601234781,-0.6829493169946199,-2.647739861825698
447.0000000000056,50.1849846423133,-0.6803990379806825,-2.648526874175486
448.10000000000565,50.29307966911494,-0.6799865126891294,-2.652641737055161
449.2000000000057,50.40019644998224,-0.6786265730097915,-2.6553138003386167
450.3000000000057,50.5082180668359,-0.6770959132531502,-2.656613775442828
451.40000000000566,50.615763113308084,-0.6755074379759461,-2.6613071008952103
452.5000000000057,50.72434572130702,-0.6716066535484063,-2.6636417418107254
453.6000000000057,50.83194233441083,-0.6715659337732099,-2.666884408465571
454.70000000000573,50.938797405610586,-0.6704023732725686,-2.6699096857054996
455.80000000000575,51.047917865795554,-0.6694195172937453,-2.671249199904751
456.9000000000058,51.155916511016606,-0.6662107097609578,-2.675979489550733
458.0000000000058,51.26365391654931,-0.6639208719184575,-2.6794943782066722
459.1000000000058,51.372135109739936,-0.6611095661148094,-2.682403885267336
460.20000000000584,51.480700367952885,-0.6582109476392936,-2.687935545962984
461.3000000000058,51.587232284236514,-0.6561802812339073,-2.6912719616028564
462.40000000000583,51.69675001426122,-0.6547795135108361,-2.693935425836345
463.50000000000585,51.80393703556227,-0.652484885174551,-2.696823343001233
464.6000000000059,51.91306708841787,-0.6498871851250834,-2.70094922264842
465.7000000000059,52.01923582358742,-0.6465660110099273,-2.7037374032572306
466.8000000000059,52.12843857083628,-0.6446505525923345,-2.708112014793621
467.90000000000595,52.23771602934446,-0.643697336180662,-2.712177202400265
469.0000000000059,52.34591264384928,-0.6427327977259281,-2.7150205054605854
470.10000000000593,52.453899274461534,-0.6400479152002511,-2.7177051166889235
471.20000000000596,52.56305715870048,-0.6380992060704253,-2.7240632203819977
472.300000000006,52.67148561859945,-0.6388003620696752,-2.7260223129155214
473.400000000006,52.77990044010277,-0.6386310995455725,-2.728077950989326
474.500000000006,52.88779770502348,-0.6382750543146674,-2.7318353956138357
475.60000000000605,52.99608878367194,-0.6406671205766772,-2.7358497655566567
476.70000000000607,53.10494987796038,-0.6396775214893909,-2.738736973725398
477.8000000000061,53.21380425281799,-0.6383896112197868,-2.7420513643619455
478.90000000000606,53.322973997465546,-0.6362711316104427,-2.74497310912897
480.0000000000061,53.43088792253998,-0.6365980085049114,-2.7474367142740856
481.1000000000061,53.53955241530708,-0.6375374973728417,-2.7515111408149835
482.2000000000061,53.64691547211426,-0.6361371236320185,-2.752799460691612
483.30000000000615,53.75727639504878,-0.6364289964778558,-2.755560325866899
484.4000000000062,53.86475926150579,-0.6376986726964743,-2.7600893247277805
485.5000000000062,53.97397609150941,-0.637669517212174,-2.762714465296453
486.60000000000616,54.080328372405724,-0.6367345457076532,-2.764135226983559
487.7000000000062,54.19070378476971,-0.6380053884257868,-2.766742339539654
488.8000000000062,54.29924984129382,-0.6387793845169797,-2.769378190872451
489.90000000000623,54.40740767776438,-0.6380910517663283,-2.7708296237770065
491.00000000000625,54.514880472639156,-0.6357591643870799,-2.773920374457317
492.1000000000063,54.62296724662774,-0.6376988241064065,-2.7782347123734725
493.2000000000063,54.73353515411073,-0.639217581771985,-2.779219353719545
494.3000000000063,54.841874272696955,-0.6375396811124023,-2.7805908446042107
495.40000000000634,54.949213574835696,-0.637266626834473,-2.7824084458524014
496.5000000000063,55.05862814269601,-0.6385825647084524,-2.785843604138991
497.60000000000633,55.167076853343865,-0.6373351889275087,-2.7871799842284557
498.70000000000636,55.274402528662286,-0.6374968935317324,-2.789804599237671
499.8000000000064,55.38409881783478,-0.638886506105852,-2.7925446035848642
500.9000000000064,55.49268788991382,-0.6393957192572093,-2.793773516346697
502.0000000000064,55.60047694854965,-0.639508197139959,-2.7963927277950154
503.10000000000645,55.70945015584691,-0.6392097966731035,-2.7990014672681163
504.2000000000064,55.81895913369525,-0.6396727713042691,-2.801579242763411
505.30000000000643,55.927192902201924,-0.6403061000394398,-2.8030119180828588
506.40000000000646,56.03634469483265,-0.6390753398677661,-2.803962290647589
507.5000000000065,56.1445306618151,-0.6387416275742608,-2.804606169305658
508.6000000000065,56.252587366726395,-0.6385065394340587,-2.806081237058346
509.7000000000065,56.36243107649547,-0.6399010808185257,-2.807148507788827
510.80000000000655,56.471558345091495,-0.639101027297479,-2.810950870358651
511.90000000000657,56.58010110529178,-0.6384235096750259,-2.810878661210186
513.0000000000066,56.68932255390282,-0.6377276487591781,-2.8121863039490993
514.1000000000065,56.79673462579012,-0.6379671395840105,-2.8158074062749154
515.2000000000066,56.906109305159625,-0.6382495055448539,-2.8165224668812945
516.3000000000065,57.015375155609526,-0.6380406741520229,-2.8178937328044946
517.4000000000067,57.12402482677166,-0.6391078871038123,-2.8205376638770887
518.5000000000066,57.23334309717538,-0.6382573215278357,-2.821632012431702
519.6000000000067,57.34221962739404,-0.6394840556107201,-2.8225128143436553
520.7000000000066,57.45154568265004,-0.6384160518198069,-2.823830628219296
521.8000000000067,57.55926208908073,-0.6383896588633133,-2.8238520247170675
522.9000000000067,57.67010675421627,-0.6387574387000529,-2.826469272266607
524.0000000000067,57.777303144992764,-0.637760750451411,-2.828457709305928
525.1000000000067,57.887710860560865,-0.638068088399763,-2.8304200090990816
526.2000000000068,57.99600012147436,-0.637930047005106,-2.830759372056765
527.3000000000068,58.10599170929397,-0.6380639928842063,-2.832095164371783
528.4000000000068,58.21303006152719,-0.6369466874121986,-2.834708510258227
529.5000000000068,58.322472541622325,-0.6370885550022273,-2.8360298892633162
530.6000000000068,58.43107951303038,-0.6369072385188257,-2.8373443826459495
531.7000000000069,58.54181923150328,-0.6366128081317116,-2.8386631667487943
532.8000000000068,58.64932755869461,-0.6363900768895477,-2.8386724193018598
533.9000000000069,58.76019265732175,-0.6350231889004048,-2.842272708704628
535.0000000000068,58.86853972923773,-0.6366669481319709,-2.843600722659713
536.100000000007,58.979157958556456,-0.6359097435949075,-2.8449242086400846
537.2000000000069,59.08796673340559,-0.6358398453397536,-2.8455780575458736
538.300000000007,59.197470448917535,-0.6339032848046766,-2.8462298067373633
539.4000000000069,59.30622817594803,-0.634330901152055,-2.8475437033631916
540.5000000000069,59.41561146420847,-0.6341912812381414,-2.850269801273358
541.600000000007,59.52430532086349,-0.6319789489539104,-2.8501077594425155
542.700000000007,59.63324869234634,-0.6316749012537693,-2.850882723903762
543.800000000007,59.742399132118855,-0.6316705170073927,-2.8522585426148654
544.900000000007,59.852304198309156,-0.6312214399718931,-2.853487027753676
546.000000000007,59.96103331144896,-0.6307056529342194,-2.855792400455881
547.1000000000071,60.07040051558023,-0.6300180952281783,-2.8577158451857456
548.2000000000071,60.18054505006614,-0.6322975579196611,-2.8571000119491403
549.300000000007,60.28855200523876,-0.6317986087582772,-2.858439096753205
550.4000000000071,60.39838734204191,-0.6300305072202106,-2.8597398737917574
551.500000000007,60.507698238236024,-0.6293426698144211,-2.8602507919368385
552.6000000000072,60.616213959964625,-0.6306721911270327,-2.8609774273129176
553.7000000000071,60.7257123912259,-0.6291108885878538,-2.863695419815161
554.8000000000072,60.835158757760304,-0.6286024261766109,-2.8650098780543094
555.9000000000071,60.94333512638526,-0.6292684812176141,-2.8663233323269917
557.0000000000072,61.053832616559575,-0.6286089823929574,-2.8649948667418514
558.1000000000072,61.16390318809881,-0.6282868895469846,-2.86797055292889
559.2000000000072,61.27288671392504,-0.625842642355425,-2.868865249963468
560.3000000000072,61.382228281819835,-0.6254419500526994,-2.870434804890986
561.4000000000073,61.4920809376709,-0.6253559905454732,-2.870579151547891
562.5000000000073,61.60196686423831,-0.6227651274057914,-2.8706727083504724
563.6000000000073,61.71054544146343,-0.6223652458343659,-2.8729098734021887
564.7000000000073,61.82151924360838,-0.6211607450420258,-2.8732953350192996
565.8000000000073,61.93059640868871,-0.6207351048255767,-2.8745504191399656
566.9000000000074,62.04009395347909,-0.6194262440908203,-2.8758699018285343
568.0000000000074,62.148345041959324,-0.6201050385357613,-2.877228889891328
569.1000000000074,62.25958219657258,-0.6180306018973297,-2.878509954280445
570.2000000000073,62.368892143384805,-0.6187535386999655,-2.878500034230858
571.3000000000073,62.4785518621806,-0.6190771471293637,-2.879819898083341
572.4000000000074,62.5876729481016,-0.6181559964955219,-2.8797325905728135
573.5000000000074,62.69518344542834,-0.6166414570353604,-2.8811393959477893
574.6000000000074,62.80596234991335,-0.6156234385150425,-2.8824598914320925
575.7000000000074,62.91525086421922,-0.6160925501438571,-2.882459889759903
576.8000000000075,63.02564573769365,-0.6159143085689651,-2.8837682763180714
577.9000000000075,63.13439646946565,-0.6134702484209692,-2.88508905582376
579.0000000000075,63.24358239625683,-0.6117868576857173,-2.8841180321610462
580.1000000000075,63.35195784522222,-0.6108127102902251,-2.885163934844176
581.2000000000075,63.46222368547187,-0.6109126353803236,-2.886338896966718
582.3000000000076,63.57289396150258,-0.6102084146324552,-2.8864199330230003
583.4000000000076,63.68161420340981,-0.6093618800008636,-2.888525493134476
584.5000000000076,63.79151260059306,-0.6072224993823845,-2.8890501000591
585.6000000000076,63.90055131250573,-0.6086498729683358,-2.8890501001957754
586.7000000000077,64.00989792014536,-0.6091424801264382,-2.890040818840162
587.8000000000077,64.11951458727663,-0.6075031860972266,-2.8903455021765705
588.9000000000076,64.2295913200671,-0.6068413658540144,-2.8916802084082414
590.0000000000076,64.33901969491033,-0.6052392182854922,-2.8920099946511244
591.1000000000076,64.44825451566787,-0.6005591853907895,-2.8920074999884773
592.2000000000077,64.55813004171884,-0.5988776907847414,-2.893329883648459
593.3000000000077,64.6678646076259,-0.596804545472166,-2.893813339611198
594.4000000000077,64.77828766665247,-0.5958046514983186,-2.8953106432136986
595.5000000000077,64.88811148178954,-0.5928558722411813,-2.8963057210065815
596.6000000000078,64.99641011630042,-0.5894916179314217,-2.896598083973024
597.7000000000078,65.1069573912634,-0.588485698050518,-2.897940189110324
598.8000000000078,65.21752622969812,-0.586158942460969,-2.896904231006358
599.9000000000078,65.32441374370859,-0.5850815605338893,-2.8966375542803116
601.0000000000078,65.43743224846274,-0.5823220036735547,-2.8979400538869156
602.1000000000079,65.54693064076419,-0.5806011651289508,-2.8979400686020345
603.2000000000079,65.65690830229309,-0.5787845427528285,-2.8992602902045963
604.3000000000079,65.7650985724315,-0.5762233117297727,-2.8992599222932363
605.4000000000078,65.8770250926979,-0.5738197989001403,-2.899289202943832
606.5000000000078,65.98592712922557,-0.57055820283533,-2.8999290466449033
607.6000000000079,66.09663162193033,-0.56671457497848,-2.901230259142813
608.7000000000079,66.20644076415451,-0.5665920639029124,-2.9012299639999073
609.8000000000079,66.31558308263712,-0.5653531360325774,-2.901229762709703
610.9000000000079,66.42646649982265,-0.5635865729068924,-2.9008996504665125
612.000000000008,66.53604420508383,-0.5641524501961007,-2.901979366027379
613.100000000008,66.64617530525928,-0.5626732216979078,-2.9018908723247794
614.200000000008,66.75616341055145,-0.5610282597820265,-2.9032100428622796
615.300000000008,66.86668361759942,-0.5627105636893487,-2.9045544347623604
616.400000000008,66.9762855311276,-0.56339077300552,-2.904519549453246
617.5000000000081,67.08606887463635,-0.5632820884321164,-2.9051872606596527
618.6000000000081,67.19734380028771,-0.5644237913791679,-2.90386779988709
619.7000000000081,67.30411213227609,-0.5651773553336523,-2.904519463162499
620.8000000000081,67.41518299123258,-0.5664557692080916,-2.905843545583698
621.9000000000082,67.52304002656378,-0.5632118631443004,-2.9048604821937687
623.0000000000082,67.63447748044813,-0.5642426602599572,-2.9048600131438223
624.1000000000081,67.74502992746409,-0.5641635426849145,-2.9058365241753075
625.2000000000081,67.855181152393,-0.5644957542926544,-2.906829804437651
626.3000000000081,67.96385325833263,-0.5628223585293582,-2.907132861336545
627.4000000000082,68.07440555007574,-0.5646337898380885,-2.907489461798014
628.5000000000082,68.18398656335197,-0.5649021883197042,-2.9071600446986885
629.6000000000082,68.2933465201125,-0.5656718180969755,-2.9071607013150187
630.7000000000082,68.40310871979199,-0.5668804512809211,-2.9084798686983144
631.8000000000083,68.5122707173092,-0.5666388198626692,-2.907158189061376
632.9000000000083,68.62310580328257,-0.5661841408842179,-2.907159920000934
634.0000000000083,68.73161803789834,-0.5663424799302262,-2.9071599200230094
635.1000000000083,68.84313507439104,-0.5660245877282428,-2.9070910664513048
636.2000000000083,68.95287947319437,-0.5650407451351662,-2.907820965912584
637.3000000000084,69.06341501078421,-0.5652512602952269,-2.9081806413645763
638.4000000000084,69.17250047930398,-0.5668743834136372,-2.9022877629698596
639.5000000000084,69.28341365572257,-0.5688812260463341,-2.9038798889334725
640.6000000000083,69.39157854897428,-0.5674181174324496,-2.9058870724912387
641.7000000000083,69.50362307007893,-0.5681302849835126,-2.914078151987085
642.8000000000084,69.61234689171714,-0.5672147765751661,-2.9146211753602014
643.9000000000084,69.72258158630954,-0.5667506431055065,-2.9118660041387217
645.0000000000084,69.83296575435041,-0.5675201047061161,-2.9118679494210875
646.1000000000084,69.94296436085777,-0.5673596971240538,-2.910990632858293
647.2000000000085,70.05268082708095,-0.5675978965941386,-2.911550006904024
648.3000000000085,70.16179599544137,-0.5695790735831354,-2.911518636204172
649.4000000000085,70.27147670472111,-0.5687577498541566,-2.912546075452869
650.5000000000085,70.38315975623351,-0.5682395419213092,-2.9099027929387375
651.6000000000085,70.49176398483009,-0.5674676232820008,-2.9122435873504533
652.7000000000086,70.6027991273942,-0.5698098800046588,-2.91090004073685
653.8000000000086,70.71287366835365,-0.5694336423599716,-2.9122088783023274
654.9000000000086,70.82311270716497,-0.56926633421179,-2.9122101878669646
656.0000000000086,70.93277153654554,-0.5701784183733417,-2.9109141296386314
657.1000000000087,71.04412518139713,-0.570221556179639,-2.910900471668226
658.2000000000087,71.15513715445903,-0.5702341740100425,-2.9122098702470693
659.3000000000086,71.26579218701984,-0.5702264654412684,-2.9122098724383427
660.4000000000086,71.37586252688277,-0.5716886130185992,-2.9131712597088226
661.5000000000086,71.48626084613227,-0.5698634503591455,-2.911867014402344
662.6000000000087,71.59670971815382,-0.5733797048508392,-2.912232534216818
663.7000000000087,71.70740208870849,-0.5714129051519623,-2.9134134885695877
664.8000000000087,71.8176703895408,-0.5686653804365562,-2.9125487260500904
665.9000000000087,71.92743487020255,-0.569808587173228,-2.9088300782935708
667.0000000000088,72.04000000000097,-0.5703700000001384,-2.9114389403127197
668.1000000000088,72.14872795894809,-0.5705576756275026,-2.9172411131330236
669.2000000000088,72.25962381694276,-0.5726315977140668,-2.9131835402330553
670.3000000000088,72.36948114300402,-0.5730372730109028,-2.913211520286751
671.4000000000088,72.47958112206918,-0.5755245429226975,-2.913494903920767
672.5000000000089,72.58966526776794,-0.5748025293667625,-2.9142029358596444
673.6000000000089,72.69968909450287,-0.5757468081289597,-2.9141923875642908
674.7000000000089,72.81116841497986,-0.5748095760239543,-2.915510107513356
675.8000000000088,72.92064776750941,-0.5780182908546783,-2.916843614364751
676.9000000000088,73.03110116127556,-0.5776308152432312,-2.915479985397062
678.0000000000089,73.14180535307366,-0.57890058652507,-2.914928825675922
679.1000000000089,73.25189114873942,-0.5797683514681282,-2.917184589041506
680.2000000000089,73.3625234625667,-0.5801584160764034,-2.915497702773198
681.3000000000089,73.47305817159277,-0.5817284344125504,-2.915499828000442
682.400000000009,73.58372021681271,-0.5817637608704589,-2.9154998262447274
683.500000000009,73.69389961407016,-0.5812409158513333,-2.9168206275651754
684.600000000009,73.80585622327922,-0.5805774339963438,-2.9168194779559604
685.700000000009,73.91700413680924,-0.5834921612019707,-2.9164900243777927
686.800000000009,74.02701556048804,-0.5845527994824157,-2.9164901697539145
687.9000000000091,74.13745266325473,-0.5834485461642147,-2.9161599579923347
689.0000000000091,74.24891344585791,-0.5846661563519424,-2.917479753680327
690.1000000000091,74.35875288022051,-0.5850364872892898,-2.9174739565127745
691.2000000000091,74.47021252617708,-0.5885237020236903,-2.9187898533039185
692.3000000000092,74.57991837955022,-0.5881058317691844,-2.918789871999998
693.4000000000092,74.69151357249483,-0.5896176199845925,-2.918789962494949
694.5000000000091,74.80106169210588,-0.5881606640369071,-2.9201105330100363
695.6000000000091,74.91277404782498,-0.5899205956077602,-2.9194500006310693
696.7000000000091,75.02260254857825,-0.5922627469170115,-2.9194351400109566
697.8000000000092,75.1335090501376,-0.5925966957601124,-2.919458423530773
698.9000000000092,75.24375241706701,-0.5925189309667538,-2.918101179139909
700.0000000000092,75.35391928381071,-0.5954353307241754,-2.919470944037124
701.1000000000092,75.46431654460967,-0.5959418589853201,-2.920119566101067
702.2000000000093,75.57448398418887,-0.5950356154704431,-2.9214315776681983
703.3000000000093,75.68443652256919,-0.5975208976134448,-2.921109997293507
704.4000000000093,75.79476248677526,-0.5978558397171362,-2.9224191754575166
705.5000000000093,75.9054178995048,-0.5984524348834018,-2.9210329086224833
706.6000000000093,76.01623942333067,-0.6007071603676897,-2.9224187821810004
707.7000000000094,76.12609824410666,-0.6001841937690789,-2.922435616114771
708.8000000000094,76.23714341099982,-0.6011177751963819,-2.923605344424712
709.9000000000094,76.34708896967554,-0.6029919930509308,-2.9237398560622587
711.0000000000093,76.4574767650166,-0.6053205716364027,-2.923752833951614
712.1000000000093,76.56894365305715,-0.6065458169999774,-2.923743941391619
713.2000000000094,76.67877719529324,-0.6098630972980709,-2.922420125654674
714.3000000000094,76.7894008537084,-0.6097352941558356,-2.9224209945175015
715.4000000000094,76.90053480406368,-0.6119485176570201,-2.923080099021981
716.5000000000094,77.01134047672228,-0.6147782361886839,-2.9244018642507266
717.6000000000095,77.12127206291649,-0.6136052240249529,-2.922089549203757
718.7000000000095,77.23342012917087,-0.6150096238434891,-2.9237019210265904
719.8000000000095,77.34276228561606,-0.6195462653359098,-2.924390260604233
720.9000000000095,77.45363303974531,-0.6186554586516902,-2.9230799329496073
722.0000000000095,77.56421380936757,-0.6171723730661884,-2.9243895591665936
723.1000000000096,77.67370527670964,-0.6159462786366089,-2.9243998344595763
724.2000000000096,77.78447083771295,-0.6154269622598008,-2.924401009520351
725.3000000000096,77.89610210980649,-0.6172197279407133,-2.925079973141706
726.4000000000096,78.00591478936536,-0.6150758425641153,-2.9263698713695243
727.5000000000097,78.1169937968986,-0.6148674777818358,-2.926369871033184
728.6000000000097,78.22737599501215,-0.6126511498818387,-2.9250501893796015
729.7000000000096,78.33756138327792,-0.6114888937726859,-2.9271248667970022
730.8000000000096,78.44859245569795,-0.6110960090828956,-2.92636671128302
731.9000000000096,78.55916197439221,-0.609962653373138,-2.928676827374309
733.0000000000097,78.66926852248565,-0.6104533407995589,-2.9273615453860344
734.1000000000097,78.78103909526645,-0.6106798025621625,-2.9273600119669503
735.2000000000097,78.89149762299813,-0.6124070244795965,-2.9274621004250494
736.3000000000097,79.00244719783994,-0.6133350843732315,-2.9273605547991033
737.4000000000098,79.11291344026021,-0.6165524870809881,-2.929992262832748
738.5000000000098,79.22427312163973,-0.6130459086339323,-2.9299537484991336
739.6000000000098,79.33537433910898,-0.6119484219253382,-2.927361485109728
740.7000000000098,79.44565098987026,-0.612821097011052,-2.928044886969669
741.8000000000098,79.55635497871606,-0.612285595513668,-2.9280199200105073
742.9000000000099,79.66749643667008,-0.611887927777692,-2.9280202189294613
744.0000000000099,79.77762275006302,-0.6137215179021456,-2.930660506223735
745.1000000000099,79.88970050351067,-0.614476515790592,-2.9300002762324975
746.0000000000099,79.97939021714356,-0.611879433221983,-2.9300001919993