File: 01_Data/EIFS_XPS/STA/N2/3K_min/EIFS_XPS_STA_N2_3KData_230905_R1.csv
##Temp./Â°C,Time/min,DSC/(mW/mg),Mass loss/mg
41.0,11.275087737617202,-2.302901548403423,-0.00528558310317262
42.100000000000016,11.82447657331183,-2.2754207165193887,-0.006693633925982656
43.20000000000003,12.311679740428422,-2.2601242365161363,-0.006476680067823981
44.30000000000005,12.749048985239707,-2.24958413519775,-0.005445053545277467
45.40000000000006,13.16460705254341,-2.242321064744881,-0.005995553771926065
46.50000000000008,13.573635631811767,-2.2363608563967055,-0.004919637387557962
47.600000000000094,13.974451145556221,-2.2301115204033843,-0.0063008024804931395
48.70000000000011,14.374366415143268,-2.2256427046365665,-0.0052692942463949954
49.800000000000125,14.760089413621698,-2.2211154251236924,-0.004879550419012002
50.90000000000014,15.149360979721296,-2.21542118522805,-0.0052700001015595355
52.000000000000156,15.52917000000008,-2.212689999999998,-0.006590015963853446
53.10000000000017,15.89893094592526,-2.208650293314513,-0.006149954470080932
54.20000000000019,16.22778211492954,-2.2019050680407632,-0.004832375757001017
55.3000000000002,16.665712811904456,-2.201581983869174,-0.006462431803362367
56.40000000000022,17.042769571202655,-2.198668084566389,-0.007138942462222797
57.500000000000234,17.41339116752148,-2.196254710516048,-0.005809718123967134
58.60000000000025,17.790084967957288,-2.191435172229945,-0.005489999999980011
59.700000000000266,18.152507000192223,-2.1876760589935573,-0.0044926585151952025
60.80000000000028,18.526666861652085,-2.184494973671171,-0.0061499974216183695
61.9000000000003,18.89349283383168,-2.1826619436890953,-0.005779538509679938
63.00000000000031,19.271270376546866,-2.179134797997565,-0.005502412883874097
64.10000000000034,19.63951856368815,-2.176105694104673,-0.005160046356833092
65.20000000000034,20.00326234526101,-2.1719822366068207,-0.005127046878806496
66.30000000000035,20.372506218379936,-2.168564279700961,-0.007159189393170173
67.40000000000038,20.72983552953276,-2.165050890043042,-0.004500012918959406
68.5000000000004,21.103681945887413,-2.161970437118505,-0.00434671801829456
69.6000000000004,21.477325296411294,-2.1603225125406538,-0.004728879936729324
70.70000000000041,21.847919572792197,-2.156720780915608,-0.006192409494347295
71.80000000000044,22.206153261206673,-2.15381136229041,-0.004720074079298531
72.90000000000046,22.57829582928367,-2.1507708873334135,-0.005381038038363872
74.00000000000047,22.94266544038731,-2.1477374187970573,-0.00603999999796212
75.10000000000048,23.30479202384136,-2.1436139596451174,-0.005275171895092523
76.2000000000005,23.676328830618864,-2.138598841137417,-0.006919662147988337
77.30000000000052,24.039170000000155,-2.133900000000011,-0.006590000000009422
78.40000000000053,24.408834605926437,-2.128971708398671,-0.005236056066068695
79.50000000000054,24.771902414909835,-2.1251577659241776,-0.007908945353474639
80.60000000000056,25.13666081806445,-2.121935618909429,-0.00527003345201571
81.70000000000059,25.499466503860877,-2.1190678039606996,-0.006590000608647006
82.8000000000006,25.865368454784985,-2.1149922158775083,-0.007909999955313829
83.9000000000006,26.233695278718216,-2.1128112128481726,-0.007799747331147078
85.00000000000063,26.597374367638643,-2.1106673923684967,-0.006149952757163568
86.10000000000065,26.967043869081646,-2.1079432032024963,-0.005166483050912607
87.20000000000066,27.325461848505114,-2.1054428168734742,-0.007460004136603082
88.30000000000067,27.691930222649425,-2.101529724342359,-0.007799995414376593
89.40000000000069,28.0576988967574,-2.1003229916844806,-0.00746999158161854
90.50000000000071,28.42500266057462,-2.098863473277241,-0.0078048838284550115
91.60000000000072,28.790158390246198,-2.096839390599603,-0.006479611538865004
92.70000000000073,29.15109913865172,-2.0961487263974727,-0.007470000496725415
93.80000000000075,29.515063432130862,-2.0956876267028823,-0.006480000124004626
94.90000000000077,29.878012904227358,-2.0961468770736955,-0.006809999481554918
96.00000000000078,30.254564006163026,-2.1012336864094423,-0.008128748344649495
97.10000000000079,30.595613800399292,-2.1042751077632786,-0.009736812739871592
98.20000000000081,30.971061253625376,-2.108586953555918,-0.009770001236959036
99.30000000000084,31.342191257549725,-2.111640119129849,-0.00992740381785806
100.40000000000084,31.704351124362958,-2.1141590508008834,-0.012117818856177909
101.50000000000085,32.06917000000029,-2.1135299999999946,-0.009442234763043622
102.60000000000088,32.42661399191055,-2.1114178255882092,-0.012049236910596672
103.7000000000009,32.78986503113418,-2.1077681747851242,-0.013730016652691912
104.8000000000009,33.15659045601972,-2.1025529123921527,-0.014053484846738407
105.90000000000092,33.51277852789832,-2.0944481410798366,-0.014708244425597705
107.00000000000094,33.87545715791197,-2.0859322439048142,-0.01570004187098517
108.10000000000096,34.23560932737236,-2.077611669089491,-0.015822497040026917
109.20000000000097,34.59287506793774,-2.071773494906284,-0.014835636146491638
110.30000000000098,34.954839130739124,-2.068195797608009,-0.015966541948492452
111.400000000001,35.31221947605533,-2.0645018078857547,-0.017011483087472357
112.50000000000102,35.66892914046632,-2.0607119767682605,-0.015734682623391283
113.60000000000103,36.03343518853489,-2.053902900896553,-0.014720010158959074
114.70000000000104,36.39332554220039,-2.051665108262165,-0.015369901050202195
115.80000000000106,36.74940009513062,-2.0467921422445365,-0.016689926148553802
116.90000000000109,37.1129198699692,-2.043185185301484,-0.015370010064625461
118.0000000000011,37.486005494152685,-2.0400755448342034,-0.016697091032947142
119.1000000000011,37.83217543827705,-2.0377349575204224,-0.016360006919511783
120.20000000000113,38.19397540498877,-2.035470519281205,-0.0158388199467554
121.30000000000115,38.557828622750655,-2.033076030694473,-0.016040729923392227
122.40000000000116,38.9149206720744,-2.0302545090399575,-0.017791079304438906
123.50000000000117,39.27623950787129,-2.0276603582830237,-0.015150000323373103
124.60000000000119,39.638434771864816,-2.0246137393076045,-0.013804637254906105
125.70000000000121,40.00022819983651,-2.0208886028174233,-0.013509417870792628
126.80000000000122,40.35838811270692,-2.022088869951267,-0.01532594616827776
127.90000000000123,40.723247794262754,-2.0166588977791546,-0.014819850479952823
129.00000000000125,41.083064863029755,-2.0155166350931113,-0.01481997081632569
130.10000000000127,41.44048699614981,-2.011820773496183,-0.016260152591724086
131.2000000000013,41.794604140506635,-2.0101538556431255,-0.013176963633009908
132.3000000000013,42.1584266054312,-2.0075734432841155,-0.014911620281988114
133.4000000000013,42.51917422420995,-2.006870022053516,-0.015920003280835537
134.50000000000134,42.876661135900704,-2.004024890807176,-0.013264554262849781
135.60000000000133,43.23368697908855,-2.0012320527853382,-0.014836376460998224
136.70000000000135,43.59317262989787,-1.9989298796932538,-0.015589984629682974
137.80000000000138,43.95293013419557,-1.9968855004910555,-0.014592436446748902
138.9000000000014,44.31354096505069,-1.9950712576010108,-0.014270000278509443
140.00000000000142,44.666765570593725,-1.9922622376182186,-0.01625078482949549
141.10000000000142,45.02647970974321,-1.990058668089941,-0.013940037182933018
142.20000000000144,45.379009028366745,-1.9885535519868225,-0.015258230641534531
143.30000000000146,45.74057658534903,-1.98563492039156,-0.014045096006381819
144.40000000000146,46.099884449192245,-1.9832305476398173,-0.01504003636657858
145.50000000000148,46.45389947624631,-1.9806287945686611,-0.015370547963196923
146.6000000000015,46.81464043846579,-1.9796118128047182,-0.015912942092763505
147.70000000000152,47.16755647122172,-1.9769049250777262,-0.015299170234571946
148.80000000000155,47.52580488676033,-1.9755129142951504,-0.015377461641843837
149.90000000000154,47.89054867682654,-1.9721490822487886,-0.018094893248661315
151.00000000000156,48.24626897065376,-1.9702516525121994,-0.016645841432397113
152.1000000000016,48.60967733479135,-1.9680100776430158,-0.015479967470036993
153.20000000000158,48.96285770974976,-1.9671097575503291,-0.0165781284866231
154.3000000000016,49.32254314107828,-1.9639061087706637,-0.01821999993654133
155.40000000000163,49.67264247523732,-1.9616490731053402,-0.01756000037176131
156.50000000000165,50.0304263564609,-1.958635910726431,-0.018337846659910895
157.60000000000167,50.39490986581608,-1.9570474891003877,-0.01891263322330694
158.70000000000167,50.758308604645194,-1.9546029781743033,-0.016184020241036823
159.8000000000017,51.116681658004644,-1.9546086622821053,-0.018712988368285277
160.9000000000017,51.470822144871605,-1.953354410197882,-0.017459710886934765
162.0000000000017,51.82315263391548,-1.949989154226265,-0.019109909347065912
163.10000000000173,52.18783745524267,-1.947543126411615,-0.020099995072286436
164.20000000000175,52.538161027890425,-1.9465841844599117,-0.018120630233247947
165.30000000000177,52.900498135398365,-1.9435183429783565,-0.01910982157916008
166.4000000000018,53.254514955218035,-1.9431158443382184,-0.020430026100158205
167.5000000000018,53.61653128311557,-1.941796785627687,-0.02074999441564085
168.6000000000018,53.968860678197345,-1.9395982489263495,-0.019535707592728713
169.70000000000184,54.32204151600715,-1.9391006491787373,-0.02075272117186433
170.80000000000183,54.6854986118128,-1.9376108845226774,-0.019547767197676258
171.90000000000185,55.039710013920676,-1.9347994295637805,-0.020859999990833433
173.00000000000188,55.399534678875625,-1.9325408815708986,-0.023956744480516434
174.1000000000019,55.7591668725738,-1.9314398828383184,-0.021080084519747633
175.20000000000192,56.11634341079049,-1.9278680862635023,-0.019989583120194165
176.30000000000192,56.476497418859765,-1.9265708421815504,-0.020969999996227173
177.40000000000194,56.82988842634547,-1.9264257679006564,-0.019641889503372756
178.50000000000196,57.18951976898103,-1.9257381216027203,-0.02089557847635426
179.60000000000196,57.54305918568216,-1.9240652842397554,-0.02260346353267728
180.70000000000198,57.90128594289666,-1.923270087192552,-0.02374501250188965
181.800000000002,58.2467329567456,-1.922066317380388,-0.021476570027005426
182.90000000000202,58.61009574719813,-1.9202781501374933,-0.02261998196377446
184.00000000000205,58.972743328117836,-1.9184565709257837,-0.023279583049132135
185.10000000000204,59.33109877823268,-1.9181394990637872,-0.02295000179250284
186.20000000000206,59.68917000000073,-1.917700000000003,-0.023059926113651485
187.3000000000021,60.04327706857832,-1.9148385705278044,-0.023601700505085255
188.40000000000208,60.39395635747029,-1.9138446604887858,-0.022949997059026117
189.5000000000021,60.75886318524282,-1.9128978061958302,-0.0225927516005906
190.60000000000213,61.1109023306426,-1.9113651824846158,-0.024269999999893432
191.70000000000215,61.47105111162741,-1.9101362095817467,-0.023379548072985035
192.80000000000217,61.82643213773574,-1.9089597476272493,-0.023939997491412512
193.90000000000217,62.188466787227966,-1.9079265097859535,-0.024920000000000275
195.0000000000022,62.54079036531071,-1.9062465481169373,-0.02492000000000205
196.1000000000022,62.88915840295028,-1.9055004408601692,-0.025260036855999424
197.2000000000022,63.257887435468504,-1.905454878914573,-0.023542148298015597
198.30000000000223,63.60806309918327,-1.9006887389636011,-0.024269967170289508
199.40000000000225,63.962238437092466,-1.899432657329466,-0.024270000014008364
200.50000000000227,64.31783662296525,-1.8982672439121273,-0.02623996557648134
201.6000000000023,64.67505112956297,-1.8975857796370927,-0.026900248895708412
202.7000000000023,65.03062689525491,-1.8957924510151336,-0.026567750005645152
203.8000000000023,65.38151570654796,-1.89638300610738,-0.02550574237796699
204.90000000000234,65.74917653161846,-1.8941197103242908,-0.025589908616900914
206.00000000000233,66.10320420142253,-1.894209314279661,-0.025580000000000158
207.10000000000235,66.45484178242774,-1.892044977894638,-0.02690010433520884
208.20000000000238,66.80188039049602,-1.8897208885588748,-0.026900002268336554
209.3000000000024,67.16052765929956,-1.8888014550437058,-0.028543965874113564
210.40000000000242,67.52299613527617,-1.8883262945932777,-0.02855000280878839
211.50000000000242,67.8787420257175,-1.887937608115168,-0.026245466700646425
212.60000000000244,68.23061423299714,-1.8851891384490782,-0.027560001105546572
213.70000000000246,68.59051454967681,-1.884431689798245,-0.028534981639906754
214.80000000000246,68.95516923600077,-1.8834669190618052,-0.0288357068436631
215.90000000000248,69.31005491024233,-1.8820792365699661,-0.02788737025207988
217.0000000000025,69.6654155541418,-1.8803181601960262,-0.027889998633006563
218.10000000000252,70.01996672611287,-1.878513726002298,-0.030271366654589738
219.20000000000255,70.37033009975777,-1.877138963906212,-0.028202796867201396
220.30000000000254,70.73258301959419,-1.8750638177375223,-0.029869113384322077
221.40000000000256,71.08121626887603,-1.8779313026144557,-0.030199692070822515
222.5000000000026,71.43725034335935,-1.8731457023314404,-0.02888000533939561
223.60000000000258,71.7942335194633,-1.8725200418813384,-0.02888000116353684
224.7000000000026,72.14917000000177,-1.8704099999999755,-0.02953510471582943
225.80000000000263,72.50547347925531,-1.8708818470701065,-0.031178019807966084
226.90000000000265,72.86039246272853,-1.8688540879848299,-0.03050779896403455
228.00000000000267,73.21733273966103,-1.868840917582468,-0.029870100082995066
229.10000000000267,73.56916759252417,-1.8687499584857374,-0.029539999984284915
230.2000000000027,73.93312593060358,-1.868192794726498,-0.03106755886084489
231.3000000000027,74.27636495312694,-1.8689910089268444,-0.031180000012208886
232.4000000000027,74.64390377397946,-1.865160199833432,-0.0311431970467968
233.50000000000273,75.00022539938485,-1.8640620995196406,-0.03085426938129876
234.60000000000275,75.35257275267873,-1.8637452477649685,-0.032182814681270155
235.70000000000277,75.71870226507377,-1.8637484780691356,-0.0324782103552721
236.8000000000028,76.07260907499341,-1.8635693887725686,-0.032500000466018975
237.9000000000028,76.42735670075278,-1.8616953929571187,-0.03084147091173106
239.0000000000028,76.78679502860818,-1.8621451083162328,-0.032830000008657656
240.10000000000284,77.14420517676056,-1.8626662565348853,-0.03316952429683262
241.20000000000283,77.50216336376155,-1.8607733397383035,-0.033159999999999634
242.30000000000285,77.85332385429854,-1.8602466778531044,-0.03174315264363381
243.40000000000288,78.21425054954835,-1.859406712430263,-0.03151000011755167
244.5000000000029,78.56980383540754,-1.8592554142272382,-0.03347999416069891
245.60000000000292,78.92498726310345,-1.8583839863388847,-0.03463007693928377
246.70000000000292,79.28199711384464,-1.8566765539409025,-0.034139999691316536
247.80000000000294,79.63704964232613,-1.8542913376885872,-0.03191103720201216
248.90000000000296,79.98956448133598,-1.8550362013950858,-0.033149689121785286
250.00000000000296,80.34997421513907,-1.8544377923403774,-0.03280291868430396
251.10000000000298,80.70628252076945,-1.8545521535469267,-0.03380999997385237
252.200000000003,81.06492551936232,-1.8549426328393506,-0.03299946431169065
253.30000000000302,81.42054015167177,-1.8549986790977089,-0.03510887383984196
254.40000000000305,81.77447953167365,-1.8532314191919785,-0.03447000000026179
255.50000000000304,82.13259941068007,-1.8538899731584273,-0.03545999278703027
256.6000000000031,82.48426605145379,-1.85429549386011,-0.03577224849527427
257.7000000000031,82.83848190519015,-1.8531888868365156,-0.03606829678870582
258.8000000000031,83.19674757917124,-1.8525754166254416,-0.03611985453594091
259.9000000000031,83.55603676665599,-1.8536380571963993,-0.037440000034962395
261.0000000000031,83.90839638429276,-1.85152628621431,-0.03678253265101272
262.10000000000315,84.26855185147669,-1.8512261699638308,-0.03709903102048129
263.2000000000032,84.6204932411676,-1.849728800863289,-0.035789999522434
264.30000000000314,84.97964128458209,-1.8506196765262,-0.03600984696024767
265.40000000000316,85.33002402473024,-1.8505208805107864,-0.03864261698136495
266.5000000000032,85.69319972743455,-1.8503729649481298,-0.03863999188410583
267.6000000000032,86.05128064626598,-1.85022843666651,-0.03864015005601873
268.70000000000323,86.40982156711036,-1.8506416603278455,-0.03831005597728465
269.80000000000325,86.76761899118874,-1.8514574778065886,-0.03995990046632203
270.9000000000033,87.12447590496336,-1.8519618541410277,-0.04006898858824126
272.0000000000033,87.48668963946196,-1.8499725065699932,-0.03896961548619027
273.1000000000033,87.844195954916,-1.8497897599756512,-0.03961531084593073
274.20000000000334,88.19645144291799,-1.849767083817106,-0.04128004916983352
275.30000000000337,88.55355370609222,-1.8497549383135679,-0.040290029017715945
276.40000000000333,88.90868748201733,-1.8488459013762542,-0.03995993900176753
277.50000000000335,89.2666347460331,-1.8484235152339226,-0.04260307490988158
278.6000000000034,89.62487264624833,-1.8497005836832114,-0.04523075213060679
279.7000000000034,89.98357488544318,-1.8497418591994832,-0.04257020730354899
280.8000000000034,90.33975418803874,-1.850864826606118,-0.0432500000000009
281.9000000000034,90.69609559715501,-1.850497335509996,-0.04355213146821768
283.0000000000034,91.05385904830953,-1.850364192945259,-0.04457104269616208
284.10000000000343,91.4115403618238,-1.851281694666675,-0.046210357123980916
285.20000000000346,91.7619233305792,-1.8501267436441415,-0.04622254358218303
286.3000000000035,92.12022601826267,-1.8505220474294821,-0.046882953796823834
287.4000000000035,92.48528937524196,-1.8492336045620779,-0.04605397804920841
288.5000000000035,92.84674853120289,-1.8498736434397545,-0.0481960727976154
289.60000000000355,93.20285081888531,-1.850933285379952,-0.049006012221946005
290.70000000000357,93.56090867914307,-1.849149390108124,-0.04981381080704628
291.8000000000036,93.91865603370455,-1.8488736744164562,-0.049506978466942186
292.9000000000036,94.27478432815592,-1.850492773851938,-0.05215516255556496
294.0000000000036,94.62766832279533,-1.8517887013367782,-0.05313998955464161
295.1000000000036,94.98916565048594,-1.8493299259262272,-0.051930066188302426
296.2000000000036,95.34760035637197,-1.8511937499258577,-0.051929995398247275
297.30000000000365,95.70744906882432,-1.8512335615129576,-0.05358952990604404
298.4000000000037,96.06917564624435,-1.8514399705477989,-0.05522377368298281
299.5000000000037,96.4241082369671,-1.8517743669813718,-0.055990620583289186
300.60000000000366,96.78290829001926,-1.8529770710916347,-0.055879675497405135
301.7000000000037,97.13873397243903,-1.8523934987687105,-0.05587999997276727
302.8000000000037,97.50261022786545,-1.85309640062511,-0.05819007127659637
303.90000000000373,97.86123822785808,-1.8526049549447683,-0.05783213147485533
305.00000000000375,98.20971512868759,-1.8525967874066644,-0.06119355574547347
306.1000000000038,98.57749465202109,-1.8520752090321086,-0.06247144857795206
307.2000000000038,98.93659590608625,-1.8534937491190042,-0.0631313866584593
308.3000000000038,99.28917468437419,-1.853460059439801,-0.06268928916921679
309.40000000000384,99.64754730745149,-1.8538366366639598,-0.0636803884919348
310.5000000000038,100.00746954008684,-1.8559729451042124,-0.06630999999994858
311.60000000000383,100.36604789391531,-1.8556082634341309,-0.06750234611004835
312.70000000000385,100.72285111330164,-1.8557973369054506,-0.06775359554466265
313.8000000000039,101.08243468290233,-1.8572572685146538,-0.06817976639798795
314.9000000000039,101.4411429296024,-1.8588860047062619,-0.06949193609711912
316.0000000000039,101.79979944920841,-1.860868968121657,-0.07080999999980264
317.10000000000394,102.15985662388252,-1.8612066198861932,-0.07311977348138399
318.2000000000039,102.51539290080478,-1.8613497585741257,-0.07746414177217575
319.30000000000393,102.87307533468231,-1.8632151273910373,-0.07739105317828665
320.40000000000396,103.23530607817645,-1.8643653899445272,-0.07866455065131861
321.500000000004,103.59129982180369,-1.8643320177844689,-0.08082137339829165
322.600000000004,103.95483738411126,-1.8640631934287517,-0.08378055944315355
323.700000000004,104.31199264144023,-1.8645520862846954,-0.08370014886452681
324.80000000000405,104.6712683458436,-1.8656960000021663,-0.08540995757444136
325.90000000000407,105.03220381690362,-1.867870088467035,-0.08892092996954926
327.0000000000041,105.39203012157378,-1.8693361196092955,-0.09035493546813322
328.10000000000406,105.75020888236644,-1.869144462082083,-0.09178005678808487
329.2000000000041,106.11194169835487,-1.8701440279266968,-0.09463321728747376
330.3000000000041,106.46955741353187,-1.8722242342270174,-0.09661000234026451
331.4000000000041,106.81385262157806,-1.875323359318866,-0.10183791409727849
332.50000000000415,107.18514881262321,-1.874237221136279,-0.1038529412696807
333.6000000000042,107.54461526957294,-1.875394826935204,-0.10582999885603028
334.7000000000042,107.90702775149879,-1.8790834644017091,-0.11019323713062246
335.80000000000416,108.26274792862367,-1.8805628938536472,-0.11237287745248192
336.9000000000042,108.621607038041,-1.8811838505022753,-0.11374373953425732
338.0000000000042,108.97950575305715,-1.8842102416043558,-0.11998704299914653
339.10000000000423,109.335246778528,-1.886521809277137,-0.12126051384865111
340.20000000000425,109.70212601449204,-1.8882154309662629,-0.1259252881911168
341.3000000000043,110.06488673715079,-1.8905169531480874,-0.12987015531504298
342.4000000000043,110.42980734187456,-1.8944236938637562,-0.13448015832977767
343.5000000000043,110.79364906976193,-1.8989350180384004,-0.13977675137042844
344.60000000000434,111.15041850640743,-1.900197620836605,-0.14548411871597855
345.7000000000043,111.51410408909666,-1.9047391341866802,-0.15105843640272898
346.80000000000433,111.86857875973965,-1.9107379157740327,-0.15590804834326866
347.90000000000435,112.23260246034039,-1.913224197883965,-0.16158776821725818
349.0000000000044,112.59075184027868,-1.9171626553310621,-0.16947928457520423
350.1000000000044,112.95464781570087,-1.9230818142059394,-0.1778177647293191
351.2000000000044,113.31688136583654,-1.9282799819805536,-0.1844581894506958
352.30000000000445,113.67969440894773,-1.9339019884746298,-0.19351382148109142
353.4000000000044,114.04104475567368,-1.9403957236164364,-0.20169146821597872
354.50000000000443,114.40354703840096,-1.9471320609343894,-0.21146652451134385
355.60000000000446,114.76052627306582,-1.9552636020759542,-0.22241990456917815
356.7000000000045,115.1257458149206,-1.9643149891491383,-0.23356498001650872
357.8000000000045,115.48748064363265,-1.974344164088399,-0.24605994191768588
358.9000000000045,115.85261987993142,-1.9842415448350765,-0.2581379352875053
360.00000000000455,116.20761287840902,-1.9963406119155978,-0.27234195915800274
361.10000000000457,116.57968184585431,-2.0085422644784514,-0.29045372573400563
362.2000000000046,116.93824081382492,-2.019948016839617,-0.3069043718045794
363.30000000000456,117.30048134827166,-2.0339922235764516,-0.3259531008454557
364.4000000000046,117.66630591231862,-2.0517995173110437,-0.34852845772235774
365.5000000000046,118.0291700000013,-2.0681900000000764,-0.37063113342608434
366.6000000000046,118.38179455496073,-2.0832712822883908,-0.39313424533694885
367.70000000000465,118.7556330956114,-2.107869248923831,-0.4211882828600384
368.8000000000047,119.1175883085579,-2.1262647461624216,-0.44881833618894973
369.9000000000047,119.48493280404797,-2.1496805675272754,-0.48064891419695854
371.00000000000466,119.84463556350455,-2.1756756341375545,-0.5154647560376091
372.1000000000047,120.21528980912312,-2.203318322495719,-0.5523299978792693
373.2000000000047,120.57857124937472,-2.2276826233159372,-0.5948777987806837
374.30000000000473,120.94787918553979,-2.2616773971116544,-0.6377424712408386
375.40000000000475,121.31386541304957,-2.293426594559784,-0.68748278151996
376.5000000000048,121.68260994112117,-2.330478923350337,-0.7367694804390181
377.6000000000048,122.04803902148655,-2.364935835247147,-0.7941912460981735
378.7000000000048,122.40743385714974,-2.4063543913799954,-0.853074724794618
379.80000000000484,122.78513639986254,-2.4482500468736927,-0.9227410134924217
380.9000000000048,123.15187470527938,-2.4891093141464165,-0.991893761536832
382.00000000000483,123.52917000000156,-2.532120000000246,-1.0700600009589132
383.10000000000485,123.89866093037564,-2.574611465069639,-1.1561647216698505
384.2000000000049,124.26833879967526,-2.618245814217468,-1.237460908243345
385.3000000000049,124.63883403491764,-2.667067343840248,-1.3335604274506911
386.4000000000049,125.00334232250242,-2.7069195240231423,-1.4325360869310737
387.50000000000495,125.37473778905193,-2.75575556194715,-1.5368850835744325
388.6000000000049,125.74089630305853,-2.7957190149293596,-1.6461320323349464
389.70000000000493,126.11117996313587,-2.8407383244268156,-1.7621536062464496
390.80000000000496,126.47575699227714,-2.859316495148236,-1.878343214821125
391.900000000005,126.84216435755754,-2.894146158891757,-2.0001066759652417
393.000000000005,127.20979263048302,-2.918244463234163,-2.128860358468274
394.100000000005,127.57527919157926,-2.9239991518343875,-2.2555758038438936
395.20000000000505,127.94169710786882,-2.9269375154602204,-2.3866622746416963
396.30000000000507,128.2977718976914,-2.9109553038500473,-2.5121042439444983
397.4000000000051,128.65662654346804,-2.894985116176659,-2.6376489423317224
398.50000000000506,129.01917000000228,-2.8595099999998372,-2.761667535803852
399.6000000000051,129.36367236917206,-2.8270759031309165,-2.8778924896291174
400.7000000000051,129.72863420457213,-2.771680194945334,-2.992560075826408
401.8000000000051,130.0715047872526,-2.712722556242589,-3.0992232315331294
402.90000000000515,130.43379822857617,-2.6440554843444097,-3.202270238455518
404.0000000000052,130.7828406830506,-2.5694346592745476,-3.293786673145194
405.1000000000052,131.1347688154553,-2.491703061002675,-3.37890285130481
406.20000000000516,131.4823972908032,-2.4150255722464964,-3.452526220790197
407.3000000000052,131.83338408944405,-2.338034497010984,-3.5206112685462365
408.4000000000052,132.1829214010637,-2.2637834778689716,-3.578015390029223
409.50000000000523,132.53319955055196,-2.1963703685630365,-3.625543677854115
410.60000000000525,132.8745452664674,-2.134035534539248,-3.6668545400886132
411.7000000000053,133.23754710313446,-2.0767818091034576,-3.7052713205391514
412.8000000000053,133.59251972904096,-2.0290350087659568,-3.735467632782311
413.9000000000053,133.94757432391089,-1.9864325779466945,-3.7601134316554656
415.00000000000534,134.30031947383839,-1.9537842692104666,-3.7822750105714524
416.1000000000053,134.65228819977423,-1.930557405414599,-3.800029904396531
417.20000000000533,135.0134097034669,-1.9088717431800974,-3.8163491151180997
418.30000000000535,135.38178696002362,-1.8914192885801238,-3.826950443599982
419.4000000000054,135.73216726163423,-1.877170764326237,-3.8381514734334456
420.5000000000054,136.097216752291,-1.8652559826463098,-3.8473629388875072
421.6000000000054,136.45047374885144,-1.8581491936267553,-3.8543789239221593
422.70000000000545,136.82250375752972,-1.850883458990198,-3.861060701168194
423.8000000000054,137.18739273339168,-1.846043739731569,-3.867511597764402
424.90000000000543,137.55100774911068,-1.841062889589044,-3.872499939709255
426.00000000000546,137.90958529431532,-1.837719093395766,-3.8774500144177404
427.1000000000055,138.27351887435682,-1.8357527865304453,-3.8800800003123697
428.2000000000055,138.6406266733777,-1.8344615019472665,-3.8833728566684353
429.3000000000055,138.9976859291508,-1.8339493347047975,-3.8853499998455936
430.40000000000555,139.365968456327,-1.8329286754041456,-3.8890503036617097
431.50000000000557,139.7302977987388,-1.8317739191184974,-3.8901719179143424
432.6000000000056,140.09586604947444,-1.8320454469881073,-3.8914900232489886
433.70000000000556,140.45171912169332,-1.8301908410433472,-3.89281
434.8000000000056,140.82467760814404,-1.830425935706102,-3.894459393637339
435.9000000000056,141.18803407046656,-1.832814008783509,-3.8941283697713587
437.0000000000056,141.5540484174222,-1.855613779125056,-3.89413
438.10000000000565,141.91483187896134,-1.8595777629180663,-3.8941300000052195
439.2000000000057,142.2753369690174,-1.8380108933523476,-3.8954500032770665
440.3000000000057,142.6385919447464,-1.8266250089877298,-3.8944624644843375
441.40000000000566,143.0016699975035,-1.8238483793113924,-3.8928198201420763
442.5000000000057,143.36495797197776,-1.8244998133862607,-3.8929562632078296
443.6000000000057,143.72263975611955,-1.822566199323777,-3.8937999940286425
444.70000000000573,144.09412290133486,-1.8213889798819884,-3.893470001213989
445.80000000000575,144.46015584501905,-1.8237616052149346,-3.892810039686942
446.9000000000058,144.82394996568675,-1.8255647666329202,-3.8938539931188036
448.0000000000058,145.1912429554634,-1.828412753525528,-3.892785632115462
449.1000000000058,145.55825270364514,-1.8318700860033321,-3.8934699999671567
450.20000000000584,145.92287155935975,-1.8336174249423245,-3.8938047690836224
451.3000000000058,146.29076128191423,-1.8366481341406073,-3.8918199966908524
452.40000000000583,146.65519831715324,-1.837019337909696,-3.8918200009288784
453.50000000000585,147.02181442267334,-1.8387249252220146,-3.8908356170779608
454.6000000000059,147.3834246403727,-1.8395651437711853,-3.892159994013277
455.7000000000059,147.74879036676367,-1.8449397910607388,-3.8931399989201156
456.8000000000059,148.1093657935422,-1.845878681978269,-3.891169999996972
457.90000000000595,148.48152747755992,-1.8463051144970712,-3.8908571947149473
459.0000000000059,148.8466443707274,-1.8491009031726682,-3.8908400000020773
460.10000000000593,149.20947820147222,-1.8525976164487754,-3.88955946073873
461.20000000000596,149.5798893821301,-1.854851149582716,-3.8921580375083757
462.300000000006,149.94182530195533,-1.8559583561783417,-3.892149719547522
463.400000000006,150.31054407544084,-1.859943660201408,-3.89148997389633
464.500000000006,150.67780564936984,-1.8596598644292066,-3.889850050687345
465.60000000000605,151.03847195369912,-1.8620423803709474,-3.8905653394420883
466.70000000000607,151.40091129076782,-1.865268299592623,-3.889388276002114
467.8000000000061,151.77072799966092,-1.8690905484815923,-3.8898499999911227
468.90000000000606,152.13527372886398,-1.8685601308600697,-3.8899141808041984
470.0000000000061,152.501312240266,-1.8687424098695262,-3.8901778384396977
471.1000000000061,152.87285775854298,-1.8722123749000334,-3.8895199999999575
472.2000000000061,153.23813976348495,-1.8755428307489184,-3.8891783896328986
473.30000000000615,153.59567420125757,-1.8793686025360805,-3.8895167554519325
474.4000000000062,153.9691742062585,-1.8817801065454711,-3.890796934583839
475.5000000000062,154.3407084254089,-1.8846971826387529,-3.8885293754911956
476.60000000000616,154.71009791385018,-1.8873736037030187,-3.887550215295895
477.7000000000062,155.07052094943595,-1.8881806779408021,-3.8876197145893268
478.8000000000062,155.44332264681933,-1.8901647797094496,-3.8878836086684
479.90000000000623,155.8061084331432,-1.8922470729879262,-3.888872649958798
481.00000000000625,156.16917000000248,-1.8944700000000108,-3.88788
482.1000000000063,156.53391532323022,-1.898388730992391,-3.8868800000000676
483.2000000000063,156.85673049600922,-1.8998352210909115,-3.8865221681012048
484.3000000000063,157.2630823952157,-1.904222679096355,-3.88755
485.40000000000634,157.6321412992145,-1.9074797769424625,-3.8875500001211076
486.5000000000063,157.99832344357134,-1.908821282650745,-3.8862299993855767
487.60000000000633,158.36662466386275,-1.9101840708162199,-3.885570090098576
488.70000000000636,158.7302257553959,-1.9110033067686092,-3.887549724044246
489.8000000000064,159.09806207714144,-1.9138746793299721,-3.884906411341529
490.9000000000064,159.4659693732855,-1.9181757112143112,-3.8868899981050182
492.0000000000064,159.835987609983,-1.9192305664434335,-3.885899966367711
493.10000000000645,160.1988538014163,-1.9219363258601314,-3.8862299999997947
494.2000000000064,160.5655310103175,-1.9241591881850142,-3.8864325006980858
495.30000000000643,160.93255905379849,-1.9251887561619359,-3.884909999997864
496.40000000000646,161.29801774595055,-1.9295204635098133,-3.8849101859350212
497.5000000000065,161.67024016047512,-1.9326488906084636,-3.8842517388645597
498.6000000000065,162.03422468208797,-1.9351063437673859,-3.884125458167367
499.7000000000065,162.400395451718,-1.936158557099881,-3.884469997495017
500.80000000000655,162.769648103353,-1.9396402133328763,-3.885129999933169
501.90000000000657,163.1342666685678,-1.9419913339881547,-3.885130000570699
503.0000000000066,163.50436443252408,-1.9435011965036102,-3.8830230033192197
504.10000000000656,163.87515297249413,-1.9466051461815488,-3.885131036408446
505.2000000000066,164.23599873275643,-1.9491123743646026,-3.883812155974364
506.3000000000066,164.61070266807138,-1.9522722737860783,-3.8824900065471675
507.4000000000066,164.97739046897578,-1.952495088594717,-3.8851293340119506
508.50000000000665,165.3389468319285,-1.956932987712766,-3.88502
509.6000000000067,165.70651906433292,-1.9579879586596751,-3.883710866870133
510.7000000000067,166.074251710232,-1.961391109696962,-3.8840300842007243
511.80000000000666,166.44036751380852,-1.9619017311915148,-3.8823472779184147
512.9000000000067,166.8088054348109,-1.9666491803111101,-3.8836999991822223
514.0000000000067,167.18041313205276,-1.9666137431244648,-3.8807369514329277
515.1000000000067,167.54512568695606,-1.9692221424753122,-3.8830674138271215
516.2000000000068,167.91034943186466,-1.9732866273668113,-3.88039975587303
517.3000000000068,168.27917409265004,-1.974759832216779,-3.880790656191558
518.4000000000068,168.64783218539515,-1.9786249418327566,-3.8815508783162778
519.5000000000068,169.01421889432405,-1.9801561129695393,-3.8820501741110527
520.6000000000068,169.3836038010426,-1.9806199689782165,-3.879420762668168
521.7000000000069,169.75302412638737,-1.983750218023791,-3.879524018412041
522.8000000000068,170.11783778574653,-1.9857298572151532,-3.8820494280060185
523.9000000000069,170.4862286637549,-1.9889185921396288,-3.8830974431254934
525.0000000000068,170.85446719307262,-1.9915910577279499,-3.8803900982649666
526.100000000007,171.2220723138979,-1.99445304807479,-3.8804900719260242
527.2000000000069,171.58916681713472,-1.9956300618197744,-3.882050129803506
528.300000000007,171.94876875779417,-1.9976038158049598,-3.8820498128923058
529.4000000000069,172.3194199253486,-2.000815374665141,-3.8810597679294014
530.5000000000069,172.68808493999,-2.00437082318067,-3.880729999999043
531.600000000007,173.0612548338735,-2.0085196088228363,-3.881720002795895
532.700000000007,173.43355055288976,-2.0116605251939785,-3.880071037743502
533.800000000007,173.80035569938482,-2.0143307218713984,-3.8790896108699053
534.900000000007,174.17142421279115,-2.0180291031498583,-3.8801108227187773
536.000000000007,174.54094367998565,-2.0195956140601194,-3.881390985084558
537.1000000000071,174.91100202677742,-2.021528271794689,-3.880398325059769
538.2000000000071,175.27950840413857,-2.024808772389806,-3.88041
539.300000000007,175.64645658823784,-2.0251064747199714,-3.8808871301677357
540.4000000000071,176.0156810344805,-2.0278567354686623,-3.880410521595711
541.500000000007,176.38239286612045,-2.0310905369478633,-3.879091161875069
542.6000000000072,176.75257985838167,-2.0342673475213973,-3.8782151355666876
543.7000000000071,177.1238459999653,-2.0391464500968777,-3.8800798135469403
544.8000000000072,177.48632930229502,-2.0414488673562556,-3.878728356786173
545.9000000000071,177.85663360987508,-2.044227387862424,-3.879750154124332
547.0000000000072,178.21917000000073,-2.046549999999899,-3.8774399999912377
548.1000000000072,178.5952622211805,-2.052134005462659,-3.878759998587786
549.2000000000072,178.9623600076544,-2.0565423054150282,-3.8800669413237845
550.3000000000072,179.33686778369858,-2.0591195834445717,-3.8800796356635985
551.4000000000073,179.70742501861574,-2.062111248652206,-3.8780348256959094
552.5000000000073,180.07898223969232,-2.0673355628703547,-3.879419999999993
553.6000000000073,180.4466060250087,-2.0703926806496518,-3.8807399999977745
554.7000000000073,180.8215322418458,-2.0721483023929896,-3.8807400000087258
555.8000000000073,181.1860865246191,-2.075380664477612,-3.8794202796618578
556.9000000000074,181.5500739603756,-2.0800833677557042,-3.8797688807038075
558.0000000000074,181.91838321145838,-2.0802590184774465,-3.8810697872728004
559.1000000000074,182.28247865728625,-2.084430453147924,-3.879093291018908
560.2000000000073,182.65613618934628,-2.0889319893676452,-3.8790903742808442
561.3000000000073,183.0234766836476,-2.090348016801969,-3.880407068787174
562.4000000000074,183.39519456191954,-2.094161802392672,-3.880080000000288
563.5000000000074,183.762140741954,-2.0992916809138653,-3.880080464617144
564.6000000000074,184.13231621716133,-2.1008009473358236,-3.879417305316968
565.7000000000074,184.50463431552535,-2.1045842902339333,-3.882051152646963
566.8000000000075,184.87640326835552,-2.108056269783636,-3.8810593329034924
567.9000000000075,185.24809448743835,-2.113660534237929,-3.88106344453192
569.0000000000075,185.61917000000267,-2.115230000000211,-3.8807299999999585
570.1000000000075,185.99743027124939,-2.1161679156398048,-3.8792989607004666
571.2000000000075,186.3629312767679,-2.1196182981573033,-3.881390006552234
572.3000000000076,186.7294850096854,-2.1200243323327403,-3.881384248612113
573.4000000000076,187.10510749633966,-2.1243705704878186,-3.8820963952702954
574.5000000000076,187.47455257798026,-2.125940864436834,-3.8823799937572705
575.6000000000076,187.8469913935058,-2.130624571247146,-3.8810600254175207
576.7000000000077,188.21659070310793,-2.1317781458700877,-3.8823603058148746
577.8000000000077,188.58086039951306,-2.135313702699931,-3.8823752751310048
578.9000000000076,188.95437249166378,-2.1377875235540063,-3.8827972777797464
580.0000000000076,189.32484547612177,-2.1409735556307554,-3.881719999999999
581.1000000000076,189.69755591988385,-2.145378732071643,-3.882575074484357
582.2000000000077,190.06611295801392,-2.148050008959555,-3.8827100041148874
583.3000000000077,190.4275921433593,-2.1528646284375377,-3.882710000021178
584.4000000000077,190.81262837831284,-2.155793357969775,-3.8827105142728064
585.5000000000077,191.17917000000298,-2.1577800000002245,-3.8830399999999994
586.6000000000078,191.55177779834622,-2.1625862923099057,-3.8833787901195733
587.7000000000078,191.9211217776536,-2.1636847727115476,-3.883356067111707
588.8000000000078,192.29029601460007,-2.1675655341430597,-3.883125980130232
589.9000000000078,192.65952328045947,-2.171280058128667,-3.8827191103652994
591.0000000000078,193.02871146325953,-2.17176580330222,-3.883369999980145
592.1000000000079,193.39609328892953,-2.175406142847309,-3.882033024037522
593.2000000000079,193.76866126589556,-2.1794298465700805,-3.881701821131863
594.3000000000079,194.13790701259984,-2.1812425750902653,-3.883260933615682
595.4000000000078,194.51352882849258,-2.1841323369216683,-3.884570167298904
596.5000000000078,194.88631120297305,-2.188575948430655,-3.884888322323278
597.6000000000079,195.25568937212464,-2.1924753097542884,-3.8842500000032567
598.7000000000079,195.62580076732058,-2.1958176019436326,-3.88425
599.8000000000079,195.99647156151357,-2.1996700472375115,-3.88555925022365
600.9000000000079,196.37078125678676,-2.204910831368624,-3.884249963199549
602.000000000008,196.7432047236267,-2.2085314935443714,-3.885240459578738
603.100000000008,197.1125978888607,-2.2096756628694227,-3.883883568034748
604.200000000008,197.48357849096368,-2.211725816677376,-3.88524369398583
605.300000000008,197.85186631698275,-2.2180825509135498,-3.884910001590594
606.400000000008,198.21856645614852,-2.2202205080335755,-3.8852398481235464
607.5000000000081,198.5914856790319,-2.2223179939838147,-3.886229983797448
608.6000000000081,198.96024070766313,-2.2268935627411266,-3.884909999801798
609.7000000000081,199.33421153424615,-2.229780436865736,-3.8842500016774224
610.8000000000081,199.69878165752596,-2.2353289110466568,-3.885569800501623
611.9000000000082,200.07329181159932,-2.2387411673559874,-3.8855870402782067
613.0000000000082,200.44557626046452,-2.2414758975667772,-3.884580987340811
614.1000000000081,200.81341150403483,-2.2466034725690402,-3.8828158284883476
615.2000000000081,201.18855691843623,-2.252278719857905,-3.884139705981086
616.3000000000081,201.55649076374795,-2.255642529838872,-3.885130000037905
617.4000000000082,201.9303856283277,-2.257739214700743,-3.88579
618.5000000000082,202.29782625978467,-2.2643712045989677,-3.8858940605119865
619.6000000000082,202.6662378377955,-2.267669040701982,-3.885789999999899
620.7000000000082,203.04972789878215,-2.269335150612283,-3.8855952729868415
621.8000000000083,203.42115794088073,-2.2738739371968513,-3.8854661800210497
622.9000000000083,203.79681503368226,-2.278298707491833,-3.886440326162398
624.0000000000083,204.16371111096527,-2.28086467667912,-3.8861100032411144
625.1000000000083,204.53251180303434,-2.2841770329846036,-3.8861078071598274
626.2000000000083,204.90015588221596,-2.2868336227205863,-3.887099983081237
627.3000000000084,205.27072199430663,-2.2920606682068825,-3.8874260172993753
628.4000000000084,205.64224544112233,-2.2966804676457655,-3.8871000000000033
629.5000000000084,206.00992187625363,-2.3001546541453384,-3.887986512140235
630.6000000000083,206.38478767037395,-2.303816802817,-3.88809019312708
631.7000000000083,206.75854250361692,-2.3069846153006055,-3.8870999999978797
632.8000000000084,207.12917401491552,-2.310090043035192,-3.886769939505733
633.9000000000084,207.50298498678822,-2.3171674520336816,-3.885988765163535
635.0000000000084,207.87128263774466,-2.3166533959246474,-3.8853232031942375
636.1000000000084,208.24302205721077,-2.3208596423810706,-3.885129999999999
637.2000000000085,208.61454030380585,-2.322481423766744,-3.8870965494029925
638.3000000000085,208.9884097101412,-2.3289737070935264,-3.8849030621201632
639.4000000000085,209.36109354233415,-2.3328165599519295,-3.886894003501632
640.5000000000085,209.73166182582744,-2.3357175716905143,-3.8862299999996335
641.6000000000085,210.10441112075256,-2.340879129436909,-3.887539968413299
642.7000000000086,210.47359348156465,-2.3448980896537033,-3.887811647768973
643.8000000000086,210.83709335157172,-2.3456715591686588,-3.886780000009299
644.9000000000086,211.21072804050894,-2.351711595875174,-3.8874165414546367
646.0000000000086,211.5903609168187,-2.3530066757387575,-3.886450000000504
647.1000000000087,211.95076719618717,-2.3572248795407846,-3.8857899999995706
648.2000000000087,212.32244460508744,-2.361944966464342,-3.886750662605294
649.3000000000086,212.69994958420662,-2.3671355460285763,-3.8854599634632683
650.4000000000086,213.07187984419386,-2.368576002220066,-3.8867799985580036
651.5000000000086,213.44647234911335,-2.3769083702532656,-3.888089999999873
652.6000000000087,213.82113938235037,-2.37728005891923,-3.8857901030787776
653.7000000000087,214.19277916692678,-2.3816943123650653,-3.885790007624567
654.8000000000087,214.56545337585138,-2.3884323526551743,-3.885465803586955
655.9000000000087,214.93787252826996,-2.391585676270722,-3.886880002376524
657.0000000000088,215.30793684957337,-2.395221319611669,-3.887209999999969
658.1000000000088,215.6784908247266,-2.3989505432694096,-3.8880231303292123
659.2000000000088,216.05060200071767,-2.4058768677321325,-3.888199887547825
660.3000000000088,216.42207135164344,-2.4078315238842447,-3.8888410502610937
661.4000000000088,216.79648114093595,-2.4116369937750592,-3.8878408735598975
662.5000000000089,217.16635342474336,-2.4168890792284388,-3.88753786392051
663.6000000000089,217.54137939839964,-2.4213060081230835,-3.886222623850274
664.7000000000089,217.91352385858474,-2.4229669493275803,-3.887208849435979
665.8000000000088,218.28732280540765,-2.4263465639123982,-3.887210199826787
666.9000000000088,218.65582354844133,-2.42961860494532,-3.887871140513017
668.0000000000089,219.02720647663898,-2.433095010760209,-3.888859312583424
669.1000000000089,219.39975785901933,-2.434536311827179,-3.8872121837475526
670.2000000000089,219.77303665606283,-2.440865562119811,-3.8898958298318678
671.3000000000089,220.14592981255112,-2.4444126293629758,-3.889736443132928
672.400000000009,220.5177845794627,-2.4479409961869165,-3.8898499999960547
673.500000000009,220.89017008415323,-2.453662465504522,-3.8885299933347373
674.600000000009,221.26289994664455,-2.4585913378904967,-3.888529999999815
675.700000000009,221.63494816298797,-2.4652876824012493,-3.8882862941636565
676.800000000009,222.00892268423584,-2.4728793840868577,-3.8888622961407058
677.9000000000091,222.37744341853636,-2.4765755370802665,-3.8901700000221364
679.0000000000091,222.75662937975787,-2.4823332393087107,-3.890170356836444
680.1000000000091,223.13030255715714,-2.4845205900751033,-3.8914901107278346
681.2000000000091,223.50161369608406,-2.48641181659134,-3.88885002638668
682.3000000000092,223.87208759596325,-2.490107734595955,-3.889840000514471
683.4000000000092,224.24508096813207,-2.4933887362623017,-3.889840194174537
684.5000000000091,224.61209088578775,-2.4948788704253912,-3.8908300289457403
685.6000000000091,224.97967775987806,-2.501788495641541,-3.88984999999816
686.7000000000091,225.35857232066894,-2.5062647738784625,-3.889850000000431
687.8000000000092,225.72772611822637,-2.506786320960509,-3.8908400703824655
688.9000000000092,226.08577312516167,-2.4188364772048527,-3.890839999420129
690.0000000000092,226.45626635822128,-2.4227188876256305,-3.890840000000443
691.1000000000092,226.81917891338873,-2.431380030110868,-3.8908399933079876
692.2000000000093,227.19214081197322,-2.432250503199587,-3.8898516261191074
693.3000000000093,227.56556474644935,-2.436212291111791,-3.890509888054192
694.4000000000093,227.93791866264772,-2.4398579327537533,-3.8905293175161515
695.5000000000093,228.31322759157135,-2.440859602885723,-3.8910470014754286
696.6000000000093,228.69256492679074,-2.441380684361599,-3.8905099577715245
697.7000000000094,229.06436168230658,-2.4479241130516893,-3.8921600145589297
698.8000000000094,229.43376406806283,-2.4530178561699425,-3.892328445408531
699.9000000000094,229.80417937482153,-2.455971179084091,-3.8928200014689
700.0000000000093,229.83633663726349,-2.456500308340216,-3.8928198530571168