File: 01_Data/Mineral_Wool_Insulation/STA/N2/10K_min/Mineral_Wool_Insulation_STA_N2_10KData_221107_R2.csv
##Temp./Â°C,Time/min,DSC/(mW/mg),Mass loss/mg
51.0,10.744947612022232,-1.7007772246905233,0.012646924748420219
52.100000000000016,11.121799017285552,-1.589939978455626,0.00833275553895696
53.20000000000003,11.373432566051669,-1.5174128406904914,0.007021558506316694
54.30000000000005,11.580000000000005,-1.4616799999999994,0.008766254520096162
55.40000000000006,11.766766501889844,-1.420439149034868,0.00660071784637406
56.50000000000008,11.939182926430018,-1.3850308146877819,0.007166200031961445
57.600000000000094,12.100000000000016,-1.3582699999999985,0.008171218062747343
58.70000000000011,12.253546857665972,-1.333212418921381,0.008639164240612729
59.800000000000125,12.405091214993387,-1.3114462602539798,0.006545411549407021
60.90000000000014,12.549498480886015,-1.293019251273178,0.007585772902878318
62.000000000000156,12.693934747197867,-1.275296673250971,0.006986932724372785
63.10000000000017,12.8301393284638,-1.260604999565565,0.008676657154489398
64.20000000000019,12.967220729110322,-1.2465219618371233,0.008424018237516151
65.30000000000021,13.102534347100713,-1.2316711937005205,0.009745104353631184
66.40000000000022,13.234791596510373,-1.2195701964669425,0.007537608274167162
67.50000000000023,13.366345428212036,-1.2082220284030714,0.007069265091277366
68.60000000000025,13.494596450734166,-1.1951100697724573,0.007294498158704421
69.70000000000027,13.624111382951575,-1.182350888276693,0.007377818454325613
70.80000000000028,13.749261034575174,-1.173131327968081,0.007246534509043556
71.90000000000029,13.875172365173084,-1.1604584232804724,0.007234224526274424
73.00000000000031,13.999329293959224,-1.1502557887545832,0.006850797662189656
74.10000000000034,14.123203290131633,-1.1403897308045963,0.005868150258505622
75.20000000000034,14.242988912623957,-1.1293478411613567,0.007306370260612205
76.30000000000035,14.36568347305625,-1.1196634515660626,0.006004659913537047
77.40000000000038,14.487308745928056,-1.1093921162153193,0.004543122142656841
78.5000000000004,14.606421220515486,-1.100654212113813,0.005933574652030593
79.6000000000004,14.724614908029638,-1.090010502449399,0.004613536950274444
80.70000000000041,14.843728468663814,-1.0823632654800874,0.004566619581693132
81.80000000000044,14.9624313626567,-1.0719893194592947,0.0046514436203430876
82.90000000000046,15.077936866473882,-1.0631491284384753,0.0048702426259694676
84.00000000000047,15.193949669903407,-1.0546982438585029,0.0047285329251369745
85.10000000000048,15.31000000000005,-1.046429999999995,0.004720235744501977
86.2000000000005,15.421731254928792,-1.0391804868590413,0.004720268383127113
87.30000000000052,15.539787451787177,-1.0327400616982616,0.0050472870456141905
88.40000000000053,15.654294107985681,-1.0252059990744233,0.004657180714194631
89.50000000000054,15.765583914083004,-1.0158438355922021,0.00430991135064307
90.60000000000056,15.878147938524988,-1.0096767098609363,0.00472468127874226
91.70000000000059,15.990873117284039,-1.002497874784996,0.0034081322848855677
92.8000000000006,16.10256124846325,-0.9946880227140298,0.0028310989164177514
93.9000000000006,16.213649083840515,-0.9888009048611257,0.0020678272590561875
95.00000000000063,16.32433178767289,-0.9823063758657502,0.0020560229451582757
96.10000000000065,16.43461710210282,-0.9765317053743443,0.0047608959873688406
97.20000000000066,16.544622029414437,-0.9687276080264828,0.0033910511448942415
98.30000000000067,16.654710541980943,-0.9612691733092131,0.0020832295956250135
99.40000000000069,16.766193940824387,-0.9551565150561161,0.002080881053433181
100.50000000000071,16.874653381584405,-0.9483367730608672,0.0024922887997922416
101.60000000000072,16.984254177427424,-0.9419115272710227,0.003398293907623362
102.70000000000073,17.09321098439071,-0.9359889862878669,0.002081889138812798
103.80000000000075,17.200284280418558,-0.9301617410277049,0.0020867255611349833
104.90000000000077,17.30989758280003,-0.9267715819707651,0.0007699225137756116
106.00000000000078,17.41716126612032,-0.9185817622037061,0.0012818870590027842
107.10000000000079,17.523152049356632,-0.9151355756791912,0.0021436262239475923
108.20000000000081,17.631713006284986,-0.9087688793347605,0.0008135915391820348
109.30000000000084,17.74156131343997,-0.9027471608803519,0.0004209055297925701
110.40000000000084,17.849500361302013,-0.8970398754572025,-0.0005500538238312203
111.50000000000085,17.95835719790018,-0.8917400186147296,-0.0005480444734224932
112.60000000000088,18.066116203501796,-0.8866885006278179,-7.223307477399743e-05
113.7000000000009,18.173164768942033,-0.8811955263701401,-0.0019034211455553063
114.8000000000009,18.280645883965644,-0.8769398733194276,-0.0005496064419743263
115.90000000000092,18.387408643182294,-0.87124539809985,0.0007695029530143671
117.00000000000094,18.495289625386377,-0.8672384046190403,-0.0005499549078136212
118.10000000000096,18.603109050508788,-0.8625971623243345,0.0008229638349259716
119.20000000000097,18.707111871726095,-0.8573802534289429,-0.0018948097086015636
120.30000000000098,18.816622809064967,-0.8528098997999174,-0.0005500530013469174
121.400000000001,18.92356918776624,-0.8482640450539054,-0.0011957871311087942
122.50000000000102,19.029908481305977,-0.843734211560853,-0.0025201841377704426
123.60000000000103,19.137348742780663,-0.8396045079896175,-0.0018657487012525564
124.70000000000104,19.24428263342021,-0.835930454639143,-0.0018682002705219247
125.80000000000106,19.350098801796165,-0.8328911647632553,-0.0005722554746920849
126.90000000000109,19.457240968584934,-0.8281190330664926,-0.0018688247576275074
128.00000000000108,19.563700019625376,-0.8236316848612064,-0.000553941763292265
129.1000000000011,19.669627634839905,-0.818732611752128,-0.0008801604030894694
130.20000000000113,19.775151917582647,-0.8161402980238264,-0.001982089345451854
131.30000000000115,19.880095938210818,-0.8133692556822704,-0.0031898875068190335
132.40000000000117,19.986813481035732,-0.8095815749657274,-0.0018685371363869052
133.50000000000117,20.093956115144824,-0.8060263172421254,-0.0031900662107480215
134.6000000000012,20.19924939587127,-0.8014432286680883,-0.0031896317209838543
135.7000000000012,20.304291637678478,-0.7978552711148298,-0.0031732760513296654
136.8000000000012,20.409363742188287,-0.7947727871469998,-0.0018557941750056983
137.90000000000123,20.515695405911973,-0.7907294975036702,-0.003179888797083308
139.00000000000125,20.61907040419693,-0.7864283766631461,-0.004480453956767327
140.10000000000127,20.725686316327014,-0.7832708491081055,-0.0031898299085053594
141.2000000000013,20.830384015221878,-0.779753920043463,-0.004591182752649026
142.3000000000013,20.935832562059126,-0.7756018510440347,-0.0031801370618556035
143.4000000000013,21.039901843374956,-0.7710277503250702,-0.003181632510264265
144.50000000000134,21.146206700885152,-0.7689463671858889,-0.004502030356031916
145.60000000000133,21.25028157726404,-0.7645240790542556,-0.004836083962057813
146.70000000000135,21.355024980441502,-0.7619617499010704,-0.004499687827490106
147.80000000000138,21.460000000000125,-0.7574999999999957,-0.0044998593006884136
148.9000000000014,21.564512064627866,-0.7546188451748677,-0.004499908373894357
150.00000000000142,21.66965923313572,-0.7508504420502855,-0.005809150742448033
151.10000000000142,21.773989544063845,-0.7463555850374926,-0.004995102625297676
152.20000000000144,21.879096759726565,-0.7428989992612921,-0.005819939549470909
153.30000000000146,21.9839832337711,-0.741441899996819,-0.0057040807639197055
154.40000000000146,22.088700819121495,-0.7357507275687056,-0.007425012192172176
155.50000000000148,22.192299344680773,-0.7331907437071185,-0.007469815926224754
156.6000000000015,22.29825858248479,-0.7284562048698934,-0.007139610651061723
157.70000000000152,22.402486033119715,-0.7256840087303974,-0.0071293827153633416
158.80000000000155,22.50586339456439,-0.7235652695139445,-0.007134617544999777
159.90000000000154,22.60978481561755,-0.7203673079830584,-0.005800202016153833
161.00000000000156,22.71500399109498,-0.7177385725499524,-0.007130005912861392
162.1000000000016,22.81990850435546,-0.7140545615361409,-0.007130027229500513
163.20000000000158,22.923828333773674,-0.7108936787257464,-0.0058478441576843565
164.3000000000016,23.02912457666323,-0.707049075684952,-0.007139931881735784
165.40000000000163,23.134210133605986,-0.7044714832235867,-0.006487354693625491
166.50000000000165,23.237393901304866,-0.7002842173068597,-0.006478128590794441
167.60000000000167,23.34258325725199,-0.6976867670248788,-0.007140177341758758
168.70000000000167,23.44480874480046,-0.6931601977632164,-0.007130138127250163
169.8000000000017,23.551098452511464,-0.689000369904798,-0.007130159488291099
170.9000000000017,23.65636749863801,-0.6865749020333212,-0.00846201513329703
172.0000000000017,23.759891720874997,-0.6844662150979254,-0.007140018595936937
173.10000000000173,23.86219892613059,-0.680246824558395,-0.008130374666126983
174.20000000000175,23.969727368938187,-0.6787189341409836,-0.00782250682590746
175.30000000000177,24.073008337431048,-0.6744576382460622,-0.007096516028815003
176.4000000000018,24.178881109701365,-0.671630332894463,-0.009001406072076001
177.5000000000018,24.281943811585005,-0.6687845354764657,-0.007793943618037424
178.6000000000018,24.38762059644489,-0.6658171455809361,-0.007800021297459381
179.70000000000184,24.49168898016051,-0.6630210916458532,-0.009110212346794988
180.80000000000183,24.597011895047928,-0.6596969686918571,-0.007828745860297914
181.90000000000185,24.700558385282683,-0.6552200988917436,-0.008120942783233609
183.00000000000188,24.80573859237671,-0.6537595200182286,-0.009109767185666584
184.1000000000019,24.908500293417582,-0.6519631004357963,-0.007785649330998012
185.20000000000192,25.014424128493925,-0.6493286817536505,-0.00911016360047956
186.30000000000192,25.116632559223884,-0.646487310411018,-0.009114825843798968
187.40000000000194,25.221773468968944,-0.6423565755191251,-0.008460147115329164
188.50000000000196,25.32606964718666,-0.6404150831593377,-0.00977723925111107
189.60000000000196,25.429154309347947,-0.6366700910348502,-0.00978199329668783
190.70000000000198,25.53420656282299,-0.6334171015607135,-0.008354621439771392
191.800000000002,25.636788509057798,-0.6314673212764836,-0.00918882841564983
192.90000000000202,25.741559204466057,-0.6277795722595418,-0.009110008162033445
194.00000000000205,25.84718973842673,-0.6254580549705133,-0.007804093739030904
195.10000000000204,25.94980477295187,-0.6216590075745676,-0.00982947209433327
196.20000000000206,26.0533360167084,-0.6207605751010536,-0.009774048194419294
197.3000000000021,26.157822323355614,-0.6173883456991599,-0.009770710049131104
198.40000000000208,26.262333752296545,-0.6151654742466981,-0.009771571821713287
199.5000000000021,26.36616154951214,-0.612228341187402,-0.008459911651218732
200.60000000000213,26.47036779705781,-0.6085632326965646,-0.009119045618636967
201.70000000000215,26.57226983129781,-0.6063617810600563,-0.009119801972587105
202.80000000000217,26.678197709101866,-0.6032554549591315,-0.009826092060832181
203.90000000000217,26.783017173601852,-0.6011880107695673,-0.011066123377099224
205.0000000000022,26.886337518848137,-0.5994179999762443,-0.009770109379207526
206.1000000000022,26.991005546051642,-0.5962643089243163,-0.009770274406636581
207.2000000000022,27.09533413306849,-0.5935501205608513,-0.009782418932585024
208.30000000000223,27.199913595438023,-0.5916345282678206,-0.01108711280262531
209.40000000000225,27.30393273755494,-0.5892690469484552,-0.011090009339238538
210.50000000000227,27.407084254426724,-0.5872634576138203,-0.011090017349920878
211.6000000000023,27.513113585390215,-0.5852521343290535,-0.012368670037112395
212.7000000000023,27.61770108228572,-0.5806119959866599,-0.01164199015664602
213.8000000000023,27.722075251942584,-0.5807445967603315,-0.011079926994439049
214.90000000000234,27.82635285833737,-0.5791370257644713,-0.011079927000541279
216.00000000000233,27.930349816042575,-0.5753875193041424,-0.011079852785053301
217.10000000000235,28.03462545186095,-0.573858181779786,-0.009769826569038464
218.20000000000238,28.13892142361523,-0.5700792179976986,-0.01042879226412774
219.3000000000024,28.243323742263897,-0.5674396922726088,-0.010099457636207454
220.40000000000242,28.34751110566726,-0.5649198215245794,-0.012090329173257253
221.50000000000242,28.450831294291174,-0.5634748461504588,-0.011066356619487738
222.60000000000244,28.55593410665289,-0.5602599530246423,-0.011090363225252364
223.70000000000246,28.661298006235754,-0.5592145507534504,-0.010759703496824535
224.80000000000246,28.76495074234972,-0.5564904674792551,-0.012080162725061516
225.90000000000248,28.868136743495178,-0.5528016255481458,-0.012064672039667546
227.0000000000025,28.97293760267372,-0.5497698819774368,-0.011090061251368688
228.10000000000252,29.07802789955549,-0.5487544687299679,-0.011090983659824527
229.20000000000255,29.182276200212684,-0.5452118753739357,-0.012400904761446618
230.30000000000254,29.286408017766796,-0.5446762308055187,-0.011078362692717114
231.40000000000256,29.39000104549579,-0.5416199702280499,-0.011079985000002068
232.5000000000026,29.49294270614913,-0.5409028791125047,-0.011079978502501753
233.60000000000258,29.595890876047644,-0.5377109073832237,-0.010741812498864522
234.7000000000026,29.70246612865634,-0.5358954045705544,-0.011540107889277618
235.80000000000263,29.807695772234084,-0.5336179008734543,-0.011739961799708709
236.90000000000265,29.912235251207143,-0.5316964648031354,-0.011240810229225406
238.00000000000267,30.016495093042277,-0.5293307882850129,-0.012080331072124029
239.10000000000267,30.11897731258645,-0.5278625157698308,-0.012079895000336016
240.2000000000027,30.22492841883222,-0.5257992823411407,-0.012079894999694307
241.3000000000027,30.329648855735034,-0.5234014077779968,-0.012079653853255934
242.4000000000027,30.435112625034524,-0.5216245589903805,-0.013399907191991023
243.50000000000273,30.53909209822508,-0.5202756950911691,-0.012411989325165962
244.60000000000275,30.642696086153155,-0.516581776964241,-0.012079789733649093
245.70000000000277,30.748129434827916,-0.5165215027329775,-0.012079802999975797
246.8000000000028,30.85329176922597,-0.5147121651165842,-0.012079820440775269
247.9000000000028,30.95840644666683,-0.5124248817417,-0.0114187481856165
249.0000000000028,31.063146029471945,-0.5112333121798034,-0.012741228736189214
250.10000000000284,31.167493372641143,-0.5088479370501413,-0.012070100158638741
251.20000000000283,31.27209074912967,-0.5072664397089603,-0.01207011200001995
252.30000000000285,31.376384301346604,-0.5058851866467314,-0.012070074009832954
253.40000000000288,31.482407517827507,-0.5048016586875823,-0.012073669436256651
254.5000000000029,31.585747924656786,-0.5018101322250816,-0.01338927496176412
255.60000000000292,31.69176465812805,-0.4995180099166184,-0.013390074404932228
256.7000000000029,31.79586420770683,-0.498236555936727,-0.01406844452247169
257.8000000000029,31.900674205168983,-0.49803682376523817,-0.013169542930096867
258.90000000000293,32.00557669037897,-0.4967114118928925,-0.013395134624597294
260.00000000000296,32.11028772053494,-0.4937420672457435,-0.013400045005028005
261.100000000003,32.21537101723619,-0.49236916065589464,-0.013489540023303714
262.200000000003,32.31652243698409,-0.49015657130678225,-0.012450679476990523
263.300000000003,32.42383295250964,-0.4881847274949248,-0.012739953892272116
264.40000000000305,32.52898625462022,-0.4868786721914268,-0.012747557807999854
265.50000000000307,32.6336039146429,-0.48558485946433844,-0.01241190699740935
266.6000000000031,32.73855154913084,-0.48362533222489323,-0.012409884006174376
267.7000000000031,32.84283805304255,-0.483265788542758,-0.01182015460624708
268.8000000000031,32.946459550541945,-0.48020123742606385,-0.009219867948378813
269.9000000000031,33.05239972848706,-0.4789040511367381,-0.009218415376181177
271.0000000000031,33.157755519700984,-0.4782684152457265,-0.012080194075108963
272.10000000000315,33.26261796978388,-0.4750002891705399,-0.012404960656652086
273.2000000000032,33.36698830713084,-0.47432882059930065,-0.013060069724985635
274.30000000000314,33.47145602561425,-0.4729160523693218,-0.01305986294404926
275.40000000000316,33.57699066380147,-0.4716454297756325,-0.014409344540098346
276.5000000000032,33.68238908252128,-0.47037732306445185,-0.01410947367825921
277.6000000000032,33.78621793885068,-0.46880994607711085,-0.013060229724624506
278.70000000000323,33.89157900131503,-0.467086102059393,-0.014381035986653856
279.80000000000325,33.99604213445922,-0.465500040132274,-0.01305782359221741
280.9000000000033,34.101992213937066,-0.4645053012569778,-0.013694444009284101
282.0000000000033,34.207220444741644,-0.46317844612621023,-0.01240019426185679
283.1000000000033,34.31124868876618,-0.4620959301668465,-0.011080386131765874
284.20000000000334,34.41660585335598,-0.46111613305869054,-0.011080122619652855
285.30000000000337,34.52155187939518,-0.4592505908970331,-0.012357857711756903
286.40000000000333,34.62688366346688,-0.45659600176673826,-0.015395415406569413
287.50000000000335,34.73121408137957,-0.45472368521864376,-0.017891326546317643
288.6000000000034,34.83711185864702,-0.454421027626508,-0.017199240219052392
289.7000000000034,34.941788637537606,-0.4523585935146457,-0.02143320154718875
290.8000000000034,35.0473955142703,-0.450574590630417,-0.024490517852769234
291.9000000000034,35.15271303551943,-0.44876462493902336,-0.021920762983091535
293.0000000000034,35.25702658268547,-0.4496053086085176,-0.01887007262848428
294.10000000000343,35.364243372788074,-0.4474166599134232,-0.019139966407831555
295.20000000000346,35.467085966915036,-0.4472852940654133,-0.017817407836593357
296.3000000000035,35.57106290323492,-0.44415520023756505,-0.016470033941953233
297.4000000000035,35.67888802988748,-0.4439830625639615,-0.015151461050988857
298.5000000000035,35.78348067155116,-0.44057100957195205,-0.0151500339999191
299.60000000000355,35.88898513512554,-0.44222720256456466,-0.01515126027899516
300.70000000000357,35.9945234914709,-0.43998915200518646,-0.015299360876960488
301.8000000000036,36.09890832646798,-0.4391625935296574,-0.015149988064598219
302.9000000000036,36.20465915810824,-0.4380339081320983,-0.015053473318064725
304.0000000000036,36.308280249263206,-0.43669376745866073,-0.016470107019212588
305.1000000000036,36.41549843355215,-0.4351080393193808,-0.015150041354564436
306.2000000000036,36.52139046438978,-0.43390078776366403,-0.01580969507039054
307.30000000000365,36.62603420364505,-0.431109900240185,-0.015809988002118747
308.4000000000037,36.732170526240985,-0.4312921392716744,-0.015808718722761572
309.5000000000037,36.83617104019922,-0.4301808055490263,-0.014393008622029857
310.60000000000366,36.94280154231725,-0.4280222150269301,-0.017115561797150125
311.7000000000037,37.04859207281996,-0.4255097122208299,-0.014819860481251279
312.8000000000037,37.15388736150271,-0.425744724485206,-0.016139276680564585
313.90000000000373,37.25881429154613,-0.42472843374472463,-0.014819944700739551
315.00000000000375,37.3651514803245,-0.42129921416914295,-0.014829511280078034
316.1000000000038,37.470582424586176,-0.4221208468990212,-0.01613949982849805
317.2000000000038,37.57522304422986,-0.4209919025739881,-0.015149731707583047
318.3000000000038,37.68048555872504,-0.42105731399985236,-0.015150368006608517
319.40000000000384,37.7876695749273,-0.41834852387141985,-0.016469941702544233
320.5000000000038,37.890520030080125,-0.4175294765344862,-0.016469918999987065
321.60000000000383,37.99745821631203,-0.41518147961086094,-0.016469918999999944
322.70000000000385,38.103738013641845,-0.41261281052513293,-0.016469918999999944
323.8000000000039,38.209292040249714,-0.4110287016599174,-0.016469918999999944
324.9000000000039,38.315603131588695,-0.4110596302610122,-0.016469919000000832
326.0000000000039,38.41923342563306,-0.41007195819512343,-0.016469918999452826
327.10000000000394,38.52566285531331,-0.4087764366274378,-0.01647268075617747
328.2000000000039,38.63170633932335,-0.4063755706483846,-0.016139893968216246
329.30000000000393,38.737519650230624,-0.4068556108362826,-0.017473160544732913
330.40000000000396,38.843172850432005,-0.40508626242156504,-0.017448474608174003
331.500000000004,38.949892327979036,-0.40489083971747514,-0.016139872169921965
332.600000000004,39.05292473311809,-0.4024013997005077,-0.01750470935901305
333.700000000004,39.1614274888895,-0.4028440419575888,-0.01611123523380975
334.80000000000405,39.2670708919545,-0.40108323125482925,-0.01743409392158668
335.90000000000407,39.371796600956024,-0.40011327008975517,-0.017449809534568317
337.0000000000041,39.47781330835492,-0.3986250055347813,-0.01647019292776264
338.10000000000406,39.58465956680437,-0.3961973841716178,-0.01646989599920401
339.2000000000041,39.69060417250942,-0.3955876985787093,-0.016469888928709597
340.3000000000041,39.79684806759217,-0.39438254072405277,-0.017775802736015756
341.4000000000041,39.90254146510592,-0.3924571852855612,-0.017774737536171425
342.50000000000415,40.00950740470252,-0.39139900223227553,-0.017119896974689297
343.6000000000042,40.11583262437431,-0.3907832383499968,-0.017119895994254897
344.7000000000042,40.22163980296023,-0.3899186356537246,-0.017130344551324672
345.80000000000416,40.32733099663472,-0.3888268328272776,-0.01844763966988161
346.9000000000042,40.43397471212404,-0.38605441409769503,-0.016129856738791304
348.0000000000042,40.539798020250316,-0.38505598256020795,-0.017779814809482097
349.10000000000423,40.64451954648604,-0.3835810452891039,-0.01735484514290153
350.20000000000425,40.752662870351195,-0.3838777869188752,-0.018809128491667604
351.3000000000043,40.857822730325616,-0.3827362122014107,-0.016879497318122105
352.4000000000043,40.96437853894526,-0.38086204791658895,-0.01678961826667269
353.5000000000043,41.07092285081699,-0.37817678004126515,-0.01811005601932525
354.60000000000434,41.17693059214567,-0.3780160606995243,-0.018117285128052885
355.7000000000043,41.282599539005844,-0.37564388649889974,-0.019429879835192843
356.80000000000433,41.38968954858446,-0.3745160961184212,-0.01737075924601683
357.90000000000435,41.496101364317234,-0.37385042574364147,-0.01811456074756501
359.0000000000044,41.60196285114411,-0.373285788516349,-0.01810989596110346
360.1000000000044,41.707919272520265,-0.3700879557107146,-0.018109896000587877
361.2000000000044,41.81345152913009,-0.3696060753311774,-0.018108961429084136
362.30000000000445,41.920497946690354,-0.36788074348456834,-0.017946668114446673
363.4000000000044,42.027427142836416,-0.36609854746203147,-0.018109847335129103
364.50000000000443,42.13360525222668,-0.3659772160138419,-0.01906950901636817
365.60000000000446,42.240167166601076,-0.3640942607899857,-0.019099919001848153
366.7000000000045,42.345952768331365,-0.36285872668007724,-0.019099919000000742
367.8000000000045,42.45337525962622,-0.3619648970064247,-0.019099918999999854
368.9000000000045,42.5589982026523,-0.36053101476946203,-0.019099918999999854
370.00000000000455,42.66678133307268,-0.3584360360985066,-0.019099918999999854
371.10000000000457,42.771863134554174,-0.3591256648425107,-0.019099918999999854
372.2000000000046,42.877964655795736,-0.35621151239210536,-0.019099919000000742
373.30000000000456,42.98541088681488,-0.35496616976211326,-0.019099918999999854
374.4000000000046,43.09193981764328,-0.35289961580673773,-0.019099918999998966
375.5000000000046,43.19929450581104,-0.3534405861022598,-0.019099919021762446
376.6000000000046,43.30524243557022,-0.35085771099653,-0.01910068306129631
377.70000000000465,43.41152300705756,-0.3492442896026232,-0.018778298628147283
378.8000000000047,43.51894286054446,-0.34844475949387155,-0.020412496788681178
379.9000000000047,43.62577327540787,-0.34665141069480887,-0.020418280402407785
381.00000000000466,43.731072691764204,-0.34526224236566105,-0.019099949235601432
382.1000000000047,43.8389851167367,-0.34479053650337393,-0.02006996004637296
383.2000000000047,43.94495824375629,-0.34528784669072227,-0.02042003382385671
384.30000000000473,44.05196869783826,-0.34360015236097957,-0.02042186012735092
385.40000000000475,44.1588214429313,-0.34300880838323394,-0.021476392189540672
386.5000000000048,44.26569862209089,-0.3423773190002184,-0.02008996561899501
387.6000000000048,44.37183261956056,-0.3412352293263271,-0.0200877439872591
388.7000000000048,44.4801930113665,-0.3389512577493558,-0.021409956256662088
389.80000000000484,44.585437105390625,-0.338329861795843,-0.020420035129067315
390.9000000000048,44.69163404429874,-0.33745892653767107,-0.020421893321413975
392.00000000000483,44.799342400788916,-0.33530912945850155,-0.021765872242197837
393.10000000000485,44.90650149104644,-0.33325137609965355,-0.021079995800488138
394.2000000000049,45.01322246138652,-0.33090640922000375,-0.02107803791717444
395.3000000000049,45.12167614431428,-0.3310088948998736,-0.02240057076759472
396.4000000000049,45.227593802666775,-0.3309911314561543,-0.022400696887436844
397.50000000000495,45.33466374788875,-0.33077988253054963,-0.02108011954863498
398.6000000000049,45.44128004645344,-0.3273935869932055,-0.02174016359377884
399.70000000000493,45.54861133266391,-0.3294700181739183,-0.02174120958703707
400.80000000000496,45.65531715217262,-0.32703980798620436,-0.023044592550705456
401.900000000005,45.762586420090116,-0.3262186348814644,-0.021676567674654645
403.000000000005,45.87010740564928,-0.3243346451277112,-0.02174352363009424
404.100000000005,45.97773850390659,-0.32413585657920146,-0.023050170547724402
405.20000000000505,46.083847464076285,-0.324215301255259,-0.02305057869416638
406.30000000000507,46.19095573831457,-0.3216611175244943,-0.021779013269366043
407.4000000000051,46.29834209667211,-0.3196467689899684,-0.023050083120900844
408.50000000000506,46.40573683926652,-0.3174565785043152,-0.0217151118203871
409.6000000000051,46.511527535096505,-0.315506654664605,-0.023049999396777654
410.7000000000051,46.6199991252537,-0.31514997665101574,-0.02362425802899759
411.8000000000051,46.72713878506001,-0.3150411986172337,-0.0227226576796955
412.90000000000515,46.83442084844194,-0.31355950761141393,-0.022720193024499125
414.0000000000052,46.942394294763275,-0.3135408690587796,-0.02376499467076565
415.1000000000052,47.04903353253988,-0.3129387725559249,-0.02401039763334678
416.20000000000516,47.15651746238126,-0.31008221861030977,-0.02364850603944957
417.3000000000052,47.26369404321936,-0.307848620549279,-0.023684894638775766
418.4000000000052,47.37069319289836,-0.30880845878391905,-0.023654636393764417
419.50000000000523,47.47869862598658,-0.3077539864360356,-0.0247010417886373
420.60000000000525,47.58585583458297,-0.3074054474694283,-0.024699883997987726
421.7000000000053,47.69394538586412,-0.3061349115469876,-0.024699884000002115
422.8000000000053,47.8000011859982,-0.30364994502260423,-0.024699880129422702
423.9000000000053,47.90807645007609,-0.30354110250189514,-0.023396841883434938
425.00000000000534,48.01641980337828,-0.30101332446792445,-0.02470022430507468
426.1000000000053,48.121830874257505,-0.3003347281590355,-0.026021035659737013
427.20000000000533,48.23167753228717,-0.3004761360999768,-0.02469995916112433
428.30000000000535,48.33803945097042,-0.29984915406510043,-0.024699976000006618
429.4000000000054,48.44538082701896,-0.29825254880960306,-0.02469997591378581
430.5000000000054,48.55370974617121,-0.29897840355694927,-0.024674173234175978
431.6000000000054,48.66082471768967,-0.29911625665970654,-0.02733005548579248
432.70000000000545,48.76832869726119,-0.2978577613217636,-0.025988612326985905
433.8000000000054,48.875861142058625,-0.29645387719380545,-0.025021807023435816
434.90000000000543,48.98367727222561,-0.2946155734329944,-0.026340044547565444
436.00000000000546,49.09135460197753,-0.29536053195967493,-0.026340042999995372
437.1000000000055,49.19802863307585,-0.2907011729437051,-0.026340034823214342
438.2000000000055,49.30589304171281,-0.29119276301990293,-0.025030686641890565
439.3000000000055,49.414082836105244,-0.2891839390189788,-0.025018415842890995
440.40000000000555,49.522217582367276,-0.2880496254105043,-0.0263400418827211
441.50000000000557,49.62846696752202,-0.28808614163378,-0.02600780129084601
442.6000000000056,49.736979943249686,-0.28646923246399303,-0.025653334663852778
443.70000000000556,49.8447581715336,-0.2841851315898396,-0.025680027072338074
444.8000000000056,49.95223327348741,-0.2841754210369325,-0.02700307498994281
445.9000000000056,50.059801603397794,-0.2824964905803967,-0.027000134995455838
447.0000000000056,50.16716318406239,-0.28159486471183914,-0.025917890202272087
448.10000000000565,50.27524742194296,-0.2773331675904772,-0.02831220285263747
449.2000000000057,50.382839281397644,-0.2771840008513166,-0.027000133848275265
450.3000000000057,50.49031076505768,-0.27532740760189295,-0.027021155418244902
451.40000000000566,50.59765537347106,-0.2748949356187233,-0.028320263195689144
452.5000000000057,50.705921823892446,-0.2719466199384568,-0.027000701886789713
453.6000000000057,50.81412107949151,-0.2706789748388862,-0.027330170378385255
454.70000000000573,50.92155368613703,-0.2695916746216168,-0.02733015799999583
455.80000000000575,51.02969538656123,-0.2668924027347475,-0.02733015800001537
456.9000000000058,51.13762563913092,-0.2636634888379318,-0.027330125154498397
458.0000000000058,51.2453888334296,-0.26394010644519317,-0.026335189474524512
459.1000000000058,51.35302746324165,-0.2616678629346962,-0.026488367758697784
460.20000000000584,51.46040167109644,-0.2600897429215505,-0.026350007118633556
461.3000000000058,51.568173025305065,-0.25782557574056353,-0.027010172121642917
462.40000000000583,51.67695909744356,-0.2561868415061288,-0.02701122542911394
463.50000000000585,51.78454417042665,-0.25323009639723076,-0.027009955033704625
464.6000000000059,51.892028545433774,-0.25187833984486674,-0.028329846822297444
465.7000000000059,52.00071278060206,-0.24931629248518447,-0.026897613657764108
466.8000000000059,52.10840498422561,-0.2481397588881181,-0.02898473996605677
467.90000000000595,52.21503384976828,-0.24651760753952487,-0.02898989498384985
469.0000000000059,52.323726896419664,-0.2436731169248328,-0.02873052618086991
470.10000000000593,52.43205192327763,-0.2405397569802648,-0.028332073096598798
471.20000000000596,52.53999895277421,-0.2405800237970698,-0.028329917999915022
472.300000000006,52.64814080569711,-0.23816905245031547,-0.028879838089036713
473.400000000006,52.75616420484558,-0.23680760559025937,-0.0289899641279745
474.500000000006,52.863689201392475,-0.2351958694398938,-0.028990374918481
475.60000000000605,52.97199745527734,-0.23348547637175743,-0.029642097593681083
476.70000000000607,53.07980396903227,-0.2312689359056267,-0.02963998500006859
477.8000000000061,53.18853229716369,-0.22956742892325427,-0.029640004050116797
478.90000000000606,53.29666192646336,-0.22904356430868658,-0.02931125098493892
480.0000000000061,53.40373581218707,-0.22578937118228265,-0.029315630019784322
481.1000000000061,53.51203662002339,-0.22566250975855168,-0.029310076997606682
482.2000000000061,53.62082573003429,-0.22340921712397208,-0.02931013610902866
483.30000000000615,53.72859327157546,-0.22013493031585768,-0.028320062850550443
484.4000000000062,53.83700776114961,-0.21938355530568948,-0.02843942345297057
485.5000000000062,53.94582974835508,-0.21918305128911278,-0.03063009936507699
486.60000000000616,54.054967699110705,-0.21678221438660458,-0.030630080193736475
487.7000000000062,54.161736326683595,-0.21492994993778172,-0.02931020628026415
488.8000000000062,54.27000089941179,-0.2139199602449619,-0.029310099999924066
489.90000000000623,54.37969500679744,-0.21455491880544503,-0.029310099700484038
491.00000000000625,54.487825936857455,-0.21231549489892523,-0.030231036126549427
492.1000000000063,54.59556964444952,-0.21087365303434247,-0.03030001465306409
493.2000000000063,54.703708206245594,-0.20798813815365352,-0.030630155266385017
494.3000000000063,54.812594955170226,-0.20719186940820422,-0.03063897346450206
495.40000000000634,54.92108395107435,-0.20569486246241267,-0.03128978741799937
496.5000000000063,55.0300000000006,-0.20412000000003425,-0.029969961807989165
497.60000000000633,55.13729141078853,-0.2025045753467377,-0.029969836999947486
498.70000000000636,55.24603542446075,-0.2008595530533766,-0.029969837073391403
499.8000000000064,55.354683373375764,-0.1995911744973159,-0.02931154020753457
500.9000000000064,55.462518145224365,-0.19833267686781197,-0.029319823525554956
502.0000000000064,55.570996222876204,-0.19510958127017244,-0.0313360899767976
503.10000000000645,55.679291522515435,-0.19309239009928236,-0.031289880766037115
504.2000000000064,55.78714435037486,-0.1934181206602109,-0.032272146887001085
505.30000000000643,55.89623640235592,-0.19057469623397089,-0.030959963018198255
506.40000000000646,56.004463108966526,-0.1902302799752407,-0.03227262798539554
507.5000000000065,56.112688148929855,-0.1895920000762752,-0.030959898574739686
508.6000000000065,56.22133461730797,-0.1878571531459491,-0.03128459667879202
509.7000000000065,56.3299990411259,-0.1860700132501459,-0.03194995158050773
510.80000000000655,56.43699700723927,-0.18388857690559438,-0.03261026781790122
511.90000000000657,56.54668979659061,-0.18277526211905631,-0.03261004199987472
513.0000000000066,56.65520160207021,-0.18116345885617577,-0.03261004199945461
514.1000000000065,56.76335656779932,-0.17826104151971278,-0.03261082671830895
515.2000000000066,56.87193266130011,-0.17513557125713228,-0.03264329545180322
516.3000000000065,56.98121518827362,-0.17508391355591324,-0.03323707662243436
517.4000000000067,57.08960846523422,-0.17214596759065187,-0.03260697065778562
518.5000000000066,57.19798288414468,-0.17159653911360506,-0.03293126591590534
519.6000000000067,57.30618937202144,-0.16855238981688606,-0.032940134008541566
520.7000000000066,57.41431484471376,-0.16668057408430317,-0.032940680301203784
521.8000000000067,57.52366056767229,-0.16604952455148866,-0.03128498898414778
522.9000000000067,57.63176050989431,-0.16506884781655498,-0.03129013397547853
524.0000000000067,57.740595147201866,-0.16286753180472804,-0.031310218901416054
525.1000000000067,57.849087474549236,-0.1608348660419462,-0.03260982524640754
526.2000000000068,57.95640494443553,-0.15909686918962723,-0.032609825000009085
527.3000000000068,58.06662292073173,-0.15828793624873203,-0.03260980654126877
528.4000000000068,58.17517055521894,-0.15586655677687747,-0.033922625800250295
529.5000000000068,58.28440102579292,-0.15303744841367925,-0.03259989199860769
530.6000000000068,58.392725665752785,-0.15330044897440315,-0.03391982293952367
531.7000000000069,58.50119859936279,-0.15162402516721932,-0.03156967464393379
532.8000000000068,58.610287029055456,-0.14932645416383314,-0.03227339672356688
533.9000000000069,58.7186966397012,-0.14836396488629805,-0.03425508351418438
535.0000000000068,58.82741089751641,-0.14860429347409082,-0.0329302984372033
536.100000000007,58.93374034109901,-0.14817516939271846,-0.03424965691137993
537.2000000000069,59.04504900013539,-0.14568401346695956,-0.034250288228588666
538.300000000007,59.15281095116156,-0.14384838148821213,-0.03293071552713567
539.4000000000069,59.261807493696175,-0.141056287238193,-0.03310796536757232
540.5000000000069,59.371426456631745,-0.1404512409327612,-0.032940007103977376
541.600000000007,59.4794174539687,-0.1385416366509563,-0.032940007131163185
542.700000000007,59.58778544364418,-0.13792856489508096,-0.03417276430590688
543.800000000007,59.69705692256134,-0.13763170731520893,-0.034260098941830464
544.900000000007,59.805486232134484,-0.13455001550917495,-0.034612108560689414
546.000000000007,59.914259722153616,-0.1352812383821508,-0.03524009903144654
547.1000000000071,60.02213806630964,-0.13216608228405818,-0.03392198419782666
548.2000000000071,60.13252154360239,-0.13232230841964063,-0.035247310911019625
549.300000000007,60.24187604011714,-0.1303577963605423,-0.035240165997093786
550.4000000000071,60.35058437125692,-0.12859171693686516,-0.035240165904309784
551.500000000007,60.45950628252798,-0.1280996643290465,-0.03390707103304802
552.6000000000072,60.569458382304184,-0.12800465994489185,-0.03520627969565693
553.7000000000071,60.678078642021816,-0.12456535960670953,-0.036232610158300815
554.8000000000072,60.78627961191634,-0.12255734789337328,-0.034783149975513794
555.9000000000071,60.89592764953416,-0.12139820959081526,-0.03490080218170366
557.0000000000072,61.005112196098096,-0.12138170371748057,-0.03623376547637891
558.1000000000072,61.11452969417517,-0.12050807459024349,-0.035768323745409614
559.2000000000072,61.22364193659352,-0.11883340650400931,-0.03506482666171351
560.3000000000072,61.33280101033706,-0.11738125446578793,-0.034809158061323675
561.4000000000073,61.44197452151866,-0.11600481852133188,-0.035900126126859
562.5000000000073,61.55093970555728,-0.11485235635001215,-0.035899948044826324
563.6000000000073,61.66028818043835,-0.11197462991396992,-0.03523830326299526
564.7000000000073,61.77093371547334,-0.10996446151876033,-0.03655953551001678
565.8000000000073,61.880000959233286,-0.10849006706438476,-0.036230018312491286
566.9000000000074,61.98834084377191,-0.10876477075130218,-0.035567410670872324
568.0000000000074,62.098339560662176,-0.10650583430112413,-0.03655981631633942
569.1000000000074,62.206988633150495,-0.10458543257214116,-0.03787014290236712
570.2000000000073,62.31716573301867,-0.10252752966787745,-0.03687991058124185
571.3000000000073,62.42573692140157,-0.10018740855357815,-0.03655729758023263
572.4000000000074,62.534683103614036,-0.09693159488171167,-0.037852868625567915
573.5000000000074,62.64414640865284,-0.09750001903602207,-0.0378701207163612
574.6000000000074,62.753077819983126,-0.09508803988616958,-0.039190291570579294
575.7000000000074,62.8632740175441,-0.09400617269360931,-0.03721859714291531
576.8000000000075,62.97220787408981,-0.0951426963526865,-0.037507738462540186
577.9000000000075,63.080115031997394,-0.09163943772265715,-0.037870226906278504
579.0000000000075,63.190582757204744,-0.08915729715015303,-0.03788001858431045
580.1000000000075,63.30000208795636,-0.08832152565047174,-0.038869960022962946
581.2000000000075,63.40949573739617,-0.08506709103144826,-0.0388699600060991
582.3000000000076,63.51752107223568,-0.08096110902159534,-0.038862623017748454
583.4000000000076,63.627756107770026,-0.0784647629324589,-0.037879964402723676
584.5000000000076,63.73752282499955,-0.07688994120377039,-0.03787697963573544
585.6000000000076,63.84713925867532,-0.07608518015525716,-0.039190061502233586
586.7000000000077,63.955907320627624,-0.07459230410792982,-0.0391900507312406
587.8000000000077,64.06561287499721,-0.07222259523166802,-0.04017287331645525
588.9000000000076,64.17581166043688,-0.0715377691220637,-0.04050933021223724
590.0000000000076,64.28404251312769,-0.06980345537272087,-0.03985049229385185
591.1000000000076,64.39351721034123,-0.06968412896802414,-0.03918789666400002
592.2000000000077,64.50346978037365,-0.06903482576108486,-0.040844014884568125
593.3000000000077,64.61238628518889,-0.06450195792941865,-0.04216030884480704
594.4000000000077,64.7201821142918,-0.0636905312980006,-0.040179735256585136
595.5000000000077,64.83107473052446,-0.06303299236232414,-0.04076964222939461
596.6000000000078,64.94098614609536,-0.06407585850978273,-0.04089057444944899
597.7000000000078,65.05023964528343,-0.063687768918914,-0.041499925776573576
598.8000000000078,65.15973847996622,-0.06593590506254161,-0.040184971297536176
599.9000000000078,65.26828015628485,-0.06652725438468728,-0.04214945508358037
601.0000000000078,65.37790735767022,-0.06855008752084839,-0.04332167606197146
602.1000000000079,65.48838255255397,-0.06778201211664933,-0.043472749924273746
603.2000000000079,65.59612498063414,-0.06870778009960715,-0.042155751119659524
604.3000000000079,65.70653320569842,-0.06804815675572437,-0.043480140827092395
605.4000000000078,65.8167337966936,-0.06727739793168398,-0.04348012999999318
606.5000000000078,65.92559025162147,-0.06731473575621981,-0.043480129999672545
607.6000000000079,66.03508034471787,-0.06628149045106374,-0.04348070020290562
608.7000000000079,66.14242565725435,-0.06536367243780808,-0.043810163465072716
609.8000000000079,66.2539226760267,-0.06266071502397401,-0.043614536522738945
610.9000000000079,66.36316165431205,-0.06246521225033953,-0.042490153202561665
612.000000000008,66.47287424642872,-0.06175599014227207,-0.04353212499950754
613.100000000008,66.58211285626611,-0.05926903841269849,-0.0434798236312286
614.200000000008,66.69245979574278,-0.059578033459709794,-0.04478149074157223
615.300000000008,66.80175982161938,-0.057429262734524276,-0.04347170521076649
616.400000000008,66.90936189169406,-0.05746807238915328,-0.044624646048689875
617.5000000000081,67.02114801934654,-0.0542896413196109,-0.04480702903000999
618.6000000000081,67.130772792183,-0.05315789631371934,-0.04544390244870522
619.7000000000081,67.240272111704,-0.05019882503093303,-0.04545002978070389
620.8000000000081,67.34900506981604,-0.04895410429699559,-0.044132951334532766
621.9000000000082,67.45873546002395,-0.046730169221577106,-0.04412986420128995
623.0000000000082,67.56904711999184,-0.04720545267070728,-0.044130885323851565
624.1000000000081,67.68103332060187,-0.043216591519547654,-0.04274320466188275
625.2000000000081,67.79020425825395,-0.04382189865454082,-0.04412980567707203
626.3000000000081,67.89921635528081,-0.040382675025827604,-0.04413002813318556
627.4000000000082,68.00988632921326,-0.04016682271345643,-0.04511439869249756
628.5000000000082,68.11930363948157,-0.03794371214982976,-0.04481610503840994
629.6000000000082,68.22980940719269,-0.03575455245321618,-0.04348007615753868
630.7000000000082,68.34010902471789,-0.035782729982131306,-0.0448005634770654
631.8000000000083,68.44886258945007,-0.03362717664406395,-0.044800164002579024
632.9000000000083,68.55980846010722,-0.031340672571356726,-0.0447974619542304
634.0000000000083,68.66923736109383,-0.027425789850491378,-0.04447124135740932
635.1000000000083,68.7797916331368,-0.026082814231906767,-0.045779880557872854
636.2000000000083,68.88835112111302,-0.02544213471721379,-0.04640439866216495
637.3000000000084,68.99891823427694,-0.02441909495021773,-0.047429903515856964
638.4000000000084,69.10777618949461,-0.02082161827338281,-0.04742992199813756
639.5000000000084,69.21743286857833,-0.020883310616086868,-0.04743510281385532
640.6000000000083,69.32751927388972,-0.018777405238662687,-0.04610992130834646
641.7000000000083,69.43684713221745,-0.01779202349131808,-0.0461099220000003
642.8000000000084,69.54732587521694,-0.015195675650491144,-0.046109921995311165
643.9000000000084,69.65741053090122,-0.015102891932823959,-0.04611928878790028
645.0000000000084,69.76687604571308,-0.01569104708608304,-0.04742073790909718
646.1000000000084,69.8760623832,-0.013882687286154782,-0.046110779014316705
647.2000000000085,69.9864506379834,-0.01427316070666602,-0.046727100112072595
648.3000000000085,70.09619388117326,-0.013368010981185003,-0.04743030078480315
649.4000000000085,70.2057123541815,-0.010070111781033201,-0.04743010615586574
650.5000000000085,70.3161137777559,-0.01002381899100822,-0.047981726277760206
651.6000000000085,70.42372214956067,-0.0082597175457488,-0.04873501744300368
652.7000000000086,70.53568081567241,-0.006596652707289744,-0.048410539494857296
653.8000000000086,70.64523129601943,-0.006185514475547113,-0.04741969973097593
654.9000000000086,70.75331275763668,-0.0030336214183986727,-0.04758083626356768
656.0000000000086,70.86461483447988,-0.0009065378245043981,-0.048739020418151924
657.1000000000087,70.97367884528038,0.00034416719362945864,-0.04611149784456048
658.2000000000087,71.08426002834018,0.0008587636327357558,-0.04611017286567343
659.3000000000086,71.19283208954242,0.0042482249315442195,-0.046287360270964584
660.4000000000086,71.30493258181247,0.005784993315329077,-0.04742986467693777
661.5000000000086,71.41514951684798,0.00809538228157694,-0.04743047467043837
662.6000000000087,71.52448237984275,0.011077317800335598,-0.04610999008066141
663.7000000000087,71.63286560275365,0.012542201304745598,-0.047106879493760356
664.8000000000087,71.74467234179086,0.013400161028647528,-0.04742996144452771
665.9000000000087,71.85420483031614,0.015481718184202214,-0.04873619031338139
667.0000000000088,71.96544593220688,0.017312946076000823,-0.04756903351403485
668.1000000000088,72.07525473231944,0.01899553885576486,-0.04677000387923469
669.2000000000088,72.18466855975036,0.02001611733170252,-0.04798839221244089
670.3000000000088,72.29583197299235,0.021301983395421623,-0.04808006902013817
671.4000000000088,72.40587342143216,0.02301711974121355,-0.0480800690000005
672.5000000000089,72.51687879993587,0.02866038816860149,-0.048080068999921455
673.6000000000089,72.6237384117035,0.028719782700049552,-0.04808019045719503
674.7000000000089,72.7366288985426,0.032959486130499635,-0.049400144817291824
675.8000000000088,72.84731841302244,0.035760226548322734,-0.04841562963916557
676.9000000000088,72.95720660870134,0.03908497662371221,-0.04940060592693829
678.0000000000089,73.06738201978712,0.04296291259824627,-0.049400389364541386
679.1000000000089,73.17725076428938,0.046975185997350594,-0.04808985863879389
680.2000000000089,73.28693354370128,0.04907735720703767,-0.0493990372155384
681.3000000000089,73.39817379792767,0.05236735770185487,-0.04991793069880934
682.400000000009,73.50832157995848,0.056044695702780256,-0.04940994398523779
683.500000000009,73.61792855360005,0.058217459378288774,-0.049409944000000205
684.600000000009,73.72841929952374,0.061958836227290114,-0.049409944000001094
685.700000000009,73.83841281953413,0.06426452866270983,-0.04940994399815146
686.800000000009,73.94843898072466,0.06736718463412819,-0.0494142543326439
687.9000000000091,74.05818712388962,0.06985080432328765,-0.049729689283454004
689.0000000000091,74.16820803945039,0.07617327824661989,-0.04972759169844654
690.1000000000091,74.27804670611648,0.0819886732905147,-0.05006005237039313
691.2000000000091,74.38763654604763,0.08722328033165788,-0.04940002753777151
692.3000000000092,74.49780210048043,0.09190844068527626,-0.04939459064946039
693.4000000000092,74.60841943722811,0.09586111165339217,-0.05072303896445396
694.5000000000091,74.71685816589519,0.09924761128153965,-0.04940010297104269
695.6000000000091,74.8279199657811,0.10141786580079942,-0.049408630824456345
696.7000000000091,74.93770688906785,0.10526911086251463,-0.05006012783312208
697.8000000000092,75.04796995646731,0.11208840122761528,-0.05006026160596333
698.9000000000092,75.1577326928647,0.11794222936022805,-0.050720379922962966
700.0000000000092,75.26867775677752,0.12462693329556619,-0.04940020882530449
701.1000000000092,75.37832768681106,0.1315848097949158,-0.050722035369873186
702.2000000000093,75.48720084240654,0.13348952924263116,-0.050719885998300906
703.3000000000093,75.598473625464,0.13643684411693913,-0.0507199279392343
704.4000000000093,75.70953013056925,0.1392297048139058,-0.05202994099673397
705.5000000000093,75.8188999263204,0.14374045503181546,-0.05127083386403708
706.6000000000093,75.93105100907924,0.14428901123338655,-0.05071995294199727
707.7000000000094,76.04079447494946,0.14730264212082742,-0.05071995300002463
708.8000000000094,76.15102336509611,0.14896374748593422,-0.05071988915893977
709.9000000000094,76.26228662630378,0.1526988615791877,-0.05039227441418781
711.0000000000093,76.37168587208237,0.15631229564318241,-0.05038309270295249
712.1000000000093,76.48223949273176,0.1578656564200431,-0.049105268450821526
713.2000000000094,76.593314504185,0.1617673095244615,-0.05169578567901256
714.3000000000094,76.70328368988335,0.16385056921626578,-0.05171013738143415
715.4000000000094,76.81404263294725,0.16510207595856616,-0.050650919118165216
716.5000000000094,76.92520187865263,0.16605546528816154,-0.05072013703134415
717.6000000000095,77.03462494906584,0.1695551274494695,-0.05072013699829947
718.7000000000095,77.14639086069423,0.17027100220743038,-0.05072400056005888
719.8000000000095,77.25458432436132,0.16991487481757833,-0.05203912853694348
720.9000000000095,77.36671295301421,0.1710652579829356,-0.05171045102469751
722.0000000000095,77.47714551598804,0.17153589477094294,-0.05039982742657889
723.1000000000096,77.58769410029491,0.17194506759965825,-0.05039982799999887
724.2000000000096,77.69753070986134,0.172747177101254,-0.05039982800028575
725.3000000000096,77.80781140141734,0.172667320152473,-0.050399285672912075
726.4000000000096,77.91916165020618,0.1742061119001242,-0.050389903551875115
727.5000000000097,78.02888747021197,0.1727364964957893,-0.0503898949999968
728.6000000000097,78.14000205560808,0.17401031969219638,-0.05038989268364702
729.7000000000096,78.24977946529941,0.177820771930835,-0.049069770836122295
730.8000000000096,78.35979072221127,0.17900233060130238,-0.05038889400054947
731.9000000000096,78.47039987239368,0.1798878606998645,-0.05236987660613934
733.0000000000097,78.58152683359218,0.17757484212144584,-0.050408383588592454
734.1000000000097,78.69154005440359,0.1779322662072401,-0.05039000998584919
735.2000000000097,78.80133596626601,0.17621479092931117,-0.05039001000000187
736.3000000000097,78.91245087486685,0.1784916395143151,-0.05039000803578686
737.4000000000098,79.02258033414084,0.17730017835604192,-0.05304156831502427
738.5000000000098,79.13136487499538,0.17697831211469478,-0.05170840192859405
739.6000000000098,79.24406467111223,0.17858477815227855,-0.050390124006945314
740.7000000000098,79.35372341409456,0.1779532728785972,-0.05170317611825492
741.8000000000098,79.46457966085705,0.17665341976081936,-0.0517001689982477
742.9000000000099,79.57462208764427,0.17741573387637752,-0.051700195715242536
744.0000000000099,79.6860303937272,0.17612826150741695,-0.05145415386866459
745.1000000000099,79.7963637761426,0.1778151683154495,-0.05170232220490778
746.2000000000098,79.90770304183232,0.18016875666099835,-0.05104969729305742
747.0000000000099,79.98768556272539,0.1822642964439901,-0.0517040989483637