File: 01_Data/Mineral_Wool_Insulation/STA/N2/10K_min/Mineral_Wool_Insulation_STA_N2_10KData_221107_R1.csv
##Temp./Â°C,Time/min,DSC/(mW/mg),Mass loss/mg
51.0,10.73550843981569,-1.6756533324893628,-0.030695109910062968
52.100000000000016,11.122709865973395,-1.5654291082731433,-0.0280228465904937
53.20000000000003,11.368618216403323,-1.4968150578598174,-0.02958792441356284
54.30000000000005,11.57234178600993,-1.4432713404968414,-0.03264752010310534
55.40000000000006,11.765577296693133,-1.3998295397320673,-0.02807321124956008
56.50000000000008,11.936411292688087,-1.3655006659370943,-0.027654483642843175
57.600000000000094,12.094147993656705,-1.33791219047898,-0.028856851927741012
58.70000000000011,12.253189723900043,-1.3122794667287276,-0.029194166281409473
59.800000000000125,12.400359177458888,-1.290754415394941,-0.029172932585794342
60.90000000000014,12.54758650863938,-1.27342926398414,-0.02703181800194887
62.000000000000156,12.691896926363889,-1.255182195948014,-0.029442927886514703
63.10000000000017,12.830590525299616,-1.2409315297849066,-0.03171696011456149
64.20000000000019,12.967095897716291,-1.2255939196916739,-0.03213359310262209
65.30000000000021,13.103461946173134,-1.2115040469266085,-0.031011991435723196
66.40000000000022,13.234883706814776,-1.197949776809518,-0.029237369471003305
67.50000000000023,13.366772882311285,-1.186588629433293,-0.030896508308261517
68.60000000000025,13.495617565647406,-1.1738796408227823,-0.032249266308351565
69.70000000000027,13.62378924283961,-1.1624166748622355,-0.03100663772989165
70.80000000000028,13.752486474724705,-1.1507303339928345,-0.03241162180541757
71.90000000000029,13.876758138191423,-1.140796650595761,-0.03121854511780775
73.00000000000031,14.002120105644618,-1.1288642972288194,-0.03307239978366461
74.10000000000034,14.124783648304252,-1.1169516270570377,-0.03264217204177822
75.20000000000034,14.246467367067504,-1.10761711433161,-0.035060835263180934
76.30000000000035,14.368489224000957,-1.0972840358398421,-0.03498075697380898
77.40000000000038,14.488217564986309,-1.0878056797443945,-0.03495279328961676
78.5000000000004,14.60938627576566,-1.077689395168819,-0.03515810263452579
79.6000000000004,14.727518259933209,-1.0670789075701257,-0.03524813972029062
80.70000000000041,14.846027548289825,-1.0588566253025082,-0.0351429308167468
81.80000000000044,14.962503047706162,-1.0499296466645036,-0.03514021481306617
82.90000000000046,15.08041964574961,-1.041131445837784,-0.03638553762541452
84.00000000000047,15.19625318359447,-1.033163859503588,-0.035140793252718794
85.10000000000048,15.312380097930362,-1.0248833588342816,-0.03545372575120176
86.2000000000005,15.427028822551357,-1.017176668223901,-0.03642131585181918
87.30000000000052,15.540536909851664,-1.0092287014786547,-0.03693683273034587
88.40000000000053,15.65439431580861,-1.0027380941178756,-0.03645304664095317
89.50000000000054,15.769170000000061,-0.9955799999999968,-0.037768033371941456
90.60000000000056,15.881360740184917,-0.9879217524851188,-0.038181246207662944
91.70000000000059,15.993640496884288,-0.9809565654836927,-0.03908994173973568
92.8000000000006,16.103446189220936,-0.9740915682733625,-0.039091064468443015
93.9000000000006,16.21673729994004,-0.9686624948410746,-0.0391218949219887
95.00000000000063,16.327836544139593,-0.9619715825418955,-0.03908269388132357
96.10000000000065,16.437407327319804,-0.9560353545683324,-0.04040157410723655
97.20000000000066,16.549651027498072,-0.9477672514126639,-0.041743589117975155
98.30000000000067,16.658800987612494,-0.9409952563881049,-0.04094151587621386
99.40000000000069,16.76810109282173,-0.9362128428898008,-0.043045041458393385
100.50000000000071,16.877379180203697,-0.9296542885298277,-0.0430446934301596
101.60000000000072,16.987138173972564,-0.9243353314799896,-0.04271477768014709
102.70000000000073,17.09467651038504,-0.9191057987703127,-0.04433851966408309
103.80000000000075,17.20357139468052,-0.9124297309965992,-0.04302953692733169
104.90000000000077,17.308391295681943,-0.9080286120069591,-0.044137598613944284
106.00000000000078,17.41979108600545,-0.901222313686828,-0.044363114446421825
107.10000000000079,17.529813076060535,-0.8966254361762617,-0.044355874452532085
108.20000000000081,17.6352282146226,-0.8917451502640447,-0.04435895786681332
109.30000000000084,17.745435373493997,-0.8861682487848559,-0.04695536667037281
110.40000000000084,17.85099618559624,-0.8807937702177875,-0.045678686784017764
111.50000000000085,17.959170000000086,-0.8769199999999954,-0.046259402439093655
112.60000000000088,18.066894194468823,-0.8716364229631038,-0.046988413570639764
113.7000000000009,18.174289035627773,-0.8659587120555063,-0.047077492028308576
114.8000000000009,18.281427067887204,-0.8622145396120583,-0.04688914789826004
115.90000000000092,18.38868705750848,-0.8562807379680902,-0.04829851241509253
117.00000000000094,18.496146130193573,-0.8524237632412329,-0.04831005110558184
118.10000000000096,18.60409974158889,-0.8472089440136128,-0.048306942107663176
119.20000000000097,18.71087851648378,-0.8436948814721921,-0.049630553510700004
120.30000000000098,18.818617602036856,-0.838415107805552,-0.049343900666615426
121.400000000001,18.925181729714186,-0.8341873300371857,-0.04956743223614346
122.50000000000102,19.03181894368867,-0.8302382498309788,-0.04963157571228827
123.60000000000103,19.13877271973442,-0.8261015232178749,-0.050949778394906
124.70000000000104,19.245291380329075,-0.8214225828947064,-0.04998992502143729
125.80000000000106,19.35153571792737,-0.8178755876841297,-0.04962995709068707
126.90000000000109,19.459170000000107,-0.8139300000000037,-0.05094740631542205
128.00000000000108,19.565521047823765,-0.8092914157016814,-0.05093939821455784
129.1000000000011,19.670703371145827,-0.8055608205046151,-0.05219727818225284
130.20000000000113,19.778591164595554,-0.8025133526016751,-0.05093998570599556
131.30000000000115,19.883478978625565,-0.7992437619756865,-0.05130358132215829
132.40000000000117,19.990719395047037,-0.7971806363853192,-0.05227530830381166
133.50000000000117,20.09616769959786,-0.792362102060926,-0.053473281900557446
134.6000000000012,20.200869059740327,-0.7890606549963767,-0.05358246768511066
135.7000000000012,20.306875230247208,-0.7864382329737443,-0.0542399596217793
136.8000000000012,20.412053254830756,-0.7812215602253618,-0.05488272004961381
137.90000000000123,20.518775717736904,-0.7783720843105837,-0.056219728405968006
139.00000000000125,20.624092342928957,-0.7753163616728449,-0.05490380225184044
140.10000000000127,20.729669478636747,-0.7713773035546958,-0.053583617533671024
141.2000000000013,20.83469291364279,-0.7694434099766216,-0.05358015147321016
142.3000000000013,20.939940704196097,-0.7660259691530852,-0.05488514726364535
143.4000000000013,21.04469846418753,-0.7629597443476199,-0.05526415390112582
144.50000000000134,21.14836580502673,-0.759783739081951,-0.05495208249545769
145.60000000000133,21.253301712533965,-0.7558253425726902,-0.055617794908945584
146.70000000000135,21.357947117492344,-0.7526900658129777,-0.056224029058199676
147.80000000000138,21.463307751187113,-0.7485514947292076,-0.056534961919912696
148.9000000000014,21.568709985449185,-0.746111052751064,-0.05654009215359679
150.00000000000142,21.672813312468595,-0.7427954210945641,-0.057853180208812915
151.10000000000142,21.778251880919516,-0.7384764460300707,-0.058160823249663096
152.20000000000144,21.882787694253867,-0.7354842216312292,-0.05949889880962811
153.30000000000146,21.98730150790084,-0.7337522563539236,-0.059848030978504774
154.40000000000146,22.091943211222947,-0.7302097726480425,-0.059203891542628284
155.50000000000148,22.196645769009187,-0.7269355604582927,-0.05883716696674224
156.6000000000015,22.299989454613023,-0.7238031071374464,-0.0588430372363824
157.70000000000152,22.404894087400983,-0.7221293618417589,-0.06023334447070994
158.80000000000155,22.510938218678923,-0.718014704573607,-0.06015621797396786
159.90000000000154,22.614513905696864,-0.7155871751862413,-0.06015997199244261
161.00000000000156,22.719170000000137,-0.7128199999999968,-0.060159971999756756
162.1000000000016,22.823142683782834,-0.7092295628069516,-0.059731719626967994
163.20000000000158,22.92805561397224,-0.7068896060869267,-0.06047908065993646
164.3000000000016,23.032385954339773,-0.7035658777633504,-0.06021126985072911
165.40000000000163,23.1366381701233,-0.7015493219297304,-0.06012635681930334
166.50000000000165,23.241547806180385,-0.6978565499130036,-0.061270070463908866
167.60000000000167,23.34651086879636,-0.6951348280300036,-0.06257202037871856
168.70000000000167,23.449480095657112,-0.6934049035151133,-0.06157308746564194
169.8000000000017,23.556449662957405,-0.6896991296869592,-0.06260911372721623
170.9000000000017,23.661117107454913,-0.6870158283755856,-0.062250010593245086
172.0000000000017,23.765310416603477,-0.6838623682150385,-0.062267282196721396
173.10000000000173,23.869074295812997,-0.6806464764678588,-0.062250197035438326
174.20000000000175,23.975060301681502,-0.6762727540217406,-0.06357624935108142
175.30000000000177,24.078909348010836,-0.6734881369867319,-0.062249828829335385
176.4000000000018,24.184063650098427,-0.6714333063145198,-0.06383179430354602
177.5000000000018,24.288261789481894,-0.6695490062398082,-0.06454982405233611
178.6000000000018,24.392251527708257,-0.6671735925509534,-0.06360278465884406
179.70000000000184,24.497312608481934,-0.6636341091730337,-0.06356591832748659
180.80000000000183,24.601609492481632,-0.6605480224236584,-0.06455864970703029
181.90000000000185,24.704409342440776,-0.6584697699093195,-0.06456740556341956
183.00000000000188,24.80993402821653,-0.6572423374140659,-0.06456020101682203
184.1000000000019,24.913609284630297,-0.6550130594795087,-0.06453863162396356
185.20000000000192,25.01867423459773,-0.6504971274951881,-0.06619941003528762
186.30000000000192,25.1205703869268,-0.6481696612158561,-0.06718970075098696
187.40000000000194,25.226106096851098,-0.6453391419801903,-0.06587045822764015
188.50000000000196,25.330939361155057,-0.6413180153558923,-0.06630786014959256
189.60000000000196,25.43488783314475,-0.6380161471676761,-0.06622500861685232
190.70000000000198,25.53662165702544,-0.636362086080512,-0.06752455094485477
191.800000000002,25.64299614862696,-0.6339089514001515,-0.06751999199722825
192.90000000000202,25.746511524824307,-0.6307636580057071,-0.0675200093848689
194.00000000000205,25.850896948336814,-0.6291140334401752,-0.06620735308049053
195.10000000000204,25.95487744696208,-0.6276144538074732,-0.06744201673562689
196.20000000000206,26.059170000000194,-0.6245600000000002,-0.0675198162844719
197.3000000000021,26.163184878890537,-0.6205738436093893,-0.06752019387367536
198.40000000000208,26.267745854841202,-0.618196554743921,-0.0675197332721158
199.5000000000021,26.370827842568957,-0.6160402440052253,-0.06883993824322499
200.60000000000213,26.475922007677884,-0.6143892575787473,-0.06883995790484754
201.70000000000215,26.57694442974748,-0.6124434878222595,-0.06880028524797765
202.80000000000217,26.68379588193998,-0.6088246157948332,-0.07015586737455992
203.90000000000217,26.787539906933063,-0.6065282866495261,-0.06884004606457683
205.0000000000022,26.89191049564655,-0.6049411846901186,-0.06788937827249164
206.1000000000022,26.99575791435734,-0.6033166898915523,-0.06782370570354068
207.2000000000022,27.100688439005367,-0.5995878039458077,-0.06884004070693717
208.30000000000223,27.20463130820109,-0.5989798844865866,-0.06982982132208093
209.40000000000225,27.30835622416483,-0.5959808225310632,-0.06983590198424405
210.50000000000227,27.41233720749607,-0.592569612668968,-0.0688489960145322
211.6000000000023,27.516579963547088,-0.5906979220724019,-0.07016430656765715
212.7000000000023,27.620524355781228,-0.5871536093895104,-0.06883681566112632
213.8000000000023,27.72435204746903,-0.5853242949450258,-0.06884012198989087
214.90000000000234,27.828310060229825,-0.5830648638905277,-0.06884012199999923
216.00000000000233,27.931724349873893,-0.5803086664519411,-0.06884012037027176
217.10000000000235,28.036803481886242,-0.5795914241795068,-0.07015285035620611
218.20000000000238,28.141626660499817,-0.5771243444883253,-0.07032116793861576
219.3000000000024,28.245693351882522,-0.5756236100868192,-0.0701780962130596
220.40000000000242,28.349568319147608,-0.5730064019658172,-0.07016008703237375
221.50000000000242,28.454209518553544,-0.5706533536256896,-0.07146218816821426
222.60000000000244,28.558562662003787,-0.5684466792543457,-0.07148008799998795
223.70000000000246,28.66332086703296,-0.5673527332098509,-0.07147985323776807
224.80000000000246,28.766868559428357,-0.5639077210542006,-0.07410978114714695
225.90000000000248,28.87116612080412,-0.5623996996561419,-0.07396022480992315
227.0000000000025,28.974451219997125,-0.5593974422873327,-0.07411008709516276
228.10000000000252,29.07998309330859,-0.5581742040044659,-0.07378766970181871
229.20000000000255,29.1848695427676,-0.5569517688913518,-0.07378008797400071
230.30000000000254,29.288890203690528,-0.5543499941115666,-0.07377619681503944
231.40000000000256,29.391685168570124,-0.5537589278654358,-0.07245299916401127
232.5000000000026,29.49850478532263,-0.5516328587255832,-0.07378018643333162
233.60000000000258,29.60201946742826,-0.550185213314561,-0.07377993470487265
234.7000000000026,29.707543912235327,-0.5482662883527568,-0.0751004453490296
235.80000000000263,29.810520274234364,-0.5472301731904498,-0.07377604131659332
236.90000000000265,29.915739287381484,-0.5468502275579007,-0.07377983600018334
238.00000000000267,30.021029807774077,-0.5443631628105419,-0.0747700506082678
239.10000000000267,30.12538121128494,-0.5429589824134605,-0.07582674368603382
240.2000000000027,30.229639580671485,-0.5411024436194686,-0.07574959704743867
241.3000000000027,30.334606651113184,-0.5386111347907724,-0.07475968703828606
242.4000000000027,30.439471158906866,-0.5376949227697728,-0.07602374255712574
243.50000000000273,30.54391045766291,-0.5352443623548312,-0.07596325366244905
244.60000000000275,30.647531372773056,-0.533506675853406,-0.07607990094762362
245.70000000000277,30.75178919813711,-0.5323727075777299,-0.07606627312043646
246.8000000000028,30.856810763369676,-0.5309918926986499,-0.07347183103280752
247.9000000000028,30.96041370668747,-0.529938080260734,-0.07475505705481744
249.0000000000028,31.06597307334316,-0.5279179253567851,-0.07543312685426073
250.10000000000284,31.17071627906488,-0.5269387978978642,-0.07674990783301938
251.20000000000283,31.275247777063697,-0.5252948897456056,-0.07679334945781102
252.30000000000285,31.380466247669457,-0.522286443321649,-0.07674001585820545
253.40000000000288,31.482341841338847,-0.5207813257149302,-0.07805800285310216
254.5000000000029,31.588879043201768,-0.5193258581927124,-0.07806002099940956
255.60000000000292,31.693919594091504,-0.518293059667112,-0.07806002100000065
256.7000000000029,31.79897334327898,-0.5174178680446546,-0.0780600210000002
257.8000000000029,31.90304523336271,-0.5160005396552153,-0.07806002065344675
258.90000000000293,32.007775845569,-0.5136291491332714,-0.07916434937061334
260.00000000000296,32.113207020639095,-0.5136911160752731,-0.082231800078723
261.100000000003,32.21759196057009,-0.5113963019518817,-0.08089010278629427
262.200000000003,32.322236431749985,-0.5094856533934289,-0.07817017231199408
263.300000000003,32.42660417598985,-0.5077977105523859,-0.07817004118024418
264.40000000000305,32.5317844367687,-0.5071649682297349,-0.07751543751006551
265.50000000000307,32.63606882566954,-0.5058487170290062,-0.07616639392737667
266.6000000000031,32.740666972309754,-0.5040942506967041,-0.07620849717034384
267.7000000000031,32.84593009812321,-0.5013031431541091,-0.0788890555321502
268.8000000000031,32.95153296143707,-0.5006967019871533,-0.08013738860768171
269.9000000000031,33.05583639551374,-0.4981567002970791,-0.08043467420429584
271.0000000000031,33.16031259680583,-0.4973060215400548,-0.08013996589883465
272.10000000000315,33.2662716718271,-0.4958545215987247,-0.08013996599863571
273.2000000000032,33.36955292843485,-0.49554672114543286,-0.08014014582804974
274.30000000000314,33.47565010792548,-0.49399721422195236,-0.078816631034762
275.40000000000316,33.5794555575502,-0.49231515025252676,-0.07948555819494896
276.5000000000032,33.68376257316689,-0.49009252143480675,-0.08015007862348611
277.6000000000032,33.78884673352158,-0.48942165484234745,-0.08015011619066348
278.70000000000323,33.89336596465068,-0.48807823626933905,-0.08145851954681316
279.80000000000325,33.99881040216033,-0.48526083508641027,-0.0814601749370798
280.9000000000033,34.104069915840114,-0.4855781592346815,-0.07994521408835586
282.0000000000033,34.2081570946712,-0.484682226420799,-0.08146734248257204
283.1000000000033,34.313900662287644,-0.4819967117827025,-0.08341835195713676
284.20000000000334,34.418533312903065,-0.4808302548813191,-0.08212039720597364
285.30000000000337,34.523726571686325,-0.47981995565568136,-0.08071792575358305
286.40000000000333,34.62944303185624,-0.4784871479510231,-0.08213041307214519
287.50000000000335,34.73454232135785,-0.477448327309739,-0.08081049573175614
288.6000000000034,34.83901564771381,-0.47561363791797706,-0.0801503684976792
289.7000000000034,34.94486448401384,-0.47490944428651377,-0.08213577509634495
290.8000000000034,35.05021972232281,-0.4745902492152305,-0.0821309241206225
291.9000000000034,35.15496640546396,-0.47147815297214357,-0.08081007914746952
293.0000000000034,35.260527406877316,-0.4707216748505737,-0.08079382370199095
294.10000000000343,35.36533096584692,-0.46934246860704837,-0.08147018620962587
295.20000000000346,35.47054535570905,-0.4682363734299015,-0.08147032592669312
296.3000000000035,35.57587564168497,-0.4671460090826282,-0.08277859877261351
297.4000000000035,35.6816263808878,-0.46567970518157575,-0.08277989361126492
298.5000000000035,35.78636770381456,-0.46432019842515176,-0.0834959517896765
299.60000000000355,35.891309604770726,-0.46249356292940663,-0.08476010987962379
300.70000000000357,35.996218029811864,-0.4624523575121381,-0.08435069820846186
301.8000000000036,36.10261725568871,-0.46006265510572614,-0.08472965540522948
302.9000000000036,36.20684721025213,-0.45852551094547117,-0.08344008616306198
304.0000000000036,36.31247758382714,-0.456376257189075,-0.08343976396218
305.1000000000036,36.41824636322127,-0.45395886241733674,-0.08409736208943253
306.2000000000036,36.522016728561454,-0.45277294511017113,-0.08456546512989016
307.30000000000365,36.627868211718194,-0.45145495014691434,-0.08542006586567785
308.4000000000037,36.73262559468345,-0.4514595123554502,-0.08541998426203135
309.5000000000037,36.839170000000344,-0.4504400000000008,-0.08561357188672991
310.60000000000366,36.94413937217791,-0.4492509795148077,-0.08571888901413915
311.7000000000037,37.0498808921778,-0.4483045830609559,-0.08509173280481619
312.8000000000037,37.15555531779335,-0.4469273880286361,-0.08606822834067662
313.90000000000373,37.25978258028343,-0.44565801538091127,-0.08606952216017216
315.00000000000375,37.36648560346069,-0.445132209044378,-0.0864060195105174
316.1000000000038,37.4701494883928,-0.44433647691974004,-0.08508013955269123
317.2000000000038,37.57700927046123,-0.44319934171961173,-0.08640000254510705
318.3000000000038,37.68293819023979,-0.4427009561905337,-0.08639987689189432
319.40000000000384,37.7889785319509,-0.44045431561009485,-0.08774542966995691
320.5000000000038,37.894065321224836,-0.4399446791795689,-0.08771987694540107
321.60000000000383,37.999777569658,-0.438356659078934,-0.08771987699997297
322.70000000000385,38.106142011264595,-0.4406139026394612,-0.08771994981300324
323.8000000000039,38.21020348814528,-0.4381678189388051,-0.0890394777543051
324.9000000000039,38.317061534361805,-0.43898345354078466,-0.08870976423265509
326.0000000000039,38.42407448111423,-0.4386533284883883,-0.0887017403912651
327.10000000000394,38.52945579994739,-0.43643872047088267,-0.08771988059328795
328.2000000000039,38.63562585870631,-0.43745366466805374,-0.08771977275269771
329.30000000000393,38.742113198621624,-0.4363906962782411,-0.0870636347806446
330.40000000000396,38.846680746301814,-0.4359986280482566,-0.08640199151803474
331.500000000004,38.95387660991539,-0.43431608109107905,-0.08770830370996086
332.600000000004,39.059081879312224,-0.4343591383210018,-0.08871012830534308
333.700000000004,39.164364640296384,-0.4350517859861651,-0.0887109745572805
334.80000000000405,39.27072744929322,-0.4315332274922146,-0.08997136306290932
335.90000000000407,39.37771918158388,-0.43182447768275656,-0.08744651601372766
337.0000000000041,39.48237980903186,-0.43005294975347297,-0.08735821416776224
338.10000000000406,39.58898504828376,-0.4295693138662863,-0.0873901281611249
339.2000000000041,39.69450785046078,-0.4278062321964926,-0.08871758420697518
340.3000000000041,39.80090593180222,-0.42690902943204034,-0.08871012999937689
341.4000000000041,39.907835313504265,-0.4254192309315563,-0.08871013493948521
342.50000000000415,40.01300672352737,-0.4239820681406935,-0.08975829298231064
343.6000000000042,40.120436639829364,-0.4232160041013032,-0.09002013301353395
344.7000000000042,40.22542028974572,-0.42438178945385296,-0.09002012555492511
345.80000000000416,40.33193791667345,-0.4231050279409781,-0.08903668143090915
346.9000000000042,40.43835237788715,-0.4221287747091274,-0.0887575808806429
348.0000000000042,40.54487661781755,-0.4212282144157316,-0.08826915055944573
349.10000000000423,40.650754331349894,-0.41950947885822376,-0.09034997542018264
350.20000000000425,40.75652746776177,-0.41915001038089744,-0.09034980000022719
351.3000000000043,40.8634038484941,-0.41825668090031465,-0.09034980000000026
352.4000000000043,40.969789021523496,-0.4149259098599987,-0.0903498000000007
353.5000000000043,41.07599521554656,-0.4155782436683722,-0.09034980025579031
354.60000000000434,41.17997168422217,-0.412857455925885,-0.09067516225593408
355.7000000000043,41.28813725205229,-0.41130637718961244,-0.09199968722817387
356.80000000000433,41.39471115422185,-0.4099195116461319,-0.0919997999998734
357.90000000000435,41.50095735704071,-0.4085761656549641,-0.09199991439511379
359.0000000000044,41.606883710702945,-0.40843513360721057,-0.09101012383803875
360.1000000000044,41.71313869770066,-0.40618296221428674,-0.09099543519453102
361.2000000000044,41.81977629512782,-0.40588648388903054,-0.09100372141159196
362.30000000000445,41.92675945129268,-0.40515382509185843,-0.09364794979676105
363.4000000000044,42.03315459379927,-0.40263946428760194,-0.09396799323513783
364.50000000000443,42.139785218377384,-0.4016188580339786,-0.09300090072400469
365.60000000000446,42.24680704293225,-0.3998721342517206,-0.09397890457342672
366.7000000000045,42.35336647732584,-0.3977920216265866,-0.09299356646698254
367.8000000000045,42.45762909791854,-0.3946695447567634,-0.09140599942531002
368.9000000000045,42.567049966948105,-0.395461661599815,-0.09269884860074828
370.00000000000455,42.673635432593365,-0.3940834907171808,-0.09398031907009452
371.10000000000457,42.77966184190798,-0.39248418991957523,-0.09398003099996144
372.2000000000046,42.886283574527376,-0.3905776901271554,-0.09398003103486818
373.30000000000456,42.99289765503682,-0.3902825940610458,-0.09397816282240212
374.4000000000046,43.09936936744061,-0.38759144329720496,-0.09529712636648302
375.5000000000046,43.20657991787493,-0.38641935676905714,-0.0966100432574164
376.6000000000046,43.3127762220137,-0.3842800951542496,-0.09660622926974094
377.70000000000465,43.418958876331345,-0.3824916604072046,-0.09529981378773256
378.8000000000047,43.52622441516248,-0.38061194809040344,-0.09398013001042882
379.9000000000047,43.630478702308096,-0.3797457283916072,-0.09428006386313648
381.00000000000466,43.738883527783955,-0.3766129651747106,-0.09464009752138791
382.1000000000047,43.84493633542444,-0.37655522457074947,-0.0953003456634165
383.2000000000047,43.95236286181659,-0.3764726686818463,-0.09464430168039417
384.30000000000473,44.05889495413754,-0.37390756009786774,-0.09332981669350282
385.40000000000475,44.16591003829807,-0.37455967917158073,-0.09596541702343675
386.5000000000048,44.272618812786334,-0.37261770637819447,-0.09578520757471054
387.6000000000048,44.38004008260616,-0.37056383499796186,-0.09563401618216538
388.7000000000048,44.48750212007174,-0.3689526663862412,-0.09563051490600882
389.80000000000484,44.594559671190076,-0.3670835285866286,-0.09628981184225038
390.9000000000048,44.70158485514717,-0.36622173975024114,-0.0933912769971661
392.00000000000483,44.80841977791843,-0.3640484203721385,-0.09683965226542979
393.10000000000485,44.91442811901287,-0.36101296938051813,-0.09703991085826136
394.2000000000049,45.02276329381451,-0.3609003748034813,-0.09749064443746791
395.3000000000049,45.12955814247835,-0.358330752866966,-0.10019263505285458
396.4000000000049,45.23645543520533,-0.35712767242438515,-0.09752396901995075
397.50000000000495,45.34353102112166,-0.35656288162928546,-0.09749986599097094
398.6000000000049,45.45068378915928,-0.35618951622114003,-0.09749986599996197
399.70000000000493,45.55772917562431,-0.3557015043741427,-0.09750001109620365
400.80000000000496,45.66568577870726,-0.35415001231373366,-0.09880974733615533
401.900000000005,45.77191741353527,-0.35353530250049925,-0.09880982830444074
403.000000000005,45.879170000000485,-0.3522700000000213,-0.09816008282518762
404.100000000005,45.986589357999456,-0.35076048784361225,-0.10072273116070729
405.20000000000505,46.093817626923645,-0.3492460012038041,-0.1007799991010585
406.30000000000507,46.200453018472466,-0.3471006499352306,-0.10076350124487998
407.4000000000051,46.30767589696165,-0.3447009209634278,-0.10060708772810933
408.50000000000506,46.41494355227782,-0.3438718862050864,-0.10077863386868158
409.6000000000051,46.5222593456742,-0.34222269530404636,-0.10177098209124091
410.7000000000051,46.627258764286076,-0.34121279900100815,-0.1004598571048052
411.8000000000051,46.73689784121503,-0.33856519884862146,-0.10045982299996314
412.90000000000515,46.84350052434443,-0.3379602369634682,-0.10045982300000045
414.0000000000052,46.951051012684836,-0.3353013259728723,-0.1004598230000262
415.1000000000052,47.05845763973446,-0.33379416671296586,-0.10045970601524212
416.20000000000516,47.16572853438534,-0.33389965150682593,-0.0994693264278026
417.3000000000052,47.27131917442427,-0.3327811497475751,-0.10079647614680631
418.4000000000052,47.38003085678487,-0.3325760747026193,-0.10078201682939625
419.50000000000523,47.48808377820524,-0.3319061976191949,-0.1020998215980673
420.60000000000525,47.5955644361089,-0.3299433286302192,-0.10121106659492574
421.7000000000053,47.70274078778032,-0.32826480566067145,-0.10077982294317467
422.8000000000053,47.81013182800573,-0.32909973324088215,-0.10077248977700393
423.9000000000053,47.91639546967317,-0.32808243612136967,-0.10210032620739407
425.00000000000534,48.024886048261095,-0.32645103668858416,-0.10242912861068953
426.1000000000053,48.132581820760585,-0.32709005089621646,-0.10242989999996466
427.20000000000533,48.23974555696754,-0.3287495178174897,-0.10242996140053284
428.30000000000535,48.34771895597013,-0.32873247069212674,-0.10352423281049283
429.4000000000054,48.455173815665724,-0.32817275800662427,-0.10299360482413311
430.5000000000054,48.56281253268608,-0.328372020115233,-0.10242983760227808
431.6000000000054,48.67090097664679,-0.3267211637597845,-0.10373491902241572
432.70000000000545,48.777803519732075,-0.32686258531956974,-0.1037498034495381
433.8000000000054,48.886076698769266,-0.32690757778347734,-0.10242254423440356
434.90000000000543,48.99046267261732,-0.325652652137841,-0.10487098670465755
436.00000000000546,49.10063448378269,-0.32362184307184977,-0.10507017294608723
437.1000000000055,49.20728612827838,-0.3214288899732694,-0.1037829196165041
438.2000000000055,49.3151624268043,-0.3208668625392963,-0.10473300114412298
439.3000000000055,49.42333587131811,-0.32005035691386785,-0.10478333349147029
440.40000000000555,49.53070538740032,-0.31883186704554617,-0.10374987731786645
441.50000000000557,49.63877458539723,-0.31698554604148294,-0.10509750878202295
442.6000000000056,49.74569715838862,-0.3140861401198879,-0.1050698784031634
443.70000000000556,49.85449989765084,-0.31442848561707853,-0.10615320009822948
444.8000000000056,49.95955320177582,-0.31334313709817757,-0.10506000794740489
445.9000000000056,50.06908490564763,-0.3117512581452584,-0.10309992901400822
447.0000000000056,50.176600710712826,-0.3096796522699003,-0.10312223386049757
448.10000000000565,50.28553354099684,-0.30827513442562304,-0.10471561894572723
449.2000000000057,50.392794613888306,-0.3095538150942221,-0.10577097903611143
450.3000000000057,50.5013799452113,-0.30671005846469196,-0.10704013892100406
451.40000000000566,50.60758524323166,-0.3060841111440752,-0.10653936284367527
452.5000000000057,50.71609409456296,-0.3043389056903669,-0.10703958311818518
453.6000000000057,50.822584615581626,-0.30321205964259945,-0.10604960915986572
454.70000000000573,50.93320374224424,-0.30151298719759717,-0.106049835000118
455.80000000000575,51.040368014116304,-0.29974410304439253,-0.10604983499999987
456.9000000000058,51.14846011678857,-0.29722769056793097,-0.10604983512361565
458.0000000000058,51.25691201000727,-0.29562018254960304,-0.1064060808606837
459.1000000000058,51.36475526965594,-0.29411050776420816,-0.10737007134019017
460.20000000000584,51.472243812288106,-0.2921697457357641,-0.10735910828984796
461.3000000000058,51.580815413701295,-0.2884433043636243,-0.10670998757546224
462.40000000000583,51.6875257860815,-0.28768289974661515,-0.10670998917857721
463.50000000000585,51.79517110692684,-0.28678511879864205,-0.1070678148636297
464.6000000000059,51.90371559232132,-0.2792635456253973,-0.10704018220777334
465.7000000000059,52.01156944181996,-0.28027235185859717,-0.10674963003394122
466.8000000000059,52.11956291612174,-0.2813159619087931,-0.10671945959565887
467.90000000000595,52.22756733755955,-0.2809514119079792,-0.10769973639524322
469.0000000000059,52.33539987542813,-0.2782599975445089,-0.10769989000007296
470.10000000000593,52.44388602376625,-0.2760908505058232,-0.10769988999999969
471.20000000000596,52.55181356182827,-0.2742794642307064,-0.10769988999999924
472.300000000006,52.66050074711278,-0.27400208123572173,-0.10769988906587802
473.400000000006,52.76857582599377,-0.2715256349478243,-0.10801795696252858
474.500000000006,52.874443452571995,-0.27066131130359167,-0.10934997431664417
475.60000000000605,52.98390032523276,-0.2699882495917192,-0.10863134798824703
476.70000000000607,53.09171252013549,-0.26763538079840854,-0.11065596751784357
477.8000000000061,53.20137647605872,-0.26695006982394703,-0.10802999832683335
478.90000000000606,53.30830145469912,-0.2656710409073317,-0.10804165401084553
480.0000000000061,53.41675983511051,-0.2630898705913475,-0.10935020937789641
481.1000000000061,53.525352330410726,-0.2646957941373609,-0.10902032213434909
482.2000000000061,53.63310315420911,-0.26133395065098697,-0.10901755789553302
483.30000000000615,53.74122803010393,-0.2588578852980963,-0.1103270412558155
484.4000000000062,53.84886473543044,-0.25810294775185416,-0.11032984699968607
485.5000000000062,53.95754151999602,-0.2566989672397828,-0.11032984708906968
486.60000000000616,54.065292179965546,-0.2551443794885376,-0.1101997591061501
487.7000000000062,54.174151908130455,-0.2521861319228291,-0.10903492678011917
488.8000000000062,54.28334462168186,-0.2505178154883867,-0.11098999908416651
489.90000000000623,54.38892645302657,-0.25004492529615174,-0.11099000099999934
491.00000000000625,54.49926068892966,-0.24744617491355445,-0.11099000095510547
492.1000000000063,54.60774024678992,-0.24719226592711646,-0.11025395821744777
493.2000000000063,54.7149699517691,-0.24455854205929625,-0.10968000085881435
494.3000000000063,54.82376621096157,-0.24334098962564288,-0.10967795267266034
495.40000000000634,54.93263178409335,-0.2414071280808471,-0.11034026743023695
496.5000000000063,55.04091459542817,-0.24179298112099032,-0.1116600188532697
497.60000000000633,55.14906822794576,-0.239535726549656,-0.111660056098136
498.70000000000636,55.25727011255008,-0.2399633445314743,-0.11236445862310607
499.8000000000064,55.36438464165913,-0.23802843413549324,-0.11264086894697423
500.9000000000064,55.47351052745576,-0.2368052376055775,-0.11001338258134563
502.0000000000064,55.58243070493444,-0.2355905672510885,-0.11133004713297101
503.10000000000645,55.69038668598916,-0.23518529689575565,-0.11132967175369535
504.2000000000064,55.798273146751846,-0.2346000179686592,-0.1119828830071321
505.30000000000643,55.90764982902632,-0.23237924226486173,-0.11099983209930997
506.40000000000646,56.01669870613123,-0.230713952685742,-0.11199075227815891
507.5000000000065,56.12507030813919,-0.22910448669679417,-0.11198745942024324
508.6000000000065,56.232641734358886,-0.23236380092026965,-0.11231979935894998
509.7000000000065,56.34197907669042,-0.2281607822750258,-0.11231970320396822
510.80000000000655,56.45017191235135,-0.22626459347844424,-0.11264985845518538
511.90000000000657,56.558410829594195,-0.2254980988773409,-0.11264987999999043
513.0000000000066,56.66735210928584,-0.22297069261106303,-0.11264987999999843
514.1000000000065,56.775481331818796,-0.22140563380748746,-0.1126498860137608
515.2000000000066,56.88314829799071,-0.22024785946854739,-0.11362587675614177
516.3000000000065,56.99178789831233,-0.21975628892976665,-0.11362994680794225
517.4000000000067,57.10156858676894,-0.2172419181001537,-0.11263121548572785
518.5000000000066,57.211030014538935,-0.2155263584606654,-0.11133064268139714
519.6000000000067,57.31927616436999,-0.21468101377653798,-0.11309283933993264
520.7000000000066,57.427647488340135,-0.21181863857693892,-0.11397124538995973
521.8000000000067,57.535064404383085,-0.2093486794461803,-0.11396008986104178
522.9000000000067,57.64558560176079,-0.20776035203943438,-0.11431571092429182
524.0000000000067,57.75387398603892,-0.20592202679865898,-0.11527999079383466
525.1000000000067,57.862417204459035,-0.20691139711576764,-0.11527999099999864
526.2000000000068,57.97188095279034,-0.20518773682923344,-0.1152799909999982
527.3000000000068,58.08096058473199,-0.20265636794686942,-0.11528002198634102
528.4000000000068,58.189070933054104,-0.2013280899362047,-0.11528019245360355
529.5000000000068,58.29927529939422,-0.2008657925517993,-0.11527989200042033
530.6000000000068,58.4074988401545,-0.19949010647693405,-0.115293893777769
531.7000000000069,58.515847569681505,-0.19791600909576756,-0.11759741541722413
532.8000000000068,58.625086905124014,-0.19552148561318614,-0.1162712622605846
533.9000000000069,58.73358833946064,-0.1948662724104626,-0.11527739681168381
535.0000000000068,58.84358882215896,-0.1931073998561377,-0.11528067755447768
536.100000000007,58.95197106313791,-0.19187178269510904,-0.11561026153762288
537.2000000000069,59.06141274819556,-0.1903873372907022,-0.11791380071054292
538.300000000007,59.16968398596423,-0.18777025595185814,-0.1166158800841588
539.4000000000069,59.2786732415429,-0.18550779566174241,-0.11692117420462234
540.5000000000069,59.387600548589575,-0.18408688750545726,-0.11889981964171792
541.600000000007,59.49670650622843,-0.18230527691967074,-0.11750585202331765
542.700000000007,59.6056151772479,-0.1807341522134619,-0.11758106977147076
543.800000000007,59.714630022080115,-0.17979738767964742,-0.11890016172328899
544.900000000007,59.82358942526465,-0.17914169981113162,-0.11889641064616407
546.000000000007,59.93237301453277,-0.17868068270333903,-0.11855754143725417
547.1000000000071,60.04100184392306,-0.17645916695186228,-0.11712019966749887
548.2000000000071,60.148981922053935,-0.174686884342535,-0.11747030232025324
549.300000000007,60.25661038959353,-0.17306461968912415,-0.11879016352488403
550.4000000000071,60.367785520303904,-0.17266714622239582,-0.1187901680000003
551.500000000007,60.47619764898331,-0.17140920876702712,-0.11879016797121222
552.6000000000072,60.585451787077005,-0.1685634192883708,-0.11828159448310949
553.7000000000071,60.69510110470862,-0.1685445870422349,-0.11779955712019907
554.8000000000072,60.80424447877242,-0.1670182924071455,-0.12010901004003571
555.9000000000071,60.91308984432199,-0.16619595732195525,-0.11878732337194009
557.0000000000072,61.02236998890466,-0.16307581651038217,-0.1196298211473712
558.1000000000072,61.13094010542336,-0.1613544793931615,-0.11878445434140739
559.2000000000072,61.24020518651385,-0.16034626228622825,-0.12010172462176838
560.3000000000072,61.34935984412079,-0.15849404275907392,-0.12010020199810967
561.4000000000073,61.45887866123279,-0.15800920109380262,-0.12010020234372121
562.5000000000073,61.56784166768266,-0.15421957256104318,-0.12141959724445073
563.6000000000073,61.67628901582815,-0.15381407757319987,-0.12142010300060768
564.7000000000073,61.78585051333234,-0.15000889915228827,-0.12142010299808748
565.8000000000073,61.89467907082982,-0.14947851210161875,-0.12142577936452792
566.9000000000074,62.00348958530236,-0.14717452716611598,-0.1211269988968775
568.0000000000074,62.11231285589026,-0.14400233867368709,-0.1214297953344512
569.1000000000074,62.22148641296621,-0.1423740584670257,-0.12241989562298361
570.2000000000073,62.33114272622804,-0.14089975415317296,-0.12164513324353532
571.3000000000073,62.439689835001076,-0.13945758801906047,-0.12144632576406522
572.4000000000074,62.54818449706997,-0.13773259776507846,-0.12340168413293284
573.5000000000074,62.657408864358274,-0.1350536217424059,-0.12339173979105533
574.6000000000074,62.768976860631085,-0.13344352410746874,-0.12274990253729001
575.7000000000074,62.87840100149663,-0.133151185286045,-0.12406039063884933
576.8000000000075,62.987824641596156,-0.13230344424343077,-0.12143177357521306
577.9000000000075,63.09659427413828,-0.12937298698618632,-0.12406004509154345
579.0000000000075,63.206578998184206,-0.12752490544353406,-0.12406003358305062
580.1000000000075,63.31422726672401,-0.12463173133253069,-0.12508704897032796
581.2000000000075,63.42523922022599,-0.12315599960316519,-0.12297534772698304
582.3000000000076,63.53409100261772,-0.11997572700756216,-0.12465251522602827
583.4000000000076,63.64377770121774,-0.11632552069199756,-0.1257100527842523
584.5000000000076,63.753291159843975,-0.11413748776785956,-0.12522357979232845
585.6000000000076,63.860833308917876,-0.11299255579385038,-0.12438904843570064
586.7000000000077,63.97284024012334,-0.10922101290664678,-0.12438991699993407
587.8000000000077,64.08165742614005,-0.10780738853468566,-0.1243899208909558
588.9000000000076,64.19173285875215,-0.10510420779321886,-0.12569676503859162
590.0000000000076,64.2997742945129,-0.10173115169692089,-0.12570004973155013
591.1000000000076,64.40830872748242,-0.10325949307157964,-0.1267040153247283
592.2000000000077,64.51847168092287,-0.10005084637206635,-0.1266279306578526
593.3000000000077,64.62787822627165,-0.09975510554332781,-0.1276773604225152
594.4000000000077,64.73803932790918,-0.10006522912923253,-0.12900037896162875
595.5000000000077,64.84680674357152,-0.1003317340608875,-0.1289998519988056
596.6000000000078,64.95606554020515,-0.1007878414355404,-0.1290003666073094
597.7000000000078,65.06595631541455,-0.10060927944146555,-0.12767550444543474
598.8000000000078,65.17555560100907,-0.10616807140785738,-0.12900017317000634
599.9000000000078,65.28500762241394,-0.10511134006349102,-0.12902091203317578
601.0000000000078,65.39421915544445,-0.10809873910394445,-0.12986580495314604
602.1000000000079,65.50451544204397,-0.10673381793318884,-0.12996755548157957
603.2000000000079,65.6127787660509,-0.10807382357696034,-0.13030911422162905
604.3000000000079,65.72342946409101,-0.10573281086810772,-0.12900017436409472
605.4000000000078,65.83343914916176,-0.1056156150473139,-0.13014394801064544
606.5000000000078,65.94287311845913,-0.10540203420359517,-0.12899824083258604
607.6000000000079,66.05218653872875,-0.10221522637021806,-0.1276851476739278
608.7000000000079,66.16226489085311,-0.1013543042996233,-0.1290007117738372
609.8000000000079,66.27111104305061,-0.10070823810167473,-0.1299935515579027
610.9000000000079,66.38126454262753,-0.0989203190930303,-0.12999013289249817
612.000000000008,66.49049044395171,-0.09723340445839604,-0.12966060243913358
613.100000000008,66.5985799111039,-0.09674309522136441,-0.12900021818737972
614.200000000008,66.70956790939547,-0.09388167229456672,-0.13031997876826296
615.300000000008,66.81805918303004,-0.09358714560929325,-0.1289949752282804
616.400000000008,66.92839825211324,-0.09273698469508457,-0.13097993471443248
617.5000000000081,67.03717699645802,-0.09273088374566617,-0.12967109116458042
618.6000000000081,67.14635470005976,-0.09164107843188778,-0.12966009499622544
619.7000000000081,67.25652441744197,-0.08991153083907132,-0.1296600949999993
620.8000000000081,67.36423148689865,-0.08817450702446272,-0.12966009503259546
621.9000000000082,67.47561342008255,-0.08776701237569522,-0.1295678345538045
623.0000000000082,67.58502672836332,-0.08524606715585417,-0.1309799961910132
624.1000000000081,67.69476251148764,-0.08300037624634496,-0.13098095138779708
625.2000000000081,67.80372305361236,-0.08095690742777578,-0.12964667311080946
626.3000000000081,67.91377351782884,-0.07997423005972511,-0.1309701052472616
627.4000000000082,68.02479743506584,-0.07954904932254454,-0.13229171130776418
628.5000000000082,68.13402684746382,-0.07925619234037638,-0.13229012901261195
629.6000000000082,68.24322512263298,-0.07675677664770023,-0.13226272465783584
630.7000000000082,68.35295033233828,-0.07685468478133746,-0.13195997122736935
631.8000000000083,68.46273915204858,-0.07582378242359304,-0.13195994958282187
632.9000000000083,68.5725859032607,-0.07281491878504817,-0.13295436741485078
634.0000000000083,68.68288527569084,-0.07027431251618711,-0.13201837897076363
635.1000000000083,68.79240448631964,-0.07042107688101669,-0.13162982140539103
636.2000000000083,68.9013626681403,-0.06705114199673186,-0.13195981969922954
637.3000000000084,69.01011207709091,-0.0644309144910776,-0.1326168446880538
638.4000000000084,69.12082289702911,-0.0644610982418179,-0.1336101533034455
639.5000000000084,69.23040165680996,-0.06100597946916625,-0.1336102492328357
640.6000000000083,69.34047949759596,-0.06066877000894358,-0.13295007594052866
641.7000000000083,69.44985123044138,-0.060193606827209235,-0.13295000799998213
642.8000000000084,69.55967938256833,-0.05849364349546072,-0.13295000768399534
643.9000000000084,69.67028146331036,-0.05708379324251607,-0.1342734183039367
645.0000000000084,69.78007765094839,-0.05520766861260575,-0.13429328021108233
646.1000000000084,69.89102091228493,-0.0529145902294263,-0.13219547340411353
647.2000000000085,69.99977952920953,-0.05279991708399579,-0.13294953447498603
648.3000000000085,70.11044310129601,-0.04913747711673357,-0.13294981100024117
649.4000000000085,70.22089208827518,-0.04700577685810535,-0.13294980855014238
650.5000000000085,70.33022557128676,-0.04478628509287615,-0.13331738980351293
651.6000000000085,70.4398532070758,-0.04410736504558556,-0.1336054642840767
652.7000000000086,70.55075032588145,-0.04313380315008832,-0.1339401188292535
653.8000000000086,70.66010733743866,-0.04040170262101182,-0.13394842631833326
654.9000000000086,70.77033911892138,-0.038400373039169065,-0.13526015596740848
656.0000000000086,70.88124653434632,-0.03719641773445645,-0.13449270513667555
657.1000000000087,70.99097096170036,-0.03590849945966005,-0.13338994810998273
658.2000000000087,71.10078896462896,-0.03502054886872147,-0.135040210106538
659.3000000000086,71.20985674642847,-0.03300801065626696,-0.13504002427072237
660.4000000000086,71.32043965856079,-0.03154069620772044,-0.13371794885234678
661.5000000000086,71.42926245667707,-0.029485921419121163,-0.1350399175405257
662.6000000000087,71.53948733399176,-0.027959554262303225,-0.13503990756361883
663.7000000000087,71.6495672594375,-0.025703534494012532,-0.13372019433358284
664.8000000000087,71.76020152945046,-0.02212298585906137,-0.13470914434631887
665.9000000000087,71.87036420106763,-0.0186892610865094,-0.13471732225977595
667.0000000000088,71.98026057411145,-0.017959715725822514,-0.13570722856432704
668.1000000000088,72.09007457982518,-0.015405520074860408,-0.13470003817931042
669.2000000000088,72.20012680756525,-0.014393418829168935,-0.13568782253307
670.3000000000088,72.31109656462208,-0.011134663655902629,-0.13568987800166843
671.4000000000088,72.41948824502919,-0.009678707175027933,-0.13568990877419207
672.5000000000089,72.53075917017323,-0.00784649823884891,-0.1360199374700901
673.6000000000089,72.64074409054248,-0.005210490417359745,-0.13471015263498742
674.7000000000089,72.75201680201589,-0.0013455844381479777,-0.1360181608640869
675.8000000000088,72.86159313461853,-0.0007307541861292439,-0.1360168540357649
676.9000000000088,72.97216817799587,0.0014196216448269646,-0.13733928352820213
678.0000000000089,73.0816747749638,0.0035428117785360497,-0.136030249850271
679.1000000000089,73.19224979078155,0.006000546991930162,-0.1347098202884407
680.2000000000089,73.3031141805256,0.010529286824217948,-0.134709867226674
681.3000000000089,73.4122716423737,0.013501317340721491,-0.1373492941497121
682.400000000009,73.5233103436708,0.015462650845410087,-0.1386629855884114
683.500000000009,73.6330178737882,0.018767781337825577,-0.1386505131517337
684.600000000009,73.74270690267609,0.02104373107851255,-0.13735146051200386
685.700000000009,73.85344038507264,0.02615795657485439,-0.13778961483864682
686.800000000009,73.96353427759271,0.029003568387984468,-0.13865922771211547
687.9000000000091,74.07346797783212,0.03311809535406342,-0.13869943548801977
689.0000000000091,74.18285225138645,0.0355506577861279,-0.13734165450727875
690.1000000000091,74.29363972243566,0.03960673960148614,-0.13601995195812044
691.2000000000091,74.40350490265048,0.044611595797606846,-0.1370098063213918
692.3000000000092,74.51279003163819,0.04874293528585245,-0.1370725749170738
693.4000000000092,74.62259646683346,0.049639335752501734,-0.13684502421159017
694.5000000000091,74.7327982474981,0.055785611750891625,-0.13766030309025057
695.6000000000091,74.84299017711548,0.06073048817597203,-0.13732694237083676
696.7000000000091,74.95248535615426,0.06635032320380241,-0.135809663172743
697.8000000000092,75.063450973268,0.06706313658178825,-0.1371924132406459
698.9000000000092,75.17400568042174,0.07148985506748454,-0.13981487467781273
700.0000000000092,75.28436645669991,0.07582521628162125,-0.138590108173144
701.1000000000092,75.39377529694397,0.0813028875325486,-0.13713013060701584
702.2000000000093,75.50435170070739,0.08532871181194873,-0.13844037763508465
703.3000000000093,75.6148819350877,0.08717815804012893,-0.138439999999854
704.4000000000093,75.72592553895143,0.09358389108367786,-0.13844008971564303
705.5000000000093,75.83631153171976,0.09627471991746409,-0.13974864246776164
706.6000000000093,75.94653191964036,0.09909971635058669,-0.1391001266990366
707.7000000000094,76.05545245315676,0.10450712009716295,-0.13852200594774766
708.8000000000094,76.16841626226895,0.10816241715463056,-0.13712006999888704
709.9000000000094,76.27836250871748,0.10998215214810156,-0.1371201330804559
711.0000000000093,76.38928504074168,0.10991544005997678,-0.1397627905284735
712.1000000000093,76.49974961795317,0.11008204486228677,-0.13844045458884402
713.2000000000094,76.60795432360298,0.11070405900530543,-0.1384400339999261
714.3000000000094,76.71917096186,0.11440002348878948,-0.13844003402399263
715.4000000000094,76.83083814341445,0.11302870207196233,-0.1397598292358322
716.5000000000094,76.94168103138662,0.11427410564881023,-0.139759934806444
717.6000000000095,77.05089515554758,0.11330320791341138,-0.13894662310888384
718.7000000000095,77.1613210369336,0.11092573600919449,-0.13877149552432488
719.8000000000095,77.27159696910783,0.1133305588579333,-0.13580008421466294
720.9000000000095,77.38295165539606,0.11511572553650601,-0.14032582691673978
722.0000000000095,77.49274043234308,0.11457378244854907,-0.14131910191091235
723.1000000000096,77.60248694501034,0.11473299872302142,-0.14031002303694162
724.2000000000096,77.71430706496143,0.11348128991709756,-0.14031002156007277
725.3000000000096,77.82469404356614,0.11435863156783065,-0.1416632695703548
726.4000000000096,77.93548038660678,0.11440319912247818,-0.1413419788664978
727.5000000000097,78.04600824341661,0.11303021323187397,-0.1399699177052982
728.6000000000097,78.15685159297523,0.11462600751758273,-0.14030004679478525
729.7000000000096,78.26641733188468,0.11516220235665858,-0.1406501038872916
730.8000000000096,78.37735030995425,0.11762481589751131,-0.14194931364875485
731.9000000000096,78.48771504464615,0.1163485392012276,-0.1419500566260119
733.0000000000097,78.59783250364828,0.11566574845158654,-0.14074373459694423
734.1000000000097,78.70906534519756,0.11609666156254198,-0.14195995776133596
735.2000000000097,78.81792905148163,0.11897600985319227,-0.1419599580000006
736.3000000000097,78.92865988117961,0.12004111649294821,-0.1419599579999975
737.4000000000098,79.03856643524566,0.12110044270098884,-0.14195996038876846
738.5000000000098,79.14994602503172,0.1207431890811274,-0.1406399392540063
739.6000000000098,79.25927380416586,0.12038894911049478,-0.1419526631406285
740.7000000000098,79.37059033134516,0.12142903272544257,-0.1432703068621688
741.8000000000098,79.48122737623339,0.1208363258670111,-0.1419438912727906
742.9000000000099,79.59107444036582,0.12190616479762949,-0.14195490599442984
744.0000000000099,79.70157511418022,0.12480687869945306,-0.14293999017850822
745.1000000000099,79.8117127501409,0.1256197207179593,-0.14293999201021057
746.0000000000099,79.90203227585613,0.12711812916124213,-0.14293839407087905