File: 01_Data/EIFS_XPS/STA/N2/10K_min/EIFS_XPS_STA_N2_10KData_230202_R1.csv
##Temp./Â°C,Time/min,DSC/(mW/mg),Mass loss/mg
50.0,10.891978558049175,-1.7869665510303077,-0.01006015644507574
51.000000000000014,11.156016545105135,-1.6827448067632118,-0.011877718658666936
52.00000000000003,11.377750938815334,-1.597834017662506,-0.011446386948778198
53.00000000000004,11.560000000000027,-1.536409999999989,-0.0136924259296336
54.00000000000006,11.7252302658506,-1.485144687575245,-0.013404969512678555
55.00000000000007,11.879681020154678,-1.4401009029666647,-0.013362097548995422
56.000000000000085,12.028800568734209,-1.4047191349613468,-0.013727097789826281
57.0000000000001,12.168938484549026,-1.3717515498408932,-0.013625795715048739
58.000000000000114,12.303082946304771,-1.3464584567358941,-0.014100066862633653
59.00000000000013,12.436758624615925,-1.322138322710826,-0.013826287572296536
60.00000000000014,12.566843447920366,-1.299259511080645,-0.01363309737666718
61.000000000000156,12.692103551184314,-1.280807129700618,-0.013979180659387858
62.00000000000017,12.816784770045683,-1.2636606555379877,-0.015024503244871035
63.000000000000185,12.939876676813569,-1.2478982275969859,-0.015487297777237785
64.0000000000002,13.06060748100435,-1.2313066453187247,-0.014167319540080214
65.00000000000021,13.178884029967826,-1.216567751530562,-0.01368507544154074
66.00000000000023,13.297197251293532,-1.2030140741189699,-0.012831789404984306
67.00000000000024,13.41450182477532,-1.1888921880904555,-0.01442836383002355
68.00000000000026,13.529886994704995,-1.1746350719159369,-0.013948702320998763
69.00000000000027,13.643555637138114,-1.1633905546651462,-0.015181155367180565
70.00000000000028,13.756483404369552,-1.1513919324883184,-0.015321052864424978
71.0000000000003,13.869749792069854,-1.1411873187035313,-0.015355388398464953
72.00000000000031,13.981297651846342,-1.131037574380086,-0.01671124932443835
73.00000000000033,14.091400857357154,-1.121873799627691,-0.01679926661903597
74.00000000000034,14.201225859544955,-1.1119169689200639,-0.01679861719205622
75.00000000000036,14.310100805331164,-1.1031469352581602,-0.0166707691022161
76.00000000000037,14.416972788402521,-1.0936373051374333,-0.016763499816050853
77.00000000000038,14.52651311318354,-1.0851677623938865,-0.015926107872904716
78.0000000000004,14.634641599101055,-1.0750297344567377,-0.01801441596413067
79.00000000000041,14.742238732807046,-1.0662025813226663,-0.018032422470845688
80.00000000000043,14.848234672770417,-1.0570471845881442,-0.018003280664822263
81.00000000000044,14.954799450046854,-1.0468794945267592,-0.017214179860435053
82.00000000000045,15.057885692507035,-1.0392134787483363,-0.01897777390083899
83.00000000000047,15.163606222242288,-1.0291355654570822,-0.018116658569385713
84.00000000000048,15.266621155733771,-1.0184878115251443,-0.019040508521768196
85.0000000000005,15.369522199152167,-1.0098627785950767,-0.019430455755474974
86.00000000000051,15.471160958770435,-0.9997230235268212,-0.01942987492784365
87.00000000000053,15.575712637684099,-0.989818893110379,-0.018497260687730055
88.00000000000054,15.676696920977644,-0.9809441179088844,-0.018781918044707524
89.00000000000055,15.77919136175511,-0.9705469113343328,-0.01945101842724828
90.00000000000057,15.88056770716656,-0.9623122524908382,-0.0191069083907065
91.00000000000058,15.981232150836805,-0.9524752344437578,-0.01943721050558267
92.0000000000006,16.081695551592304,-0.9426715411133063,-0.019447199232691226
93.00000000000061,16.182513668355725,-0.929948890619738,-0.020740693307294222
94.00000000000063,16.281925058161246,-0.9204536622230829,-0.02010191483379753
95.00000000000064,16.381055057652034,-0.9088357198571893,-0.022072668275938234
96.00000000000065,16.479519135912973,-0.8966356989473266,-0.020717266469500117
97.00000000000067,16.578442356078057,-0.8867217824504674,-0.02208098806855663
98.00000000000068,16.676542486933325,-0.8747537576563543,-0.022061004552154984
99.0000000000007,16.77493954218099,-0.8623411306105048,-0.02239131437460884
100.00000000000071,16.87292117433766,-0.8458863487132476,-0.0233794003163883
101.00000000000072,16.97124891704648,-0.83052312673984,-0.023378698869020553
102.00000000000074,17.07028975868979,-0.8152301196867665,-0.023378642002299443
103.00000000000075,17.16796782799426,-0.7969103207600712,-0.023379813475928657
104.00000000000077,17.26658985980334,-0.7774326346634484,-0.024470639827866236
105.00000000000078,17.36260673823595,-0.7574277399675495,-0.026021560372608832
106.0000000000008,17.461578665887824,-0.7380315506789407,-0.02470092290513648
107.00000000000081,17.557512482648644,-0.7199792839893224,-0.026020097069349823
108.00000000000082,17.655714163602546,-0.7047294423802232,-0.026978956813006327
109.00000000000084,17.753208818795986,-0.6953468899271872,-0.027656442782001633
110.00000000000085,17.84921036369233,-0.6870404309417751,-0.029145579728727
111.00000000000087,17.94785726332001,-0.6823576987792974,-0.030707591637284537
112.00000000000088,18.043239784843383,-0.6797563623802729,-0.028993780022585902
113.0000000000009,18.141357549110136,-0.6815226614871446,-0.031096276717769378
114.00000000000091,18.23872823150931,-0.6845068184592321,-0.03030037073244074
115.00000000000092,18.33626201642444,-0.6888035644875172,-0.0315954066475479
116.00000000000094,18.432502696914465,-0.6920074778933234,-0.031620839571212755
117.00000000000095,18.529039156606085,-0.6961619966697333,-0.032928550939820056
118.00000000000097,18.62578387885958,-0.6972947124693549,-0.033270892573260546
119.00000000000098,18.721278704665544,-0.6988218286809074,-0.03327017704350954
120.000000000001,18.816965883484674,-0.6987523424595551,-0.032545565905630625
121.00000000000101,18.914737645865067,-0.6979774916506948,-0.03279795683269615
122.00000000000102,19.011103968357702,-0.6980334067051067,-0.03561366483055206
123.00000000000104,19.107406200419117,-0.6954880995547392,-0.034248013689597734
124.00000000000105,19.203426224329952,-0.6919166022370927,-0.03425698667926369
125.00000000000107,19.299236577672126,-0.6885531762422665,-0.03530729421283496
126.00000000000108,19.39483216097328,-0.6845924727772874,-0.03259793991476023
127.0000000000011,19.4900000000001,-0.6780899999999858,-0.03269751682525257
128.0000000000011,19.586888328690677,-0.6725998278282365,-0.03259997437591977
129.00000000000114,19.68256948272378,-0.6672404208295979,-0.033919926785273447
130.00000000000114,19.77756445245814,-0.6645457093913039,-0.033988460150528255
131.00000000000114,19.872418988013944,-0.6602582958115426,-0.032633753929012244
132.00000000000117,19.968903886648302,-0.6550244254648077,-0.03522939235625966
133.0000000000012,20.0633539071703,-0.6496632224776322,-0.03637127620792224
134.0000000000012,20.160897457785595,-0.6450841981165638,-0.03589889988208039
135.0000000000012,20.25510456943182,-0.6389799665942766,-0.03524174588478779
136.00000000000122,20.34929217580378,-0.634717676352735,-0.03654436500700431
137.00000000000125,20.444591825595147,-0.6304898361144123,-0.0352349022870424
138.00000000000125,20.539405562562457,-0.6244032407411816,-0.03656043960790889
139.00000000000125,20.63379380276448,-0.6184178749555139,-0.034018576114075216
140.00000000000128,20.728152669080604,-0.6144311654510539,-0.035243826980954296
141.0000000000013,20.823899384115563,-0.6091296661677467,-0.03655382897498338
142.0000000000013,20.918206300272974,-0.6053807319547828,-0.03610347977938133
143.0000000000013,21.012723171807238,-0.5997976589576036,-0.03482752228018082
144.00000000000134,21.108162788736344,-0.5941998360174261,-0.03519377493170417
145.00000000000136,21.2019369887401,-0.5892122610938774,-0.03667028673252748
146.00000000000136,21.296463881847554,-0.5849021315216014,-0.03534943179244543
147.00000000000136,21.391408534285777,-0.5811202580282256,-0.03535026992161949
148.0000000000014,21.48570550346102,-0.5755954540651915,-0.03423831760170959
149.00000000000142,21.580087301644728,-0.5693000257254245,-0.0353396138255091
150.00000000000142,21.674416799071164,-0.5679478304803008,-0.03665990163329891
151.00000000000142,21.76799824130563,-0.5633681491835177,-0.03667565846022036
152.00000000000145,21.86338497095639,-0.5590793404747243,-0.0360100548386626
153.00000000000148,21.958982186036994,-0.5559173806436649,-0.03601005149869163
154.00000000000148,22.051992018026695,-0.5514439271762951,-0.036838903707860915
155.00000000000148,22.146626061309775,-0.5477265936423011,-0.03805319386282324
156.0000000000015,22.24207889450612,-0.5418366626443037,-0.03796456593111586
157.00000000000153,22.3365353849921,-0.5376183358015205,-0.03789138507106049
158.00000000000153,22.430827859188362,-0.5340858605206257,-0.03666073195892494
159.00000000000153,22.522922555211615,-0.5302908367900707,-0.03798769598645091
160.00000000000156,22.618354227865456,-0.524128765505219,-0.0379898649578303
161.0000000000016,22.713333047833114,-0.5219046372913602,-0.03799319463460815
162.0000000000016,22.80872676646037,-0.5172447930452027,-0.03733014076029573
163.0000000000016,22.902176309131942,-0.5136135950130167,-0.037324619150274074
164.00000000000162,22.996995208980795,-0.508726050748971,-0.03680612114603221
165.00000000000165,23.09189358320303,-0.5043478426427187,-0.036674521797619875
166.00000000000165,23.186321232124392,-0.5002828191870456,-0.037980075911864475
167.00000000000165,23.279467771375597,-0.4954544441461079,-0.0393038480268002
168.00000000000168,23.375139295255835,-0.4909187900492512,-0.03927109916289773
169.0000000000017,23.46959782310355,-0.4862105927729452,-0.03798016216613842
170.0000000000017,23.562677507322675,-0.48236392987753623,-0.037980255784064276
171.0000000000017,23.657786410449646,-0.47889343783067395,-0.03929984104970341
172.00000000000173,23.75196301023528,-0.4748652814285759,-0.040754937457267104
173.00000000000176,23.846352917028035,-0.47149637851083714,-0.0394200170003991
174.00000000000176,23.939534077323614,-0.4691567081232033,-0.039420037759728466
175.00000000000176,24.033733438414348,-0.4649612856703027,-0.039428970614855174
176.0000000000018,24.12653425711618,-0.4605038712463281,-0.03810023777384508
177.00000000000182,24.22236287710349,-0.4560611276694339,-0.03936902509015816
178.00000000000182,24.31539335085776,-0.45333685799815693,-0.0432614583480877
179.00000000000182,24.410958387439376,-0.4505158247029658,-0.04193996060049976
180.00000000000185,24.505895888800378,-0.44717273730498286,-0.0419426523612616
181.00000000000188,24.59706732297405,-0.44352501150217294,-0.0419327988185616
182.00000000000188,24.69448735082541,-0.43996292314455576,-0.041931519860598954
183.00000000000188,24.787868907232507,-0.43668775286051215,-0.04293000043460449
184.0000000000019,24.882275184558594,-0.43418304528896756,-0.043133645968913115
185.00000000000193,24.976186086240116,-0.4311452876602517,-0.04325005619299738
186.00000000000193,25.070700411316256,-0.4274487508102662,-0.04259044796378664
187.00000000000193,25.16192810164144,-0.4248465151397727,-0.04287979577270473
188.00000000000196,25.258446132108148,-0.42084640472053325,-0.043910134567410886
189.000000000002,25.352990870311277,-0.4178794541997672,-0.04407416994236435
190.000000000002,25.447131057223206,-0.41481358129850904,-0.0445741398754258
191.000000000002,25.541557209301033,-0.4099562836749859,-0.04384220035526987
192.00000000000202,25.63528841144837,-0.40628628563081703,-0.04457679058636277
193.00000000000205,25.730000000000196,-0.40255999999998704,-0.04588130848213723
194.00000000000205,25.823069778747826,-0.39893658066753734,-0.044569681984436116
195.00000000000205,25.916801827055654,-0.39440310030838,-0.04651999377786886
196.00000000000207,26.011236288754436,-0.38960417800280955,-0.045881555193399315
197.0000000000021,26.104833378363733,-0.387487980314234,-0.04589011610654303
198.0000000000021,26.195867185609657,-0.38205171550718403,-0.04589009338515915
199.0000000000021,26.292665538605057,-0.3782919565248232,-0.04580424719459231
200.00000000000213,26.387598842286533,-0.3749662908497733,-0.04653873759865945
201.00000000000216,26.4805528670104,-0.3696446910380779,-0.04754253804204822
202.00000000000216,26.574801439605924,-0.3651759223060686,-0.04615750378917216
203.00000000000216,26.66871823544177,-0.3614499096966192,-0.04650422399714227
204.0000000000022,26.763146784100204,-0.35788830709516267,-0.04852930586781312
205.00000000000222,26.856983262933724,-0.3537880062722695,-0.04851980792601385
206.00000000000222,26.95009033532456,-0.34982691241392033,-0.04818144644117872
207.00000000000222,27.04436479887707,-0.3468867394391022,-0.048520376872246196
208.00000000000225,27.136801885343836,-0.3424056498192059,-0.04983323570959186
209.00000000000227,27.232954911722118,-0.339609162063771,-0.04984155918694455
210.00000000000227,27.327150971740448,-0.33694116017935616,-0.04980904468813829
211.00000000000227,27.420641257921595,-0.3331021152443151,-0.05016999025726854
212.0000000000023,27.515278817519665,-0.331278406144511,-0.05050369946446853
213.00000000000233,27.609618957881146,-0.3278509286740066,-0.05182793224510984
214.00000000000233,27.70430615958015,-0.32487398938164663,-0.0518190739495914
215.00000000000233,27.798427938355392,-0.3213936126302563,-0.0511598321800566
216.00000000000236,27.89211449650257,-0.3181874769181088,-0.05115990709550555
217.0000000000024,27.987278429418144,-0.31559143642527393,-0.05114328290143888
218.0000000000024,28.07990550531501,-0.3111562255928225,-0.05246990010477326
219.0000000000024,28.175093817055004,-0.3084026009571098,-0.05246990700004073
220.00000000000242,28.266884618630176,-0.3066861833679222,-0.05246990884017588
221.00000000000244,28.36420519202156,-0.30299164883042845,-0.05358591695301218
222.00000000000244,28.457277579336917,-0.2983488232855481,-0.05378990765476299
223.00000000000244,28.551545860849046,-0.2947073214573656,-0.05382472149571704
224.00000000000247,28.64677397127765,-0.2908525228867619,-0.0531003467735669
225.0000000000025,28.740249557411893,-0.28821414455409955,-0.05444948091055668
226.0000000000025,28.834546645432898,-0.2851256529359888,-0.05444508597557185
227.0000000000025,28.928945719452937,-0.2825921272182911,-0.05640939204048934
228.00000000000253,29.023661137307887,-0.2795376306917696,-0.055109912094563285
229.00000000000256,29.118354744595436,-0.27743378771201116,-0.05510996877549523
230.00000000000256,29.212980599948477,-0.2729688439213801,-0.055441499014905915
231.00000000000256,29.30691178615441,-0.2708002017665631,-0.05544008298712999
232.0000000000026,29.40286196076547,-0.265870988307071,-0.05544008300000769
233.00000000000261,29.496370455989247,-0.2641915030043369,-0.05544008130086375
234.00000000000261,29.59053343194265,-0.2610945920622382,-0.05672532200923186
235.00000000000261,29.685020687205668,-0.2583450235377934,-0.058011012838035114
236.00000000000264,29.779537841265924,-0.25599270856210643,-0.05806997852567708
237.00000000000267,29.875095685393685,-0.2521518216610863,-0.059038524410672366
238.00000000000267,29.968385198971145,-0.2492300629933012,-0.05906010212740931
239.00000000000267,30.0624576643891,-0.24622988345008673,-0.05872883330219114
240.0000000000027,30.15701298787143,-0.24252282663056318,-0.058069810751550044
241.00000000000273,30.25186715104604,-0.2394141071244495,-0.058070541177180246
242.00000000000273,30.345926998687773,-0.2357515000228227,-0.059389497463324226
243.00000000000273,30.440729989721117,-0.2331442633747257,-0.0593912369586187
244.00000000000276,30.53585320787882,-0.23097573683330952,-0.06203080892947721
245.00000000000279,30.631229145249584,-0.2281768159200204,-0.06052173266921024
246.00000000000279,30.7245044825723,-0.22355089494923672,-0.05971990554026796
247.00000000000279,30.819543715349145,-0.22037916501856458,-0.05972556154831388
248.0000000000028,30.912715061599048,-0.2172392111058987,-0.06235938732434043
249.00000000000284,31.008133326477616,-0.2132077826425368,-0.061043420922676894
250.00000000000284,31.102600776481577,-0.21037456137829816,-0.0637372445998503
251.00000000000284,31.19753819611794,-0.20638492918375795,-0.06137266458130419
252.00000000000287,31.29167180771461,-0.20336198317446788,-0.06271845640817464
253.0000000000029,31.38611387797043,-0.20187804896976055,-0.06267998450076018
254.0000000000029,31.48029418140434,-0.19949571250570178,-0.06269301442843123
255.0000000000029,31.575422401708835,-0.19578706217088723,-0.06407038188918168
256.00000000000296,31.669653956206783,-0.19397498954842116,-0.06531987572562326
257.00000000000296,31.764829921844566,-0.19119549956825416,-0.06532019479390971
258.00000000000296,31.859017711434284,-0.1873647444597741,-0.0657488631619545
259.00000000000296,31.953654486260998,-0.1837171518927719,-0.06663504821987587
260.00000000000296,32.04927337444959,-0.18217710884464947,-0.06564995673883711
261.000000000003,32.14296319200159,-0.17846225273299302,-0.06564749846335971
262.000000000003,32.23838411439368,-0.17619506118190556,-0.06735657075798951
263.000000000003,32.33232352486835,-0.17353706118847148,-0.06721381059073916
264.00000000000307,32.42818334871233,-0.1695134838349389,-0.06862315039912392
265.00000000000307,32.522762492672534,-0.16770832455567658,-0.0673220231448477
266.00000000000307,32.61608219200728,-0.1652239318791516,-0.0686061604148378
267.00000000000307,32.71252668580824,-0.16264238520399502,-0.06861992574804265
268.00000000000307,32.80768844133421,-0.15904481625328526,-0.0695997921398872
269.0000000000031,32.90183925886775,-0.15638780683789302,-0.06959996200004959
270.0000000000031,32.997575785899556,-0.15388407905671264,-0.06959996200006913
271.0000000000031,33.09154223013859,-0.14991688144851792,-0.06959994887621868
272.0000000000032,33.18568193866281,-0.14776880797045167,-0.06993214153646843
273.0000000000032,33.28134646444941,-0.1446713013813285,-0.07028395072939597
274.0000000000032,33.37530653065018,-0.14194567242216877,-0.07058034023221138
275.0000000000032,33.47095878744571,-0.1394722619207856,-0.0722663111091677
276.0000000000032,33.56584061504717,-0.13655916326468723,-0.07256986267231635
277.00000000000324,33.66050574795199,-0.13223023984045626,-0.07256994005707718
278.00000000000324,33.755360225995474,-0.13018781632541043,-0.07157974718426185
279.00000000000324,33.84970659824306,-0.1269456831656517,-0.07189089716293484
280.0000000000033,33.94555839655329,-0.12523705305425487,-0.0725698648699229
281.0000000000033,34.04076213759857,-0.12328551031514882,-0.07256986300001422
282.0000000000033,34.13571812668108,-0.12025710463116021,-0.07256986479976257
283.0000000000033,34.23018842290535,-0.11835474068891044,-0.07384016952273864
284.0000000000033,34.32551567751715,-0.11521704414832479,-0.07385398890282557
285.00000000000335,34.42127189969076,-0.11077739955390767,-0.07354813955326778
286.00000000000335,34.515562242497076,-0.10667070982304644,-0.07485802911100814
287.00000000000335,34.6108911871938,-0.10278278043284038,-0.07501043090047066
288.0000000000034,34.70657194117767,-0.10036798922158761,-0.07619007472558037
289.0000000000034,34.80211232477706,-0.09787924998296542,-0.07616315336523716
290.0000000000034,34.896829203553025,-0.0965969141846456,-0.07750998406144438
291.0000000000034,34.99201942820314,-0.09393099781414073,-0.07750997400002557
292.0000000000034,35.08737295556622,-0.09142214481840494,-0.07750997400634718
293.00000000000347,35.18340358783027,-0.08928052816136393,-0.0775090623415573
294.00000000000347,35.27761773849319,-0.08624172492996092,-0.07847833600245968
295.00000000000347,35.3728631814925,-0.08293544561378977,-0.08152668421574827
296.0000000000035,35.46953648307129,-0.0798757566110414,-0.08144759794062262
297.0000000000035,35.56370963902869,-0.07768282521715775,-0.0801399704437844
298.0000000000035,35.660294885273814,-0.07248041218993292,-0.08145005558692242
299.0000000000035,35.75557748614249,-0.06997289904584124,-0.08145077642384102
300.0000000000035,35.850492362736894,-0.06805293134473085,-0.08243994739669036
301.0000000000036,35.94569913241235,-0.06431200112259214,-0.08417191318314377
302.0000000000036,36.03917160530524,-0.060638331995288834,-0.08408990866526622
303.0000000000036,36.135947671700556,-0.0576686511240133,-0.08408990873837041
304.00000000000364,36.2307691921137,-0.05614962500083784,-0.08475563519980245
305.00000000000364,36.327237165589914,-0.05357377625822223,-0.08672975236844316
306.00000000000364,36.42327045752041,-0.05099507517627918,-0.08671102791958951
307.00000000000364,36.51887415624679,-0.049189533396701804,-0.08672996306723535
308.00000000000364,36.61386679809937,-0.046268143868224997,-0.08747182653095997
309.0000000000037,36.70826868594849,-0.04432704168699528,-0.08973114098136037
310.0000000000037,36.804877468175924,-0.04179731672010426,-0.08969017442932836
311.0000000000037,36.90063938531407,-0.03929065754334067,-0.08970678973058188
312.00000000000375,36.99617197155462,-0.03760548631549579,-0.09152288522003715
313.00000000000375,37.09168531323675,-0.03529235415629384,-0.09266008623801003
314.00000000000375,37.18824006413345,-0.030772465065974117,-0.09266321716024217
315.00000000000375,37.28363365041183,-0.0291028292918746,-0.09398006508488876
316.00000000000375,37.37831029450995,-0.026200658552005388,-0.09332110498291302
317.0000000000038,37.47244568012981,-0.021866315185753136,-0.09331677975801123
318.0000000000038,37.57019424056393,-0.018272627555412316,-0.09465308244185477
319.0000000000038,37.666204100631795,-0.015566327618963092,-0.09587767795502167
320.00000000000387,37.761735497384066,-0.012823450186159598,-0.09798326805424784
321.00000000000387,37.8572170815324,-0.010820127165782992,-0.09988408478688093
322.00000000000387,37.95277619616855,-0.007953002935083714,-0.09989539673292835
323.00000000000387,38.04936661882817,-0.003301226273668734,-0.0998998130928026
324.00000000000387,38.14422819072756,-6.814440118237273e-05,-0.10187995996145283
325.0000000000039,38.240000000000414,0.005364582000016785,-0.10187980296828236
326.0000000000039,38.336008329159085,0.005347455901700207,-0.10385018533529422
327.0000000000039,38.43263249885393,0.008516147677076282,-0.10446164989547224
328.000000000004,38.52915761581594,0.011461736896737433,-0.10516985551760705
329.000000000004,38.625173381557495,0.014619974414281874,-0.10549893201982341
330.000000000004,38.721610724894184,0.01737991509144556,-0.10686758324162993
331.000000000004,38.816149529417594,0.022137688625937724,-0.10813987722684093
332.000000000004,38.91336652265154,0.024776835825089043,-0.10944725461346128
333.00000000000404,39.00854349434615,0.028678925420323662,-0.1107701905645424
334.00000000000404,39.10533108774326,0.03179877391347485,-0.11211562060042413
335.00000000000404,39.20068536969903,0.03629111461391493,-0.11141887914984938
336.0000000000041,39.29665489341494,0.03982897108710044,-0.11512213047018394
337.0000000000041,39.392920451000265,0.04433379072976541,-0.1175737502776677
338.0000000000041,39.48936643150947,0.046978737593768694,-0.11765572456943652
339.0000000000041,39.58513545189303,0.05099159987648747,-0.11894849742409663
340.0000000000041,39.68101769951445,0.05364811975563636,-0.12106460588852785
341.00000000000415,39.7771503432858,0.05738383802619138,-0.12272737415548862
342.00000000000415,39.87398923688151,0.06257098898898364,-0.12428725633656335
343.00000000000415,39.968221957684676,0.06461845199713023,-0.12592240223021411
344.0000000000042,40.06565224500894,0.06887176178513083,-0.1272377829527227
345.0000000000042,40.16175827886337,0.07265999193497559,-0.12951838608335997
346.0000000000042,40.25583258675311,0.07557005631748537,-0.13087438601087387
347.0000000000042,40.354487624168605,0.0828645902685115,-0.1335021758156154
348.0000000000042,40.45130459316584,0.0870999446270922,-0.1347946148907031
349.00000000000426,40.547387416280436,0.09272745945000191,-0.137500905210044
350.00000000000426,40.643485249886425,0.09852758038833029,-0.13883075735229244
351.00000000000426,40.73940566569731,0.10329121582246086,-0.14151057693764413
352.0000000000043,40.835925240979684,0.10918470777997898,-0.14305061085391158
353.0000000000043,40.93236600169142,0.11621432837376698,-0.14577278570538654
354.0000000000043,41.02884090484118,0.12111707143303065,-0.14853313152101455
355.0000000000043,41.12344566124626,0.12707680972594815,-0.15256891240885517
356.0000000000043,41.21991079906144,0.13413702232337318,-0.15380036478275683
357.0000000000044,41.31555108795521,0.14060834308072984,-0.15670809017436138
358.0000000000044,41.41289239883874,0.14686035037995174,-0.15946398668582917
359.0000000000044,41.50894726663536,0.153491806740359,-0.1625079246393799
360.00000000000443,41.605807529918806,0.16202771396583357,-0.16635798590374495
361.00000000000443,41.70201282856429,0.16792956719429114,-0.1705388364471001
362.00000000000443,41.79852309178075,0.17651919089736745,-0.1732170784733893
363.00000000000443,41.895539312523546,0.18477055551194357,-0.17777566848243742
364.00000000000443,41.99134202378009,0.19304434132896384,-0.1805352823973565
365.0000000000045,42.0901033950609,0.20278325321492813,-0.1849820440001393
366.0000000000045,42.18616828995795,0.21445446804905816,-0.1909828594430487
367.0000000000045,42.28273242864475,0.22420325154132728,-0.1967505245835648
368.00000000000455,42.37942044332179,0.2370688321664619,-0.20144897436681664
369.00000000000455,42.477201502134584,0.2505053437678966,-0.20618312915544612
370.00000000000455,42.57544563801713,0.26298684841928105,-0.2125277613519745
371.00000000000455,42.672115085106554,0.2772619926043667,-0.2189610375488602
372.00000000000455,42.768995951700475,0.2936812235754256,-0.22535908897132062
373.0000000000046,42.866022108188325,0.3095376053138042,-0.23294489963861986
374.0000000000046,42.96468109562008,0.32820134514515314,-0.24151248796815494
375.0000000000046,43.060553357078554,0.34898222849418137,-0.24926188833312946
376.00000000000466,43.15852585899055,0.37116437428260696,-0.257653719704241
377.00000000000466,43.25477529122246,0.3956295228011407,-0.2666508095027691
378.00000000000466,43.35245918477578,0.4207743633920198,-0.2767835049767613
379.00000000000466,43.44859023175808,0.44738189735367173,-0.2879746500642977
380.00000000000466,43.54607520818345,0.4742253130742923,-0.2986392553306443
381.0000000000047,43.643499504081205,0.5069075900030305,-0.3094023826875798
382.0000000000047,43.739324025095826,0.5389980565424694,-0.32464321408572694
383.0000000000047,43.837189932455004,0.5743813726148036,-0.33696023590240154
384.0000000000048,43.933996058564404,0.6113746585395092,-0.35254747161759603
385.0000000000048,44.03077874027689,0.651288168009805,-0.3678496090583505
386.0000000000048,44.128535383126156,0.6924545160619873,-0.38516630793413986
387.0000000000048,44.22543837904905,0.7378380101647768,-0.4031309165599448
388.0000000000048,44.32278438599033,0.7890783736262775,-0.4245964059515246
389.00000000000483,44.42052465255671,0.8416572405291515,-0.44582086009591126
390.00000000000483,44.51752652454462,0.8969072108365439,-0.468847869684887
391.00000000000483,44.61431375287192,0.955515097878734,-0.4943800874638722
392.0000000000049,44.71149634290327,1.0149461443727896,-0.5200454680144198
393.0000000000049,44.80951923020337,1.0856475468979103,-0.5487137272887264
394.0000000000049,44.90685789850955,1.160717327787681,-0.5781002811454785
395.0000000000049,45.00378235622642,1.2165683096386386,-0.6124797252987948
396.0000000000049,45.101494389406746,1.2770778424854419,-0.6459755112647714
397.00000000000495,45.197490677282595,1.351357988995463,-0.6823786314711966
398.00000000000495,45.296359295738206,1.4343942910772178,-0.7229286127511387
399.00000000000495,45.39234795367861,1.5199239683370869,-0.7629220290879317
400.000000000005,45.49187108458439,1.6086875713256954,-0.8089450996480743
401.000000000005,45.589731230612735,1.7297792411610196,-0.8544123061790816
402.000000000005,45.68636648960448,1.8248108061048387,-0.9072040932169996
403.000000000005,45.78494950406978,1.9365312663371321,-0.961949248272822
404.000000000005,45.88395138271662,2.0433230215890696,-1.0214945577140058
405.00000000000506,45.98182301160234,2.1506290449810206,-1.0822334083713177
406.00000000000506,46.07928437457689,2.2704618227085915,-1.1463496630739676
407.00000000000506,46.1782733645805,2.3877937219268257,-1.2165864633841235
408.0000000000051,46.27462662700001,2.528863060816162,-1.2877498814787312
409.0000000000051,46.374480626341466,2.67762849917327,-1.3704030480443654
410.0000000000051,46.47234358209544,2.7963717711029417,-1.4520695797347019
411.0000000000051,46.57071223611279,2.9071200029331496,-1.5420962691056985
412.0000000000051,46.66959979898761,3.0185871469546144,-1.6304620672431707
413.0000000000052,46.76751277747823,3.1464518696584176,-1.726089078560464
414.0000000000052,46.86584265279088,3.232223571228758,-1.8228320676738732
415.0000000000052,46.96462718509479,3.32886708315569,-1.9261624797207149
416.00000000000523,47.063216563711194,3.4250385651257926,-2.0303370821327116
417.00000000000523,47.161297904618685,3.472538015813539,-2.1394326945906377
418.00000000000523,47.260000000000495,3.5230900000008596,-2.249240136000438
419.00000000000523,47.35903241037299,3.572495886045516,-2.3615859769687395
420.00000000000523,47.45690964063755,3.571669226182347,-2.475916538526419
421.0000000000053,47.55567128108267,3.5374482290800215,-2.5881875482935954
422.0000000000053,47.653235693617624,3.5127518004392217,-2.7041860485805715
423.0000000000053,47.751027800602024,3.449978429758061,-2.8141892296274134
424.00000000000534,47.84893748102006,3.3531661978509453,-2.9239093311352238
425.00000000000534,47.94371825703127,3.2266868659793064,-3.025427748918696
426.00000000000534,48.043703848826645,3.072748951460703,-3.1303262502839413
427.00000000000534,48.14040809016518,2.9001201284959217,-3.22731797586178
428.00000000000534,48.23748157970047,2.6915941338056566,-3.324432337811148
429.0000000000054,48.335204955467,2.4635656333680394,-3.4126872721447805
430.0000000000054,48.43143849598527,2.2311734156230685,-3.487088076114674
431.0000000000054,48.528965726794176,1.989475259832476,-3.562569743795839
432.00000000000546,48.6253356995092,1.7444048326944426,-3.625936152678168
433.00000000000546,48.72097662035367,1.510119313072659,-3.6823166037871293
434.00000000000546,48.81698256663462,1.2820618889588402,-3.7320340860783765
435.00000000000546,48.91388111795783,1.0754315491820323,-3.7736013658659906
436.00000000000546,49.01009007927738,0.8886585316096518,-3.8110528849309495
437.0000000000055,49.10606018303264,0.7241600380361318,-3.840527040653545
438.0000000000055,49.20237619740488,0.5833610115772182,-3.8688003924227234
439.0000000000055,49.29904408553413,0.45884580913137873,-3.89115843088979
440.00000000000557,49.39503808590345,0.35518432836577163,-3.909763018423956
441.00000000000557,49.491546836831745,0.27109814035554697,-3.923471302515389
442.00000000000557,49.58913619027199,0.19700961840602269,-3.936993180093154
443.00000000000557,49.685013123187986,0.1364209109881206,-3.948086763565821
444.00000000000557,49.78218947184177,0.08916164778226329,-3.9581590937469913
445.0000000000056,49.88010573267259,0.044848201908794884,-3.9652255368002294
446.0000000000056,49.9771729518029,0.008688580301222016,-3.972026250389649
447.0000000000056,50.075300959646256,-0.017991088010185403,-3.9771731749447587
448.0000000000057,50.17181884862123,-0.041461982230081365,-3.983793143131458
449.0000000000057,50.269687294201375,-0.06035735171107802,-3.9880956435093897
450.0000000000057,50.36765162524914,-0.07245263562893,-3.9912218106060258
451.0000000000057,50.46506947832322,-0.08240916033530095,-3.99391027624493
452.0000000000057,50.56175197037497,-0.09270289885644807,-3.9977441361950796
453.00000000000574,50.65950301107569,-0.09783518276641436,-4.000616475953698
454.00000000000574,50.75703618568821,-0.10217896145563013,-4.003279965240235
455.00000000000574,50.85413313664351,-0.10470849656584877,-4.004778456718172
456.0000000000058,50.951584960626256,-0.10882573967747729,-4.00477862528231
457.0000000000058,51.04848409003885,-0.1114442305620798,-4.006096511696159
458.0000000000058,51.14803104770889,-0.11380757530412225,-4.009397529255695
459.0000000000058,51.24418623960365,-0.11600119990684195,-4.011491445048687
460.0000000000058,51.34247453976523,-0.11863929219564874,-4.01236822766948
461.00000000000585,51.44131975921339,-0.1215060817015417,-4.013665525867613
462.00000000000585,51.538573547161484,-0.12131443584937456,-4.014340000363366
463.00000000000585,51.636415514656505,-0.12363877730890292,-4.0157201951007915
464.0000000000059,51.73434786225895,-0.1273458231531239,-4.0150039314286925
465.0000000000059,51.83141572661434,-0.12905518517456852,-4.016288507820795
466.0000000000059,51.92968487545871,-0.12842306129072178,-4.017070886458005
467.0000000000059,52.02753450691252,-0.12390463619442864,-4.016309802114668
468.0000000000059,52.12557881785714,-0.11770475323531596,-4.016309790421456
469.00000000000597,52.22398372280968,-0.11348574903867276,-4.016642759683927
470.00000000000597,52.32098329290034,-0.11667473188011696,-4.017965283382679
471.00000000000597,52.41881470219115,-0.1230497952803219,-4.016611877788322
472.000000000006,52.51780663897559,-0.1276965903149043,-4.016639880247525
473.000000000006,52.61584999029074,-0.13189456641652986,-4.016639879743422
474.000000000006,52.714537879815445,-0.13436832379518113,-4.016493978977824
475.000000000006,52.81285540764875,-0.13423847574963738,-4.0162566351030025
476.000000000006,52.911210714004156,-0.1347972689344837,-4.015772671895682
477.0000000000061,53.00961286753084,-0.1373620832172698,-4.017959919701208
478.0000000000061,53.10787479140878,-0.139195205932065,-4.017960996859719
479.0000000000061,53.206751491680215,-0.14155648966198384,-4.019280199760744
480.00000000000614,53.30499779087653,-0.1439090462653274,-4.018425373575444
481.00000000000614,53.40393510299611,-0.14530909030512698,-4.0179607238686
482.00000000000614,53.50207677099928,-0.14524886540181678,-4.016979711007605
483.00000000000614,53.600193642312036,-0.1453739932454474,-4.0156603718773765
484.00000000000614,53.69989573323737,-0.14596353503045148,-4.016980109899434
485.0000000000062,53.79799871000483,-0.14498848616575932,-4.016980111025236
486.0000000000062,53.89697114076355,-0.14485651286729015,-4.016993614821037
487.0000000000062,53.99610479032457,-0.14378702959829326,-4.018300024937506
488.00000000000625,54.09362068248179,-0.14563144898008812,-4.018300012872483
489.00000000000625,54.19274649068743,-0.14586355853053837,-4.017932486771381
490.00000000000625,54.29130948365728,-0.14461970170301833,-4.01797005333496
491.00000000000625,54.389701923529586,-0.1431514006885268,-4.0189501058275665
492.00000000000625,54.488539569277606,-0.1427538675683872,-4.018282948465112
493.0000000000063,54.587035283149596,-0.1435743738794001,-4.018289863932843
494.0000000000063,54.6858590034377,-0.14313388413180414,-4.017002660773987
495.0000000000063,54.78499212881143,-0.14337437522045796,-4.017309931654325
496.00000000000637,54.88326970172764,-0.14268566359325177,-4.017300387866661
497.00000000000637,54.98254133638021,-0.1440917035248668,-4.018293894350584
498.00000000000637,55.08093211872034,-0.142668348426086,-4.0176179901793
499.00000000000637,55.18019120235119,-0.14212799753834174,-4.0186368147120675
500.00000000000637,55.27799697158076,-0.14132750841271063,-4.018949991023795
501.0000000000064,55.377309532106636,-0.14017319681155832,-4.018949990999989
502.0000000000064,55.47502185111865,-0.14041414515801345,-4.018949985129485
503.0000000000064,55.5745677717327,-0.1398645207723776,-4.017622134976564
504.0000000000065,55.67308460595835,-0.1403009183821897,-4.017629041734063
505.0000000000065,55.77245200588255,-0.137989347771695,-4.018964029260145
506.0000000000065,55.87069796618476,-0.13635557156773548,-4.017302902832064
507.0000000000065,55.969135120787996,-0.13604379093909846,-4.017299913994628
508.0000000000065,56.068495755861704,-0.13543118970650755,-4.017299997929613
509.00000000000654,56.16624012461205,-0.13452485602432418,-4.018622449696746
510.00000000000654,56.266092918743276,-0.13435324743845625,-4.017629868599064
511.00000000000654,56.36461552391362,-0.13288047883538137,-4.017622477107064
512.0000000000066,56.464477943809996,-0.1330211965669581,-4.01729981849969
513.0000000000066,56.56342932548485,-0.13096828289004,-4.017299815191513
514.0000000000066,56.662366176151615,-0.1322713164584399,-4.01796699195149
515.0000000000066,56.76109051141074,-0.12990085694523446,-4.019610122846854
516.0000000000066,56.860494702049564,-0.12938637062010327,-4.019637628881212
517.0000000000066,56.959508402292315,-0.1284964756056054,-4.018289735861795
518.0000000000066,57.05742499090436,-0.12922318423916546,-4.018293712017631
519.0000000000066,57.15687119243778,-0.12717187491044982,-4.016357151110805
520.0000000000067,57.25502346327952,-0.126598669764364,-4.016969464025768
521.0000000000067,57.3543767728783,-0.12482309759213464,-4.016970122998159
522.0000000000067,57.45403360301812,-0.1241482074895071,-4.016970122999996
523.0000000000067,57.55213450422588,-0.12298684538330307,-4.016970121898545
524.0000000000067,57.649336423920104,-0.12209717121109953,-4.017898115104045
525.0000000000068,57.74935290733826,-0.12163270761702492,-4.018290024025488
526.0000000000068,57.849496894965164,-0.11994748971300231,-4.018290024002525
527.0000000000068,57.94775780276185,-0.11984291676547919,-4.018289899309572
528.0000000000068,58.047366624991994,-0.12149324512006714,-4.017640174544816
529.0000000000068,58.145780842822106,-0.12189417305216929,-4.018949878960476
530.0000000000068,58.24592591328427,-0.11960679754359885,-4.018950193779622
531.0000000000068,58.343528532977146,-0.11855844086953425,-4.017641595136534
532.0000000000068,58.44473925684564,-0.11845837407430601,-4.017940868199643
533.0000000000068,58.54408774872923,-0.11939479542706008,-4.0189876227791315
534.0000000000068,58.64218721687256,-0.11846287434543498,-4.019279261264671
535.0000000000068,58.74286031315617,-0.11996951838566174,-4.017956631535949
536.0000000000069,58.84204387446403,-0.12015205311455843,-4.0179597470869854
537.0000000000069,58.94113382945954,-0.11837306878474821,-4.018615615090012
538.0000000000069,59.04019265288366,-0.11896638735863564,-4.018549992233058
539.0000000000069,59.14041126824901,-0.11760010894597903,-4.019939953540394
540.0000000000069,59.23930767233984,-0.11846600739190613,-4.018617157461395
541.000000000007,59.33816311169803,-0.11756143832900534,-4.018619981175612
542.000000000007,59.437231232161835,-0.11809126003705388,-4.018869951282441
543.000000000007,59.536548844159235,-0.1175791908160402,-4.018950076456992
544.000000000007,59.635133077815716,-0.11537262267549106,-4.019941106066758
545.000000000007,59.73420757982334,-0.11518363032135562,-4.019940056047371
546.000000000007,59.83336903229249,-0.11430007582175895,-4.021134691688176
547.000000000007,59.93236911170279,-0.1122390507034439,-4.021259958949191
548.000000000007,60.03177155512933,-0.11091098162721214,-4.0212599590035
549.000000000007,60.13009779157628,-0.11285265219138939,-4.021260053518015
550.000000000007,60.22958160192507,-0.10924919602948494,-4.020895448215052
551.000000000007,60.330846795124984,-0.10750201894174541,-4.022581862478236
552.0000000000072,60.429080240169654,-0.10646735372790062,-4.021275553990884
553.0000000000072,60.52800004637321,-0.1051374210036529,-4.019940550714293
554.0000000000072,60.62726196288291,-0.10326207221323681,-4.021262056651542
555.0000000000072,60.7262868612991,-0.1014060263029488,-4.021228722696585
556.0000000000072,60.8258826108311,-0.10193591531522368,-4.018622063341773
557.0000000000073,60.92619376770552,-0.09841480906480678,-4.019733624761783
558.0000000000073,61.026373552577645,-0.09840479989266375,-4.020929525299289
559.0000000000073,61.12459554319855,-0.09771225435223489,-4.022238932694362
560.0000000000073,61.22474347406555,-0.09566386541279055,-4.020931723482049
561.0000000000073,61.32355660279649,-0.09323018913385643,-4.020929859108243
562.0000000000073,61.42416417588233,-0.09380496853819092,-4.0219117251422185
563.0000000000073,61.52371071468277,-0.09097959778049107,-4.022239992602221
564.0000000000073,61.62235039201978,-0.08885588870922963,-4.022239993006249
565.0000000000073,61.722896543171586,-0.08614300001793297,-4.022231141191947
566.0000000000073,61.82000000000072,-0.08346982999993692,-4.02190981463626
567.0000000000074,61.92086468412731,-0.07998393599973647,-4.021909817000124
568.0000000000074,62.020824741715536,-0.07777991946197292,-4.0219098170000125
569.0000000000074,62.11989666301933,-0.0778822653853984,-4.021909816295969
570.0000000000074,62.22020414859547,-0.07543280622756453,-4.022239817226641
571.0000000000074,62.320622548358955,-0.07318117370992298,-4.023255592578945
572.0000000000074,62.42028282597057,-0.07125653173780055,-4.024550178838991
573.0000000000074,62.51968676677355,-0.06878261345319368,-4.02322991107393
574.0000000000075,62.618430591251915,-0.06775326552566478,-4.023228230975871
575.0000000000075,62.71783899458114,-0.0650422545957732,-4.023230202353058
576.0000000000075,62.81826182418086,-0.06324358528787223,-4.023660428070981
577.0000000000075,62.91846582228293,-0.06187064271367787,-4.02388986143629
578.0000000000075,63.015501119905565,-0.05898733495616902,-4.025209944819303
579.0000000000075,63.11686832116144,-0.05774092990863561,-4.024493149786703
580.0000000000075,63.21694682788285,-0.05630288179315511,-4.023890150334189
581.0000000000075,63.31609362594393,-0.05305596388550924,-4.02389010165347
582.0000000000075,63.41669366999226,-0.049138587734028016,-4.022516830034202
583.0000000000076,63.5162635578706,-0.04876501793633234,-4.023951107623349
584.0000000000076,63.615900455423564,-0.04593855105933004,-4.023889829115896
585.0000000000076,63.71605870518732,-0.04419012121153952,-4.023889829000001
586.0000000000076,63.813619271460624,-0.04187045074188983,-4.023889829
587.0000000000076,63.91489932240942,-0.040519995977598804,-4.023889829000003
588.0000000000076,64.01611513858919,-0.03750324032614357,-4.0238898308281374
589.0000000000076,64.11462926461886,-0.034747855890148914,-4.023166908523406
590.0000000000077,64.21476015201053,-0.033353208505504155,-4.024527097413184
591.0000000000077,64.3152548523208,-0.029471454988739643,-4.024548857399636
592.0000000000077,64.4152956629918,-0.029556877899136393,-4.0238902025636945
593.0000000000077,64.51476365815701,-0.025970367862897418,-4.0238902157841885
594.0000000000077,64.61399692298862,-0.023374158004473046,-4.024881596553763
595.0000000000077,64.714308894893,-0.020899672350044425,-4.023522920049158
596.0000000000077,64.81414608214473,-0.020327439490099294,-4.024213367866904
597.0000000000077,64.91460049385269,-0.017764569257289007,-4.026188262779424
598.0000000000077,65.014666664425,-0.016354488026469764,-4.024880026677162
599.0000000000078,65.11471708640657,-0.013936423824121738,-4.024880038001324
600.0000000000078,65.21531082297041,-0.011134577971503308,-4.024880872523321
601.0000000000078,65.31522291861384,-0.008362791227032429,-4.02356014409257
602.0000000000078,65.41528831044542,-0.006058882278814694,-4.02351094166056
603.0000000000078,65.51537122681466,-0.003915147902459449,-4.024873035499161
604.0000000000078,65.61631118515601,-0.0017185813263841268,-4.024220186364095
605.0000000000078,65.7166095752564,0.00011971920800498472,-4.0242201915271
606.000000000008,65.81673472549762,0.0009391063371871716,-4.023757231614747
607.000000000008,65.91589615899605,0.005020338468546985,-4.023539504649882
608.000000000008,66.01654562436106,0.006277639676080838,-4.0248726240183625
609.000000000008,66.11788010519547,0.008294147854723127,-4.023570660095185
610.000000000008,66.21805195037498,0.010186633331914986,-4.024881278464312
611.000000000008,66.3178535119199,0.01436480135185643,-4.024880352911677
612.000000000008,66.41814257788491,0.013568621443888842,-4.024066274772474
613.000000000008,66.51798162968203,0.016830112773685766,-4.026045917311208
614.000000000008,66.61862278546202,0.017967660923446482,-4.025785098771596
615.0000000000081,66.71868942935849,0.01974472654179946,-4.024880072496943
616.0000000000081,66.81920360041396,0.02035519615467554,-4.024824073847861
617.0000000000081,66.91932886379811,0.02149217833370985,-4.026190069587002
618.0000000000081,67.01922773721728,0.023396784647735154,-4.02487716837433
619.0000000000081,67.1202021225893,0.0248069119608773,-4.024880164060274
620.0000000000081,67.22000000000078,0.025633849999976182,-4.025185414356717
621.0000000000081,67.32000000000079,0.02701523999995503,-4.023890071954402
622.0000000000082,67.41989451951284,0.02542361057142461,-4.025206914468065
623.0000000000082,67.519630255073,0.028393231437651188,-4.026552831269716
624.0000000000082,67.62051002431764,0.0311898553923177,-4.02505482144659
625.0000000000082,67.71953285615115,0.030912735999058055,-4.024879876584332
626.0000000000082,67.82058565996259,0.03066957997661394,-4.026206873758911
627.0000000000082,67.9213591540685,0.03031783524419427,-4.026415193420807
628.0000000000082,68.02172446190102,0.03195670724598244,-4.026200103084423
629.0000000000082,68.1213342528029,0.03434385194252597,-4.0262161125683935
630.0000000000082,68.22216552906069,0.033947883520112035,-4.027180510179842
631.0000000000083,68.32255800581495,0.03357979993983488,-4.025864249098773
632.0000000000083,68.42280272491718,0.03495374384980162,-4.026768623732511
633.0000000000083,68.5240204165864,0.035412740081088384,-4.027179808559762
634.0000000000083,68.62451814321815,0.037636097602393885,-4.027179809043738
635.0000000000083,68.72417669920453,0.038303697422383,-4.027207678498511
636.0000000000083,68.82511410077599,0.039690060528928754,-4.027123798719501
637.0000000000083,68.92518151957557,0.0429358878699804,-4.025862052942824
638.0000000000084,69.02571412747189,0.04299151200286855,-4.026860076406921
639.0000000000084,69.12620856445206,0.045289790298347045,-4.027183071549331
640.0000000000084,69.22763106018951,0.04816053436420254,-4.027210004330814
641.0000000000084,69.32753336877028,0.049195227622836485,-4.028499843691503
642.0000000000084,69.42855653326842,0.05213148026600274,-4.028499756207182
643.0000000000084,69.52820249235916,0.052047354157115595,-4.027841614811076
644.0000000000084,69.6285818943444,0.05428531484626638,-4.027179408707603
645.0000000000084,69.72989552286907,0.05730044508470961,-4.02817244685891
646.0000000000084,69.82939432726785,0.0590137113967182,-4.028146514373942
647.0000000000085,69.92979593509668,0.05911855988105564,-4.029818474927809