File: 01_Data/EIFS_XPS/STA/N2/10K_min/EIFS_XPS_STA_N2_10KData_230203_R2.csv
##Temp./Â°C,Time/min,DSC/(mW/mg),Mass loss/mg
50.0,10.863688586696718,-1.831048057906679,0.012606544122503394
50.80000000000001,11.102857147038021,-1.7379227865509532,0.014516316457054756
51.60000000000002,11.289343889020039,-1.6653683053696524,0.012121228738013912
52.400000000000034,11.448137294518713,-1.6072789665095066,0.011832626850067918
53.200000000000045,11.591951920785453,-1.5598729132963636,0.022215686631360754
54.00000000000006,11.720458552929362,-1.5193882468579583,0.01819073455348974
54.80000000000007,11.849496320616979,-1.4838428281985707,0.011204678620286401
55.60000000000008,11.969714520809958,-1.4493213648010022,0.013101509438126158
56.40000000000009,12.08454314065635,-1.4215329294579493,0.018160287085636106
57.2000000000001,12.196884256381088,-1.3979775346054548,0.019241962756304964
58.000000000000114,12.304297157408852,-1.3781260354869944,0.016783164503382686
58.800000000000125,12.411572370668186,-1.35742648400516,0.020739754972743718
59.600000000000136,12.517238600393476,-1.3400541505216792,0.019764258215269948
60.40000000000015,12.618115732149707,-1.3248083561581419,0.016099109311272564
61.20000000000016,12.718415831995138,-1.30748459748598,0.013720135580126858
62.00000000000017,12.819080259864759,-1.293251569831014,0.014789712683003664
62.80000000000018,12.918533026690817,-1.277292243615695,0.013729312305019725
63.60000000000019,13.016727831871092,-1.2658787651009717,0.018601809515038426
64.4000000000002,13.111678784714412,-1.2543179287586348,0.011104303369513069
65.20000000000022,13.207770918231546,-1.240959839909828,0.010902908405697076
66.00000000000023,13.300532650035922,-1.2302406100241712,0.016410859948797096
66.80000000000024,13.394041905401224,-1.2194037667071012,0.018667185567662337
67.60000000000025,13.486910919789468,-1.2077422415746641,0.021910258430677843
68.40000000000026,13.578736171657585,-1.1983912843694728,0.02458406708230232
69.20000000000027,13.670378960444257,-1.1875767552888659,0.019111015240850016
70.00000000000028,13.7579033998984,-1.178163525261305,0.012232200401794735
70.8000000000003,13.851702735018552,-1.1687936106186283,0.010926782633339016
71.6000000000003,13.941675025008758,-1.157923506431613,0.012659066451312206
72.40000000000032,14.030679970282888,-1.150599048253428,0.015636532073560083
73.20000000000033,14.117710934259089,-1.14234735034523,0.018441696392644147
74.00000000000034,14.204390155154654,-1.1342330661371014,0.01976484931561462
74.80000000000035,14.293285995454255,-1.1264949251731164,0.018376409970717766
75.60000000000036,14.378527830468286,-1.1193731498838078,0.015941631109837928
76.40000000000038,14.465708251102294,-1.1132411532889266,0.016939151971770094
77.20000000000039,14.551818080253595,-1.1054800567551808,0.019851312927964493
78.0000000000004,14.636641462071127,-1.0985998857894126,0.024144229990397115
78.80000000000041,14.721857063474875,-1.0903423711333082,0.023279198533832535
79.60000000000042,14.80838572717312,-1.0823735333679685,0.020590073524670238
80.40000000000043,14.890848704556607,-1.0756867187462802,0.01931857171491025
81.20000000000044,14.975106681800161,-1.0679872090035072,0.015542001413137108
82.00000000000045,15.058634191385806,-1.0598535441244898,0.011081329214143842
82.80000000000047,15.141793863344594,-1.0524979954387559,0.009310309853943544
83.60000000000048,15.225186731636722,-1.043740945916069,0.013727196439843325
84.40000000000049,15.307654237223456,-1.0382184187771188,0.01917919833395665
85.2000000000005,15.391861792303246,-1.0285014352666886,0.022027624447110483
86.00000000000051,15.474584557176032,-1.0220757478027866,0.017368720645275282
86.80000000000052,15.55535452601188,-1.0139417633779533,0.01865237590887947
87.60000000000053,15.636872167563372,-1.0069119053516244,0.017365133333929528
88.40000000000055,15.718260561337393,-0.9980970113007205,0.01849039268143393
89.20000000000056,15.798351834653243,-0.9914892630234998,0.02269651300453379
90.00000000000057,15.880688444795183,-0.9854096503336319,0.02404212784346882
90.80000000000058,15.95938118585866,-0.976527679956036,0.024053561452701544
91.60000000000059,16.042003282903966,-0.969433854908169,0.022295630560425828
92.4000000000006,16.121782055626287,-0.9596529834439019,0.019748354239001564
93.20000000000061,16.20269845657508,-0.9527397569332462,0.01989798447140778
94.00000000000063,16.283657159971664,-0.9421173244048451,0.019659089795489137
94.80000000000064,16.362440742604335,-0.9342811071543028,0.01858892394374667
95.60000000000065,16.4411517752327,-0.9267017307741706,0.019209467501601907
96.40000000000066,16.52046701290892,-0.9155566817293836,0.018867795535941312
97.20000000000067,16.599539829879163,-0.9065871908281266,0.014919804550007854
98.00000000000068,16.679377924956114,-0.8960980135251753,0.015391250532949208
98.8000000000007,16.758965067765715,-0.8853372744894221,0.01399461459389606
99.6000000000007,16.83430994905811,-0.874323519521727,0.011901609445020611
100.40000000000072,16.91661659758193,-0.8630316376734114,0.009871550549991781
101.20000000000073,16.99419746477621,-0.849925168814643,0.011141581892193386
102.00000000000074,17.07276011127692,-0.8359535212440244,0.011349885688355599
102.80000000000075,17.149583905749243,-0.822702539952773,0.010204322173119174
103.60000000000076,17.2295397398222,-0.8074311279665819,0.012022731276989163
104.40000000000077,17.305045379507984,-0.7936641094456542,0.015576403042020459
105.20000000000078,17.382766037315513,-0.7777633032029982,0.015590188609458266
106.0000000000008,17.46279464864986,-0.7617788268802796,0.01427561003265776
106.80000000000081,17.540793743743347,-0.7484584802213793,0.012870497865059782
107.60000000000082,17.6191178111139,-0.7349570236913683,0.011515841245361536
108.40000000000083,17.695794538875575,-0.7234954821330984,0.012244460939708546
109.20000000000084,17.77327658026751,-0.7128718463630649,0.015267883467178223
110.00000000000085,17.851835630901256,-0.7045409332376988,0.015721120439873282
110.80000000000086,17.929441972372203,-0.6959129623759434,0.012295292859307416
111.60000000000088,18.008500510623392,-0.6903533351980977,0.00790106725389883
112.40000000000089,18.085397368978693,-0.6871474458592312,0.009098113511897488
113.2000000000009,18.162381740180795,-0.6852712595036641,0.009448947017262732
114.00000000000091,18.23969208413411,-0.6848633570261586,0.009430195681536802
114.80000000000092,18.316445953122678,-0.6857696922780571,0.00943032143486544
115.60000000000093,18.39378758330205,-0.6895104748805473,0.010705654527295216
116.40000000000094,18.472108035905713,-0.6935766074316805,0.012742055874848113
117.20000000000095,18.54939618810475,-0.698169534117096,0.014048492760713849
118.00000000000097,18.626629880873963,-0.7016331470100937,0.015184373373775983
118.80000000000098,18.702634105767217,-0.7008958170950242,0.014045408752730637
119.60000000000099,18.780087895424934,-0.6998984254680615,0.009653491134783643
120.400000000001,18.856780443831333,-0.7012835207022035,0.009333738875104913
121.20000000000101,18.933255447288083,-0.7006651611486485,0.010102786998165136
122.00000000000102,19.008402284112826,-0.7004592954025202,0.00756830751303017
122.80000000000103,19.087826483712025,-0.6989822737393581,0.007513064242733236
123.60000000000105,19.16440973091605,-0.6968380353277875,0.008576434438979597
124.40000000000106,19.24154365762921,-0.69487658986267,0.008563160145746096
125.20000000000107,19.315586337437278,-0.6931533467996125,0.008391567724157056
126.00000000000108,19.394999922270912,-0.6897084807388146,0.008779873665951676
126.80000000000109,19.471391187010727,-0.6858816414283362,0.00877913940686792
127.6000000000011,19.547767885142324,-0.6844143007030868,0.007457605418229818
128.4000000000011,19.623428144869063,-0.6779844734082696,0.007457272565369877
129.20000000000113,19.700191682969585,-0.6759046157288632,0.007983528604079915
130.00000000000114,19.776627414965944,-0.6731360629548221,0.008734573978245841
130.80000000000115,19.851947213400845,-0.6697019672653217,0.0067629403590672155
131.60000000000116,19.929832199309864,-0.6638404781679603,0.0063102039274651744
132.40000000000117,20.00411486524273,-0.6615162058437604,0.004888845385208285
133.20000000000118,20.080948613020315,-0.6576223581200283,0.004927777031700664
134.0000000000012,20.157119331998512,-0.6540214684597253,0.007800359466196838
134.8000000000012,20.23345378806927,-0.6495438021814909,0.005021818760409857
135.60000000000122,20.309301804781448,-0.6442560151478917,0.0032929936420922346
136.40000000000123,20.385329186919872,-0.6405591336143607,0.00111579724330646
137.20000000000124,20.462371114224904,-0.6363170149405376,0.0015202761193977565
138.00000000000125,20.53765666612418,-0.6335976346392648,0.006308337834162181
138.80000000000126,20.61451717147127,-0.6294303004379966,0.005143617755829055
139.60000000000127,20.689329728482463,-0.6258843737300069,0.004875418800845743
140.40000000000128,20.7662115296541,-0.6229812957282543,0.0020861547287127635
141.2000000000013,20.84111415212733,-0.6189715027182712,-0.0016421488041746812
142.0000000000013,20.91711072282165,-0.6147705433828836,-0.001594546031409294
142.80000000000132,20.992180332359816,-0.6111200310797151,0.002512543992944316
143.60000000000133,21.068790147616575,-0.6072586632764718,0.005628272576433169
144.40000000000134,21.144453645581923,-0.6017808038826917,0.005716721934549085
145.20000000000135,21.218045065471273,-0.5973961319843881,0.007947750800433084
146.00000000000136,21.29517737069072,-0.5935494056429912,0.009768786780650629
146.80000000000138,21.370914645026183,-0.5904742950452582,0.011090660127251795
147.6000000000014,21.446420305835804,-0.5866028512936252,0.011319773451685222
148.4000000000014,21.521817305476873,-0.5837667874044132,0.01287540999871073
149.2000000000014,21.598355723340187,-0.5794797142838617,0.015077879988855791
150.00000000000142,21.674486542807234,-0.575952923412771,0.01034204315045173
150.80000000000143,21.749641585012526,-0.5732951496586755,0.007128626277346228
151.60000000000144,21.824830595552676,-0.5679719931743427,0.0029178116715957714
152.40000000000146,21.900105356265403,-0.564249827739951,0.002299988661171426
153.20000000000147,21.976014788592842,-0.5597752875336347,0.0022802746259209528
154.00000000000148,22.05218974912635,-0.5558239627895147,0.000991465917109302
154.8000000000015,22.127545675465463,-0.5530597115519756,0.002299508211881296
155.6000000000015,22.202687440988758,-0.549774803116468,0.0029238137036502465
156.4000000000015,22.278017209730624,-0.5458177973140402,0.0029632234923777645
157.20000000000152,22.354385719612978,-0.5411505212007519,0.005006364411162423
158.00000000000153,22.429724921515184,-0.5390588312454295,0.0071534912786761495
158.80000000000155,22.5054027649429,-0.5362027432768129,0.008480975926896228
159.60000000000156,22.58054018991425,-0.5316797208152759,0.008417100768959962
160.40000000000157,22.65650038232149,-0.5267843586284706,0.005797325472691739
161.20000000000158,22.73116520624239,-0.5221064612190652,-0.0011778122655599077
162.0000000000016,22.807062721532994,-0.5153686436483993,-0.004751596454063645
162.8000000000016,22.882483595356526,-0.5128020434319563,-0.006026490132263085
163.60000000000161,22.95782000447141,-0.5081795298379769,-0.0017903947430220057
164.40000000000163,23.03291930435996,-0.5074003964936341,0.00566893145212255
165.20000000000164,23.108315053637927,-0.503698377432161,0.006028061722233247
166.00000000000165,23.18429044860018,-0.49896272942057024,0.008702074898526035
166.80000000000166,23.258596232476776,-0.4962432726782481,0.00931658766576593
167.60000000000167,23.334065260665074,-0.4923853506098123,0.007653214011727805
168.40000000000168,23.4096095239392,-0.48890949624289576,0.005054535801129134
169.2000000000017,23.482224751353666,-0.48378533006112806,0.002340545747484768
170.0000000000017,23.559122757877766,-0.4794905787077759,-0.0003288701129777749
170.80000000000172,23.6341330157631,-0.47630213400279275,-0.0016477365866336413
171.60000000000173,23.70931331552924,-0.4729022938153774,-0.00020863309971375088
172.40000000000174,23.785069744996544,-0.4699100943720174,0.0039007794929197814
173.20000000000175,23.85980734286194,-0.4682631225930848,0.0041654111979951836
174.00000000000176,23.936401104005917,-0.4653802471315321,0.003499934188653242
174.80000000000177,24.011757098495533,-0.46140407703476083,0.0029438064115856477
175.60000000000178,24.086029564630337,-0.4609294460935755,0.005962071771125288
176.4000000000018,24.160980582112447,-0.45659484257014465,0.0054746740485649426
177.2000000000018,24.235593475509386,-0.4543529304062323,0.002370813236104219
178.00000000000182,24.312000758327457,-0.45032891023209887,0.00010997525635492167
178.80000000000183,24.387150415667634,-0.4483600064019033,-8.844500085647411e-05
179.60000000000184,24.46217668030628,-0.4452356570304233,-0.0009723273808814881
180.40000000000185,24.538465495519574,-0.44219373303579773,0.000753167193533244
181.20000000000186,24.613878977373396,-0.43807448030256735,0.003107801035107549
182.00000000000188,24.688771486546997,-0.43564085801203994,-0.0010195163477577651
182.8000000000019,24.76310428047783,-0.43175897958068715,-0.002216966561861433
183.6000000000019,24.836626040151295,-0.430232315290229,0.00405104383647803
184.4000000000019,24.91394375699451,-0.42863425494651575,0.00253487910134087
185.20000000000192,24.99000000000018,-0.42638999999998856,0.0032457342938361222
186.00000000000193,25.06563456739707,-0.4235607631698931,0.0011211276616904797
186.80000000000194,25.141439697767268,-0.42022700824639164,-0.0016293591162765964
187.60000000000196,25.21687257969804,-0.41667145048118637,0.0006027466254554525
188.40000000000197,25.29142145405797,-0.41476039276986376,0.004203615357280199
189.20000000000198,25.367213507439796,-0.41192675147480157,0.003255506786826956
190.000000000002,25.442196964618812,-0.40971884588581625,0.004644925374643449
190.800000000002,25.515494727056875,-0.4061971867773732,0.0017591937687946313
191.600000000002,25.592793248618467,-0.403828574588688,0.003132439246794405
192.40000000000202,25.668279642297016,-0.4010264951866958,0.0017855544109721677
193.20000000000203,25.74256806476535,-0.39704736991238815,-0.004145851572893378
194.00000000000205,25.817951111302005,-0.39299482446968387,-0.002102671690268565
194.80000000000206,25.893330441617767,-0.38999005848724316,0.0020668576196953836
195.60000000000207,25.96835101718049,-0.3876286944213797,0.00405989983839028
196.40000000000208,26.043321880584895,-0.38525976282819835,0.0026662060106286134
197.2000000000021,26.119023403572818,-0.3807629258770291,-0.00023364696141126018
198.0000000000021,26.194708492901718,-0.3776838602005069,-0.00189895816624297
198.80000000000211,26.269466643405394,-0.37494317359163304,0.0018176256577939753
199.60000000000213,26.34492276412927,-0.37110242833213036,0.001833411347933911
200.40000000000214,26.42045422169162,-0.3687846808716837,0.0014900202728931333
201.20000000000215,26.49504742093269,-0.3641385309709398,-0.00414412646123985
202.00000000000216,26.56868414551979,-0.3603357255019234,-0.001580615049491918
202.80000000000217,26.644956605041855,-0.35853690165545116,0.007035308352044467
203.60000000000218,26.721079366029947,-0.35692923584477754,0.00867821782080469
204.4000000000022,26.795608802776954,-0.3540141037804825,0.0025561283477992802
205.2000000000022,26.871864271989736,-0.3487286842426696,-0.0028513565068521984
206.00000000000222,26.946271135988148,-0.3456314035835584,-0.005894034574712492
206.80000000000223,27.02233643813619,-0.34204376061710595,-0.010255272964244
207.60000000000224,27.095955763238678,-0.3386139330065203,-0.011869824342364055
208.40000000000225,27.172397250187487,-0.33699650190954117,-0.008770555217425091
209.20000000000226,27.247350149010362,-0.3352298202538984,-0.0006084015715179802
210.00000000000227,27.323816028621348,-0.3330845233066526,0.0069365836787707025
210.80000000000229,27.399401613890184,-0.3307210005633627,-0.0021432180378662125
211.6000000000023,27.474133544626515,-0.3281049026681051,-0.006436543356976188
212.4000000000023,27.550000905546575,-0.32357995998303596,-0.0020980864043167458
213.20000000000232,27.625510646035394,-0.31990217511126856,-0.0033321697750618995
214.00000000000233,27.700534289480863,-0.31689320593763237,-0.004730862429827454
214.80000000000234,27.775799970373168,-0.31528760312129334,-0.0015179803172715722
215.60000000000235,27.8515241022523,-0.3130751459973754,-0.004090256519051039
216.40000000000236,27.927554697611644,-0.31051007572865813,-0.0019650011596308303
217.20000000000238,28.00293506578311,-0.30693838326176653,-0.002963925766454878
218.0000000000024,28.0778089748025,-0.30604540586064904,-0.00014199212275034512
218.8000000000024,28.153810134447966,-0.30203354859997217,-0.003827987890314688
219.6000000000024,28.229315674983532,-0.297467058463772,-0.011150846742248088
220.40000000000242,28.30457992476317,-0.2940903475781063,-0.014854065183137699
221.20000000000243,28.379910505627738,-0.2924494118390676,-0.010099476412815722
222.00000000000244,28.45594586942635,-0.2906803265771083,-0.009114443529853133
222.80000000000246,28.530415776074474,-0.28826573510623976,-0.009175821019825392
223.60000000000247,28.606528668663003,-0.2850823947018312,-0.015375488504145274
224.40000000000248,28.683598908167514,-0.2840405481933848,-0.01692998904858456
225.2000000000025,28.758647235391695,-0.281974587386,-0.008398052791261712
226.0000000000025,28.833688175024996,-0.2787246486040102,-0.001978270219407996
226.8000000000025,28.91000000000024,-0.2782599999999912,-0.0009894734698336904
227.60000000000252,28.984790742621158,-0.27506566550754125,-0.006060680865732415
228.40000000000254,29.060542042705254,-0.27148702396896107,-0.01431982200505555
229.20000000000255,29.1360607150052,-0.27060779861091333,-0.014710805872948818
230.00000000000256,29.211655933984446,-0.266932461217769,-0.011084033938943083
230.80000000000257,29.287493437208486,-0.2658192926044581,-0.007021215928342706
231.60000000000258,29.3621641466241,-0.2625625018559431,-0.010006778558444118
232.4000000000026,29.43835885111463,-0.259125083445039,-0.017250957186135008
233.2000000000026,29.514225008222176,-0.25617648259235776,-0.018153009356982608
234.00000000000261,29.58894210516798,-0.2533142106729519,-0.01322345789569157
234.80000000000263,29.665047897275194,-0.25102765083080225,-0.008841732737695729
235.60000000000264,29.73999900504776,-0.24782004863309542,-0.005930071632809231
236.40000000000265,29.81636743259945,-0.24573712225723077,-0.009656153769013187
237.20000000000266,29.891495714331416,-0.2422872209912115,-0.014717152078774554
238.00000000000267,29.96606103554502,-0.24023785298110092,-0.014068624805448682
238.80000000000268,30.04288655740752,-0.23822865833641066,-0.013739262162816956
239.6000000000027,30.118287581004893,-0.2351440281493334,-0.012408364234866465
240.4000000000027,30.193739263360733,-0.23253786419938038,-0.015796077916153006
241.20000000000272,30.26901147306925,-0.23009877219866282,-0.01679071094858564
242.00000000000273,30.344929686053963,-0.22654344091470904,-0.016811296015668997
242.80000000000274,30.41935391888736,-0.22479146350676255,-0.017018105340105727
243.60000000000275,30.495058933224918,-0.2210792359660577,-0.01801253504162892
244.40000000000276,30.571723500057868,-0.21962430237211,-0.01800929458585232
245.20000000000277,30.64642000108402,-0.2162782733233653,-0.016656560501149276
246.00000000000279,30.722629801754227,-0.21411676268123173,-0.015778315249585617
246.8000000000028,30.797440562708417,-0.2120413112451352,-0.015163169753510175
247.6000000000028,30.874704140048955,-0.2097445710751299,-0.013744157789375766
248.40000000000282,30.946804327370018,-0.20694693675124565,-0.015867709494698623
249.20000000000283,31.025711401702182,-0.20663309785670497,-0.014495315466366954
250.00000000000284,31.100596146355144,-0.20531726199813624,-0.013590585712080827
250.80000000000285,31.176959079741184,-0.20314264866008686,-0.01409650288698705
251.60000000000286,31.252630336232336,-0.1989938546505153,-0.017622787259064854
252.40000000000288,31.32869875791154,-0.1962844483414388,-0.018140384149122113
253.2000000000029,31.40371963183929,-0.1937511895308142,-0.019418527574798894
254.0000000000029,31.480373757161995,-0.1932298225111468,-0.01677996820049943
254.8000000000029,31.55587777156859,-0.19154985991780252,-0.015480212210608357
255.60000000000292,31.630104230544237,-0.18752046471137523,-0.018426549509726442
256.40000000000293,31.70594985633021,-0.18648323873340242,-0.022849879380371085
257.20000000000294,31.78285009426639,-0.1833393780234518,-0.026870243085796996
258.00000000000296,31.859570404911082,-0.1811063989952431,-0.026899930041662135
258.80000000000297,31.93522344274247,-0.17823472376302887,-0.02352169568203788
259.600000000003,32.009637806891526,-0.1763831366001404,-0.01713803168556982
260.400000000003,32.086243904985004,-0.1746735711531121,-0.016327498952231956
261.200000000003,32.162385175271694,-0.17159183891891794,-0.0196324671522361
262.000000000003,32.23703034643299,-0.16766945948571155,-0.017951873497282556
262.800000000003,32.31249440088134,-0.16660244031894927,-0.016792129413838452
263.60000000000304,32.38832018654198,-0.1650582197248987,-0.017378531408694275
264.40000000000305,32.464375708150726,-0.1626810318610316,-0.020486406395602508
265.20000000000306,32.54020623127944,-0.16212604637207698,-0.019414010105958557
266.00000000000307,32.614674916772216,-0.15923393537521444,-0.018676006000410528
266.8000000000031,32.690903760055,-0.15596880888274756,-0.021700809460851733
267.6000000000031,32.76656599668747,-0.1527871135929276,-0.023144852276179684
268.4000000000031,32.842689486176894,-0.1505935732134089,-0.024640763104947894
269.2000000000031,32.918647570983644,-0.14790144077840697,-0.021747211731499405
270.0000000000031,32.99268147480799,-0.14754630060195403,-0.018352760574322335
270.80000000000314,33.070387682679105,-0.14452792891344082,-0.01972000081024916
271.60000000000315,33.14655824556331,-0.14422903012615507,-0.019879688410298968
272.40000000000316,33.22060937778813,-0.14115877509196617,-0.024334632383697485
273.2000000000032,33.29779099020167,-0.13854464170966976,-0.025098042450449665
274.0000000000032,33.37443160467223,-0.13730358752946084,-0.025364844272486753
274.8000000000032,33.45159405148428,-0.13481008898581567,-0.02581583750155758
275.6000000000032,33.52621796568061,-0.13171178697118777,-0.027337811716741545
276.4000000000032,33.602018042454375,-0.1288796263210107,-0.024949719392874492
277.20000000000323,33.67912072337534,-0.12643199709135194,-0.023059872447130036
278.00000000000324,33.754418180887896,-0.12484141908884162,-0.023456612331606674
278.80000000000325,33.831453999507836,-0.12039835602614081,-0.026837497209975858
279.60000000000326,33.90671918048101,-0.11786507569233688,-0.030801388426922927
280.4000000000033,33.9828787256299,-0.11550550893574583,-0.030078607513183364
281.2000000000033,34.05886550811494,-0.11445378310487987,-0.027450051726131797
282.0000000000033,34.13396851680096,-0.11043911977329236,-0.02888276462953243
282.8000000000033,34.21094805266416,-0.10888478554932406,-0.028768039625483688
283.6000000000033,34.28640961029101,-0.10689839794285182,-0.028550967302300556
284.40000000000333,34.36298247403159,-0.10580272731986495,-0.026066436096487067
285.20000000000334,34.43919446667704,-0.10374456273624211,-0.026115419373652582
286.00000000000335,34.51510259668057,-0.10119807904788558,-0.02613376373049414
286.80000000000337,34.59179289676158,-0.09805482665956418,-0.027425347781819376
287.6000000000034,34.6679063586887,-0.09597738146914801,-0.02876621763139786
288.4000000000034,34.74373167589748,-0.09316386212413198,-0.026769799052244192
289.2000000000034,34.82083459929843,-0.09083817274791882,-0.02351487931581442
290.0000000000034,34.89617662390995,-0.08979170335017742,-0.0236533876737286
290.8000000000034,34.97282342487282,-0.08465267619220489,-0.024889948570768095
291.60000000000343,35.04803427377339,-0.08274227296175124,-0.027676944800819836
292.40000000000344,35.12483407650431,-0.07906663451013943,-0.03024339737943693
293.20000000000346,35.200295294704596,-0.07725769753592159,-0.03320793260354282
294.00000000000347,35.27715206207639,-0.07369202689284424,-0.03547453105668641
294.8000000000035,35.35222293331289,-0.07269058835364298,-0.03502926885704705
295.6000000000035,35.42904183140728,-0.07098798041120245,-0.03404919614227264
296.4000000000035,35.50528730049741,-0.06856212119362866,-0.03540131794008383
297.2000000000035,35.58201890581689,-0.06598631915785301,-0.03370259680777066
298.0000000000035,35.657939910886306,-0.06395425687637868,-0.03106665396764008
298.80000000000354,35.73420328959218,-0.061514915918938234,-0.031121524086346497
299.60000000000355,35.809809761370886,-0.05919568068402997,-0.03218577828384772
300.40000000000356,35.88592668938835,-0.0574500349305036,-0.031190145318228613
301.20000000000357,35.9623856959891,-0.05464507506653916,-0.032004268516454104
302.0000000000036,36.037051127182096,-0.05364285842494345,-0.035450108218415544
302.8000000000036,36.115008646708766,-0.05054255119209367,-0.03473031483221689
303.6000000000036,36.1910848809872,-0.04914102796415322,-0.03552804141268551
304.4000000000036,36.26718980771464,-0.04596764165664958,-0.03822846894111365
305.2000000000036,36.34280146318634,-0.04486805649145011,-0.0396392080413559
306.00000000000364,36.42028511391665,-0.042212068988984754,-0.03676995082249235
306.80000000000365,36.4958775367547,-0.04061375937268261,-0.035464258835317786
307.60000000000366,36.5727501759817,-0.03872304713516603,-0.0354798040021973
308.4000000000037,36.648715124633455,-0.0382846690583448,-0.032907519026194265
309.2000000000037,36.72599605263436,-0.03570347470760116,-0.034132136373689725
310.0000000000037,36.80294220648248,-0.033249253228849744,-0.036795339819558404
310.8000000000037,36.87846241089615,-0.03130568395938754,-0.038416056039665136
311.6000000000037,36.95435828199905,-0.029229139273196023,-0.03953002417507001
312.40000000000373,37.03180076975269,-0.027948614402963225,-0.03951858374257
313.20000000000374,37.10814209665768,-0.02452774310366338,-0.042159973123546024
314.00000000000375,37.18379792199837,-0.021840549893984883,-0.0426762526708826
314.80000000000376,37.26101137632861,-0.021465226105330006,-0.04228811691310019
315.6000000000038,37.33659525409743,-0.019469916674943837,-0.041811828482023916
316.4000000000038,37.41143915885349,-0.01669223863512049,-0.04222488145149628
317.2000000000038,37.49037897227745,-0.013764153832019375,-0.042178870424848025
318.0000000000038,37.56795835076139,-0.012504373581797429,-0.043480407750679184
318.8000000000038,37.64062089490627,-0.009351794346458457,-0.04623215580905393
319.60000000000383,37.71962723222448,-0.006882826024697066,-0.04820115417764814
320.40000000000384,37.7962344566839,-0.004254031062069721,-0.04958990234398186
321.20000000000385,37.873003362526696,-0.0014501689696055813,-0.05082697193157948
322.00000000000387,37.949900278515116,-0.0020969399027480524,-0.052754905248973305
322.8000000000039,38.026806642079514,0.0017792116808326975,-0.05106331272968223
323.6000000000039,38.10315657390541,0.003546123612791226,-0.04700266952384702
324.4000000000039,38.18018370049865,0.005640944437486706,-0.04709459043354425
325.2000000000039,38.25722911196941,0.008585179189135077,-0.05025403385172034
326.0000000000039,38.33106373368519,0.010264668942649137,-0.05770478976135163
326.80000000000393,38.410930435939036,0.012930451321833234,-0.06160260221289793
327.60000000000394,38.48818505382619,0.015063725902366537,-0.0570729069933682
328.40000000000396,38.565313426717374,0.017074690687832895,-0.0534898988055974
329.20000000000397,38.64224583884495,0.01870703864210207,-0.04996181746556161
330.000000000004,38.71950979660289,0.02096823021534779,-0.049960306051471726
330.800000000004,38.796542720344824,0.024907801637839656,-0.051274167155871186
331.600000000004,38.87221498149546,0.026656089931506925,-0.05545183818603716
332.400000000004,38.94899032980487,0.029673240308187496,-0.05958843727299623
333.200000000004,39.026167442211374,0.034694129803637924,-0.05786097904059995
334.00000000000404,39.10302583687763,0.03659066560570738,-0.0564783831600999
334.80000000000405,39.18010534965465,0.03898291474302781,-0.06048502524742938
335.60000000000406,39.25469080401548,0.04361608060472215,-0.06600092859259821
336.40000000000407,39.33461064723158,0.04816035677585548,-0.07083412072844197
337.2000000000041,39.41113940282154,0.05003555470602823,-0.07082901556455745
338.0000000000041,39.48654901249476,0.05452304168990863,-0.06828937946702407
338.8000000000041,39.56357847881549,0.05675604425336774,-0.06828884087799159
339.6000000000041,39.640997735411645,0.05961418999966455,-0.06894659132125236
340.4000000000041,39.717110027062915,0.06250739013228868,-0.06894945680807263
341.20000000000414,39.794095580766644,0.06634638998773296,-0.06993955313991007
342.00000000000415,39.8712449615574,0.07015538556944961,-0.06965643294797275
342.80000000000416,39.94817942834035,0.07343194351816153,-0.07262829827197947
343.6000000000042,40.02404122048139,0.07722327989346264,-0.07521317936150718
344.4000000000042,40.10134089857302,0.08057114471941756,-0.07444513200258474
345.2000000000042,40.17824886896765,0.08327261260319874,-0.07366803977013126
346.0000000000042,40.25274573172313,0.08779857205364988,-0.074650355978366
346.8000000000042,40.330928059829205,0.09022049491307878,-0.07443235750444854
347.60000000000423,40.40735930751978,0.09452096886092887,-0.0757132883979259
348.40000000000424,40.48466995714206,0.09939440278423226,-0.07795481912152269
349.20000000000425,40.56163382449711,0.10085529884624819,-0.08400829886420347
350.00000000000426,40.63874843728436,0.10714092591440053,-0.089684827131296
350.8000000000043,40.71575006685853,0.10990307667657073,-0.09468126905829433
351.6000000000043,40.79195980326693,0.11482589991230403,-0.09760038222104361
352.4000000000043,40.868845814847276,0.12036092627468521,-0.09760003405976336
353.2000000000043,40.94724300022072,0.12300756921160201,-0.09740984859059854
354.0000000000043,41.02368530173561,0.12754716960054335,-0.09627842003328801
354.80000000000433,41.10157401940267,0.13263606746467005,-0.09619918615241785
355.60000000000434,41.17842885213547,0.13687483816789614,-0.10035974199532971
356.40000000000435,41.25594592635635,0.14165079447763368,-0.10166909110667399
357.20000000000437,41.33280082544148,0.1457106616477833,-0.10656347123251253
358.0000000000044,41.41009443356409,0.15153581717145093,-0.11112028852639844
358.8000000000044,41.48620535443273,0.1581708999360163,-0.11190283053403238
359.6000000000044,41.56502809362803,0.1646867644684931,-0.1129085011283344
360.4000000000044,41.64188008060393,0.17096341769762538,-0.11239235956977645
361.2000000000044,41.71877458629497,0.17712335999807594,-0.11504986484999957
362.00000000000443,41.79586438065215,0.18630626740385767,-0.1209155964636266
362.80000000000445,41.873118616025565,0.19370357848953865,-0.12605751493486528
363.60000000000446,41.95094836655156,0.2031562713036189,-0.13044751489975237
364.40000000000447,42.02809971609474,0.21026855020242172,-0.1331095872054262
365.2000000000045,42.10541531092792,0.21866627531245406,-0.13545210611999092
366.0000000000045,42.18248698277067,0.2277621745313457,-0.1362566564145613
366.8000000000045,42.259703729508345,0.2374643883866909,-0.13611269466235898
367.6000000000045,42.33738820965385,0.24782473310240807,-0.14352462329034488
368.4000000000045,42.414183098003186,0.257836742183169,-0.15201881357951086
369.20000000000454,42.492004091755305,0.2682355783865842,-0.15947609332014467
370.00000000000455,42.568879351574395,0.27976916438384913,-0.16555990621792382
370.80000000000456,42.646971614299666,0.29446570231781866,-0.169405413320729
371.60000000000457,42.72492039567575,0.3062256906859184,-0.17263072875628271
372.4000000000046,42.802205910390555,0.3217085977982348,-0.1778588658526612
373.2000000000046,42.87908878450881,0.3338443751813611,-0.1821465306981871
374.0000000000046,42.957634330666394,0.34829052815006817,-0.18789285307673742
374.8000000000046,43.03388041162276,0.36410006456705263,-0.1926499247167559
375.6000000000046,43.11268562463345,0.3809046995490943,-0.2033670281131985
376.40000000000464,43.18949542316432,0.3994689409375026,-0.21029533085751773
377.20000000000465,43.26579457091858,0.4173776202338836,-0.2165869934849458
378.00000000000466,43.3438803951314,0.43610877702768114,-0.22284484931971482
378.8000000000047,43.42157334619054,0.4573166293503843,-0.2288239890374575
379.6000000000047,43.498925665184274,0.48117373490777154,-0.2377802906051425
380.4000000000047,43.57694905064897,0.5044194624972014,-0.247497295793774
381.2000000000047,43.65487594969312,0.5273032306360432,-0.25857301805983024
382.0000000000047,43.73280924510497,0.5536598271658449,-0.2690064415866056
382.80000000000473,43.80946684955127,0.5821701974491745,-0.28324346821130586
383.60000000000474,43.886000173600095,0.6110360293235351,-0.297326254536034
384.40000000000475,43.964847101516305,0.6436814274223043,-0.3075740387847796
385.20000000000476,44.04313522833326,0.6764308832807627,-0.3198718761862711
386.0000000000048,44.121137824110924,0.7080525649859298,-0.3333121908321166
386.8000000000048,44.19896101170429,0.7439607605747706,-0.3467040478070147
387.6000000000048,44.2758787803397,0.7832401613275937,-0.3610127512650285
388.4000000000048,44.35434665606251,0.8258122236883295,-0.3827337489683349
389.2000000000048,44.43211101816198,0.868618159516938,-0.4041394035674295
390.00000000000483,44.51179693394237,0.9157078072616257,-0.41762481071645086
390.80000000000484,44.58691680943942,0.9564956615837933,-0.4356247145412411
391.60000000000485,44.66623349310146,1.0087440669020853,-0.45657450144523537
392.40000000000487,44.74396491529507,1.0634941476780124,-0.4800772539770408
393.2000000000049,44.82055433413838,1.1177946958298746,-0.4997456866479424
394.0000000000049,44.900723379780224,1.1772331527518631,-0.5281577200302148
394.8000000000049,44.979624463459004,1.2352193785574026,-0.5510121941319484
395.6000000000049,45.057163823429924,1.2995206702510362,-0.5801411144233253
396.4000000000049,45.13410496756193,1.3634216356942312,-0.6100128855356273
397.20000000000493,45.213603232023914,1.4389067174319186,-0.6405940363683396
398.00000000000495,45.29174966416697,1.497613553085344,-0.6726536466219106
398.80000000000496,45.367684821956644,1.545825983153032,-0.6994020064187527
399.60000000000497,45.44798763208428,1.612693656557157,-0.7308151353158365
400.400000000005,45.52682420535075,1.7013535385564773,-0.7736040672816631
401.200000000005,45.60488667084839,1.7803847123874026,-0.8152491404683357
402.000000000005,45.68365656830682,1.8517111634861638,-0.861397681837972
402.800000000005,45.76274549599442,1.9440741384507256,-0.905459657935805
403.600000000005,45.83990579284183,2.0320939255284687,-0.9494645552351826
404.40000000000504,45.92061475458051,2.121293524814554,-0.9991937851636084
405.20000000000505,45.99931873405554,2.221507572659048,-1.0488896598735158
406.00000000000506,46.07808415741722,2.3266933695921845,-1.102552002293971
406.80000000000507,46.15622903230171,2.4160871658171055,-1.1614653082733755
407.6000000000051,46.235194567690314,2.517784682681662,-1.2198395451106272
408.4000000000051,46.3151687941584,2.6227452748990965,-1.2769138255268397
409.2000000000051,46.39371663267537,2.6936462645502965,-1.335210172214826
410.0000000000051,46.47156378584563,2.780346010325476,-1.3960320833718058
410.8000000000051,46.550103378173205,2.8666331035958637,-1.4660328225612962
411.60000000000514,46.62886109413558,2.9658791846400554,-1.5361359999712407
412.40000000000515,46.70687968643071,3.0513592352797234,-1.6073186813280405
413.20000000000516,46.78634441055034,3.1397214648623013,-1.6814334047354182
414.0000000000052,46.86431813382752,3.209082448263281,-1.7525566761245837
414.8000000000052,46.943471193348046,3.286683082019694,-1.834148185183134
415.6000000000052,47.02144738901478,3.369662707782843,-1.9176824902913494
416.4000000000052,47.100458623639234,3.443473442665383,-2.0060041872133008
417.2000000000052,47.17769211168363,3.4745054018353434,-2.0888739401494907
418.00000000000523,47.25843240968658,3.5157535123664654,-2.1755073957662816
418.80000000000524,47.336048895378724,3.533400776483768,-2.262698149536077
419.60000000000525,47.41458915505011,3.543664966759941,-2.3461075929108244
420.40000000000526,47.49236873941977,3.5307483959743777,-2.4377398681814366
421.2000000000053,47.57099556160745,3.5023845889541896,-2.5300520205914996
422.0000000000053,47.64728116765286,3.4628449581751433,-2.6139356441509776
422.8000000000053,47.72714086321634,3.4245397293079773,-2.70243020959555
423.6000000000053,47.80410463831759,3.35063840617656,-2.7862031970990673
424.4000000000053,47.88322861567575,3.257602134911693,-2.8746407456979455
425.20000000000533,47.96091358787643,3.144955962962216,-2.9535178239206625
426.00000000000534,48.03857030683663,3.016008974385478,-3.0290047899057218
426.80000000000535,48.11573797347063,2.8814928466207124,-3.101015989021497
427.60000000000537,48.19338358477951,2.717226630947047,-3.176959969070035
428.4000000000054,48.27071604628493,2.5413529302402726,-3.2526802693254933
429.2000000000054,48.34827937438052,2.357061569030639,-3.3169772043630266
430.0000000000054,48.42557085146221,2.1671085963526493,-3.3762559671638823
430.8000000000054,48.50225751421424,1.9749253180584356,-3.431227231501764
431.6000000000054,48.579115004548704,1.7833999576830233,-3.4835424795736047
432.40000000000543,48.656112901822546,1.5950380380657583,-3.5280018320683912
433.20000000000545,48.73299711953521,1.4081731558232458,-3.568271160449319
434.00000000000546,48.80961726690164,1.2333081789718112,-3.600811766942742
434.80000000000547,48.887478655088486,1.065933372752128,-3.632818759633994
435.6000000000055,48.964094426950986,0.917249032684467,-3.6653900747202273
436.4000000000055,49.041545204591635,0.7756456927112032,-3.693176164319426
437.2000000000055,49.118342962844835,0.6498086762296849,-3.7145804925329555
438.0000000000055,49.19375983448696,0.5435354837357693,-3.7315626908481736
438.8000000000055,49.272825722628525,0.44226852134634076,-3.747550036069316
439.60000000000554,49.349695943100045,0.358303327038058,-3.7649725347530953
440.40000000000555,49.424441492635964,0.2850150422450096,-3.7765640362694493
441.20000000000556,49.50304420997402,0.21930861470892057,-3.788441303618168
442.00000000000557,49.58220847446975,0.16139063623024594,-3.7961677743714755
442.8000000000056,49.65899641663413,0.11668482760308718,-3.8052073258347385
443.6000000000056,49.73581886954683,0.07598321420464277,-3.8120480624997497
444.4000000000056,49.81266274173267,0.04112057850199793,-3.815547173815995
445.2000000000056,49.89290395139577,0.009687884194464882,-3.8221300387452173
446.0000000000056,49.97058571567844,-0.01555786603614597,-3.824972381943257
446.80000000000564,50.04798030600357,-0.039960188309958955,-3.82755844189783
447.60000000000565,50.125291789269255,-0.05517141364563957,-3.8347258151404056
448.40000000000566,50.20456634320547,-0.07024469990613658,-3.836030928059476
449.2000000000057,50.28248052123779,-0.08494988975957928,-3.837518464814276
450.0000000000057,50.36045437666884,-0.0927392851829162,-3.8426482643118978
450.8000000000057,50.438061052758556,-0.10261615899098579,-3.8452677544044493
451.6000000000057,50.516315666854865,-0.1090882694023883,-3.8453644552475508
452.4000000000057,50.59550431997793,-0.11689167619679354,-3.852722251252865
453.20000000000573,50.67266110293644,-0.11993179498195256,-3.8503922666070554
454.00000000000574,50.7522908167692,-0.1262266639240022,-3.8602395057892167
454.80000000000575,50.83019194720124,-0.12930011188829885,-3.8571402052415933
455.60000000000576,50.90894663786394,-0.13253787105433507,-3.859135953862427
456.4000000000058,50.987640502336156,-0.13468564815884376,-3.866889445366069
457.2000000000058,51.065826968252445,-0.13714496828307413,-3.8648301945871735
458.0000000000058,51.14414144616982,-0.13780994783686493,-3.8654644869003247
458.8000000000058,51.22137259465594,-0.14089663117714402,-3.86676645703868
459.6000000000058,51.302003573682406,-0.1411967159366363,-3.8695361264826458
460.40000000000583,51.37903382910092,-0.14469577755943652,-3.865932552945916
461.20000000000584,51.45859142727326,-0.14541599331873098,-3.8619611879900364
462.00000000000585,51.53767721669496,-0.14628349458666412,-3.8674398221278716
462.80000000000587,51.615602760750974,-0.14770164836899743,-3.871937864448994
463.6000000000059,51.69460217357276,-0.14946280491842764,-3.8717641610853235
464.4000000000059,51.773897688342814,-0.15041649554370232,-3.8732634560568315
465.2000000000059,51.852752903715015,-0.15077948373359049,-3.8742527958226836
466.0000000000059,51.93049794898818,-0.15175593984780406,-3.8722854905679833
466.8000000000059,52.00865979826806,-0.15289585537485703,-3.870858541301487
467.60000000000593,52.087720522861595,-0.15056156864409645,-3.8722548781757937
468.40000000000595,52.166334044382005,-0.14943027564397007,-3.873630260277715
469.20000000000596,52.24442837826691,-0.14311292797992078,-3.8711300739699084
470.00000000000597,52.32277180960056,-0.13979883641834803,-3.866901699388646
470.800000000006,52.40133291696583,-0.13686238762115424,-3.865043862107381
471.600000000006,52.479474590339215,-0.1398470310651406,-3.8680548259459493
472.400000000006,52.55862449916264,-0.1410302933564468,-3.8708728733289703
473.200000000006,52.637814930456756,-0.14143378792443007,-3.874834549860023
474.000000000006,52.71713048950347,-0.1428801936639975,-3.8773852419955124
474.80000000000604,52.79623380548376,-0.14605010292397186,-3.8764633476719785
475.60000000000605,52.8737838800502,-0.14890098051427605,-3.8763870660503907
476.40000000000606,52.95266954300882,-0.15175485770195205,-3.8765739898394966
477.20000000000607,53.032032784877735,-0.15270442019776653,-3.8778803767099554
478.0000000000061,53.11061965651439,-0.15326210631342313,-3.8778972260149644
478.8000000000061,53.18873346577565,-0.15428262116821648,-3.8751155207407315
479.6000000000061,53.26753826381052,-0.15477992232780963,-3.8698037945721477
480.4000000000061,53.34616995142267,-0.15560616446131728,-3.866613786193225
481.2000000000061,53.42273222133727,-0.15603832571139342,-3.8657687383815276
482.00000000000614,53.503424839671496,-0.1544064767607651,-3.867564496157241
482.80000000000615,53.5815901423921,-0.15661819294508741,-3.866247377764651
483.60000000000616,53.66078922555951,-0.15716107763409154,-3.864261713244293
484.4000000000062,53.7402008927324,-0.15792199674991436,-3.8629567950369745
485.2000000000062,53.818752007127316,-0.15891024390038103,-3.8658256734363463
486.0000000000062,53.896520013003126,-0.16124938651671333,-3.8657998537243596
486.8000000000062,53.97701851482399,-0.16314371269962802,-3.8644744159636826
487.6000000000062,54.054072702435555,-0.16259599731201343,-3.870746367185058
488.40000000000623,54.1345966097613,-0.16358168419604263,-3.873818723203689
489.20000000000624,54.21356988140685,-0.16241238751019266,-3.875762453544216
490.00000000000625,54.293168940965266,-0.16289277942295016,-3.8762673485964996
490.80000000000626,54.37184743052836,-0.16361062959608988,-3.873682517619091
491.6000000000063,54.45203712771314,-0.16339792601561606,-3.870212331246589
492.4000000000063,54.52953951907741,-0.16345154845247006,-3.867638423369481
493.2000000000063,54.61059768781965,-0.16351169793523176,-3.868376963624725
494.0000000000063,54.6901915505315,-0.16296409646291188,-3.8667732599606874
494.8000000000063,54.76939140394745,-0.16216782336993618,-3.8714863200156646
495.60000000000633,54.848561574582845,-0.16070851256326318,-3.8757724479332127
496.40000000000634,54.92670435510709,-0.16111930983796452,-3.8777309051723
497.20000000000636,55.006230301978206,-0.160275145723977,-3.873610850248572
498.00000000000637,55.08454529477083,-0.16011298631477883,-3.8698767842846924
498.8000000000064,55.16506631647906,-0.16008172073708435,-3.8663790308328507
499.6000000000064,55.24467996307828,-0.15940729982967625,-3.8688696033692564
500.4000000000064,55.32302340377338,-0.15855551337560794,-3.870199941987025
501.2000000000064,55.40253315994642,-0.1582970500227757,-3.8708215782887887
502.0000000000064,55.48072751285065,-0.15750551033074006,-3.8717159181375838
502.80000000000643,55.56020285651932,-0.1568457053993933,-3.8692965370754147
503.60000000000645,55.637655313784066,-0.15477804005353912,-3.8700613683730847
504.40000000000646,55.71751269617013,-0.15295891565300004,-3.8716297637057027
505.20000000000647,55.795813187382535,-0.153787221024303,-3.8699778762710157
506.0000000000065,55.874441137185094,-0.1523042388632879,-3.87086008357019
506.8000000000065,55.95384163340304,-0.15141822605096086,-3.8727304737189874
507.6000000000065,56.032935903438045,-0.1511980179290477,-3.8754292225590157
508.4000000000065,56.11066648716384,-0.14897205293556243,-3.874626257535706
509.2000000000065,56.19058225804884,-0.15002370604488,-3.871781815264745
510.00000000000654,56.26782963243564,-0.1488602453271069,-3.8694869187912246
510.80000000000655,56.34722096356109,-0.14859851303162508,-3.8730409654187015
511.60000000000656,56.426189101692856,-0.14746878218189927,-3.876966812720794
512.4000000000066,56.50564094443271,-0.14916834938568324,-3.871489174227654
513.2000000000066,56.58308449578909,-0.149792637271421,-3.8665103864586574
514.0000000000066,56.66212601740688,-0.1483809511625775,-3.867297172468732
514.8000000000065,56.74172201390186,-0.14827358813650557,-3.868854965996142
515.6000000000066,56.81901259341189,-0.14492066285201605,-3.8751322163982027
516.4000000000067,56.898581599798916,-0.14362314927068348,-3.8806048469904306
517.2000000000066,56.977777405611505,-0.1453020640340514,-3.8717187814975156
518.0000000000066,57.0567786699272,-0.14616705693134138,-3.863967659691543
518.8000000000067,57.13541380702338,-0.14592854565395455,-3.8682319949623576
519.6000000000067,57.214684371753876,-0.1437714638511469,-3.8714373327063183
520.4000000000067,57.29424546018913,-0.14152878218040335,-3.8774541200241157
521.2000000000066,57.37328640748259,-0.13935545396562224,-3.878395191793934
522.0000000000067,57.452771359333155,-0.13941905221570225,-3.8772439221845456
522.8000000000068,57.53289327039929,-0.14054178222364372,-3.873570903130517
523.6000000000067,57.61169969952274,-0.14156537883560588,-3.872577060801364
524.4000000000067,57.6908101545966,-0.13953394344088718,-3.8716201308006357
525.2000000000068,57.76881033373752,-0.14093919702141255,-3.8722564811543907
526.0000000000068,57.85009344274846,-0.1404852436229508,-3.8742731140415154
526.8000000000068,57.929484096482774,-0.13867776776178778,-3.875181522599079
527.6000000000067,58.009399858109724,-0.1382000103983387,-3.872932189874345
528.4000000000068,58.08787982782911,-0.13635830926265538,-3.8720602684932564
529.2000000000069,58.16825755723048,-0.1366226179687975,-3.874885054965732
530.0000000000068,58.248035418480676,-0.13628221933137713,-3.8753480695270217
530.8000000000068,58.326270195481726,-0.1338459739506287,-3.8733788653811976
531.6000000000068,58.405930897967266,-0.13265894092231884,-3.8717298376146023
532.4000000000069,58.485045506786015,-0.13116291060424237,-3.8710878740046555
533.2000000000069,58.564692351380444,-0.13077567993857142,-3.8724441023398573
534.0000000000068,58.64398070118495,-0.12827505742983542,-3.873066911987023
534.8000000000069,58.72284248470676,-0.12845637808326146,-3.871693967253469
535.600000000007,58.802418733586855,-0.12797102749545644,-3.870421865631089
536.4000000000069,58.88108928146313,-0.1265104487499025,-3.8704199144458498
537.2000000000069,58.96150992381353,-0.12677163226179392,-3.8719169743450705
538.0000000000069,59.03991428693472,-0.12696953663259167,-3.8679925097327224
538.800000000007,59.119529907036515,-0.12657615082322177,-3.8679864429276005
539.600000000007,59.198450629122455,-0.12664365943000894,-3.8695195433725305
540.4000000000069,59.2788146878366,-0.12643660386462002,-3.873160993815759
541.200000000007,59.3576812333725,-0.1261675083246376,-3.8734462302269708
542.000000000007,59.437214844356404,-0.12334675393738369,-3.873122939969926
542.800000000007,59.51574994789796,-0.12595816776532134,-3.8664125135319805
543.600000000007,59.59538059731235,-0.12586755924560356,-3.8643318371665902
544.400000000007,59.67505549970905,-0.12642273713584842,-3.868428489871796
545.2000000000071,59.7543205708256,-0.12308020894747057,-3.8684412448211987
546.000000000007,59.83179541077124,-0.12546267595601596,-3.869972550459045
546.800000000007,59.912416024466964,-0.12337897524043925,-3.874086204332087
547.000000000007,59.93327903164977,-0.12441022817816479,-3.8745898934692824