File: 01_Data/EIFS_XPS/STA/N2/10K_min/EIFS_XPS_STA_N2_10KData_230203_R3.csv
##Temp./Â°C,Time/min,DSC/(mW/mg),Mass loss/mg
50.0,10.85043523384103,-1.8576056184192036,0.00301911769267571
50.80000000000001,11.096458744326092,-1.7640914412474107,-0.00018869757953821065
51.60000000000002,11.28061274932506,-1.6943686799907829,0.0038642494428993146
52.400000000000034,11.438466203112787,-1.637887774208525,0.0020173110614236656
53.200000000000045,11.585130176026569,-1.5887231342919181,0.005492479755559998
54.00000000000006,11.714485769477434,-1.5498648380708284,0.00609315378034303
54.80000000000007,11.839283434205115,-1.513915664761909,0.008169464812161298
55.60000000000008,11.959867734729189,-1.4844579468517436,0.004625974763813101
56.40000000000009,12.075187264636597,-1.4599428494390103,-0.006057490371812246
57.2000000000001,12.185550795821907,-1.4354876827871401,-0.007653413774521223
58.000000000000114,12.296392282819143,-1.4126458263254476,0.005447813040621696
58.800000000000125,12.403334597436297,-1.3946170181033641,0.0027613110276965003
59.600000000000136,12.50826249470893,-1.3771375345369075,0.007826992128143306
60.40000000000015,12.609431871055389,-1.3622371427950724,0.009576754326266812
61.20000000000016,12.712524879514534,-1.3457674806649689,0.007022264788004495
62.00000000000017,12.81069003671007,-1.3310850346845693,0.001726408669636026
62.80000000000018,12.908019730138879,-1.319352373984367,0.0012660482350956848
63.60000000000019,13.00416148254462,-1.30773260074365,0.004555896190706843
64.4000000000002,13.101417231208478,-1.2953463143424282,0.004677569789456992
65.20000000000022,13.197546265578511,-1.2856797588543616,0.003792282917228995
66.00000000000023,13.290830000000028,-1.2729000000000017,0.0009900597095047203
66.80000000000024,13.385159806665108,-1.2601705750788392,0.0007087563945940012
67.60000000000025,13.479771283239376,-1.2514488480737274,0.0010851137798528754
68.40000000000026,13.571335698997055,-1.240132651380778,0.004682673403530568
69.20000000000027,13.663526541451958,-1.2303346551690089,0.007605632355319081
70.00000000000028,13.751935546903963,-1.2220779324645425,0.005617405964812416
70.8000000000003,13.843089384143157,-1.213352677298745,0.002416849212760308
71.6000000000003,13.93371942281627,-1.2036440234214805,0.001442770442005692
72.40000000000032,14.020830000000036,-1.195929999999999,0.004159892505847029
73.20000000000033,14.108982649351,-1.187370846389023,-1.1395691539739516e-05
74.00000000000034,14.196280874801952,-1.1812896667344868,-0.0040227279102089675
74.80000000000035,14.283548832186613,-1.1732710458553153,-0.002341666698669531
75.60000000000036,14.36893035035923,-1.1664827963005238,0.0008248037046927337
76.40000000000038,14.456810597287433,-1.1584615123230468,0.000899133026247334
77.20000000000039,14.541863763442915,-1.152816327920697,0.004961301000874219
78.0000000000004,14.627996213920305,-1.1450235926290686,0.005590173895443584
78.80000000000041,14.714179429108718,-1.137609706438673,0.006690884362433813
79.60000000000042,14.797422481041728,-1.1313552463909198,0.0039148660095409404
80.40000000000043,14.882607908913654,-1.1238708824821266,0.003839594540241187
81.20000000000044,14.967027351485596,-1.116091478784783,0.0027767380038166145
82.00000000000045,15.050136688251582,-1.1077143229187592,0.005819967732050735
82.80000000000047,15.133752830223855,-1.100642627826292,0.0077770033177451126
83.60000000000048,15.217418115991926,-1.0931213900077061,0.003274329387183972
84.40000000000049,15.29980802829305,-1.0854461592259659,-0.002313764246923089
85.2000000000005,15.38112108615022,-1.0779454318629906,0.0003879758606495365
86.00000000000051,15.461156915881336,-1.0700200439613567,0.006347433820600212
86.80000000000052,15.545889402434296,-1.063494206888881,0.009360262883657988
87.60000000000053,15.626972595184256,-1.0555833382055222,0.005075026408786432
88.40000000000055,15.709095551013393,-1.0478384090627662,5.999775584442091e-05
89.20000000000056,15.790428025758514,-1.040268719451783,0.0008737138099137454
90.00000000000057,15.871227847795765,-1.032251818889458,0.002327215810986605
90.80000000000058,15.951022329377421,-1.0249371920751946,0.0011288469709023197
91.60000000000059,16.032012652072634,-1.0170016074016497,-0.00044685131004662537
92.4000000000006,16.11137325463509,-1.0088384786938558,0.0010974855965479868
93.20000000000061,16.191109731434363,-1.0020745618370461,0.0024115855951194476
94.00000000000063,16.27139296045775,-0.9912303869219626,0.0003370296148292873
94.80000000000064,16.351839503331906,-0.9851953043232992,0.0003269144412256786
95.60000000000065,16.430158128836332,-0.975332703034379,0.0016396283519557464
96.40000000000066,16.506417618097057,-0.9677837367062414,0.0029599653053331565
97.20000000000067,16.588459376357427,-0.9565546546939029,0.0039175974565801575
98.00000000000068,16.66840988301835,-0.947689250968857,0.0010948494555038657
98.8000000000007,16.745798269929587,-0.9374419957443791,0.00029383768434776414
99.6000000000007,16.825470303168363,-0.9274283614438965,0.0013223991744775176
100.40000000000072,16.90366979615714,-0.9154081383927761,0.0002748063016775326
101.20000000000073,16.98167836822052,-0.9028461225688678,0.0024938964715275347
102.00000000000074,17.05953719235842,-0.888370073106049,0.0017492288442682025
102.80000000000075,17.138755299077925,-0.8734700274287341,-0.0009145433823376514
103.60000000000076,17.216248917659893,-0.8578329654027912,-0.001732655409896644
104.40000000000077,17.294362153832164,-0.8414456906970509,-0.000957295602599384
105.20000000000078,17.37211828160245,-0.8229818656746749,-0.0012577772855788538
106.0000000000008,17.45034802840019,-0.8081074492614388,-0.003976475056706175
106.80000000000081,17.52844445605865,-0.7914980826407362,-0.0027295538592224666
107.60000000000082,17.60703975168345,-0.7766785348289459,0.00015189679069438355
108.40000000000083,17.684411512524388,-0.7654136048428948,0.001535691239079373
109.20000000000084,17.762334783811585,-0.7546061947780323,-0.0015857775733567614
110.00000000000085,17.8392110469237,-0.7476094745386556,-0.005937272195890131
110.80000000000086,17.917298172149305,-0.7421220855346554,-0.00869197167121838
111.60000000000088,17.9915176757352,-0.7392720373560321,-0.004462107159198592
112.40000000000089,18.068569430243347,-0.7411568289295078,-0.004517148023615913
113.2000000000009,18.14959242247441,-0.7441174424617729,-0.007376080045856437
114.00000000000091,18.226237193243755,-0.7493743357167151,-0.007330072531208209
114.80000000000092,18.305002432524333,-0.7564439792022282,-0.008679191698238053
115.60000000000093,18.381124608131323,-0.7665631024001766,-0.007360230312912552
116.40000000000094,18.45862281430221,-0.7758233152583531,-0.007378319020323154
117.20000000000095,18.535868053754612,-0.7820580772943575,-0.007364850079532914
118.00000000000097,18.612125279552185,-0.7851606555073878,-0.008684794871812063
118.80000000000098,18.689809182551222,-0.7871976685247295,-0.010243676763300513
119.60000000000099,18.76518668705751,-0.7872239898724299,-0.012620185198769285
120.400000000001,18.84148139025165,-0.7854300219631404,-0.012629284006388186
121.20000000000101,18.918958506019028,-0.7836814474250174,-0.009865485475800906
122.00000000000102,18.99516208409528,-0.7818372375489834,-0.008260664995908495
122.80000000000103,19.074844401861412,-0.7807221817071999,-0.005634088213914534
123.60000000000105,19.15041190902376,-0.7764366977559316,-0.00688659200252717
124.40000000000106,19.22827161695537,-0.7755223800278211,-0.006960691699166688
125.20000000000107,19.30492694652778,-0.7719047134543471,-0.006709356210195416
126.00000000000108,19.38048221343464,-0.7685551089803784,-0.0050602348929373875
126.80000000000109,19.45732319283031,-0.765377757484469,-0.003787085899602083
127.6000000000011,19.534756891173974,-0.7606238780831471,-0.007853106059229287
128.4000000000011,19.6106294913997,-0.7569890286608059,-0.007798914683443847
129.20000000000113,19.686694922405945,-0.7527645284329835,-0.009281465149764578
130.00000000000114,19.759255736931962,-0.7496161399882251,-0.01186284934546622
130.80000000000115,19.838890320016876,-0.7446343228210048,-0.01218605406930573
131.60000000000116,19.915125881838645,-0.7410729378739044,-0.010804736917647606
132.40000000000117,19.991905929209718,-0.7375647562332115,-0.010688279725335814
133.20000000000118,20.068936252550277,-0.7351248274992107,-0.012130398581634338
134.0000000000012,20.14401693126076,-0.7309620648163156,-0.012757581504606819
134.8000000000012,20.221719779288698,-0.7269033700461873,-0.012367761601132177
135.60000000000122,20.29691810971891,-0.72398253553789,-0.011414214587324611
136.40000000000123,20.371549277229825,-0.7208307221218127,-0.011100642707648767
137.20000000000124,20.445292446266286,-0.7160331111131798,-0.013508472985912068
138.00000000000125,20.523609422878593,-0.7133174551780875,-0.010870351614411522
138.80000000000126,20.59952188520109,-0.7097983022858041,-0.009544320693358532
139.60000000000127,20.675840847976954,-0.7055078638425979,-0.006586277191823253
140.40000000000128,20.750830935693582,-0.7037499918358404,-0.006699912168708799
141.2000000000013,20.82681716224099,-0.6982255696676943,-0.009877876888696235
142.0000000000013,20.90138160937447,-0.6945184990429927,-0.014546382398100022
142.80000000000132,20.978753217257804,-0.6903513257817796,-0.015080941344728593
143.60000000000133,21.05360197089628,-0.687382085125203,-0.012535605273496397
144.40000000000134,21.128976822429642,-0.6834161474251207,-0.008263390408708826
145.20000000000135,21.204292571133507,-0.680055874621173,-0.006937723536597051
146.00000000000136,21.279455316945793,-0.6764918211758527,-0.008236469313445127
146.80000000000138,21.355103148491736,-0.6716219405256396,-0.011059346657858349
147.6000000000014,21.430640221322413,-0.6691462157816721,-0.013511393997202248
148.4000000000014,21.50548419932359,-0.6645899524880287,-0.01228697452833094
149.2000000000014,21.582225920441946,-0.6596081780469205,-0.011269475195598844
150.00000000000142,21.656594433431003,-0.6561231749028904,-0.010841492520023532
150.80000000000143,21.73177101925929,-0.6530291287108403,-0.010590009373176112
151.60000000000144,21.80903127345823,-0.6480153893766213,-0.009396095133054061
152.40000000000146,21.883072256814632,-0.6454600130760757,-0.012059254809036357
153.20000000000147,21.958788332927035,-0.6415109531175961,-0.012079723647011598
154.00000000000148,22.03401756064864,-0.6369751262550893,-0.013035083325351415
154.8000000000015,22.10882497238554,-0.63421664956687,-0.013620145264320538
155.6000000000015,22.185245004405225,-0.6302162381351937,-0.012212116364267889
156.4000000000015,22.261026409010114,-0.6278968948976611,-0.011012108189608405
157.20000000000152,22.334734685176418,-0.6242094241479887,-0.012298801669821557
158.00000000000153,22.410162769926604,-0.6206605041082113,-0.0123005917156922
158.80000000000155,22.48641783359537,-0.6161152262012491,-0.013611998211335852
159.60000000000156,22.560725585791328,-0.6136878889008949,-0.014939864247851986
160.40000000000157,22.6360851253457,-0.6089478571785283,-0.01463574475940499
161.20000000000158,22.71203441915645,-0.606854703948642,-0.010768744026626642
162.0000000000016,22.787047412978684,-0.6036872284062632,-0.00945886121255235
162.8000000000016,22.85926679276212,-0.6000714419350224,-0.009439019569183582
163.60000000000161,22.938667955980883,-0.5970829255301293,-0.009903239745563841
164.40000000000163,23.01242321795473,-0.5927018118176088,-0.01188344939003727
165.20000000000164,23.085822370224893,-0.5898285409993985,-0.012080172918486731
166.00000000000165,23.163395154546702,-0.5872102857322286,-0.010774483210819419
166.80000000000166,23.23930330057787,-0.5835567806555565,-0.011110836402897561
167.60000000000167,23.312781069692637,-0.5801141400425285,-0.012426291059237204
168.40000000000168,23.388553967746393,-0.5763513279029423,-0.013900602607239687
169.2000000000017,23.46600680306435,-0.574261064151372,-0.015160560995303385
170.0000000000017,23.540733911914174,-0.5714261768185015,-0.014178183822733281
170.80000000000172,23.616139163611354,-0.5684786027692148,-0.012530648520487908
171.60000000000173,23.692041326046272,-0.5659263901954674,-0.010980953775606928
172.40000000000174,23.767362070170723,-0.5616389784315413,-0.011026724931808563
173.20000000000175,23.842488051413827,-0.5618283006208614,-0.009670142646459823
174.00000000000176,23.91977376392998,-0.557048602992988,-0.009670152821725786
174.80000000000177,23.992771891537817,-0.5552343319303897,-0.009138256459114036
175.60000000000178,24.066728950819083,-0.5526268014756955,-0.006247979806408566
176.4000000000018,24.144386759147608,-0.5497240110652986,-0.009650680475006279
177.2000000000018,24.21951905071338,-0.5464698304076401,-0.014051184967789343
178.00000000000182,24.294617184374108,-0.5423047053292567,-0.017693252807750248
178.80000000000183,24.370830000000183,-0.5400799999999949,-0.01734866060947038
179.60000000000184,24.44619805567627,-0.5373067774063581,-0.01823973576509763
180.40000000000185,24.520830889024133,-0.5344799147171051,-0.017680034994890015
181.20000000000186,24.596281228792023,-0.5328291426146453,-0.013201518652647959
182.00000000000188,24.67073106043285,-0.5310444869404201,-0.009447100589710988
182.8000000000019,24.746730111896838,-0.5272075345807036,-0.008510858285291079
183.6000000000019,24.820451724669812,-0.5248354481080675,-0.012515829715952886
184.4000000000019,24.89639682456316,-0.5214227103039205,-0.016556840686355656
185.20000000000192,24.971898327786548,-0.5185152668105486,-0.019099744123370677
186.00000000000193,25.04676965874761,-0.5164665984992068,-0.019030728698119947
186.80000000000194,25.120830000000193,-0.513019999999979,-0.018118712609954457
187.60000000000196,25.196399971763586,-0.5103415592876688,-0.01937125865907996
188.40000000000197,25.27224657729881,-0.5073081465493887,-0.01943720986368591
189.20000000000198,25.345511461007053,-0.5023771771872695,-0.01797883591919236
190.000000000002,25.420659562823996,-0.5009923037740075,-0.01800996964101298
190.800000000002,25.495892028448303,-0.49636240544982546,-0.019250001009440076
191.600000000002,25.569743423183432,-0.49541847319907745,-0.016617514975991732
192.40000000000202,25.645853552751316,-0.49168637263369264,-0.01463591622070437
193.20000000000203,25.722532965250974,-0.49113221059555,-0.015384988146006418
194.00000000000205,25.79655331881283,-0.4896717258341359,-0.015914752706441604
194.80000000000206,25.87128222627771,-0.48706089469412195,-0.018580369474722414
195.60000000000207,25.947120505464266,-0.48433146950313166,-0.019859322817016523
196.40000000000208,26.021843166701128,-0.48194617592821715,-0.019595135491627502
197.2000000000021,26.097031121097658,-0.4802782919684991,-0.01888927209131941
198.0000000000021,26.17257945720879,-0.4765888952242989,-0.01841388165814406
198.80000000000211,26.246724132605294,-0.47546340857959646,-0.01770672291836295
199.60000000000213,26.32303995820344,-0.4710241674594432,-0.01636331103620625
200.40000000000214,26.397525542821064,-0.46836897052082216,-0.01778893360718925
201.20000000000215,26.473014292816096,-0.46563645724360614,-0.01646681362821134
202.00000000000216,26.547607831953833,-0.4630362655605808,-0.017909680168173736
202.80000000000217,26.623290815300408,-0.45901542533922834,-0.021426093021315484
203.60000000000218,26.6984750279972,-0.4573717142269011,-0.022841626704192652
204.4000000000022,26.772749953181947,-0.45424184432881437,-0.021524162745436115
205.2000000000022,26.849391780515322,-0.45177048925801755,-0.02021000955751484
206.00000000000222,26.922691027873004,-0.4483850506932651,-0.020218639253142268
206.80000000000223,26.998495308611552,-0.44561167044482464,-0.021530417721960404
207.60000000000224,27.07301395283149,-0.44363380917130946,-0.022828865166030443
208.40000000000225,27.148770069871844,-0.44102651550326905,-0.02416117657335537
209.20000000000226,27.224246770012872,-0.4391258500493572,-0.024173288117580682
210.00000000000227,27.298570818689427,-0.4351660183535923,-0.020397008504301706
210.80000000000229,27.375492208441912,-0.43298858317865946,-0.022278343956958935
211.6000000000023,27.44937678143315,-0.43283633654518916,-0.02229008612543737
212.4000000000023,27.52481263761274,-0.42820479418703467,-0.02333418801757592
213.20000000000232,27.600499115675348,-0.42469144463663816,-0.022511026385775956
214.00000000000233,27.67565322673141,-0.4208985748690585,-0.022501994026518535
214.80000000000234,27.75060266325157,-0.42099508080616055,-0.022511851204008337
215.60000000000235,27.826190433370083,-0.4179292185031616,-0.023854393354425518
216.40000000000236,27.901260270460202,-0.41446270330950896,-0.0265604412477769
217.20000000000238,27.973537407916286,-0.41288944400362887,-0.026563030716352465
218.0000000000024,28.051213546354013,-0.4099696489966221,-0.02481523530679519
218.8000000000024,28.125375371754075,-0.40773478592509754,-0.019864964852300826
219.6000000000024,28.202483714616267,-0.4060306547608713,-0.022901336109163672
220.40000000000242,28.278333747791752,-0.4027364384104369,-0.026694891246109353
221.20000000000243,28.354251662940694,-0.3999369393195748,-0.03107668475622427
222.00000000000244,28.426394944673522,-0.3996683911702327,-0.029229354211743885
222.80000000000246,28.504710688268247,-0.3955181349867977,-0.029814663002107
223.60000000000247,28.579833882435075,-0.3933581987706105,-0.029659503158569578
224.40000000000248,28.654825047915274,-0.39002639125691047,-0.030199768795578397
225.2000000000025,28.73107819637055,-0.388020513828953,-0.028872175711641912
226.0000000000025,28.80627883129834,-0.38512349693281905,-0.026885916143538413
226.8000000000025,28.88172495472402,-0.3851114602703506,-0.024160663644507085
227.60000000000252,28.956762335321855,-0.3832253415374141,-0.02558140118005614
228.40000000000254,29.0316949691012,-0.38096403502488563,-0.026009657982675183
229.20000000000255,29.10745597356735,-0.378460466602322,-0.025470374309937593
230.00000000000256,29.183268183804827,-0.37657567211148785,-0.026798016943385683
230.80000000000257,29.258619366447814,-0.37440917704604776,-0.026663409587233566
231.60000000000258,29.33508831924626,-0.37226830803274147,-0.025370467521737883
232.4000000000026,29.410263977475626,-0.3714356722618336,-0.028192309434909912
233.2000000000026,29.484959741435496,-0.367010887837869,-0.03052340353714822
234.00000000000261,29.561548611224822,-0.36439115058111576,-0.03538093201886161
234.80000000000263,29.63553048189522,-0.36267349686542505,-0.036017814232823575
235.60000000000264,29.712028115187643,-0.35979739119174275,-0.034689975422140584
236.40000000000265,29.78624587064872,-0.35692652608343806,-0.034689935911313974
237.20000000000266,29.862900514026155,-0.35418804798207393,-0.03468982194917336
238.00000000000267,29.937749313214635,-0.3516707300790132,-0.03349960605215374
238.80000000000268,30.01313732442103,-0.3500845570574489,-0.03070498188632076
239.6000000000027,30.088686162829653,-0.3483175672782663,-0.03210068617372208
240.4000000000027,30.163973754363564,-0.34498456901906177,-0.03207709707893258
241.20000000000272,30.23819972026905,-0.34391010580026665,-0.032062707892606124
242.00000000000273,30.315009846588737,-0.3420642419255632,-0.03337977580909168
242.80000000000274,30.389596252170655,-0.3384426071254868,-0.033350309972085324
243.60000000000275,30.46515345269371,-0.3361428678118808,-0.035734178552324636
244.40000000000276,30.54031875152716,-0.3351294624413583,-0.03733013060022694
245.20000000000277,30.61531624686147,-0.33109825233409246,-0.03595547725420145
246.00000000000279,30.692391267572447,-0.330530183504463,-0.03472491946908596
246.8000000000028,30.76725189219315,-0.3287545342546952,-0.033377887080336954
247.6000000000028,30.841121499896364,-0.32707162229272807,-0.03207010047641168
248.40000000000282,30.91741360032811,-0.3247269484358195,-0.032066871460024515
249.20000000000283,30.99371249364622,-0.322296383086157,-0.03413121659965723
250.00000000000284,31.068734905510496,-0.32030017100484726,-0.03600990501740098
250.80000000000285,31.14387608798037,-0.3163599256673451,-0.03619317326094018
251.60000000000286,31.219415450382133,-0.3156590882581861,-0.03732984952164786
252.40000000000288,31.293137046349575,-0.31399758132630873,-0.03600569193846326
253.2000000000029,31.3702705902112,-0.31218394731836097,-0.03469445768246482
254.0000000000029,31.447268196341717,-0.3099560592577924,-0.03605223387328049
254.8000000000029,31.522215157754374,-0.30807137671748086,-0.03700384455074346
255.60000000000292,31.59724899313241,-0.3062033468204732,-0.03862608298408032
256.40000000000293,31.673552792435213,-0.30354600862368325,-0.04150543976690324
257.20000000000294,31.748844686331815,-0.30256807740249947,-0.044130252177579266
258.00000000000296,31.825515029518378,-0.2994527830068405,-0.04413699183233888
258.80000000000297,31.900573037040715,-0.29821130855795863,-0.04280315757414055
259.600000000003,31.97520010296336,-0.2964858685809397,-0.04021206367159058
260.400000000003,32.05207611552417,-0.2930331420228132,-0.03602973130234721
261.200000000003,32.126753610355415,-0.2924304087450409,-0.03603683113930645
262.000000000003,32.20332078033204,-0.2904678966675397,-0.03664913925515423
262.800000000003,32.279551430809626,-0.2889981089984067,-0.036670616533173384
263.60000000000304,32.35509106683724,-0.2865927293565002,-0.03799399968396733
264.40000000000305,32.43158217288145,-0.28450518397662206,-0.040659354940224546
265.20000000000306,32.50681349803089,-0.2827296390954515,-0.0411804208452371
266.00000000000307,32.58275610992769,-0.27943407333832737,-0.04390977122318995
266.8000000000031,32.658092532065254,-0.2774244380021428,-0.044152571393314854
267.6000000000031,32.73404441377799,-0.2765842311297877,-0.043923016638482526
268.4000000000031,32.80910248927471,-0.27394976104264823,-0.04390662304971826
269.2000000000031,32.886641092438964,-0.2705755963146649,-0.04523582216660049
270.0000000000031,32.96205504977529,-0.26994484616152575,-0.04491725143897041
270.80000000000314,33.03743837769431,-0.2666496179505708,-0.04644351645688882
271.60000000000315,33.11398722941837,-0.26457886451472307,-0.048314169146360886
272.40000000000316,33.18707588711625,-0.2629023573262829,-0.04678182179992474
273.2000000000032,33.26456640721073,-0.260653393330749,-0.04402976655696067
274.0000000000032,33.340552319532506,-0.25815189623996415,-0.04544395139954016
274.8000000000032,33.417049079576216,-0.2561795673585939,-0.0424830582185276
275.6000000000032,33.49267853097306,-0.25293052607270894,-0.04249002299237059
276.4000000000032,33.568136135761286,-0.25147085923991747,-0.041580891045904345
277.20000000000323,33.64301598754307,-0.24878551389820686,-0.041228699653904854
278.00000000000324,33.72008342193087,-0.24623783619195427,-0.04241667920558578
278.80000000000325,33.7958113377117,-0.24350152847852266,-0.045327713801631475
279.60000000000326,33.871028701367386,-0.24205456181812135,-0.04512998957196901
280.4000000000033,33.945714647284575,-0.23978142930507018,-0.0464591029353576
281.2000000000033,34.02313971325242,-0.2376956661696798,-0.045777871770857015
282.0000000000033,34.09933630945641,-0.23422073872269625,-0.048554707410302544
282.8000000000033,34.17492373611613,-0.2345789041053409,-0.04973992719436415
283.6000000000033,34.25082894694871,-0.23249008459106096,-0.04973986626148097
284.40000000000333,34.32725569603033,-0.2305672102762333,-0.04940887057025245
285.20000000000334,34.40318127937322,-0.2275270257316822,-0.04697318401041173
286.00000000000335,34.479033130989684,-0.22775017693808736,-0.04467291571376952
286.80000000000337,34.55605388525389,-0.22512371348272364,-0.04184512282792685
287.6000000000034,34.6315238030914,-0.22179477505914394,-0.039293560192389165
288.4000000000034,34.70840150172755,-0.2214120104673839,-0.04338748130859171
289.2000000000034,34.78499336840855,-0.21840689458384,-0.04661777076568541
290.0000000000034,34.8605079697702,-0.2172041379858843,-0.04905415455321904
290.8000000000034,34.936951194042194,-0.21287563048171435,-0.05136969419511406
291.60000000000343,35.01261753022601,-0.21176505921326244,-0.04903837390059884
292.40000000000344,35.08960535349762,-0.20861519631832937,-0.04853148567675447
293.20000000000346,35.165425464907685,-0.20676819557727394,-0.05117580142886391
294.00000000000347,35.240492354043695,-0.20363314639435526,-0.05260120685048042
294.8000000000035,35.31685768419449,-0.20026022602571206,-0.053943939341854374
295.6000000000035,35.393960520544944,-0.19851985220643406,-0.05523414380705294
296.4000000000035,35.46782344531802,-0.1966244633864729,-0.053975332886821104
297.2000000000035,35.545551724986574,-0.19576853030787628,-0.051266170241810016
298.0000000000035,35.62065121103694,-0.1936893165236078,-0.049959946730309124
298.80000000000354,35.69779431749208,-0.19117829395357339,-0.050068307892600306
299.60000000000355,35.77355156906534,-0.18924594942418643,-0.05642361555560571
300.40000000000356,35.8472764766312,-0.185542297452459,-0.060352820178441124
301.20000000000357,35.926162258890095,-0.18487930877991868,-0.06291502746362587
302.0000000000036,36.00254433978432,-0.1819102375981755,-0.06015148573528384
302.8000000000036,36.078186489483095,-0.17956364445259373,-0.05852749659817302
303.6000000000036,36.15447209328022,-0.1770950040355985,-0.06004162358875753
304.4000000000036,36.23083091270685,-0.17627995098735347,-0.057530022893264476
305.2000000000036,36.30622442111288,-0.17474197658534463,-0.05483864978560282
306.00000000000364,36.38208427387248,-0.17369639800943007,-0.058427293617430376
306.80000000000365,36.459533986365,-0.1715860301911748,-0.06531560447687079
307.60000000000366,36.53428390607665,-0.17008149244425688,-0.06209405595962458
308.4000000000037,36.61101606307906,-0.16686785436437687,-0.0593503164007565
309.2000000000037,36.68706879591126,-0.16676493055225844,-0.05885762498193836
310.0000000000037,36.76360357961784,-0.1648316168156972,-0.06232412221351913
310.8000000000037,36.840209791436834,-0.16338153608381384,-0.06247041029384315
311.6000000000037,36.91624649716965,-0.16159924184936247,-0.061148394382406046
312.40000000000373,36.99295227129076,-0.1598282356760764,-0.06408089871822797
313.20000000000374,37.06886702871677,-0.15573834243251458,-0.06705750509744712
314.00000000000375,37.14446361188457,-0.1542470918837045,-0.07121066450076974
314.80000000000376,37.221500759620184,-0.15095591117772106,-0.07277921979001745
315.6000000000038,37.297600600692746,-0.14894296155301368,-0.06397923305130204
316.4000000000038,37.37387278378472,-0.1482410331850857,-0.05863913179141056
317.2000000000038,37.450182574416615,-0.14638395926767744,-0.06047174551438683
318.0000000000038,37.526807837980876,-0.1455756612063209,-0.06414065620863196
318.8000000000038,37.60201044345,-0.1440058727626489,-0.06851783019339708
319.60000000000383,37.67918631625194,-0.14116608633673336,-0.06851330552978174
320.40000000000384,37.75550689116582,-0.13832615505647455,-0.06983372513189545
321.20000000000385,37.83232394710743,-0.1368864584616254,-0.06686340035737492
322.00000000000387,37.90832754945413,-0.13511197435647476,-0.06576677041781975
322.8000000000039,37.98568892063877,-0.13290748694297772,-0.07140822668364111
323.6000000000039,38.06159467291455,-0.13107099899234287,-0.07482128149922396
324.4000000000039,38.13916675175536,-0.12952228362009383,-0.06743111276112712
325.2000000000039,38.21560980547271,-0.12683360473197228,-0.06780303913286945
326.0000000000039,38.29227473707034,-0.12517778387789896,-0.07032831474513657
326.80000000000393,38.36885212751145,-0.12191777412300504,-0.07419888783654827
327.60000000000394,38.445713001438314,-0.1191612472577466,-0.07861298783176807
328.40000000000396,38.52178279444441,-0.11727479266976727,-0.07934932149171692
329.20000000000397,38.59677545698547,-0.11472719320310118,-0.07997439192088995
330.000000000004,38.67522954758557,-0.11112537253717233,-0.08201832898566996
330.800000000004,38.7516808433318,-0.10886477160415889,-0.0820182901133717
331.600000000004,38.828192959801676,-0.1074180766571673,-0.07873700199201794
332.400000000004,38.90458606821035,-0.10396246336359956,-0.0759442661574381
333.200000000004,38.981848308259686,-0.10284130790657187,-0.0797407927046021
334.00000000000404,39.05824672643176,-0.09893774038807737,-0.0860809921371457
334.80000000000405,39.13543293974299,-0.09754488888809318,-0.09204445753183021
335.60000000000406,39.21239562261864,-0.094290610560101,-0.09115809701653976
336.40000000000407,39.28860894133974,-0.09336931975859966,-0.08698047017552657
337.2000000000041,39.36579260805188,-0.09023180095935024,-0.08696013831086224
338.0000000000041,39.4429449542483,-0.08816323226007385,-0.0869601282171768
338.8000000000041,39.519766375128306,-0.08371377133295607,-0.08829794492816223
339.6000000000041,39.59452889961447,-0.08361137559489054,-0.08617861043396635
340.4000000000041,39.672162947240636,-0.08083207164725001,-0.08747537204649358
341.20000000000414,39.75064545410983,-0.07718856768407874,-0.08940213133443331
342.00000000000415,39.82667482313715,-0.0759282443241882,-0.09104412775724091
342.80000000000416,39.902875654909984,-0.07117884210362255,-0.09180868927184704
343.6000000000042,39.980481492001395,-0.068767027724636,-0.09603011337121004
344.4000000000042,40.057400259378106,-0.06360498401940537,-0.09733047430859276
345.2000000000042,40.13426825987728,-0.05943903030601038,-0.10131971867594336
346.0000000000042,40.21003244354569,-0.0571555697783274,-0.1041398156201887
346.8000000000042,40.2876565617579,-0.053293984591025724,-0.10683347250109021
347.60000000000423,40.364490152009935,-0.04963504102533181,-0.10680945644904138
348.40000000000424,40.44214339278683,-0.046127879579507654,-0.1055462157219389
349.20000000000425,40.51825328372076,-0.043994841875576084,-0.10169689683161742
350.00000000000426,40.59598449490545,-0.04019590782390427,-0.10493609762241052
350.8000000000043,40.67326938164426,-0.036408935626746006,-0.10900992765426176
351.6000000000043,40.75082900796236,-0.03220327944808042,-0.11385977444486484
352.4000000000043,40.82818085101874,-0.026422223611973467,-0.11386047793344023
353.2000000000043,40.90366549227876,-0.023345094196496087,-0.11649299459267537
354.0000000000043,40.98004750906531,-0.017755724433573324,-0.11913594141563744
354.80000000000433,41.058010864840774,-0.015321732604544594,-0.11911972149433492
355.60000000000434,41.1350455951507,-0.011012085990468037,-0.12187524517238879
356.40000000000435,41.21101924653575,-0.006661113616444811,-0.12350854495688779
357.20000000000437,41.28791924345926,-0.0022657409644463457,-0.12351310628746903
358.0000000000044,41.366714307375126,0.0031507057810004385,-0.1274643731574634
358.8000000000044,41.44167089115346,0.009767656604766469,-0.13143356631201142
359.6000000000044,41.52036681600217,0.017229914286316962,-0.1399411334484273
360.4000000000044,41.59806806926965,0.02362145187980072,-0.1437184087732044
361.2000000000044,41.67382813846616,0.03218039447071194,-0.14622683439957695
362.00000000000443,41.7511011503427,0.03676696081764922,-0.14471314502689792
362.80000000000445,41.82954011425802,0.044433026698125336,-0.14644640977336687
363.60000000000446,41.90640707124458,0.05164311034594566,-0.14770761731189141
364.40000000000447,41.98317472821667,0.05804640433071467,-0.15037097015001466
365.2000000000045,42.06064336890911,0.06718631111643536,-0.15436092255073097
366.0000000000045,42.13735296595985,0.0745795750409102,-0.15730845501050927
366.8000000000045,42.21518614224741,0.08380827092352551,-0.15976125704430855
367.6000000000045,42.29301778309517,0.0941481830965817,-0.16491799404320107
368.4000000000045,42.36922983071655,0.10328888467548272,-0.16988445309784606
369.20000000000454,42.447630720496406,0.11700629498667518,-0.1762466158936178
370.00000000000455,42.524690139649245,0.12565089588759076,-0.1839377415687835
370.80000000000456,42.60257407753373,0.13933684964097243,-0.18811902050652973
371.60000000000457,42.67961796474737,0.1531155151239299,-0.19148478553559256
372.4000000000046,42.75655447709686,0.16632007552388306,-0.19634895029230304
373.2000000000046,42.83517663968731,0.18027481287110975,-0.20529653401271775
374.0000000000046,42.91227024328439,0.19488581797969864,-0.21578755775850667
374.8000000000046,42.98916196146937,0.20985221344671398,-0.21886791113063753
375.6000000000046,43.0668839315715,0.22730233341081438,-0.22576516349632758
376.40000000000464,43.14487834335935,0.24476205946313562,-0.23118249659451795
377.20000000000465,43.221122671770146,0.26566288600890664,-0.23791804945230632
378.00000000000466,43.29956895844512,0.2844936171118144,-0.24604414423624288
378.8000000000047,43.37771994843297,0.30709905743479216,-0.25532552626189764
379.6000000000047,43.45482945687813,0.3280738836352429,-0.2647929295377476
380.4000000000047,43.53217473623843,0.3518528295723556,-0.27290056625574133
381.2000000000047,43.60934841162733,0.3770688926586496,-0.27906500895149877
382.0000000000047,43.68699905553439,0.40552374002246777,-0.29708761365676306
382.80000000000473,43.76561591001593,0.43297607157424167,-0.31057090694610423
383.60000000000474,43.84247997260101,0.4651979661760428,-0.3217297570334203
384.40000000000475,43.91966957376203,0.4940734195009142,-0.3313013341450204
385.20000000000476,43.99751143444113,0.5256559734342852,-0.3441483865680923
386.0000000000048,44.07499642440662,0.5587233928719489,-0.35717404816227516
386.8000000000048,44.15200435993909,0.5968974539836969,-0.37206913418003085
387.6000000000048,44.23052450055326,0.6370491027294498,-0.38692582202598347
388.4000000000048,44.30766025682598,0.6777740986651268,-0.4037361874448542
389.2000000000048,44.386058238377956,0.7228895447602152,-0.42097410459405804
390.00000000000483,44.46313876922457,0.7667759302978793,-0.43921203778710405
390.80000000000484,44.539070018402775,0.8122323482605018,-0.4601627171999332
391.60000000000485,44.61858514388805,0.8665070880173498,-0.48046754744492004
392.40000000000487,44.69734273571689,0.9193140708938276,-0.5016110473661533
393.2000000000049,44.77427427548732,0.9731228572070161,-0.5243158096718155
394.0000000000049,44.85303381215564,1.0336689159799237,-0.5483584071682186
394.8000000000049,44.93072212728728,1.099499591676051,-0.5765661813117844
395.6000000000049,45.00906559664175,1.1608733384016663,-0.6069761340779531
396.4000000000049,45.08636786425609,1.2346141891686742,-0.6380766105071287
397.20000000000493,45.16490824861919,1.3047213805800169,-0.6676899295981515
398.00000000000495,45.24340661591012,1.3844082117400032,-0.7016476323693435
398.80000000000496,45.32131494021507,1.4570912257598612,-0.7351592736123114
399.60000000000497,45.39906863448351,1.5315853114910887,-0.7712353723885692
400.400000000005,45.478239844226664,1.6258358512746736,-0.8098256900279139
401.200000000005,45.55559822733875,1.7144721194957635,-0.8496811342413113
402.000000000005,45.63493778527878,1.7974760908461866,-0.8933367009229412
402.800000000005,45.712848522604716,1.8840356555592308,-0.9395732705730504
403.600000000005,45.79131015603929,1.9782062339092643,-0.9867014129818736
404.40000000000504,45.87033489859281,2.074733182470524,-1.0380118085854746
405.20000000000505,45.94805029553511,2.186954590916623,-1.0893247882921546
406.00000000000506,46.026244338253676,2.2926181994635124,-1.1455290613409064
406.80000000000507,46.106079229419926,2.382278009527038,-1.2045974260298165
407.6000000000051,46.18417527169406,2.4753683402467823,-1.2628870365468998
408.4000000000051,46.26276203789889,2.579561419532863,-1.330789633330704
409.2000000000051,46.34124935498686,2.672429440592949,-1.3973951418854607
410.0000000000051,46.41972829715807,2.7725080173179917,-1.4636251880583102
410.8000000000051,46.49770628832922,2.8649833438356693,-1.5327515435804475
411.60000000000514,46.57578600107987,2.958872564821529,-1.603274414307466
412.40000000000515,46.65472935931623,3.0421826844756628,-1.676793857844796
413.20000000000516,46.73397393922517,3.122676874519537,-1.7564720523933643
414.0000000000052,46.812724990698406,3.191935519796519,-1.8367394344568666
414.8000000000052,46.8917257285756,3.276774814321807,-1.9196921804149913
415.6000000000052,46.97033099647793,3.3391971520069186,-2.0049615475997244
416.4000000000052,47.04920360295704,3.4055236708394383,-2.0958721118751904
417.2000000000052,47.12740096115946,3.449299461343332,-2.1849075142419325
418.00000000000523,47.20515781963767,3.4649883337181593,-2.2741927714939987
418.80000000000524,47.283935929285676,3.4844424312169013,-2.360344842936391
419.60000000000525,47.36131964158558,3.4868592497655144,-2.4495156012508117
420.40000000000526,47.440730034743936,3.464957087799621,-2.5415771185300366
421.2000000000053,47.51918242540808,3.4255512173820124,-2.6299418977994735
422.0000000000053,47.596380731570086,3.380700562583885,-2.716293225964132
422.8000000000053,47.67452307687876,3.3089720464223946,-2.8019413879416986
423.6000000000053,47.752276822913565,3.214354029581952,-2.8838220816554285
424.4000000000053,47.83072685335549,3.103901537587554,-2.9663777673497513
425.20000000000533,47.90826925739962,2.978332231314845,-3.043969420936437
426.00000000000534,47.985190545818156,2.8308366989393456,-3.1193775546629845
426.80000000000535,48.063796814509175,2.672759364034211,-3.196340929573326
427.60000000000537,48.140924367920604,2.504123068199704,-3.262821426304775
428.4000000000054,48.21816629656699,2.32218132772132,-3.330271531998428
429.2000000000054,48.295720619244904,2.131846772735976,-3.3912951407769776
430.0000000000054,48.372668795597086,1.9371990817326528,-3.444843476158744
430.8000000000054,48.449693482385044,1.7392776082368562,-3.4968089230304207
431.6000000000054,48.52676457023534,1.5466832166044913,-3.543689627460174
432.40000000000543,48.60328961132262,1.3561507740745289,-3.582570862609496
433.20000000000545,48.68048547698649,1.1756431263409923,-3.6188397044304854
434.00000000000546,48.75750009878491,1.0037209819754531,-3.6518626596648978
434.80000000000547,48.83451592469919,0.8437531715427586,-3.6827566607215956
435.6000000000055,48.909861500279774,0.7007366191858402,-3.7100173019714235
436.4000000000055,48.987169690212895,0.5697712002542294,-3.733918140722138
437.2000000000055,49.06485855013396,0.4485520200406572,-3.7553371958590076
438.0000000000055,49.14226726092243,0.34424545006782925,-3.7727314555584277
438.8000000000055,49.21875714591222,0.2514243378591393,-3.784453537256652
439.60000000000554,49.296095010097176,0.1719932356815355,-3.7978705045009526
440.40000000000555,49.37370768406234,0.10376766999213395,-3.8122763122560284
441.20000000000556,49.451232741236964,0.044319645709952234,-3.8251117682209443
442.00000000000557,49.52895520748445,-0.006875028419799935,-3.831136521875781
442.8000000000056,49.60720308445955,-0.05123103969470411,-3.8455856356192357
443.6000000000056,49.68474251944389,-0.08798202214106121,-3.853188642452094
444.4000000000056,49.76281433791355,-0.1205237092168757,-3.8588357837976988
445.2000000000056,49.84015812035057,-0.14759521797266467,-3.8627387452045348
446.0000000000056,49.917658074822455,-0.17261590838934218,-3.867151804060714
446.80000000000564,49.99503118370037,-0.19186241821629985,-3.8673781833265277
447.60000000000565,50.07350852678479,-0.20846245407414754,-3.870342583108441
448.40000000000566,50.152080314923566,-0.22171976788192144,-3.8760340190999627
449.2000000000057,50.227177497426496,-0.23335832363179163,-3.878441546680566
450.0000000000057,50.30772599999878,-0.24283045112642426,-3.8784609212426178
450.8000000000057,50.38538232625584,-0.25350589508749793,-3.8783862986632966
451.6000000000057,50.46382563132893,-0.25916937333279394,-3.883626448141386
452.4000000000057,50.54120737513297,-0.26484662526291475,-3.8890115486472148
453.20000000000573,50.61962904403694,-0.2672947273337337,-3.89160084283695
454.00000000000574,50.698642065002005,-0.27280735417340524,-3.8906118997918955
454.80000000000575,50.77769582781087,-0.27563644570689705,-3.891978672207639
455.60000000000576,50.85485657002805,-0.2780132004641249,-3.8933839220444204
456.4000000000058,50.934266471407255,-0.27822764305840525,-3.892871234500852
457.2000000000058,51.01190444636575,-0.2839480943725871,-3.8929975337985767
458.0000000000058,51.09010975569504,-0.2873744803382237,-3.8941895160880877
458.8000000000058,51.16919908715349,-0.28902800724200856,-3.896504314436087
459.6000000000058,51.247215970217525,-0.290489649200749,-3.896879951133867
460.40000000000583,51.32635699478837,-0.2933611977092754,-3.8968799076625595
461.20000000000584,51.40408925582297,-0.2949540763633544,-3.8981600539069623
462.00000000000585,51.482987801550834,-0.298212720330202,-3.902054963950283
462.80000000000587,51.56184990203442,-0.3005803975100045,-3.905312293762431
463.6000000000059,51.63974516408682,-0.30351918736629174,-3.906209879507524
464.4000000000059,51.71749013994949,-0.30680340399761397,-3.906134950004897
465.2000000000059,51.798544895878614,-0.3080329634537568,-3.903750949364552
466.0000000000059,51.877166583047924,-0.3072031468180191,-3.9042701977914356
466.8000000000059,51.95559917866808,-0.3066355832305486,-3.90775761000268
467.60000000000593,52.03444131341549,-0.3057880199062292,-3.907739709691327
468.40000000000595,52.110528245635706,-0.30300508690055705,-3.903523482144208
469.20000000000596,52.191222912523976,-0.30015046493648817,-3.899264155924704
470.00000000000597,52.26903431518855,-0.29718151097050177,-3.899290448676539
470.800000000006,52.34799432698027,-0.29503512123963216,-3.900821375025771
471.600000000006,52.42606904352718,-0.29591759932133016,-3.9054586970710345
472.400000000006,52.50467612150432,-0.29702657226801255,-3.905002160030809
473.200000000006,52.583856801619525,-0.29844940083843696,-3.915038051407159
474.000000000006,52.66131589902379,-0.29914828015309614,-3.9155342418943953
474.80000000000604,52.740240150666274,-0.30119824937079087,-3.9101252718000206
475.60000000000605,52.8188725903986,-0.3050797325987719,-3.905897259460824
476.40000000000606,52.89660676964173,-0.3073341743763678,-3.9039993145731113
477.20000000000607,52.97591994563539,-0.30933937172088755,-3.898542912890075
478.0000000000061,53.05511905670978,-0.31172594946822296,-3.898959982018735
478.8000000000061,53.13228597839363,-0.31356271616228254,-3.8989601542668706
479.6000000000061,53.21063761453607,-0.3139681098604071,-3.902257463443354
480.4000000000061,53.2897154855726,-0.31295199067138346,-3.90550531280155
481.2000000000061,53.36817204961322,-0.314018506741252,-3.9061059801590323
482.00000000000614,53.44667649411215,-0.31358092116657366,-3.9038954215728507
482.80000000000615,53.52576241125887,-0.311763881593319,-3.903899979804699
483.60000000000616,53.60519690357064,-0.3151787271530495,-3.903901241151572
484.4000000000062,53.68449031861896,-0.316410422764827,-3.906278466912519
485.2000000000062,53.76232173596263,-0.3186069423500306,-3.907948083124805
486.0000000000062,53.84154909379798,-0.31898794584270884,-3.9092040925347566
486.8000000000062,53.920620946784304,-0.31894448102165646,-3.909291075259514
487.6000000000062,54.00043601556067,-0.32084901931666027,-3.906666707551778
488.40000000000623,54.07919173200604,-0.3218246349117396,-3.9053236233601996
489.20000000000624,54.157916548144975,-0.321654731122526,-3.905937421547382
490.00000000000625,54.23785182570714,-0.3235057994828066,-3.909222948606065
490.80000000000626,54.31603577026118,-0.32283446482058875,-3.906681315063626
491.6000000000063,54.39588761168109,-0.32212951414431157,-3.9058969222582927
492.4000000000063,54.47525767390885,-0.3227178740631338,-3.905990149101773
493.2000000000063,54.55189342280171,-0.32251468009589684,-3.9052478553705368
494.0000000000063,54.63318895263147,-0.32353166110342124,-3.906036335673555
494.8000000000063,54.71206850725463,-0.32403575384663963,-3.905992675995409
495.60000000000633,54.791124725254065,-0.3218618659356545,-3.9086733928481525
496.40000000000634,54.86903740028972,-0.3221633161629883,-3.9087330351943046
497.20000000000636,54.94874114077767,-0.32284737863494306,-3.905501619486735
498.00000000000637,55.027767356596726,-0.3222649278032622,-3.9047809933099065
498.8000000000064,55.10655639102063,-0.3198628291615677,-3.907459086091142
499.6000000000064,55.1856935819398,-0.3203461312452208,-3.9077499727273297
500.4000000000064,55.2640784339319,-0.3192108359612266,-3.9120518856441198
501.2000000000064,55.34244472742991,-0.31998259695221065,-3.9105979968494275
502.0000000000064,55.42236949281492,-0.3186857924232407,-3.905764398100002
502.80000000000643,55.50073312881863,-0.3197096628205518,-3.9061031906941825
503.60000000000645,55.5793941753001,-0.317574440698242,-3.901659611845016
504.40000000000646,55.65898412915781,-0.31879812689688775,-3.895027328892764
505.20000000000647,55.73791362968441,-0.31895520862163385,-3.8960585843818634
506.0000000000065,55.81690039440183,-0.31748940331808384,-3.9014121937014523
506.8000000000065,55.89573134559394,-0.31659836932765495,-3.909827226188758
507.6000000000065,55.97448995811267,-0.316366224766976,-3.9114794307999152
508.4000000000065,56.05420644877066,-0.3151365423126673,-3.9114618739474594
509.2000000000065,56.131723600792284,-0.3170088482838776,-3.9115340531758265
510.00000000000654,56.21323487481264,-0.3150860903940492,-3.9100872913705462
510.80000000000655,56.29150442200737,-0.3163542389503107,-3.9084025926316666
511.60000000000656,56.370250524053844,-0.31562276288758967,-3.907681906975943
512.4000000000066,56.44907732686783,-0.31583145028552995,-3.9082408366643953
513.2000000000066,56.527406068319834,-0.313654097386904,-3.912374775475237
514.0000000000066,56.606556896566275,-0.3118055773996646,-3.9123599466442394
514.8000000000065,56.68558275086886,-0.31210042410263233,-3.9124827380109855
515.6000000000066,56.76483783041754,-0.30990586626402655,-3.9084084368801526
516.4000000000067,56.84432571089917,-0.3125373302743855,-3.909718583954023
517.2000000000066,56.92363362343222,-0.31197145186674524,-3.908395586375543
518.0000000000066,57.0024287342285,-0.31015850984662047,-3.907452036889649
518.8000000000067,57.08165310080375,-0.3106711675035629,-3.9070801695396096
519.6000000000067,57.16072499026109,-0.30748853763181483,-3.9084013374325646
520.4000000000067,57.23878268253366,-0.3054390770463773,-3.9083999428214007
521.2000000000066,57.318204458933906,-0.3045236831846956,-3.9083990550092467
522.0000000000067,57.39637287604969,-0.3035101619499432,-3.909717594407146
522.8000000000068,57.47627809535231,-0.30215397945249356,-3.9113583729656156
523.6000000000067,57.55517140639964,-0.3013905758745559,-3.9098515936851066
524.4000000000067,57.63500711886018,-0.3000126541767359,-3.907099697612554
525.2000000000068,57.71428731409134,-0.30025550220592573,-3.9058815128118787
526.0000000000068,57.79276390041937,-0.29906502838936194,-3.9057045173228295
526.8000000000068,57.872627159552934,-0.2982480358229687,-3.9044505019606515
527.6000000000067,57.9523318714637,-0.29802077100985025,-3.90451994688403
528.4000000000068,58.031528653987344,-0.29831199333933645,-3.9096953692592975
529.2000000000069,58.111396541428824,-0.29850070033161563,-3.9117731888257343
530.0000000000068,58.189980136903806,-0.30009230578668983,-3.914894213780426
530.8000000000068,58.27003994846602,-0.2992115044389759,-3.909367275106513
531.6000000000068,58.34996416197428,-0.2974812221035008,-3.904519204243625
532.4000000000069,58.42868224433426,-0.2987755705455579,-3.9052951903174264
533.2000000000069,58.50691907372119,-0.2981566047586916,-3.9098518281044132
534.0000000000068,58.58830977177023,-0.29686478575832353,-3.906752590156088
534.8000000000069,58.66774752974166,-0.2972209941656612,-3.9067572977011693
535.600000000007,58.74697364245769,-0.2957401832782446,-3.9064338278201802
536.4000000000069,58.826809450275064,-0.29527487320839485,-3.905001980384377
537.2000000000069,58.90677712337205,-0.29677808202053035,-3.906430009866725
538.0000000000069,58.986155933237605,-0.29620165110349517,-3.90643000612928
538.800000000007,59.06494639845006,-0.2957388285588898,-3.904994201271592
539.600000000007,59.144244678748485,-0.29512619201472906,-3.903569225214526
540.4000000000069,59.22376866645424,-0.29477945560317376,-3.9029206529892413
541.200000000007,59.30303047634363,-0.2952965689039073,-3.90424486025703
542.000000000007,59.38173112848495,-0.29365511790280724,-3.906198837562544
542.800000000007,59.46179537021814,-0.29390479108441,-3.9075204219279738
543.600000000007,59.54053889002099,-0.2948850783261092,-3.9081760452186893
544.400000000007,59.61922750268061,-0.2933255395227733,-3.909615296151245
545.2000000000071,59.700063084510575,-0.29203079377958674,-3.9098432925533895
546.000000000007,59.77927542155387,-0.29103570539428963,-3.9098440320502013
546.800000000007,59.85916236590407,-0.2904505176766056,-3.9085198444449847
547.000000000007,59.87894998928064,-0.28830449942608316,-3.9085198729763233