File: 01_Data/EIFS_Coating/STA/N2/30K_min/EIFS_Coating_STA_N2_30KData_230914_R2.csv
##Temp./Â°C,Time/min,DSC/(mW/mg),Mass loss/mg
41.0,10.543527548051298,-2.2717556685896967,0.0060222328329926356
42.40000000000002,10.776923629000233,-2.171179076260475,0.005844397025173365
43.80000000000004,10.917899506352718,-2.0916532009166056,0.0048680569487897785
45.20000000000006,11.02753177417097,-2.0259895850596217,0.005160484545919886
46.60000000000008,11.124908678481487,-1.9642098201489884,0.005976167902445262
48.0000000000001,11.209138268369028,-1.9102803513257105,0.005421257997701545
49.40000000000012,11.286689656042329,-1.859806752992399,0.0050592012256514
50.80000000000014,11.35959196195117,-1.813906373111151,0.005528872985168576
52.20000000000016,11.427998161537813,-1.7690857171574048,0.005378754074588876
53.60000000000018,11.494407547486853,-1.7267276033124856,0.005401560791355564
55.0000000000002,11.555766236365606,-1.6889836744771025,0.004006683510066722
56.40000000000022,11.618468552290265,-1.6510197792661665,0.004432464675533154
57.80000000000024,11.676788870654029,-1.6187668714430856,0.004512156844382886
59.20000000000026,11.73454699932981,-1.5873040137000844,0.003355336886657234
60.60000000000028,11.791032410304359,-1.5556010446247701,0.0038426927214150197
62.0000000000003,11.845965370214081,-1.5279746102036336,0.0034003953853884994
63.40000000000032,11.899916648591288,-1.501059915255257,0.0035363297770505397
64.80000000000034,11.95249470598658,-1.4769364922327264,0.0021784231447918856
66.20000000000036,12.006572516970841,-1.4536152461759984,0.0023132137739736436
67.60000000000038,12.058381230393188,-1.431132900778847,0.0015092892772452515
69.0000000000004,12.109890890550554,-1.4107738854863887,-0.0001359793438280299
70.40000000000042,12.160557813038817,-1.391764128194179,0.0003562540009065529
71.80000000000044,12.211292718075454,-1.3718702142701937,-8.037649115566481e-05
73.20000000000046,12.262170329140488,-1.353881609769084,6.930394441262422e-05
74.60000000000048,12.312251193152782,-1.341005089849413,-0.00030882706598456267
76.0000000000005,12.361708566216725,-1.3268091138883926,0.0003071193021506602
77.40000000000052,12.411757331929293,-1.312432828866571,0.00021050042806081137
78.80000000000054,12.46086973433463,-1.3030810562029453,-0.001709662470200879
80.20000000000056,12.510036239338607,-1.2902888684022236,-0.0015243661584407597
81.60000000000058,12.558616728771458,-1.2801379799939574,-0.001540278170592213
83.0000000000006,12.60787579571032,-1.2700991545655134,-0.0015930975446387663
84.40000000000062,12.656260221218844,-1.2608693515054687,-0.0029462422905979224
85.80000000000064,12.70370104569702,-1.2504432488325692,-0.0032430365665216954
87.20000000000066,12.751902481665633,-1.2410383089203207,-0.004276614220183994
88.60000000000068,12.799966376924402,-1.2295029776961348,-0.005058520703292491
90.0000000000007,12.847898484801371,-1.216121182259061,-0.005659264095486893
91.40000000000072,12.89524641630999,-1.2028619322049996,-0.006910381951015232
92.80000000000074,12.941760290110214,-1.1815409189851822,-0.008307708737262054
94.20000000000076,12.989176097913104,-1.1595423233528384,-0.008245930118270017
95.60000000000078,13.03563465289153,-1.130759008763236,-0.00954031338723249
97.0000000000008,13.082063514424501,-1.0992548392757853,-0.009452476403194687
98.40000000000082,13.128771099531185,-1.0684201159371904,-0.008226588578740923
99.80000000000084,13.1745430432707,-1.0389391140526618,-0.009531261819800907
101.20000000000086,13.221531972807172,-1.0094483283543525,-0.009550140229014126
102.60000000000088,13.267777386701509,-0.984815763345599,-0.00954760563335455
104.0000000000009,13.314004962577995,-0.9602806356869068,-0.010843572185671224
105.40000000000092,13.359454091613348,-0.9387193266007063,-0.010869568018575748
106.80000000000094,13.405472177491493,-0.9178378763150123,-0.012283066774358087
108.20000000000095,13.452700849879488,-0.8960092440228689,-0.0107751440633157
109.60000000000097,13.49946467145302,-0.8769251407311908,-0.010866714087565121
111.000000000001,13.545421883047034,-0.8588245729993993,-0.012216929222249817
112.40000000000101,13.591382794025456,-0.8416760246859638,-0.012179469401262466
113.80000000000103,13.637578665777877,-0.8264000935700344,-0.013596444329257551
115.20000000000105,13.684097296127348,-0.8089557603420808,-0.013499964781974683
116.60000000000107,13.730130492591057,-0.7952395924815121,-0.0134999925608974
118.0000000000011,13.775804591126636,-0.7811573272679887,-0.013502931999433088
119.40000000000111,13.821760183655261,-0.7670724209396856,-0.012819109965222175
120.80000000000113,13.86694621194246,-0.7535801094221207,-0.011518806593876718
122.20000000000115,13.91404155743813,-0.7401487876067008,-0.01152000436099021
123.60000000000117,13.959868166627736,-0.7244777344650654,-0.01152257666424683
125.0000000000012,14.00552171189706,-0.709151119745552,-0.012819465368095084
126.40000000000121,14.050697793390436,-0.6931021366122402,-0.01283994598802174
127.80000000000123,14.096302185888254,-0.6756166962219688,-0.012839931348040512
129.20000000000124,14.141855982349636,-0.6600503918980772,-0.012857637064302097
130.60000000000127,14.187145990993484,-0.6440170987684292,-0.011528917841760578
132.0000000000013,14.232194163750002,-0.6283684992965878,-0.012157895338930746
133.4000000000013,14.277382477972523,-0.6128601870462629,-0.012403765993399762
134.80000000000132,14.322285139321796,-0.5984469972625447,-0.011531288134896123
136.20000000000135,14.366953080170793,-0.5836128984399505,-0.011952730076085771
137.6000000000014,14.412111109539957,-0.5671599377248198,-0.013474886089831717
139.0000000000014,14.457119814352884,-0.5533847261156485,-0.01391576044491849
140.4000000000014,14.501202333989335,-0.5386843429365489,-0.014809648489212623
141.80000000000143,14.545973745544314,-0.5244705698154398,-0.01469873786326481
143.20000000000147,14.590718750315848,-0.5110898520443112,-0.0125081190555969
144.60000000000147,14.634772101496422,-0.49726336131926724,-0.012510061892582414
146.00000000000148,14.679299810563169,-0.4836973413891047,-0.01251493485318722
147.4000000000015,14.723600547316002,-0.46929648205276686,-0.013823646446478488
148.80000000000155,14.767562183165554,-0.4567547859153996,-0.015146120303138222
150.20000000000155,14.811556534640534,-0.4429457008435647,-0.01513999988464576
151.60000000000156,14.855675485388495,-0.4308358777020203,-0.015139997287441087
153.0000000000016,14.899745906811198,-0.4183577212133729,-0.015139924626587753
154.40000000000163,14.944037950512923,-0.4049855627105994,-0.014646003934766227
155.80000000000163,14.987912612079896,-0.39321063611528834,-0.014480194630682508
157.20000000000164,15.032157154737499,-0.3813110399520603,-0.01447999941122946
158.60000000000167,15.075704757816048,-0.3692532444383737,-0.014479999997229154
160.0000000000017,15.119568788295474,-0.35565912434655333,-0.014479999999999826
161.4000000000017,15.163101804435255,-0.3442115782241364,-0.01448000000000027
162.80000000000172,15.206857614769168,-0.3328685865595729,-0.01448000000000027
164.20000000000175,15.249758846214375,-0.32282483987837096,-0.01448000000000027
165.60000000000178,15.293953476721734,-0.3105410840369802,-0.014480000000002491
167.0000000000018,15.33789083257193,-0.2984132149279063,-0.014480000000261839
168.4000000000018,15.381501676886199,-0.2886970938222405,-0.014479999866486182
169.80000000000183,15.424957818900296,-0.27660074846823934,-0.014479947157195916
171.20000000000186,15.468358947499642,-0.266356630242951,-0.014474419998612653
172.60000000000187,15.51206518533043,-0.2536748700131721,-0.01416260494110988
174.00000000000188,15.555241467988122,-0.24392073150389237,-0.015567636173124733
175.4000000000019,15.598450703122579,-0.23337029208782245,-0.01547027698652359
176.80000000000194,15.641917108099172,-0.22186252976833246,-0.015472634672037966
178.20000000000195,15.685424445919722,-0.21166946858113464,-0.014389482018120514
179.60000000000196,15.728048937738453,-0.20147527532379436,-0.014199857582748887
181.000000000002,15.771549019584047,-0.19273952974477834,-0.01414988207620338
182.40000000000202,15.814620689122183,-0.1817601395583252,-0.014151224109659744
183.80000000000203,15.857779536807588,-0.1723513992108558,-0.01554360463039961
185.20000000000203,15.900805418937605,-0.1643443974347121,-0.015470047660545827
186.60000000000207,15.943724176660158,-0.152790824081737,-0.015471901118447207
188.0000000000021,15.986732169052166,-0.14355070380972756,-0.014372772186853844
189.4000000000021,16.029509632482824,-0.13509788517185078,-0.014150125702312
190.80000000000211,16.071965925079322,-0.1259394001814285,-0.013326117377231217
192.20000000000215,16.11492612851944,-0.11621618396589999,-0.012524705771733036
193.60000000000218,16.157895661317433,-0.10834912322900885,-0.01381872988604016
195.0000000000022,16.200381167508493,-0.09866895179325814,-0.013830007056102822
196.4000000000022,16.24330013674311,-0.09219608578708266,-0.013830033796136565
197.80000000000223,16.286045016149526,-0.08105290844877433,-0.013841588254552839
199.20000000000226,16.32881694798241,-0.07406213721692811,-0.012847551821299596
200.60000000000227,16.371324622982222,-0.06515746921067814,-0.012838832301554692
202.00000000000227,16.41366206231759,-0.05877036385679396,-0.014156746044415414
203.4000000000023,16.456116580584627,-0.04970911051403792,-0.014150178751422438
204.80000000000234,16.498968826865333,-0.043674821033262215,-0.014168416852174737
206.20000000000235,16.541315997973488,-0.03547733037952942,-0.015469772260486625
207.60000000000235,16.584164253295327,-0.026640965503443616,-0.014066426243440677
209.0000000000024,16.62688832127349,-0.021099648137914352,-0.012660453934225213
210.40000000000242,16.66907268530825,-0.01292294371483449,-0.012741807418662265
211.80000000000243,16.71193280492835,-0.006013145796237112,-0.014049175660374669
213.20000000000243,16.754537714672647,0.000843638122679074,-0.015450007709351343
214.60000000000247,16.79657292674731,0.007887225064032631,-0.015360339905251319
216.0000000000025,16.83905514922644,0.011900221892785747,-0.015360064794474937
217.4000000000025,16.88185360624239,0.019313170143923752,-0.015865975491800022
218.8000000000025,16.923548682895326,0.02762175004825494,-0.01539235628695046
220.20000000000255,16.966607439281308,0.03338795072988291,-0.015373915442445263
221.60000000000258,17.00896494080453,0.03699463126763912,-0.016369812765419933
223.0000000000026,17.05129712246555,0.04444205946466058,-0.016359876942050544
224.4000000000026,17.093711279623697,0.049290092766789105,-0.01632128402709032
225.80000000000263,17.136375748059052,0.054111496569305924,-0.017659822837564843
227.20000000000266,17.178562314283546,0.060700580033785805,-0.017670027875935634
228.60000000000267,17.221174427624806,0.06524130884308489,-0.017658292369231887
230.00000000000267,17.26320573423917,0.06999617608576165,-0.018976913787784433
231.4000000000027,17.30546417248213,0.07622307593111347,-0.018989873634609022
232.80000000000274,17.348221606330814,0.08004365533023178,-0.018980923453195242
234.20000000000275,17.390389647586478,0.0852281440316421,-0.01767534370821977
235.60000000000275,17.432803573692677,0.09028101011934184,-0.01767005720321757
237.00000000000279,17.47498860471488,0.09379338085768733,-0.017664843313746292
238.40000000000282,17.5172841393619,0.09898941283548891,-0.018364031987475826
239.80000000000283,17.55969687511324,0.10109662356537072,-0.018330052949618203
241.20000000000283,17.601932792937173,0.10583605670663672,-0.01832936873924096
242.60000000000286,17.64429258733345,0.1104526051087284,-0.016917571550592925
244.0000000000029,17.686468363827377,0.11484584938777215,-0.017010734493466906
245.4000000000029,17.728931627637877,0.11743830655912323,-0.01758307475612364
246.8000000000029,17.771169295568185,0.12217329871017257,-0.018329453262677653
248.20000000000294,17.813287607153075,0.12513819866829298,-0.018329993222546914
249.60000000000298,17.85554476579041,0.129751578477737,-0.018329469608198146
251.00000000000298,17.8978819468185,0.13087133552185548,-0.018244868882224097
252.400000000003,17.93961986010476,0.13558852593939716,-0.019649938988377524
253.80000000000302,17.982601178580957,0.13522864533073065,-0.019650001445802978
255.20000000000306,18.024890870608786,0.13948717489451254,-0.01965003323959902
256.6000000000031,18.066696208878316,0.1428313518604797,-0.019656453405498375
258.00000000000307,18.109387374581832,0.14376603192644558,-0.01832483904748461
259.4000000000031,18.151703825069344,0.1457708349460153,-0.017011631046559117
260.80000000000314,18.19354286471366,0.1475322153832788,-0.017028131148886683
262.2000000000031,18.236061959718302,0.14878400243999793,-0.018336623835543353
263.60000000000315,18.278419627279085,0.15135747246699147,-0.01833001273308099
265.0000000000032,18.320574356981403,0.15418450514075863,-0.018329975006414756
266.4000000000032,18.362882620078274,0.15596011956200345,-0.01830247961903053
267.80000000000325,18.405084384682695,0.15583120663602412,-0.019627627931015912
269.20000000000323,18.44718777490821,0.1573956601202119,-0.019639961748344703
270.60000000000326,18.489562165624786,0.1582728411136024,-0.019639995483418993
272.0000000000033,18.531869143529516,0.15892670557941183,-0.01962737697611816
273.4000000000033,18.573838731940224,0.16055011872584657,-0.020292965862973578
274.8000000000033,18.61624027543241,0.16133184926828484,-0.020160548777385046
276.20000000000334,18.658626295593727,0.1617364534375908,-0.01899699082570372
277.6000000000034,18.700962498696278,0.16064185269153144,-0.017730069906018553
279.0000000000034,18.74311428202205,0.1609383811627655,-0.018990371947638085
280.4000000000034,18.784711173012866,0.16134574328323134,-0.018990002427531127
281.8000000000034,18.827766811171898,0.16224728276721204,-0.018990087744039652
283.20000000000346,18.870178292589767,0.16125769856828298,-0.01933540825127933
284.60000000000343,18.912391595442287,0.15887183538969593,-0.020308335749849693
286.00000000000347,18.95500108818126,0.15822821788504168,-0.02030991208943167
287.4000000000035,18.996925283009833,0.1593418591877992,-0.018922526964197495
288.80000000000354,19.039444675883693,0.15654136372359226,-0.018330009496986044
290.20000000000357,19.081883844364487,0.15460418145971724,-0.018326788107558833
291.60000000000355,19.12424964361821,0.15426002395199825,-0.019623867794332117
293.0000000000036,19.166713549027413,0.15323610556702588,-0.01964991054720011
294.4000000000036,19.209319032572417,0.14946197107215725,-0.019650003093646173
295.8000000000036,19.251321187517288,0.14679252435877801,-0.019648353958372944
297.2000000000036,19.294237817245904,0.1462353909999925,-0.020877262880651948
298.60000000000366,19.33685108457628,0.14226080069850966,-0.02096989859143461
300.0000000000037,19.37921072270696,0.14178470444089297,-0.020970037571767186
301.40000000000373,19.42133168474358,0.13690189631557123,-0.020948022458104898
302.8000000000037,19.46362575626934,0.1328186147626851,-0.01997619762286229
304.20000000000374,19.50637730595068,0.13038034507510352,-0.020338087879721467
305.6000000000038,19.549144058887247,0.1253671066756783,-0.021290633302963435
307.00000000000375,19.59136067965311,0.12418192532761979,-0.021263298214912574
308.4000000000038,19.633888436688455,0.12057392347308245,-0.02228560923517664
309.8000000000038,19.67616698257658,0.11688399015475529,-0.022156706227280054
311.20000000000385,19.718944664978743,0.11445183130470556,-0.020959031041448473
312.6000000000039,19.761802743601912,0.11125845798228763,-0.020960006307904955
314.00000000000387,19.804083830029196,0.10678620349707435,-0.020959998906762145
315.4000000000039,19.846470125033733,0.10272110488808692,-0.020959713679585157
316.80000000000393,19.88911811606954,0.10030315194938684,-0.02093590221743913
318.2000000000039,19.931927269119203,0.09667609441498204,-0.022283080972441915
319.60000000000394,19.97442641820837,0.0923966784249885,-0.022279898086623895
321.000000000004,20.016993027742803,0.08994974991497236,-0.022252710380713747
322.400000000004,20.05972066096694,0.08634192180223672,-0.022339256717275546
323.80000000000405,20.102203704839212,0.08220895935455537,-0.021630840106560356
325.200000000004,20.14465544778397,0.07827007389701736,-0.021628169976888323
326.60000000000406,20.187687313446663,0.07524289910471682,-0.02027748827806919
328.0000000000041,20.230276441555386,0.06997987425248246,-0.020961448515645742
329.40000000000407,20.27290582375864,0.06555450131712517,-0.02232885421961983
330.8000000000041,20.315336749373238,0.059536325673785494,-0.02227976733983228
332.20000000000414,20.358190236288774,0.05547728657253239,-0.022206961461749497
333.6000000000042,20.401052649131284,0.05130739996413954,-0.023600271137721673
335.0000000000042,20.443645264326687,0.04637076561208757,-0.023601741196357384
336.4000000000042,20.48641540545517,0.04430661416276108,-0.024981862247685616
337.8000000000042,20.529470173149207,0.03838622441955493,-0.023618085208994444
339.20000000000425,20.572342322353435,0.03188540387834082,-0.023599526314362684
340.60000000000423,20.615094232082395,0.027587522550116213,-0.023596445826060464
342.00000000000426,20.65734667284542,0.025250192177354105,-0.02480284814681255
343.4000000000043,20.700579996474474,0.01880763075822688,-0.0249100835121987
344.80000000000433,20.743794480955806,0.017076499001963646,-0.024920709129361285
346.20000000000437,20.786699748598526,0.012249262731479405,-0.026264063953465477
347.60000000000434,20.829600378119096,0.008121398845002669,-0.02722000666108082
349.0000000000044,20.872398916696888,0.0031155845744831397,-0.027220192881973748
350.4000000000044,20.915428810277824,-0.0006385407666492402,-0.02711113446868829
351.8000000000044,20.958695113242555,-0.0024008517910272557,-0.027301762609594604
353.2000000000044,21.001540488123958,-0.005448482556933632,-0.030097166525821617
354.60000000000446,21.04427786554291,-0.008778681794225331,-0.030093453030179074
356.0000000000045,21.08673080486744,-0.014018741538435882,-0.030103332859464427
357.4000000000045,21.13068333386598,-0.017690656040722914,-0.029603414396349503
358.8000000000045,21.173774071859555,-0.020012489284577155,-0.029960492813958517
360.20000000000454,21.216930130681053,-0.022706044074645042,-0.03064060743443564
361.60000000000457,21.260189102571257,-0.0265978391295254,-0.03127998743385607
363.00000000000455,21.302693714990415,-0.03198187444377815,-0.031280086598326484
364.4000000000046,21.346454196921318,-0.0354302173374563,-0.03139943249752353
365.8000000000046,21.389570062984205,-0.041974829515073656,-0.03260035561690078
367.20000000000465,21.43308353978788,-0.04692658693623442,-0.03400719613696168
368.6000000000047,21.476423566270764,-0.049932343689208535,-0.03402747932178807
370.00000000000466,21.51940352165006,-0.05636969095467683,-0.035234247139596775
371.4000000000047,21.562254022773107,-0.06320548435914275,-0.036537246468160145
372.80000000000473,21.605951245398604,-0.0703879919079015,-0.03664183988290537
374.2000000000047,21.649560767196288,-0.07749384189970429,-0.03756950599923936
375.60000000000474,21.6928033850098,-0.08451293949819516,-0.03892470315736363
377.0000000000048,21.735948914455474,-0.09324476275297583,-0.04079164655541723
378.4000000000048,21.779362512047335,-0.10204787568103307,-0.04260189411570492
379.80000000000484,21.8231493701026,-0.1124494010919108,-0.043912459148192085
381.2000000000048,21.866972981020535,-0.12004242058338754,-0.04519157749789304
382.60000000000485,21.910031256392568,-0.13118845397441656,-0.04666185279673485
384.0000000000049,21.953766130927423,-0.14093949621294208,-0.04913487572974873
385.40000000000487,21.997363674328117,-0.15422791244762954,-0.051160167760100794
386.8000000000049,22.041259400480214,-0.16668902739275945,-0.05390904067149549
388.20000000000493,22.084684049504002,-0.18345952563936213,-0.0549823132663545
389.60000000000497,22.128343674392376,-0.19697573993097323,-0.05783714244622118
391.000000000005,22.17216846723136,-0.21397444234524166,-0.06150540981741148
392.400000000005,22.21557811713842,-0.2304826737179156,-0.06466122604730451
393.800000000005,22.2595645229421,-0.25036824402599067,-0.06815420958630991
395.20000000000505,22.30330667986592,-0.2699062586923022,-0.07103949408553856
396.600000000005,22.347107504143096,-0.2900547415478263,-0.07537195759300053
398.00000000000506,22.390942120016234,-0.31353707250807117,-0.07898278755657717
399.4000000000051,22.434874808224123,-0.33385047581018185,-0.08208520264033137
400.8000000000051,22.478834128003065,-0.35501801644619085,-0.08792885963478225
402.20000000000516,22.522651318041916,-0.37593382369243095,-0.09514791104834552
403.60000000000514,22.56646990705774,-0.396008570681,-0.10038143904554309
405.0000000000052,22.610769923270517,-0.414603819159409,-0.10590239838338533
406.4000000000052,22.654355801312462,-0.43416904491517255,-0.11333108497433964
407.8000000000052,22.698503847465062,-0.44926125563400854,-0.11824492806391662
409.2000000000052,22.74231752861284,-0.46158589703021197,-0.1252109035446134
410.60000000000525,22.786259287357908,-0.4700195087125645,-0.1332740530461658
412.0000000000053,22.829781223455164,-0.4769404370586264,-0.1414039236315281
413.4000000000053,22.873239317835928,-0.4777400347290032,-0.14819805761419547
414.8000000000053,22.917200393753134,-0.47540457060244334,-0.15507065319947566
416.20000000000533,22.960903133628285,-0.4709882696200316,-0.1628215498600718
417.60000000000537,23.00467439904332,-0.4630220577247019,-0.17105134081937923
419.00000000000534,23.04856203889851,-0.4533415807690213,-0.1774154853275962
420.4000000000054,23.091918712722958,-0.43864071448977865,-0.18389981555347923
421.8000000000054,23.135730828823707,-0.4235915383309611,-0.18861647152333738
423.20000000000545,23.179573830663273,-0.40476531228213114,-0.19569302205547734
424.6000000000055,23.222861451735763,-0.3866761936647251,-0.19994455174876968
426.00000000000546,23.266565789996733,-0.36479009633703746,-0.20685577848649173
427.4000000000055,23.310249103118018,-0.346105689522591,-0.21310470517116942
428.8000000000055,23.353980428199463,-0.3231204600086529,-0.21775507336586353
430.2000000000055,23.397553716645458,-0.3034705467761938,-0.22109502645255308
431.60000000000554,23.44157555736468,-0.2866182337709153,-0.22472855464220842
433.00000000000557,23.485130702247005,-0.2703156106718733,-0.22761743892186104
434.4000000000056,23.529250232908343,-0.2601711668475236,-0.22813046593095843
435.80000000000564,23.57310078174149,-0.25158730888675646,-0.2283852662589716
437.2000000000056,23.61705767018546,-0.24966907021900936,-0.23042279316041459
438.60000000000565,23.66098137551313,-0.2451523499784883,-0.23226550033779603
440.0000000000057,23.70487538008372,-0.24612880860222813,-0.23252549339680417
441.40000000000566,23.749200502362516,-0.24834375296937503,-0.23251955344665376
442.8000000000057,23.79324241625957,-0.2514103896483228,-0.23277218051818682
444.20000000000573,23.837346060861893,-0.25564897192693,-0.2325535766074629
445.60000000000576,23.88180210374222,-0.2614928117131558,-0.23252224497455343
447.0000000000058,23.926040424154685,-0.26563798714430653,-0.23251428703504207
448.4000000000058,23.96984234609149,-0.2717020740087302,-0.23384243076202127
449.8000000000058,24.014399867000503,-0.27721628272981114,-0.23352146186646117
451.20000000000584,24.058781510374022,-0.28590383417782717,-0.23383979554920353
452.6000000000058,24.102847265992693,-0.29291859066780984,-0.23444506184273228
454.00000000000585,24.147452195108748,-0.3014000266857193,-0.23514994671546807
455.4000000000059,24.191966742796446,-0.3105323271319335,-0.2359710367687997
456.8000000000059,24.23614371306557,-0.3137774607424708,-0.23646938338723755
458.20000000000596,24.280368721631618,-0.32482222330148613,-0.23646464855145988
459.60000000000593,24.32507265900775,-0.33315750826877566,-0.23778819430554332
461.00000000000597,24.369678527785933,-0.33961911604735395,-0.23778876604922417
462.400000000006,24.41398456603686,-0.34988288365043,-0.2391061343819194
463.800000000006,24.458329224967667,-0.35744857590876145,-0.23911002649197677
465.200000000006,24.502390434050444,-0.36606797751940606,-0.24041062014493075
466.60000000000605,24.54762588291548,-0.3755907862112134,-0.23941205819521016
468.0000000000061,24.592021850435604,-0.3838476575804106,-0.2404182606063503
469.4000000000061,24.636880035065165,-0.393738526971592,-0.24147855871620783
470.8000000000061,24.681178720645118,-0.40583616364835146,-0.2417382959519334
472.2000000000061,24.72587824265108,-0.4143463676817785,-0.2430284414792383
473.60000000000616,24.770351056348634,-0.4231989426869412,-0.24305000671600174
475.00000000000614,24.815087455325752,-0.43376375352188634,-0.24304950378119416
476.4000000000062,24.859839006679895,-0.44442304255057496,-0.24304120373407478
477.8000000000062,24.90446730126949,-0.4537389799776573,-0.2443705354358654
479.20000000000624,24.94948911264967,-0.4637080615471002,-0.24465914212540207
480.6000000000063,24.99395438845082,-0.47412087047731233,-0.24568286824443808
482.00000000000625,25.038409386926983,-0.4826123450934069,-0.2470014550114943
483.4000000000063,25.083478361201443,-0.49385893959866556,-0.2470402793718316
484.8000000000063,25.12819983814698,-0.5028421430378556,-0.24731098489892211
486.2000000000063,25.172834891376237,-0.511936251432717,-0.24865626594347923
487.60000000000633,25.217756886072646,-0.5190569297056569,-0.24864408682040295
489.00000000000637,25.26277583012434,-0.5297834680977057,-0.24997730475804225
490.4000000000064,25.307715769497154,-0.5373253293571927,-0.24996998703430462
491.80000000000643,25.352512790353693,-0.5466133678728002,-0.24998295508395074
493.2000000000064,25.39722638478045,-0.5529735431871183,-0.25129279575507724
494.60000000000645,25.442276126616854,-0.5599923810590318,-0.2512900236386799
496.0000000000065,25.487458511139263,-0.5695487841890147,-0.25130136845031226
497.40000000000646,25.53157907842583,-0.5772784969750041,-0.25259049895372154
498.8000000000065,25.577324615707607,-0.5847091810678533,-0.2526016104499944
500.2000000000065,25.62218495704482,-0.5922138590420317,-0.2537459918170235
501.60000000000656,25.667116414089456,-0.6009322249825884,-0.25429131026639684
503.0000000000066,25.71247076172064,-0.6078277801781758,-0.25490984020441587
504.40000000000657,25.75728587945451,-0.6194394450132419,-0.2539250548605221
505.8000000000066,25.80263618623457,-0.6258398730462077,-0.25525676078958126
507.20000000000664,25.847417617033216,-0.6350560116164017,-0.2552500188525557
508.6000000000066,25.892606274762766,-0.6426448283985945,-0.255250000305252
510.00000000000665,25.937590225906593,-0.6585789098605409,-0.2552501178093731
511.4000000000067,25.98271762550184,-0.676919203931925,-0.25519937983672225
512.8000000000068,26.02786771434382,-0.6931736699002484,-0.25658012699534183
514.2000000000068,26.07273308825537,-0.7063310614937104,-0.2578779408671026
515.6000000000067,26.117954330654893,-0.7208187766205212,-0.2578766195901925
517.0000000000068,26.162488116796236,-0.7338607045113973,-0.2588807306002683
518.4000000000068,26.208590527837725,-0.7423394355862293,-0.25885586315370945
519.8000000000068,26.25354986820591,-0.7530576354924742,-0.2582553411839865
521.2000000000069,26.297996847435357,-0.764659084430008,-0.2588694461566581
522.6000000000068,26.34380300752231,-0.7790467746536628,-0.25879279124659993
524.0000000000068,26.38967136407387,-0.788340177850251,-0.26017991754236114
525.4000000000069,26.43450677154987,-0.7981089055775932,-0.26018000380731454
526.8000000000069,26.479839590027776,-0.8111749578894416,-0.26018038882036
528.2000000000069,26.525018218431093,-0.8201731382725066,-0.25877123806532554
529.600000000007,26.57032497804802,-0.8295133333566087,-0.25885990949676163
531.0000000000069,26.61582567879047,-0.8391558235664711,-0.25885304966671185
532.4000000000069,26.661299014567085,-0.8485869280538942,-0.260185234780419
533.800000000007,26.706518706619452,-0.8570117711506164,-0.2592801829704747
535.2000000000071,26.751457412147783,-0.864233591588556,-0.2588645602908959
536.6000000000071,26.79677156831128,-0.8712383845369749,-0.25955519961178153
538.000000000007,26.84270495064382,-0.8780374995997512,-0.2603727595481615
539.4000000000071,26.887984097084185,-0.8845300830470828,-0.261286692984144
540.8000000000071,26.93330261169668,-0.8887170508303931,-0.26040110445612186
542.2000000000071,26.978820344254252,-0.8885529536822556,-0.26039818575284324
543.6000000000072,27.024102610815763,-0.8889672433131716,-0.25931619026869424
545.0000000000072,27.069542678588892,-0.8927093699275666,-0.25941991044038204
546.4000000000071,27.114813604297378,-0.8907607006845791,-0.25967691310009977
547.8000000000072,27.160464970032145,-0.8937978276557855,-0.26072885288038083
549.2000000000072,27.20612648855482,-0.8986397534950363,-0.2620012045729361
550.6000000000072,27.251479120720905,-0.9041528170658195,-0.26158180127240405
552.0000000000073,27.29680729568638,-0.9136995707032565,-0.2607310783900303
553.4000000000073,27.342600489765683,-0.9250330726560506,-0.26078612549186353
554.8000000000073,27.38819216918499,-0.9322216586379063,-0.26075138137450793
556.2000000000073,27.433832209965857,-0.9404721270597002,-0.2622139777735364
557.6000000000073,27.479341056526142,-0.9489866463403617,-0.262164953698349
559.0000000000074,27.524960256297025,-0.9581243642703969,-0.2634655906493295
560.4000000000074,27.5706634738298,-0.9618460388208355,-0.26347979445580183
561.8000000000075,27.616440224063677,-0.9677246815854511,-0.2628614342340363
563.2000000000074,27.661941163558005,-0.9750551216897325,-0.26216008050779216
564.6000000000074,27.707660308469833,-0.9810913718045525,-0.26216138729726923
566.0000000000075,27.753299375105282,-0.9883654419697719,-0.26267275968117687
567.4000000000075,27.799120980741197,-0.998633781905501,-0.26358880845661314
568.8000000000075,27.84490137884896,-1.0105773814147672,-0.2651114596767963
570.2000000000075,27.89058056174696,-1.0201837854986808,-0.26508960462996445
571.6000000000075,27.936511584439284,-1.0362821463745622,-0.2636731181558942
573.0000000000075,27.983365844042616,-1.1313479430243032,-0.2623457782820453
574.4000000000076,28.02886466436856,-1.128105091058968,-0.26368733175714976
575.8000000000076,28.074198390192507,-1.0887607839601268,-0.2636900160197624
577.2000000000077,28.119801448970378,-1.0675210244833166,-0.263690004034697
578.6000000000076,28.165458191150563,-1.057234434711335,-0.2656692644651155
580.0000000000076,28.211246954373202,-1.055874755576472,-0.26566951294592656
581.4000000000077,28.257266285658993,-1.0598509380024785,-0.2651438114476501
582.8000000000077,28.30301101937332,-1.0635577527445828,-0.26518817244746673
584.2000000000078,28.34884531283991,-1.0704674004846297,-0.26566774000142734
585.6000000000078,28.394911156340456,-1.078265281830965,-0.26704311647630474
587.0000000000077,28.440836406300875,-1.0841860500961322,-0.2670121352817483
588.4000000000078,28.48656373831905,-1.0940411549031925,-0.26632725479676056
589.8000000000078,28.532970383526653,-1.104889075224989,-0.2663300073506374
591.2000000000078,28.578628586960455,-1.1134039658644164,-0.26633000000349716
592.6000000000079,28.624472857424625,-1.1222285339700926,-0.2663300000069646
594.0000000000078,28.670635766290598,-1.1318917304867009,-0.26633000224854353
595.4000000000078,28.71689215582374,-1.1411702880425316,-0.26632776568950733
596.8000000000079,28.762883704725304,-1.152817066792012,-0.2662858209047756
598.2000000000079,28.809054266764697,-1.1621614542454328,-0.26630645163616995
599.600000000008,28.855040441811237,-1.1734731692742193,-0.26764362187850566
601.000000000008,28.901131209834517,-1.1841757550907666,-0.26763999914510794
602.4000000000079,28.947462538656755,-1.1914888201331344,-0.26764163695825527
603.800000000008,28.993477981350154,-1.2003496650244116,-0.2689352759216783
605.200000000008,29.03961879307084,-1.2101751566096537,-0.26895999207726273
606.6000000000081,29.085102160175325,-1.2203047142772148,-0.26895997815007533
608.0000000000081,29.13188927808591,-1.232665594665246,-0.26896611489753397
609.400000000008,29.17798356517053,-1.2411449806933113,-0.26995635145659547
610.8000000000081,29.22452705523699,-1.2504493858148238,-0.26995053355759735
612.2000000000081,29.27046382900769,-1.2624779322556596,-0.26859728818069595
613.6000000000081,29.31616724746563,-1.27281794565961,-0.26863971042775425
615.0000000000082,29.363040183307117,-1.2822890136368525,-0.26866200918326477
616.4000000000082,29.40905296179046,-1.2917462888461069,-0.2699325895506379
617.8000000000081,29.455632158775003,-1.300429617837725,-0.2701830878802638
619.2000000000082,29.501754463325486,-1.3110031748121123,-0.2715660711012693
620.6000000000082,29.548292508921318,-1.3193660159277174,-0.271999271089149
622.0000000000083,29.594478566318145,-1.3305729978108598,-0.2716001331521194
623.4000000000083,29.640563910485522,-1.3404659837095032,-0.2715999967662399
624.8000000000083,29.68677541640157,-1.3490145721837583,-0.27159393320241243
626.2000000000083,29.73339959534751,-1.359512578085227,-0.2729269328222932
627.6000000000083,29.779540152026776,-1.370199610385777,-0.2729200029162433
629.0000000000084,29.825914312667617,-1.382051782494146,-0.27291996994825896
630.4000000000084,29.872480837510494,-1.393880568475725,-0.2729354620017981
631.8000000000084,29.918486613658143,-1.4058377980317598,-0.2742510872576176
633.2000000000085,29.96500447537808,-1.4180095822588634,-0.2755694869447409
634.6000000000084,30.011386405435868,-1.427979318119478,-0.27686893236692667
636.0000000000084,30.057707574834886,-1.4422823676626895,-0.2769121226556104
637.4000000000085,30.104208465385923,-1.4556559259871211,-0.2774415974899629
638.8000000000085,30.151012613990158,-1.470394849502428,-0.2775299176052308
640.2000000000085,30.196705793776964,-1.4830186394249938,-0.2774267298252511
641.6000000000085,30.24388766793456,-1.4978243558277582,-0.27883435299919723
643.0000000000085,30.290172908866612,-1.5135724486520752,-0.278187732016411
644.4000000000086,30.336604508741264,-1.526841877941444,-0.27818998930556615
645.8000000000086,30.382922076356245,-1.54394364947601,-0.2781875031520542
647.2000000000086,30.429664686310097,-1.561748845940587,-0.2795048554853161
648.6000000000087,30.476167309781875,-1.581357269792686,-0.27983873107272794
650.0000000000086,30.522330229713102,-1.598290622621327,-0.2808575646696325
651.4000000000087,30.568920058389736,-1.6152854706768134,-0.2810100085338165
652.8000000000087,30.61573700818727,-1.634063948953372,-0.2823767260367802
654.2000000000087,30.6615897361954,-1.654189795853225,-0.28334726775186647
655.6000000000088,30.70896925360507,-1.6748419516787099,-0.28359926429375015
657.0000000000088,30.75524284353276,-1.6926990182072028,-0.28367880490851727
658.4000000000087,30.801980247476752,-1.7122280509351948,-0.28503108096666363
659.8000000000088,30.84830569890761,-1.733260637283912,-0.28491382004676646
661.2000000000088,30.894874644597664,-1.7546675041855955,-0.2863099863582983
662.6000000000088,30.941679994657243,-1.7738490256720434,-0.2864295233588221
664.0000000000089,30.988038904009425,-1.7941644219749757,-0.2876064048695657
665.4000000000088,31.035083609769398,-1.8192335322434987,-0.2877164043351783
666.8000000000089,31.081386344162595,-1.8436339343837038,-0.2887113759550015
668.2000000000089,31.128027193729423,-1.865468576568787,-0.28889475354487937
669.6000000000089,31.174540050976223,-1.8933099303411842,-0.29025785501643897
671.000000000009,31.22144904089849,-1.9156021146267306,-0.29158364270629056
672.400000000009,31.268094002798797,-1.9441543121356997,-0.292126925927795
673.800000000009,31.31457309858991,-1.9672266159544995,-0.29300264275647514
675.200000000009,31.36142479449952,-1.9968479245324333,-0.29417400172121333
676.600000000009,31.408152269353465,-2.0219549155482586,-0.29594925698404717
678.0000000000091,31.454555731089133,-2.0532046385727205,-0.2980846303949387
679.4000000000091,31.501753230312918,-2.0852622582931137,-0.2999041683671253
680.800000000009,31.547885514801305,-2.1136599312447983,-0.3003124289932053
682.2000000000091,31.594970859341302,-2.147529050962447,-0.3051333081039691
683.6000000000091,31.641157501562777,-2.1796615662667187,-0.3077489818638215
685.0000000000091,31.68844780169939,-2.2182113290701517,-0.31015931784125517
686.4000000000092,31.73555359039826,-2.2501908674209274,-0.31182688554186866
687.8000000000092,31.78178576401721,-2.285612514320756,-0.3136106148401794
689.2000000000093,31.82887178433779,-2.326382960044034,-0.31531399018827466
690.6000000000092,31.875720720184326,-2.3648912013013157,-0.3173829405470583
692.0000000000092,31.922356422527024,-2.405826384491694,-0.31944922413427346
693.4000000000093,31.96937557457074,-2.4484679064486454,-0.3240465084953139
694.8000000000093,32.016140085927454,-2.492395976173996,-0.3274403746251693
696.2000000000094,32.06293765885981,-2.5359541956835385,-0.33250054749914115
697.6000000000093,32.110032452271774,-2.5809169941500714,-0.33360957985902173
699.0000000000093,32.15686842888317,-2.6294700881220607,-0.3358954337906477
700.4000000000094,32.20395898608275,-2.680144626375462,-0.3365199084363768
701.8000000000094,32.25112279284792,-2.730995582632113,-0.33982308401836914
703.2000000000094,32.29797664630234,-2.781611297222304,-0.34336893877541286
704.6000000000095,32.345132557792915,-2.839245866288338,-0.3475167887909132
706.0000000000094,32.39213966992346,-2.896751772222933,-0.35163616718901247
707.4000000000094,32.4394132326808,-2.9538259727986786,-0.35474839123792856
708.8000000000095,32.486668438440574,-3.0121415953463657,-0.35894191351134985
710.2000000000095,32.53390597367101,-3.078579158933241,-0.36249396136374035
711.6000000000096,32.58077386029771,-3.1442447030642797,-0.36411171510840434
713.0000000000095,32.628336358521146,-3.210470674390866,-0.3731129618000186
714.4000000000095,32.67563625088028,-3.280004859763875,-0.37870375418318325
715.8000000000096,32.72233638872016,-3.3533955480713704,-0.38436633010614507
717.2000000000096,32.7701986766086,-3.4272593156803466,-0.38996414086709574
718.6000000000097,32.817702560724484,-3.50004839371199,-0.39557608418012524
720.0000000000097,32.864758259768465,-3.5784465541045574,-0.4016507330202752
721.4000000000096,32.91257998594369,-3.661085556438446,-0.4074593431347959
722.8000000000097,32.960210878764904,-3.7425402850829523,-0.41291262222520553
724.2000000000097,33.007623228674184,-3.8304410032031173,-0.4190159560449369
725.6000000000097,33.055404716988754,-3.915895268263887,-0.4254890072558908
727.0000000000098,33.102894822130246,-4.006705610615793,-0.4316579998055059
728.4000000000098,33.1503050623523,-4.101835575579252,-0.43554898072509474
729.8000000000097,33.19814474938564,-4.195869396704485,-0.4470277052939342
731.2000000000098,33.24564421969394,-4.291918176746234,-0.45729408381835013
732.6000000000098,33.29364419720333,-4.390263470195088,-0.46537585550731064
734.0000000000099,33.34140821640213,-4.491141730500646,-0.4743853911226603
735.4000000000099,33.3891052220242,-4.59865880693436,-0.4825784778761535
736.8000000000098,33.436836224018116,-4.699828178201436,-0.49067771028349805
738.2000000000099,33.48464920108408,-4.804838442525999,-0.4999672602805094
739.6000000000099,33.53271970748285,-4.9146032313182975,-0.5111052493831325
741.00000000001,33.58020699699113,-5.019622669098386,-0.5206402859441863
742.40000000001,33.628225047071076,-5.1272760554395935,-0.5304923477090346
743.80000000001,33.67603812593231,-5.2428076294043855,-0.5413101819994113
745.20000000001,33.72413598697253,-5.35866989515564,-0.5529097582253906
746.60000000001,33.77207356713296,-5.473889198514395,-0.564750013858994
748.00000000001,33.819967407343064,-5.5906593607353,-0.5766837067243924
749.4000000000101,33.8679283567565,-5.709920568793923,-0.5889557507205723
750.8000000000101,33.91518124403528,-5.835089040178579,-0.6000463892575105
752.20000000001,33.96404204236285,-5.95867805048766,-0.6143132921545926
753.6000000000101,34.01217513907407,-6.083025454519978,-0.6288793088937661
755.0000000000101,34.06006789619351,-6.21074546356868,-0.6421357236729794
756.4000000000102,34.108220735647706,-6.342668756238687,-0.6565017458638138
757.8000000000102,34.15619854665661,-6.46980207559245,-0.6716841799475453
759.2000000000102,34.204455968024725,-6.603132338439392,-0.6868207956896342
760.6000000000103,34.252707437194154,-6.734464049917924,-0.7041836877478191
762.0000000000102,34.300899771061914,-6.869065407137094,-0.719777718903535
763.4000000000103,34.34926950209086,-7.0088462862815675,-0.7363600387703446
764.8000000000103,34.39697590220815,-7.146475066469622,-0.7519875962802343
766.2000000000103,34.44548461449108,-7.282511701237303,-0.7727074902604953
767.6000000000104,34.49378467018713,-7.420626943706198,-0.7926941687639828
769.0000000000103,34.54171725973628,-7.556339735680842,-0.8077013014366603
770.4000000000103,34.589999312698296,-7.691808112076797,-0.8233244030761249
771.8000000000104,34.63819444185727,-7.822376982309306,-0.8436532168133968
773.2000000000104,34.68618991685513,-7.946477569769258,-0.8646943277517649
774.6000000000104,34.73420749446697,-8.072618761542046,-0.8863553160153623
776.0000000000105,34.78219518666032,-8.187316362655856,-0.9065290165157736
777.4000000000104,34.830208832170975,-8.298950316325945,-0.9268783598538946
778.8000000000105,34.878456194380476,-8.404190920970423,-0.9493166621950189
780.2000000000105,34.926283561175765,-8.4971966434605,-0.969407024987603
781.6000000000105,34.97396926635841,-8.577549758157781,-0.9934561938319533
783.0000000000106,35.02148285662039,-8.643082503221123,-1.0137493394557096
784.4000000000106,35.06914857904875,-8.694340972533881,-1.036603963008881
785.8000000000106,35.116199255580206,-8.719963337527041,-1.0591021151966795
787.2000000000106,35.163654045029084,-8.719898746173477,-1.0819890061159425
788.6000000000106,35.21013546090099,-8.681341240133225,-1.1065372226107981
790.0000000000107,35.256811225192706,-8.60491544225375,-1.1281153290466546
791.4000000000107,35.30299066360085,-8.472611702858778,-1.1489736372284818
792.8000000000106,35.34859303514379,-8.277403311623136,-1.1697743754533398
794.2000000000107,35.39372794203325,-8.00890364801726,-1.1885500331381578
795.6000000000107,35.43795919555505,-7.659442443450505,-1.2077340362437603
797.0000000000107,35.481264642430645,-7.211337348964039,-1.2250475359332569
798.4000000000108,35.524237981233156,-6.647400840480402,-1.2400280077722412
799.8000000000108,35.56586315272365,-6.000940335922396,-1.2535594500411964
801.2000000000108,35.60726033655477,-5.278361470999914,-1.264848789764239
802.6000000000108,35.64898823993505,-4.541080153790662,-1.2745858243011385
804.0000000000108,35.690603277967384,-3.861728222683711,-1.281723792368401
805.4000000000109,35.733238116352894,-3.292468864427804,-1.2864010620114805
806.8000000000109,35.77679598539181,-2.857009740309134,-1.289370789475385
808.200000000011,35.82113441594385,-2.5520201284712405,-1.2910206446993961
809.6000000000109,35.866490215885264,-2.346826786111995,-1.2942725082769067
811.0000000000109,35.91256577081421,-2.2164358287634487,-1.2957578516194506
812.400000000011,35.95882357660373,-2.145267479277896,-1.296602431921826
813.800000000011,36.004980538373346,-2.1063557708114784,-1.2965397316185814
815.200000000011,36.052593557735946,-2.0880571675467854,-1.2965649748941286
816.600000000011,36.099864780397745,-2.085148248562749,-1.2952214918124456
818.000000000011,36.14678983312747,-2.0897567337569987,-1.2962753956656945
819.400000000011,36.193850325039335,-2.092560542138724,-1.296209842178551
820.8000000000111,36.24126450618876,-2.1003782184945976,-1.2962137484264327
822.2000000000111,36.288636478406865,-2.105625219663407,-1.2952253766907105
823.6000000000112,36.33570612470282,-2.1142059919128164,-1.2952201611527725
825.0000000000111,36.38324681106352,-2.1228073089653186,-1.29587558777932
826.4000000000111,36.43042747843761,-2.129353014565847,-1.2965301147945105
827.8000000000112,36.47768409463493,-2.1359765377795483,-1.2965300011078575
829.2000000000112,36.52519511703779,-2.1417775930004654,-1.2965300053099078
830.6000000000113,36.5721577360277,-2.1470770918767745,-1.2965282997834708
832.0000000000113,36.61996739496828,-2.1538567794855528,-1.2978490371192182
833.4000000000112,36.667074677088166,-2.155193435944546,-1.2964766943908996
834.8000000000113,36.71433996672253,-2.157354906325654,-1.296540128421924
836.2000000000113,36.761758311710906,-2.1673754489036727,-1.2965404306635318
837.6000000000113,36.8092941757,-2.1714217285017394,-1.2971527852177145
839.0000000000114,36.85640530060388,-2.1761908513070565,-1.2975344584547739
840.4000000000113,36.90382439642195,-2.1836170371876955,-1.296522804382418
841.8000000000113,36.951201720393826,-2.1848818728432855,-1.2965404091054746
843.2000000000114,36.998446059712954,-2.188969704362362,-1.2978882808785452
844.6000000000114,37.04597143973612,-2.1921812642753946,-1.2978598925041185
846.0000000000115,37.09334214653963,-2.1935972444872145,-1.2978615043873716
847.4000000000115,37.14047542034865,-2.201214033309661,-1.299163793493053
848.8000000000114,37.18764560643478,-2.2062263396921535,-1.2991540978990548
850.2000000000115,37.23548550630803,-2.2101487996317566,-1.2984920326617706
851.6000000000115,37.2830423221043,-2.2122860387457224,-1.2972135139782504
853.0000000000116,37.33054128824595,-2.212422746545647,-1.2972001715833326
854.4000000000116,37.37801285330114,-2.217365393460828,-1.2986074275707002
855.8000000000116,37.425226033478204,-2.22204381835778,-1.2978283370404964
857.2000000000116,37.472685281915986,-2.2340975088455988,-1.297131448410131
858.6000000000116,37.520382521072854,-2.2403197859571127,-1.2978501007009284
860.0000000000116,37.567900524936604,-2.2443323200244083,-1.2978482976808454
861.4000000000117,37.61535099173613,-2.2498576956143865,-1.2965597985823516
862.8000000000117,37.662755855735426,-2.255575963862095,-1.2978636810237458
864.2000000000116,37.710268282686435,-2.256840264720129,-1.2978611796148671
865.6000000000117,37.757776905443514,-2.2596287590871453,-1.2991829751079145
867.0000000000117,37.805610523519086,-2.267844357026026,-1.2992129718858725
868.4000000000118,37.85293842358376,-2.277644912566421,-1.298850648924625
869.8000000000118,37.90030822836992,-2.2738691896807794,-1.298849999894744
871.2000000000118,37.948013508732025,-2.2719725645539217,-1.2988503019889377
872.6000000000118,37.99553473605524,-2.2718036038693503,-1.2985275301435881
874.0000000000118,38.042962847606574,-2.271583350633604,-1.298859261351054
875.4000000000119,38.09055090702178,-2.271089508822354,-1.2994708310111056
876.8000000000119,38.13782553978953,-2.2740379641275665,-1.2988404467634598
878.2000000000119,38.185231460353,-2.275337692443149,-1.2988399987553034
879.600000000012,38.23280486419779,-2.2788858350304255,-1.2988399978126681
881.0000000000119,38.280369472291355,-2.284420174360645,-1.29884024160945
882.4000000000119,38.32792986538336,-2.2892320297567603,-1.2985071930525853
883.800000000012,38.37572074638233,-2.293646042731565,-1.2998177539945859
885.200000000012,38.42290321970443,-2.2967688804219515,-1.2992186707491014
886.600000000012,38.47098719603778,-2.299412007154829,-1.3001601466542376
888.000000000012,38.51834872911181,-2.306559525885064,-1.3001599412604445
889.400000000012,38.565825906553286,-2.3089739479163507,-1.300281794240918
890.8000000000121,38.61359745765641,-2.3132250524824833,-1.3011454692182696
892.000000000012,38.65397741519555,-2.3163380212719957,-1.301876889909157