File: 01_Data/EIFS_Coating/STA/N2/30K_min/EIFS_Coating_STA_N2_30KData_230914_R1.csv
##Temp./Â°C,Time/min,DSC/(mW/mg),Mass loss/mg
41.0,10.546326641144722,-2.3031149774375277,0.03578303396617111
42.40000000000002,10.781606824161363,-2.2277464647788316,0.033726816266210324
43.80000000000004,10.925064620215776,-2.1704728224401793,0.03305077242240584
45.20000000000006,11.035859768080524,-2.1257763390268893,0.03362973846936734
46.60000000000008,11.128810863905702,-2.0832035446151855,0.03197426624178101
48.0000000000001,11.213470345908622,-2.0462442778828156,0.033207653285753036
49.40000000000012,11.29360132538214,-2.0114340568943,0.03325165821055398
50.80000000000014,11.365627181722918,-1.9788150498682269,0.03259724798372465
52.20000000000016,11.434406474426485,-1.9470046993793377,0.032751700463438116
53.60000000000018,11.49991145751981,-1.920035536585361,0.03272950194975399
55.0000000000002,11.562997395013335,-1.8918110993612047,0.030257843800920003
56.40000000000022,11.624169926599315,-1.8650065569275964,0.03181103617847425
57.80000000000024,11.683215571865103,-1.8417588829286795,0.030498980384014995
59.20000000000026,11.740527946649093,-1.823513019607487,0.03028534368716551
60.60000000000028,11.796857319676118,-1.8018162050386648,0.03292388595692097
62.0000000000003,11.85244939711513,-1.7844775432593687,0.03307375667409351
63.40000000000032,11.906669348813294,-1.7676548427535352,0.03167793527797658
64.80000000000034,11.959739813587397,-1.7501136554203596,0.03183300470919592
66.20000000000036,12.012065595432006,-1.7370256846540741,0.0319973618744025
67.60000000000038,12.064965379439855,-1.7237897887758562,0.030856051402981866
69.0000000000004,12.117067769839462,-1.7134534406070248,0.029415551057392353
70.40000000000042,12.168017710285389,-1.7023691756463102,0.030010322373958953
71.80000000000044,12.219287442335013,-1.6934746125438338,0.029022677072668923
73.20000000000046,12.26961094616853,-1.6849270882094198,0.029204725598774406
74.60000000000048,12.32003640177578,-1.676916355132878,0.028138373913241477
76.0000000000005,12.369857656371368,-1.67174530737416,0.027767755484746193
77.40000000000052,12.419686788577888,-1.6669657263561495,0.027333419680493964
78.80000000000054,12.469034441562222,-1.6628480534964196,0.02630974664385244
80.20000000000056,12.51805773705772,-1.6604247816963,0.02874560259352199
81.60000000000058,12.567561118674952,-1.6570892744065564,0.02744336099157829
83.0000000000006,12.61620002596619,-1.65287790230081,0.026607766691674417
84.40000000000062,12.664725151956356,-1.6520974233115986,0.02602878831590205
85.80000000000064,12.712979752388115,-1.6482797444311261,0.025986424368801497
87.20000000000066,12.761182319206139,-1.643642889148043,0.025970173817850384
88.60000000000068,12.809238945675085,-1.6394820470783453,0.024198942533772527
90.0000000000007,12.857259553643615,-1.6314606345621527,0.024827571141173177
91.40000000000072,12.90445629438355,-1.622201866735646,0.02336060031549758
92.80000000000074,12.951846157106095,-1.6097747737555528,0.022060913047454722
94.20000000000076,12.999159672989549,-1.592198911901516,0.022098998981859186
95.60000000000078,13.04623691837474,-1.5682679621145759,0.020744735756840438
97.0000000000008,13.093018486366152,-1.5430684784557165,0.01964054535585147
98.40000000000082,13.139157960458736,-1.5151550726606908,0.019413387153349948
99.80000000000084,13.1865207307332,-1.490485521996676,0.018112067292995082
101.20000000000086,13.232629539472912,-1.470055167916526,0.018104121297112474
102.60000000000088,13.278761920647916,-1.4478977533569513,0.018147503148096877
104.0000000000009,13.325537717117172,-1.4278855547503626,0.01810970148811153
105.40000000000092,13.372181193742653,-1.4091327400150258,0.018156812525478738
106.80000000000094,13.417274046002534,-1.3934517887926408,0.016826658576436504
108.20000000000095,13.464429464660885,-1.3784247746725165,0.01777363700493728
109.60000000000097,13.511490021163892,-1.3646520540098583,0.016471505282179777
111.000000000001,13.557575679885861,-1.3500228406808004,0.016469527815952123
112.40000000000101,13.604072778375583,-1.3365323359657146,0.01596803732741403
113.80000000000103,13.650747380166388,-1.3259243302877972,0.015450265551102849
115.20000000000105,13.696029113784336,-1.3159828085506242,0.015150958725991703
116.60000000000107,13.743167783524964,-1.3066363396404097,0.015503682932883844
118.0000000000011,13.789166561913012,-1.299178174872764,0.014102529191984736
119.40000000000111,13.835230816485794,-1.2899423642508943,0.015470566215022963
120.80000000000113,13.881559993719868,-1.2810516529762468,0.015450774989808291
122.20000000000115,13.926462656531974,-1.2713525128057783,0.014487100106946205
123.60000000000117,13.973157229309285,-1.2598592715543593,0.014537005127806424
125.0000000000012,14.018386299048709,-1.2492410170667538,0.015481432042926624
126.40000000000121,14.064545034167788,-1.2378927266907405,0.015477495671445851
127.80000000000123,14.109968771757543,-1.2266067235814755,0.015809971967262637
129.20000000000124,14.15557254844835,-1.2127397756448905,0.017247081538150244
130.60000000000127,14.200611917800448,-1.2020930080053074,0.01571627156153932
132.0000000000013,14.246116740210645,-1.1901335945402995,0.014390443267509045
133.4000000000013,14.290729748777128,-1.1801291366000226,0.014349167941165586
134.80000000000132,14.336171024095528,-1.1704094780912315,0.013377999111487515
136.20000000000135,14.380929919515468,-1.1590408926356246,0.013056736724667228
137.6000000000014,14.42598850542862,-1.1492778150575327,0.012633647729578534
139.0000000000014,14.470602781505045,-1.1426024348675357,0.014050100095531981
140.4000000000014,14.515442683865105,-1.132023394299857,0.014051032184178247
141.80000000000143,14.559868332572744,-1.1234141445230807,0.013032339528459946
143.20000000000147,14.603751878310751,-1.1146769252682043,0.013061082222674436
144.60000000000147,14.648223729377513,-1.1056882279701992,0.013886034071370457
146.00000000000148,14.693510220588974,-1.097102991950598,0.014379970474395432
147.4000000000015,14.73783663129848,-1.0885290054266448,0.01437678538914966
148.80000000000155,14.78240041112621,-1.080139480793948,0.015746537820355844
150.20000000000155,14.8262159037107,-1.0717907326062595,0.01569939112840446
151.60000000000156,14.870241726564124,-1.063103006724112,0.015351330511349293
153.0000000000016,14.91472890619958,-1.0563453922391803,0.015352894712891807
154.40000000000163,14.958299394693668,-1.0475829414823248,0.014715874411890706
155.80000000000163,15.002632099875193,-1.041068204608042,0.014709997605415914
157.20000000000164,15.046513833817237,-1.0336642671278973,0.01471001342688849
158.60000000000167,15.090346563778036,-1.0251728586265025,0.014710317938780193
160.0000000000017,15.134192329387316,-1.019559284739043,0.014009328354517514
161.4000000000017,15.178158540765116,-1.0115470117607572,0.013050178358968267
162.80000000000172,15.221638348421118,-1.0038113597763865,0.013057520449217819
164.20000000000175,15.265558355483535,-0.9963119002966243,0.014357170995613622
165.60000000000178,15.309248425324235,-0.9901436820193807,0.014379886783729035
167.0000000000018,15.352865708360856,-0.9824544954971276,0.014379879289902586
168.4000000000018,15.39681828416124,-0.974176737623289,0.014370811396021477
169.80000000000183,15.440478622629819,-0.9689011532350581,0.014049948259609923
171.20000000000186,15.483921911927439,-0.9622658259636466,0.014049905992103984
172.60000000000187,15.527053554798162,-0.9529619083026247,0.014053975464991542
174.00000000000188,15.570443173929318,-0.9488913850291084,0.013053827958720898
175.4000000000019,15.61395473568502,-0.9396584401407655,0.012767266906330565
176.80000000000194,15.65760962491203,-0.9334130907173319,0.012408808582115238
178.20000000000195,15.700742092263315,-0.9269135002580525,0.012410020432272795
179.60000000000196,15.744142424572557,-0.9220897672746616,0.012408947807620585
181.000000000002,15.787073008196206,-0.9152299891432979,0.011916937797927574
182.40000000000202,15.830439996874459,-0.9089310456019195,0.011750053583607922
183.80000000000203,15.873549102124706,-0.9018294548324147,0.011750235796990083
185.20000000000203,15.916802066578445,-0.8959177895683952,0.011775305272730296
186.60000000000207,15.959722286952253,-0.890609785900956,0.013071242755865242
188.0000000000021,16.002624173122122,-0.8839902073683628,0.012734096297515318
189.4000000000021,16.045331923494466,-0.8786145597143808,0.011415395924937233
190.80000000000211,16.087743680409623,-0.8734334871342229,0.011420122845715142
192.20000000000215,16.130969284442934,-0.8672868645852693,0.011420182995530936
193.60000000000218,16.17366682134381,-0.8610639017151849,0.011460170115721535
195.0000000000022,16.216632488922816,-0.8551702309696596,0.010109349355080344
196.4000000000022,16.259343817642144,-0.850447150842928,0.010099978163292445
197.80000000000223,16.302263745880243,-0.8456368791612903,0.010099969914574292
199.20000000000226,16.344824915951683,-0.8389887677376542,0.01009996999952234
200.60000000000227,16.387246384483497,-0.8346235129152358,0.0100999699991422
202.00000000000227,16.430060938578805,-0.8298326263019924,0.010099970006374637
203.4000000000023,16.47255396389396,-0.8248300502343425,0.010100036831830028
204.80000000000234,16.515005567963982,-0.8195974103788505,0.010123532040747119
206.20000000000235,16.557602087261998,-0.8167159657307997,0.01142341858789564
207.60000000000235,16.599788420061657,-0.811993449226017,0.011420137286301646
209.0000000000024,16.642690552473972,-0.8071154768686263,0.011420135884956828
210.40000000000242,16.684780950717165,-0.8022788049057925,0.011420106815768438
211.80000000000243,16.72767509855906,-0.7978373480096359,0.011413521553102601
213.20000000000243,16.769453707456137,-0.7927151094819618,0.012727673979587628
214.60000000000247,16.812586930115508,-0.7879611097041265,0.012007190676994739
216.0000000000025,16.85511987487617,-0.7859635717604301,0.010101086845984764
217.4000000000025,16.897761843453583,-0.782112098204913,0.01009997263809792
218.8000000000025,16.940121932193478,-0.7773921342103418,0.010099969997478642
220.20000000000255,16.98216206407472,-0.7754654386674275,0.010099969997155345
221.60000000000258,17.024743115886782,-0.7709279028963091,0.010099968770532541
223.0000000000026,17.067414896814554,-0.7676328705222477,0.010099683680024008
224.4000000000026,17.109527856121105,-0.7641575764042594,0.010067248313369692
225.80000000000263,17.151991792207095,-0.7603095851811795,0.011410341852116535
227.20000000000266,17.194344300994484,-0.7556271011538022,0.011410137160174472
228.60000000000267,17.236926700661975,-0.7521105941523074,0.009477588343078214
230.00000000000267,17.279118329101255,-0.7482757696661333,0.009441072867778733
231.4000000000027,17.3212018864189,-0.7464853332131165,0.008125728473526994
232.80000000000274,17.363452986252884,-0.7431870882524461,0.008118928773479084
234.20000000000275,17.40607579107405,-0.7412717585461844,0.007487941600754056
235.60000000000275,17.44848275194568,-0.7364436466145976,0.00747480951962709
237.00000000000279,17.490797352663392,-0.7328318531266055,0.008127174936936488
238.40000000000282,17.532971434908674,-0.7312240847230516,0.008129835941963037
239.80000000000283,17.575350943206736,-0.7270762477816418,0.00812970404209823
241.20000000000283,17.617717583447618,-0.7240827924457154,0.0080909321136855
242.60000000000286,17.659751869595464,-0.7236707841749295,0.008801263100152834
244.0000000000029,17.702244926604553,-0.7198803952870656,0.009111092130760667
245.4000000000029,17.744255371057562,-0.7167115414760244,0.00911028457452323
246.8000000000029,17.78673387070823,-0.7141761688678709,0.008056162141425016
248.20000000000294,17.828815498569632,-0.7130078283632305,0.008004340923450926
249.60000000000298,17.87161311863899,-0.7100939339858692,0.009440345460243638
251.00000000000298,17.91347501164914,-0.7085792363673792,0.009439061493451195
252.400000000003,17.955677317513018,-0.7055570130288595,0.007917670554078882
253.80000000000302,17.997381933067025,-0.7040361803344838,0.008009181870123339
255.20000000000306,18.040117897387084,-0.701534322365291,0.007674720488952236
256.6000000000031,18.082748967003234,-0.6989123613158569,0.007030048105660658
258.00000000000307,18.12479334609594,-0.6976994982547803,0.007051137016991671
259.4000000000031,18.16671615262201,-0.6959545558482773,0.006688386884754038
260.80000000000314,18.20945847161917,-0.6956712018840323,0.006690163430260299
262.2000000000031,18.25143909315856,-0.692315114139582,0.006686236801386247
263.60000000000315,18.293673584595627,-0.6906508032758774,0.007432209205707974
265.0000000000032,18.33587712664585,-0.689987335538125,0.007679476095231674
266.4000000000032,18.378019399936804,-0.689289196412305,0.007682968928540035
267.80000000000325,18.4206272795353,-0.6886386294048241,0.0060501858516301965
269.20000000000323,18.462847797408653,-0.6876383456332051,0.005041120866156934
270.60000000000326,18.50520270227257,-0.6863910427377302,0.00503992997408842
272.0000000000033,18.547050964953687,-0.6841545587191504,0.005039922033805766
273.4000000000033,18.58942062776462,-0.6842013766744376,0.005039922000069197
274.8000000000033,18.63129366825888,-0.6813409630105518,0.005039922000001695
276.20000000000334,18.674075538231385,-0.6821054790068773,0.005039921999999475
277.6000000000034,18.715840512815678,-0.6817254107870946,0.005039921999999475
279.0000000000034,18.757813785501277,-0.679919764933812,0.005039922000000363
280.4000000000034,18.800201020344595,-0.6802926815086063,0.005039922000000363
281.8000000000034,18.84309724517197,-0.6794740227151009,0.005039922000581676
283.20000000000346,18.88493390236609,-0.6795114109128352,0.005039922182692447
284.60000000000343,18.927428970304657,-0.6807808038064734,0.005039953879049985
286.00000000000347,18.969817162408127,-0.6807987278282883,0.005040609622119163
287.4000000000035,19.01224173716448,-0.6785350427074806,0.003722214596378226
288.80000000000354,19.054629789897067,-0.6804697791471174,0.003983525249042774
290.20000000000357,19.096201790878332,-0.6793652276633559,0.004720773609960371
291.60000000000355,19.139515368189873,-0.6783569407053524,0.004718240229191206
293.0000000000036,19.181027289683755,-0.6785440664227804,0.004063707488349166
294.4000000000036,19.223811846415117,-0.6806710048843567,0.003331293250465439
295.8000000000036,19.266273898877945,-0.6803243787705928,0.003399676859405343
297.2000000000036,19.30859878012189,-0.6815805784452726,0.0033997297777612623
298.60000000000366,19.350454315034924,-0.6821410711141577,0.003040900621472442
300.0000000000037,19.393207864692066,-0.6827132459393376,0.0024111849219576875
301.40000000000373,19.435898959023156,-0.6832251790165667,0.002410116900544157
302.8000000000037,19.478402225171948,-0.6857078527349293,0.002410112009507248
304.20000000000374,19.52062338823183,-0.6868243899654987,0.002410111999843867
305.6000000000038,19.563285228736884,-0.6876909317127687,0.002410111838267337
307.00000000000375,19.605447358632915,-0.6895429778317608,0.0024100665217736683
308.4000000000038,19.647898334469847,-0.6923612340453016,0.002402282531531963
309.8000000000038,19.69063107481335,-0.6929766389752997,0.0020778421739851005
311.20000000000385,19.732635637756157,-0.6940450402445232,0.0007180493288916345
312.6000000000039,19.775465490613577,-0.6959747195657715,-0.0004944801594004566
314.00000000000387,19.81783378650661,-0.6954628868152681,-0.0005497567170826834
315.4000000000039,19.860613195165815,-0.6978563717793016,-0.000549863517668836
316.80000000000393,19.902857523098458,-0.6998584954507618,6.384471400755487e-05
318.2000000000039,19.94550907862866,-0.7008686289748729,0.0007653836171450656
319.60000000000394,19.987960287697668,-0.7014747338594896,-0.0005391657105584535
321.000000000004,20.0303366198335,-0.7031444193940204,-0.0005498189079502502
322.400000000004,20.07288884632681,-0.7047952490990116,-0.0005498086207222919
323.80000000000405,20.11547560893131,-0.7051159519101042,-0.0005480193061138117
325.200000000004,20.157283109910946,-0.7074322336416557,-0.0011522067835909588
326.60000000000406,20.20048484111316,-0.7098621305628864,-0.001209984596756808
328.0000000000041,20.243179347728155,-0.7113692641433181,-0.0016691658957621591
329.40000000000407,20.285996816665907,-0.7147201157190302,-0.001967860541975952
330.8000000000041,20.328586043449853,-0.7154158656435587,-0.0031920525568929214
332.20000000000414,20.37115364391707,-0.7188224599336418,-0.0031901376487186717
333.6000000000042,20.41378840448916,-0.7204119765212232,-0.003189421507604706
335.0000000000042,20.45691227898124,-0.7245018658260466,-0.002868086456634611
336.4000000000042,20.49930712797198,-0.7268956412955903,-0.002860144774646578
337.8000000000042,20.54224652161724,-0.7275417177477465,-0.003292436707237112
339.20000000000425,20.585009230943985,-0.731931039525261,-0.004150917022445633
340.60000000000423,20.627797544185555,-0.7317029319585044,-0.0041708988938125025
342.00000000000426,20.670629238727706,-0.7332731338334324,-0.005480877024967246
343.4000000000043,20.71330248968744,-0.7330654947250682,-0.005489991649369141
344.80000000000433,20.75590643483549,-0.736254679845366,-0.005490130031948315
346.20000000000437,20.798920506180504,-0.7407248349364821,-0.00549019100991055
347.60000000000434,20.841685016232827,-0.7405958049098037,-0.00598022835451717
349.0000000000044,20.88485383461723,-0.74227370201491,-0.0068077109453335005
350.4000000000044,20.927702020169907,-0.7430722782208659,-0.0067278375420687375
351.8000000000044,20.970668519970165,-0.7426168792250002,-0.008130228383727012
353.2000000000044,21.01343279892121,-0.7403896621000637,-0.008063932584551292
354.60000000000446,21.056460252117372,-0.7424883210648231,-0.009440425999839963
356.0000000000045,21.099190644510983,-0.7421423472396843,-0.010359456499912323
357.4000000000045,21.142336404688038,-0.741204618247391,-0.01076038730371165
358.8000000000045,21.18543008823833,-0.7412612524411158,-0.011059480786224984
360.20000000000454,21.228274492231197,-0.7384112787248603,-0.01208103855128595
361.60000000000457,21.27181218154799,-0.7408070416541944,-0.01206299768226815
363.00000000000455,21.314551724970975,-0.739327161356753,-0.01338651101930255
364.4000000000046,21.357394362342042,-0.7401187853981107,-0.013471753872737136
365.8000000000046,21.400674560364166,-0.7375051380990545,-0.01504278835970796
367.20000000000465,21.44368450931751,-0.7413035049721706,-0.01536329865096997
368.6000000000047,21.486865140802323,-0.7409306752992957,-0.016360506016091403
370.00000000000466,21.52984434904371,-0.743600248004642,-0.01635996222642122
371.4000000000047,21.572703963589458,-0.7436053821425236,-0.016377206903618546
372.80000000000473,21.616500198788515,-0.7445336287091511,-0.01812680396132249
374.2000000000047,21.659598584800893,-0.7501995218891367,-0.020832368833548554
375.60000000000474,21.703143215078224,-0.7502070497309018,-0.0221863781766527
377.0000000000048,21.746445484618583,-0.7541730944327719,-0.02219446952346127
378.4000000000048,21.7900619199229,-0.7588898305325174,-0.023499591217312155
379.80000000000484,21.83327510147683,-0.7612357478924134,-0.023499419073211403
381.2000000000048,21.87641990312705,-0.7655414715862163,-0.024957463737313557
382.60000000000485,21.91993849885847,-0.7714821000698657,-0.026566335261556162
384.0000000000049,21.963574172317365,-0.7764565786678562,-0.028689926705426583
385.40000000000487,22.006810148502353,-0.7856125615300434,-0.030444516459136484
386.8000000000049,22.050300969095773,-0.7928789281359643,-0.032325125965737556
388.20000000000493,22.093694545471088,-0.8005147132773675,-0.033855003413915785
389.60000000000497,22.137477649745684,-0.8102518018824176,-0.03705666307915623
391.000000000005,22.180993898536865,-0.8218070835569127,-0.04068713851242478
392.400000000005,22.224511416178863,-0.8330144658893541,-0.044114793262694185
393.800000000005,22.268111626248142,-0.8473934740637874,-0.04763176915541312
395.20000000000505,22.311614827038046,-0.8577371020224525,-0.05104702149151796
396.600000000005,22.35572637029449,-0.8731672385785917,-0.05426697368942257
398.00000000000506,22.399414447558573,-0.8895247449929023,-0.05888497927021863
399.4000000000051,22.44304823026806,-0.905041099955422,-0.06405957894780778
400.8000000000051,22.486795332771013,-0.9219429943445834,-0.0693262179272125
402.20000000000516,22.530596869431598,-0.9357422960963244,-0.0726921259312423
403.60000000000514,22.574415209148167,-0.9522708605564124,-0.0777487045070604
405.0000000000052,22.617990998045602,-0.9644500668334904,-0.08314906312231818
406.4000000000052,22.661747220344186,-0.9782859779027893,-0.08958022802957721
407.8000000000052,22.70585452237306,-0.989678247251626,-0.09677159076721642
409.2000000000052,22.749319761062583,-0.9991205667465318,-0.10274228639870397
410.60000000000525,22.793217392005314,-1.0059980492015912,-0.11019641692430238
412.0000000000053,22.836601560268182,-1.0068311959845393,-0.1192130795880404
413.4000000000053,22.8804447969651,-1.0063464020341923,-0.12676592970192413
414.8000000000053,22.924052683555285,-0.9994046004570082,-0.1327594872740785
416.20000000000533,22.967846121042587,-0.9908955101497126,-0.13989992430377107
417.60000000000537,23.0113832129316,-0.9817816324985439,-0.14806834527747315
419.00000000000534,23.055227866327733,-0.9670592012812937,-0.15401826062416957
420.4000000000054,23.0984586405535,-0.9493428888744574,-0.16064964504743928
421.8000000000054,23.14190641193205,-0.9289207216765588,-0.16677175273338785
423.20000000000545,23.185520160819806,-0.907557744802184,-0.17474096170394748
424.6000000000055,23.22917545508229,-0.8840847727098626,-0.18113177739449826
426.00000000000546,23.27288818525235,-0.8601442741569105,-0.18648165748490175
427.4000000000055,23.316416267511,-0.8352538016142051,-0.1909136497528241
428.8000000000055,23.359879625322485,-0.8118863751870518,-0.19463552095184378
430.2000000000055,23.403742974156298,-0.7856153012579878,-0.19889539192801964
431.60000000000554,23.447321371997567,-0.7633726109172423,-0.20102515820495848
433.00000000000557,23.490863195095177,-0.7463749515761505,-0.20357217698116425
434.4000000000056,23.534769291860385,-0.7259936929484548,-0.20601958492641526
435.80000000000564,23.57852689627368,-0.7128234292544422,-0.20792716746182638
437.2000000000056,23.622577566598085,-0.703070618021816,-0.20944253607319885
438.60000000000565,23.666609639459455,-0.6961456661631191,-0.2106302434800189
440.0000000000057,23.710634724968394,-0.6914642077786283,-0.21234519020073117
441.40000000000566,23.75458298117903,-0.6882395432481369,-0.21373539437822808
442.8000000000057,23.798470497858013,-0.6849097670632153,-0.2135701615238541
444.20000000000573,23.842725891511964,-0.6813955372570786,-0.2149613362141567
445.60000000000576,23.886737631191465,-0.679937544399662,-0.2156248109514034
447.0000000000058,23.931014025850132,-0.6795543920810159,-0.2162799772748083
448.4000000000058,23.9754301401018,-0.6816894062325409,-0.21635757540073985
449.8000000000058,24.01870888360083,-0.6824223132337774,-0.21758273312982235
451.20000000000584,24.063497091776334,-0.6808932050984379,-0.21958592133915067
452.6000000000058,24.108170702283523,-0.6865712598915065,-0.22022428285445717
454.00000000000585,24.152160167619122,-0.6872470517076432,-0.22039532037231302
455.4000000000059,24.196089310927846,-0.6897724489609535,-0.22155064768864063
456.8000000000059,24.24087648936942,-0.6902076485723089,-0.22154962223654096
458.20000000000596,24.284977374773327,-0.6927743989651437,-0.22260436040704912
459.60000000000593,24.329712898496947,-0.6957098586739029,-0.22192530210344064
461.00000000000597,24.37410842673845,-0.6999114066464056,-0.22285776914015143
462.400000000006,24.41795283462704,-0.7018959437401664,-0.22422526333447168
463.800000000006,24.462655505314178,-0.7055442411590438,-0.22517407550735058
465.200000000006,24.50715841726129,-0.7082235983052436,-0.22606982914695273
466.60000000000605,24.551547845145752,-0.7123951518247981,-0.22615074683775616
468.0000000000061,24.596179370603192,-0.7156021548545558,-0.2275416593640709
469.4000000000061,24.640707149797805,-0.7189246251575866,-0.2274700384552859
470.8000000000061,24.68536427724781,-0.7221655472148845,-0.22746869760282484
472.2000000000061,24.729589865682673,-0.72488509919468,-0.22766478855563577
473.60000000000616,24.774023894409254,-0.7314530355236126,-0.2276016403896941
475.00000000000614,24.8187589890161,-0.73589513490215,-0.2289011909839136
476.4000000000062,24.863427524352037,-0.7386582964899251,-0.2295808784239366
477.8000000000062,24.90779898389632,-0.7418982621833374,-0.23021875778295886
479.20000000000624,24.952454057341676,-0.746608926494706,-0.23041369625272612
480.6000000000063,24.997249462510137,-0.7499304022648482,-0.23154027142815714
482.00000000000625,25.042096015306154,-0.7532893364522796,-0.23149879194021628
483.4000000000063,25.086617765159883,-0.7556147378109305,-0.23286292748679127
484.8000000000063,25.131214198787983,-0.758817320830478,-0.23416001592929803
486.2000000000063,25.17578653408327,-0.7622409162094793,-0.23544369626810369
487.60000000000633,25.220589223716548,-0.7638675183159864,-0.23652694710334243
489.00000000000637,25.265317788203358,-0.7664009300540079,-0.23680982026692243
490.4000000000064,25.310062533740165,-0.7671481903665421,-0.2368120806209535
491.80000000000643,25.354799499348342,-0.7718257181131585,-0.23812365258083812
493.2000000000064,25.39921135119756,-0.7734578415809565,-0.23812000082064122
494.60000000000645,25.444006760024433,-0.7743978913284086,-0.23811471822369645
496.0000000000065,25.489135094945457,-0.7719841628225291,-0.23943556413071487
497.40000000000646,25.533656426440196,-0.7742639609527667,-0.23976040272948085
498.8000000000065,25.57841617518634,-0.7752113102852005,-0.24069070097094158
500.2000000000065,25.62347146485849,-0.7765660594984677,-0.24207605513878327
501.60000000000656,25.667985943915973,-0.776657868258876,-0.24474185662418257
503.0000000000066,25.713292531391183,-0.7760099939552005,-0.2442722241404649
504.40000000000657,25.75798936841252,-0.774709775440471,-0.24321635366724115
505.8000000000066,25.802787371289668,-0.7766014326487528,-0.2433979817455323
507.20000000000664,25.847819216644453,-0.7775447941841334,-0.2445076108326143
508.6000000000066,25.892887734950808,-0.7779146569770926,-0.24470998553318868
510.00000000000665,25.937641967837052,-0.7808261589868803,-0.24471007816393664
511.4000000000067,25.98205206454962,-0.7812017010304954,-0.24471007800078537
512.8000000000068,26.02780457822166,-0.7905232175299143,-0.2447100780240099
514.2000000000068,26.072525277341903,-0.8007572992503262,-0.24471006774138093
515.6000000000067,26.11752333889477,-0.8097942611005944,-0.2447064265454335
517.0000000000068,26.162483956318233,-0.8215118371817599,-0.2460732036458113
518.4000000000068,26.207387622323964,-0.8269997886602991,-0.24602943641073072
519.8000000000068,26.25253803075716,-0.8310414034294787,-0.24743888844519102
521.2000000000069,26.297924371097757,-0.8371179979287917,-0.24735018656172203
522.6000000000068,26.342830828636234,-0.8413365025662887,-0.24733041436509762
524.0000000000068,26.387632840814913,-0.8416365442467366,-0.24668494072637026
525.4000000000069,26.43295348341457,-0.8440377674290611,-0.2480941303066726
526.8000000000069,26.47763693277745,-0.844130534093916,-0.2480003091388019
528.2000000000069,26.522814588440795,-0.8458201344124168,-0.2485290957221009
529.600000000007,26.56732451887335,-0.8464577160291588,-0.24898940192251118
531.0000000000069,26.613178641097573,-0.8459941657069228,-0.24899048104215193
532.4000000000069,26.658565823174875,-0.8472971338999139,-0.24928178673080748
533.800000000007,26.70368589149347,-0.8435007200704793,-0.24932018259378275
535.2000000000071,26.748732601338666,-0.8426293816645543,-0.24932056347542542
536.6000000000071,26.79439612405311,-0.8394516170380838,-0.2503257350880874
538.000000000007,26.839416015736635,-0.8353464063398168,-0.25015653607458654
539.4000000000071,26.884757009139115,-0.8325007189930759,-0.24997697957958476
540.8000000000071,26.929792664882704,-0.8307822909312067,-0.2512932964975607
542.2000000000071,26.975575952174562,-0.8295551752127912,-0.25130118559807224
543.6000000000072,27.020869657426196,-0.8295379311554933,-0.2520209175897232
545.0000000000072,27.06621214674698,-0.8252663769436891,-0.25260936544541224
546.4000000000071,27.11169415328693,-0.8228821451136527,-0.25261014695581707
547.8000000000072,27.15729740428427,-0.8238726304757965,-0.25261014600379594
549.2000000000072,27.20243184410752,-0.824689010468726,-0.2526101460267691
550.6000000000072,27.247929528452854,-0.826384557011553,-0.2526101548295894
552.0000000000073,27.293644419970157,-0.8265125817771757,-0.25260451325462174
553.4000000000073,27.33897640698591,-0.8309861510201356,-0.25392507194300284
554.8000000000073,27.38444955902214,-0.8293478085908486,-0.2539300769578716
556.2000000000073,27.430132644862407,-0.828050094188896,-0.2539276266004782
557.6000000000073,27.475419690419542,-0.8270309235662505,-0.25492701268196827
559.0000000000074,27.52162630521065,-0.830094004106588,-0.2549042803354089
560.4000000000074,27.56694966945585,-0.8318051903064386,-0.25393214819497745
561.8000000000075,27.612883084893024,-0.8319261808374584,-0.25393576579935173
563.2000000000074,27.658560511017182,-0.8376770551175926,-0.2542575005491998
564.6000000000074,27.70437390361471,-0.8395102729117675,-0.25426009342251055
566.0000000000075,27.749867762375704,-0.8447351465524373,-0.2542600876450356
567.4000000000075,27.79544632277427,-0.8487602668627733,-0.25426207868379125
568.8000000000075,27.84126295599408,-0.8587060486203172,-0.25394010055395144
570.2000000000075,27.887181354473093,-0.864904292597596,-0.25393735110235394
571.6000000000075,27.932863501106272,-0.8767860379171105,-0.2527382305756851
573.0000000000075,27.97947937198543,-0.9529892057046668,-0.25402751483567476
574.4000000000076,28.025122374845232,-0.9670836521216435,-0.2552501564580192
575.8000000000076,28.070445108991905,-0.923107283927454,-0.2552493077358
577.2000000000077,28.116090561870937,-0.8961824028731622,-0.2565181538242358
578.6000000000076,28.161572121802372,-0.8771270741462336,-0.2565600904626102
580.0000000000076,28.207212048213734,-0.8670200076209339,-0.2565600641097867
581.4000000000077,28.25284500290719,-0.8629396156734899,-0.25656005508551827
582.8000000000077,28.298622907822573,-0.8617403087924923,-0.256562570686488
584.2000000000078,28.34381900933127,-0.8617958291483484,-0.25525205248571003
585.6000000000078,28.390505554185875,-0.8607308482012034,-0.2552400275333242
587.0000000000077,28.436003596941205,-0.8673347340628244,-0.25524006398616894
588.4000000000078,28.48182367716017,-0.8684810180715642,-0.2552400668412771
589.8000000000078,28.527570268962315,-0.8696053018194463,-0.25524158455599233
591.2000000000078,28.57340081022801,-0.8732952580625142,-0.25654739506513957
592.6000000000079,28.61970593194382,-0.8781302499311893,-0.2572271149358749
594.0000000000078,28.665830327788818,-0.8822203809620556,-0.25852925880288113
595.4000000000078,28.711381213027817,-0.8842372831808812,-0.2571906873182028
596.8000000000079,28.75754376271246,-0.8896426385099051,-0.25722392489231627
598.2000000000079,28.803308658533904,-0.8894410778032574,-0.2585443426781988
599.600000000008,28.849220655028205,-0.8928169580043518,-0.2585398191854056
601.000000000008,28.895346754700515,-0.8961489454141519,-0.25853981631364276
602.4000000000079,28.941251988013562,-0.9021535801934032,-0.25853975886078784
603.800000000008,28.987390323004142,-0.9036080963443803,-0.2584973696575661
605.200000000008,29.03343652267639,-0.9054889392644889,-0.2598638477658626
606.6000000000081,29.079191311667458,-0.9120009537268211,-0.2598598786759556
608.0000000000081,29.125268191803965,-0.9158361041490252,-0.26014235343461145
609.400000000008,29.171666732175698,-0.9195775854078571,-0.2612116085520202
610.8000000000081,29.21767924356896,-0.9225739204256462,-0.25986177784583475
612.2000000000081,29.263741024814834,-0.9239982532853561,-0.2608273013955129
613.6000000000081,29.310000667736674,-0.9302401418318614,-0.2611801499664663
615.0000000000082,29.356376163799034,-0.9312716483390896,-0.26117892144924904
616.4000000000082,29.402032501968264,-0.9356873212674799,-0.2611622229054338
617.8000000000081,29.448246050218746,-0.9380606409204144,-0.26118006877810673
619.2000000000082,29.4943197528416,-0.9386344858094889,-0.26117834955256436
620.6000000000082,29.540881565702424,-0.943610519910051,-0.2622060763454921
622.0000000000083,29.587000619039017,-0.9474995079458363,-0.2621659154472078
623.4000000000083,29.63346106584541,-0.9509454635989745,-0.2635374964874484
624.8000000000083,29.679259522029476,-0.9556270081151501,-0.2624665563288273
626.2000000000083,29.72544677786928,-0.9593446784504528,-0.2634208360063539
627.6000000000083,29.77212049947952,-0.9614145640824918,-0.2634799280171083
629.0000000000084,29.81810459536031,-0.967471217884797,-0.2634769256490217
630.4000000000084,29.86438995860608,-0.9704255049376224,-0.26485068696994674
631.8000000000084,29.910342784628863,-0.9793442726974055,-0.2648000531396506
633.2000000000085,29.957235814438132,-0.985443457879894,-0.26480006417616186
634.6000000000084,30.003416205562544,-0.9908647573748064,-0.26480017778123655
636.0000000000084,30.04993155447315,-0.9978114544520409,-0.263913945056486
637.4000000000085,30.09609891304327,-1.0024291702072168,-0.2638097581387533
638.8000000000085,30.14225439760307,-1.0086601082814626,-0.26380983433262273
640.2000000000085,30.188655231242638,-1.015810020131403,-0.2637521392831479
641.6000000000085,30.23513042459888,-1.0240292200311174,-0.26513217432208114
643.0000000000085,30.28131375441553,-1.030311686334888,-0.2664240742148869
644.4000000000086,30.327788437336032,-1.040265387777653,-0.2664416401264824
645.8000000000086,30.374122743038203,-1.0495222237203505,-0.26766944268328885
647.2000000000086,30.42064782773441,-1.0600552471670321,-0.26775984872812897
648.6000000000087,30.467256843037404,-1.0711431138468597,-0.2679140030711129
650.0000000000086,30.51366176872614,-1.0848869631033051,-0.26907816264680884
651.4000000000087,30.56020612840082,-1.0960041566963048,-0.2690801327674648
652.8000000000087,30.606648075752496,-1.1097352252376587,-0.2689452923159208
654.2000000000087,30.653458139535093,-1.125089443455099,-0.2700252389695099
655.6000000000088,30.70000065402865,-1.138750134597508,-0.2690783382413877
657.0000000000088,30.74647256539426,-1.1516827482197296,-0.2704230074327785
658.4000000000087,30.79281538677031,-1.1652685173456778,-0.2723826473372042
659.8000000000088,30.839528899727185,-1.1776820888975394,-0.27280911143294917
661.2000000000088,30.886251720266344,-1.1966113691298867,-0.2741817520998526
662.6000000000088,30.93284548274416,-1.2128705964245852,-0.2754418937020273
664.0000000000089,30.979208002416254,-1.2275046347967968,-0.2767609099663497
665.4000000000088,31.02593618439622,-1.2500189933062409,-0.27788535306023343
666.8000000000089,31.072842156114557,-1.265951527702968,-0.27831119844729724
668.2000000000089,31.119624902809363,-1.286989303117097,-0.2793997773334205
669.6000000000089,31.166055640207567,-1.3074506029663178,-0.27997717108456
671.000000000009,31.212684579607604,-1.3303600221595413,-0.2806335094868744
672.400000000009,31.25946649569003,-1.351404066930146,-0.28144777293717693
673.800000000009,31.306004464302188,-1.3747912309627324,-0.2821411444169102
675.200000000009,31.352866009531215,-1.4028271030300898,-0.28346618583299943
676.600000000009,31.39960080616434,-1.4282037800366403,-0.2848910328324843
678.0000000000091,31.445741981862344,-1.4509703987233011,-0.28620133294112904
679.4000000000091,31.493019168988173,-1.4826637850506348,-0.2874683833874525
680.800000000009,31.539832247431924,-1.5086655410856413,-0.289263658170821
682.2000000000091,31.58665115710854,-1.5375784491341227,-0.29196921669227205
683.6000000000091,31.633411289305357,-1.5707758394117266,-0.2932488230636241
685.0000000000091,31.680134082452497,-1.6031680699834399,-0.29588382041919736
686.4000000000092,31.727146721175313,-1.6367182488318168,-0.2984714786966274
687.8000000000092,31.773776722390696,-1.6714864599835757,-0.300107895922205
689.2000000000093,31.820764845516297,-1.70577472007911,-0.3013628078792925
690.6000000000092,31.867739345712057,-1.7450206967718538,-0.3045962507173954
692.0000000000092,31.914697233685438,-1.7833779451715837,-0.3076721661584969
693.4000000000093,31.96132985169148,-1.822567391068251,-0.3096324119923919
694.8000000000093,32.00848159838325,-1.8679514328569162,-0.3127555881863566
696.2000000000094,32.05532860784383,-1.9092301077236307,-0.31588985981540274
697.6000000000093,32.1024651502367,-1.9545675639589726,-0.31967225402727273
699.0000000000093,32.14960780977024,-2.0025101568375083,-0.32327706150523916
700.4000000000094,32.19652677154093,-2.0505711512804146,-0.32532841635603615
701.8000000000094,32.24375414605772,-2.1029598630142115,-0.3289330203360463
703.2000000000094,32.290938948341605,-2.1528504024403894,-0.3323881952927459
704.6000000000095,32.33788145641085,-2.2056192775347805,-0.3372602972391525
706.0000000000094,32.38492997622306,-2.2603168223373538,-0.34085075187161085
707.4000000000094,32.432143599474635,-2.318336590994335,-0.3433552901031196
708.8000000000095,32.479487824143725,-2.3789706203005503,-0.3480915006451455
710.2000000000095,32.52651855778303,-2.4377831640386978,-0.3515252486521514
711.6000000000096,32.57372669343124,-2.4981349748365584,-0.35661218230359726
713.0000000000095,32.621076451802836,-2.5622116981116716,-0.3606556972343107
714.4000000000095,32.66840310245958,-2.6301101466982906,-0.36591624593235483
715.8000000000096,32.71570097877738,-2.696951542846778,-0.37056258650047846
717.2000000000096,32.763132874438405,-2.7677236682112314,-0.3752318820400071
718.6000000000097,32.80983697028397,-2.8376135802729543,-0.38114376566272323
720.0000000000097,32.857743317353865,-2.9139381236696043,-0.38798050495940783
721.4000000000096,32.90528237537858,-2.9910304921246706,-0.39457832950010774
722.8000000000097,32.95276907885638,-3.0729976221171764,-0.3999531474550757
724.2000000000097,33.00026617752639,-3.1535700086123946,-0.4066915515542795
725.6000000000097,33.047725209810906,-3.2364665119597,-0.4144509666323821
727.0000000000098,33.095354872261915,-3.324340681170269,-0.42240723313033124
728.4000000000098,33.14278890110705,-3.412702836939677,-0.42755577810252143
729.8000000000097,33.19037197991707,-3.5021260590428853,-0.435793362875057
731.2000000000098,33.23838138703484,-3.5949358699142127,-0.4446554166513863
732.6000000000098,33.28594019825808,-3.6898788911831346,-0.45094911700627494
734.0000000000099,33.333839254940514,-3.789292883086619,-0.46174519679073533
735.4000000000099,33.38169738872685,-3.8907330964460423,-0.4699749063145444
736.8000000000098,33.42910196441929,-3.9919275773646783,-0.4782138055888199
738.2000000000099,33.47720559682991,-4.094063668854483,-0.4882060563052768
739.6000000000099,33.524915922501734,-4.20305470194191,-0.4980424223972988
741.00000000001,33.57282034688498,-4.312530270935973,-0.5084878764383669
742.40000000001,33.62068234453374,-4.42478117948082,-0.5205321154095706
743.80000000001,33.66870875353262,-4.539470494625128,-0.530167148816862
745.20000000001,33.71679443556643,-4.657661547862199,-0.5428807650755387
746.60000000001,33.76454172378017,-4.7779575853084975,-0.5533230672620619
748.00000000001,33.81254464856684,-4.898608829173937,-0.5643900701891602
749.4000000000101,33.86009974055954,-5.025386389749806,-0.5778255357842377
750.8000000000101,33.90881978180318,-5.152349586063939,-0.5917161925792098
752.20000000001,33.9569346731222,-5.280849406162035,-0.6049627715490558
753.6000000000101,34.004964598239646,-5.411559026757947,-0.6181296411840895
755.0000000000101,34.05258480085013,-5.542133257753081,-0.633117374131448
756.4000000000102,34.10136378196968,-5.678048721951537,-0.6452050492650079
757.8000000000102,34.149451776875175,-5.812747307123564,-0.6607107098804281
759.2000000000102,34.19776086895007,-5.951487884429037,-0.6757844956830494
760.6000000000103,34.245871152767975,-6.089632043028651,-0.6909463228886015
762.0000000000102,34.294217791099825,-6.229073241893482,-0.7073948300910033
763.4000000000103,34.34238194435705,-6.368249270877779,-0.7226280760334496
764.8000000000103,34.39058013275243,-6.50846100778724,-0.7397157634115135
766.2000000000103,34.438857009813596,-6.645717586056565,-0.7578294679999584
767.6000000000104,34.48700732084438,-6.78125159897389,-0.7747335300455949
769.0000000000103,34.53488674550695,-6.920548644787278,-0.7949128135618824
770.4000000000103,34.58320613024291,-7.056945308959404,-0.8150052192385226
771.8000000000104,34.631731153277244,-7.192163865570035,-0.834994898648127
773.2000000000104,34.6801007351969,-7.319426848614138,-0.8534921741743049
774.6000000000104,34.727817997386374,-7.443042430582194,-0.8731598480163192
776.0000000000105,34.77603767232528,-7.562330567706603,-0.8943362472449046
777.4000000000104,34.8243051636514,-7.678591346138018,-0.9149239061957162
778.8000000000105,34.872175810676666,-7.77912854195572,-0.9368511256066929
780.2000000000105,34.91993119374399,-7.874309991145214,-0.9575049150855701
781.6000000000105,34.96790893522424,-7.953967932395333,-0.9779465102771394
783.0000000000106,35.01550715591289,-8.016674871632906,-1.000100566612704
784.4000000000106,35.06274720941394,-8.057925332186967,-1.0234758494285705
785.8000000000106,35.110534451130846,-8.071305512773849,-1.0473556163076947
787.2000000000106,35.15699745751569,-8.052607320512642,-1.0683543473672144
788.6000000000106,35.20373186429223,-7.994281713843169,-1.0903465122080336
790.0000000000107,35.25022905532048,-7.891597608326618,-1.1113313475762396
791.4000000000107,35.29611546269579,-7.7344864271969955,-1.1321442563118436
792.8000000000106,35.34133382054562,-7.514493513883947,-1.153593869891802
794.2000000000107,35.3863433123916,-7.226141055402174,-1.1742976270386145
795.6000000000107,35.43074906593591,-6.862314350726927,-1.1910028534041213
797.0000000000107,35.474006982936395,-6.413071187386889,-1.2071230332628264
798.4000000000108,35.51701247773355,-5.869769783587879,-1.2222939885209172
799.8000000000108,35.559397238391945,-5.244940695373609,-1.2361200433980857
801.2000000000108,35.60129031417075,-4.573225756490833,-1.2477280553862307
802.6000000000108,35.642999457830186,-3.897473531010426,-1.257158708157652
804.0000000000108,35.68528320498481,-3.2599365449319766,-1.266097660386737
805.4000000000109,35.72800866545291,-2.7067797758935583,-1.270317496543163
806.8000000000109,35.77115364195491,-2.2608151470563382,-1.2748580385758892
808.200000000011,35.81588120115099,-1.9067206176928153,-1.2763374163295094
809.6000000000109,35.860530959799824,-1.6505480499374294,-1.2782396154120432
811.0000000000109,35.90631157392947,-1.4650859603027977,-1.2815895578184673
812.400000000011,35.95243113328755,-1.3431555650187406,-1.281503732887916
813.800000000011,35.9986079021722,-1.2602019486172011,-1.2828126616118536
815.200000000011,36.04542573906536,-1.2002127333787402,-1.2842216551256498
816.600000000011,36.092358836804394,-1.1639644943337444,-1.2841300058840077
818.000000000011,36.13946328719551,-1.1381006509152594,-1.284418017298909
819.400000000011,36.186455752410055,-1.1261065832423456,-1.2854485150794397
820.8000000000111,36.233491727377256,-1.1184695368343442,-1.2854405568571
822.2000000000111,36.28077685272093,-1.1154067665844667,-1.2841410379363292
823.6000000000112,36.32790554720486,-1.112703439251701,-1.284139841374024
825.0000000000111,36.3749538595423,-1.116386891114522,-1.2841395876327204
826.4000000000111,36.422357686851996,-1.1166003786719103,-1.2842352568830013
827.8000000000112,36.4696910776373,-1.1184755263979131,-1.2848890286400465
829.2000000000112,36.51713195877099,-1.120075453371139,-1.2862634384551699
830.6000000000113,36.56424668133685,-1.1250864577568425,-1.2868807921116825
832.0000000000113,36.61166948781161,-1.1322599156651159,-1.2875921945341537
833.4000000000112,36.65858239799284,-1.1410560402656413,-1.2861930779542834
834.8000000000113,36.70628379865641,-1.147123820904095,-1.2862201927464771
836.2000000000113,36.753709637104755,-1.1509519897107954,-1.2862200898337943
837.6000000000113,36.80120658094752,-1.1537333824715899,-1.2862200900000782
839.0000000000114,36.84858487219046,-1.154509920458614,-1.2862200900000036
840.4000000000113,36.896147407435215,-1.1523569120017627,-1.2862200899967848
841.8000000000113,36.94301056537383,-1.1501392676987288,-1.2862200912513444
843.2000000000114,36.99049689217916,-1.1542174673341945,-1.2862200781316742
844.6000000000114,37.03800191021169,-1.1537420966622758,-1.284848525140787
846.0000000000115,37.08525630383865,-1.1567280964324562,-1.2855424146754202
847.4000000000115,37.13192040754192,-1.1581963431510658,-1.2855984978114043
848.8000000000114,37.18000034052511,-1.1627000918946542,-1.2828201200490117
850.2000000000115,37.227326133021776,-1.1603376651220711,-1.284493514166098
851.6000000000115,37.27456342754734,-1.169048097628445,-1.2850835320862983
853.0000000000116,37.322357814708965,-1.1703238952058772,-1.2864485630239373
854.4000000000116,37.369306469970724,-1.1741440196321788,-1.286450115735879
855.8000000000116,37.416815922354964,-1.1754370968768184,-1.2864521193220435
857.2000000000116,37.46470918848882,-1.1727678396103598,-1.2876361022757643
858.6000000000116,37.51138460158358,-1.1764756919336574,-1.2864416456679892
860.0000000000116,37.55979960495705,-1.1796062463644137,-1.2864399369744164
861.4000000000117,37.606861607063266,-1.1825590977010707,-1.2864394672131856
862.8000000000117,37.654517955433185,-1.1881036011313442,-1.2878505529734725
864.2000000000116,37.70213380176833,-1.1920225136107931,-1.2878000187597443
865.6000000000117,37.74953393580228,-1.1921524205308027,-1.2864401801000307
867.0000000000117,37.79712858536377,-1.196928793036689,-1.286435059494563
868.4000000000118,37.84466921521358,-1.1948901180625697,-1.2870569327092944
869.8000000000118,37.89239606459692,-1.200540247707265,-1.2877622777341875
871.2000000000118,37.94006836084599,-1.1976119371099097,-1.2884234845372613
872.6000000000118,37.98723796333193,-1.2000540084573166,-1.2874322840118673
874.0000000000118,38.03497850834868,-1.2036647211045788,-1.2873594923672549
875.4000000000119,38.082665517774124,-1.2044628991098838,-1.2880887136489685
876.8000000000119,38.13019920832885,-1.20283975581565,-1.2880904934391775
878.2000000000119,38.17749009646695,-1.2026356415725956,-1.287758682543409
879.600000000012,38.224828885900465,-1.2087617554238128,-1.28908127016253
881.0000000000119,38.27251908568483,-1.2073273376548443,-1.287753511820227
882.4000000000119,38.3201742259809,-1.2073727235185683,-1.2874122834886879
883.800000000012,38.367682721677006,-1.2072765975818482,-1.2852294757228027
885.200000000012,38.41523368319301,-1.2117094817820067,-1.2868116876670288
886.600000000012,38.462979500484664,-1.2145897303952968,-1.2881989518410926
888.000000000012,38.5104084528839,-1.215413494002263,-1.287875739147803
889.400000000012,38.55788707003039,-1.2197928674436076,-1.2885309561250042
890.8000000000121,38.605433941350825,-1.2262070437766894,-1.2885301475790096
892.000000000012,38.646293880634936,-1.2311641014164263,-1.2885301499897164