File: 01_Data/EIFS_Coating/STA/N2/30K_min/EIFS_Coating_STA_N2_30KData_230914_R3.csv
##Temp./Â°C,Time/min,DSC/(mW/mg),Mass loss/mg
41.0,10.537941958868915,-2.2203244656823706,0.01664041736550903
42.40000000000002,10.77192081286495,-2.101257811939963,0.017639270337999946
43.80000000000004,10.915034264252476,-2.010710737739356,0.017791760082273456
45.20000000000006,11.02401071025154,-1.9333848899162485,0.016186108582080472
46.60000000000008,11.117250989496384,-1.8668397860417036,0.015947777479237146
48.0000000000001,11.203081065012578,-1.800862044756972,0.014282935356359161
49.40000000000012,11.281443253244788,-1.7417742657966684,0.01627040746907582
50.80000000000014,11.35340559944466,-1.6868079522472417,0.015810018731118092
52.20000000000016,11.42225577831091,-1.6352174052898132,0.015444469920693038
53.60000000000018,11.487429304733363,-1.588888818664587,0.016113805429359473
55.0000000000002,11.550475858058066,-1.5424157868254242,0.016187107477339424
56.40000000000022,11.610698724205738,-1.49763412880299,0.017309895261671038
57.80000000000024,11.669498833128724,-1.456187939367076,0.015320124305471694
59.20000000000026,11.726809811185353,-1.4193936579914201,0.015366344383125785
60.60000000000028,11.783296186168705,-1.3830316032903887,0.015220733358368044
62.0000000000003,11.838077163251505,-1.3505359314155372,0.015617479877248819
63.40000000000032,11.89080552961899,-1.318500581363,0.015459032988128563
64.80000000000034,11.945386630069532,-1.2894768026351586,0.014221398430933618
66.20000000000036,11.998182857379973,-1.260501423595998,0.014379744298422814
67.60000000000038,12.050102920144138,-1.2360204965538308,0.014745501691533214
69.0000000000004,12.101973949748803,-1.2103339701169862,0.01500135070542541
70.40000000000042,12.153044343813349,-1.1849307758477534,0.013206406053448916
71.80000000000044,12.20352208450854,-1.1623199906405544,0.011802505876657321
73.20000000000046,12.254184177731897,-1.1405740392185888,0.013568084295486393
74.60000000000048,12.303943734701278,-1.1213694882136414,0.01240350926110878
76.0000000000005,12.35306148195333,-1.1023078036052003,0.012292649747049467
77.40000000000052,12.403435858405082,-1.0844487253808595,0.011328958804333489
78.80000000000054,12.452463080988784,-1.067765759299731,0.010687810843537981
80.20000000000056,12.501972284251396,-1.0536966920006698,0.009682243609278274
81.60000000000058,12.55048392307249,-1.0384063097150784,0.009507836070490328
83.0000000000006,12.598857050076191,-1.0251601113933422,0.010881610550739218
84.40000000000062,12.64759228214563,-1.0111635828559802,0.0100785046812506
85.80000000000064,12.695651634769254,-0.9971709274762126,0.009791885362440134
87.20000000000066,12.743607613501055,-0.9838396614821552,0.009557458306758804
88.60000000000068,12.791192202504188,-0.968696558841823,0.00826789529334171
90.0000000000007,12.839373920568516,-0.95253452024433,0.006919372632212095
91.40000000000072,12.886234175086617,-0.9342490589448105,0.006855787074147912
92.80000000000074,12.933881192574674,-0.9130197156623783,0.006927831497093528
94.20000000000076,12.980485807470888,-0.8867652260932063,0.005615621848185981
95.60000000000078,13.027012128367367,-0.8546712940107397,0.005609372582580541
97.0000000000008,13.073265203608692,-0.820126050978182,0.004318567611992563
98.40000000000082,13.119632704239475,-0.7842775516517888,0.004289979425093904
99.80000000000084,13.166009027102962,-0.749509622405076,0.004170298689359697
101.20000000000086,13.212435699467193,-0.7173269557535451,0.0042964971040371225
102.60000000000088,13.258706647704363,-0.6878379315147714,0.0029619440380503903
104.0000000000009,13.304940951659955,-0.6591050669142504,0.0026432058524283875
105.40000000000092,13.350956914063662,-0.6319330950924892,0.0016599922430513558
106.80000000000094,13.397422753186001,-0.6057261115587489,0.0029625384328282323
108.20000000000095,13.4435953398304,-0.5813478395531646,0.0029603112923481945
109.60000000000097,13.48864541434522,-0.5588578314995131,0.0029520480341806987
111.000000000001,13.535732071094268,-0.5353857545710361,0.0026787491076154524
112.40000000000101,13.582027961599952,-0.5148277259878685,0.0029853705149234244
113.80000000000103,13.627930921131092,-0.4923766970008777,0.004291290679804938
115.20000000000105,13.673918845360062,-0.47468931518933677,0.0043704319581188145
116.60000000000107,13.719031654137614,-0.455585049357707,0.0029699841454027265
118.0000000000011,13.765790064222676,-0.4384887806158289,0.0029698464046488127
119.40000000000111,13.812101582793668,-0.4196593212697277,0.002980983238104251
120.80000000000113,13.857441496543995,-0.4032925425535108,0.0016595730355906113
122.20000000000115,13.90375470802126,-0.3850104252106133,0.0016498958401989228
123.60000000000117,13.948875376728054,-0.36416177824015117,0.0016499143765935642
125.0000000000012,13.993499849133746,-0.34540404064634334,0.0016502411473426903
126.40000000000121,14.039303306914114,-0.32209528504831797,0.0017076615605073897
127.80000000000123,14.085393425542511,-0.3030521202186332,0.00032936599707067415
129.20000000000124,14.130487833866574,-0.2848787824498623,0.0003302651646972521
130.60000000000127,14.175813545480148,-0.26400913975112933,0.0013346643453937546
132.0000000000013,14.220941611743704,-0.24430834551197997,0.001649859103710405
133.4000000000013,14.266113653718484,-0.22398539384921137,0.0016508167649780248
134.80000000000132,14.310513943740855,-0.20668790250044258,0.0024234688623927525
136.20000000000135,14.355699399353172,-0.18600824651940526,0.002969161435826706
137.6000000000014,14.400092601938878,-0.16878334412609614,0.0029698161784299515
139.0000000000014,14.444790709280241,-0.14966160247305058,0.002970141573825913
140.4000000000014,14.48945057947573,-0.13215991555502205,0.003055501077374956
141.80000000000143,14.533948317926395,-0.11511514268859636,0.0016494070081218837
143.20000000000147,14.578493591424925,-0.09562090560194936,0.001649813795384425
144.60000000000147,14.623059192334079,-0.07965955544335192,0.001649825779725056
146.00000000000148,14.66707094364275,-0.06141120990153379,0.0016519656425799667
147.4000000000015,14.711459057914364,-0.04462878560981074,0.0013285823084991932
148.80000000000155,14.755156751283556,-0.027757662520910928,0.0013202124908779922
150.20000000000155,14.799262998481044,-0.012714010736443267,0.0013293953173558748
151.60000000000156,14.843760269196343,0.006562647744352696,0.0016516092897944645
153.0000000000016,14.887282971664387,0.02140368365828822,0.0016501586552006842
154.40000000000163,14.93099650804314,0.03741043839830322,0.0016501463819231788
155.80000000000163,14.975147996547808,0.05360093038098963,0.0016498592919669264
157.20000000000164,15.018984300187274,0.07118503144984549,0.0014691621632145768
158.60000000000167,15.06260674639832,0.08677630828060781,0.0023166493430819557
160.0000000000017,15.10636876034376,0.10164162374886429,0.0023133386591629446
161.4000000000017,15.150167829635635,0.11774585600904691,0.0009750945349464857
162.80000000000172,15.193402722839506,0.13295624631145345,0.0009999982811574881
164.20000000000175,15.237408525472398,0.14887833250597177,0.0012029545963700983
165.60000000000178,15.280781797380344,0.16490756732169998,0.0023089037221541986
167.0000000000018,15.32428256325656,0.17925894759494063,0.002192416388934859
168.4000000000018,15.367783566196227,0.1977076426814975,0.0016524371244335256
169.80000000000183,15.411480740337014,0.2140507718080716,0.0009990668916923795
171.20000000000186,15.45450213493875,0.22774848630030484,-6.261375631311239e-07
172.60000000000187,15.497885439493986,0.24276441339675997,1.2061622278736195e-07
174.00000000000188,15.541440958501196,0.2576687900161835,1.249952958914946e-07
175.4000000000019,15.58448301493848,0.27259850465481006,1.250000334351853e-07
176.80000000000194,15.628124051298165,0.2852173337045784,1.2500000146076218e-07
178.20000000000195,15.67149396939998,0.30073457569043544,1.2499999968440534e-07
179.60000000000196,15.714205891403175,0.3151429783636574,1.2499999968440534e-07
181.000000000002,15.757553849126053,0.3282855684342271,1.2500015866834246e-07
182.40000000000202,15.800307246939353,0.3439947447814936,1.250259442642232e-07
183.80000000000203,15.84340917805737,0.3554052436155153,1.2087156875395522e-07
185.20000000000203,15.886151602037252,0.36956980150285884,-3.3016824838583148e-06
186.60000000000207,15.928934351803838,0.38277082297661036,0.0012994130786312397
188.0000000000021,15.97189980857722,0.39686893336791984,0.0013049314618056584
189.4000000000021,16.014857760072427,0.4083046279412634,0.0026339547109905936
190.80000000000211,16.05762349898578,0.4212268337147554,0.002630176860858313
192.20000000000215,16.100334036614314,0.4341635621922926,0.002635957044202719
193.60000000000218,16.1426789499516,0.44692318410126364,0.0012395093330415108
195.0000000000022,16.185447786475727,0.45886851877355006,0.0006657676997932072
196.4000000000022,16.228122674067514,0.47231391033030234,0.0013185665284858317
197.80000000000223,16.270914272482194,0.48294251062539895,0.0019827103833289783
199.20000000000226,16.31291797753512,0.49718986943852267,0.001980146397539073
200.60000000000227,16.355904143070802,0.507395165153003,0.001980145961577584
202.00000000000227,16.398615553606504,0.5203651303554105,0.0019801458512773706
203.4000000000023,16.441124296642673,0.5304857263252646,0.001980286912136364
204.80000000000234,16.483586602984918,0.5425953355398916,0.001186137575113655
206.20000000000235,16.52623655233487,0.553650950381736,0.0006609821405119121
207.60000000000235,16.568543862444827,0.5634725775164308,0.00066359978837216
209.0000000000024,16.611104242266848,0.5765266517047603,-0.0002886728577138342
210.40000000000242,16.65370232343313,0.5876515584110055,-0.0006475394302913884
211.80000000000243,16.696279277476307,0.5977233065367894,-0.000650319676358535
213.20000000000243,16.73862708190316,0.6088043464283387,-0.0006502044283882569
214.60000000000247,16.7808117900295,0.6197857999901485,-0.0006581932677587332
216.0000000000025,16.823347491018218,0.6290866208220703,-0.0009250939398564029
217.4000000000025,16.865446126153895,0.6381320837912651,-0.0029530979140215408
218.8000000000025,16.9076728135742,0.64811356525468,-0.0030305069590639278
220.20000000000255,16.950755447289833,0.658082443737734,-0.0015238235137529088
221.60000000000258,16.993102713168934,0.6680586707545981,-0.00032045202102537473
223.0000000000026,17.035439282487136,0.6773252519085475,0.00044819627903258663
224.4000000000026,17.077419070424547,0.6848722480161968,-0.00033010785441067725
225.80000000000263,17.11973108633623,0.6975198793501434,-0.00042827516814369915
227.20000000000266,17.162286333344028,0.7051912687226034,0.0009880983688264067
228.60000000000267,17.204358437579007,0.7137456477739641,1.4245367649934337e-05
230.00000000000267,17.246775146017576,0.723453640840993,-0.0003298347965756676
231.4000000000027,17.28914010218912,0.7313447605873528,-0.00033006180514849603
232.80000000000274,17.331222016803117,0.7409100067163481,-0.0003299496880941888
234.20000000000275,17.37359076185142,0.7486218254113703,-0.00028221264552463765
235.60000000000275,17.41571654741088,0.7568344082974965,-0.0016408136628216496
237.00000000000279,17.457990649229245,0.7658092176111492,-0.0008938749769589194
238.40000000000282,17.50030015649225,0.7741178611027915,-0.0003314495018811314
239.80000000000283,17.542734058813554,0.7810060963974494,-0.0003311710207993812
241.20000000000283,17.584873563267497,0.7892655752684128,-0.0008601253010054322
242.60000000000286,17.627037366976786,0.7981430711711883,-0.0016627983204982044
244.0000000000029,17.66943734018813,0.8045860208436841,-0.0030646229929160995
245.4000000000029,17.711642774932333,0.8124723612065703,-0.0043894342495889305
246.8000000000029,17.75374490124812,0.8194564364819741,-0.004438412432707928
248.20000000000294,17.79583580020562,0.8266042479118562,-0.0030788702095287945
249.60000000000298,17.838176620687857,0.8330725619734769,-0.00306990011633701
251.00000000000298,17.880223020545976,0.8402852151896749,-0.0030699481663791772
252.400000000003,17.922629061162933,0.8471446289547324,-0.003110648033038288
253.80000000000302,17.964812166461112,0.85332858275894,-0.0020838165662357966
255.20000000000306,18.006943601885553,0.8604958859816261,-0.0006519114843062113
256.6000000000031,18.048896649572697,0.8656472243996989,-0.0007595827559239154
258.00000000000307,18.09140100786969,0.8729220911942575,-0.0007600671146281712
259.4000000000031,18.13356648414896,0.8783096566594785,-0.0007614598552185825
260.80000000000314,18.17559159954528,0.8848790484601041,-0.0013817690153459239
262.2000000000031,18.218017045898563,0.890779140468616,-0.0007683376343994297
263.60000000000315,18.260164029816064,0.8952761408110188,0.0002276831325502826
265.0000000000032,18.301947445112233,0.9009302140387971,0.00021997069359258603
266.4000000000032,18.344803303406053,0.9064923899057484,0.00022653446274745193
267.80000000000325,18.386844765646565,0.9108908051274609,-0.0010836250715753337
269.20000000000323,18.429258113839495,0.9152367575032125,-0.0011279269370865208
270.60000000000326,18.47128097769834,0.9201711414899549,-0.0004424735906178867
272.0000000000033,18.513381707162342,0.9238913770999727,-0.00044004401955444195
273.4000000000033,18.555734381116483,0.9261779782367934,-0.00044005413588976694
274.8000000000033,18.597780308348366,0.9306488168721907,-0.00044449566972382115
276.20000000000334,18.640323823627245,0.9368656277400558,0.00026198118744780174
277.6000000000034,18.682211969399706,0.938415442711977,-0.0011460351073360187
279.0000000000034,18.72469009698535,0.9408596863743004,-0.0011001780328134814
280.4000000000034,18.766546230408846,0.943994243017508,-0.00110590567028801
281.8000000000034,18.809050652204437,0.94633048682175,0.00020345948631472766
283.20000000000346,18.851381600924917,0.9506356855354111,-0.0012983370706551867
284.60000000000343,18.893797250724877,0.9548044457581838,-0.0025230555312090175
286.00000000000347,18.936208606044882,0.9562859509689384,-0.0035926365485332568
287.4000000000035,18.978184072022245,0.9601533750435584,-0.003846743288732135
288.80000000000354,19.020754398314956,0.9613247153816266,-0.005149819201027306
290.20000000000357,19.062731345200426,0.9634318504403138,-0.005159993135928076
291.60000000000355,19.10547654111031,0.9666254320024303,-0.005150449457984152
293.0000000000036,19.147649683551816,0.9674907231860925,-0.00379682026562822
294.4000000000036,19.18993324289876,0.9685551597588906,-0.0037903173801323575
295.8000000000036,19.232269070302756,0.9688134916945138,-0.002504126526606143
297.2000000000036,19.27472742423032,0.971736619684296,-0.0011906132967416383
298.60000000000366,19.31727398985814,0.9737949767186984,-0.0003782420692637345
300.0000000000037,19.359609687578082,0.9739315183252734,0.0014431151953289145
301.40000000000373,19.401883145165787,0.9731575994212744,0.001429991623911775
302.8000000000037,19.444366075314935,0.9739272610857663,0.0014298473474392281
304.20000000000374,19.486505486889452,0.9740666556482074,0.002534600101624207
305.6000000000038,19.529231817244114,0.9756426170740925,0.00340584800192012
307.00000000000375,19.571697715041065,0.9752737762897885,0.0054383154939481315
308.4000000000038,19.614060180800184,0.9758537570147998,0.00560007468299073
309.8000000000038,19.656683989226057,0.9767123328439746,0.005614502653380704
311.20000000000385,19.698713372473676,0.9762490154041717,0.005478721630633565
312.6000000000039,19.741628933995315,0.9753108079732284,0.004235722728857638
314.00000000000387,19.783868134580842,0.9757910465994165,0.003282323158168232
315.4000000000039,19.82633663759434,0.9767746987951599,0.001785351646165445
316.80000000000393,19.868871370485465,0.9780290081213809,0.00013497342335622164
318.2000000000039,19.911370197052676,0.977200921019746,-0.0006411538964830044
319.60000000000394,19.954076941771724,0.9764923781976047,-0.001862683243288643
321.000000000004,19.99658161078745,0.9766652286866598,-0.0015611132747812562
322.400000000004,20.03905043553465,0.9763650176457712,-0.0015297893434169652
323.80000000000405,20.081832812734042,0.977147348946283,-0.001526419089486808
325.200000000004,20.124331589899825,0.9742756639631492,-0.002810216489168127
326.60000000000406,20.1669601875456,0.9734427314227208,-0.0023463430322774315
328.0000000000041,20.2098531593761,0.9739906461031576,-0.0028575574535478765
329.40000000000407,20.2521581646768,0.9716568814044584,-0.004030833610377371
330.8000000000041,20.29501126655076,0.9697897555681886,-0.0041698711213138395
332.20000000000414,20.33781358701968,0.9693789750178344,-0.004169988829521465
333.6000000000042,20.380481495694493,0.968179885126886,-0.004169983630699647
335.0000000000042,20.422855491255365,0.9667100733948111,-0.004166774895870695
336.4000000000042,20.465653450948913,0.964764828448902,-0.005090644938036348
337.8000000000042,20.508522069238797,0.9616620372265411,-0.005150009031084757
339.20000000000425,20.551415202023012,0.96168113164298,-0.005148933891995888
340.60000000000423,20.59417156279821,0.9606619276486802,-0.005512232386916338
342.00000000000426,20.636780423529412,0.9593762722512037,-0.005481817088983654
343.4000000000043,20.6796614976671,0.958255489242863,-0.00459866086993177
344.80000000000433,20.72284427443606,0.9547633526086828,-0.0058272614655852095
346.20000000000437,20.76558553264572,0.9558499952392463,-0.00581172525314777
347.60000000000434,20.808568890616773,0.9555170744039094,-0.006815583623514421
349.0000000000044,20.85154038786803,0.9551392093486878,-0.00690858797621452
350.4000000000044,20.894792422637103,0.9544519063397715,-0.0077749459553979605
351.8000000000044,20.93750557763107,0.9530714888371629,-0.006803130570922633
353.2000000000044,20.980619821820483,0.9542892563478435,-0.008102551205591446
354.60000000000446,21.023597874382002,0.9536762739030572,-0.00814150255761703
356.0000000000045,21.066593153979866,0.9529612114059087,-0.009444858765692565
357.4000000000045,21.109799546240072,0.9526091904699575,-0.009439282776676272
358.8000000000045,21.152612908318467,0.9503978816916838,-0.010736096444494692
360.20000000000454,21.196056396467096,0.9501833508584304,-0.010892398395871972
361.60000000000457,21.239108890611817,0.9495032693103092,-0.012069963714568921
363.00000000000455,21.281928819276075,0.9476812350984994,-0.012679131828181589
364.4000000000046,21.32535488374764,0.9468732072188786,-0.013365332279297704
365.8000000000046,21.36874113545954,0.9457617503353145,-0.013688575787063506
367.20000000000465,21.411244081253265,0.943948502922676,-0.014250173544123612
368.6000000000047,21.454757778617296,0.9414517330927137,-0.015029856439188194
370.00000000000466,21.49857221195425,0.939079992218306,-0.01634796025086871
371.4000000000047,21.541886967970676,0.9372211188542887,-0.017227015369470244
372.80000000000473,21.58477436308228,0.9352501626471365,-0.01898822815071366
374.2000000000047,21.62839925424348,0.9290891546663083,-0.020055386783373486
375.60000000000474,21.671601135033068,0.925711002715269,-0.02019117026593431
377.0000000000048,21.715430797589963,0.9212360418885155,-0.021355172776367226
378.4000000000048,21.758552233300993,0.9163856951223761,-0.02272339930746803
379.80000000000484,21.80230755787935,0.9082474407474128,-0.02402671840000803
381.2000000000048,21.845584016875826,0.9036748763140873,-0.025559785726358975
382.60000000000485,21.889293830956007,0.8959239740705094,-0.026688632037767945
384.0000000000049,21.93270315520553,0.8881768150936229,-0.029537977145587924
385.40000000000487,21.97631675930179,0.8785927313071524,-0.0310632086592717
386.8000000000049,22.01997338013626,0.8700513370098489,-0.032511011604134055
388.20000000000493,22.063672197570742,0.8578817712430229,-0.0354338640481453
389.60000000000497,22.106671387497304,0.8475196008119916,-0.03772408104505143
391.000000000005,22.15061533493142,0.8335643145817091,-0.0404847103127457
392.400000000005,22.19461126434949,0.8201180095744928,-0.043069333678880994
393.800000000005,22.238600431044254,0.8051097920137935,-0.047265026797461474
395.20000000000505,22.28218564065395,0.7910454712028249,-0.0511586759366347
396.600000000005,22.32611614241007,0.7750706041049454,-0.0549529454201938
398.00000000000506,22.369997848246793,0.7548472612918316,-0.05806611600864109
399.4000000000051,22.4139393303679,0.7381006113153812,-0.06258844677820274
400.8000000000051,22.457854230256057,0.7199495027039978,-0.06766827960304234
402.20000000000516,22.50168557653491,0.7040845111942275,-0.07173466409522833
403.60000000000514,22.54573016915432,0.6867977664768387,-0.07799232560982716
405.0000000000052,22.589265030095284,0.6732423402203357,-0.08454115803998352
406.4000000000052,22.633266554151387,0.6584951546562209,-0.09008610332708544
407.8000000000052,22.677009261227795,0.6475435518148358,-0.09588950773150806
409.2000000000052,22.721101081919386,0.6381154674116862,-0.10221856419631337
410.60000000000525,22.765087316301873,0.6332018461815676,-0.11009149782371574
412.0000000000053,22.809106469858445,0.6299110302140246,-0.11756226565000771
413.4000000000053,22.85278382059941,0.6323313875384334,-0.1254036153458249
414.8000000000053,22.896337016317926,0.6360202960514784,-0.1315116880748195
416.20000000000533,22.93946770740266,0.6452812225483162,-0.13967684766119914
417.60000000000537,22.983787302097966,0.6533893483017057,-0.1471187345539211
419.00000000000534,23.02755033669866,0.6668505961498381,-0.1537337988488252
420.4000000000054,23.071322600634005,0.6840059867918444,-0.15954546249889168
421.8000000000054,23.11499245847384,0.7018191998078253,-0.16627475164653616
423.20000000000545,23.15849174106036,0.7184168215124495,-0.17326207270241634
424.6000000000055,23.202215820670652,0.7380725398165978,-0.18002822668885976
426.00000000000546,23.24583358985852,0.7628381070819727,-0.1840095466563887
427.4000000000055,23.289602359288203,0.7846985909060731,-0.18787834409812199
428.8000000000055,23.333018614411518,0.8092675911404913,-0.1930008545667139
430.2000000000055,23.37694945151717,0.8316272727390036,-0.19581386824496594
431.60000000000554,23.42052192067406,0.8522609391694138,-0.19983137803736284
433.00000000000557,23.464482811433857,0.868135217831847,-0.20152334267699068
434.4000000000056,23.508238803949055,0.882133764402544,-0.20350544241581092
435.80000000000564,23.552149100499292,0.8929938876320836,-0.20510031226736736
437.2000000000056,23.595955606714583,0.8994916559628872,-0.2063845202304746
438.60000000000565,23.640132550902404,0.9051474867598829,-0.20700791208701208
440.0000000000057,23.684354765826928,0.9060254051916492,-0.20783387792165087
441.40000000000566,23.72833331137,0.9084302339354131,-0.20909952908891105
442.8000000000057,23.77247728064761,0.9097451030371542,-0.20778667453867472
444.20000000000573,23.816657436241574,0.9067798770724822,-0.20911679132974337
445.60000000000576,23.861093525055185,0.9046299996773474,-0.20912706166012685
447.0000000000058,23.90523788595294,0.9028152523996662,-0.21042698335767263
448.4000000000058,23.949456121535228,0.9011593564935844,-0.21177267001336775
449.8000000000058,23.993810200226722,0.8962369515301143,-0.21072811091839316
451.20000000000584,24.03824788482814,0.89211265917362,-0.21208813071297605
452.6000000000058,24.082604446932816,0.8904394837376075,-0.21302853994016546
454.00000000000585,24.126944421425087,0.8867669007622542,-0.21340954896784492
455.4000000000059,24.171044997702634,0.8796156077744478,-0.21341000395379117
456.8000000000059,24.215691888126496,0.8770864805107501,-0.21341439461204725
458.20000000000596,24.26018419895224,0.8719027524917479,-0.21415652861252665
459.60000000000593,24.304747229074714,0.8679518287036797,-0.2144271956589079
461.00000000000597,24.34923660046586,0.8640847729866847,-0.21452001187739
462.400000000006,24.393795779202108,0.8562316107134157,-0.21532666325046002
463.800000000006,24.438249313780823,0.8517988562337948,-0.2155334013502781
465.200000000006,24.48278627660131,0.8465362060317928,-0.21453034741761545
466.60000000000605,24.527565874497657,0.8386102707550928,-0.2158328340810618
468.0000000000061,24.57200963084781,0.8335371279383129,-0.21577334722922137
469.4000000000061,24.616261646076243,0.8273349493862169,-0.21714889623027966
470.8000000000061,24.6613701759206,0.8224493020859089,-0.21716088112369292
472.2000000000061,24.70603914270541,0.8142619821858882,-0.21821755664245046
473.60000000000616,24.750644161853742,0.8074379715435227,-0.21806128748978004
475.00000000000614,24.795365871531455,0.7999795083887811,-0.21910933774455943
476.4000000000062,24.840156566064945,0.7942638885887019,-0.21915443734986617
477.8000000000062,24.88478461078215,0.7863111863448075,-0.22044320641105397
479.20000000000624,24.929420810204423,0.7807199765904351,-0.22043996556458456
480.6000000000063,24.97443781866272,0.7725092110768204,-0.22051560086047317
482.00000000000625,25.019234681456673,0.7672797725251974,-0.22175986578799245
483.4000000000063,25.063771799608755,0.7585801791319364,-0.2218320778738887
484.8000000000063,25.108625422277377,0.7522415226186923,-0.2217148363831538
486.2000000000063,25.15362108211026,0.7460723355476543,-0.2224188206733233
487.60000000000633,25.198595994213928,0.7400134304661126,-0.2236925257748159
489.00000000000637,25.243582555693436,0.7334156347694503,-0.22373036669273683
490.4000000000064,25.288213473192116,0.7305736698502137,-0.22372627424082836
491.80000000000643,25.33342337660163,0.7235188495734495,-0.22507669384514806
493.2000000000064,25.378258765117018,0.7212991298652502,-0.22535333430900728
494.60000000000645,25.423093041904323,0.7160682029968194,-0.2264669862149158
496.0000000000065,25.467622271434323,0.7119260387329343,-0.22636995903421742
497.40000000000646,25.512364237291813,0.7065041979571641,-0.22637956005277582
498.8000000000065,25.55773437719039,0.7039655764138428,-0.22770381575488008
500.2000000000065,25.602437741048302,0.699770281608996,-0.22768560835823282
501.60000000000656,25.648094779298404,0.6967017557261479,-0.2290046994793573
503.0000000000066,25.692864760051886,0.6924478980161498,-0.22900728271730086
504.40000000000657,25.73782961973908,0.6872989853996534,-0.23028145408112666
505.8000000000066,25.78282718194078,0.6837275082112052,-0.23033020292729445
507.20000000000664,25.82817650346891,0.6740823094537548,-0.23033000797550818
508.6000000000066,25.873196278087345,0.6631167912020471,-0.23024724732536983
510.00000000000665,25.91832035369068,0.6474712135901648,-0.23163991675434614
511.4000000000067,25.963378136959523,0.636880327567597,-0.23240855336121813
512.8000000000068,26.00826736314771,0.6244663128795717,-0.23295971279025807
514.2000000000068,26.053297979342144,0.6176126965764622,-0.23301732666488206
515.6000000000067,26.098789370158574,0.6084835267498179,-0.23163825064857235
517.0000000000068,26.14360833522827,0.6005508524118989,-0.23203717797812606
518.4000000000068,26.189202794681073,0.591413026454715,-0.2329600228789923
519.8000000000068,26.234314944798857,0.5835562592237433,-0.23428664601936777
521.2000000000069,26.279627471133,0.5746389506918143,-0.23428018068522238
522.6000000000068,26.324779958277148,0.5678126457394834,-0.23428018305319265
524.0000000000068,26.369726338161612,0.5610413648310655,-0.23428015107525946
525.4000000000069,26.415210169831226,0.5543570889569766,-0.23426757437714452
526.8000000000069,26.460465198280254,0.5495380954177754,-0.2329701945629319
528.2000000000069,26.505744785891824,0.5449896823557651,-0.23297435258216082
529.600000000007,26.550910356288192,0.5431033357433368,-0.23425970370734506
531.0000000000069,26.596153824012223,0.5359308650507818,-0.23427121113394334
532.4000000000069,26.641481246927942,0.5301641806350872,-0.23478564801264
533.800000000007,26.686945211530148,0.5240609964709319,-0.23459965226703794
535.2000000000071,26.732160502228567,0.521771762043211,-0.2346006476533251
536.6000000000071,26.777124972739294,0.5168989183065243,-0.23515051127580167
538.000000000007,26.82285995655533,0.5127936142461105,-0.23526033348728825
539.4000000000071,26.868164209931678,0.5058013876899894,-0.2352599643403699
540.8000000000071,26.913378180503514,0.5098479075757207,-0.23525996950061812
542.2000000000071,26.95894247442735,0.5104416179243864,-0.23526014068016732
543.6000000000072,27.004293784699954,0.5136307690441101,-0.23598604279476332
545.0000000000072,27.050054295616857,0.5192008946078164,-0.23591514917550427
546.4000000000071,27.095267424397278,0.5216531008200712,-0.23559544241060726
547.8000000000072,27.140751546227424,0.5202657689724205,-0.2366537334540384
549.2000000000072,27.186366109022114,0.5155290375409334,-0.23692807685192863
550.6000000000072,27.23165262416998,0.5094835519240125,-0.23625768729509922
552.0000000000073,27.277365668704906,0.5039369081056939,-0.23649722193794664
553.4000000000073,27.323179691177803,0.498061608315886,-0.23657855755023594
554.8000000000073,27.368674334271454,0.49311174188945184,-0.23723168367900493
556.2000000000073,27.413908632834115,0.49006088465642195,-0.23723982455106585
557.6000000000073,27.459688746170272,0.4838435885748819,-0.23861916845072706
559.0000000000074,27.505340070681385,0.47948321713088027,-0.23856344139662022
560.4000000000074,27.551315291654674,0.47612359259572984,-0.23909623141375036
561.8000000000075,27.59671777064113,0.47185980267943023,-0.23856003874260479
563.2000000000074,27.642446060762673,0.47179811566074187,-0.238536747401914
564.6000000000074,27.68837716213993,0.46902811796236143,-0.23724131443449803
566.0000000000075,27.73376742233872,0.46468943161334164,-0.23715867480770259
567.4000000000075,27.779540327808512,0.4595628416018746,-0.2385613340849111
568.8000000000075,27.825283060559588,0.4547116032712858,-0.2399029211034942
570.2000000000075,27.87091665598842,0.4476502545677288,-0.23987983252671974
571.6000000000075,27.91648405399011,0.4301458247848347,-0.23987995439100018
573.0000000000075,27.96364003762104,0.3315298311296747,-0.2398871939208318
574.4000000000076,28.009460161501913,0.348674868329253,-0.23855878651799323
575.8000000000076,28.0541846953369,0.38967115001237623,-0.23855995665276009
577.2000000000077,28.100115154654794,0.4141306835493636,-0.23855915013263873
578.6000000000076,28.145802576760243,0.42618605666351705,-0.23986151816679246
580.0000000000076,28.191252669686005,0.4302633560493581,-0.23987988468994415
581.4000000000077,28.23713794325283,0.434160610061365,-0.2398798550932102
582.8000000000077,28.283077651877132,0.4304851802074997,-0.23987984269109885
584.2000000000078,28.329104601706828,0.42839666380111635,-0.23987973390025008
585.6000000000078,28.37491910333993,0.42229207041489186,-0.24119614235295117
587.0000000000077,28.42013296777503,0.4174621069561016,-0.24118997657360053
588.4000000000078,28.46677009587195,0.4118171431520356,-0.2411837244030206
589.8000000000078,28.51246016247725,0.4053875999760497,-0.2425164168224594
591.2000000000078,28.5583364225577,0.3989765841204097,-0.2424991434462429
592.6000000000079,28.604580170842222,0.39109693055012895,-0.24118683127432572
594.0000000000078,28.65060167893314,0.38324948755754884,-0.24124314536480584
595.4000000000078,28.696297077576297,0.3791761933313583,-0.2425123283096271
596.8000000000079,28.74286912722644,0.36973523746793546,-0.24251019182123734
598.2000000000079,28.78897441213525,0.3631712938724527,-0.24251019699962484
599.600000000008,28.834897109517822,0.3587379865456849,-0.2425101976484747
601.000000000008,28.880876341435975,0.3522215053381973,-0.24250994406240034
602.4000000000079,28.927336816906617,0.344735019295572,-0.24372694397014172
603.800000000008,28.973235159686695,0.3381094284354955,-0.2428526396128654
605.200000000008,29.019426985291524,0.3343354035591061,-0.24251079150638422
606.6000000000081,29.065603035931094,0.3268401594114648,-0.242537863867895
608.0000000000081,29.111945038226697,0.3198611612190809,-0.2438181658244689
609.400000000008,29.158086935306628,0.31727796557812965,-0.2438198478233078
610.8000000000081,29.20405553361813,0.3095234172197946,-0.2438173979853442
612.2000000000081,29.250201159326707,0.30300866341588323,-0.24315720352002668
613.6000000000081,29.296525624841884,0.2972133299976184,-0.24381989780134283
615.0000000000082,29.343091143092447,0.29367832343367717,-0.24383015145231557
616.4000000000082,29.38904068980677,0.2857180901329719,-0.24382999086941615
617.8000000000081,29.434796203061747,0.27729850775214315,-0.24443859629993314
619.2000000000082,29.48162660480789,0.2713570222055668,-0.24514854021532306
620.6000000000082,29.52804660297468,0.2635644034152204,-0.24526984654579298
622.0000000000083,29.574466027514898,0.25821645197942317,-0.2463661374642907
623.4000000000083,29.620688686910917,0.25395507872524997,-0.24777799267099176
624.8000000000083,29.666879429290738,0.2484124492107516,-0.2464551773050374
626.2000000000083,29.713281500862006,0.23970226400502972,-0.2464824575508291
627.6000000000083,29.759834417202338,0.23292068154307302,-0.24746811469348895
629.0000000000084,29.805479975411853,0.22471646862559216,-0.2477790611273214
630.4000000000084,29.852660482114377,0.2189189134223841,-0.2480688420236845
631.8000000000084,29.89899925941385,0.21191252457055476,-0.249099983911516
633.2000000000085,29.945405276338,0.20050586182912108,-0.24909996727002293
634.6000000000084,29.99194153604715,0.19308428167878913,-0.2491000115917501
636.0000000000084,30.03808397623392,0.18319271109834048,-0.24910677390712888
637.4000000000085,30.084584612980745,0.1756359940763937,-0.24955713239635502
638.8000000000085,30.13072869736109,0.16760663877862872,-0.24908398488828354
640.2000000000085,30.17726695382543,0.15468899005603773,-0.2504047371638536
641.6000000000085,30.22378818810257,0.14504174878221265,-0.2496499928892999
643.0000000000085,30.269827389984552,0.13565973890877966,-0.24909314510848501
644.4000000000086,30.316746394913647,0.12379856492491656,-0.2504123259787727
645.8000000000086,30.363366758603544,0.11148687150492156,-0.25172497610845257
647.2000000000086,30.40936610255107,0.09933948258325441,-0.2528874626684412
648.6000000000087,30.45626036967414,0.08628380159852322,-0.25172305918806437
650.0000000000086,30.50251121051966,0.06982898636524026,-0.2530560400263484
651.4000000000087,30.549374693184756,0.0513006039939974,-0.2534700874777056
652.8000000000087,30.596190195314136,0.034763815912843714,-0.25468257774283964
654.2000000000087,30.64247723326007,0.020902889656741742,-0.2570291470227368
655.6000000000088,30.688636263255827,0.0015950072568844903,-0.25699828525783763
657.0000000000088,30.73501488500682,-0.015356546312090364,-0.2583538594501271
658.4000000000087,30.782703560547933,-0.031390955916584626,-0.25693073507530073
659.8000000000088,30.828834388453746,-0.048602395032489365,-0.2583185551359026
661.2000000000088,30.87598208113843,-0.06508099255510746,-0.25963533825147955
662.6000000000088,30.922336711918064,-0.07996230208764758,-0.259751171154996
664.0000000000089,30.968940031374192,-0.09469984254713115,-0.25963342797973166
665.4000000000088,31.015721412200058,-0.11486548266762542,-0.2609541310397425
666.8000000000089,31.062117391428043,-0.1346043264917268,-0.2622542181636587
668.2000000000089,31.108379827906887,-0.15522319961139996,-0.2635565460998963
669.6000000000089,31.155721140966765,-0.1788598033812414,-0.2649399719621299
671.000000000009,31.202376743030793,-0.1992769017183311,-0.2665408499277655
672.400000000009,31.24920424801786,-0.22287089543550526,-0.2687480724829907
673.800000000009,31.295825431691597,-0.2416524012775152,-0.2684517096104311
675.200000000009,31.342670388311905,-0.26626061330941175,-0.2697341080052804
676.600000000009,31.389272810837195,-0.2905702115380217,-0.27106074335727026
678.0000000000091,31.43623256337243,-0.31537948598079246,-0.2725079930001866
679.4000000000091,31.48278079331061,-0.342689380040179,-0.27511756919986663
680.800000000009,31.529560371354922,-0.3727225624820915,-0.2770946338413047
682.2000000000091,31.57636101238608,-0.3992778643172981,-0.2784067762022717
683.6000000000091,31.62323823399796,-0.4291685124172377,-0.27932912333026705
685.0000000000091,31.67030202789339,-0.46015871726489954,-0.28150037124301575
686.4000000000092,31.71687819977923,-0.4911207099453247,-0.28417750147065135
687.8000000000092,31.76376887701485,-0.5203128131135689,-0.2854647582968175
689.2000000000093,31.810754682001697,-0.5545413626060673,-0.28835339766999724
690.6000000000092,31.857801618475087,-0.5890835768475771,-0.2905150563068126
692.0000000000092,31.904491846204035,-0.6287268144328194,-0.2922001829832026
693.4000000000093,31.951491037352177,-0.6670177150452968,-0.295224120960774
694.8000000000093,31.99876883161336,-0.7073137418805959,-0.298251180743736
696.2000000000094,32.04526496671549,-0.7465478968113365,-0.3010758949184211
697.6000000000093,32.09237266486513,-0.7909453463155437,-0.3030337487481698
699.0000000000093,32.13951608311387,-0.8335376725961848,-0.30654696138410387
700.4000000000094,32.18636960027901,-0.880183175889613,-0.31013147033869926
701.8000000000094,32.23328439252579,-0.9288789455438166,-0.3124954888371767
703.2000000000094,32.280394956233906,-0.976222687508341,-0.315482679677785
704.6000000000095,32.327535824785365,-1.0242602525122755,-0.3197610261972019
706.0000000000094,32.37491054375293,-1.0776909252758193,-0.32479246613702806
707.4000000000094,32.421675334325116,-1.1348220060109848,-0.32954159472137423
708.8000000000095,32.469441847152666,-1.1922405026432803,-0.3328712718551641
710.2000000000095,32.51644478060135,-1.2469531701100887,-0.3373072101824577
711.6000000000096,32.56387365945666,-1.3106770037350375,-0.3422004923647646
713.0000000000095,32.61141096027326,-1.371024399875548,-0.3468993451877074
714.4000000000095,32.65826379042026,-1.435186779596671,-0.3514050753227478
715.8000000000096,32.7051807296112,-1.4997565524808614,-0.3558789462804719
717.2000000000096,32.75298612134498,-1.5657219248721044,-0.36067233743611693
718.6000000000097,32.800472182647475,-1.635380755727176,-0.3655387825686738
720.0000000000097,32.8472555093224,-1.7075204157008401,-0.37167773911501767
721.4000000000096,32.89422105298463,-1.7804680059659184,-0.37762676189985145
722.8000000000097,32.94236435890251,-1.8555648796043336,-0.38417126721033723
724.2000000000097,32.98985675510323,-1.936318348959265,-0.3904679435481615
725.6000000000097,33.03807559571745,-2.016357169988839,-0.3975400598484584
727.0000000000098,33.08532071917599,-2.099246706270044,-0.405739574897503
728.4000000000098,33.13299475741856,-2.187075799835157,-0.41255769155672306
729.8000000000097,33.180833571496905,-2.27347717391447,-0.4195120281100917
731.2000000000098,33.2283047736247,-2.3661603574358874,-0.42776332813128537
732.6000000000098,33.2760989631013,-2.4566736314303945,-0.4364720041329737
734.0000000000099,33.32409876287393,-2.5518145237383143,-0.4451454415089402
735.4000000000099,33.37172579094158,-2.647027211146511,-0.452624850559054
736.8000000000098,33.418866405681996,-2.7419536110316223,-0.4619254765563139
738.2000000000099,33.46754276861613,-2.8429000796191666,-0.4723984120221285
739.6000000000099,33.51536621785797,-2.9452761557388336,-0.482254985573896
741.00000000001,33.563473449986006,-3.0508170326582995,-0.4921313864104464
742.40000000001,33.611256938397155,-3.1537200148696956,-0.5028228432703532
743.80000000001,33.65889716865818,-3.2617059091697773,-0.5117165551299832
745.20000000001,33.70735880166096,-3.3707658938869884,-0.5238306368105103
746.60000000001,33.75534208897159,-3.4841946475260457,-0.5354566868538018
748.00000000001,33.80318038795424,-3.598872764463621,-0.548005671871298
749.4000000000101,33.85108161314168,-3.710530124882531,-0.5612941512200211
750.8000000000101,33.899102077735385,-3.8296768878750638,-0.574221359803953
752.20000000001,33.947415682307835,-3.9475548966145704,-0.5866287301641484
753.6000000000101,33.995268627608965,-4.068065151508394,-0.5990751746849212
755.0000000000101,34.0435520942846,-4.192230576449819,-0.6137105280681676
756.4000000000102,34.09154815305221,-4.314810570051146,-0.6284530518171465
757.8000000000102,34.13985755552436,-4.441388665571049,-0.643527710380277
759.2000000000102,34.188210978550735,-4.569825278054564,-0.658887348973026
760.6000000000103,34.23598507323146,-4.698945380235884,-0.6745143574184111
762.0000000000102,34.284463143684235,-4.830439750279337,-0.689831359359466
763.4000000000103,34.332473285283214,-4.961783523023664,-0.7067780338118728
764.8000000000103,34.38106694978622,-5.096122780916451,-0.7256047656011804
766.2000000000103,34.42931117835219,-5.2328678155061565,-0.7426104231201225
767.6000000000104,34.47731994376566,-5.370460767275085,-0.76102131400943
769.0000000000103,34.52559678243309,-5.505396358512114,-0.7800748274305875
770.4000000000103,34.57419192393177,-5.6444106369046745,-0.7999642945297447
771.8000000000104,34.62252117019681,-5.780097948884321,-0.8205661829880526
773.2000000000104,34.67061738741921,-5.91419158395799,-0.8409231250360012
774.6000000000104,34.71841484975171,-6.043101924695749,-0.8623461708387574
776.0000000000105,34.76678573355547,-6.172810857755769,-0.8835638495509293
777.4000000000104,34.81495313793865,-6.294972911855278,-0.9046155387885069
778.8000000000105,34.86289269060767,-6.409843301737741,-0.927175606578412
780.2000000000105,34.910993056676,-6.5151773609920625,-0.9490485427007722
781.6000000000105,34.95894002483598,-6.607126097556281,-0.9716913267127145
783.0000000000106,35.007142684732926,-6.686837338361391,-0.9948495498987766
784.4000000000106,35.05459484298768,-6.744383805234506,-1.0175815484837547
785.8000000000106,35.10177917160795,-6.779021649872436,-1.0414019405853514
787.2000000000106,35.14889515632067,-6.783335965952466,-1.0639077316274355
788.6000000000106,35.19589032202937,-6.752149263487263,-1.0870594615901328
790.0000000000107,35.24210104924228,-6.682524999374302,-1.1097654381421127
791.4000000000107,35.288517083255165,-6.559297213901758,-1.132031045041313
792.8000000000106,35.33414953497277,-6.377143067906512,-1.1549875807120795
794.2000000000107,35.37956251194472,-6.120919339847082,-1.176392593033463
795.6000000000107,35.42376122366786,-5.791962024810431,-1.1957306334433433
797.0000000000107,35.467249020600704,-5.379498241478063,-1.2133771982866999
798.4000000000108,35.51088886025939,-4.859846795559395,-1.2296085786238895
799.8000000000108,35.55313998125897,-4.258038883720351,-1.2430651599929052
801.2000000000108,35.59503508420981,-3.5950259608207937,-1.2553460573414115
802.6000000000108,35.63660210732182,-2.918682326391328,-1.2659693269578538
804.0000000000108,35.67883717084979,-2.2703382150362903,-1.2751574812785487
805.4000000000109,35.72146953601041,-1.7038143847127758,-1.282039745920617
806.8000000000109,35.76461756849752,-1.2431668542168088,-1.2868519051017162
808.200000000011,35.80881814230789,-0.8947718588872621,-1.2900688722823501
809.6000000000109,35.85345349063275,-0.6464288133782811,-1.292536681608612
811.0000000000109,35.89978476427582,-0.4671728377114764,-1.2945501869102047
812.400000000011,35.94569533337456,-0.34974701266943675,-1.2958631490371815
813.800000000011,35.99208432449582,-0.27381336318115684,-1.2973302384258574
815.200000000011,36.038837185416604,-0.22907670727692828,-1.296508916353019
816.600000000011,36.0856857108278,-0.20387842748321972,-1.2971822601040555
818.000000000011,36.13302451407302,-0.18910694457884583,-1.2958798055325986
819.400000000011,36.18008781294865,-0.18151286370314096,-1.2972347262761414
820.8000000000111,36.227224374680574,-0.174813286353121,-1.2971905564344564
822.2000000000111,36.274495425120705,-0.17727868270966107,-1.2971027620691609
823.6000000000112,36.32149758115137,-0.17677311274793023,-1.2965994016004938
825.0000000000111,36.3688664160731,-0.17826966334046673,-1.296535054491664
826.4000000000111,36.416237967053796,-0.1785561184498727,-1.2976581359212571
827.8000000000112,36.46352446066231,-0.18442899218085926,-1.2978504105386537
829.2000000000112,36.5107392898597,-0.18959768350836861,-1.2978500277602927
830.6000000000113,36.55827740048933,-0.18931101438056508,-1.2978506960009026
832.0000000000113,36.60544445547818,-0.19203104609637922,-1.2991178675218213
833.4000000000112,36.65277589084376,-0.1944840253464377,-1.2978606670795911
834.8000000000113,36.70013956422349,-0.1952636874276945,-1.297859930173518
836.2000000000113,36.74710652531027,-0.19620082412645906,-1.297859961055242
837.6000000000113,36.79469054800507,-0.2017786484437611,-1.2978460863935393
839.0000000000114,36.842038814816036,-0.201700365448593,-1.2979549829335295
840.4000000000113,36.88916931617407,-0.20346993033192187,-1.297859832574952
841.8000000000113,36.93670960124479,-0.2047737426830097,-1.297859827655099
843.2000000000114,36.98380504575846,-0.20606710866644562,-1.2978598269789945
844.6000000000114,37.031117740894544,-0.20953285014633502,-1.29786013685567
846.0000000000115,37.07865187958237,-0.20954067292665998,-1.2984723174519641
847.4000000000115,37.12641014337181,-0.21217742568690015,-1.3003718706153502
848.8000000000114,37.173205619843166,-0.21292134358144316,-1.3006037148035916
850.2000000000115,37.220836666290566,-0.21563008021634453,-1.2992819750268119
851.6000000000115,37.26819048199858,-0.21585954650087763,-1.2992561126634605
853.0000000000116,37.31569722095144,-0.21536157382387697,-1.2979621358121172
854.4000000000116,37.3634711868242,-0.21293773229855328,-1.2979601561047813
855.8000000000116,37.41111479659843,-0.21537031006021815,-1.2979603556012056
857.2000000000116,37.45823438669848,-0.2230369919501948,-1.2992973258541323
858.6000000000116,37.50574288051609,-0.22172098733022097,-1.2982826918607109
860.0000000000116,37.552714226723594,-0.22639094861956602,-1.2979644493715314
861.4000000000117,37.60082434716511,-0.22976813134924956,-1.29929427453908
862.8000000000117,37.64815556158294,-0.23265464336222363,-1.2992899665992206
864.2000000000116,37.69585630617034,-0.2368547515184825,-1.2992898602430896
865.6000000000117,37.743099231198634,-0.2343132234295383,-1.2993392401340373
867.0000000000117,37.790930467011606,-0.24045975920465207,-1.299608775837767
868.4000000000118,37.83820371336841,-0.23701366056387635,-1.2996435362201195
869.8000000000118,37.8856210118678,-0.2407056847048576,-1.2992807604574628
871.2000000000118,37.9332599985639,-0.24470442771615847,-1.2992800920225145
872.6000000000118,37.98099551364034,-0.24753360439194788,-1.2992804525751667
874.0000000000118,38.02844403189321,-0.2445448996663277,-1.2998796024906238
875.4000000000119,38.07575611280107,-0.23330881649915758,-1.3005742818598365
876.8000000000119,38.1233535858421,-0.23174459865664113,-1.299486567180311
878.2000000000119,38.17073738552929,-0.23011165888065663,-1.3005992345883959
879.600000000012,38.21816860291088,-0.23322318708598394,-1.3006034343593127
881.0000000000119,38.2658043517227,-0.23572788893114577,-1.29923920722951
882.4000000000119,38.313242712666316,-0.23700494277500386,-1.2992899423007742
883.800000000012,38.36057443081373,-0.2361325584874092,-1.2992937590559483
885.200000000012,38.40760937075268,-0.23682828471409023,-1.3006228697771274
886.600000000012,38.45572475668123,-0.23871319592477136,-1.3005540878987927
888.000000000012,38.50330577178936,-0.2418753878881851,-1.2993124015273438
889.400000000012,38.550811404609235,-0.24598629690439505,-1.3005984509956088
890.8000000000121,38.59812599680668,-0.24772904616468444,-1.3005999279600227
892.000000000012,38.63913648482302,-0.2522737579157465,-1.3005999299996809