File: 01_Data/Cinder_Block/STA/N2/10K_min/Cinder_Block_STA_N2_10KData_230919_R1.csv
##Temp./Â°C,Time/min,DSC/(mW/mg),Mass loss/mg
41.0,10.83745026356017,-2.2901926276590214,-0.006660176938717122
42.40000000000002,11.177380591778975,-2.2197789930520995,-0.007236526343389116
43.80000000000004,11.419503044232181,-2.170793904594975,-0.00593745648610966
45.20000000000006,11.624716531477643,-2.1355643552580617,-0.005223117391666143
46.60000000000008,11.812515560214168,-2.10464232238941,-0.006148393529045393
48.0000000000001,11.9880246861559,-2.0815832138583863,-0.005972957340769192
49.40000000000012,12.15625577479607,-2.0627335134088027,-0.0071639977713431335
50.80000000000014,12.315490164188319,-2.0479258304173333,-0.005795028311245787
52.20000000000016,12.4760598149492,-2.0336157672552577,-0.007011175462161567
53.60000000000018,12.633173567542029,-2.023215824908229,-0.005581746313639613
55.0000000000002,12.788880846693695,-2.0120916793437016,-0.008550011219098153
56.40000000000022,12.94237970936631,-2.0024757658360026,-0.005760650439287751
57.80000000000024,13.092887967759642,-1.9943654577409644,-0.006792628091954356
59.20000000000026,13.242871117530639,-1.9859610132416663,-0.005921162867011276
60.60000000000028,13.393450067076852,-1.9794564055057406,-0.007348235845631379
62.0000000000003,13.541871462540927,-1.9717134184998675,-0.007251218935072856
63.40000000000032,13.688938964569374,-1.9634961515624025,-0.007126822969232727
64.80000000000034,13.836770856273345,-1.9563756163177888,-0.008558123386459116
66.20000000000036,13.982292758563515,-1.9485329653905903,-0.008699139447507775
67.60000000000038,14.127161369853843,-1.9425748863477608,-0.009875695148786612
69.0000000000004,14.272175071274189,-1.934596574632908,-0.011228258990105822
70.40000000000042,14.416268829511308,-1.928427336135111,-0.010516522658245542
71.80000000000044,14.55861007169656,-1.9207271387416909,-0.008543594791214026
73.20000000000046,14.700414484934768,-1.9140606960812965,-0.010502233241758141
74.60000000000048,14.842250286821733,-1.908107856834452,-0.009819734936577618
76.0000000000005,14.984799810349589,-1.899508665528232,-0.011189895896454694
77.40000000000052,15.124306207646121,-1.8930836338342583,-0.011189596665048818
78.80000000000054,15.266172847376483,-1.885601179561235,-0.011199601538244508
80.20000000000056,15.406148043995564,-1.879665858854456,-0.013149932779742635
81.60000000000058,15.544975819337628,-1.8728132574270164,-0.013139162475715338
83.0000000000006,15.686108185630564,-1.8655051792063768,-0.010869407649062524
84.40000000000062,15.826302468085247,-1.8603743182953387,-0.012527583728866531
85.80000000000064,15.965777317447998,-1.852059153522006,-0.013719920919131212
87.20000000000066,16.104064621855084,-1.8472167112489695,-0.01240511970913083
88.60000000000068,16.242783669956438,-1.8384714738012942,-0.014376839418074105
90.0000000000007,16.382152507399773,-1.8325545249577646,-0.015683411926074697
91.40000000000072,16.520266764964642,-1.8264130036406259,-0.01569027716531668
92.80000000000074,16.657233904310267,-1.8203272052069384,-0.015737333961599376
94.20000000000076,16.79500414380895,-1.8130741209116463,-0.016021184085539986
95.60000000000078,16.93059612429409,-1.8060786902874368,-0.017365738125218577
97.0000000000008,17.06821870228589,-1.8015130462037705,-0.018650185361070548
98.40000000000082,17.20537438115751,-1.7950413515046364,-0.018330840951799487
99.80000000000084,17.34227467920283,-1.78690997207672,-0.018329941627738933
101.20000000000086,17.478366894134,-1.781747582319552,-0.019650171435548813
102.60000000000088,17.61491086794141,-1.77344986294189,-0.0183451708194573
104.0000000000009,17.751169330480913,-1.7687858213258554,-0.019650084389373212
105.40000000000092,17.887457568225738,-1.7631058982257553,-0.01866029959808113
106.80000000000094,18.02219299254072,-1.7547491795804047,-0.018528774655035996
108.20000000000095,18.158206074825003,-1.7484223924325408,-0.0192897955112743
109.60000000000097,18.294616310887147,-1.743052582218332,-0.019648371978738588
111.000000000001,18.430166781682274,-1.7361206346365494,-0.01915318560211965
112.40000000000101,18.56419948122864,-1.7297079189017464,-0.020623433756840726
113.80000000000103,18.701819503779042,-1.723398951576506,-0.02250899329680678
115.20000000000105,18.835853056635177,-1.717506686927563,-0.021315799354431064
116.60000000000107,18.970958824238547,-1.71028725486267,-0.020937622179626025
118.0000000000011,19.106188846610188,-1.7064405097415456,-0.022279831024601293
119.40000000000111,19.240697933572708,-1.700580327029201,-0.02227982718867061
120.80000000000113,19.37609212310688,-1.6942580882272682,-0.022318953148622533
122.20000000000115,19.510435972199787,-1.6901422189096045,-0.02326869112744312
123.60000000000117,19.645247392594,-1.6837836155528707,-0.02393007177709361
125.0000000000012,19.778871705695497,-1.6799912942142892,-0.024195674613863183
126.40000000000121,19.915170862963805,-1.6741544603720686,-0.024250182984238755
127.80000000000123,20.0508162010287,-1.6699691135780332,-0.023599685040080587
129.20000000000124,20.184820542888456,-1.6648140421038806,-0.023920118464321405
130.60000000000127,20.31847792923916,-1.659476568642967,-0.02655456209072593
132.0000000000013,20.453239169466272,-1.6556062371161289,-0.026900028149273503
133.4000000000013,20.586890214878892,-1.6509098553728665,-0.026899796999878767
134.80000000000132,20.720125431138275,-1.6447668866456757,-0.026899797000000447
136.20000000000135,20.854840815490007,-1.64118041963841,-0.026899796998868908
137.6000000000014,20.987246116487228,-1.6343419806763722,-0.026932871359136357
139.0000000000014,21.12337808873591,-1.629915071035473,-0.027897463156375757
140.4000000000014,21.257466819094116,-1.6274298369204079,-0.0265598202320545
141.80000000000143,21.39059617372817,-1.6228554196935916,-0.025578230685384007
143.20000000000147,21.52634945599604,-1.6181251003548582,-0.02687392768705088
144.60000000000147,21.660087158672507,-1.613276860000974,-0.026229995006230133
146.00000000000148,21.79326807600147,-1.6103725763951475,-0.026199663807875417
147.4000000000015,21.926811404184896,-1.6053916984419632,-0.0275427695304451
148.80000000000155,22.060863758980258,-1.603782413498751,-0.02863787944912133
150.20000000000155,22.194528018461657,-1.5989182852424835,-0.02722001761330528
151.60000000000156,22.3285694459235,-1.592320518326681,-0.02852954746358982
153.0000000000016,22.462248900463823,-1.588088216697827,-0.028530131564615147
154.40000000000163,22.595267934649982,-1.5846718297162505,-0.029850013114939955
155.80000000000163,22.728896525587896,-1.5814055348743115,-0.0288934581110043
157.20000000000164,22.862449443485087,-1.5758907706394745,-0.028539869787848282
158.60000000000167,22.995939918761962,-1.5730874937890986,-0.029529619727628464
160.0000000000017,23.129832022731847,-1.5690161655060408,-0.029859883634133944
161.4000000000017,23.262859432670993,-1.563913590651178,-0.030606986345491194
162.80000000000172,23.39586061804907,-1.560482056791284,-0.029529999084572545
164.20000000000175,23.530588981107847,-1.5578815265819506,-0.029859993073818814
165.60000000000178,23.663880795966957,-1.5527780559134459,-0.03039714989268294
167.0000000000018,23.797437916782833,-1.5490587914596672,-0.03084372786140399
168.4000000000018,23.93098267391678,-1.547095607961498,-0.031170080503623687
169.80000000000183,24.06406676423127,-1.5435942304474664,-0.030840080598097508
171.20000000000186,24.198110003315875,-1.5395116827508888,-0.030840081999984115
172.60000000000187,24.331717116673975,-1.5339745193813479,-0.030840801024790032
174.00000000000188,24.46612801201667,-1.5336436620488223,-0.030658716691462473
175.4000000000019,24.599452500012145,-1.5287596427682228,-0.032600961213538504
176.80000000000194,24.73241716145559,-1.5254309839442763,-0.03250116945974213
178.20000000000195,24.866014457134817,-1.5220742180662155,-0.031509531779498445
179.60000000000196,24.99869058458294,-1.5185498047283075,-0.03183244894017001
181.000000000002,25.13250386243933,-1.5186360893743358,-0.03184012500183009
182.40000000000202,25.26399845954692,-1.5140711702504364,-0.03179002001655373
183.80000000000203,25.398645501222028,-1.5106111259062704,-0.0331777678246592
185.20000000000203,25.53123723724805,-1.5082560888536651,-0.0327504519752031
186.60000000000207,25.6653927021193,-1.5067078701242957,-0.032819512015361596
188.0000000000021,25.799073836618685,-1.503845680495156,-0.034140048011259694
189.4000000000021,25.931981614771523,-1.5017894996623837,-0.03282062692122256
190.80000000000211,26.065622519866803,-1.4993651339031882,-0.03153765015258703
192.20000000000215,26.1990776756957,-1.496556454675598,-0.030510715129459243
193.60000000000218,26.331547405636382,-1.493719408686327,-0.03315017069942705
195.0000000000022,26.463170209574855,-1.4915072215982363,-0.03190866881076815
196.4000000000022,26.59765437348527,-1.48974165958935,-0.03246610230311919
197.80000000000223,26.730478991523768,-1.4868557969934435,-0.031169839030876112
199.20000000000226,26.864211262813217,-1.4819158279316231,-0.03246612718509745
200.60000000000227,26.99596672738282,-1.4809278840196076,-0.03248983900042912
202.00000000000227,27.129270999011766,-1.4767452228737337,-0.03248983899999924
203.4000000000023,27.25967866399483,-1.4758733174534204,-0.032489839029838485
204.80000000000234,27.395210103506706,-1.4717492806385097,-0.033204046345812976
206.20000000000235,27.52806051624295,-1.4710925348995119,-0.032919333952306395
207.60000000000235,27.66123615153899,-1.4698697796856142,-0.03381010888424907
209.0000000000024,27.794520228684856,-1.4666794235763292,-0.03380995071232018
210.40000000000242,27.928024422718124,-1.4647642974479937,-0.034470102337746944
211.80000000000243,28.059936640739235,-1.4605225104076336,-0.03418300775600969
213.20000000000243,28.19247695763195,-1.460552527378603,-0.03587008574180306
214.60000000000247,28.326224339139866,-1.4557784726808376,-0.03450823759650312
216.0000000000025,28.45890365656966,-1.4547910609297465,-0.03380981148487994
217.4000000000025,28.59232341486499,-1.4523053502197831,-0.035123999583393406
218.8000000000025,28.72423003569791,-1.4490514358849136,-0.03446466919460622
220.20000000000255,28.85578617275042,-1.448134316477407,-0.034469805313032786
221.60000000000258,28.991387770770018,-1.4462542244858276,-0.035787134428919565
223.0000000000026,29.124230500214534,-1.4445732558870712,-0.03477436673225931
224.4000000000026,29.256673839439493,-1.4431274469819062,-0.0334799032187556
225.80000000000263,29.389642118867062,-1.4409070719723776,-0.034800675080441934
227.20000000000266,29.52291691218465,-1.4408742928561593,-0.033479207876827566
228.60000000000267,29.656374294074773,-1.4377459881551025,-0.03446954411490921
230.00000000000267,29.788524804135076,-1.4369828119277408,-0.03447022895639318
231.4000000000027,29.92294221849451,-1.4353460844202512,-0.03446982699998635
232.80000000000274,30.05594001576179,-1.4326744847862074,-0.03446982699999879
234.20000000000275,30.18757502115166,-1.4317310581801943,-0.03446982699729961
235.60000000000275,30.321625970891393,-1.4301760685948361,-0.034939021521847025
237.00000000000279,30.45528337029813,-1.4274963931967335,-0.0347586498290573
238.40000000000282,30.587890253957493,-1.4288788172506504,-0.03611000420569077
239.80000000000283,30.720309748611367,-1.4242126848179546,-0.03545217170505399
241.20000000000283,30.851517360132867,-1.4233915796033407,-0.036223275671976474
242.60000000000286,30.984238996206415,-1.4238960536069019,-0.0341303924473193
244.0000000000029,31.118681381165786,-1.4206891790096454,-0.035117775426959597
245.4000000000029,31.252396158066738,-1.4194658114085859,-0.03511984900004883
246.8000000000029,31.385175860240675,-1.4200410455521253,-0.03511984899243892
248.20000000000294,31.51802612722486,-1.4176052061094906,-0.03570239690883348
249.60000000000298,31.65176199703331,-1.4157491373864868,-0.03611012560773297
251.00000000000298,31.784961504127796,-1.4141469786861518,-0.035448454065378776
252.400000000003,31.91712842518855,-1.4149694621338809,-0.035236507364777125
253.80000000000302,32.05095816472477,-1.4134760229948633,-0.03545994700307542
255.20000000000306,32.183550363262185,-1.4101505711539504,-0.03545994700000055
256.6000000000031,32.31749872109023,-1.4106969376801557,-0.03545991769333767
258.00000000000307,32.451010172651486,-1.4108370875781424,-0.036440037642731404
259.4000000000031,32.584620919549224,-1.4090202071376705,-0.035561763169574157
260.80000000000314,32.7171407084444,-1.4087860546629067,-0.036119870158485945
262.2000000000031,32.85044976537018,-1.4086997595129789,-0.0361209370638802
263.60000000000315,32.98445127048319,-1.40685894344228,-0.034799598676201526
265.0000000000032,33.117078694350646,-1.4057801381518837,-0.03611987073738199
266.4000000000032,33.25033195995511,-1.4072412835225225,-0.036119870138178634
267.80000000000325,33.383718185022836,-1.404894989090158,-0.03579064052303238
269.20000000000323,33.51655560451791,-1.4040645274003876,-0.03710266092742476
270.60000000000326,33.6507833960714,-1.4032837088798615,-0.035789869696672305
272.0000000000033,33.78432798895992,-1.4029429986597703,-0.03578987000000122
273.4000000000033,33.91766547443287,-1.4023782750606681,-0.03578987000000122
274.8000000000033,34.051730870430816,-1.401403535026286,-0.03578994375056954
276.20000000000334,34.185361016315746,-1.4013041723050053,-0.03841159737064004
277.6000000000034,34.31916909062514,-1.4000198942419522,-0.035789883970009484
279.0000000000034,34.45365053893374,-1.398508719155371,-0.03710988627487222
280.4000000000034,34.58829772010373,-1.3968267447703853,-0.03710986832299756
281.8000000000034,34.7210861150621,-1.3963848237734295,-0.03775938547259816
283.20000000000346,34.854373175930604,-1.3960095293041304,-0.03808986388848634
284.60000000000343,34.98821332763262,-1.3954054847192894,-0.03677997203576311
286.00000000000347,35.12070777566259,-1.3968036242101538,-0.036779870002966675
287.4000000000035,35.25485770403527,-1.3961859321027246,-0.03545228395510769
288.80000000000354,35.387523425667,-1.3957091309457281,-0.036707645161290436
290.20000000000357,35.521949196595024,-1.3963957850979005,-0.0366099658957495
291.60000000000355,35.6557558761281,-1.394737787538798,-0.0361201230174899
293.0000000000036,35.78990964807877,-1.3954936858943832,-0.03744822714218632
294.4000000000036,35.924629006749065,-1.3944303386045322,-0.03742984899812374
295.8000000000036,36.05772116716989,-1.3971100211004128,-0.03742997471770071
297.2000000000036,36.19223652599823,-1.393911006940156,-0.03871552650859211
298.60000000000366,36.32582304229153,-1.3926317000494797,-0.03814240046731321
300.0000000000037,36.459265178087236,-1.3952144050130582,-0.03940029448828497
301.40000000000373,36.593591862598615,-1.3947949101201345,-0.03808984941128468
302.8000000000037,36.727888777634114,-1.3934991895272402,-0.03810079270556166
304.20000000000374,36.86301521417311,-1.394730180841536,-0.0374389179018495
305.6000000000038,36.996451887447904,-1.392450742167045,-0.038772480322712966
307.00000000000375,37.13132723629297,-1.394312684618119,-0.0399240486353305
308.4000000000038,37.26316076802906,-1.3939994207219004,-0.03874987212966108
309.8000000000038,37.399833801315864,-1.3936174908755694,-0.037439653472483236
311.20000000000385,37.5334358527241,-1.3954933983653297,-0.03873616671739111
312.6000000000039,37.66720009356428,-1.3941612344588017,-0.037359704900406854
314.00000000000387,37.80134800502228,-1.3942284688524302,-0.03841889018818545
315.4000000000039,37.936867379893826,-1.3937286541116962,-0.040069746605976064
316.80000000000393,38.070772410634326,-1.3929826241969223,-0.04018796321506635
318.2000000000039,38.20478953563464,-1.3947271755649004,-0.04005994661631096
319.60000000000394,38.33935871538714,-1.3944248662923981,-0.03744008371229235
321.000000000004,38.47405098934755,-1.395773532505295,-0.03861272279257921
322.400000000004,38.60872919625096,-1.3944471598814046,-0.03733709458075207
323.80000000000405,38.74229080392454,-1.3949881910670352,-0.03874999429607495
325.200000000004,38.876961092484784,-1.3962880521325434,-0.04005952009164204
326.60000000000406,39.01280411056702,-1.3958013324198248,-0.04006000299999801
328.0000000000041,39.14526574915698,-1.3965908820903932,-0.04006000463001236
329.40000000000407,39.281496478072775,-1.3967940360129176,-0.04105010166269807
330.8000000000041,39.416357617782644,-1.3967397650889821,-0.038434534936182096
332.20000000000414,39.552322284541575,-1.3980430239280799,-0.03708586313287121
333.6000000000042,39.68656075342304,-1.3999979058758938,-0.040120849977181905
335.0000000000042,39.82251791954286,-1.400421679466223,-0.04170740104567461
336.4000000000042,39.95586734041806,-1.400614435478948,-0.04072027759460628
337.8000000000042,40.09304848683542,-1.4008349586536144,-0.04039008226879126
339.20000000000425,40.22882100122717,-1.4025915799079312,-0.040390077261516666
340.60000000000423,40.36349747964702,-1.4028957782005644,-0.03973001273505972
342.00000000000426,40.4985102716713,-1.403565827756193,-0.04105023745237801
343.4000000000043,40.63441997828116,-1.4053613143651251,-0.0410500919826875
344.80000000000433,40.76848802519748,-1.403489708924689,-0.04035877998707882
346.20000000000437,40.90493862946371,-1.4059679475193385,-0.041682957033743584
347.60000000000434,41.04167720575553,-1.4057692255001382,-0.04138344894314372
349.0000000000044,41.17684078842991,-1.4047837012469826,-0.04041795717175667
350.4000000000044,41.31157741070335,-1.405961175074992,-0.04270329220450986
351.8000000000044,41.44783804063148,-1.4058970642343775,-0.04138016615724638
353.2000000000044,41.58292916898686,-1.4079260502279467,-0.04138005800000144
354.60000000000446,41.718405573884795,-1.4089944510993173,-0.04138005799966482
356.0000000000045,41.85523588695656,-1.4090653245206557,-0.04129291454031492
357.4000000000045,41.98947808007041,-1.4100717568745071,-0.04269981242648235
358.8000000000045,42.124840040708904,-1.4110838862374122,-0.04270099570714869
360.20000000000454,42.26027707722758,-1.4115081580763977,-0.04302912058120434
361.60000000000457,42.396501470114615,-1.4122640492699579,-0.043027654263729787
363.00000000000455,42.53229522550598,-1.4143128081883884,-0.044399153746929265
364.4000000000046,42.667418838111274,-1.4156218878845077,-0.044193555173778876
365.8000000000046,42.803804308100744,-1.4143111644582596,-0.04302995897923445
367.20000000000465,42.93937351462707,-1.4162726934598273,-0.04435413603005944
368.6000000000047,43.07609915203293,-1.4171529529637978,-0.043030652527044744
370.00000000000466,43.21194336487439,-1.4185194034989035,-0.04302664274510981
371.4000000000047,43.34797001891226,-1.422555343160519,-0.044680107558216164
372.80000000000473,43.484135496436906,-1.42217346366818,-0.04501012534744131
374.2000000000047,43.62081790819365,-1.4243444625226331,-0.04501011158389456
375.60000000000474,43.75577670693497,-1.425550238945261,-0.046000788325430975
377.0000000000048,43.89266622476511,-1.4273306042327443,-0.04407474050402449
378.4000000000048,44.03067117549816,-1.427295524570401,-0.04401009200072803
379.80000000000484,44.16621783150165,-1.4300383596278339,-0.044010131435746835
381.2000000000048,44.30248984607499,-1.431766904787368,-0.042699990349632344
382.60000000000485,44.439169079987714,-1.4314697759398647,-0.04171991692719157
384.0000000000049,44.575187813023874,-1.435491541743656,-0.04303007340990117
385.40000000000487,44.71212495202346,-1.435983039998934,-0.04401977833954618
386.8000000000049,44.84835459621218,-1.4384276185457014,-0.044015039027170744
388.20000000000493,44.98340887787677,-1.4403001692397748,-0.04402336446378108
389.60000000000497,45.12023836186283,-1.439794267716928,-0.04504501189283161
391.000000000005,45.259070179891424,-1.4410068844342514,-0.04598987738699556
392.400000000005,45.39569271720722,-1.44173655695787,-0.04599003702963156
393.800000000005,45.53255177161109,-1.4444570722284111,-0.04598753313702897
395.20000000000505,45.66947077570742,-1.4440096875658543,-0.04600003509685724
396.600000000005,45.80563705711895,-1.4455246241260729,-0.0472470116789534
398.00000000000506,45.94208664583995,-1.4463727328846872,-0.04862935100928745
399.4000000000051,46.079752704932346,-1.449386201236281,-0.04863678864785648
400.8000000000051,46.21597575425789,-1.4503258820819258,-0.046329979485352446
402.20000000000516,46.35135199409869,-1.4549669491533646,-0.04533319829733262
403.60000000000514,46.49048273480672,-1.457178483646262,-0.047970287750422
405.0000000000052,46.62765041440767,-1.4597929226277448,-0.0492251626409983
406.4000000000052,46.76459248553952,-1.4656549612070786,-0.04797000499185078
407.8000000000052,46.89797276312899,-1.4688639293560775,-0.04797028267077508
409.2000000000052,47.03684281396935,-1.4714572103615031,-0.04665000558916965
410.60000000000525,47.17155010060331,-1.4733515173201723,-0.046650010024706035
412.0000000000053,47.31137104576625,-1.475247838956666,-0.049344685973773394
413.4000000000053,47.44998368326969,-1.4758441572665577,-0.04927753038036453
414.8000000000053,47.5861581667929,-1.4771581632245707,-0.05060220202426002
416.20000000000533,47.72364874324831,-1.4752339486092518,-0.050618122358230266
417.60000000000537,47.860028135567454,-1.476946761524867,-0.049179769842268684
419.00000000000534,47.9976718081193,-1.4781115156330866,-0.04787475823001852
420.4000000000054,48.13472736728562,-1.4767786871133635,-0.04983980840644442
421.8000000000054,48.27116245153446,-1.478882046075561,-0.051151463219949456
423.20000000000545,48.40926380528234,-1.4791431877748364,-0.04983980382215414
424.6000000000055,48.5452099594426,-1.4818124654963793,-0.04956138891443018
426.00000000000546,48.68316458238679,-1.4844123097614317,-0.04922783369763195
427.4000000000055,48.819359120747414,-1.485209531056054,-0.05148254272773389
428.8000000000055,48.95741204474009,-1.4867813009060724,-0.050506437004433025
430.2000000000055,49.09449454425643,-1.4874053983891349,-0.05180994604114986
431.60000000000554,49.23241144238791,-1.4892901497886863,-0.051828342966040886
433.00000000000557,49.36997887355387,-1.4944331157111879,-0.051479917998485725
434.4000000000056,49.506620290728144,-1.4938667505417575,-0.05147991835064847
435.80000000000564,49.643988157041086,-1.4972774623803513,-0.05280255449274929
437.2000000000056,49.78149574390115,-1.499597511677238,-0.05279981900003161
438.60000000000565,49.91876559853635,-1.5042934425222296,-0.052799821120978585
440.0000000000057,50.05784292331384,-1.5045232430381152,-0.05379001603985323
441.40000000000566,50.19467134078753,-1.5070996468217621,-0.05224202632057384
442.8000000000057,50.33248424812608,-1.512059967585619,-0.0530443185706746
444.20000000000573,50.467089431487295,-1.5121249213665477,-0.05379005000255521
445.60000000000576,50.60767651052372,-1.5161455084551174,-0.053836124232406135
447.0000000000058,50.746214045200055,-1.5192504724914373,-0.054130165141665465
448.4000000000058,50.88496537429436,-1.5177393595329696,-0.054448507641136956
449.8000000000058,51.02235784480973,-1.52077996452614,-0.055759929953106635
451.20000000000584,51.158338132731984,-1.5266709285223807,-0.05442455609705554
452.6000000000058,51.29739253074728,-1.5282481369835597,-0.054439930020303784
454.00000000000585,51.43651597272943,-1.5299799183081653,-0.055787064083087756
455.4000000000059,51.57467395691563,-1.5321105623370466,-0.055759831000441906
456.8000000000059,51.71263369398691,-1.536241542799174,-0.05575981850367029
458.20000000000596,51.85053991921883,-1.5402304013785106,-0.05707914050254104
459.60000000000593,51.98888018031582,-1.5431756197598567,-0.05575610201877712
461.00000000000597,52.12828865048656,-1.5455077932818886,-0.055770252311100776
462.400000000006,52.26611526296312,-1.5475407967062367,-0.05678253148997303
463.800000000006,52.40446784338937,-1.553742026999456,-0.056727685523929594
465.200000000006,52.542347285930326,-1.5570794488553346,-0.05709004000455131
466.60000000000605,52.68128162229044,-1.559970179787279,-0.05709002575239985
468.0000000000061,52.81907194673612,-1.56297052765064,-0.05840017326694724
469.4000000000061,52.95830661465838,-1.5652663174213715,-0.05741939019573117
470.8000000000061,53.09500241195709,-1.5713551365276914,-0.058730238383674305
472.2000000000061,53.23325537998563,-1.5745159482861402,-0.05866625056409713
473.60000000000616,53.3733267979052,-1.5773162355047976,-0.058679709881722
475.00000000000614,53.51164417034415,-1.581415217588968,-0.05938965935446738
476.4000000000062,53.6508852927977,-1.58380378370716,-0.058074409155276285
477.8000000000062,53.78917099622735,-1.5898299536535185,-0.05873003119052278
479.20000000000624,53.927587412875,-1.594735176823212,-0.061384783665083376
480.6000000000063,54.06636362324002,-1.5979213077113807,-0.06063525122717284
482.00000000000625,54.20484192541073,-1.5990322762180895,-0.06069989298355338
483.4000000000063,54.34370300978885,-1.6007873699841548,-0.06333956885759662
484.8000000000063,54.48232791394169,-1.6039560909916775,-0.06202322620911804
486.2000000000063,54.6192719147047,-1.60824643167568,-0.06334000044989985
487.60000000000633,54.75976228013085,-1.6092421242080268,-0.06271603083132504
489.00000000000637,54.89866627060542,-1.611880014448911,-0.06400461868538176
490.4000000000064,55.03717771608013,-1.615111951671217,-0.0646189785606861
491.80000000000643,55.17635048971647,-1.6193904237575714,-0.06463115038529477
493.2000000000064,55.31507023309042,-1.617783456385604,-0.06488029766353165
494.60000000000645,55.45387088509416,-1.6199498096317817,-0.06465017102853032
496.0000000000065,55.59318386545889,-1.6234103288962374,-0.06564061607574612
497.40000000000646,55.731899438320866,-1.6247192747624708,-0.06596007921198854
498.8000000000065,55.87006455121587,-1.6275098049363064,-0.06597996400081563
500.2000000000065,56.010216302199666,-1.6300882469424898,-0.06696997744989375
501.60000000000656,56.14740370320914,-1.6315970181772876,-0.06630306420474419
503.0000000000066,56.288247748237104,-1.6342438154762315,-0.0676298788165095
504.40000000000657,56.42830563881083,-1.6376527702500494,-0.06860840958657732
505.8000000000066,56.56795856585551,-1.6389569983510883,-0.06992353054686529
507.20000000000664,56.70626012189398,-1.6401102644407608,-0.06997626222285813
508.6000000000066,56.846230506201536,-1.6452323248455012,-0.0702934108430866
510.00000000000665,56.98510877088844,-1.6493043018631894,-0.07087068349347758
511.4000000000067,57.12398199973044,-1.6525797986894022,-0.071303091819924
512.8000000000068,57.2645663919092,-1.6550948295864436,-0.06860954226519844
514.2000000000068,57.40406008201752,-1.6571239500671966,-0.07066766037959438
515.6000000000067,57.54310056255923,-1.6599044810241752,-0.07123994596434269
517.0000000000068,57.68287962747962,-1.6658771625038318,-0.0699215142710381
518.4000000000068,57.82219516503187,-1.6680447134722163,-0.07135509931167228
519.8000000000068,57.962245229329554,-1.67116091141419,-0.07365147447667963
521.2000000000069,58.10123579732486,-1.6716453972789906,-0.0726701059721333
522.6000000000068,58.240560480553604,-1.6759247834057232,-0.07501007741101473
524.0000000000068,58.379774577730046,-1.677971170135204,-0.07537639180848243
525.4000000000069,58.519365488360535,-1.682035714078676,-0.0733292858800847
526.8000000000069,58.65907222753266,-1.6873499207688278,-0.07332740077245736
528.2000000000069,58.797933579245736,-1.6897966781939566,-0.07464995537558883
529.600000000007,58.938113839438394,-1.6947132060794527,-0.07528066735388217
531.0000000000069,59.07851908848658,-1.6984430193897677,-0.07727999134110464
532.4000000000069,59.21601764183413,-1.7026124317092723,-0.07846788499312352
533.800000000007,59.358647314477714,-1.7068666088232813,-0.078599889706636
535.2000000000071,59.4990682810134,-1.7102471240555153,-0.07990586287447465
536.6000000000071,59.63848157546451,-1.7168908594291694,-0.08022997701016488
538.000000000007,59.77917000000071,-1.718909999999981,-0.07991992005768855
539.4000000000071,59.91906729166469,-1.7250638531580993,-0.08123982174172184
540.8000000000071,60.05947258159603,-1.7276940817554058,-0.07987486998617932
542.2000000000071,60.199169058712855,-1.7318898442126003,-0.08222972343275048
543.6000000000072,60.33946187135487,-1.7363287617200835,-0.08320209328218864
545.0000000000072,60.48092363725274,-1.7418138975533604,-0.08323808717390913
546.4000000000071,60.621088146040556,-1.743188377686342,-0.08427691999866838
547.8000000000072,60.76168703378274,-1.7499324594153929,-0.08353966089015863
549.2000000000072,60.902344480626724,-1.755043529643245,-0.08452515794554039
550.6000000000072,61.04177278210774,-1.7561163339233858,-0.08352402641996015
552.0000000000073,61.18159401100568,-1.7622510170947232,-0.08583999286870103
553.4000000000073,61.32271568842378,-1.768788034021675,-0.08715986875013249
554.8000000000073,61.459797383030086,-1.7694432961718316,-0.0871597412157441
556.2000000000073,61.602238227696695,-1.7734934025699853,-0.0894687267612202
557.6000000000073,61.74218820131591,-1.777966412927785,-0.08946981075715232
559.0000000000074,61.88266076232872,-1.781978835470833,-0.09078019227876588
560.4000000000074,62.02335002143163,-1.786591048449239,-0.09078019188255748
561.8000000000075,62.16339696771291,-1.789573753433037,-0.09078568409479137
563.2000000000074,62.30321223685472,-1.7921025247778133,-0.09150199892471012
564.6000000000074,62.443981960927594,-1.797486779571537,-0.09473947422596529
566.0000000000075,62.58283051055699,-1.8017984096611126,-0.09506475817708537
567.4000000000075,62.724603083172596,-1.8052077474204675,-0.09466189461576135
568.8000000000075,62.86468342316761,-1.8063631656950216,-0.09539993004069558
570.2000000000075,63.00498587015116,-1.8138786852806357,-0.09672555782182579
571.6000000000075,63.14591566621508,-1.8198059316620319,-0.09680245433822376
573.0000000000075,63.28439455443055,-1.8248165139008037,-0.09606093496747015
574.4000000000076,63.427820112870364,-1.8320753486187173,-0.09869073074979262
575.8000000000076,63.5681909116159,-1.8353030252946498,-0.1000108882718056
577.2000000000077,63.70863880028182,-1.8392134951800934,-0.10066310706748638
578.6000000000076,63.84895712989294,-1.8417510557483272,-0.10132998916391145
580.0000000000076,63.9892838352436,-1.8430727989817048,-0.10264044693361152
581.4000000000077,64.13116859340471,-1.8481365919455068,-0.10395977266316025
582.8000000000077,64.27115379883134,-1.8502506031755237,-0.1052803646512106
584.2000000000078,64.41369773977488,-1.8533854519581063,-0.10527613708386507
585.6000000000078,64.55347798270495,-1.8561005600932639,-0.10657498057287418
587.0000000000077,64.69485507330592,-1.86093293707555,-0.10750395187896622
588.4000000000078,64.83515150911582,-1.8639498242695178,-0.10922939131551423
589.8000000000078,64.97481692845179,-1.8644516647660994,-0.10914967063552217
591.2000000000078,65.11659123061473,-1.866262471405426,-0.11071007146173795
592.6000000000079,65.25765075976261,-1.8672933323990653,-0.11186078613279005
594.0000000000078,65.39611781311754,-1.8692793639160172,-0.11186008736285569
595.4000000000078,65.5382570425714,-1.873538108916883,-0.11317414319079644
596.8000000000079,65.67829427385689,-1.878280301462788,-0.11670683058876508
598.2000000000079,65.81887590740254,-1.8801908178109368,-0.11645790197618355
599.600000000008,65.95937223196601,-1.8854158592183456,-0.11712992220411422
601.000000000008,66.09782265768857,-1.888846088514456,-0.11845276204346478
602.4000000000079,66.24045108842402,-1.8939807153242163,-0.11878548485781426
603.800000000008,66.38065056757053,-1.8949655986561962,-0.12009985897962405
605.200000000008,66.5220635203921,-1.898811998705114,-0.12140278499420232
606.6000000000081,66.66324335387029,-1.9043571207024972,-0.12241036812888018
608.0000000000081,66.80307660603587,-1.907107100777166,-0.12371955474895513
609.400000000008,66.94458256416341,-1.91237574990476,-0.12503990453934044
610.8000000000081,67.08506680377342,-1.9171445632913224,-0.1263565113305649
612.2000000000081,67.22644505122818,-1.9227789381133449,-0.12755038907466343
613.6000000000081,67.36586892171819,-1.9272802363760582,-0.1270389777096348
615.0000000000082,67.50855549815881,-1.9330248148545937,-0.1283436576068282
616.4000000000082,67.64916800613244,-1.939759997543002,-0.12800110157203415
617.8000000000081,67.78994097662071,-1.9487167835749009,-0.13195222125223616
619.2000000000082,67.93067475260258,-1.9535058235419578,-0.13205197965339988
620.6000000000082,68.0715367796903,-1.9590254734929717,-0.13459026670095398
622.0000000000083,68.21175426962832,-1.9695481375073178,-0.13517079644452812
623.4000000000083,68.35291535561522,-1.9757056066949612,-0.13624029236515955
624.8000000000083,68.4927073457824,-1.9847496207507844,-0.13917676876163254
626.2000000000083,68.63404618856761,-1.9933513556156957,-0.13913138168824224
627.6000000000083,68.77551978517641,-2.001984112759936,-0.14216252708692068
629.0000000000084,68.91466136204825,-2.013527474107097,-0.14349199529090306
630.4000000000084,69.05653727828471,-2.021157555989081,-0.14480631583635262
631.8000000000084,69.19992448630757,-2.0336042164863044,-0.1461199380125131
633.2000000000085,69.3404241467523,-2.0449209181820964,-0.14748733244208267
634.6000000000084,69.4823198358142,-2.0567058824879165,-0.150070654339316
636.0000000000084,69.6244329005542,-2.069086707057692,-0.1516153935841853
637.4000000000085,69.76643172947234,-2.0782997273725883,-0.1546792856314565
638.8000000000085,69.9077802156712,-2.0922945323945803,-0.15541202370479246
640.2000000000085,70.04928737333948,-2.1048367021135777,-0.1579705853095832
641.6000000000085,70.19055234531339,-2.117955540946032,-0.15970008872473596
643.0000000000085,70.33282403137194,-2.129084156177289,-0.16225102992805018
644.4000000000086,70.47498077642402,-2.143620662817603,-0.16751757800265032
645.8000000000086,70.61611991441636,-2.155192037760108,-0.1688443304216607
647.2000000000086,70.75896817211134,-2.169607043689125,-0.1714832179552186
648.6000000000087,70.89837020597416,-2.180720360168909,-0.17222649856402317
650.0000000000086,71.04176111695705,-2.196914472528738,-0.17478985065093022
651.4000000000087,71.18470879560802,-2.2106718568478803,-0.18026562300213556
652.8000000000087,71.32612381278037,-2.225627663646027,-0.18291663563641158
654.2000000000087,71.46877522917161,-2.239530607828715,-0.18593697725412195
655.6000000000088,71.61211332874025,-2.2550132225093646,-0.18833486331753369
657.0000000000088,71.7530181659324,-2.27325116031119,-0.19362137677003588
658.4000000000087,71.89508713049084,-2.286317434973633,-0.1958828145198428
659.8000000000088,72.03956421084348,-2.303303114963058,-0.2004485584365976
661.2000000000088,72.18191796897996,-2.324128521398243,-0.20319890662658624
662.6000000000088,72.32395777727336,-2.340779738520335,-0.20728347937577674
664.0000000000089,72.46660775561658,-2.3607445329335164,-0.2114577278293921
665.4000000000088,72.6089689268818,-2.3787695327221403,-0.21570160605802302
666.8000000000089,72.75103689004652,-2.3999705707962984,-0.2197607333937115
668.2000000000089,72.89401546482917,-2.4203897162357055,-0.22510559724309465
669.6000000000089,73.03562246540498,-2.442450213391458,-0.23106452088904827
671.000000000009,73.17782539030556,-2.4654236719537495,-0.2351041022134388
672.400000000009,73.31832848597033,-2.4850146958473873,-0.24079772283414913
673.800000000009,73.46147423851473,-2.5130617330261735,-0.2449613734528695
675.200000000009,73.60377244867382,-2.5311955788545686,-0.2519274198898014
676.600000000009,73.74684368660714,-2.561924850462717,-0.25618537136275643
678.0000000000091,73.88886004467729,-2.5889596185155392,-0.26257668970985204
679.4000000000091,74.03065320603352,-2.6124938302186793,-0.270216511708413
680.800000000009,74.17269461477837,-2.639265504899908,-0.2766900539449728
682.2000000000091,74.31428580583284,-2.670971285372879,-0.2819201780663154
683.6000000000091,74.45659307691365,-2.699749535729528,-0.2892674331713039
685.0000000000091,74.59926888733666,-2.732406720583668,-0.29707306664714306
686.4000000000092,74.74123540681532,-2.7651146415681445,-0.3056819342426693
687.8000000000092,74.88438744562248,-2.803925194213442,-0.3121342278814061
689.2000000000093,75.0268805617404,-2.8374612112301527,-0.32018300621064366
690.6000000000092,75.17076644946263,-2.8785563669063454,-0.32896181607074393
692.0000000000092,75.31292081398857,-2.919851189257928,-0.33651611163304285
693.4000000000093,75.45625978470846,-2.9586169048676147,-0.346040771645888
694.8000000000093,75.60028627522858,-3.0031838206192263,-0.35665849088816115
696.2000000000094,75.74389483134097,-3.0486257610814707,-0.3680182177896154
697.6000000000093,75.88683624478654,-3.092153697031387,-0.37978367619696174
699.0000000000093,76.03093632568277,-3.1400166488135475,-0.39049500013780314
700.4000000000094,76.17423366565512,-3.187184231159666,-0.4013519158288772
701.8000000000094,76.31870307155673,-3.237286927795824,-0.41065089372200925
703.2000000000094,76.46052227654341,-3.289173645245767,-0.4238028120835642
704.6000000000095,76.60402928951254,-3.3386717067914335,-0.4383259285386818
706.0000000000094,76.74718615698211,-3.3928305453730356,-0.45362844717768036
707.4000000000094,76.89191852898799,-3.4523807862009375,-0.46265829664271463
708.8000000000095,77.03503140470843,-3.511617675640365,-0.4748311994121934
710.2000000000095,77.17916905763161,-3.5728095574795464,-0.48687055993513795
711.6000000000096,77.32340502789454,-3.634583602070157,-0.496700627065652
713.0000000000095,77.46774378990253,-3.698316563116027,-0.5199188400206358
714.4000000000095,77.61167324341643,-3.763546807503999,-0.5369979088438828
715.8000000000096,77.75626756944192,-3.8283875715581317,-0.5560691855153279
717.2000000000096,77.90080708773083,-3.9001664998336407,-0.5755392368336425
718.6000000000097,78.0452612209593,-3.9698525897869725,-0.5931848104797108
720.0000000000097,78.19002145157016,-4.037931988375325,-0.6124318916665898
721.4000000000096,78.33356817418183,-4.110268869902119,-0.6314967725929197
722.8000000000097,78.47747438182907,-4.18051933882656,-0.6530487666428728
724.2000000000097,78.62192117617712,-4.256338607586908,-0.6735419251598325
725.6000000000097,78.76737317938411,-4.333208757581723,-0.6969956863690685
727.0000000000098,78.91155572432058,-4.410400889819582,-0.7192449440981665
728.4000000000098,79.05648347003002,-4.487926494432301,-0.7418911851560579
729.8000000000097,79.20103879562286,-4.567493941655366,-0.7657404523291835
731.2000000000098,79.34575769239609,-4.642129998467897,-0.7922605299568706
732.6000000000098,79.48986733884652,-4.718902893977496,-0.8159411173658682
734.0000000000099,79.63431971136552,-4.79203439163063,-0.8419709307586554
735.4000000000099,79.77792728660329,-4.865366035366028,-0.867886949394336
736.8000000000098,79.92259116322386,-4.935620246752229,-0.8979281707188376
738.2000000000099,80.067424710695,-5.000829488825988,-0.9243027098048118
739.6000000000099,80.21151461464993,-5.061402736031635,-0.952246927961939
741.00000000001,80.35530773978486,-5.116826528903501,-0.9821250653087064
742.40000000001,80.49937327137707,-5.16227940805671,-1.0120816257353842
743.80000000001,80.64262553722531,-5.194250166708815,-1.045028296877422
745.20000000001,80.78570070563342,-5.215803449653794,-1.0739232233141869
746.60000000001,80.92847506208044,-5.220373368060357,-1.102480948046602
748.00000000001,81.07076430536723,-5.202157273847049,-1.131445822566583
749.4000000000101,81.21229109582767,-5.161723821026892,-1.1603899751044806
750.8000000000101,81.35204109110224,-5.084106324494573,-1.1900895449069528
752.20000000001,81.49120761952675,-4.97251077513657,-1.2184282458053222
753.6000000000101,81.62978035374687,-4.814518097023807,-1.242498540568794
755.0000000000101,81.76677889169171,-4.6010929378637435,-1.2673046180692507
756.4000000000102,81.90204601975965,-4.296852234078551,-1.2897196270759004
757.8000000000102,82.03339484982233,-3.8810652381300836,-1.3060577016925428
759.2000000000102,82.16144728320845,-3.345616965201319,-1.3193136514779642
760.6000000000103,82.2913912668022,-2.7870799932852797,-1.3263407847072508
762.0000000000102,82.42262820415897,-2.4246888731150222,-1.3305772749350524
763.4000000000103,82.56159204299684,-2.2575921935013024,-1.334607494162103
764.8000000000103,82.70307966146929,-2.202450236619088,-1.3358407557320082
766.2000000000103,82.8481277777903,-2.196478937944083,-1.3358157167366977
767.6000000000104,82.99105522363064,-2.1990495666195393,-1.3351799286158745
769.0000000000103,83.1334946718141,-2.206507645725848,-1.3345395078583846
770.4000000000103,83.27725912364951,-2.2077177722426784,-1.3345198962734575
771.8000000000104,83.42149373650193,-2.208335600605436,-1.3358390159334763
773.2000000000104,83.56403890124841,-2.212678141616199,-1.335697548648374
774.6000000000104,83.70730496395768,-2.217673010994207,-1.3345195918477306
776.0000000000105,83.85047602435115,-2.222483089728635,-1.3371601195440226
777.4000000000104,83.99424581856636,-2.2289938709600317,-1.3357698069112574
778.8000000000105,84.13720003787057,-2.2341569262306824,-1.3363865591547932
780.2000000000105,84.28017505965295,-2.2366386389181603,-1.33716014133278
781.6000000000105,84.42407012533896,-2.2443242474544105,-1.338479135331939
783.0000000000106,84.5678357104922,-2.2486840069196026,-1.3384969792310395
784.4000000000106,84.70916786219806,-2.2527801525365057,-1.337150077399583
785.8000000000106,84.85348636470759,-2.256453857375324,-1.3384700391646684
787.2000000000106,84.99682941516903,-2.2634308349485974,-1.3371494378052629
788.6000000000106,85.1405350311069,-2.2688269064759456,-1.3371413967084993
790.0000000000107,85.28319882209719,-2.2740715325481506,-1.33912870904921
791.4000000000107,85.42599105251324,-2.280719711644351,-1.3383246607065908
792.8000000000106,85.57090395596094,-2.2875151932669384,-1.3384619323394755
794.2000000000107,85.71540126327525,-2.291664657149232,-1.3388817624763454
795.6000000000107,85.85852659295617,-2.298879872356119,-1.3411097335219475
797.0000000000107,86.0018935260498,-2.3045849612827394,-1.3402355257573828
798.4000000000108,86.14582758259435,-2.3087320505746898,-1.3397999016986968
799.8000000000108,86.28875208483801,-2.3147941110579753,-1.340421785160701
801.2000000000108,86.43219366989224,-2.321080754391689,-1.3407801061237348
802.6000000000108,86.57582092964945,-2.3250896835946877,-1.3407958821238575
804.0000000000108,86.71823390500413,-2.3281098357204435,-1.340780104735014
805.4000000000109,86.8614537985088,-2.3295247484553037,-1.3407801069998424
806.8000000000109,87.00487501676727,-2.335827045836718,-1.3407427313706775
808.200000000011,87.14715725096927,-2.344086750105835,-1.3420997545492215
809.6000000000109,87.29222057141861,-2.3504931649730594,-1.3423887688860456
811.0000000000109,87.43445491686911,-2.3536067080441585,-1.340120031050028
812.400000000011,87.57825585040281,-2.36132108201558,-1.34201383586102
813.800000000011,87.72203375746685,-2.360488389019737,-1.3427563490160108
815.200000000011,87.86532998442576,-2.368758024099211,-1.3427422431501679
816.600000000011,88.01077993265673,-2.371317323119537,-1.342760783331677
818.000000000011,88.15461807307102,-2.3810290891383747,-1.3427615004138276
819.400000000011,88.29804731673964,-2.3870841186615377,-1.3443146530505268
820.8000000000111,88.4428848166478,-2.3909350053457863,-1.3441401566118931
822.2000000000111,88.5860322189454,-2.3928534307633447,-1.346707714882918
823.6000000000112,88.728790020403,-2.3928813867456578,-1.3454016317215811
825.0000000000111,88.87306652377673,-2.396845618184361,-1.3470592675148536
826.4000000000111,89.01580768351975,-2.4032105961876282,-1.3467768406994138
827.8000000000112,89.16018787462332,-2.409678295867936,-1.3454155549249949
829.2000000000112,89.30435988640126,-2.407086001455234,-1.346710321578231
830.6000000000113,89.44844022081301,-2.408412078456886,-1.346709934593941
832.0000000000113,89.59177058937013,-2.4102975210089093,-1.347360643505561
833.4000000000112,89.73511001827234,-2.4161912537363484,-1.3500010193007124
834.8000000000113,89.87959610171943,-2.4199440415467017,-1.3499999647927559
836.2000000000113,90.02395105726568,-2.424903314226598,-1.3490509221534341
837.6000000000113,90.16869950680127,-2.4285516873905046,-1.348345284843321
839.0000000000114,90.31304045019561,-2.4324539312195315,-1.3499992298264951
840.4000000000113,90.45764755295289,-2.439006197303275,-1.3486901754903426
841.8000000000113,90.60124564579185,-2.4477511371826393,-1.349297589740409
843.2000000000114,90.74526096135624,-2.4541832122251668,-1.3506532734772003
844.6000000000114,90.88926636080471,-2.456737308505985,-1.3506563151633624
846.0000000000115,91.03331842826807,-2.464770689249932,-1.350655192725001
847.4000000000115,91.17697037299219,-2.4677436752338893,-1.3516713231529867
848.8000000000114,91.31997665636256,-2.472912625903405,-1.3516500302963244
850.2000000000115,91.4633519795538,-2.48059081900358,-1.3507050153228164
851.6000000000115,91.60642011531037,-2.482921097726814,-1.3506598721645564
853.0000000000116,91.74968876342558,-2.4909471586500875,-1.3506581510598754
854.4000000000116,91.89136575762214,-2.495017378455146,-1.3506600997653098
855.8000000000116,92.03548653205492,-2.5033401420277968,-1.3506625362187696
857.2000000000116,92.17773202694512,-2.505347960931098,-1.3532888735637232
858.6000000000116,92.32379728250329,-2.5125655665708027,-1.3532900502976024
860.0000000000116,92.46676507449801,-2.520186070257086,-1.3552726850694015
861.4000000000117,92.61114184690888,-2.5236781640685755,-1.3552808748975518
862.8000000000117,92.75293533425696,-2.5278718588656366,-1.3552798485450768
864.2000000000116,92.89806312298347,-2.534502406574929,-1.3552798864188835
865.6000000000117,93.0424793082127,-2.5423125135777567,-1.355285447744314
867.0000000000117,93.18583361216105,-2.5447306703290975,-1.3552698350444685
868.4000000000118,93.32927720545858,-2.5463087754693516,-1.3559302447300832
869.8000000000118,93.47390190424801,-2.5537713999255667,-1.3553102024265695
871.2000000000118,93.61854741721066,-2.5555590224810723,-1.3565325325617823
872.6000000000118,93.76118795797207,-2.5611095011444753,-1.3595683410806871
874.0000000000118,93.90587910658358,-2.5645273857926765,-1.356920588203304
875.4000000000119,94.0493908157646,-2.5734566881658627,-1.358230069946523
876.8000000000119,94.19393112323563,-2.581837293199198,-1.36086681142107
878.2000000000119,94.33788330553857,-2.585264853825015,-1.3596600749452148
879.600000000012,94.48040881492625,-2.5912565350264196,-1.359988453891142
881.0000000000119,94.62294990688869,-2.5940785762242973,-1.3593301253804335
882.4000000000119,94.76875746691424,-2.5951930660655633,-1.3603206165042026
883.800000000012,94.91099646372787,-2.6014693656198555,-1.3590100259983422
885.200000000012,95.05666858371717,-2.604445700945332,-1.3599069749470543
886.600000000012,95.2009013676584,-2.6090332878041265,-1.3589573660661607
888.000000000012,95.34358679262985,-2.613846540689714,-1.3616400613402653
889.400000000012,95.48837054401082,-2.6226259880315514,-1.3603200382917442
890.8000000000121,95.63216352698701,-2.629667164107243,-1.3612620669435902
892.2000000000121,95.7764218627731,-2.637647646164582,-1.3622999150857193
893.6000000000121,95.9211925520212,-2.6440175398757297,-1.3629549210100849
894.0000000000122,95.96171078290112,-2.647511516921331,-1.362959836128987