File: 01_Data/Cinder_Block/STA/N2/10K_min/Cinder_Block_STA_N2_10KData_230920_R2.csv
##Temp./Â°C,Time/min,DSC/(mW/mg),Mass loss/mg
41.0,10.810497362272242,-2.3731583873865727,0.008430890234359278
42.40000000000002,11.165319976426382,-2.30755511748069,0.005918061695199928
43.80000000000004,11.409814135600799,-2.2662426165617027,0.005076009761270761
45.20000000000006,11.615881572930407,-2.235222716410627,0.00535803942048485
46.60000000000008,11.805200354165592,-2.2086599711896393,0.005421296572502232
48.0000000000001,11.980648004883038,-2.1857936706086085,0.004723063181080622
49.40000000000012,12.147191873309662,-2.1705605939724912,0.005043672149852796
50.80000000000014,12.310381073630483,-2.1545938571951004,0.005336826056559829
52.20000000000016,12.468237230962819,-2.1438334748524968,0.00449179940561617
53.60000000000018,12.624903911746484,-2.1325929990633354,0.004996360466366756
55.0000000000002,12.77955903919819,-2.1237877362928996,0.0042086129022278485
56.40000000000022,12.93408646260602,-2.1164654185001255,0.004881447934125482
57.80000000000024,13.084633655576663,-2.107885510227259,0.0035087990379563117
59.20000000000026,13.235007577071519,-2.104601323250601,0.0034845597693609065
60.60000000000028,13.38581457840458,-2.0961726530079208,0.0035579622662735844
62.0000000000003,13.533338408789913,-2.0893409039696396,0.003509124307895739
63.40000000000032,13.6803525602785,-2.0835955646170157,0.0027030613308625107
64.80000000000034,13.828581063708135,-2.077959579326708,0.0048319554272375775
66.20000000000036,13.974473272272983,-2.071644581436265,0.0032271680885398446
67.60000000000038,14.119670864290542,-2.065261161706794,0.003228065827717952
69.0000000000004,14.264074627938303,-2.061858228931797,0.0028867855078953397
70.40000000000042,14.408753285211702,-2.053145091457471,0.0018763953239555597
71.80000000000044,14.552330423109902,-2.048791287929256,0.002777202772004106
73.20000000000046,14.694731631810775,-2.0418759265690514,0.0022370824170132586
74.60000000000048,14.836414594757901,-2.03601662406548,0.0015376092251768725
76.0000000000005,14.978895851296205,-2.032841143991752,0.0008800616955872975
77.40000000000052,15.121797816993988,-2.0260602923596314,-0.00043971529278952204
78.80000000000054,15.26306769323266,-2.0203341215906363,0.0008799676166755255
80.20000000000056,15.403477855725173,-2.013372031018298,0.00087973338930869
81.60000000000058,15.544532651630787,-2.0084795347958955,4.1329185493488296e-05
83.0000000000006,15.682782664872507,-2.0031390000007363,0.0008022670120966247
84.40000000000062,15.822198217094028,-1.9967937243734002,-0.0007555720078160633
85.80000000000064,15.96071116929036,-1.9914229514184993,-0.0010837965722592102
87.20000000000066,16.10005319634943,-1.9864861792947082,-0.0023901973490740858
88.60000000000068,16.238403521832375,-1.979811082465386,-0.0017503128507665444
90.0000000000007,16.375976448435956,-1.9759636357931156,-0.00042140542041613216
91.40000000000072,16.514681679342516,-1.9689531444113857,-0.0010999733645653542
92.80000000000074,16.651852529759342,-1.964841262107322,-0.002420132722435575
94.20000000000076,16.788091275362945,-1.9608166453240887,-0.002376701358666189
95.60000000000078,16.925264504234093,-1.95365427502269,-0.0024097734349570743
97.0000000000008,17.06263842873712,-1.9508090574000059,-0.0023117511456085538
98.40000000000082,17.19854173867002,-1.944061818621123,-0.0024079262715979155
99.80000000000084,17.335301506816293,-1.9394351635239842,-0.0036919632634968558
101.20000000000086,17.47264257232001,-1.9353599680954243,-0.003740039618421509
102.60000000000088,17.609062311464097,-1.9273265824919439,-0.0037393455416205867
104.0000000000009,17.744136117981796,-1.9229384542595342,-0.004537821960317157
105.40000000000092,17.880343956213245,-1.9179110053752895,-0.003710886163909688
106.80000000000094,18.016272421392074,-1.9148540753210446,-0.006040033935987843
108.20000000000095,18.152175015229812,-1.9087364478218811,-0.004720152009829004
109.60000000000097,18.28908151843082,-1.9032274846391515,-0.0060420614203824385
111.000000000001,18.424310141667856,-1.8985683455757345,-0.004719879051537923
112.40000000000101,18.55763681118852,-1.89428306120269,-0.004733498903274125
113.80000000000103,18.696020941337462,-1.8880299635316897,-0.00604036973105293
115.20000000000105,18.83085814255958,-1.8832519106752887,-0.006029863831622961
116.60000000000107,18.9667475988323,-1.8786665242728582,-0.007340747190428765
118.0000000000011,19.098184176156227,-1.8739132025854985,-0.007020082000404937
119.40000000000111,19.23806061370896,-1.8685314605685452,-0.00643467083853233
120.80000000000113,19.37160755341225,-1.8659013157307986,-0.007690042993556023
122.20000000000115,19.506416456109946,-1.8606316525087352,-0.007690154979232311
123.60000000000117,19.641068170981672,-1.856736469057925,-0.008680007597860584
125.0000000000012,19.775630408667425,-1.851717121428292,-0.008652133598168188
126.40000000000121,19.911586031164248,-1.8488069660402198,-0.0086701780006746
127.80000000000123,20.045059070115073,-1.8438950944422627,-0.00868128363101306
129.20000000000124,20.1800112051679,-1.8415096949655252,-0.008009256943341647
130.60000000000127,20.31423331022487,-1.836320738851666,-0.008059877086993072
132.0000000000013,20.449170000000123,-1.8341400000000017,-0.00920420577610015
133.4000000000013,20.58286292450751,-1.8293730828440695,-0.008999892464740533
134.80000000000132,20.71641031396192,-1.8255341917192627,-0.009899473157737315
136.20000000000135,20.851899440649845,-1.8212003687818763,-0.009000074729347496
137.6000000000014,20.9864122582481,-1.817745425402088,-0.010311896716641122
139.0000000000014,21.121410656925253,-1.8138024197846108,-0.010309993981173715
140.4000000000014,21.25452962374314,-1.8083009856665664,-0.01163397315972059
141.80000000000143,21.388726972097267,-1.805023650840904,-0.011629995021683381
143.20000000000147,21.52185425778672,-1.802754707786921,-0.010331082655321566
144.60000000000147,21.65585211325607,-1.7994601506023629,-0.010980086736539718
146.00000000000148,21.78999951415017,-1.7962074923483033,-0.010980078187110998
147.4000000000015,21.922568370731074,-1.792799291249647,-0.009643899835588332
148.80000000000155,22.057204466595323,-1.788895548177719,-0.010988766499735458
150.20000000000155,22.191441241520305,-1.7849877689834954,-0.01229849915347403
151.60000000000156,22.324736577614104,-1.7822845123609306,-0.011640192785117964
153.0000000000016,22.458491658127656,-1.7801461871796072,-0.01164018600357375
154.40000000000163,22.59280678175273,-1.776949892087585,-0.010898825482178687
155.80000000000163,22.726076590637938,-1.7743330548972438,-0.012343925235627662
157.20000000000164,22.860169456881117,-1.7713253187203755,-0.011548214782305166
158.60000000000167,22.994224918480658,-1.765644832336633,-0.01196484588209712
160.0000000000017,23.127479848595307,-1.7633401337742205,-0.011959947233041834
161.4000000000017,23.261876533530703,-1.7611692813821154,-0.011319459107942187
162.80000000000172,23.39452700326663,-1.7567767496180353,-0.012950035894336853
164.20000000000175,23.529068261814444,-1.7536438841786604,-0.012950002999999377
165.60000000000178,23.661761934812322,-1.7508595478307891,-0.012949999218016206
167.0000000000018,23.796534169650396,-1.7475476178183111,-0.012299808917038746
168.4000000000018,23.928998196918723,-1.7445787673972346,-0.013620033051592983
169.80000000000183,24.062664383668576,-1.7410923063766528,-0.01293635760084344
171.20000000000186,24.194944923534624,-1.739027466758664,-0.01328624512580312
172.60000000000187,24.330125981946043,-1.7363025516074877,-0.011960850482970908
174.00000000000188,24.46206360816429,-1.7327431645142402,-0.013280140418005626
175.4000000000019,24.597249023035154,-1.7312048462081864,-0.014599079685362781
176.80000000000194,24.727845512679494,-1.728447080197336,-0.013381871624626562
178.20000000000195,24.863171384157926,-1.7267899161229436,-0.0142696666838793
179.60000000000196,24.994080388136098,-1.7249123887064637,-0.013280463218449778
181.000000000002,25.12700592221116,-1.7223678503399658,-0.014629011510268963
182.40000000000202,25.262075889280244,-1.7202093189466532,-0.013274330591622974
183.80000000000203,25.39611211178476,-1.7185060765953541,-0.013252127903790711
185.20000000000203,25.527628235484634,-1.7148436315043873,-0.014550503094409528
186.60000000000207,25.661730572146134,-1.712101217119664,-0.01261517178662741
188.0000000000021,25.795478879839344,-1.7096493943649906,-0.013913196381454718
189.4000000000021,25.926758093240284,-1.708238806514075,-0.014930004067633895
190.80000000000211,26.060660432438354,-1.7051369184572625,-0.01361006132067999
192.20000000000215,26.195052725866535,-1.7038613210380853,-0.014929950342195575
193.60000000000218,26.327178074614622,-1.7019807351401899,-0.01459973803349257
195.0000000000022,26.460963769531627,-1.700363996152278,-0.013290044697837011
196.4000000000022,26.594181564808647,-1.6972799187971321,-0.015900202458399626
197.80000000000223,26.725685914576196,-1.6961811498575332,-0.015910438974471752
199.20000000000226,26.859436835814,-1.6933993462427293,-0.014600040154955973
200.60000000000227,26.991854012302518,-1.6919276466154316,-0.014600129206283174
202.00000000000227,27.126029755677184,-1.6910513512781031,-0.01592210851642184
203.4000000000023,27.258573000231486,-1.6878586701287006,-0.014938539380029425
204.80000000000234,27.391268752838933,-1.6849862549284282,-0.016237166666078107
206.20000000000235,27.525067621945027,-1.6831581952911832,-0.015259298167023427
207.60000000000235,27.658330601370988,-1.6824254943942478,-0.016583036506965687
209.0000000000024,27.79127737837384,-1.679273558485663,-0.01783416415396566
210.40000000000242,27.924242522135174,-1.6781329617625098,-0.015590148027546213
211.80000000000243,28.058070553644182,-1.6766677999134365,-0.01691016080011254
213.20000000000243,28.190704997505833,-1.6742289381801934,-0.016910147963110855
214.60000000000247,28.32290175742999,-1.67123828422925,-0.015617115310258
216.0000000000025,28.457078831965216,-1.671540319812277,-0.015919884780438043
217.4000000000025,28.59011216795149,-1.6711111293876837,-0.01592060023245523
218.8000000000025,28.72152806466102,-1.6701323657638272,-0.01689982925326694
220.20000000000255,28.85540906122356,-1.66930857751565,-0.01690761191172685
221.60000000000258,28.986764274084763,-1.6699698359980821,-0.017260693605780197
223.0000000000026,29.120109030410923,-1.670722969345695,-0.016899856815758785
224.4000000000026,29.253236567881856,-1.6675785569334924,-0.01656829946371685
225.80000000000263,29.387666542485125,-1.6681896893082575,-0.01709897557503215
227.20000000000266,29.519740143518238,-1.6672725386138758,-0.01788985700325263
228.60000000000267,29.651919052801187,-1.6667053800502158,-0.017858427749711137
230.00000000000267,29.784989477010686,-1.664899152565097,-0.01727080961252847
231.4000000000027,29.91925997386733,-1.6632563264666373,-0.016899962201077923
232.80000000000274,30.05247222263595,-1.6651880300280224,-0.018220195014091
234.20000000000275,30.18577141240857,-1.6649175668599328,-0.016901737500683467
235.60000000000275,30.318850745194208,-1.6627713444057188,-0.018219964899437002
237.00000000000279,30.45274468005636,-1.662552504903151,-0.018587657548833292
238.40000000000282,30.585700385330096,-1.6621732014284467,-0.01822341050491927
239.80000000000283,30.71887124336094,-1.6608338641806812,-0.019538807274621206
241.20000000000283,30.852213522375,-1.6602744652837251,-0.019560878273914728
242.60000000000286,30.985547644540027,-1.6602877041464719,-0.01887363935261943
244.0000000000029,31.117705819092958,-1.6587839644772084,-0.018878186877320235
245.4000000000029,31.251625078314515,-1.6599934680834874,-0.020199938399924733
246.8000000000029,31.383560239575363,-1.6587098804477591,-0.020195081996068787
248.20000000000294,31.516646352161004,-1.6572433517916798,-0.020846079247907046
249.60000000000298,31.64991982831036,-1.6582292049246763,-0.021237769781304205
251.00000000000298,31.783874000864547,-1.6572891825571918,-0.021509931841805052
252.400000000003,31.917098410531338,-1.6584748443565531,-0.02031056053075364
253.80000000000302,32.04981547203684,-1.6568055016750995,-0.02021152405161475
255.20000000000306,32.182895084177055,-1.6577618703873294,-0.01985999641280456
256.6000000000031,32.31621211009048,-1.6561327090513944,-0.021179961419398374
258.00000000000307,32.44899033587065,-1.6569995201947991,-0.01986581289625411
259.4000000000031,32.58280605354755,-1.6575257200154871,-0.021179991879718862
260.80000000000314,32.71587717505046,-1.657446882553137,-0.021179991999987102
262.2000000000031,32.849541053971315,-1.6577014068867404,-0.02118085011880977
263.60000000000315,32.98239120355534,-1.6571345345790565,-0.022499990911420298
265.0000000000032,33.11586992184432,-1.6566085107869193,-0.020524461804884986
266.4000000000032,33.248525960270854,-1.6557947572225649,-0.0218399917845038
267.80000000000325,33.38358420827309,-1.6571735811459023,-0.022517386551485163
269.20000000000323,33.517790900303105,-1.657048299760353,-0.021190203754472225
270.60000000000326,33.65132822309163,-1.6563698780124827,-0.02250036860463034
272.0000000000033,33.78562023121467,-1.6558754275097334,-0.022355128326115192
273.4000000000033,33.91801868329093,-1.6557001230385953,-0.0208478689314342
274.8000000000033,34.05219421245507,-1.6562597313304357,-0.020534682070144417
276.20000000000334,34.18666290393188,-1.6557743209488303,-0.02218905878628874
277.6000000000034,34.32027606571776,-1.6555039915992553,-0.02119057166270366
279.0000000000034,34.454592545912135,-1.6554672125595706,-0.022509115624302467
280.4000000000034,34.58733929332777,-1.6568099116525012,-0.02251254570107486
281.8000000000034,34.72107260089977,-1.656232875242032,-0.021850028839737412
283.20000000000346,34.85468440278688,-1.6564498784392494,-0.021925077538143434
284.60000000000343,34.98860050002914,-1.657106494182187,-0.0218507067299325
286.00000000000347,35.121157009542344,-1.6579234477940732,-0.02185026662938183
287.4000000000035,35.25523051641005,-1.6584525201243188,-0.02251042784846158
288.80000000000354,35.38877449152729,-1.65851739011057,-0.02251004799411449
290.20000000000357,35.52328349156642,-1.659621341240796,-0.021865483512778727
291.60000000000355,35.65591637110255,-1.6600861103873068,-0.02207257032878207
293.0000000000036,35.79090289215532,-1.6617047401483582,-0.022840075029852525
294.4000000000036,35.92499933118963,-1.6611638004594793,-0.022849303448051028
295.8000000000036,36.05868971798436,-1.6615950765063257,-0.023170048005594968
297.2000000000036,36.19284366307814,-1.6628548780043784,-0.02317004800000122
298.60000000000366,36.32672977685952,-1.6632165194297093,-0.02317004805713685
300.0000000000037,36.461021238048815,-1.6636282673706502,-0.02181437247694351
301.40000000000373,36.59562895887628,-1.664290639406743,-0.023170047724708098
302.8000000000037,36.72945453960477,-1.6640396459201783,-0.023170373680037937
304.20000000000374,36.864069308702284,-1.6663533807369177,-0.023829993865275956
305.6000000000038,36.99880640370464,-1.6682537810319897,-0.023829994592853065
307.00000000000375,37.132827583718345,-1.6694223640803483,-0.022510222634656518
308.4000000000038,37.26707610717573,-1.6697767962120809,-0.023829970048327542
309.8000000000038,37.401585909828555,-1.6695012311917796,-0.0238299939999993
311.20000000000385,37.536009149023585,-1.6715459682207587,-0.02382999401417152
312.6000000000039,37.67071611913498,-1.6726067996170506,-0.02276109380001401
314.00000000000387,37.80503691766597,-1.6732671603438034,-0.02350007495739259
315.4000000000039,37.93917088508566,-1.6757699622332778,-0.02349486660691058
316.80000000000393,38.07434540858983,-1.6734747041322486,-0.02546028893554597
318.2000000000039,38.20860272338044,-1.6761333407981183,-0.023547870035006913
319.60000000000394,38.34119136963182,-1.6753543591066196,-0.02481002099409846
321.000000000004,38.47721018456723,-1.6778768098720287,-0.024810021000000404
322.400000000004,38.611533207058514,-1.6780993716520696,-0.02481002008236821
323.80000000000405,38.74702894580941,-1.6796790151430359,-0.02578497237699029
325.200000000004,38.881723014631426,-1.6805027190301849,-0.025793294875710693
326.60000000000406,39.01604224366723,-1.6809804951106289,-0.023074503302147775
328.0000000000041,39.151575997577936,-1.6811330560540052,-0.025792184933019602
329.40000000000407,39.28557659950424,-1.6829649060165406,-0.024488191464951292
330.8000000000041,39.42134815732699,-1.6842977632457834,-0.023766639470359063
332.20000000000414,39.55514137942393,-1.684852693989897,-0.023809421801276986
333.6000000000042,39.68990812813126,-1.6884370759687601,-0.025789936821981385
335.0000000000042,39.8255732250843,-1.6883513967481996,-0.025789937999999957
336.4000000000042,39.9609983649983,-1.6884908638933256,-0.025789939557000707
337.8000000000042,40.09615087793169,-1.6897774378484343,-0.024810090485449354
339.20000000000425,40.23074816328869,-1.6933785153781273,-0.024809937999994425
340.60000000000423,40.36563568602879,-1.6939603532711895,-0.024809938000000198
342.00000000000426,40.50120050989734,-1.6943251457467987,-0.02480993380417562
343.4000000000043,40.634367128149506,-1.696943939694197,-0.025139853059012562
344.80000000000433,40.77178564931596,-1.6970481276671523,-0.02611992437145627
346.20000000000437,40.908355229207615,-1.7008585889702,-0.02611991099999278
347.60000000000434,41.04352778093841,-1.7015615150317365,-0.02611803041960936
349.0000000000044,41.17951934935957,-1.7035342691478357,-0.02512999222609036
350.4000000000044,41.31424606747354,-1.703605220057508,-0.026448450913297172
351.8000000000044,41.45002965823833,-1.7051039413895086,-0.02931013616487288
353.2000000000044,41.58531926426065,-1.7067141538357753,-0.029310185422988688
354.60000000000446,41.719259294725695,-1.710751977692476,-0.027990080900629266
356.0000000000045,41.85725236530107,-1.7095440758721427,-0.026670131452909196
357.4000000000045,41.9921402551396,-1.7100834098199127,-0.026670131999927627
358.8000000000045,42.12819403724658,-1.7126844949102595,-0.026663137685771776
360.20000000000454,42.26177714751524,-1.7138477615795624,-0.026570889665383124
361.60000000000457,42.39951632754977,-1.716711058525012,-0.02724599200460487
363.00000000000455,42.5345370522845,-1.7174070056923714,-0.026684159496555004
364.4000000000046,42.670711138276886,-1.7194787190854954,-0.025957012283774894
365.8000000000046,42.806745922613736,-1.721042947955164,-0.025687807354615178
367.20000000000465,42.94351536958154,-1.7229311513948127,-0.025690105000123697
368.6000000000047,43.07639169806444,-1.7236153585165088,-0.025690105044236855
370.00000000000466,43.2146751990933,-1.7267285595941533,-0.027016174865018616
371.4000000000047,43.35136269459089,-1.727329823327785,-0.027003303064075723
372.80000000000473,43.487213518227115,-1.7291587449838157,-0.025511546283163877
374.2000000000047,43.622959119490936,-1.7303566393708283,-0.026679997220286022
375.60000000000474,43.75907055838873,-1.7307329858086837,-0.026679991015959637
377.0000000000048,43.89484946114961,-1.7322739082465455,-0.02602005692046827
378.4000000000048,44.031640003663824,-1.7356656776817327,-0.026013878547188174
379.80000000000484,44.16744539684065,-1.7361129352921882,-0.027342799876738155
381.2000000000048,44.303281756500134,-1.7366372882054784,-0.026020012486155597
382.60000000000485,44.44016628152266,-1.7377984580532924,-0.02668017983676574
384.0000000000049,44.57556550086709,-1.7396766755008646,-0.02668063029880008
385.40000000000487,44.71310058606801,-1.741912990962148,-0.028235994988570212
386.8000000000049,44.84936019542643,-1.7432516889978205,-0.02733994212768076
388.20000000000493,44.985626665982856,-1.746294519893272,-0.027339942999999423
389.60000000000497,45.12187028664931,-1.7472160847908353,-0.027339942999998534
391.000000000005,45.25799604464768,-1.7514716570923912,-0.027339943000088684
392.400000000005,45.395117079568614,-1.752963916442709,-0.027345979918657726
393.800000000005,45.53097841916414,-1.753141826739005,-0.027669943015017573
395.20000000000505,45.668262698328704,-1.7567304335110432,-0.027669828449695455
396.600000000005,45.80540008654276,-1.7587190332358298,-0.028319804731924414
398.00000000000506,45.94271822459449,-1.7604521123330226,-0.028319859999998975
399.4000000000051,46.07885766896525,-1.7638009875193545,-0.028319859999999863
400.8000000000051,46.21514947498876,-1.7681295515228677,-0.028319859999999863
402.20000000000516,46.352311885867536,-1.771103293306549,-0.028319859999998975
403.60000000000514,46.48985485511008,-1.7770817277410476,-0.02831986176318413
405.0000000000052,46.62640927161039,-1.7813456000912078,-0.029640232026890256
406.4000000000052,46.764186827836575,-1.7841636377628796,-0.029640108396997267
407.8000000000052,46.90133215748316,-1.7885671535873673,-0.027629016322918254
409.2000000000052,47.03783885964742,-1.7911391295128678,-0.029970105129070834
410.60000000000525,47.17545455105789,-1.7939277522300254,-0.029245237887637554
412.0000000000053,47.3123301609932,-1.794843309304892,-0.029307352213008286
413.4000000000053,47.449373580753495,-1.7979759535839528,-0.030630015935098065
414.8000000000053,47.58656341217481,-1.797754175856006,-0.02926245011556805
416.20000000000533,47.72428984482376,-1.8001321560494064,-0.03070222841470338
417.60000000000537,47.86086767083238,-1.8026921279938486,-0.03062361561874294
419.00000000000534,47.9983365799698,-1.8043888608874574,-0.030629991013310764
420.4000000000054,48.13664898186129,-1.8057368482018372,-0.029310039865374282
421.8000000000054,48.273130163401206,-1.8082305629771929,-0.0293098139896375
423.20000000000545,48.41155568097143,-1.8105038045960258,-0.030631431759688965
424.6000000000055,48.548688250079366,-1.8125340770627183,-0.03194928866468061
426.00000000000546,48.68634742422841,-1.8140983990327206,-0.030629880548836308
427.4000000000055,48.82225494315143,-1.8178138844045246,-0.03062988086690721
428.8000000000055,48.96044290626237,-1.8234324286984875,-0.030300311893054044
430.2000000000055,49.09740533663145,-1.8271979341470812,-0.030299907999991937
431.60000000000554,49.23589016338507,-1.8323845989576903,-0.030299908582445134
433.00000000000557,49.37271689653123,-1.8318059876432375,-0.028989814813360493
434.4000000000056,49.51041100122124,-1.835667544555817,-0.030012915911228788
435.80000000000564,49.64763525069913,-1.8380338512924836,-0.03127982499212667
437.2000000000056,49.78520141131254,-1.8417018301419892,-0.03129967075906137
438.60000000000565,49.923011599042766,-1.8426739108043015,-0.029963063064625484
440.0000000000057,50.06044322649249,-1.8455627312147234,-0.029935506516745036
441.40000000000566,50.197756276083744,-1.8464646950348331,-0.030619825419960556
442.8000000000057,50.33466000357071,-1.851638871006687,-0.03061982499951066
444.20000000000573,50.47273691945348,-1.8554314116930142,-0.030582273849316444
445.60000000000576,50.610069094477886,-1.8611541477710405,-0.03161038424760587
447.0000000000058,50.74801496469277,-1.861092513414892,-0.030300165549153046
448.4000000000058,50.885086573384896,-1.866880475308206,-0.031290428825279104
449.8000000000058,51.02364797522087,-1.8689840845895351,-0.03162029806823963
451.20000000000584,51.16148145358396,-1.8715534271171341,-0.03162011207335036
452.6000000000058,51.29990578972918,-1.876949882023176,-0.03128459477149903
454.00000000000585,51.43846998420783,-1.8822077912937596,-0.032609411682398726
455.4000000000059,51.57684524197505,-1.8831013333024793,-0.031286184936105244
456.8000000000059,51.71560066682838,-1.886551483097297,-0.030840615646199776
458.20000000000596,51.853875525324916,-1.8900839077201985,-0.030220068599496663
459.60000000000593,51.992240450262095,-1.892365703097991,-0.031620008000496025
461.00000000000597,52.1306991189822,-1.8958159073489589,-0.03162000799999776
462.400000000006,52.26743894703012,-1.8996713767152993,-0.03162000799915221
463.800000000006,52.40655213251914,-1.9011118426014437,-0.03151892131946399
465.200000000006,52.54559115079372,-1.9082433338864069,-0.03299335795384151
466.60000000000605,52.683796313003256,-1.9120234603888655,-0.03194988612679239
468.0000000000061,52.820861424105324,-1.9128224190533263,-0.03194989999999942
469.4000000000061,52.95907181857754,-1.9207709198186824,-0.03194989999999942
470.8000000000061,53.09759093905894,-1.928456139676542,-0.03194989336789211
472.2000000000061,53.23566192333411,-1.9326496764348078,-0.032599710883116195
473.60000000000616,53.37355787415235,-1.9384228985194198,-0.033259770202456185
475.00000000000614,53.51196090501742,-1.944419424288623,-0.03196017045000721
476.4000000000062,53.64926109802,-1.9466739900030658,-0.03193981705559157
477.8000000000062,53.79002165913335,-1.952949273898523,-0.03293015242741548
479.20000000000624,53.92726899551963,-1.9591178693145483,-0.032929983517947736
480.6000000000063,54.066438074815615,-1.9636923019177723,-0.03386572945631672
482.00000000000625,54.20506136668323,-1.9678347229425037,-0.03084724129847105
483.4000000000063,54.34378080671122,-1.9737095111135983,-0.03315005818361172
484.8000000000063,54.4832197618716,-1.9785401323883458,-0.034457161033122574
486.2000000000063,54.621812452931074,-1.9840471957429817,-0.034469225023620265
487.60000000000633,54.75996382312583,-1.9870338717861633,-0.03316007589078085
489.00000000000637,54.89826052851973,-1.9881345228472391,-0.034151186288350566
490.4000000000064,55.03552599612794,-1.9923252300244698,-0.03413989001463502
491.80000000000643,55.17486185905673,-1.9971558526582998,-0.03413641912258347
493.2000000000064,55.31288341055892,-1.9982148072049735,-0.03579170193226844
494.60000000000645,55.45234853331325,-2.0004722467312375,-0.03579017447951216
496.0000000000065,55.590915567940634,-2.0050057155380023,-0.037102830619441196
497.40000000000646,55.728791098316606,-2.0072695063206836,-0.03711004597995338
498.8000000000065,55.86889714453192,-2.0111403449830547,-0.03841685289014718
500.2000000000065,56.0072273082581,-2.014341301259886,-0.037109937892110256
501.60000000000656,56.146978905060934,-2.0175768616292094,-0.03685314161183584
503.0000000000066,56.288094715120906,-2.021331273713344,-0.03612042444618835
504.40000000000657,56.42701067290971,-2.028462650298248,-0.03676700485677742
505.8000000000066,56.56407105213555,-2.030941473232693,-0.039198150365939544
507.20000000000664,56.705987612464924,-2.0349285666741666,-0.03786998249445794
508.6000000000066,56.845845447502796,-2.03588726350856,-0.03885995135379483
510.00000000000665,56.98269429444641,-2.0423950797156,-0.04015596846442904
511.4000000000067,57.124420206342876,-2.0450805853615504,-0.03885981443524322
512.8000000000068,57.26317988053255,-2.0485228293876707,-0.04017962549033971
514.2000000000068,57.40281624357661,-2.0557262291130005,-0.03985016027664168
515.6000000000067,57.542079955765786,-2.0587451556204397,-0.04116998221403101
517.0000000000068,57.68157142749079,-2.0622752356340777,-0.039850067105982934
518.4000000000068,57.82058613983976,-2.0690744625918644,-0.04182300349436607
519.8000000000068,57.95886701071023,-2.070387444525464,-0.04115997124603288
521.2000000000069,58.09849004630271,-2.076749423686515,-0.04116315296340867
522.6000000000068,58.237509493721205,-2.0825614986878187,-0.04052266747148625
524.0000000000068,58.37521311788024,-2.084964291104307,-0.04116944076512663
525.4000000000069,58.51594817089428,-2.087758253107996,-0.041170819299419126
526.8000000000069,58.65600452512018,-2.0909431810143397,-0.04348413307882515
528.2000000000069,58.79499910721916,-2.0948409577368956,-0.04347007921067414
529.600000000007,58.93399692971078,-2.1028172857564256,-0.043140105122530414
531.0000000000069,59.07339051088489,-2.107359557116448,-0.043140165845382494
532.4000000000069,59.21460141002617,-2.1161719990192425,-0.044357862545651106
533.800000000007,59.354153899425725,-2.122908384869615,-0.044618589250745355
535.2000000000071,59.49237553752577,-2.1302173725993803,-0.04577988418362855
536.6000000000071,59.63538813652935,-2.134245210314984,-0.04578267095745181
538.000000000007,59.77506249445149,-2.1394543728298148,-0.04578014631868088
539.4000000000071,59.91532960376649,-2.1447856074006832,-0.04525087058344557
540.8000000000071,60.054964966469534,-2.1485028965208737,-0.04711139670335074
542.2000000000071,60.194491437547086,-2.1565462235707487,-0.04772921635866112
543.6000000000072,60.33466215360734,-2.1618320316460875,-0.04906909783074376
545.0000000000072,60.47382472670757,-2.1638070621502705,-0.048411838138573415
546.4000000000071,60.61512422071302,-2.1699289884597275,-0.04973016454786139
547.8000000000072,60.75432453754154,-2.1760267600610117,-0.0500583687784073
549.2000000000072,60.89609843952519,-2.1798825434335063,-0.05006008231741399
550.6000000000072,61.0360868692744,-2.1872334414677117,-0.05138505223868117
552.0000000000073,61.17597230069239,-2.1927310791736394,-0.05269986643917601
553.4000000000073,61.317125406788975,-2.1972545999411617,-0.052369672204309214
554.8000000000073,61.45755917086036,-2.2036421744456165,-0.052367504762795836
556.2000000000073,61.59530764541758,-2.209657679874517,-0.054661557221836965
557.6000000000073,61.73754494837748,-2.215590604815195,-0.05366349279107485
559.0000000000074,61.87829035032527,-2.2185644691930935,-0.055005120543693664
560.4000000000074,62.019463578938925,-2.2272251960572684,-0.05631997915185005
561.8000000000075,62.15977941567144,-2.2331847097615904,-0.05664988132099724
563.2000000000074,62.299072262333084,-2.239557488252367,-0.05560145953603479
564.6000000000074,62.439573546303166,-2.244800527206587,-0.05698014906705451
566.0000000000075,62.57814610285407,-2.249290192272059,-0.05828975542637149
567.4000000000075,62.72058155357501,-2.2553551373406493,-0.05830156331991887
568.8000000000075,62.86089817371841,-2.2614347092258313,-0.060929728690926055
570.2000000000075,63.002244624317164,-2.268986863832515,-0.060929930760050155
571.6000000000075,63.14258974984539,-2.2759398479300663,-0.06231720039177446
573.0000000000075,63.2831684481065,-2.2810902603908665,-0.06159014274127195
574.4000000000076,63.42429251967344,-2.2907195617821983,-0.06288931842790824
575.8000000000076,63.56440211426548,-2.2945248140876204,-0.062258483443187185
577.2000000000077,63.70516436089384,-2.3004787754036755,-0.06452205362132757
578.6000000000076,63.84684165885567,-2.305959381381346,-0.06521471085876707
580.0000000000076,63.98746788269123,-2.308293259548257,-0.06613163484679507
581.4000000000077,64.12822391251501,-2.3143819107775587,-0.06883132658441626
582.8000000000077,64.26955587822646,-2.3194574924569404,-0.06882995818360715
584.2000000000078,64.41040728268281,-2.325262700129587,-0.06783889043287017
585.6000000000078,64.55122081313834,-2.32996965717432,-0.06916032991892118
587.0000000000077,64.69202370385207,-2.335404595889935,-0.07014125830077145
588.4000000000078,64.83170569513295,-2.338058025057121,-0.07146004697376718
589.8000000000078,64.97370388511415,-2.343878274101118,-0.07147332949661145
591.2000000000078,65.1153530753932,-2.3505064688868793,-0.07390865855209139
592.6000000000079,65.25590672637803,-2.35382400998809,-0.0747590781737113
594.0000000000078,65.3971837368648,-2.3558409688313495,-0.07475995531861956
595.4000000000078,65.5386061093738,-2.362481595145814,-0.07541800340408811
596.8000000000079,65.67917099035353,-2.3653799612017377,-0.07772993074321422
598.2000000000079,65.81809202195842,-2.367208789340451,-0.07670350959972572
599.600000000008,65.96108995104841,-2.369960013174381,-0.07806884944603354
601.000000000008,66.10038468995194,-2.373836118462525,-0.08002237709640925
602.4000000000079,66.24129288279693,-2.380736992037813,-0.08036587339616963
603.800000000008,66.38467257380447,-2.386998628292366,-0.08072134292345012
605.200000000008,66.52481962781606,-2.393436676515657,-0.08309619647076705
606.6000000000081,66.66681625605386,-2.3981178665456784,-0.08310314366836691
608.0000000000081,66.80771340251263,-2.4062700838071236,-0.08630917791706905
609.400000000008,66.94959415443878,-2.4108105757741,-0.08628991093893301
610.8000000000081,67.0904407761164,-2.4195704207478186,-0.08760277529996019
612.2000000000081,67.2325846408427,-2.4240932971369133,-0.08851271398278238
613.6000000000081,67.37428769421372,-2.42904944465546,-0.08892936584380706
615.0000000000082,67.51449258599803,-2.438128085224025,-0.09022639733991777
616.4000000000082,67.65623809212134,-2.4464239312503344,-0.09293583083163481
617.8000000000081,67.79760505859953,-2.4571849526755627,-0.09418954835181959
619.2000000000082,67.94040563502934,-2.462034935532703,-0.09418921729121799
620.6000000000082,68.08097437137303,-2.47033334631824,-0.09551025229265031
622.0000000000083,68.22259110434713,-2.4782299188657815,-0.09617818049761429
623.4000000000083,68.36387537025186,-2.485845193489352,-0.09682948785274359
624.8000000000083,68.50550497184389,-2.4941226291285563,-0.09814936275571906
626.2000000000083,68.647310117046,-2.5045129406082705,-0.1007838565582464
627.6000000000083,68.7883981830142,-2.5181347143353885,-0.10210002756936998
629.0000000000084,68.9300703533152,-2.524875375246956,-0.10473146893925955
630.4000000000084,69.0713431590698,-2.5364149045946953,-0.104725442002227
631.8000000000084,69.21283628949477,-2.5451379698572523,-0.10958338991849592
633.2000000000085,69.35362764783042,-2.557952558180825,-0.10878515400210409
634.6000000000084,69.49571203647137,-2.5701369027654524,-0.10971916005251625
636.0000000000084,69.63743588563118,-2.584645383457932,-0.11198117539217911
637.4000000000085,69.77947914099097,-2.5942463415307007,-0.11592552712150272
638.8000000000085,69.92106219611867,-2.607528347611484,-0.11592996573916103
640.2000000000085,70.06318254327086,-2.617976089529866,-0.11891996710335828
641.6000000000085,70.20600450292781,-2.62656797645239,-0.12152985560204188
643.0000000000085,70.34801242959364,-2.640801245884793,-0.12393182372068168
644.4000000000086,70.49031323598837,-2.655110651666528,-0.12548447934824658
645.8000000000086,70.63192552059796,-2.662571614543035,-0.12811216190472363
647.2000000000086,70.77434285814832,-2.676849973945584,-0.12943707522590397
648.6000000000087,70.91542746278347,-2.689517711454235,-0.1333704634304267
650.0000000000086,71.0569649420453,-2.70272058975607,-0.1348394317482775
651.4000000000087,71.20059912531836,-2.7180337412505087,-0.138945638931955
652.8000000000087,71.34175652402384,-2.7326361671027595,-0.14055483837708893
654.2000000000087,71.48389207290425,-2.749512941264872,-0.1445965495911823
655.6000000000088,71.6257148069021,-2.762981888783391,-0.14689501284931605
657.0000000000088,71.76764636644056,-2.7805516317057877,-0.15005403282764762
658.4000000000087,71.90746304267955,-2.793970663108656,-0.15411144625314677
659.8000000000088,72.05161802275491,-2.81504537744027,-0.15791092966454867
661.2000000000088,72.19335973271947,-2.8334755225443318,-0.1606748786900889
662.6000000000088,72.33662979940078,-2.8531163322004534,-0.16423079867588974
664.0000000000089,72.47678240863513,-2.872893334834513,-0.16851102083817793
665.4000000000088,72.62208177681703,-2.896749130296936,-0.17277051340382465
666.8000000000089,72.76335966909693,-2.9163535569284513,-0.17687882697885726
668.2000000000089,72.90643440619739,-2.939972982417547,-0.18061100644094807
669.6000000000089,73.0483565446196,-2.959163750857175,-0.18601718981144222
671.000000000009,73.19127631409187,-2.984875511726813,-0.18951946682941845
672.400000000009,73.333656291878,-3.0091216310654705,-0.19383307817939954
673.800000000009,73.47641698662999,-3.0341369504463875,-0.20062476561808396
675.200000000009,73.61789719655367,-3.057919333025274,-0.20561799926859248
676.600000000009,73.76146219232412,-3.0819245486360853,-0.2114931496857717
678.0000000000091,73.9041038209436,-3.111607098656938,-0.21865997555804073
679.4000000000091,74.04606573786334,-3.1406735982658938,-0.22487605634676333
680.800000000009,74.18884856459698,-3.1716954804152833,-0.2297679946284661
682.2000000000091,74.33284480370067,-3.2012971227909297,-0.23637173311037074
683.6000000000091,74.47618023989044,-3.2363597563607978,-0.24372876697824886
685.0000000000091,74.61795134432442,-3.270576434222626,-0.25160188173308295
686.4000000000092,74.76036924401126,-3.3048341719961867,-0.25712473462558894
687.8000000000092,74.90527610719433,-3.3417435176743164,-0.2640539459002538
689.2000000000093,75.04938060673373,-3.3785535026122275,-0.27348596075672305
690.6000000000092,75.19231879154104,-3.418465879899535,-0.28183136435400025
692.0000000000092,75.33586341518661,-3.456303306235687,-0.29033531100473997
693.4000000000093,75.47806652792877,-3.4987493205620734,-0.29877909200088926
694.8000000000093,75.62163124287721,-3.5378456649985663,-0.3088205228158083
696.2000000000094,75.76431816664787,-3.5832422278078293,-0.31846706905823075
697.6000000000093,75.90835034838182,-3.6273629774363307,-0.32661058132199017
699.0000000000093,76.05233247392488,-3.6759801500227463,-0.33811117103822363
700.4000000000094,76.19585425075844,-3.724764666282086,-0.35003309747358546
701.8000000000094,76.33917099736672,-3.776110492759001,-0.36195989127537054
703.2000000000094,76.48304133791585,-3.8322755755766713,-0.37306347808414353
704.6000000000095,76.6263597991506,-3.8868422607925295,-0.38491012345936904
706.0000000000094,76.77038027520334,-3.9422369097439858,-0.3971261918236939
707.4000000000094,76.91412122587337,-3.9992440411935535,-0.41125031198210893
708.8000000000095,77.05631848227617,-4.062427106815163,-0.42455070103371195
710.2000000000095,77.20190041143749,-4.123266128224327,-0.43856562370097496
711.6000000000096,77.34548604226505,-4.1823210243089655,-0.45411978743101056
713.0000000000095,77.48927169711033,-4.248058472900805,-0.46922279770535047
714.4000000000095,77.63449302027877,-4.3163766834561095,-0.4863992555819272
715.8000000000096,77.77868150410008,-4.381569303934993,-0.5000174456621247
717.2000000000096,77.92299664012585,-4.450729334452384,-0.5189262844969913
718.6000000000097,78.06648875377309,-4.520052352131952,-0.5357731919446738
720.0000000000097,78.21136323976116,-4.592369977537327,-0.5538310212892261
721.4000000000096,78.35548318964919,-4.663344016324521,-0.5710576585554277
722.8000000000097,78.49824260187285,-4.736292041087157,-0.5910920189209321
724.2000000000097,78.64313291239903,-4.80882192599446,-0.6114029026723844
725.6000000000097,78.78711959738632,-4.88647696309224,-0.6321779298928996
727.0000000000098,78.93050508103386,-4.966319699159669,-0.6542086177761286
728.4000000000098,79.07586077205181,-5.040579822996596,-0.6757334832305251
729.8000000000097,79.2200249407485,-5.119512030727069,-0.6999503116491548
731.2000000000098,79.36420510756746,-5.196110028618928,-0.7220190619149789
732.6000000000098,79.50854090963492,-5.276184534475988,-0.747837215220394
734.0000000000099,79.65276270553346,-5.3474178527233445,-0.7713357757101238
735.4000000000099,79.79807035034011,-5.423062595877798,-0.7951979537376634
736.8000000000098,79.94234777609891,-5.4935232044410505,-0.8227547464225302
738.2000000000099,80.08651893483449,-5.563736945015874,-0.8477799891703128
739.6000000000099,80.23096748396316,-5.623040162982562,-0.8750016853021569
741.00000000001,80.37505163201654,-5.67431004783244,-0.9013468499959423
742.40000000001,80.51858313629731,-5.720793211274959,-0.9305611533345712
743.80000000001,80.66286752255935,-5.759305484990859,-0.960418416612765
745.20000000001,80.80537502490407,-5.784518495495277,-0.98745345473036
746.60000000001,80.94770211276976,-5.797660922050527,-1.0157342728527095
748.00000000001,81.09069252997556,-5.791542872671948,-1.0446236992811064
749.4000000000101,81.23039663840146,-5.763686233714573,-1.071208668107897
750.8000000000101,81.37330814773546,-5.714209622205382,-1.0987727469863855
752.20000000001,81.51459509644653,-5.6428467899694175,-1.1272406900786858
753.6000000000101,81.65405545449305,-5.541425013094156,-1.1524474897550898
755.0000000000101,81.79440832542218,-5.396244021193165,-1.1786580553490342
756.4000000000102,81.93204777044241,-5.214850149656988,-1.1997724938119219
757.8000000000102,82.06655951567757,-4.981311383864696,-1.221168921896671
759.2000000000102,82.20306002449516,-4.676972419876811,-1.239745580721391
760.6000000000103,82.33436816323416,-4.297501706448347,-1.255957490716637
762.0000000000102,82.46541696553551,-3.8505653117459295,-1.2682976446942331
763.4000000000103,82.5977533482185,-3.40425634131056,-1.2760135109367123
764.8000000000103,82.73176522889497,-3.087233497156849,-1.2788709271360466
766.2000000000103,82.86947606696391,-2.9081336394361212,-1.281389644827855
767.6000000000104,83.01004159452665,-2.840758218532445,-1.283370737644272
769.0000000000103,83.15266922007882,-2.8223536080539606,-1.2827100920759005
770.4000000000103,83.29429805226303,-2.820990282896418,-1.2840202378477548
771.8000000000104,83.43715722585348,-2.823946032586099,-1.2840200034689038
773.2000000000104,83.57701152476801,-2.826279928423167,-1.2853744971636565
774.6000000000104,83.72211305607334,-2.8310203738583986,-1.2840198970029966
776.0000000000105,83.86596566486865,-2.8373763873451563,-1.2841508921696088
777.4000000000104,84.0091679219986,-2.842249608127199,-1.284811075423569
778.8000000000105,84.15158443600441,-2.8471600661170546,-1.2853471372894365
780.2000000000105,84.29466148437153,-2.852648538208872,-1.2853489010222705
781.6000000000105,84.4382056188815,-2.853223142726717,-1.2852188304488523
783.0000000000106,84.58074334886633,-2.8636413752593146,-1.2853400067078113
784.4000000000106,84.7247020200427,-2.869121871608676,-1.28632995727197
785.8000000000106,84.86766678818708,-2.8742652886248146,-1.285011227528822
787.2000000000106,85.01129307927201,-2.880978311144291,-1.2850067965926568
788.6000000000106,85.15408037172757,-2.8850281712032295,-1.2846799256745465
790.0000000000107,85.29840807762693,-2.8934419164170153,-1.284679916102431
791.4000000000107,85.44174422937006,-2.896288857165776,-1.285012719918452
792.8000000000106,85.58589075350835,-2.8987042286402636,-1.2867751131991532
794.2000000000107,85.72873391737716,-2.9046160194336954,-1.285999809845579
795.6000000000107,85.87290283732308,-2.911821642908693,-1.287097983329918
797.0000000000107,86.01568487737241,-2.9126665065340522,-1.2863300392613204
798.4000000000108,86.1607496461526,-2.9199311013884786,-1.286323646565307
799.8000000000108,86.30156572930943,-2.9221035647268416,-1.287468067405698
801.2000000000108,86.44574374917784,-2.926585636859572,-1.2863295258575045
802.6000000000108,86.58824588398319,-2.9306133115606374,-1.2876498808695005
804.0000000000108,86.7323452015126,-2.937563162723558,-1.2876498796843294
805.4000000000109,86.87457122713978,-2.9428730854003824,-1.2883102523826224
806.8000000000109,87.01811696843725,-2.946633671155331,-1.287650879721551
808.200000000011,87.16029697594755,-2.952843057410086,-1.2889600892164599
809.6000000000109,87.3035543996921,-2.9580171490222367,-1.2883097617139394
811.0000000000109,87.44637479794827,-2.9616264293359857,-1.2886122246912124
812.400000000011,87.59024194920649,-2.9699528414950955,-1.288630032175559
813.800000000011,87.73334513087562,-2.9765675939260148,-1.2912579316616135
815.200000000011,87.8759031026514,-2.979609918090604,-1.2899367304441665
816.600000000011,88.01937462943093,-2.9853918162018527,-1.2912698218283825
818.000000000011,88.16212935351875,-2.9973699223422052,-1.2912698194362675
819.400000000011,88.30425033048188,-3.002614048436892,-1.2926288937832546
820.8000000000111,88.44852439758523,-3.010832203892757,-1.2912800161532894
822.2000000000111,88.5920060682039,-3.0171666661792136,-1.2912704444812269
823.6000000000112,88.73528826321666,-3.0252624151535756,-1.2921021940375987
825.0000000000111,88.8788543883051,-3.0334001176543994,-1.2939783977745831
826.4000000000111,89.02328193818094,-3.043857718916419,-1.2919299471594545
827.8000000000112,89.16663453299742,-3.0503231919391935,-1.2920806843903052
829.2000000000112,89.31010689783099,-3.0603112594316997,-1.2919298235557775
830.6000000000113,89.45396880430252,-3.0643568647604207,-1.2932389811801182
832.0000000000113,89.59898597004693,-3.072443116839087,-1.29321380161492
833.4000000000112,89.74325097799994,-3.0784047193110315,-1.2938968394421813
834.8000000000113,89.88649629602234,-3.081106898159793,-1.2939000752525365
836.2000000000113,90.03014476387635,-3.083793176691789,-1.292573258091005
837.6000000000113,90.17322411571301,-3.093946697753663,-1.293900046552063
839.0000000000114,90.31607410028117,-3.097080849190651,-1.2952227520482889
840.4000000000113,90.45982703765443,-3.1054743926931363,-1.2945698566848645
841.8000000000113,90.60373019083164,-3.111344828409463,-1.294569655047412
843.2000000000114,90.74726943638566,-3.117815006545138,-1.2952189073791884
844.6000000000114,90.89107186256554,-3.123695833452865,-1.2965386762729159
846.0000000000115,91.03480433098167,-3.1289377720571845,-1.2956250078626752
847.4000000000115,91.17799828607004,-3.137955150570299,-1.2965408826731681
848.8000000000114,91.32035016499731,-3.144273492706895,-1.2965394998811255
850.2000000000115,91.46392156716348,-3.150665083888855,-1.2965380183633788
851.6000000000115,91.6097283924986,-3.1571538936087804,-1.2962053305910728
853.0000000000116,91.75204529940632,-3.1636222383701327,-1.2975332376778135
854.4000000000116,91.89608544896087,-3.171644223367935,-1.2979001465302655
855.8000000000116,92.03985411275389,-3.1758031169043415,-1.2977469710479426
857.2000000000116,92.1842327147274,-3.1863487572925835,-1.2967963916282321
858.6000000000116,92.32693984938145,-3.1907311774208447,-1.2975199433485267
860.0000000000116,92.47138097678479,-3.1951486249793764,-1.2975215250097345
861.4000000000117,92.61279024815548,-3.200514070312257,-1.2988400169856984
862.8000000000117,92.75874599186724,-3.2068275792701186,-1.298697096183763
864.2000000000116,92.90279930576395,-3.2177117385542493,-1.2985206264859035
865.6000000000117,93.04649852348946,-3.2161012264337105,-1.3008549853581028
867.0000000000117,93.19067093630011,-3.2234676046115194,-1.301460087124136
868.4000000000118,93.3345853635056,-3.2268097601112276,-1.3008256263827755
869.8000000000118,93.47708572453251,-3.2339987796200846,-1.2994209406216628
871.2000000000118,93.62104283129594,-3.240331034178021,-1.3021332962702115
872.6000000000118,93.7644516587854,-3.2451207327412326,-1.3008199949944856
874.0000000000118,93.90774131987172,-3.248057914959113,-1.3008199950000048
875.4000000000119,94.05239259713018,-3.2511119203719163,-1.300818508459419
876.8000000000119,94.1938033147891,-3.257513794216826,-1.3008712617556921
878.2000000000119,94.33945209245104,-3.260787839349599,-1.30081988703999
879.600000000012,94.48264136340264,-3.2691518007356097,-1.3021402839612843
881.0000000000119,94.62646426798449,-3.275902851718149,-1.3008597382801756
882.4000000000119,94.77011154020995,-3.2816718432895584,-1.300830269246454
883.800000000012,94.91529233851098,-3.290494329396238,-1.3008164365972186
885.200000000012,95.05762963071285,-3.2918101333931724,-1.30181225619252
886.600000000012,95.20163458619034,-3.303440874872889,-1.3034649646093732
888.000000000012,95.34461302698398,-3.3066773129149345,-1.3034599032974041
889.400000000012,95.48916798335398,-3.311379651178726,-1.302139876243321
890.8000000000121,95.63269355237013,-3.315480242328895,-1.303790170054949
892.2000000000121,95.7750263272978,-3.3245573753208286,-1.3010404460241656
893.6000000000121,95.91937800967413,-3.3286717657198133,-1.3037801920089684
894.0000000000122,95.96130789906701,-3.3336968387797707,-1.303780116953504