File: 01_Data/Cotton_Rug/STA/N2/10K_min/Cotton_Rug_STA_N2_10KData_220113_R3.csv
##Temp./Â°C,Time/min,DSC/(mW/mg),Mass loss/mg
50.0,10.742408069056617,-0.911846199358335,-0.009173814749579456
51.20000000000002,11.065359799751205,-0.8008143603740046,-0.0066272483317932895
52.400000000000034,11.288994970575851,-0.7264229436885201,-0.007907267565000708
53.60000000000005,11.47424984757776,-0.6724536737478907,-0.008538834631013792
54.80000000000007,11.639955952045048,-0.6283335274362503,-0.008198054081650419
56.000000000000085,11.796693335436988,-0.5959229006665886,-0.008075339388367908
57.2000000000001,11.945613290106271,-0.566415221711563,-0.007261780507512583
58.40000000000012,12.088221477944256,-0.5437175410166885,-0.007638909178370845
59.600000000000136,12.227659088365941,-0.5234088517570687,-0.0073893134152873685
60.80000000000015,12.362941759764432,-0.5037270256523528,-0.008770035680776722
62.00000000000017,12.499430247073455,-0.490236140255409,-0.008738825755826518
63.20000000000019,12.631946739414008,-0.4759785963410277,-0.007830077110527967
64.4000000000002,12.762789761293353,-0.46234052885456345,-0.008709335861593281
65.60000000000022,12.893768437340123,-0.45042123279070434,-0.010064325274939279
66.80000000000024,13.025409366621435,-0.4388287880059385,-0.00878118458490551
68.00000000000026,13.154613193829492,-0.42879425424687684,-0.008766596701065943
69.20000000000027,13.284768287670552,-0.41935813869880345,-0.009755859145024637
70.40000000000029,13.412295775707008,-0.41112494161474655,-0.010745182345083037
71.6000000000003,13.540905356747736,-0.4012431904663314,-0.010026479666466415
72.80000000000032,13.667840453898839,-0.3930226645140311,-0.01141387273230432
74.00000000000034,13.795298719303771,-0.38555687141067163,-0.011752596402221371
75.20000000000036,13.92334311034754,-0.3749123844797859,-0.011285494082764913
76.40000000000038,14.047716853962122,-0.3664106039643205,-0.011360212685119997
77.60000000000039,14.173567631338084,-0.35879967842580773,-0.012693924768935716
78.80000000000041,14.296775441321497,-0.34778543125350125,-0.012370369547848092
80.00000000000043,14.421383816092991,-0.34030083830857116,-0.014030232557508349
81.20000000000044,14.541919754249166,-0.33103387675367957,-0.014026347788604454
82.40000000000046,14.668497834415819,-0.32160841251189853,-0.01406430295863803
83.60000000000048,14.791830807190225,-0.3148213056874639,-0.014039807306019725
84.8000000000005,14.91380990576588,-0.3065221644946844,-0.015349917258512313
86.00000000000051,15.03590376460731,-0.29961052450939457,-0.01418776443502967
87.20000000000053,15.15715331087068,-0.2907204896564695,-0.015030611549176065
88.40000000000055,15.27838798536151,-0.28431268235744883,-0.01667588935744213
89.60000000000056,15.399269858977807,-0.2775729103219411,-0.01667008490239219
90.80000000000058,15.518500038963818,-0.27181072743515866,-0.01667005400094368
92.0000000000006,15.638401903681942,-0.2646102401851341,-0.01636737636363428
93.20000000000061,15.75784546661141,-0.2586262522670713,-0.016669797779911733
94.40000000000063,15.878300222038638,-0.25353449168636605,-0.01666993584076959
95.60000000000065,15.997617885603212,-0.2481585000029481,-0.017990155436836908
96.80000000000067,16.116657346743214,-0.24221164357047792,-0.016792883785132773
98.00000000000068,16.235782219743303,-0.23593489534543163,-0.018103603775238675
99.2000000000007,16.35403506222839,-0.2296874446080786,-0.01941260445381765
100.40000000000072,16.472072487328038,-0.22530691747224588,-0.018090069914070916
101.60000000000073,16.590086961106653,-0.21834954478490193,-0.019080517615473802
102.80000000000075,16.709694448774112,-0.213585895666439,-0.018098240424713197
104.00000000000077,16.827648511867398,-0.20642449620001593,-0.019420233287426925
105.20000000000078,16.94563363292657,-0.19934288392481767,-0.01942031420277779
106.4000000000008,17.0633327403441,-0.19309300728031553,-0.02040295610978493
107.60000000000082,17.18255847547545,-0.1897054111914087,-0.02039976890527928
108.80000000000084,17.29890202417587,-0.18268019484038936,-0.020399143249727913
110.00000000000085,17.41660507297205,-0.17759575926161136,-0.01941956388159305
111.20000000000087,17.534632017770114,-0.17043101979001846,-0.019565148919824082
112.40000000000089,17.652458239362993,-0.16329485971451804,-0.02083388571205891
113.6000000000009,17.769753236427253,-0.1577151324405275,-0.019410100346227033
114.80000000000092,17.887076614298554,-0.15271067892498322,-0.02072979211773074
116.00000000000094,18.004786740527777,-0.14504607651996332,-0.019876593741412485
117.20000000000095,18.121045227689976,-0.14025803937572992,-0.020730014524227514
118.40000000000097,18.238689418499778,-0.13339074608215,-0.019409446906743177
119.60000000000099,18.35637334090537,-0.12776231621328016,-0.020535642403469723
120.800000000001,18.473768209921737,-0.12073656528651022,-0.020729940349728082
122.00000000000102,18.590631070379978,-0.1156961923330511,-0.019946678744932278
123.20000000000104,18.707926912724083,-0.1082489010279298,-0.02126703363404303
124.40000000000106,18.824704227873397,-0.1032580876978289,-0.02037311798239827
125.60000000000107,18.94197279037031,-0.09689076346954864,-0.021375717968910912
126.80000000000109,19.057865414263514,-0.09051092871802605,-0.020937728477496087
128.0000000000011,19.175174971914537,-0.08459064098547713,-0.022270047100535706
129.20000000000113,19.291659371696166,-0.07927098911554115,-0.021232763318552728
130.40000000000114,19.40802244416468,-0.0730192791654884,-0.022334233727593578
131.60000000000116,19.52488717154847,-0.06876687727429201,-0.021600021668579217
132.80000000000118,19.641146309444583,-0.061177052239676934,-0.02130309137489128
134.0000000000012,19.758164843154816,-0.05609384918074501,-0.022249482827126243
135.2000000000012,19.87494868101372,-0.04835544297188133,-0.02357971947025561
136.40000000000123,19.991661987059693,-0.04313696144002453,-0.022269670065849567
137.60000000000124,20.107743830777764,-0.036865581515292706,-0.022929969289308794
138.80000000000126,20.223556211078485,-0.03173509450057943,-0.02255426789608883
140.00000000000128,20.33966727632062,-0.024794571895794683,-0.022260426447986426
141.2000000000013,20.455301892294113,-0.019122428487892487,-0.021858378284012936
142.4000000000013,20.570982997501805,-0.013752421341999922,-0.02291988861156824
143.60000000000133,20.686298242423387,-0.007447019897362234,-0.0240799461290937
144.80000000000135,20.801870316757544,0.00038563836852146025,-0.022919871832619343
146.00000000000136,20.918175401741944,0.0063624853743768205,-0.022963887220844192
147.20000000000138,21.03229870691741,0.012905779321839716,-0.02073530793451539
148.4000000000014,21.14852430896254,0.020458566988474657,-0.023360501134672695
149.60000000000142,21.26541098321388,0.024997718501568886,-0.023360114758424366
150.80000000000143,21.379936567543865,0.030427868754312224,-0.02204082240037053
152.00000000000145,21.494990934421235,0.03745804611721091,-0.022049237407067324
153.20000000000147,21.60966271283933,0.04250908655267028,-0.02335986042291971
154.40000000000148,21.725645884909476,0.048516771505352475,-0.023357603747622413
155.6000000000015,21.840415446320044,0.053986891464763355,-0.023359832657094515
156.80000000000152,21.955896058737334,0.0602040332750481,-0.023359835276572483
158.00000000000153,22.072016566733147,0.06687249992808901,-0.024673294539024226
159.20000000000155,22.187498287412012,0.07433192238973237,-0.023359412931191592
160.40000000000157,22.30228457306084,0.07917701349679734,-0.023388821440303076
161.6000000000016,22.41769328717279,0.0832613465335232,-0.024687716166225115
162.8000000000016,22.53320816496964,0.08874732230275344,-0.023363744367244976
164.00000000000162,22.648646482607266,0.09404090653421851,-0.02373842250287428
165.20000000000164,22.76183766753112,0.10093433247225764,-0.023369964008498556
166.40000000000165,22.875443587607275,0.10438522263401953,-0.023370696202114516
167.60000000000167,22.991499800305352,0.11015171570312089,-0.024679964304982427
168.8000000000017,23.109267911619185,0.11496968737674343,-0.024347921090416946
170.0000000000017,23.22433351882702,0.12025441444303522,-0.024350121003675618
171.20000000000172,23.340686774635607,0.12666407593663476,-0.02407330771301286
172.40000000000174,23.455425157583555,0.13439507266036804,-0.024350121085931598
173.60000000000176,23.570298922578665,0.1377852089601165,-0.025603988623186247
174.80000000000177,23.685732806542543,0.14360824435680616,-0.02501402323409785
176.0000000000018,23.801550779333592,0.14978875013550697,-0.024880926943834147
177.2000000000018,23.916751629608488,0.1552990599282094,-0.024990539982685078
178.40000000000182,24.031331949353255,0.16088206248754489,-0.025659878886046705
179.60000000000184,24.145176108682307,0.1659452403641544,-0.025659869000002722
180.80000000000186,24.261219589384822,0.1716434546092429,-0.025659876188898423
182.00000000000188,24.375659969340433,0.17608630993677638,-0.024612610019996595
183.2000000000019,24.49056032665963,0.18055280942253482,-0.02566984221592694
184.4000000000019,24.60637839727861,0.18555918886423142,-0.025669841999977017
185.60000000000193,24.71962396122485,0.19031587373825873,-0.025669166876700622
186.80000000000194,24.835058320642464,0.19645776264107276,-0.02697962998654191
188.00000000000196,24.950393182063195,0.20010178045765448,-0.025659978635013125
189.20000000000198,25.064343296837794,0.20479850022555116,-0.025659999003720735
190.400000000002,25.17890160524179,0.2097245103169785,-0.025682510303761674
191.600000000002,25.294736399037436,0.2146771609227674,-0.026981274916474618
192.80000000000203,25.408781394444564,0.21999159952513728,-0.02764012674907157
194.00000000000205,25.52245508021222,0.22722763125774506,-0.027640369860616687
195.20000000000206,25.636871813111636,0.23109484162027738,-0.025774710057163475
196.40000000000208,25.752374890386825,0.2380333327136381,-0.0270879258684511
197.6000000000021,25.86563480424346,0.24103801398482466,-0.027315856834314367
198.80000000000211,25.980612819279756,0.24762652918322817,-0.028410023699105835
200.00000000000213,26.09547184239046,0.25145690492954814,-0.028079651198346767
201.20000000000215,26.209481739624078,0.25806341422197426,-0.029060168407951004
202.40000000000217,26.324479538566504,0.26153573859852813,-0.029059893998808484
203.60000000000218,26.439264371709164,0.26607474302526135,-0.029083898343614578
204.8000000000022,26.553328561247962,0.27062555498919977,-0.030389298016697985
206.00000000000222,26.66679439287873,0.2762496997765249,-0.03130653392623106
207.20000000000223,26.78241971642503,0.28159273429508097,-0.030379893884338927
208.40000000000225,26.898389797264738,0.2856394124802808,-0.030379894000174268
209.60000000000227,27.012146229953387,0.29110576650221526,-0.030379552089075723
210.80000000000229,27.125544396900864,0.29600641233778163,-0.03169987430992549
212.0000000000023,27.24029993181339,0.30110157842225777,-0.031699894673608675
213.20000000000232,27.356177252744857,0.30716676071996774,-0.030273892056554175
214.40000000000234,27.469994455638513,0.31328611154314,-0.0328998920618675
215.60000000000235,27.58393844629315,0.31871477113189034,-0.034222792238362665
216.80000000000237,27.6994357779291,0.3235812172344284,-0.03289982032919614
218.0000000000024,27.812959998679123,0.3279757769761227,-0.03290221676300753
219.2000000000024,27.927828723104202,0.3336941523177625,-0.03290598495573338
220.40000000000242,28.041915381242106,0.3400273064647211,-0.033507669175193655
221.60000000000244,28.156497567313505,0.3428214421025239,-0.035540036685262955
222.80000000000246,28.270982590052288,0.3486873556409342,-0.03554012500001047
224.00000000000247,28.386231723763743,0.35054984839398107,-0.03554013310581894
225.2000000000025,28.499799937608188,0.3546797047264182,-0.036512162604566356
226.4000000000025,28.6158594754723,0.3612586338680454,-0.036850125039558534
227.60000000000252,28.731444496604464,0.36704627223750325,-0.03685012058011239
228.80000000000254,28.845389641794203,0.37104331706113125,-0.035868916442708176
230.00000000000256,28.960253054228478,0.37700244991539816,-0.03848928106353089
231.20000000000258,29.07398908286031,0.3808148457974298,-0.03981034723488719
232.4000000000026,29.188260344496513,0.388369584996903,-0.039810400757901654
233.6000000000026,29.303781516544003,0.3931292126314934,-0.03881691515127983
234.80000000000263,29.41866554665196,0.399215802240894,-0.04112999644460391
236.00000000000264,29.53284358441325,0.40475567494748105,-0.04113003765999412
237.20000000000266,29.64817717492174,0.4124421740177022,-0.04246563005409332
238.40000000000268,29.762117570781335,0.4204981202746102,-0.043769754969545716
239.6000000000027,29.87661211253046,0.4293435690083221,-0.042777246404948066
240.8000000000027,29.991816985418367,0.44050084841793846,-0.044094715046123056
242.00000000000273,30.105084091201473,0.45357261270803534,-0.046752458722438384
243.20000000000275,30.22118383156889,0.46907385192416123,-0.04672011698673195
244.40000000000276,30.33458709941297,0.4843900234562688,-0.04673859826235738
245.60000000000278,30.450583913250334,0.5031668140436202,-0.0480959878386793
246.8000000000028,30.565281172356787,0.5216149916412054,-0.050670414968900346
248.0000000000028,30.681263956417173,0.5354440000120201,-0.050747103576832764
249.20000000000283,30.795445690201543,0.5528333943039986,-0.05266337178422198
250.40000000000285,30.91033524408457,0.5827282226453228,-0.05327772741150216
251.60000000000286,31.02534231556119,0.644543696398553,-0.054615912251750665
252.80000000000288,31.14103576706664,0.7201812612569427,-0.05592863774906309
254.0000000000029,31.256019100954777,0.7762404883648915,-0.058240121466046624
255.20000000000292,31.37188231165162,0.7952657064202279,-0.05956676035206776
256.40000000000293,31.4872411587258,0.7655232307922097,-0.06116497687375144
257.600000000003,31.601928687216922,0.6904346780907934,-0.06273578630686849
258.80000000000297,31.71601851218509,0.6192710185561553,-0.06428242703905784
260.00000000000296,31.831332504004763,0.5693509436018911,-0.06749336147310903
261.200000000003,31.94425934565143,0.5446710450919195,-0.06878160679818812
262.40000000000305,32.0593718918032,0.5301692787944974,-0.07142082713383235
263.60000000000304,32.17436545180512,0.5254988749478441,-0.0737095578080913
264.800000000003,32.288498152029796,0.5230064359847919,-0.07501913200178123
266.00000000000307,32.40227060613382,0.5256248716495484,-0.07774101446679005
267.2000000000031,32.516804563218194,0.5258474890263259,-0.07943402804902888
268.4000000000031,32.63122904713808,0.5302882460379332,-0.08279810896035755
269.6000000000031,32.7451767451132,0.53390674503722,-0.08705702909850821
270.80000000000314,32.859786689723116,0.5379357185008143,-0.08851413136214337
272.0000000000032,32.97335728440721,0.5416734089737767,-0.09125570400896876
273.2000000000032,33.089245552456866,0.5460337010403279,-0.09508828633661048
274.40000000000316,33.20410352311416,0.5477525463556028,-0.0985093339138996
275.6000000000032,33.318659710841494,0.554590707890572,-0.1011870899157743
276.80000000000325,33.43252304150977,0.5582574483064331,-0.10459710499045549
278.00000000000324,33.5473018630841,0.5620099893132474,-0.10969311736360954
279.20000000000323,33.662049983631874,0.5648641371446459,-0.11305132139216756
280.4000000000033,33.777280063243914,0.5699287653231989,-0.11854051390371367
281.6000000000033,33.891803288719686,0.5739563069109624,-0.12276480834259518
282.8000000000033,34.007738097440765,0.5783790466799773,-0.1271389153547111
284.0000000000033,34.12283902288493,0.5828873814926662,-0.13142958390384463
285.20000000000334,34.23770287722919,0.5878169923380026,-0.13715337089990598
286.4000000000034,34.353321500133546,0.5924253485192654,-0.14335961103870565
287.6000000000034,34.46788443167642,0.5998755171877402,-0.14782791710896825
288.80000000000337,34.58220585263906,0.6039866772406762,-0.15384752429704251
290.0000000000034,34.69823387678537,0.6094574299168349,-0.15889833387279406
291.20000000000346,34.813761832798384,0.6126094407820804,-0.16728988120176602
292.40000000000344,34.928697776661124,0.6169120696037271,-0.17374128670535827
293.60000000000343,35.0441832832698,0.6223366485579197,-0.17941942397728372
294.8000000000035,35.15897545345054,0.6251279130841303,-0.18394001675826566
296.0000000000035,35.27404793307942,0.6281814695728521,-0.1917638093832883
297.2000000000035,35.38868301767137,0.6318720952755411,-0.20111327020498226
298.4000000000035,35.504127804845915,0.6352024985445772,-0.21086567669441036
299.60000000000355,35.61868606829164,0.6369102812562425,-0.220098799886697
300.8000000000036,35.73373306199971,0.6404991168680616,-0.22935378868730494
302.0000000000036,35.849716939640544,0.6426799584933854,-0.23840508696584717
303.20000000000357,35.96519867039144,0.6460837606894538,-0.24832016375402333
304.4000000000036,36.08079557210424,0.6512424751422075,-0.25905311545089926
305.60000000000366,36.19665547615497,0.6562001190823523,-0.2690447252870354
306.80000000000365,36.31241912654723,0.6638253656591954,-0.28028423366148747
308.00000000000364,36.427988253721566,0.6699124084313438,-0.29230674508070065
309.2000000000037,36.54299121113449,0.677661247040366,-0.30426278041633736
310.40000000000373,36.65826079546456,0.6858400139828982,-0.31831131942745694
311.6000000000037,36.773500131573,0.6952768444577224,-0.3310653840713491
312.8000000000037,36.88935294804641,0.7023862815346862,-0.3444401789359648
314.00000000000375,37.0048525329921,0.7132059849202322,-0.36088281472693895
315.2000000000038,37.121142915130925,0.7187241881819558,-0.3750797927167122
316.4000000000038,37.236287955211786,0.7264710586735194,-0.3926053885902885
317.6000000000038,37.352154036817,0.7362830917427015,-0.40925333433106426
318.8000000000038,37.46755305786498,0.7431553310686257,-0.42622239643215654
320.00000000000387,37.58223020979818,0.7520583915412433,-0.4462311479106824
321.20000000000385,37.69851501956778,0.7613099597296406,-0.4654734707162924
322.40000000000384,37.81507748660379,0.7729030341400749,-0.4866570605811509
323.6000000000039,37.931083744328525,0.7865062462876151,-0.5100235241527957
324.80000000000393,38.04680064888859,0.8034112966567934,-0.5329211455187313
326.0000000000039,38.162461759171165,0.8216079009566022,-0.5591938147927618
327.2000000000039,38.2792745890228,0.8468782832400654,-0.5860779959947626
328.40000000000396,38.395448123021374,0.8730709948537514,-0.6143427855356345
329.600000000004,38.51123405182707,0.9043308109562403,-0.6435094811314963
330.800000000004,38.62790500998007,0.9371882012855353,-0.6742443373338003
332.000000000004,38.74439252455157,0.9722428151313327,-0.7115414230963881
333.200000000004,38.86051183593092,1.0080841930943303,-0.7453089698782711
334.40000000000407,38.97719901533612,1.0436992586687006,-0.78459198012819
335.60000000000406,39.093088574996465,1.0798855916848575,-0.8248129644328617
336.80000000000405,39.20897689349608,1.1149060321272601,-0.8683076710556183
338.0000000000041,39.3257714713237,1.1516217919303848,-0.9129822480796754
339.20000000000414,39.44176925221095,1.1869647582802847,-0.9606671443799439
340.4000000000041,39.5567949966655,1.2174533799541565,-1.0107862837356811
341.6000000000041,39.67482082551116,1.2496313432908868,-1.0631086542342034
342.80000000000416,39.79124249402204,1.2738404497653044,-1.118945328772317
344.0000000000042,39.90852727513019,1.2963603637460681,-1.1798997553120278
345.2000000000042,40.02389638635595,1.308090667005918,-1.2406148488673026
346.4000000000042,40.14053388107358,1.3156365898975781,-1.3052607573765425
347.60000000000423,40.25737297347827,1.3130585307211673,-1.3697497936858056
348.8000000000043,40.37353329868579,1.30538494944556,-1.435191902117833
350.00000000000426,40.48936065148428,1.2930872287306485,-1.5008166082894863
351.20000000000425,40.60589722034866,1.2761237148719409,-1.5658366134561992
352.4000000000043,40.72321991047152,1.2562364305806417,-1.6317888006687489
353.60000000000434,40.838772531826756,1.2271357721362677,-1.6948432872742805
354.80000000000433,40.95543845037019,1.1930986828583212,-1.7590039490261193
356.0000000000043,41.07170787338734,1.151771264662359,-1.8183352524501069
357.20000000000437,41.18736887230547,1.1023687794249166,-1.8756917459417641
358.4000000000044,41.30319290559683,1.0485711860300924,-1.9289468365632247
359.6000000000044,41.42064849962774,0.9901767754981079,-1.9808753521114157
360.8000000000044,41.53481962081823,0.9314860193474763,-2.026656276892662
362.00000000000443,41.65139230884675,0.8725007764248216,-2.0657992606400404
363.2000000000045,41.76807865017127,0.8144725534015038,-2.101332916199316
364.40000000000447,41.88332715201363,0.763912476076139,-2.1314513263451
365.60000000000446,41.99916909826761,0.7182603832048542,-2.1588396119850493
366.8000000000045,42.11572433793249,0.6817430162575131,-2.183341874044155
368.00000000000455,42.23078896459014,0.6528791583160628,-2.2030644777365014
369.20000000000454,42.34812217283881,0.6288804931443764,-2.2216092001017707
370.4000000000045,42.46353986068543,0.6149603222506628,-2.2358864897706345
371.60000000000457,42.57852634413202,0.6030648226432906,-2.2483729501207117
372.8000000000046,42.69512554913938,0.5967442369239845,-2.2635252947880913
374.0000000000046,42.811561998111806,0.5923799611383614,-2.2765609231491646
375.2000000000046,42.926662409587415,0.5927002466266361,-2.2880431843830937
376.40000000000464,43.0436931999861,0.5914172158567679,-2.2998949283192385
377.6000000000047,43.16046990970921,0.5933386931683653,-2.310785186918374
378.8000000000047,43.2763983992169,0.5957152303298696,-2.321648348303596
380.00000000000466,43.39342640485744,0.5964109785740463,-2.3324287656590172
381.2000000000047,43.51078299366997,0.5999170149910307,-2.3441641297809057
382.40000000000475,43.627082275030915,0.6024411184119391,-2.3544545836304396
383.60000000000474,43.74315157032862,0.6068204622749052,-2.366294948340975
384.80000000000473,43.860134660387445,0.610310607775268,-2.376998841689766
386.0000000000048,43.977812354663065,0.6128967226944065,-2.39036866650367
387.2000000000048,44.094639437601884,0.6164056477693429,-2.400603792139395
388.4000000000048,44.21145318530962,0.6189738933692808,-2.4117663489799126
389.6000000000048,44.32764175853844,0.6244438948537735,-2.422923014534259
390.80000000000484,44.445601085852765,0.6304059168639985,-2.4343586573657827
392.0000000000049,44.562849086388994,0.6321741499338603,-2.446437162950233
393.2000000000049,44.679169055654974,0.6358300853977762,-2.4582720417316035
394.40000000000487,44.79652305700184,0.6397423363384663,-2.470723632646542
395.6000000000049,44.91260997025987,0.6421787303155383,-2.4834201790923194
396.80000000000496,45.02959480077135,0.6477357536429587,-2.4951825889019505
398.00000000000495,45.14651648389139,0.6509074369245298,-2.5084765844181844
399.20000000000493,45.26305592953909,0.6545461095064249,-2.5215149378391946
400.400000000005,45.3802565737654,0.6566960867542391,-2.5342996242581064
401.600000000005,45.497163200510116,0.6615491873465102,-2.5483247179405977
402.800000000005,45.61457903227047,0.6655622905171095,-2.5628865585355296
404.000000000005,45.73152553563038,0.6696220514560172,-2.576679127507547
405.20000000000505,45.84896734110001,0.6730315886116952,-2.5911987716304123
406.4000000000051,45.96650805740253,0.6773330378647319,-2.6057766066234285
407.6000000000051,46.0832245188902,0.6832207600566178,-2.621669252321395
408.80000000000507,46.20175640124156,0.6893686575614507,-2.6381323666875263
410.0000000000051,46.31710150617558,0.6960264691072557,-2.652167183260266
411.20000000000516,46.4348926086671,0.6997172676127354,-2.6710108749973713
412.40000000000515,46.55203611500626,0.706458083785474,-2.689247951868533
413.60000000000514,46.669744061635384,0.7120435514504563,-2.7067564524327627
414.8000000000052,46.78626059636725,0.7174365678455219,-2.724063685887996
416.00000000000523,46.90338923451871,0.7200310179142486,-2.745058432402954
417.2000000000052,47.02143141547254,0.7265589925663684,-2.7629219423181537
418.4000000000052,47.13857020221136,0.7331812951195955,-2.7828198377511746
419.60000000000525,47.25566892552871,0.7394634583132095,-2.8028974898255337
420.8000000000053,47.37299950431627,0.7446787717051685,-2.8237636521205234
422.0000000000053,47.49064859885353,0.7509608103349413,-2.840784025861513
423.2000000000053,47.60801766146865,0.7566225710447323,-2.8619423692916452
424.4000000000053,47.726188190702956,0.7607926548725067,-2.8832186927420533
425.60000000000537,47.84349882650265,0.7667752774888413,-2.903032476910162
426.80000000000535,47.961543285919696,0.7740590646504831,-2.9225833632950353
428.00000000000534,48.079170000000516,0.7781100000000019,-2.941780168000068
429.2000000000054,48.1956514469096,0.7829840802158926,-2.9601252588789073
430.40000000000543,48.31343421301119,0.787254368291719,-2.9781441170253093
431.6000000000054,48.43046833777436,0.7903587408259622,-2.996147567768742
432.8000000000054,48.548887163917726,0.7929623042782168,-3.0119464474490165
434.00000000000546,48.66711901000496,0.7967974198282978,-3.0276098488121437
435.2000000000055,48.78453357807042,0.7984293316394921,-3.0433208789016493
436.4000000000055,48.90275907831552,0.7986638362554256,-3.0576518974390203
437.6000000000055,49.01988244596726,0.7970814136965576,-3.0710470559204666
438.8000000000055,49.13766754603067,0.7980789701465272,-3.083883927478639
440.00000000000557,49.25477947915417,0.797973742484411,-3.0971507039343376
441.20000000000556,49.373572894552936,0.794592782950235,-3.1074600535008567
442.40000000000555,49.49079421158453,0.7923583871826769,-3.119346505180925
443.6000000000056,49.608688564763106,0.792888894702872,-3.128854168639637
444.80000000000564,49.7275993124278,0.7891706413181319,-3.1395285612603985
446.0000000000056,49.84520680086619,0.7853749143313369,-3.150351155386752
447.2000000000056,49.96275783130398,0.7812496843600103,-3.1592042772522517
448.40000000000566,50.0808636734218,0.7791461345731593,-3.1688300316644833
449.6000000000057,50.198481586920025,0.7719269246506523,-3.1780929358512604
450.8000000000057,50.31690667223238,0.7685768905283237,-3.183672965679683
452.0000000000057,50.435603476661626,0.7635044958724487,-3.1900223951204256
453.20000000000573,50.553189602138204,0.7585745469063379,-3.196936542512656
454.4000000000058,50.67084797937835,0.7551129918967396,-3.203455372213427
455.60000000000576,50.789944503512245,0.7483516151405907,-3.2093680628589984
456.80000000000575,50.90725336656706,0.7459620859672458,-3.213470109454587
458.0000000000058,51.02487566564511,0.7416829392704469,-3.2197319597357525
459.20000000000584,51.14273393816208,0.7371243680074577,-3.223928271430858
460.40000000000583,51.26110834071592,0.7363674586624938,-3.228484411991291
461.6000000000058,51.378971316446226,0.7338552149483547,-3.2339291591030648
462.80000000000587,51.497472952892934,0.7310695972777812,-3.2382470408332664
464.0000000000059,51.61494724359062,0.7294304751236951,-3.241170944659836
465.2000000000059,51.73369515856493,0.7288931803254702,-3.2446668366532263
466.4000000000059,51.852691244569435,0.7288127522280804,-3.2484659280838892
467.60000000000593,51.97044116485859,0.7281244014513428,-3.250618385501486
468.800000000006,52.08873230112908,0.7289333754951157,-3.2554843782108853
470.00000000000597,52.20463335493333,0.7308455025382664,-3.2566267170473124
471.20000000000596,52.32482290815199,0.7325068237946875,-3.259521327440509
472.400000000006,52.442670526686385,0.732858415117397,-3.2612001035630875
473.60000000000605,52.560839666191235,0.7341449544083065,-3.264609584736456
474.80000000000604,52.67951171732703,0.7377539095160599,-3.2658993307610333
476.000000000006,52.797168459701034,0.7403908725353179,-3.268540312007163
477.20000000000607,52.9155005283051,0.7430096964065672,-3.269790397082103
478.4000000000061,53.03369187728737,0.744282744224787,-3.2738963365419758
479.6000000000061,53.15285948085918,0.747906712602716,-3.2751969685725126
480.8000000000061,53.270956426819346,0.7506510408228872,-3.276666742364149
482.00000000000614,53.389170000000654,0.756149999999913,-3.2778600161294307
483.2000000000062,53.50703520317546,0.7588698156475687,-3.2818049505855615
484.4000000000062,53.62566718334383,0.7633476852664964,-3.28309759727061
485.60000000000616,53.744739659639464,0.7663004008561641,-3.283061841838587
486.8000000000062,53.863597144535824,0.7704982781085277,-3.284487694960334
488.00000000000625,53.98156994617307,0.7750140856443118,-3.286905640254483
489.20000000000624,54.10001818746555,0.7788967494186547,-3.2883901256871417
490.40000000000623,54.218430275240436,0.7852924574686843,-3.2897074763771443
491.6000000000063,54.33629303632397,0.7918859675773217,-3.291021256184923
492.8000000000063,54.45584956883819,0.8007247840346431,-3.2921833085991783
494.0000000000063,54.573458794584994,0.8053627921855385,-3.2922758345003116
495.2000000000063,54.693149972307474,0.8130905031870624,-3.294652459161374
496.40000000000634,54.81208534622521,0.8188857599598877,-3.295957678706238
497.6000000000064,54.93083798318524,0.8237484736577457,-3.2972495853252815
498.8000000000064,55.04968971033719,0.8303530439055778,-3.29688488535728
500.00000000000637,55.16859637418847,0.8365839054022357,-3.2997393374285493
501.2000000000064,55.28735558653534,0.8434899314977293,-3.302759995389935
502.40000000000646,55.405756860320935,0.8472102583922269,-3.3041218324107953
503.60000000000645,55.52504854919062,0.8526897850429961,-3.303848244897531
504.80000000000643,55.6444310947782,0.8586224206997839,-3.304121257956897
506.0000000000065,55.76369127434063,0.8637401515954718,-3.3053911810869545
507.2000000000065,55.88241394032354,0.8698373933027502,-3.306751473803068
508.4000000000065,56.00118131041941,0.8747260113912666,-3.3090094239197163
509.6000000000065,56.119656139852324,0.8804549310411112,-3.310312363430658
510.80000000000655,56.23947749572871,0.8859838526887313,-3.309000054627132
512.0000000000066,56.35790168758298,0.8923336865856781,-3.3109720258335136
513.2000000000066,56.47713050283741,0.8999980944333283,-3.3109047628112416
514.4000000000066,56.59573169997537,0.9012542789660918,-3.3136096126054815
515.6000000000066,56.714888706283446,0.9073584686693573,-3.314599769501121
516.8000000000067,56.83384018464568,0.9142211548847092,-3.315244294198161
518.0000000000066,56.95218253692915,0.9157725066794516,-3.316786611250974
519.2000000000066,57.070906933173,0.9199780908684513,-3.3181925325981583
520.4000000000067,57.19059344020101,0.9253767008805182,-3.3185504554724132
521.6000000000067,57.309656359829724,0.9289184446029641,-3.319861878872362
522.8000000000068,57.427537983692915,0.9325123190517111,-3.3184320194436308
524.0000000000067,57.54780455467238,0.9373307802308695,-3.3211801124560445
525.2000000000068,57.66609838625682,0.9393387478595858,-3.3225000395577933
526.4000000000068,57.78501289617214,0.9444579819298593,-3.3224091336044506
527.6000000000067,57.904122267161405,0.9498545736113547,-3.323809848176575
528.8000000000068,58.02377819247183,0.95484160437958,-3.3248439194717916
530.0000000000068,58.141931071125555,0.9578546025943049,-3.3247538502986753
531.2000000000069,58.26083238775561,0.9615724963469745,-3.3269026516686333
532.4000000000069,58.37967854918184,0.9628480042081895,-3.327429392618864
533.6000000000068,58.498307148969126,0.9634083856047364,-3.3286356005337794
534.8000000000069,58.617976378568244,0.9677049566783611,-3.328100179231515
536.0000000000069,58.73776174831423,0.9659936245198981,-3.3306525499727817
537.2000000000069,58.857305975959186,0.9688694202032333,-3.330738752287397
538.4000000000069,58.97617207272397,0.9722940820731946,-3.3307300879808235
539.600000000007,59.09564698632115,0.9756218756196429,-3.3314297117482488
540.800000000007,59.21560406709521,0.9787991868693007,-3.3336798681505964
542.000000000007,59.334976562081685,0.9808612357138328,-3.333679746515357
543.200000000007,59.4548668329426,0.9831532113254456,-3.3346436447156425
544.400000000007,59.573964803501596,0.9880823334157476,-3.336407875779869
545.6000000000071,59.69353447646225,0.9927815812524338,-3.3363203007640236
546.800000000007,59.813967869037626,0.9959706341914403,-3.3374493691119755
548.000000000007,59.932075777637415,0.9972130788631842,-3.3373113951527866
549.2000000000071,60.05272442813645,1.0032545828471409,-3.3377998643088214
550.4000000000071,60.17142916021592,1.0059035398876575,-3.340238590746015
551.6000000000072,60.28917226151639,1.0087400831348374,-3.3402216008167365
552.8000000000071,60.41040466057896,1.0123936661670905,-3.3416193243056607
554.0000000000072,60.52917000000063,1.015630000000018,-3.3415900449999567
555.2000000000072,60.64907319147572,1.0209572152571686,-3.3425617983720737
556.4000000000071,60.76906123067968,1.0239646677844922,-3.3428958412451206
557.6000000000072,60.889172138556724,1.0283897589981659,-3.343230198031944
558.8000000000072,61.0081386435939,1.0314056526252384,-3.34388998730607
560.0000000000073,61.12798108530095,1.0356939518666168,-3.3442195207297964
561.2000000000073,61.24833174758484,1.0404729734146283,-3.3452099427046784
562.4000000000073,61.3673465719475,1.0429565786363333,-3.346520082408452
563.6000000000073,61.48585059507876,1.0479786248176612,-3.3461976280856343
564.8000000000073,61.605536054041,1.0527325340427636,-3.3475098412141424
566.0000000000073,61.72560367219197,1.054853004514009,-3.3488623593449036
567.2000000000073,61.84547207362485,1.0605511920927677,-3.3488192852712793
568.4000000000074,61.965114238681466,1.0658230232848536,-3.3501329979394967
569.6000000000074,62.08481003949402,1.0723309209749028,-3.350478412402176
570.8000000000075,62.204901641072695,1.0744844884282145,-3.3504701590024393
572.0000000000074,62.32471610395554,1.0804906057130501,-3.350543220799965
573.2000000000074,62.444790497944666,1.0849680336864678,-3.3526454666198444
574.4000000000075,62.564628773668105,1.08991020792213,-3.351895373970475
575.6000000000074,62.683993439327075,1.0979516545754457,-3.3514768638156083
576.8000000000075,62.805735565234876,1.1014605830537214,-3.3567980654158722
578.0000000000075,62.92406193300476,1.1087426526446564,-3.3554100231317596
579.2000000000075,63.04427385800838,1.1131463091465956,-3.3567281532060753
580.4000000000076,63.165346756017215,1.1177260388219434,-3.356729893895657
581.6000000000075,63.28542743472318,1.125257304199033,-3.35901978952213
582.8000000000076,63.40591557431776,1.1274884028406085,-3.3603409736979692
584.0000000000076,63.5260447769222,1.1318569850448017,-3.3590514962310265
585.2000000000075,63.64693215733814,1.1335452849255752,-3.3603399474755205
586.4000000000076,63.76750350448074,1.138075719137958,-3.364282175944581
587.6000000000076,63.88768775956427,1.1398196035097905,-3.364290788455863
588.8000000000077,64.00707681329392,1.1408686624714142,-3.3644101931036428
590.0000000000077,64.12878630599155,1.1424045292238307,-3.3663689382711177
591.2000000000077,64.24852860516597,1.1476531694753513,-3.3692179787296594
592.4000000000077,64.36860176704029,1.1516676329788302,-3.3692298127753446
593.6000000000078,64.48958467026793,1.157276053957523,-3.370540440372507
594.8000000000077,64.60927231632296,1.1667433254658608,-3.3718600845506277
596.0000000000077,64.72926947183835,1.172575984629393,-3.3718600062309756
597.2000000000078,64.84964273137311,1.1823401860783125,-3.373208272240097
598.4000000000078,64.96926206269731,1.1931999322683033,-3.37449006626781
599.6000000000079,65.08947218597436,1.2031128595477714,-3.3758099088589875
600.8000000000078,65.20895090890318,1.2128985093249933,-3.377119472583168
602.0000000000078,65.32926714624477,1.2191174831833045,-3.3771199261133837
603.2000000000079,65.44936341091893,1.228334306634815,-3.3784390411567875
604.4000000000078,65.5696799382803,1.234289959226239,-3.3771201836847524
605.6000000000079,65.69064960273225,1.2396000890027359,-3.3795781501868207
606.8000000000079,65.81106433232505,1.2469454986707078,-3.379762952764234
608.000000000008,65.93026122173863,1.2505095945012255,-3.379750070460172
609.200000000008,66.05025041355677,1.257866560611748,-3.3823903939235773
610.4000000000079,66.17145075724258,1.2625264041029685,-3.3810720437773547
611.600000000008,66.2912414951307,1.2685120567407293,-3.3823901637114577
612.800000000008,66.40896787709286,1.2707307604529454,-3.38239022053014
614.000000000008,66.53195414961613,1.2780426519958668,-3.3805095256979634
615.200000000008,66.65193487526967,1.2818141877830074,-3.3837007283482023
616.400000000008,66.77247077239447,1.28778880653184,-3.3850200347704433
617.6000000000081,66.89333080515549,1.2914125156548744,-3.3837005115097742
618.8000000000081,67.01329532879458,1.2964007459666336,-3.384674240776927
620.0000000000081,67.13379957106602,1.3002448902606172,-3.384455364280277
621.2000000000081,67.2557093033154,1.3064016145470876,-3.3886550852208357
622.4000000000082,67.37524065512096,1.308773067030488,-3.3867698775617106
623.6000000000081,67.49525946927965,1.3139985406940196,-3.3867698490000047
624.8000000000081,67.61651133576764,1.3215018952753717,-3.386769848982445
626.0000000000082,67.73538161257366,1.3263032122299845,-3.3863251203836646
627.2000000000082,67.85662343252736,1.332032151499324,-3.3870001327161123
628.4000000000083,67.97680812809104,1.3373948584838016,-3.388108075034523
629.6000000000082,68.09722759892698,1.3431095095780763,-3.3882629596447327
630.8000000000083,68.21713001070313,1.3475773422712791,-3.390620012566366
632.0000000000083,68.33751506547125,1.3530486367767012,-3.3906200129998485
633.2000000000082,68.45865069058051,1.3569391317203474,-3.390619554623441
634.4000000000083,68.57866790380785,1.3651928625475502,-3.3906198562322496
635.6000000000083,68.6995872928149,1.3704913793512912,-3.391953814450405
636.8000000000084,68.82071764830438,1.3778847288198488,-3.3919298972384793
638.0000000000084,68.94141916718509,1.3832006087227857,-3.391929887726896
639.2000000000083,69.06124450011666,1.3860898262876982,-3.3919323579440466
640.4000000000084,69.18282954990835,1.393605849873647,-3.393255756455922
641.6000000000084,69.3028454275321,1.4003654731251511,-3.3932501350035893
642.8000000000084,69.42414382495794,1.404579685201508,-3.3933206638168243
644.0000000000084,69.54433555967252,1.4103829879888643,-3.3945601255274003
645.2000000000085,69.66527477178279,1.4179858262937746,-3.3958834832725837
646.4000000000085,69.78673970238944,1.4228509091677877,-3.3945600089905534
647.6000000000085,69.90610135587778,1.4320545700506755,-3.394560005775351
648.8000000000085,70.02696216414127,1.4343157698364415,-3.3958939004027524
650.0000000000085,70.14819183694901,1.442307303915813,-3.3968594979142033
651.2000000000086,70.26805622115997,1.4474751206940168,-3.3969159073190713
652.4000000000085,70.38885758370749,1.4528111781529292,-3.3974578380195246
653.6000000000085,70.50947428072834,1.4587140449791405,-3.3960998749999867
654.8000000000086,70.63073268309108,1.4641932079044182,-3.396099929968548
656.0000000000086,70.75066065132563,1.471157246255472,-3.3978943201173117
657.2000000000087,70.87209342960112,1.4762323205101173,-3.3974165076801057
658.4000000000086,70.99178632495936,1.4822851983603524,-3.3985563578841016
659.6000000000087,71.11248947174974,1.4865584311022602,-3.399586126756546
660.8000000000087,71.2334883442677,1.4959637644142336,-3.398851671911819
662.0000000000086,71.3551480188062,1.5007238915575434,-3.398839800455034
663.2000000000087,71.47530179105257,1.511092100366456,-3.398839997089939
664.4000000000087,71.59584758293057,1.5172683255745996,-3.399880411754075
665.6000000000088,71.71705910938834,1.522254340265175,-3.4001598399082953
666.8000000000088,71.8364794278068,1.5272170565879273,-3.40015994162485
668.0000000000088,71.95784842797278,1.5336580311119195,-3.3994985022806663
669.2000000000088,72.0788477271955,1.5403024981029108,-3.401469858731425
670.4000000000088,72.1992782613463,1.5471140909113317,-3.402790811412863
671.6000000000088,72.32043147276846,1.5502580775839059,-3.4014770027592
672.8000000000088,72.4404383529875,1.5584791292281148,-3.4008757075248837
674.0000000000089,72.56192231453622,1.5628035635923962,-3.4031201845494454
675.2000000000089,72.68316415447957,1.5695740578635229,-3.4043432651861982
676.400000000009,72.80348251382469,1.5761056786878511,-3.403450028908037
677.6000000000089,72.9234337730503,1.5831870859900177,-3.403450025
678.8000000000089,73.04460494316534,1.5885809448134498,-3.4034500249939237
680.000000000009,73.16585255622671,1.5951419551844337,-3.4034113711825658
681.2000000000089,73.2862142373719,1.599696389783441,-3.4047600517835157
682.400000000009,73.40792307568941,1.608418186732637,-3.4047591296109454
683.600000000009,73.52876332425257,1.6147297927775914,-3.4044300520744555
684.800000000009,73.64879756478066,1.6209480834970393,-3.403765792862868
686.0000000000091,73.77097278166033,1.625869926651036,-3.405496734862781
687.200000000009,73.89110287853467,1.6310104422811498,-3.404446933470643
688.4000000000091,74.01240258742247,1.6396789070161584,-3.405749921626293
689.6000000000091,74.13268143596409,1.650231830875358,-3.4064153536191206
690.800000000009,74.25392570384147,1.6524681138216142,-3.407734586775829
692.0000000000091,74.37507829559404,1.6591704781345067,-3.405102931543179
693.2000000000091,74.49351623808406,1.6685746488187367,-3.4062534341965107
694.4000000000092,74.61661074953653,1.6731198546136303,-3.408719980762405
695.6000000000092,74.73756457751266,1.680132491030695,-3.4073969474707995
696.8000000000092,74.85863954367996,1.6866522159011885,-3.408034584038723
698.0000000000092,74.97957793416698,1.692892095932733,-3.4082785913182336
699.2000000000093,75.1011330230444,1.7024461426533601,-3.4087102784500236
700.4000000000092,75.22155175017436,1.70721095831522,-3.4082841935964474
701.6000000000092,75.34277700642082,1.7132716622967328,-3.4090398239523267
702.8000000000093,75.46314049442138,1.723729816134386,-3.4090398237279986
704.0000000000093,75.585994346353,1.7296107632334528,-3.40770803101693
705.2000000000094,75.70555011824284,1.7356821663150113,-3.4102499990361217
706.4000000000093,75.82678529175234,1.7442757215959523,-3.410364879740575
707.6000000000093,75.94833464524064,1.7513185655798078,-3.409261018284307
708.8000000000094,76.06856455026387,1.7587035731001355,-3.409920172049228
710.0000000000093,76.19063858598119,1.7622118448551711,-3.409926493359113
711.2000000000094,76.31180565917204,1.769159820158586,-3.410579676078753
712.4000000000094,76.4332746348306,1.776564564597835,-3.4105797989999873
713.6000000000095,76.55503104790289,1.782735704141968,-3.4105797989998288
714.8000000000095,76.67719039435933,1.7889707046233527,-3.4105791575365423
716.0000000000094,76.79846511773972,1.7976061011805453,-3.4106077166055337
717.2000000000095,76.9198668375178,1.8039280797292623,-3.4112396764578268
718.4000000000095,77.04154594817858,1.8115076393541054,-3.4114146605588953
719.6000000000095,77.16307466704897,1.8212605994232973,-3.411389612745676
720.8000000000095,77.28488745664289,1.825697886844142,-3.412276468352233
722.0000000000095,77.40603942462093,1.833001847733949,-3.4132097643170667
723.2000000000096,77.5270455909712,1.8411122531992539,-3.413209952490183
724.4000000000096,77.64885103112036,1.846805483243543,-3.412549866414877
725.6000000000096,77.7695747224829,1.8541508881333337,-3.412879623555906
726.8000000000096,77.88959686953834,1.860509007893561,-3.412544715500988
728.0000000000097,78.01214027133224,1.8708983335362996,-3.4134790094304517
729.2000000000096,78.13347804826006,1.8789542286762309,-3.4145281083961345
730.4000000000096,78.25527703090246,1.882781284857292,-3.4148501997716476
731.6000000000097,78.37700018163606,1.8919116623054895,-3.414850140463919
732.8000000000097,78.4978628679936,1.8988825683484905,-3.4133235686984915
734.0000000000098,78.61999173424081,1.9059424503353335,-3.410688744200031
735.2000000000097,78.7398340404227,1.9134684180744235,-3.417535066257608
736.4000000000098,78.86166752108414,1.920803031863562,-3.417489912675488
737.6000000000098,78.98311743802417,1.9279166168511086,-3.416176638239893
738.8000000000097,79.10382030022755,1.9361005524529546,-3.4174961592144455
740.0000000000098,79.22529128054737,1.9445798571470556,-3.415897392144093
741.2000000000098,79.3468922662119,1.9525994245676697,-3.4151868338817963
742.4000000000099,79.46864445073948,1.960601959586515,-3.4165004016539537
743.6000000000099,79.58944522770699,1.9696552473418865,-3.4178201648000743
744.8000000000098,79.71160077054051,1.9746401431471483,-3.4174896629839626
746.0000000000099,79.83331090151025,1.9844693080208589,-3.416500062533431
747.2000000000099,79.95315796949461,1.9921680300854505,-3.4178108029569323
748.4000000000099,80.0739598834338,2.0006904367498657,-3.4178101917728867
749.6000000000099,80.1956962195762,2.009367008610126,-3.4191195852432217
750.80000000001,80.31633008430187,2.017778710888854,-3.4191320007660764
752.00000000001,80.43775212482446,2.0271312199425924,-3.419130034838431
753.20000000001,80.55928521126037,2.0314464210758336,-3.419130035
754.40000000001,80.68023505755554,2.0397944819129004,-3.419130034996867
755.60000000001,80.80263854175007,2.047783650665679,-3.419103622355639
756.8000000000101,80.92418119505547,2.0582930714796426,-3.4204944519676306
758.00000000001,81.04513197281138,2.0623581937675746,-3.4204454672239497
759.20000000001,81.16729357187009,2.0699199938922277,-3.42044155773082
760.4000000000101,81.28869717332633,2.081766601887629,-3.420449905039487
761.6000000000101,81.40999768788551,2.0888840913715203,-3.4194981590644162
762.8000000000102,81.53062636609964,2.09855539411519,-3.420219737490614
764.0000000000101,81.6520165061372,2.1081651435744098,-3.421770200698578
765.2000000000102,81.77296179678052,2.1145163239491302,-3.4204500839012897
766.4000000000102,81.89677405053867,2.1249397481427015,-3.420450156992893
767.6000000000101,82.01732991918186,2.129782706127535,-3.4203998717361266
768.8000000000102,82.14120670221698,2.1380148775712216,-3.4212965957939465
770.0000000000102,82.26223203451131,2.144525380571448,-3.4207796584777896
771.2000000000103,82.3839289452714,2.1536053687719066,-3.422168041662658
772.4000000000103,82.50698406085255,2.161351550276872,-3.420770116336449
773.6000000000103,82.62779440157398,2.1704368942699106,-3.4220900898056694
774.8000000000103,82.74956178928258,2.181767303763611,-3.4220900899999998
776.0000000000103,82.87141870238958,2.1888172115572386,-3.422090089344392
777.2000000000103,82.9926571126383,2.1992141676380674,-3.423399890621962
778.4000000000103,83.11497547228112,2.2056764355805893,-3.422181048421639
779.6000000000104,83.23600334784263,2.215529161861837,-3.422095561852314
780.8000000000104,83.35706395378338,2.225293107658659,-3.422104576382214
782.0000000000105,83.47937846909718,2.2331787769812146,-3.4217399091596397
783.2000000000104,83.60112347152639,2.241179900466593,-3.423407795938409
784.4000000000104,83.72292333859488,2.2511853268474686,-3.4231023148890776
785.6000000000105,83.84312988745869,2.2608405384768564,-3.4237484187236253
786.8000000000104,83.96512692969621,2.2705089364794016,-3.4231638908466335
788.0000000000105,84.0867936588636,2.2793491017108516,-3.42340980122173
789.2000000000105,84.20863503211432,2.2889695239755845,-3.4234098071073893
790.4000000000106,84.33012067477486,2.294408671785606,-3.424729920646309
791.6000000000106,84.45141588791624,2.306427917712387,-3.423420021178333
792.8000000000105,84.57286005093496,2.314096158121466,-3.4234200454586743
794.0000000000106,84.6954057476489,2.3212025324155214,-3.4220989241700606
795.2000000000106,84.8159834819319,2.3320675045533723,-3.424729508005072
796.0000000000106,84.89787136735544,2.3395602864005873,-3.424750732307504