File: 01_Data/Cotton_Rug/STA/N2/10K_min/Cotton_Rug_STA_N2_10KData_220112_R2.csv
##Temp./Â°C,Time/min,DSC/(mW/mg),Mass loss/mg
50.0,10.762945068941171,-0.9272540142686139,-0.041677238649963755
51.20000000000002,11.076806957787154,-0.8338578179709577,-0.04181032856299982
52.400000000000034,11.295568329968066,-0.771586944069114,-0.043187377942180305
53.60000000000005,11.48278217159048,-0.7249013498514212,-0.04310201196522723
54.80000000000007,11.647376990887166,-0.6889757656670108,-0.0431880046191262
56.000000000000085,11.805273804931838,-0.6607165355914757,-0.04343805651735355
57.2000000000001,11.951079407867152,-0.6362198093705659,-0.04425357275739472
58.40000000000012,12.095102775620305,-0.6173273993635305,-0.044972109861492804
59.600000000000136,12.233546956044123,-0.6004849247135495,-0.04503210847861361
60.80000000000015,12.370397620139236,-0.5855155157463448,-0.044979836481625846
62.00000000000017,12.505183500000923,-0.5727114168455073,-0.04646943181555674
63.20000000000019,12.639187688646498,-0.5610270195991687,-0.046220430550033775
64.4000000000002,12.770102093132143,-0.5494585930353671,-0.047051484693668044
65.60000000000022,12.901124266955891,-0.5404992051622578,-0.04907430611997121
66.80000000000024,13.030926994252766,-0.5287651176506764,-0.0477115001642181
68.00000000000026,13.161004949240885,-0.5196329546802546,-0.04902624207324724
69.20000000000027,13.29050062679842,-0.5109683600945417,-0.04863720730666987
70.40000000000029,13.418237178525626,-0.5051866022179932,-0.047859577568856615
71.6000000000003,13.546017749040626,-0.49692091402143196,-0.049029276360900376
72.80000000000032,13.67247796511396,-0.4888558718375245,-0.049689708143525024
74.00000000000034,13.7988848727068,-0.48115788731962067,-0.051633571122035704
75.20000000000036,13.923693393655235,-0.4727371574761707,-0.050349631994484056
76.40000000000038,14.049183903054876,-0.4652293682451318,-0.050340488507186976
77.60000000000039,14.176060325013488,-0.4567527891198149,-0.05037165817433564
78.80000000000041,14.296139126370875,-0.4491534763092043,-0.05164997747322708
80.00000000000043,14.422212735117371,-0.44167256299522234,-0.05293734125337046
81.20000000000044,14.54576381758289,-0.43369523882793454,-0.05297265087287695
82.40000000000046,14.66911668728898,-0.427445815844634,-0.05297020120265916
83.60000000000048,14.792810838565755,-0.4189199322683182,-0.0542898112529171
84.8000000000005,14.91455516899515,-0.412128781460436,-0.05546651204269715
86.00000000000051,15.033664831085279,-0.4043285613743178,-0.055600505571621106
87.20000000000053,15.156071372904318,-0.3978576311824748,-0.05560016652845157
88.40000000000055,15.276935711312579,-0.3935053935331869,-0.05703163345480711
89.60000000000056,15.3974380247194,-0.3877974535042568,-0.05691999384015478
90.80000000000058,15.51910370649534,-0.3821351117692829,-0.05694343981709604
92.0000000000006,15.639415167820589,-0.37605722289805776,-0.05824037041091046
93.20000000000061,15.758058863744623,-0.37004053894206573,-0.056929812503553556
94.40000000000063,15.877897136940396,-0.3648286039321706,-0.05824040625938842
95.60000000000065,15.993807696430439,-0.35942096466650436,-0.058240023587058154
96.80000000000067,16.117292952826855,-0.3527504839180352,-0.05817810941646595
98.00000000000068,16.234941384224907,-0.3483612799728774,-0.05953432258552116
99.2000000000007,16.354215821154046,-0.3423862941076172,-0.060801208663800566
100.40000000000072,16.473065896331587,-0.33901685384143765,-0.059549752384326915
101.60000000000073,16.590976173073354,-0.33138546979201833,-0.06014258404451045
102.80000000000075,16.70913608703394,-0.32612451768843836,-0.06055856274702309
104.00000000000077,16.82713475770862,-0.3195333667286321,-0.060869014154194545
105.20000000000078,16.944657473599445,-0.3141781134987524,-0.0627102951040528
106.4000000000008,17.063307536330743,-0.30665742930118667,-0.062184990939204265
107.60000000000082,17.18213925454111,-0.30142322287596246,-0.06261898746523054
108.80000000000084,17.300211357046834,-0.29498759717108747,-0.0619584693454005
110.00000000000085,17.417799137906425,-0.2896269319978926,-0.06131005493910191
111.20000000000087,17.535842851762155,-0.2831819375910548,-0.06263495747943137
112.40000000000089,17.65365003004281,-0.2791151813639105,-0.063056452796447
113.6000000000009,17.769806090620804,-0.27327393578401843,-0.06230001842310795
114.80000000000092,17.888930915385405,-0.2646523103079853,-0.0636100907963777
116.00000000000094,18.004642241114677,-0.25778545253180385,-0.06493383255646323
117.20000000000095,18.123266068505693,-0.25209060408837436,-0.06393998273808466
118.40000000000097,18.24043002772376,-0.24768594170028133,-0.06361891979400314
119.60000000000099,18.35840053666148,-0.24139782518667746,-0.06230366582255531
120.800000000001,18.475209145602005,-0.23450199430573446,-0.06360873544254941
122.00000000000102,18.592243095504738,-0.22840899381897742,-0.06361078001765419
123.20000000000104,18.710098183785625,-0.2242986886491874,-0.06360892955022468
124.40000000000106,18.826065876392164,-0.21637361402265878,-0.06427045074088111
125.60000000000107,18.943969368122676,-0.20998811822756908,-0.06295917928520467
126.80000000000109,19.0600000000001,-0.20397000000001914,-0.06361993805501776
128.0000000000011,19.17832930301903,-0.19805512741045928,-0.0641055787173519
129.20000000000113,19.293301462297098,-0.19215328607321444,-0.06360862919196286
130.40000000000114,19.409811617856334,-0.1867825375433617,-0.062290120938988114
131.60000000000116,19.52717368360335,-0.1810521945419052,-0.06360783739508014
132.80000000000118,19.64302567149847,-0.1745666385037079,-0.06496319984751642
134.0000000000012,19.759109472740164,-0.16954311860610508,-0.06492398498117558
135.2000000000012,19.874894923190578,-0.16252233149290926,-0.06360996019659515
136.40000000000123,19.991699740646563,-0.15784232183740216,-0.06497777272372351
137.60000000000124,20.107365423686044,-0.1508948094466834,-0.0649304059866056
138.80000000000126,20.22341513305431,-0.1466218492033233,-0.06374330424709962
140.00000000000128,20.339461904380077,-0.1403595791141174,-0.06493005398454255
141.2000000000013,20.45609255876485,-0.13479797375602984,-0.06496076922115135
142.4000000000013,20.572941581111756,-0.12932867797446335,-0.06558006695390395
143.60000000000133,20.688177426333255,-0.12373831839242179,-0.06490842713306888
144.80000000000135,20.804067451104384,-0.11894627510481143,-0.06559022956647143
146.00000000000136,20.918856214342533,-0.11222869723802259,-0.06493002669566339
147.20000000000138,21.036075732643198,-0.10744967968843666,-0.06589541546442534
148.4000000000014,21.15141670346273,-0.10093682329214401,-0.06624997712414427
149.60000000000142,21.265490530650144,-0.09451371238114661,-0.06564084354408362
150.80000000000143,21.381761241108904,-0.08887937222170784,-0.06558275968861027
152.00000000000145,21.4978588531753,-0.0821820206275698,-0.06624008067670939
153.20000000000147,21.611844236794976,-0.07587544852096556,-0.06624008000000892
154.40000000000148,21.728640526564558,-0.0687508866768505,-0.06623795441306513
155.6000000000015,21.84381152380831,-0.06465376774018637,-0.06625005532943096
156.80000000000152,21.958615252241803,-0.057209513353352164,-0.06894136361341996
158.00000000000153,22.073248925152534,-0.05198061534581283,-0.0678899629369134
159.20000000000155,22.1885853481698,-0.04670055890655992,-0.06753904421741463
160.40000000000157,22.304763760552085,-0.04036921845051842,-0.06752519427539294
161.6000000000016,22.419702719975195,-0.0348018133625424,-0.06887980379098213
162.8000000000016,22.535254016811937,-0.028332434959601013,-0.0682310384781708
164.00000000000162,22.650501751396966,-0.02414347772230767,-0.068880272817744
165.20000000000164,22.765830701764155,-0.01859918172204726,-0.06887600742277433
166.40000000000165,22.881300987320493,-0.011824003593003443,-0.06986001327831914
167.60000000000167,22.99586266296648,-0.008612197094432299,-0.06986001200000169
168.8000000000017,23.10991285024265,-0.0026918191026173628,-0.06986001197964731
170.0000000000017,23.226760712564754,0.0020983664733415625,-0.0686016610739757
171.20000000000172,23.34140247441033,0.008221418244392875,-0.07018539381934241
172.40000000000174,23.45525518167179,0.013777975176479952,-0.0701907123089276
173.60000000000176,23.57129671390976,0.019350518077630847,-0.07151009038960066
174.80000000000177,23.68550778715926,0.024253616195158218,-0.06952238196246574
176.0000000000018,23.801467433331222,0.027387097958277037,-0.07085228807719801
177.2000000000018,23.916192752101097,0.03405241709220398,-0.0708607779530559
178.40000000000182,24.0311904149027,0.03981381811894147,-0.0721707393641089
179.60000000000184,24.14718073721354,0.04388752403732135,-0.07217176021734728
180.80000000000186,24.26227187580621,0.04956299679517599,-0.07183994470063304
182.00000000000188,24.377076310332072,0.053810892313655996,-0.07183984357997986
183.2000000000019,24.491455690300537,0.05928656389788732,-0.07249997443856415
184.4000000000019,24.606580896459466,0.06268674753898988,-0.0725007198837786
185.60000000000193,24.721243571823113,0.06739998330925549,-0.07268597933086118
186.80000000000194,24.835878685967817,0.07389963588651426,-0.07446883818985572
188.00000000000196,24.95065331927161,0.07790550285111539,-0.07315421651443277
189.20000000000198,25.06460987984634,0.08355490389971924,-0.07315639713407363
190.400000000002,25.18039008407404,0.08711215076525394,-0.07549449985970336
191.600000000002,25.295961454031847,0.09178718167850147,-0.07447144437962505
192.80000000000203,25.410493386097947,0.09733319205692867,-0.07447003799983243
194.00000000000205,25.52454345677744,0.10392947696056229,-0.07447414199003566
195.20000000000206,25.63833826205594,0.10913339184631593,-0.07677868106553243
196.40000000000208,25.75381354568616,0.11385051122803919,-0.07677974226682815
197.6000000000021,25.868220926916504,0.11928974069268806,-0.07578819472431597
198.80000000000211,25.982729714577665,0.12390475162267882,-0.07710003975148094
200.00000000000213,26.096675558322314,0.13049502363945248,-0.07709368668858829
201.20000000000215,26.210799689490504,0.13386386341432824,-0.07709653494405
202.40000000000217,26.326019432205925,0.13917100224252865,-0.07841999458213644
203.60000000000218,26.44113805615262,0.14387560248953637,-0.07809003303928685
204.8000000000022,26.553717759053566,0.14871885935973408,-0.07808754329126
206.00000000000222,26.669589546944447,0.1543744105346269,-0.0787501936155266
207.20000000000223,26.78529308796896,0.15913086998450843,-0.07966587358276289
208.40000000000225,26.899292736349853,0.163473225852853,-0.08005776812470389
209.60000000000227,27.01390657814956,0.1691103957079161,-0.07868681826772939
210.80000000000229,27.129908536494238,0.17374418348827633,-0.07878195540074184
212.0000000000023,27.243303979111907,0.17828569385997692,-0.08137814798534526
213.20000000000232,27.359026851802664,0.18462560980032425,-0.08138005486158795
214.40000000000234,27.4737029948679,0.19060646405093296,-0.08138086910649855
215.60000000000235,27.587939701646583,0.196512471714595,-0.0813898771274415
216.80000000000237,27.702604007749983,0.20135950224527693,-0.08174548805027326
218.0000000000024,27.81816353829904,0.2053701098021836,-0.08270206815041181
219.2000000000024,27.933465705272962,0.21067912892585172,-0.08399969194513668
220.40000000000242,28.045552252378634,0.21743830949097756,-0.08321946270453795
221.60000000000244,28.160740083849547,0.22091403221415631,-0.08533055288230029
222.80000000000246,28.275982825186375,0.22660148217814644,-0.08400307502591531
224.00000000000247,28.391177791497988,0.23133772187677548,-0.08665009031169424
225.2000000000025,28.50557320341389,0.23528448338839555,-0.08532980551944425
226.4000000000025,28.621276174021336,0.2401783811594051,-0.08532843862460648
227.60000000000252,28.735620150880212,0.24579761292241378,-0.08664029382558347
228.80000000000254,28.849900557716076,0.2516392150101245,-0.08730935831300668
230.00000000000256,28.963187984441987,0.2562813434863228,-0.08928624502496296
231.20000000000258,29.07897226152667,0.26290862214567645,-0.0892773404901499
232.4000000000026,29.19143017672026,0.2686618420474394,-0.09027015790783599
233.6000000000026,29.307125823922632,0.27341055287291344,-0.09061038355355011
234.80000000000263,29.4216586073039,0.28077781652625444,-0.09190980476581823
236.00000000000264,29.53670880472403,0.2863966383032066,-0.09192014105440949
237.20000000000266,29.648478141998513,0.29298297252276606,-0.09389443905937433
238.40000000000268,29.76494617884022,0.30003813876019614,-0.09330638651247636
239.6000000000027,29.87999903723803,0.3086899821214346,-0.09499014205547018
240.8000000000027,29.99526537418526,0.318223865269507,-0.09499007524009118
242.00000000000273,30.109153471496015,0.33120529767972207,-0.0972798942984272
243.20000000000275,30.224327439294207,0.34707265930525144,-0.09720868066989485
244.40000000000276,30.339337728337856,0.36271532838132886,-0.09991353664489377
245.60000000000278,30.453738090002197,0.38197591687513727,-0.10123770227435358
246.8000000000028,30.567994105430618,0.39858125708327447,-0.102480764788345
248.0000000000028,30.683687476551004,0.41323500537507707,-0.10188413102809779
249.20000000000283,30.798403799935258,0.4281048244777877,-0.1032101833903214
250.40000000000285,30.913206114917326,0.4583637476200334,-0.10453122522320646
251.60000000000286,31.026947110322105,0.5158069956937966,-0.10845943525090807
252.80000000000288,31.14283519629362,0.5854823990384167,-0.10688521881035218
254.0000000000029,31.25756407858811,0.633438142582123,-0.10955938989009928
255.20000000000292,31.372544599510444,0.6534004495247333,-0.11088964641402077
256.40000000000293,31.488149158373865,0.6311002547720944,-0.11373857539508636
257.600000000003,31.60412963543196,0.5631715843743126,-0.11375866169202897
258.80000000000297,31.7194562194428,0.49506941749606026,-0.11703108272626528
260.00000000000296,31.833428949396275,0.4481191977271043,-0.1196748085062933
261.200000000003,31.947248499996114,0.42260066331681906,-0.12098203633980464
262.40000000000305,32.062337867899,0.41044227454486687,-0.1223065578167164
263.60000000000304,32.17732569695801,0.40576049257916186,-0.1254123153650104
264.800000000003,32.29235977216551,0.4039070690890694,-0.1297734215191566
266.00000000000307,32.40715121963779,0.40548081104473993,-0.13120327622742112
267.2000000000031,32.52247156523788,0.4079873123115973,-0.13095719400961858
268.4000000000031,32.63595797699413,0.41152157664359623,-0.1349546427500754
269.6000000000031,32.75080612400166,0.4139673131112672,-0.13827018914283817
270.80000000000314,32.86636763430726,0.41869866495588504,-0.14094935052119384
272.0000000000032,32.9808296472354,0.42346829353342846,-0.1437917171383627
273.2000000000032,33.095848063582274,0.42826338189550167,-0.14895363234293768
274.40000000000316,33.210290013578124,0.43313195335447563,-0.15006636888798086
275.6000000000032,33.323457959631185,0.43630182763437514,-0.15311791545071207
276.80000000000325,33.438267137113314,0.44257955451708353,-0.1575889787571758
278.00000000000324,33.55467654590742,0.4473629748675955,-0.16138437873640932
279.20000000000323,33.67010077343929,0.45158414325051216,-0.1656251522036527
280.4000000000033,33.78507882315623,0.4551717736777323,-0.16912833556551998
281.6000000000033,33.89954310818041,0.4606193017205615,-0.1731928551933306
282.8000000000033,34.01489614934739,0.46607230015758555,-0.17867407617775344
284.0000000000033,34.130624084354345,0.4683759337760151,-0.18244433189188136
285.20000000000334,34.24270601045792,0.4734089667181283,-0.18668236703208674
286.4000000000034,34.36054544564113,0.47792381209085677,-0.19178786863288133
287.6000000000034,34.47393086736241,0.4828636067816996,-0.19748283874997918
288.80000000000337,34.59064578043066,0.48661403950852006,-0.20336510288727006
290.0000000000034,34.70492336553446,0.4918516246901548,-0.2111061987251901
291.20000000000346,34.8199989463092,0.49701979099630544,-0.21729008036597008
292.40000000000344,34.934585253905134,0.5000614108818751,-0.2230244603222431
293.60000000000343,35.04910707647666,0.50418706543339,-0.22989838952811725
294.8000000000035,35.16458993158074,0.5082333955599297,-0.23826160484641523
296.0000000000035,35.27922958054821,0.5116113285839292,-0.24324445890276758
297.2000000000035,35.39453000867234,0.5144955959010619,-0.25115664869031695
298.4000000000035,35.509721249826576,0.5182711250568508,-0.260578003334488
299.60000000000355,35.62471115939893,0.5225874644081621,-0.26795342834942604
300.8000000000036,35.74065217894944,0.5255907036834044,-0.27719834957655554
302.0000000000036,35.855411633449165,0.5273978697989878,-0.2856866750820384
303.20000000000357,35.970747153298944,0.5312446646854925,-0.2961269454823441
304.4000000000036,36.08602943081427,0.5366017435657021,-0.304662875313352
305.60000000000366,36.20138919788022,0.5411220785585024,-0.3156610690321484
306.80000000000365,36.31777728709178,0.5477290373533092,-0.326949731565231
308.00000000000364,36.43248102561813,0.556467211129486,-0.3368880011423818
309.2000000000037,36.54698864776161,0.5624793845218798,-0.35000926410004984
310.40000000000373,36.662531379518114,0.5717805571987999,-0.3616787822496206
311.6000000000037,36.77773974524709,0.5825833890928647,-0.37391764941307937
312.8000000000037,36.8941636353701,0.5899364655841978,-0.3864626384925818
314.00000000000375,37.00907121030193,0.5993586719265254,-0.4013232204159971
315.2000000000038,37.12450593833949,0.6076108237893756,-0.41418203123668684
316.4000000000038,37.24086130438301,0.6167084215294597,-0.42978931488604744
317.6000000000038,37.35567615203612,0.6271193603478393,-0.44723980265065144
318.8000000000038,37.47078219397881,0.6327601041212579,-0.4639552555369253
320.00000000000387,37.58678145922828,0.6441657788307013,-0.4808400803914217
321.20000000000385,37.70321124611734,0.6545864114652342,-0.49790889669078675
322.40000000000384,37.819799120897,0.6650199844009334,-0.5216272785975837
323.6000000000039,37.935099362067874,0.678448521061383,-0.5422634505742288
324.80000000000393,38.05068663755562,0.6951395043057322,-0.5626319491036655
326.0000000000039,38.1671657616792,0.7123190455645595,-0.5866780264606857
327.2000000000039,38.2830163170672,0.7332373252450752,-0.6125821741894959
328.40000000000396,38.39907349463755,0.7596714260746583,-0.6365309739036507
329.600000000004,38.515589160719976,0.7875130972811271,-0.6657061356558067
330.800000000004,38.63215777971418,0.8193280477177408,-0.6952507832205082
332.000000000004,38.74798724760148,0.8507177310684819,-0.726010658563335
333.200000000004,38.86136074197664,0.8848531676166259,-0.7589513685571081
334.40000000000407,38.979789525045305,0.9215972122211461,-0.7943362874906992
335.60000000000406,39.09534949633589,0.9589618346097728,-0.8326336304615167
336.80000000000405,39.21262025324124,0.9981440466857614,-0.8712094507654395
338.0000000000041,39.32872409484823,1.0355933003159277,-0.9124389428262165
339.20000000000414,39.44542171499547,1.0729175776680548,-0.9575036793419476
340.4000000000041,39.562342421590074,1.1113177739392983,-1.0057910934596537
341.6000000000041,39.67788992670431,1.1521188908955748,-1.0546377194145955
342.80000000000416,39.79567144607395,1.1864849443955263,-1.1096891121911074
344.0000000000042,39.912171178291935,1.2205966254529221,-1.1655547114698495
345.2000000000042,40.0276515441545,1.252513651616977,-1.2240237861606458
346.4000000000042,40.14410895357174,1.2768491539915077,-1.2865918781873829
347.60000000000423,40.262833936775216,1.295607558788652,-1.353334748214412
348.8000000000043,40.37812224099,1.305263339660789,-1.417360200281732
350.00000000000426,40.495648555673576,1.3042332100745806,-1.4860701750552185
351.20000000000425,40.61122362307796,1.298208274610567,-1.5553468607002792
352.4000000000043,40.72805321589723,1.284726876427907,-1.6219812568695202
353.60000000000434,40.84413787186081,1.2673245937509299,-1.6907269612309017
354.80000000000433,40.96009292017928,1.2445979121213084,-1.7560274459020375
356.0000000000043,41.07753374173679,1.211627842351975,-1.8203980345901738
357.20000000000437,41.19317870988114,1.172072722519343,-1.8830494712496555
358.4000000000044,41.30939485454894,1.122250376053806,-1.9458686681720376
359.6000000000044,41.42527732229674,1.0641668533087256,-2.0021735245430596
360.8000000000044,41.54108562482731,1.0037239950125145,-2.054027184784382
362.00000000000443,41.656964615843435,0.937736059859803,-2.101660502563404
363.2000000000045,41.77285124297408,0.8720057084738424,-2.1454079870109957
364.40000000000447,41.88886967152873,0.8075720998567821,-2.1833615104934454
365.60000000000446,42.00496707923276,0.7484749834417148,-2.2171453318995775
366.8000000000045,42.11949189729711,0.6952776844790735,-2.2444857162306624
368.00000000000455,42.235224862591465,0.6510584082128622,-2.2697835340803065
369.20000000000454,42.35195175920223,0.6127983573191372,-2.290604826190932
370.4000000000045,42.46685044885865,0.5841916187798102,-2.3100567197030024
371.60000000000457,42.581435299667824,0.5643756404075281,-2.3279023454502337
372.8000000000046,42.698834285317204,0.5498014257660255,-2.340761312501712
374.0000000000046,42.81524692594943,0.5387993520885165,-2.353944443864631
375.2000000000046,42.93228251342224,0.5327753927188887,-2.3680662107729233
376.40000000000464,43.04736411612073,0.5322939195564135,-2.3798657780725145
377.6000000000047,43.16411402013881,0.5312391761624401,-2.3903511259294095
378.8000000000047,43.281001892292544,0.5327519859466371,-2.4009304770128255
380.00000000000466,43.39705865051948,0.5340228075629367,-2.4147247921697543
381.2000000000047,43.513835086827456,0.5369214787488861,-2.4245762143489413
382.40000000000475,43.629797223631556,0.5413090034572986,-2.4357719640539877
383.60000000000474,43.74646909555618,0.5451523360252492,-2.446204810270065
384.80000000000473,43.863984524158425,0.5484708985698074,-2.45756555031997
386.0000000000048,43.97989493484244,0.550838317546977,-2.469346555073124
387.2000000000048,44.097443550175576,0.5548194133332417,-2.479522194486883
388.4000000000048,44.21422545546,0.5586861389430224,-2.491517692104079
389.6000000000048,44.331865729677936,0.5643523874826959,-2.503837556684733
390.80000000000484,44.4486720028244,0.5673853502157089,-2.5153068178839812
392.0000000000049,44.56568287998418,0.5714405748488378,-2.5269351719464197
393.2000000000049,44.6817435512484,0.5746149738064827,-2.538246167156002
394.40000000000487,44.799808126544875,0.57924256606436,-2.5524754320863945
395.6000000000049,44.917916425416024,0.5853748866663167,-2.562703842839217
396.80000000000496,45.03391219323586,0.5876941714367294,-2.5748619187442703
398.00000000000495,45.15086805511763,0.5918161519735357,-2.5874812617367446
399.20000000000493,45.268734627133625,0.5948272036699664,-2.600748807965644
400.400000000005,45.38572132154071,0.6015083995769952,-2.6154156910272843
401.600000000005,45.50310574729506,0.6070432964692822,-2.6277318705410693
402.800000000005,45.62110153159448,0.6089084487762433,-2.641379851207319
404.000000000005,45.737600503672105,0.6163235798835461,-2.6578667290777527
405.20000000000505,45.85530606774726,0.6201431159430093,-2.6715278455814597
406.4000000000051,45.97327169109246,0.6274780471727566,-2.6858673164759947
407.6000000000051,46.09020129361704,0.6319807054014535,-2.701495818300914
408.80000000000507,46.20742269429597,0.6363199874501221,-2.716977018657238
410.0000000000051,46.32510807645496,0.6418308602597578,-2.7340927042420535
411.20000000000516,46.44102719468613,0.6481090161818917,-2.750302817632009
412.40000000000515,46.558801839285785,0.6548178719097415,-2.768892505131494
413.60000000000514,46.6758470134448,0.6610558990489585,-2.7873356133260527
414.8000000000052,46.791799520942874,0.6654884546311173,-2.803447553294998
416.00000000000523,46.909327526792424,0.6725751876769909,-2.8235084215786928
417.2000000000052,47.02625908072209,0.6777703261534201,-2.842657166503833
418.4000000000052,47.14302197410992,0.6846536436290279,-2.862009748255699
419.60000000000525,47.26102054185778,0.689322520970911,-2.8840754037709617
420.8000000000053,47.377981842316196,0.6941494353733699,-2.9031956361373763
422.0000000000053,47.4954619908415,0.7013211276758143,-2.923707661946618
423.2000000000053,47.611019757652045,0.7067693504806926,-2.9445024178266737
424.4000000000053,47.729291360928116,0.7099479456835455,-2.964535413252883
425.60000000000537,47.84626584022138,0.7144679934484363,-2.9854299383260283
426.80000000000535,47.96394477581478,0.7194750406588817,-3.0052449845463327
428.00000000000534,48.081715923771746,0.7230699642942651,-3.023840584890795
429.2000000000054,48.19833802817923,0.7291242683175608,-3.0437033666478412
430.40000000000543,48.316309157108684,0.7334857926686584,-3.0618172394480943
431.6000000000054,48.43377968970732,0.7346416373724187,-3.078802751969296
432.8000000000054,48.551963750107916,0.7403337120158124,-3.097124118746291
434.00000000000546,48.669439622145035,0.743744228993846,-3.112730058209467
435.2000000000055,48.78761686002753,0.7437701805500407,-3.1286350794331326
436.4000000000055,48.90485447489075,0.7455992556090315,-3.143079085543331
437.6000000000055,49.02366838562261,0.7453034348692381,-3.1555639795649686
438.8000000000055,49.14114994862502,0.7454245531281454,-3.1701543315491785
440.00000000000557,49.259899081533284,0.7439962204051502,-3.183011092990148
441.20000000000556,49.37779365175508,0.7441339841759009,-3.1933641595442164
442.40000000000555,49.496451737157706,0.7425369226924206,-3.205196879311889
443.6000000000056,49.61326195720087,0.7413242596885361,-3.2148193575410438
444.80000000000564,49.730845773730444,0.7390198704584058,-3.2258602437619266
446.0000000000056,49.848936001790236,0.7380103668565167,-3.2346212548618984
447.2000000000056,49.966760554553204,0.7335108645882029,-3.2421395160029864
448.40000000000566,50.08383860740489,0.7294981857388813,-3.2520886176642785
449.6000000000057,50.201702349775665,0.7280361987568954,-3.259620146187487
450.8000000000057,50.320181292927195,0.7245625023273702,-3.266888250561319
452.0000000000057,50.43865011762307,0.7198736483674217,-3.2728187407670117
453.20000000000573,50.55572619679837,0.7189910388666968,-3.280271704397884
454.4000000000058,50.672819908610506,0.7141804716369762,-3.2856472563497165
455.60000000000576,50.7908911935119,0.7097666836289105,-3.2926115787828216
456.80000000000575,50.9081732024108,0.7071897744322004,-3.2968607478389425
458.0000000000058,51.025867984569935,0.7031456764690702,-3.30128730293432
459.20000000000584,51.14368768785903,0.7035495189722716,-3.3067799586001314
460.40000000000583,51.26118055381285,0.7010655850421813,-3.3105456881420374
461.6000000000058,51.38038634153158,0.7001858791332577,-3.3156094587774985
462.80000000000587,51.496543197893864,0.7000546636908843,-3.3193669659303118
464.0000000000059,51.615127439285466,0.6981496156836808,-3.3237207913261706
465.2000000000059,51.73293604835534,0.6985544211676395,-3.3265638473746533
466.4000000000059,51.85051146050933,0.6987485159954103,-3.3306229429946415
467.60000000000593,51.96999897441648,0.6977899263472616,-3.3322601837997516
468.800000000006,52.08780249844316,0.7006679345460537,-3.3350054775253035
470.00000000000597,52.20655030499838,0.7029912134272015,-3.337791462354583
471.20000000000596,52.325158411965866,0.705101249649732,-3.3402362928426927
472.400000000006,52.44381259839064,0.7061784248497527,-3.343233177037948
473.60000000000605,52.55980822686652,0.7089478283782086,-3.3455395676069686
474.80000000000604,52.680590601602475,0.7131982096750134,-3.3481696781285963
476.000000000006,52.79946905182582,0.7166815287154702,-3.3507685043088355
477.20000000000607,52.91746185090759,0.7185058529323523,-3.3521445850854654
478.4000000000061,53.03556510671319,0.7217667799262303,-3.35473874935293
479.6000000000061,53.15437470457776,0.7258631018053919,-3.3560702427054796
480.8000000000061,53.27270037729408,0.7312453231469376,-3.3545370657337688
482.00000000000614,53.390569470926714,0.7363981393953613,-3.356106369418239
483.2000000000062,53.50947885524973,0.7414876377286712,-3.3587424687383782
484.4000000000062,53.62820513188226,0.7464416876610698,-3.360666027704929
485.60000000000616,53.74522802319677,0.7531675846786893,-3.361979256372628
486.8000000000062,53.863662836488444,0.7623796814682673,-3.3623081416954372
488.00000000000625,53.980795712275835,0.772225253215193,-3.364445765581442
489.20000000000624,54.09988088792686,0.779419468908591,-3.3656932279993343
490.40000000000623,54.21730731619827,0.7874700718269105,-3.367347200033085
491.6000000000063,54.33622836078068,0.7957957412764247,-3.368463757867216
492.8000000000063,54.454747682614766,0.8018360812950796,-3.370376006386057
494.0000000000063,54.57243746399577,0.8089839027632889,-3.373175330318679
495.2000000000063,54.690492299292686,0.8155954075975244,-3.373169361288143
496.40000000000634,54.810101898029224,0.8232147713536991,-3.3744905075426925
497.6000000000064,54.92927678279773,0.8277622430007757,-3.37445618893644
498.8000000000064,55.047569407343694,0.8362787669673601,-3.377119638116233
500.00000000000637,55.16589806962509,0.8408705323184159,-3.3770349701498006
501.2000000000064,55.284853425873585,0.8470499134194467,-3.3789630040835017
502.40000000000646,55.40240364132435,0.8526059493863823,-3.3797494514208464
503.60000000000645,55.52308804820502,0.8605674167199989,-3.3818630706141164
504.80000000000643,55.64084023791557,0.8629824449714351,-3.381724342690495
506.0000000000065,55.76063895786815,0.8703591859115929,-3.3823921276947497
507.2000000000065,55.88038551692504,0.8741992466687296,-3.383660634345411
508.4000000000065,55.99862792759626,0.8778747332189151,-3.386500536650691
509.6000000000065,56.117938924644015,0.884037188174908,-3.386315545641436
510.80000000000655,56.23650246266108,0.8888997292588295,-3.3866117271420717
512.0000000000066,56.35605717605411,0.8928640450057055,-3.387646372084946
513.2000000000066,56.47598317142689,0.8960494354130601,-3.388969893877631
514.4000000000066,56.59491042147657,0.9007384615030447,-3.3902914091318803
515.6000000000066,56.714575123184744,0.9061144589439489,-3.390279690109903
516.8000000000067,56.83301155068232,0.91257248322964,-3.3916393852751803
518.0000000000066,56.952810808637736,0.9185930518169666,-3.3916008243241733
519.2000000000066,57.07220394132563,0.9209875156834825,-3.3929216696420155
520.4000000000067,57.19092823712976,0.925858134946054,-3.394211003296434
521.6000000000067,57.30921354365091,0.929681182670905,-3.3965401261953634
522.8000000000068,57.429684981404044,0.9330313468909263,-3.3965304490126105
524.0000000000067,57.54855679511115,0.9343046133169326,-3.396841578693188
525.2000000000068,57.66696855812463,0.9341776008214607,-3.396744668479869
526.4000000000068,57.7871888290554,0.938811309007709,-3.398912936392854
527.6000000000067,57.90630502131721,0.941165430294378,-3.3994900969807
528.8000000000068,58.0257084696739,0.9463276005052326,-3.3997924552303775
530.0000000000068,58.145300808860014,0.9504667898224857,-3.402129007005273
531.2000000000069,58.263879960976986,0.9538378561483073,-3.4031019117828425
532.4000000000069,58.38453052819788,0.95595067002988,-3.403439882969591
533.6000000000068,58.50401599965025,0.9617522663168462,-3.4031071701170004
534.8000000000069,58.62279884023108,0.965228044277687,-3.404430018454013
536.0000000000069,58.74282494219792,0.9711575588304486,-3.405102358243197
537.2000000000069,58.86227826261068,0.9734908363143471,-3.406984586273428
538.4000000000069,58.98198689331846,0.9772370481222119,-3.407470334179809
539.600000000007,59.10186925930806,0.9807590931077835,-3.4087108386335925
540.800000000007,59.22051313933086,0.986773344302416,-3.410019924695315
542.000000000007,59.34039692108524,0.9913854387197819,-3.4100196558883136
543.200000000007,59.46022312666219,0.9959818070305364,-3.4100296679996216
544.400000000007,59.579609079638956,0.9983901227078982,-3.412330146195095
545.6000000000071,59.69960341672869,1.008287132064468,-3.413299170098659
546.800000000007,59.81915933907697,1.0114818970972306,-3.41265989798793
548.000000000007,59.9385220806913,1.013143362467496,-3.413921271750466
549.2000000000071,60.05815010974128,1.0165642060064797,-3.4139804879456093
550.4000000000071,60.177591656188554,1.022056764809151,-3.4149599801208748
551.6000000000072,60.297164960106805,1.0285058770056545,-3.4162771444663713
552.8000000000071,60.41679173194266,1.0312274742431973,-3.4172701359561684
554.0000000000072,60.53646116546431,1.0384222748193899,-3.4172701031632533
555.2000000000072,60.65576707152962,1.0465392538172853,-3.418571018779976
556.4000000000071,60.77545730825736,1.0501760545967964,-3.4192432389329666
557.6000000000072,60.89398029206256,1.0552828691582496,-3.420234421514771
558.8000000000072,61.014334779297755,1.0607604688728818,-3.420550105666167
560.0000000000073,61.13382150334681,1.0657571262298018,-3.4218958334503538
561.2000000000073,61.253289237296556,1.06995876980136,-3.422860418851732
562.4000000000073,61.37279285504074,1.0729899515153865,-3.422987149945932
563.6000000000073,61.492432913666946,1.0794099461516524,-3.423509326159392
564.8000000000073,61.61250558011053,1.0850171893708835,-3.4241749408994853
566.0000000000073,61.731105736454964,1.092244686781492,-3.436480838887817
567.2000000000073,61.850976402148476,1.0952684213352457,-3.4325549068987247
568.4000000000074,61.970614786557036,1.1005367889323003,-3.429945355293428
569.6000000000074,62.0911143498619,1.106896090141803,-3.4296627124760732
570.8000000000075,62.20969707104912,1.1096615922139008,-3.426592695266087
572.0000000000074,62.32971737450154,1.1162496979769692,-3.425244943869183
573.2000000000074,62.44850583459936,1.1198192961068734,-3.4271732689679406
574.4000000000075,62.56909596847024,1.127205115422722,-3.4272488655638593
575.6000000000074,62.68694548424984,1.1340713616237545,-3.4302944868193292
576.8000000000075,62.80819598418667,1.1395517889536968,-3.4325200649100083
578.0000000000075,62.92656210373698,1.145859274115463,-3.433866920059551
579.2000000000075,63.046091289503124,1.1513401388162934,-3.4356096058497876
580.4000000000076,63.1661937886004,1.1584239384070238,-3.4384422933144627
581.6000000000075,63.28529820244344,1.1651928193014618,-3.439748571658622
582.8000000000076,63.40548582405062,1.1691099757472774,-3.43978749502367
584.0000000000076,63.525204183113054,1.1714149324155325,-3.4360760958351335
585.2000000000075,63.64457774501318,1.1783847427765293,-3.4351080228440307
586.4000000000076,63.76540726861528,1.177863648468023,-3.4314535131409953
587.6000000000076,63.88483944875879,1.1813417616609938,-3.432429773931431
588.8000000000077,64.0039898271177,1.1860650350130237,-3.438526707208325
590.0000000000077,64.1251007696133,1.1911585170629824,-3.4416042412066505
591.2000000000077,64.24434899114517,1.1953623956355728,-3.4439137314421817
592.4000000000077,64.36455803012032,1.2046181633566369,-3.4465472782160487
593.6000000000078,64.4842152997878,1.2117470657691538,-3.4465581074205094
594.8000000000077,64.60393724434776,1.2196968061250233,-3.447869300583199
596.0000000000077,64.72343228185608,1.2281371197941209,-3.449509760651488
597.2000000000078,64.84384854924338,1.2370660442366987,-3.4508284088048358
598.4000000000078,64.96387067088233,1.245715800668744,-3.4521394690201097
599.6000000000079,65.08334368293325,1.2550385829850526,-3.4511601849514366
600.8000000000078,65.20245564072891,1.261529824663556,-3.451160432008656
602.0000000000078,65.32395223975364,1.266868357285441,-3.4521501122376814
603.2000000000079,65.44382945668656,1.2699018622080924,-3.45346029420008
604.4000000000078,65.56299322382938,1.2809424931821236,-3.4527538005005285
605.6000000000079,65.68315937587698,1.2861322550093168,-3.4537901651512812
606.8000000000079,65.80348763820344,1.2915894148619982,-3.4540792914779646
608.000000000008,65.92393752738899,1.2996263594744641,-3.4554400779570624
609.200000000008,66.04431331481122,1.302529938476876,-3.4554194737082433
610.4000000000079,66.16486483324721,1.308184055627967,-3.456805433238878
611.600000000008,66.28547058366914,1.3147635196753242,-3.45740469154401
612.800000000008,66.40633869578627,1.3186801029382575,-3.458400017789441
614.000000000008,66.5259965718467,1.3264899660886182,-3.457756148660936
615.200000000008,66.64686418000056,1.333369026697142,-3.4590600405221648
616.400000000008,66.76646366233132,1.3397669529588587,-3.4603485468048936
617.6000000000081,66.88657786471339,1.3456549538070828,-3.4608164019308694
618.8000000000081,67.00749725600659,1.3550427938883691,-3.459776699282158
620.0000000000081,67.12777984970462,1.361023742871305,-3.460380725738665
621.2000000000081,67.24828957307822,1.3659854655105244,-3.4609122126108334
622.4000000000082,67.36799155018754,1.3695912687210503,-3.4623440885368977
623.6000000000081,67.48917955861451,1.3793064314333532,-3.4610306653859384
624.8000000000081,67.60816273010845,1.383197170497704,-3.4623501763181546
626.0000000000082,67.72913657571272,1.3902544557637242,-3.4626384543819366
627.2000000000082,67.849047661932,1.396186633466483,-3.4630002014698364
628.4000000000083,67.97010296998958,1.4039159598354265,-3.4633461263625787
629.6000000000082,68.08892740590652,1.4096280645198407,-3.463010068117623
630.8000000000083,68.21120675425398,1.4171935244310254,-3.4616900835258053
632.0000000000083,68.33155039311468,1.4259351470138086,-3.46282779215843
633.2000000000082,68.45303639899839,1.4297688627795329,-3.463942441364197
634.4000000000083,68.57304727351624,1.4364492875963804,-3.4639887521152684
635.6000000000083,68.69364130643822,1.4438828720784729,-3.4653098326420997
636.8000000000084,68.81414669241101,1.4503792320850684,-3.464329369053745
638.0000000000084,68.93414257661637,1.4574959217534118,-3.465630369149319
639.2000000000083,69.05465141074681,1.4664330848050604,-3.465629973083559
640.4000000000084,69.17564385551711,1.470389270565651,-3.466883710444843
641.6000000000084,69.29712152407292,1.4773405706194915,-3.467282251942577
642.8000000000084,69.4180674856922,1.4861153566489922,-3.466263727071344
644.0000000000084,69.53824980115688,1.4940116079596086,-3.4676093851406344
645.2000000000085,69.65882092955624,1.5019908212081097,-3.466633129024441
646.4000000000085,69.77919333468692,1.5082711134056606,-3.4666301239996717
647.6000000000085,69.90000230293856,1.515750333641478,-3.466630137386678
648.8000000000085,70.02076433271266,1.5222010761383837,-3.4679398803594736
650.0000000000085,70.14019191775958,1.5304867650991796,-3.4676075371639787
651.2000000000086,70.26136162619939,1.5342497396311965,-3.4676063079064416
652.4000000000085,70.38189925679916,1.5393089916230343,-3.468930193913955
653.6000000000085,70.50125514979943,1.5471354937986812,-3.467615077467359
654.8000000000086,70.62458566380322,1.5558919776045284,-3.4696687174748133
656.0000000000086,70.74629523716094,1.5622685186188165,-3.469592977568433
657.2000000000087,70.86736470476065,1.5711968357585695,-3.4709029859509375
658.4000000000086,70.98754835981454,1.577083781022266,-3.4699201743938803
659.6000000000087,71.1081269264394,1.5850470877123064,-3.471226856282282
660.8000000000087,71.23046264130342,1.5918019476810168,-3.471229845521831
662.0000000000086,71.35128064072691,1.5986146311389402,-3.4712298380000024
663.2000000000087,71.47208174905064,1.608523123564095,-3.47122983799697
664.4000000000087,71.59314790568168,1.6137400685309506,-3.471190266123732
665.6000000000088,71.71462839516252,1.6243841993405312,-3.472539999596499
666.8000000000088,71.8352977000547,1.6303281428194427,-3.4725405968379013
668.0000000000088,71.95603695938105,1.6402487406757853,-3.47303932584787
669.2000000000088,72.07545269093376,1.6455561458242676,-3.4738612300135356
670.4000000000088,72.19620321149985,1.6544946821128428,-3.472552907776599
671.6000000000088,72.31633371803626,1.659823586905019,-3.473860303153044
672.8000000000088,72.43733509190884,1.6670568588432122,-3.4748498639662766
674.0000000000089,72.55844388490736,1.6745262937391454,-3.474199124458476
675.2000000000089,72.67886897063394,1.6804641957837416,-3.4741998955245537
676.400000000009,72.80010915032534,1.6892123530918899,-3.4751800043627625
677.6000000000089,72.92176348103297,1.6983287228335564,-3.4751799740000546
678.8000000000089,73.04222539372351,1.7055803921799764,-3.47517996799473
680.000000000009,73.16284780780664,1.712930457536203,-3.4755103460320376
681.2000000000089,73.28357343401973,1.7222843453939667,-3.476830000885802
682.400000000009,73.40364165746328,1.7278426153425368,-3.47551263861415
683.600000000009,73.52433598542527,1.7389491913572173,-3.476831843660873
684.800000000009,73.64484868648177,1.743424918569525,-3.4768272351501612
686.0000000000091,73.76570191454978,1.7525460104402106,-3.476820120000758
687.200000000009,73.88650205216311,1.761632021887209,-3.4768201205997564
688.4000000000091,74.00812044357123,1.7687703160272619,-3.4781392062834864
689.6000000000091,74.1289572170176,1.7768046475731907,-3.4768250456936602
690.800000000009,74.24989896909577,1.7825052941075317,-3.4774819125165477
692.0000000000091,74.37052486053916,1.7922058627868651,-3.4775002717070915
693.2000000000091,74.49096618830514,1.801571517082414,-3.478140193920916
694.4000000000092,74.61257473443483,1.810005832951751,-3.4794501901016925
695.6000000000092,74.73314025166049,1.8184288781355764,-3.4794490707066617
696.8000000000092,74.8546017780528,1.8243452134849398,-3.478869477509211
698.0000000000092,74.97518056659243,1.8330880476173743,-3.479562512782062
699.2000000000093,75.09630286338925,1.8400713868026217,-3.4794598440078044
700.4000000000092,75.21717161094395,1.8500881474755158,-3.4794598429709374
701.6000000000092,75.33810258334452,1.8593143171673965,-3.4807733495272113
702.8000000000093,75.46000098902262,1.8681502148652833,-3.480780156
704.0000000000093,75.58198053539627,1.874150461234338,-3.4807801560176452
705.2000000000094,75.7019172682289,1.8839758289384088,-3.479458205326975
706.4000000000093,75.82245353015064,1.8916623744885281,-3.4818479229154042
707.6000000000093,75.94453722174474,1.9027041988041127,-3.4817599120122438
708.8000000000094,76.06506190993215,1.9092285272058418,-3.4817599169736964
710.0000000000093,76.18615329698184,1.92120222762602,-3.481086871044202
711.2000000000094,76.30802616438257,1.9282215893718813,-3.481324628010256
712.4000000000094,76.43054128622703,1.9360175018336336,-3.48093809612756
713.6000000000095,76.55031434363502,1.9436932797556619,-3.480469782369121
714.8000000000095,76.67238596101018,1.9533796547484907,-3.481762747255184
716.0000000000094,76.792338560759,1.9622013036779449,-3.481109962540004
717.2000000000095,76.91359294984252,1.9723867182678774,-3.482419372366417
718.4000000000095,77.03493189735558,1.9824238831993113,-3.4824201359998903
719.6000000000095,77.15652722502905,1.9898293037882349,-3.4824201359859526
720.8000000000095,77.27694705972324,2.0027296446706635,-3.4821432591423607
722.0000000000095,77.39804957429406,2.0094794995507606,-3.4834102354571006
723.2000000000096,77.52010257294921,2.0222883324379644,-3.482420360138697
724.4000000000096,77.64032680621783,2.02741133545634,-3.482419743607436
725.6000000000096,77.76232919625478,2.038938967320173,-3.4837399995533844
726.8000000000096,77.88391735531378,2.047707726842938,-3.4850460608327687
728.0000000000097,78.00498161075545,2.0590113735131337,-3.4853044436380007
729.2000000000096,78.12688087708747,2.0634524191434607,-3.4865661304428555
730.4000000000096,78.24787797994857,2.07436103291112,-3.4838414027259557
731.6000000000097,78.36938834307121,2.0797394050998674,-3.4838203091330113
732.8000000000097,78.49064553013511,2.0907947794640447,-3.485160016025028
734.0000000000098,78.61020362191385,2.0993847811365693,-3.4851600159078004
735.2000000000097,78.73272072791315,2.109229877447319,-3.486478119028397
736.4000000000098,78.85611481899521,2.118535046511727,-3.485185554896242
737.6000000000098,78.97796551937749,2.1257395654794777,-3.4865046926502528
738.8000000000097,79.09788811080634,2.135801468797339,-3.487790084287061
740.0000000000098,79.21949728650664,2.1444384446046163,-3.4864800825084235
741.2000000000098,79.34154878722073,2.154574950539387,-3.486487317693264
742.4000000000099,79.46192481051571,2.16353779212944,-3.487462186603281
743.6000000000099,79.58512188652576,2.1740745946499147,-3.488124050862945
744.8000000000098,79.707228277677,2.1840116384414947,-3.4874699893835794
746.0000000000099,79.82793291255179,2.192024156134852,-3.4880834638895077
747.2000000000099,79.94959686400078,2.2025142263564677,-3.4887797144306276
748.4000000000099,80.07057192428238,2.2133919897136916,-3.4891106697704823
749.6000000000099,80.19141749241018,2.222283681728359,-3.4881220394124575
750.80000000001,80.31403499016781,2.233889578403671,-3.4894145580011204
752.00000000001,80.4347523037184,2.2422279795781748,-3.489440135996681
753.20000000001,80.55718828433788,2.254305989430162,-3.489440136052535
754.40000000001,80.67736168349249,2.264219694223682,-3.4901725542394493
755.60000000001,80.79865334028591,2.2740106153969832,-3.4888797014094486
756.8000000000101,80.92019433384738,2.2841119462707717,-3.4901000280501626
758.00000000001,81.04225954979421,2.2937360234621784,-3.4894401316744554
759.20000000001,81.16441571683119,2.304690595082521,-3.4907494367924015
760.4000000000101,81.28607363479392,2.3099110153457914,-3.4917129703861782
761.6000000000101,81.40878705462556,2.323493913372962,-3.4907016293414634
762.8000000000102,81.52961513757636,2.331567790392949,-3.4920701099936107
764.0000000000101,81.65258472081622,2.342174232074623,-3.4920701099999794
765.2000000000102,81.77388322038878,2.3492869608812064,-3.4920701101693794
766.4000000000102,81.89588332360809,2.363263263226251,-3.492118065784206
767.6000000000101,82.01711169613237,2.3702337533632063,-3.4920698660045497
768.8000000000102,82.13823346865603,2.3813412378759455,-3.492069830361399
770.0000000000102,82.25882226305802,2.3919932228427623,-3.4933798450765177
771.2000000000103,82.38028563656245,2.4039888903841544,-3.493390002917062
772.4000000000103,82.50128896987106,2.4173377478028484,-3.4923997634819086
773.6000000000103,82.62258119073039,2.424699605828082,-3.49355935741772
774.8000000000103,82.74409621772828,2.4358919392872775,-3.493719698750083
776.0000000000103,82.86583502041331,2.447414568746645,-3.4940497066818645
777.2000000000103,82.98682956638521,2.458837291918716,-3.493084046090944
778.4000000000103,83.1081470414174,2.4663606428353892,-3.4940501617195876
779.6000000000104,83.23000195363701,2.476959899557302,-3.494050161999466
780.8000000000104,83.35176908703215,2.490625224456367,-3.494704142497784
782.0000000000105,83.47211274764196,2.4983715151012706,-3.4943694310878275
783.2000000000104,83.5942988880838,2.5106417551120632,-3.49435052479458
784.4000000000104,83.71768412764409,2.520889069838045,-3.4940399227041743
785.6000000000105,83.83885305527707,2.5307303741604126,-3.495359926072357
786.8000000000104,83.96043396576358,2.5418047909489103,-3.494039855641139
788.0000000000105,84.081950721776,2.55442621831987,-3.4953600201858297
789.2000000000105,84.20425962201864,2.5639857619279294,-3.495359768299778
790.4000000000106,84.32586971147813,2.5728701145464403,-3.496669891198442
791.6000000000106,84.44940120662663,2.5861122911806746,-3.496317610948216
792.8000000000105,84.57071667233578,2.598103807401196,-3.49502654080216
794.0000000000106,84.6931860814636,2.607972664226017,-3.4950375500507986
795.2000000000106,84.81497262977412,2.621041126674759,-3.496350077005753
796.4000000000106,84.93686298331583,2.6325437723931873,-3.4956900228024805
796.8000000000106,84.97732804698593,2.6350509975217125,-3.49569014142945