File: 01_Data/Cotton_Rug/STA/N2/10K_min/Cotton_Rug_STA_N2_10KData_220112_R1.csv
##Temp./Â°C,Time/min,DSC/(mW/mg),Mass loss/mg
50.0,10.78040499342348,-0.9326459783096126,-0.04500852482866158
51.20000000000002,11.090884972306046,-0.8262959215630676,-0.04554095639605826
52.400000000000034,11.305761448944736,-0.7558466600559758,-0.04732344044378367
53.60000000000005,11.4918178266136,-0.7025205268837723,-0.0481411560871825
54.80000000000007,11.66112631395788,-0.6614938303312247,-0.04989952551241039
56.000000000000085,11.812190267125285,-0.6281479935680843,-0.05035315575722521
57.2000000000001,11.963203250642199,-0.6011997211150467,-0.04863415351412792
58.40000000000012,12.104825743921833,-0.5787140479106196,-0.048704773809173485
59.600000000000136,12.243539979936541,-0.5582683012999438,-0.04985647901506818
60.80000000000015,12.382346725909283,-0.5402118854327811,-0.05286117927070766
62.00000000000017,12.517146401024196,-0.5276587853070517,-0.05165578431357387
63.20000000000019,12.651231777003067,-0.5118165634232293,-0.050522700156409694
64.4000000000002,12.78246337176695,-0.49966938819594847,-0.05156039175643112
65.60000000000022,12.913406299182853,-0.485266673340628,-0.05135719797823324
66.80000000000024,13.044077489909851,-0.47514267138764676,-0.05251879190728426
68.00000000000026,13.172968296785038,-0.46421300856888453,-0.05417813472558475
69.20000000000027,13.302314926940252,-0.45400127803545753,-0.05420639637620717
70.40000000000029,13.431064699723846,-0.44433902390801105,-0.05360793700200217
71.6000000000003,13.559012863807542,-0.4371995389337219,-0.05493223632385691
72.80000000000032,13.684560993497703,-0.4286066832658225,-0.05421711138966989
74.00000000000034,13.812164591360558,-0.41965924278854605,-0.05558278217896451
75.20000000000036,13.937458862933504,-0.4095025658040251,-0.057212433307108235
76.40000000000038,14.062298406639991,-0.40129226890456804,-0.056857700054527616
77.60000000000039,14.187064214850114,-0.39296025717667327,-0.05789403719960129
78.80000000000041,14.312993125486678,-0.3836596709490481,-0.05772460209659824
80.00000000000043,14.437130234712935,-0.374529309538141,-0.0576958184221974
81.20000000000044,14.560443933567106,-0.36711200712157094,-0.06122295501586317
82.40000000000046,14.68424774914096,-0.35862862019846997,-0.06185886006710328
83.60000000000048,14.807794228026784,-0.3505578871996033,-0.06183194026555183
84.8000000000005,14.930315424884542,-0.34207341717103046,-0.06339738520976956
86.00000000000051,15.051839547367035,-0.33598624968352847,-0.06238276567686185
87.20000000000053,15.17415092414047,-0.3286194983022121,-0.06162837079283934
88.40000000000055,15.294923820456777,-0.32158548252044933,-0.06039882237024141
89.60000000000056,15.414917381980063,-0.31547366833527785,-0.0639436498505832
90.80000000000058,15.535712822286799,-0.3076218649499234,-0.0659201859948455
92.0000000000006,15.656385552810235,-0.30110769716704794,-0.06456360937985295
93.20000000000061,15.77660483260668,-0.2952809186048337,-0.06721483952213791
94.40000000000063,15.896449144364995,-0.2889813861442128,-0.06766890273732429
95.60000000000065,16.013479065712193,-0.2837672981716687,-0.06792148149352872
96.80000000000067,16.133878384889492,-0.2770080861399489,-0.07083229354225073
98.00000000000068,16.253565799152543,-0.2704159145282115,-0.06788235041245771
99.2000000000007,16.372402009229468,-0.2637751089971334,-0.06908972955290427
100.40000000000072,16.49147526254569,-0.25878759153012304,-0.06923133139817939
101.60000000000073,16.6093245662628,-0.25329415012969353,-0.06895319242335685
102.80000000000075,16.7270384083803,-0.24789009114934504,-0.07108011403755743
104.00000000000077,16.844808916515127,-0.24217214440702928,-0.07075733013259056
105.20000000000078,16.961905033627758,-0.23759364201326866,-0.07155248295587047
106.4000000000008,17.08185378424938,-0.22919458761423514,-0.07182265117243336
107.60000000000082,17.19926538280953,-0.2221344378252159,-0.07211443742532664
108.80000000000084,17.31747624671523,-0.21669683522281669,-0.07336582922772328
110.00000000000085,17.43607825640242,-0.21088725153275603,-0.0727104375404517
111.20000000000087,17.55262336188733,-0.2049082947460559,-0.07407784298397857
112.40000000000089,17.670496112828058,-0.19884718496352413,-0.074040153111806
113.6000000000009,17.7884189701036,-0.19292021182093813,-0.07271893588989986
114.80000000000092,17.905062339446882,-0.18764854988254698,-0.07402988861685511
116.00000000000094,18.022122437102773,-0.1827367270846581,-0.07403084400809146
117.20000000000095,18.138275178768644,-0.17478054047401176,-0.07536203901572769
118.40000000000097,18.257907360064127,-0.16925813374740017,-0.07484725901334155
119.60000000000099,18.3750374099098,-0.16210506365255684,-0.07397712086546226
120.800000000001,18.492166164372275,-0.15623216621078084,-0.07403026067366181
122.00000000000102,18.6100000000001,-0.14965000000000833,-0.07382287547737887
123.20000000000104,18.724468636984522,-0.14283185159230963,-0.07643914664418938
124.40000000000106,18.843379864226247,-0.1364639125910893,-0.0764420780041406
125.60000000000107,18.960000000000107,-0.12873999999999747,-0.0754600398716816
126.80000000000109,19.07504125846983,-0.12335540796570404,-0.07645770984780142
128.0000000000011,19.19200959338163,-0.11675555763898329,-0.07515484933595307
129.20000000000113,19.308929417096678,-0.11039735850116336,-0.07643989925500438
130.40000000000114,19.42477854707496,-0.1048739684865262,-0.07775980725041665
131.60000000000116,19.542102959349126,-0.09763950840065835,-0.0784189607105108
132.80000000000118,19.658360653120347,-0.09102519991021724,-0.08151507299174643
134.0000000000012,19.774107149039885,-0.08516654510817454,-0.0787300943506466
135.2000000000012,19.891196534132394,-0.08018047980987132,-0.07732970396779049
136.40000000000123,20.006593644091623,-0.0726547729470572,-0.07732836124596787
137.60000000000124,20.12293108596641,-0.06681968345315022,-0.08026662676199603
138.80000000000126,20.23891569845948,-0.0607601620995277,-0.08006977400701576
140.00000000000128,20.35534647044345,-0.05546018667189821,-0.07874950259737412
141.2000000000013,20.471801201285718,-0.048773183243262665,-0.08005694440614741
142.4000000000013,20.58651733571822,-0.04151215947378936,-0.08137994119853165
143.60000000000133,20.70136382081537,-0.0381521931159828,-0.08138159898466402
144.80000000000135,20.817124007417018,-0.030970664967059705,-0.0813905094621421
146.00000000000136,20.932771334863887,-0.02508550206384619,-0.08072994615559148
147.20000000000138,21.04913666783944,-0.018708535124703152,-0.08203983291218409
148.4000000000014,21.164797268611757,-0.011342563242034353,-0.08300959392691665
149.60000000000142,21.281237056472804,-0.007292507683393169,-0.08237010341221396
150.80000000000143,21.39519031579297,0.00046346998827198485,-0.08139222837239402
152.00000000000145,21.51082867389929,0.005090377417519281,-0.08260204834077944
153.20000000000147,21.626078619005575,0.012374533953031092,-0.08139013644769477
154.40000000000148,21.740269318896097,0.018120799385139035,-0.08278695358633748
155.6000000000015,21.85665369007455,0.022843389115377272,-0.08269834499153816
156.80000000000152,21.971707476268513,0.030217173515956177,-0.0832737302157347
158.00000000000153,22.088365608258123,0.035681185572893244,-0.08306675270175257
159.20000000000155,22.201787474202305,0.040327441107714364,-0.08558945685435893
160.40000000000157,22.316517238376036,0.0463995470064728,-0.08597248532984869
161.6000000000016,22.432815897991674,0.053045119825430906,-0.08466984343834971
162.8000000000016,22.545322121366308,0.05613391644788149,-0.08598992745312861
164.00000000000162,22.662346294057855,0.06190776142893278,-0.08468163210104773
165.20000000000164,22.778925184864857,0.06838172572417259,-0.08467803512445071
166.40000000000165,22.893940134620248,0.07380984325207829,-0.08368590999063219
167.60000000000167,23.009744850515,0.08015022439020664,-0.08601947678082134
168.8000000000017,23.12473770046044,0.0859887251206461,-0.08774044241355794
170.0000000000017,23.239405966114823,0.09107301032399086,-0.08300591341896402
171.20000000000172,23.353874637840814,0.09612136432555966,-0.08400056042193205
172.40000000000174,23.46990363967837,0.10250351404859992,-0.08676197528379781
173.60000000000176,23.583876387289127,0.10889958464585049,-0.08639243812250053
174.80000000000177,23.70029273122691,0.11435281941015062,-0.08635908459298092
176.0000000000018,23.815239756668497,0.11685639752196035,-0.08770033957818191
177.2000000000018,23.93059896885204,0.12368998258670302,-0.08906976009685241
178.40000000000182,24.04580577621133,0.12899523528092263,-0.0913600926750906
179.60000000000184,24.15955513523628,0.13187561922560032,-0.09005206691901035
180.80000000000186,24.275045754917432,0.13839316284203793,-0.0887400406886587
182.00000000000188,24.39056240197514,0.1423560164468387,-0.08972008473637194
183.2000000000019,24.505454666107003,0.148140202978709,-0.08878925403122384
184.4000000000019,24.62107389662588,0.15469874124691724,-0.08841017055748246
185.60000000000193,24.73507014340637,0.1572443401046578,-0.09015275241134946
186.80000000000194,24.8517928528053,0.1605249208603872,-0.0897197690604341
188.00000000000196,24.965631407114802,0.1685774707461637,-0.0910399606719916
189.20000000000198,25.080208705280153,0.1722466152265344,-0.0910392765518453
190.400000000002,25.194522682954773,0.17573104349069082,-0.09105991524050028
191.600000000002,25.309033107554992,0.18200937178831247,-0.09036993588185327
192.80000000000203,25.42426215049317,0.18492035574475627,-0.09166695549063553
194.00000000000205,25.53899814837725,0.19261771647511605,-0.09170076007567429
195.20000000000206,25.653648729687166,0.19507226136653427,-0.09300993233259547
196.40000000000208,25.767741516338273,0.2003103586228976,-0.09367163840302606
197.6000000000021,25.882108345714187,0.20561744004966287,-0.09301115230131574
198.80000000000211,25.99834946918437,0.21082119104366953,-0.09300987330107224
200.00000000000213,26.111864863119848,0.21594474745436823,-0.09433012875039859
201.20000000000215,26.226724702537034,0.21972862270484073,-0.09432996800003401
202.40000000000217,26.34207072326898,0.22479340447098253,-0.0943299664251569
203.60000000000218,26.456121782214414,0.23001030141809403,-0.09564776935695685
204.8000000000022,26.57067372060309,0.23486306557202896,-0.09432983788772553
206.00000000000222,26.685151401897382,0.24180961264204476,-0.09426371635563369
207.20000000000223,26.79963147806526,0.2466773010457858,-0.09432834291036984
208.40000000000225,26.915192177136653,0.25128514608576835,-0.09853285379834542
209.60000000000227,27.02879534776946,0.25683442605746565,-0.0970618889830388
210.80000000000229,27.143353997517135,0.2611147047344937,-0.09673319908394884
212.0000000000023,27.257511111765098,0.2685635921122043,-0.09761993301636229
213.20000000000232,27.372835659006686,0.27510128885677776,-0.09892946634252109
214.40000000000234,27.487104218201935,0.2811901010845948,-0.09767001487644178
215.60000000000235,27.60309211469398,0.28740956400059314,-0.0979505153472644
216.80000000000237,27.71646328491929,0.2925925541303883,-0.09827925921261604
218.0000000000024,27.831592797401907,0.29666377594798765,-0.10067549702617296
219.2000000000024,27.944334350958744,0.30098733552781887,-0.10221660750204453
220.40000000000242,28.060000855784345,0.3064599896566493,-0.10221974684922008
221.60000000000244,28.17552638754992,0.3117127588050518,-0.10199855624251608
222.80000000000246,28.290412258669612,0.31572042228340563,-0.10221981266861269
224.00000000000247,28.40485940709369,0.3187638044484844,-0.1035391088866584
225.2000000000025,28.51666825451749,0.3241584771868147,-0.10354037319678344
226.4000000000025,28.63392177683134,0.3295861905152954,-0.10446525004687057
227.60000000000252,28.748253068349477,0.335346489182053,-0.10211984621624515
228.80000000000254,28.862484649506193,0.341498044346225,-0.10342904654984064
230.00000000000256,28.977555423180757,0.3491401816433695,-0.10342980467180718
231.20000000000258,29.09224701181478,0.3544544504399573,-0.10606690016928244
232.4000000000026,29.204866358739707,0.3587447469932731,-0.10605979381202069
233.6000000000026,29.321848158427212,0.3656643678230176,-0.10736868033694869
234.80000000000263,29.435234037281287,0.3697711286310515,-0.10723894499317499
236.00000000000264,29.549694124364994,0.3771282786980471,-0.10672412025094857
237.20000000000266,29.665074843667714,0.38399214547541993,-0.10802533226869881
238.40000000000268,29.779898424550545,0.3915561972751834,-0.10934974737813086
239.6000000000027,29.893755864954258,0.40147978189290273,-0.11131505602873393
240.8000000000027,30.006683835868316,0.4104114013092387,-0.11261032065743715
242.00000000000273,30.123613767575833,0.4237173121294262,-0.11331023996833878
243.20000000000275,30.2370467870896,0.44036637083669916,-0.11593400379446273
244.40000000000276,30.351519818976875,0.45651335495394385,-0.11592987819410494
245.60000000000278,30.466818035969705,0.47410410232390265,-0.11592220764942507
246.8000000000028,30.582870060996985,0.4924771792692355,-0.11627017153004715
248.0000000000028,30.695370755755352,0.5062479592347364,-0.1175808134873404
249.20000000000283,30.811562283393783,0.5221529000317001,-0.11922411688148937
250.40000000000285,30.925437079847658,0.5528689964929765,-0.12021170037470474
251.60000000000286,31.0402977970266,0.6093397050165429,-0.12284928998998934
252.80000000000288,31.155572576294418,0.6795313473571943,-0.12385264329797074
254.0000000000029,31.27029611604773,0.7295025576951892,-0.1251496629543407
255.20000000000292,31.385224127388778,0.7498730681743242,-0.1291961014241787
256.40000000000293,31.50048323727141,0.7285668632791752,-0.13043423179431857
257.600000000003,31.615007180136644,0.6617461820349636,-0.13172838645686236
258.80000000000297,31.726747064684115,0.5907327224832586,-0.13422573221307665
260.00000000000296,31.844019862554106,0.539282407693,-0.13451875426689375
261.200000000003,31.95825747210936,0.5127634668322356,-0.13803790548273254
262.40000000000305,32.07262491329454,0.499389684439693,-0.1385262674894574
263.60000000000304,32.186945880245176,0.4925001003992102,-0.14116594080137457
264.800000000003,32.300094849170335,0.4920707434879526,-0.1437888014044777
266.00000000000307,32.415150444982814,0.49361510288950494,-0.1456048556761198
267.2000000000031,32.529706686978166,0.49380427526908977,-0.14801287918426276
268.4000000000031,32.64554591856884,0.497468015214948,-0.15052800510094766
269.6000000000031,32.75742782298022,0.5012574173983311,-0.15300996154980684
270.80000000000314,32.874728719078036,0.5066294833914848,-0.15588432341774672
272.0000000000032,32.988908621912785,0.5106694514035703,-0.15960608321802017
273.2000000000032,33.10398992300983,0.5149690126844612,-0.16363051102802917
274.40000000000316,33.21750283301614,0.5174678151143889,-0.16643305048272783
275.6000000000032,33.33300812884519,0.522331638244444,-0.17043727141951726
276.80000000000325,33.44814135962891,0.5267523468844023,-0.17295082004163165
278.00000000000324,33.562773400226234,0.5291708450247398,-0.17687122792584464
279.20000000000323,33.67817827765142,0.5368728087476873,-0.18109365928977095
280.4000000000033,33.79245049467161,0.5400434973014112,-0.18542149522130558
281.6000000000033,33.90722511818098,0.5457586884299545,-0.18973555513096452
282.8000000000033,34.02136194032544,0.5476257684964098,-0.19557866001090218
284.0000000000033,34.13725485312951,0.5543121853542144,-0.1994645318601016
285.20000000000334,34.25236173888753,0.5580030085834341,-0.20444973143884493
286.4000000000034,34.367021933590294,0.5631878592843612,-0.20982161738879945
287.6000000000034,34.4821648038101,0.5676857198383162,-0.2146196165832106
288.80000000000337,34.598211787644644,0.5708911219718029,-0.222322315128463
290.0000000000034,34.712444131665016,0.5753298039865192,-0.22714019221583825
291.20000000000346,34.82676164046419,0.581802255878812,-0.23352979827249332
292.40000000000344,34.942615314710785,0.5845471038352156,-0.2403565525543203
293.60000000000343,35.057279667229075,0.5907138613029458,-0.2477621347703014
294.8000000000035,35.17257617862832,0.5950759844976538,-0.2543880174338793
296.0000000000035,35.28740851996409,0.5968146574859375,-0.2607345724440129
297.2000000000035,35.4033325075674,0.6016341882881541,-0.27046834635876715
298.4000000000035,35.51617135678772,0.6039320380267735,-0.27838758233071026
299.60000000000355,35.63244124191226,0.6065183430304649,-0.2864807209897515
300.8000000000036,35.748039540528445,0.6090697440695156,-0.2952898602577565
302.0000000000036,35.86264363050768,0.6113617282360744,-0.30393738353648114
303.20000000000357,35.97694967412214,0.6165824263048787,-0.3137329138884932
304.4000000000036,36.09343237245396,0.6210171720792552,-0.3255677525815033
305.60000000000366,36.20859103235967,0.6267941939151883,-0.3354188395626161
306.80000000000365,36.324019276761945,0.631565630516003,-0.34674730873172077
308.00000000000364,36.439616231986115,0.6398173411927541,-0.3570927556201866
309.2000000000037,36.55560673476341,0.648033564851665,-0.37042150660670004
310.40000000000373,36.670376290636284,0.6545455010327781,-0.3838304899482128
311.6000000000037,36.78546752258563,0.6630495911013444,-0.3965379037049037
312.8000000000037,36.900475126016765,0.6715458406489146,-0.4097367572561792
314.00000000000375,37.016815946332,0.6810709431266032,-0.42620642888583804
315.2000000000038,37.13143418399245,0.6891537351402452,-0.44008306011774767
316.4000000000038,37.24742181342429,0.6977725709333794,-0.4560076432622613
317.6000000000038,37.362802662107725,0.7045075419896086,-0.4726590872319907
318.8000000000038,37.47831392101643,0.7132416014136059,-0.48988490095620296
320.00000000000387,37.593242171798146,0.7221689093258542,-0.5077101752262316
321.20000000000385,37.70969557340424,0.7306322158137895,-0.5289706290750895
322.40000000000384,37.82585011319497,0.7415992472760908,-0.547533179630681
323.6000000000039,37.94161506779388,0.752626993804888,-0.5703106276970145
324.80000000000393,38.05611016989679,0.7698616012565068,-0.5952926093408029
326.0000000000039,38.172026861235345,0.7867806113621577,-0.6182356002106864
327.2000000000039,38.28763634958358,0.8093596084978449,-0.6439715149202754
328.40000000000396,38.40419687048549,0.8344962032655776,-0.67343292656727
329.600000000004,38.52030895461729,0.8621441236565791,-0.7018400108265119
330.800000000004,38.63626293124169,0.8936167616553341,-0.7315391202858086
332.000000000004,38.75380840788823,0.9265293723032582,-0.7639876531161041
333.200000000004,38.86902392503666,0.9592355006646289,-0.7999213078123537
334.40000000000407,38.985157303796946,0.9950905590503176,-0.8357572683285031
335.60000000000406,39.101674248563185,1.030167269010596,-0.8740582456948633
336.80000000000405,39.21742513703922,1.0650164640090125,-0.915294534921915
338.0000000000041,39.33407699349673,1.0991108029489272,-0.9593139632153722
339.20000000000414,39.450283053112734,1.1341549024376139,-1.004081607080896
340.4000000000041,39.56685087410162,1.1664471349999241,-1.0530233313001522
341.6000000000041,39.68267027960221,1.1973232034700791,-1.1032657832526436
342.80000000000416,39.799902115362514,1.223549118481193,-1.157025234410093
344.0000000000042,39.91558440945657,1.2465012087832619,-1.2123045571795843
345.2000000000042,40.03155439436982,1.2634762973880482,-1.2713020580805803
346.4000000000042,40.147997915908775,1.2736272785989535,-1.3327497932717294
347.60000000000423,40.26442994284828,1.2769782915406696,-1.3942025571719268
348.8000000000043,40.3800009204959,1.2748999516574495,-1.457616860551044
350.00000000000426,40.49650477673632,1.2633122163283792,-1.5194871191887938
351.20000000000425,40.6118820077159,1.2534871051025285,-1.5825244497329676
352.4000000000043,40.72900362812348,1.2336042439069888,-1.6477646130276602
353.60000000000434,40.84449921165478,1.2127024249098572,-1.7092675415370637
354.80000000000433,40.96090743323215,1.182706860617656,-1.7701638791860748
356.0000000000043,41.07730027169288,1.1473911542660964,-1.830431594588315
357.20000000000437,41.19266144986738,1.10327953280135,-1.8862007051054483
358.4000000000044,41.30847331058728,1.0517056607144095,-1.937826726529385
359.6000000000044,41.42518828984393,0.9951636068939932,-1.990396247582553
360.8000000000044,41.54104227519045,0.9346600051689374,-2.0366118502800536
362.00000000000443,41.6566756186056,0.8759143056440315,-2.0778014777905014
363.2000000000045,41.772035466924706,0.8165541601462251,-2.112936779859524
364.40000000000447,41.8883795391184,0.760810728441304,-2.146746638731084
365.60000000000446,42.00440313375505,0.7095223187825088,-2.1755066640868375
366.8000000000045,42.119204176446715,0.6673799056040607,-2.19998664648733
368.00000000000455,42.23574046013894,0.6315034401520668,-2.220912772573459
369.20000000000454,42.349523002162194,0.602883495476066,-2.238591927556733
370.4000000000045,42.467826951047755,0.5807339793789992,-2.253086888893126
371.60000000000457,42.58456106537349,0.5675680849567254,-2.267810501384006
372.8000000000046,42.700266234353904,0.5562694796458048,-2.281825168347981
374.0000000000046,42.81639585544073,0.5517018923302264,-2.29337659508058
375.2000000000046,42.933266623663485,0.5488917237754573,-2.3047232407929967
376.40000000000464,43.04989988957757,0.5481175676759882,-2.3181980746424067
377.6000000000047,43.16612805153152,0.5485391350716711,-2.3276654553377067
378.8000000000047,43.283118437395174,0.5492844623032379,-2.3395993715140264
380.00000000000466,43.39900345740287,0.5510138026323393,-2.34931902459114
381.2000000000047,43.51574503322691,0.5556968819985642,-2.360627113156993
382.40000000000475,43.63249859751519,0.5593200014536147,-2.3712303397759875
383.60000000000474,43.747638173111824,0.5616736295593812,-2.381170290999487
384.80000000000473,43.866437053435575,0.5655197955965579,-2.3934327351117224
386.0000000000048,43.981873494262636,0.5687407505091037,-2.403780562051015
387.2000000000048,44.09989783095749,0.5737719701655595,-2.4152681922529076
388.4000000000048,44.21383890279932,0.5753329602841599,-2.425880959146873
389.6000000000048,44.332902214634345,0.5801790411254416,-2.437548485935853
390.80000000000484,44.45061044241347,0.5838752787671593,-2.448651285390376
392.0000000000049,44.56732734708007,0.5877316750155204,-2.458965395156535
393.2000000000049,44.68488209638649,0.5896946895387396,-2.4708180464734157
394.40000000000487,44.802694310275456,0.5937928587866191,-2.4841037762698805
395.6000000000049,44.918786197331855,0.5963889862310667,-2.4955708172279785
396.80000000000496,45.03656487062649,0.6005706015410794,-2.5088174974899093
398.00000000000495,45.153441647171675,0.6015585961597114,-2.521217930030744
399.20000000000493,45.27180397443851,0.6068452513438811,-2.5345939801776507
400.400000000005,45.38833405230278,0.6097828859890944,-2.548651476798308
401.600000000005,45.50583858467289,0.6137115048500373,-2.562775877867928
402.800000000005,45.622945524282734,0.619112154280426,-2.575538807221032
404.000000000005,45.74037926996436,0.6233636876004075,-2.589510118432366
405.20000000000505,45.857741070234454,0.6284188300024333,-2.605114830394375
406.4000000000051,45.97265697767423,0.6323719074806996,-2.618461712860005
407.6000000000051,46.09157685908803,0.637369905352802,-2.6356230482467486
408.80000000000507,46.21029635452847,0.6412331673519761,-2.6518094635359812
410.0000000000051,46.32738833170215,0.6475292119478064,-2.6676785364662816
411.20000000000516,46.44360101270626,0.6507957401245799,-2.6849135150410985
412.40000000000515,46.55971461934224,0.657646799789553,-2.7002219943788663
413.60000000000514,46.678471516142494,0.662788243501613,-2.7199066186477623
414.8000000000052,46.796234088830715,0.6673179309722097,-2.737064537941907
416.00000000000523,46.913758408060005,0.6722510228621895,-2.755880290240012
417.2000000000052,47.030304463371614,0.6783065182675942,-2.7751046700758417
418.4000000000052,47.14851287416582,0.6843321983305144,-2.7952590505800363
419.60000000000525,47.266155944025286,0.690178288218442,-2.8128993507776463
420.8000000000053,47.382502705942436,0.6967399558563786,-2.8332042730157756
422.0000000000053,47.5000948548007,0.7003918238612062,-2.8526170822720767
423.2000000000053,47.61746915064553,0.7061936996456563,-2.8734752180746472
424.4000000000053,47.7346783787154,0.7105439278900711,-2.892951030282851
425.60000000000537,47.85192262629354,0.7164277894203396,-2.914059902397687
426.80000000000535,47.97000087323198,0.7194899230870193,-2.930485185730251
428.00000000000534,48.087359366200474,0.7239681567409108,-2.9527918983275034
429.2000000000054,48.204458417734806,0.7281481462386838,-2.9705638464583197
430.40000000000543,48.32299936101697,0.731714680707266,-2.988278453142547
431.6000000000054,48.44057043347579,0.7334473624356925,-3.0035068904283584
432.8000000000054,48.558792241354475,0.7370021776542961,-3.0217249445960768
434.00000000000546,48.67676407495835,0.7373282514624564,-3.0377799940747323
435.2000000000055,48.79365566058552,0.73881405030041,-3.051359642614343
436.4000000000055,48.911878256719646,0.7406638262765547,-3.065398611032103
437.6000000000055,49.02880505442131,0.741433536804129,-3.0808742078429887
438.8000000000055,49.14675308537829,0.7396663615628978,-3.0942885735058354
440.00000000000557,49.26440528209792,0.7399785283322566,-3.1054300476559487
441.20000000000556,49.38270692787681,0.7358944103059304,-3.117026026151102
442.40000000000555,49.499216625610245,0.7361204758224837,-3.129213722343697
443.6000000000056,49.617193878373946,0.733998823233571,-3.1409465596368564
444.80000000000564,49.73450616281597,0.7309051010476786,-3.1490207075815912
446.0000000000056,49.85197070716075,0.7289359894188413,-3.1580290365093666
447.2000000000056,49.97036938854223,0.72264404085971,-3.1672661470265524
448.40000000000566,50.08786756609262,0.7197001201920371,-3.1736189340398364
449.6000000000057,50.20528678477179,0.7152801136677596,-3.185660598793195
450.8000000000057,50.32407587645343,0.7093936806742803,-3.192406318901457
452.0000000000057,50.441421467692145,0.7036382706381864,-3.1986199098237256
453.20000000000573,50.559519033800356,0.7021664600440202,-3.20410641178868
454.4000000000058,50.67743390536303,0.6953542980945863,-3.2115355208972876
455.60000000000576,50.794285750096584,0.6930477048398046,-3.219303991775942
456.80000000000575,50.91241876836261,0.6881441067590102,-3.2221873394270406
458.0000000000058,51.03037608164009,0.6834274016486152,-3.2269598031858138
459.20000000000584,51.14805256412185,0.6807145402468292,-3.2312624515892527
460.40000000000583,51.26692742876017,0.6764871206716275,-3.235817960097512
461.6000000000058,51.383722413027066,0.6745160243281225,-3.2405059903171303
462.80000000000587,51.50256319343544,0.6721716940776866,-3.2438440856142146
464.0000000000059,51.62070077655382,0.6715015521997915,-3.2482596218086623
465.2000000000059,51.73886480383851,0.6709849380409812,-3.2508834555677106
466.4000000000059,51.85606588240616,0.6683277861533226,-3.2548857385311907
467.60000000000593,51.97551202346942,0.6694825812007787,-3.256987592396171
468.800000000006,52.09461892957651,0.6723646851152925,-3.2590194538188655
470.00000000000597,52.21076404536708,0.6685598281224742,-3.261777096979186
471.20000000000596,52.33121899102263,0.6702302055197265,-3.2644347882723412
472.400000000006,52.448491562072995,0.6719278197883927,-3.2670223689095597
473.60000000000605,52.56713469415723,0.67300795562311,-3.268221888090252
474.80000000000604,52.68583367211,0.6794835619598882,-3.27225133891091
476.000000000006,52.80377867102439,0.6793198619278014,-3.273650078882498
477.20000000000607,52.92239195061217,0.6830896554368415,-3.2762222326904924
478.4000000000061,53.03990866757745,0.6867192398936766,-3.278282251402541
479.6000000000061,53.1580394433546,0.6900259158176609,-3.280182615682957
480.8000000000061,53.27633709109641,0.6941483454519155,-3.281580529406772
482.00000000000614,53.39441121294871,0.6974750855970603,-3.2841523253283493
483.2000000000062,53.5136579506499,0.7012178915756422,-3.286765217158166
484.4000000000062,53.631365286785524,0.706956705502515,-3.288143274262362
485.60000000000616,53.74938415154805,0.7090705763542368,-3.2921944587225163
486.8000000000062,53.86705397072234,0.717701621362008,-3.290801977094744
488.00000000000625,53.98568925126117,0.726535343492758,-3.291788234133924
489.20000000000624,54.104453865085965,0.733090970681081,-3.2932395085430444
490.40000000000623,54.22222640425198,0.7417417242964398,-3.2940897323106615
491.6000000000063,54.339999086939635,0.7504300147608806,-3.296719698535159
492.8000000000063,54.45889078065463,0.7558259051643405,-3.2980400819868825
494.0000000000063,54.57713715240046,0.7637416211745408,-3.2978413477153623
495.2000000000063,54.69554890224957,0.7661219786031345,-3.300668561649752
496.40000000000634,54.81457563668709,0.7717586705776509,-3.3005751844916893
497.6000000000064,54.932697367253915,0.7763078064125268,-3.302905537388757
498.8000000000064,55.05234027269252,0.7806315759138182,-3.305278227373984
500.00000000000637,55.17029937385406,0.7848177693346333,-3.3056067150123685
501.2000000000064,55.29029478540234,0.7910576962854458,-3.3042999619057545
502.40000000000646,55.40854715726924,0.7977334455880454,-3.304949915082764
503.60000000000645,55.52846166191944,0.8005245327569723,-3.305645091511519
504.80000000000643,55.6466529401543,0.8074501226245924,-3.3085403502519553
506.0000000000065,55.76568606169502,0.8124044886568679,-3.310540180772005
507.2000000000065,55.885603835257164,0.8183260580443854,-3.3103481785609996
508.4000000000065,56.002797490467785,0.8223149085158759,-3.3088986444573534
509.6000000000065,56.122195213846744,0.8276727710682776,-3.3101726119408754
510.80000000000655,56.24097193467255,0.8318999154553794,-3.3121800154019025
512.0000000000066,56.359315468827305,0.8342422279485682,-3.313459293254931
513.2000000000066,56.479414598861695,0.8374881928205914,-3.316130846204717
514.4000000000066,56.59845119895165,0.8409618995504161,-3.3161321283341167
515.6000000000066,56.717275838264676,0.8467952772875326,-3.316163005283781
516.8000000000067,56.83618728020787,0.8489268578142395,-3.31744986897331
518.0000000000066,56.95535777187681,0.8523831557189856,-3.3200555553804394
519.2000000000066,57.07462723503797,0.8586244518605528,-3.321383554399412
520.4000000000067,57.192153593787665,0.863645843718663,-3.322394478315937
521.6000000000067,57.31333095425949,0.8672775774023731,-3.322718897942874
522.8000000000068,57.43280982771805,0.8695530025106779,-3.322719547647134
524.0000000000067,57.55105456037167,0.8763584320464122,-3.3240376291539255
525.2000000000068,57.6711925973144,0.8784904538918747,-3.3263329089931597
526.4000000000068,57.78999796482012,0.8859796632717123,-3.3276598551298933
527.6000000000067,57.90932023495169,0.8877906768880045,-3.3263398696584083
528.8000000000068,58.02841569834726,0.8912816292405977,-3.3276499935439103
530.0000000000068,58.14776901711245,0.890316947806525,-3.328411738853272
531.2000000000069,58.26789048993932,0.8913217871438903,-3.3296301600486498
532.4000000000069,58.38708375370038,0.8902035228709574,-3.3309362191883505
533.6000000000068,58.50739612808278,0.8911012407946647,-3.331010827108955
534.8000000000069,58.62468347069634,0.891554639617078,-3.3312699712198413
536.0000000000069,58.745921248309244,0.8945234326923905,-3.3332497673851256
537.2000000000069,58.86620222079569,0.8972223891091012,-3.331925893628186
538.4000000000069,58.986338841079764,0.8990953382140346,-3.3345404132419874
539.600000000007,59.105404429213,0.901898549523468,-3.334560091412603
540.800000000007,59.225141721732285,0.9046138175693427,-3.335548780496468
542.000000000007,59.34410164356385,0.9066038488846289,-3.337248170807885
543.200000000007,59.463532222219214,0.911593376558396,-3.3368700361260224
544.400000000007,59.58399662668942,0.9153720282922049,-3.3358808474809134
545.6000000000071,59.70251658996625,0.9195851868130152,-3.338209668698937
546.800000000007,59.82211629631208,0.9231814369077815,-3.338187699764915
548.000000000007,59.94204941998408,0.9276319235095686,-3.3385200784198807
549.2000000000071,60.06227838052551,0.9319711084294044,-3.3398331007012265
550.4000000000071,60.18152909235977,0.935021745872009,-3.3388397519355193
551.6000000000072,60.30156208153666,0.939105607820463,-3.3401599791609433
552.8000000000071,60.42041167898171,0.9422184816379332,-3.3410702075316485
554.0000000000072,60.54021119588017,0.9485142422080395,-3.3401607286578376
555.2000000000072,60.65907449753236,0.9502535058950121,-3.342468495640855
556.4000000000071,60.77873078884995,0.9551516347790147,-3.3437798604723663
557.6000000000072,60.8957927494959,0.9554858753578445,-3.343780187151588
558.8000000000072,61.01869815942213,0.9584176623169282,-3.3437800021372936
560.0000000000073,61.13703721814268,0.9636972483082419,-3.3464076285009137
561.2000000000073,61.25676697619849,0.9684118124477404,-3.3449783747343056
562.4000000000073,61.37714795134343,0.9726180899733032,-3.347612807097341
563.6000000000073,61.49730220791497,0.9760688887076862,-3.346413625549236
564.8000000000073,61.615874367959655,0.9806764988485909,-3.3477299733890407
566.0000000000073,61.736569491688805,0.982901031659289,-3.3491051739220192
567.2000000000073,61.855822601495284,0.9895989108142208,-3.3503634742648316
568.4000000000074,61.97594932975569,0.9894418118162145,-3.3489715692705126
569.6000000000074,62.09600541238141,0.9946266442760251,-3.3490398733178957
570.8000000000075,62.21634544767857,0.9984616333354224,-3.350359326468264
572.0000000000074,62.335785284679496,1.005900561239838,-3.3529934599464863
573.2000000000074,62.45614850483749,1.009604983700711,-3.351609990391574
574.4000000000075,62.57509400060539,1.0119876710153737,-3.3517231595548216
575.6000000000074,62.69591934214615,1.01992867729509,-3.3539941789125454
576.8000000000075,62.81545983018188,1.026844944878581,-3.3556201330168975
578.0000000000075,62.934895039421924,1.0303907874069296,-3.355622138564558
579.2000000000075,63.05541832762159,1.0363522968630863,-3.3569540080249363
580.4000000000076,63.17537013734589,1.0423306373334547,-3.3569420424466987
581.6000000000075,63.29562529185831,1.0509311463019992,-3.358250109295559
582.8000000000076,63.414014009135855,1.0550852872812848,-3.3595729308918165
584.0000000000076,63.534899752752054,1.061536572586865,-3.3605597490833867
585.2000000000075,63.65523767682737,1.0655231488079617,-3.360568584246511
586.4000000000076,63.77437558929368,1.0651441310338505,-3.3608245988219765
587.6000000000076,63.89539875118328,1.06938894595104,-3.3631919773084844
588.8000000000077,64.01590490594299,1.0696979246591758,-3.3631883597538668
590.0000000000077,64.1361769018665,1.0735635201596168,-3.364510026822421
591.2000000000077,64.25541457713037,1.076021001768294,-3.365034835392426
592.4000000000077,64.37568991027335,1.0832901803765345,-3.3687695452996453
593.6000000000078,64.49477219609298,1.087786741663917,-3.3687122326398597
594.8000000000077,64.614640143274,1.0953225495300773,-3.370128223517103
596.0000000000077,64.73439222564785,1.107431161566203,-3.371423058416827
597.2000000000078,64.85342478874693,1.1153904644397659,-3.3714270850858226
598.4000000000078,64.97491427340314,1.1236867839894056,-3.37147433067224
599.6000000000079,65.0956201271247,1.131708660524653,-3.3727369215053766
600.8000000000078,65.21520132589026,1.1365962461106374,-3.3738279347109112
602.0000000000078,65.33562798557996,1.1418887950231622,-3.3740499439551224
603.2000000000079,65.45558201055537,1.1478558359316275,-3.373650689163714
604.4000000000078,65.57536307360019,1.1518601483527275,-3.3753562877505927
605.6000000000079,65.69560607877557,1.1605847024716072,-3.3753612675581204
606.8000000000079,65.81548765423001,1.1659832728240929,-3.3756853666670597
608.000000000008,65.9353400595343,1.1699311974032915,-3.378000021646927
609.200000000008,66.05627194623656,1.1733825101725293,-3.3793141973836773
610.4000000000079,66.17582090948878,1.179763277591678,-3.3779475110659014
611.600000000008,66.29632586712623,1.1847967765946414,-3.3793109305219566
612.800000000008,66.41608928250149,1.1898370202247617,-3.3798951888240163
614.000000000008,66.5370174826331,1.1943908416848832,-3.3799929442361925
615.200000000008,66.65805430120294,1.1990785884175739,-3.380628763282363
616.400000000008,66.77800302136565,1.2034312655585824,-3.379320104831314
617.6000000000081,66.89822846873285,1.2081043530043323,-3.3806301262469662
618.8000000000081,67.01841857051784,1.214061677993954,-3.3806504975314247
620.0000000000081,67.13773543094776,1.2174546989090056,-3.3819499163906324
621.2000000000081,67.25620297567089,1.224132990720471,-3.3812175920034875
622.4000000000082,67.37844144848543,1.226391036058726,-3.3819449883016923
623.6000000000081,67.49918771378498,1.2327197035944863,-3.383253074360219
624.8000000000081,67.61938871998736,1.2366838082557792,-3.383270234525928
626.0000000000082,67.73978843303087,1.2432939585077492,-3.384579690820007
627.2000000000082,67.85957634250101,1.2483690381691739,-3.384579929222978
628.4000000000083,67.98077413554653,1.251620604870156,-3.3848794302199092
629.6000000000082,68.10139395687027,1.2584686322757719,-3.386001507170083
630.8000000000083,68.22128401927837,1.264282835643085,-3.3850130963866425
632.0000000000083,68.34195220226285,1.2685756931186591,-3.3850912979736774
633.2000000000082,68.46221963988047,1.2743215797357754,-3.385019756026127
634.4000000000083,68.58233039699289,1.2800073776804273,-3.385020006453058
635.6000000000083,68.70302796230861,1.286995026791737,-3.3863303586993756
636.8000000000084,68.82314100900795,1.2935985744421825,-3.3873298715610867
638.0000000000084,68.94363367102932,1.2985391966816757,-3.3873298720000053
639.2000000000083,69.06335041830177,1.3043945496761131,-3.3873299088694644
640.4000000000084,69.18373173417723,1.310971627736604,-3.387660084179214
641.6000000000084,69.30371192991063,1.3173800726162954,-3.3876178580670686
642.8000000000084,69.42470016284796,1.3222988645576572,-3.388635739257905
644.0000000000084,69.54519075016927,1.3274329583735127,-3.387972255931695
645.2000000000085,69.66570445166923,1.3331747783814274,-3.3879801039821498
646.4000000000085,69.78636534915731,1.3382104347665142,-3.3878409445827486
647.6000000000085,69.90727033868454,1.344068080607683,-3.389299972026276
648.8000000000085,70.02888176100817,1.3498425085419428,-3.389299972430682
650.0000000000085,70.15058263848871,1.3559457097103942,-3.3906092708897875
651.2000000000086,70.27046616510191,1.3605897715691389,-3.391608165465504
652.4000000000085,70.39179238357639,1.366742827786367,-3.3902800140334715
653.6000000000085,70.51249575147366,1.3717932630574678,-3.391599973607345
654.8000000000086,70.63304183320271,1.3792328949181074,-3.3902796041211296
656.0000000000086,70.75415881136205,1.3820652007267,-3.391268067759789
657.2000000000087,70.87379089928862,1.3902933631420125,-3.3902903897635586
658.4000000000086,70.99443723229328,1.3939418383914657,-3.3929108199347877
659.6000000000087,71.11596917490907,1.4011320221097225,-3.391600051784242
660.8000000000087,71.2374431282693,1.4060756876234206,-3.3928944514758475
662.0000000000086,71.35791099798098,1.4105418714748807,-3.391519997639611
663.2000000000087,71.4770791121204,1.4175568859019094,-3.3928578620629315
664.4000000000087,71.59968910877106,1.4234202619309915,-3.3929215221114317
665.6000000000088,71.72132076262181,1.4282201294553223,-3.393514156328334
666.8000000000088,71.84178232301409,1.4321559344098556,-3.391609963402872
668.0000000000088,71.96144997678655,1.4390195133471044,-3.392920260145087
669.2000000000088,72.08284557699659,1.4480742172636638,-3.394271119945727
670.4000000000088,72.20344148579623,1.451397703507977,-3.395575121129208
671.6000000000088,72.32324241981661,1.4597988042573509,-3.3945039036188844
672.8000000000088,72.44512807592398,1.466426695288743,-3.394237298376204
674.0000000000089,72.56508599940561,1.4739612943242566,-3.394890173620876
675.2000000000089,72.68570822864376,1.4807436022095435,-3.3955499843203887
676.400000000009,72.80613254849787,1.4860607080892057,-3.3955495361616483
677.6000000000089,72.92640792487924,1.49070627821935,-3.3978503319825397
678.8000000000089,73.04828803634744,1.4979396463477141,-3.39784984396432
680.000000000009,73.16870639083061,1.499574279450995,-3.3973573477146637
681.2000000000089,73.2895796709728,1.506255061464528,-3.3965295400626356
682.400000000009,73.4096829101532,1.5149771938011374,-3.3969144653938903
683.600000000009,73.53082288224194,1.521133085295558,-3.3969336523583755
684.800000000009,73.65193783498133,1.5307471656805651,-3.3965561869871506
686.0000000000091,73.77289234182989,1.5370578080351038,-3.397863059137581
687.200000000009,73.89275832581404,1.5438766375718669,-3.397859975960958
688.4000000000091,74.01463892001867,1.5503988152575072,-3.397440424809372
689.6000000000091,74.13500278319923,1.5562552632099893,-3.3977936436630554
690.800000000009,74.25582988626691,1.561894506470986,-3.3991754957053546
692.0000000000091,74.37760810906396,1.5674709590575606,-3.3978499445652837
693.2000000000091,74.49936556590183,1.5741215319082447,-3.3988459163362563
694.4000000000092,74.62017799155588,1.5850839167009507,-3.3988399439654207
695.6000000000092,74.74173026392033,1.5904878403536504,-3.3978846421611872
696.8000000000092,74.86261787177841,1.595355181092771,-3.3988398053027096
698.0000000000092,74.98528946838843,1.6035670385779308,-3.4001500826455215
699.2000000000093,75.10798763225564,1.6115411556962476,-3.4001501759999946
700.4000000000092,75.22798388615314,1.6174261187448131,-3.4001501759999755
701.6000000000092,75.34990657264566,1.6221362888401947,-3.4001501588547627
702.8000000000093,75.47278511757585,1.6270794632904664,-3.400479584361428
704.0000000000093,75.59438093922579,1.6349723492625563,-3.3994918115398267
705.2000000000094,75.71297411207269,1.6411247959288493,-3.4008139353151825
706.4000000000093,75.83742576665573,1.650877301701603,-3.402107693106188
707.6000000000093,75.95970850093688,1.654595224259059,-3.403450120757706
708.8000000000094,76.08058400308455,1.6649231159172628,-3.4021050683156524
710.0000000000093,76.20276092291529,1.6705886435311086,-3.3998095961422257
711.2000000000094,76.32414108734446,1.6757886031213487,-3.400479859781508
712.4000000000094,76.4454350921976,1.6852319812893433,-3.401910172631987
713.6000000000095,76.5669423625178,1.6918446463418233,-3.403544845515649
714.8000000000095,76.68749215239619,1.7008146053204423,-3.40421084177673
716.0000000000094,76.80880256120349,1.7080292286117538,-3.402900727129207
717.2000000000095,76.92878754047285,1.7141179702317402,-3.402897487769278
718.4000000000095,77.0493890427382,1.720625066205449,-3.4045482145784582
719.6000000000095,77.17000204528983,1.730140353425004,-3.403860364467966
720.8000000000095,77.291280140197,1.7348521484788981,-3.4028984442477066
722.0000000000095,77.41185276284274,1.7428397468147827,-3.404864173389592
723.2000000000096,77.53518086949977,1.7496729784742227,-3.404815517814164
724.4000000000096,77.65504523454698,1.7580106602030037,-3.40499983948778
725.6000000000096,77.77643396312597,1.7639711871764892,-3.404880120084036
726.8000000000096,77.89689809483275,1.7721212016534218,-3.4061805457535046
728.0000000000097,78.01882172721682,1.7795016027829256,-3.4075000799554656
729.2000000000096,78.14095774417116,1.7873936345228736,-3.407535892497446
730.4000000000096,78.26128649186447,1.793811954380454,-3.4075121118301306
731.6000000000097,78.3809721054199,1.8006844643434325,-3.407509948000251
732.8000000000097,78.50461871811156,1.8077724220801261,-3.4075099515670986
734.0000000000098,78.62639663209158,1.8140993132989123,-3.4078444298435393
735.2000000000097,78.74861212029752,1.8245982586600484,-3.4091513611974373
736.4000000000098,78.87021189056385,1.8300985154294425,-3.409145094571515
737.6000000000098,78.99211312939872,1.8357892955970412,-3.4078567447662587
738.8000000000097,79.11325336717965,1.8456875287437553,-3.4091424140737794
740.0000000000098,79.23516831842443,1.8538970566969952,-3.4099649898062
741.2000000000098,79.35794356817333,1.8618524667639078,-3.4085082026536617
742.4000000000099,79.47749454431796,1.8706349063715895,-3.4088226358730367
743.6000000000099,79.59948111327391,1.8762478500778217,-3.408818402835459
744.8000000000098,79.72120055638776,1.8877789886021934,-3.408819756229226
746.0000000000099,79.84331191326672,1.8959339351726223,-3.4087308381728043
747.2000000000099,79.96466367036246,1.9018901369728147,-3.408490381791759
748.4000000000099,80.0859699742035,1.9104213979230744,-3.4098100712263903
749.6000000000099,80.20725982039902,1.9221700511121131,-3.409811443615432
750.80000000001,80.3290171463945,1.9269476758147241,-3.411719166881408
752.00000000001,80.45120684396895,1.9332038148872082,-3.410800020154087
753.20000000001,80.57258146601625,1.9425343762924572,-3.409480873171683
754.40000000001,80.6934018650406,1.949342974428252,-3.410800540667443
755.60000000001,80.81561934373828,1.9592528675969172,-3.409708640882208
756.8000000000101,80.93673174401799,1.9669092939933492,-3.4098100159691276
758.00000000001,81.05769860009656,1.9711629613953179,-3.410960487769304
759.20000000001,81.17978570551355,1.9867354346649517,-3.4114498742760513
760.4000000000101,81.30111258879656,1.9937825854339455,-3.411450009037448
761.6000000000101,81.42292607289308,2.0029786807286425,-3.4111198377420378
762.8000000000102,81.54434044006962,2.0106199673766967,-3.4124391493195243
764.0000000000101,81.66595889069266,2.0188126223458016,-3.4124401159999103
765.2000000000102,81.78755748846552,2.0267485996197907,-3.4124401160004014
766.4000000000102,81.90862890195096,2.0372717251162347,-3.412442700709789
767.6000000000101,82.02922800685427,2.0429595175464685,-3.412118735266502
768.8000000000102,82.15082227066863,2.054774271723147,-3.4134297459502507
770.0000000000102,82.27183999286952,2.0634501505528315,-3.413753222954054
771.2000000000103,82.39391540366107,2.073718321796587,-3.413403925257466
772.4000000000103,82.51576976141473,2.0821933723594666,-3.4135732955300533
773.6000000000103,82.63801430358379,2.090341907203462,-3.4124399334900954
774.8000000000103,82.75961185191807,2.100311276891712,-3.4134299690056125
776.0000000000103,82.88114117957137,2.1087418303778898,-3.414749165851628
777.2000000000103,83.00459339881078,2.1188189852139194,-3.4147498260493476
778.4000000000103,83.12580660951782,2.1291304513147025,-3.4133311768451993
779.6000000000104,83.2486445694108,2.1392015757524923,-3.41599604235867
780.8000000000104,83.3698293919861,2.149145975768775,-3.4147500977307095
782.0000000000105,83.4913283755699,2.15785283662177,-3.41473807411563
783.2000000000104,83.6124154325984,2.1679329333448116,-3.415069902618423
784.4000000000104,83.73386314874257,2.1747773626345155,-3.415088833721073
785.6000000000105,83.85528207272134,2.1867433617800525,-3.4163901842016946
786.8000000000104,83.97763219700211,2.1928105426806606,-3.4149891485815367
788.0000000000105,84.09855662037464,2.20353118138944,-3.4160601575738125
789.2000000000105,84.2210755239483,2.2082362664427158,-3.4173802132008038
790.4000000000106,84.34210346320268,2.2228053614727687,-3.4160843908939538
791.6000000000106,84.46446733112911,2.2339108775597145,-3.415349597798872
792.8000000000105,84.58602677542561,2.244292336063847,-3.416669220477032
794.0000000000106,84.70947840588968,2.2536399763187003,-3.417380051958059
795.2000000000106,84.83090546309555,2.2595594111728023,-3.4173800515086876
796.0000000000106,84.91198541578446,2.264616484955771,-3.4188690255273007