File: 01_Data/EPDM_Membrane/STA/N2/10K_min/EPDM_Membrane_STA_N2_10KData_220928_R2.csv
##Temp./Â°C,Time/min,DSC/(mW/mg),Mass loss/mg
51.0,10.78363012849364,-1.599553439514636,0.029752771023604296
52.100000000000016,11.146865609506523,-1.4850874551399373,0.030815144875397493
53.20000000000003,11.392779062742191,-1.4116488849322293,0.029406320463806424
54.30000000000005,11.602136229648417,-1.3545344954453187,0.030706905465934575
55.40000000000006,11.784891239798993,-1.3121426382866646,0.027825763975315887
56.50000000000008,11.959424122489253,-1.2733819118813166,0.02817585113978005
57.600000000000094,12.118723962886568,-1.2444154238009355,0.02938527800836077
58.70000000000011,12.272126926788522,-1.2209041332617954,0.029096318358194928
59.800000000000125,12.426124022082984,-1.1971802998169272,0.028765783453987837
60.90000000000014,12.572111027686757,-1.1767910517914337,0.029279555833749527
62.000000000000156,12.712482244244,-1.16203392067579,0.029290610708232023
63.10000000000017,12.85314428182233,-1.1453582403733515,0.02921173415125189
64.20000000000019,12.98849634355547,-1.130307914103009,0.0294112779254716
65.30000000000021,13.123326862602358,-1.1156064208113219,0.029331428250023883
66.40000000000022,13.25722064693029,-1.1029105964639003,0.030208720786264465
67.50000000000023,13.38652734347642,-1.0891819361114967,0.029547334319040885
68.60000000000025,13.516262415615312,-1.078184122067851,0.029839222323444936
69.70000000000027,13.64492337520767,-1.0655923018068836,0.030764865650071194
70.80000000000028,13.772817647415305,-1.0529635971050149,0.03074277717838214
71.90000000000029,13.897102598191536,-1.045419149391607,0.03355786394221916
73.00000000000031,14.020904347998504,-1.0335590376358423,0.030740531781512814
74.10000000000034,14.146608422372099,-1.0236802599715231,0.03296718163263268
75.20000000000034,14.267894596564524,-1.0141779316242905,0.03205473186947572
76.30000000000035,14.387814375317943,-1.0042926207297886,0.030658119856419752
77.40000000000038,14.511360906176401,-0.99390214426164,0.030789383738190956
78.5000000000004,14.630000000000045,-0.9838899999999956,0.029418049774427857
79.6000000000004,14.750000000000044,-0.9756099999999923,0.028155736497786243
80.70000000000041,14.868915276394716,-0.9670001488611829,0.02943958174938377
81.80000000000044,14.985073552274093,-0.9573925094486996,0.0311963668703088
82.90000000000046,15.10278161303403,-0.9490273645959979,0.03063278201984332
84.00000000000047,15.218482230275237,-0.9402931884971013,0.032075370368544576
85.10000000000048,15.33416407472656,-0.9323882566258749,0.032152346400717846
86.2000000000005,15.448796348481306,-0.9249906199395662,0.03161211391375218
87.30000000000052,15.563579190169552,-0.9153814490548695,0.03348643599468826
88.40000000000053,15.676451536179991,-0.9070949891783197,0.03350029965116974
89.50000000000054,15.790187724483692,-0.8986649945781371,0.0321700010352588
90.60000000000056,15.902941946133573,-0.8894649551160757,0.032169600360624884
91.70000000000059,16.013762783361088,-0.8837402524990843,0.030901128357603724
92.8000000000006,16.127809990819337,-0.8755909057757958,0.031625109561868925
93.9000000000006,16.23766999782478,-0.8686101290902195,0.03217498190104262
95.00000000000063,16.346388184682787,-0.8612133437859163,0.029522851573624997
96.10000000000065,16.459917720226493,-0.8545923430592586,0.0321642235150561
97.20000000000066,16.57062652049079,-0.8475500545261948,0.03208078219875521
98.30000000000067,16.679505125258785,-0.8412064962084936,0.029785769593163813
99.40000000000069,16.786575977382288,-0.8343719090507986,0.030886709220806274
100.50000000000071,16.89796444838287,-0.8265174117289269,0.03215551483563939
101.60000000000072,17.007152997045335,-0.8203214772735249,0.031533695858453115
102.70000000000073,17.11587479672079,-0.8137849409339509,0.033208543986174455
103.80000000000075,17.22555351850199,-0.8079825704202429,0.032769160750438786
104.90000000000077,17.333056500496404,-0.8036031108250878,0.03081678098832441
106.00000000000078,17.440000000000087,-0.7982499999999981,0.030880124645004337
107.10000000000079,17.5487739179498,-0.791292647672295,0.03086824926228271
108.20000000000081,17.65672739541384,-0.7844670766168341,0.030899160374797674
109.30000000000084,17.765000730514235,-0.7795987819179464,0.02949353106534147
110.40000000000084,17.87305316481692,-0.7740326959441775,0.029542859832889512
111.50000000000085,17.97950065387087,-0.7690484589961493,0.032167857613456086
112.60000000000088,18.0875440581526,-0.7630900494706024,0.03184580609342191
113.7000000000009,18.19263269070738,-0.7595379781882077,0.030329442824167607
114.8000000000009,18.30324784414623,-0.7538117620829335,0.030738782360944406
115.90000000000092,18.410491426529887,-0.75024914001054,0.03045842635852658
117.00000000000094,18.51840689102995,-0.7475960194462933,0.030750028302325205
118.10000000000096,18.624356831142478,-0.745970137278691,0.03208431875515316
119.20000000000097,18.731135685003746,-0.7425409400508859,0.03195210326965814
120.30000000000098,18.838271540333096,-0.7389339875390832,0.030629999999350233
121.400000000001,18.945268122551962,-0.7346632245514629,0.03063187977015236
122.50000000000102,19.05160509534193,-0.7297136981226527,0.03194922757774865
123.60000000000103,19.15907602140146,-0.7260271774673399,0.03158735129278423
124.70000000000104,19.26628316472142,-0.7213765665236227,0.030287506676339504
125.80000000000106,19.373140703978155,-0.7175154905422118,0.029317398707727094
126.90000000000109,19.479168783103226,-0.7129905587568377,0.03190799024031765
128.00000000000108,19.585872055019877,-0.708215179339823,0.030207426308722418
129.1000000000011,19.68853654646389,-0.7047471462697211,0.029310674553639338
130.20000000000113,19.7974798258809,-0.7021624025790175,0.030629976405829318
131.30000000000115,19.903767511441124,-0.6970939904094572,0.030637939174066986
132.40000000000117,20.008867796002384,-0.6939707379646092,0.0293199989155406
133.50000000000117,20.115599494660845,-0.6898996369846957,0.030639888343758415
134.6000000000012,20.22180434700975,-0.6873993480331135,0.02933553427136104
135.7000000000012,20.327141549911776,-0.68321783372064,0.029309991128923407
136.8000000000012,20.432914110880006,-0.679226274477597,0.028001967369047698
137.90000000000123,20.538821795639326,-0.6756147340202431,0.029328519648164075
139.00000000000125,20.645085034142863,-0.6713102492066627,0.028643106783666106
140.10000000000127,20.749017562457894,-0.6681666808694502,0.027339359139023856
141.2000000000013,20.85284806661517,-0.6631919115920354,0.027353358446777776
142.3000000000013,20.9601958443655,-0.657510264388937,0.02834754994401667
143.4000000000013,21.065407187341744,-0.6552954699596198,0.02866000000316582
144.50000000000134,21.170739591810538,-0.6509377965173527,0.028659370445196508
145.60000000000133,21.275554189591183,-0.6480622264431621,0.028620765095557665
146.70000000000135,21.378610880757936,-0.6448376461371027,0.027538393827766683
147.80000000000138,21.482622432254555,-0.6398526492266727,0.028659928107360066
148.9000000000014,21.58914513558153,-0.6356464923124825,0.028648439234530088
150.00000000000142,21.693572973233668,-0.6321718796257259,0.02866393136559786
151.10000000000142,21.79796028809823,-0.6289602032561326,0.02464755146246489
152.20000000000144,21.903267981313352,-0.624632909309799,0.023360354830186836
153.30000000000146,22.00738857635039,-0.6215560368120229,0.023389934893406128
154.40000000000146,22.113480014907463,-0.618457227912495,0.02369857370227102
155.50000000000148,22.216739548975124,-0.6149404886536834,0.02452521263810503
156.6000000000015,22.320876586797485,-0.6117499522140821,0.02520695510420712
157.70000000000152,22.42737961085485,-0.6090007599811463,0.02514999728288636
158.80000000000155,22.532059448371466,-0.6043622229733238,0.024145212599425925
159.90000000000154,22.636381868448954,-0.6028628052546426,0.024148849803598438
161.00000000000156,22.737793922359494,-0.5986489830821872,0.02412083158732692
162.1000000000016,22.844747694668904,-0.594262456705828,0.025470011977667184
163.20000000000158,22.94888868178697,-0.5918528966517254,0.026158834789325347
164.3000000000016,23.05419844795918,-0.5894301292702183,0.024149696008240795
165.40000000000163,23.155539107977653,-0.5863106150478575,0.024232043561290162
166.50000000000165,23.262169961958765,-0.5836268420731456,0.02348994111651237
167.60000000000167,23.366504238900685,-0.5806070604033639,0.022134150188937163
168.70000000000167,23.470881406867946,-0.5778709805291684,0.022069999532107865
169.8000000000017,23.575510942788167,-0.5756489110231298,0.022068070777625515
170.9000000000017,23.67951308707253,-0.5728321945437489,0.01942248679731229
172.0000000000017,23.784102403013446,-0.56989955762786,0.018110447762637705
173.10000000000173,23.889570384719573,-0.567213508441432,0.018122333905298937
174.20000000000175,23.993074030794013,-0.5649503854263475,0.020742556134883294
175.30000000000177,24.09853329566214,-0.5621677019854708,0.019431756487401586
176.4000000000018,24.20230523928563,-0.5609512721643132,0.018113112433954193
177.5000000000018,24.307484651394347,-0.560781348370456,0.016777982623085386
178.6000000000018,24.411759942308475,-0.5583049205487225,0.016805523096167008
179.70000000000184,24.5155682905246,-0.5567914880975219,0.015480204132033215
180.80000000000183,24.619436786375235,-0.555191932216226,0.014162704003704896
181.90000000000185,24.722984262310238,-0.5554912756767891,0.01449004949262278
183.00000000000188,24.828634902700404,-0.5534147582822394,0.015474833963779133
184.1000000000019,24.93245819189922,-0.5511616794081524,0.01393276526910281
185.20000000000192,25.037159793774393,-0.5497693350044665,0.0113100405621811
186.30000000000192,25.14016917755721,-0.5474829517266666,0.009998873022085242
187.40000000000194,25.245008217537446,-0.5458658893153029,0.010979995777583795
188.50000000000196,25.34940855979873,-0.5447205593880631,0.010981910631534753
189.60000000000196,25.45130539329296,-0.5436521096532089,0.00966002920123632
190.70000000000198,25.557248900443284,-0.5415793032737671,0.009662680494749054
191.800000000002,25.661630328520793,-0.5383209425817538,0.0070297880348322295
192.90000000000202,25.7659302868546,-0.5372324635443064,0.007359462654094706
194.00000000000205,25.86937208308427,-0.535534154492034,0.008679982467559633
195.10000000000204,25.974109604472524,-0.5341063267195831,0.007404436461622588
196.20000000000206,26.07903303879506,-0.5315865276543872,0.004718378054882066
197.3000000000021,26.18310215774959,-0.5306723884337996,0.00301215196069915
198.40000000000208,26.28738631919595,-0.5291436467683573,0.00055028929014167
199.5000000000021,26.391234253578556,-0.5258808400418561,-0.0007700323411889975
200.60000000000213,26.49576761052636,-0.5245767652446556,-0.0007699828036682455
201.70000000000215,26.600876109638598,-0.5220495723397445,-0.001990072675029708
202.80000000000217,26.704086530378234,-0.5181382791719599,-0.003399986458519244
203.90000000000217,26.808341222737,-0.5147382447595156,-0.00375261105892033
205.0000000000022,26.91402655098894,-0.5103834166085981,-0.0034000043912740807
206.1000000000022,27.017167667344935,-0.507095241917629,-0.005847244301662169
207.2000000000022,27.120487946320065,-0.5056665428617603,-0.006039999965429477
208.30000000000223,27.22605038380618,-0.5012054562703926,-0.006039882957394216
209.40000000000225,27.32980512787081,-0.49852224408798707,-0.008680029779408294
210.50000000000227,27.432158672488203,-0.49526269012093177,-0.007538147010203389
211.6000000000023,27.536491426639436,-0.49047317224264325,-0.009989903852995141
212.7000000000023,27.641711602505957,-0.4869981871165343,-0.012290007970319206
213.8000000000023,27.74620142701114,-0.48372696186398323,-0.013569892896057478
214.90000000000234,27.85109032588276,-0.4806603530664165,-0.014961338997121487
216.00000000000233,27.954074604249424,-0.4784441033404094,-0.017890532401717785
217.10000000000235,28.058534740837523,-0.4735467065420263,-0.01922436208565692
218.20000000000238,28.163166519300027,-0.47165340983127324,-0.020498971388974496
219.3000000000024,28.26675713849465,-0.4679627929083923,-0.023158972946967005
220.40000000000242,28.371464181670355,-0.4667891197558128,-0.023160496017979426
221.50000000000242,28.475762462938928,-0.46382583608387024,-0.024499945343151808
222.60000000000244,28.579908366043384,-0.45929652961595746,-0.027119444676441784
223.70000000000246,28.683664566870373,-0.4572423918577332,-0.028428255601341323
224.80000000000246,28.78860393701074,-0.45583476292497743,-0.029751119686137528
225.90000000000248,28.893354877128004,-0.45240852495416506,-0.032395890251730286
227.0000000000025,28.997242622951568,-0.44912305183188467,-0.03413832463298272
228.10000000000252,29.101104365660824,-0.4481765549910767,-0.03633175604625327
229.20000000000255,29.207077424206357,-0.44540014863200067,-0.03885975005780473
230.30000000000254,29.310250300863324,-0.4431924185154902,-0.03897110394384917
231.40000000000256,29.41450580821391,-0.4404704697087828,-0.04028900747768871
232.5000000000026,29.519025611218233,-0.4401401658472921,-0.04217891497804427
233.60000000000258,29.623363393950108,-0.4367047399722441,-0.044234732451751135
234.7000000000026,29.726716462665657,-0.4354377866366095,-0.04557580844257547
235.80000000000263,29.83225643553151,-0.4320827005973629,-0.04755592954918164
236.90000000000265,29.93716324939941,-0.431971716428256,-0.05033546545663503
238.00000000000267,30.04155634362829,-0.4290030508134474,-0.052258867978775214
239.10000000000267,30.145598584821208,-0.42697230279240334,-0.054851209123699896
240.2000000000027,30.25009202994923,-0.4242483529526387,-0.05753000747241588
241.3000000000027,30.35237289260705,-0.4236841385046856,-0.058969492321911954
242.4000000000027,30.458070013503413,-0.4205240091272703,-0.06166274917583303
243.50000000000273,30.56220164859016,-0.42018739713664727,-0.064070449043784
244.60000000000275,30.666707153236935,-0.41827551665852797,-0.06660962298895745
245.70000000000277,30.773422303422524,-0.4180295873027677,-0.06808044664103363
246.8000000000028,30.877093088244642,-0.41632935387344433,-0.07069470647336118
247.9000000000028,30.978881321256345,-0.41509692599451664,-0.07327929103243491
249.0000000000028,31.086047661544644,-0.41433159189307917,-0.07597230691798673
250.10000000000284,31.190951652704662,-0.41311811793675024,-0.07833848542042432
251.20000000000283,31.29542017733899,-0.41306063433555623,-0.08000011650573668
252.30000000000285,31.39962479464202,-0.41282828727228715,-0.0851801314368803
253.40000000000288,31.505767155411384,-0.4114891636247468,-0.0864362804271388
254.5000000000029,31.609094741387928,-0.40967292640690317,-0.0905609409542869
255.60000000000292,31.714942197303685,-0.4100598315681203,-0.09198274837999199
256.7000000000029,31.81887993399195,-0.40810875506041955,-0.09639146650022301
257.8000000000029,31.92201920085181,-0.4082897194518448,-0.09769952856758213
258.90000000000293,32.02709102577455,-0.40775350116555437,-0.09915112861970199
260.00000000000296,32.13168619528504,-0.4063698335042041,-0.10319819809708841
261.100000000003,32.23451802518285,-0.4066753506194402,-0.10440962225455719
262.200000000003,32.34087510990552,-0.4057718261975548,-0.10717294316418391
263.300000000003,32.44540285241221,-0.40561507582136935,-0.1095924569589104
264.40000000000305,32.5489822781857,-0.40397257643653806,-0.1138799853153194
265.50000000000307,32.6531227227579,-0.40422347079717313,-0.11692123328203374
266.6000000000031,32.759162043275325,-0.40249740979098236,-0.11955050094100184
267.7000000000031,32.86393123538674,-0.4026656679657984,-0.12252656782189097
268.8000000000031,32.96670892515656,-0.40087594760843726,-0.12518790517919154
269.9000000000031,33.07323113008125,-0.4008838506566527,-0.12835955983021696
271.0000000000031,33.17752502568751,-0.40023829044321163,-0.13215953129338764
272.10000000000315,33.2821648864386,-0.39973235483530595,-0.1375065336709227
273.2000000000032,33.387016011233854,-0.40043914675374603,-0.1408457671050023
274.30000000000314,33.491783343029596,-0.3994620334845103,-0.14268192401231072
275.40000000000316,33.59736398999958,-0.39786748679006667,-0.1474349624195117
276.5000000000032,33.70192652800091,-0.3996689637949143,-0.15099582837071424
277.6000000000032,33.80719216848449,-0.39814897974628205,-0.1550088407978003
278.70000000000323,33.91203957366972,-0.3987031676793322,-0.15794784864758427
279.80000000000325,34.016629407256715,-0.3983228313861347,-0.16227685890850152
280.9000000000033,34.12229709888764,-0.3974122380183066,-0.16488740428647786
282.0000000000033,34.22709997717381,-0.39709992259961935,-0.16619411070136092
283.1000000000033,34.33262733711692,-0.39690276041008793,-0.1704009232803445
284.20000000000334,34.43864533613814,-0.3979086927755943,-0.17314981948292552
285.30000000000337,34.54295698529561,-0.39740939666570396,-0.17669154197566517
286.40000000000333,34.647432265469284,-0.397977668847924,-0.18111312207826913
287.50000000000335,34.75193330259643,-0.39726833351354546,-0.1836692274630778
288.6000000000034,34.85643003895222,-0.3987498874760749,-0.18628863690919717
289.7000000000034,34.96353174857356,-0.3986055086692761,-0.19238114690031427
290.8000000000034,35.06804021365104,-0.39747616679174574,-0.19701217987784503
291.9000000000034,35.17252809203878,-0.3996705789464037,-0.19981145079330842
293.0000000000034,35.27735060886174,-0.3996055137898388,-0.20526891817615311
294.10000000000343,35.38341927493086,-0.39839955077606914,-0.2100783458177098
295.20000000000346,35.487838580895286,-0.399038063165379,-0.21418088415880687
296.3000000000035,35.59358638563232,-0.39952261454932536,-0.21755027207980238
297.4000000000035,35.69813898697689,-0.39893172903117724,-0.2228769843577636
298.5000000000035,35.80213976748476,-0.3991964213564843,-0.22469289196035502
299.60000000000355,35.9068907169542,-0.40116633535840446,-0.2267646177140068
300.70000000000357,36.01336812255775,-0.4004785403692413,-0.2322873093670519
301.8000000000036,36.11960440122015,-0.40202980348769124,-0.2353525585847791
302.9000000000036,36.22386726358165,-0.40383565847604824,-0.2405322707910189
304.0000000000036,36.327980364016895,-0.40530064039772723,-0.24632628472692586
305.1000000000036,36.43563223813652,-0.4060703619744959,-0.2511987439956034
306.2000000000036,36.54093394118888,-0.4077011544176146,-0.25468022654301503
307.30000000000365,36.64470724162311,-0.4076378267704027,-0.2571816161113816
308.4000000000037,36.75100838793516,-0.4091110737077854,-0.26172420843840394
309.5000000000037,36.85599469040962,-0.4095383492821909,-0.26605587391872865
310.60000000000366,36.961347213881226,-0.4111115643565977,-0.270213769106745
311.7000000000037,37.066939283647294,-0.41244375736786704,-0.2766260606016404
312.8000000000037,37.171609025223006,-0.4141895199843866,-0.2809503096563435
313.90000000000373,37.27839825727407,-0.4159407999426257,-0.28531881743342025
315.00000000000375,37.383401676610525,-0.41697549668262524,-0.28934890695534676
316.1000000000038,37.48890112417558,-0.42028652231208447,-0.2946635393173431
317.2000000000038,37.592356716332084,-0.42168334611537966,-0.2994570914743018
318.3000000000038,37.699713725494995,-0.4235271028034234,-0.30519575620718786
319.40000000000384,37.80581487026246,-0.4257955246960259,-0.3098799661081424
320.5000000000038,37.91153058250492,-0.42809350242069033,-0.3131557948383743
321.60000000000383,38.01701057210751,-0.4312555239939629,-0.3183452847723518
322.70000000000385,38.122386371320744,-0.43268222095426884,-0.32436833146846666
323.8000000000039,38.22717937061602,-0.43552695183654944,-0.330313476271038
324.9000000000039,38.33306404344477,-0.4362650927037374,-0.33612928625524274
326.0000000000039,38.43913059374948,-0.4388599054943635,-0.3432490207588019
327.10000000000394,38.54435703381417,-0.44158434839035865,-0.348839265478333
328.2000000000039,38.649632106341016,-0.44365187006523954,-0.3534880138620693
329.30000000000393,38.756190073517125,-0.4477216955673126,-0.3604182582592905
330.40000000000396,38.859799706323635,-0.4486510680654413,-0.3664544099682647
331.500000000004,38.96736546686247,-0.45238802483396623,-0.3738948749954907
332.600000000004,39.073171651107835,-0.4554084317935683,-0.3803495639432217
333.700000000004,39.17903235039177,-0.45836530108539925,-0.3854470552266056
334.80000000000405,39.28436136544231,-0.4606215664846149,-0.3931351944947479
335.90000000000407,39.390000934637314,-0.4630400428951775,-0.40092053955077356
337.0000000000041,39.49585679149437,-0.4668595531269704,-0.40841328761053397
338.10000000000406,39.60167277893039,-0.47058179301098063,-0.4153099468833803
339.2000000000041,39.708016714647506,-0.4727182658656496,-0.4223308614642671
340.3000000000041,39.81399601152588,-0.4749594579963637,-0.4299514430246072
341.4000000000041,39.91920247229865,-0.47851676045352415,-0.4377595253336706
342.50000000000415,40.025989185533454,-0.4820119625488464,-0.4477315388302685
343.6000000000042,40.13136220782448,-0.4841530345310925,-0.456082728285065
344.7000000000042,40.23788947963056,-0.4856168772824244,-0.466327202588527
345.80000000000416,40.343660124059255,-0.48835735247307327,-0.4757429363575376
346.9000000000042,40.449712446984314,-0.4894809920112665,-0.48604044968472104
348.0000000000042,40.55516048823206,-0.49272918870501925,-0.49661099774618433
349.10000000000423,40.66160698754515,-0.494262203693635,-0.5073214643649266
350.20000000000425,40.765552872454165,-0.49769613018459846,-0.517815018686484
351.3000000000043,40.873317284328564,-0.49763659183828685,-0.5300490730018099
352.4000000000043,40.979144706649386,-0.5005690517052477,-0.5431660532633176
353.5000000000043,41.08494094849734,-0.5032897780248909,-0.5562565304106291
354.60000000000434,41.191697557078726,-0.5032720876950997,-0.5701670664117353
355.7000000000043,41.29731559473616,-0.5035752607761278,-0.5850800015985609
356.80000000000433,41.40341992903537,-0.5032109613199949,-0.6001024723690618
357.90000000000435,41.50963172240398,-0.5033281427835751,-0.6147247531892459
359.0000000000044,41.61606700427016,-0.5016614403970501,-0.6313936783976786
360.1000000000044,41.72250533005304,-0.5001800981212178,-0.6479578039457294
361.2000000000044,41.829104389744764,-0.4987096566167916,-0.6646539330080077
362.30000000000445,41.9346931595251,-0.49820387602902116,-0.6833996921120753
363.4000000000044,42.04060753844224,-0.49487905392847203,-0.7038361816740677
364.50000000000443,42.14649134775233,-0.4944952488176501,-0.7235826340948157
365.60000000000446,42.25259414073718,-0.4908389853881773,-0.7412882706710211
366.7000000000045,42.360492536961786,-0.4882669926930332,-0.7614127699256352
367.8000000000045,42.46414715994648,-0.4863556998153702,-0.7820696838885945
368.9000000000045,42.57292873381841,-0.48327568153318995,-0.8075377333765577
370.00000000000455,42.679287468656405,-0.4777341623965684,-0.8306664655106912
371.10000000000457,42.78667139828765,-0.4734890575467477,-0.853878877421427
372.2000000000046,42.89309064361338,-0.4691109967397658,-0.8785825750882448
373.30000000000456,42.999721664468545,-0.4644556897163489,-0.9021208274348891
374.4000000000046,43.10610862520656,-0.45954235774569546,-0.9264474015954143
375.5000000000046,43.21211533200969,-0.4550724577497001,-0.9505999059052486
376.6000000000046,43.3199990451428,-0.4500799885254991,-0.9774997176530285
377.70000000000465,43.42611189310237,-0.4452724367470607,-1.0016700788138801
378.8000000000047,43.53200288941147,-0.4409532136392749,-1.025340072325359
379.9000000000047,43.63948881123623,-0.4358623743786397,-1.0539143403601372
381.00000000000466,43.7461740768059,-0.43086583096612757,-1.0782984634673562
382.1000000000047,43.85281047509386,-0.42627627766253506,-1.1020659336967515
383.2000000000047,43.95980138787422,-0.4206577085720808,-1.128298148623978
384.30000000000473,44.065881843777696,-0.41855516477221144,-1.1523435726302464
385.40000000000475,44.17291499850248,-0.4131730588563796,-1.1762484675545224
386.5000000000048,44.27774018250039,-0.4085877241463674,-1.2029856749278482
387.6000000000048,44.38597179963005,-0.4047082622491745,-1.226306445358785
388.7000000000048,44.492279994775856,-0.4032019663026291,-1.2523576118005284
389.80000000000484,44.59802102980396,-0.4000009878107565,-1.2747390713641145
390.9000000000048,44.70586653438526,-0.3968456063304859,-1.2965776382475522
392.00000000000483,44.810503473936976,-0.3938633247856023,-1.3193361523962088
393.10000000000485,44.91858857612747,-0.3911366880722131,-1.3398645871754225
394.2000000000049,45.025783938831985,-0.38807593520843076,-1.361697765055029
395.3000000000049,45.133355182554645,-0.3863276993842707,-1.382951270441068
396.4000000000049,45.23939858267253,-0.38423098396328,-1.403800492904196
397.50000000000495,45.346712045891856,-0.3841559941281805,-1.4258543172970986
398.6000000000049,45.4529075913841,-0.3834240540426192,-1.4462087909819314
399.70000000000493,45.561040348172924,-0.3815719056795084,-1.464513722365171
400.80000000000496,45.667652955165075,-0.38132544233538673,-1.4819281021390944
401.900000000005,45.7753606891748,-0.3793529452390628,-1.5007100848083912
403.000000000005,45.88329511469173,-0.37774816571315,-1.5179925490908017
404.100000000005,45.98884426093434,-0.3775278590963459,-1.534993176347843
405.20000000000505,46.09693812254676,-0.375744412036751,-1.5515395057331034
406.30000000000507,46.204514645898705,-0.3752518211157918,-1.5695299219957537
407.4000000000051,46.311480052213476,-0.37416718910918084,-1.5877817193434098
408.50000000000506,46.417818877381464,-0.37246318558897945,-1.6038855566153924
409.6000000000051,46.52605943414452,-0.372008541206487,-1.6188442480089078
410.7000000000051,46.63433422957873,-0.3692764964588312,-1.6361284511526657
411.8000000000051,46.74020257755652,-0.3688135932205935,-1.6522481292544429
412.90000000000515,46.84770733147612,-0.36900972783926134,-1.6668695253710348
414.0000000000052,46.95556140581254,-0.36814491986419917,-1.683456581022582
415.1000000000052,47.06198926253201,-0.3675559670427649,-1.6989317878240993
416.20000000000516,47.1692672792992,-0.36610138240716844,-1.7140275084767116
417.3000000000052,47.27695507663876,-0.3647910718876649,-1.7286141888121334
418.4000000000052,47.38321507913858,-0.36412130867330417,-1.7440673817801877
419.50000000000523,47.49088260743059,-0.36312438582109885,-1.7557781938116563
420.60000000000525,47.598189703774956,-0.3645034593242058,-1.7698557644909951
421.7000000000053,47.70531874844981,-0.36221893852704456,-1.783341614232028
422.8000000000053,47.8129619182514,-0.3633738092462001,-1.7978526905060748
423.9000000000053,47.91979013799624,-0.3645627505387131,-1.8119398479212618
425.00000000000534,48.027715147374174,-0.36584752823247885,-1.8251916292342227
426.1000000000053,48.134389344665095,-0.3656119378356403,-1.8370767954326541
427.20000000000533,48.24176341328227,-0.3679120464074426,-1.8523432076972512
428.30000000000535,48.34912960391023,-0.36991199990477835,-1.8676847667683374
429.4000000000054,48.45615553246216,-0.3718933114776365,-1.8804022498915969
430.5000000000054,48.564226362251226,-0.37201432126039796,-1.8934938616421206
431.6000000000054,48.67192263513274,-0.37624803879966867,-1.9050066824775622
432.70000000000545,48.77834063448505,-0.37858701740045186,-1.918792677064987
433.8000000000054,48.885974332702254,-0.3811223448576027,-1.9310926692368193
434.90000000000543,48.99332960018296,-0.38427692292436333,-1.9437931884643551
436.00000000000546,49.10120622386446,-0.3882780039769392,-1.957318828819862
437.1000000000055,49.20818012751862,-0.393281469427122,-1.9682710582309988
438.2000000000055,49.31551014937168,-0.3964806403161864,-1.9777941235791472
439.3000000000055,49.42301322606421,-0.39904298279077843,-1.987631087893924
440.40000000000555,49.53120152252352,-0.40251500045222666,-1.9997870960104578
441.50000000000557,49.63603901392793,-0.405314233464235,-2.009829050947025
442.6000000000056,49.74571523998656,-0.41000414260103324,-2.0231357296059693
443.70000000000556,49.85381703107922,-0.41259091584472357,-2.0305722185051485
444.8000000000056,49.96133521189109,-0.4178622690584059,-2.0386653546748392
445.9000000000056,50.06981117984704,-0.42172005241534666,-2.050936929106375
447.0000000000056,50.17803162553963,-0.4260737521694391,-2.0597244412500624
448.10000000000565,50.28456282560551,-0.429620472331598,-2.0670477943453167
449.2000000000057,50.39180587100232,-0.43349805305689193,-2.0765152831220894
450.3000000000057,50.499799923333256,-0.43743755984180477,-2.084318800039918
451.40000000000566,50.60758725194013,-0.44083733927373553,-2.092869327162227
452.5000000000057,50.71487311973115,-0.44480269033763453,-2.102713291441211
453.6000000000057,50.82162921383305,-0.4480945090496012,-2.1096745536175803
454.70000000000573,50.93209289179926,-0.4516915219042344,-2.1162614327818776
455.80000000000575,51.03953854212432,-0.4553408172769521,-2.1227270249330727
456.9000000000058,51.14824104288978,-0.4593069817136594,-2.1305652233967267
458.0000000000058,51.253635884663645,-0.4616130876018303,-2.1344809052754004
459.1000000000058,51.36229327275007,-0.4656343665253668,-2.1405503672626898
460.20000000000584,51.47058452328703,-0.4688723000622045,-2.1458975432008565
461.3000000000058,51.57970452279319,-0.4706539062212298,-2.150531858172264
462.40000000000583,51.68475506328094,-0.474770189811576,-2.1537001363779535
463.50000000000585,51.79504734332556,-0.47741739123544435,-2.156767834112865
464.6000000000059,51.90112592195784,-0.4808217393500028,-2.1621806835930126
465.7000000000059,52.0097964226679,-0.48205341616785774,-2.167199110680155
466.8000000000059,52.11879153798639,-0.48622279233467086,-2.1724803543595046
467.90000000000595,52.226143697488325,-0.48749586798393213,-2.176537559735155
469.0000000000059,52.333175763689674,-0.4902246768317458,-2.181862168787516
470.10000000000593,52.441231216400936,-0.49225898087930114,-2.187088453532467
471.20000000000596,52.54928322487421,-0.4954501925116,-2.1893366206080014
472.300000000006,52.65735333175069,-0.49676425447234485,-2.1914268503554113
473.400000000006,52.764982484698116,-0.4989968796606059,-2.1937899108682624
474.500000000006,52.872574047162544,-0.5010387367779214,-2.1963685012566607
475.60000000000605,52.978981439396485,-0.5014664247203217,-2.199071042442987
476.70000000000607,53.088820352046255,-0.503423022350236,-2.201609221992679
477.8000000000061,53.196280902795536,-0.5049342999056544,-2.20403017572868
478.90000000000606,53.303690443621704,-0.5093128189876114,-2.2071287505044523
480.0000000000061,53.4139122969919,-0.5092766961627979,-2.2096203105204064
481.1000000000061,53.52105208010656,-0.5123490988302027,-2.2109204935257787
482.2000000000061,53.62902381830674,-0.5131730614491049,-2.2135592238134225
483.30000000000615,53.736511030956024,-0.5154394878145013,-2.214869953765684
484.4000000000062,53.84414602383284,-0.5170301705570046,-2.216187474269184
485.5000000000062,53.95368933405661,-0.5164588919733044,-2.217510329978467
486.60000000000616,54.06050085323912,-0.5163308770243867,-2.220048287882573
487.7000000000062,54.16928663602456,-0.5179405315368076,-2.220139997651861
488.8000000000062,54.277320145609465,-0.5198378530725405,-2.220140003013321
489.90000000000623,54.383228761875124,-0.5206772698859208,-2.2214364985653097
491.00000000000625,54.4924131245307,-0.521289924130198,-2.2227692625784385
492.1000000000063,54.601401473830734,-0.521076568645491,-2.222734004946753
493.2000000000063,54.7088972273471,-0.5246545529023081,-2.224094662636244
494.3000000000063,54.817524324867854,-0.5255370344765755,-2.22410000081637
495.40000000000634,54.92560823691874,-0.5250599177995591,-2.225296861694252
496.5000000000063,55.03422561676371,-0.527229127784512,-2.2279234745426275
497.60000000000633,55.141783736552746,-0.5271348647607976,-2.230748636243458
498.70000000000636,55.24961499326174,-0.5257109221429954,-2.2280589440016643
499.8000000000064,55.356516096163666,-0.5276502021691185,-2.229359932114563
500.9000000000064,55.46683715792436,-0.5292006192026479,-2.230018253045476
502.0000000000064,55.57371334598478,-0.5276536229057729,-2.2316732305036906
503.10000000000645,55.684472932458064,-0.5272748600596706,-2.2324404069210884
504.2000000000064,55.792185850854125,-0.5166151315946124,-2.2316659274341144
505.30000000000643,55.900770284909406,-0.5098548627314919,-2.232989992926272
506.40000000000646,56.00902227105039,-0.5077301640333806,-2.232993376627194
507.5000000000065,56.11707766050942,-0.5065541305235722,-2.2343322454949623
508.6000000000065,56.22483750892201,-0.5035106838018526,-2.234619931930952
509.7000000000065,56.33142980865715,-0.5046087227479877,-2.231988905516131
510.80000000000655,56.4420374021998,-0.5060650297859112,-2.2334992618104317
511.90000000000657,56.550964438407306,-0.5066199473871547,-2.2333099940533883
513.0000000000066,56.65851701900793,-0.5075774393921809,-2.234637233826147
514.1000000000065,56.76855485784609,-0.5095534955473554,-2.235949994411651
515.2000000000066,56.876712376550124,-0.5143371780233889,-2.238589606938324
516.3000000000065,56.98489624482095,-0.5179180048442344,-2.2385988763086884
517.4000000000067,57.09177448027783,-0.5227136072568092,-2.2375999881418296
518.5000000000066,57.20279545734353,-0.5266488265513426,-2.23759524252395
519.6000000000067,57.310861928835145,-0.5301059367619403,-2.2376006924022604
520.7000000000066,57.420588477022555,-0.5321942839752862,-2.23725390756965
521.8000000000067,57.52902144750108,-0.5342460665550901,-2.238580080386625
522.9000000000067,57.63744530740176,-0.5379913204228857,-2.239251677193229
524.0000000000067,57.74706677797018,-0.5407999710755494,-2.241211392343113
525.1000000000067,57.85498780788355,-0.543779234370916,-2.2425404500547703
526.2000000000068,57.963469738433496,-0.5453399557736592,-2.243858225986581
527.3000000000068,58.07252476386166,-0.5490215729035692,-2.2413151492332912
528.4000000000068,58.180633389293035,-0.5504418985358456,-2.2398999758527913
529.5000000000068,58.29065355862953,-0.5532387948415335,-2.2398999996964104
530.6000000000068,58.3991849299796,-0.5549814202824099,-2.2388510043847942
531.7000000000069,58.507133218399716,-0.5588632897257031,-2.2385899781797898
532.8000000000068,58.617435457431235,-0.5594960438244528,-2.2397093021883094
533.9000000000069,58.72699178963814,-0.5618861375837515,-2.2388292302022488
535.0000000000068,58.835356204713776,-0.5644122595556792,-2.240246049840309
536.100000000007,58.94432855265989,-0.5644630569401529,-2.2422051166319146
537.2000000000069,59.052631989150434,-0.5656940437631377,-2.2421999806014545
538.300000000007,59.16185535130609,-0.5671876720639892,-2.2428180159761264
539.4000000000069,59.27031018413029,-0.5701440554669804,-2.241665019022009
540.5000000000069,59.38052952334286,-0.5726233842291231,-2.2436717147946146
541.600000000007,59.48889622601637,-0.5741616652474305,-2.2428711092788163
542.700000000007,59.5971945193275,-0.5734131094925118,-2.242870083639552
543.800000000007,59.70681585822807,-0.5761641532383273,-2.2454540487915993
544.900000000007,59.81600579627263,-0.5769215509112581,-2.2442175528309503
546.000000000007,59.924810883817415,-0.5771698216143403,-2.2448365561608457
547.1000000000071,60.033566934221774,-0.5783533333876857,-2.246989327771489
548.2000000000071,60.14408038691558,-0.5786862497529089,-2.2484940831186924
549.300000000007,60.25129918717846,-0.5775796033884333,-2.2510980789768134
550.4000000000071,60.36091146969768,-0.5787182582544731,-2.2471514560491817
551.500000000007,60.47000000000069,-0.5788200000000673,-2.2471505915222227
552.6000000000072,60.57911864980646,-0.5811408541439794,-2.2464896290347385
553.7000000000071,60.688410666085744,-0.5804701969931293,-2.2484775963381503
554.8000000000072,60.79813904659815,-0.5810586994522062,-2.2476999618806937
555.9000000000071,60.907780956717225,-0.5806684566029846,-2.2480202414587493
557.0000000000072,61.01636577221903,-0.5834254652149995,-2.2493398331935603
558.1000000000072,61.12584492318144,-0.5808000311508608,-2.251979808288029
559.2000000000072,61.235234985077,-0.5819462025627116,-2.2509900191779195
560.3000000000072,61.342069166569964,-0.5835920970201844,-2.2523095500302013
561.4000000000073,61.453085522958276,-0.5842856974908374,-2.2509684573043067
562.5000000000073,61.561827942230714,-0.5850283142254997,-2.248380935656936
563.6000000000073,61.67159557059821,-0.5839887184385234,-2.2483636438569494
564.7000000000073,61.78063197476702,-0.5862666437711368,-2.2496799940097603
565.8000000000073,61.889569097474514,-0.586229884154761,-2.2510956780385247
566.9000000000074,61.9984406647546,-0.5869059810375433,-2.2536250115273773
568.0000000000074,62.10752257683983,-0.5871911684616032,-2.2575689392707496
569.1000000000074,62.216159817809064,-0.5877266690448639,-2.2575779585282416
570.2000000000073,62.32672138711556,-0.5901090731884312,-2.2562648190841457
571.3000000000073,62.435227703435736,-0.5904704136764269,-2.2541711599704644
572.4000000000074,62.544048482457505,-0.5920725369143593,-2.2518620347195775
573.5000000000074,62.65349068245895,-0.59192000339326,-2.2550486373660212
574.6000000000074,62.76310478121613,-0.592649162157548,-2.2576028040241325
575.7000000000074,62.872321930373346,-0.594900004642573,-2.2597096132840364
576.8000000000075,62.98201262248969,-0.5948019930921801,-2.259070936635044
577.9000000000075,63.09144573830602,-0.5946024724287285,-2.2576900029458526
579.0000000000075,63.2008388630008,-0.5960016570818739,-2.2590092597477325
580.1000000000075,63.31000200563441,-0.5969500740114229,-2.2603049614127375
581.2000000000075,63.418672919137634,-0.5955172765157806,-2.2590101371370133
582.3000000000076,63.527112172151924,-0.5966228405206467,-2.2590019838169324
583.4000000000076,63.63599382668032,-0.5952289142398147,-2.259010006426182
584.5000000000076,63.74509711642556,-0.5940954472952694,-2.2596653519899865
585.6000000000076,63.85494828379435,-0.5919065166987666,-2.2629379773042695
586.7000000000077,63.96439543106162,-0.5923165901672571,-2.2642697107231444
587.8000000000077,64.0731669915895,-0.5902966007516994,-2.2646074683713837
588.9000000000076,64.18200019458519,-0.5874580785849706,-2.2642846427985983
590.0000000000076,64.29066187748086,-0.5855351043057524,-2.2628699814679383
591.1000000000076,64.40050191820312,-0.5833446527162547,-2.2615302293829354
592.2000000000077,64.5099034146086,-0.5782995721477584,-2.2634804060162073
593.3000000000077,64.61940418900465,-0.5752340201044206,-2.26349999924077
594.4000000000077,64.72943929610781,-0.5710463169916447,-2.2647314249315027
595.5000000000077,64.83811001214195,-0.5668233715439355,-2.2643520243033404
596.6000000000078,64.94819032963787,-0.5607300116878965,-2.266799547368855
597.7000000000078,65.05722815465703,-0.5562135393245181,-2.2681202949128285
598.8000000000078,65.16622648140692,-0.5498310379005327,-2.268120000004192
599.9000000000078,65.27687143649383,-0.5470856258156588,-2.2681112441454077
601.0000000000078,65.38744518132835,-0.5427644204570677,-2.2696212543538303
602.1000000000079,65.49402893782214,-0.537882688125559,-2.270879492611977
603.2000000000079,65.60587348364835,-0.5353397928071219,-2.271061640956018
604.3000000000079,65.71310567446456,-0.530765046966191,-2.272070087762753
605.4000000000078,65.82481040963077,-0.526979067252175,-2.27349376472786
606.5000000000078,65.93489800908792,-0.5208365821008741,-2.2724630050800783
607.6000000000079,66.04358172695107,-0.5189324131095665,-2.2750306550150707
608.7000000000079,66.15420443739492,-0.514472289640979,-2.275978394025875
609.8000000000079,66.26362775998479,-0.5098691316348515,-2.276581204389659
610.9000000000079,66.37285884639165,-0.5072105835162999,-2.2776698283208376
612.000000000008,66.48308124973228,-0.502980003644971,-2.2789900357894344
613.100000000008,66.59167362258988,-0.4991074102132772,-2.2794778546580097
614.200000000008,66.70145067753195,-0.496031380297269,-2.2813251307731424
615.300000000008,66.81159225453652,-0.49111314351207497,-2.282930289560379
616.400000000008,66.92069427636251,-0.4907650903338199,-2.2833231868652555
617.5000000000081,67.03000000000083,-0.48644000000000454,-2.285569539816029
618.6000000000081,67.1401028007071,-0.4841093484301132,-2.2855793317332522
619.7000000000081,67.25031076854523,-0.48027570458101737,-2.2869852724954383
620.8000000000081,67.35838836975667,-0.47643551802950307,-2.288303291129829
621.9000000000082,67.46890797923425,-0.47342802928004574,-2.289219626384941
623.0000000000082,67.57878191696014,-0.4719789338507657,-2.2899699547492425
624.1000000000081,67.68875496863166,-0.46836793589332826,-2.291295101538683
625.2000000000081,67.79831355712707,-0.4644777293805627,-2.293794486813163
626.3000000000081,67.90856712072575,-0.4614775233274807,-2.2952394248937766
627.4000000000082,68.01745881554625,-0.4571256917561518,-2.296275023242016
628.5000000000082,68.12454985336488,-0.45370432723038534,-2.2962194281686807
629.6000000000082,68.23761267404797,-0.4506253539621717,-2.297459807794867
630.7000000000082,68.3463119511162,-0.4457667044003283,-2.3001426142022243
631.8000000000083,68.45622991905798,-0.4368954686620151,-2.2988833783262312
632.9000000000083,68.56614635641334,-0.43134970692466046,-2.301093931157885
634.0000000000083,68.67567736851568,-0.425283318944716,-2.3029985236056483
635.1000000000083,68.78634509997278,-0.4165785722691183,-2.3049387346285837
636.2000000000083,68.89548569608466,-0.41311313384742415,-2.3056151267830214
637.3000000000084,69.00489133290472,-0.4044197659727082,-2.308243208625537
638.4000000000084,69.11423964202102,-0.39600721871154276,-2.310127944007025
639.5000000000084,69.22348507079165,-0.38645752856526805,-2.3139207447839905
640.6000000000083,69.3334958444199,-0.3798690023099507,-2.3152477308830908
641.7000000000083,69.44296715297483,-0.36738072028836427,-2.319451330314854
642.8000000000084,69.55277856303735,-0.35958264285883806,-2.322791955650266
643.9000000000084,69.66136167118047,-0.3524335454466642,-2.3238055471028467
645.0000000000084,69.77147401345762,-0.34207682501932607,-2.3260598985095893
646.1000000000084,69.87968667148176,-0.3269093141946302,-2.3276196221680743
647.2000000000085,69.99022157786449,-0.31958268738918777,-2.329928670480091
648.3000000000085,70.09930490476471,-0.3102791526769158,-2.331250340800514
649.4000000000085,70.20876024239209,-0.30267595907050704,-2.334047808544587
650.5000000000085,70.31806392529226,-0.29746430476386415,-2.3341729185617157
651.6000000000085,70.42729105891587,-0.291943122493469,-2.339476383963836
652.7000000000086,70.53704572950191,-0.2882067701604663,-2.341441207256139
653.8000000000086,70.64609397094164,-0.2843081534858624,-2.344003587067582
654.9000000000086,70.7566746264093,-0.2840775945919115,-2.3466146608445317
656.0000000000086,70.86601284904049,-0.2871311940836699,-2.349425866097305
657.1000000000087,70.97479856947979,-0.29342766494051076,-2.3524049710627164
658.2000000000087,71.08507158509325,-0.2996895873574206,-2.3563611999930636
659.3000000000086,71.19571904621716,-0.30841666511422167,-2.3605776288920026
660.4000000000086,71.30528251980654,-0.3182893592395578,-2.361861694677554
661.5000000000086,71.4129981397719,-0.3268253255784237,-2.364499058461631
662.6000000000087,71.52599095084697,-0.33124387113446013,-2.364935720806711
663.7000000000087,71.63409492170383,-0.32639688398256916,-2.369009817570858
664.8000000000087,71.74475235499445,-0.3141647297976208,-2.3740100599507543
665.9000000000087,71.85649246304285,-0.2980316286902415,-2.3769540685999684
667.0000000000088,71.96607139083835,-0.27997327149902085,-2.378348485511563
668.1000000000088,72.07613725597012,-0.26386810973712965,-2.3817759519713206
669.2000000000088,72.18560924543115,-0.25390921947042966,-2.383761771943773
670.3000000000088,72.29582883229226,-0.24527865435561522,-2.387407099169943
671.4000000000088,72.40594571197678,-0.24339161481211954,-2.38987872892102
672.5000000000089,72.51612894716125,-0.24891262403803596,-2.3942455949466352
673.6000000000089,72.62621583534225,-0.26221518733988153,-2.3988326142291534
674.7000000000089,72.73621932219058,-0.28305446885694957,-2.401398055253696
675.8000000000088,72.84588902819073,-0.30808153933794086,-2.404248184878865
676.9000000000088,72.956128359043,-0.34246484455169157,-2.4070016271096146
678.0000000000089,73.06392201206154,-0.3833883137277219,-2.4093257145291247
679.1000000000089,73.17552090169869,-0.42749266871606245,-2.41093991811082
680.2000000000089,73.28585395357142,-0.4680633859521675,-2.4135920385481855
681.3000000000089,73.39574134698826,-0.5077102964597515,-2.4149786998637093
682.400000000009,73.50471208488405,-0.5436054027811754,-2.4161914056395313
683.500000000009,73.61547485366727,-0.5722181243934702,-2.415879422383843
684.600000000009,73.72437885317007,-0.597083952558533,-2.4184947933498337
685.700000000009,73.83329616470353,-0.6189529116815711,-2.4198402188344033
686.800000000009,73.94506243762652,-0.6339200330585558,-2.421161574323415
687.9000000000091,74.05323953273484,-0.6471438045798626,-2.4214937782981174
689.0000000000091,74.16505357956959,-0.6585571552134704,-2.421176159679689
690.1000000000091,74.2742693545517,-0.6625584623096998,-2.4211538166377258
691.2000000000091,74.38495300141368,-0.6673642376431522,-2.4224700429325075
692.3000000000092,74.4948948970742,-0.6715382221661581,-2.4237905089121714
693.4000000000092,74.60503303343337,-0.6744545760712948,-2.425675484787141
694.5000000000091,74.71582370867118,-0.6760147943214744,-2.4263978612953663
695.6000000000091,74.82523364251847,-0.6805763665183167,-2.4251815044614045
696.7000000000091,74.9350602628617,-0.6838984258269124,-2.4227438513399635
697.8000000000092,75.04637924698122,-0.6863066842937935,-2.42377999743448
698.9000000000092,75.15536815836975,-0.687445884981708,-2.4250674228361953
700.0000000000092,75.26459155437695,-0.6901747364488326,-2.4264310526664197
701.1000000000092,75.37577410359951,-0.6915095041386428,-2.425074631663282
702.2000000000093,75.48705261573141,-0.6965819183638877,-2.427701661266065
703.3000000000093,75.59731386611463,-0.6966167888347419,-2.426800293222022
704.4000000000093,75.70706225775774,-0.6999414633191068,-2.4264249037203203
705.5000000000093,75.81773313926145,-0.7030552768268573,-2.4263429874895945
706.6000000000093,75.92812524799614,-0.7038005508067073,-2.4264200000349057
707.7000000000094,76.0381339705863,-0.7042574025969783,-2.4263991403468097
708.8000000000094,76.14941448363116,-0.7079928768974078,-2.4270799786888304
709.9000000000094,76.25929515258338,-0.7091371736122619,-2.428382742588101
711.0000000000093,76.36951113092977,-0.7101057182010251,-2.426456502063994
712.1000000000093,76.47830294208232,-0.7137841196370094,-2.429079813290902
713.2000000000094,76.5879505954893,-0.7141856004761337,-2.42897498186572
714.3000000000094,76.6995971492789,-0.7165858042721751,-2.430415034123679
715.4000000000094,76.81052658362628,-0.7207054995844351,-2.4290513296501066
716.5000000000094,76.92080524668653,-0.7205729306560177,-2.4277399966741555
717.6000000000095,77.03161232659083,-0.7185794297829495,-2.4290401990868316
718.7000000000095,77.14150595228352,-0.720765718978153,-2.430369969143567
719.8000000000095,77.25304716751135,-0.7236748546053611,-2.431561852971146
720.9000000000095,77.36196097815117,-0.7257940005162057,-2.43303054796682
722.0000000000095,77.47252079669006,-0.7227953311958482,-2.4330099934511233
723.1000000000096,77.58383521354939,-0.7266566040285924,-2.43201107862017
724.2000000000096,77.69481311329868,-0.7270991880408361,-2.433009999993785
725.3000000000096,77.80584007452312,-0.7256612763891681,-2.4330100000397503
726.4000000000096,77.91628651426659,-0.7290489561504219,-2.4323205315568956
727.5000000000097,78.02525813243321,-0.7299030621510868,-2.431649444282673
728.6000000000097,78.13704413026088,-0.7315017460376987,-2.4344222830331157
729.7000000000096,78.24630985112744,-0.7333939726673827,-2.435379473397129
730.8000000000096,78.3566006315385,-0.7340412690782852,-2.436081531320627
731.9000000000096,78.4667469507872,-0.7357243924729923,-2.4337857948312625
733.0000000000097,78.57688942844968,-0.7387663085896734,-2.4325898437276736
734.1000000000097,78.68758831628334,-0.7378008861025617,-2.4350275121989045
735.2000000000097,78.79704650388221,-0.7395630576680787,-2.4364100150048724
736.3000000000097,78.90754961519157,-0.7391268912631509,-2.4372138436893946
737.4000000000098,79.0173570669717,-0.7410506916459412,-2.438840501292484
738.5000000000098,79.12748458831683,-0.7420720843922552,-2.436426519377126
739.6000000000098,79.23820275817259,-0.7423566969530035,-2.433780940265264
740.7000000000098,79.34799813577149,-0.7460858342494097,-2.434439147008729
741.8000000000098,79.4581298872448,-0.7449741795006609,-2.4360797407345807
742.9000000000099,79.56890877705928,-0.7483579742438697,-2.4360882149871093
744.0000000000099,79.67894917358456,-0.7493867680962424,-2.437395865337078
745.1000000000099,79.78877343810716,-0.7487045688800757,-2.440358184748257
746.2000000000098,79.89980561694703,-0.7495357355886322,-2.4403664675205103
747.0000000000099,79.98039783086409,-0.7520692302920906,-2.4407326748595746