File: 01_Data/EPDM_Membrane/STA/N2/10K_min/EPDM_Membrane_STA_N2_10KData_220928_R3.csv
##Temp./Â°C,Time/min,DSC/(mW/mg),Mass loss/mg
51.0,10.870162231520586,-1.532326596494903,0.02408125998584776
52.100000000000016,11.191897620053505,-1.4277189282573015,0.023556030769903202
53.20000000000003,11.431666150729349,-1.3526555031551517,0.02344222009334107
54.30000000000005,11.634201136552667,-1.2994666938958401,0.024325274508345096
55.40000000000006,11.815724104777189,-1.254344895056635,0.02230941478681281
56.50000000000008,11.986716254327012,-1.2184917869594851,0.02202854592399106
57.600000000000094,12.146063980639882,-1.1906623895553603,0.023445597166441345
58.70000000000011,12.299615112077687,-1.1650368985775736,0.021358955326324924
59.800000000000125,12.44598917364439,-1.1444992609093003,0.021321146173931105
60.90000000000014,12.593524946786166,-1.1261344420650032,0.0231209803614032
62.000000000000156,12.731282844969105,-1.1066730067795703,0.022333797919303677
63.10000000000017,12.874423980517514,-1.0931463878523624,0.022560242636616934
64.20000000000019,13.011948229720575,-1.0767669105778086,0.02382370717673954
65.30000000000021,13.145176170236825,-1.0632397016121902,0.024986263669440234
66.40000000000022,13.278226955465357,-1.04923107882397,0.024083835759071803
67.50000000000023,13.407406919396873,-1.037478430526846,0.023050410608818517
68.60000000000025,13.536206553976035,-1.025203073448027,0.022626744216000638
69.70000000000027,13.663653854301897,-1.0135483478310878,0.022664274096515058
70.80000000000028,13.790692703736633,-1.0018142805038992,0.02388081756863425
71.90000000000029,13.916076375945627,-0.9922983746779237,0.023781366960222705
73.00000000000031,14.040324227973013,-0.9808206517241722,0.022373909723070184
74.10000000000034,14.16297793067048,-0.9713586307962528,0.023635183055435327
75.20000000000034,14.285311473755513,-0.9621033438801175,0.021693262969023408
76.30000000000035,14.406755705334717,-0.9512164340215705,0.023818483945186486
77.40000000000038,14.526750468022243,-0.9432399955265753,0.022210547066829456
78.5000000000004,14.646464409976831,-0.9333179336246347,0.023584110287242055
79.6000000000004,14.765388253380925,-0.9236316618493308,0.023611603189712227
80.70000000000041,14.884640468773416,-0.9131217906345073,0.023687398838188933
81.80000000000044,15.001009027471843,-0.9051263719784897,0.02475409211972579
82.90000000000046,15.117699980382724,-0.8977806785879112,0.023589594884834142
84.00000000000047,15.23340671324792,-0.8884757414025632,0.02373390736754377
85.10000000000048,15.34917000000005,-0.8810599999999988,0.022293595373391817
86.2000000000005,15.46200096940626,-0.8715225028219608,0.022698484705513167
87.30000000000052,15.578602768578417,-0.8639753502271058,0.023227437578473342
88.40000000000053,15.693372395507232,-0.8559185563550319,0.022262069530444073
89.50000000000054,15.805602914850212,-0.8475602919479761,0.0223164031609695
90.60000000000056,15.917909605884908,-0.840734364539172,0.02361200153306431
91.70000000000059,16.029260263993343,-0.8337258692179904,0.02361260672865395
92.8000000000006,16.141306476170897,-0.8243449923610343,0.023717576230591675
93.9000000000006,16.25327041685436,-0.818357824479704,0.023618500839710954
95.00000000000063,16.36217508327945,-0.8104218700688243,0.02461421142521214
96.10000000000065,16.474840730578098,-0.8043050233465312,0.0242896044350287
97.20000000000066,16.584013136615017,-0.7959214102995975,0.022247089666883824
98.30000000000067,16.693822084003806,-0.7893808986032512,0.02266255757788027
99.40000000000069,16.80061997100008,-0.7836300960155591,0.022355737858246627
100.50000000000071,16.911443508429844,-0.7758143584380459,0.023518550075213085
101.60000000000072,17.022528483002773,-0.7691626294090513,0.021040197503930713
102.70000000000073,17.12937131961138,-0.763179483807882,0.022296125282291968
103.80000000000075,17.23885397397601,-0.7569101244148138,0.020968859790973404
104.90000000000077,17.346794957660844,-0.750460858974379,0.02358856455224778
106.00000000000078,17.455199954106252,-0.7456396087744049,0.02243223785844073
107.10000000000079,17.55995732697496,-0.7387372843526178,0.023619912901766682
108.20000000000081,17.669822404115585,-0.7356875557813568,0.023608112874954124
109.30000000000084,17.777968664085492,-0.7298714406381073,0.02285091571776654
110.40000000000084,17.885668852586026,-0.7249904116073419,0.0222512226426943
111.50000000000085,17.993611361528313,-0.7193600575632194,0.022300002239567185
112.60000000000088,18.100832260510956,-0.7140123106031658,0.023687741607885116
113.7000000000009,18.206173588863447,-0.7091251580547555,0.024269023567774717
114.8000000000009,18.31584063089996,-0.7049694749142301,0.022244584744715468
115.90000000000092,18.421773769740145,-0.7015144580031023,0.02358368290069457
117.00000000000094,18.52885638652473,-0.7005485778546174,0.02229013701691951
118.10000000000096,18.635783269890005,-0.6963721348494822,0.022374945671677082
119.20000000000097,18.743877505623203,-0.6928928218306385,0.02361071483474575
120.30000000000098,18.851102071483172,-0.6898480013396424,0.022285200354171586
121.400000000001,18.95710129854531,-0.6859561112315526,0.02097036314821743
122.50000000000102,19.064801014996352,-0.6815219235346129,0.020979854673697673
123.60000000000103,19.170591156611625,-0.676053488267459,0.022301863401029465
124.70000000000104,19.277411624041413,-0.6743343769752868,0.020979910751512953
125.80000000000106,19.383823118781,-0.6693314320882564,0.022290040668481836
126.90000000000109,19.490079115701995,-0.6650372478298823,0.021359664759038388
128.00000000000108,19.595942842952397,-0.6625232116387165,0.02098201520628251
129.1000000000011,19.70198490943561,-0.6591952395876913,0.02092213903295992
130.20000000000113,19.80841472329988,-0.6528867072652363,0.02098005497676869
131.30000000000115,19.91455000621667,-0.650362072311842,0.020980061546193696
132.40000000000117,20.020705106320865,-0.6471176655447481,0.021086070240053267
133.50000000000117,20.12696702263626,-0.6434203026446622,0.021165236126830855
134.6000000000012,20.233285465333946,-0.6392451148778934,0.01959848859738944
135.7000000000012,20.339255988384075,-0.6333974321250402,0.020983632188822376
136.8000000000012,20.444082935482626,-0.6321867047506278,0.019660172273441745
137.90000000000123,20.54832515573141,-0.6290831318983698,0.020975551835046957
139.00000000000125,20.653328478532906,-0.6248971431169762,0.02098367207144758
140.10000000000127,20.759069676335738,-0.6208127619232716,0.02103663594846239
141.2000000000013,20.86516196087282,-0.6174006818871468,0.02162986890429508
142.3000000000013,20.96969401192075,-0.6149613725761595,0.02093203349661188
143.4000000000013,21.07500536504113,-0.6093569818632939,0.019659866386828817
144.50000000000134,21.178981968897112,-0.607285077960374,0.020649769527508965
145.60000000000133,21.282863791376034,-0.6035307720904413,0.019326582563572003
146.70000000000135,21.387008739344733,-0.6001664930046207,0.019983872219342835
147.80000000000138,21.49295811014716,-0.5965624060634055,0.019659984867105074
148.9000000000014,21.598462334448257,-0.5932312663223263,0.018775294763669237
150.00000000000142,21.702570882814864,-0.5891029296259336,0.01965964604721382
151.10000000000142,21.8069303375975,-0.5850270963006154,0.019687450127745088
152.20000000000144,21.913012100794187,-0.5820514513854677,0.017030186230876154
153.30000000000146,22.016126262362725,-0.5786000699628536,0.017098616327752225
154.40000000000146,22.120700254552165,-0.5752754283376781,0.016689332703408333
155.50000000000148,22.22519452743725,-0.5718599413672336,0.01836166560130259
156.6000000000015,22.329375705069577,-0.5696504687868014,0.019778320171011998
157.70000000000152,22.4334975800805,-0.5671081000732691,0.01562268290932245
158.80000000000155,22.538588351089395,-0.5642844227841681,0.014496802879736315
159.90000000000154,22.643887628333925,-0.5610003934042829,0.017814149265635848
161.00000000000156,22.747236868896277,-0.5582454907426017,0.016378429434450226
162.1000000000016,22.85201484964057,-0.5548589642609981,0.015159949142763196
163.20000000000158,22.95620430669545,-0.5533354325517297,0.015159895312503835
164.3000000000016,23.060321592744664,-0.5510561715414649,0.01383960750121016
165.40000000000163,23.165127627886974,-0.5486200973457321,0.013839964084814582
166.50000000000165,23.269581067587826,-0.545178239618755,0.014499950341456014
167.60000000000167,23.37465804642106,-0.5426669350950752,0.014999462789150542
168.70000000000167,23.478694541877807,-0.5402913777645821,0.013151972380991417
169.8000000000017,23.582773116953202,-0.5373185004410829,0.010548102361187972
170.9000000000017,23.687083313417048,-0.5358833374720116,0.011869837906173686
172.0000000000017,23.792080574492843,-0.5340349161454951,0.010549822911011475
173.10000000000173,23.896361393091407,-0.5313148152247579,0.010550202106361262
174.20000000000175,24.001098669180145,-0.5286443378420055,0.009473955800689104
175.30000000000177,24.10490643122105,-0.5265803577642092,0.007920201950439854
176.4000000000018,24.209355235410825,-0.5258928316654259,0.007923601906451694
177.5000000000018,24.313806934492042,-0.5228828683358497,0.006906328358889269
178.6000000000018,24.416668751556998,-0.5225585050414652,0.005610013485984666
179.70000000000184,24.522153661998292,-0.5229771510770682,0.005638940780620771
180.80000000000183,24.627910443642982,-0.521450905544611,0.006919981425538957
181.90000000000185,24.73228663843578,-0.5199329044989783,0.005610055497525579
183.00000000000188,24.83639180805075,-0.5195462340286486,0.005278298200357412
184.1000000000019,24.93994138102359,-0.5189147382176306,0.005279779952292785
185.20000000000192,25.043195664913192,-0.5169989879406249,0.002969686205887001
186.30000000000192,25.145567295008856,-0.5156247514939107,0.0029700129995617885
187.40000000000194,25.25279141520236,-0.5144079304594738,0.0029622579499974933
188.50000000000196,25.355241218674376,-0.5134538464549889,0.0016603454600234713
189.60000000000196,25.460561824664737,-0.511503184206284,0.00033997551416664606
190.70000000000198,25.56440088452401,-0.5111040141874283,1.1696868160271379e-05
191.800000000002,25.6691700000002,-0.509929999999999,-0.0013128140008547007
192.90000000000202,25.77306952141071,-0.5083945261455888,-0.002625470281604869
194.00000000000205,25.877387307393917,-0.5071423415247597,-0.0026296912145715723
195.10000000000204,25.982319324169925,-0.504246289446297,-0.003940311761856385
196.20000000000206,26.085394976840988,-0.5023186294595906,-0.004269620551312414
197.3000000000021,26.18973424789493,-0.5014416171506813,-0.005260171040259998
198.40000000000208,26.293426779113748,-0.49840696581252597,-0.005260144739154704
199.5000000000021,26.396560790714712,-0.49446582753668805,-0.005897557194520786
200.60000000000213,26.50198534631435,-0.4935633437773897,-0.007233228017522464
201.70000000000215,26.605878064762408,-0.4909355513715429,-0.008107278071414648
202.80000000000217,26.70793042742208,-0.48826673432214296,-0.010531662857945712
203.90000000000217,26.81357975164674,-0.4851321860727824,-0.012070407318354626
205.0000000000022,26.918422909570552,-0.48284063553868023,-0.013461858840717156
206.1000000000022,27.02146995968261,-0.47980664797733047,-0.014479856909649591
207.2000000000022,27.126119021314544,-0.4757706613108854,-0.01578192813536461
208.30000000000223,27.230439421940623,-0.4736370470020023,-0.015805530199294537
209.40000000000225,27.33418704636791,-0.47135561551755656,-0.018540154094645267
210.50000000000227,27.437549251708923,-0.4679359154959727,-0.01985996518893174
211.6000000000023,27.543162171895258,-0.4658699398146354,-0.019861271976210126
212.7000000000023,27.646993877347626,-0.4622226888394996,-0.02250032373021238
213.8000000000023,27.751543356605357,-0.459994540736809,-0.023820076332628837
214.90000000000234,27.854632104491966,-0.4571312226273178,-0.025129919087024
216.00000000000233,27.959267367080855,-0.4534865984139295,-0.026504339059542303
217.10000000000235,28.0645432083146,-0.44994966180640783,-0.02806465615034348
218.20000000000238,28.168872041711623,-0.4475938370573471,-0.02974897854316083
219.3000000000024,28.272046142009096,-0.4441408143073795,-0.031060123432578024
220.40000000000242,28.377087631185418,-0.44176136717366143,-0.03254007455317609
221.50000000000242,28.481003527605314,-0.4395590174368717,-0.033646564525911415
222.60000000000244,28.585149204397045,-0.4367426506633578,-0.03633004264159467
223.70000000000246,28.6888789114433,-0.4342089251044285,-0.03729530356141808
224.80000000000246,28.794061215212515,-0.43196255903804465,-0.03997536283874226
225.90000000000248,28.898839136079683,-0.4297823371905892,-0.040280688948956644
227.0000000000025,29.002270887541723,-0.4257333669782811,-0.04293583133701695
228.10000000000252,29.106887181681195,-0.42496998091932037,-0.045735967266449684
229.20000000000255,29.211367941903298,-0.42365695251987945,-0.04669573449458664
230.30000000000254,29.315175445027766,-0.4214287661175417,-0.0494999931734581
231.40000000000256,29.419951077200206,-0.41892531924195775,-0.05213022060002448
232.5000000000026,29.524764826074655,-0.41577005825826296,-0.05248670918051701
233.60000000000258,29.628606669172793,-0.41418173171587086,-0.05641925479920129
234.7000000000026,29.733617664248726,-0.4124403182114729,-0.0587468708047858
235.80000000000263,29.83548907310941,-0.41147391010780965,-0.06037200349311167
236.90000000000265,29.941405202564244,-0.40869464430398655,-0.06250706555846186
238.00000000000267,30.046525150988867,-0.4077106492382234,-0.06447298097500287
239.10000000000267,30.151144899960087,-0.40679495778318825,-0.06746386696483953
240.2000000000027,30.25538766999222,-0.4054281936117947,-0.07087749539362243
241.3000000000027,30.360204527854574,-0.4043249338484227,-0.07359708064223014
242.4000000000027,30.464537159910744,-0.4032474555527749,-0.07444427218149574
243.50000000000273,30.56842252321182,-0.401621959770207,-0.07617562227454489
244.60000000000275,30.673616000526188,-0.40087065301908104,-0.07923128605412089
245.70000000000277,30.778080362886126,-0.39932049546577364,-0.08144718301117315
246.8000000000028,30.883217395472286,-0.3998924700457316,-0.08346819837156083
247.9000000000028,30.987699837829055,-0.39824477538295067,-0.0867144323745821
249.0000000000028,31.091796524205435,-0.3969739341619863,-0.08943212387643396
250.10000000000284,31.196741498830814,-0.3958490862419548,-0.09123241045603914
251.20000000000283,31.301158231040198,-0.39573329249263983,-0.09355805742714551
252.30000000000285,31.405666074925286,-0.39572047363302676,-0.09609739371928328
253.40000000000288,31.50979839133637,-0.3937394178549029,-0.099685794160568
254.5000000000029,31.6151821017792,-0.3940177798224726,-0.10230646722425485
255.60000000000292,31.719888152996017,-0.39380888101497163,-0.1062521450848859
256.7000000000029,31.82389451449135,-0.3924164810798398,-0.10757246919959496
257.8000000000029,31.925959493897864,-0.391667711716023,-0.11023963861126962
258.90000000000293,32.033992084830274,-0.39175222273634536,-0.1131674888063472
260.00000000000296,32.13676326128956,-0.39050004495124446,-0.11848094124630393
261.100000000003,32.241668631702794,-0.3906643129624796,-0.12267770777166076
262.200000000003,32.346161226868105,-0.38890901144913903,-0.12279532384084657
263.300000000003,32.45136456930647,-0.38884556286309924,-0.12545578716051642
264.40000000000305,32.55543684356537,-0.38986260584228144,-0.1294957575684248
265.50000000000307,32.66048269293284,-0.3889305708878769,-0.13217460449216523
266.6000000000031,32.76303879382797,-0.38942126870880606,-0.1347296478233222
267.7000000000031,32.868609314057295,-0.3882998505835727,-0.13905434016849316
268.8000000000031,32.9736681570808,-0.389517187778229,-0.14158336624739443
269.9000000000031,33.07935632127824,-0.38837010197053345,-0.14689339824970293
271.0000000000031,33.18388872606668,-0.3890908182565575,-0.14952791906154994
272.10000000000315,33.28818929796992,-0.38994228805858244,-0.1531679161925834
273.2000000000032,33.39425914406615,-0.390132875015741,-0.15622459656983656
274.30000000000314,33.498815093806236,-0.3893281415850023,-0.15885258355786647
275.40000000000316,33.60337015788389,-0.38972058292560274,-0.16247316714000526
276.5000000000032,33.70767659270163,-0.3894240862197341,-0.16398851985297114
277.6000000000032,33.810550705702276,-0.3892684227804034,-0.1679854515473571
278.70000000000323,33.91750932411713,-0.38950973574974945,-0.17275244924461486
279.80000000000325,34.0233758900726,-0.39007801892897764,-0.17686713451519243
280.9000000000033,34.127961819438276,-0.3908032490730432,-0.1799424760420183
282.0000000000033,34.23335670943429,-0.3896179107554204,-0.18395340093717616
283.1000000000033,34.33868365057583,-0.39104428657957035,-0.18572512747257441
284.20000000000334,34.44390676894903,-0.3900915694530488,-0.19131563682868968
285.30000000000337,34.54757855627673,-0.38948840382457894,-0.1955171537190159
286.40000000000333,34.653902843891615,-0.3889583817873225,-0.1995887690158944
287.50000000000335,34.759170000000296,-0.39031999999999734,-0.20353034883968224
288.6000000000034,34.863636295485286,-0.3898003818242985,-0.2070857690806922
289.7000000000034,34.96986354486301,-0.3904168241437181,-0.20967441798660413
290.8000000000034,35.0726219057826,-0.39030614478409287,-0.21364305185853327
291.9000000000034,35.17917083692756,-0.39018000075209364,-0.2167000838868849
293.0000000000034,35.283149576286206,-0.39158158934753023,-0.2209698862441276
294.10000000000343,35.39002658630494,-0.39254598115009964,-0.2263575102293225
295.20000000000346,35.4947822001405,-0.39244992280866714,-0.23040687642718005
296.3000000000035,35.599576536485166,-0.39388325992414386,-0.23430530448665987
297.4000000000035,35.70530298251179,-0.39404897550860546,-0.23755134510715648
298.5000000000035,35.81029929873484,-0.3954052221706207,-0.24144210163208069
299.60000000000355,35.91593240878938,-0.3955543780184703,-0.24693003618477416
300.70000000000357,36.021254148533785,-0.3964154587918366,-0.25163144762180867
301.8000000000036,36.127195703062895,-0.3967360270276209,-0.2554949022014381
302.9000000000036,36.23189449117621,-0.39751417090217983,-0.26009295142413924
304.0000000000036,36.33638623276324,-0.39953688235289037,-0.26464613169460716
305.1000000000036,36.44017968312402,-0.4010915051705172,-0.2688651830764939
306.2000000000036,36.547203992365795,-0.40131242334322326,-0.27458595349370407
307.30000000000365,36.65095429497066,-0.4035795301426829,-0.27911016778214126
308.4000000000037,36.7579313117359,-0.4054801362056303,-0.2825037054734052
309.5000000000037,36.86266562281483,-0.4081617508379276,-0.28695799536552435
310.60000000000366,36.96800502581707,-0.40978100175908627,-0.29089280808385354
311.7000000000037,37.07332061808967,-0.4113511625509928,-0.2944296034765883
312.8000000000037,37.178234208576264,-0.41138540137298363,-0.3007602978729085
313.90000000000373,37.284476727296,-0.4156419454954723,-0.3053776733788416
315.00000000000375,37.38973427785111,-0.4182762111614449,-0.30919052027471583
316.1000000000038,37.495478024843884,-0.41917313909162573,-0.3148240693705908
317.2000000000038,37.601465066959896,-0.42167730099621664,-0.31945895280169845
318.3000000000038,37.706732003373816,-0.4239556227792517,-0.3240062863903579
319.40000000000384,37.812129627752626,-0.4259738056326767,-0.33012573917771126
320.5000000000038,37.91836308593756,-0.4298316079571197,-0.33514804024754685
321.60000000000383,38.02361860218406,-0.432030979821143,-0.33978503012443007
322.70000000000385,38.12860194083627,-0.4354636122899282,-0.34600900476859753
323.8000000000039,38.23505249332253,-0.43709402391027125,-0.3505070807706696
324.9000000000039,38.339343318534006,-0.43832882720625393,-0.3582299899748538
326.0000000000039,38.44582353538287,-0.4419883900415254,-0.3637344366263737
327.10000000000394,38.55140740613644,-0.4444212142091876,-0.3680545565719595
328.2000000000039,38.65646583402539,-0.44688210381241633,-0.37321047175216027
329.30000000000393,38.76255061585325,-0.45145652101034905,-0.3793693365401083
330.40000000000396,38.868139962556654,-0.452494477994182,-0.38706596958828454
331.500000000004,38.974091355745415,-0.4562714266506201,-0.39289218483854604
332.600000000004,39.080043475279844,-0.4586091712457379,-0.398378966180569
333.700000000004,39.18523774459818,-0.46127469177285985,-0.4074416842348061
334.80000000000405,39.290731060239224,-0.4645341135552547,-0.4138598549623467
335.90000000000407,39.39623077982677,-0.4683963916004602,-0.42178630754417945
337.0000000000041,39.50183425034934,-0.47044786019548956,-0.4276054440510997
338.10000000000406,39.60621090985725,-0.4743941384655845,-0.43451436779008734
339.2000000000041,39.71332321364189,-0.47601341195908947,-0.4449918343968613
340.3000000000041,39.817747619123125,-0.480547147641381,-0.45214434305035267
341.4000000000041,39.92533245327488,-0.48534564186943085,-0.4616500755860051
342.50000000000415,40.03214348624275,-0.486642498662438,-0.47175827257615444
343.6000000000042,40.136671218275545,-0.49015508652711953,-0.4793944725755641
344.7000000000042,40.24340228546916,-0.49362821708409604,-0.490162886982914
345.80000000000416,40.34886898208312,-0.4967920250293411,-0.5003094289452217
346.9000000000042,40.454883765463194,-0.49847933947438916,-0.5091619644323475
348.0000000000042,40.561239517645824,-0.49990555825639976,-0.5200817480438484
349.10000000000423,40.66713184276659,-0.5033319079917198,-0.5306535473041105
350.20000000000425,40.77300447862635,-0.5053047945083231,-0.5424486692155819
351.3000000000043,40.87875905666672,-0.5078199770261401,-0.5556607751687261
352.4000000000043,40.983517164587305,-0.5094711416541376,-0.5679277715953717
353.5000000000043,41.09058764821461,-0.5113639469137221,-0.5816521606123604
354.60000000000434,41.195978743376095,-0.5113348422044877,-0.5967567580572615
355.7000000000043,41.30257573264693,-0.5125049852963247,-0.6128778727958974
356.80000000000433,41.40887474132408,-0.5152741137957009,-0.6257975790450532
357.90000000000435,41.514522174866684,-0.514206652495866,-0.6425201782020808
359.0000000000044,41.62132891314085,-0.513408260063802,-0.6586407690710705
360.1000000000044,41.72726188840744,-0.513340885974272,-0.6760076618784194
361.2000000000044,41.832265001356035,-0.5134537760038823,-0.6932896590690873
362.30000000000445,41.940005276557024,-0.5121641200786418,-0.7131670897194495
363.4000000000044,42.045778684661414,-0.5105910048853207,-0.7327326023569403
364.50000000000443,42.15198356706627,-0.5087198644914595,-0.7537139792513612
365.60000000000446,42.25935769251981,-0.5073014183759523,-0.7735458348215594
366.7000000000045,42.365910312156004,-0.5061270966015207,-0.7928100343726321
367.8000000000045,42.47269772380768,-0.502527640104266,-0.8165002287891086
368.9000000000045,42.57878422789253,-0.5008955614045864,-0.8388790912089572
370.00000000000455,42.68587608089762,-0.4957445308775158,-0.8633656729332411
371.10000000000457,42.79154543231244,-0.49281380728319224,-0.8869324367238609
372.2000000000046,42.898027445503274,-0.48798380805194747,-0.9128509762186545
373.30000000000456,43.00342335666036,-0.48271872787277764,-0.9370591142217606
374.4000000000046,43.11146582418316,-0.47932069984799125,-0.9637699857233324
375.5000000000046,43.21889621358465,-0.4747436690388347,-0.9882993276403438
376.6000000000046,43.32501103017337,-0.4705780516695405,-1.0135382750476412
377.70000000000465,43.43065648159654,-0.4680733028927197,-1.0411836600786009
378.8000000000047,43.538189903566625,-0.46481400102911014,-1.0672206560986641
379.9000000000047,43.64557423829267,-0.46129422564666545,-1.0942965476219855
381.00000000000466,43.75222629045487,-0.4552098294119126,-1.119863185874904
382.1000000000047,43.8587728018872,-0.4512210736481211,-1.145248459892502
383.2000000000047,43.965360580676716,-0.44706604655511817,-1.17247938236221
384.30000000000473,44.071302509038,-0.4427990883638038,-1.200075245158771
385.40000000000475,44.178306811093,-0.44084541453932957,-1.2247684742009834
386.5000000000048,44.28470406258546,-0.4377897451017925,-1.2494008431410069
387.6000000000048,44.39105932405465,-0.4345079112488389,-1.273870407937888
388.7000000000048,44.49784948777136,-0.43114150712507454,-1.2978814951886548
389.80000000000484,44.604506500536075,-0.42867954199468056,-1.3214381146513992
390.9000000000048,44.71250643802722,-0.4243794907382067,-1.3446114665795843
392.00000000000483,44.81762663825471,-0.42348285400166846,-1.3666133030105527
393.10000000000485,44.9230404342596,-0.4214705814578551,-1.3909546583110046
394.2000000000049,45.03119756431507,-0.4187783562318613,-1.4114486820880834
395.3000000000049,45.13935524578798,-0.41775441499844973,-1.43401710677119
396.4000000000049,45.24355325633171,-0.4152709721841712,-1.4539796318891294
397.50000000000495,45.35221572563201,-0.41310728022254023,-1.4737510748715574
398.6000000000049,45.45886719209227,-0.41255671987170484,-1.4936364361407724
399.70000000000493,45.56558271699248,-0.40898148499754144,-1.513597513018698
400.80000000000496,45.66993251363989,-0.4096489099666145,-1.5328904217190318
401.900000000005,45.778968161191365,-0.40873684171072694,-1.5532939341720846
403.000000000005,45.88612451023589,-0.4078717493148665,-1.5727933097506854
404.100000000005,45.9930604978971,-0.40613674085419593,-1.5907417571413727
405.20000000000505,46.09966344513164,-0.4059361725936007,-1.6070636083024832
406.30000000000507,46.20702483688328,-0.40377706913195854,-1.6231744997985538
407.4000000000051,46.31475611826335,-0.40342875933243955,-1.640005462811918
408.50000000000506,46.420461310516096,-0.4032987057846655,-1.6588430006283854
409.6000000000051,46.52625980581064,-0.4024099468878367,-1.6736792383740133
410.7000000000051,46.634145072048796,-0.40117149875296987,-1.690345390120355
411.8000000000051,46.742360815953866,-0.40132439657864355,-1.7065772123763212
412.90000000000515,46.84988479954961,-0.4021506257770295,-1.7223592145992708
414.0000000000052,46.955736515156104,-0.40053382804246696,-1.7370289761489879
415.1000000000052,47.0642652811675,-0.40042180352053947,-1.7535114245742305
416.20000000000516,47.1718035467994,-0.401129404120675,-1.7692374983979833
417.3000000000052,47.27717741241569,-0.39835855017654126,-1.7840256915286692
418.4000000000052,47.38514673135887,-0.3986747271408671,-1.7996930267655689
419.50000000000523,47.49230789616327,-0.3990599897944847,-1.8147908588562256
420.60000000000525,47.6004138355022,-0.40110636610717243,-1.8292224459994042
421.7000000000053,47.70794632994778,-0.40053193856895636,-1.844091645302261
422.8000000000053,47.815115313801726,-0.4015572282279582,-1.8563825187005265
423.9000000000053,47.92134725439474,-0.403195610864039,-1.8713841205996564
425.00000000000534,48.029561654035,-0.4038275876081579,-1.8854647465730356
426.1000000000053,48.13686309654917,-0.4053807666298291,-1.8967005776526502
427.20000000000533,48.24373061005072,-0.4079290638926491,-1.9102266674529225
428.30000000000535,48.35100116393639,-0.4097595359549661,-1.9231457971729116
429.4000000000054,48.45906731831854,-0.41213564246735224,-1.9377581775082051
430.5000000000054,48.56596253562543,-0.41471674898390554,-1.9511070385687965
431.6000000000054,48.67279639663221,-0.41825422152291986,-1.965474742218038
432.70000000000545,48.78085048658656,-0.41929250527133194,-1.9782015019888384
433.8000000000054,48.88877708282497,-0.42377746395529287,-1.9907527366920004
434.90000000000543,48.99457841746007,-0.4253323839591158,-2.003080720605234
436.00000000000546,49.102660501017105,-0.4297521963297908,-2.015204785853804
437.1000000000055,49.209531005854906,-0.43297163164874475,-2.0261903202083915
438.2000000000055,49.317078525471764,-0.4368205931664761,-2.03992916767666
439.3000000000055,49.42480791648982,-0.4422233936937294,-2.050987232050904
440.40000000000555,49.52993594713798,-0.4450587863591752,-2.061141506073954
441.50000000000557,49.6368860656356,-0.4484684867280977,-2.0714687339154287
442.6000000000056,49.746747983586644,-0.4535727399091405,-2.0815838339325663
443.70000000000556,49.85488144783248,-0.45888758320576306,-2.090813926064795
444.8000000000056,49.96155518292035,-0.4615817296896435,-2.1019654435321584
445.9000000000056,50.069715584209256,-0.46657788598978933,-2.109746861898235
447.0000000000056,50.1766140100277,-0.46987065225773206,-2.1208547182383617
448.10000000000565,50.28529021811556,-0.47392274749101476,-2.1316845010197665
449.2000000000057,50.3920703843712,-0.4765234863236707,-2.1390312365275514
450.3000000000057,50.499474764005825,-0.48128090348039343,-2.145079289899212
451.40000000000566,50.60696602517089,-0.4836315361951655,-2.154896010023818
452.5000000000057,50.7150176997647,-0.4878100749975451,-2.160918396380257
453.6000000000057,50.823163735676644,-0.49271824820013094,-2.1700334373247685
454.70000000000573,50.929694729169,-0.49589249348214953,-2.1766045557448863
455.80000000000575,51.03669520936292,-0.5007033605190719,-2.1844006358271146
456.9000000000058,51.145272083093076,-0.503707937224171,-2.190930573674123
458.0000000000058,51.25278913400861,-0.5070606033815307,-2.195774511836071
459.1000000000058,51.36124286248101,-0.5102321367641021,-2.20298765067199
460.20000000000584,51.46792341870919,-0.5144908662718245,-2.2080753512872935
461.3000000000058,51.574612210725405,-0.516324107536186,-2.213564306993298
462.40000000000583,51.68393551521906,-0.5205447684807375,-2.21944805221199
463.50000000000585,51.792134086495174,-0.5232784363406262,-2.2232926618651976
464.6000000000059,51.89927488461131,-0.5257008871083827,-2.227492345972962
465.7000000000059,52.00833876463783,-0.5275490880709202,-2.233754136455282
466.8000000000059,52.11615512039248,-0.5305768661278352,-2.2379839684788174
467.90000000000595,52.221830035444185,-0.5318425894709164,-2.2420759883724486
469.0000000000059,52.330186294712476,-0.5341148143428042,-2.2448703720691805
470.10000000000593,52.439567126774875,-0.5371333682423581,-2.249113024260651
471.20000000000596,52.547975295827904,-0.5392179621454899,-2.2513127589725253
472.300000000006,52.653673828000464,-0.5421451834259939,-2.2531797079145237
473.400000000006,52.764560489594324,-0.5472707074159426,-2.2573759183099167
474.500000000006,52.8720152315932,-0.5489341764252206,-2.260397470152429
475.60000000000605,52.97906064453304,-0.5510538784620527,-2.2632830160419255
476.70000000000607,53.087966348616035,-0.5540161005665086,-2.2655796398645096
477.8000000000061,53.19610403278109,-0.5557904809784142,-2.268264317296667
478.90000000000606,53.303593538277106,-0.5570850680292877,-2.2695861162017037
480.0000000000061,53.41194646592037,-0.5591241696276289,-2.270857006147213
481.1000000000061,53.51866912550106,-0.560638349869545,-2.272170536545164
482.2000000000061,53.62863069981784,-0.5634542721721741,-2.2747956553581083
483.30000000000615,53.735871007424706,-0.5661569602647113,-2.2761200936549213
484.4000000000062,53.845243947790266,-0.5692009835774483,-2.2785630345967953
485.5000000000062,53.95269060822531,-0.5693464068246985,-2.27876008523163
486.60000000000616,54.06032641046669,-0.5706286071944076,-2.2800635359678223
487.7000000000062,54.16887939361267,-0.5717369531195741,-2.282379740139608
488.8000000000062,54.27719760773156,-0.5739070437369289,-2.2834934152710233
489.90000000000623,54.38573697287261,-0.5754336200477793,-2.2853435624354583
491.00000000000625,54.49339349853525,-0.5762967190289672,-2.2866704125610715
492.1000000000063,54.60100700140454,-0.5771944046492076,-2.28797999973049
493.2000000000063,54.71000444441351,-0.5792597899035369,-2.2879782902870334
494.3000000000063,54.818427098904365,-0.5802572492041412,-2.2879790918957066
495.40000000000634,54.92655960810485,-0.5815165908649607,-2.2881245907542884
496.5000000000063,55.035695944762196,-0.5817265061782106,-2.28994987441381
497.60000000000633,55.14388726915871,-0.5819863959665237,-2.289949840642706
498.70000000000636,55.250908965658724,-0.5824374876875296,-2.2912704819741307
499.8000000000064,55.35984833803927,-0.5726872992895443,-2.292590917982471
500.9000000000064,55.467403886989814,-0.5642066955980856,-2.294218905535079
502.0000000000064,55.57528383017467,-0.5601631294740899,-2.294224980171801
503.10000000000645,55.68317600948458,-0.5593155785612205,-2.2942403809419796
504.2000000000064,55.789847884631556,-0.5574544969802154,-2.29423983919544
505.30000000000643,55.89944555063836,-0.5571158059943286,-2.2968256321819958
506.40000000000646,56.00926589117135,-0.5580660405861934,-2.2968700152201684
507.5000000000065,56.11704060597154,-0.559484412046246,-2.2958903494343565
508.6000000000065,56.22250022669525,-0.5618847633258108,-2.297306749908876
509.7000000000065,56.33286895656317,-0.5647664746514047,-2.297209932836581
510.80000000000655,56.43997123566197,-0.5680227755508934,-2.296863164457509
511.90000000000657,56.54906337973101,-0.5694755763982862,-2.2981901198865744
513.0000000000066,56.65771441246594,-0.5728574627811123,-2.2995129755593875
514.1000000000065,56.76362365773439,-0.578880799471798,-2.2981898487356442
515.2000000000066,56.874608070141264,-0.5854412047165889,-2.2995091335888564
516.3000000000065,56.98202470204183,-0.5900658567926228,-2.2998346872017583
517.4000000000067,57.09169187708125,-0.5938057199280297,-2.3005846775204084
518.5000000000066,57.199622710200195,-0.5991647463715281,-2.3004955471219324
519.6000000000067,57.308514117622614,-0.602504768116271,-2.301705516017467
520.7000000000066,57.41745364828477,-0.6064287532872489,-2.3007855659315926
521.8000000000067,57.52611722535101,-0.6083849641435218,-2.302123466691244
522.9000000000067,57.6349024634815,-0.6128637853715838,-2.302139886984657
524.0000000000067,57.74329155358155,-0.6153721531634918,-2.300820206418064
525.1000000000067,57.85004001105815,-0.618019812653377,-2.30214242809557
526.2000000000068,57.96081510856065,-0.6222385459665059,-2.3028808136461576
527.3000000000068,58.06936186849527,-0.624690051461176,-2.304119883878494
528.4000000000068,58.17821774665112,-0.6277222235942431,-2.3041200199995737
529.5000000000068,58.28489889726268,-0.6293327802786466,-2.304120136226723
530.6000000000068,58.39528246605983,-0.6322236319937746,-2.3054397297077625
531.7000000000069,58.50460645330444,-0.6347929581614962,-2.304120965871295
532.8000000000068,58.6128016710527,-0.6358162828535758,-2.304119871685269
533.9000000000069,58.72210488955327,-0.6395105670318545,-2.3069630456315635
535.0000000000068,58.831706745805604,-0.6413938986802321,-2.305692950215663
536.100000000007,58.94098780046589,-0.6437912606387292,-2.304339890415385
537.2000000000069,59.04880490637039,-0.6470609469150622,-2.3056050954921377
538.300000000007,59.15800936666864,-0.6498424592619945,-2.3045775864703706
539.4000000000069,59.26716277795943,-0.6509752540243386,-2.3059795391677267
540.5000000000069,59.37574260181855,-0.6518310474475729,-2.3056625919758096
541.600000000007,59.4854146569132,-0.6547167376853661,-2.308196661618141
542.700000000007,59.592559992307415,-0.6548103967807719,-2.3067531124691625
543.800000000007,59.70347875798413,-0.6576563254189957,-2.3067599679929036
544.900000000007,59.81073131993635,-0.6590979790844234,-2.3080803082980683
546.000000000007,59.92094056693663,-0.6593772113846081,-2.309389259267423
547.1000000000071,60.03025182444395,-0.6603127497930781,-2.3093898290228756
548.2000000000071,60.13946817692936,-0.6625960376090152,-2.3103692677221437
549.300000000007,60.248141637828176,-0.6631133221777777,-2.3103702024799686
550.4000000000071,60.35686327849108,-0.66402805687099,-2.3095140133517953
551.500000000007,60.46666084945212,-0.6633651639939605,-2.3107100006218064
552.6000000000072,60.57547732071159,-0.66529454895488,-2.310884889708691
553.7000000000071,60.68395506238038,-0.6636538232731217,-2.311370025965086
554.8000000000072,60.79452090067171,-0.6648005938388777,-2.3110409330628916
555.9000000000071,60.90314304578317,-0.6644479792345684,-2.3122748181063124
557.0000000000072,61.01227281727488,-0.6652618976982405,-2.312345230573772
558.1000000000072,61.12166780710323,-0.6660024686198353,-2.312374403349467
559.2000000000072,61.23052544123779,-0.6655636283583075,-2.3123602019893026
560.3000000000072,61.3395763654727,-0.6673434587795736,-2.312361953362411
561.4000000000073,61.447124661254385,-0.6670781125654244,-2.31502899412717
562.5000000000073,61.5583334391829,-0.66840624196622,-2.315326374040517
563.6000000000073,61.668410622471306,-0.6682442582301202,-2.3153200588502925
564.7000000000073,61.77694337632932,-0.6720503410559975,-2.3166399685424306
565.8000000000073,61.886376676497896,-0.673324406683231,-2.316309351308537
566.9000000000074,61.99563008078969,-0.6765899473735572,-2.3154008067546687
568.0000000000074,62.10458878401864,-0.6758371472178398,-2.3149899150080797
569.1000000000074,62.21394907927661,-0.6785568642386368,-2.3149908204731586
570.2000000000073,62.32204241993758,-0.6791666589531263,-2.3162909675982486
571.3000000000073,62.43073211185817,-0.6789207621732914,-2.318143911264864
572.4000000000074,62.542489320892635,-0.680981986416211,-2.3189403069517267
573.5000000000074,62.6510481647214,-0.6806202602787944,-2.3181807983735316
574.6000000000074,62.76074571872287,-0.6806229060736539,-2.3182916953807826
575.7000000000074,62.87133662798688,-0.6806207345002542,-2.3195920176566043
576.8000000000075,62.97917106403152,-0.6812199894925316,-2.3199293081739354
577.9000000000075,63.0890705922102,-0.6818077018997237,-2.321570029132428
579.0000000000075,63.19825051754208,-0.6826258477227234,-2.3215663227455217
580.1000000000075,63.308381057825194,-0.6829407249703312,-2.320909907464315
581.2000000000075,63.417490779390874,-0.6831156725477299,-2.3208701857497744
582.3000000000076,63.52741158707886,-0.6845127022737716,-2.3221927404604337
583.4000000000076,63.636307555855375,-0.6832768115101654,-2.322887979830741
584.5000000000076,63.74569515191667,-0.6796202289376636,-2.323503697667068
585.6000000000076,63.85636024169487,-0.6794491597260409,-2.322899920833004
586.7000000000077,63.96480054341691,-0.6775589639130983,-2.322901889127186
587.8000000000077,64.07511783497584,-0.6750648011088464,-2.325524060029129
588.9000000000076,64.18420408726789,-0.6734912231067177,-2.325259846049435
590.0000000000076,64.29324535637272,-0.6701551530528909,-2.325530124031273
591.1000000000076,64.40247447719973,-0.6670562806215722,-2.325675849910034
592.2000000000077,64.5119807404311,-0.663190529302078,-2.3268529672647515
593.3000000000077,64.62114574126554,-0.6582946273597295,-2.3261966290573577
594.4000000000077,64.7310194774736,-0.6561582428243135,-2.3281711481449934
595.5000000000077,64.84033920176424,-0.6508658634114354,-2.3282090634022894
596.6000000000078,64.94906239448775,-0.6483326316349275,-2.329479834980738
597.7000000000078,65.05724832776441,-0.6444160807330671,-2.330800481139616
598.8000000000078,65.16719784405404,-0.6404800796868426,-2.3308000238370195
599.9000000000078,65.27693384433904,-0.6349133344596348,-2.3307871834929
601.0000000000078,65.38625505787199,-0.6317449623605795,-2.332113540064049
602.1000000000079,65.49591280157425,-0.627992623258896,-2.3321200778002478
603.2000000000079,65.60499789014236,-0.6270743193210173,-2.3321893568444865
604.3000000000079,65.71473984376439,-0.6234707742708503,-2.332035273422429
605.4000000000078,65.82367466620616,-0.6204509841489381,-2.334753872417889
606.5000000000078,65.93348268486334,-0.6161055090539606,-2.3347671322198917
607.6000000000079,66.04281790707556,-0.6150693104056272,-2.3347580113360307
608.7000000000079,66.15324273580674,-0.6109407117695853,-2.3373783818092573
609.8000000000079,66.26184742076106,-0.6092037257217903,-2.3387046066709725
610.9000000000079,66.3721479713484,-0.6069651711481986,-2.3410158511873664
612.000000000008,66.48127849260423,-0.6041520781992341,-2.3396898740450935
613.100000000008,66.59091992852457,-0.6010522987292645,-2.3410419102926454
614.200000000008,66.69936733275715,-0.5977642518432911,-2.3410000182093813
615.300000000008,66.8090620149816,-0.5961755231927621,-2.342319950071426
616.400000000008,66.91936009013523,-0.5938066244992415,-2.343644404642133
617.5000000000081,67.02865703261202,-0.5902882171882157,-2.3436403143914566
618.6000000000081,67.13855108214838,-0.5892941433828077,-2.3462662064582984
619.7000000000081,67.24808965488818,-0.584783838251461,-2.3482500066106358
620.8000000000081,67.35847721606221,-0.5827306762247805,-2.3481560310883385
621.9000000000082,67.46769198798005,-0.5798279502632567,-2.3481504015284314
623.0000000000082,67.57733381077132,-0.5809614158779475,-2.3482460391998705
624.1000000000081,67.68658823374507,-0.5768551457371858,-2.350813729084768
625.2000000000081,67.79630990053485,-0.5766060674015707,-2.3535734792052523
626.3000000000081,67.90645553244687,-0.5718725537707043,-2.3548400053277865
627.4000000000082,68.01597775516773,-0.5685962572285269,-2.3548375627693523
628.5000000000082,68.1260318742028,-0.5645250169909645,-2.3568169644608425
629.6000000000082,68.23551180947982,-0.5611351938231202,-2.3587725853797092
630.7000000000082,68.34588388584815,-0.5547139680093875,-2.3614048627935
631.8000000000083,68.45538664892858,-0.5482431352037735,-2.3614342813328384
632.9000000000083,68.56584955148726,-0.5437078202576902,-2.3627500588560144
634.0000000000083,68.67489207954789,-0.5373860843054236,-2.3654776670250826
635.1000000000083,68.7836768673163,-0.5312829538765124,-2.366799960930669
636.2000000000083,68.89463600132657,-0.5234385520094006,-2.3681264380769016
637.3000000000084,69.00515755919143,-0.5148591827618471,-2.3705744318690667
638.4000000000084,69.11463340535474,-0.5063735451981377,-2.3720605306778846
639.5000000000084,69.22499073163483,-0.4974790161880267,-2.3734273596267355
640.6000000000083,69.33450959417084,-0.48974931761878443,-2.374995155187883
641.7000000000083,69.4444973180578,-0.47899394308942805,-2.378698141164863
642.8000000000084,69.55376170575298,-0.4685158719328229,-2.3800031864496787
643.9000000000084,69.66427783892333,-0.45773485057572566,-2.3835622755189503
645.0000000000084,69.7734390982952,-0.44796841201304444,-2.3853239029213325
646.1000000000084,69.88423842295796,-0.43896287951859425,-2.386682410928187
647.2000000000085,69.99337940523235,-0.42994121928710566,-2.3904366602757197
648.3000000000085,70.10253124460941,-0.4217697681810072,-2.3933521896748093
649.4000000000085,70.21204779045269,-0.41713442169716797,-2.395996100324097
650.5000000000085,70.3223560066125,-0.41070580831840475,-2.3984988264284834
651.6000000000085,70.43234706085227,-0.405033495186383,-2.4000015752498687
652.7000000000086,70.54169025842897,-0.40180434494608896,-2.4056917897924106
653.8000000000086,70.65143845225694,-0.40021170788753146,-2.4069897400216256
654.9000000000086,70.76119433968888,-0.39946952903664235,-2.409702514714299
656.0000000000086,70.86971204460386,-0.4016180376480937,-2.413513322716506
657.1000000000087,70.97977856009484,-0.40686387677433344,-2.4164774817561785
658.2000000000087,71.08928566572816,-0.4151270611383761,-2.4192889666514175
659.3000000000086,71.19957918118152,-0.4230091829127968,-2.4209442062055926
660.4000000000086,71.30926716000552,-0.43540108905346975,-2.4245582853179837
661.5000000000086,71.41888580679057,-0.44201048870683146,-2.427619516127146
662.6000000000087,71.52816294415538,-0.443857435123351,-2.430232295092099
663.7000000000087,71.63865678557633,-0.43955241736862777,-2.4316671685937674
664.8000000000087,71.74781253052868,-0.43022648712485845,-2.4329276720173665
665.9000000000087,71.85935375660262,-0.4120247048853619,-2.4383937250145005
667.0000000000088,71.9682861691626,-0.39524490154437697,-2.441351907777282
668.1000000000088,72.07822471794726,-0.38071059969826754,-2.4442095134041617
669.2000000000088,72.1883946341571,-0.3711120255913767,-2.4463192370942135
670.3000000000088,72.29830937427145,-0.3640506445757419,-2.4499162716979077
671.4000000000088,72.40825521419522,-0.36612326142100604,-2.4541827306532613
672.5000000000089,72.51819938171936,-0.37315273240752567,-2.458329762846403
673.6000000000089,72.62855149139526,-0.387466919871083,-2.4608323426539758
674.7000000000089,72.73759929157248,-0.4068884957214492,-2.4638782045217575
675.8000000000088,72.84782834722324,-0.4371675468998787,-2.467806012648572
676.9000000000088,72.95683434454517,-0.47265162873681593,-2.469136921100238
678.0000000000089,73.06680307634149,-0.5182739553544972,-2.4715805007786544
679.1000000000089,73.17672220701594,-0.5595015364186791,-2.4744557134138567
680.2000000000089,73.2868660642994,-0.6049442084424371,-2.4763569744491463
681.3000000000089,73.39598327231947,-0.647072757193945,-2.4776892240287793
682.400000000009,73.50614784845988,-0.6840148061544077,-2.478354672543559
683.500000000009,73.6153138085331,-0.7151968639142026,-2.480792945981416
684.600000000009,73.72535096700236,-0.7411243291504188,-2.481035769838572
685.700000000009,73.83438664476292,-0.7623273667120082,-2.4810895039618273
686.800000000009,73.94411602424404,-0.7775537133749938,-2.4826722213184658
687.9000000000091,74.05460459396778,-0.7945126880643522,-2.482407529220932
689.0000000000091,74.16533962497765,-0.8051199664738292,-2.481518274875864
690.1000000000091,74.27437094843829,-0.813684469605652,-2.482729905303433
691.2000000000091,74.38519816905183,-0.8193907245594199,-2.48506861325476
692.3000000000092,74.49466265945912,-0.8254770842026419,-2.485039804006009
693.4000000000092,74.60542019691061,-0.832646800108198,-2.4857654230408635
694.5000000000091,74.71495183718709,-0.837881304395176,-2.4850718980513165
695.6000000000091,74.82542302657714,-0.840854892201918,-2.485039977278203
696.7000000000091,74.9370098759416,-0.8461460112840642,-2.4837298126894773
697.8000000000092,75.04796954868412,-0.8489304886429931,-2.485040073196045
698.9000000000092,75.1567463763886,-0.8535283208817592,-2.486333329361953
700.0000000000092,75.26765863693103,-0.8571232965187322,-2.48701954867066
701.1000000000092,75.37770186632072,-0.8613295014300641,-2.487019716920996
702.2000000000093,75.48783303014966,-0.8665271261902695,-2.4870201210001333
703.3000000000093,75.59917112766364,-0.8703200450169788,-2.4870201209585536
704.4000000000093,75.70850649768397,-0.8729093486845265,-2.488225581971739
705.5000000000093,75.81875252938084,-0.8790562860086292,-2.4870199641337614
706.6000000000093,75.92927357995283,-0.8824664093155984,-2.4870279994285722
707.7000000000094,76.03898366061654,-0.8866989523416122,-2.4880099278868646
708.8000000000094,76.14843616079835,-0.8899411837087227,-2.489367512037076
709.9000000000094,76.25878471642892,-0.8883685452936687,-2.4879878920190563
711.0000000000093,76.36907117704058,-0.8868812038040711,-2.4893198340234264
712.1000000000093,76.47823416106557,-0.8896703155130339,-2.489319833321138
713.2000000000094,76.58829608072575,-0.8880479995136754,-2.4906483980524055
714.3000000000094,76.69886230585571,-0.8892797746907164,-2.4906400484992326
715.4000000000094,76.80888021354967,-0.8916534846631914,-2.489652403057076
716.5000000000094,76.91847198420032,-0.8923794076484979,-2.4899363251103397
717.6000000000095,77.02680979713533,-0.8943438290683559,-2.4906407710049345
718.7000000000095,77.13765688747777,-0.8989408770073883,-2.4902781628320882
719.8000000000095,77.24877678292584,-0.8990784525760463,-2.49031981119785
720.9000000000095,77.35779725779089,-0.9025944702191627,-2.490309857757843
722.0000000000095,77.46813161295182,-0.9022970477002911,-2.4916215902695544
723.1000000000096,77.5779271418629,-0.9028492431145463,-2.491296083109126
724.2000000000096,77.68800790089935,-0.9080484237405252,-2.4912774182823725
725.3000000000096,77.79795924143363,-0.909098316482829,-2.4929504047380533
726.4000000000096,77.90927707849225,-0.9109816758593645,-2.493598160544035
727.5000000000097,78.01937708497059,-0.9134800170433798,-2.4935998580005796
728.6000000000097,78.12989443692692,-0.9136954971943597,-2.4935998644102413
729.7000000000096,78.24123529519156,-0.9167131893171677,-2.4954438700662003
730.8000000000096,78.3510845344817,-0.9182717483361582,-2.4949170728455745
731.9000000000096,78.46215565781422,-0.9199832127737406,-2.495152339166378
733.0000000000097,78.572223201775,-0.9215001449355287,-2.496237058889723
734.1000000000097,78.68361279694506,-0.9236337914651351,-2.496239817145435
735.2000000000097,78.79437458583506,-0.9276540598236077,-2.496212737280953
736.3000000000097,78.90607140771499,-0.9290111886719447,-2.4952550294281073
737.4000000000098,79.01648318114697,-0.9304618296413402,-2.4977574798844775
738.5000000000098,79.12658801539405,-0.9318614260486444,-2.496569618397709
739.6000000000098,79.23735531821185,-0.9317018733533047,-2.4962530457657692
740.7000000000098,79.348569165259,-0.935445088846002,-2.496900818738281
741.8000000000098,79.45807290059592,-0.9372049172699419,-2.498220206524808
742.9000000000099,79.56820175027839,-0.9398172442298789,-2.4984501213777763
744.0000000000099,79.67725884866043,-0.941393764945863,-2.4998600078481337
745.1000000000099,79.78927350092053,-0.9445353121679405,-2.499860008025574
746.2000000000098,79.89897669850535,-0.9454258406497066,-2.5011800691127064
747.0000000000099,79.97995937048071,-0.9494244729131469,-2.501179850978428