File: 01_Data/EPDM_Membrane/STA/N2/10K_min/EPDM_Membrane_STA_N2_10KData_220927_R1.csv
##Temp./Â°C,Time/min,DSC/(mW/mg),Mass loss/mg
51.0,10.753978432817938,-1.587879703888719,-0.016468933552491904
52.100000000000016,11.136770943109461,-1.4659018710718366,-0.015319520088139527
53.20000000000003,11.390517305117443,-1.389423103243254,-0.01606592198855772
54.30000000000005,11.598363716768674,-1.3318834403127304,-0.017361388961810498
55.40000000000006,11.78366198935182,-1.2870707784987299,-0.01564873130169442
56.50000000000008,11.956038083849958,-1.2494607561536168,-0.013555228893127769
57.600000000000094,12.117417914371632,-1.219018033412463,-0.013425349848240842
58.70000000000011,12.274851905907019,-1.1941460108131496,-0.016100764461124406
59.800000000000125,12.421332439990316,-1.1730095083585097,-0.01404630521378536
60.90000000000014,12.5676955568773,-1.15306666771993,-0.015600914974622349
62.000000000000156,12.712252448038093,-1.1343494301570916,-0.016873618245794475
63.10000000000017,12.85211439804049,-1.11848079347868,-0.018334675861611416
64.20000000000019,12.98967356984552,-1.1025443247783995,-0.017925436062846245
65.30000000000021,13.124717756597546,-1.0888393401146785,-0.016751459091023158
66.40000000000022,13.25677189910414,-1.0781091208690177,-0.013657205506505399
67.50000000000023,13.387659087476946,-1.064897810708965,-0.00948587626462949
68.60000000000025,13.516632264888312,-1.0534558399473144,-0.006758174185992338
69.70000000000027,13.64216236769673,-1.0414364727372722,-0.009699014203245149
70.80000000000028,13.771203789320147,-1.028889541844588,-0.013625239672437672
71.90000000000029,13.895778774249395,-1.0162842823647116,-0.013691585999713318
73.00000000000031,14.019542442445996,-1.0079428877756498,-0.014958073254136117
74.10000000000034,14.144140477023218,-0.9964052994758139,-0.0162371754121704
75.20000000000034,14.266523372359359,-0.98512037399267,-0.014897409179940979
76.30000000000035,14.38734201511373,-0.976575342838447,-0.01624268784400673
77.40000000000038,14.508538777097122,-0.9662097990549211,-0.01537397788781103
78.5000000000004,14.628417193578457,-0.9570185970282533,-0.016777161837775445
79.6000000000004,14.748025603143212,-0.9464040134930991,-0.017569677890944213
80.70000000000041,14.86604548425815,-0.9375578368834416,-0.017541741558495083
81.80000000000044,14.983343758823873,-0.9278946629440507,-0.018723716625323128
82.90000000000046,15.10092370275046,-0.9200766091101934,-0.017680144642320705
84.00000000000047,15.216434117461825,-0.9122336445830415,-0.017775213787171396
85.10000000000048,15.331312554790687,-0.9043055497383683,-0.017685268777579033
86.2000000000005,15.445906892839838,-0.8946359151684875,-0.018970143352177615
87.30000000000052,15.56189534083802,-0.8864728803092802,-0.017698268067587897
88.40000000000053,15.676478122653501,-0.8787643303666915,-0.01768281094072055
89.50000000000054,15.790930504568312,-0.8703913383634189,-0.017681234749337804
90.60000000000056,15.901677499837845,-0.8628137689827923,-0.01767865732439322
91.70000000000059,16.01395555137122,-0.85638280093436,-0.01784959414692544
92.8000000000006,16.1260758920756,-0.8476296366867289,-0.017767180193144938
93.9000000000006,16.237135610053276,-0.8414835213059918,-0.018996498139588702
95.00000000000063,16.347286842206973,-0.8340611652614957,-0.017975514447662988
96.10000000000065,16.457428422561954,-0.8250856224091648,-0.019349508807295024
97.20000000000066,16.565173534174097,-0.819177685891272,-0.018997265769342242
98.30000000000067,16.678087341578603,-0.8130246823595406,-0.018947568309140905
99.40000000000069,16.788131494939936,-0.8074755248501655,-0.01899876874554085
100.50000000000071,16.89795142341057,-0.7982835052615735,-0.020305624161391478
101.60000000000072,17.00625677465029,-0.7923852022947995,-0.02030997886581698
102.70000000000073,17.115192542463443,-0.7865752559925477,-0.02168099575309501
103.80000000000075,17.224286879015636,-0.780683590107661,-0.02052700877857294
104.90000000000077,17.33251722608806,-0.7761136839902295,-0.021620051889257752
106.00000000000078,17.44087722546596,-0.7705364651067312,-0.021629667899083493
107.10000000000079,17.54785369874923,-0.7637806592275855,-0.02294914192015174
108.20000000000081,17.65703087526934,-0.7577944395365934,-0.021628502000923255
109.30000000000084,17.765790665834274,-0.7514481410260682,-0.02160391444463361
110.40000000000084,17.874172081628018,-0.7470542157749371,-0.02162037127897154
111.50000000000085,17.981287314707878,-0.7429076934865101,-0.02243985889656752
112.60000000000088,18.088967888727655,-0.7356057436700888,-0.022950200903625984
113.7000000000009,18.196933313154453,-0.7286576755651942,-0.021960444269092605
114.8000000000009,18.304930881740052,-0.7240593190078889,-0.022950374343669644
115.90000000000092,18.411437689268624,-0.7195532304002871,-0.022938497130566837
117.00000000000094,18.51832637028309,-0.7182319593442734,-0.02293537939593282
118.10000000000096,18.625547544535987,-0.7154941768626416,-0.023314437918211972
119.20000000000097,18.732720392084758,-0.7114047735604376,-0.022935021279625545
120.30000000000098,18.840626461799747,-0.7080911511833696,-0.024289265018179407
121.400000000001,18.946404217235205,-0.7029777848859432,-0.025577918107440034
122.50000000000102,19.054501717072746,-0.6995090730456565,-0.024575657351607383
123.60000000000103,19.160257796572782,-0.6945128670398089,-0.024264715855311536
124.70000000000104,19.266617955852695,-0.6907318848335,-0.025582384181959128
125.80000000000106,19.374815366064535,-0.6872936337395942,-0.024244295888482092
126.90000000000109,19.479974324576453,-0.6824690214617701,-0.025249976910552974
128.00000000000108,19.587508239064654,-0.6791588639380514,-0.026537385164584926
129.1000000000011,19.69382244391384,-0.6753017985488025,-0.025251888007325363
130.20000000000113,19.798680023197917,-0.6693500619608411,-0.025909948431152685
131.30000000000115,19.906060070311927,-0.6662371912890255,-0.026570854193979088
132.40000000000117,20.01162270051294,-0.6621060194988606,-0.02657172678267994
133.50000000000117,20.11742720966328,-0.6588190538420541,-0.02736656622632072
134.6000000000012,20.223189416492026,-0.6535466752799557,-0.02656936279595712
135.7000000000012,20.329080678636533,-0.6488158134634842,-0.027938443080072872
136.8000000000012,20.433899159567428,-0.6444663739105749,-0.02787996330598741
137.90000000000123,20.538130326798957,-0.6410508192549941,-0.028010402991135663
139.00000000000125,20.64455845022991,-0.6368208316374008,-0.02787376438033551
140.10000000000127,20.749863146547398,-0.634542080740601,-0.027890363139682073
141.2000000000013,20.85439164610471,-0.6290841127225082,-0.02859964092688383
142.3000000000013,20.959636870893608,-0.625575381947426,-0.02788957919300472
143.4000000000013,21.0641412009149,-0.6209465939722006,-0.02920843797576822
144.50000000000134,21.168398138962385,-0.6170763147953768,-0.02788943125546961
145.60000000000133,21.274163594238548,-0.6149910479894979,-0.028490166669801198
146.70000000000135,21.378893679440868,-0.6109476875316707,-0.029529965026373617
147.80000000000138,21.482013660886984,-0.6080959174326172,-0.030520451926022485
148.9000000000014,21.587984171720596,-0.6040303875302958,-0.03052016000102853
150.00000000000142,21.693264062105147,-0.6005596637671701,-0.03055831378059448
151.10000000000142,21.797688590602466,-0.5973490753308338,-0.031842352765777626
152.20000000000144,21.902356288232482,-0.5943902369315506,-0.03182985410669836
153.30000000000146,22.006361075232853,-0.5894018544926658,-0.03293762234238695
154.40000000000146,22.111687595552965,-0.5851278704761824,-0.03182183876210454
155.50000000000148,22.213884124165517,-0.5838180651421815,-0.03226303477496861
156.6000000000015,22.320250726496845,-0.579842408173593,-0.034577860662458715
157.70000000000152,22.42536408125724,-0.576482431258396,-0.03360154542925242
158.80000000000155,22.52859805171408,-0.5722758859041674,-0.03351523445911342
159.90000000000154,22.633382234988765,-0.5707493582289116,-0.0358923449352071
161.00000000000156,22.738086235888737,-0.5659190668437319,-0.03623018195297201
162.1000000000016,22.841239513932607,-0.5635201643342395,-0.03623018214465956
163.20000000000158,22.946756164873314,-0.5603572689918479,-0.03752059258150808
164.3000000000016,23.051301342330365,-0.5578492166502186,-0.036999662991679116
165.40000000000163,23.155753039957983,-0.5549244138448065,-0.03689010835519024
166.50000000000165,23.261078152139564,-0.5514295341642955,-0.03787982669134937
167.60000000000167,23.365505797735565,-0.5490117311446848,-0.03788032524827578
168.70000000000167,23.469458756960144,-0.545681769745605,-0.03920011515515087
169.8000000000017,23.57445610068367,-0.54441999051673,-0.039200125011327636
170.9000000000017,23.678985570920155,-0.541593677405557,-0.03915980456658241
172.0000000000017,23.78319634796072,-0.539260992098041,-0.042526331780893045
173.10000000000173,23.88906358662733,-0.5369491407760961,-0.0411686391898054
174.20000000000175,23.993290825943784,-0.5362190796902053,-0.041103736275849734
175.30000000000177,24.09762295850577,-0.5331668830952788,-0.041088765773298785
176.4000000000018,24.202185500681985,-0.5319394339263788,-0.03831439030184036
177.5000000000018,24.306908884882848,-0.5292252394269722,-0.03963202446559899
178.6000000000018,24.411670736730155,-0.5278291414432605,-0.04312267189079444
179.70000000000184,24.51612451249196,-0.5254123879869242,-0.04563245957927986
180.80000000000183,24.616628939497474,-0.5247465075521649,-0.045560306249766924
181.90000000000185,24.724160765411224,-0.5227700817444818,-0.046879666492291694
183.00000000000188,24.82898491605102,-0.5203368573248093,-0.04818986924900592
184.1000000000019,24.93306566221455,-0.5184078700578492,-0.048189874692097234
185.20000000000192,25.034605313285496,-0.516890630349841,-0.048733097495961
186.30000000000192,25.141812240752888,-0.5154599715197696,-0.0501638796845163
187.40000000000194,25.24489088982887,-0.5142038447391885,-0.051490368766447414
188.50000000000196,25.34917000000017,-0.5130299999999918,-0.05017887636110441
189.60000000000196,25.45320189770565,-0.5099101770918752,-0.05148954713533893
190.70000000000198,25.557578659332414,-0.5085432949426746,-0.05278790892459195
191.800000000002,25.661548133589275,-0.5064410545128738,-0.05192426064095912
192.90000000000202,25.765981461145465,-0.5034034195312718,-0.052262433659596486
194.00000000000205,25.86927307758483,-0.5025281877627745,-0.05356939008490569
195.10000000000204,25.972013553097245,-0.49972327294990215,-0.05621010633612089
196.20000000000206,26.07809373628707,-0.4977347968961741,-0.05621021064336196
197.3000000000021,26.182521434056977,-0.4949063710318888,-0.057530123915499054
198.40000000000208,26.286638216612573,-0.4934046288191872,-0.0589045521819207
199.5000000000021,26.3905960192869,-0.4908711001967073,-0.05947421811879838
200.60000000000213,26.495066469738216,-0.4893681751279276,-0.06106819131596852
201.70000000000215,26.599622802823777,-0.4854497509913145,-0.0634886998744042
202.80000000000217,26.70259206443038,-0.48419228235620954,-0.06410761649672869
203.90000000000217,26.8073444133274,-0.48060837543551677,-0.06444651797412604
205.0000000000022,26.911488008391604,-0.47708107637631103,-0.06707021947871894
206.1000000000022,27.01606285988738,-0.47485928333186217,-0.06707000884748338
207.2000000000022,27.120022879184816,-0.4716960549677053,-0.06772302873574132
208.30000000000223,27.224005433597004,-0.4678698861668011,-0.06970963992924784
209.40000000000225,27.328480582868945,-0.4650528238129119,-0.07232493448288935
210.50000000000227,27.432002937585427,-0.4619118230070188,-0.07374264044245082
211.6000000000023,27.536564203355837,-0.4577952690184176,-0.07466754431238387
212.7000000000023,27.64150279454184,-0.4549996886097533,-0.07575943241807703
213.8000000000023,27.745057055857515,-0.4511820665433384,-0.07630220779107333
214.90000000000234,27.849170941575235,-0.4495399541222525,-0.07992937340814166
216.00000000000233,27.9542832706984,-0.44582465887060163,-0.0797981617874477
217.10000000000235,28.055819653341995,-0.44218505348809917,-0.08122362378448633
218.20000000000238,28.162394981078485,-0.4405023915734102,-0.08255037205056404
219.3000000000024,28.266377655430798,-0.43546717972539284,-0.08480881390661343
220.40000000000242,28.37056129364377,-0.4330509656168048,-0.08684684950645716
221.50000000000242,28.47510547411251,-0.42951120344405636,-0.08843146450535855
222.60000000000244,28.5797668654014,-0.42532661114882836,-0.09079003720486911
223.70000000000246,28.683632004563396,-0.4247158205026548,-0.09219421517323134
224.80000000000246,28.789170000000244,-0.42108000000000434,-0.09474973474479542
225.90000000000248,28.892737659112367,-0.41781980049470707,-0.09604817758222683
227.0000000000025,28.99719724528374,-0.41643761760603865,-0.09738018817096972
228.10000000000252,29.101278690179353,-0.41413000187832005,-0.10001956219546049
229.20000000000255,29.20547358490685,-0.4111110138359066,-0.10259411149432385
230.30000000000254,29.310926733249477,-0.4088838058470732,-0.10330343664750119
231.40000000000256,29.41516566238958,-0.4068954054936261,-0.10528352649667871
232.5000000000026,29.519892161637543,-0.4053436798589841,-0.10691460427382715
233.60000000000258,29.624307217652564,-0.40312285154130645,-0.10949015154438735
234.7000000000026,29.728770385974087,-0.4007024037670431,-0.1131629405767618
235.80000000000263,29.833769498744193,-0.39818659570783793,-0.11553578591665659
236.90000000000265,29.937924413173004,-0.3958511564115724,-0.1150514391312929
238.00000000000267,30.043163573263186,-0.3943303993946754,-0.11788509983789774
239.10000000000267,30.1481298308148,-0.3931978712029036,-0.12121273622732431
240.2000000000027,30.251798115090637,-0.3910291462070897,-0.12320255980537897
241.3000000000027,30.356462221147194,-0.38954116085627094,-0.12580553006469541
242.4000000000027,30.460033970211466,-0.3872896117919328,-0.12711922244160512
243.50000000000273,30.565296443623897,-0.38601321390321375,-0.1305180802491579
244.60000000000275,30.66846315977589,-0.3859972826656239,-0.13313840589255443
245.70000000000277,30.774112703176797,-0.3843199210727433,-0.13574731584444288
246.8000000000028,30.878298764434412,-0.3821927156728435,-0.13713322593555288
247.9000000000028,30.982482242427388,-0.38048020169973185,-0.14070076659971376
249.0000000000028,31.08805766843814,-0.37943237434097715,-0.14247785560813098
250.10000000000284,31.19159290407806,-0.3787081055295618,-0.14644542575691055
251.20000000000283,31.296579485212344,-0.3774267445491175,-0.1487508039793699
252.30000000000285,31.40074615265646,-0.377308745302505,-0.15171249386127927
253.40000000000288,31.503176242610433,-0.37653771709984135,-0.15562840826183466
254.5000000000029,31.610440832954517,-0.37516202894113504,-0.15831497699018682
255.60000000000292,31.713949886210383,-0.37442081825997586,-0.15957570803468712
256.7000000000029,31.81916901451854,-0.3726399977519213,-0.16357829127115142
257.8000000000029,31.922430549651803,-0.3724371541496224,-0.16719352987433034
258.90000000000293,32.02742402457071,-0.37286467632356424,-0.1698620942178426
260.00000000000296,32.13133837702614,-0.37139641153910385,-0.17247660240222862
261.100000000003,32.23693957226358,-0.3720711383195569,-0.17545432438816988
262.200000000003,32.34098921383242,-0.36936449644085834,-0.17812912362790678
263.300000000003,32.44539974550996,-0.36859132403291056,-0.18085286666786082
264.40000000000305,32.55057285034761,-0.3676899036226203,-0.1850791002152694
265.50000000000307,32.65509696519195,-0.36721511331856593,-0.18899986724969509
266.6000000000031,32.75994437967525,-0.3661467606529931,-0.19102283473187542
267.7000000000031,32.86328671305077,-0.3666851207309312,-0.19264941230988786
268.8000000000031,32.9700953832714,-0.36600135776462744,-0.19691693766700435
269.9000000000031,33.07399706017829,-0.36478336338293754,-0.2008085178606529
271.0000000000031,33.17869063714626,-0.3659125937371066,-0.20453934538141683
272.10000000000315,33.28343121982449,-0.3633866126472522,-0.20650256126921196
273.2000000000032,33.3891689902719,-0.3640199687297181,-0.21045073189533836
274.30000000000314,33.49370222335613,-0.3635960916354134,-0.21438323944158633
275.40000000000316,33.597731217983515,-0.3639194583071453,-0.21727445482318775
276.5000000000032,33.70229240526858,-0.3628099563952809,-0.22121272045534113
277.6000000000032,33.80868241986515,-0.3628809523997171,-0.2254110377445464
278.70000000000323,33.91317025319366,-0.3628966658986982,-0.2284862026875807
279.80000000000325,34.017965216888555,-0.36236791292261605,-0.23214890412386247
280.9000000000033,34.12336649325791,-0.36217208339734197,-0.2347869054069749
282.0000000000033,34.22881929403897,-0.36317812937193644,-0.23896558574033033
283.1000000000033,34.33324364072711,-0.3617346263485808,-0.24265270706673103
284.20000000000334,34.43838508891799,-0.3609408007655143,-0.24680068960966395
285.30000000000337,34.544132666503,-0.36091270033855727,-0.2501721897214968
286.40000000000333,34.64797329991358,-0.36027224812175546,-0.2540297343730167
287.50000000000335,34.752059442818194,-0.359845062806361,-0.2581422947992573
288.6000000000034,34.85858596236137,-0.3588098395382451,-0.26388701450043905
289.7000000000034,34.96419454382477,-0.35896010736485995,-0.26660623239171866
290.8000000000034,35.069267156323725,-0.3590881983252114,-0.2703976789989664
291.9000000000034,35.174443916691885,-0.3593509802906548,-0.2746544202708412
293.0000000000034,35.2773843450891,-0.3599128961001624,-0.2788355717678823
294.10000000000343,35.38471129853135,-0.3603754517798071,-0.2834522434046387
295.20000000000346,35.4891690810079,-0.35850000907454643,-0.28620028647051043
296.3000000000035,35.59311315550911,-0.3584449195548335,-0.28992804295400143
297.4000000000035,35.698958401480375,-0.3587966634980044,-0.2945776278173886
298.5000000000035,35.80565021065971,-0.3603917111449519,-0.29879942021448036
299.60000000000355,35.90936904561719,-0.36082688792341217,-0.3025577488881681
300.70000000000357,36.01469087101521,-0.3606270369537194,-0.30768383775866903
301.8000000000036,36.12087462550573,-0.3610449484609301,-0.31147627586142335
302.9000000000036,36.22532756080526,-0.36149413808832137,-0.3185721992291053
304.0000000000036,36.330576199243275,-0.36111013551960774,-0.3219189105739684
305.1000000000036,36.434838543946185,-0.36296276286344925,-0.3248617932672362
306.2000000000036,36.54235723516321,-0.36414664718116946,-0.3277175879538796
307.30000000000365,36.64628082950511,-0.3653159758307604,-0.3334041601594566
308.4000000000037,36.75222350498783,-0.36618149406908246,-0.3380837327545949
309.5000000000037,36.85679128659997,-0.3677096009138009,-0.3422544109164676
310.60000000000366,36.96226895068904,-0.37032765474863194,-0.34676886689714337
311.7000000000037,37.06926825521976,-0.3709130169256695,-0.35153810447340295
312.8000000000037,37.17248586397104,-0.3727001513082341,-0.3567511897578086
313.90000000000373,37.27857968403867,-0.3735498945846488,-0.3625487899322275
315.00000000000375,37.38350029766375,-0.37540957115129575,-0.3672245061295758
316.1000000000038,37.48946400246584,-0.37801809721014534,-0.3723709928730421
317.2000000000038,37.595232314651774,-0.3779945277747054,-0.377176620335109
318.3000000000038,37.700759097505774,-0.38173172925626697,-0.3828699974099923
319.40000000000384,37.806167035167306,-0.3824444926525359,-0.3883250268318883
320.5000000000038,37.91238438903818,-0.3837746505037198,-0.39336693811440826
321.60000000000383,38.017103339863695,-0.38538303512928895,-0.39917980351687055
322.70000000000385,38.12295066182594,-0.38840982392535617,-0.4037186909954591
323.8000000000039,38.22887684867072,-0.3903794798995005,-0.4094597049448172
324.9000000000039,38.33391966131735,-0.3945346845542923,-0.41512957326857824
326.0000000000039,38.44089042574182,-0.39692755683735914,-0.4206188678085523
327.10000000000394,38.546727323969876,-0.4003500087538883,-0.42615155095338464
328.2000000000039,38.65263932646257,-0.40326752513218095,-0.43360715458388865
329.30000000000393,38.75871759663883,-0.4060103638479087,-0.4399710764347389
330.40000000000396,38.86371476369922,-0.4094454693732507,-0.44361762199031407
331.500000000004,38.96981625855483,-0.4131160065195813,-0.4499942334628302
332.600000000004,39.07559133932971,-0.41403280073635396,-0.4579918293776326
333.700000000004,39.18176908620722,-0.416827830892516,-0.46561182878309637
334.80000000000405,39.28798579710322,-0.42025632260851764,-0.4727536609597651
335.90000000000407,39.393111476208226,-0.420978798685138,-0.47867574755754116
337.0000000000041,39.49955705601515,-0.4247288742482326,-0.4862452675044766
338.10000000000406,39.60527468953258,-0.42792809500286527,-0.49387491386125326
339.2000000000041,39.71183029646196,-0.4295602592270745,-0.5021475198769751
340.3000000000041,39.817230750449774,-0.43174698020771096,-0.5099410237008297
341.4000000000041,39.92292877781634,-0.43621492116019744,-0.518246974641249
342.50000000000415,40.02883768064528,-0.437651991355137,-0.5279269012409271
343.6000000000042,40.134723421524434,-0.4401690355344601,-0.5375297297355299
344.7000000000042,40.23953455484601,-0.44070489762282405,-0.5465399829792847
345.80000000000416,40.344986394783234,-0.44407704785476776,-0.5550727138048774
346.9000000000042,40.452157039519264,-0.44801380594942114,-0.5673146070048269
348.0000000000042,40.55791159687376,-0.4506726836953818,-0.5773043483760394
349.10000000000423,40.664485410349975,-0.45100537525014844,-0.5899229547267284
350.20000000000425,40.7706803182328,-0.4525341051344401,-0.6007315564837241
351.3000000000043,40.876594537492494,-0.4532551788287516,-0.613617280573084
352.4000000000043,40.98226089589707,-0.4558375618264761,-0.625814370162149
353.5000000000043,41.08805728229388,-0.4562159209845806,-0.6408679888053213
354.60000000000434,41.19414695155267,-0.45636762865528757,-0.6537613930743014
355.7000000000043,41.3005671366963,-0.4571444909381678,-0.668938473300325
356.80000000000433,41.40756390608991,-0.45797793210833604,-0.6832199311350804
357.90000000000435,41.51361600406199,-0.45740683802375964,-0.6984091672148383
359.0000000000044,41.61993934365813,-0.4569670542655623,-0.7147145745968357
360.1000000000044,41.726739996485236,-0.45633882790195707,-0.7329535329841526
361.2000000000044,41.83189250346371,-0.4536692795269681,-0.7500073256276014
362.30000000000445,41.93815840877281,-0.4537682317302313,-0.7680553714804161
363.4000000000044,42.044848899930855,-0.44975313245477516,-0.7872172921922793
364.50000000000443,42.150629925246044,-0.4494373319527273,-0.8064774931746461
365.60000000000446,42.25757424946165,-0.44735603709734334,-0.8278877856603004
366.7000000000045,42.3647519087985,-0.442341144714514,-0.8502721427089326
367.8000000000045,42.47132549994416,-0.4393584250532959,-0.8719420119019214
368.9000000000045,42.577155833380566,-0.4356764284053719,-0.8923960891422897
370.00000000000455,42.68319207852708,-0.4324769294987685,-0.9152661457212474
371.10000000000457,42.787415374511916,-0.4280510955556225,-0.9396043411216941
372.2000000000046,42.89598983574297,-0.4229431974385693,-0.9636151813349212
373.30000000000456,43.00184383773862,-0.41960874201966036,-0.9891424405385112
374.4000000000046,43.1098510594862,-0.4132291266241505,-1.013938058054805
375.5000000000046,43.21488054492538,-0.4087848476579388,-1.039053361758639
376.6000000000046,43.3221062771038,-0.40413468695389804,-1.0651357659831726
377.70000000000465,43.42936781282033,-0.3983324817153971,-1.0880008998675508
378.8000000000047,43.53547482367683,-0.3929258130060538,-1.111761776176651
379.9000000000047,43.64266113076292,-0.38896743209231704,-1.1396532865479534
381.00000000000466,43.748585650270506,-0.3849991747623863,-1.1635418292509776
382.1000000000047,43.85573163006314,-0.37865558946394373,-1.1895597059803604
383.2000000000047,43.96174161730134,-0.37549273891321755,-1.2158299718209769
384.30000000000473,44.068847197325056,-0.37297812094604815,-1.2405801810370134
385.40000000000475,44.175541523459756,-0.3659075619987328,-1.264179458543186
386.5000000000048,44.281572444380544,-0.36416499882829884,-1.2887962287726697
387.6000000000048,44.38960685777202,-0.3617240012339813,-1.3129818984953614
388.7000000000048,44.49601630399494,-0.3561171402853062,-1.3367284382105988
389.80000000000484,44.602340879154575,-0.35305908426820176,-1.3588414960966886
390.9000000000048,44.70980894846129,-0.34921923688640405,-1.3817564694776419
392.00000000000483,44.81676729280261,-0.3481112789997216,-1.4059921565188662
393.10000000000485,44.92312677509099,-0.3456755154429889,-1.4279608993238124
394.2000000000049,45.030686393421604,-0.34297283472229045,-1.4485751039095187
395.3000000000049,45.137155051353545,-0.3419088066476735,-1.4695569937139452
396.4000000000049,45.24460557077676,-0.33824338474443005,-1.4896568136392858
397.50000000000495,45.3513934262318,-0.3351466734206679,-1.509398571381951
398.6000000000049,45.457942232856496,-0.33454969402855395,-1.5281475109598133
399.70000000000493,45.565364741120156,-0.33279082928182274,-1.5462902016367295
400.80000000000496,45.67232898891942,-0.33158660178674193,-1.5682074167152766
401.900000000005,45.77834289794565,-0.3294713915559612,-1.5863462057995918
403.000000000005,45.8857680761253,-0.3271597653583523,-1.6032730640467703
404.100000000005,45.99098446005769,-0.32687812283193185,-1.6222429910774845
405.20000000000505,46.10075111252999,-0.3238388596089111,-1.6384046424891054
406.30000000000507,46.2079325003413,-0.32294287955577067,-1.6561846449450957
407.4000000000051,46.31551473751385,-0.3220929226114711,-1.671177356243426
408.50000000000506,46.4218636888082,-0.3194068903353465,-1.687563223738426
409.6000000000051,46.529381853028525,-0.3203261633966335,-1.705173872872869
410.7000000000051,46.6359492436971,-0.3178156253238741,-1.720033114875732
411.8000000000051,46.74278079770737,-0.3148798051179361,-1.7372607143741332
412.90000000000515,46.85064613715628,-0.3158937022145331,-1.751738816960386
414.0000000000052,46.95737528276862,-0.3161302148077505,-1.765657926247925
415.1000000000052,47.065108900995824,-0.31527879527310915,-1.7781895119873394
416.20000000000516,47.17273015816094,-0.3142375951204269,-1.7949847587043197
417.3000000000052,47.278978030461325,-0.3138494404004271,-1.811061665486971
418.4000000000052,47.38667246481586,-0.3142380717412969,-1.8255458657252093
419.50000000000523,47.494161039692585,-0.31516625357118305,-1.8407792229068018
420.60000000000525,47.60007119373111,-0.3126227741141935,-1.857215158752458
421.7000000000053,47.70782012247486,-0.3126413948759934,-1.871687295507535
422.8000000000053,47.81438628841809,-0.31448735183394355,-1.885724414252043
423.9000000000053,47.92250469171407,-0.3126899066654906,-1.89859302959151
425.00000000000534,48.03013985208709,-0.3153849612700036,-1.911205845446791
426.1000000000053,48.136368021498924,-0.3161040218622974,-1.9234401082753956
427.20000000000533,48.244732838844925,-0.31809369933642717,-1.9370727370729037
428.30000000000535,48.34858489403546,-0.31814443096204076,-1.950395060397101
429.4000000000054,48.458382483012485,-0.32166956029297666,-1.9662071606689233
430.5000000000054,48.56579844916485,-0.3237526859659062,-1.9799429458187334
431.6000000000054,48.672724329434224,-0.3246171980042481,-1.9928015543850819
432.70000000000545,48.78055200039386,-0.3261225303856208,-2.005748686659978
433.8000000000054,48.888151280327385,-0.329102447048179,-2.0173751355294653
434.90000000000543,48.996643281420376,-0.33144608168464346,-2.029033819889959
436.00000000000546,49.10360070266288,-0.3339424030443626,-2.041297776493564
437.1000000000055,49.208859474151154,-0.3368631082155017,-2.051489225177928
438.2000000000055,49.317391208684064,-0.34069504942578,-2.0637735836806357
439.3000000000055,49.426205647633516,-0.3442491062096208,-2.075529880737941
440.40000000000555,49.53296734943513,-0.3478613005873831,-2.0867023633056405
441.50000000000557,49.64101430516364,-0.35150144825930413,-2.098212010786737
442.6000000000056,49.74802988866272,-0.3539977387758022,-2.1079565306526273
443.70000000000556,49.85525406800529,-0.35889365900177167,-2.1174870790054054
444.8000000000056,49.96246080101675,-0.3633369783088188,-2.1262212275014374
445.9000000000056,50.07023804684309,-0.3668423253568775,-2.134207319076019
447.0000000000056,50.17757317161016,-0.36919937407880843,-2.144797418682211
448.10000000000565,50.285147048273735,-0.37122919504365276,-2.1551693794956037
449.2000000000057,50.392590361767034,-0.37487691167187276,-2.165360869278344
450.3000000000057,50.49988242319638,-0.37829852426055754,-2.1726817571851464
451.40000000000566,50.607292029250154,-0.3814376485595444,-2.1793506889226926
452.5000000000057,50.71480154684422,-0.3850173254525327,-2.1879430654156526
453.6000000000057,50.82312896978935,-0.38854651880852276,-2.1954145040031445
454.70000000000573,50.92997735455774,-0.39210525386960654,-2.20028499411532
455.80000000000575,51.03804140109784,-0.3945110967032919,-2.206684304083002
456.9000000000058,51.14539241026808,-0.39708842011628187,-2.2132301706814004
458.0000000000058,51.25387753400762,-0.4003497031948143,-2.220582984541167
459.1000000000058,51.35880448236332,-0.4041760824006939,-2.223631908153007
460.20000000000584,51.46834002648767,-0.40618428699971304,-2.231371316347629
461.3000000000058,51.57649295417399,-0.4095551206198922,-2.2372226751297437
462.40000000000583,51.68439966376882,-0.4121618323456989,-2.242996900201544
463.50000000000585,51.790357086140084,-0.4152896622592558,-2.248603976369736
464.6000000000059,51.90003009379905,-0.41777206832557273,-2.2527356584389775
465.7000000000059,52.00878572784583,-0.4206320495640532,-2.255696997457145
466.8000000000059,52.11562457079174,-0.42251716310315185,-2.259920458093651
467.90000000000595,52.22393972539638,-0.42370424186952044,-2.26414766808488
469.0000000000059,52.332168076013176,-0.426796402488714,-2.268551523016996
470.10000000000593,52.44052620339525,-0.4284643084475107,-2.271537042442713
471.20000000000596,52.54676149932041,-0.43135454651241795,-2.276291958932386
472.300000000006,52.65566221116193,-0.4333452611346922,-2.2789893693797554
473.400000000006,52.763625378105225,-0.4327369465586931,-2.2792197254573643
474.500000000006,52.87243659367229,-0.43487899558239446,-2.283965044575301
475.60000000000605,52.97986923871036,-0.43601624282120016,-2.2869525802911004
476.70000000000607,53.08840788031433,-0.4386769567789221,-2.289960434371164
477.8000000000061,53.19647721717686,-0.4395391153563025,-2.2912899314765385
478.90000000000606,53.30435549500717,-0.44494801870414746,-2.292985631728332
480.0000000000061,53.411845018703204,-0.4452487349525477,-2.295804267712647
481.1000000000061,53.52040129526378,-0.44612041500638966,-2.2983149750046885
482.2000000000061,53.62860575540442,-0.4473378117641533,-2.298592663417689
483.30000000000615,53.735037336934774,-0.4487073570551059,-2.3005883175323856
484.4000000000062,53.8429692423554,-0.448924504532942,-2.301267978399916
485.5000000000062,53.95329276900712,-0.45150770928154055,-2.3019251339299798
486.60000000000616,54.05926198735461,-0.45069244797204705,-2.3050751671006084
487.7000000000062,54.16958012077043,-0.45218402585325856,-2.30545446754941
488.8000000000062,54.27790392589007,-0.4542793464726534,-2.306545557925053
489.90000000000623,54.38620240953956,-0.45440860284992435,-2.307539456038901
491.00000000000625,54.493129112387926,-0.4560168174495365,-2.3088846937467498
492.1000000000063,54.60189789122034,-0.4571806734066522,-2.3111431208944495
493.2000000000063,54.7089676732386,-0.45662036418885094,-2.310159964149414
494.3000000000063,54.81732938136098,-0.45817127492110116,-2.311471825077974
495.40000000000634,54.926161547051265,-0.4577209642015405,-2.31280003568415
496.5000000000063,55.034339548459734,-0.45786335404027223,-2.312894869215085
497.60000000000633,55.143528070993625,-0.4580927030189923,-2.31411975325225
498.70000000000636,55.25062817804946,-0.4584571460848627,-2.316750093989568
499.8000000000064,55.358568848940415,-0.45915638337441667,-2.3167492879611027
500.9000000000064,55.466215590960694,-0.46046752699669896,-2.3167507175480724
502.0000000000064,55.574937786813074,-0.46108158081166845,-2.3167774919861372
503.10000000000645,55.68231425707839,-0.46144650543069204,-2.3160651550343476
504.2000000000064,55.79108977227745,-0.4617451245703887,-2.3167507137139447
505.30000000000643,55.89994251926881,-0.4535898745954911,-2.317440790233529
506.40000000000646,56.00648738813766,-0.44586117058387037,-2.3180698541090394
507.5000000000065,56.11523927984836,-0.44206573555794165,-2.3180694343160604
508.6000000000065,56.2241240342118,-0.4390502234865366,-2.319380055815661
509.7000000000065,56.33158342326785,-0.4380739750815985,-2.319347735291851
510.80000000000655,56.44193589640073,-0.43824141622700336,-2.3206984303280507
511.90000000000657,56.54906102738234,-0.43770860181770466,-2.322680111699755
513.0000000000066,56.657735982331104,-0.4363527823685418,-2.322680107002302
514.1000000000065,56.76630629335888,-0.4379580807458343,-2.322672761076033
515.2000000000066,56.87391402613436,-0.4403210062273515,-2.32267994522892
516.3000000000065,56.98244276934698,-0.4397787761790285,-2.3239623102139353
517.4000000000067,57.08925945934231,-0.4425228187324194,-2.323990365054003
518.5000000000066,57.200259284711564,-0.44500331704136886,-2.3253099066800487
519.6000000000067,57.30935848563186,-0.449413614948067,-2.3253093574563444
520.7000000000066,57.41535534852859,-0.452544656871155,-2.323999739640322
521.8000000000067,57.527686067291405,-0.4557157428159584,-2.325310691711027
522.9000000000067,57.63559794816752,-0.46048130179068636,-2.327948365051031
524.0000000000067,57.744527077499,-0.462291261210219,-2.326585801423322
525.1000000000067,57.852771085851444,-0.467021372585227,-2.3278976402363436
526.2000000000068,57.96164560511891,-0.47063282051613464,-2.326639963480903
527.3000000000068,58.07072896362135,-0.47437806515258707,-2.326639955965125
528.4000000000068,58.17799424217477,-0.47816788919264774,-2.327946971977481
529.5000000000068,58.28669642149857,-0.4809853267387516,-2.327950116002704
530.6000000000068,58.39769778288859,-0.4829651459810651,-2.3279501031539827
531.7000000000069,58.5058044003346,-0.48425571620827923,-2.3292731909932303
532.8000000000068,58.61624054846106,-0.4871930530637961,-2.330260756451195
533.9000000000069,58.723693142467155,-0.487569620105212,-2.3302600940612397
535.0000000000068,58.833209289234325,-0.4875749836142428,-2.328941168580572
536.100000000007,58.94258121279316,-0.4883562693199601,-2.329270952225964
537.2000000000069,59.051086816024736,-0.4896418592966384,-2.3305797581010856
538.300000000007,59.16035461889727,-0.48987099505741055,-2.331899926921145
539.4000000000069,59.269168077012445,-0.4911300308265992,-2.333880161630552
540.5000000000069,59.378350992358946,-0.4913855759905339,-2.333892552875297
541.600000000007,59.486614195566595,-0.49126687457604,-2.3325875486122536
542.700000000007,59.596257173899005,-0.4924124264570399,-2.3338966413324727
543.800000000007,59.704530906584345,-0.4931847614692199,-2.3352680979867673
544.900000000007,59.81382193696357,-0.4942667920740444,-2.3355280902116062
546.000000000007,59.92239534950365,-0.496752345329003,-2.3345459613993325
547.1000000000071,60.03142282650374,-0.49727576744592017,-2.333220198643929
548.2000000000071,60.14046617278463,-0.498503678955267,-2.3332786424326715
549.300000000007,60.24907254566243,-0.4998194492019892,-2.334529949849917
550.4000000000071,60.3580753954158,-0.49808260745972516,-2.3355415946334386
551.500000000007,60.46490748279535,-0.49865870531215967,-2.3368401218114743
552.6000000000072,60.57534259987163,-0.49877925303505677,-2.336952607526552
553.7000000000071,60.68419499082376,-0.4997513439954888,-2.336843004455367
554.8000000000072,60.79402233796793,-0.5006355066815097,-2.3369002713162192
555.9000000000071,60.90319219744446,-0.5012124152987019,-2.3381619476924502
557.0000000000072,61.0106594846471,-0.503805142262226,-2.337820496675702
558.1000000000072,61.12189042388349,-0.5051317697863448,-2.338159821330092
559.2000000000072,61.23090365027476,-0.5060291084520895,-2.3394725223316213
560.3000000000072,61.33986350691945,-0.5087168250912185,-2.338159962301639
561.4000000000073,61.449732066361584,-0.5099458898448094,-2.339460721499754
562.5000000000073,61.55897617900674,-0.5116695277457799,-2.3391498031430653
563.6000000000073,61.66800524003981,-0.5115225085399431,-2.3391500529246625
564.7000000000073,61.77633720067237,-0.512315868970439,-2.3394794834504475
565.8000000000073,61.88624604515681,-0.5149485600731993,-2.34080367074605
566.9000000000074,61.99618910944646,-0.5143392435280096,-2.339479983364546
568.0000000000074,62.1049075302072,-0.5142161512266632,-2.3421183602912854
569.1000000000074,62.21444074835099,-0.5153174219100393,-2.34342918305218
570.2000000000073,62.3241311627861,-0.5153631926690758,-2.3421111415558107
571.3000000000073,62.43283892097036,-0.5180725048427827,-2.3428450210789276
572.4000000000074,62.5425713854376,-0.5182442644308675,-2.3434298371894897
573.5000000000074,62.65162870616799,-0.5170524085646124,-2.34343031389946
574.6000000000074,62.76117393980621,-0.5199303948652145,-2.344741859514073
575.7000000000074,62.87043710283073,-0.5187202539107582,-2.343760066323932
576.8000000000075,62.97840571884153,-0.5213723479825206,-2.344689181389512
577.9000000000075,63.089269039191635,-0.5241475964349775,-2.3447220117584493
579.0000000000075,63.19806433258415,-0.5253823402795965,-2.3459997359277422
580.1000000000075,63.30746304375296,-0.5243076224350457,-2.346060047147862
581.2000000000075,63.41645277201687,-0.5252669191205445,-2.347372413573839
582.3000000000076,63.52676556533387,-0.5253596298157818,-2.347379869339643
583.4000000000076,63.63562443030918,-0.5241622216294466,-2.348683572982336
584.5000000000076,63.74479408079111,-0.5219916264226833,-2.348544294256775
585.6000000000076,63.85467590762521,-0.5224088498083195,-2.348699908265033
586.7000000000077,63.963708256720025,-0.5226505449055088,-2.349969050642261
587.8000000000077,64.07191609851935,-0.5194385643329402,-2.3499852360265914
588.9000000000076,64.1827764715503,-0.5182910036184118,-2.3520077894310925
590.0000000000076,64.2921184619217,-0.5164136542991589,-2.3513302299546552
591.1000000000076,64.40098359645812,-0.5119214397951266,-2.351352378992621
592.2000000000077,64.51116673479864,-0.5090179681209868,-2.3523200697193243
593.3000000000077,64.61897760955628,-0.5054183276754391,-2.352646134594254
594.4000000000077,64.72840504943642,-0.5011217758297966,-2.3539703679420336
595.5000000000077,64.8366762024015,-0.4975410763219758,-2.354950095303214
596.6000000000078,64.94689611664415,-0.49344134918695637,-2.353972166298388
597.7000000000078,65.05660818305383,-0.49098469075435125,-2.354753493255208
598.8000000000078,65.16524339554589,-0.48643232819252424,-2.3556193895081767
599.9000000000078,65.27521957547172,-0.4811017223696597,-2.356940192020936
601.0000000000078,65.38467799370076,-0.47633951306947037,-2.3582484779993407
602.1000000000079,65.49291507682958,-0.47168218173242593,-2.357919362992753
603.2000000000079,65.60386290217218,-0.4687203018317635,-2.3592518759980114
604.3000000000079,65.71221200467674,-0.4648254070843742,-2.359239596885216
605.4000000000078,65.82259106335157,-0.46090096504101163,-2.3618833927018392
606.5000000000078,65.93152637651914,-0.4576571522337468,-2.3623232165735057
607.6000000000079,66.04134686686683,-0.45442641871527073,-2.361867834851753
608.7000000000079,66.15028156813652,-0.4492070807592554,-2.3631901661410177
609.8000000000079,66.25999580025888,-0.4469812089582646,-2.3641795377750774
610.9000000000079,66.37008382709689,-0.443335162193609,-2.3645088818226965
612.000000000008,66.47908257310218,-0.44064458471019985,-2.3658134957198094
613.100000000008,66.58936981557392,-0.43803202849590817,-2.368460194138337
614.200000000008,66.69746375877422,-0.43301368107877686,-2.368214252572421
615.300000000008,66.80861471195419,-0.4298114378076779,-2.3687459771346955
616.400000000008,66.9191679916773,-0.42723007726916384,-2.3697798477221834
617.5000000000081,67.0289729061378,-0.42483203576425477,-2.3710797239036845
618.6000000000081,67.13846948352206,-0.4205304583526274,-2.3727458169019884
619.7000000000081,67.24772976047774,-0.41734676509334806,-2.37405397566254
620.8000000000081,67.35839117474308,-0.4119314810206499,-2.375367872474988
621.9000000000082,67.4676032325983,-0.4068737028590912,-2.37540514198207
623.0000000000082,67.57714457370022,-0.40472924649613146,-2.3766575131610086
624.1000000000081,67.68740822214292,-0.40032736273701175,-2.380664689723825
625.2000000000081,67.7980871953366,-0.39544988531024305,-2.380651029296561
626.3000000000081,67.90677868658567,-0.3902210261766904,-2.3826216214292657
627.4000000000082,68.01641437690797,-0.3843055591149135,-2.3839352220505905
628.5000000000082,68.12720257208979,-0.37725459511356657,-2.383958594472997
629.6000000000082,68.23477601350687,-0.3722853953073197,-2.3855541665258526
630.7000000000082,68.34595173191707,-0.36721219742153105,-2.387906012006072
631.8000000000083,68.45494343583763,-0.3599982749726382,-2.3891970063767287
632.9000000000083,68.56481085131225,-0.35095931863535024,-2.3918862466284665
634.0000000000083,68.67476053678772,-0.3434614122395446,-2.3935763116576103
635.1000000000083,68.7848132805889,-0.33585636852677136,-2.3959096430004037
636.2000000000083,68.89262171881364,-0.329357674231764,-2.3958908730088275
637.3000000000084,69.00401606891032,-0.32019908040107264,-2.3985384918195063
638.4000000000084,69.11271051142225,-0.31117022108197095,-2.401174728310348
639.5000000000084,69.2225130764587,-0.30141123191973146,-2.403485060651806
640.6000000000083,69.33218226973315,-0.2935057204828591,-2.4064219165930103
641.7000000000083,69.44168130682216,-0.2847512985334925,-2.4077576119509176
642.8000000000084,69.55215861637227,-0.27565157433023435,-2.41053171302259
643.9000000000084,69.66130651886087,-0.26948998572741173,-2.412058608364191
645.0000000000084,69.7712957588712,-0.25914847439109423,-2.413385679966411
646.1000000000084,69.88084781548689,-0.25413830345022353,-2.4159718365973752
647.2000000000085,69.99028349989075,-0.2461987127565898,-2.418671833973023
648.3000000000085,70.10038531154049,-0.23903093401870382,-2.4212632500864157
649.4000000000085,70.21062809261296,-0.23564108511445428,-2.423890808922464
650.5000000000085,70.3198389860093,-0.2323434293330484,-2.42691618855045
651.6000000000085,70.42896025437288,-0.22989321298806684,-2.4301364380571417
652.7000000000086,70.53879676184188,-0.23175198307849737,-2.433343482297035
653.8000000000086,70.64835929712703,-0.23384742823966453,-2.4359719143606156
654.9000000000086,70.75866180747731,-0.23687594802238623,-2.4378379175369527
656.0000000000086,70.86801375604463,-0.2431818706006841,-2.441269622924454
657.1000000000087,70.97857549935458,-0.25053677172497846,-2.443493372759667
658.2000000000087,71.08789231932322,-0.2577731487560036,-2.4470856410050867
659.3000000000086,71.19780675780228,-0.2642752508405414,-2.4481619841241318
660.4000000000086,71.30698142848861,-0.2657964514262269,-2.4507984876319986
661.5000000000086,71.41660491011453,-0.2571826447685171,-2.4533494671441645
662.6000000000087,71.5270444124526,-0.24490314477927935,-2.4564519371660705
663.7000000000087,71.63684502077423,-0.23002005322126434,-2.4586148032516877
664.8000000000087,71.74740865807209,-0.21426733200793666,-2.461448574313901
665.9000000000087,71.85661820145162,-0.20115041226239228,-2.4649393451239767
667.0000000000088,71.96723969161927,-0.18933594019747252,-2.4681685233013644
668.1000000000088,72.07707995235423,-0.18399738133065693,-2.470792041148418
669.2000000000088,72.18546671516503,-0.1844752797497887,-2.473988544385829
670.3000000000088,72.29712423713437,-0.19039206046930177,-2.4765851870195372
671.4000000000088,72.40577323844546,-0.2035571306254976,-2.4779245599787503
672.5000000000089,72.51492858500922,-0.22022865260748506,-2.480817276708967
673.6000000000089,72.6244485294805,-0.24544004888111698,-2.484137427441203
674.7000000000089,72.73644371990964,-0.28191687460870324,-2.4876087048183244
675.8000000000088,72.84613238436492,-0.3146204775140379,-2.491193191245667
676.9000000000088,72.95575437186862,-0.3539460798522153,-2.4938446909500778
678.0000000000089,73.06612466559942,-0.3918162630089335,-2.4950059142335084
679.1000000000089,73.17588542314074,-0.4280215536255962,-2.495150173017294
680.2000000000089,73.28557544612595,-0.4604637175810997,-2.4978103564213736
681.3000000000089,73.39555990680752,-0.48888157836492135,-2.5005711776966857
682.400000000009,73.50476187436709,-0.5124728149246606,-2.500498759066444
683.500000000009,73.61522250617843,-0.5316049507760754,-2.5031135978660544
684.600000000009,73.72660210554942,-0.5476940637405252,-2.501849958209348
685.700000000009,73.83683585045179,-0.5594922876687343,-2.502680369970816
686.800000000009,73.94705554228058,-0.5683123957875326,-2.501839930288521
687.9000000000091,74.0568558970684,-0.5746192328483967,-2.503200498588403
689.0000000000091,74.16725171841,-0.5821861789812256,-2.5031604270673102
690.1000000000091,74.27828263824414,-0.5862204058561253,-2.504479968330229
691.2000000000091,74.38774993310753,-0.5888345273666041,-2.504479346795915
692.3000000000092,74.49751182750833,-0.5942972748265853,-2.5031779625412818
693.4000000000092,74.60883499481442,-0.5973899537347658,-2.5031609907869075
694.5000000000091,74.71848648596833,-0.6007921061902918,-2.5031601370138707
695.6000000000091,74.82937175766128,-0.6040544089115872,-2.503125898291686
696.7000000000091,74.93916896980915,-0.6044799628342457,-2.505788307815796
697.8000000000092,75.05024850550475,-0.6060778074760783,-2.5044799627061636
698.9000000000092,75.15916805650825,-0.6095400036450604,-2.505469967013406
700.0000000000092,75.26988624571881,-0.6119979712399634,-2.506458611608464
701.1000000000092,75.3797903497872,-0.6146561149289235,-2.508129283142147
702.2000000000093,75.49081655752946,-0.6160024928865384,-2.508100421856777
703.3000000000093,75.60110515234163,-0.6188353764319807,-2.5071136662178675
704.4000000000093,75.71065564477968,-0.6205852601055255,-2.507766602125053
705.5000000000093,75.82099446078975,-0.623162190826695,-2.508429993613304
706.6000000000093,75.93146845901134,-0.6237818549937051,-2.5098368819539663
707.7000000000094,76.04263492220541,-0.6273832998063691,-2.5078856355387433
708.8000000000094,76.15279604840478,-0.6282678672059914,-2.5090897320728844
709.9000000000094,76.26326646246686,-0.6293108911508157,-2.508429931587561
711.0000000000093,76.3717296466608,-0.6306972735244372,-2.509750038177196
712.1000000000093,76.48401603166339,-0.632511312075088,-2.5105743986021007
713.2000000000094,76.59292009367279,-0.632478388880314,-2.5110601847838643
714.3000000000094,76.70378914468488,-0.6361225125146491,-2.510081249699239
715.4000000000094,76.81387933911049,-0.6372103900223898,-2.510171262818157
716.5000000000094,76.92188791455649,-0.6397967990424863,-2.511103385297277
717.6000000000095,77.03424651695757,-0.639672291025803,-2.512375059219004
718.7000000000095,77.14455430256024,-0.6418063012084824,-2.5110698493758523
719.8000000000095,77.25403219290469,-0.6416283161171582,-2.5110696665255836
720.9000000000095,77.36463873657628,-0.643784100924556,-2.512390105627055
722.0000000000095,77.4751334042111,-0.6446509157377462,-2.5123901852353656
723.1000000000096,77.5846544190697,-0.6456940727964374,-2.5135436738184715
724.2000000000096,77.69466319405552,-0.6477003419624145,-2.5123678884739773
725.3000000000096,77.80542616137461,-0.6482660607923029,-2.5123801427531576
726.4000000000096,77.91596763590141,-0.6509189710354456,-2.513745856531504
727.5000000000097,78.02546455750456,-0.6520002323298261,-2.5150199070285337
728.6000000000097,78.1357360378116,-0.650773424217667,-2.514447438675007
729.7000000000096,78.24568796308934,-0.651433439612463,-2.514062842816342
730.8000000000096,78.3563922686451,-0.6517235616917475,-2.5156067842932233
731.9000000000096,78.46721477254724,-0.6519078267800272,-2.516329849946831
733.0000000000097,78.57831136449175,-0.6533802665468,-2.5150205922183053
734.1000000000097,78.68879717417262,-0.6539888801821624,-2.5163400874039628
735.2000000000097,78.7993500783876,-0.6525542559461214,-2.516336475497596
736.3000000000097,78.90804888407366,-0.6561096229892188,-2.518319554196014
737.4000000000098,79.01963196748457,-0.6563399886593828,-2.5183199090104926
738.5000000000098,79.13097999620884,-0.6569972332910154,-2.5183530799907263
739.6000000000098,79.24098911810565,-0.6574987248910131,-2.5184517955660284
740.7000000000098,79.35192443493862,-0.6571899118284436,-2.519629827585336
741.8000000000098,79.46162561314979,-0.6575754983244654,-2.5183099975216385
742.9000000000099,79.57279264689363,-0.6598108444483461,-2.519629947287655
744.0000000000099,79.68313555670906,-0.6585944915869058,-2.5196297982832885
745.1000000000099,79.79305611478414,-0.6595276701881566,-2.5209499744696586
746.2000000000098,79.90308963797372,-0.6595627134585842,-2.5209499459823888
747.0000000000099,79.9831576316528,-0.657834217354802,-2.5200066607903615