File: 01_Data/Concrete_Block/STA/N2/10K_min/Concrete_Block_STA_N2_10KData_230919_R1.csv
##Temp./Â°C,Time/min,DSC/(mW/mg),Mass loss/mg
41.0,10.837249437322841,-2.315944341121745,-0.00035963613499845337
42.40000000000002,11.181069686420049,-2.253835330577693,-0.0006733793793198828
43.80000000000004,11.423875577604031,-2.2116295812754316,-0.0007302018807990862
45.20000000000006,11.629392638342608,-2.179524675151567,-0.0008156344759235878
46.60000000000008,11.81592005390466,-2.1540814184016464,-0.002571760358473618
48.0000000000001,11.989638769470202,-2.1336022225877613,-0.0036482810761127027
49.40000000000012,12.154831379971416,-2.117613815075225,-0.0008791870302777838
50.80000000000014,12.319212235911653,-2.102521648390063,-0.003862496337125876
52.20000000000016,12.47695143021756,-2.0923924739216795,-0.0024447389981778755
53.60000000000018,12.63351088873972,-2.08135276561797,-0.0020854921566737517
55.0000000000002,12.788911040218066,-2.07292903797538,-0.00320267784484507
56.40000000000022,12.940213721288211,-2.0638858853442916,-0.002428362652889149
57.80000000000024,13.092173276830948,-2.0559256632017844,-0.002357615792986323
59.20000000000026,13.243119832208047,-2.0490971279226695,-0.00503396376457399
60.60000000000028,13.392176879630787,-2.042410797085398,-0.004881379212063663
62.0000000000003,13.540000000000028,-2.0351000000000043,-0.003730003667209658
63.40000000000032,13.688794327922949,-2.0281855661927684,-0.002451426315830396
64.80000000000034,13.835688690236461,-2.0245906281959454,-0.0034140357482712602
66.20000000000036,13.980107587687948,-2.0151553027613804,-0.0024022147032676244
67.60000000000038,14.126535677731793,-2.009495645759147,-0.0050564841769178415
69.0000000000004,14.27010640044918,-2.0033964815853036,-0.005036148840323662
70.40000000000042,14.413656902523604,-1.9965914598946677,-0.005040487770635593
71.80000000000044,14.558299020593315,-1.9880508114704711,-0.005039216949836778
73.20000000000046,14.698990043165825,-1.983042361285128,-0.0050781712008030055
74.60000000000048,14.841642804147353,-1.9763309404718357,-0.006357137854786643
76.0000000000005,14.98413653572689,-1.9700468205216835,-0.008339863399116965
77.40000000000052,15.124956411886833,-1.9658623889797286,-0.007679755630263685
78.80000000000054,15.264095125189558,-1.9581807166263212,-0.004111895673192478
80.20000000000056,15.404156462996616,-1.952208462484918,-0.008645944324133126
81.60000000000058,15.546408987410079,-1.9457426097285366,-0.005964745029492846
83.0000000000006,15.685015041146352,-1.9398473757385537,-0.007302878346422403
84.40000000000062,15.825621929719752,-1.9320182137651623,-0.007349489010777255
85.80000000000064,15.964462828995227,-1.9258504702597707,-0.008671215978983682
87.20000000000066,16.103129495274285,-1.9192027754340664,-0.009980349814076028
88.60000000000068,16.240985866766803,-1.9140421518593618,-0.011300178798893334
90.0000000000007,16.380000000000095,-1.9049200000000002,-0.010508747820147768
91.40000000000072,16.51679613181222,-1.9006112757057652,-0.011312592387255016
92.80000000000074,16.651203912800405,-1.894128454370828,-0.009979831945888584
94.20000000000076,16.79239337575499,-1.8888764637171063,-0.008669738503462199
95.60000000000078,16.930413413372943,-1.8837971256679047,-0.008971887811550339
97.0000000000008,17.066560260387558,-1.8768668289365333,-0.010636181183961035
98.40000000000082,17.203870590068203,-1.8711258451710717,-0.011959914718688403
99.80000000000084,17.34000000000008,-1.8646499999999995,-0.01163009686996297
101.20000000000086,17.476243187781158,-1.8590947044995767,-0.011282196640607367
102.60000000000088,17.61256995919499,-1.854061936990064,-0.010311430182012415
104.0000000000009,17.747756272502727,-1.8493062651568037,-0.01132157124043065
105.40000000000092,17.8855597251508,-1.8430659109712464,-0.011650436005147036
106.80000000000094,18.02305132200852,-1.836297358852984,-0.014259936894877256
108.20000000000095,18.156363797844456,-1.8310561523656452,-0.012940948617806036
109.60000000000097,18.29168782466246,-1.8251803652098288,-0.012950147360885289
111.000000000001,18.42637837505464,-1.8187346154620383,-0.014005430901618432
112.40000000000101,18.562123950930804,-1.8121026544773624,-0.015579952194421764
113.80000000000103,18.697789360205444,-1.8063006238927457,-0.014257285668914932
115.20000000000105,18.833244079991296,-1.7991487402787567,-0.01412267032131087
116.60000000000107,18.968558523391746,-1.7940864117535416,-0.01492563951064696
118.0000000000011,19.10204885366424,-1.78591848056459,-0.015579833985332137
119.40000000000111,19.237141835028762,-1.7819536671082699,-0.015579750323977848
120.80000000000113,19.371775775852193,-1.7736091089334336,-0.015590264603130954
122.20000000000115,19.506359687073253,-1.7683393219304615,-0.015980539685060968
123.60000000000117,19.64194350950571,-1.7635716932484773,-0.016900057204435548
125.0000000000012,19.776337263821638,-1.7568143706419794,-0.01557885684721061
126.40000000000121,19.910631060301185,-1.753163159627717,-0.01690017568025226
127.80000000000123,20.045534252926675,-1.7471000233177465,-0.01690017599913496
129.20000000000124,20.180299821802507,-1.7412221937097252,-0.01690927974138212
130.60000000000127,20.315175563511165,-1.7369555415565296,-0.01756004001670064
132.0000000000013,20.44855281174383,-1.7321313127026683,-0.017544610240371128
133.4000000000013,20.580637293287644,-1.7273641028777644,-0.016897545969401406
134.80000000000132,20.71641591465938,-1.7241901868671528,-0.015898239539844816
136.20000000000135,20.850717533250666,-1.7201854836793813,-0.016900037078011465
137.6000000000014,20.985524139182225,-1.714389333061661,-0.018213417454117753
139.0000000000014,21.11936804965739,-1.7088863367357932,-0.01821003600001614
140.4000000000014,21.254894056863773,-1.7046519194051233,-0.018219556094797085
141.80000000000143,21.387760968757892,-1.6997469569749688,-0.017885333361554068
143.20000000000147,21.52209978755368,-1.6954906138381451,-0.01722884703897254
144.60000000000147,21.656565902958256,-1.6916533058462953,-0.01758829858394151
146.00000000000148,21.790687963225952,-1.6889798740906679,-0.01855013554914553
147.4000000000015,21.923756759643453,-1.6840861351174812,-0.017897302538632864
148.80000000000155,22.058670884336497,-1.680660056714458,-0.0195399324440233
150.20000000000155,22.192521793096557,-1.6759423848712482,-0.018375691259977955
151.60000000000156,22.325294957959088,-1.6698447312537081,-0.018223010881641244
153.0000000000016,22.45961749506929,-1.665531633178247,-0.017855772208873688
154.40000000000163,22.59200615493368,-1.6610322336455534,-0.017880513427268596
155.80000000000163,22.726276340726944,-1.6565984063707844,-0.018539924745127223
157.20000000000164,22.860566036000677,-1.6518440800161813,-0.018210074017053657
158.60000000000167,22.992989700606806,-1.6474504151488125,-0.018209602212246878
160.0000000000017,23.1262118734903,-1.6430965082787365,-0.018742006102912434
161.4000000000017,23.260453441921427,-1.6391969571382472,-0.020849855323928246
162.80000000000172,23.39260067422836,-1.634075882326751,-0.019540324050743685
164.20000000000175,23.524852391084018,-1.6311300975799676,-0.018509856819638237
165.60000000000178,23.658717191591347,-1.6255848496940524,-0.020402025896084197
167.0000000000018,23.790937112556833,-1.6242564101264436,-0.02052619313983417
168.4000000000018,23.9234294589784,-1.6193140699266289,-0.020514578002522654
169.80000000000183,24.056588048713905,-1.6168131340330703,-0.020629353710261533
171.20000000000186,24.189324088245442,-1.612010872012923,-0.01930994194720892
172.60000000000187,24.322254932669694,-1.6099379561805478,-0.020629694820939903
174.00000000000188,24.45333902748749,-1.604948385644359,-0.020629824569490474
175.4000000000019,24.589191901208842,-1.6020962913240606,-0.0202997390987667
176.80000000000194,24.72229508125629,-1.5978217165832906,-0.02031971555092671
178.20000000000195,24.85477323461286,-1.5952598790413512,-0.020957220661860454
179.60000000000196,24.987988198137213,-1.5919192211795337,-0.021280276968830947
181.000000000002,25.120990588288954,-1.5892812092416164,-0.021328707313264417
182.40000000000202,25.253364944670455,-1.58725664523042,-0.020529738280822052
183.80000000000203,25.386653266696484,-1.5850857432704806,-0.021840753352218023
185.20000000000203,25.520000000000195,-1.5837000000000063,-0.02314991145375256
186.60000000000207,25.654245726355477,-1.5792630657073945,-0.021919160112267022
188.0000000000021,25.78534417638737,-1.5777477378963363,-0.02249971222228364
189.4000000000021,25.92112017404014,-1.575711913773904,-0.02182923505962897
190.80000000000211,26.056312678605256,-1.5744217916176735,-0.022952714552993747
192.20000000000215,26.18958982576567,-1.572194088516794,-0.021509963638341567
193.60000000000218,26.322796328068385,-1.5706893280754084,-0.021567084106086654
195.0000000000022,26.45747089578009,-1.5671838384771746,-0.02415034282376194
196.4000000000022,26.59139368939388,-1.5639348996210882,-0.02468109831010068
197.80000000000223,26.725742174268802,-1.562553074795885,-0.022840850841931548
199.20000000000226,26.857861633328426,-1.559233605327467,-0.024151818619468024
200.60000000000227,26.99302392385546,-1.5566798245891986,-0.024149569968105133
202.00000000000227,27.126013678272404,-1.5547679623220403,-0.022853335902233596
203.4000000000023,27.25874539395577,-1.5529650020572519,-0.022830321248821228
204.80000000000234,27.39173524694755,-1.549756671161423,-0.023492094372074668
206.20000000000235,27.526899531846233,-1.5462887701092662,-0.023479827061533065
207.60000000000235,27.65850740026504,-1.544138732352566,-0.023479890845787388
209.0000000000024,27.791403565715502,-1.542414326030097,-0.02216001181424776
210.40000000000242,27.924189815282272,-1.539191778143284,-0.024454906457060943
211.80000000000243,28.055917303682744,-1.5362013168171176,-0.024469880000085098
213.20000000000243,28.190000000000232,-1.536269999999997,-0.024469879999999833
214.60000000000247,28.32341224480062,-1.5345025071790475,-0.024477889828481203
216.0000000000025,28.45674993965364,-1.5318023219929884,-0.023505788412093054
217.4000000000025,28.58990848454568,-1.5303270852321351,-0.026166952796320864
218.8000000000025,28.721688009351926,-1.5297078935387742,-0.024795497190751803
220.20000000000255,28.855214283175528,-1.5281933169438415,-0.024792894614407146
221.60000000000258,28.990598352598205,-1.5270310968725496,-0.024798157773632035
223.0000000000026,29.122432700734432,-1.5237987408414326,-0.026163418472291866
224.4000000000026,29.25582624800605,-1.5220499925069997,-0.02578982865379409
225.80000000000263,29.3892607034644,-1.5221044007648834,-0.024469710320043525
227.20000000000266,29.52276424064845,-1.5188312751657165,-0.02578984280684793
228.60000000000267,29.656455669475072,-1.517022574050769,-0.02645002102248384
230.00000000000267,29.788755392305923,-1.515651775245306,-0.025139847315076125
231.4000000000027,29.92182294909135,-1.5130437888529849,-0.025136242109269347
232.80000000000274,30.05589389363681,-1.5121592216137356,-0.024809837831721637
234.20000000000275,30.187941968308273,-1.511238639318932,-0.02611991137319869
235.60000000000275,30.320703261165654,-1.5097474029217965,-0.027429312785568705
237.00000000000279,30.454093915662273,-1.509029489398477,-0.02743001200007633
238.40000000000282,30.58793569367518,-1.5063724757291235,-0.027430003370985112
239.80000000000283,30.721104836196012,-1.5047206841596639,-0.024423105644094
241.20000000000283,30.85309262685533,-1.5039401960643937,-0.02709914149491066
242.60000000000286,30.987135654830524,-1.5023250736842328,-0.0257805325527789
244.0000000000029,31.119813711871483,-1.5009443823434625,-0.025453589681529998
245.4000000000029,31.25333233046303,-1.5001171750782254,-0.026779971060983954
246.8000000000029,31.385254048393353,-1.4993468144250504,-0.02677989664357039
248.20000000000294,31.51909889778531,-1.4972862211579991,-0.026779282247240133
249.60000000000298,31.65335919098204,-1.4954630358274041,-0.024139839111364303
251.00000000000298,31.7861782720119,-1.4942011269754103,-0.02674503504714476
252.400000000003,31.91878786828846,-1.4934698697235247,-0.02677935285624944
253.80000000000302,32.0493214225042,-1.4935680235698514,-0.02518517382601626
255.20000000000306,32.18376076540634,-1.4930909736336095,-0.02611565977187169
256.6000000000031,32.3186082342863,-1.493340692240857,-0.024801043771115694
258.00000000000307,32.45204357937575,-1.4910322223122114,-0.025789353224489275
259.4000000000031,32.58565422425793,-1.4912829788771707,-0.025789757023546578
260.80000000000314,32.72019937281946,-1.4899918948165172,-0.025129971499468162
262.2000000000031,32.85411302314398,-1.4905158559752785,-0.02512924296546526
263.60000000000315,32.98766978103015,-1.487458642047801,-0.027989510498850123
265.0000000000032,33.12009779723084,-1.4871919011622474,-0.028320020059322992
266.4000000000032,33.25425065367293,-1.4870559231678593,-0.02818959039279445
267.80000000000325,33.386754870547016,-1.4880669869836172,-0.026980925755943908
269.20000000000323,33.52026713363936,-1.4869151672848693,-0.027990653607457006
270.60000000000326,33.65409333160009,-1.485967581377765,-0.028981134421165677
272.0000000000033,33.787062703805496,-1.4865687847529712,-0.028979951999978937
273.4000000000033,33.92149137372722,-1.48495845583516,-0.02897995732976444
274.8000000000033,34.05465616539079,-1.4860529216826994,-0.02770043462517524
276.20000000000334,34.187502222510254,-1.4828235695262737,-0.026670084189386323
277.6000000000034,34.320912053803504,-1.483134422520811,-0.02535061086235224
279.0000000000034,34.45556088883839,-1.4819340135839405,-0.027561173185803867
280.4000000000034,34.58689858176906,-1.4835279985116538,-0.028319811588745303
281.8000000000034,34.722238488481686,-1.4831304889151158,-0.026956991942205022
283.20000000000346,34.85636699588136,-1.482287542646129,-0.026674131295775894
284.60000000000343,34.98981303198074,-1.4826009506392945,-0.026670152364208555
286.00000000000347,35.124504297246865,-1.4826149055869826,-0.026999768242953692
287.4000000000035,35.25842608738487,-1.482322646330042,-0.02835878296901928
288.80000000000354,35.39251876874548,-1.48212598699788,-0.029640063425080854
290.20000000000357,35.525764144861554,-1.4823915069104505,-0.02831908097783309
291.60000000000355,35.65946692798921,-1.4815773285519556,-0.029348754849852554
293.0000000000036,35.793212423038824,-1.4799512857426231,-0.026669761710521378
294.4000000000036,35.927670221172434,-1.479697681233222,-0.02798982805675365
295.8000000000036,36.06179229281442,-1.4802532011063574,-0.028019981549643802
297.2000000000036,36.19582092083523,-1.4806370443247714,-0.027329959696981376
298.60000000000366,36.329721958824514,-1.4810905911761045,-0.02834253005453835
300.0000000000037,36.46395156014749,-1.4812405970677207,-0.02863752573470979
301.40000000000373,36.597744825299316,-1.4812935662441338,-0.028305063210637194
302.8000000000037,36.732417346187624,-1.4811505378355085,-0.028319816001369347
304.20000000000374,36.8646768078639,-1.4807984103500433,-0.028319820866107293
305.6000000000038,37.00071214426611,-1.4818573914857245,-0.02939860180619025
307.00000000000375,37.13524403752341,-1.4836840817026113,-0.028320567403905095
308.4000000000038,37.27048150600301,-1.4834083759844203,-0.028650352333104756
309.8000000000038,37.40518420731048,-1.4827722776220582,-0.028641021976191006
311.20000000000385,37.539696081208334,-1.4834726241454144,-0.02831818750691273
312.6000000000039,37.674664895332214,-1.4830893218591144,-0.028320083276178742
314.00000000000387,37.80954255725397,-1.4839413651636093,-0.027000034465235245
315.4000000000039,37.943140694053916,-1.484617127509536,-0.02837124740799446
316.80000000000393,38.07846413344589,-1.4830285319443632,-0.02765460978934975
318.2000000000039,38.21209337590515,-1.4827677052590797,-0.027783604417679797
319.60000000000394,38.347375438194554,-1.4815584574123504,-0.028290206059139678
321.000000000004,38.48227098851628,-1.4835225616525685,-0.030620124055854347
322.400000000004,38.61612692436965,-1.4862343729359209,-0.029627188856991005
323.80000000000405,38.75121620101122,-1.4854941482413522,-0.029310019946803045
325.200000000004,38.883500189218594,-1.4853238880247002,-0.02931001958457813
326.60000000000406,39.02087361673108,-1.4872987444569987,-0.030299069018946412
328.0000000000041,39.15450686668268,-1.4897599322588255,-0.028590698943383508
329.40000000000407,39.289098409300976,-1.488332432304167,-0.027989815445626398
330.8000000000041,39.42490891629848,-1.488848522540315,-0.02734331389561362
332.20000000000414,39.5597947219357,-1.4894164352991124,-0.02865051337693103
333.6000000000042,39.69510529825833,-1.4891800187797293,-0.03126483096641941
335.0000000000042,39.8292463938323,-1.4906230760684855,-0.029850051330063465
336.4000000000042,39.965070392916175,-1.4941832246644033,-0.029850124129655597
337.8000000000042,40.098818731330084,-1.4923387842530589,-0.030508215098849156
339.20000000000425,40.23469155142733,-1.4938750039517774,-0.02985772892682892
340.60000000000423,40.369828078325725,-1.4951494507284178,-0.029850123999991318
342.00000000000426,40.50487131603895,-1.4959923276692402,-0.029850123999998424
343.4000000000043,40.64059838688429,-1.4971830350289297,-0.02985008565846403
344.80000000000433,40.775856550431456,-1.4964536519502747,-0.03049693303073653
346.20000000000437,40.909593364093276,-1.4971842857435917,-0.02863621681741524
347.60000000000434,41.04706847617345,-1.4979644161767258,-0.02667596721944321
349.0000000000044,41.1815065610864,-1.4971513286135203,-0.027415125506053073
350.4000000000044,41.31754798299268,-1.4977095723944782,-0.029300088866088814
351.8000000000044,41.45174370216119,-1.500819484369257,-0.030936460896891838
353.2000000000044,41.58845875203405,-1.4976674087396016,-0.030930840694043837
354.60000000000446,41.723984572383,-1.499628701768964,-0.03194012147042269
356.0000000000045,41.8598824564294,-1.5008346736035176,-0.029961846555195848
357.4000000000045,41.99518409526882,-1.5019907415913318,-0.029959893142420313
358.8000000000045,42.13189717022662,-1.5051321350848839,-0.02929986179714472
360.20000000000454,42.26706101389511,-1.5055084042499518,-0.029299855999998847
361.60000000000457,42.402561852990154,-1.5074899640376118,-0.02929985600000684
363.00000000000455,42.539156552799454,-1.5077784947537876,-0.029299689643536908
364.4000000000046,42.675022812242915,-1.5090661391995985,-0.030620127137910735
365.8000000000046,42.81075625886315,-1.508299410479614,-0.029066196893552387
367.20000000000465,42.94732585362619,-1.5085729036754651,-0.03193943739309013
368.6000000000047,43.08236308693931,-1.5097632355603368,-0.03202919191849318
370.00000000000466,43.218238218402504,-1.510765200495996,-0.027884337212518595
371.4000000000047,43.35519875462083,-1.512900377082017,-0.029284603338104453
372.80000000000473,43.490091165036624,-1.5135663826973105,-0.028199048426306383
374.2000000000047,43.62652218244672,-1.5142964670712318,-0.030949956516781008
375.60000000000474,43.76280543335183,-1.5143131294182308,-0.03094999600405579
377.0000000000048,43.89906532551648,-1.5162586744263713,-0.030366418407131057
378.4000000000048,44.03557575109056,-1.517942862689911,-0.029268433886239897
379.80000000000484,44.17082550391268,-1.5191346857017842,-0.028012789036553798
381.2000000000048,44.30772098556705,-1.5210428756458196,-0.029300058688320085
382.60000000000485,44.443644639274,-1.5215730623350365,-0.027990079497755893
384.0000000000049,44.57924824852911,-1.523622832648996,-0.02931000649316129
385.40000000000487,44.716269637562675,-1.5238323009239498,-0.030290169901544317
386.8000000000049,44.851031216676965,-1.5240397298016193,-0.031609847345734465
388.20000000000493,44.988521695708464,-1.525663280624796,-0.029345418790772904
389.60000000000497,45.12493926325536,-1.5256402914992522,-0.028001621430260748
391.000000000005,45.26120074783073,-1.529564160803722,-0.02957073954377254
392.400000000005,45.39778976087869,-1.5315319519322705,-0.028979859981400402
393.800000000005,45.53543687248119,-1.5337423014644018,-0.027652704332284728
395.20000000000505,45.67122346112397,-1.53588744241825,-0.027659860028205863
396.600000000005,45.80793059053672,-1.5391256338391985,-0.02644874858615598
398.00000000000506,45.94478165747674,-1.5383368455483593,-0.0263516381083031
399.4000000000051,46.081029669511956,-1.5416707343206257,-0.028650591264773873
400.8000000000051,46.217667190895185,-1.5448910659006934,-0.028643776765910012
402.20000000000516,46.354423165120494,-1.547755304416482,-0.028649861128513088
403.60000000000514,46.49324089049571,-1.5507482028123645,-0.030001432714320764
405.0000000000052,46.63043152178399,-1.5566121258821395,-0.027659265489431206
406.4000000000052,46.768166614062636,-1.562769435642969,-0.028588285152316928
407.8000000000052,46.905239637579704,-1.566046450549426,-0.02909015623662281
409.2000000000052,47.04188495953452,-1.571278973656525,-0.028101505277793315
410.60000000000525,47.18039892403655,-1.573778198928372,-0.029079951768379075
412.0000000000053,47.31667753298957,-1.5757906460476263,-0.026437415079520576
413.4000000000053,47.4534396756097,-1.5775958953951585,-0.029079768988435006
414.8000000000053,47.591320466045254,-1.5761457493777276,-0.030203138079060388
416.20000000000533,47.728066817240155,-1.5724253210366799,-0.030728540619191946
417.60000000000537,47.86234039109253,-1.570537298530935,-0.029078438127175588
419.00000000000534,48.00040974665742,-1.5677608030177743,-0.029079991998168353
420.4000000000054,48.13893790153504,-1.5696259911418404,-0.029045169878286536
421.8000000000054,48.2762251984591,-1.570273745217885,-0.02942263875020501
423.20000000000545,48.41298496509223,-1.572680640434128,-0.028093266544593654
424.6000000000055,48.55009728537578,-1.5723076393775972,-0.029085772361432838
426.00000000000546,48.68743099805428,-1.5738832279546788,-0.029090150764770506
427.4000000000055,48.82373525355085,-1.5753786883596383,-0.027770313105285105
428.8000000000055,48.96111771691999,-1.5790164457803546,-0.030455766144737773
430.2000000000055,49.09785058109982,-1.5812997491136367,-0.029089456361821142
431.60000000000554,49.236632965751305,-1.5826649028021667,-0.029084972884864335
433.00000000000557,49.37591818532728,-1.585100094819219,-0.030167228429116122
434.4000000000056,49.51326101377793,-1.5894460944094349,-0.02875975031587963
435.80000000000564,49.65088427666176,-1.591244265319368,-0.027445979892579686
437.2000000000056,49.788602454554194,-1.5900976059784842,-0.02876013187857751
438.60000000000565,49.92663007106078,-1.5938883555831043,-0.030067732480906884
440.0000000000057,50.065002637929446,-1.595393479455558,-0.03011143736088684
441.40000000000566,50.202299932814775,-1.5986063333767997,-0.02785289217728959
442.8000000000057,50.33968740244422,-1.599326909316474,-0.0300701064981741
444.20000000000573,50.47815363334285,-1.6007127254005329,-0.028749781078079018
445.60000000000576,50.615011627199486,-1.6057269397908651,-0.027515901482654037
447.0000000000058,50.754085907502734,-1.604682090877774,-0.02776863422400666
448.4000000000058,50.89118889535001,-1.6075872966165468,-0.027759832045627597
449.8000000000058,51.02928331324872,-1.6086692213364497,-0.028419086362757362
451.20000000000584,51.16749292371074,-1.6110257911702273,-0.02908114513954274
452.6000000000058,51.3038172187094,-1.6129422954812322,-0.02908010400289296
454.00000000000585,51.4431112887308,-1.6157096511107767,-0.02781330502961854
455.4000000000059,51.58135538020215,-1.6191089454354615,-0.029083321344337776
456.8000000000059,51.719090897311986,-1.619384533135538,-0.029080044476617495
458.20000000000596,51.85696992653478,-1.6208717146576852,-0.028420109431738005
459.60000000000593,51.995111098950055,-1.6246980533496158,-0.028388378945144233
461.00000000000597,52.1324903899456,-1.6259909414862639,-0.028018170067619863
462.400000000006,52.270874030950246,-1.62808071427821,-0.02845449818429291
463.800000000006,52.41000092278202,-1.6324000993528018,-0.03105421717254142
465.200000000006,52.54787616717141,-1.6346149897653328,-0.03138708430230164
466.60000000000605,52.6865354904524,-1.6374050418065667,-0.030079840045243778
468.0000000000061,52.823604370482975,-1.6393809043396552,-0.03007984014477927
469.4000000000061,52.96310288501935,-1.6430169717875807,-0.028761970515923885
470.8000000000061,53.10261954255972,-1.6467029748941393,-0.02842908292066859
472.2000000000061,53.240793119128334,-1.648337820728412,-0.02843290801940146
473.60000000000616,53.38008820649328,-1.6513903479292051,-0.029740041154705743
475.00000000000614,53.51839372963452,-1.6559635373636992,-0.028420021702902254
476.4000000000062,53.6574076329873,-1.6577521601959284,-0.029739102063378375
477.8000000000062,53.79510737440306,-1.6620577075937142,-0.03128247756314462
479.20000000000624,53.934051100924776,-1.664550560753488,-0.03127934114627973
480.6000000000063,54.07350434389703,-1.6688139603205185,-0.02899850496513423
482.00000000000625,54.21351121284996,-1.6745837458888828,-0.03072802154336607
483.4000000000063,54.352091280886405,-1.6764046044802967,-0.03203636142596977
484.8000000000063,54.492141734288154,-1.680579563340491,-0.03041749351334655
486.2000000000063,54.63111691165491,-1.6816857707615638,-0.03173178366641416
487.60000000000633,54.769061164730644,-1.6831995490927851,-0.0304204771264045
489.00000000000637,54.907840763494306,-1.687477900703066,-0.030399228060765893
490.4000000000064,55.04600853936606,-1.6909759724666484,-0.029077312380583642
491.80000000000643,55.186251725568454,-1.6922161455891218,-0.031376519359186616
493.2000000000064,55.32359520838512,-1.6970535200362382,-0.03140013554600074
494.60000000000645,55.46399186484388,-1.6991178119337682,-0.030276903390282328
496.0000000000065,55.60259202392908,-1.7036803705509451,-0.03260985497257618
497.40000000000646,55.74324562228303,-1.705069996578636,-0.03238000816307629
498.8000000000065,55.88140609651163,-1.710079493926501,-0.03237997946782123
500.2000000000065,56.02083122762333,-1.7098569212883317,-0.03097918420503465
501.60000000000656,56.15980381082522,-1.713983124182823,-0.03369987244115524
503.0000000000066,56.29951202329371,-1.7166595755977647,-0.03370025203623772
504.40000000000657,56.438446576702944,-1.71874232525957,-0.03238019603556008
505.8000000000066,56.576936303521336,-1.7214341143137841,-0.032380195999999195
507.20000000000664,56.71624388261317,-1.7250820543060048,-0.03238014906349562
508.6000000000066,56.85552402078635,-1.7266413918189893,-0.030398930171805283
510.00000000000665,56.99462145031051,-1.7300017127190908,-0.031810861183706685
511.4000000000067,57.134761672048384,-1.7292275713767846,-0.034459711370128154
512.8000000000068,57.27432217239037,-1.7341976353589048,-0.03577770145470094
514.2000000000068,57.414254343291994,-1.7351597715401699,-0.03445985474305502
515.6000000000067,57.55301052532886,-1.7383470807331438,-0.035781062747391346
517.0000000000068,57.693015650398316,-1.7437812701707442,-0.03577962124777567
518.4000000000068,57.832222394860594,-1.7428272118820216,-0.0344532876501793
519.8000000000068,57.97100082250949,-1.747326023133961,-0.03578066854094697
521.2000000000069,58.111801601924505,-1.7524187757340257,-0.034460041822837795
522.6000000000068,58.25037644078829,-1.755602766137711,-0.03577983240091154
524.0000000000068,58.390202053442124,-1.7589115999202818,-0.03578005441334842
525.4000000000069,58.529613014812625,-1.7607811289194073,-0.03644006303359859
526.8000000000069,58.66981404540647,-1.764094955362861,-0.037734236699838775
528.2000000000069,58.809685302392026,-1.7686372977149545,-0.03643981511043748
529.600000000007,58.94867854912816,-1.7714443787609768,-0.038745321423139245
531.0000000000069,59.08848315970757,-1.7746080342668238,-0.037430095690496934
532.4000000000069,59.22827374821038,-1.7798406820677808,-0.03875003858719328
533.800000000007,59.368668991188734,-1.782000387050884,-0.0388361657485774
535.2000000000071,59.508215772488846,-1.7881414760806231,-0.037868099522830434
536.6000000000071,59.64582723212414,-1.7903849153163305,-0.037865408830018765
538.000000000007,59.78806907271308,-1.7940848741556032,-0.03918983989289071
539.4000000000071,59.92743456415205,-1.7978171526332378,-0.04055086304199085
540.8000000000071,60.067993578693844,-1.7999443604713066,-0.04049848935375078
542.2000000000071,60.208388177586166,-1.805258313742491,-0.042148763233358366
543.6000000000072,60.347326953123336,-1.8083674683813453,-0.04214981742069224
545.0000000000072,60.48822382391543,-1.810982109457658,-0.04349543249612964
546.4000000000071,60.62760733216447,-1.8159805730274414,-0.04248772855438032
547.8000000000072,60.76822782892006,-1.8179644540050568,-0.04380029623248616
549.2000000000072,60.90710228856858,-1.8216117187063066,-0.04248002798947459
550.6000000000072,61.04821501427729,-1.823568968252805,-0.042465968948630195
552.0000000000073,61.188253258732544,-1.830016284201487,-0.04378992398765069
553.4000000000073,61.328385544254296,-1.8351827010093085,-0.043789481435843935
554.8000000000073,61.46806212459285,-1.838187474255275,-0.045024835422755594
556.2000000000073,61.608346788882606,-1.8420617311226049,-0.04642179878420061
557.6000000000073,61.75008438961035,-1.8456338461124846,-0.04873010389732979
559.0000000000074,61.88896450434352,-1.8461873987982234,-0.04872619270199463
560.4000000000074,62.02919101802502,-1.8528677278192514,-0.04775010389592982
561.8000000000075,62.16966199601411,-1.8579440630184936,-0.04871135536633986
563.2000000000074,62.30999903021371,-1.862260269409528,-0.04906998500676174
564.6000000000074,62.4503178171562,-1.864139115849295,-0.04905576975971071
566.0000000000075,62.590818744338236,-1.8695633225603918,-0.04775000643390204
567.4000000000075,62.73159155252074,-1.8722917448399548,-0.04776224319177258
568.8000000000075,62.87193552137105,-1.876667603226091,-0.05051286242673081
570.2000000000075,63.01184880367226,-1.8847757141330106,-0.051665949178339776
571.6000000000075,63.15266058775517,-1.888586885772422,-0.05580265122102146
573.0000000000075,63.29456668020573,-1.898961296967028,-0.05442205190987304
574.4000000000076,63.433688466467025,-1.9069212874618133,-0.05707881216640365
575.8000000000076,63.574495480533926,-1.9036407645858864,-0.054440568348720575
577.2000000000077,63.71478399332666,-1.9043686897167094,-0.0553367047588198
578.6000000000076,63.854453306286466,-1.9059259743026513,-0.056429369180246436
580.0000000000076,63.996599744035755,-1.907668751091971,-0.05905684326509508
581.4000000000077,64.13738238383607,-1.9096257936702785,-0.057720945157040404
582.8000000000077,64.27671614228107,-1.9122347484302589,-0.05906239356512444
584.2000000000078,64.41878213070954,-1.9210486843465266,-0.0577267399004322
585.6000000000078,64.55855628324905,-1.9229502546760116,-0.05928030858660849
587.0000000000077,64.69890230925553,-1.93104118825266,-0.060380208433802984
588.4000000000078,64.84238819765517,-1.9309478113516716,-0.060933141855194606
589.8000000000078,64.98152962093265,-1.9344753753009636,-0.06071023671822129
591.2000000000078,65.12397459512708,-1.9365726895334148,-0.06273862936092733
592.6000000000079,65.26417584286484,-1.9369401702098814,-0.06336370066686614
594.0000000000078,65.40552019175767,-1.9392321395436911,-0.06506203106096464
595.4000000000078,65.54637538780737,-1.942240296069902,-0.0656326781235852
596.8000000000079,65.68660687664439,-1.9451459613920081,-0.06640223376695431
598.2000000000079,65.82734023138657,-1.945781758185689,-0.06729838393397758
599.600000000008,65.96617055979938,-1.9488138146244138,-0.06879260601148074
601.000000000008,66.10875596880904,-1.9532693303752924,-0.06980772544338842
602.4000000000079,66.25043663012276,-1.953381668524341,-0.06848970613468719
603.800000000008,66.39050840388691,-1.95563826129288,-0.0698487260369065
605.200000000008,66.53202254523121,-1.9584072891114501,-0.07219242667410786
606.6000000000081,66.67254417849787,-1.9634145635888538,-0.07480736517187925
608.0000000000081,66.81401078457067,-1.966623924338004,-0.0761801319987514
609.400000000008,66.95495429257052,-1.9735304161569212,-0.0761801320476505
610.8000000000081,67.09521763003677,-1.9788467235648826,-0.07749694440032551
612.2000000000081,67.23688502095258,-1.9838990173796176,-0.07684070098512485
613.6000000000081,67.37704153402022,-1.985720101088933,-0.07934072494536615
615.0000000000082,67.51812988532859,-1.9902720017145783,-0.0808001172270516
616.4000000000082,67.65859670334753,-2.0001829669788744,-0.08144954524547154
617.8000000000081,67.8006070064147,-2.005474606143238,-0.0850749336455312
619.2000000000082,67.94088788686787,-2.014334283022272,-0.08508235719958046
620.6000000000082,68.08230800209493,-2.021055011991816,-0.08640545525800869
622.0000000000083,68.2238558097834,-2.029384512578174,-0.08902756912954812
623.4000000000083,68.36417567812038,-2.039105315748591,-0.09007759616970201
624.8000000000083,68.5058037941732,-2.047611738310352,-0.09180409284503188
626.2000000000083,68.64706689216435,-2.059547901804785,-0.09268868381218365
627.6000000000083,68.78911788792253,-2.0706680178565016,-0.09393342387643377
629.0000000000084,68.93010624924554,-2.083514254590528,-0.09524760091509865
630.4000000000084,69.07201842788079,-2.094520966110379,-0.09738848464183114
631.8000000000084,69.21378850638246,-2.110643613770325,-0.09824521202534298
633.2000000000085,69.3551298399534,-2.121058907162638,-0.10198031920646633
634.6000000000084,69.4976251408385,-2.138555779665069,-0.10465719722789402
636.0000000000084,69.6385568358971,-2.1515968078961687,-0.10787052285717058
637.4000000000085,69.78089376250885,-2.1678724563487677,-0.10989037031242521
638.8000000000085,69.92250935248929,-2.181963096222749,-0.11132235788997447
640.2000000000085,70.06491485278586,-2.2000490644951505,-0.11535590537144547
641.6000000000085,70.20594932967302,-2.2146928778807693,-0.11794152576883876
643.0000000000085,70.3485836846471,-2.233298508180881,-0.12056701058718344
644.4000000000086,70.49178071000176,-2.2481298583348583,-0.12330256801029549
645.8000000000086,70.63449349750329,-2.2683719288413053,-0.1274684496961367
647.2000000000086,70.77714662892959,-2.2842901136332445,-0.13288662302285337
648.6000000000087,70.91859561875556,-2.306502935029386,-0.13546093334126486
650.0000000000086,71.06212468742052,-2.328109247087518,-0.14051202625330417
651.4000000000087,71.20480967846865,-2.349500512715749,-0.14490957375000368
652.8000000000087,71.34642512926476,-2.368949576354234,-0.14789446547647467
654.2000000000087,71.48778562654881,-2.391867291306038,-0.1525074468783183
655.6000000000088,71.63066410161971,-2.4170146020393357,-0.15666347666487024
657.0000000000088,71.7726530045154,-2.43991137792212,-0.16272005588381422
658.4000000000087,71.91482529737834,-2.462865243305839,-0.16883053438891826
659.8000000000088,72.05702191444286,-2.487404164600874,-0.1742945292517648
661.2000000000088,72.19894431161637,-2.5163243927889436,-0.18095734811090436
662.6000000000088,72.34147284327919,-2.5438610000248767,-0.18979656033291636
664.0000000000089,72.48348766070677,-2.569116165110705,-0.19617350118017418
665.4000000000088,72.62593658050409,-2.597755575236646,-0.20113912546560808
666.8000000000089,72.768357212934,-2.6296177051213796,-0.20661196359268574
668.2000000000089,72.90989355756443,-2.65843283656078,-0.21429526386463582
669.6000000000089,73.05262163129356,-2.6896360274888664,-0.2209847001631835
671.000000000009,73.19542366222821,-2.727508660759298,-0.22863666746170752
672.400000000009,73.33821243109566,-2.761069925200685,-0.23919645392399858
673.800000000009,73.48000110434093,-2.7932102285048166,-0.2478799697594094
675.200000000009,73.62153596539329,-2.8311053690482884,-0.255526323380765
676.600000000009,73.7673053824031,-2.865903950749396,-0.2650972870950734
678.0000000000091,73.90895418002626,-2.903398382031693,-0.2740833179650153
679.4000000000091,74.05358134800905,-2.9434987008108435,-0.28297508294319673
680.800000000009,74.19637204572034,-2.9791168794354146,-0.2950694982683215
682.2000000000091,74.33999907710177,-3.01951945387421,-0.3058499039885221
683.6000000000091,74.48408505327318,-3.062688665705954,-0.3187095109078846
685.0000000000091,74.62540083371623,-3.1041917183377303,-0.3273117533690977
686.4000000000092,74.77110926246073,-3.1452694091208246,-0.3409489720029675
687.8000000000092,74.91419162165913,-3.1902694861160588,-0.354681674605934
689.2000000000093,75.05803071990948,-3.230124364790705,-0.3677826895116403
690.6000000000092,75.20102181744022,-3.2764272944729784,-0.38005248576316886
692.0000000000092,75.34525947993383,-3.3214873064828545,-0.39259843886663326
693.4000000000093,75.48841086114811,-3.37107364079078,-0.4059398101597118
694.8000000000093,75.63262857311315,-3.4098676960458176,-0.4231112126026795
696.2000000000094,75.77548157009633,-3.455125921944767,-0.4407579037598013
697.6000000000093,75.9195780457515,-3.506216659618885,-0.4516037651611713
699.0000000000093,76.06340384772797,-3.5498867053877063,-0.4699615152350005
700.4000000000094,76.20732000244202,-3.595107376647847,-0.4859952512528096
701.8000000000094,76.35058451683813,-3.644211865667478,-0.5043237564087044
703.2000000000094,76.49386262648083,-3.6902470528963804,-0.5200451290758705
704.6000000000095,76.63659147577695,-3.733316593849154,-0.538809487798964
706.0000000000094,76.7795426397811,-3.782224367610188,-0.5577459400209936
707.4000000000094,76.92309871910977,-3.8256590320632182,-0.5768653980192244
708.8000000000095,77.0665997891941,-3.870671536152845,-0.5949126566176495
710.2000000000095,77.20990180425838,-3.916865069084758,-0.6144474693811484
711.6000000000096,77.35420471134705,-3.9617754997022647,-0.6358062652920631
713.0000000000095,77.4966126452496,-4.0083308800135935,-0.657255388328998
714.4000000000095,77.63877652669768,-4.053224781000582,-0.676794506202465
715.8000000000096,77.78318542251141,-4.097024952323432,-0.7019598790413397
717.2000000000096,77.92703661940504,-4.141035469283705,-0.7231383481002722
718.6000000000097,78.0694679182811,-4.185897881792464,-0.7439866357009217
720.0000000000097,78.21378559322362,-4.230355256875392,-0.7674020364341199
721.4000000000096,78.35700907867077,-4.27102725380972,-0.7906973360858882
722.8000000000097,78.50111034614368,-4.3121196698981965,-0.8142807028038526
724.2000000000097,78.64497339724268,-4.354410865953428,-0.8409869434860262
725.6000000000097,78.78871153874164,-4.395306056333554,-0.8637613580856502
727.0000000000098,78.93336676694823,-4.433616324820049,-0.889112906840293
728.4000000000098,79.07667244263355,-4.4706080523793315,-0.9138170704406536
729.8000000000097,79.22101727718079,-4.511350129128393,-0.9405715823109158
731.2000000000098,79.36323407167444,-4.552955644877972,-0.966417875372406
732.6000000000098,79.50753035447363,-4.595381817458984,-0.9939543130874684
734.0000000000099,79.6511590894138,-4.648521375220248,-1.0224788097717417
735.4000000000099,79.7952233437166,-4.709110343294943,-1.0492936250417486
736.8000000000098,79.93936214762002,-4.781320901180901,-1.0762722347618814
738.2000000000099,80.08432357179034,-4.8634265895009925,-1.1031018053544748
739.6000000000099,80.22919858959531,-4.955867969390387,-1.133641172944822
741.00000000001,80.37258239364668,-5.042372181836515,-1.1629535487681246
742.40000000001,80.51771866661224,-5.118330898059885,-1.194409076838403
743.80000000001,80.66021051241219,-5.17154413180293,-1.2236949710229292
745.20000000001,80.80609607494944,-5.1863572062721675,-1.2560838609200555
746.60000000001,80.9477573671531,-5.144095614018863,-1.288334840904036
748.00000000001,81.08690837710952,-5.020723030361015,-1.3163521998210022
749.4000000000101,81.22391271154805,-4.801795157289567,-1.342103996151034
750.8000000000101,81.35768302973375,-4.458407189234405,-1.3666252007744064
752.20000000001,81.48799023912005,-3.950674828013244,-1.3875541273955467
753.6000000000101,81.61252865199648,-3.2540771458147084,-1.3985395056171979
755.0000000000101,81.74041021614055,-2.6971990814842224,-1.407314788751345
756.4000000000102,81.87535889633828,-2.3895524786191777,-1.4110349119760772
757.8000000000102,82.01298638195092,-2.23748137407528,-1.412997360504043
759.2000000000102,82.1524345375577,-2.1680179941083453,-1.4143299248906138
760.6000000000103,82.29426596989119,-2.1334388454590467,-1.4157508491769737
762.0000000000102,82.43630114578282,-2.1162072980179665,-1.4143404473256962
763.4000000000103,82.57966753493272,-2.113210626759799,-1.415318735104686
764.8000000000103,82.72257909605003,-2.1134475480799724,-1.416629903446594
766.2000000000103,82.86503546872275,-2.113492348414003,-1.4166898711635514
767.6000000000104,83.00897839733867,-2.1065123257431724,-1.4166399932574478
769.0000000000103,83.15107713049143,-2.110189893183213,-1.4156498721312243
770.4000000000103,83.29345665619215,-2.114299344175334,-1.4155326297693365
771.8000000000104,83.43715048772034,-2.116614867415823,-1.4130403712659416
773.2000000000104,83.5792680069409,-2.1202947395685783,-1.4157586589487723
774.6000000000104,83.7235072752821,-2.1255884215618566,-1.4157352003580272
776.0000000000105,83.86678163696865,-2.129105154319866,-1.4183069349767594
777.4000000000104,84.00929944237473,-2.136264539167344,-1.4190501740123622
778.8000000000105,84.15184600426551,-2.1393989953276944,-1.4162024101148338
780.2000000000105,84.29574108146365,-2.1417815853364495,-1.4173008562299056
781.6000000000105,84.43943469115256,-2.1443310200209886,-1.4194941950328608
783.0000000000106,84.58264728844317,-2.144735584209184,-1.419474090874552
784.4000000000106,84.72524331062202,-2.1471264130148424,-1.4181822389591958
785.8000000000106,84.86951239621415,-2.1509400586600718,-1.4194901266250803
787.2000000000106,85.01186595664845,-2.156384484013494,-1.4181801298070655
788.6000000000106,85.15503793661196,-2.159961190332279,-1.4185338122408337
790.0000000000107,85.30010305798797,-2.1613906046410927,-1.418510330574302
791.4000000000107,85.44276744553298,-2.167831578516201,-1.4162167477265073
792.8000000000106,85.58488281030355,-2.1723401102365996,-1.4161807133907969
794.2000000000107,85.72745735308476,-2.1746224064011,-1.4175813109041626
795.6000000000107,85.87152803674998,-2.175395941791269,-1.416640730984298
797.0000000000107,86.01496941062723,-2.1783595773257067,-1.417614908195107
798.4000000000108,86.15795010015917,-2.181756628422169,-1.416309903260303
799.8000000000108,86.30101315692197,-2.1869081865172357,-1.4163098519974548
801.2000000000108,86.44472065369483,-2.1871463312817307,-1.4177125861035775
802.6000000000108,86.5883098848142,-2.189616380160458,-1.4167579158793027
804.0000000000108,86.73105005391982,-2.193309831516399,-1.416192474600955
805.4000000000109,86.87468879372794,-2.197074450228432,-1.4171918078198873
806.8000000000109,87.01759291850159,-2.1994235858371383,-1.4175079460993945
808.200000000011,87.16071422825767,-2.2043213259373884,-1.4149338145672048
809.6000000000109,87.30443494328188,-2.2073934359024756,-1.4151769811433321
811.0000000000109,87.44766607033348,-2.2141571072206356,-1.416332735150812
812.400000000011,87.58936553300114,-2.2187790778548133,-1.4162596460477483
813.800000000011,87.73262937480509,-2.224904726941621,-1.4141125075449574
815.200000000011,87.8777155267656,-2.2265662213306414,-1.4149889999292462
816.600000000011,88.02104311621267,-2.225609415205702,-1.4156501401279984
818.000000000011,88.16436825637679,-2.229568202647887,-1.4169596678616685
819.400000000011,88.30693304299476,-2.2263262439513065,-1.41698538659345
820.8000000000111,88.45058958367774,-2.235221524473912,-1.4182801854505764
822.2000000000111,88.59079450834999,-2.236575392103873,-1.4176299479478645
823.6000000000112,88.7356836148821,-2.236527410765869,-1.4163041055637295
825.0000000000111,88.87823788920934,-2.238308986237868,-1.4139996737474876
826.4000000000111,89.02263000750803,-2.2433828046429602,-1.4150078449378838
827.8000000000112,89.16664338932698,-2.247304757021907,-1.4166316449028233
829.2000000000112,89.3103805173547,-2.2491970877620506,-1.4166483967478847
830.6000000000113,89.45660098076301,-2.252961149421488,-1.4146272500290427
832.0000000000113,89.59950066912498,-2.2543813939271886,-1.4159799605677463
833.4000000000112,89.74394948437666,-2.259327946464231,-1.4139998070885178
834.8000000000113,89.88797859673826,-2.2642590471930175,-1.4167470651890341
836.2000000000113,90.03166725840562,-2.2673653914405545,-1.414120082387373
837.6000000000113,90.174767263408,-2.2705603767851255,-1.4140434751867086
839.0000000000114,90.31766703348407,-2.273307343156379,-1.4167489815309224
840.4000000000113,90.46273957831038,-2.274936737533877,-1.416750159234871
841.8000000000113,90.60508550938644,-2.27791700247078,-1.4182842533909636
843.2000000000114,90.74831593630154,-2.2818749269598966,-1.416835248503249
844.6000000000114,90.89051093960549,-2.2815857626536267,-1.4140582393888526
846.0000000000115,91.034997982333,-2.286941244182673,-1.4156499360991588
847.4000000000115,91.17824143391972,-2.292220807821901,-1.4169699482184996
848.8000000000114,91.3204915745387,-2.293158600080278,-1.416982536120523
850.2000000000115,91.46415684491768,-2.2988089862034973,-1.4170780802008998
851.6000000000115,91.60676289449003,-2.2992308149944547,-1.4182785435745555
853.0000000000116,91.75128140783873,-2.305715282909962,-1.4182798468533
854.4000000000116,91.89359418256352,-2.3051779706028332,-1.415985406179895
855.8000000000116,92.03794912961689,-2.3089986481564955,-1.417557773889821
857.2000000000116,92.18286187930698,-2.3116337330601784,-1.4148900144829866
858.6000000000116,92.32718279939141,-2.315774390124329,-1.4171803480511675
860.0000000000116,92.4708270625293,-2.3178487962777266,-1.415871435737623
861.4000000000117,92.61546906314364,-2.316924128939906,-1.4131908425129978
862.8000000000117,92.75842732870935,-2.31817956123871,-1.415888545253401
864.2000000000116,92.90420686178787,-2.3252678686625203,-1.4161999684095599
865.6000000000117,93.04715285835097,-2.32527328341726,-1.4157568836859586
867.0000000000117,93.19171226902806,-2.3291224119256184,-1.4157891238756366
868.4000000000118,93.3352075974018,-2.3266986208608906,-1.4144400720703874
869.8000000000118,93.47818212697528,-2.3279454123707186,-1.4157598849565085
871.2000000000118,93.62225113803935,-2.3314419285239496,-1.4159629581601596
872.6000000000118,93.76561693009494,-2.3383148581535145,-1.4168294811177993
874.0000000000118,93.90825534614265,-2.340189548036167,-1.4146599302037441
875.4000000000119,94.05241190532347,-2.3458221085035422,-1.4174785286348577
876.8000000000119,94.19585259332821,-2.348570106127798,-1.4155744102936936
878.2000000000119,94.3389012701039,-2.356135995433724,-1.4138966902377188
879.600000000012,94.48260269434849,-2.355995176821239,-1.4134759786664985
881.0000000000119,94.62574203231767,-2.360426912204058,-1.4191768634296378
882.4000000000119,94.76760581073879,-2.365860032390526,-1.4165301016977514
883.800000000012,94.91357233334413,-2.3683454955267904,-1.4165300960001068
885.200000000012,95.05804966764788,-2.3731449090759593,-1.4165452400320007
886.600000000012,95.20146150076324,-2.3694092518800143,-1.416526424280609
888.000000000012,95.34540424036729,-2.3724423122428355,-1.416200083495096
889.400000000012,95.48946154246438,-2.37185995000428,-1.4144742325849844
890.8000000000121,95.63327912353179,-2.3675102195372992,-1.4152458679521516
892.2000000000121,95.77801779214231,-2.370074833972356,-1.4151000237911364
893.6000000000121,95.91980440007889,-2.371714639125938,-1.4125716031172995
894.0000000000122,95.96080134721396,-2.3728917961452627,-1.4125700212869106