File: 01_Data/Concrete_Block/STA/N2/10K_min/Concrete_Block_STA_N2_10KData_220913_R2.csv
##Temp./Â°C,Time/min,DSC/(mW/mg),Mass loss/mg
51.0,10.87921941769604,-1.5195019399543837,-0.019399944727654272
52.100000000000016,11.203946758285099,-1.418644560062994,-0.018265724588134802
53.20000000000003,11.445283376285175,-1.3502659994394313,-0.018547392228481563
54.30000000000005,11.642176046868514,-1.299725086368355,-0.018142984123389994
55.40000000000006,11.824934761655367,-1.2564249866396853,-0.01814468361957644
56.50000000000008,11.995026362099132,-1.2240155904528591,-0.019179158117592188
57.600000000000094,12.156073038131053,-1.194907877526187,-0.01903206335622265
58.70000000000011,12.30916157648089,-1.1707925843224976,-0.019067190870943662
59.800000000000125,12.458506478801727,-1.1503670232965486,-0.018431399088804312
60.90000000000014,12.604729718497627,-1.129462707573189,-0.020315475069067723
62.000000000000156,12.745366140047935,-1.1108323980803536,-0.019664645439092965
63.10000000000017,12.884021899493206,-1.0954776980504928,-0.019454822378320635
64.20000000000019,13.017193464588287,-1.0800271572041047,-0.019099214134164377
65.30000000000021,13.15423755312636,-1.0672279161921987,-0.02086467540563408
66.40000000000022,13.288524703802802,-1.0528374420356084,-0.022047815678915228
67.50000000000023,13.42023054730865,-1.0410650879065728,-0.020642502762825643
68.60000000000025,13.549368491460493,-1.0275553569357365,-0.021864977636504968
69.70000000000027,13.676931126346675,-1.0162657589434956,-0.021792873227982845
70.80000000000028,13.803934736357947,-1.0034531439839898,-0.022630279446852697
71.90000000000029,13.928452635909377,-0.9945026301114579,-0.023332294827180355
73.00000000000031,14.05266675315898,-0.9822666708910844,-0.022964766202122178
74.10000000000034,14.175497198249179,-0.9710074681690789,-0.023466322018224517
75.20000000000034,14.298550739080978,-0.9592803046756924,-0.022073465660179536
76.30000000000035,14.420213505998746,-0.94805457603767,-0.022823399242983378
77.40000000000038,14.54222384850607,-0.939471286384465,-0.02345975353956664
78.5000000000004,14.660102896016856,-0.9283169166765001,-0.024787297411187126
79.6000000000004,14.777963961546131,-0.9200140968713394,-0.023635785024895384
80.70000000000041,14.897824802596228,-0.9086833487405139,-0.023500665720839642
81.80000000000044,15.015138251283412,-0.9018044831934392,-0.02481138166077468
82.90000000000046,15.132249458276213,-0.8938759255095166,-0.026080695961506528
84.00000000000047,15.248263780992993,-0.8841333861283044,-0.027197496830567935
85.10000000000048,15.36407045066082,-0.8760077268579235,-0.027459599457821504
86.2000000000005,15.480000000000055,-0.8672700000000005,-0.027450232035824307
87.30000000000052,15.591921959713906,-0.8590739975415317,-0.027455284219528586
88.40000000000053,15.707646787419591,-0.8515172393362442,-0.02753657840777013
89.50000000000054,15.820741753834659,-0.8442010359291728,-0.030119905001434244
90.60000000000056,15.93371167688871,-0.8364886177614556,-0.028706472170753727
91.70000000000059,16.045284581522402,-0.8289497561469394,-0.03136328797070975
92.8000000000006,16.157308339450157,-0.8221021194511409,-0.03008895851762805
93.9000000000006,16.268077375354203,-0.8154973453951664,-0.030135922821528993
95.00000000000063,16.380198962228782,-0.8084767786039481,-0.030086309609886452
96.10000000000065,16.490751906494726,-0.8028146983950011,-0.03139900136762375
97.20000000000066,16.60030419380366,-0.7948033026342112,-0.03170499528554371
98.30000000000067,16.710442815254687,-0.7882767466132654,-0.03235615209102871
99.40000000000069,16.82100791156507,-0.7815750142441269,-0.032318061356575
100.50000000000071,16.92875564845955,-0.7751196623415614,-0.03271889232443437
101.60000000000072,17.038686822840734,-0.7677874735753666,-0.03273040789890258
102.70000000000073,17.14803715240098,-0.7611972631730819,-0.03404127351706743
103.80000000000075,17.25753778910528,-0.7546769987272217,-0.034122890292944685
104.90000000000077,17.36454941903295,-0.7476872568018235,-0.033430030380594555
106.00000000000078,17.470239398587374,-0.740378450782334,-0.0351996844961735
107.10000000000079,17.580109000794188,-0.7365766403816917,-0.03392669272150117
108.20000000000081,17.688747143361734,-0.730642675011222,-0.03443620318837537
109.30000000000084,17.79696388636132,-0.7243547348049576,-0.03535869929938862
110.40000000000084,17.90342716076025,-0.719375413372533,-0.03537320268575472
111.50000000000085,18.012737119345637,-0.7144983600340153,-0.03534886748310262
112.60000000000088,18.119451909218505,-0.7108193357798529,-0.03668051742487233
113.7000000000009,18.226216850348546,-0.7060348215654363,-0.03789859819499597
114.8000000000009,18.334673536056847,-0.700766082220521,-0.03915871515193814
115.90000000000092,18.44246226877492,-0.697453354694606,-0.03832100828531937
117.00000000000094,18.548008034543408,-0.6935082603635009,-0.03805946581829911
118.10000000000096,18.6550187956044,-0.690065938280067,-0.039048539931689774
119.20000000000097,18.762809271829635,-0.68577446848182,-0.03875282006538594
120.30000000000098,18.870795109605776,-0.6828445387603892,-0.039639810731581626
121.400000000001,18.97923914668497,-0.6794139145577041,-0.0406320395465527
122.50000000000102,19.08508421157318,-0.6753100712062631,-0.040544740796502055
123.60000000000103,19.19262096297359,-0.6714670113615471,-0.04062290852691364
124.70000000000104,19.299711608081644,-0.6667323009874976,-0.04195173850092715
125.80000000000106,19.405692763716086,-0.6636365663495652,-0.04195000175215968
126.90000000000109,19.51313439540529,-0.6603719806043027,-0.04323404832050004
128.00000000000108,19.61919101672222,-0.6564404089127209,-0.043259820276987604
129.1000000000011,19.725381284195322,-0.6523698480157017,-0.04326066007525098
130.20000000000113,19.832548124613506,-0.6491568361811205,-0.04194884018982892
131.30000000000115,19.93754280127979,-0.6439784099234823,-0.04326912243524239
132.40000000000117,20.043177717642163,-0.6409628120545003,-0.04326005962982382
133.50000000000117,20.149502427150413,-0.6370465682083012,-0.04325990300972071
134.6000000000012,20.254357554579226,-0.6330145025406977,-0.04320338592425088
135.7000000000012,20.361136123192406,-0.6290763566429721,-0.04459059996010106
136.8000000000012,20.466982696689517,-0.6263946789831625,-0.04458012678261669
137.90000000000123,20.56821498664126,-0.6224294248558508,-0.04598631084811089
139.00000000000125,20.678681226370518,-0.6179061999412957,-0.04458971394822164
140.10000000000127,20.782426455766608,-0.614460883116511,-0.04487358586459855
141.2000000000013,20.88762388720838,-0.6120280956284894,-0.046230162835021904
142.3000000000013,20.992620308170736,-0.6076573599077906,-0.04615266909642024
143.4000000000013,21.097868981460028,-0.6034633034226571,-0.04671942056069778
144.50000000000134,21.20362885113592,-0.6016996739485266,-0.04618157808423318
145.60000000000133,21.308218879550427,-0.597679563899829,-0.04698768728637326
146.70000000000135,21.4139598477383,-0.5949761676985412,-0.04623007712627025
147.80000000000138,21.5183307271105,-0.5910647689631241,-0.047539881108101145
148.9000000000014,21.6209506378735,-0.5880393839273358,-0.047540112809275836
150.00000000000142,21.72523693731286,-0.5833317756992829,-0.04886043163465237
151.10000000000142,21.833214568360848,-0.5813818204163478,-0.04852801091759451
152.20000000000144,21.938067577146036,-0.5767867136316727,-0.04964755651776409
153.30000000000146,22.040425092566974,-0.5751711848277417,-0.047216062478780074
154.40000000000146,22.144868353709672,-0.5706164402298055,-0.04721353702962139
155.50000000000148,22.249516817365855,-0.5666365731087989,-0.048529841607791724
156.6000000000015,22.351641697182753,-0.5649334806442621,-0.04885420586317846
157.70000000000152,22.45876111574692,-0.5597059939592902,-0.04984965096537142
158.80000000000155,22.560536999943153,-0.555546557463129,-0.049168605171302726
159.90000000000154,22.669207235384587,-0.5535975592186851,-0.04985002139513961
161.00000000000156,22.774352657448045,-0.5499097344458679,-0.04978357719003412
162.1000000000016,22.879024784033966,-0.5459810406495135,-0.04985018648770456
163.20000000000158,22.98322660789106,-0.5442925503893303,-0.051159548214070316
164.3000000000016,23.087315974629966,-0.5411530542843344,-0.04985015615914046
165.40000000000163,23.190738916933338,-0.5376055339626501,-0.0511656537525873
166.50000000000165,23.296158841746227,-0.5349227263183256,-0.04987509224248088
167.60000000000167,23.402157764809644,-0.5318196294343871,-0.04981507315141842
168.70000000000167,23.505907717219085,-0.5285852228589721,-0.05116980992138753
169.8000000000017,23.61168695724757,-0.5252206869413312,-0.05116987728433742
170.9000000000017,23.71571905398478,-0.5224100348337034,-0.05114649095809698
172.0000000000017,23.820000000000164,-0.5192299999999928,-0.0511599850003277
173.10000000000173,23.923905524020817,-0.5170956274391424,-0.05117203100932777
174.20000000000175,24.028783119810832,-0.5144348210662264,-0.052416807874196
175.30000000000177,24.13347033633696,-0.511541573836339,-0.05247975448384601
176.4000000000018,24.23888789331228,-0.5082399764174531,-0.0511700638883843
177.5000000000018,24.342799734570967,-0.5070385491088614,-0.05249143841631465
178.6000000000018,24.44744613743753,-0.5039035780908022,-0.05248541207223223
179.70000000000184,24.550803581985047,-0.5012167626967011,-0.053014579580172416
180.80000000000183,24.656259495836146,-0.4965896409326655,-0.052499726847177186
181.90000000000185,24.759532906586948,-0.4945436223471551,-0.05280433812856211
183.00000000000188,24.8642088794464,-0.4916825395281495,-0.05347018048126673
184.1000000000019,24.96896077572066,-0.48946048297730954,-0.053469497170722136
185.20000000000192,25.073244023424305,-0.48646319007823,-0.05389628093373888
186.30000000000192,25.17809745929675,-0.4852476466885462,-0.05379995369769208
187.40000000000194,25.28186149962666,-0.4833138686296894,-0.052676252932863044
188.50000000000196,25.386732916213127,-0.48062318525501346,-0.05314979991895319
189.60000000000196,25.489998930328966,-0.47725003748932154,-0.0531498262995882
190.70000000000198,25.59357957534367,-0.47487436077567136,-0.05381006486912776
191.800000000002,25.69923879650133,-0.4722232684302368,-0.054399214075200764
192.90000000000202,25.803664548962537,-0.469877267125002,-0.05477787244104171
194.00000000000205,25.90843683735818,-0.46847233112710346,-0.053469699145013205
195.10000000000204,26.0123380293194,-0.46666220216314924,-0.05299846940067665
196.20000000000206,26.11702258700424,-0.463368892443472,-0.05380015770957547
197.3000000000021,26.221753866666344,-0.45947043097356605,-0.05512012050279713
198.40000000000208,26.324990037388126,-0.4576916510809687,-0.05381405910299142
199.5000000000021,26.430853064685724,-0.45584137774364897,-0.05379998495360283
200.60000000000213,26.534869045213604,-0.4532884618700436,-0.05511911046817408
201.70000000000215,26.640732787681504,-0.4516950901653953,-0.0554448299150736
202.80000000000217,26.744423729316097,-0.4473065682166227,-0.05512918015632229
203.90000000000217,26.848341511599823,-0.44339250422641674,-0.05578246235418449
205.0000000000022,26.951277279132512,-0.4412615867304913,-0.05511018989711758
206.1000000000022,27.055256928922496,-0.4396479782040311,-0.05511672751041852
207.2000000000022,27.159901275105263,-0.43588992662265613,-0.05644058448888778
208.30000000000223,27.266301159487995,-0.43387468807743124,-0.05644005822768916
209.40000000000225,27.37091707652416,-0.4310108600366803,-0.055367117314131686
210.50000000000227,27.474773739878323,-0.4290173903697578,-0.05511988933716161
211.6000000000023,27.578014158261,-0.4257822190134519,-0.05644250604998824
212.7000000000023,27.683106768169075,-0.4234877965867636,-0.056439830620805154
213.8000000000023,27.788584297712898,-0.42040240216588154,-0.056835749986641204
214.90000000000234,27.89222963480934,-0.4179711976409366,-0.056430796096246016
216.00000000000233,27.99571569289158,-0.41678099547260145,-0.05676002270401259
217.10000000000235,28.10151417297275,-0.4122251057376509,-0.056759647422094606
218.20000000000238,28.20575531610711,-0.41000954739392464,-0.05755541988657331
219.3000000000024,28.310371096794,-0.40685549384672093,-0.05808239005865712
220.40000000000242,28.414838752543794,-0.404261453879741,-0.059171203013510976
221.50000000000242,28.519409312916693,-0.4016313006886004,-0.057759853554716134
222.60000000000244,28.624622839046424,-0.39773414868198176,-0.05776165468887129
223.70000000000246,28.72772115435413,-0.3959380649411905,-0.059079717933482545
224.80000000000246,28.83313051399196,-0.39459037388156787,-0.05776005928939432
225.90000000000248,28.936584185241788,-0.3932117242594711,-0.06039942016981836
227.0000000000025,29.042459987509407,-0.39117585822535844,-0.05907002640714465
228.10000000000252,29.14714531092764,-0.3891832663322382,-0.05907002799658967
229.20000000000255,29.25135246304335,-0.3887504765166232,-0.059071815068708844
230.30000000000254,29.354662240855884,-0.38674840891332635,-0.057874239640654856
231.40000000000256,29.46048055222816,-0.3855147823492861,-0.0590697998406049
232.5000000000026,29.56545386182198,-0.38196582659215633,-0.058431014532224435
233.60000000000258,29.66982190513386,-0.38044678394393283,-0.059730107389260656
234.7000000000026,29.77355915711063,-0.37831451426743123,-0.059730089048070756
235.80000000000263,29.877649785321776,-0.37536523103053626,-0.06005959588171672
236.90000000000265,29.98301469028364,-0.37460119516193546,-0.06103995173337218
238.00000000000267,30.087197171323115,-0.371938890241806,-0.05982533026801207
239.10000000000267,30.191845843757342,-0.371416126917445,-0.06038997499990151
240.2000000000027,30.29663925967479,-0.3690029864834844,-0.06038997534114543
241.3000000000027,30.40143558424805,-0.36649202648161355,-0.05951184001052168
242.4000000000027,30.504458188479003,-0.36444936460602817,-0.059084031456711816
243.50000000000273,30.609797753664548,-0.3626463074022425,-0.06038983221879635
244.60000000000275,30.71409899050219,-0.36140609637610616,-0.061448044160439697
245.70000000000277,30.81950503456041,-0.35828272215085544,-0.06172121642978423
246.8000000000028,30.922363740241085,-0.35745877244142993,-0.06035280553253708
247.9000000000028,31.027537993705817,-0.35509214025198854,-0.0630390958657494
249.0000000000028,31.13212474195192,-0.35249469181917614,-0.06271505283394863
250.10000000000284,31.23674190582024,-0.3512051242795238,-0.06138000250185316
251.20000000000283,31.341031234231664,-0.3489421503173612,-0.06209439240859327
252.30000000000285,31.446066497513463,-0.3464100098871902,-0.06269787012116801
253.40000000000288,31.549652045029955,-0.34594259047578585,-0.06138017260075257
254.5000000000029,31.65539206688301,-0.34273122196815686,-0.0626984697265689
255.60000000000292,31.76032720609539,-0.3430623322145376,-0.06302034701161219
256.7000000000029,31.864407699610464,-0.3419688885672483,-0.06229209433276317
257.8000000000029,31.9698946444666,-0.3410233679835465,-0.06203260849414116
258.90000000000293,32.07348861874591,-0.33911167200762676,-0.06202984625049979
260.00000000000296,32.178443513990935,-0.3378962656786102,-0.06276639785558613
261.100000000003,32.282520601576834,-0.3360078913277934,-0.062359990061870096
262.200000000003,32.38761023362781,-0.3331037614320867,-0.062359987918520154
263.300000000003,32.49239780625785,-0.332338798078862,-0.06368271186224739
264.40000000000305,32.59753935784784,-0.3303762969402774,-0.06368000100349214
265.50000000000307,32.70143288779599,-0.3281914182676758,-0.0636798020741236
266.6000000000031,32.80619725966845,-0.32632558511267784,-0.06335017379968022
267.7000000000031,32.911139735333265,-0.3257648068307819,-0.06301748723376344
268.8000000000031,33.015957121814935,-0.3242449569882274,-0.0643387261777737
269.9000000000031,33.12020275126351,-0.32118559132656566,-0.06433988701979754
271.0000000000031,33.22573230438746,-0.3187392919296427,-0.06359077608318398
272.10000000000315,33.33028389023604,-0.3177878592715195,-0.06336019097840095
273.2000000000032,33.43444305937993,-0.3168600861862122,-0.06425831398847714
274.30000000000314,33.53942291589085,-0.3154976361733661,-0.06334799831558202
275.40000000000316,33.64382548264444,-0.31376287541916387,-0.06345246838225416
276.5000000000032,33.74923839122411,-0.3132952853779883,-0.06334992690819741
277.6000000000032,33.855119466064146,-0.31050751707634655,-0.06367938713370869
278.70000000000323,33.95990632316064,-0.30905260229908904,-0.06466995163024958
279.80000000000325,34.062141125017796,-0.30852405082878903,-0.06466996600004382
280.9000000000033,34.16860738349987,-0.3062507041626432,-0.06466996600004915
282.0000000000033,34.274584558437006,-0.30316068235799903,-0.06466983723364583
283.1000000000033,34.37919639601301,-0.3023995098732971,-0.06335009562346805
284.20000000000334,34.48369717088012,-0.3006754476509738,-0.06462970431772774
285.30000000000337,34.589321807103204,-0.2991852215965413,-0.0653298522165886
286.40000000000333,34.69446625143697,-0.29718701612599224,-0.06532985160000271
287.50000000000335,34.79941683360348,-0.29554799973523666,-0.06663698392789241
288.6000000000034,34.905295086601676,-0.2942645710916457,-0.0666498514524747
289.7000000000034,35.01016604278397,-0.2930389986260454,-0.06564425467392931
290.8000000000034,35.114996408234894,-0.2917641275514121,-0.06533002720794201
291.9000000000034,35.220842078928825,-0.29074857199462484,-0.06571839470715846
293.0000000000034,35.32536932502592,-0.28884313814231044,-0.06599002685853872
294.10000000000343,35.43020905309605,-0.28633593930014767,-0.06599002700000023
295.20000000000346,35.53602499529467,-0.2843925295319108,-0.06599002699999845
296.3000000000035,35.64049603168664,-0.2830930876305895,-0.06599002699953305
297.4000000000035,35.74581868628244,-0.2817637840168719,-0.06598783565236666
298.5000000000035,35.85188211126141,-0.28175062463619577,-0.06564973787289752
299.60000000000355,35.95700828344305,-0.2789947490639242,-0.06649616930076974
300.70000000000357,36.062181973006915,-0.2788723684581342,-0.06663985610244527
301.8000000000036,36.1667794460785,-0.2785566222935623,-0.06663985600000144
302.9000000000036,36.27220817586258,-0.27653507903169927,-0.06663985600000455
304.0000000000036,36.37825326670559,-0.2758689268037522,-0.06663985887575752
305.1000000000036,36.4832535546645,-0.2751350802299901,-0.06697269065837075
306.2000000000036,36.58680193673853,-0.27353325325277533,-0.06821088693059352
307.30000000000365,36.694059427128735,-0.2726924393569184,-0.06696950666126522
308.4000000000037,36.799170393609586,-0.2709387582959839,-0.0682855357574863
309.5000000000037,36.90555567525695,-0.2694860708387857,-0.06828985148740907
310.60000000000366,37.01072808112201,-0.2686486950338077,-0.06729831942873998
311.7000000000037,37.11547411440281,-0.26637585851192297,-0.06696321957121709
312.8000000000037,37.22187995421366,-0.26549436716256825,-0.0664687863910971
313.90000000000373,37.327196488582466,-0.2647807851668724,-0.06698004802435431
315.00000000000375,37.43317945121512,-0.2643069607866371,-0.0676722643523835
316.1000000000038,37.53856143735292,-0.2617410126366665,-0.06764027720995358
317.2000000000038,37.64397997607207,-0.2608686209132343,-0.06831540308051487
318.3000000000038,37.74981226236718,-0.2614895343087095,-0.06895987378372048
319.40000000000384,37.855960428407684,-0.2612710461557771,-0.06802431920592777
320.5000000000038,37.96061581144578,-0.25978723064839876,-0.06764004901760945
321.60000000000383,38.067315869432846,-0.25761208892732207,-0.0672941186888063
322.70000000000385,38.172644777441505,-0.25834073773458405,-0.0682866416597272
323.8000000000039,38.27809177357151,-0.2572569080184155,-0.06830339144820385
324.9000000000039,38.38325862174002,-0.25566501482400084,-0.06730668985120136
326.0000000000039,38.48913081808868,-0.2548862881295873,-0.06730937975992157
327.10000000000394,38.59473113698678,-0.2543263018693871,-0.06730948725738539
328.2000000000039,38.70096574366951,-0.2539731956824801,-0.06730901326263128
329.30000000000393,38.80783493397614,-0.253522796118758,-0.06765215059846819
330.40000000000396,38.91280755588663,-0.2516948221563642,-0.06896010267203323
331.500000000004,39.01895791041216,-0.24972345293182402,-0.06895209167444571
332.600000000004,39.124965713388875,-0.24947833233190794,-0.06763988058173842
333.700000000004,39.230094160670824,-0.2500278443735746,-0.06895308236595055
334.80000000000405,39.33584386727931,-0.24792757666582613,-0.06894688124305581
335.90000000000407,39.443192271419704,-0.24721469676134195,-0.06981498944895126
337.0000000000041,39.54823318198954,-0.24544604090221395,-0.06862491269048432
338.10000000000406,39.65494215368383,-0.24424196966656742,-0.0689660753668897
339.2000000000041,39.76095449909329,-0.24358420264020128,-0.06828897737923478
340.3000000000041,39.86731334925943,-0.24099860533235334,-0.06961005394237052
341.4000000000041,39.97366340241861,-0.24065804229328622,-0.06828660927546926
342.50000000000415,40.080097560400056,-0.23878006037800434,-0.06894898426337903
343.6000000000042,40.185413303155734,-0.23734304506302034,-0.07000180184219884
344.7000000000042,40.29098851587696,-0.2358320244628316,-0.06894605928314768
345.80000000000416,40.3991258460816,-0.23327161437507515,-0.06895563054752696
346.9000000000042,40.50398553968498,-0.2337775570282588,-0.07026998749056279
348.0000000000042,40.61054973400186,-0.23290422874467823,-0.07026980244502523
349.10000000000423,40.71671146834577,-0.232897027456242,-0.06885807806120159
350.20000000000425,40.820338533679646,-0.23267649178287383,-0.07092997065152273
351.3000000000043,40.929139102979434,-0.23083763585037637,-0.06993792424453993
352.4000000000043,41.035300821041936,-0.22913135130090242,-0.06994066444677127
353.5000000000043,41.13904346305696,-0.22888401032354244,-0.07126008282764928
354.60000000000434,41.24852399615514,-0.22875544168097028,-0.07027019727287254
355.7000000000043,41.35418165761015,-0.2262195489341855,-0.07026945408657159
356.80000000000433,41.458656965322,-0.227053510470473,-0.07159012590316483
357.90000000000435,41.56665663151269,-0.22631872775656775,-0.07026912624479964
359.0000000000044,41.67148296698481,-0.22570631196667781,-0.07159010932958898
360.1000000000044,41.779708640500196,-0.22507953151932794,-0.07060000694973656
361.2000000000044,41.885361927587184,-0.22321542537626268,-0.07059993499930783
362.30000000000445,41.993630612065566,-0.2229862777433291,-0.07059993499929451
363.4000000000044,42.099320986448625,-0.22182795836643504,-0.070599705680912
364.50000000000443,42.20607203201983,-0.22202558573535167,-0.07026986833453464
365.60000000000446,42.312423372851235,-0.22075293886361907,-0.07026979491894325
366.7000000000045,42.41888881552859,-0.21984546481767417,-0.0709300082273252
367.8000000000045,42.525832965296836,-0.21993631616378048,-0.07092990094843987
368.9000000000045,42.63190361384296,-0.21770264136068868,-0.07191916425107836
370.00000000000455,42.73879001843851,-0.21835392401002987,-0.07192006899256942
371.10000000000457,42.84608919489214,-0.2166285100055702,-0.07059955981429988
372.2000000000046,42.95285707021034,-0.2158237637338818,-0.07191900077694813
373.30000000000456,43.05921889016536,-0.21661960607495956,-0.07192004900335824
374.4000000000046,43.16610245610745,-0.21427957486607965,-0.07190334171955959
375.5000000000046,43.27282418830176,-0.2134365830475447,-0.07092992851428903
376.6000000000046,43.378749383442994,-0.2145398680380911,-0.07157175925097548
377.70000000000465,43.48657201541446,-0.21339095206104114,-0.0722570944057992
378.8000000000047,43.593548588882996,-0.21292449479921977,-0.0725847243138027
379.9000000000047,43.70021087567423,-0.21188843309514768,-0.07125987784983279
381.00000000000466,43.80597648681404,-0.2093105810269518,-0.0712874183314196
382.1000000000047,43.913246991663016,-0.21001690255759936,-0.07258010901191048
383.2000000000047,44.01980303469232,-0.20783571682380708,-0.07159052417631839
384.30000000000473,44.12744288753691,-0.20813473510159858,-0.07159007434609066
385.40000000000475,44.234060602243,-0.20710180280702972,-0.07291032800062824
386.5000000000048,44.340000000000465,-0.2065999999999914,-0.0705996664766202
387.6000000000048,44.446972851425855,-0.20473040539453802,-0.07328685916110533
388.7000000000048,44.55465215245161,-0.20412559726820012,-0.07324015973083675
389.80000000000484,44.66107451004705,-0.20515488360001355,-0.07155355752906001
390.9000000000048,44.76881923584611,-0.20372990902517213,-0.07157375279316636
392.00000000000483,44.87396325512535,-0.20366961618150128,-0.07284746933609476
393.10000000000485,44.98170422205614,-0.20075909921483395,-0.07357016260195337
394.2000000000049,45.089042522096975,-0.20116925795420776,-0.07357342055816662
395.3000000000049,45.1964040468909,-0.19933670069425802,-0.0712597924682794
396.4000000000049,45.301112198329676,-0.19962413726741782,-0.07125993907901318
397.50000000000495,45.40880389111946,-0.19764795703832877,-0.07390262125312308
398.6000000000049,45.516759174229094,-0.19565286371440602,-0.0737731325225166
399.70000000000493,45.62148352815205,-0.19408027974014513,-0.07257960432032506
400.80000000000496,45.730766671829834,-0.19152688536032209,-0.07173262248767909
401.900000000005,45.83816415863433,-0.18731206482687796,-0.07269506967719508
403.000000000005,45.942998759908036,-0.18554726189961382,-0.07258016294636072
404.100000000005,46.05195928884093,-0.17959331649290458,-0.0726267935234115
405.20000000000505,46.158520569428106,-0.1749430709290214,-0.07290744776527225
406.30000000000507,46.26554445563266,-0.17098281001165092,-0.072912394435237
407.4000000000051,46.3730584882833,-0.1661179228896376,-0.0735256310968877
408.50000000000506,46.4801991020676,-0.16179938742597536,-0.07323188688043647
409.6000000000051,46.58578235433786,-0.157644427367249,-0.07291010612026128
410.7000000000051,46.69253574088298,-0.1571608555261629,-0.07291213533915597
411.8000000000051,46.800910974115055,-0.15700064099194636,-0.07356154899325817
412.90000000000515,46.91000099817175,-0.15936005535847775,-0.07355985599999926
414.0000000000052,47.01624739248979,-0.16355479143515278,-0.07355985599990333
415.1000000000052,47.12430983904001,-0.16995578154685856,-0.07355976526302399
416.20000000000516,47.23133375689632,-0.17273182707390053,-0.07289929752531865
417.3000000000052,47.338064474021515,-0.1755719768268314,-0.07355670612136045
418.4000000000052,47.445369764645875,-0.17928594512477006,-0.07456500135463529
419.50000000000523,47.55202142999572,-0.18027150467123462,-0.07454997003400887
420.60000000000525,47.66018396655596,-0.18281121431116928,-0.0745317516175068
421.7000000000053,47.76801813731416,-0.18251378561538692,-0.0743519922883431
422.8000000000053,47.87544312112511,-0.18250539709676394,-0.07455106896530372
423.9000000000053,47.98174121995454,-0.18242079151988874,-0.0732303692889551
425.00000000000534,48.08918912320699,-0.18063832679670958,-0.07322997018680288
426.1000000000053,48.196849431276114,-0.17973501150789645,-0.07392709259135044
427.20000000000533,48.303959967727444,-0.17942712768097266,-0.07471073160852493
428.30000000000535,48.41131402750212,-0.17870963931500863,-0.07584509037022658
429.4000000000054,48.51875855307369,-0.1772673705819432,-0.07513600174345303
430.5000000000054,48.626618389334624,-0.17702188034606633,-0.0738896055723921
431.6000000000054,48.7337641675994,-0.17593930916695813,-0.07520996922377243
432.70000000000545,48.841347832644786,-0.17579023480491335,-0.07520990435047459
433.8000000000054,48.94678843109997,-0.17437617835464686,-0.07620438039912525
434.90000000000543,49.05457682111605,-0.1738043797685293,-0.07619955781376087
436.00000000000546,49.16351796093948,-0.17378848007626135,-0.07520989138326772
437.1000000000055,49.271738694446704,-0.1711191910904921,-0.07520990823874296
438.2000000000055,49.37892245882891,-0.17073692702217202,-0.07653644300949347
439.3000000000055,49.48619487049244,-0.16817209011485276,-0.07559946123738692
440.40000000000555,49.59333533892148,-0.16893184070025125,-0.07587002745445126
441.50000000000557,49.701205207781626,-0.16675706051076108,-0.07487584987825002
442.6000000000056,49.80556951762509,-0.1647644303692131,-0.07488005001622966
443.70000000000556,49.916348755338966,-0.164723033970487,-0.07553986759313736
444.8000000000056,50.02390832565314,-0.16319389266256512,-0.07554002300152618
445.9000000000056,50.13074159455468,-0.16392081012535165,-0.07553930070706016
447.0000000000056,50.23946081887665,-0.16112613041144008,-0.07620013975086515
448.10000000000565,50.34698105404055,-0.16014950149206789,-0.07620013700477202
449.2000000000057,50.45418241355617,-0.1601426488561282,-0.07619179464502635
450.3000000000057,50.56156958238081,-0.15914848102518578,-0.0775093085165568
451.40000000000566,50.66819544123871,-0.1591812448043088,-0.07492016844402372
452.5000000000057,50.775573845903516,-0.15873469102723972,-0.07487603711322288
453.6000000000057,50.883498138446214,-0.15647427287735444,-0.07618097692912018
454.70000000000573,50.99170987803191,-0.15628984558887576,-0.07619056057455476
455.80000000000575,51.10018922335998,-0.15642603010990336,-0.0755241306652672
456.9000000000058,51.20574321163003,-0.15435786013897815,-0.07625430479623185
458.0000000000058,51.31457162024972,-0.15406439998360208,-0.0758967802499293
459.1000000000058,51.421208566117706,-0.15545970553371521,-0.0761898870500528
460.20000000000584,51.53103830972114,-0.15267445408919345,-0.0761898813281725
461.3000000000058,51.64018446194507,-0.15176366359507226,-0.07751022407160679
462.40000000000583,51.74752003240314,-0.15161330494768133,-0.0775101150007762
463.50000000000585,51.85576929684061,-0.150860105258336,-0.07751011492640902
464.6000000000059,51.96353528294603,-0.1491537767273813,-0.07877850674638731
465.7000000000059,52.071345202166164,-0.14696177969577615,-0.07789013219605723
466.8000000000059,52.1794155326757,-0.14729893469697183,-0.07751011482628734
467.90000000000595,52.286846607758285,-0.145330328704126,-0.07751011500000082
469.0000000000059,52.39520547838125,-0.14191186253830498,-0.0775101150000328
470.10000000000593,52.50365793868941,-0.14274817727097872,-0.07751006466780197
471.20000000000596,52.612133490078875,-0.1401520049483107,-0.07883157048290013
472.300000000006,52.71968651845348,-0.1400084513068077,-0.07784992090713683
473.400000000006,52.82790048088674,-0.13830956790499938,-0.07783778845149358
474.500000000006,52.93508576901819,-0.13842227559910494,-0.07916018850818363
475.60000000000605,53.04318891919753,-0.1380438680183352,-0.07784991745981085
476.70000000000607,53.14896499676495,-0.13772344937782827,-0.07785117450826196
477.8000000000061,53.260293890212736,-0.1356483080235282,-0.07982016576835171
478.90000000000606,53.36849432089744,-0.13406489019465687,-0.07982016799965086
480.0000000000061,53.475853717885414,-0.13356498133007935,-0.0798212432222094
481.1000000000061,53.58474456399909,-0.1322527308247053,-0.07799809584332174
482.2000000000061,53.69374974479827,-0.13061083804147106,-0.0795073144299625
483.30000000000615,53.800557685507336,-0.13020580705917176,-0.08014977253044275
484.4000000000062,53.909507936503154,-0.12816546883029925,-0.08014989509121495
485.5000000000062,54.01866480376973,-0.12546254580343208,-0.07785419915482938
486.60000000000616,54.126567582410814,-0.125744685700503,-0.0785217542884813
487.7000000000062,54.234100632608,-0.1230303309811513,-0.07981991305872249
488.8000000000062,54.34274668214681,-0.12355640170020282,-0.07982041725873756
489.90000000000623,54.45118109413051,-0.12343012794341117,-0.08188218832937366
491.00000000000625,54.55901826350385,-0.12217286690656544,-0.08049197661700047
492.1000000000063,54.66753971866136,-0.1214695571403599,-0.07982003163960005
493.2000000000063,54.77719158263229,-0.12097274770227684,-0.0798201508340961
494.3000000000063,54.88427845665781,-0.11820154573638321,-0.08115980375962195
495.40000000000634,54.99291804466086,-0.11843675643122543,-0.08244908392025696
496.5000000000063,55.100302140878135,-0.11810592244376793,-0.08179997070613876
497.60000000000633,55.20938197683539,-0.11672875069038763,-0.0817999709999997
498.70000000000636,55.31627620760704,-0.11672406944845516,-0.08179997101049441
499.8000000000064,55.42508158836616,-0.11671206715986064,-0.08160781401845085
500.9000000000064,55.53506747029424,-0.11371025380639183,-0.08126329074976812
502.0000000000064,55.64087220928366,-0.11391883463634775,-0.08246021955119609
503.10000000000645,55.75100378214152,-0.11462154777721713,-0.08246021732371167
504.2000000000064,55.85989788176414,-0.11364359641206692,-0.08113976959827252
505.30000000000643,55.968422700392246,-0.1140571123562598,-0.08244975614278305
506.40000000000646,56.07818117607528,-0.11091766978387238,-0.08306936077819849
507.5000000000065,56.185466895361834,-0.11045510327799124,-0.08307472920995451
508.6000000000065,56.29419413823169,-0.11007447961194959,-0.0831197952952043
509.7000000000065,56.403097774379205,-0.10790148942697964,-0.08304410384173311
510.80000000000655,56.511369225015024,-0.10593046695353957,-0.08443017729310931
511.90000000000657,56.62000096858667,-0.10710994362910396,-0.0841590315695071
513.0000000000066,56.728767941160434,-0.10671688772033062,-0.08376714424255338
514.1000000000065,56.83666711664323,-0.10571364910244607,-0.0844387664654751
515.2000000000066,56.94553242290561,-0.10486377660768018,-0.08666072209594944
516.3000000000065,57.05421534909047,-0.10287984202559612,-0.08673545008319383
517.4000000000067,57.16256387700449,-0.099486641508478,-0.08575691515946993
518.5000000000066,57.270090454407224,-0.09841228289152551,-0.08574982699485201
519.6000000000067,57.37883676445365,-0.09715057952634884,-0.08574982691157906
520.7000000000066,57.48801462001975,-0.09672909375062455,-0.08653925875574675
521.8000000000067,57.595935796546954,-0.09761670767783075,-0.08841531305290751
522.9000000000067,57.70483896989684,-0.09678587668879074,-0.08706589703661294
524.0000000000067,57.81349470358671,-0.09510554431379098,-0.0883798050000002
525.1000000000067,57.92130100693701,-0.09560725272608676,-0.08726184659817937
526.2000000000068,58.0299012519763,-0.0930667540727429,-0.08773665325229718
527.3000000000068,58.138291112337946,-0.09300950034808202,-0.08640975603757362
528.4000000000068,58.24643747171147,-0.09158689780054896,-0.08846774720221173
529.5000000000068,58.35594701309935,-0.08952123173811326,-0.08970098357296319
530.6000000000068,58.46395634066801,-0.08870777248491987,-0.08970014700122775
531.7000000000069,58.57256427460588,-0.08791786587524208,-0.08969757918655219
532.8000000000068,58.681111461633435,-0.08754454499910015,-0.09067984324805067
533.9000000000069,58.7897847075873,-0.08608632137684863,-0.09067764932010602
535.0000000000068,58.89808826731476,-0.08615689684970516,-0.08969963475030118
536.100000000007,59.00777289807942,-0.08533659974526732,-0.09102011491471451
537.2000000000069,59.11539272744134,-0.08453318779442338,-0.09102012500000445
538.300000000007,59.22354201542047,-0.08551564072589356,-0.09102013188519686
539.4000000000069,59.33305185669786,-0.08465335558953203,-0.09233849413472939
540.5000000000069,59.442400902980786,-0.08487780899877827,-0.09328000861120289
541.600000000007,59.550404260032316,-0.08443637147348337,-0.09333596983525538
542.700000000007,59.65895342799423,-0.08332658927497062,-0.09333017799512566
543.800000000007,59.768336509435045,-0.08243276496392182,-0.09333017800611865
544.900000000007,59.87815072986311,-0.08037122117953044,-0.0933186489837432
546.000000000007,59.98662502465079,-0.07712117049766573,-0.093000271704474
547.1000000000071,60.094957015068886,-0.07744639479392912,-0.09468291732876599
548.2000000000071,60.20373652854209,-0.07668145277093313,-0.09465123067902503
549.300000000007,60.31313319619717,-0.07421434798964678,-0.09463996980465872
550.4000000000071,60.42104200472985,-0.07288073333151279,-0.09664663555495734
551.500000000007,60.52980733464871,-0.0719859548805307,-0.0972897280776559
552.6000000000072,60.63640294758617,-0.06867809626200784,-0.09627712102075403
553.7000000000071,60.74681215208386,-0.0681850238514107,-0.09630535031429766
554.8000000000072,60.85592073746302,-0.06815665208749291,-0.09727410856319896
555.9000000000071,60.96471162020441,-0.06595203044453951,-0.0972699589977215
557.0000000000072,61.07323097316163,-0.06532698304591297,-0.0972647879154871
558.1000000000072,61.181690261878686,-0.0644963065099946,-0.09728385704352949
559.2000000000072,61.29205656436093,-0.063125059946582,-0.09860000526611978
560.3000000000072,61.400101296837356,-0.06222081423197438,-0.09992829884652599
561.4000000000073,61.50893528609951,-0.06254072660943058,-0.09925528351637247
562.5000000000073,61.61803570771964,-0.05970144751288358,-0.09854514654753288
563.6000000000073,61.72734692212776,-0.05664773347158413,-0.09497607652646778
564.7000000000073,61.83595494939097,-0.055979533356699196,-0.09673861996459898
565.8000000000073,61.944900700695996,-0.05576088449733805,-0.10022496545414894
566.9000000000074,62.05505711172679,-0.05425194296506211,-0.10023956207778006
568.0000000000074,62.164390834580985,-0.05361842358119479,-0.10123068422670611
569.1000000000074,62.27447975334973,-0.05143517615494384,-0.102549971623076
570.2000000000073,62.383942388409466,-0.048942387147166505,-0.10377746045544578
571.3000000000073,62.493856829581546,-0.045194133021874014,-0.10484644541275578
572.4000000000074,62.60167171848468,-0.03848690646102475,-0.10386173164293133
573.5000000000074,62.71049084532183,-0.03264326805626877,-0.10518014275417897
574.6000000000074,62.8198966209018,-0.03990506185081082,-0.10550990835608198
575.7000000000074,62.92907556320843,-0.04323180548869806,-0.10684465438663615
576.8000000000075,63.03756923796068,-0.047485323349869574,-0.10683007329343797
577.9000000000075,63.14801985933544,-0.04730195332808609,-0.10780348028318887
579.0000000000075,63.257621564153936,-0.04590241034299507,-0.10516553997131961
580.1000000000075,63.367079538841885,-0.045357145055015737,-0.10341555858388185
581.2000000000075,63.477044974854856,-0.043152295907223706,-0.10514901332641191
582.3000000000076,63.58799195551788,-0.03978526432874154,-0.10638639513936843
583.4000000000076,63.69694455167732,-0.039321772857447486,-0.11067667639233125
584.5000000000076,63.805186411057626,-0.03842073452876003,-0.11463583653891707
585.6000000000076,63.91538522974646,-0.03573409064343055,-0.11941527756111903
586.7000000000077,64.02370609914824,-0.03548344562856218,-0.12659451386372567
587.8000000000077,64.13382648486954,-0.0352324616887874,-0.12263575569967111
588.9000000000076,64.24181573214801,-0.03352582405900514,-0.11977424331149855
590.0000000000076,64.35268376112384,-0.03167086658350448,-0.11846977242294088
591.1000000000076,64.46171614986521,-0.03060422581334199,-0.11715046634218718
592.2000000000077,64.57088491086195,-0.030831949123254463,-0.11587536941477872
593.3000000000077,64.68041504337198,-0.027528651189239015,-0.11714120500092662
594.4000000000077,64.78950537238342,-0.027886391753016687,-0.11742937044378943
595.5000000000077,64.89904520953779,-0.02553318458701104,-0.11847124444968182
596.6000000000078,65.00899564618143,-0.02388665048173264,-0.11846994429380331
597.7000000000078,65.11889064281732,-0.022906960716203406,-0.11946169712521826
598.8000000000078,65.22713728368657,-0.021074533514515215,-0.11981276169939603
599.9000000000078,65.3346043384714,-0.02087809682047141,-0.1201128168181933
601.0000000000078,65.44570493910328,-0.020016720800431407,-0.12146843748276748
602.1000000000079,65.55594761265841,-0.018652775139942984,-0.12208998596015075
603.2000000000079,65.66473662172555,-0.016991135454008238,-0.12244054597533394
604.3000000000079,65.77436470385054,-0.015141543180918954,-0.1224194819243487
605.4000000000078,65.88359624359606,-0.0134350881002689,-0.1250264083494268
606.5000000000078,65.99277889010175,-0.01247133002320113,-0.1263730067403479
607.6000000000079,66.1028322529993,-0.008998955192509397,-0.1263700611107912
608.7000000000079,66.21256271296532,-0.008626748044595086,-0.1263704825449432
609.8000000000079,66.32143448851869,-0.005063772455199987,-0.12834011269467327
610.9000000000079,66.43146090042775,-0.005272672195917851,-0.12834474452955336
612.000000000008,66.54068881893572,-0.003363047488252992,-0.1296628702571887
613.100000000008,66.64728149388446,0.0007756004258723556,-0.13097092624649997
614.200000000008,66.75773997641392,0.0027568453367984025,-0.130772252934924
615.300000000008,66.8684548961983,0.005854671354097537,-0.13252022720733914
616.400000000008,66.978613856794,0.008037335301613588,-0.13286616185486633
617.5000000000081,67.08867520978505,0.011515361432139644,-0.13390187388825048
618.6000000000081,67.19790797079837,0.0156330919725266,-0.135196918618675
619.7000000000081,67.3043747537861,0.020942932542805912,-0.1362498047046623
620.8000000000081,67.41554500469556,0.02554606478162164,-0.13756920183991683
621.9000000000082,67.52614943008867,0.030729750943971682,-0.13755610788356876
623.0000000000082,67.6340930186052,0.034829514085983594,-0.1388918318514869
624.1000000000081,67.74479653442111,0.040668074645390115,-0.1414048800936687
625.2000000000081,67.85413828406222,0.04661025457645283,-0.14152947508072433
626.3000000000081,67.96322960229489,0.05230535200102926,-0.14283571313089372
627.4000000000082,68.0727052827846,0.06047023827623084,-0.14416101430515615
628.5000000000082,68.18224059780191,0.06860307674682611,-0.14561738642154287
629.6000000000082,68.29257726688996,0.07568442298917576,-0.14678705364046252
630.7000000000082,68.4016196058838,0.08148455168355849,-0.14811779103370082
631.8000000000083,68.51201329527461,0.08827565938934381,-0.1507552405870154
632.9000000000083,68.62144478989708,0.09652702791536061,-0.15208007666272927
634.0000000000083,68.73010179084218,0.10553789794572442,-0.15271386841268786
635.1000000000083,68.8396811811568,0.11450535891252384,-0.15534886207881193
636.2000000000083,68.94969673825814,0.12167265776243058,-0.15797927752580954
637.3000000000084,69.05950533909619,0.1309543307945147,-0.15996456630842815
638.4000000000084,69.16885659317862,0.1411277805081367,-0.1612811205999325
639.5000000000084,69.27839625854028,0.15326059609341627,-0.16392311740076648
640.6000000000083,69.38886862069744,0.1647734432928905,-0.1646392809110364
641.7000000000083,69.49854618407952,0.1737201278968263,-0.16740749009139355
642.8000000000084,69.60731463112901,0.1859410462558683,-0.16992300373136837
643.9000000000084,69.71888587183506,0.19754623797684606,-0.17176661278398075
645.0000000000084,69.82737234240273,0.20826968446121827,-0.1749871695452585
646.1000000000084,69.93806058731883,0.22237677650120105,-0.17719339031243786
647.2000000000085,70.04782779587197,0.23504122544435008,-0.17911438885795494
648.3000000000085,70.15705803473038,0.24964245362966644,-0.18278906522853333
649.4000000000085,70.26742292032704,0.2637776529056034,-0.18538929387820513
650.5000000000085,70.37692560316478,0.27667839986513826,-0.18950218702646726
651.6000000000085,70.48724787590854,0.29055303519709075,-0.19103550936078095
652.7000000000086,70.5959960504675,0.30721148088282124,-0.19585220867327013
653.8000000000086,70.70688255291321,0.32095300716384284,-0.20005597788288254
654.9000000000086,70.81685904440256,0.3367933262172681,-0.20349263922671978
656.0000000000086,70.92649976361795,0.3521322999473956,-0.20709469948756176
657.1000000000087,71.03700221216035,0.36963432815339314,-0.211292840099635
658.2000000000087,71.14757077576029,0.38633167416347736,-0.21438551814133566
659.3000000000086,71.25747054707828,0.4023878798450913,-0.21872527565421285
660.4000000000086,71.36772295725504,0.42109506774793465,-0.22307866983003866
661.5000000000086,71.47630361669313,0.4396195211664309,-0.22747901961164718
662.6000000000087,71.58654815938856,0.4596995843295829,-0.23252499639554491
663.7000000000087,71.69739896885332,0.4770458931747182,-0.237103049437843
664.8000000000087,71.80674304891745,0.4983210229011945,-0.24128785553449061
665.9000000000087,71.91653187840012,0.5197925258504589,-0.24698544257805288
667.0000000000088,72.02755457538242,0.5397905686451493,-0.25162168165632925
668.1000000000088,72.13703227438594,0.5646662977823388,-0.25661032368914416
669.2000000000088,72.24544892140325,0.5851490898442273,-0.26325640746615164
670.3000000000088,72.35553980895519,0.6076913144740361,-0.27020904162636716
671.4000000000088,72.46520203341949,0.6328673827568395,-0.2759150817518998
672.5000000000089,72.57515708545215,0.6556734738054528,-0.2809081195986858
673.6000000000089,72.68538639488057,0.6803425108819613,-0.2877350825068947
674.7000000000089,72.79560263027659,0.7063705062884983,-0.29431474397899526
675.8000000000088,72.90587119351639,0.737154010826112,-0.30143147486158783
676.9000000000088,73.01623430336763,0.761300923496259,-0.30944276672613036
678.0000000000089,73.12680939640481,0.7893597486366131,-0.31499686361293744
679.1000000000089,73.23752840027386,0.8187264064180915,-0.3227006640100103
680.2000000000089,73.3465165587632,0.8461342212435522,-0.32976707916617576
681.3000000000089,73.45758004289777,0.873106579972562,-0.3390993122964816
682.400000000009,73.56733814264976,0.9025522339415414,-0.348165280254475
683.500000000009,73.67830401104656,0.9328508112537667,-0.35531574419107814
684.600000000009,73.78837446996842,0.964700028955158,-0.3633705392293227
685.700000000009,73.89785800575548,0.9945448493398005,-0.3727948606067759
686.800000000009,74.00658337361315,1.028604388324638,-0.3817970943637836
687.9000000000091,74.11897580641697,1.0602173788948717,-0.3912545496171269
689.0000000000091,74.22908194995368,1.0950485988130085,-0.4015747110626684
690.1000000000091,74.3398940325882,1.130068885790118,-0.41106054913530166
691.2000000000091,74.45011430847792,1.1627923423586874,-0.42148027056962256
692.3000000000092,74.56022625221348,1.1950268845011731,-0.4320398857023844
693.4000000000092,74.67092975675709,1.2283375408141417,-0.442487769313757
694.5000000000091,74.78092607267925,1.2621758743920881,-0.4539354905618955
695.6000000000091,74.89020106767094,1.2984173732180542,-0.4655124037830518
696.7000000000091,75.0011152004278,1.3317845214740889,-0.4768129067906397
697.8000000000092,75.11163777678324,1.3685859357529702,-0.48934534872500457
698.9000000000092,75.21908253032166,1.4033239941128761,-0.5002785023276264
700.0000000000092,75.3302738749807,1.4402931786968807,-0.5129567916292905
701.1000000000092,75.44113249316267,1.4717574656640247,-0.5256510112515933
702.2000000000093,75.55100483420121,1.508856776760209,-0.5394735101713151
703.3000000000093,75.66074182991579,1.5424801901155474,-0.5526728098728215
704.4000000000093,75.77075039059183,1.576576712639871,-0.5659466555055856
705.5000000000093,75.88182870929909,1.6119037559460396,-0.5788541977994743
706.6000000000093,75.9918697417605,1.6452628319461888,-0.5929563572650931
707.7000000000094,76.10271996624984,1.6806089959017396,-0.6084236369132023
708.8000000000094,76.21383664171586,1.7159990666237883,-0.6215941039150117
709.9000000000094,76.32392528798177,1.7498156190204808,-0.6371142756742021
711.0000000000093,76.43418746611093,1.7815835352018565,-0.6523788910942825
712.1000000000093,76.54412215509566,1.8158284461142233,-0.6675072648722398
713.2000000000094,76.65263810472153,1.8475539730039745,-0.6838477200335378
714.3000000000094,76.76288342501627,1.8803064830663334,-0.7010086193085816
715.4000000000094,76.8743994902844,1.9142623689267466,-0.7182248907896471
716.5000000000094,76.98420998791472,1.9461767092437015,-0.7331907706832888
717.6000000000095,77.09433069428987,1.9796336458929575,-0.7499301729449823
718.7000000000095,77.20438698445776,2.0126413004775654,-0.7658621319394192
719.8000000000095,77.31411940100278,2.044866760336729,-0.782620159035428
720.9000000000095,77.42488859975812,2.079505119400525,-0.8016089672754183
722.0000000000095,77.53503825054136,2.1104475459487406,-0.8185510650091836
723.1000000000096,77.64464349687756,2.1418085185562066,-0.837267138709243
724.2000000000096,77.75501624598472,2.1746826218294357,-0.8551684331423677
725.3000000000096,77.86627806885086,2.205356252261572,-0.8734345306364868
726.4000000000096,77.97458056254852,2.2406258549611593,-0.8922005590023581
727.5000000000097,78.08383564753504,2.271938529450132,-0.9106106558502298
728.6000000000097,78.19494935888702,2.3068443773051803,-0.9309356051174875
729.7000000000096,78.30416213708487,2.33573768706246,-0.9501781862647145
730.8000000000096,78.41687386783082,2.3693534614550655,-0.9686870663932212
731.9000000000096,78.52767231506803,2.3976017967022707,-0.9897898201522439
733.0000000000097,78.63833547944539,2.4258917635618724,-1.0104982450846913
734.1000000000097,78.74735776415038,2.454484683053111,-1.0309446754526275
735.2000000000097,78.85874349231402,2.4811039491935407,-1.04983323192638
736.3000000000097,78.96904307583614,2.5068014310885753,-1.0713280452779395
737.4000000000098,79.07939880232642,2.5335901283296938,-1.0938996083196582
738.5000000000098,79.18870627870852,2.559481537966156,-1.1132314145601288
739.6000000000098,79.30029153199543,2.600227975641753,-1.1363372881391358
740.7000000000098,79.4096275771068,2.653353157269019,-1.1563184235098367
741.8000000000098,79.52092240532959,2.7147713141007506,-1.1782986009198724
742.9000000000099,79.63011016566003,2.792001898250168,-1.2008383748174447
744.0000000000099,79.74291293064749,2.875618947897365,-1.2221116161348013
745.1000000000099,79.85326479132773,2.9567353802962733,-1.246087834704844
746.0000000000099,79.94475998775623,3.019764035218656,-1.2650281505255117