File: 01_Data/Concrete_Block/STA/N2/10K_min/Concrete_Block_STA_N2_10KData_220912_R1.csv
##Temp./Â°C,Time/min,DSC/(mW/mg),Mass loss/mg
51.0,10.89,-1.49209,-0.00886494706188401
52.100000000000016,11.212853353780002,-1.39132283853593,-0.010151342161058174
53.20000000000003,11.446866000137351,-1.325443096408924,-0.010369740392399684
54.30000000000005,11.649860117822408,-1.2717575129562908,-0.010294937678069438
55.40000000000006,11.829143899719966,-1.2312996082860421,-0.011536132607339766
56.50000000000008,11.999690264557602,-1.1993063548400116,-0.011172728247250241
57.600000000000094,12.160621413927354,-1.1685603487941236,-0.009962753531926438
58.70000000000011,12.315049958853708,-1.145324608878203,-0.008790147922040248
59.800000000000125,12.463488888944424,-1.123701307002936,-0.011528164267205376
60.90000000000014,12.609257875228325,-1.1042980360105208,-0.010572363246341254
62.000000000000156,12.750476613621489,-1.0856453872576148,-0.011235505876782348
63.10000000000017,12.890000000000024,-1.0688299999999955,-0.011614287602073503
64.20000000000019,13.025970051025629,-1.0557633363955439,-0.011831797564995306
65.30000000000021,13.161631487820916,-1.041495092195311,-0.012269573502145192
66.40000000000022,13.293884494736739,-1.027883583370162,-0.011738746224652985
67.50000000000023,13.42413975298207,-1.0158735310451148,-0.011621513237684233
68.60000000000025,13.553740600341168,-1.00239775607777,-0.012014936273469168
69.70000000000027,13.682795244606707,-0.9924527534807469,-0.012037401909494427
70.80000000000028,13.811615870888799,-0.979844400185214,-0.012747913767227281
71.90000000000029,13.9364944223356,-0.9668395356520071,-0.012825927456488806
73.00000000000031,14.058409805788866,-0.9567709102213915,-0.01149700802166187
74.10000000000034,14.183032680191413,-0.9447214718909419,-0.012825236418021468
75.20000000000034,14.30517307054741,-0.9339322519804648,-0.012781922649442556
76.30000000000035,14.428572213696098,-0.9217600153769853,-0.013255571574881664
77.40000000000038,14.547927018522044,-0.9124318858256214,-0.014140479023231123
78.5000000000004,14.66678453509135,-0.9024362928195698,-0.013753022942578852
79.6000000000004,14.78667753893656,-0.8920390999665987,-0.014237786321336543
80.70000000000041,14.905109012074675,-0.8823100805327797,-0.01425006136676732
81.80000000000044,15.02247741435665,-0.8740887780968617,-0.015470147730251682
82.90000000000046,15.138914466998697,-0.8647061825800061,-0.01418513300919777
84.00000000000047,15.256094706836043,-0.8548144400913303,-0.014522902083677458
85.10000000000048,15.370602902830763,-0.8478352369555285,-0.015455861176111974
86.2000000000005,15.48531166018203,-0.8399063760294799,-0.01589771229787118
87.30000000000052,15.601180035934435,-0.8316373411039242,-0.016267225011444175
88.40000000000053,15.713131627159012,-0.8227957411593534,-0.016820658242093778
89.50000000000054,15.827141533378738,-0.8155775336809967,-0.016435763644075507
90.60000000000056,15.94144880852528,-0.8083300287990581,-0.018035894468158453
91.70000000000059,16.047813136353497,-0.8014937454507044,-0.015543729006281204
92.8000000000006,16.163320304522784,-0.7937410908137532,-0.0194021653757801
93.9000000000006,16.27441565505692,-0.785994109060727,-0.02075205312729622
95.00000000000063,16.384525200778373,-0.7793967164803898,-0.01946112480944784
96.10000000000065,16.496139237388615,-0.7710560095672465,-0.019420837919259526
97.20000000000066,16.607802866251376,-0.7659751569475217,-0.01972058963200407
98.30000000000067,16.71652438873907,-0.7589837565211812,-0.01997709713400031
99.40000000000069,16.826184980007966,-0.7510404786556042,-0.02075748895315499
100.50000000000071,16.93509574855411,-0.7466092741129924,-0.020740909640426075
101.60000000000072,17.043949213191844,-0.738957502630239,-0.021816671676070598
102.70000000000073,17.153645145671852,-0.7338633500017805,-0.02206015796068339
103.80000000000075,17.26166156377056,-0.727469709345308,-0.02208574607517022
104.90000000000077,17.371154026348915,-0.7206095983211559,-0.0233060101499607
106.00000000000078,17.479813378032844,-0.7140057884969173,-0.02338015704243901
107.10000000000079,17.586188993301324,-0.7072030374434659,-0.02338155618255211
108.20000000000081,17.695219659531382,-0.7030367361786528,-0.024699948288627205
109.30000000000084,17.802866780654067,-0.6957602774825062,-0.024697683371806
110.40000000000084,17.91000000000009,-0.6908099999999956,-0.02601935320568849
111.50000000000085,18.018798386128744,-0.6856054104715287,-0.024843239485419666
112.60000000000088,18.126128376095455,-0.6803083427139773,-0.02470015414846216
113.7000000000009,18.2337203422252,-0.6738776492999797,-0.02462083548726568
114.8000000000009,18.34140377365345,-0.6692613199309095,-0.02600995498564096
115.90000000000092,18.449674979613473,-0.6653360268760752,-0.026010056132053982
117.00000000000094,18.557009493761555,-0.6608801200072153,-0.02633981562431309
118.10000000000096,18.664918159169755,-0.6571468698058687,-0.027350674443511025
119.20000000000097,18.768776572210008,-0.6537504000203072,-0.02734218133739752
120.30000000000098,18.87791605891168,-0.6490786645417801,-0.028647363857451147
121.400000000001,18.984574069143203,-0.6460251991974398,-0.028327681555594175
122.50000000000102,19.09021061504563,-0.6430189191830722,-0.02865196139787063
123.60000000000103,19.197771534775228,-0.6384308041038493,-0.029960364385416938
124.70000000000104,19.304193265725267,-0.6336915791664773,-0.028650927565378126
125.80000000000106,19.41200107549502,-0.6310388935183106,-0.028575488877746302
126.90000000000109,19.517616103229848,-0.6263227116802419,-0.029966051143589745
128.00000000000108,19.624229925856213,-0.6217794439785344,-0.029631055464563794
129.1000000000011,19.73049419781664,-0.6184638011530864,-0.029874497312896153
130.20000000000113,19.83559954959957,-0.6143889853249117,-0.03128004398388917
131.30000000000115,19.941379559164027,-0.6106211212923945,-0.031318709095036645
132.40000000000117,20.048935934896914,-0.6061930419229361,-0.03130352294288752
133.50000000000117,20.154317152821303,-0.6027124401648929,-0.03161375798506416
134.6000000000012,20.25963286000132,-0.5993945129090603,-0.03126574777147795
135.7000000000012,20.363166145441582,-0.5950613864756382,-0.031768546586063096
136.8000000000012,20.470638081180585,-0.5920084205989524,-0.030246649861576103
137.90000000000123,20.576505532302935,-0.5880185609165156,-0.031128527519904914
139.00000000000125,20.682267817769954,-0.5843670180409961,-0.033397139737990855
140.10000000000127,20.786974995167164,-0.580006118792866,-0.03338997844386604
141.2000000000013,20.89226249839847,-0.5768806080741272,-0.03193996111735764
142.3000000000013,20.99840186066337,-0.5736641243814675,-0.03227107945487884
143.4000000000013,21.103213657213356,-0.5696668476874592,-0.0336441109039578
144.50000000000134,21.2078029595049,-0.5646364393126142,-0.0329399133682049
145.60000000000133,21.31266460046697,-0.5623051171139354,-0.032280086233862804
146.70000000000135,21.41715328600865,-0.559532167879006,-0.03359004875773497
147.80000000000138,21.52338267101139,-0.5553191761467454,-0.033938934867951076
148.9000000000014,21.628058465743116,-0.5510992857818618,-0.03360253583396755
150.00000000000142,21.732137928747683,-0.547071749437635,-0.035217691089214576
151.10000000000142,21.83767347165094,-0.542771294885892,-0.034589858355459135
152.20000000000144,21.941882396098453,-0.5390915754471332,-0.03455334105647179
153.30000000000146,22.046240900427126,-0.5352971677641198,-0.03587475471610091
154.40000000000146,22.150791693536878,-0.532429028269134,-0.03489969467071319
155.50000000000148,22.255791508535047,-0.5276686875289069,-0.036220081699697815
156.6000000000015,22.360261819962215,-0.5247424922996645,-0.03622060467818766
157.70000000000152,22.46378571230197,-0.522723523033161,-0.036228554663761514
158.80000000000155,22.56919789709611,-0.520499944883318,-0.0355663996994684
159.90000000000154,22.67404894005424,-0.5156934202656775,-0.03623571783906154
161.00000000000156,22.77926905645976,-0.5125356736211139,-0.03754318750912233
162.1000000000016,22.884650104678872,-0.5105120298394834,-0.03621995033872061
163.20000000000158,22.986491161655785,-0.5064973288657214,-0.036219980254641015
164.3000000000016,23.09015074444349,-0.5013004992960256,-0.03623461217794777
165.40000000000163,23.197479307642094,-0.4995260106456557,-0.037068820261731084
166.50000000000165,23.301079413895913,-0.49549180229512724,-0.03753471175169043
167.60000000000167,23.40653284488734,-0.4934337882768961,-0.03753970475968149
168.70000000000167,23.51116175228386,-0.48868847009153915,-0.037540081891311416
169.8000000000017,23.615597039267218,-0.4877783128625466,-0.03753284711651084
170.9000000000017,23.71965761094488,-0.48363955635092576,-0.038973122113378444
172.0000000000017,23.824333366623495,-0.4815817512027038,-0.037649827487696186
173.10000000000173,23.929998991790832,-0.47738002095972115,-0.03764526568560278
174.20000000000175,24.03468040945438,-0.4755844001802314,-0.0379805585803652
175.30000000000177,24.13902525298225,-0.4735156776853786,-0.0389681040925014
176.4000000000018,24.24475269873941,-0.4713427027936499,-0.037617128279187284
177.5000000000018,24.349740082820038,-0.4670417439388817,-0.0390617643503397
178.6000000000018,24.453686212566407,-0.465016016808484,-0.03896995931027103
179.70000000000184,24.558998444244608,-0.46114282568215753,-0.039346958356507145
180.80000000000183,24.663932319827953,-0.45725039103635345,-0.04029002295791351
181.90000000000185,24.768457702483452,-0.45403796364391824,-0.03896909985750341
183.00000000000188,24.872874956282008,-0.4514341172570705,-0.03863986967980804
184.1000000000019,24.9780285747464,-0.44954150499717405,-0.03996016547444903
185.20000000000192,25.081553071200535,-0.4464849756294995,-0.04127988224776313
186.30000000000192,25.18678084070695,-0.44327394548475146,-0.03995958970711477
187.40000000000194,25.29134006542944,-0.4401717693550863,-0.04118414428200179
188.50000000000196,25.394649945194907,-0.43587676311281826,-0.04028008562830454
189.60000000000196,25.49926915491479,-0.4330527721038562,-0.040427899170262016
190.70000000000198,25.60426123087536,-0.43082922429347625,-0.04160009692768263
191.800000000002,25.707204371482476,-0.4285311270753955,-0.04129681117463235
192.90000000000202,25.813564512482802,-0.42508833120160117,-0.04127998419923262
194.00000000000205,25.918019141812895,-0.423683879055004,-0.04128001958192673
195.10000000000204,26.021959569536598,-0.4200460884706564,-0.039953389601950384
196.20000000000206,26.12567976147874,-0.41755547790360814,-0.04128015042755795
197.3000000000021,26.23029886505476,-0.4153808922676343,-0.041280138153616974
198.40000000000208,26.3350475471765,-0.41252070600956264,-0.04255844864623448
199.5000000000021,26.439209688234126,-0.4085507318373156,-0.04126990051626045
200.60000000000213,26.54388292486348,-0.4063776222388435,-0.04228795442824573
201.70000000000215,26.64759800051208,-0.40325873972580367,-0.04103985447871672
202.80000000000217,26.75229313652002,-0.4010896532599227,-0.04126231292877858
203.90000000000217,26.85738944057022,-0.39768448856525696,-0.040170035887122424
205.0000000000022,26.961585387735123,-0.39621270848565887,-0.04259892679821675
206.1000000000022,27.066259021283678,-0.39235037628631925,-0.042624115236608695
207.2000000000022,27.170202425884135,-0.3895185262068248,-0.042600029029871145
208.30000000000223,27.27518787110222,-0.3858415492742001,-0.041245873656736265
209.40000000000225,27.379811118772828,-0.3845217261730036,-0.04291540320672471
210.50000000000227,27.484256887761948,-0.3814419256131573,-0.042919841068114195
211.6000000000023,27.587600165244755,-0.37795538865434525,-0.04291984027629692
212.7000000000023,27.69189473435469,-0.376288943234094,-0.042859372901566495
213.8000000000023,27.797359080228105,-0.37125149962468845,-0.04258999309584244
214.90000000000234,27.901709645396764,-0.37027649933879997,-0.042927024945596415
216.00000000000233,28.00432948839128,-0.36620404387851574,-0.042929873608952285
217.10000000000235,28.10980498104215,-0.36471766665496513,-0.043916984903589196
218.20000000000238,28.213784606764577,-0.3614052085085299,-0.044239606513525764
219.3000000000024,28.319805343549035,-0.35784633715616043,-0.044240154969426015
220.40000000000242,28.423434915135424,-0.3543599610961731,-0.04329923046820827
221.50000000000242,28.528123691125558,-0.3511572856526198,-0.04424016474962933
222.60000000000244,28.63311811239856,-0.3486167659894291,-0.044227932304847783
223.70000000000246,28.73658282821742,-0.3448296946599612,-0.042590834924105536
224.80000000000246,28.83918615662023,-0.3430388114402932,-0.0435800540688831
225.90000000000248,28.94481078087084,-0.3406418694192817,-0.04354499059450756
227.0000000000025,29.050090493639043,-0.33665950993404753,-0.04493520102127224
228.10000000000252,29.153990427513907,-0.33681864448200427,-0.0462052251515388
229.20000000000255,29.257690615136006,-0.3352416333114306,-0.045692633184128084
230.30000000000254,29.36289075444529,-0.3316744742298094,-0.04539699883093817
231.40000000000256,29.466998413863465,-0.3283072858007379,-0.04391145300561217
232.5000000000026,29.57121331552044,-0.32661807836352746,-0.04388351848241889
233.60000000000258,29.675890401772726,-0.325618901726585,-0.043615396896973024
234.7000000000026,29.780836931849016,-0.32311976333802195,-0.0449186057351838
235.80000000000263,29.884993670774183,-0.3208419819810833,-0.045205620319388906
236.90000000000265,29.988460770833566,-0.31936777891676,-0.04522000509777957
238.00000000000267,30.093022777677817,-0.31636262754718897,-0.04523134209314961
239.10000000000267,30.197175480182704,-0.31329427093951173,-0.0462101269740991
240.2000000000027,30.2991092243227,-0.3120147546803418,-0.04653259658632436
241.3000000000027,30.405350717363522,-0.3082534207939204,-0.04654012700213883
242.4000000000027,30.510630294311238,-0.3060265446696579,-0.04654002342944885
243.50000000000273,30.613028778531948,-0.30346945631646605,-0.045229919918391204
244.60000000000275,30.718903758649923,-0.3029691266396379,-0.04655015170064569
245.70000000000277,30.822032536629884,-0.3001783781163715,-0.04655010000001791
246.8000000000028,30.9275224205332,-0.29868432419685736,-0.04655010011255367
247.9000000000028,31.03136940603059,-0.2963863560447597,-0.04651044986549113
249.0000000000028,31.13652851468796,-0.29602991070517665,-0.046536218123261364
250.10000000000284,31.242171600766074,-0.29182740382466626,-0.04719618279783688
251.20000000000283,31.3449038581394,-0.2898909094715101,-0.04719956458317487
252.30000000000285,31.44925586817461,-0.2897062792956389,-0.04720013099985021
253.40000000000288,31.554958651109036,-0.2879090605787383,-0.04720030252242502
254.5000000000029,31.659044832622374,-0.28668372352541266,-0.04687003537622303
255.60000000000292,31.764765666920244,-0.2856445453242886,-0.046870275523494875
256.7000000000029,31.868507036407042,-0.2826141576656843,-0.04818961069071115
257.8000000000029,31.97274508667078,-0.28127812248375517,-0.047199913572315566
258.90000000000293,32.07884196815385,-0.27900238018848955,-0.04840173813257387
260.00000000000296,32.181957059325,-0.2778269646434411,-0.049840135842881494
261.100000000003,32.28865191200782,-0.2753793018511083,-0.04897983617710544
262.200000000003,32.39298658118449,-0.27343079976303686,-0.0471997786532814
263.300000000003,32.49770256867697,-0.2718474850307392,-0.04851938683720647
264.40000000000305,32.601622180689716,-0.26968802335675585,-0.04713950537324241
265.50000000000307,32.70755625050721,-0.2697220538896088,-0.04918016128376479
266.6000000000031,32.811987700768874,-0.26589890300885977,-0.04845903628998105
267.7000000000031,32.91686686712724,-0.26265849088669374,-0.04852107189668242
268.8000000000031,33.020771745757045,-0.2626452193734921,-0.04719759697886605
269.9000000000031,33.125552664169064,-0.2600337333793178,-0.04720109140793394
271.0000000000031,33.23190975328141,-0.25736631567110635,-0.04983782853738372
272.10000000000315,33.33489841166243,-0.2553232862427948,-0.04851999681942232
273.2000000000032,33.44123116914316,-0.2538977948458696,-0.04852000899997222
274.30000000000314,33.54550899903693,-0.25187673448460285,-0.04851994249889113
275.40000000000316,33.650584052324355,-0.2509138758853087,-0.04752992490720498
276.5000000000032,33.75561013763003,-0.2506893999829305,-0.04752867732945809
277.6000000000032,33.86020581475308,-0.24826280261595832,-0.04884980747810275
278.70000000000323,33.965405677463856,-0.24584204539178348,-0.048849820000004485
279.80000000000325,34.07045603110345,-0.24425230176182144,-0.048849819998960875
280.9000000000033,34.174694171470534,-0.2425426278460523,-0.04884201066544236
282.0000000000033,34.2804779483539,-0.24083602343611257,-0.04987703311706415
283.1000000000033,34.38541045517229,-0.23944694818839507,-0.049840165984489815
284.20000000000334,34.49065964734907,-0.23684425579096993,-0.04984016999573804
285.30000000000337,34.5950668041958,-0.2349295093425843,-0.048521865608155856
286.40000000000333,34.700410457955904,-0.23399367387913614,-0.04852590779462407
287.50000000000335,34.80551199470217,-0.23171553567139688,-0.04983492195082739
288.6000000000034,34.9112901498044,-0.22935875097380093,-0.04982124379707997
289.7000000000034,35.01600059013417,-0.22827082140989954,-0.05015998342485606
290.8000000000034,35.12128442451628,-0.22598106367515777,-0.05081784376770404
291.9000000000034,35.22568948990944,-0.2246217872253305,-0.05015580300834266
293.0000000000034,35.33055164494829,-0.22156169728872113,-0.050131106647511636
294.10000000000343,35.43687533692414,-0.22122989623999206,-0.049509950245806955
295.20000000000346,35.541298406690345,-0.21960778413035753,-0.049530356860587155
296.3000000000035,35.645523732441006,-0.2184350082410764,-0.050562538648572186
297.4000000000035,35.752388298218676,-0.21760549919489228,-0.05082755781418946
298.5000000000035,35.8580828690443,-0.21586132397136126,-0.05016981915643193
299.60000000000355,35.96292372244551,-0.21431752206962779,-0.04943081232127877
300.70000000000357,36.06868408576045,-0.21334659095436398,-0.05012534692881587
301.8000000000036,36.17484143903246,-0.21179138508356601,-0.052480401428093515
302.9000000000036,36.280422338231524,-0.21172182573064563,-0.05116009614912986
304.0000000000036,36.38568068095873,-0.21026407816106776,-0.051160107567922
305.1000000000036,36.49142526511308,-0.20770846303148888,-0.05116753207569413
306.2000000000036,36.5959221734692,-0.20570365512404012,-0.051169110219576375
307.30000000000365,36.70267989165327,-0.2038429446484934,-0.05082998618981094
308.4000000000037,36.80763872216771,-0.20317815658908764,-0.05082998101432956
309.5000000000037,36.91387154926675,-0.2021737015370516,-0.05082998099999969
310.60000000000366,37.019235149834536,-0.20024689727768158,-0.05082998099999969
311.7000000000037,37.1235175781135,-0.19893258361346766,-0.0508299809999988
312.8000000000037,37.23070073927768,-0.19658308397721078,-0.05082998100000147
313.90000000000373,37.33638852925747,-0.19617181406861242,-0.05082998052362342
315.00000000000375,37.44095496398,-0.19437944510141567,-0.051171313066546986
316.1000000000038,37.547915068833,-0.19382989459810498,-0.05180592451295496
317.2000000000038,37.65175834739423,-0.19113095068238237,-0.05246983747883327
318.3000000000038,37.758612737067104,-0.18933243239273645,-0.05147400142795
319.40000000000384,37.86406572630149,-0.18790831664071328,-0.052800202610325364
320.5000000000038,37.970379536502676,-0.18562167895620268,-0.05280020099999483
321.60000000000383,38.0747053897515,-0.183940592561151,-0.052800162939130146
322.70000000000385,38.179300649077454,-0.1827170330327671,-0.052470219764044757
323.8000000000039,38.28775248865766,-0.18055328016867636,-0.05247013799984135
324.9000000000039,38.39266280241211,-0.17944861935441833,-0.05247013799983247
326.0000000000039,38.498769329854426,-0.17761393666984995,-0.05246990299658094
327.10000000000394,38.60459542285452,-0.1770848897713439,-0.05379043080568913
328.2000000000039,38.71018363272093,-0.17539028744976692,-0.0537901380000374
329.30000000000393,38.817054560591636,-0.174918726779844,-0.053790270147133334
330.40000000000396,38.920913047687385,-0.1737990012552521,-0.05510998818573043
331.500000000004,39.02846514843744,-0.17274070018842805,-0.05379018259105983
332.600000000004,39.134090857166576,-0.17198834670730218,-0.05374058027659778
333.700000000004,39.23981314037212,-0.17057707534553224,-0.05445013788047515
334.80000000000405,39.345635118737334,-0.16968331429525738,-0.05445013799999998
335.90000000000407,39.45175832638437,-0.16935461734645882,-0.05445013797417264
337.0000000000041,39.55860776714349,-0.16598292644646714,-0.054436934222642286
338.10000000000406,39.664786642049165,-0.1641390647080597,-0.055110138339218295
339.2000000000041,39.770561327096885,-0.16440533062225365,-0.05511013800000075
340.3000000000041,39.87760010286688,-0.1634711859484578,-0.055110139591706186
341.4000000000041,39.98429564914776,-0.15927207908382648,-0.05378263117041815
342.50000000000415,40.09091862351769,-0.15856612871689524,-0.0550968520929116
343.6000000000042,40.19572251140754,-0.15659514763181134,-0.05511168849455306
344.7000000000042,40.302449405187616,-0.15450561480210817,-0.05576016344571322
345.80000000000416,40.409018852638084,-0.15308157486136456,-0.055760533206492546
346.9000000000042,40.515261423080226,-0.15127348238649319,-0.056420161973691485
348.0000000000042,40.62114996316341,-0.15059156978412638,-0.05642013799999823
349.10000000000423,40.72709943120068,-0.14732940170950437,-0.056420151081393755
350.20000000000425,40.83296176650974,-0.14669682899834785,-0.056090663814747366
351.3000000000043,40.93945466152693,-0.1439848917656547,-0.056090184971299806
352.4000000000043,41.046478856113126,-0.1433908612100508,-0.0554300052132799
353.5000000000043,41.15055171654126,-0.14255445359253907,-0.0554299490458412
354.60000000000434,41.256073676776516,-0.1417926452824856,-0.056037789921740355
355.7000000000043,41.365529467590456,-0.14099565261688377,-0.0577401946887619
356.80000000000433,41.472439188196965,-0.14017610219995322,-0.057739760340032475
357.90000000000435,41.57864444232087,-0.13997355799199662,-0.057392250850294424
359.0000000000044,41.683566037041864,-0.13745296812221675,-0.05641598376825385
360.1000000000044,41.789896403231836,-0.13678293434660804,-0.0574102010032016
361.2000000000044,41.89650568254361,-0.13693382590891026,-0.05741020100000771
362.30000000000445,42.003107487084215,-0.1364428744205588,-0.05741018082011795
363.4000000000044,42.10958143128142,-0.13270999471429298,-0.05873058315144686
364.50000000000443,42.215745811601415,-0.1324121860652155,-0.05633956114272909
365.60000000000446,42.322788740850285,-0.13143781690722328,-0.05608999155845318
366.7000000000045,42.42920908274477,-0.12921106565942717,-0.05669090214471151
367.8000000000045,42.53543089945212,-0.12839185921618676,-0.058729299315576355
368.9000000000045,42.64207591063929,-0.12818620019486437,-0.05741082938505482
370.00000000000455,42.749102246521964,-0.12512946174702885,-0.058730102921981775
371.10000000000457,42.85586903011887,-0.12485292466237267,-0.059796492050568695
372.2000000000046,42.96154873490936,-0.1236197094635169,-0.05939020116243743
373.30000000000456,43.069076809465564,-0.1217140051208942,-0.059390200999999365
374.4000000000046,43.17467860535574,-0.12003102905210104,-0.05939020100000114
375.5000000000046,43.28211459870478,-0.11877465778971535,-0.059390200995006914
376.6000000000046,43.38809086533801,-0.1184459086532579,-0.059384229080150064
377.70000000000465,43.494464661321224,-0.11640514359334676,-0.06076610483982137
378.8000000000047,43.60120112704404,-0.11479161030721342,-0.06070876277161208
379.9000000000047,43.706919759276886,-0.11517037940116481,-0.06036915273474719
381.00000000000466,43.814124203530206,-0.1134944915862199,-0.06005019977700066
382.1000000000047,43.92021849845886,-0.11355382723590582,-0.060050201000001024
383.2000000000047,44.02741324421657,-0.1124440709916367,-0.060050200999991254
384.30000000000473,44.133266887131484,-0.1113430907314996,-0.06005021268627875
385.40000000000475,44.24091874658045,-0.11040545559260592,-0.05872833486828366
386.5000000000048,44.34772465631552,-0.10855947552516036,-0.058730712070950375
387.6000000000048,44.45483043198634,-0.10823650261954633,-0.060050134380823295
388.7000000000048,44.559763694259374,-0.10759888503004464,-0.060048771840999215
389.80000000000484,44.66810590890924,-0.10672066382337345,-0.058729802325714786
390.9000000000048,44.77514113252562,-0.10457274026240382,-0.06069944416631046
392.00000000000483,44.88261801162964,-0.10533878103707,-0.06069979742966769
393.10000000000485,44.98969577891326,-0.1028293015305981,-0.060040116805192945
394.2000000000049,45.09629372060321,-0.10119456317191472,-0.06004007499968367
395.3000000000049,45.203766144809734,-0.09997994236185637,-0.060040075000191706
396.4000000000049,45.30981494958042,-0.09946805738789222,-0.06003959853127494
397.50000000000495,45.41742036947263,-0.0969291925161008,-0.06005527170549829
398.6000000000049,45.52263320012588,-0.09564829425189769,-0.06037985481853436
399.70000000000493,45.6312290306935,-0.09275500590257317,-0.06037985500000076
400.80000000000496,45.73858263781853,-0.09183098766153261,-0.06037985500000431
401.900000000005,45.84417729809499,-0.08866415320421461,-0.06037984703303678
403.000000000005,45.95266020795328,-0.08520557078356916,-0.06070935684575307
404.100000000005,46.059482457983066,-0.08224780063197687,-0.06071001276843102
405.20000000000505,46.166070831026005,-0.07643818162933358,-0.05938869423027615
406.30000000000507,46.273626758163196,-0.07019419725086347,-0.06070912430020137
407.4000000000051,46.37916423467612,-0.06411871716310129,-0.06070991799979808
408.50000000000506,46.487407732650894,-0.05730670699318281,-0.06070991800000236
409.6000000000051,46.595570227834706,-0.05353953650450923,-0.060709920003260365
410.7000000000051,46.70217281980772,-0.048941014672826966,-0.061356609052465316
411.8000000000051,46.809430278279315,-0.04487251129562901,-0.061370169985702105
412.90000000000515,46.91665557263576,-0.04440879009313534,-0.061370512059818694
414.0000000000052,47.02410951940081,-0.0453990022136651,-0.06268014315405956
415.1000000000052,47.13119906067446,-0.04764624391544774,-0.061342244047920325
416.20000000000516,47.238631066563315,-0.05125091556170092,-0.06201982970846309
417.3000000000052,47.345058707660314,-0.055701966380091464,-0.06334110284371341
418.4000000000052,47.4518159402141,-0.061568207413130696,-0.062680254084027
419.50000000000523,47.55982333689994,-0.06430727241087242,-0.0626802018756285
420.60000000000525,47.66751671410319,-0.06763307930134611,-0.061370014947440765
421.7000000000053,47.774356483724645,-0.06902334171723015,-0.06268003663791166
422.8000000000053,47.88197128769587,-0.07033435150297773,-0.0633399092293292
423.9000000000053,47.98863986535011,-0.06932985436271417,-0.06334064112017312
425.00000000000534,48.09571593259677,-0.06883947658164948,-0.06202017263492099
426.1000000000053,48.203958981493415,-0.06751742345149113,-0.06330047874272982
427.20000000000533,48.31142249392339,-0.06547277258684325,-0.06334019702990723
428.30000000000535,48.41893374547873,-0.06402173184623026,-0.0633401969128089
429.4000000000054,48.52625086656615,-0.0637861407548035,-0.06395722368967238
430.5000000000054,48.6338348997217,-0.06251401004362336,-0.06437719553490506
431.6000000000054,48.74133724301008,-0.060776701748314614,-0.06334016663748354
432.70000000000545,48.848565577445484,-0.06023694136462499,-0.06333032711115738
433.8000000000054,48.956794025059395,-0.058812915273944694,-0.06202032006126945
434.90000000000543,49.063183316065576,-0.058404114909953724,-0.06399999448403548
436.00000000000546,49.17096881646254,-0.05742096672000926,-0.06468525867695618
437.1000000000055,49.2793690631539,-0.05584292003436968,-0.06200997142914666
438.2000000000055,49.387128297561624,-0.055583435966978505,-0.06334021784398125
439.3000000000055,49.4951469348256,-0.053584898207378294,-0.06334000476382506
440.40000000000555,49.6025856122893,-0.052197618933152265,-0.06300264759080498
441.50000000000557,49.7103129878324,-0.05147133509252411,-0.0630172103296287
442.6000000000056,49.81792702817574,-0.049752167247167675,-0.06432981924305814
443.70000000000556,49.92540899300178,-0.049038856422224116,-0.06433208028147241
444.8000000000056,50.032550282719434,-0.04752279117608833,-0.06308447385490368
445.9000000000056,50.14030678420307,-0.046047816217249946,-0.0636864296824271
447.0000000000056,50.247314731354344,-0.0451590022466019,-0.06497395352935342
448.10000000000565,50.35528931868227,-0.04207667705856524,-0.06569326970854661
449.2000000000057,50.46367791859925,-0.0423180518371331,-0.06565000893014972
450.3000000000057,50.57123507487556,-0.039862429482235354,-0.0656500090000014
451.40000000000566,50.67921521516834,-0.03819422347750142,-0.06565001070622145
452.5000000000057,50.78664844498801,-0.037645679764736,-0.06465578375595715
453.6000000000057,50.89481648279742,-0.03439744799706086,-0.06490185163166906
454.70000000000573,51.00166211861974,-0.032624325508622605,-0.0659800717626906
455.80000000000575,51.11062031666031,-0.033042802799467835,-0.06598007199999945
456.9000000000058,51.21860321940677,-0.03020052624554849,-0.06598007200000033
458.0000000000058,51.32683719686659,-0.027548541422921572,-0.06598007200490574
459.1000000000058,51.43302027850538,-0.02709036406054743,-0.06597480163765113
460.20000000000584,51.54262198305355,-0.024935032451510266,-0.0672999170203834
461.3000000000058,51.65138226336864,-0.02447012233994063,-0.06729991500512611
462.40000000000583,51.75961606714548,-0.02341078115593557,-0.06729364071811172
463.50000000000585,51.866403476425845,-0.020768708242547985,-0.06630991638094397
464.6000000000059,51.97422048912733,-0.018290357975383774,-0.06762323254153113
465.7000000000059,52.08444348250631,-0.017609350175754112,-0.06631043026867722
466.8000000000059,52.191701407822215,-0.015574211281056717,-0.06631216907192705
467.90000000000595,52.30068874786226,-0.013864585476249677,-0.06761886794061311
469.0000000000059,52.409071857128886,-0.012204861439798684,-0.06893994174834095
470.10000000000593,52.51612355696767,-0.011107959158124623,-0.0686182806950395
471.20000000000596,52.62509615303322,-0.007815918017959514,-0.06814516837202778
472.300000000006,52.732929912299255,-0.007477418425852449,-0.06893994177329432
473.400000000006,52.84036717454305,-0.006098811428977409,-0.06893992467365795
474.500000000006,52.94840619606557,-0.004082610655433253,-0.07029427917858921
475.60000000000605,53.05712399508765,-0.002047921625559481,-0.0685577194483411
476.70000000000607,53.16447826452801,-0.0004894908062047074,-0.06894019700949272
477.8000000000061,53.27217266406569,6.126483380207287e-06,-0.06894018541698799
478.90000000000606,53.38117119609083,0.0010826272505777815,-0.07026219188031124
480.0000000000061,53.488776361190254,0.00548950545833185,-0.07025933917592386
481.1000000000061,53.597085597192496,0.005444700382902924,-0.07058986961661073
482.2000000000061,53.70492954269381,0.007652773084123517,-0.07031579845766345
483.30000000000615,53.81357946190454,0.009433790016934524,-0.07026003697403738
484.4000000000062,53.92099196277242,0.01106759375425933,-0.07026003699999972
485.5000000000062,54.029234655797254,0.01209859767253877,-0.07026003686886728
486.60000000000616,54.136304147514366,0.01433006775188975,-0.07050496566517861
487.7000000000062,54.24668370330313,0.015497060153082878,-0.07091982969316213
488.8000000000062,54.35343983416293,0.01702124493282414,-0.07077588447887084
489.90000000000623,54.46239184656136,0.01975025726522755,-0.07123875628919318
491.00000000000625,54.570835951649165,0.01898025692790101,-0.0719001282399061
492.1000000000063,54.67846935298524,0.021374591072590217,-0.07190438842822999
493.2000000000063,54.7868094786239,0.022390894731658395,-0.07193280531612523
494.3000000000063,54.895916265153204,0.024722785506016823,-0.07322627594315101
495.40000000000634,55.00397108421182,0.02428488966277784,-0.07057727309981221
496.5000000000063,55.113389502728566,0.025759409383190882,-0.0732212732735471
497.60000000000633,55.22141459526331,0.02787973282052291,-0.07321780659422927
498.70000000000636,55.32915193953308,0.027977063420391173,-0.07323870905395768
499.8000000000064,55.43719405496962,0.030328188709060663,-0.07319458308685967
500.9000000000064,55.54585099676647,0.03143103742719047,-0.07294365822380566
502.0000000000064,55.65393015284778,0.03543883612502819,-0.07420981297127405
503.10000000000645,55.7626718292873,0.037046952057403826,-0.0742098129666866
504.2000000000064,55.87061898065592,0.0382366406217995,-0.07425527097079598
505.30000000000643,55.978695790525364,0.03861666198833549,-0.07387028305482524
506.40000000000646,56.087218804313665,0.039494615350783246,-0.07464357867969618
507.5000000000065,56.195601490251526,0.04214858886911672,-0.07559191031996271
508.6000000000065,56.30338425214632,0.04278843870138343,-0.07553605252429385
509.7000000000065,56.41260845119894,0.04366036871434885,-0.07599712770289813
510.80000000000655,56.52163721269765,0.04414977478643398,-0.0755200935995779
511.90000000000657,56.6297078666331,0.043470328371207394,-0.07533064482911378
513.0000000000066,56.7372389566567,0.04764103401674618,-0.07486009196690091
514.1000000000065,56.84628329696635,0.05061885488598246,-0.07523523464514792
515.2000000000066,56.95559896887136,0.0508692124221466,-0.07749996302292672
516.3000000000065,57.06383964003504,0.05168826509940696,-0.07618410666078379
517.4000000000067,57.172270590000785,0.054856324551790285,-0.07758887986595653
518.5000000000066,57.28081710918446,0.05606304319557095,-0.07603548419256256
519.6000000000067,57.38839096193796,0.054614156327904,-0.07815148333818644
520.7000000000066,57.49781851165195,0.056598574568014655,-0.0784572493675384
521.8000000000067,57.6047708118838,0.05723234735565808,-0.07750024125878863
522.9000000000067,57.714508380549404,0.05967675630189902,-0.07882791767963493
524.0000000000067,57.82311982839118,0.0616910504370366,-0.07882002999572979
525.1000000000067,57.93105746403946,0.06235176498132773,-0.0788200440108815
526.2000000000068,58.0404966308157,0.06417898822779528,-0.08012979236473505
527.3000000000068,58.14841123403116,0.06591022168695793,-0.07980019020167983
528.4000000000068,58.257952724291485,0.069909504548954,-0.08112245400932938
529.5000000000068,58.366701773998535,0.06959997799095374,-0.08227701408978927
530.6000000000068,58.474125171100425,0.0717104143251308,-0.08243981446811333
531.7000000000069,58.58316153160936,0.07258503665415462,-0.0814085960792772
532.8000000000068,58.692731861730465,0.07685851547786482,-0.08145095668614744
533.9000000000069,58.80045334690304,0.07704476300196197,-0.08279944815760132
535.0000000000068,58.91019358652824,0.0797918731101125,-0.08409077746741911
536.100000000007,59.018770900833864,0.08286292816692993,-0.08278036242626019
537.2000000000069,59.127604602976405,0.08207695217327333,-0.08342782434958007
538.300000000007,59.23689970113353,0.08445674746632632,-0.08376003515830988
539.4000000000069,59.346098949444546,0.08650069713053087,-0.08442038035817134
540.5000000000069,59.45470327451419,0.08858050511876231,-0.08507854951357885
541.600000000007,59.562800860073494,0.08942659360261271,-0.08507909596148355
542.700000000007,59.67156830010398,0.09052060164214008,-0.08607000291788403
543.800000000007,59.7811430963464,0.09209776002525732,-0.08639978390631242
544.900000000007,59.889997864808095,0.09313111794246197,-0.08771989727738472
546.000000000007,59.9991831259961,0.09404513530389576,-0.08757248802883488
547.1000000000071,60.10664140261389,0.09661301888094184,-0.08640634151847326
548.2000000000071,60.21808454234044,0.09786025152795542,-0.08694399844328338
549.300000000007,60.32664611742738,0.1000462422631888,-0.08771021004331381
550.4000000000071,60.436286661497256,0.10216977137128022,-0.08770990492180974
551.500000000007,60.54268271461034,0.10443511946582769,-0.08903017779338729
552.6000000000072,60.654109068704116,0.10647027933974404,-0.08903017600201046
553.7000000000071,60.76348282933695,0.10645101794573729,-0.08902704857392063
554.8000000000072,60.87184323117372,0.10732827976472288,-0.09035005569181243
555.9000000000071,60.98074113413713,0.10929167522095948,-0.08903032565028113
557.0000000000072,61.090300825900385,0.1117700511976202,-0.08936007066076979
558.1000000000072,61.20038786231437,0.11369151099756222,-0.09067989427049472
559.2000000000072,61.30835634112213,0.11549295164281705,-0.09067986199671196
560.3000000000072,61.41880278573003,0.11581148268192923,-0.09090652835177826
561.4000000000073,61.5288435503103,0.11916864891828972,-0.09066993239576471
562.5000000000073,61.63667947583079,0.12242949961452239,-0.09132223396820205
563.6000000000073,61.74687860408613,0.12396570274728808,-0.09265013436100578
564.7000000000073,61.8551888666704,0.1262798690780259,-0.09165386883159865
565.8000000000073,61.96451890358171,0.12688341993332475,-0.0929785177634388
566.9000000000074,62.073043130718006,0.1308386707639375,-0.09428989748262051
568.0000000000074,62.1830523551537,0.13308336580708105,-0.09429001067119103
569.1000000000074,62.292252718148646,0.135812845832077,-0.09495870057861477
570.2000000000073,62.40173336009522,0.1389383529699119,-0.0956050393928467
571.3000000000073,62.50912641519274,0.14338990387369044,-0.09529085892286826
572.4000000000074,62.61941911820492,0.1529318613234139,-0.09661010395930658
573.5000000000074,62.72680788871046,0.15839474966786202,-0.09662291743189488
574.6000000000074,62.838356477077696,0.15253182084300243,-0.09661968814840449
575.7000000000074,62.947552160018475,0.14810054116299476,-0.09690389588985449
576.8000000000075,63.05724455101471,0.14789886044341044,-0.09859014452998949
577.9000000000075,63.165609448228764,0.14821341205159255,-0.09745590919153369
579.0000000000075,63.275943439344104,0.14667948419968102,-0.09758993329902266
580.1000000000075,63.384606939395795,0.14898560644087908,-0.09890705039761638
581.2000000000075,63.49363459137502,0.15138200148849118,-0.0996454153133155
582.3000000000076,63.60367006461115,0.15438145933606065,-0.09890742029982258
583.4000000000076,63.71182187573426,0.15650980217393284,-0.10022988383080733
584.5000000000076,63.821200914067745,0.15805743951552387,-0.10253081979635237
585.6000000000076,63.93058616054773,0.15997630426974097,-0.10253459792412078
586.7000000000077,64.04087579789118,0.1620757221848189,-0.10193964306207626
587.8000000000077,64.1493614132858,0.1636219776616557,-0.10253016076561616
588.9000000000076,64.25941033741611,0.16588293521147152,-0.10351923387630269
590.0000000000076,64.36835806572067,0.16880800192043885,-0.10378843177851582
591.1000000000076,64.47766693514625,0.1695044629600171,-0.10516988870297972
592.2000000000077,64.58746705109532,0.17430353800314805,-0.10647926371039418
593.3000000000077,64.69641314596656,0.17626080466410124,-0.10647965772405499
594.4000000000077,64.80557363685637,0.17843512143324985,-0.10767442852208475
595.5000000000077,64.91426381938749,0.18118418147914064,-0.10780000068771933
596.6000000000078,65.02421881474811,0.1817320420101266,-0.10779974898800937
597.7000000000078,65.13406031374313,0.18639109500756249,-0.11044369439198087
598.8000000000078,65.2440317564509,0.18909500040573968,-0.11177219615243406
599.9000000000078,65.35239394987636,0.1902692329766956,-0.11042993069772855
601.0000000000078,65.4623729509377,0.19229536890266982,-0.11175007961499661
602.1000000000079,65.57130244468127,0.1937058674035915,-0.11175072385128937
603.2000000000079,65.68128881332642,0.1948299999895572,-0.11208936363325162
604.3000000000079,65.79098252569078,0.19767369231129367,-0.11340976612258791
605.4000000000078,65.90076774690982,0.19958107417882542,-0.11471992513340012
606.5000000000078,66.010541602607,0.20249207802328542,-0.1173986171605641
607.6000000000079,66.11969394843766,0.2039259509839682,-0.11603992865560375
608.7000000000079,66.2294670461466,0.20546699058816897,-0.1170345678362601
609.8000000000079,66.33945613856079,0.20834395658176152,-0.11736019093645211
610.9000000000079,66.44904486361348,0.21070322475257902,-0.11997966444602781
612.000000000008,66.5580244917029,0.2143018838174599,-0.11999247445427441
613.100000000008,66.66730677161779,0.22033421764829436,-0.12131004553905367
614.200000000008,66.77677348729381,0.22160858361274166,-0.12263038436314178
615.300000000008,66.88644286412827,0.22428912297656856,-0.12294912451604967
616.400000000008,66.99511289575307,0.22605341353028477,-0.12427730405531356
617.5000000000081,67.10602715528996,0.2298012326025993,-0.12426283407666228
618.6000000000081,67.2148037527647,0.23526908397407814,-0.1255178400495387
619.7000000000081,67.32454660549084,0.23672454051215072,-0.12658340355938957
620.8000000000081,67.43420962923868,0.2430456679833098,-0.1254783928468588
621.9000000000082,67.54388798325003,0.24636763197860193,-0.12685095001516755
623.0000000000082,67.65282275167498,0.2514954057066988,-0.12915130483054904
624.1000000000081,67.763309326524,0.25556280481603344,-0.13053619167327657
625.2000000000081,67.87236975495254,0.26087132575052646,-0.1318424181568898
626.3000000000081,67.98271882140672,0.2676237800367958,-0.1318362230079071
627.4000000000082,68.0925505966867,0.27330826824331383,-0.1333578359299521
628.5000000000082,68.20201038837892,0.27747734100859917,-0.13462960549935277
629.6000000000082,68.31193588783366,0.28536435913394187,-0.13583211644857274
630.7000000000082,68.42160838572875,0.29183381920682994,-0.13711007042311607
631.8000000000083,68.53050915069322,0.2989492610165398,-0.13844553939620674
632.9000000000083,68.64127115877875,0.3074536456660428,-0.14074584736973383
634.0000000000083,68.75127626815542,0.31598572627206306,-0.1433699468727072
635.1000000000083,68.86124747228678,0.32466141939250076,-0.14469008157692453
636.2000000000083,68.97060190384231,0.3328003041379178,-0.14535190453531843
637.3000000000084,69.0806770727866,0.3398089696345544,-0.14704664381779775
638.4000000000084,69.18999791427922,0.3484099215621559,-0.1489698420631025
639.5000000000084,69.3002909391816,0.3546780683450159,-0.1515995357497042
640.6000000000083,69.41000217003199,0.36567995805648096,-0.15303011887949358
641.7000000000083,69.52092353001544,0.3741034280511316,-0.15532167643273187
642.8000000000084,69.63047962849184,0.38405068689279265,-0.1566595487533351
643.9000000000084,69.73961093021832,0.3933961126136655,-0.15930776912689737
645.0000000000084,69.84972009753562,0.40402512652202804,-0.160672673556304
646.1000000000084,69.95931852209834,0.4150899907867255,-0.1619119115276355
647.2000000000085,70.06843493477668,0.4266228838616256,-0.16590632887200796
648.3000000000085,70.17899835853746,0.43609251450514636,-0.1672222739182736
649.4000000000085,70.28836877643239,0.4482853759460918,-0.16982181350646774
650.5000000000085,70.39847703698672,0.46182183518891634,-0.172589261280637
651.6000000000085,70.50897567819392,0.47349289528154515,-0.1752207789917124
652.7000000000086,70.61906065549621,0.4874640120632995,-0.17764827293696728
653.8000000000086,70.7283154850217,0.5015149620859589,-0.1806848608139484
654.9000000000086,70.83897526042406,0.5139998244295434,-0.18355493891417796
656.0000000000086,70.9477193453003,0.5290722513418615,-0.1850203591067796
657.1000000000087,71.05709346236308,0.5435988363052575,-0.18913127037842647
658.2000000000087,71.1690178669025,0.5595584532551293,-0.1958158577284359
659.3000000000086,71.27947706955143,0.5737852679739714,-0.19824462969693268
660.4000000000086,71.38957997715646,0.5892822571485342,-0.20100006674494786
661.5000000000086,71.49868023449604,0.6064919562018198,-0.20318848935125633
662.6000000000087,71.60898287862784,0.6215029782256427,-0.20760490020479594
663.7000000000087,71.71942750172688,0.6409891986709452,-0.21126434278724338
664.8000000000087,71.83010373644325,0.6563261886290077,-0.21681390010149704
665.9000000000087,71.93980892909622,0.6759585432906263,-0.21973843177202612
667.0000000000088,72.05021635164212,0.6926018909576489,-0.224736144032605
668.1000000000088,72.16114867643901,0.7135740861185428,-0.2301046962946045
669.2000000000088,72.27070014239392,0.7312247734049621,-0.23444765567882087
670.3000000000088,72.38113836076988,0.7509298903353093,-0.2392864567131907
671.4000000000088,72.49092972012517,0.7715980793106906,-0.2428997188134434
672.5000000000089,72.60116957204542,0.7984809727118447,-0.2480078233003118
673.6000000000089,72.7105730911669,0.8179949926901519,-0.25509674255942993
674.7000000000089,72.8201092118298,0.8394310764691192,-0.2599707309187562
675.8000000000088,72.93107843869156,0.8622653086425273,-0.26523738301920474
676.9000000000088,73.04150241647515,0.8847622388372302,-0.27108785712763694
678.0000000000089,73.15169871473871,0.9088777100659661,-0.2770676832685859
679.1000000000089,73.26095927693613,0.9319686374733193,-0.28445707731865433
680.2000000000089,73.37089714721284,0.9570991738478568,-0.2911537349919362
681.3000000000089,73.48010922338382,0.984040836866983,-0.2975154780356002
682.400000000009,73.59156166660384,1.0111580037105987,-0.30290972772654
683.500000000009,73.70020736804521,1.0366501724775965,-0.31124242285442394
684.600000000009,73.81113791078,1.0649856365337338,-0.3171585329497324
685.700000000009,73.92038827531744,1.0922248923926614,-0.32576612602167865
686.800000000009,74.03038164867147,1.121300779799963,-0.332999544320864
687.9000000000091,74.14037299705511,1.1479081882022661,-0.3411106170202416
689.0000000000091,74.25036995973767,1.1754903330935198,-0.348926376658667
690.1000000000091,74.3610899107036,1.206091060164588,-0.35749541512413296
691.2000000000091,74.46989996914195,1.2342971172300583,-0.3668812727232149
692.3000000000092,74.58078984349495,1.2687390621326915,-0.3759390782533165
693.4000000000092,74.69049140485316,1.2960473806707007,-0.38484533115362307
694.5000000000091,74.80099870985623,1.3276719981324292,-0.39304167680410274
695.6000000000091,74.91139566754819,1.3598964466221586,-0.404650119590221
696.7000000000091,75.02261446882763,1.3893994600512465,-0.4137769882640585
697.8000000000092,75.13197880427971,1.4237984832893236,-0.42350521252553497
698.9000000000092,75.24300519694066,1.4540429150722096,-0.4332962404618841
700.0000000000092,75.35138485457367,1.4881604224402494,-0.4449023305831905
701.1000000000092,75.46442802223555,1.522922671278876,-0.4563648299861862
702.2000000000093,75.5742635183594,1.5557530447376702,-0.4670188381931455
703.3000000000093,75.68386706115515,1.5907065281313664,-0.47914949383729066
704.4000000000093,75.79435849302916,1.6247680348332674,-0.49185740530017563
705.5000000000093,75.90549518445964,1.657694662148842,-0.5028197601379816
706.6000000000093,76.01532903833504,1.6902276171158304,-0.5164716183709812
707.7000000000094,76.12522153505078,1.725988714350929,-0.5293825884939198
708.8000000000094,76.23470449872707,1.757555292548734,-0.5415657797901665
709.9000000000094,76.34504010440082,1.7903038173080676,-0.5544892689828975
711.0000000000093,76.45554884325152,1.8220216034904098,-0.568397764305117
712.1000000000093,76.56490019866534,1.854806901006495,-0.5810052045700882
713.2000000000094,76.67361622742675,1.8895107360750854,-0.5957287373666791
714.3000000000094,76.78629959497931,1.9202127021554904,-0.6100340452387618
715.4000000000094,76.8953286558012,1.9556282817382187,-0.624954486401061
716.5000000000094,77.007033332201,1.9937362996781944,-0.6405332957847105
717.6000000000095,77.11585180535484,2.024724423022079,-0.6547501354455121
718.7000000000095,77.22699807141046,2.059743496395694,-0.6697282475173219
719.8000000000095,77.3376462079849,2.0909406824919796,-0.6860902296148419
720.9000000000095,77.44854470141438,2.125119700227064,-0.7020244681599594
722.0000000000095,77.55859357232026,2.1566698103078266,-0.7191611156781796
723.1000000000096,77.66821427775596,2.1882762257758284,-0.7349279389889394
724.2000000000096,77.77919892869198,2.21578437746044,-0.7520862028032758
725.3000000000096,77.89067744545194,2.251614627613944,-0.7682355933902003
726.4000000000096,78.00048173271345,2.276174580355821,-0.7853657867503783
727.5000000000097,78.11102246642935,2.308687215873886,-0.8039777234639871
728.6000000000097,78.22185863829051,2.3404454713870524,-0.8215868426970196
729.7000000000096,78.33169323252693,2.3685601756373247,-0.8401998429664825
730.8000000000096,78.44191664149085,2.397173271744274,-0.8581714900608977
731.9000000000096,78.5524786501316,2.426582511563139,-0.8768442310249416
733.0000000000097,78.66306756543543,2.4564918468137944,-0.8967637346001025
734.1000000000097,78.77310317377876,2.486881197340079,-0.915002932517095
735.2000000000097,78.88319282466433,2.516362101877017,-0.9333060259569388
736.3000000000097,78.99338119389884,2.5490492621744063,-0.9536103428817606
737.4000000000098,79.10402107516258,2.57899911957487,-0.9734416531993091
738.5000000000098,79.21418831173986,2.6103102900733086,-0.9936287627543052
739.6000000000098,79.32461403937232,2.647081163188511,-1.0123036894781263
740.7000000000098,79.434800466372,2.680888401271558,-1.032539321268581
741.8000000000098,79.54522459161142,2.7193023000150887,-1.0538566863344583
742.9000000000099,79.65588867673208,2.759485371869494,-1.0757498128994358
744.0000000000099,79.76585724571561,2.8038910497358325,-1.0947850387659837
745.1000000000099,79.87709021736976,2.8542661446418043,-1.1164101038845824
746.0000000000099,79.96714819209933,2.899631162104111,-1.1348799777065448