File: 01_Data/Concrete_Block/STA/N2/10K_min/Concrete_Block_STA_N2_10KData_220914_R3.csv
##Temp./Â°C,Time/min,DSC/(mW/mg),Mass loss/mg
51.0,10.830300065048432,-1.5381890809332688,0.03287853858938039
52.100000000000016,11.169861813472586,-1.4354553765980436,0.0314458685190413
53.20000000000003,11.41627585271011,-1.3646340875593117,0.03113959952753209
54.30000000000005,11.616622376269465,-1.3097381585115508,0.030546929571697135
55.40000000000006,11.801028928749282,-1.2690166367812892,0.03191802277939537
56.50000000000008,11.972248682966383,-1.23483322232905,0.031377945207371916
57.600000000000094,12.132794170299515,-1.2044870822745979,0.029787665773246985
58.70000000000011,12.286512677060934,-1.181177805479172,0.029135261327853712
59.800000000000125,12.434475840809984,-1.1591006617295219,0.03083177331917053
60.90000000000014,12.581070056356706,-1.1400789837198335,0.02936096818018097
62.000000000000156,12.725194120502012,-1.1217612571931805,0.030389047813232928
63.10000000000017,12.863883774703218,-1.1067570280888932,0.03168918305165924
64.20000000000019,13.001587798511931,-1.0919551238525003,0.03183050458726555
65.30000000000021,13.136490826789021,-1.0780819792819316,0.03177968270074594
66.40000000000022,13.269419911986803,-1.0632858729591654,0.03068284241230934
67.50000000000023,13.399409606755786,-1.0510336803005293,0.030391782094541853
68.60000000000025,13.53045309790045,-1.0385519767980462,0.028183288049594246
69.70000000000027,13.659728516082582,-1.025680499981822,0.02993222119029504
70.80000000000028,13.785720879090015,-1.0121639087249146,0.0313224102832379
71.90000000000029,13.911628457147449,-1.000841319312018,0.03010578694374111
73.00000000000031,14.034425296619718,-0.9916905813376622,0.030810453535436544
74.10000000000034,14.158306598408293,-0.9801670828831494,0.030430335329759473
75.20000000000034,14.279585884839413,-0.9688355074614932,0.02895910307604055
76.30000000000035,14.401844941063427,-0.9577020470870532,0.02911624545161917
77.40000000000038,14.524419771577753,-0.9476428005739852,0.029384176145869745
78.5000000000004,14.642351747503927,-0.9389836442330874,0.02898557927524603
79.6000000000004,14.76112637956687,-0.928408039543028,0.029074136998305633
80.70000000000041,14.879495134885726,-0.9189539101005556,0.02891021517872705
81.80000000000044,14.997344054132405,-0.9109173248988411,0.028995127633374196
82.90000000000046,15.113682056648132,-0.9012156594548397,0.029103504888564835
84.00000000000047,15.22988209313868,-0.8948209143097432,0.028996866470969884
85.10000000000048,15.345996349787473,-0.8841162011708463,0.029822025556160092
86.2000000000005,15.461260367226556,-0.8757630490096571,0.03041001261368148
87.30000000000052,15.57542758875282,-0.8679482524658749,0.0293734285998708
88.40000000000053,15.690283341787417,-0.8600405225697131,0.029100906710333163
89.50000000000054,15.799452641356524,-0.8529953091071503,0.02974216740838287
90.60000000000056,15.915134345863942,-0.8461143131075979,0.029133545382119763
91.70000000000059,16.028371560773245,-0.837070156029716,0.027774357702769592
92.8000000000006,16.13931375617628,-0.8303124732856155,0.030417498404765375
93.9000000000006,16.250942651973073,-0.8235054187105907,0.029842526444114448
95.00000000000063,16.362025961988333,-0.8167622705634011,0.02909869191731662
96.10000000000065,16.47263643459443,-0.808000792046832,0.027757998305524723
97.20000000000066,16.582204463954177,-0.8028289290383183,0.029105632588311003
98.30000000000067,16.690250089040923,-0.79504772017692,0.026943065483843398
99.40000000000069,16.80290661360596,-0.7880061029892942,0.02773957314767639
100.50000000000071,16.91125267799233,-0.7816829846798701,0.026974145335504573
101.60000000000072,17.019788522810916,-0.7752681455444435,0.026471227756674764
102.70000000000073,17.12799722661085,-0.769561904438332,0.026462699232131293
103.80000000000075,17.234914137489305,-0.7616228280151643,0.027785792280101695
104.90000000000077,17.346127888640208,-0.7544953937162531,0.026459263983047876
106.00000000000078,17.45453685405522,-0.7490630415553741,0.025140873151898724
107.10000000000079,17.562714634378054,-0.7427590726812178,0.025111891954153975
108.20000000000081,17.671727092817513,-0.7361243065466296,0.023821931632403093
109.30000000000084,17.780309283461083,-0.7312853123377691,0.02514042213952994
110.40000000000084,17.88647565133433,-0.7247818091820416,0.02545932267683515
111.50000000000085,17.99478187523809,-0.7181444684279472,0.025266644801482663
112.60000000000088,18.101675682274134,-0.7153345343756439,0.02382825865146021
113.7000000000009,18.209339864601294,-0.7104822474588036,0.024238045587844148
114.8000000000009,18.317141900957157,-0.7046422780104181,0.022505087112033806
115.90000000000092,18.420441365240478,-0.7010792376113093,0.023810959790521835
117.00000000000094,18.531845216192384,-0.6967269707757576,0.026572161333221267
118.10000000000096,18.63806140501912,-0.6919587273443679,0.023908949805963253
119.20000000000097,18.74575176855398,-0.6889999804752601,0.02394105890620235
120.30000000000098,18.85316106341705,-0.6850431875948217,0.025269310874734607
121.400000000001,18.959500129023468,-0.6801618062418073,0.02524982887156213
122.50000000000102,19.066537492717657,-0.6753707497538897,0.024133540339676074
123.60000000000103,19.173390084525664,-0.6717945395637848,0.023929865604179312
124.70000000000104,19.28000000000012,-0.6682500000000032,0.022619171131782245
125.80000000000106,19.386669395977005,-0.6644123498299065,0.02259314145785485
126.90000000000109,19.493977242236962,-0.6608179141833801,0.02342535179191163
128.00000000000108,19.599278656709348,-0.6558311255804998,0.022889114926764265
129.1000000000011,19.705649201235538,-0.6527580444622375,0.022620023892684138
130.20000000000113,19.81274627775664,-0.6498556393335371,0.022619914998601054
131.30000000000115,19.91696076590684,-0.6444223309158689,0.022619959932694833
132.40000000000117,20.023284367180597,-0.6413282334038546,0.021309918626379876
133.50000000000117,20.128976748962003,-0.6378191126557943,0.02130991383940728
134.6000000000012,20.235658100686084,-0.6333312335527393,0.022632701841842184
135.7000000000012,20.34260481626538,-0.6288190907313749,0.024744637601602726
136.8000000000012,20.446042716517926,-0.6252549181030049,0.02230634793838515
137.90000000000123,20.553828851598368,-0.6212125607506652,0.022620064672070228
139.00000000000125,20.658873514747857,-0.6172712455150857,0.022485176039889865
140.10000000000127,20.76379997351242,-0.6124588443881832,0.021419039237716042
141.2000000000013,20.868937397267153,-0.6078340843311825,0.021310312389242192
142.3000000000013,20.974312998822423,-0.6045246971053031,0.02195888329428808
143.4000000000013,21.078948252516923,-0.5999930651589915,0.020661656811256535
144.50000000000134,21.184038671000184,-0.5968060777193994,0.021299943073388228
145.60000000000133,21.28878352283539,-0.5936286436795937,0.021325238254331857
146.70000000000135,21.39337998600144,-0.5890115976269611,0.021286470016519843
147.80000000000138,21.49932499201222,-0.5868712437983639,0.020307159175064093
148.9000000000014,21.604092281585977,-0.582536824020813,0.02130014539463776
150.00000000000142,21.7085488563752,-0.5782442497301087,0.021300470533911486
151.10000000000142,21.81231517684625,-0.5748903603815099,0.021299020139732505
152.20000000000144,21.918935045981048,-0.5712664963498462,0.019980008893122125
153.30000000000146,22.019575355382504,-0.5682631948863418,0.01997991500384
154.40000000000146,22.126910947474354,-0.566124542168322,0.019979470448289405
155.50000000000148,22.231950595929607,-0.5616019978693381,0.020309740894248307
156.6000000000015,22.336947679411704,-0.5573502881816285,0.021302801476009492
157.70000000000152,22.44065735675125,-0.555471380483897,0.02005018328136199
158.80000000000155,22.54424859866859,-0.5518495840358073,0.019989634259777844
159.90000000000154,22.64886092826611,-0.5503772182379044,0.0199738637281488
161.00000000000156,22.754170412325873,-0.5452086729496164,0.021312900335060725
162.1000000000016,22.860088000494475,-0.5417754462560447,0.01998918273364314
163.20000000000158,22.965107032976942,-0.5372724512740382,0.019978067166964486
164.3000000000016,23.06940670177545,-0.5334483290682535,0.019980179974084855
165.40000000000163,23.173933083080463,-0.5299883559916518,0.020065163329300972
166.50000000000165,23.279102728934777,-0.5270325813650554,0.01956738637898514
167.60000000000167,23.38298744458022,-0.5232894720316427,0.021165352953746108
168.70000000000167,23.488084905648638,-0.52027383481095,0.01998996795753971
169.8000000000017,23.592985755334098,-0.5177604293756051,0.021262322847105608
170.9000000000017,23.69786530564294,-0.5127043987361888,0.021959865273581514
172.0000000000017,23.802181287282444,-0.5105579629689572,0.02197151186632329
173.10000000000173,23.906127934829115,-0.5076765720710676,0.020652164075852575
174.20000000000175,24.01032758927876,-0.5034237430671579,0.020639981453646428
175.30000000000177,24.115480122008893,-0.5020298107607586,0.020484780643242217
176.4000000000018,24.221582777764233,-0.4980713849090657,0.02070729776245095
177.5000000000018,24.322434129328816,-0.49576130695005355,0.01932018563687876
178.6000000000018,24.429187875477517,-0.49135809882890874,0.018009896548148774
179.70000000000184,24.533866817887155,-0.4899358541041018,0.019379144468807397
180.80000000000183,24.637403333488216,-0.4866874627221,0.017995222055085414
181.90000000000185,24.743794240113136,-0.48424745670369523,0.019329832838515415
183.00000000000188,24.84750072987346,-0.48052078761256717,0.02012638902961683
184.1000000000019,24.952652768107928,-0.4791466152461011,0.019147689607477147
185.20000000000192,25.056794914833525,-0.4755371415354642,0.019000054972998726
186.30000000000192,25.161542174536653,-0.4715248087114944,0.019000054736001637
187.40000000000194,25.266090538188376,-0.4690956732581557,0.019363780282150245
188.50000000000196,25.369804094700935,-0.4661830055273483,0.01855738511482663
189.60000000000196,25.47603812434668,-0.46408155632138665,0.019099719973854512
190.70000000000198,25.57931861831846,-0.45987086938454397,0.019106532092260764
191.800000000002,25.68235027708119,-0.458385612175486,0.019124125897913125
192.90000000000202,25.7875600642026,-0.4545517742231035,0.019090033424026487
194.00000000000205,25.89223127773866,-0.45361797929014663,0.020425199892732948
195.10000000000204,25.995024427329916,-0.44878189164487714,0.02173924797076765
196.20000000000206,26.099326676372883,-0.44537361696331534,0.021740123302887326
197.3000000000021,26.20401042475855,-0.4427732430299251,0.020431022462227055
198.40000000000208,26.30882090735176,-0.441102010512479,0.017765654537450715
199.5000000000021,26.41332932038436,-0.437665529482273,0.017789456389762925
200.60000000000213,26.517150552169376,-0.43422989381121174,0.018461380075477152
201.70000000000215,26.620503259233267,-0.4320942424059165,0.018066915370973824
202.80000000000217,26.725187411358494,-0.42930568394385393,0.017790035518853387
203.90000000000217,26.828465206866042,-0.4270740425560618,0.017786275445092592
205.0000000000022,26.93135540725448,-0.42641042790126465,0.017789436748451237
206.1000000000022,27.037987967357438,-0.42317923328841334,0.01647229175823295
207.2000000000022,27.14370880613798,-0.4199739747146817,0.019110062208204326
208.30000000000223,27.24808394121671,-0.4171554528808752,0.01715141160544409
209.40000000000225,27.352378776331594,-0.41303307014477175,0.01679975010413326
210.50000000000227,27.45560409816777,-0.41003559102197645,0.017779568204225882
211.6000000000023,27.561858589833932,-0.40711226556374763,0.016800118167114242
212.7000000000023,27.665025152733506,-0.40484779269316107,0.01811420365864702
213.8000000000023,27.769906883721376,-0.4020643098979664,0.017608573636671565
214.90000000000234,27.875207213777323,-0.3990048358335353,0.018451460340991765
216.00000000000233,27.977074309476627,-0.39691298032441685,0.017130102164755634
217.10000000000235,28.08330621286718,-0.39365130327209424,0.017130104908596344
218.20000000000238,28.187690381269494,-0.39045069404296584,0.017049886734226583
219.3000000000024,28.292604933018936,-0.3871467188211494,0.016799514073574606
220.40000000000242,28.39689194241935,-0.3864126851419849,0.018121278697289078
221.50000000000242,28.50124714023981,-0.38323908739060925,0.016799872794152293
222.60000000000244,28.603200575931073,-0.37998119647091005,0.016800102924931615
223.70000000000246,28.710378643005686,-0.37911808207196335,0.015494195367760533
224.80000000000246,28.815114370052616,-0.3760353071956747,0.016673061048011917
225.90000000000248,28.91896747060136,-0.37382614236642997,0.01679999348006156
227.0000000000025,29.02174353823325,-0.37409295412155086,0.016808361379172077
228.10000000000252,29.127137361688025,-0.37191297513604377,0.01811989442745343
229.20000000000255,29.233199102695387,-0.3691768013365084,0.017147199751659237
230.30000000000254,29.33812052228839,-0.36702145372246087,0.01580986706620635
231.40000000000256,29.442241457643373,-0.36520245678266694,0.016773765171969934
232.5000000000026,29.547150717585204,-0.362994762314553,0.016794102127165367
233.60000000000258,29.65173422478568,-0.35971651067577876,0.01581988549254376
234.7000000000026,29.75625075485129,-0.35767788307970305,0.015818683279878343
235.80000000000263,29.860399078745136,-0.3536075589565355,0.015489899300572318
236.90000000000265,29.96474179000828,-0.352321644941251,0.01449934098071104
238.00000000000267,30.06981371566024,-0.35065629248814956,0.015149797866103931
239.10000000000267,30.17385171055667,-0.3481665621092379,0.015164934095252214
240.2000000000027,30.278265808219665,-0.3456676320071161,0.015810067904572733
241.3000000000027,30.382940104188084,-0.3438386637436249,0.015810064219500042
242.4000000000027,30.488189642501574,-0.34169191202416443,0.017065823157463633
243.50000000000273,30.592457107526435,-0.3393526222170431,0.018107658871155508
244.60000000000275,30.69672701912023,-0.3366159696271881,0.01679982890585041
245.70000000000277,30.801241923394233,-0.33398201557431156,0.01679985683074392
246.8000000000028,30.906406745801995,-0.33353727211800144,0.015819867150422162
247.9000000000028,31.010430162129587,-0.3312880842077429,0.015809855144118146
249.0000000000028,31.112220027770068,-0.32886338116089686,0.01679674417318555
250.10000000000284,31.219688261740302,-0.3254249427304233,0.01418224617416275
251.20000000000283,31.323668523535595,-0.32390647347605106,0.014169862087752172
252.30000000000285,31.42829222116371,-0.3221601078659364,0.015492323266294683
253.40000000000288,31.53297840532823,-0.32018995891520824,0.015490154997110928
254.5000000000029,31.637656040383586,-0.31973493659139796,0.01549015500000106
255.60000000000292,31.74305916318462,-0.31641473656053504,0.015490147958686862
256.7000000000029,31.847803177036656,-0.3136835343629847,0.01646707644707135
257.8000000000029,31.952712610967016,-0.31312924358912203,0.015161155210056343
258.90000000000293,32.05693679839906,-0.3099057186297654,0.015467376945912825
260.00000000000296,32.1612968907235,-0.30788618525607037,0.0154799226368878
261.100000000003,32.26651045897924,-0.30543735109920583,0.014813231511521252
262.200000000003,32.37095868330544,-0.30399951852091767,0.014164615710802408
263.300000000003,32.475150847239405,-0.30162326509912474,0.015397111696612953
264.40000000000305,32.58046315485032,-0.30015156647823,0.014159818409559044
265.50000000000307,32.684461659075254,-0.2978652767781692,0.015470913592505298
266.6000000000031,32.78898671742262,-0.29631603372367826,0.016800241461701226
267.7000000000031,32.89206130868055,-0.2953732060015973,0.015476759938020557
268.8000000000031,32.99765749975776,-0.2929737731764278,0.015141767119811966
269.9000000000031,33.10298246673511,-0.29097769113007693,0.01548382209952237
271.0000000000031,33.20788277382789,-0.28925264799992195,0.014819879954869997
272.10000000000315,33.312372710925516,-0.28714688308842556,0.013507670566437646
273.2000000000032,33.41707649080793,-0.28626748631163196,0.016144013671083535
274.30000000000314,33.52134718606291,-0.28389359628762006,0.01484615186548055
275.40000000000316,33.627315951220645,-0.2825627531318599,0.013510110533622388
276.5000000000032,33.731502508545965,-0.279771784848755,0.013510337477881329
277.6000000000032,33.836430423309544,-0.27736325653799787,0.013649754236125133
278.70000000000323,33.941609446039415,-0.2763340271931279,0.013179820108720541
279.80000000000325,34.04525847450904,-0.2747319681093173,0.01318040472984272
280.9000000000033,34.150000910126685,-0.2730499886261209,0.011859808947317418
282.0000000000033,34.25589788779244,-0.2696614965611513,0.014217278093760832
283.1000000000033,34.359998989010755,-0.26883997416166755,0.014635961683321597
284.20000000000334,34.46621053790045,-0.26721788161763016,0.014169865960723449
285.30000000000337,34.57137285488393,-0.2654398183947433,0.012850199035702836
286.40000000000333,34.675558343621084,-0.26420483135335016,0.012850120015547084
287.50000000000335,34.780000000000314,-0.26213999999999793,0.013180195000027872
288.6000000000034,34.88569797017949,-0.26257394212766555,0.01417001436544929
289.7000000000034,34.99113186978081,-0.2588095678599526,0.014163925387165932
290.8000000000034,35.09596290662658,-0.2571228735699495,0.013747412001282378
291.9000000000034,35.201030005726004,-0.25543741822834026,0.012824147840820643
293.0000000000034,35.30633674469502,-0.25431301791255545,0.013831064785315483
294.10000000000343,35.41019297817233,-0.25350936244453676,0.013830471432707547
295.20000000000346,35.51624771862447,-0.2519887060298012,0.011539777121358341
296.3000000000035,35.62147015900927,-0.24967445634174884,0.012106353280427307
297.4000000000035,35.726884077434825,-0.24640058820593785,0.012850014707433743
298.5000000000035,35.83312209441879,-0.24606248994008745,0.012866403468807519
299.60000000000355,35.93726731937831,-0.2442977293428911,0.012843053966729912
300.70000000000357,36.042518450516674,-0.2434019039034209,0.011432104046127378
301.8000000000036,36.14789314217253,-0.2442191114898463,0.01152975502025555
302.9000000000036,36.252646592981705,-0.24209611766490738,0.012850202190263005
304.0000000000036,36.35880636378973,-0.23957446920976455,0.012850190000000872
305.1000000000036,36.46444594364729,-0.2376817526683122,0.012850143548178927
306.2000000000036,36.569271222086805,-0.23589168070993713,0.012520565241876724
307.30000000000365,36.674493145002984,-0.2341284318879529,0.011530215627426621
308.4000000000037,36.77916149195179,-0.23208274115046293,0.01153016440085608
309.5000000000037,36.88482555588903,-0.23025828793796324,0.011531838122871285
310.60000000000366,36.989999087916985,-0.22991996834841316,0.010209901788787334
311.7000000000037,37.095944133250775,-0.2278826136581007,0.012848641277389383
312.8000000000037,37.20213581929469,-0.22617646097239563,0.012976485026857887
313.90000000000373,37.30721604334453,-0.22535647003814394,0.012850894067442553
315.00000000000375,37.41199854647726,-0.22311828279394882,0.012850085001718803
316.1000000000038,37.51784117372038,-0.2215599127519679,0.012849664569714925
317.2000000000038,37.62297440880076,-0.2196492607531618,0.01351010923861029
318.3000000000038,37.729265255367025,-0.2182166053413446,0.011782439504201214
319.40000000000384,37.8348838157927,-0.21818585018837167,0.011859929901356203
320.5000000000038,37.93914342493686,-0.21653593434501375,0.0108707836303914
321.60000000000383,38.04590219163172,-0.21438160920697838,0.01219007962558738
322.70000000000385,38.15059131743514,-0.214697616506644,0.011451324584568212
323.8000000000039,38.25664386449972,-0.2129060257891776,0.011992208048669184
324.9000000000039,38.36298327051038,-0.2112221781108408,0.012520979966851975
326.0000000000039,38.46847176440543,-0.2095908152253992,0.01256549730630141
327.10000000000394,38.57346060527234,-0.20892731646211893,0.011859889681439917
328.2000000000039,38.679746553055445,-0.20757933951866658,0.013180156786976482
329.30000000000393,38.785402395788594,-0.20450295785348999,0.01318015244149251
330.40000000000396,38.89120168792083,-0.2038794144184701,0.012520714036181602
331.500000000004,38.99776172035692,-0.20090677518719346,0.012519980000896602
332.600000000004,39.10313170615553,-0.1993332150775764,0.012519978140440813
333.700000000004,39.209895493398925,-0.19849987553854204,0.011353594364317487
334.80000000000405,39.31516553467108,-0.19704889984901539,0.01020842764988572
335.90000000000407,39.42125156024176,-0.19553220332432675,0.011529811407427815
337.0000000000041,39.52742673649766,-0.19212870863385417,0.010203053173498233
338.10000000000406,39.63277294097541,-0.19083076293008633,0.011533118274585696
339.2000000000041,39.739647097557636,-0.19035702447312983,0.010999555667669192
340.3000000000041,39.84550782739617,-0.1857175377610421,0.010209830393220543
341.4000000000041,39.95000105867543,-0.1864099078166964,0.010209829999760167
342.50000000000415,40.057209058240026,-0.1854200490472169,0.01021008106956689
343.6000000000042,40.162474049607866,-0.18594889794663239,0.01218989173560292
344.7000000000042,40.268752769255535,-0.1832147872387678,0.010869673301835192
345.80000000000416,40.375420686304416,-0.18275442502836606,0.012189978914810773
346.9000000000042,40.480522183156864,-0.18078326574872441,0.01089580756545594
348.0000000000042,40.58833528072604,-0.178969357132457,0.010869980004667212
349.10000000000423,40.69368466984395,-0.1790914420867357,0.010869980176715366
350.20000000000425,40.799825456134485,-0.1786862816805445,0.010722891907600562
351.3000000000043,40.90571566665456,-0.17771837330544868,0.009559954246422642
352.4000000000043,41.01282731110946,-0.17433721645489164,0.01087018902719894
353.5000000000043,41.118774316701995,-0.17552370256281916,0.0108699800000851
354.60000000000434,41.22645566401219,-0.17304424207384025,0.010869980012360614
355.7000000000043,41.330669349667055,-0.17241995047126793,0.01084660736523091
356.80000000000433,41.43773883466296,-0.170899295737367,0.010219810489203063
357.90000000000435,41.54301707771564,-0.16875672740460024,0.009957476629545603
359.0000000000044,41.64956607152477,-0.1663936046361638,0.008580379716995878
360.1000000000044,41.756838011491716,-0.16529990444376977,0.009559897147558338
361.2000000000044,41.863325127926615,-0.16401433885641095,0.010871899552597597
362.30000000000445,41.96961178926837,-0.16548713050228953,0.009559965906705159
363.4000000000044,42.07605256832726,-0.16321840962468448,0.009560678092472408
364.50000000000443,42.18237122290627,-0.16100049759173224,0.009890042704394197
365.60000000000446,42.285848259042325,-0.1617341241293406,0.012507911530163618
366.7000000000045,42.39537238716937,-0.16020864905448876,0.012519949978100797
367.8000000000045,42.5003690241888,-0.15936547710756793,0.012156736091963438
368.9000000000045,42.60730497865896,-0.15887230732638657,0.009889515273654226
370.00000000000455,42.71464314325502,-0.15789322465018013,0.01119837555678771
371.10000000000457,42.82055476753208,-0.15819166749292682,0.009890156990482346
372.2000000000046,42.928080655776355,-0.15603426087675226,0.011225681449767322
373.30000000000456,43.03459811340094,-0.1569125098000949,0.011439522046053696
374.4000000000046,43.13958945129154,-0.15510983245775795,0.00995403478877499
375.5000000000046,43.24783324184912,-0.15414393846411964,0.009890054979183382
376.6000000000046,43.35493051206244,-0.1521512765868279,0.009890055000008502
377.70000000000465,43.462091546782126,-0.15203168422980495,0.009890047702684868
378.8000000000047,43.56787898772671,-0.15030665680289204,0.008567268169435316
379.9000000000047,43.675350240347534,-0.14877178542734834,0.008569985041902761
381.00000000000466,43.78222338540582,-0.14799949915783053,0.008899516610551217
382.1000000000047,43.88825088709828,-0.14441672490347754,0.009891009454659816
383.2000000000047,43.993757985107734,-0.14573775145623544,0.011186778190290347
384.30000000000473,44.102055546424026,-0.14366365015605306,0.008570132336624958
385.40000000000475,44.20718099173856,-0.14294443295218842,0.007594765253975844
386.5000000000048,44.31506262401313,-0.14222967237961953,0.00759228067003459
387.6000000000048,44.42188974010662,-0.14075517462786877,0.007579838477859369
388.7000000000048,44.52823509404641,-0.13911643847837576,0.008900354493582618
389.80000000000484,44.635208079728685,-0.13735228021438578,0.008618662620330397
390.9000000000048,44.74295195203719,-0.13653384270772848,0.007909182149806071
392.00000000000483,44.84980407787486,-0.1356601485916068,0.007242137451077824
393.10000000000485,44.95598654439621,-0.1328719226872367,0.007909913259910972
394.2000000000049,45.06248110543056,-0.13095583146896117,0.009221546909665257
395.3000000000049,45.16936697560712,-0.13024900787608482,0.008239855441355637
396.4000000000049,45.276170004573125,-0.12870248283520874,0.007916726332392265
397.50000000000495,45.383361478600186,-0.12603072752899555,0.007921121566885958
398.6000000000049,45.49053320530381,-0.1242721704542683,0.008227028376587953
399.70000000000493,45.59746550814963,-0.12272298874233442,0.007913994868283147
400.80000000000496,45.70521143234903,-0.11861090621616234,0.007929800943823118
401.900000000005,45.81323950317817,-0.11574968800292126,0.008237836615192506
403.000000000005,45.92069579281912,-0.11137794826700564,0.008238194081890526
404.100000000005,46.0262849086909,-0.10757724805581423,0.006919088356079683
405.20000000000505,46.1347273372802,-0.10208977689315261,0.005921687146835275
406.30000000000507,46.24182577597758,-0.09646360480265787,0.00494721804582543
407.4000000000051,46.34947423502854,-0.09036580499821123,0.006259858790722106
408.50000000000506,46.45576719365531,-0.08796571826361124,0.0064703366598504175
409.6000000000051,46.5638617836607,-0.08576129206922875,0.006270089489530228
410.7000000000051,46.66940187108514,-0.0849693421256753,0.007237143792141687
411.8000000000051,46.77744123173017,-0.08414938379398536,0.00790932658496235
412.90000000000515,46.88518365739069,-0.08620541337283451,0.0052958832093947805
414.0000000000052,46.990617616617115,-0.09049845270548673,0.005280014989528681
415.1000000000052,47.10018956741096,-0.09542893887281033,0.005280015840829044
416.20000000000516,47.20655538554685,-0.09739557502185738,0.003961363548369512
417.3000000000052,47.31357659012142,-0.09910090787389655,0.003960069313182046
418.4000000000052,47.42182275506277,-0.10076241713483484,0.0013323237668156906
419.50000000000523,47.52959762951179,-0.10267591894205681,0.004027662798562481
420.60000000000525,47.63436656349038,-0.10006215341316098,0.004364323474013609
421.7000000000053,47.74378414884017,-0.09984591941413139,0.003296562726337271
422.8000000000053,47.8504826635657,-0.09916117165042775,0.0046198883066868035
423.9000000000053,47.95859069890182,-0.09748470589368284,0.004619865056375794
425.00000000000534,48.06374185442832,-0.09723004230534435,0.0045033831459733165
426.1000000000053,48.17307740165231,-0.09552429459948193,0.004644336049822506
427.20000000000533,48.280273680543885,-0.09452592485867684,0.00395669331058901
428.30000000000535,48.38699819213953,-0.09303447227428985,0.003961730434774324
429.4000000000054,48.49378925215982,-0.09336774606546588,0.005204992073701398
430.5000000000054,48.60150940038036,-0.09176598483840194,0.005279844745731843
431.6000000000054,48.70914189452546,-0.08965045667575802,0.0042899562743805575
432.70000000000545,48.816648617701375,-0.08798707916655206,0.004279194586826129
433.8000000000054,48.92462181243329,-0.08668237008688294,0.00395988661326907
434.90000000000543,49.03216819738278,-0.08665875772086282,0.0026407047286696184
436.00000000000546,49.139371479567714,-0.08598075358034124,0.0030664680583551984
437.1000000000055,49.24776482729887,-0.08297235710374053,0.002639872746903471
438.2000000000055,49.35562551704858,-0.07949200366609774,0.003330464345202344
439.3000000000055,49.46000118326414,-0.08014301960255191,0.004619997497220751
440.40000000000555,49.56963122222089,-0.07876817794106736,0.0032967907483429926
441.50000000000557,49.676742694410876,-0.0774142319366507,0.0036200712872656027
442.6000000000056,49.78505043967295,-0.07583702514364718,0.002314314155835717
443.70000000000556,49.89307699687949,-0.07271770102517318,0.0036312412012717843
444.8000000000056,50.000512276687445,-0.0708743638535875,0.002310006420392696
445.9000000000056,50.10911555293359,-0.0694435439998351,0.0023236873161369687
447.0000000000056,50.215442245661954,-0.06757779565311707,0.0045766741763726415
448.10000000000565,50.322878641624094,-0.06676301212022435,0.003300142508050996
449.2000000000057,50.43036326862365,-0.06608165313832555,0.003300366453774295
450.3000000000057,50.538196475566174,-0.06322695319476228,0.0019802339987284867
451.40000000000566,50.645865294406725,-0.061550636973997055,0.001987594227909284
452.5000000000057,50.75354512514106,-0.05944754555009036,0.0032982580011866602
453.6000000000057,50.86171816761804,-0.05868254988738698,0.001921997307795742
454.70000000000573,50.96934012900138,-0.057558690315062014,0.0006696507503010096
455.80000000000575,51.07748273861223,-0.05579296203430495,0.001989924614949068
456.9000000000058,51.185369712447624,-0.055745279778295895,0.0019899000000274114
458.0000000000058,51.29358097124091,-0.05313844747513074,0.001989927206655473
459.1000000000058,51.40147784991159,-0.053300427481744087,0.001331557865388966
460.20000000000584,51.50950744553574,-0.05079028611145932,0.00132505750298062
461.3000000000058,51.616020530061014,-0.04896506505337867,-0.000650016463319858
462.40000000000583,51.72546191529591,-0.04855814201819218,0.002031561227679113
463.50000000000585,51.83239070270952,-0.046288891618574524,0.0019898999748679813
464.6000000000059,51.94029052173688,-0.04461219608795818,0.0019899000297227687
465.7000000000059,52.04891196061719,-0.04293982206116999,0.0013503004445087896
466.8000000000059,52.156549412750635,-0.042991420708382674,0.0006699777721488331
467.90000000000595,52.2641775079355,-0.04084489849891935,-0.0006477848453094737
469.0000000000059,52.371695739103146,-0.0397697696471311,0.000623560850643301
470.10000000000593,52.47959194682431,-0.03908590834901364,0.0006545807541140647
471.20000000000596,52.588290412048565,-0.03611744975482755,-0.0006601834352100155
472.300000000006,52.695280503272905,-0.03319844111078585,0.0009770618101976325
473.400000000006,52.80484006549581,-0.03131130260490387,0.0013202390024718014
474.500000000006,52.912829864194286,-0.02991028191950313,0.0013199494446709537
475.60000000000605,53.02089837142056,-0.027677897116169373,1.0728373212032238e-07
476.70000000000607,53.128857788601984,-0.02519871655124592,-1.0384258670725899e-06
477.8000000000061,53.236906321865334,-0.023053605637300145,-0.0009902137886044216
478.90000000000606,53.344948189344414,-0.021267017387888082,-0.0009901691178200167
480.0000000000061,53.452639250520036,-0.01948683090285116,0.0003300078481149882
481.1000000000061,53.561948236869235,-0.016651488955179445,-0.0013962880290474544
482.2000000000061,53.66980726134991,-0.016506804608733213,-0.0013100350064254584
483.30000000000615,53.775413479875304,-0.01354848408161513,-0.0013100096547029594
484.4000000000062,53.88620273153094,-0.013476881129512348,-0.0026318254375459205
485.5000000000062,53.99439629263688,-0.014260683721456696,-0.002630558270541705
486.60000000000616,54.103700711302345,-0.013646694964592462,5.197763943698419e-06
487.7000000000062,54.2115810520422,-0.012131685046616762,4.9461000048545145e-05
488.8000000000062,54.31865689869641,-0.012726480775401127,-0.002577963345885337
489.90000000000623,54.42544651592424,-0.012686757723589338,-0.002577022165418441
491.00000000000625,54.536584693370024,-0.011237462110068862,-0.0013132134540461138
492.1000000000063,54.644971508567075,-0.01074268929067713,-0.0003200880859557387
493.2000000000063,54.75403202257867,-0.010316618125274634,-0.0004794835685686394
494.3000000000063,54.861862736746104,-0.009136250313737403,-0.0016400046698672455
495.40000000000634,54.97051829322322,-0.007994976811708965,-0.001643519298553997
496.5000000000063,55.076885611735875,-0.007301830115847666,-0.004280602136251588
497.60000000000633,55.18725665656207,-0.004509460984411346,-0.004277360531951935
498.70000000000636,55.29579072700545,-0.0042754910613941625,-0.005920222855559487
499.8000000000064,55.40477491071017,-0.003587351396882441,-0.00565604904776329
500.9000000000064,55.51216159072111,-0.0009607533327089715,-0.0032900585922792658
502.0000000000064,55.62153773698635,0.0007712061916373476,-0.0012971623964279644
503.10000000000645,55.731259463376546,0.0028094917695334755,-0.003942700737620264
504.2000000000064,55.83999900000991,0.004802161426810339,-0.003950125009253291
505.30000000000643,55.94742981044052,0.006086274714578525,-0.003950162024120907
506.40000000000646,56.05619096549169,0.008078848654322943,-0.0026438907748680407
507.5000000000065,56.164672707546785,0.012014945376666324,-0.003939985777300592
508.6000000000065,56.2728567668634,0.013984143573259611,-0.0046003963986276375
509.7000000000065,56.38164274992005,0.01688003983051613,-0.006253175997573024
510.80000000000655,56.4894721937486,0.017531353520277182,-0.007570091407185231
511.90000000000657,56.59861680181089,0.019918603626387928,-0.007515179688801332
513.0000000000066,56.70666354945728,0.021042995847894683,-0.007900090223396106
514.1000000000065,56.816220059285016,0.02300706705279841,-0.008294566504162937
515.2000000000066,56.924092012264985,0.023986788375517393,-0.0072428133027209185
516.3000000000065,57.03308364894657,0.025350791467527622,-0.005965216715513755
517.4000000000067,57.142325631149525,0.02499453263795889,-0.003837482311667806
518.5000000000066,57.24981255769754,0.026528188564535364,-0.005933346679842799
519.6000000000067,57.35784276499712,0.02844778557601959,-0.007234192988784471
520.7000000000066,57.467386764652076,0.031943716075578,-0.007240010334156111
521.8000000000067,57.57589433367572,0.0332809546924004,-0.00847448142262408
522.9000000000067,57.68341291435838,0.03461137877889961,-0.008559359249057152
524.0000000000067,57.792607566904415,0.036463479935795046,-0.009308291689360537
525.1000000000067,57.90127203723657,0.038954229738518635,-0.009219799971773135
526.2000000000068,58.01029844294009,0.04029466091217865,-0.009219798444330074
527.3000000000068,58.11838159774307,0.0411070555501629,-0.01053936227832164
528.4000000000068,58.226957353560145,0.043445776924214606,-0.010540100000554276
529.5000000000068,58.33580360328155,0.04434726593622532,-0.010540100716642797
530.6000000000068,58.4447555675907,0.04714861510438896,-0.011277511448769317
531.7000000000069,58.55252242315919,0.048471604192455456,-0.011189906391932958
532.8000000000068,58.66221656665779,0.05254552150528998,-0.011850015682479231
533.9000000000069,58.77083629562269,0.05273468015302594,-0.01184987000446025
535.0000000000068,58.87951292884301,0.05565848842562543,-0.011853930631807508
536.100000000007,58.98809451890342,0.056614869668109635,-0.013168617914284475
537.2000000000069,59.09745608940697,0.05755182608972559,-0.011703179445198053
538.300000000007,59.20620772043146,0.059103335301637076,-0.011611712961372866
539.4000000000069,59.3139374015379,0.06258876910609683,-0.010538853092739053
540.5000000000069,59.42420658956564,0.06424265893641823,-0.012802300047937365
541.600000000007,59.53173547961578,0.06792306290310328,-0.014404249180514306
542.700000000007,59.6404788265811,0.07078879566469937,-0.015810878014342222
543.800000000007,59.74867527415894,0.07461466861267294,-0.01546258472534845
544.900000000007,59.85759028924493,0.07595488977255997,-0.015799816176063075
546.000000000007,59.96659959100642,0.07665193023194697,-0.015995458660637674
547.1000000000071,60.07568207846825,0.07814222884065294,-0.01579819427329099
548.2000000000071,60.18418710568266,0.08018703343577087,-0.014492731430406636
549.300000000007,60.292747835875616,0.08039528105334659,-0.014159986643244693
550.4000000000071,60.40114494982071,0.08157487495270213,-0.015467108580645927
551.500000000007,60.509907498031986,0.08462260949212873,-0.015026036017419031
552.6000000000072,60.61917125026803,0.08605371625225529,-0.01712847719703703
553.7000000000071,60.7272395984996,0.08877357805676013,-0.01755100632974127
554.8000000000072,60.83579753560525,0.09235266251296904,-0.019011887907320002
555.9000000000071,60.94419521250029,0.09471981627580928,-0.01976006088705784
557.0000000000072,61.05365191787411,0.09477622125315335,-0.019759889999936497
558.1000000000072,61.16253094096292,0.09724727609334168,-0.019759838068910796
559.2000000000072,61.27091425437591,0.0983461019513654,-0.021074323313015064
560.3000000000072,61.37910279255431,0.10062481722571533,-0.022400084429939682
561.4000000000073,61.48836997226558,0.10346815533423401,-0.023012635939959836
562.5000000000073,61.597624018012624,0.10662189285582085,-0.023709850915460073
563.6000000000073,61.705071289373244,0.10919100944643943,-0.023705847668129998
564.7000000000073,61.81390424078448,0.11231700087243086,-0.025986064504492923
565.8000000000073,61.922343025933245,0.11211277922917609,-0.02195779929104269
566.9000000000074,62.03095930903541,0.11351891070826543,-0.022059796551462618
568.0000000000074,62.141204070102354,0.11682351407211497,-0.02337887432799235
569.1000000000074,62.2495387420341,0.11936105834741167,-0.024700632625666685
570.2000000000073,62.35833553058813,0.1226227133638432,-0.027329691501741138
571.3000000000073,62.468277481897175,0.1274246727228859,-0.026009554166090965
572.4000000000074,62.57693293441989,0.1326382406462191,-0.02744978145273791
573.5000000000074,62.68627444183782,0.14136378982362713,-0.027330911636124
574.6000000000074,62.79472375822069,0.13538974457359348,-0.02665000551394403
575.7000000000074,62.903744971159476,0.13023580367406487,-0.027989568621990202
576.8000000000075,63.013722230424165,0.12995611055992246,-0.029374565605892577
577.9000000000075,63.12237657001425,0.12945030449550768,-0.029937385672556438
579.0000000000075,63.23083818641602,0.1298149673934858,-0.028640066883476756
580.1000000000075,63.34064561193486,0.1300351886008639,-0.028639452609990457
581.2000000000075,63.447793469689486,0.13067158263640868,-0.030519366218070054
582.3000000000076,63.55733882803241,0.1328280229519072,-0.029581971430109988
583.4000000000076,63.66825453369962,0.1339337107035153,-0.029472475894581684
584.5000000000076,63.77650853800498,0.13633479595393133,-0.03362583613844006
585.6000000000076,63.885968569178075,0.1368714292461917,-0.033589919983794125
586.7000000000077,63.99482146599028,0.13912216751805356,-0.03358278102585288
587.8000000000077,64.10444018230815,0.14114227779531727,-0.033518051772771784
588.9000000000076,64.21338023965356,0.14195668383019364,-0.03491019475251811
590.0000000000076,64.32297997300824,0.1445404325979112,-0.03621080756294148
591.1000000000076,64.4327935870394,0.14579304226324025,-0.037562062632654936
592.2000000000077,64.54198295174723,0.14612669457020858,-0.03819791475864598
593.3000000000077,64.64935909262135,0.14856376030123714,-0.038195930070132
594.4000000000077,64.76172644880074,0.15066491259098908,-0.03753995716279501
595.5000000000077,64.87009253342585,0.15475825134125099,-0.03885564864566238
596.6000000000078,64.97929619592537,0.15712363910982713,-0.041498989297137356
597.7000000000078,65.08581599931507,0.15674621113706483,-0.04152757083134784
598.8000000000078,65.19812283774644,0.1597289155765293,-0.040496000534367305
599.9000000000078,65.30807314839974,0.16319838988018104,-0.042646561216855616
601.0000000000078,65.4172972965182,0.1639252487933037,-0.0441296182549058
602.1000000000079,65.52596421375992,0.16797197325195012,-0.04471163525668942
603.2000000000079,65.63505812189167,0.17032795365697603,-0.044131081353165236
604.3000000000079,65.74525576023454,0.17239197746499127,-0.0454401378692042
605.4000000000078,65.85396168713822,0.17622593526865798,-0.04667427760356002
606.5000000000078,65.96235798168178,0.17728484341274958,-0.046762063751288885
607.6000000000079,66.07169610098013,0.1790796632320957,-0.049398863455610176
608.7000000000079,66.18130423409862,0.18402848791940307,-0.04940076307266317
609.8000000000079,66.2892541259325,0.18367383948880805,-0.05071117182259277
610.9000000000079,66.39999790664298,0.18898994051471368,-0.05202996611477673
612.000000000008,66.50947682398133,0.1924069668879908,-0.050711250622345716
613.100000000008,66.6192922874487,0.19432646027345726,-0.05335622909301074
614.200000000008,66.7255314180571,0.19850784456809334,-0.05335376537789038
615.300000000008,66.8374607613203,0.20153597503592874,-0.054660158044766316
616.400000000008,66.9463835669284,0.2080850976482402,-0.05600475635290936
617.5000000000081,67.05462009158961,0.2113523017467033,-0.057296800010260274
618.6000000000081,67.16543503599434,0.21360845864030614,-0.057299677603454224
619.7000000000081,67.27584549419674,0.21944342798631958,-0.060024728470795985
620.8000000000081,67.38418893862803,0.22349091566458504,-0.06091932523980592
621.9000000000082,67.49356109676131,0.2285156003180551,-0.0609140542618265
623.0000000000082,67.60387203994122,0.23497679733131105,-0.06224013934833339
624.1000000000081,67.71175173219012,0.23948796352484,-0.062312702186920976
625.2000000000081,67.82194544813414,0.24460094970543614,-0.06356550849974152
626.3000000000081,67.93107409463586,0.2509453948592539,-0.06622028958942572
627.4000000000082,68.03890217795781,0.2584793852284485,-0.06751093883801129
628.5000000000082,68.15123377268873,0.2667303920829221,-0.06927420900562176
629.6000000000082,68.26073397510933,0.27567904867683785,-0.07015687031973306
630.7000000000082,68.37117463804076,0.28520721158752926,-0.07274570598327479
631.8000000000083,68.48079639691147,0.2924764093545633,-0.07278005985594005
632.9000000000083,68.58960467077307,0.3008305324577938,-0.07406334576209206
634.0000000000083,68.70000000000084,0.30901000000009093,-0.0760701199994358
635.1000000000083,68.80957526265065,0.3192073294337375,-0.07738835674076006
636.2000000000083,68.91980677309911,0.32617197833997214,-0.08002995670942248
637.3000000000084,69.02669274701233,0.3366721683568428,-0.08276500322915759
638.4000000000084,69.13849291760098,0.34661172777991517,-0.08364340381632829
639.5000000000084,69.24877941098305,0.36014689476923767,-0.08607010538344362
640.6000000000083,69.3572929673225,0.36816090574130067,-0.08887580836553832
641.7000000000083,69.46626347172213,0.37624229676414345,-0.09012183031687604
642.8000000000084,69.57861387474124,0.3881600609353735,-0.09335869215036086
643.9000000000084,69.6881345481798,0.4010088790156242,-0.09466705075277426
645.0000000000084,69.79832055900904,0.41368390268326327,-0.09861542506778243
646.1000000000084,69.90680294016266,0.42715679641337945,-0.1026497815473495
647.2000000000085,70.01731398397827,0.441019610382448,-0.10392789589959328
648.3000000000085,70.12694646675267,0.45460621632783166,-0.10710761985614115
649.4000000000085,70.23742953329415,0.4695611548132966,-0.11012700467685121
650.5000000000085,70.34570549554813,0.48284517702767954,-0.11409966777899916
651.6000000000085,70.45712390681526,0.4962418000080831,-0.11683931309490347
652.7000000000086,70.56720050618554,0.5113572118264633,-0.11811259796565077
653.8000000000086,70.6773962485391,0.5273279929768852,-0.12326762112463552
654.9000000000086,70.78705456942815,0.542498475573695,-0.12526097617144716
656.0000000000086,70.89713261686119,0.5611794318284208,-0.12942026769166093
657.1000000000087,71.00680255968831,0.5789068034830173,-0.13182026776309463
658.2000000000087,71.11640472667376,0.5940455771822333,-0.1352923212280288
659.3000000000086,71.22741465479817,0.6135142694846407,-0.14057613957461035
660.4000000000086,71.33678217031691,0.6311096291261994,-0.1466254391809354
661.5000000000086,71.44694748679358,0.6520448463948957,-0.14955219918007057
662.6000000000087,71.55768296015104,0.6682951377672498,-0.1536648941598524
663.7000000000087,71.66759135005461,0.6875991440742997,-0.15844412349306447
664.8000000000087,71.77857139601278,0.7068726065674034,-0.16549243311287132
665.9000000000087,71.8880292842798,0.727518585257739,-0.16572031883228
667.0000000000088,71.99716894521556,0.7464297451724069,-0.17181088539930256
668.1000000000088,72.10720112296309,0.767306471879361,-0.17751766038714845
669.2000000000088,72.21859569982726,0.789397293410807,-0.18035870873048276
670.3000000000088,72.32818826436669,0.8132289854696714,-0.1908477976696359
671.4000000000088,72.43912194989883,0.8313069962115327,-0.19773142943730715
672.5000000000089,72.54927342102454,0.8583225282813054,-0.2039339377827467
673.6000000000089,72.66000210707148,0.8828504344614987,-0.20912616351166546
674.7000000000089,72.77059097997113,0.9035836873086796,-0.21572692195955678
675.8000000000088,72.88187855984594,0.9281299785310123,-0.2222710507513641
676.9000000000088,72.99102850653894,0.9569285938310974,-0.22824926669882117
678.0000000000089,73.10205053082927,0.981363741191989,-0.23424207638717975
679.1000000000089,73.21214507696315,1.0097044158564346,-0.24447622241201383
680.2000000000089,73.32230369576688,1.0370357317778438,-0.25147018912931696
681.3000000000089,73.43287973808681,1.0648628787526055,-0.25951370881975677
682.400000000009,73.54330507187674,1.0946472495885502,-0.2664383909652708
683.500000000009,73.65357743992935,1.122726015125892,-0.2738510875869484
684.600000000009,73.76346490783263,1.1501426376793988,-0.28142885252141703
685.700000000009,73.87372554420227,1.1803922095009043,-0.29067586202195006
686.800000000009,73.98346377788774,1.2089735722715698,-0.29974654086677877
687.9000000000091,74.09481301432828,1.241575461290495,-0.31027683743125234
689.0000000000091,74.20484881436064,1.269857712873904,-0.3194158481915341
690.1000000000091,74.31534186782326,1.3038155090199404,-0.3288318220993207
691.2000000000091,74.42504207681093,1.3370933104410188,-0.339723605150863
692.3000000000092,74.53550956150265,1.3674909013327778,-0.34960066158510106
693.4000000000092,74.64554587393894,1.4025500935716024,-0.3587427483692158
694.5000000000091,74.75617986669562,1.4337731718816351,-0.3698369547578899
695.6000000000091,74.86684488983894,1.4683988765286509,-0.3826939148775441
696.7000000000091,74.97767985625958,1.5008428759446146,-0.3942051838576841
697.8000000000092,75.08791518682942,1.532928885178529,-0.4055718566989843
698.9000000000092,75.19898734340487,1.5685079663965205,-0.41513114568586884
700.0000000000092,75.30879784975417,1.5987631170371424,-0.42613184172786633
701.1000000000092,75.41920161203434,1.6360403111126436,-0.4400138736393395
702.2000000000093,75.5291889035529,1.6674578627126078,-0.45376468843192264
703.3000000000093,75.64117825512956,1.7008608775170457,-0.46817119599783075
704.4000000000093,75.7518444118792,1.737453244864697,-0.48057368825167357
705.5000000000093,75.86142186809184,1.7735392847950007,-0.49307039390451735
706.6000000000093,75.97190507141576,1.8053981033129995,-0.506584148040937
707.7000000000094,76.0838649478999,1.8377303753107792,-0.5206117720451777
708.8000000000094,76.19331939254084,1.8698579611008894,-0.5350671875732478
709.9000000000094,76.3029314578544,1.9013126648394858,-0.5482346580494606
711.0000000000093,76.41342235427484,1.9331068418977018,-0.5662722555171014
712.1000000000093,76.52350994001759,1.9663863975055347,-0.5814171323966768
713.2000000000094,76.63565575467739,1.9953298448917003,-0.5954435023681541
714.3000000000094,76.74389612317007,2.0268804573837382,-0.6096720812325556
715.4000000000094,76.8555439196528,2.061723249983005,-0.6258615013045414
716.5000000000094,76.96581665850543,2.0933591300125958,-0.642598481388065
717.6000000000095,77.07573568097503,2.129503908123161,-0.6579818554043504
718.7000000000095,77.18605366747767,2.160842091012252,-0.6747725594606622
719.8000000000095,77.29511251433927,2.1944344464021484,-0.6922142838761114
720.9000000000095,77.40563720173428,2.227724241026178,-0.7073679902676524
722.0000000000095,77.51566869518005,2.2629929010597754,-0.7252013090168794
723.1000000000096,77.62683685330305,2.2976308634109603,-0.7421402075576324
724.2000000000096,77.73770718712314,2.3321149464292614,-0.763666363716351
725.3000000000096,77.84672046878553,2.370289659837636,-0.7805756832807047
726.4000000000096,77.95747728395612,2.4045837420176155,-0.800750508031963
727.5000000000097,78.06763788580436,2.43985972162628,-0.81640407860194
728.6000000000097,78.17611944927366,2.4751286691046963,-0.8382156315316274
729.7000000000096,78.28875542260815,2.5076586782373984,-0.8567522261494784
730.8000000000096,78.398510396699,2.5383408378320294,-0.8773037956938547
731.9000000000096,78.50841520459745,2.571513765844341,-0.897407906684542
733.0000000000097,78.61970138058099,2.6031477068333935,-0.9179001689687438
734.1000000000097,78.72866690560244,2.6331756740575196,-0.9385530065279521
735.2000000000097,78.84039723257156,2.6598864004299987,-0.9581855993977695
736.3000000000097,78.9509131779565,2.6882031089690237,-0.9775552254268378
737.4000000000098,79.06149977374511,2.7141980499242693,-1.0013991850408015
738.5000000000098,79.17233604151382,2.7450235781841177,-1.0184296403938267
739.6000000000098,79.28231718032617,2.7832769603063143,-1.041684623190736
740.7000000000098,79.39314329320197,2.8260472481762213,-1.063442018185162
741.8000000000098,79.50396895556825,2.8844077495641782,-1.0825916840039516
742.9000000000099,79.61436817540125,2.949933431761029,-1.1057891932343131
744.0000000000099,79.72424198852435,3.0214517699421775,-1.1244744189900544
745.1000000000099,79.83435251353089,3.0926702405372657,-1.1474739127489069
746.0000000000099,79.92529378959061,3.1501673211676797,-1.1671217757721402