File: 01_Data/Asphalt_Shingle/STA/N2/10K_min/Asphalt_Shingle_STA_N2_10KData_220916_R3.csv
##Temp./Â°C,Time/min,DSC/(mW/mg),Mass loss/mg
51.0,10.881785420955465,-1.607786768328636,0.0028289448652389915
52.100000000000016,11.205693869862298,-1.5267963200991734,0.0012192219609126198
53.20000000000003,11.440501611800878,-1.4736891504252798,0.0022354962183976923
54.30000000000005,11.642359582770176,-1.436113231208335,0.0003717433082681687
55.40000000000006,11.821633809841696,-1.406075940509424,0.0007214081011950313
56.50000000000008,11.992796213384665,-1.3840169103254853,0.0016243267786202331
57.600000000000094,12.153537720697432,-1.3623350146155795,0.0027221825795447074
58.70000000000011,12.305910200693308,-1.3449342217190132,0.0007346382037920485
59.800000000000125,12.45886371829265,-1.3305134272338808,0.0002840839139972573
60.90000000000014,12.603826515571422,-1.3183569379513298,0.001238975591962177
62.000000000000156,12.743874325527122,-1.3069488724250007,0.001291382410081976
63.10000000000017,12.88413040193552,-1.2969301761228555,0.0004091277485360756
64.20000000000019,13.018972510069842,-1.286355100744501,0.000230299727365324
65.30000000000021,13.153054936666528,-1.2772202995152415,0.000412947099857508
66.40000000000022,13.28468734672607,-1.2688686881546,0.0004422517160027617
67.50000000000023,13.418601810368491,-1.2605261475849547,0.00013058925456332915
68.60000000000025,13.545946790906832,-1.2518669127151054,0.0001046261090822398
69.70000000000027,13.674786965710437,-1.2450197874605824,0.00037870347015100947
70.80000000000028,13.801615059987082,-1.2370537490705684,0.00137662218577006
71.90000000000029,13.92648984182419,-1.2290953434342144,-0.0008592505518283389
73.00000000000031,14.05042009068534,-1.221139190612114,7.349647334287113e-06
74.10000000000034,14.173311690448516,-1.2143080812101292,3.6404624052632784e-05
75.20000000000034,14.295834607632898,-1.2071557654666,0.0012704263577942854
76.30000000000035,14.416169683543766,-1.19974052153854,-8.696030104449193e-06
77.40000000000038,14.534175094762295,-1.1939899294246668,-5.345017671132268e-06
78.5000000000004,14.657485818088238,-1.1874315377013505,-0.001087614448577412
79.6000000000004,14.77440304256362,-1.180933587326067,-0.0006019193659319022
80.70000000000041,14.895137580025594,-1.173857920055979,0.00036008438038370727
81.80000000000044,15.011199341716164,-1.1666341186455185,-1.366203385089193e-06
82.90000000000046,15.127820577709617,-1.1625827998422305,-0.001089831844546918
84.00000000000047,15.244805718428035,-1.155792009048112,5.546198454275952e-06
85.10000000000048,15.36168897677535,-1.1488865527930434,-0.0013301810554660065
86.2000000000005,15.47564780485227,-1.1441727578839085,-4.352720634859253e-05
87.30000000000052,15.588978877648033,-1.1388587769010565,-0.0013323358829540055
88.40000000000053,15.704730934363512,-1.133595276395822,-0.00010759897568890509
89.50000000000054,15.818242186086378,-1.1274950530854202,-9.836304899435433e-05
90.60000000000056,15.929824677274436,-1.1222632844676297,-9.988454667331226e-05
91.70000000000059,16.042105792776105,-1.117153195860661,-0.00010049442243298401
92.8000000000006,16.154380587685093,-1.1119479814919573,-0.001431404997246144
93.9000000000006,16.26534605306967,-1.10676039424849,-0.0004551599938631412
95.00000000000063,16.375445819605503,-1.1016329540018324,-9.45965575160912e-05
96.10000000000065,16.48732592851948,-1.0952579923562489,-0.00021707232705958646
97.20000000000066,16.59748969166336,-1.08952998570351,-0.00011544270957442038
98.30000000000067,16.706404859566977,-1.0856168225742988,-0.00027147789307191417
99.40000000000069,16.815710196869247,-1.0813591673686378,-0.0014190140194969558
100.50000000000071,16.925416983991962,-1.077032587321692,-0.0014809033632579016
101.60000000000072,17.034352004640613,-1.0724748643152895,-0.001414738956799333
102.70000000000073,17.142809954634224,-1.0671244184035353,-0.0017461535475491452
103.80000000000075,17.251211566268278,-1.0635179668087569,-0.00274918099287369
104.90000000000077,17.35882749230304,-1.0571368132101235,-0.0014418527805366566
106.00000000000078,17.46802285040851,-1.0537069191771982,-0.0015278784723391503
107.10000000000079,17.57560564240247,-1.0498111256681961,-0.0014364028724127564
108.20000000000081,17.684794305921947,-1.0457040806904898,-0.0014079089756857677
109.30000000000084,17.792076547022468,-1.041979780189741,-0.0014246396216561763
110.40000000000084,17.899407587590716,-1.0371542138012972,-0.0014197654601968424
111.50000000000085,18.006942076149375,-1.0330162557081612,-0.00045558014945923375
112.60000000000088,18.113696882096168,-1.0287333574295425,-0.0014312924992978537
113.7000000000009,18.223284972809115,-1.0246649875993727,-0.0020752888073114484
114.8000000000009,18.329074116895672,-1.0220557376072898,-0.0010978986979308658
115.90000000000092,18.437153797634124,-1.0198553119385037,-0.0010120849839005963
117.00000000000094,18.545237997612215,-1.0138668641749424,-0.0014233182095066965
118.10000000000096,18.65112610413628,-1.0114336609687633,-0.0026679463480761
119.20000000000097,18.75875893690773,-1.006779033914184,-0.00207998171487489
120.30000000000098,18.866120198963674,-1.0028720323962124,-0.002739884679084259
121.400000000001,18.973117405095003,-1.0000160141625674,-0.0014198687856539216
122.50000000000102,19.07951913226898,-0.9962656443271569,-0.002454269594262648
123.60000000000103,19.18602319779217,-0.9927158467015734,-0.0015510076946214646
124.70000000000104,19.292964629869445,-0.9899753774864515,-0.0014401237942438527
125.80000000000106,19.39936736885629,-0.985454441918664,-0.001419761023034205
126.90000000000109,19.506114366453605,-0.9823077523148259,-0.0020663989553257878
128.00000000000108,19.612572573949677,-0.9804187220179166,-0.0004264993399574202
129.1000000000011,19.717821070506425,-0.9753955566654208,-0.0007560568300815085
130.20000000000113,19.82388545205196,-0.9734987489149473,-0.001750030360036181
131.30000000000115,19.93038070308855,-0.9696945113754019,-0.0026253949421408684
132.40000000000117,20.03634631646016,-0.9669511953019843,-0.0017522821217070828
133.50000000000117,20.14101137571857,-0.9638872070746624,-0.0017500697713637159
134.6000000000012,20.246821793649303,-0.9614178600690145,-0.002017216533054089
135.7000000000012,20.35373716982885,-0.9577065732330013,-0.0028265846847266296
136.8000000000012,20.45917000000011,-0.9549799999999893,-0.003064832400746731
137.90000000000123,20.564423758452453,-0.9522513106767859,-0.0030691824966395664
139.00000000000125,20.670130435355752,-0.9487679167718628,-0.0017502635148800572
140.10000000000127,20.775460304508574,-0.945504398816239,-0.0030688718320388553
141.2000000000013,20.881024149448805,-0.9415609074033914,-0.004401577531150558
142.3000000000013,20.986245352123817,-0.9383842970415729,-0.0030617066177094365
143.4000000000013,21.09062862524043,-0.9360452635498836,-0.003069582063182086
144.50000000000134,21.195548246093367,-0.9323313866246027,-0.003102009300828712
145.60000000000133,21.301371950373106,-0.9305875677320226,-0.004386738391734646
146.70000000000135,21.405948077792814,-0.9271440400666275,-0.004389553754900355
147.80000000000138,21.510256143770075,-0.9255396890966578,-0.0033496494159299672
148.9000000000014,21.616202434123196,-0.9222992254467223,-0.00438435482233368
150.00000000000142,21.72037408872783,-0.9189523473776987,-0.0033901120728065948
151.10000000000142,21.825262789366672,-0.915942518909062,-0.004255540177427797
152.20000000000144,21.930096728162916,-0.9145616952063789,-0.003723509237077316
153.30000000000146,22.03470481530253,-0.90998179516198,-0.005099284929529269
154.40000000000146,22.13955001021598,-0.9072392054509353,-0.003070408293217586
155.50000000000148,22.244834014404827,-0.9049918090735657,-0.004143213975391191
156.6000000000015,22.349467555518626,-0.9021922490038351,-0.0036228994599141195
157.70000000000152,22.45454653002405,-0.8986426875562502,-0.004380013522508275
158.80000000000155,22.559940335433655,-0.8949774187471101,-0.004380015932861525
159.90000000000154,22.664037796910986,-0.8935115818920297,-0.0030714707690768783
161.00000000000156,22.76898430129343,-0.8895867296612272,-0.004379999289243042
162.1000000000016,22.87329393764885,-0.8876646917527231,-0.003072061663417891
163.20000000000158,22.97777177386565,-0.8839550571597187,-0.004444351452817408
164.3000000000016,23.08324141176164,-0.8808225807467758,-0.003069740779046981
165.40000000000163,23.188640629879302,-0.8788990833260589,-0.004714518719314942
166.50000000000165,23.29261698970045,-0.8765774357623973,-0.006030148476486197
167.60000000000167,23.396738246835994,-0.8739234944073373,-0.0047180916509406146
168.70000000000167,23.501778268181084,-0.8713655859972012,-0.005321498266103841
169.8000000000017,23.604611029197866,-0.8684852467117725,-0.004721377648834846
170.9000000000017,23.711845516584408,-0.8658815721836947,-0.004709897436487864
172.0000000000017,23.815756154679846,-0.8639248233987659,-0.006030232075151076
173.10000000000173,23.91972484837709,-0.8629921055511849,-0.006643315310403963
174.20000000000175,24.02595373106537,-0.8603943677904796,-0.006039855701608143
175.30000000000177,24.128588824825798,-0.8575742247048106,-0.006089380973458791
176.4000000000018,24.234496050243393,-0.8545124010592556,-0.0060298108630516545
177.5000000000018,24.339268357883377,-0.8524906822959883,-0.007349249844162298
178.6000000000018,24.443982127759075,-0.850412202266838,-0.0053684939726657
179.70000000000184,24.547860232857314,-0.8474235972693093,-0.006093584402503183
180.80000000000183,24.65266631989031,-0.8465929602783143,-0.006031489433806048
181.90000000000185,24.757576255450562,-0.8421019870834988,-0.007349821678359625
183.00000000000188,24.862765799164503,-0.8413315878920193,-0.008084175956432738
184.1000000000019,24.96708798402152,-0.8394471438729242,-0.007349663567679521
185.20000000000192,25.070067884709754,-0.8367595219460728,-0.007349814044402159
186.30000000000192,25.175782718709282,-0.8348619987344165,-0.00736912321598604
187.40000000000194,25.280108148815923,-0.8312873659571343,-0.007019869515968669
188.50000000000196,25.384376313132492,-0.8293470160307438,-0.006690546846771284
189.60000000000196,25.48774904495663,-0.8262179910281088,-0.0073611542659568485
190.70000000000198,25.591089933348808,-0.8241876777558154,-0.007349943484608268
191.800000000002,25.69768911902422,-0.8206125089866545,-0.007678192348745672
192.90000000000202,25.801917584841956,-0.8193909893949216,-0.00899995419763755
194.00000000000205,25.90572760213055,-0.8173681761441479,-0.008989674687124083
195.10000000000204,26.00961161261976,-0.8156021133530513,-0.010309952447536297
196.20000000000206,26.113796013367473,-0.8137723812167171,-0.010642208317066082
197.3000000000021,26.217640938354787,-0.8110426303678002,-0.010639940613328402
198.40000000000208,26.320834009338444,-0.8087651510351057,-0.010316047158537955
199.5000000000021,26.425299556897887,-0.8065200567410131,-0.010309937697238869
200.60000000000213,26.52946985453763,-0.8041550037748595,-0.008997740725755765
201.70000000000215,26.634013112765228,-0.803686591650494,-0.010311991374432061
202.80000000000217,26.738416469183885,-0.8003157415649829,-0.011629910666924204
203.90000000000217,26.842391691263344,-0.7981416872531714,-0.011630167433003713
205.0000000000022,26.946267011170345,-0.7956417855859468,-0.012296542788371667
206.1000000000022,27.051742405608614,-0.7948463584816216,-0.01229007801640103
207.2000000000022,27.155129801366947,-0.7917599204250071,-0.012290079289849487
208.30000000000223,27.25857822789925,-0.7886701657590776,-0.013609768207487605
209.40000000000225,27.36307431037182,-0.787361486659344,-0.013610078032966655
210.50000000000227,27.467798286892812,-0.7859874709829757,-0.013624797141740252
211.6000000000023,27.572316228059762,-0.783162230830731,-0.014293435591683057
212.7000000000023,27.67662306603058,-0.781487051989819,-0.014270069995249823
213.8000000000023,27.781152340958343,-0.7805990366525805,-0.014270063268249977
214.90000000000234,27.884640412763968,-0.7774969239444108,-0.012941476787562411
216.00000000000233,27.98896416393339,-0.7760482385522707,-0.009230105499647312
217.10000000000235,28.094203651615338,-0.7741373628567872,-0.023534580311248998
218.20000000000238,28.197023426848705,-0.7722283498176131,-0.015373299043273114
219.3000000000024,28.29984550303611,-0.77142684314474,-0.015360068517255687
220.40000000000242,28.404737978568356,-0.7698008105020024,-0.016356866019673788
221.50000000000242,28.509919204013567,-0.7673544225764123,-0.016721472512803537
222.60000000000244,28.614276657643522,-0.7649901065465409,-0.016350008361517343
223.70000000000246,28.718776798183136,-0.7623394324721622,-0.017669259717558283
224.80000000000246,28.82277480318086,-0.7621201383486566,-0.017990801509058407
225.90000000000248,28.926810813444373,-0.7601585763804111,-0.01800037666904819
227.0000000000025,29.03206334859766,-0.7599068126889038,-0.019617808131537906
228.10000000000252,29.13668316142689,-0.7563672956133312,-0.018659769545282145
229.20000000000255,29.241399206004623,-0.7562030873741384,-0.020310654672731854
230.30000000000254,29.344372031088504,-0.7536918764826619,-0.020318059947314726
231.40000000000256,29.450387956458687,-0.7529227960637617,-0.02029784417424274
232.5000000000026,29.55473284155197,-0.750468539762029,-0.02063003024850829
233.60000000000258,29.65896045904442,-0.7501901492463516,-0.0219500243416908
234.7000000000026,29.764602734207386,-0.7492650935756519,-0.020646317576388018
235.80000000000263,29.867327306735408,-0.7494463550456731,-0.023199610781076796
236.90000000000265,29.972991642313403,-0.7487915664961539,-0.02327007743475784
238.00000000000267,30.07878310650499,-0.7485639970942822,-0.0245830789721162
239.10000000000267,30.181603004271366,-0.7466855375242352,-0.02313369569289847
240.2000000000027,30.287331529398088,-0.7465037567396995,-0.02557002579495604
241.3000000000027,30.39333182090416,-0.7455124177765343,-0.025539015037566948
242.4000000000027,30.497931216290468,-0.7436390361484037,-0.026564754571809956
243.50000000000273,30.60305065584265,-0.7429303407401553,-0.026873556101407736
244.60000000000275,30.707972880451273,-0.7410872037173982,-0.02787978882947506
245.70000000000277,30.81087727120323,-0.7403085501871645,-0.029189822456267223
246.8000000000028,30.916340825943553,-0.7371597438930912,-0.030179823813571982
247.9000000000028,31.021958472287064,-0.7375100333697028,-0.030179933322700858
249.0000000000028,31.126773663053633,-0.7353199016850567,-0.030511699688637428
250.10000000000284,31.22967946916792,-0.733219328822437,-0.03151487677167575
251.20000000000283,31.33538469771443,-0.7316174035984533,-0.0328199330012251
252.30000000000285,31.439464354279608,-0.7287528238836887,-0.032160788085365155
253.40000000000288,31.5453359268507,-0.7280465458707057,-0.03251147447243907
254.5000000000029,31.647508198133504,-0.7276529696978083,-0.035121071343501065
255.60000000000292,31.753792641794256,-0.7256824699848228,-0.03511981444132051
256.7000000000029,31.859949828829937,-0.7254424621933879,-0.035845367509401704
257.8000000000029,31.96318034797158,-0.7234331433127152,-0.037100313425718845
258.90000000000293,32.065724736319886,-0.7218775822602891,-0.03904008716671381
260.00000000000296,32.172400665880794,-0.719799631636155,-0.03973996372316435
261.100000000003,32.27699713762655,-0.7196422089089458,-0.03973984581693912
262.200000000003,32.3815493121463,-0.7165309544296297,-0.03992480421444666
263.300000000003,32.48571051612219,-0.7153819633950027,-0.04106099993831114
264.40000000000305,32.59054249985514,-0.714579643429195,-0.04300550455054264
265.50000000000307,32.69502001762508,-0.7124634356042603,-0.044340161110716814
266.6000000000031,32.79996225010471,-0.711776554484526,-0.04434011332150245
267.7000000000031,32.90533145442458,-0.7107830807290548,-0.0456629599593632
268.8000000000031,33.00925777391422,-0.7087719076777851,-0.04698050163687073
269.9000000000031,33.112111219323936,-0.7086556034024221,-0.048299355242996
271.0000000000031,33.21811121435541,-0.7071394171634912,-0.04958917931573925
272.10000000000315,33.323702597717315,-0.7074687794705506,-0.05098055903970389
273.2000000000032,33.42820085999571,-0.7065591846047468,-0.050930001015775606
274.30000000000314,33.53270669398424,-0.7052595461419439,-0.0509298520352619
275.40000000000316,33.63758930638376,-0.7048105452915022,-0.05224257917250208
276.5000000000032,33.74349142952207,-0.7037485331698973,-0.05459583906790488
277.6000000000032,33.848474744007774,-0.7031242930128708,-0.0558800330166882
278.70000000000323,33.95287905359243,-0.7019738779809963,-0.057084632750674213
279.80000000000325,34.058346055946316,-0.7002367036734342,-0.05718990192241602
280.9000000000033,34.164182498871,-0.6988531583147313,-0.058824784297832
282.0000000000033,34.265524257655194,-0.6974596001009159,-0.06120083230907891
283.1000000000033,34.37056280483604,-0.6979107657036074,-0.06157477925520771
284.20000000000334,34.47776252175261,-0.696179454953443,-0.06278014561620227
285.30000000000337,34.58241046255823,-0.6956348625852898,-0.06410059710346161
286.40000000000333,34.68825482335649,-0.6943552481763066,-0.0640760699354157
287.50000000000335,34.79300095010118,-0.6936215856051199,-0.06673982025549297
288.6000000000034,34.89767712530671,-0.6932001579495951,-0.068055912910292
289.7000000000034,35.002320124681845,-0.6931850364262324,-0.06937039556970248
290.8000000000034,35.107520453097756,-0.6926292449628215,-0.07201121183304293
291.9000000000034,35.21218776358209,-0.6914306271613909,-0.07261706482354091
293.0000000000034,35.31761484789556,-0.691287824646436,-0.07399241118564204
294.10000000000343,35.4222685129059,-0.6909238689976871,-0.07530165678628586
295.20000000000346,35.52716907172703,-0.6907955885364134,-0.07796886410672199
296.3000000000035,35.63266444255668,-0.691158943093184,-0.07923542453493582
297.4000000000035,35.73784815810385,-0.6899240737067321,-0.07926023639588031
298.5000000000035,35.84293381924074,-0.6894463946561951,-0.08086843447579284
299.60000000000355,35.947521882908724,-0.6897103147264213,-0.083209882279204
300.70000000000357,36.05359187408911,-0.6908283749667666,-0.08454306528706512
301.8000000000036,36.15917101112583,-0.6880100436167069,-0.08455525362977356
302.9000000000036,36.26456116701522,-0.688308952099961,-0.08584689849189653
304.0000000000036,36.369745402706855,-0.6893731897434753,-0.0871212391216476
305.1000000000036,36.47450388452986,-0.6876019358649538,-0.08979902184172017
306.2000000000036,36.57980223809638,-0.6859923841765316,-0.08984234243179845
307.30000000000365,36.68297986592284,-0.6858016842968913,-0.09375692043887396
308.4000000000037,36.79080687735637,-0.6840941452152884,-0.09508929514445752
309.5000000000037,36.89710468957847,-0.6842212393024203,-0.09736011623037655
310.60000000000366,37.000917704621955,-0.6833793047788956,-0.09711972481572806
311.7000000000037,37.108239925831846,-0.6834932857735052,-0.09966157030479028
312.8000000000037,37.21220909770764,-0.682116141333753,-0.10031813859940186
313.90000000000373,37.31895964471676,-0.6814322312602734,-0.10328109059903978
315.00000000000375,37.42399049701329,-0.6821293113757508,-0.10362230361921432
316.1000000000038,37.529741303398716,-0.6811763311396042,-0.10626106260620327
317.2000000000038,37.6352582784636,-0.6824323498716829,-0.1066073022077152
318.3000000000038,37.741155022767074,-0.6809073599951336,-0.10941322490184335
319.40000000000384,37.845826449413,-0.6801767741200793,-0.1128524133265123
320.5000000000038,37.950827015472115,-0.6795995163445585,-0.11285511239516977
321.60000000000383,38.057802733248536,-0.6789678962049572,-0.11424820714899031
322.70000000000385,38.16302112554659,-0.679293973259848,-0.11789868018988336
323.8000000000039,38.26917096676142,-0.6781500623420335,-0.11921998726114724
324.9000000000039,38.37393434349889,-0.6772877480769588,-0.12097693792843423
326.0000000000039,38.480656635397146,-0.6768432546261638,-0.12228018807945196
327.10000000000394,38.585883839092695,-0.6778709615851226,-0.12482266850762702
328.2000000000039,38.69103733077965,-0.6760597327890334,-0.1264698705644225
329.30000000000393,38.797502560047626,-0.6754087389786199,-0.1277775849234417
330.40000000000396,38.90355084752127,-0.6749799835346848,-0.130518948783505
331.500000000004,39.00917000000035,-0.6747299999999863,-0.13256234308557335
332.600000000004,39.11488727385147,-0.6759735818286314,-0.13404135218530744
333.700000000004,39.219446266592826,-0.6751945959983847,-0.13536129983416867
334.80000000000405,39.32436952069856,-0.6740464786249787,-0.13796578634167034
335.90000000000407,39.43303303457339,-0.6718945976000136,-0.14066958810202435
337.0000000000041,39.53981192051872,-0.6719061302416723,-0.1419498233287757
338.10000000000406,39.6455326010367,-0.6710503499440723,-0.14457221566312883
339.2000000000041,39.75237916072821,-0.67009585614541,-0.14455650328423575
340.3000000000041,39.85623211032321,-0.6700662156290361,-0.14724991975663126
341.4000000000041,39.96394767768232,-0.670511793797544,-0.14971700761703532
342.50000000000415,40.07093742296242,-0.67011956478667,-0.1521511085168843
343.6000000000042,40.176826714699246,-0.6705321525416917,-0.15510907714248523
344.7000000000042,40.28350868966111,-0.6701018957630585,-0.15606979751355743
345.80000000000416,40.38926419418468,-0.6695178332187616,-0.1591807025647407
346.9000000000042,40.494880594378884,-0.6695830138685923,-0.16051978189814875
348.0000000000042,40.602371339857825,-0.6702881029676956,-0.16312797120940292
349.10000000000423,40.705946480373534,-0.6691749429509531,-0.16430746069619495
350.20000000000425,40.813468985727404,-0.6694756511000002,-0.16706657916880285
351.3000000000043,40.91966524719338,-0.6688267314779028,-0.16940412652612702
352.4000000000043,41.02656767389642,-0.6682332894438616,-0.17233645987470592
353.5000000000043,41.13284802418309,-0.6662559639046264,-0.17330506063793782
354.60000000000434,41.238265313787466,-0.6692793454424987,-0.17559177101235202
355.7000000000043,41.34472540615597,-0.6703263451846846,-0.17894974777891193
356.80000000000433,41.45044062761422,-0.6718340484971271,-0.1815607862431463
357.90000000000435,41.55742987409441,-0.6713731366088613,-0.18281922711841592
359.0000000000044,41.66307576500373,-0.6718086033177516,-0.18557303298431105
360.1000000000044,41.7687857082727,-0.6737223908828955,-0.18815920286700116
361.2000000000044,41.87600684672937,-0.6759070940684664,-0.1912272141453495
362.30000000000445,41.98226040811229,-0.6772753083610903,-0.19241388750205424
363.4000000000044,42.088207871637856,-0.6748365436905328,-0.19507797593123666
364.50000000000443,42.1938131473989,-0.679515311356009,-0.1964395939275363
365.60000000000446,42.300219696991086,-0.6833974804223091,-0.19957031331899522
366.7000000000045,42.40586372885788,-0.6866461905595176,-0.2017714622868345
367.8000000000045,42.51223770993765,-0.687111225425566,-0.20552862497831015
368.9000000000045,42.620007811919635,-0.688062737726586,-0.20722966737100768
370.00000000000455,42.72662079619095,-0.6893313542851319,-0.2101286845886987
371.10000000000457,42.83261251556027,-0.6916701437793848,-0.2130465916857185
372.2000000000046,42.939664269792374,-0.6917556081838377,-0.21427837036365815
373.30000000000456,43.046390624001454,-0.6923766334625554,-0.21831991492519087
374.4000000000046,43.15202433334512,-0.6924735288022177,-0.22083226207573547
375.5000000000046,43.25907646320566,-0.6923146816532655,-0.2223003110254802
376.6000000000046,43.36581591532385,-0.6939176440596901,-0.22488041018080285
377.70000000000465,43.47243762702789,-0.6939602235088184,-0.22760671604722127
378.8000000000047,43.579264388720794,-0.6958208725960771,-0.23120783456068672
379.9000000000047,43.68639434995772,-0.6946216463553164,-0.2329956963126838
381.00000000000466,43.79233483273323,-0.6929181290106903,-0.23550340627841226
382.1000000000047,43.898948288421686,-0.694163307628323,-0.23952613218742602
383.2000000000047,44.00637443647439,-0.6930454298142342,-0.2422943551998591
384.30000000000473,44.11311137459505,-0.6932017166215515,-0.24488517457515613
385.40000000000475,44.218003642000795,-0.6922696204589966,-0.2489936248837794
386.5000000000048,44.32663620694113,-0.6919166378667368,-0.25036153055623167
387.6000000000048,44.43350125078705,-0.6920908269930864,-0.2528638868123405
388.7000000000048,44.54024451649725,-0.6896283703695908,-0.2572150336820034
389.80000000000484,44.64666301661943,-0.6912618510577981,-0.2598657407096283
390.9000000000048,44.753436421426684,-0.6915352325199107,-0.2625351075997475
392.00000000000483,44.859840296159355,-0.6909258359327883,-0.26521633083984764
393.10000000000485,44.96643857267714,-0.6922969261098095,-0.26829771830722215
394.2000000000049,45.073855603771214,-0.6915054243642123,-0.2728084407214397
395.3000000000049,45.18091111141166,-0.6912285483363882,-0.27465616404865356
396.4000000000049,45.285244395902936,-0.6937059986093728,-0.27827604394442274
397.50000000000495,45.394527645222674,-0.6940399135983527,-0.28258254603385646
398.6000000000049,45.50096046125121,-0.6939742638649241,-0.28603704962136245
399.70000000000493,45.608366244792094,-0.6935191511949019,-0.2879586721516847
400.80000000000496,45.71580795239486,-0.6927004465761477,-0.29220100959627393
401.900000000005,45.822133518337495,-0.6928328344533562,-0.2965618040927236
403.000000000005,45.92990265085494,-0.6911252055265521,-0.29914459379494485
404.100000000005,46.03599720134284,-0.6900319694711795,-0.3032561874101871
405.20000000000505,46.14286519689513,-0.6916776393096241,-0.30627145698744496
406.30000000000507,46.25038773358879,-0.6910234177007675,-0.30973411990005983
407.4000000000051,46.35768090391078,-0.6897516991109842,-0.3139574862239556
408.50000000000506,46.464538873040134,-0.6880492515096865,-0.31675531443171856
409.6000000000051,46.571648650619515,-0.686385436977178,-0.3221627921819592
410.7000000000051,46.677978024498735,-0.6862527025384588,-0.3264491940538279
411.8000000000051,46.78576711791848,-0.6851288937412807,-0.3294563561961428
412.90000000000515,46.89259017078076,-0.6863952758413249,-0.33261547709013284
414.0000000000052,47.00076293056818,-0.684922121543814,-0.33707925727341514
415.1000000000052,47.106451244736995,-0.6837814100012215,-0.3420727143829465
416.20000000000516,47.21343605047433,-0.6835345029780527,-0.34513884785657556
417.3000000000052,47.32141304712998,-0.681341259891374,-0.34973339272104464
418.4000000000052,47.427682811016524,-0.681185232864906,-0.35399320944793544
419.50000000000523,47.53551198413573,-0.6808698591019193,-0.3568838888427335
420.60000000000525,47.64189864136626,-0.6788078568671021,-0.3608851127888606
421.7000000000053,47.748673845802045,-0.6770222626327962,-0.3671122587765816
422.8000000000053,47.854780652974846,-0.6756157190703926,-0.3727267923505173
423.9000000000053,47.96447478005705,-0.6746639219597147,-0.37733104242968585
425.00000000000534,48.07241907630715,-0.6733264886581262,-0.38154169957955775
426.1000000000053,48.17925962049523,-0.6738377884860262,-0.3849004691154825
427.20000000000533,48.28705226580204,-0.671598897974559,-0.38946346071448
428.30000000000535,48.39399703464599,-0.6734623761172593,-0.39419522823800524
429.4000000000054,48.50131285638243,-0.6732876335588159,-0.39823183036205423
430.5000000000054,48.608954585881634,-0.6702348400906942,-0.40408895673334433
431.6000000000054,48.71646400042934,-0.6699689768264092,-0.40889504915732733
432.70000000000545,48.82372668265417,-0.6678814588490657,-0.4133476316189544
433.8000000000054,48.93132364621057,-0.6673292011645579,-0.41791400633140796
434.90000000000543,49.038118269096614,-0.6662037558183381,-0.42378441965958125
436.00000000000546,49.14635700238377,-0.6640974041897756,-0.42883286151002986
437.1000000000055,49.25442885354373,-0.6638213883268163,-0.43407776169774026
438.2000000000055,49.361958908527306,-0.6641237425123298,-0.4389221776300025
439.3000000000055,49.46896976602984,-0.662799233736426,-0.4438501368099872
440.40000000000555,49.57574368671574,-0.6597970607009452,-0.44982570139112354
441.50000000000557,49.68482327004952,-0.6600530035637135,-0.45489824214412167
442.6000000000056,49.79238483634193,-0.661259462654595,-0.46067212934818524
443.70000000000556,49.90047495565951,-0.6595415877206069,-0.46481651190664364
444.8000000000056,50.00703966600548,-0.6573330501591966,-0.47106478599208135
445.9000000000056,50.11604142675808,-0.6565808810723808,-0.4770142899199947
447.0000000000056,50.22224825052795,-0.6552215751107812,-0.4801321631150408
448.10000000000565,50.32973904777355,-0.6531071088029098,-0.4865450355186365
449.2000000000057,50.43721380189015,-0.6506645868132983,-0.4948548673703934
450.3000000000057,50.544426037251625,-0.6491459799545144,-0.49982427580926236
451.40000000000566,50.65293301564622,-0.6469982634522784,-0.5033709044832193
452.5000000000057,50.75979836683876,-0.6450879560908356,-0.5077570903125843
453.6000000000057,50.86791947332237,-0.6445800761577112,-0.5125758986416136
454.70000000000573,50.97601429296364,-0.6437405006501913,-0.5182032151525138
455.80000000000575,51.08165896737012,-0.6424982351137141,-0.5236791257153506
456.9000000000058,51.19137772443675,-0.6415518954505266,-0.5307644109237075
458.0000000000058,51.2991700000006,-0.6415699999999839,-0.5353008568688518
459.1000000000058,51.407739463847314,-0.6413022551004869,-0.539691033732415
460.20000000000584,51.51586167436388,-0.6412673169148735,-0.5439153110259025
461.3000000000058,51.62340289242311,-0.6400067457821819,-0.5498153477784031
462.40000000000583,51.73083724560285,-0.6390752953618649,-0.5562435137126815
463.50000000000585,51.83896755374949,-0.6406888052031385,-0.5596534947983294
464.6000000000059,51.94715592987032,-0.6405663043490551,-0.56452100258169
465.7000000000059,52.05508916930979,-0.6420368305112606,-0.5674263259591168
466.8000000000059,52.16073839755533,-0.6427716070039852,-0.5707984091152101
467.90000000000595,52.2700032461376,-0.6438927079972478,-0.5756015413087101
469.0000000000059,52.37824100600965,-0.6448999044875297,-0.5791265518353979
470.10000000000593,52.48631882469156,-0.6455026123340659,-0.5811031108228666
471.20000000000596,52.595546855214444,-0.645379872398849,-0.584998556965497
472.300000000006,52.70315050296833,-0.6458458313028302,-0.5880226232613843
473.400000000006,52.810666954947,-0.6483782335662968,-0.5918332777760318
474.500000000006,52.9183846444776,-0.6496604183516317,-0.5944198256633944
475.60000000000605,53.0263120678345,-0.6499368721916805,-0.5971529131785616
476.70000000000607,53.13442819993296,-0.6523762086732727,-0.5993415168232072
477.8000000000061,53.24146593307278,-0.6551697931749731,-0.6022278276022535
478.90000000000606,53.34928065747164,-0.6547538121720883,-0.6040203812873832
480.0000000000061,53.45832838554818,-0.6581857367603964,-0.6066568152675957
481.1000000000061,53.567489597686574,-0.6586003072300924,-0.6078388044457443
482.2000000000061,53.6763699853737,-0.6592426387779272,-0.6093262882593757
483.30000000000615,53.784010628287405,-0.6623127697594852,-0.6109293614363756
484.4000000000062,53.892036542820286,-0.6626688501622865,-0.6122546173976735
485.5000000000062,53.9999719684616,-0.6660364916457944,-0.6136861074355378
486.60000000000616,54.10582388424422,-0.6671511240658239,-0.6162969279313382
487.7000000000062,54.21549564367383,-0.6675904579330828,-0.6176302298484804
488.8000000000062,54.32330779625757,-0.6698413960670995,-0.6176434959140269
489.90000000000623,54.431687189585,-0.6723233113029523,-0.6199870287637066
491.00000000000625,54.539914359523415,-0.6737640569726409,-0.6212388570658893
492.1000000000063,54.64853241842812,-0.6727356207392019,-0.6225701590394652
493.2000000000063,54.75660438874743,-0.6756198977406265,-0.6238899969812763
494.3000000000063,54.86456368460745,-0.6765508969041117,-0.6249666158155298
495.40000000000634,54.9733544795491,-0.6779506598810688,-0.6252280302505402
496.5000000000063,55.08044374368718,-0.6790060013265613,-0.6265215329750884
497.60000000000633,55.19024562954845,-0.6774474434628478,-0.6265152105573084
498.70000000000636,55.29795141488675,-0.6773752765236121,-0.6288247419116306
499.8000000000064,55.40611178782961,-0.6743870522590971,-0.6288298774833154
500.9000000000064,55.514008419203506,-0.6696415745834691,-0.6291486660647347
502.0000000000064,55.62308305921518,-0.6647575239078747,-0.6298366213268909
503.10000000000645,55.730721084437604,-0.6594451244527731,-0.6311308779341775
504.2000000000064,55.83948455049039,-0.6581548202237311,-0.6311301520436041
505.30000000000643,55.949171097947776,-0.6531299537925693,-0.6321202645804371
506.40000000000646,56.05633126274577,-0.6540739714132241,-0.6324513168696901
507.5000000000065,56.16521340380447,-0.6517309778412296,-0.6330786232282573
508.6000000000065,56.273918573646824,-0.650511725810495,-0.634430444323042
509.7000000000065,56.38156364473006,-0.6501647838118945,-0.6347618411318905
510.80000000000655,56.491005890378034,-0.6509948632604888,-0.6347600254057335
511.90000000000657,56.60007368474775,-0.6507638493986666,-0.6347593750324241
513.0000000000066,56.70774533161455,-0.652263911702893,-0.6361086491454002
514.1000000000065,56.81721847466141,-0.6524776291774412,-0.6367400359589075
515.2000000000066,56.92562270997823,-0.6519441236866654,-0.6367337372464554
516.3000000000065,57.03130696019937,-0.651967098267828,-0.6375391173171638
517.4000000000067,57.14280851656052,-0.651000098654491,-0.636842953968964
518.5000000000066,57.250378287831985,-0.6520296169396036,-0.638343250385057
519.6000000000067,57.359469059512875,-0.6539041426383461,-0.6403592486173553
520.7000000000066,57.46948729860263,-0.653889461245135,-0.6401217070823026
521.8000000000067,57.57816064589745,-0.653980448533745,-0.6393702546222699
522.9000000000067,57.686615178831815,-0.6556813681845904,-0.6421103589221264
524.0000000000067,57.79527448476541,-0.6528226792954357,-0.6408004891840937
525.1000000000067,57.90431936033349,-0.6524355333736572,-0.6421324713828525
526.2000000000068,58.013009471583956,-0.6511792091498698,-0.6407937171831364
527.3000000000068,58.1223483651801,-0.6516064686536296,-0.6434302560338958
528.4000000000068,58.23109623593515,-0.6495716802637942,-0.6421097876138351
529.5000000000068,58.340287853975916,-0.6491705467227586,-0.6420831035113812
530.6000000000068,58.44898555382576,-0.6464416069129976,-0.6447498470337978
531.7000000000069,58.55775740579192,-0.6456658178641907,-0.6460714380069139
532.8000000000068,58.66601962439856,-0.643537424603747,-0.6460705297102294
533.9000000000069,58.775433650644125,-0.6422735291538653,-0.644995356397764
535.0000000000068,58.884622690402956,-0.6399634342191084,-0.6451769619542205
536.100000000007,58.99353594439537,-0.6402872014980461,-0.6463570476768377
537.2000000000069,59.10236968241405,-0.639015853752698,-0.6479261985950937
538.300000000007,59.21129512877017,-0.6399253047175135,-0.6489565417060681
539.4000000000069,59.32037352503218,-0.6396326153377359,-0.6485868083393678
540.5000000000069,59.42936994160427,-0.6395213635825882,-0.6495801535800894
541.600000000007,59.538231768151455,-0.6381073494938344,-0.6495800332620876
542.700000000007,59.6472857084095,-0.6367657480157715,-0.6509002619524766
543.800000000007,59.7555550933351,-0.6342623311535749,-0.650810458328198
544.900000000007,59.86478433277774,-0.6334391875572907,-0.6522094243046133
546.000000000007,59.97377673468627,-0.630535323517058,-0.6528303670980251
547.1000000000071,60.08176475868135,-0.6277917693421053,-0.6528698316414956
548.2000000000071,60.19018918676655,-0.6271940200910493,-0.6542703890763395
549.300000000007,60.299467203328724,-0.6233440355439634,-0.6561680225822517
550.4000000000071,60.40947610970168,-0.6209744527514017,-0.6558012585051722
551.500000000007,60.51861340620271,-0.6167005241129793,-0.6558401930851492
552.6000000000072,60.627888441709594,-0.6140731486723695,-0.6561559773506329
553.7000000000071,60.735966797196596,-0.6115952208950501,-0.6581406874006879
554.8000000000072,60.84590316689879,-0.6076562420827616,-0.6594241085785888
555.9000000000071,60.95446579297764,-0.6039475768408172,-0.6549474000009314
557.0000000000072,61.06113480623837,-0.6026450953767488,-0.6543715732583211
558.1000000000072,61.17210024521345,-0.6013526170461939,-0.657359046373295
559.2000000000072,61.28113564149955,-0.6016351883084683,-0.6612283277962923
560.3000000000072,61.39087838158247,-0.6002258782202403,-0.6612194787378955
561.4000000000073,61.49978025128798,-0.600293403521786,-0.663530035391017
562.5000000000073,61.60886482455056,-0.6016994196945856,-0.6635131943306636
563.6000000000073,61.71794565221508,-0.6020054881064635,-0.6648410827786333
564.7000000000073,61.8279001361505,-0.6059835384986909,-0.666480184972893
565.8000000000073,61.93667500004868,-0.6086213097143621,-0.6671883866215338
566.9000000000074,62.04636784813229,-0.6127774522249781,-0.6668200941957725
568.0000000000074,62.15543289241099,-0.6181195941635106,-0.6678028682481205
569.1000000000074,62.264313431274005,-0.6238975011100582,-0.6664767096937472
570.2000000000073,62.373664164075045,-0.6298616466373799,-0.6651697817820219
571.3000000000073,62.48283866362086,-0.636369422479567,-0.6658282063418777
572.4000000000074,62.59150988270358,-0.6419581633481136,-0.6671611607731207
573.5000000000074,62.699948862774626,-0.6475156095788698,-0.672285105661035
574.6000000000074,62.809064862453006,-0.6547248472096666,-0.6766858208553077
575.7000000000074,62.91876134230094,-0.6608531556872326,-0.680584212608184
576.8000000000075,63.02763974328015,-0.6653582871134994,-0.6828999027466987
577.9000000000075,63.13644863158898,-0.6712575480730811,-0.680110859657411
579.0000000000075,63.24612766174189,-0.6738684228681259,-0.6777883385351178
580.1000000000075,63.354830736251806,-0.6777932545255111,-0.6764968375848568
581.2000000000075,63.464501658387476,-0.6796484366934931,-0.6761479321907826
582.3000000000076,63.57124578188818,-0.6813544995304867,-0.6751612309178645
583.4000000000076,63.68297125603354,-0.6813956024112552,-0.6764804443850236
584.5000000000076,63.79201652931165,-0.6823486042813076,-0.6764799248598705
585.6000000000076,63.901590601934345,-0.6839117444260885,-0.6777960437793222
586.7000000000077,64.01104050784883,-0.6861522116120904,-0.6768752260386242
587.8000000000077,64.11987783451984,-0.6866755141164708,-0.6778018398995114
588.9000000000076,64.23073853185423,-0.6868687651828465,-0.6784501838360866
590.0000000000076,64.33938119353016,-0.6871123905359728,-0.6797770782443529
591.1000000000076,64.4490527202005,-0.686256908492333,-0.679433234410693
592.2000000000077,64.55761102889417,-0.6846824741337453,-0.6787173588215998
593.3000000000077,64.66720587959024,-0.6847892582145305,-0.6801121031468909
594.4000000000077,64.77700188581983,-0.6840327873978592,-0.6814100611902831
595.5000000000077,64.88598260735299,-0.6813118922477517,-0.6827636299869053
596.6000000000078,64.99443914043702,-0.6806668396997042,-0.6831299835040068
597.7000000000078,65.10481227864899,-0.6770310231586352,-0.683210602403038
598.8000000000078,65.21427596894374,-0.6766523044855508,-0.6837199900116362
599.9000000000078,65.32373893802175,-0.6735947786008866,-0.6842738207679302
601.0000000000078,65.43250852441933,-0.6701961168331215,-0.6838939343519117
602.1000000000079,65.54197993428143,-0.6668004235811132,-0.6850399604305815
603.2000000000079,65.65195962033587,-0.6632173732821547,-0.687666425604557
604.3000000000079,65.7602193802679,-0.662669995479041,-0.6872144619477041
605.4000000000078,65.87010873571471,-0.6588023252770221,-0.6877899305713742
606.5000000000078,65.97886984003273,-0.6569579975579602,-0.6891106411759669
607.6000000000079,66.08814373731158,-0.6535178851417104,-0.6917154555398013
608.7000000000079,66.19742633689782,-0.6517155504384489,-0.6917419497928456
609.8000000000079,66.3064560947606,-0.6486765569355495,-0.691751974867409
610.9000000000079,66.4165946245854,-0.6435853997152586,-0.6917405584637488
612.000000000008,66.5254853711688,-0.6401532936110719,-0.6943754076904067
613.100000000008,66.63422365159438,-0.6366314104179546,-0.6943713704241792
614.200000000008,66.74469562883334,-0.6312525953675149,-0.6956901557608042
615.300000000008,66.85357571159668,-0.6250251337881272,-0.6959160480114686
616.400000000008,66.96343454907452,-0.6203097022959596,-0.6983370428749618
617.5000000000081,67.07200574311038,-0.613403547934278,-0.6996087352590492
618.6000000000081,67.17886711354745,-0.6062833425069635,-0.700959969519845
619.7000000000081,67.29091342308708,-0.6012565727961343,-0.700903282920363
620.8000000000081,67.40034440924319,-0.5964021606504826,-0.7028108288346777
621.9000000000082,67.50975564420877,-0.5897480380506527,-0.7042959641461048
623.0000000000082,67.61907367648242,-0.582185949064088,-0.7072195733115789
624.1000000000081,67.72907445094825,-0.5758065434518015,-0.7072101728899485
625.2000000000081,67.83796366258122,-0.5683618259461073,-0.7085295206559228
626.3000000000081,67.9475794042586,-0.560910077111356,-0.7100801707097113
627.4000000000082,68.05751978795017,-0.5546185748465947,-0.7121614867173478
628.5000000000082,68.16742683401236,-0.5460985785911582,-0.7134157328943065
629.6000000000082,68.27631274812813,-0.5384287435213382,-0.7161209279031615
630.7000000000082,68.38489830163121,-0.5314393993640947,-0.7174152088370516
631.8000000000083,68.4954449658071,-0.5245264322666796,-0.7181436685667606
632.9000000000083,68.60580621888549,-0.5159202413437373,-0.7201734387495504
634.0000000000083,68.71550935760338,-0.5086484754147611,-0.7234651972271284
635.1000000000083,68.82461926822947,-0.4991876338962671,-0.725311348025897
636.2000000000083,68.93490255431293,-0.4929969812719258,-0.7269807117869669
637.3000000000084,69.04545700204564,-0.48503860111713815,-0.7290936746523409
638.4000000000084,69.15307918684873,-0.47405959816066007,-0.7314994800820971
639.5000000000084,69.26482484252782,-0.4632232416895676,-0.7350953852476172
640.6000000000083,69.37501936265205,-0.4547001277047991,-0.7379438519651011
641.7000000000083,69.484554541284,-0.44573672773913675,-0.7409221684308207
642.8000000000084,69.59409567641326,-0.435689629174609,-0.7437198037087027
643.9000000000084,69.7039503949796,-0.42595916821240526,-0.746607452877547
645.0000000000084,69.81431586317616,-0.4165714536209973,-0.7492881038278183
646.1000000000084,69.92436582226556,-0.4075975837348325,-0.7512193920147405
647.2000000000085,70.03389215255287,-0.3955229578297285,-0.7544840404315347
648.3000000000085,70.14307133025927,-0.3830894044597396,-0.7567887799784896
649.4000000000085,70.25301113708419,-0.3733224253951232,-0.7595089272043527
650.5000000000085,70.36270218107653,-0.36241108593951593,-0.7634336333766614
651.6000000000085,70.47393525803913,-0.3521036629642475,-0.7661702580969592
652.7000000000086,70.5832104802,-0.3390260239179062,-0.7703199726939185
653.8000000000086,70.69317839611486,-0.32803126405554756,-0.7730333267962548
654.9000000000086,70.80321362303802,-0.31182449976415094,-0.7766408355451131
656.0000000000086,70.91285716239435,-0.3001645108082437,-0.7810110592782022
657.1000000000087,71.02294981966479,-0.28551153645173444,-0.7847246076677052
658.2000000000087,71.1325648875358,-0.27288903579063384,-0.7876065803154693
659.3000000000086,71.24216764607105,-0.2522486585099933,-0.7921391850723549
660.4000000000086,71.35002167721277,-0.23760353303794102,-0.7964520678449496
661.5000000000086,71.46227403324954,-0.22288467631607345,-0.8006812563799599
662.6000000000087,71.57214129724846,-0.20863590045963068,-0.8037794864578434
663.7000000000087,71.68106415394028,-0.19583769853129093,-0.8081579865648081
664.8000000000087,71.7919192282231,-0.17858572607699755,-0.814373259284825
665.9000000000087,71.90097842069788,-0.16149285955258055,-0.8183310191223185
667.0000000000088,72.01174654309966,-0.145891712590853,-0.822142186845285
668.1000000000088,72.12094671396723,-0.12908839942839329,-0.8285818289902918
669.2000000000088,72.22866513702797,-0.11035560489028656,-0.8322397419324017
670.3000000000088,72.34147958330408,-0.09234805195210771,-0.8387791288404758
671.4000000000088,72.45091261529387,-0.07513514785184285,-0.8446145587212284
672.5000000000089,72.5607216258674,-0.055965937792110225,-0.8497138754876188
673.6000000000089,72.67098530200455,-0.03623741226386419,-0.855626990615757
674.7000000000089,72.78072414701471,-0.01604388565167455,-0.8605859648480507
675.8000000000088,72.89026262418037,0.004283148759120953,-0.8684156570570924
676.9000000000088,73.00132216901643,0.025200519284264318,-0.8736804517127927
678.0000000000089,73.11180490028987,0.043050437974126374,-0.8761745074379332
679.1000000000089,73.2210434358958,0.06576500773063702,-0.8843499503490846
680.2000000000089,73.3319739244527,0.08626579487403488,-0.8912894762900674
681.3000000000089,73.44156647788321,0.1082584794953655,-0.8988460348484462
682.400000000009,73.55236328159131,0.13195902192589223,-0.9062003389145361
683.500000000009,73.66264595657842,0.15981974897983842,-0.9130046310449123
684.600000000009,73.77244151461555,0.18130120544921705,-0.9202679442033306
685.700000000009,73.8827422521648,0.20628899254944943,-0.9286009491551845
686.800000000009,73.99283868695368,0.2308860842304199,-0.9365142245049016
687.9000000000091,74.10311400157984,0.25940288202046813,-0.9445355936850586
689.0000000000091,74.21265748188242,0.2861244404423339,-0.9518149648761551
690.1000000000091,74.32310588879749,0.3188785247091272,-0.9618958522958891
691.2000000000091,74.43349706626498,0.34485914546770285,-0.9692917379003116
692.3000000000092,74.54395280972633,0.3704368899659934,-0.9798382441307179
693.4000000000092,74.65340749990939,0.4012385966158831,-0.9882520273401738
694.5000000000091,74.76448621254585,0.4296624522871463,-0.9969815712024919
695.6000000000091,74.87444129363878,0.4606702902338489,-1.0053621304745692
696.7000000000091,74.98509656904797,0.4885553042585617,-1.0152800532258874
697.8000000000092,75.09424248724049,0.5175301090805537,-1.0252730946391653
698.9000000000092,75.20499429742536,0.5503117603343257,-1.0353058763530276
700.0000000000092,75.31505304715868,0.5755152690768002,-1.045938269952409
701.1000000000092,75.42493713398439,0.5986311025750414,-1.0556079398673996
702.2000000000093,75.53582047423902,0.6234961015848671,-1.066561306706507
703.3000000000093,75.64572728327435,0.6497773068506232,-1.0774884758558945
704.4000000000093,75.75538298593722,0.674027849424473,-1.0865495536556358
705.5000000000093,75.86511731126872,0.6967552858072441,-1.0981997621218849
706.6000000000093,75.97530874456046,0.7173970732397925,-1.1099498755681898
707.7000000000094,76.08554294175352,0.7332581271088642,-1.1221126223900302
708.8000000000094,76.19394400616532,0.7517918596433708,-1.133571381001461
709.9000000000094,76.30612801591083,0.7609917243168155,-1.1448217392173246
711.0000000000093,76.41692193170148,0.7695008694628405,-1.156505526047015
712.1000000000093,76.52718241675663,0.7690949578938017,-1.1692880399253234
713.2000000000094,76.63699289050946,0.7622827044153098,-1.180039444819084
714.3000000000094,76.74711020544464,0.7508115402720097,-1.19078488709432
715.4000000000094,76.8565123747847,0.7286361019717008,-1.2014847895192236
716.5000000000094,76.96656749847695,0.6973072225522919,-1.214136818289425
717.6000000000095,77.07767449917247,0.6541013727241675,-1.2178520359092078
718.7000000000095,77.18625045959577,0.6010555833712843,-1.2361755511786479
719.8000000000095,77.29789275272441,0.5249870162081449,-1.2442663327945347
720.9000000000095,77.40744329682414,0.4209194674630016,-1.2520366269566336
722.0000000000095,77.51848299819451,0.25854315679862033,-1.2617069662855247
723.1000000000096,77.62647665361817,0.00889975980128386,-1.2680900351547044
724.2000000000096,77.73803744816041,-0.36752033974750287,-1.2752621325271938
725.3000000000096,77.84730353192334,-0.6383996974107357,-1.2784538332085438
726.4000000000096,77.95718901962053,-0.7667885511196499,-1.2782623840294125
727.5000000000097,78.06741690954311,-0.8204770307656809,-1.2777618681240348
728.6000000000097,78.17732115414316,-0.849096763271532,-1.2779467807562668
729.7000000000096,78.28779986755976,-0.8631807107700218,-1.2797347561186312
730.8000000000096,78.39804674027597,-0.8685654436153115,-1.2804072390578942
731.9000000000096,78.50841652784419,-0.8771176019196689,-1.281708389363911
733.0000000000097,78.61830299623071,-0.876498053511059,-1.280488418608856
734.1000000000097,78.72906787184537,-0.882091784733803,-1.2820394552712013
735.2000000000097,78.83916898226941,-0.8806999634852277,-1.2820400200069324
736.3000000000097,78.94948697113148,-0.8835345595185495,-1.2820252864862107
737.4000000000098,79.05970151225627,-0.8857555438414106,-1.2817344960866022
738.5000000000098,79.17010535352503,-0.8828327497653576,-1.2823700372756295
739.6000000000098,79.28002088153414,-0.8826636014219819,-1.2833405077993234
740.7000000000098,79.38996476854267,-0.8821133212526935,-1.2833604228674065
741.8000000000098,79.50076626431114,-0.8809214109635223,-1.2849309211270006
742.9000000000099,79.61158398463452,-0.8823363485195407,-1.286210525522001
744.0000000000099,79.72150495077221,-0.8801425498703773,-1.2835707318656469
745.1000000000099,79.83129499959654,-0.8833107498788514,-1.284970552907983
746.0000000000099,79.92134661058203,-0.8865511963416001,-1.2862087010732872