File: 01_Data/Asphalt_Shingle/STA/N2/10K_min/Asphalt_Shingle_STA_N2_10KData_220915_R1.csv
##Temp./Â°C,Time/min,DSC/(mW/mg),Mass loss/mg
51.0,10.867588648218723,-1.5428683310116103,0.003719328020269863
52.100000000000016,11.184314838591355,-1.466202066203696,-0.0015862028873732115
53.20000000000003,11.425987800930518,-1.4121705584928457,-0.002421230433865773
54.30000000000005,11.628347391837703,-1.3740242105940712,-0.0006087828015841623
55.40000000000006,11.811083710357472,-1.3442542829269908,-0.0030901131926786007
56.50000000000008,11.981658553139976,-1.3200168900856724,-0.0018978180859763327
57.600000000000094,12.144761180262678,-1.3001890831074827,-0.0011532581321116453
58.70000000000011,12.29953082874486,-1.2840824311018828,-0.0012656709338667582
59.800000000000125,12.446482460171982,-1.2712249362890204,-0.0018837467424948073
60.90000000000014,12.593695271474099,-1.2579461388484405,-0.0003350705307898494
62.000000000000156,12.737590619514933,-1.247053106311782,-0.0028533203439984334
63.10000000000017,12.873379947588273,-1.2348464962161425,-0.0009629056385307422
64.20000000000019,13.01227466007511,-1.227154548734301,-0.0019383819916862777
65.30000000000021,13.146096851685892,-1.2186784357596718,-0.0021528722861710037
66.40000000000022,13.278070411849773,-1.2100117397875598,-0.003369845430111873
67.50000000000023,13.40862728057748,-1.2013680473671173,-0.0036550445136427356
68.60000000000025,13.538483854868483,-1.1931707833321261,-0.0021720530326634346
69.70000000000027,13.666406288419555,-1.1836803570224896,-0.002081777122171502
70.80000000000028,13.794564420872414,-1.1774236040751653,-0.0020829673976914265
71.90000000000029,13.919490236412075,-1.170189613854659,-0.001304734417884923
73.00000000000031,14.043531691540608,-1.1612292509802082,-0.003418337897330481
74.10000000000034,14.16520685586369,-1.152958771516313,-0.0035093100538716726
75.20000000000034,14.291136780852003,-1.1466136228627426,-0.0011040230270999984
76.30000000000035,14.411539957547099,-1.140224045891102,-0.0007509352910757272
77.40000000000038,14.53079880349267,-1.1343592890239869,-0.0024011972784538926
78.5000000000004,14.651130487253644,-1.127610448195758,-0.001970880766605454
79.6000000000004,14.770797023899233,-1.1209871458827625,-0.001052587707309982
80.70000000000041,14.889162557528577,-1.1153273142098517,-0.0024135451053570733
81.80000000000044,15.006676921980914,-1.1102836890745562,-0.0037317407768826527
82.90000000000046,15.122303849833377,-1.1026973297704248,-0.0024478934724996293
84.00000000000047,15.240090959337913,-1.0970530838653683,-0.003724603397818882
85.10000000000048,15.354678405451441,-1.0916517939818284,-0.0024467081572341343
86.2000000000005,15.46914946992775,-1.0849536950314407,-0.001812870786202403
87.30000000000052,15.583785443637415,-1.081253564469323,-0.0024017727961833657
88.40000000000053,15.696394576500108,-1.07344728986109,-0.0037632833348721917
89.50000000000054,15.810418250691932,-1.0702546376504027,-0.0010933372543471265
90.60000000000056,15.922352072452131,-1.064867765296733,-0.0024349834413852633
91.70000000000059,16.036498809147268,-1.0600229547521358,-0.0014113703229972074
92.8000000000006,16.14585022085746,-1.0553544242195254,-0.002720281496099375
93.9000000000006,16.25771939133278,-1.0497837818651328,-0.002393064513857013
95.00000000000063,16.36717770600844,-1.0454814897641471,-0.0024979321721820824
96.10000000000065,16.479900239585774,-1.0397628039657363,-0.002366328677426033
97.20000000000066,16.590192926782862,-1.0362079012206205,-0.002410966897550715
98.30000000000067,16.700287217583416,-1.0314918871194747,-0.0024103911062223204
99.40000000000069,16.808516310651363,-1.0254509309889885,-0.0024541817106404906
100.50000000000071,16.918618997931667,-1.0220809763695549,-0.003732916815458509
101.60000000000072,17.028155487296395,-1.0174417298320024,-0.003701890452968648
102.70000000000073,17.13330104470446,-1.0120690377223367,-0.002422229553283195
103.80000000000075,17.243850155404026,-1.0076756452955897,-0.003731963753978107
104.90000000000077,17.35332866932132,-1.0035374169136377,-0.002208925629680003
106.00000000000078,17.459543508371812,-1.000238105629431,-0.0035100277693294046
107.10000000000079,17.568936916949966,-0.9950085355819112,-0.003508326425324171
108.20000000000081,17.6781663005288,-0.9908740850911155,-0.0035101822630361212
109.30000000000084,17.785448686797206,-0.9873173986562107,-0.003501937989256909
110.40000000000084,17.89357565458087,-0.9822375620207283,-0.0035202774321634323
111.50000000000085,18.001804175249035,-0.979223085090473,-0.003509849793504216
112.60000000000088,18.108828254692728,-0.9760033162311977,-0.002685393576201456
113.7000000000009,18.21689961813286,-0.972319386372724,-0.003573667637505551
114.8000000000009,18.323801916673233,-0.9677862174585383,-0.004864848805545385
115.90000000000092,18.428970684036607,-0.9647196549680791,-0.0035004689885713702
117.00000000000094,18.538910658440432,-0.9617742723751572,-0.004819929245577725
118.10000000000096,18.646064989581053,-0.9579506889235601,-0.0032051093507377004
119.20000000000097,18.753051244577705,-0.9537824828509915,-0.0046082800961126935
120.30000000000098,18.860394186987758,-0.9495232189302132,-0.004610114277162403
121.400000000001,18.967410015383688,-0.9470400445233011,-0.005597464681538433
122.50000000000102,19.075053194708058,-0.943624369338546,-0.005917567443902705
123.60000000000103,19.181193705303002,-0.9403518341748333,-0.005933599028805858
124.70000000000104,19.287806401336027,-0.9367442462360759,-0.005931703918421682
125.80000000000106,19.393340115936862,-0.9349617906775262,-0.004215015542188283
126.90000000000109,19.496402572194853,-0.9317852056112494,-0.0035001330122437224
128.00000000000108,19.606487983795382,-0.9279685990069864,-0.004820498203677026
129.1000000000011,19.712376961820958,-0.9247595813167689,-0.004490099307189688
130.20000000000113,19.81788179078557,-0.9226113108477618,-0.0031798856499465344
131.30000000000115,19.924150447558734,-0.91930125084976,-0.0020987574114412766
132.40000000000117,20.030183957176916,-0.9152515622831061,-0.0031799746403118334
133.50000000000117,20.13545531910132,-0.913530463010466,-0.004062611960695683
134.6000000000012,20.2410248592819,-0.9089337377516228,-0.005824188880271031
135.7000000000012,20.34843898824184,-0.9071586810545326,-0.005785009909375027
136.8000000000012,20.45363600783102,-0.9039305887379779,-0.006605600133563705
137.90000000000123,20.560328972479855,-0.9011513591407311,-0.004820112663435516
139.00000000000125,20.665109769269584,-0.8975401856452958,-0.0035064523085432953
140.10000000000127,20.770648793063973,-0.8953634004928356,-0.00487432187477399
141.2000000000013,20.876790558464073,-0.8924382471028425,-0.006008989703234491
142.3000000000013,20.98156552940714,-0.8899681356928172,-0.006143031129820287
143.4000000000013,21.08621132138416,-0.8867348923289833,-0.007459919841392271
144.50000000000134,21.192047384296814,-0.883862120052881,-0.0048202673797526074
145.60000000000133,21.297972743306783,-0.8810312602820676,-0.004820250926364622
146.70000000000135,21.402140559182847,-0.8789622382956495,-0.004828591782492175
147.80000000000138,21.507131875183276,-0.8752419492244111,-0.0038533812749381724
148.9000000000014,21.612715839801993,-0.8713579022095859,-0.0063215401918315095
150.00000000000142,21.71680174510162,-0.8668822077943708,-0.006139714663473406
151.10000000000142,21.820817088818988,-0.8656926452642112,-0.006730638570110692
152.20000000000144,21.926955690322487,-0.8636923024354113,-0.00613995713412141
153.30000000000146,22.03153706320626,-0.8591560711914796,-0.006050661989846162
154.40000000000146,22.136260229102966,-0.8566485900288584,-0.004857647816232991
155.50000000000148,22.24093386193208,-0.8554119542303628,-0.006136001834375904
156.6000000000015,22.344074285028583,-0.851621368927919,-0.006138626948150261
157.70000000000152,22.45000000000015,-0.8494200000000001,-0.004776560233488603
158.80000000000155,22.55497001551286,-0.8458767679420721,-0.005479407957562188
159.90000000000154,22.65919694609217,-0.8434581170224785,-0.005479989996359791
161.00000000000156,22.763898306368397,-0.8413242521536608,-0.005497694415134369
162.1000000000016,22.869197646186652,-0.8378053624856692,-0.004820414004169216
163.20000000000158,22.972006692223147,-0.8360376284570394,-0.00483936637543092
164.3000000000016,23.077806157552192,-0.8329899025527865,-0.007457682237882679
165.40000000000163,23.181239232911572,-0.8295371119064738,-0.006070192962803311
166.50000000000165,23.28755715370926,-0.8279766097037486,-0.0038085221352046617
167.60000000000167,23.392184897512035,-0.8258517312773661,-0.004817593650500385
168.70000000000167,23.495809996243864,-0.8224810636320204,-0.007130323463103494
169.8000000000017,23.599732698838285,-0.8196019364877993,-0.0058116873082880716
170.9000000000017,23.70430264812328,-0.8182295929940686,-0.007422961473286804
172.0000000000017,23.808898830758153,-0.8149123398446321,-0.00614540079559589
173.10000000000173,23.913987218882145,-0.8132910495004136,-0.006877301777071132
174.20000000000175,24.01898649678111,-0.8100412181822806,-0.006150059904913796
175.30000000000177,24.12367340928459,-0.8076218265724091,-0.006150058270155689
176.4000000000018,24.22779846345476,-0.8043251741845783,-0.007575541638107808
177.5000000000018,24.33233737126818,-0.802780923851556,-0.006469832224613725
178.6000000000018,24.435911569276616,-0.8003466570235127,-0.007457357783242635
179.70000000000184,24.540830191581627,-0.7988502685349134,-0.007465468322476632
180.80000000000183,24.643467311236236,-0.7967250415663695,-0.006923713280333921
181.90000000000185,24.750096325745762,-0.7938443104579689,-0.008780352608273034
183.00000000000188,24.854280901009737,-0.7907624982566234,-0.007459878150857691
184.1000000000019,24.9591538750428,-0.7910593759585519,-0.008451408759624357
185.20000000000192,25.06297162818437,-0.7879064697819506,-0.007451502751418815
186.30000000000192,25.167628992174443,-0.784502674262878,-0.0074599701019204545
187.40000000000194,25.271475814272378,-0.7849515987201648,-0.0073828109326115055
188.50000000000196,25.37539833904696,-0.7826360849148964,-0.006799765607956587
189.60000000000196,25.480656577721774,-0.7797214388610761,-0.008109754269728597
190.70000000000198,25.585044141681045,-0.7786890231207346,-0.008111789595481866
191.800000000002,25.688567464366077,-0.7764177047313048,-0.009432640577214713
192.90000000000202,25.792792958060303,-0.772688809495491,-0.008783897369465166
194.00000000000205,25.8947071500853,-0.7719477444827845,-0.007512716522329654
195.10000000000204,26.001452777359226,-0.7697080755571324,-0.010119291996073976
196.20000000000206,26.105557837907668,-0.7681038824997076,-0.011429105073814227
197.3000000000021,26.209607586232945,-0.766413217026091,-0.01009988826007202
198.40000000000208,26.315290468784603,-0.7639468669118042,-0.010099898817073516
199.5000000000021,26.419298141628985,-0.7629052857368538,-0.01142641417403567
200.60000000000213,26.522895949771467,-0.7610398360196831,-0.011416879990935769
201.70000000000215,26.62727366302417,-0.7584989189176518,-0.011409831847724483
202.80000000000217,26.73214072381877,-0.7559076767529067,-0.012709623148743354
203.90000000000217,26.834933519159925,-0.7550027451551817,-0.01001616831981611
205.0000000000022,26.94184351841602,-0.7511120261414236,-0.011335475287435948
206.1000000000022,27.04491987821861,-0.7501799307294188,-0.012399930070759346
207.2000000000022,27.149805665455286,-0.7480380660115383,-0.012400011247837739
208.30000000000223,27.25350590853768,-0.7466477023041328,-0.01372021800129275
209.40000000000225,27.35716271385228,-0.7451285883216117,-0.013719932840908555
210.50000000000227,27.46102327045964,-0.7438839463991346,-0.015031372827651879
211.6000000000023,27.56693392865509,-0.7416050426183274,-0.015095311149426749
212.7000000000023,27.670832291917442,-0.7407160505926804,-0.015044583123046351
213.8000000000023,27.77417510116932,-0.7368513397984161,-0.012728078595202419
214.90000000000234,27.87698673321729,-0.7365708562273108,-0.015468745452023924
216.00000000000233,27.98271823787249,-0.7351261340718872,-0.015832872256443586
217.10000000000235,28.088487276434773,-0.7340330382492185,-0.018382488918167184
218.20000000000238,28.192563445037887,-0.730648988239001,-0.018440005087269284
219.3000000000024,28.29735234540241,-0.729840402236246,-0.01844000496674525
220.40000000000242,28.401864578902696,-0.7284681221616637,-0.018572144121708156
221.50000000000242,28.50688011782202,-0.7263323377886116,-0.01910000475559137
222.60000000000244,28.61069446030589,-0.7245879875311859,-0.01910000500000031
223.70000000000246,28.7146351823553,-0.7235402244734208,-0.019100005000057152
224.80000000000246,28.818888332740194,-0.7228643828579434,-0.019100025038480517
225.90000000000248,28.924256321074054,-0.7212967667321938,-0.017779731584393055
227.0000000000025,29.02904905893413,-0.7187371030549699,-0.018428829292330917
228.10000000000252,29.13332257832742,-0.71814199907377,-0.019748738268654975
229.20000000000255,29.23724844549036,-0.716241366982271,-0.019750110001385934
230.30000000000254,29.341457695374487,-0.7159674755801216,-0.019748063948223482
231.40000000000256,29.44672453858023,-0.7135987710490621,-0.0210757780661881
232.5000000000026,29.54980983872358,-0.71252291205784,-0.021070335593218026
233.60000000000258,29.654472035982973,-0.710947559217372,-0.02236326599873717
234.7000000000026,29.76000000000024,-0.7099200000000048,-0.0223957233584704
235.80000000000263,29.863635170321878,-0.7073350856290306,-0.02247021500765989
236.90000000000265,29.96812101559841,-0.7070822354215431,-0.02371734333979525
238.00000000000267,30.07307946410816,-0.705242513587641,-0.02502995532447727
239.10000000000267,30.177833023164425,-0.7043260553442251,-0.025689613175253534
240.2000000000027,30.282320600157618,-0.7044980998863887,-0.026319050440931413
241.3000000000027,30.386189529548403,-0.7031478046022148,-0.026341240380712172
242.4000000000027,30.490725250126037,-0.7011977887872264,-0.027672859214248113
243.50000000000273,30.59547539045953,-0.6996397952454959,-0.027660200697110504
244.60000000000275,30.699660211690496,-0.6989852485129114,-0.028747559891921348
245.70000000000277,30.802314452327895,-0.6976327250305073,-0.030289979057730676
246.8000000000028,30.9092998118751,-0.6955872787697384,-0.02896706989691289
247.9000000000028,31.01347966604796,-0.6938452586329529,-0.030282543846261945
249.0000000000028,31.119611725040603,-0.6924375718592879,-0.030289971936116267
250.10000000000284,31.222803114939975,-0.6925412274007072,-0.03160813558309972
251.20000000000283,31.32825177211934,-0.6911246636282684,-0.031609864998739745
252.30000000000285,31.432126792701098,-0.6902220442952576,-0.031609865421160954
253.40000000000288,31.53689132712544,-0.6893598833243884,-0.034301385100683035
254.5000000000029,31.641848017945595,-0.6881278043983409,-0.03425016454835994
255.60000000000292,31.74531367394067,-0.6860139954704093,-0.035334562327963503
256.7000000000029,31.849110015106458,-0.6860906300081067,-0.03692545700728633
257.8000000000029,31.95455306950756,-0.6835073765162327,-0.037195800451626404
258.90000000000293,32.059252295459224,-0.6826818703174695,-0.03917981590162345
260.00000000000296,32.16455922382423,-0.6806728673560561,-0.03917996478850139
261.100000000003,32.26870057083188,-0.679698936234453,-0.04050008133811911
262.200000000003,32.3736501098634,-0.6787581578888812,-0.04050013000128505
263.300000000003,32.47797368970472,-0.6797976367515488,-0.04050102467266292
264.40000000000305,32.5851254997515,-0.6783032561652703,-0.04182001481247255
265.50000000000307,32.68927474840448,-0.6778267539636316,-0.04215684737982972
266.6000000000031,32.79362633708426,-0.6768639953597558,-0.04478990002288974
267.7000000000031,32.89781861911476,-0.6754332644714428,-0.04612622131045008
268.8000000000031,33.00329870322441,-0.6740000758349839,-0.046099798417007065
269.9000000000031,33.10680678701889,-0.6728901623159372,-0.04741989275409164
271.0000000000031,33.212597433952205,-0.673226986580871,-0.04857877372146646
272.10000000000315,33.31799663432273,-0.6720151103194177,-0.051364705715368775
273.2000000000032,33.422624172607094,-0.6704830428902123,-0.05070716826257904
274.30000000000314,33.52768835969601,-0.6692846750343355,-0.05202883999506902
275.40000000000316,33.63288933123901,-0.6678423165991262,-0.05432386204002704
276.5000000000032,33.736911019561795,-0.6677116504279669,-0.05532996676007551
277.6000000000032,33.842252487928576,-0.6666971692125979,-0.05665006014123497
278.70000000000323,33.94853251267088,-0.6663733751478124,-0.056653646510715916
279.80000000000325,34.051611639325344,-0.6646461289362883,-0.05663621443458888
280.9000000000033,34.156868684352084,-0.6645256185909902,-0.059281771928118676
282.0000000000033,34.26000000000027,-0.6634999999999861,-0.061910099046468936
283.1000000000033,34.363966107367844,-0.6635863898842959,-0.061917298530253184
284.20000000000334,34.47236942598225,-0.6625535524213261,-0.06059716146073635
285.30000000000337,34.574969697423235,-0.6613964411465341,-0.06191002543814017
286.40000000000333,34.68153259373975,-0.6598012752552842,-0.06456064070192591
287.50000000000335,34.78675194535308,-0.6603647289371448,-0.06850516810828688
288.6000000000034,34.8913792040542,-0.6581388456167406,-0.06982389530384125
289.7000000000034,34.99750366153212,-0.6583484357965943,-0.06981042907997637
290.8000000000034,35.101144920113285,-0.6575025453963634,-0.0697075748955549
291.9000000000034,35.20604663559064,-0.6557915453008633,-0.07233431368278254
293.0000000000034,35.30953559629984,-0.6555310679237167,-0.07376993148201016
294.10000000000343,35.41756525045715,-0.6544618713798085,-0.07451633727937867
295.20000000000346,35.52303257314229,-0.6549418972654499,-0.07509047565084437
296.3000000000035,35.62787605947521,-0.6555872290618586,-0.07639328540143353
297.4000000000035,35.73306199238172,-0.6545448741868358,-0.07771552199342091
298.5000000000035,35.83869633010751,-0.653913322976601,-0.08033085382787952
299.60000000000355,35.944222585035256,-0.6540348473503385,-0.08267061683844856
300.70000000000357,36.049317994392204,-0.6539734301179989,-0.08398006614154196
301.8000000000036,36.1546463572448,-0.6531504406597095,-0.08530945031910164
302.9000000000036,36.25959633959449,-0.6523326874910517,-0.08824415534129226
304.0000000000036,36.36471431959971,-0.6513174437242372,-0.08831427553182403
305.1000000000036,36.47072494092009,-0.6509080491216166,-0.09030193680526732
306.2000000000036,36.575531279192795,-0.6503791899993053,-0.0908907797648264
307.30000000000365,36.68159446264778,-0.649997129460275,-0.09352711534840452
308.4000000000037,36.78688133280141,-0.6487932010781916,-0.09485018234105214
309.5000000000037,36.892713171750195,-0.6486971693943462,-0.09616374372178438
310.60000000000366,36.99726408224175,-0.6488838832738036,-0.09880168550088442
311.7000000000037,37.10274175699761,-0.6487372470733929,-0.10141017562985244
312.8000000000037,37.208588095347025,-0.6476627753579702,-0.10276190596499735
313.90000000000373,37.313897445896465,-0.645878562073063,-0.10406987363240638
315.00000000000375,37.41960148707271,-0.6455444062379647,-0.1067000240587781
316.1000000000038,37.525598187026944,-0.6452888139407827,-0.10671149947218561
317.2000000000038,37.63029357538639,-0.645528848478222,-0.10802225987020186
318.3000000000038,37.73537429487743,-0.6450531777236446,-0.11200335966176578
319.40000000000384,37.84145452147578,-0.6433062525693636,-0.11331928137214975
320.5000000000038,37.94765826464086,-0.6434230395224007,-0.1133009548979822
321.60000000000383,38.052835772291566,-0.6434890482918262,-0.11461640241131832
322.70000000000385,38.159181744018454,-0.6431115424507474,-0.11592806213442808
323.8000000000039,38.264646314985086,-0.6419208842792832,-0.11988315636865288
324.9000000000039,38.370190911997916,-0.6425259748624481,-0.12118988836046096
326.0000000000039,38.476198376385014,-0.6422568716138757,-0.12389599597461753
327.10000000000394,38.581811712744695,-0.6417496555608191,-0.12513997020024537
328.2000000000039,38.688014354472244,-0.64272480777387,-0.12638306775687713
329.30000000000393,38.79116211665418,-0.6416507432409407,-0.12908816236027487
330.40000000000396,38.899420118247036,-0.6413317790189323,-0.13172990558648
331.500000000004,39.005623158926014,-0.6408436382631644,-0.1331662231124131
332.600000000004,39.111300658346764,-0.6403565419854452,-0.13547043628887856
333.700000000004,39.217403586251095,-0.6404420299343342,-0.13806754189898784
334.80000000000405,39.323100421840714,-0.6394410947734452,-0.13943777959183556
335.90000000000407,39.42948704873175,-0.63877663002994,-0.1394324810564136
337.0000000000041,39.53567062308052,-0.6391277881437932,-0.14336834339328375
338.10000000000406,39.64057106397659,-0.6391994304522165,-0.14339207695865763
339.2000000000041,39.74552676468305,-0.6382302343347861,-0.1466364501914752
340.3000000000041,39.85109280579028,-0.6390197943838105,-0.15001405362198383
341.4000000000041,39.95889486318221,-0.6389188095285092,-0.15127368702913957
342.50000000000415,40.06515152505083,-0.637288815175002,-0.15379888868235936
343.6000000000042,40.171107336421336,-0.6374053083950665,-0.15630742025149624
344.7000000000042,40.27809035331075,-0.6373792845158021,-0.15796430456561827
345.80000000000416,40.38102544495222,-0.6370364872278576,-0.15929122801063667
346.9000000000042,40.488314482663974,-0.6363269035547302,-0.16157950499784723
348.0000000000042,40.59627198984335,-0.635909525022959,-0.16422760688386218
349.10000000000423,40.701931245988916,-0.6374527532772147,-0.16563012214467365
350.20000000000425,40.80845890790499,-0.6362134014677356,-0.16686683317169315
351.3000000000043,40.91539635613736,-0.6357847713482475,-0.16824064517775206
352.4000000000043,41.02164098148382,-0.6343154490462055,-0.17323615994262997
353.5000000000043,41.12752834905023,-0.6343954434367025,-0.1760860811896081
354.60000000000434,41.23350939097679,-0.6328254115530756,-0.17731567183337393
355.7000000000043,41.33991234947353,-0.6332156458751977,-0.18003455782111777
356.80000000000433,41.44568325498661,-0.6306729390936119,-0.18268905100248478
357.90000000000435,41.553126672246314,-0.6316095204412425,-0.18457465051380506
359.0000000000044,41.65934098265722,-0.6305130846120387,-0.18823131090434675
360.1000000000044,41.765185963187584,-0.6313619234887283,-0.18889152713732082
361.2000000000044,41.87192619098511,-0.6306620051988039,-0.19208777080257988
362.30000000000445,41.97764352245504,-0.6301907975501948,-0.1916266624818097
363.4000000000044,42.08465995846877,-0.6290212332022203,-0.19710264158734025
364.50000000000443,42.1906086601385,-0.6293843834039436,-0.19892518256589797
365.60000000000446,42.29663770735145,-0.628930074840157,-0.20160365600996233
366.7000000000045,42.403829077932784,-0.6298348743812782,-0.20405581554046925
367.8000000000045,42.51067433243683,-0.6288969039123238,-0.20430176541460865
368.9000000000045,42.617495798947836,-0.6290761166393322,-0.20632629320894313
370.00000000000455,42.723861628900174,-0.6288818181217194,-0.2074653561590587
371.10000000000457,42.83019550924317,-0.6281887608352594,-0.2138632936144882
372.2000000000046,42.93650591417827,-0.6275164150545246,-0.21661278073009615
373.30000000000456,43.042528811043184,-0.6258102916865779,-0.21942534935201863
374.4000000000046,43.148857404502536,-0.6266384401528455,-0.2205969616678254
375.5000000000046,43.25683970572082,-0.6261216422967132,-0.22199091261502657
376.6000000000046,43.36337088315386,-0.6253693293521199,-0.226067951878131
377.70000000000465,43.47039150827244,-0.6257798056572584,-0.22826281097477708
378.8000000000047,43.5775104331258,-0.6242536439918424,-0.23046886617390028
379.9000000000047,43.682286340995596,-0.6246122952626116,-0.23438282242249686
381.00000000000466,43.79091192490148,-0.6240880552535758,-0.23939832953094964
382.1000000000047,43.89801183393607,-0.6239753397995467,-0.24035064249507299
383.2000000000047,44.003851718552134,-0.6234178619861378,-0.24312900224750056
384.30000000000473,44.110678151175485,-0.6240132028191502,-0.24606926886388125
385.40000000000475,44.21870405964977,-0.6230109309850489,-0.2499157378279082
386.5000000000048,44.32528247873437,-0.6232290280597979,-0.25135783544874934
387.6000000000048,44.43071588555023,-0.6235346240244324,-0.2548027819510694
388.7000000000048,44.538012003035284,-0.6218308195944724,-0.2584782893401454
389.80000000000484,44.64512912628363,-0.6217523507532725,-0.25928799452539497
390.9000000000048,44.75215102543892,-0.6223176372039739,-0.2631017412702854
392.00000000000483,44.85781826660121,-0.621304592359864,-0.26491120393657086
393.10000000000485,44.965581829178696,-0.6215223734920527,-0.2690716142790466
394.2000000000049,45.073113898979194,-0.6219250786193499,-0.27086147655819337
395.3000000000049,45.18027791040351,-0.6200172950206587,-0.2731402290639444
396.4000000000049,45.287526349995694,-0.6213053348334033,-0.2774196136700917
397.50000000000495,45.39463941858285,-0.6209341990487534,-0.28332712915170566
398.6000000000049,45.500540069138935,-0.6199733488630326,-0.28950071521818455
399.70000000000493,45.605273833756044,-0.6210863206521299,-0.2893402963481093
400.80000000000496,45.71516662385647,-0.6194420269235262,-0.2927113260587073
401.900000000005,45.820577184213924,-0.6203859257666271,-0.29286567612430137
403.000000000005,45.92784262479424,-0.6189671978534744,-0.2971885190150636
404.100000000005,46.03563496909721,-0.6182637131697586,-0.3030225023529378
405.20000000000505,46.141951978015655,-0.6176910154156425,-0.3078184794436689
406.30000000000507,46.2495000592374,-0.6187928114917569,-0.30978586694019583
407.4000000000051,46.354887022027995,-0.6182628912172807,-0.31191827540552497
408.50000000000506,46.46376613320471,-0.6173091375360332,-0.317230737389238
409.6000000000051,46.570475934428835,-0.616568154707171,-0.3221117180696651
410.7000000000051,46.677261838990106,-0.6154685407066913,-0.32515902219236015
411.8000000000051,46.78518542101481,-0.615696866130322,-0.3287368915376154
412.90000000000515,46.89224130638052,-0.6142202735877677,-0.3333323116575819
414.0000000000052,46.99942866513659,-0.6134797171157884,-0.33759457300058493
415.1000000000052,47.104585470024084,-0.613061868789003,-0.3419753060001063
416.20000000000516,47.21318379640258,-0.6130663058990709,-0.34485985998961954
417.3000000000052,47.320662543316615,-0.6110851178448266,-0.3475882440029272
418.4000000000052,47.42842432070388,-0.6104581859299054,-0.35179947554303626
419.50000000000523,47.53522345203421,-0.6099621834919112,-0.3583233811485962
420.60000000000525,47.64208222532208,-0.6084488049942981,-0.3610100880003011
421.7000000000053,47.75059921786434,-0.6084885183957559,-0.36606792273492417
422.8000000000053,47.85711703885395,-0.606654597464343,-0.37197927857139224
423.9000000000053,47.96551491576696,-0.6064642428344159,-0.3759943672737913
425.00000000000534,48.07208859999017,-0.60581464769691,-0.3794666693409834
426.1000000000053,48.1792993721834,-0.6058756035623651,-0.3850411819890178
427.20000000000533,48.28682590765988,-0.603361281667609,-0.38817523096734163
428.30000000000535,48.394133426787974,-0.6023038386398339,-0.3947669089597392
429.4000000000054,48.50199534870329,-0.6026711928231733,-0.39991687194207426
430.5000000000054,48.60920762249735,-0.5997763037663066,-0.40468871584715327
431.6000000000054,48.71759378596172,-0.5987752581521225,-0.4097534805017262
432.70000000000545,48.824231983444314,-0.5989511539731944,-0.4168404896356961
433.8000000000054,48.931422759327916,-0.5985785490201808,-0.4223459441946882
434.90000000000543,49.03823487212243,-0.5972282690057816,-0.4253436759987155
436.00000000000546,49.14606010968247,-0.596365885029785,-0.4294897335483925
437.1000000000055,49.254423893785074,-0.595493067313119,-0.4336067469897791
438.2000000000055,49.361034443494475,-0.5955231153363868,-0.4409841090265525
439.3000000000055,49.46895841699591,-0.5949592575878984,-0.44760285937385413
440.40000000000555,49.5760735724071,-0.5944813812866981,-0.4539166337917626
441.50000000000557,49.68432209936717,-0.592932028839596,-0.45961534319641295
442.6000000000056,49.7924432342392,-0.5912946610008505,-0.4646793708565098
443.70000000000556,49.899330444234955,-0.5914449962232244,-0.4715548281929598
444.8000000000056,50.00677757822511,-0.5913921351996508,-0.4754134434217625
445.9000000000056,50.11511481732087,-0.5886980381453326,-0.4810307351299383
447.0000000000056,50.22282457174195,-0.5882199805902825,-0.4862584421581486
448.10000000000565,50.33020679927335,-0.5865756069449332,-0.4907308261183525
449.2000000000057,50.437757509069236,-0.5862970635964924,-0.4976606108149779
450.3000000000057,50.54285311078445,-0.5832283807850854,-0.5036807065493125
451.40000000000566,50.653959266537335,-0.5827505664799315,-0.5087102102737959
452.5000000000057,50.761057338187584,-0.5828669933758374,-0.5139920236319941
453.6000000000057,50.86876341916284,-0.580918763333114,-0.5190955469787837
454.70000000000573,50.97579961646218,-0.5804661658981456,-0.5235508420952537
455.80000000000575,51.08387877277145,-0.5797083957961829,-0.5313106177213158
456.9000000000058,51.191530613998765,-0.5797644266361834,-0.537087205821817
458.0000000000058,51.30000000000061,-0.5794199999999088,-0.5401871333859645
459.1000000000058,51.40713456250623,-0.5781713910988662,-0.5463299837694469
460.20000000000584,51.51573905595404,-0.5780653394112103,-0.551305390643134
461.3000000000058,51.62375946446171,-0.5778773548335322,-0.5569547651745053
462.40000000000583,51.73110472971895,-0.5768145313556081,-0.5595503249862044
463.50000000000585,51.838654912251585,-0.5772212101277393,-0.564920951675302
464.6000000000059,51.945622221101566,-0.5773029363249971,-0.570184715705528
465.7000000000059,52.05531721107654,-0.5791549057008915,-0.5743270068658215
466.8000000000059,52.162332102673155,-0.5811180897410236,-0.5788483811458289
467.90000000000595,52.27051647112935,-0.5807330743323509,-0.5807880512313353
469.0000000000059,52.37768095641183,-0.5808459305199478,-0.5848223470617389
470.10000000000593,52.4859958023758,-0.5822468432349046,-0.5891638854971766
471.20000000000596,52.595185008382295,-0.5839836701189153,-0.5920429308557855
472.300000000006,52.70318711577278,-0.5853197850856722,-0.5958937199639407
473.400000000006,52.809525132368066,-0.5874637708158666,-0.5997388055032435
474.500000000006,52.91873540038327,-0.5887971295906805,-0.6011920247000817
475.60000000000605,53.024108603320855,-0.59108378164715,-0.6038118097625267
476.70000000000607,53.13407807000845,-0.5940297135121158,-0.607852355955206
477.8000000000061,53.24220005810868,-0.5959247025107464,-0.6090810095992665
478.90000000000606,53.35079862380827,-0.5974489666955837,-0.611741774396962
480.0000000000061,53.458362015244596,-0.5989127752327997,-0.6135635632199259
481.1000000000061,53.56584874968775,-0.6025212323151433,-0.6162651042831389
482.2000000000061,53.674464751521704,-0.6038270238770636,-0.617203232638861
483.30000000000615,53.78273130342571,-0.6068629407422099,-0.6195884730416625
484.4000000000062,53.891284947473835,-0.6079960312648631,-0.619687103287736
485.5000000000062,53.99875308892851,-0.6096011679553248,-0.6219200654341397
486.60000000000616,54.10752664413604,-0.613079134934036,-0.6245556400494143
487.7000000000062,54.21304692407749,-0.6169524761945362,-0.625868949568388
488.8000000000062,54.32322808396803,-0.6194172778852299,-0.6271821569126783
489.90000000000623,54.4320837851168,-0.6213213241390784,-0.6285211829305024
491.00000000000625,54.54009761161241,-0.6225514219803304,-0.6298281639995098
492.1000000000063,54.64752328707495,-0.6250222793437665,-0.631450911959377
493.2000000000063,54.75635905024734,-0.6265387939196106,-0.6302385994432651
494.3000000000063,54.8645762811305,-0.629041022085026,-0.6314110958340362
495.40000000000634,54.973464980870844,-0.6296757329520694,-0.6340822565571531
496.5000000000063,55.081683183394425,-0.631663456382004,-0.6341098395434428
497.60000000000633,55.18929325577531,-0.634221330428862,-0.6340999759647312
498.70000000000636,55.297829527820674,-0.6363681281707552,-0.636571201101571
499.8000000000064,55.40684165053821,-0.6358301339857898,-0.6354195782877574
500.9000000000064,55.51414431045416,-0.6366216419543506,-0.6367404214653649
502.0000000000064,55.62225799033976,-0.6394156995206024,-0.6393833244062166
503.10000000000645,55.73095709983676,-0.6378996906670198,-0.6406886178747948
504.2000000000064,55.83932608237978,-0.6378062829621779,-0.6398522015382215
505.30000000000643,55.9484749198983,-0.6316211358284645,-0.6393698406732153
506.40000000000646,56.05530367256855,-0.628117685139633,-0.640688197365793
507.5000000000065,56.163569390545305,-0.6240567941642039,-0.6433293875158705
508.6000000000065,56.27168361617249,-0.623220574939785,-0.6433188791870195
509.7000000000065,56.379212077989486,-0.6211339022613132,-0.6419958631956728
510.80000000000655,56.489673652359166,-0.6193103590580391,-0.6446400874787099
511.90000000000657,56.59865194975966,-0.6184731800447637,-0.6433161168014125
513.0000000000066,56.70691181786718,-0.6188209617848722,-0.6435637719317349
514.1000000000065,56.81529019193048,-0.6184005762504905,-0.6446399671506522
515.2000000000066,56.92475366801558,-0.6185728038036551,-0.6466217612493086
516.3000000000065,57.03259021830966,-0.619922457488648,-0.6452685799756392
517.4000000000067,57.140763192746775,-0.6207471969456823,-0.6459598984896644
518.5000000000066,57.24989281125021,-0.6187182960291722,-0.6472701261302456
519.6000000000067,57.35781876721829,-0.6173706825474137,-0.6472701443125866
520.7000000000066,57.46770789023758,-0.6149795478417736,-0.6485895882358874
521.8000000000067,57.57614680861875,-0.61511937514188,-0.648592056357423
522.9000000000067,57.68479916929437,-0.6155688908864241,-0.6499098462024784
524.0000000000067,57.79414376791867,-0.6160568248795887,-0.6485999662999067
525.1000000000067,57.90298815839221,-0.6142790383767013,-0.6512218221316988
526.2000000000068,58.01125453118218,-0.6166141609173327,-0.6525943413323252
527.3000000000068,58.12067801423673,-0.6163503664719104,-0.6525398642581854
528.4000000000068,58.23029226996677,-0.6163388430939174,-0.6525899831360915
529.5000000000068,58.33901464318977,-0.6155760929656742,-0.6525498199345785
530.6000000000068,58.44839894824751,-0.6144834941925649,-0.6530967493550772
531.7000000000069,58.55685763641651,-0.6171510823287911,-0.6537794194503714
532.8000000000068,58.66430342443756,-0.6180917221887916,-0.6561601329032647
533.9000000000069,58.77467137484421,-0.6167521060759249,-0.6561596671147112
535.0000000000068,58.883616064821794,-0.6178439009155559,-0.6561673203417939
536.100000000007,58.993083027093334,-0.6182214485852716,-0.6561048310425113
537.2000000000069,59.10199368344174,-0.619336944993432,-0.6581399404017856
538.300000000007,59.21000109104332,-0.6205900458316265,-0.6581274692466224
539.4000000000069,59.31848089992771,-0.622068877211589,-0.6581501964247791
540.5000000000069,59.42881383555696,-0.6244045052769199,-0.6581244032035078
541.600000000007,59.53708148158644,-0.6253045015890052,-0.6594601627587289
542.700000000007,59.64546424356786,-0.6252821744988153,-0.6604741110272339
543.800000000007,59.755718883453525,-0.6254676264651422,-0.6607894316137539
544.900000000007,59.864090359810554,-0.6245299805623573,-0.6620999444758238
546.000000000007,59.9730944769962,-0.6258052586357249,-0.6621005082913394
547.1000000000071,60.082407611491746,-0.6239069053328545,-0.6634198793076442
548.2000000000071,60.19149134889683,-0.6226988671570945,-0.6647299291336366
549.300000000007,60.2990863750411,-0.621377975480778,-0.6660687027382943
550.4000000000071,60.40897066484174,-0.6222816855458551,-0.6660499100170982
551.500000000007,60.51733899516002,-0.6219990196222711,-0.6659565211501448
552.6000000000072,60.62665813772988,-0.6217510612086656,-0.6683593965508359
553.7000000000071,60.73596392267427,-0.6198956451849235,-0.6683602580287098
554.8000000000072,60.84282652308828,-0.6198408019090916,-0.669669808130561
555.9000000000071,60.95327497413333,-0.6194576481115224,-0.6696280621843274
557.0000000000072,61.06209544560525,-0.6179991895575173,-0.6697507557192193
558.1000000000072,61.17090545995033,-0.6189090823572144,-0.6705434573498463
559.2000000000072,61.28019091122603,-0.6189231430809276,-0.6706762122798531
560.3000000000072,61.389303879427956,-0.6193373545980793,-0.6722963735542447
561.4000000000073,61.49902986878911,-0.6214484782517016,-0.6723001436267997
562.5000000000073,61.606826435763715,-0.6237628746705212,-0.6749727209649787
563.6000000000073,61.716190647823936,-0.6281196022844019,-0.6768696332385198
564.7000000000073,61.824197297257115,-0.6329171538090156,-0.676919922249716
565.8000000000073,61.93461740538716,-0.638320657409588,-0.6769800670962862
566.9000000000074,62.04347900094836,-0.6457622640562304,-0.6782365734527209
568.0000000000074,62.15264581994346,-0.6515181061955133,-0.6795499830563441
569.1000000000074,62.260191018366115,-0.6595227127776239,-0.6783562778894172
570.2000000000073,62.36969688074541,-0.6688353940936412,-0.6795501392285521
571.3000000000073,62.47925981167678,-0.6767024624954386,-0.6782403302779776
572.4000000000074,62.58800632675318,-0.6856392609676882,-0.6795504067914773
573.5000000000074,62.69801093788986,-0.6910234011794669,-0.6808600052991842
574.6000000000074,62.80547875773079,-0.6979496585131367,-0.681200367633779
575.7000000000074,62.91660864047496,-0.7045306589935089,-0.6811317361127518
576.8000000000075,63.02626049197392,-0.7120758171877901,-0.6838732820252189
577.9000000000075,63.13529915354374,-0.7158014483304999,-0.6839034149494543
579.0000000000075,63.243847986787515,-0.7223807341155786,-0.683838648394512
580.1000000000075,63.35462874563851,-0.726080844950431,-0.6828533518353948
581.2000000000075,63.463184024939615,-0.7289156957463293,-0.6858147083650357
582.3000000000076,63.572254687539676,-0.7313090129874142,-0.6858099419842949
583.4000000000076,63.68322641771203,-0.7327828583473391,-0.6854889857138122
584.5000000000076,63.79125295843471,-0.7352699951343229,-0.6868005142591649
585.6000000000076,63.90133404835637,-0.7353582039699111,-0.6854953883086279
586.7000000000077,64.01048034939089,-0.7369233470465609,-0.6851496848261367
587.8000000000077,64.1197375120457,-0.73618440210938,-0.6868058478537766
588.9000000000076,64.22926211838359,-0.7357194756860924,-0.6894141859045759
590.0000000000076,64.33847301486605,-0.7361253925117649,-0.6894280929746301
591.1000000000076,64.44724789171195,-0.7358537441259266,-0.689430647989921
592.2000000000077,64.55755464699143,-0.7352376482576746,-0.6894321253529361
593.3000000000077,64.66809162798131,-0.7343866769531635,-0.6895583029136665
594.4000000000077,64.77750173040458,-0.7356782182460939,-0.6908033927336263
595.5000000000077,64.88632490954336,-0.73468776546563,-0.6921144181355263
596.6000000000078,64.99590515160244,-0.7348921371732834,-0.6909722451643501
597.7000000000078,65.10435142058287,-0.7319246553078548,-0.692077425213121
598.8000000000078,65.21259572581701,-0.7321022593346973,-0.6933798247366703
599.9000000000078,65.32423458603243,-0.7305172924373801,-0.6947009327131002
601.0000000000078,65.43258416325266,-0.7294610285060268,-0.6946453246742954
602.1000000000079,65.54187668079378,-0.7257842624788747,-0.6960732592324206
603.2000000000079,65.651079143159,-0.7242417432781396,-0.6947074706989369
604.3000000000079,65.7600009249074,-0.7229800267664169,-0.6939301454619811
605.4000000000078,65.8698000807281,-0.7183373917984016,-0.6945901798070024
606.5000000000078,65.97927773356274,-0.7166077331998678,-0.6972301579196749
607.6000000000079,66.08765133957334,-0.7118876003217234,-0.698661398664099
608.7000000000079,66.19668065364355,-0.7085006136845677,-0.6998692705268241
609.8000000000079,66.30710740575142,-0.7039436271072816,-0.7010817832159164
610.9000000000079,66.41578658847797,-0.7003695935696451,-0.7015095284206545
612.000000000008,66.52461688196972,-0.6948511393864272,-0.7028299114058503
613.100000000008,66.63482730211193,-0.6931360088145727,-0.7041384574459215
614.200000000008,66.74414474380094,-0.6877540884499115,-0.7055652652219209
615.300000000008,66.85312407844498,-0.6809604410941014,-0.7061103365450969
616.400000000008,66.96239150615104,-0.6783776502444023,-0.7081086714376359
617.5000000000081,67.073496356307,-0.6713941090282917,-0.7090899398753647
618.6000000000081,67.18199910625489,-0.667070926065631,-0.7103967596788463
619.7000000000081,67.29196178443578,-0.6619304627240246,-0.7104803323986784
620.8000000000081,67.40094463562676,-0.6543567493750729,-0.7117198503778344
621.9000000000082,67.51121996208035,-0.6489431110767321,-0.7147851464297719
623.0000000000082,67.61980132773726,-0.6441105483394829,-0.7156700627563746
624.1000000000081,67.72992311578717,-0.6365874131712334,-0.7169899580688752
625.2000000000081,67.83979702560957,-0.6288244924781974,-0.7189647021123049
626.3000000000081,67.94981772415267,-0.6229573843285707,-0.7212537271755797
627.4000000000082,68.05776540263368,-0.6153451916993788,-0.7220319980191636
628.5000000000082,68.16846642044953,-0.6090659144431845,-0.7242261176864964
629.6000000000082,68.27817502283908,-0.6021549946955197,-0.7231759213616655
630.7000000000082,68.38743622268062,-0.5941309553170536,-0.7254685123845768
631.8000000000083,68.49776526971317,-0.5875986214488684,-0.7280759318890739
632.9000000000083,68.60811667694416,-0.5799066541854083,-0.7293908445442381
634.0000000000083,68.71796919217107,-0.5728307612120949,-0.7321022089368872
635.1000000000083,68.82711537013586,-0.5651155256395277,-0.7352126504875733
636.2000000000083,68.93781010857234,-0.5570861269842418,-0.737429204276137
637.3000000000084,69.04647095886085,-0.5486368292839692,-0.7395619045596162
638.4000000000084,69.15717267801983,-0.540283581111477,-0.7410683493092338
639.5000000000084,69.26697085101421,-0.5322308325415027,-0.7445221619102584
640.6000000000083,69.37697984680962,-0.5243305548981491,-0.7472710495806489
641.7000000000083,69.48724013807612,-0.5136946490504495,-0.7501245495784032
642.8000000000084,69.5969904549694,-0.5037167189704116,-0.7521394438944666
643.9000000000084,69.70681932048609,-0.49642936625063194,-0.7552196576047172
645.0000000000084,69.81607197313704,-0.48560828439264164,-0.7561582917793279
646.1000000000084,69.92545756463893,-0.47804016364345026,-0.7588220478192458
647.2000000000085,70.03538665776178,-0.46613108785154284,-0.7625269962883934
648.3000000000085,70.14565415766995,-0.45628810368216915,-0.765755039496002
649.4000000000085,70.2551536980678,-0.4452644799171039,-0.7698593368806885
650.5000000000085,70.36554414537581,-0.4327864061826199,-0.7731639769233087
651.6000000000085,70.47549321551715,-0.42076673034716106,-0.7777499743381222
652.7000000000086,70.58574871019829,-0.41129460208176344,-0.779624495175717
653.8000000000086,70.69474269618034,-0.39932938839982624,-0.7829088547341918
654.9000000000086,70.80389368720247,-0.3867661089543385,-0.7862759870611211
656.0000000000086,70.91417906746643,-0.3721341520711065,-0.7901570295536002
657.1000000000087,71.0238156607778,-0.3585979679360498,-0.7935803423448582
658.2000000000087,71.13385125751282,-0.34422771726714235,-0.7991192908200131
659.3000000000086,71.24371465801673,-0.33409269955466725,-0.8022520089546288
660.4000000000086,71.35368780224104,-0.31794564163264644,-0.8064829690998345
661.5000000000086,71.46265704161405,-0.30591465607660545,-0.812072922707519
662.6000000000087,71.57292351587826,-0.29117357041006153,-0.8166092053154141
663.7000000000087,71.68321255253304,-0.27610745654213004,-0.8196733608281259
664.8000000000087,71.79283358305825,-0.26319267343038055,-0.8266039719850253
665.9000000000087,71.90211132792518,-0.24830014750988566,-0.8296571862981752
667.0000000000088,72.01228433655955,-0.22996218374987804,-0.8358622200144805
668.1000000000088,72.1226143904177,-0.21044846022290933,-0.8404651318216683
669.2000000000088,72.23248540427232,-0.19328842096450896,-0.843860275485437
670.3000000000088,72.34222949814666,-0.17532338443872972,-0.8501300540960659
671.4000000000088,72.4497836766028,-0.15790303108912765,-0.8585962987613653
672.5000000000089,72.56156359267949,-0.138394387585728,-0.8641859132745195
673.6000000000089,72.67115651196276,-0.11816274034684826,-0.8687055119389759
674.7000000000089,72.78228797896624,-0.0995618906457641,-0.8743201562191811
675.8000000000088,72.89234436944345,-0.07885079149729361,-0.8807697767463272
676.9000000000088,73.00130444027059,-0.05577103709074181,-0.887187971232609
678.0000000000089,73.11146265267043,-0.03375094738199463,-0.8940086030092846
679.1000000000089,73.22063677853292,-0.008760664396030439,-0.9006733377220217
680.2000000000089,73.33211812742199,0.011612582125741917,-0.9076146560272216
681.3000000000089,73.44148981121604,0.033303856312805344,-0.9129719319520571
682.400000000009,73.55288424833117,0.055770564162535625,-0.9209190510881711
683.500000000009,73.662016451195,0.08466311161573299,-0.9298133841522378
684.600000000009,73.77219214518776,0.11027766238969483,-0.9376162545612039
685.700000000009,73.88347319595405,0.137033673639395,-0.945592162326633
686.800000000009,73.99386895946422,0.1636092199470918,-0.9541573029405526
687.9000000000091,74.10367759092871,0.18883840226193493,-0.96286469193543
689.0000000000091,74.21375155101016,0.21697880495332783,-0.9697437451832047
690.1000000000091,74.32392869092601,0.24245323911460676,-0.980285932941185
691.2000000000091,74.43341191537246,0.2696906628273402,-0.9880626450342938
692.3000000000092,74.54478703618423,0.29823773877349213,-0.9970706260239237
693.4000000000092,74.65448678038163,0.3227697478111591,-1.006920065427209
694.5000000000091,74.76393524174087,0.3505156063501666,-1.0160355612815621
695.6000000000091,74.87580100322661,0.37902506056536395,-1.0259282830363339
696.7000000000091,74.9863292331998,0.40530957798621364,-1.034493372421207
697.8000000000092,75.09462073620216,0.43411683992876626,-1.0448900195234003
698.9000000000092,75.20562000673021,0.4539853084937953,-1.0558789341856927
700.0000000000092,75.31655858128771,0.4809288652527762,-1.0668673715048036
701.1000000000092,75.42531035630594,0.5033258292848218,-1.0781223896846925
702.2000000000093,75.53668061294225,0.52391531817123,-1.0892137769309334
703.3000000000093,75.64714476670773,0.5455197130903217,-1.1008497008791358
704.4000000000093,75.75719234454309,0.5662419402101705,-1.1121426680865851
705.5000000000093,75.86721190403827,0.5799594753003137,-1.123694673600327
706.6000000000093,75.97735119666112,0.5944782588058132,-1.1345337243368299
707.7000000000094,76.0871908800871,0.6074227730978281,-1.1455412061353711
708.8000000000094,76.19810427978658,0.615793882605747,-1.1535417382797797
709.9000000000094,76.30850113773374,0.622094288976338,-1.1673672240050643
711.0000000000093,76.4193919469405,0.6194440384215626,-1.1795567591170015
712.1000000000093,76.53050576598707,0.6139093758937605,-1.190999802744836
713.2000000000094,76.64037759095547,0.6026906474424525,-1.2031389299192101
714.3000000000094,76.75031000676998,0.5891009883406825,-1.214121310045012
715.4000000000094,76.8605975554004,0.5604559076713511,-1.2258964443317817
716.5000000000094,76.97098665679623,0.5270634293292222,-1.2364739501421549
717.6000000000095,77.08090646381314,0.4832830981768308,-1.2480913526719477
718.7000000000095,77.19112843340382,0.4235768912371344,-1.257033145960949
719.8000000000095,77.30073202437457,0.3490972180627624,-1.2678349827138273
720.9000000000095,77.41104301005232,0.24760494688523976,-1.2760102515991978
722.0000000000095,77.52091453597552,0.10903458177340698,-1.2856275146186005
723.1000000000096,77.63185043971777,-0.08758811349835073,-1.2942208253331926
724.2000000000096,77.74063502952225,-0.32942818056448714,-1.2974285151809286
725.3000000000096,77.85084678856144,-0.569766842019737,-1.3026941705864736
726.4000000000096,77.96029347005974,-0.7434933611386905,-1.3047612871700793
727.5000000000097,78.06980393977004,-0.8602945621895663,-1.308722218101698
728.6000000000097,78.17970302593781,-0.934095751070328,-1.3093554085392443
729.7000000000096,78.29019856192137,-0.9699386421562065,-1.3100307476425908
730.8000000000096,78.39970675194583,-0.991532088868088,-1.3100359212234989
731.9000000000096,78.51038908394699,-1.005594096038917,-1.3100295877649675
733.0000000000097,78.62119727165604,-1.0110193008683184,-1.308725134584925
734.1000000000097,78.73107743240142,-1.0176336382974063,-1.3091598284680366
735.2000000000097,78.84043708413132,-1.0197953847976637,-1.3087365242359845
736.3000000000097,78.95029132016882,-1.0236967912480248,-1.3113616285496397
737.4000000000098,79.06140462787762,-1.023351062922626,-1.3126773440375707
738.5000000000098,79.17142601736822,-1.0258529840155453,-1.3124307528482642
739.6000000000098,79.2822008604994,-1.0261422679511767,-1.3113792915418268
740.7000000000098,79.3917502058659,-1.0305500212569494,-1.3127225774708622
741.8000000000098,79.50243916473543,-1.0328796747111277,-1.3138860794238991
742.9000000000099,79.61293385199268,-1.0333301200491734,-1.3138783795936733
744.0000000000099,79.72346619278498,-1.0337551134626999,-1.3125576494019935
745.1000000000099,79.83104896260286,-1.038840709904906,-1.3125600250090206
746.0000000000099,79.92290830720404,-1.0405801855384542,-1.3125552715963988