File: 01_Data/XPS_Foam_Board/STA/N2/10K_min/XPS_Foam_Board_STA_N2_10KData_221018_R2.csv
##Temp./Â°C,Time/min,DSC/(mW/mg),Mass loss/mg
51.0,10.67,-1.6853,0.0010537736321003521
51.80000000000001,11.000000000000007,-1.5817899999999971,0.0023322562454737295
52.60000000000002,11.213967921041041,-1.5073647482018455,0.003705141213377061
53.400000000000034,11.38614610471264,-1.4498183641182525,0.004435908831851965
54.200000000000045,11.540398797880252,-1.4030211756633282,0.004545475066329185
55.00000000000006,11.682977941728547,-1.3642936971679251,0.0034032614219268176
55.80000000000007,11.813387346520784,-1.3321940250881859,0.003518853991347104
56.60000000000008,11.937875277159447,-1.3034676289566791,0.004481823419584252
57.40000000000009,12.055010155732816,-1.2794859691128648,0.004186148313833016
58.2000000000001,12.172080431821493,-1.2577581090365864,0.0038667141234842717
59.000000000000114,12.283480014273728,-1.240530440742412,0.0025210095273657807
59.800000000000125,12.390570261636416,-1.222450416222506,0.004217257484413928
60.600000000000136,12.499865205814759,-1.2054036871310672,0.004635663143420565
61.40000000000015,12.603816261317416,-1.1917104533756417,0.003584819330500366
62.20000000000016,12.706633606740152,-1.1773753257582757,0.004234708840718415
63.00000000000017,12.808812354673403,-1.166535927917085,0.003383627635298314
63.80000000000018,12.908282099803836,-1.153516101955208,0.005088082043943398
64.6000000000002,13.008876895689454,-1.1415901036534317,0.003630190211373119
65.4000000000002,13.106272135587377,-1.1328393323494885,0.0037092824952402736
66.20000000000022,13.20328085585227,-1.1206720004524884,0.0025738321049075807
67.00000000000023,13.295927658963857,-1.1111941910806482,0.0036201172474550347
67.80000000000024,13.392949637970489,-1.1012315086927562,0.00359262374336744
68.60000000000025,13.488399038514276,-1.0929354415530363,0.006272228291960946
69.40000000000026,13.582573985412829,-1.0842812732933422,0.005082353027938691
70.20000000000027,13.674265231869688,-1.0745884276322244,0.004969039216478066
71.00000000000028,13.766302166388037,-1.0642170032919773,0.004949790338532711
71.8000000000003,13.856681374411915,-1.0553548507138777,0.0049081891224456164
72.6000000000003,13.946291908461243,-1.0462591301817363,0.004935065294746188
73.40000000000032,14.040000000000033,-1.0377099999999944,0.004507535097494131
74.20000000000033,14.130356235406746,-1.0282265428373147,0.004947961480947782
75.00000000000034,14.216628596455744,-1.0213607939831502,0.004549482098782143
75.80000000000035,14.307155104815436,-1.0118679938670678,0.004900469841694566
76.60000000000036,14.395214739297458,-1.0049613800018846,0.005233241988920501
77.40000000000038,14.483535502699633,-0.9972071246209542,0.006304043363633216
78.20000000000039,14.569690447187277,-0.9888165373845217,0.00568702695429657
79.0000000000004,14.658288157523831,-0.9806899161615911,0.005786785330390121
79.80000000000041,14.7429838413605,-0.9705288571533662,0.006279156975333766
80.60000000000042,14.829792007081663,-0.9632196359876424,0.006261306181531534
81.40000000000043,14.914689941604879,-0.9538990174890181,0.004960744245604332
82.20000000000044,14.998195600942347,-0.9457134525503514,0.005385717127316614
83.00000000000045,15.085516962717756,-0.9393191848342305,0.004905089637897042
83.80000000000047,15.171317435958816,-0.9319532308971762,0.00369516516024726
84.60000000000048,15.252859256916114,-0.9259890666600822,0.0038013477867537837
85.40000000000049,15.337310156846295,-0.9231694007145137,0.003642462149408665
86.2000000000005,15.422474342423556,-0.9210134414828164,0.004184294333983818
87.00000000000051,15.503829790980095,-0.9204314470133399,0.004962785290937077
87.80000000000052,15.587495677080197,-0.9201922816839243,0.0053204534727400166
88.60000000000053,15.670112716243214,-0.919057772596946,0.006260242276277417
89.40000000000055,15.753461346348702,-0.9169104267313207,0.004980018978243628
90.20000000000056,15.83452071315475,-0.914031852284045,0.00495959301837523
91.00000000000057,15.915399228058478,-0.9090204635760807,0.004930505013153841
91.80000000000058,15.997730421651298,-0.904768323002306,0.004940608376420741
92.60000000000059,16.078502698812223,-0.8974870788694411,0.005077767157754209
93.4000000000006,16.161170564824545,-0.8914244866449059,0.0050663080560262586
94.20000000000061,16.242182433372818,-0.8842926641138932,0.0036324250242438794
95.00000000000063,16.323680795583847,-0.8787390529265228,0.0036601329063277177
95.80000000000064,16.401823916452386,-0.8699759913349805,0.004234542416877041
96.60000000000065,16.483742248662754,-0.8642079567503653,0.005006920319146513
97.40000000000066,16.563436552011783,-0.8569570037527383,0.0049399800464078325
98.20000000000067,16.64397392370047,-0.8488811538849224,0.004053384094468537
99.00000000000068,16.72426059906756,-0.8409308148076402,0.0035390792520710868
99.8000000000007,16.804278476721507,-0.8303878488069384,0.00493005664720636
100.6000000000007,16.88338717025678,-0.822896321108053,0.0035831563493506913
101.40000000000072,16.962339133570676,-0.812879380794855,0.004946762800946747
102.20000000000073,17.04292834923568,-0.8034149981668302,0.003630089937729508
103.00000000000074,17.121590637902997,-0.7947260483927734,0.0023098805967216585
103.80000000000075,17.201764317933396,-0.7822137564351093,0.0036951074284945484
104.60000000000076,17.280539668821376,-0.7734990435658515,0.005273116985242243
105.40000000000077,17.358332479383428,-0.765356578442386,0.0065847260402112084
106.20000000000078,17.437667988208055,-0.7552979235642536,0.004845587328325962
107.0000000000008,17.5172090341175,-0.7490583594441783,0.0036066324276378126
107.80000000000081,17.595681001301745,-0.745264776851353,0.0034494743855244536
108.60000000000082,17.674549599985937,-0.7391124847274266,0.0036265959706689443
109.40000000000083,17.753682577311544,-0.7352041052230883,0.004982185418898055
110.20000000000084,17.832345907884395,-0.7293484669488461,0.0022689299986291545
111.00000000000085,17.912483310837576,-0.7245150473590587,0.003619994714067598
111.80000000000086,17.988684615511982,-0.7202992471786881,0.0032060864949960965
112.60000000000088,18.067718773748627,-0.7157051936373219,0.0036242003987023708
113.40000000000089,18.14662586059461,-0.7112250905354732,0.002307000152237393
114.2000000000009,18.223348181603296,-0.706839801582604,0.003629205099386912
115.00000000000091,18.30169398986559,-0.7041640625589716,0.004950455240673612
115.80000000000092,18.381188237487873,-0.7000393347825786,0.004926744634757618
116.60000000000093,18.458151266161256,-0.6965786313174744,0.003550564796812594
117.40000000000094,18.537354598252467,-0.6923988197400914,0.004940109160839867
118.20000000000095,18.615834680777027,-0.6880781930741258,0.003957653711749831
119.00000000000097,18.693769740541946,-0.6856327668922669,0.0036200511105932698
119.80000000000098,18.771256890253948,-0.6817702420307267,0.003046954176434191
120.60000000000099,18.84872625719347,-0.6775917656877868,0.0036288932524590756
121.400000000001,18.927867530354952,-0.6727050209653912,0.0036317056339933984
122.20000000000101,19.00556178667643,-0.6700469750855247,0.0023095918515836367
123.00000000000102,19.083608899413225,-0.6655148520380428,0.003707906651859716
123.80000000000103,19.16058763343414,-0.6650350124918235,0.0023089325170699837
124.60000000000105,19.23908274561389,-0.6606464626320004,0.0036199047596001677
125.40000000000106,19.315708999473795,-0.6579109712033846,0.003617968290787754
126.20000000000107,19.39311117227146,-0.6542798703467304,0.0023146043434185692
127.00000000000108,19.471077164297697,-0.6507889794172369,0.003620149905511738
127.80000000000109,19.54864580622329,-0.6481621872521766,0.0036379554382661716
128.6000000000011,19.626413727163598,-0.6427019617101849,0.0036301608562889776
129.4000000000011,19.703288521113187,-0.6383289249316609,0.0036301599963484144
130.20000000000113,19.780474842224596,-0.6366327517469911,0.003630094706387421
131.00000000000114,19.858288744634677,-0.6326806338559603,0.002670159666018357
131.80000000000115,19.935028236047046,-0.6285801279737795,0.003616648579478632
132.60000000000116,20.012756061448314,-0.6267834668888445,0.003631367676656172
133.40000000000117,20.089530907283887,-0.6213354203338386,0.003565427351770012
134.20000000000118,20.167247038302534,-0.6190977597060958,0.003619919066227606
135.0000000000012,20.242557058839132,-0.617250871933925,0.0036177566219639523
135.8000000000012,20.32032054141488,-0.6137706837198135,0.0023094711970168547
136.60000000000122,20.396471981721394,-0.610652741435575,0.002309897355606605
137.40000000000123,20.474393015946113,-0.607127894882121,0.0009840507434306645
138.20000000000124,20.547218384734535,-0.6052788947039378,0.0009899205447871928
139.00000000000125,20.628450042127984,-0.5999712322946306,0.0018287509423839943
139.80000000000126,20.703562669277467,-0.5957735549384896,0.0013146006203794691
140.60000000000127,20.78165507083211,-0.5937117356561783,0.0009900898484245246
141.40000000000128,20.857703872230452,-0.5896638098375847,0.0009900784296905663
142.2000000000013,20.934255773315996,-0.5872976147090566,0.0010007657962001204
143.0000000000013,21.011093341060615,-0.5846047121588762,0.0009980036543568716
143.80000000000132,21.08765658302125,-0.5804638048360526,0.002344006764275708
144.60000000000133,21.16317356379016,-0.5772848008783834,0.0024352577095267947
145.40000000000134,21.236982367833193,-0.5740306674067552,0.0023098240214647348
146.20000000000135,21.314607804574273,-0.5697657955160087,0.0023098294759447136
147.00000000000136,21.392099166753006,-0.5667503213560957,0.002289602256049683
147.80000000000138,21.46956165025122,-0.565273781714209,0.0009898102523262509
148.6000000000014,21.544152072243865,-0.5625476061991422,0.0017059245295141245
149.4000000000014,21.62152584830764,-0.5580217234062822,0.0009901058582180156
150.2000000000014,21.696084150705442,-0.5558405706451715,-0.00021159981420781904
151.00000000000142,21.773031893191572,-0.5519661419201973,0.00029561280331202866
151.80000000000143,21.84899109584538,-0.5510739984088759,0.001000168575547633
152.60000000000144,21.92230224526536,-0.5481494399198167,0.0010001626374442907
153.40000000000146,22.00070834840194,-0.5455305626234298,0.0010059035419485163
154.20000000000147,22.075365693342718,-0.5415667451327018,0.0013835562051704997
155.00000000000148,22.1531467808355,-0.5398313323246474,0.0009899783107933935
155.8000000000015,22.229714800887507,-0.5365310965656137,0.0009899397628401196
156.6000000000015,22.304574934954967,-0.5331629253173467,0.0002900831027776718
157.4000000000015,22.381071673055956,-0.5307620097173424,0.0003848660945098281
158.20000000000152,22.45737742014,-0.5277455237817699,0.001000839849688795
159.00000000000153,22.53379733344622,-0.5253194696657872,-0.000316717758806373
159.80000000000155,22.608525955053285,-0.5219493922392049,0.0009405366807593296
160.60000000000156,22.68480236293598,-0.5201054070920487,6.365854575030028e-06
161.40000000000157,22.76088994226327,-0.5169650106943867,0.0013200243203224105
162.20000000000158,22.83678735968749,-0.5154537908135258,0.0013198115999806248
163.0000000000016,22.91201665090029,-0.5124936911557628,0.0009899535659929626
163.8000000000016,22.98907619073666,-0.511000002513024,0.0009894285422271665
164.60000000000161,23.065961224942118,-0.5073326217339797,-0.00031380205208897394
165.40000000000163,23.141789344319715,-0.5062624030966166,-0.00023100881792803563
166.20000000000164,23.217774483919193,-0.5033182458532337,0.000324353776525399
167.00000000000165,23.29338915988189,-0.5009648224990556,0.00011906750710277691
167.80000000000166,23.36928749581717,-0.49902416886428735,-0.00032774961497938904
168.60000000000167,23.44487605151959,-0.49618558730124585,-0.001320427552084169
169.40000000000168,23.52146563415115,-0.49448071957494166,-5.768983371012837e-07
170.2000000000017,23.59670066527105,-0.49172096622936406,0.001319024341659869
171.0000000000017,23.67288634515451,-0.49069796939750676,0.0009374263560917306
171.80000000000172,23.748489929177612,-0.48789676499901435,-0.0013109391773711287
172.60000000000173,23.825558363380917,-0.4845400485886321,-0.002629338053728336
173.40000000000174,23.90181130928345,-0.483710224865433,-0.0026299469368979977
174.20000000000175,23.97731650954726,-0.47969674910859883,-0.0014075966017830233
175.00000000000176,24.053700714637838,-0.47800897641679185,-0.0013098316562500933
175.80000000000177,24.129508100959058,-0.4758485225846915,-0.0013087474185757841
176.60000000000178,24.20485757861266,-0.47255828743635897,-0.0022368832885852896
177.4000000000018,24.281564301395033,-0.47247503865368984,-0.0035903247311783737
178.2000000000018,24.35721368244078,-0.4688914382373217,-0.002296838022055603
179.00000000000182,24.433495456947888,-0.46740833850358926,-0.0022990556069486523
179.80000000000183,24.508399471156892,-0.4633494599592639,-0.002298415028117784
180.60000000000184,24.58564625716684,-0.4615604682704377,-0.0023100670606472917
181.40000000000185,24.6618197791802,-0.46023757299054224,-0.00231010019403044
182.20000000000186,24.737641067766837,-0.45740260726584403,-0.0024740665158153874
183.00000000000188,24.813160660720715,-0.4558444352295393,-0.0022999011533695324
183.8000000000019,24.888601648960986,-0.45261208892661614,-0.0027023691130465544
184.6000000000019,24.96474281875756,-0.4505656664785817,-0.002311709226096692
185.4000000000019,25.039819274724323,-0.4482390238779386,-0.002300141215469509
186.20000000000192,25.116345416996673,-0.44651676825225983,-0.003668751597428521
187.00000000000193,25.19092980272959,-0.442986339155881,-0.004656401648234887
187.80000000000194,25.268921889691757,-0.4411147776243008,-0.00494110994103103
188.60000000000196,25.343057906947166,-0.4387089988153542,-0.004280017054679952
189.40000000000197,25.419552118005242,-0.4354724998943086,-0.004285488270999505
190.20000000000198,25.494796565177516,-0.43242688301493265,-0.0053504236359156465
191.000000000002,25.570541856852127,-0.4299094249982349,-0.004280128310591547
191.800000000002,25.647006427117052,-0.42741379887263753,-0.004279766562711895
192.600000000002,25.72293701990936,-0.4251962059386682,-0.0055885396886705685
193.40000000000202,25.797253441785156,-0.4236030334841145,-0.004266203106490174
194.20000000000203,25.873226533568214,-0.42006955279164665,-0.0042701138345151435
195.00000000000205,25.949438031460577,-0.4178892700768299,-0.0029541219282220865
195.80000000000206,26.02440590225749,-0.4161377664819346,-0.002982787348576821
196.60000000000207,26.09999904433633,-0.4126800146661456,-0.004269970214437091
197.40000000000208,26.176635890187143,-0.4125411502142736,-0.004230095507103737
198.2000000000021,26.251937276211965,-0.40990481943196755,-0.005589878380580338
199.0000000000021,26.327582865250132,-0.40860788641028745,-0.005589979986045268
199.80000000000211,26.403583104042845,-0.4054243488561459,-0.007012405980800995
200.60000000000213,26.47946809152008,-0.40278057502982406,-0.008228946555597805
201.40000000000214,26.554840100564427,-0.40147013166133366,-0.008230133769794534
202.20000000000215,26.63147929643129,-0.40091188040317804,-0.008230645120710811
203.00000000000216,26.707119458177647,-0.3987652062577882,-0.007700102459372804
203.80000000000217,26.78273599296541,-0.395934663067227,-0.007569949126961184
204.60000000000218,26.858579416969874,-0.39565886809476164,-0.006915079276322178
205.4000000000022,26.93462690963315,-0.3929690331540633,-0.006922415163785889
206.2000000000022,27.009534099413536,-0.3914257648722804,-0.0076351418741418264
207.00000000000222,27.084998789388788,-0.38840508072501057,-0.007569804403474656
207.80000000000223,27.162016383437802,-0.38613132893808677,-0.007569810004139033
208.60000000000224,27.237054447155415,-0.3829036122603449,-0.007569704596770421
209.40000000000225,27.313673610724504,-0.3819506733458217,-0.006575759037824813
210.20000000000226,27.388381697338637,-0.38133280298927236,-0.008232243423379249
211.00000000000227,27.46431490320001,-0.3789952024849252,-0.008229982125514734
211.80000000000229,27.540285055363267,-0.37681830664833793,-0.008584651804392607
212.6000000000023,27.616659946432936,-0.3751101840283771,-0.009550172770070642
213.4000000000023,27.69335215382792,-0.3726337688772409,-0.009575409332407858
214.20000000000232,27.770087644239602,-0.36974671236176626,-0.01021102043638189
215.00000000000233,27.845559336335498,-0.36838086367876616,-0.010209866966256698
215.80000000000234,27.9216542931656,-0.36561599914176235,-0.010220468614775324
216.60000000000235,27.997328625166613,-0.3639097340743484,-0.01120040800643407
217.40000000000236,28.07235123266511,-0.3610505296844861,-0.011200262821736917
218.20000000000238,28.14832063877489,-0.36043531153837716,-0.012516881989205864
219.0000000000024,28.224203998218,-0.35682630722733183,-0.012519389854343643
219.8000000000024,28.300855884718345,-0.3541504499361178,-0.011189312304118904
220.6000000000024,28.37729584126621,-0.3528485820777513,-0.012510039893192992
221.40000000000242,28.45212235518885,-0.35092624283447515,-0.012507626868059951
222.20000000000243,28.529298569801675,-0.3474781016032678,-0.013796607855785403
223.00000000000244,28.60414152988083,-0.34745345947987666,-0.014945514051472486
223.80000000000246,28.680087827188768,-0.34511187053254483,-0.013830090684391116
224.60000000000247,28.756288258545176,-0.3429843132819172,-0.013799609561187864
225.40000000000248,28.831489602566368,-0.34158088303811707,-0.013829103109726404
226.2000000000025,28.90606092191581,-0.3398156845927948,-0.013829929929465745
227.0000000000025,28.984252303840936,-0.336345370896043,-0.014055848071947707
227.8000000000025,29.06020306666679,-0.33451727544621,-0.016137116296266907
228.60000000000252,29.136805793309343,-0.3330403168387142,-0.016140137733512194
229.40000000000254,29.212137311802866,-0.3311256741672589,-0.014748122842038303
230.20000000000255,29.28826592022458,-0.328426305118514,-0.01484086104486293
231.00000000000256,29.364286938975667,-0.32661336506813715,-0.014199086625641844
231.80000000000257,29.44079666674081,-0.32407062443201307,-0.018283507342388372
232.60000000000258,29.51324550875135,-0.3235435967449936,-0.0197599723930324
233.4000000000026,29.593061386676695,-0.32110285882437806,-0.019763869883272722
234.2000000000026,29.66901647571254,-0.3195972029300087,-0.017760373908738192
235.00000000000261,29.745309429545962,-0.3181195072546435,-0.016040427724177242
235.80000000000263,29.819126537454988,-0.31599905109935367,-0.018000340608294252
236.60000000000264,29.896982927688722,-0.3156487301596678,-0.018010526947946914
237.40000000000265,29.972927553073028,-0.31295625708803115,-0.019310279193941238
238.20000000000266,30.04788370410056,-0.31277407549124747,-0.01931003022500466
239.00000000000267,30.12450674680655,-0.3100005447412561,-0.019633119961779855
239.80000000000268,30.199734685099255,-0.30958637398519884,-0.02094121168219898
240.6000000000027,30.27540291199567,-0.3074470331954075,-0.019980133232619046
241.4000000000027,30.3513539969792,-0.3053381799534314,-0.019980185999073807
242.20000000000272,30.42926187137852,-0.3047746727399957,-0.019980186400884836
243.00000000000273,30.505083102965294,-0.302928825332417,-0.02005241152717918
243.80000000000274,30.580572522320097,-0.3020116305477351,-0.02260833465923051
244.60000000000275,30.657187789942295,-0.2991179086818923,-0.02261000589549278
245.40000000000276,30.732026820352957,-0.2989925337274359,-0.02264095255676679
246.20000000000277,30.808645687301286,-0.296058352138773,-0.02130017638748205
247.00000000000279,30.88565697356721,-0.2954338071913125,-0.021300229425246897
247.8000000000028,30.960094371022144,-0.2940786659371,-0.024005146825059942
248.6000000000028,31.036024198525148,-0.292569712971699,-0.023932661412687573
249.40000000000282,31.112855109477053,-0.291511884081244,-0.02525045970413453
250.20000000000283,31.188691760305847,-0.2897171934415202,-0.025250239766055227
251.00000000000284,31.26546862786782,-0.28917206437093873,-0.027390473989044928
251.80000000000285,31.340922316791552,-0.2870931104346327,-0.02787993883728479
252.60000000000286,31.416497186744557,-0.2860000772313414,-0.02787993800678157
253.40000000000288,31.493376555456503,-0.2842133974228507,-0.02787868770388391
254.2000000000029,31.571004602273227,-0.28302630810229157,-0.027231153484187587
255.0000000000029,31.64522810313615,-0.2821150830365646,-0.02848177227927229
255.8000000000029,31.722576163327922,-0.2809853787917926,-0.02855010030652716
256.6000000000029,31.798701111948088,-0.2807276365252115,-0.028511028469805133
257.40000000000293,31.87477040351464,-0.27987052887758185,-0.02989999509289243
258.20000000000294,31.949712898197443,-0.2791312784706461,-0.028539924608774303
259.00000000000296,32.026690928013146,-0.2766724334183985,-0.028539868033335303
259.80000000000297,32.10225804213059,-0.276078367007267,-0.031178372705406243
260.600000000003,32.179072283222915,-0.27438998761721345,-0.031180102844870827
261.400000000003,32.25495530634703,-0.27273710366668064,-0.031096133591296482
262.200000000003,32.33038725627003,-0.2726541065592676,-0.03248991983352001
263.000000000003,32.407155890935755,-0.2709595890451663,-0.032490089008700096
263.800000000003,32.48340545028838,-0.2700007795894454,-0.033808557955743446
264.60000000000304,32.56044993108703,-0.26859670561719967,-0.033810523716456764
265.40000000000305,32.636645239816204,-0.2684659820452441,-0.03249123269796428
266.20000000000306,32.712470260978094,-0.2666927193401316,-0.033760179916235256
267.00000000000307,32.78860153600463,-0.26602921849155137,-0.035125467540643385
267.8000000000031,32.864448551569296,-0.26449041086155795,-0.03644034027597298
268.6000000000031,32.9407812797246,-0.2617273087908467,-0.03644993304243105
269.4000000000031,33.01759665924563,-0.2617552098994694,-0.03512712006595997
270.2000000000031,33.093756959682885,-0.26054134762325476,-0.03512969177831149
271.0000000000031,33.170554610992596,-0.2590469582335514,-0.036448672860732945
271.80000000000314,33.24645102765416,-0.2576886551055615,-0.03777009780069296
272.60000000000315,33.32278292941627,-0.25653793400697705,-0.03777073519777385
273.40000000000316,33.39842829765012,-0.25598954237138666,-0.04039451081587986
274.2000000000032,33.47474134604376,-0.2550075995799584,-0.04167169828524919
275.0000000000032,33.55139563271699,-0.25299844056902326,-0.04167315378911596
275.8000000000032,33.62728086841311,-0.2493661689286741,-0.041906329844159096
276.6000000000032,33.702828479197635,-0.24833308177311283,-0.044344568051740474
277.4000000000032,33.779523139036726,-0.24732477572120312,-0.04562526754321583
278.20000000000323,33.85499799223083,-0.24468335242239697,-0.046541211680346084
279.00000000000324,33.92832992962073,-0.24485383971315602,-0.04668725295424414
279.80000000000325,34.008300475788005,-0.2432960370239486,-0.04665015853407084
280.60000000000326,34.08411321480364,-0.2409555985788715,-0.046650156853639047
281.4000000000033,34.160736939135035,-0.2395854010797568,-0.048006588095678815
282.2000000000033,34.23679271342459,-0.2379351967784407,-0.048958032808195995
283.0000000000033,34.313401949821724,-0.2367060504561877,-0.05027960313722524
283.8000000000033,34.389559980710395,-0.23570503225903183,-0.048965376788900894
284.6000000000033,34.464791327545285,-0.23448699706269618,-0.04901519346630723
285.40000000000333,34.5411818835638,-0.23377073395057116,-0.051590080964325935
286.20000000000334,34.61743950258867,-0.23179010339848613,-0.051534086246453725
287.00000000000335,34.69512420671721,-0.23156441134657524,-0.05291001558657049
287.80000000000337,34.770808865735596,-0.2302171392027132,-0.05291659391474335
288.6000000000034,34.84908143380315,-0.2294701289694152,-0.05552181665188494
289.4000000000034,34.92428530651908,-0.22755476815464554,-0.05620824407731728
290.2000000000034,35.00149075779762,-0.2264547197546442,-0.056868586976866364
291.0000000000034,35.0772365651156,-0.22477156255056047,-0.056210138826067624
291.8000000000034,35.15378373553947,-0.22366007689816703,-0.05752728239902982
292.60000000000343,35.229145325684065,-0.2218172790903714,-0.05881295476417847
293.40000000000344,35.306091015370484,-0.22201687685118304,-0.06020533420600804
294.20000000000346,35.38317387833478,-0.22117611587854907,-0.061443497557041926
295.00000000000347,35.458496036892655,-0.21908674188319047,-0.06148015882725977
295.8000000000035,35.53605997420412,-0.21789656403241447,-0.06147990277698456
296.6000000000035,35.61278860566309,-0.21730982616756542,-0.06280220760411614
297.4000000000035,35.69031010463993,-0.21746903170715304,-0.06411026444109469
298.2000000000035,35.76627601659806,-0.21589648480527002,-0.06608873509784097
299.0000000000035,35.843136702494,-0.21264196662266788,-0.06605649172752015
299.80000000000354,35.919230217979674,-0.21331008187360595,-0.06741011154663168
300.60000000000355,35.99620050620645,-0.2111812165578795,-0.0674100760049785
301.40000000000356,36.073057964381505,-0.21109086115940967,-0.0674100746869124
302.20000000000357,36.14935656907131,-0.21078816035431486,-0.0674121884892247
303.0000000000036,36.2257767772253,-0.20920910256555153,-0.06919468401918483
303.8000000000036,36.30400471519968,-0.20712746212859123,-0.07061221580301691
304.6000000000036,36.37960283348198,-0.2062739829574449,-0.07067008554644927
305.4000000000036,36.456225755263986,-0.203818678325784,-0.07200982004165324
306.2000000000036,36.53260557442593,-0.2025321128026344,-0.07200982799976163
307.00000000000364,36.60981038340081,-0.20114867604345718,-0.07200982800062938
307.80000000000365,36.68668735710701,-0.20046137361959476,-0.07200998272019454
308.60000000000366,36.76354731060858,-0.19909374526526114,-0.07296695554394717
309.4000000000037,36.839695290244315,-0.19718800075803095,-0.0743218204547702
310.2000000000037,36.91635155434134,-0.19630464953969035,-0.07598321512711737
311.0000000000037,36.99302855675274,-0.19488672522369066,-0.07727278866772602
311.8000000000037,37.06990861948563,-0.19441325900830658,-0.07860031816092006
312.6000000000037,37.14618733928111,-0.1927473043662141,-0.07857599572239637
313.40000000000373,37.2231403907528,-0.1926400897025667,-0.07960241365236209
314.20000000000374,37.29930327303983,-0.19146539157003578,-0.08125102952063701
315.00000000000375,37.37642491568626,-0.18920368778317004,-0.08255679544050487
315.80000000000376,37.45409419499845,-0.18782624212631333,-0.08139881585079145
316.6000000000038,37.53082464258858,-0.18682091522292738,-0.08523173299222409
317.4000000000038,37.60809141075698,-0.18544713234022497,-0.0864960421661265
318.2000000000038,37.68248895636193,-0.1854131492454133,-0.0878274863285724
319.0000000000038,37.761368996821965,-0.18278264514901774,-0.08781981503168002
319.8000000000038,37.838815700753344,-0.18065107072473624,-0.08778909724559991
320.60000000000383,37.91463820559438,-0.1800815271226713,-0.0884346277426249
321.40000000000384,37.99218556236038,-0.17846886801726528,-0.09010738486809
322.20000000000385,38.068671624662976,-0.1763032600185437,-0.0901295743521855
323.00000000000387,38.14617635819509,-0.1751725521446136,-0.09177335215939042
323.8000000000039,38.22238045004329,-0.17364656436053189,-0.09274692261973394
324.6000000000039,38.29944318820841,-0.1722244969174307,-0.09309339656767834
325.4000000000039,38.37640847857193,-0.17126147882375248,-0.09438558395747121
326.2000000000039,38.45315996674054,-0.16901919126869921,-0.0970699785266107
327.0000000000039,38.53019686026519,-0.16643930948918215,-0.09837006887934141
327.80000000000393,38.608172555270244,-0.16478502219656455,-0.09954352486701223
328.60000000000394,38.684999006575524,-0.1636709572967506,-0.09879924325350542
329.40000000000396,38.7620520526946,-0.1604074275964493,-0.09968005049049955
330.20000000000397,38.83913277692244,-0.15961807962302724,-0.09968002080674365
331.000000000004,38.916502301293676,-0.15681939230751543,-0.10091065625047335
331.800000000004,38.99348224418334,-0.15449286490838568,-0.10431206336342891
332.600000000004,39.06835976919186,-0.15272956597063267,-0.10626883329758519
333.400000000004,39.14752702429295,-0.15001284917398303,-0.10758319077856271
334.200000000004,39.224651046966066,-0.147113363440348,-0.10882516073113369
335.00000000000404,39.3018950886324,-0.14502293397452548,-0.10971475627142668
335.80000000000405,39.378576287765036,-0.141309140240844,-0.11014091692683214
336.60000000000406,39.45533777386942,-0.13874387214639092,-0.11213030550137804
337.40000000000407,39.532981257085034,-0.13655961159607707,-0.11445600268162881
338.2000000000041,39.60952164479542,-0.13273134349819224,-0.11723292914375749
339.0000000000041,39.687781319260125,-0.13128236346444538,-0.118492412874319
339.8000000000041,39.76476776754962,-0.12973642643741992,-0.12117280338362946
340.6000000000041,39.84208566601592,-0.12547046387417862,-0.1233511682126256
341.4000000000041,39.9185085080705,-0.1225680049104662,-0.12514437644528176
342.20000000000414,39.995854876910116,-0.12041137207570801,-0.1264715452334757
343.00000000000415,40.073713277595374,-0.1174733638422734,-0.12797128951889736
343.80000000000416,40.15076853762942,-0.11377193628705963,-0.13245562439413927
344.6000000000042,40.227248077728824,-0.10792622560702955,-0.13438024719954988
345.4000000000042,40.30533184619329,-0.10647306565162461,-0.13656071209010578
346.2000000000042,40.382497410026225,-0.10235279189440083,-0.1394251785802143
347.0000000000042,40.459049165775355,-0.10056683827028516,-0.14186921233699135
347.8000000000042,40.53736444301651,-0.09661523559581783,-0.14227298263873367
348.60000000000423,40.614035111525666,-0.0938171700706853,-0.1435909827041315
349.40000000000424,40.691852950071805,-0.08892127870216829,-0.14556457695468739
350.20000000000425,40.769131736304494,-0.08636637362323839,-0.14714267482538057
351.00000000000426,40.84683743657293,-0.08324586676062859,-0.15109265849719344
351.8000000000043,40.92384262075366,-0.07761454524026569,-0.15376282012234732
352.6000000000043,41.00173798220752,-0.07269626339696243,-0.15710452177171375
353.4000000000043,41.07829082764447,-0.0704844759274605,-0.15829980393873821
354.2000000000043,41.15530187007237,-0.065270535026515,-0.1597363711655797
355.0000000000043,41.23387713665816,-0.06042950762826379,-0.16536168406818064
355.80000000000433,41.310703480241315,-0.05446562611442057,-0.1685707274613577
356.60000000000434,41.38873987320919,-0.04834267002099822,-0.17157167446155075
357.40000000000435,41.46579067054745,-0.04163583241957749,-0.17615700420117975
358.20000000000437,41.543019934733636,-0.03809000374117055,-0.17876536234720497
359.0000000000044,41.62109824602846,-0.028856512755669656,-0.1815105608962435
359.8000000000044,41.69891314172381,-0.02451551831678953,-0.184534101634247
360.6000000000044,41.775641758077825,-0.018797508418876244,-0.18897063862950425
361.4000000000044,41.852826772626045,-0.011308014784988584,-0.19461129463332227
362.2000000000044,41.931238498958756,-0.0045311661794403,-0.20182256024869627
363.00000000000443,42.00864026258968,0.004364175173800627,-0.2054488829488168
363.80000000000445,42.08538163600011,0.012249899924186057,-0.2090777911352073
364.60000000000446,42.16362802513604,0.020312144045472998,-0.2173649496439367
365.40000000000447,42.24033111231759,0.030007345117294186,-0.22001378225534918
366.2000000000045,42.318726528201395,0.038558955912542534,-0.22447379619961705
367.0000000000045,42.39587862556695,0.04705925643472664,-0.22991198914518574
367.8000000000045,42.47300092414801,0.05762159644699153,-0.23462559338768507
368.6000000000045,42.55009973688036,0.06867669977179663,-0.24141882187628205
369.4000000000045,42.6287742345326,0.07861937004710398,-0.2485554054861554
370.20000000000454,42.705745737172094,0.08914166464199086,-0.2549922015122945
371.00000000000455,42.7838536598594,0.1024018690715451,-0.2622977334092482
371.80000000000456,42.86186694697769,0.11516214805651354,-0.26971552736414495
372.60000000000457,42.936458511234896,0.12667943697700704,-0.27660686610753293
373.4000000000046,43.01712172004735,0.14177527230843792,-0.2844087100589565
374.2000000000046,43.094848625414244,0.15505989171651494,-0.29159401070886215
375.0000000000046,43.172143124006084,0.17017948911595393,-0.3002547944861642
375.8000000000046,43.25026245966778,0.18812704944277217,-0.31050476972742347
376.6000000000046,43.326050442222986,0.20407660089218332,-0.3207542828724348
377.40000000000464,43.40568815291955,0.2237839912918948,-0.32930391246594093
378.20000000000465,43.48396224432282,0.24284865894226002,-0.34062384862555195
379.00000000000466,43.56129686665388,0.26123407074069777,-0.3501191797231784
379.8000000000047,43.63903714446832,0.28208134043285654,-0.3611070774239695
380.6000000000047,43.717344864800424,0.30591251432030847,-0.3748354217471124
381.4000000000047,43.79471235305494,0.32732907426540087,-0.38782041024265457
382.2000000000047,43.87267675993406,0.3507705238863903,-0.40133375893325596
383.0000000000047,43.95077363822194,0.37795360578040504,-0.4154232575096328
383.80000000000473,44.02812951575264,0.40363528918536695,-0.426367994959846
384.60000000000474,44.10588240075247,0.43172057355391236,-0.4407906247727844
385.40000000000475,44.18391939498527,0.4629590322639108,-0.4557644639564007
386.20000000000476,44.26224501844288,0.4957499930661464,-0.4717288225666523
387.0000000000048,44.3382232885644,0.52662245453251,-0.4925275706620118
387.8000000000048,44.41694627607458,0.5642333770813253,-0.5099285016326949
388.6000000000048,44.494576134668755,0.6007424777285437,-0.5303010055303901
389.4000000000048,44.57355841506508,0.6393012670325048,-0.5534779720988006
390.2000000000048,44.651456396090936,0.6810987088456092,-0.5748554485054229
391.00000000000483,44.7291633456704,0.7248989538318941,-0.5984435233089425
391.80000000000484,44.80796412266479,0.7708720695827173,-0.6226561513853168
392.60000000000485,44.88629325969858,0.8181154022469084,-0.6449120079039763
393.40000000000487,44.964766148607126,0.8686681478130405,-0.6718707188993625
394.2000000000049,45.04235352453261,0.9207727612472504,-0.7000659900986017
395.0000000000049,45.121412044215504,0.974964469039538,-0.7288376670059815
395.8000000000049,45.19940689939903,1.031551859023658,-0.7583794574507832
396.6000000000049,45.27732282875233,1.0885398135526219,-0.7892879676027076
397.4000000000049,45.356362090159394,1.1507679064370369,-0.8236783969197776
398.20000000000493,45.434365536881096,1.2131412346332229,-0.8597322011049822
399.00000000000495,45.513014212568905,1.2772989867360949,-0.8956702920837016
399.80000000000496,45.59157222997576,1.346561541058261,-0.9348611151190283
400.60000000000497,45.67053496949403,1.4146073155765775,-0.9774029391842438
401.400000000005,45.74915122175842,1.4882967919611008,-1.0199544857797105
402.200000000005,45.827450259331236,1.5593920293072234,-1.0640416951819067
403.000000000005,45.90580312623711,1.631666935722587,-1.1110136589914403
403.800000000005,45.98416542260338,1.704492097523061,-1.1597513863364255
404.600000000005,46.062164957512834,1.7854941665551767,-1.2123632425274806
405.40000000000504,46.14154455952977,1.8805997829073524,-1.2639653856671118
406.20000000000505,46.219405990575424,1.9625140651517397,-1.3198015210035843
407.00000000000506,46.29878155133253,2.0210730052639736,-1.3778366378650362
407.80000000000507,46.37700786294605,2.0804209494867107,-1.4349459885209113
408.6000000000051,46.455750507786625,2.151936433822017,-1.4932554964209568
409.4000000000051,46.533973530539534,2.235204148521237,-1.5550537291805346
410.2000000000051,46.612640966357255,2.3147246396968426,-1.6183744056456768
411.0000000000051,46.69000000000057,2.396090000000587,-1.6848432386631456
411.8000000000051,46.77000102506878,2.464920844589238,-1.7551009932524448
412.60000000000514,46.848369693897,2.52818924606439,-1.8270301999256886
413.40000000000515,46.92714069687168,2.5851146825158775,-1.8993450754191357
414.20000000000516,47.00615305156781,2.641546308978475,-1.9784423725944138
415.0000000000052,47.083609933965285,2.679326451319881,-2.053892832599035
415.8000000000052,47.16235834300594,2.7156198885934066,-2.1295435601416166
416.6000000000052,47.241354036538056,2.7397463197525913,-2.2099700906918955
417.4000000000052,47.31932844289431,2.764414702255219,-2.288768550362417
418.2000000000052,47.39862588979539,2.7709658341477925,-2.3713490338044703
419.00000000000523,47.4763211658815,2.763412344435371,-2.450822521752402
419.80000000000524,47.55493425678888,2.7487334703737636,-2.5312739447547785
420.60000000000525,47.630113244277105,2.7180618568804444,-2.6098579853035995
421.40000000000526,47.71170916280519,2.6768338204107156,-2.695199518352828
422.2000000000053,47.78935699568186,2.621130050888173,-2.7712908447552564
423.0000000000053,47.86735426112833,2.550019926943005,-2.8459038165448334
423.8000000000053,47.945598025056796,2.4659354500261568,-2.921634084342751
424.6000000000053,48.02277579782118,2.3714269841543487,-2.9959966549116084
425.4000000000053,48.100001012264364,2.269328586203458,-3.0680011556676137
426.20000000000533,48.17896775773355,2.149645237029424,-3.1354660323789756
427.00000000000534,48.25636992546307,2.02326653352427,-3.20008269502053
427.80000000000535,48.333689504278084,1.8900224912385855,-3.2613761419204748
428.60000000000537,48.41099722149192,1.755798540178943,-3.318924415523769
429.4000000000054,48.488484588715195,1.6101891032693352,-3.3755432437597754
430.2000000000054,48.56585983088205,1.4622021178626063,-3.4293623320364155
431.0000000000054,48.641565496748534,1.3155982709953828,-3.47271894624111
431.8000000000054,48.71909470460142,1.1717967311087758,-3.517911224084831
432.6000000000054,48.79682505385626,1.0339536999714962,-3.556685402472084
433.40000000000543,48.873160282636306,0.9034025684367126,-3.593940499173628
434.20000000000545,48.9501975388323,0.7776598405326568,-3.6274075776256383
435.00000000000546,49.0270875712262,0.6577997000892649,-3.6580121137287014
435.80000000000547,49.104843072204034,0.545220186662749,-3.686664824000083
436.6000000000055,49.17937496594351,0.4459916096647708,-3.7120175840560146
437.4000000000055,49.2591943617974,0.3490350627998671,-3.734231355763268
438.2000000000055,49.33725808157422,0.2605682890899105,-3.7555538110543134
439.0000000000055,49.413988488761916,0.18238771114701877,-3.772497753859202
439.8000000000055,49.491808457584916,0.113394019556066,-3.789803979118896
440.60000000000554,49.568832617596,0.05049834092554128,-3.8045114390170047
441.40000000000555,49.64669084338962,-0.010364270233653302,-3.8175384127434158
442.20000000000556,49.72373551549256,-0.0584999207407938,-3.830406297787338
443.00000000000557,49.80236811594741,-0.10529583574220554,-3.8432303661859613
443.8000000000056,49.88106772152305,-0.146620930305894,-3.852150913761521
444.6000000000056,49.958156618279574,-0.18145816137001208,-3.860687147760055
445.4000000000056,50.03594271340159,-0.21390467749016037,-3.868580941332521
446.2000000000056,50.11396674314081,-0.24191545330967318,-3.875349575184349
447.0000000000056,50.19261106905926,-0.26791287099349875,-3.8825959800977756
447.80000000000564,50.27036308328331,-0.28719361082383066,-3.88964000832457
448.60000000000565,50.3480151939318,-0.3087128044403394,-3.894942788078377
449.40000000000566,50.423895209197795,-0.32552603608818453,-3.9006021610869546
450.2000000000057,50.50435750459215,-0.3416045082994507,-3.905651064504742
451.0000000000057,50.582646478688694,-0.35560068375575477,-3.9081032726504734
451.8000000000057,50.66099899891339,-0.3679172939068299,-3.912941942852121
452.6000000000057,50.73891450892743,-0.38113839545646566,-3.9156259908055824
453.4000000000057,50.81684767158997,-0.3901163178969013,-3.9197740447392153
454.20000000000573,50.89605489797337,-0.3997598733166552,-3.922955462212915
455.00000000000574,50.97371737195989,-0.40685765778718463,-3.92570751428786
455.80000000000575,51.052307648222076,-0.4177467885015071,-3.927931149357728
456.60000000000576,51.13048106343522,-0.4218339564489571,-3.930650525072671
457.4000000000058,51.208645331365254,-0.4276254087837268,-3.9306808873835872
458.2000000000058,51.287260725441946,-0.4334633353840035,-3.932058218552246
459.0000000000058,51.36601587499804,-0.43718975375116037,-3.9342633722329388
459.8000000000058,51.44332129520958,-0.4422516264340577,-3.9361241779087788
460.6000000000058,51.5232847420756,-0.44805769245064175,-3.9401242329055752
461.40000000000583,51.60071135260511,-0.45414441087930163,-3.9400500351580465
462.20000000000584,51.67871298079465,-0.45957592369614203,-3.9408734425229546
463.00000000000585,51.75695538585509,-0.46508626234858264,-3.943299230327715
463.80000000000587,51.835412953030676,-0.47370354714436386,-3.943629777106322
464.6000000000059,51.913570080074514,-0.48089749094700684,-3.944955988047272
465.4000000000059,51.9929930910554,-0.48655405322544276,-3.9436298033631756
466.2000000000059,52.06865223660973,-0.48900423231710166,-3.943629786192993
467.0000000000059,52.14933741764736,-0.49103312794398685,-3.94297392456793
467.8000000000059,52.22795113844818,-0.49198445978678035,-3.9442733356117192
468.60000000000593,52.30610693115751,-0.49019587744566945,-3.9436301527763415
469.40000000000595,52.384619649823875,-0.4892633118543951,-3.943630066003162
470.20000000000596,52.46235117768167,-0.4868554248608493,-3.943630071793824
471.00000000000597,52.541381555044374,-0.4862188409562204,-3.9436300390845633
471.800000000006,52.619784150954835,-0.4852272271240228,-3.9436180007078283
472.600000000006,52.698325011126485,-0.4862379542369264,-3.9450100781039588
473.400000000006,52.777104400623614,-0.48611573301567107,-3.9454071068412997
474.200000000006,52.85536879341051,-0.48741038304262324,-3.94538006618842
475.000000000006,52.9336342273119,-0.4873416142977337,-3.945504076930646
475.80000000000604,53.0122514756988,-0.48854280872343114,-3.945379646773665
476.60000000000605,53.09090619864406,-0.48919924793737857,-3.9453798975920624
477.40000000000606,53.16926172170923,-0.4912038764345891,-3.9453907096372594
478.20000000000607,53.24846829948092,-0.49066968148303536,-3.946695903691584
479.0000000000061,53.326318244736406,-0.4928277448973864,-3.9478172959019324
479.8000000000061,53.405223276423115,-0.49404972391985646,-3.9469890675500583
480.6000000000061,53.484872638746886,-0.49505737759047075,-3.9466872468859293
481.4000000000061,53.562228398360205,-0.49523264018543556,-3.944117908196195
482.2000000000061,53.64235096553356,-0.4955703772981228,-3.946683387891483
483.00000000000614,53.71917085984604,-0.49865892984196264,-3.946695237411925
483.80000000000615,53.79901063107789,-0.4990609851477714,-3.9453798433974026
484.60000000000616,53.87551111484497,-0.4989116660217993,-3.946970302545583
485.4000000000062,53.95571815024291,-0.497691202954074,-3.9483622840648414
486.2000000000062,54.03473709543062,-0.49792386771780567,-3.94603122491069
487.0000000000062,54.11366273480994,-0.49986083755232724,-3.9457100691983604
487.8000000000062,54.193003311952175,-0.5000043084080704,-3.9445172214158775
488.6000000000062,54.27169033251615,-0.49896690085655127,-3.94439899559658
489.40000000000623,54.349704663803465,-0.4986256510888244,-3.945710006042106
490.20000000000624,54.42952525845353,-0.4982769169817164,-3.9457100060001444
491.00000000000625,54.50787090792683,-0.49853683650084435,-3.9457100219273435
491.80000000000626,54.587208475169724,-0.49826214384097234,-3.9445182921156934
492.6000000000063,54.66536273972841,-0.4991517466932778,-3.94438984122932
493.4000000000063,54.744419161360526,-0.49952349713887373,-3.944103415342523
494.2000000000063,54.82362684834965,-0.4993334918772718,-3.944386077081244
495.0000000000063,54.8997769899452,-0.49721469216965797,-3.946054700163624
495.8000000000063,54.98082789641658,-0.4981426758709213,-3.9467001778292334
496.60000000000633,55.060675550018495,-0.499676874842603,-3.946700547077057
497.40000000000634,55.13929568392652,-0.49820074446458384,-3.945379524977323
498.20000000000636,55.218224017109186,-0.4981992626083267,-3.946673049561962
499.00000000000637,55.29840761310589,-0.49874338142241037,-3.9495330650577567
499.8000000000064,55.37658511458059,-0.49699277348391335,-3.9469849150386285
500.6000000000064,55.455781857147336,-0.4961917119116847,-3.9457278831621525
501.4000000000064,55.533792528258566,-0.49636718414227765,-3.9457100771549816
502.2000000000064,55.61355501106263,-0.4971097685634858,-3.946981377236162
503.0000000000064,55.69333280060777,-0.4977478821884202,-3.9448417866563417
503.80000000000643,55.77239157090916,-0.49502170134261947,-3.9443886448069185
504.60000000000645,55.852460830717945,-0.49625113221912115,-3.946103471491715
505.40000000000646,55.931431963270526,-0.49367740354042466,-3.9466997794672665
506.20000000000647,56.011144908263695,-0.4942140015027287,-3.946717526025442
507.0000000000065,56.090733830172354,-0.4945647683572031,-3.946367819889603
507.8000000000065,56.17072220782226,-0.49396916371669075,-3.94767196178894
508.6000000000065,56.24858605734564,-0.4945651214479184,-3.945088976816452
509.4000000000065,56.33163046277589,-0.4931225910407444,-3.9463761999044964
510.2000000000065,56.41050488226662,-0.49390723406608905,-3.947680181690669
511.00000000000654,56.489281023316934,-0.49159717665521185,-3.9476801559988655
511.80000000000655,56.56960646299661,-0.49172444067231313,-3.9476801560142434
512.6000000000065,56.64958449274606,-0.4922472896735318,-3.9476806727980156
513.4000000000066,56.727707676818746,-0.49215813521363116,-3.9464716209397213
514.2000000000066,56.80777642653629,-0.4914681541771106,-3.9463699429197434
515.0000000000066,56.88719224787362,-0.49314428812015415,-3.946387133473793
515.8000000000065,56.966288902839224,-0.4909272917432414,-3.9453799120148814
516.6000000000066,57.04659295938462,-0.4913177275224953,-3.9466753539453694
517.4000000000067,57.12645587826276,-0.49004740664235313,-3.948008613827045
518.2000000000066,57.2040853388982,-0.49122001358137246,-3.9468197073010187
519.0000000000066,57.28506492996441,-0.49079130514848807,-3.9453898892048214
519.8000000000067,57.364046473614714,-0.4901536150322862,-3.9453898824243616
520.6000000000067,57.44394717525206,-0.48787908812692693,-3.945426083385745
521.4000000000067,57.52159943413226,-0.4876968119194992,-3.946773722680627
522.2000000000066,57.60277508319191,-0.487130885954603,-3.9460400719809985
523.0000000000067,57.6818643785042,-0.48682988119560827,-3.946040097969359
523.8000000000068,57.76121461664512,-0.48680897922498206,-3.9460394649338975
524.6000000000067,57.84108460647855,-0.4853211035764301,-3.946700403365267
525.4000000000067,57.92031635456608,-0.4862376285105146,-3.9466998876034545
526.2000000000068,57.99999902314387,-0.4845499999131521,-3.945380096192597
527.0000000000068,58.07989377809257,-0.48446230889595476,-3.9453800961392145
527.8000000000068,58.159276817224814,-0.4829291053973223,-3.946355718140562
528.6000000000067,58.239063392707294,-0.4824538964970415,-3.9463696193946722
529.4000000000068,58.318984974942886,-0.48001994098376694,-3.946377394681556
530.2000000000069,58.39828218824176,-0.48177532449590765,-3.946369868258014
531.0000000000068,58.479031572322825,-0.4809594384844016,-3.946424805671998
531.8000000000068,58.559292962494055,-0.4811787150398961,-3.9450498007378174
532.6000000000068,58.638727799769185,-0.48284030284908946,-3.947043724030563
533.4000000000069,58.71898199808751,-0.48150615680829484,-3.947031541131248
534.2000000000069,58.79971251452816,-0.48067632941666183,-3.9476883540049803
535.0000000000068,58.87899796549989,-0.4804129176464087,-3.9476900319625616
535.8000000000069,58.95870027705164,-0.48051048364383225,-3.947689991681503
536.600000000007,59.03770630556119,-0.4812362114603974,-3.94867124720269
537.4000000000069,59.118951452931476,-0.4792191301806538,-3.9483497133385694
538.2000000000069,59.19824033729661,-0.47958005148813615,-3.9460534892531625
539.0000000000069,59.27869769645593,-0.4787934260088045,-3.946040016215425
539.800000000007,59.358038653683906,-0.4781474885008882,-3.944717006538344
540.600000000007,59.437403510930224,-0.4763456731560344,-3.9460427559907867
541.4000000000069,59.51767102463007,-0.4774304950638239,-3.946040090051269
542.200000000007,59.59788871214024,-0.47580896660310995,-3.946039827900358
543.000000000007,59.67716020779261,-0.4747318040046716,-3.948659232502274
543.800000000007,59.75793524105893,-0.47242197811753867,-3.9487922754987643
544.600000000007,59.83651897878458,-0.47331908223394376,-3.950727008189545
545.400000000007,59.91680393680453,-0.47214172168366614,-3.9494694762626334
546.000000000007,59.976840798350366,-0.4729469920879877,-3.9494999184499973