File: 01_Data/XPS_Foam_Board/STA/N2/10K_min/XPS_Foam_Board_STA_N2_10KData_221018_R3.csv
##Temp./Â°C,Time/min,DSC/(mW/mg),Mass loss/mg
51.0,10.71,-1.62926,0.012862270518397168
51.80000000000001,11.024363807768951,-1.5329997294912556,0.012335722331920707
52.60000000000002,11.233337691308467,-1.4692158143160166,0.012741556134268528
53.400000000000034,11.405477922267114,-1.4172618747796881,0.012110833973088653
54.200000000000045,11.550201157779783,-1.3764048741617152,0.012146006024186917
55.00000000000006,11.691857980234825,-1.3406528396345163,0.01381888404038989
55.80000000000007,11.823026386610152,-1.3112925912445228,0.014067442463456814
56.60000000000008,11.948517721058476,-1.2870068693365284,0.014034316094339694
57.40000000000009,12.064351056082929,-1.2651695260800089,0.016939166284005935
58.2000000000001,12.17924834811473,-1.2466665986137473,0.012645849120651143
59.000000000000114,12.291879659972711,-1.2301052843914204,0.013792517890656164
59.800000000000125,12.400000000000016,-1.2157799999999972,0.014176656182997682
60.600000000000136,12.505543237911615,-1.201794863377949,0.014568501607797657
61.40000000000015,12.609575349912387,-1.1892916721411273,0.013930458174321814
62.20000000000016,12.715189880304123,-1.1778120983701956,0.015217251341129057
63.00000000000017,12.816944211296718,-1.1672690858361048,0.015274563626385351
63.80000000000018,12.917582938848444,-1.156653005560956,0.016543031379939066
64.6000000000002,13.01587118811531,-1.1474586426311382,0.01618419713522723
65.4000000000002,13.114433073673421,-1.1380765638871801,0.015097560466941218
66.20000000000022,13.211244868125933,-1.1305954522506332,0.01510604347953226
67.00000000000023,13.306742959653938,-1.1189628603986723,0.015119294140217399
67.80000000000024,13.401776621284302,-1.1104391354439724,0.015033446346191859
68.60000000000025,13.495192858611187,-1.1014470938041623,0.015638959644872052
69.40000000000026,13.590652437988572,-1.0943340764847418,0.01523315550198756
70.20000000000027,13.682868692654509,-1.0871062291315172,0.015122571006290997
71.00000000000028,13.775670598747872,-1.0791979327590804,0.016468659642936423
71.8000000000003,13.86497589710044,-1.0719352506090172,0.016480132543499337
72.6000000000003,13.956436358314843,-1.0627998341930884,0.01650561332490952
73.40000000000032,14.045598897244933,-1.0571831980226385,0.016442411967521053
74.20000000000033,14.136486337515707,-1.0503122808436853,0.015347123132308127
75.00000000000034,14.225196130715144,-1.042899051068835,0.015637546213556064
75.80000000000035,14.314305252367433,-1.036597532147652,0.017115872577956104
76.60000000000036,14.402767924227122,-1.0305058320839158,0.016466277797870355
77.40000000000038,14.49062974164503,-1.0211070636714468,0.01511884760029858
78.20000000000039,14.578409025019633,-1.0151139067105541,0.015143725753216764
79.0000000000004,14.665618062091127,-1.0068603960352784,0.013738888743461075
79.80000000000041,14.75271821758636,-0.9985284167156092,0.013723871799974141
80.60000000000042,14.836987196745403,-0.9932081130733332,0.01361086428711733
81.40000000000043,14.924391125232889,-0.9864512037132924,0.015201883728326315
82.20000000000044,15.008401830704562,-0.9783494061663444,0.015049144963744432
83.00000000000045,15.094372846508405,-0.9725944030804372,0.014972503133860116
83.80000000000047,15.177494290015389,-0.9665379975562985,0.017553065450003125
84.60000000000048,15.262632502820802,-0.9609742978097641,0.016317461629637542
85.40000000000049,15.347126842363863,-0.9599661040707592,0.017641451638039207
86.2000000000005,15.429781797919757,-0.9582702687592899,0.015011477610650914
87.00000000000051,15.51311565957507,-0.9576654533515803,0.01569922770441501
87.80000000000052,15.596583423381324,-0.9580814038892778,0.014709930106633351
88.60000000000053,15.676947420004383,-0.9570829642386103,0.01628550966996567
89.40000000000055,15.761613537387003,-0.9551709913109316,0.01701788676073157
90.20000000000056,15.843357766691504,-0.9511279061272448,0.016341501362984623
91.00000000000057,15.925286987859971,-0.9465689757800494,0.016323968312991433
91.80000000000058,16.006283871857388,-0.9428251185543879,0.0160340535545771
92.60000000000059,16.087719348780585,-0.9374296566833067,0.016736596919749047
93.4000000000006,16.168804971389573,-0.9322351292335321,0.017599937726849646
94.20000000000061,16.250679316949878,-0.9264268732205126,0.016738941895601656
95.00000000000063,16.331222019907138,-0.9197238291399004,0.016728771506713258
95.80000000000064,16.410783593422785,-0.9143549449220147,0.016348522350906336
96.60000000000065,16.491516881252895,-0.9075503992453817,0.015042780708041548
97.40000000000066,16.571922698828665,-0.9009371204712375,0.016032076944197726
98.20000000000067,16.651668098636446,-0.8931923320926226,0.015027813759132869
99.00000000000068,16.731820931728567,-0.8870577953087232,0.016402890639096057
99.8000000000007,16.81134264740343,-0.8778725349396267,0.016352583757281103
100.6000000000007,16.89110455473595,-0.8705422851122883,0.016210870075040518
101.40000000000072,16.970742152836984,-0.8616696073478716,0.016343000624173598
102.20000000000073,17.048113575988847,-0.8532709449746103,0.01634352592708055
103.00000000000074,17.129112915694634,-0.84387380083655,0.017562013090421047
103.80000000000075,17.20852752801021,-0.8333196068472677,0.016299964515806842
104.60000000000076,17.28679493111883,-0.8261874255899236,0.01502708232331873
105.40000000000077,17.367101871914276,-0.8186292240418707,0.01605702621861127
106.20000000000078,17.441296147011357,-0.8139879757620445,0.01633234055953725
107.0000000000008,17.523884781943472,-0.8089771916937097,0.018973295311226934
107.80000000000081,17.60205690042546,-0.8063339001513231,0.018975406678486628
108.60000000000082,17.682242112130094,-0.802502137617418,0.01709018781015459
109.40000000000083,17.760769463850764,-0.8007512503832881,0.01766894192875057
110.20000000000084,17.838681757622403,-0.7970458196306307,0.016346955128801355
111.00000000000085,17.915424318219507,-0.794058565794093,0.016321134402907056
111.80000000000086,17.99643201635604,-0.7914235601087135,0.015030089965579307
112.60000000000088,18.071694752634773,-0.7891464542734007,0.013749073610738627
113.40000000000089,18.152868016689265,-0.7873027101017511,0.016329130193718733
114.2000000000009,18.230703766587286,-0.7843833047205306,0.01635297554023296
115.00000000000091,18.31040817982113,-0.7804395099316006,0.01636388033793601
115.80000000000092,18.384854393901858,-0.7775909674675883,0.018359946161558227
116.60000000000093,18.46545666369589,-0.7739099570797024,0.015575890623506616
117.40000000000094,18.54506866342613,-0.7705544780797898,0.015654595825487228
118.20000000000095,18.621998871286458,-0.7689191003666839,0.016899368471923637
119.00000000000097,18.699816781686494,-0.7655290268867643,0.016716237149229762
119.80000000000098,18.777028274767705,-0.7637582191982571,0.016900134806663303
120.60000000000099,18.856184391519868,-0.7599098502648564,0.0175036082454616
121.400000000001,18.932412014981857,-0.7583599177143585,0.018281762381875843
122.20000000000101,19.011686342042413,-0.7550040466166668,0.016703411960687475
123.00000000000102,19.08854674558715,-0.7511202104741744,0.018326586100736897
123.80000000000103,19.166737701503635,-0.7515249779434273,0.019639080186538038
124.60000000000105,19.244044106567912,-0.7490418881462783,0.01832016808707415
125.40000000000106,19.321007261611328,-0.744539330862117,0.01695725667743453
126.20000000000107,19.398438452636903,-0.7422429509040049,0.017009694585646606
127.00000000000108,19.476115820380645,-0.7395134270642486,0.018323646239201352
127.80000000000109,19.55366806670769,-0.7381817112441825,0.017036096527801803
128.6000000000011,19.63189335446815,-0.7359032072340622,0.016994625464548996
129.4000000000011,19.707815264576364,-0.7322315127255017,0.015865132430078255
130.20000000000113,19.78487056319432,-0.7301147820331768,0.017010053035730444
131.00000000000114,19.862331142215446,-0.7284073158557015,0.01710564000409409
131.80000000000115,19.93959115158024,-0.7262011292346241,0.015690035230351285
132.60000000000116,20.01640838155794,-0.7239615740271772,0.015689528494309712
133.40000000000117,20.09347080573583,-0.7221152312019545,0.01520755705256338
134.20000000000118,20.170715951737932,-0.7200226624580477,0.015405024212694407
135.0000000000012,20.24807922367914,-0.716430769979338,0.01507669179293547
135.8000000000012,20.32482627161819,-0.7138696938217814,0.0156898860648802
136.60000000000122,20.401016306583287,-0.7108560109011841,0.01426950046345965
137.40000000000123,20.47837304087058,-0.7066831689456445,0.012949502824096903
138.20000000000124,20.554609490496137,-0.7053882525314956,0.014260337452435934
139.00000000000125,20.630918426932556,-0.7007208294471975,0.01532530017849787
139.80000000000126,20.70749565981762,-0.6983788266643431,0.017039297427828615
140.60000000000127,20.784697928576552,-0.694335046624306,0.015661770746006276
141.40000000000128,20.860480009477143,-0.6923325188427093,0.015723160313941165
142.2000000000013,20.93695979036912,-0.6895856139880032,0.015369836913792234
143.0000000000013,21.011221419735893,-0.6860688471648696,0.015370058592676372
143.80000000000132,21.089443418990964,-0.6828956199042475,0.014381178248041415
144.60000000000133,21.16578723902882,-0.6795838817621668,0.014445881435400487
145.40000000000134,21.242625058878993,-0.6780931779454616,0.014366023105585768
146.20000000000135,21.319427820060675,-0.6738158543040977,0.015690300962332593
147.00000000000136,21.39535539042859,-0.6727645944716076,0.01438551079398298
147.80000000000138,21.471100593819713,-0.6693491811154516,0.014360560929317145
148.6000000000014,21.547401714170505,-0.6659017761433322,0.015696725794303035
149.4000000000014,21.6248125784379,-0.6635972556925457,0.014699662926041412
150.2000000000014,21.699725962911316,-0.6619088700471448,0.013585958244291874
151.00000000000142,21.77700053970367,-0.6588760443439869,0.013382321489342708
151.80000000000143,21.851482027929215,-0.6557596326842585,0.014685268003960417
152.60000000000144,21.92826698314075,-0.6539117389749216,0.016020260275099396
153.40000000000146,22.00392296846377,-0.651879679566462,0.014707979749238653
154.20000000000147,22.080196160337387,-0.6505588823938266,0.016020320202047245
155.00000000000148,22.15694555620478,-0.6475899965569417,0.01588475795377331
155.8000000000015,22.232447604680583,-0.6470953605777287,0.016655530000327268
156.6000000000015,22.30923260615666,-0.645111594652257,0.01727477513219533
157.4000000000015,22.384775378420255,-0.6437361563482381,0.01733869734530291
158.20000000000152,22.46141751747407,-0.6413677687167101,0.015377167400943748
159.00000000000153,22.537490825038436,-0.6411345102437844,0.015358900974931089
159.80000000000155,22.612671519010206,-0.6388567226854679,0.014700069747298983
160.60000000000156,22.690104213014703,-0.638752613489557,0.013347041807707072
161.40000000000157,22.765021667675132,-0.6372296075525903,0.013385021866251456
162.20000000000158,22.84110736299457,-0.6361742624132996,0.014702829595963252
163.0000000000016,22.916641248848947,-0.6358856286519122,0.01371986326774266
163.8000000000016,22.991028528282804,-0.6344854858893739,0.013725986873907026
164.60000000000161,23.068923668801478,-0.633777999565644,0.013900411688402059
165.40000000000163,23.145318895125083,-0.6324820829704553,0.015036453301745745
166.20000000000164,23.221073990608154,-0.6306164433685123,0.015029932058377327
167.00000000000165,23.296737897260403,-0.6308557613378282,0.015030638757897563
167.80000000000166,23.374070810082745,-0.6299184453614997,0.014368635654922635
168.60000000000167,23.449999078549446,-0.6282300288849612,0.01503016364210108
169.40000000000168,23.525180820356038,-0.6288412993486042,0.014198104637491049
170.2000000000017,23.602267048430253,-0.6279807873695435,0.012395633005910511
171.0000000000017,23.6774738715702,-0.6267267671375679,0.012399932290707127
171.80000000000172,23.75428833195393,-0.6247477746771293,0.012399777120114308
172.60000000000173,23.82948563320884,-0.6236982850146451,0.011076800455384728
173.40000000000174,23.906101174559033,-0.6229519734380569,0.01096812851111828
174.20000000000175,23.981466368731713,-0.6220130045343881,0.0110807063753251
175.00000000000176,24.057139842186864,-0.621449185363948,0.011099529593662005
175.80000000000177,24.134466199060036,-0.6200756743266292,0.012395325656065381
176.60000000000178,24.210398556939968,-0.6195654536160099,0.013061588502648824
177.4000000000018,24.28644960446882,-0.6183411581871422,0.013709999978233078
178.2000000000018,24.35910396627682,-0.6166346277361703,0.013710053999790084
179.00000000000182,24.43826335719624,-0.6148263807329007,0.013710016932686031
179.80000000000183,24.511685430678433,-0.613686411128159,0.01242117544782051
180.60000000000184,24.589802697935383,-0.6119255584190267,0.013719866473262066
181.40000000000185,24.665777648052,-0.6112212220804917,0.014383366474566728
182.20000000000186,24.74130594389325,-0.609687262267389,0.014380038257229444
183.00000000000188,24.816638212600747,-0.6093987514876896,0.013533805915120212
183.8000000000019,24.893014446925477,-0.6068901587409331,0.013062317457373851
184.6000000000019,24.968458854822828,-0.6040214733141588,0.011747316382154871
185.4000000000019,25.044355446819253,-0.6046870096895454,0.013071471258435885
186.20000000000192,25.12059918848188,-0.6024723477502855,0.01362880005280065
187.00000000000193,25.195937095233404,-0.6006966683397713,0.013059912524507666
187.80000000000194,25.272039113543027,-0.5984385613298959,0.01306037784469627
188.60000000000196,25.347470364544208,-0.5973133213937516,0.011742694426436273
189.40000000000197,25.423453719776543,-0.5948335576986039,0.01140963279426721
190.20000000000198,25.498845234682893,-0.5950361881264028,0.01144685965263914
191.000000000002,25.574639628033268,-0.5915925218009507,0.010097461109388917
191.800000000002,25.650545509790344,-0.5900093624069811,0.008779840470412914
192.600000000002,25.72661841879174,-0.5880025002407161,0.01014832422164158
193.40000000000202,25.801571529051465,-0.5877188687729251,0.011419976039887203
194.20000000000203,25.87867101736984,-0.5848913757991314,0.012729642169905908
195.00000000000205,25.953535422702103,-0.5843236162538759,0.012730087917526056
195.80000000000206,26.030742962312477,-0.5832469005152513,0.012769399518314017
196.60000000000207,26.105148186120942,-0.5821338902137514,0.014038447205247273
197.40000000000208,26.181316913562604,-0.5804602846888979,0.011410495413471722
198.2000000000021,26.256605062092586,-0.5771923123295463,0.010103852553299042
199.0000000000021,26.33240134508532,-0.5752584445902698,0.008834396424208357
199.80000000000211,26.408233990470862,-0.574483897137684,0.007463968134280741
200.60000000000213,26.48382808856454,-0.5733228210672179,0.006149632365612057
201.40000000000214,26.560174433709445,-0.5705925346901461,0.007459852625903096
202.20000000000215,26.635626357997552,-0.5684087534123263,0.0074604038766139524
203.00000000000216,26.71133965581193,-0.5675460281981094,0.008438169038320176
203.80000000000217,26.78490884514212,-0.5650510039231007,0.0084529225723875
204.60000000000218,26.862877415082064,-0.5646279735414356,0.008117745214861749
205.4000000000022,26.938794699765396,-0.5622446495650346,0.008119861814078533
206.2000000000022,27.015807531457536,-0.560558766336319,0.00811986200000181
207.00000000000222,27.090557558624415,-0.558144683995861,0.008119862000000033
207.80000000000223,27.16582530044264,-0.5579988830064625,0.008119861999999145
208.60000000000224,27.242408881195974,-0.5561761277971284,0.008119862000938838
209.40000000000225,27.317796524945862,-0.5543004355734482,0.008119896655103709
210.20000000000226,27.394322505073003,-0.5527428759594937,0.00679664309803929
211.00000000000227,27.470277803344857,-0.5517460576622725,0.005835358292843651
211.80000000000229,27.54589897602548,-0.5507667231123653,0.004819846829809293
212.6000000000023,27.62279172908565,-0.5488664699600849,0.004494416244268606
213.4000000000023,27.697795542654887,-0.5480098618691993,0.004484378164332448
214.20000000000232,27.77357375704595,-0.5459259416965498,0.005809799948806926
215.00000000000233,27.849901162932433,-0.5439137020986836,0.005809925001609706
215.80000000000234,27.926091369428196,-0.5436107868252612,0.005811009333852368
216.60000000000235,28.001523909461937,-0.5422762266890664,0.007233843385924921
217.40000000000236,28.077858104681333,-0.5391023081143382,0.005799204033061223
218.20000000000238,28.153954934699122,-0.537675365599105,0.004489612347037486
219.0000000000024,28.22919507161667,-0.5358574264776955,0.0044899250039218686
219.8000000000024,28.305093074369186,-0.5333714670591294,0.004489925000001449
220.6000000000024,28.381590960827488,-0.5327282924256198,0.004489924995723982
221.40000000000242,28.457090454234876,-0.5292052765543002,0.004489865144720717
222.20000000000243,28.533645075658317,-0.5280979792955225,0.003188163972301261
223.00000000000244,28.609722270014455,-0.5267121318656593,0.003125423836560337
223.80000000000246,28.685060294250647,-0.5257449130892923,0.001749917963670633
224.60000000000247,28.761629808264555,-0.5236391875693398,0.0017499258907340831
225.40000000000248,28.837307162577716,-0.5205882363889991,0.0017520805761268576
226.2000000000025,28.91253082767305,-0.5193335076791715,0.0017464836705922693
227.0000000000025,28.98962967116983,-0.5184798618145482,0.0004320946794527103
227.8000000000025,29.06471371579896,-0.5162193531017841,0.001156534176987023
228.60000000000252,29.141638921380835,-0.5155079102559341,0.0017499345252067755
229.40000000000254,29.216907627146803,-0.514640000557382,0.0017499250003352174
230.20000000000255,29.293146196466964,-0.5131865433815654,0.001749925000000374
231.00000000000256,29.368371041972278,-0.5118979710053447,0.001749925155309917
231.80000000000257,29.44561312910591,-0.5108465392774427,0.0017504916851267538
232.60000000000258,29.521519149297273,-0.5079197970158082,0.00043003118133100315
233.4000000000026,29.597253609673068,-0.5077783326660278,-0.0008764765553515019
234.2000000000026,29.67281792095302,-0.5055290218437895,-0.0008807716960728129
235.00000000000261,29.749538895091654,-0.5047628572712163,-0.0015405809689195138
235.80000000000263,29.825494795694183,-0.5043544154009826,-0.0016918463166719633
236.60000000000264,29.90135536680043,-0.504043316831869,-0.0021999325453840868
237.40000000000265,29.977368432312815,-0.5025077882406581,-0.00239641879339203
238.20000000000266,30.05306563391993,-0.5008765541260327,-0.0018658143456589116
239.00000000000267,30.129398338827265,-0.5008179319309952,-0.0022030486359216894
239.80000000000268,30.204995642811923,-0.4989259130284365,-0.002498051748341723
240.6000000000027,30.28136475056932,-0.49731223023964655,-0.004839923253468825
241.4000000000027,30.357326070476436,-0.4964831487064839,-0.00484027497789441
242.20000000000272,30.434317774264734,-0.49660878846473133,-0.005828868918944963
243.00000000000273,30.50884647994838,-0.4951712239703546,-0.0052394981929904105
243.80000000000274,30.586496458853937,-0.4934268579884885,-0.00385045486592972
244.60000000000275,30.662080662181225,-0.4937939769728757,-0.003846508084792255
245.40000000000276,30.73721930954693,-0.49278662812133484,-0.005169654837872351
246.20000000000277,30.814321218822652,-0.4915246189735999,-0.005970299857244399
247.00000000000279,30.890190486146928,-0.4908563819984488,-0.0075745821025856586
247.8000000000028,30.966047705151713,-0.4896588762300326,-0.007799896065074918
248.6000000000028,31.04011891371981,-0.48921154314999404,-0.00911941633838076
249.40000000000282,31.119336596523937,-0.4880171127762712,-0.007766966588938828
250.20000000000283,31.193879420439778,-0.48700771554972166,-0.008172239911489854
251.00000000000284,31.271282817608366,-0.48592705763032545,-0.008905831326257108
251.80000000000285,31.347296532602737,-0.4853045261545631,-0.009440010463945825
252.60000000000286,31.423894956993703,-0.4849643916811836,-0.010591267852120723
253.40000000000288,31.500000856304936,-0.48349989907095753,-0.01208014703496918
254.2000000000029,31.5761429703069,-0.48245742710249445,-0.010765594904516895
255.0000000000029,31.6519633535209,-0.48230682894347665,-0.00943989197851014
255.8000000000029,31.727631548678985,-0.4802214591038464,-0.010756736604131234
256.6000000000029,31.804109902578343,-0.4793902231100073,-0.012079803368694186
257.40000000000293,31.8809137425542,-0.47880145687911435,-0.01208231213781552
258.20000000000294,31.956354179005913,-0.47692667071595773,-0.013399924834815558
259.00000000000296,32.03265912659767,-0.4758747372098779,-0.013399850892851894
259.80000000000297,32.10859270920936,-0.47542971518854255,-0.013400963740434868
260.600000000003,32.184982451694886,-0.47471690579624926,-0.01472105012956959
261.400000000003,32.262103844170795,-0.472952700081844,-0.014720103018152741
262.200000000003,32.33841480817567,-0.47234440255143956,-0.014720227227846827
263.000000000003,32.414001106231275,-0.4721692380373744,-0.01701092758364986
263.800000000003,32.48990654452942,-0.4710688546050474,-0.0157093488290192
264.60000000000304,32.56654230908978,-0.4695315201739769,-0.015710101870475057
265.40000000000305,32.64290514445469,-0.46762996408635715,-0.015706283999402437
266.20000000000306,32.71838609500167,-0.467246562548465,-0.017030133958601645
267.00000000000307,32.79580989723613,-0.46611294060354996,-0.018318112558792343
267.8000000000031,32.87148654082859,-0.4644694574280135,-0.018550325965593473
268.6000000000031,32.94780741070926,-0.46457609052487825,-0.019990722190372345
269.4000000000031,33.02424105297888,-0.46373661280213613,-0.021299966050969843
270.2000000000031,33.09999906626027,-0.4631400263054671,-0.022620066982349307
271.0000000000031,33.17690112597575,-0.46201239766877095,-0.023191316598077272
271.80000000000314,33.25350819505846,-0.45980371716749074,-0.023940100522993113
272.60000000000315,33.329711635896885,-0.45840666420221665,-0.02487817046137142
273.40000000000316,33.40580839130405,-0.45731058160334587,-0.02492990248189919
274.2000000000032,33.481448670462946,-0.45673116068571695,-0.02492991094855146
275.0000000000032,33.55800020040357,-0.4559100715540935,-0.024931348702246225
275.8000000000032,33.63406942685638,-0.45345746332879605,-0.02624032353009831
276.6000000000032,33.71065230700646,-0.45312936900451334,-0.02758909184379199
277.4000000000032,33.78654980651019,-0.4515770291757457,-0.027652817188817735
278.20000000000323,33.86318470087321,-0.45118003333691775,-0.028880116239434983
279.00000000000324,33.939334089129034,-0.4498604579711129,-0.02751266304112754
279.80000000000325,34.015876211662146,-0.4489713183355153,-0.02763064667480819
280.60000000000326,34.09225247735878,-0.4467782178503753,-0.030385430316044015
281.4000000000033,34.16922299385365,-0.44623255896281033,-0.031786855930577396
282.2000000000033,34.244885245834645,-0.44514593440160277,-0.03283026871918704
283.0000000000033,34.32104535538812,-0.44402777628226137,-0.0341528739116681
283.8000000000033,34.39688517623714,-0.4423706120364074,-0.03547047236061207
284.6000000000033,34.47420567920515,-0.4417787625070038,-0.036789994283242144
285.40000000000333,34.55048060120922,-0.44213796388574456,-0.03547010763475544
286.20000000000334,34.626738732843634,-0.44123071306446104,-0.03580010390507038
287.00000000000335,34.70427979496998,-0.43966652692346214,-0.03823969871387245
287.80000000000337,34.77768802586202,-0.4404307948178301,-0.039094937864062373
288.6000000000034,34.85715056207971,-0.4384788533229937,-0.03908980821406072
289.4000000000034,34.93252261578223,-0.43830337590529456,-0.03916467835718507
290.2000000000034,35.00962857975253,-0.43545959139919094,-0.03942305230517018
291.0000000000034,35.08626850673134,-0.43522834208415484,-0.041616157520715014
291.8000000000034,35.162794988589255,-0.43285598006814985,-0.04149744265593913
292.60000000000343,35.24010042220477,-0.4324157139514138,-0.04206659864852469
293.40000000000344,35.31686592863811,-0.4312811105221676,-0.04336942464525961
294.20000000000346,35.393471516592506,-0.4292154097501362,-0.04468798846251598
295.00000000000347,35.46890547764427,-0.42914949763232646,-0.04600030884585937
295.8000000000035,35.54662363339244,-0.427759629025013,-0.04599984173330185
296.6000000000035,35.62190942297425,-0.42716786606431595,-0.047156819662321325
297.4000000000035,35.699549953655776,-0.42608768644527834,-0.04794087973695049
298.2000000000035,35.77581160812068,-0.42532581878302367,-0.048652054680508705
299.0000000000035,35.85171516339914,-0.4251488506032263,-0.04862261929067646
299.80000000000354,35.92928017074214,-0.42344265447697826,-0.04995002703617768
300.60000000000355,36.00446258673504,-0.42380981352569086,-0.05130989299853361
301.40000000000356,36.08106318427302,-0.42160134733380805,-0.05391204805772354
302.20000000000357,36.1582910239064,-0.4210523928618011,-0.05258309091202751
303.0000000000036,36.234687324904165,-0.42039456038772144,-0.052590347591274345
303.8000000000036,36.31083961237848,-0.4200590783063707,-0.05358167520283974
304.6000000000036,36.38734608914406,-0.41876346300076067,-0.05501807615962573
305.4000000000036,36.46419481395742,-0.4184258465246692,-0.05514150278234631
306.2000000000036,36.54095611576957,-0.4179218651237589,-0.055216425722623974
307.00000000000364,36.61803873450128,-0.41721404997047623,-0.057849601829849995
307.80000000000365,36.694361300340965,-0.41661825892150245,-0.05786017157770118
308.60000000000366,36.77075768703304,-0.414110927762006,-0.057861798515856044
309.4000000000037,36.847267392107625,-0.4126972397668925,-0.060522304684782036
310.2000000000037,36.92346198226832,-0.4114008918566758,-0.06318359843048516
311.0000000000037,37.00100262602939,-0.41122255221741555,-0.06312987693200434
311.8000000000037,37.07759365139261,-0.41079225972175204,-0.06283235691598499
312.6000000000037,37.15434177666952,-0.40930276648080677,-0.06313028774404561
313.40000000000373,37.229795017004044,-0.4076248801874583,-0.06313011318307638
314.20000000000374,37.30581416651458,-0.4068281972867723,-0.06438718704821511
315.00000000000375,37.38449738551555,-0.4051201167084242,-0.06569594342334995
315.80000000000376,37.46111405259821,-0.4037643213033525,-0.06778226031853407
316.6000000000038,37.535142957053765,-0.40345899452072526,-0.06773329152801733
317.4000000000038,37.61462217410041,-0.40199525697624106,-0.06905990302740328
318.2000000000038,37.691267458091545,-0.3997232912393273,-0.0703692526228572
319.0000000000038,37.76772166760741,-0.3988990659311909,-0.07310677013727851
319.8000000000038,37.844635285628094,-0.39819018807425005,-0.07247034126749785
320.60000000000383,37.9223226335964,-0.3955584130369972,-0.07425814953600085
321.40000000000384,37.998403962815445,-0.3952384502974122,-0.07381601234705304
322.20000000000385,38.075556272663164,-0.3942126656739269,-0.0765092625099788
323.00000000000387,38.15240421834693,-0.39332358380383364,-0.07882563609694149
323.8000000000039,38.229716332465124,-0.39103532349062403,-0.078830275647924
324.6000000000039,38.30648372790917,-0.38903547604739463,-0.07891028485234575
325.4000000000039,38.38360198550675,-0.3873065086299597,-0.0801340449819481
326.2000000000039,38.45999894413328,-0.3866000332357169,-0.080149785118941
327.0000000000039,38.538454251408005,-0.38465525284847585,-0.08407417735174505
327.80000000000393,38.614102418534934,-0.38253827474592345,-0.08672887001788787
328.60000000000394,38.69180697024282,-0.3801711348021313,-0.08724175814547763
329.40000000000396,38.76901448990806,-0.37743907345135497,-0.08673137325035984
330.20000000000397,38.84644253560935,-0.3763942758356733,-0.08941355749008384
331.000000000004,38.92396324994466,-0.3742566734846559,-0.08806518335235847
331.800000000004,39.00042186778752,-0.37141880443529457,-0.09266101081582567
332.600000000004,39.07750877320656,-0.3700859885548716,-0.09398079529624637
333.400000000004,39.15488937039811,-0.36805215872315383,-0.09533846631045684
334.200000000004,39.23103231977165,-0.3652485715578082,-0.09660363776681491
335.00000000000404,39.308751166484285,-0.36400268946599745,-0.09924412203359045
335.80000000000405,39.3859073354035,-0.36064694770588823,-0.10057942262064934
336.60000000000406,39.46168493037297,-0.35921848478390767,-0.1018787403001924
337.40000000000407,39.53771140756126,-0.35542523884231647,-0.10321969433555722
338.2000000000041,39.61773322187829,-0.35454401558377213,-0.10588574324459055
339.0000000000041,39.693911049563056,-0.35106199261668325,-0.10716009804100901
339.8000000000041,39.77244805938914,-0.3486441264483016,-0.10844852168812658
340.6000000000041,39.848904066093034,-0.34536441943874563,-0.11122772277554205
341.4000000000041,39.925865373752984,-0.3444043626203765,-0.11309306839122746
342.20000000000414,40.003448395052686,-0.3395170742246179,-0.1140098695606695
343.00000000000415,40.08088218899839,-0.3368825402977308,-0.11659119765908699
343.80000000000416,40.15770167763574,-0.3337835389963505,-0.11923441834286397
344.6000000000042,40.23391797315137,-0.3299490613360428,-0.1210221029989178
345.4000000000042,40.31113228847146,-0.3273508367083615,-0.12418168833714249
346.2000000000042,40.38951923953382,-0.3242284149671595,-0.12746561638535558
347.0000000000042,40.46501498096376,-0.3218839470696644,-0.1288001294839951
347.8000000000042,40.544519155579195,-0.31825591889192967,-0.1319497545200532
348.60000000000423,40.62206155722194,-0.31524480573257924,-0.13531156806833344
349.40000000000424,40.69923563256485,-0.31143848972577776,-0.13710110798286035
350.20000000000425,40.776043015252675,-0.30847182330609946,-0.13903089241281918
351.00000000000426,40.853499150380486,-0.3042539273902274,-0.1410982745026068
351.8000000000043,40.93051476733597,-0.29978730514898694,-0.1443233128157586
352.6000000000043,41.008388022288614,-0.2943101903083092,-0.14825467010841065
353.4000000000043,41.086014707863285,-0.29018825245525526,-0.15004084704241638
354.2000000000043,41.161826374020826,-0.28540611650610825,-0.1541805912606602
355.0000000000043,41.24069288295324,-0.2816479814839333,-0.15688937439807837
355.80000000000433,41.317462160798726,-0.27705990978363204,-0.15931730209656436
356.60000000000434,41.39377226538631,-0.27124039662339705,-0.1641235140344759
357.40000000000435,41.4728784517481,-0.26534939439530403,-0.16990766498205456
358.20000000000437,41.55064723817353,-0.26009255685950855,-0.17209905329913466
359.0000000000044,41.62638044371998,-0.25442853427597883,-0.1758574879382251
359.8000000000044,41.70480916803258,-0.24694647622369797,-0.17886162767711689
360.6000000000044,41.781902346314375,-0.2431638395709268,-0.18346711218210743
361.4000000000044,41.85923311723221,-0.2361218360026141,-0.18854019783467724
362.2000000000044,41.93712444184269,-0.2284856259650102,-0.1925158349558327
363.00000000000443,42.01453447961046,-0.22091726616323717,-0.19868048717659237
363.80000000000445,42.09308324569521,-0.21312906165021753,-0.20386073875599253
364.60000000000446,42.17009909889823,-0.20417139783764007,-0.2069582174285558
365.40000000000447,42.24765523324821,-0.19847837918478092,-0.21365417220266902
366.2000000000045,42.32472454465046,-0.1875692473445135,-0.21976568022692566
367.0000000000045,42.402252896427164,-0.17640608867941981,-0.22550532721114358
367.8000000000045,42.48204186758261,-0.16836730829370408,-0.23056327131929422
368.6000000000045,42.558667690490964,-0.15725241211994354,-0.23646290025156302
369.4000000000045,42.63692079345951,-0.14737366066101734,-0.2434805979322232
370.20000000000454,42.71299953539477,-0.1370662980545001,-0.25078778361924225
371.00000000000455,42.79204851439187,-0.12451003357964861,-0.2578590492566981
371.80000000000456,42.8692749175215,-0.1120712938979272,-0.2660521747775104
372.60000000000457,42.94721267812535,-0.09940077204156765,-0.2732911522684436
373.4000000000046,43.02614285947542,-0.08641662435772729,-0.2813007594149326
374.2000000000046,43.10297937135952,-0.07182375505193234,-0.29073379826217627
375.0000000000046,43.18164523670005,-0.055657923787179396,-0.2977030503141256
375.8000000000046,43.259133343442194,-0.03960952121992026,-0.3065687989210435
376.6000000000046,43.337093666911024,-0.021008164423177,-0.3162531864786957
377.40000000000464,43.41539832102142,-0.0033621767348031356,-0.3260304759632229
378.20000000000465,43.492251409565576,0.01414430396966606,-0.33828004887238405
379.00000000000466,43.570420090727104,0.03616147319337879,-0.3493036123705582
379.8000000000047,43.64969036520394,0.057795052940017924,-0.3618972124795907
380.6000000000047,43.726490196626436,0.0780434411292797,-0.374341892930139
381.4000000000047,43.8054650680589,0.09710821721763632,-0.3880652160358826
382.2000000000047,43.88167423330235,0.122761106066913,-0.4001476661581487
383.0000000000047,43.96116653905031,0.14999359520908873,-0.4145412355342275
383.80000000000473,44.038687244746335,0.17408630265653646,-0.42838798363075625
384.60000000000474,44.11710950199765,0.2050200908537725,-0.44455822346308116
385.40000000000475,44.195511047980176,0.23269994427524432,-0.46115526286804265
386.20000000000476,44.27356356363824,0.2660577635977191,-0.47728883105506226
387.0000000000048,44.35159193518507,0.3008210544636344,-0.4970476894658127
387.8000000000048,44.42931608072234,0.3382388417614652,-0.5186619252743889
388.6000000000048,44.508084161697134,0.37678781808529443,-0.5377249191613869
389.4000000000048,44.58686349261127,0.4144556715869898,-0.5592979909713058
390.2000000000048,44.66294343951084,0.45788838396362747,-0.5829642847908154
391.00000000000483,44.7433232926872,0.5017814068534712,-0.6077948068918726
391.80000000000484,44.82069052350062,0.5482601695899606,-0.6303500107518532
392.60000000000485,44.899601201753626,0.5989489937432737,-0.6565851223380044
393.40000000000487,44.977778817415796,0.6495928517181099,-0.6847840263694516
394.2000000000049,45.05572106681175,0.701783357639605,-0.7150993618263084
395.0000000000049,45.133936699831516,0.7580094218725963,-0.7450380646339614
395.8000000000049,45.21357735877673,0.815281789700928,-0.7751497095005844
396.6000000000049,45.29009408058767,0.8712507003775158,-0.8071711755305406
397.4000000000049,45.36862642600437,0.9358008859629223,-0.8429216458006077
398.20000000000493,45.44764437127757,1.0010230765053363,-0.8811388728503649
399.00000000000495,45.52613930266791,1.0705864769876694,-0.9191652541584121
399.80000000000496,45.60479283929424,1.1410026402703843,-0.9596107838461387
400.60000000000497,45.68263553616351,1.2115412753922,-1.0024357024355464
401.400000000005,45.762186042910585,1.285626317558167,-1.0485012751556955
402.200000000005,45.83990278059049,1.3558437201042415,-1.0953708056296985
403.000000000005,45.918853052422094,1.4328953721598077,-1.1437968908718545
403.800000000005,45.997584171886245,1.5158404295161012,-1.1957992288382333
404.600000000005,46.07580728196949,1.59666788656557,-1.2492340994369977
405.40000000000504,46.155057319407575,1.6778958936526316,-1.3055069953943619
406.20000000000505,46.23244909168233,1.7551498092356077,-1.36354195628383
407.00000000000506,46.31208025081497,1.8407976152215109,-1.4236211423239702
407.80000000000507,46.39099114855535,1.9310973775387585,-1.487904506525731
408.6000000000051,46.470508305975514,2.0096775977217356,-1.5535374064694611
409.4000000000051,46.54940757977565,2.0838380240963206,-1.6231422376725169
410.2000000000051,46.62876150053258,2.1610508039583536,-1.693562894679967
411.0000000000051,46.70661875960799,2.2345495432032876,-1.764204956653447
411.8000000000051,46.78279755358659,2.296383239335195,-1.8341873255479721
412.60000000000514,46.86400967340295,2.36087194915449,-1.911406506091375
413.40000000000515,46.942917926223394,2.4184535113247185,-1.9898339784952448
414.20000000000516,47.02260524396082,2.4660939532077903,-2.0687622454873553
415.0000000000052,47.100651526736144,2.5079356231274805,-2.1474496512164736
415.8000000000052,47.179008122295194,2.536170976574502,-2.2291661445167743
416.6000000000052,47.25771567678101,2.5620442627953652,-2.3115914844293033
417.4000000000052,47.33687685191431,2.577666753369099,-2.395054421999136
418.2000000000052,47.41530943458181,2.578008993561867,-2.477789678818713
419.00000000000523,47.49427014155766,2.5693837031316806,-2.5619866288564936
419.80000000000524,47.5731156000989,2.545722890505987,-2.6477228534911585
420.60000000000525,47.64980078811996,2.512505857970476,-2.725297650386827
421.40000000000526,47.72930700491709,2.464260869808869,-2.808432052948034
422.2000000000053,47.807384830828774,2.4005300140446613,-2.889173374553346
423.0000000000053,47.88553296234549,2.3308072354525406,-2.9643800962199407
423.8000000000053,47.96319634531204,2.2457088060780466,-3.039339170759127
424.6000000000053,48.04122600018836,2.1461493281520028,-3.1128862816360443
425.4000000000053,48.11870260860965,2.0395859461355648,-3.18578108976263
426.20000000000533,48.19707310849537,1.923584414897655,-3.254235721362601
427.00000000000534,48.274350767362364,1.795130980766164,-3.317820020876571
427.80000000000535,48.35075625653153,1.6638554725721828,-3.379049388643698
428.60000000000537,48.42941333967461,1.5239980408231348,-3.437220008778324
429.4000000000054,48.505382189513305,1.3844268793880532,-3.4910202098407996
430.2000000000054,48.58399449408513,1.2413646412055122,-3.5413819393085086
431.0000000000054,48.66165062693369,1.0994437236581476,-3.587866621242227
431.8000000000054,48.73782332552163,0.9640991259395241,-3.6291432573230122
432.6000000000054,48.815857809534194,0.827192223681388,-3.6694210222158286
433.40000000000543,48.89248940747242,0.7015051946313635,-3.704764638657084
434.20000000000545,48.96970085718135,0.5780364976194178,-3.737788671201014
435.00000000000546,49.047420932819,0.4655269197038755,-3.7694519484846745
435.80000000000547,49.12403626675468,0.3617860639621871,-3.795892556264371
436.6000000000055,49.20135365930969,0.2646842442508792,-3.821095889508047
437.4000000000055,49.27843297615246,0.17805921036210706,-3.840864971139456
438.2000000000055,49.35604115917864,0.09863265749574984,-3.862771527514786
439.0000000000055,49.433966600156985,0.02637160717463674,-3.8803243088876402
439.8000000000055,49.510791212768225,-0.038042935354758646,-3.895201253081978
440.60000000000554,49.58901716645348,-0.09437348047868824,-3.911064027912841
441.40000000000555,49.66652069746925,-0.1450557619752906,-3.9247230365975296
442.20000000000556,49.744055554267234,-0.19182156444192636,-3.9363660487973866
443.00000000000557,49.821558118113764,-0.2296171294200636,-3.94433717705913
443.8000000000056,49.89933433386407,-0.2675616472247714,-3.95472142045986
444.6000000000056,49.97656785792629,-0.2997240884973069,-3.9640549339417355
445.4000000000056,50.05550369522325,-0.32371331187118985,-3.9726864436504803
446.2000000000056,50.13308930841639,-0.3500492358590922,-3.978756856125935
447.0000000000056,50.210906482316105,-0.3710166485320608,-3.986198623504199
447.80000000000564,50.288499359263874,-0.39175723474457846,-3.991785092694989
448.60000000000565,50.367188979292365,-0.4068795658143071,-3.997634674306599
449.40000000000566,50.445828722809466,-0.4222534657396794,-4.003108763955018
450.2000000000057,50.522538125637055,-0.4356090272144414,-4.007657180643863
451.0000000000057,50.60205110076691,-0.44811731447333925,-4.011585538147052
451.8000000000057,50.6796458113991,-0.46017628751888395,-4.015528451737801
452.6000000000057,50.75719596359177,-0.4685336141029978,-4.019420629725799
453.4000000000057,50.83658312942605,-0.4783059165664762,-4.0226166579381415
454.20000000000573,50.91228107309426,-0.4862998669525005,-4.025700724474088
455.00000000000574,50.993196203228706,-0.4933443653119531,-4.028477055153191
455.80000000000575,51.07028512936103,-0.5002769689035793,-4.0288133759684275
456.60000000000576,51.14990022543848,-0.5086396145216412,-4.031680787841525
457.4000000000058,51.22533888035712,-0.5137462009563786,-4.033272079415744
458.2000000000058,51.306624362370755,-0.5186390497050005,-4.035529322349657
459.0000000000058,51.38456607462819,-0.5244651111823377,-4.036661880324365
459.8000000000058,51.46337233270148,-0.5294438472917748,-4.03683769935868
460.6000000000058,51.54166352956008,-0.5348335765795683,-4.039703485812955
461.40000000000583,51.61962067933546,-0.5417725245421404,-4.042207823929134
462.20000000000584,51.69900053625021,-0.5503132980347545,-4.043544149511921
463.00000000000585,51.77567907348148,-0.556139679223212,-4.043516572752527
463.80000000000587,51.85612078140164,-0.5661229580669648,-4.04355159517061
464.6000000000059,51.935219110368564,-0.5690112607003109,-4.045718778982852
465.4000000000059,52.013039433879044,-0.5747913559579754,-4.0461701286407505
466.2000000000059,52.09152083705375,-0.5792026879176204,-4.046119896051533
467.0000000000059,52.17095610214242,-0.5781963623135217,-4.047490059667693
467.8000000000059,52.24960299923327,-0.579047312119281,-4.047490128233738
468.60000000000593,52.32796276427169,-0.5766929156758195,-4.047685472428465
469.40000000000595,52.405880891042585,-0.577176431604395,-4.048809997730741
470.20000000000596,52.4847497188599,-0.5760664440396827,-4.048555570869512
471.00000000000597,52.56291921687179,-0.5751053076269398,-4.047489948562489
471.800000000006,52.641806906912734,-0.5753352379379719,-4.047489969953256
472.600000000006,52.72073617202583,-0.5763519188374847,-4.047475820949969
473.400000000006,52.79802701519329,-0.5773328132116003,-4.048809826129329
474.200000000006,52.87758212960854,-0.5783189879433149,-4.048850358698003
475.000000000006,52.95719070417084,-0.5803677080097172,-4.047490011292193
475.80000000000604,53.03529415694373,-0.5818571013808027,-4.047491861932311
476.60000000000605,53.11435167207791,-0.5836744987608103,-4.048808465581796
477.40000000000606,53.19285378119058,-0.5851429127686903,-4.047489650555446
478.20000000000607,53.27007742718399,-0.5862357747437326,-4.047486905780571
479.0000000000061,53.350476221379374,-0.5876515251068942,-4.050125965454516
479.8000000000061,53.428689412165255,-0.5888777850223931,-4.048809385770154
480.6000000000061,53.50768565838792,-0.589523692183007,-4.048116016239584
481.4000000000061,53.586846639303545,-0.5909477180913522,-4.046831034817348
482.2000000000061,53.66553740929224,-0.5904654148701147,-4.04742223954109
483.00000000000614,53.74420574095595,-0.5913486868885058,-4.0474900923170445
483.80000000000615,53.82357063761857,-0.5926252507768401,-4.047490096999857
484.60000000000616,53.902386636181646,-0.5922630377258975,-4.047490097000148
485.4000000000062,53.98121191029173,-0.5908998806486758,-4.0474900997377645
486.2000000000062,54.06138936073286,-0.592449280142955,-4.048870794402422
487.0000000000062,54.13949442284966,-0.5920687911052088,-4.0474769199784815
487.8000000000062,54.218341506906704,-0.5922559694410051,-4.047491710797206
488.6000000000062,54.29734538013588,-0.5926476683402263,-4.046513482501812
489.40000000000623,54.37645026086956,-0.5920366482682292,-4.046534483851145
490.20000000000624,54.453728847751414,-0.5932732717572032,-4.048789995820049
491.00000000000625,54.53376541881601,-0.5931552798218733,-4.0487999035822755
491.80000000000626,54.61338114648061,-0.5947441633673666,-4.048799903999988
492.6000000000063,54.69213001645464,-0.5929107857512937,-4.048799904
493.4000000000063,54.77111594957699,-0.5948581026113455,-4.048799904
494.2000000000063,54.849365781962206,-0.5940829516533123,-4.048799903999999
495.0000000000063,54.929060567037524,-0.5942970024245793,-4.048799903970023
495.8000000000063,55.0074995216558,-0.5936336028507752,-4.0487974891189875
496.60000000000633,55.08707385076421,-0.5929070957000405,-4.0495737449037845
497.40000000000634,55.16680258345728,-0.5935821438401689,-4.05012015998921
498.20000000000636,55.24517962766221,-0.5929123176456835,-4.050120156000144
499.00000000000637,55.323394155980516,-0.5945312142447288,-4.050120156
499.8000000000064,55.40225748676421,-0.5935200022133021,-4.050120156
500.6000000000064,55.48193928902934,-0.5927778861907244,-4.0501201560000375
501.4000000000064,55.560422996615436,-0.5923094767152032,-4.050120156225628
502.2000000000064,55.64020271105918,-0.592731261188374,-4.050124161664846
503.0000000000064,55.7167514431617,-0.5931274046824658,-4.0504482864308455
503.80000000000643,55.79786361593516,-0.5921624698618753,-4.051765957478095
504.60000000000645,55.876026145736816,-0.592712644799892,-4.049517460977649
505.40000000000646,55.95291705573069,-0.5918999337705234,-4.049469811057466
506.20000000000647,56.03406443514805,-0.5930112029239847,-4.049471838107195
507.0000000000065,56.11364697672072,-0.5917945542895398,-4.049139982072442
507.8000000000065,56.19292411762503,-0.5918289650844575,-4.047955747680067
508.6000000000065,56.27143761736018,-0.5920660604048966,-4.049140116762836
509.4000000000065,56.35205348750652,-0.5920507052666155,-4.049807583367471
510.2000000000065,56.43086044704912,-0.5927064360745431,-4.050130791185909
511.00000000000654,56.50981736293903,-0.5914077068813991,-4.048809685160729
511.80000000000655,56.58895840112018,-0.5920503934279061,-4.048810067623283
512.6000000000065,56.668324002208784,-0.5902359674090315,-4.049475359374047
513.4000000000066,56.74795080893978,-0.5915254224175707,-4.048357735065721
514.2000000000066,56.82644943309733,-0.5911253592116557,-4.049798635549321
515.0000000000066,56.905933625604774,-0.5912055592452912,-4.049797836175142
515.8000000000065,56.98549711352972,-0.5909551792461971,-4.048536501307657
516.6000000000066,57.06572548027782,-0.5919296169604495,-4.05111086466797
517.4000000000067,57.14423543847885,-0.5918725177306176,-4.052100220802206
518.2000000000066,57.2236832630882,-0.5913552658658426,-4.05210018862423
519.0000000000066,57.30360955527619,-0.5907699802501795,-4.051401714950576
519.8000000000067,57.38220808317719,-0.5886579478759014,-4.0519423359541555
520.6000000000067,57.46174512744375,-0.5894693414747689,-4.052099805780767
521.4000000000067,57.54127595444249,-0.5890602476804214,-4.052099805986755
522.2000000000066,57.62097749017045,-0.5885713074650024,-4.052099401325574
523.0000000000067,57.69969987899947,-0.5872571116198871,-4.052760036452956
523.8000000000068,57.77926282117502,-0.5883014912246372,-4.051440239937724
524.6000000000067,57.85873361526776,-0.5886769093957249,-4.051439931993453
525.4000000000067,57.9378748417548,-0.5876245773689324,-4.051438905461102
526.2000000000068,58.0168851333895,-0.5885567091185621,-4.049211808755445
527.0000000000068,58.09633703436461,-0.5883023232042126,-4.050321543329069
527.8000000000068,58.17612498905916,-0.5877855502339434,-4.050340130438297
528.6000000000067,58.25489615639178,-0.5874427930909608,-4.05034013099998
529.4000000000068,58.33402567017953,-0.5856580993138056,-4.050340131000002
530.2000000000069,58.414086695867006,-0.5869416100420298,-4.050340131086365
531.0000000000068,58.49170535734458,-0.5848230706659813,-4.050341333473133
531.8000000000068,58.57158455144839,-0.5859988701841642,-4.049030795849774
532.6000000000068,58.651189394776054,-0.5858461184562446,-4.050338906438115
533.4000000000069,58.72980302679808,-0.584999821057592,-4.049656609300029
534.2000000000069,58.80941209623303,-0.5857012938921531,-4.050339929041326
535.0000000000068,58.88885128586175,-0.5840846985330186,-4.050339828024459
535.8000000000069,58.96787155716383,-0.5852153587522303,-4.05100057021331
536.600000000007,59.04658205248938,-0.5844179487386711,-4.050810963289327
537.4000000000069,59.126078202563534,-0.5839343903093163,-4.051088189570742
538.2000000000069,59.20595924784932,-0.5839860778051206,-4.050999830193954
539.0000000000069,59.285659437425,-0.5832174864345603,-4.0515271798280725
539.800000000007,59.3646241601668,-0.5835547389505777,-4.052320070615314
540.600000000007,59.44473162042805,-0.5817786257624538,-4.0523495371907865
541.4000000000069,59.523431217031764,-0.5814302371478193,-4.0516615810137875
542.200000000007,59.602502451228126,-0.5818714385062843,-4.0500197903109765
543.000000000007,59.681763685588464,-0.5811719886649305,-4.050046697345071
543.800000000007,59.76183864934053,-0.582383756824889,-4.05196152630946
544.600000000007,59.84173450406851,-0.5810331429658957,-4.050914065555695
545.400000000007,59.91906109758482,-0.581100476618716,-4.051000165171641
546.000000000007,59.98080000250873,-0.5824872871952189,-4.051000162999568