File: 01_Data/Cotton_Sheet/STA/N2/10K_min/Cotton_Sheet_STA_N2_10KData_220719_R2.csv
##Temp./Â°C,Time/min,DSC/(mW/mg),Mass loss/mg
50.0,10.596552585631722,-1.40032264408388,0.0004227206223808011
51.000000000000014,10.961902110408895,-1.3063218775211891,-0.001628368967509175
52.00000000000003,11.176543592770246,-1.2488202578775225,0.0007295401353966113
53.00000000000004,11.349449863016511,-1.205179733313199,-0.0007130618599200389
54.00000000000006,11.500172704570044,-1.1736039170796349,0.0003290168739740196
55.00000000000007,11.641903006164918,-1.1478233203871133,0.000612815484761775
56.000000000000085,11.771932849985928,-1.1260802075028329,-0.00036152161674873895
57.0000000000001,11.896984372094717,-1.1065084146441873,-4.434393233498923e-05
58.000000000000114,12.016910995729639,-1.0900089632520955,0.0009193509612144268
59.00000000000013,12.134308724264653,-1.0765639728109702,0.0007140858017598006
60.00000000000014,12.250146391375047,-1.0636714757992622,0.00039130886963878453
61.000000000000156,12.364261779968041,-1.0522276666192596,-0.0006398101520748156
62.00000000000017,12.474429523884837,-1.043911165442428,-0.0005490867995368021
63.000000000000185,12.586187203482442,-1.032322639078585,-0.0006611808830347954
64.0000000000002,12.695982454035546,-1.0233814016003473,-0.0006296668734693256
65.00000000000021,12.806248333360761,-1.014017397658113,-0.0006585044847957633
66.00000000000023,12.913620375959717,-1.004879858164842,-0.0006604352079326858
67.00000000000024,13.022120903482385,-0.995165958403817,0.0006554281070734191
68.00000000000026,13.129170000000025,-0.9889699999999944,-0.0006637417605448448
69.00000000000027,13.236587620993731,-0.9790433558956924,-0.0007818789442408658
70.00000000000028,13.345050543721774,-0.97097383305773,-0.0032906821925529073
71.0000000000003,13.445956474310446,-0.9622483429676743,-0.003289864681503829
72.00000000000031,13.556689171919219,-0.9558066892818669,-0.003327619306353391
73.00000000000033,13.661977597069468,-0.9468418903028556,-0.004624883495526255
74.00000000000034,13.767039853125999,-0.9388643036507163,-0.004608594400411725
75.00000000000036,13.870148103320561,-0.9307867097373326,-0.003628301784022625
76.00000000000037,13.977040940248548,-0.9240156411883592,-0.0037709938806029797
77.00000000000038,14.081093263262336,-0.9177095470085871,-0.004609871654649211
78.0000000000004,14.183338255406479,-0.9121750122559669,-0.005929891759813621
79.00000000000041,14.286996973791398,-0.9054086535317002,-0.007229445986621563
80.00000000000043,14.388141040434299,-0.8994971347964894,-0.005939635475312954
81.00000000000044,14.492963902698154,-0.8935928136584032,-0.007240473908876943
82.00000000000045,14.595763219047909,-0.8884140025935078,-0.009857617706822808
83.00000000000047,14.698385167444112,-0.8843121363881514,-0.010276779301033656
84.00000000000048,14.799973662126321,-0.8802422350361121,-0.00988003445249408
85.0000000000005,14.901786313147289,-0.8761463592914128,-0.01118967444314034
86.00000000000051,15.003775966264714,-0.8720494838841478,-0.010966077798646445
87.00000000000053,15.103265187963563,-0.8693250539432064,-0.011200304255181592
88.00000000000054,15.205510406011427,-0.8663914807358225,-0.011200199967570157
89.00000000000055,15.30642486507223,-0.8625848763196385,-0.011055903588291116
90.00000000000057,15.406545054105006,-0.8605276307496292,-0.011199842682947825
91.00000000000058,15.506983227244094,-0.8588106674462218,-0.01120029328369121
92.0000000000006,15.606736064106613,-0.8550873459678761,-0.012519924792305126
93.00000000000061,15.705918391887488,-0.8534543227774601,-0.012519835023757864
94.00000000000063,15.8055164502126,-0.850897470662702,-0.013866401024722919
95.00000000000064,15.90478929998415,-0.8491038080238038,-0.013607155229433232
96.00000000000065,16.002544436921493,-0.84707321013589,-0.013831797402345636
97.00000000000067,16.102326007960773,-0.8453212036737192,-0.01383000391568423
98.00000000000068,16.199950337412343,-0.8447696518321928,-0.015056675473886116
99.0000000000007,16.300568747151868,-0.8438542774941866,-0.015150005980795633
100.00000000000071,16.398202619129297,-0.8433399406274309,-0.01425112441239662
101.00000000000072,16.496110116261704,-0.8406348807478153,-0.014819766725493011
102.00000000000074,16.594826705324206,-0.838899782656503,-0.01514854048934744
103.00000000000075,16.693095973588626,-0.8362991331834101,-0.015479998243002058
104.00000000000077,16.79008617980041,-0.8364565595257261,-0.015480063353447981
105.00000000000078,16.887711654899622,-0.8328020379057829,-0.016792915120124263
106.0000000000008,16.98531316078107,-0.832405137207759,-0.01647052093161161
107.00000000000081,17.084450963779773,-0.8311718968230103,-0.015155420708778067
108.00000000000082,17.179296408632407,-0.8287582337904867,-0.015517165745200678
109.00000000000084,17.280780048484186,-0.8264398812358827,-0.015150169275576886
110.00000000000085,17.37528720151622,-0.8243572651836808,-0.015150146077258064
111.00000000000087,17.474842349541834,-0.821235284335933,-0.016475289528393056
112.00000000000088,17.572936368066742,-0.8192263489829085,-0.01631090035571514
113.0000000000009,17.669170000000086,-0.8168300000000013,-0.016459845016078667
114.00000000000091,17.76782182468027,-0.8134368586578259,-0.016459845000423634
115.00000000000092,17.863923056737512,-0.8112384704978035,-0.016460194275863316
116.00000000000094,17.962517183620086,-0.8081132976981156,-0.016469920363714863
117.00000000000095,18.06035567430673,-0.8050003052007793,-0.016096848502246353
118.00000000000097,18.156910993069406,-0.8017564322067293,-0.017154490474816875
119.00000000000098,18.254455887603655,-0.7985872570004068,-0.01644800137323088
120.000000000001,18.351667524678184,-0.7955527967907358,-0.015149835348011287
121.00000000000101,18.4477998834517,-0.7932023142327426,-0.016460165166550134
122.00000000000102,18.545965111730876,-0.787067726017409,-0.01645988044692892
123.00000000000104,18.642645585131312,-0.7839410420524476,-0.016444812011113363
124.00000000000105,18.7405412106667,-0.7813509730158599,-0.016397215729575088
125.00000000000107,18.837689998746544,-0.7781081412309216,-0.015481095836030079
126.00000000000108,18.935633587712612,-0.7724392137508405,-0.01680011228359035
127.0000000000011,19.030639635607095,-0.7691604308381009,-0.016809981722753164
128.0000000000011,19.128279025076065,-0.7654138285560561,-0.015882587828623507
129.00000000000114,19.22527940413855,-0.7627260972715354,-0.013784319056714622
130.00000000000114,19.322641609742853,-0.759420343292171,-0.015150014122577993
131.00000000000114,19.419555145300073,-0.7559248044120509,-0.01515002199232196
132.00000000000117,19.515721896660875,-0.7516853423904233,-0.01580039718427173
133.0000000000012,19.61264876675484,-0.7479813862674436,-0.015810013753529084
134.0000000000012,19.707490629388865,-0.7444903991998022,-0.014826253541786905
135.0000000000012,19.804988344465013,-0.740904856913249,-0.015140070044817655
136.00000000000122,19.9018813045064,-0.7357002753491415,-0.015135074958847028
137.00000000000125,19.997545819437654,-0.7326552220110452,-0.015149950006184021
138.00000000000125,20.09542408047798,-0.7292799421437633,-0.015150146393042796
139.00000000000125,20.190963735292495,-0.7271810523403823,-0.015145751142992658
140.00000000000128,20.287186384144675,-0.722146742293505,-0.013830055001573527
141.0000000000013,20.385524019660487,-0.7199529037214043,-0.015148294218508163
142.0000000000013,20.48070962660249,-0.7157722477115839,-0.015150054756407627
143.0000000000013,20.576453548166096,-0.7110965046818034,-0.015246200639084329
144.00000000000134,20.6716421441211,-0.7073682331560753,-0.01548054212463601
145.00000000000136,20.769821256870127,-0.705117009865403,-0.015479823212428911
146.00000000000136,20.864266901165486,-0.699354281695708,-0.015147813155875767
147.00000000000136,20.961273886454943,-0.6974498536224499,-0.015268609071281247
148.0000000000014,21.056793600933265,-0.6927255872996031,-0.015149984807276695
149.00000000000142,21.153730585478883,-0.6887102582175892,-0.016222381433252053
150.00000000000142,21.248251537236214,-0.6866461514179862,-0.013760103809786095
151.00000000000142,21.34421843460932,-0.6826576393856544,-0.013820279745490716
152.00000000000145,21.440452968666712,-0.6786619769226374,-0.014830177050543014
153.00000000000148,21.53706835245407,-0.6738885518582196,-0.013830532020365105
154.00000000000148,21.632206407850173,-0.6713972763744038,-0.013769424243557538
155.00000000000148,21.728985389357454,-0.6667926627577871,-0.015150755696580198
156.0000000000015,21.82487515360703,-0.6644899254253368,-0.013830343799431155
157.00000000000153,21.920790149766376,-0.6605738496955804,-0.013833146872227253
158.00000000000153,22.015754517858472,-0.6580356336459767,-0.014818727896452444
159.00000000000153,22.111994744737512,-0.6521361555668079,-0.013829854411424591
160.00000000000156,22.20777773279398,-0.6485484040496303,-0.014134678733521255
161.0000000000016,22.302812370146782,-0.6447356899284674,-0.014159542146391146
162.0000000000016,22.399775490052907,-0.6407820012271948,-0.014820054131353011
163.0000000000016,22.494674649331245,-0.6370820466723417,-0.014839169051842127
164.00000000000162,22.590740253170956,-0.6356582193330982,-0.015480581441663865
165.00000000000165,22.687263287009134,-0.6306636471152401,-0.015156485221264226
166.00000000000165,22.78243074592092,-0.6270821215914202,-0.015150148189333024
167.00000000000165,22.878092737888075,-0.6245050184729058,-0.013841885185977176
168.00000000000168,22.9743074194837,-0.6217098574833478,-0.013757536143590876
169.0000000000017,23.069779475582976,-0.6170615941723426,-0.013829864066738473
170.0000000000017,23.165345695860562,-0.6137025422270919,-0.013747346308818464
171.0000000000017,23.261705547418632,-0.6112153310044313,-0.015149929128379647
172.00000000000173,23.356049409915787,-0.6056101063452587,-0.015115790108865212
173.00000000000176,23.452109658279216,-0.6015317219385973,-0.013500305867907514
174.00000000000176,23.547532175501537,-0.5989115923034058,-0.014156872492767647
175.00000000000176,23.644049074917262,-0.5954003719773994,-0.01441894460414428
176.0000000000018,23.737043940410366,-0.5931901953310934,-0.014054276776842123
177.00000000000182,23.83429177704218,-0.5906079580789916,-0.01350985987277653
178.00000000000182,23.92927025328229,-0.5853875549235301,-0.013509874241433018
179.00000000000182,24.024681957202112,-0.5829517596412945,-0.0141746515556882
180.00000000000185,24.120030846120102,-0.5795664755545588,-0.014169726148201
181.00000000000188,24.214329999703484,-0.5749469814725305,-0.012851237231957136
182.00000000000188,24.311214573408126,-0.5729618884860481,-0.01281921752796844
183.00000000000188,24.407872672604167,-0.570201643756977,-0.014159974835725286
184.0000000000019,24.502171129909023,-0.5660050508671373,-0.01416006354169319
185.00000000000193,24.59798667719275,-0.5652429817319345,-0.014820651588626
186.00000000000193,24.691874521871853,-0.5620175698695739,-0.014293410598557266
187.00000000000193,24.78825110460771,-0.5571693116243535,-0.013830144694420454
188.00000000000196,24.88334285491107,-0.5541716834932606,-0.013830189113130942
189.000000000002,24.979170000000202,-0.5509699999999897,-0.01449165675873676
190.000000000002,25.073827355259198,-0.5471489029596147,-0.014490139907013422
191.000000000002,25.16945530875877,-0.5444213418921103,-0.015147264287013407
192.00000000000202,25.263374450919052,-0.5433128322098744,-0.01515007030527471
193.00000000000205,25.35955588857056,-0.5394592335878011,-0.015150070013772776
194.00000000000205,25.456138456121227,-0.5361391654788513,-0.015122044398505174
195.00000000000205,25.550624511747863,-0.532875860101267,-0.013830175287266933
196.00000000000207,25.644950435291772,-0.5282899110707877,-0.013830142729474026
197.0000000000021,25.740132265447407,-0.5249869616022861,-0.01546908458121532
198.0000000000021,25.83595630223459,-0.5224927395061899,-0.014156378061876751
199.0000000000021,25.930675927868123,-0.5183871270646656,-0.015470432572765702
200.00000000000213,26.026302161066447,-0.5175996421197464,-0.015470175000146469
201.00000000000216,26.12168085548863,-0.5132564545695942,-0.015470175000000808
202.00000000000216,26.217262646110775,-0.5104020290781961,-0.015470175000001696
203.00000000000216,26.311631436618754,-0.5071704380967342,-0.015470174995188657
204.0000000000022,26.40770385126521,-0.5046047565743632,-0.015469600546137663
205.00000000000222,26.503877992045695,-0.5029976644573221,-0.018083559814493277
206.00000000000222,26.597390381645223,-0.49986102055678105,-0.016730731502694773
207.00000000000222,26.692846307559936,-0.49641768743788495,-0.01547014403773872
208.00000000000225,26.788997466151447,-0.49395061470049006,-0.016787152301982466
209.00000000000227,26.88363328415922,-0.4914766547014025,-0.016719559624945646
210.00000000000227,26.978871246050737,-0.48878991940492467,-0.015465980946589575
211.00000000000227,27.07414224964003,-0.48567931570777095,-0.016837536048257995
212.0000000000023,27.169263079322928,-0.4834643983888876,-0.018110335206063866
213.00000000000233,27.26375974828731,-0.4804050491396547,-0.018110174442150573
214.00000000000233,27.36009169380109,-0.47553194931274656,-0.01805013839780578
215.00000000000233,27.456131171385994,-0.47382527641725025,-0.018175463283681914
216.00000000000236,27.550447865338562,-0.46999595022590407,-0.01877002092999991
217.0000000000024,27.64555987189637,-0.46554459279519084,-0.0184398088838007
218.0000000000024,27.7406792173373,-0.4615470421263788,-0.017461392653422614
219.0000000000024,27.83350007177293,-0.4588542740846388,-0.018123703352254772
220.00000000000242,27.93076837950843,-0.4565586107445561,-0.019108308867609836
221.00000000000244,28.026323085222913,-0.4540135581422669,-0.019088956092738307
222.00000000000244,28.121325005245595,-0.4497603171972047,-0.017785858252526765
223.00000000000244,28.216383740110242,-0.4458337151139527,-0.02042238318011158
224.00000000000247,28.31163648709102,-0.4430686045951668,-0.019370263008104516
225.0000000000025,28.406861321057875,-0.44024005131420774,-0.019154887822318223
226.0000000000025,28.501833573190154,-0.43673904116366113,-0.019065508796529684
227.0000000000025,28.59705016730602,-0.4353645226433312,-0.020420437840881434
228.00000000000253,28.69191171113524,-0.4332802205121159,-0.01943674572912535
229.00000000000256,28.787417179326518,-0.429500859671771,-0.022023825479086767
230.00000000000256,28.88158661231201,-0.42537068918485693,-0.02074983967421762
231.00000000000256,28.977327322568204,-0.4231644197400527,-0.020749845218173135
232.0000000000026,29.073398118338847,-0.42036109458058,-0.022188983960067965
233.00000000000261,29.167376629502037,-0.4168927064652753,-0.02337845206900191
234.00000000000261,29.26290589786814,-0.4150045782499995,-0.02338926366328309
235.00000000000261,29.359069054512013,-0.4126020950136394,-0.024698167424286765
236.00000000000264,29.45418367851528,-0.41053724510830847,-0.023710144999999905
237.00000000000267,29.548798617948368,-0.40773830260087984,-0.023710144998795535
238.00000000000267,29.64447584779458,-0.40538378034238326,-0.02371014551289985
239.00000000000267,29.73907336613931,-0.4030179085390186,-0.02517422231264721
240.0000000000027,29.834149164333315,-0.4015206879577975,-0.026421604564607293
241.00000000000273,29.929860566577098,-0.39864674105073644,-0.026130039834917795
242.00000000000273,30.02481160911762,-0.39554559026638225,-0.026130037401767225
243.00000000000273,30.120819764563738,-0.3941111739149314,-0.027250743310207604
244.00000000000276,30.215719821569202,-0.3914270660684883,-0.02744993505215465
245.00000000000279,30.310685165530995,-0.3885992972126527,-0.027450793410331187
246.00000000000279,30.405784076599858,-0.3852096265497322,-0.026907581794246127
247.00000000000279,30.500842864438038,-0.38391283983441293,-0.028549758402335534
248.0000000000028,30.595956622932633,-0.3808076987561842,-0.029528090882002367
249.00000000000284,30.690792220805445,-0.37696296988588945,-0.03028521706722387
250.00000000000284,30.78751684590015,-0.37645480481032567,-0.030825968792676406
251.00000000000284,30.8818029284316,-0.37186601433238853,-0.03096001410693905
252.00000000000287,30.97684177824161,-0.3701802147808915,-0.03096006033486809
253.0000000000029,31.07317376179785,-0.3671072818856772,-0.031289251371578786
254.0000000000029,31.168522167890394,-0.3665458933468198,-0.03273025009629826
255.0000000000029,31.263659831361608,-0.3644009685778356,-0.03271990455884577
256.00000000000296,31.358885452475587,-0.3621391974149251,-0.03403909014656481
257.00000000000296,31.453382908081814,-0.3594818432535861,-0.03403988233578126
258.00000000000296,31.549554428797045,-0.35638060646112146,-0.03541406804432867
259.00000000000296,31.643724024062834,-0.3547533066738935,-0.03538824644438421
260.00000000000296,31.740500729089106,-0.35352297313326797,-0.036337620097569356
261.000000000003,31.83427640550275,-0.3511758192556531,-0.036670396930514215
262.000000000003,31.93008041842926,-0.348111626767263,-0.037979799300677186
263.000000000003,32.026280378294516,-0.34399929881915314,-0.03797994889057765
264.00000000000307,32.12102795100618,-0.34353642074014784,-0.03970497587003319
265.00000000000307,32.21601165982766,-0.34060736376091866,-0.04073218125492062
266.00000000000307,32.31178234793365,-0.3393153068051653,-0.04206582065126785
267.00000000000307,32.40620578675003,-0.33632364676286264,-0.042400288721387014
268.00000000000307,32.50257765396434,-0.3339984083459176,-0.04203986062925136
269.0000000000031,32.59724293235437,-0.33168682789067594,-0.0430318807537482
270.0000000000031,32.690466185759945,-0.32969031231673457,-0.04479209560746167
271.0000000000031,32.787793799222,-0.32519869373580823,-0.046110182654300225
272.0000000000032,32.88391114321696,-0.3231849268319217,-0.046105903575598184
273.0000000000032,32.97866163089256,-0.31815785243405603,-0.04860037340380341
274.0000000000032,33.074511377203336,-0.31554310491035215,-0.04874262109736005
275.0000000000032,33.169365574432156,-0.3131066576261935,-0.049416143656499045
276.0000000000032,33.26471005019172,-0.3098993840503037,-0.051465224418878464
277.00000000000324,33.361756539326706,-0.304290715965471,-0.052697070071543006
278.00000000000324,33.455473260470136,-0.3013869770485249,-0.05439235044013202
279.00000000000324,33.55124381198949,-0.2974911303276423,-0.056630630168838625
280.0000000000033,33.64824495451516,-0.2927711458699741,-0.057554598309457194
281.0000000000033,33.74253811742224,-0.28707697290437245,-0.060021035047884475
282.0000000000033,33.83814557281243,-0.28462270085068736,-0.06153795402997764
283.0000000000033,33.93339810320793,-0.2806832474708689,-0.06414655390380641
284.0000000000033,34.02935666242884,-0.27448832295268366,-0.06520994766686972
285.00000000000335,34.12516291562623,-0.26913840744910855,-0.06754195882757097
286.00000000000335,34.22060687146601,-0.26473796972161556,-0.07048443298579654
287.00000000000335,34.315175334309664,-0.258729140948321,-0.0721600678958847
288.0000000000034,34.40932375070865,-0.2542064160051153,-0.07375802050662639
289.0000000000034,34.50717578127016,-0.24871813981474228,-0.07743714817146685
290.0000000000034,34.6026518945808,-0.24282651553126336,-0.07995660768939494
291.0000000000034,34.69648981277299,-0.23595898239916918,-0.08420196104305022
292.0000000000034,34.79373687545791,-0.23185791046091497,-0.08870177935864954
293.00000000000347,34.89039864022228,-0.22702642404316628,-0.08937300538594828
294.00000000000347,34.986491939637595,-0.2199598033674515,-0.09397229618912117
295.00000000000347,35.081770571447265,-0.21544405425425714,-0.097369679371901
296.0000000000035,35.177558116890296,-0.20991171864496033,-0.10379706885615514
297.0000000000035,35.27403117044619,-0.20185504894453718,-0.10811899222543442
298.0000000000035,35.36986454057138,-0.19608910890029832,-0.11402015666067378
299.0000000000035,35.46539282690359,-0.18897174416965765,-0.11868424645908826
300.0000000000035,35.56033399743763,-0.1830544012197395,-0.12426587588617721
301.0000000000036,35.65690466318744,-0.17540765366808966,-0.12918109278186485
302.0000000000036,35.751807204370046,-0.16926503646057625,-0.13548952736638142
303.0000000000036,35.84819240664423,-0.16061181518055925,-0.1410932442324322
304.00000000000364,35.94419324837301,-0.15291653195501684,-0.1484240119452176
305.00000000000364,36.039889155219385,-0.14191157382387493,-0.15498016303201734
306.00000000000364,36.13629552476294,-0.13261502049817242,-0.16282249286135908
307.00000000000364,36.231330087572935,-0.1238632616854157,-0.17049770113734475
308.00000000000364,36.32542559318591,-0.11505486469428322,-0.17903131210572187
309.0000000000037,36.42284716481414,-0.10525630219213017,-0.18795528324940403
310.0000000000037,36.51917000000037,-0.09404627999996681,-0.19771988963838583
311.0000000000037,36.6150796197173,-0.08408447289121966,-0.20739663492182148
312.00000000000375,36.71123909012036,-0.07357248177476101,-0.21336755184658518
313.00000000000375,36.80562574656942,-0.062027793608236466,-0.22533925746024952
314.00000000000375,36.90280727997568,-0.050329297118666454,-0.23730925032792305
315.00000000000375,36.99927247919586,-0.03613500393760918,-0.25144235563693673
316.00000000000375,37.093184302198765,-0.023328022026775037,-0.26398896158412644
317.0000000000038,37.19088220671008,-0.011436785950988973,-0.2772735346097379
318.0000000000038,37.286384402326945,0.0031038845228047473,-0.2923435591355381
319.0000000000038,37.3834565579076,0.01930944068671274,-0.3074446711110723
320.00000000000387,37.47917000000036,0.033508820000109754,-0.32213015696383174
321.00000000000387,37.574832574056785,0.048296001005674265,-0.33775162014135995
322.00000000000387,37.671170814456914,0.06428502847433061,-0.35433136499652074
323.00000000000387,37.76806513223571,0.08256352837230876,-0.373929155718165
324.00000000000387,37.86393082792633,0.10142070362231138,-0.39191300296643083
325.0000000000039,37.96046505953064,0.11777402784059764,-0.4115744709991498
326.0000000000039,38.05647430961399,0.13580026846545662,-0.4322459195612427
327.0000000000039,38.15341574679938,0.15564068306967824,-0.45376752146147625
328.000000000004,38.249865046877964,0.17555881827783051,-0.4773942760650254
329.000000000004,38.34561027093321,0.19522340937632154,-0.5000101665330545
330.000000000004,38.44240762008544,0.2151727847169799,-0.5253917035251945
331.000000000004,38.539066070953,0.23751818791025592,-0.5507563073535771
332.000000000004,38.63487571801243,0.260522203427811,-0.5781594925413533
333.00000000000404,38.73189480463978,0.2826492176808028,-0.6067422442386516
334.00000000000404,38.828204973943585,0.306726151755623,-0.6351315430068905
335.00000000000404,38.925842435362114,0.32931505761961155,-0.6645727582465208
336.0000000000041,39.023186788850886,0.35556031338594885,-0.6995713880009831
337.0000000000041,39.11961500501364,0.3823632619025242,-0.7326501908577843
338.0000000000041,39.21485756554001,0.40930957407726026,-0.7679820323814024
339.0000000000041,39.311959484368735,0.43499411927040715,-0.8037011718399443
340.0000000000041,39.408392559728846,0.46315117618495705,-0.8427175666451481
341.00000000000415,39.50573263058139,0.49388827729122126,-0.881198907368852
342.00000000000415,39.60212796137133,0.5219113682739691,-0.9239170231141225
343.00000000000415,39.69871576339789,0.5546444950282159,-0.9668803185945563
344.0000000000042,39.79573134852098,0.5839693398714016,-1.0101306791531344
345.0000000000042,39.893230167183475,0.6178995189952563,-1.058177240277741
346.0000000000042,39.98965583016735,0.6491525153629202,-1.1049913393110677
347.0000000000042,40.08709782656826,0.6839720292597062,-1.1574545762424013
348.0000000000042,40.18343431777234,0.7177848237919819,-1.206516552109647
349.00000000000426,40.28130222302319,0.7543475694020445,-1.263495883452431
350.00000000000426,40.37829418198144,0.7914150809464645,-1.3189589164638669
351.00000000000426,40.475450434424054,0.8281447203851652,-1.3776007849886591
352.0000000000043,40.572303893511666,0.8636841028849346,-1.4391779430442067
353.0000000000043,40.669070112105125,0.8995574737965301,-1.5000184482409171
354.0000000000043,40.76596173741073,0.9359134004425229,-1.56621784755687
355.0000000000043,40.864619751842355,0.970626422805729,-1.6329786379328435
356.0000000000043,40.96113066607946,1.0031743235147221,-1.701868117907888
357.0000000000044,41.058754783864394,1.0328436413170596,-1.7721892728715254
358.0000000000044,41.154461535917335,1.0627026239928914,-1.8425443595231656
359.0000000000044,41.25156547284583,1.0856214178538972,-1.9168701984319099
360.00000000000443,41.350581954871906,1.1054001694610776,-1.990900194013066
361.00000000000443,41.44786426190791,1.121816547243226,-2.069509842929233
362.00000000000443,41.544720340559664,1.1289248103270457,-2.1436391094213114
363.00000000000443,41.64149031555704,1.1293157991302731,-2.219236458127262
364.00000000000443,41.7389782199501,1.122909081873577,-2.296437495991118
365.0000000000045,41.8362286143955,1.1065499428450762,-2.3721706995552747
366.0000000000045,41.93313593369441,1.0833959610793054,-2.4475327732343155
367.0000000000045,42.028975725877224,1.051498152487041,-2.518505859622536
368.00000000000455,42.12657939869292,1.0132376774795346,-2.591382597875386
369.00000000000455,42.22336688123968,0.9683364411737961,-2.659329203107724
370.00000000000455,42.31906311000184,0.9164193161224361,-2.725617329333774
371.00000000000455,42.41662465679225,0.8552493029822392,-2.788657545783271
372.00000000000455,42.51172987486609,0.79068556800988,-2.846811425883474
373.0000000000046,42.60806658793274,0.7186174423312426,-2.90554195367201
374.0000000000046,42.70479679838118,0.6416451746624097,-2.957289549316108
375.0000000000046,42.801222552125076,0.55879853201476,-3.0048788058861
376.00000000000466,42.8978975403251,0.46956238250254945,-3.0501415892828265
377.00000000000466,42.99337914913818,0.38094324677391406,-3.089944917717994
378.00000000000466,43.08963380649906,0.29163186219492515,-3.1261246678157866
379.00000000000466,43.18529822906828,0.1985483852321404,-3.154582203511808
380.00000000000466,43.28216620319284,0.11173395270228297,-3.1831933466184976
381.0000000000047,43.37774254142146,0.029184854802886764,-3.2032617474076286
382.0000000000047,43.473315831438605,-0.047579830565827264,-3.2218948850789317
383.0000000000047,43.56887528402201,-0.11408912686177185,-3.2358161690975984
384.0000000000048,43.66629962162063,-0.17654112919257753,-3.2458209157455378
385.0000000000048,43.76198082268531,-0.22360772557176367,-3.2553362909059267
386.0000000000048,43.858684563665626,-0.2612005611058325,-3.2606409343223306
387.0000000000048,43.95399271035758,-0.288318862071214,-3.266965775209654
388.0000000000048,44.0501131563234,-0.3063704945176811,-3.269680495897889
389.00000000000483,44.14767016347812,-0.3188842725355308,-3.2722965870557315
390.00000000000483,44.243239113771374,-0.32274768712445323,-3.274904507380705
391.00000000000483,44.34114155783516,-0.324847566906206,-3.2771924642339263
392.0000000000049,44.435969595763936,-0.32587061218594243,-3.2790456765865654
393.0000000000049,44.53301827993439,-0.32415594996287256,-3.280264449092856
394.0000000000049,44.6305464240619,-0.3205558583037602,-3.2826166215268744
395.0000000000049,44.72593073610787,-0.3097817302113009,-3.2852146547543235
396.0000000000049,44.823207018217964,-0.3024950009804506,-3.2866395109864164
397.00000000000495,44.91974717685118,-0.2977450852796748,-3.287917834724445
398.00000000000495,45.01645283081587,-0.2928321760908465,-3.2869083788501383
399.00000000000495,45.11391604430458,-0.29140631896237174,-3.289843769681032
400.000000000005,45.21083462947722,-0.29094678182766676,-3.289768849358683
401.000000000005,45.30846970968274,-0.2882255372888693,-3.2910743622714866
402.000000000005,45.40483595361329,-0.2860236196858406,-3.2933907646291836
403.000000000005,45.50294970307364,-0.2827520621488804,-3.294694351417207
404.000000000005,45.599072272950515,-0.2809523100006362,-3.296029339077312
405.00000000000506,45.697006503564346,-0.2793988179264735,-3.2973519219539
406.00000000000506,45.794205873606494,-0.27772154652476316,-3.2986374089243427
407.00000000000506,45.891626692578484,-0.27485730723197144,-3.2999682842409275
408.0000000000051,45.989275923574986,-0.27385248289578573,-3.2999797876043053
409.0000000000051,46.0865865333874,-0.2723368663318124,-3.3023908202213224
410.0000000000051,46.183243894591264,-0.2700018712775544,-3.3026099025784026
411.0000000000051,46.28047393735741,-0.26880571236085044,-3.303916707560644
412.0000000000051,46.378852491429626,-0.26628578840284106,-3.3039299543742713
413.0000000000052,46.47545672067838,-0.2646957723348297,-3.3052714166495827
414.0000000000052,46.571933696810575,-0.2624183551124404,-3.306566879793576
415.0000000000052,46.671551496193906,-0.26168814092681336,-3.307880094332171
416.00000000000523,46.769068572654405,-0.2601770615640667,-3.309200221895873
417.00000000000523,46.866484155482325,-0.25897243454587743,-3.310131417412278
418.00000000000523,46.964321173277696,-0.25583704343802277,-3.3107995370419037
419.00000000000523,47.06179445886143,-0.25445936995657326,-3.3122838638189425
420.00000000000523,47.158981948226675,-0.2523361903666356,-3.313479957028993
421.0000000000053,47.256404777302215,-0.24918711210750105,-3.312869847231766
422.0000000000053,47.35333657823031,-0.24675835404895585,-3.316185599923359
423.0000000000053,47.45200690150241,-0.2459130222106832,-3.314786333265673
424.00000000000534,47.546886832305574,-0.24445660042099596,-3.3161541821033684
425.00000000000534,47.64685244521421,-0.24282021205601964,-3.318785581223281
426.00000000000534,47.74465499887829,-0.23902105948523353,-3.320070650499317
427.00000000000534,47.84279782194248,-0.23796317366130595,-3.31975406524181
428.00000000000534,47.939563010125006,-0.23521396795246757,-3.320069844856148
429.0000000000054,48.03760993298832,-0.23329518442541355,-3.321399539746906
430.0000000000054,48.135997857536786,-0.23161068332382612,-3.3237014281479826
431.0000000000054,48.23421798313613,-0.23002226688300142,-3.323683591641424
432.00000000000546,48.33185745733753,-0.22872717928970004,-3.323696102257118
433.00000000000546,48.42906655071015,-0.2278558962030116,-3.325001546841455
434.00000000000546,48.52852861607532,-0.22398523904561898,-3.3270141712065913
435.00000000000546,48.62689419640164,-0.22119843235517464,-3.3279701255137244
436.00000000000546,48.72499643421937,-0.21794527062770833,-3.3293802220326736
437.0000000000055,48.82247120328335,-0.21654434198412323,-3.3292967557782043
438.0000000000055,48.920916878792866,-0.21347240372006376,-3.3306110022086752
439.0000000000055,49.01887127172333,-0.21288380647842206,-3.3332273480973114
440.00000000000557,49.116656996610985,-0.20956218532401333,-3.3319211955242327
441.00000000000557,49.214953258452766,-0.2073894498941709,-3.333246774104949
442.00000000000557,49.31066536165207,-0.20465953647255267,-3.335228981664635
443.00000000000557,49.41092618090222,-0.20257002854411113,-3.336843998238364
444.00000000000557,49.50795094730261,-0.20229570950459203,-3.3372036676677475
445.0000000000056,49.60665226620829,-0.19890752157645492,-3.338076063106251
446.0000000000056,49.70441480569607,-0.1955739551953614,-3.3381801397450217
447.0000000000056,49.802451065860886,-0.19374887085474307,-3.3381802241356184
448.0000000000057,49.89897507642734,-0.19222530429910184,-3.3394992821721488
449.0000000000057,49.998185515041655,-0.18963668610969023,-3.340819911995449
450.0000000000057,50.09682864207162,-0.1877296045887495,-3.3421288741318387
451.0000000000057,50.19380624791279,-0.18423382332059834,-3.3434633590567127
452.0000000000057,50.29158038497439,-0.1821894051715591,-3.342127409065388
453.00000000000574,50.38974346602088,-0.17981894236431895,-3.3447709962812158
454.00000000000574,50.48576716809717,-0.177617089162851,-3.3460946998155205
455.00000000000574,50.58547135205254,-0.1743171334256875,-3.345430054213932
456.0000000000058,50.68339652317091,-0.17311848510703895,-3.3472468958399766
457.0000000000058,50.782879696665574,-0.1702018117020408,-3.3485632194185113
458.0000000000058,50.880904402750154,-0.16858376372990655,-3.348167837193735
459.0000000000058,50.9802014786089,-0.16784357828273275,-3.349490429188828
460.0000000000058,51.07871873805723,-0.16475140672927524,-3.3508100374619056
461.00000000000585,51.17599198605565,-0.16073542475982033,-3.3521127942088684
462.00000000000585,51.27485893495957,-0.15871666261747774,-3.352411863006812
463.00000000000585,51.372814640714815,-0.1560660482176298,-3.3547603076564805
464.0000000000059,51.4720676546152,-0.15288125792794036,-3.3547600249858247
465.0000000000059,51.57069724768973,-0.15142059717766815,-3.3560874204230196
466.0000000000059,51.66869533232898,-0.1471810726531409,-3.3568037438477063
467.0000000000059,51.76673841272982,-0.14557325837008034,-3.3567300612024544
468.0000000000059,51.86628833417217,-0.14442353300089936,-3.3580485649152076
469.00000000000597,51.96247445644355,-0.14189675909809704,-3.3580499583653634
470.00000000000597,52.06221644437238,-0.1382618247213333,-3.3593648545952624
471.00000000000597,52.16246096880304,-0.13649314680924482,-3.360690156391609
472.000000000006,52.25947481175873,-0.1353519388372566,-3.3606916204653023
473.000000000006,52.35867741887962,-0.13155027251679863,-3.361999949358305
474.000000000006,52.456661921893684,-0.13010113373406215,-3.363303324183615
475.000000000006,52.55511900943042,-0.12670543650500368,-3.3636178756660975
476.000000000006,52.65507358410631,-0.12534104782314962,-3.3640183879757837
477.0000000000061,52.75355824362345,-0.12270334130360247,-3.3652200467390094
478.0000000000061,52.852094341598814,-0.11918006004700218,-3.365289695085437
479.0000000000061,52.95063971652983,-0.1172704556694919,-3.366609870194094
480.00000000000614,53.04964015170999,-0.11648244955613367,-3.366939903381307
481.00000000000614,53.1480192246876,-0.11506588639455934,-3.3678661002459096
482.00000000000614,53.24629360674772,-0.11250632813046048,-3.3699275991906164
483.00000000000614,53.34488284562258,-0.10940734488203797,-3.369233773563886
484.00000000000614,53.44226562381782,-0.10801540548843204,-3.370560176126056
485.0000000000062,53.54201178140892,-0.10705798491300138,-3.3719192965303337
486.0000000000062,53.6399949055189,-0.10440512052409127,-3.3718838936678366
487.0000000000062,53.73877764818138,-0.1033560348562505,-3.372540018458471
488.00000000000625,53.83818784414794,-0.09993224086203571,-3.3751839741272267
489.00000000000625,53.9369001553445,-0.09724952384670468,-3.3751799118167707
490.00000000000625,54.03566104305933,-0.09556122533408219,-3.3764909120753126
491.00000000000625,54.135072096148306,-0.09413336690376631,-3.376528659792657
492.00000000000625,54.23397854376568,-0.09266916218874824,-3.376489937083111
493.0000000000063,54.33380946398523,-0.09160486535924882,-3.3778136629632134
494.0000000000063,54.432036277619915,-0.08932144090570292,-3.379129834902642
495.0000000000063,54.531577629505954,-0.0873078413811409,-3.378144607887701
496.00000000000637,54.62958229279085,-0.08603125503192006,-3.3781393678426084
497.00000000000637,54.728521371128075,-0.08294218710125092,-3.3794528945765494
498.00000000000637,54.829593057660986,-0.08121751534425392,-3.380439902114789
499.00000000000637,54.92841462739619,-0.07945796367289201,-3.3804399052199074
500.00000000000637,55.02648440536575,-0.07776708968914187,-3.3817604630029465
501.0000000000064,55.12547387520544,-0.07690066870836632,-3.3819814852849195
502.0000000000064,55.224292586709005,-0.07508060574917545,-3.383085204231916
503.0000000000064,55.32320687301008,-0.0723030918872172,-3.3830516846053076
504.0000000000065,55.42240761282434,-0.07041835576699097,-3.3843991181985045
505.0000000000065,55.52124788200095,-0.06896143398295282,-3.3857150227271964
506.0000000000065,55.62006611596008,-0.06763380264937187,-3.3857101226854835
507.0000000000065,55.71704774151702,-0.0674198951490134,-3.3870324190864927
508.0000000000065,55.818773923601185,-0.06642638888297414,-3.387030059758596
509.00000000000654,55.91723963850297,-0.06550967413249989,-3.3868911980590397
510.00000000000654,56.015961485446766,-0.06472524546828602,-3.387368791680471
511.00000000000654,56.115224337057676,-0.06373679395195944,-3.3883365933137357
512.0000000000066,56.21453466367594,-0.06582199570803315,-3.3885387139815437
513.0000000000066,56.31264940174962,-0.06482079854641223,-3.389971350009222
514.0000000000066,56.41214641547578,-0.06331820698097645,-3.390979972377754
515.0000000000066,56.5112026076575,-0.06360808193537333,-3.3909403791557216
516.0000000000066,56.61072823766008,-0.06202907580870257,-3.3909940001206973
517.0000000000066,56.70906423536553,-0.061956843347796095,-3.3923101440216974
518.0000000000066,56.80865563595233,-0.06084110730927053,-3.392310145048775
519.0000000000066,56.90711504386409,-0.05879194700825083,-3.3923353437097408
520.0000000000067,57.00684944609426,-0.05736659829299256,-3.3945963979667475
521.0000000000067,57.10575952604281,-0.05581035452090474,-3.394610040299492
522.0000000000067,57.2038935139701,-0.05497623709203567,-3.3943449519611955
523.0000000000067,57.3054918592255,-0.052788407186065305,-3.394609809731678
524.0000000000067,57.403054843534946,-0.05168058034133104,-3.3946098099965396
525.0000000000068,57.50260306893597,-0.04865822330682581,-3.394605731356206
526.0000000000068,57.60265335602976,-0.04818314987171569,-3.3958980792861704
527.0000000000068,57.7016185584126,-0.04681435906241798,-3.3958964074191953
528.0000000000068,57.802561241930896,-0.04275594322710709,-3.3968532892366934
529.0000000000068,57.901434639002986,-0.03976111671269298,-3.3972500044784892
530.0000000000068,58.00151217138493,-0.03825166707063752,-3.397777218807655
531.0000000000068,58.09974725625596,-0.038510096734585976,-3.3985724405737323
532.0000000000068,58.199766927220665,-0.037628038812703456,-3.399880075771403
533.0000000000068,58.29834008613002,-0.03378914970592478,-3.399892058000889
534.0000000000068,58.3985424378181,-0.03348966265090908,-3.4011999705703237
535.0000000000068,58.497078078413665,-0.031228655896466936,-3.4012543925130276
536.0000000000069,58.5958872411047,-0.02872828270278553,-3.399887190244377
537.0000000000069,58.69608988120254,-0.027177219570407737,-3.402423988523747
538.0000000000069,58.79530588849268,-0.024436954419569123,-3.4022242746891473
539.0000000000069,58.894955675126425,-0.021454921171330445,-3.4010634744213233
540.0000000000069,58.99276623139739,-0.020814845632399655,-3.4024013842227845
541.000000000007,59.092977637300486,-0.017723194821943927,-3.4024110609922467
542.000000000007,59.193763583817905,-0.01596801249041107,-3.403719951253052
543.000000000007,59.292256517395586,-0.012920748821570575,-3.4023992813386195
544.000000000007,59.39151876461302,-0.009391731699569571,-3.403719976086337
545.000000000007,59.49096741924475,-0.0073758302928204076,-3.4037199349977563
546.000000000007,59.590627187394574,-0.005895746473446265,-3.403718859570885
547.000000000007,59.689449107601476,-0.001176698752529964,-3.4050399126706212
548.000000000007,59.78917000000068,-0.00047554830001108434,-3.405443484443338
549.000000000007,59.888074673376096,0.0038596910277192984,-3.4053701301162604
550.000000000007,59.988324868967275,0.007517453517957488,-3.405635408184155
551.000000000007,60.08718850108169,0.010981837634037577,-3.408006388117795
552.0000000000072,60.188136254101124,0.012412473466231724,-3.4066799077629017
553.0000000000072,60.287781499103566,0.016248832513410194,-3.4079942463531445
554.0000000000072,60.387503720900945,0.01761039313207259,-3.40832992819702
555.0000000000072,60.4860289203946,0.020924797564995542,-3.4083301241698987
556.0000000000072,60.58404344816706,0.025085131060181322,-3.409320318653682
557.0000000000073,60.68562225972751,0.030116868370242973,-3.410308533812158
558.0000000000073,60.78434059819895,0.032982110278095424,-3.410309914997304
559.0000000000073,60.884450536235235,0.03550905997934955,-3.41031057158464
560.0000000000073,60.983040261781994,0.038268241129150685,-3.411609718704372
561.0000000000073,61.08299673276893,0.04223247253894007,-3.410960163520274
562.0000000000073,61.182998879217635,0.04477768073663581,-3.412283059270777
563.0000000000073,61.28262933510521,0.046987590852398765,-3.412284960400111
564.0000000000073,61.38273283038001,0.05122052285323329,-3.4122773400541373
565.0000000000073,61.48155109081213,0.05408151774534039,-3.413600045097107
566.0000000000073,61.58091317876522,0.05821799910366552,-3.4109744822866213
567.0000000000074,61.68166128656922,0.06081854113240078,-3.4122397019729025
568.0000000000074,61.78210066318922,0.06409627209845407,-3.414588377835693
569.0000000000074,61.88209574945455,0.06970877562179757,-3.4132802340055504
570.0000000000074,61.981859222087756,0.0723766978433194,-3.4145913573369766
571.0000000000074,62.08137533932331,0.07724969933006141,-3.415900044080228
572.0000000000074,62.180769552446016,0.07950728817468444,-3.4159078911628873
573.0000000000074,62.2812950598207,0.08443548925780296,-3.4145906890755264
574.0000000000075,62.380161882231974,0.0864633149956604,-3.415250346511713
575.0000000000075,62.47971219975688,0.09064518537190945,-3.4159098931789758
576.0000000000075,62.58042997766107,0.09466567713867077,-3.415909343460668
577.0000000000075,62.68002061984305,0.09902356419651463,-3.4169009086545215
578.0000000000075,62.78007107947982,0.10448871555646891,-3.4169001427737076
579.0000000000075,62.87974327905322,0.10778231552091516,-3.4172296857750837
580.0000000000075,62.97987040951535,0.11092624601681823,-3.418550111798093
581.0000000000075,63.079170000000865,0.115890000000095,-3.4185501149999986
582.0000000000075,63.17777812922461,0.12270576810626177,-3.41908464672804
583.0000000000076,63.278851772405204,0.12698970616769714,-3.418813866314659
584.0000000000076,63.37927216310986,0.13138193000123446,-3.4188690698744173
585.0000000000076,63.479259159955774,0.13722584034432275,-3.4201901847389586
586.0000000000076,63.57830291414672,0.1408297360365212,-3.420190185000007
587.0000000000076,63.67896775767335,0.14797103062932138,-3.42019018546365
588.0000000000076,63.778753574945306,0.15082181237502798,-3.4205191547817737
589.0000000000076,63.87960515669091,0.15431284932322278,-3.4205282721115458
590.0000000000077,63.979377354544454,0.1591952487898607,-3.420187859841869
591.0000000000077,64.07937201284152,0.16364654619532554,-3.4198600815078155
592.0000000000077,64.17878945489646,0.16801750352946326,-3.421180013044893
593.0000000000077,64.27876709459449,0.17273495395669533,-3.4223420636082373
594.0000000000077,64.37990722146283,0.1775155061173835,-3.422501025566987
595.0000000000077,64.4794711126345,0.18169990000686279,-3.4238120783862076
596.0000000000077,64.57897356664154,0.18713292053858696,-3.4224902072006658
597.0000000000077,64.67833706458264,0.19133172392946476,-3.4224923744162625
598.0000000000077,64.77820810239301,0.1976260664462838,-3.424381797162631
599.0000000000078,64.87732961502422,0.2019708677427699,-3.424800016498299
600.0000000000078,64.97896205835862,0.20694614541293513,-3.423812738066518
601.0000000000078,65.07801043650764,0.20994117668598028,-3.4234799761482235
602.0000000000078,65.17840182371235,0.21577233903017184,-3.424836270522863
603.0000000000078,65.27827089069794,0.22086700667613107,-3.4241414546648845
604.0000000000078,65.3782188349477,0.2253827698440512,-3.4256116117586357
605.0000000000078,65.477700401374,0.22952530722306308,-3.424151995240741
606.000000000008,65.57790293068828,0.23765907545559678,-3.4241508632288222
607.000000000008,65.67820516142298,0.24163398669256983,-3.426766387566912
608.000000000008,65.77926520662812,0.247896274001745,-3.4271067223718727
609.000000000008,65.87848104593832,0.25422603037666347,-3.4267816591216516
610.000000000008,65.97958012017693,0.2597352588495484,-3.4261208830082817
611.000000000008,66.07821099914979,0.26461984957133794,-3.42776000604445
612.000000000008,66.17880236709954,0.26768859581028304,-3.4277601610669057
613.000000000008,66.27945356386263,0.27270814489322887,-3.427441481226551
614.000000000008,66.37838256834884,0.2777987867166494,-3.428415096283347
615.0000000000081,66.47823957677862,0.2836859183677132,-3.4271102850474007
616.0000000000081,66.57896711259276,0.288583621216913,-3.427109980000668
617.0000000000081,66.67855338966629,0.2924657331466545,-3.4271099763704176
618.0000000000081,66.77806504697175,0.2998656775501316,-3.42744165459862
619.0000000000081,66.87874073976253,0.30562125263742257,-3.430073198360261
620.0000000000081,66.97832943797258,0.31128564720980934,-3.4303692215916755
621.0000000000081,67.0783931619859,0.31776404051257623,-3.4310490447184323
622.0000000000082,67.17887601398748,0.32130283953044714,-3.4287593354490795
623.0000000000082,67.27886613936997,0.3276176939378241,-3.430070121517745
624.0000000000082,67.3791700000008,0.3319500000000302,-3.4300701249999994
625.0000000000082,67.47973181388376,0.33786252674545914,-3.4300700733271015
626.0000000000082,67.5789732319522,0.3423885879820206,-3.431390027577348
627.0000000000082,67.6791700000009,0.3485700000000949,-3.4310685103335827
628.0000000000082,67.77990347112423,0.35295084399717136,-3.431060020057742
629.0000000000082,67.88039913705327,0.36081525940789727,-3.4310952261818506
630.0000000000082,67.98053068934362,0.3653038146169553,-3.431055578175854
631.0000000000083,68.08096173502327,0.3692536045122175,-3.4310600732141916
632.0000000000083,68.18123011407252,0.3770140604709741,-3.432380301058987
633.0000000000083,68.28127820385023,0.38145130084021495,-3.43170090876984
634.0000000000083,68.38095111985187,0.38561686592545685,-3.431714016629881
635.0000000000083,68.48141651664697,0.3922883731947654,-3.432710135370172
636.0000000000083,68.58124046173663,0.39797333164877735,-3.4330328989812027
637.0000000000083,68.68208869845371,0.40415811235530136,-3.433369943883278
638.0000000000084,68.78311548018509,0.4097462475402908,-3.434347973965266
639.0000000000084,68.88241194489133,0.4145743582093114,-3.4340199505867584
640.0000000000084,68.98404889159677,0.4223723802941897,-3.434027295393622
641.0000000000084,69.08490213459139,0.42754492944428446,-3.433595551256886
642.0000000000084,69.18609216717628,0.4339453285338055,-3.434020115058325
643.0000000000084,69.28511413459968,0.4385283515401353,-3.434019987564961
644.0000000000084,69.38686517855234,0.44276596325324447,-3.4336501610795938
645.0000000000084,69.48826565868487,0.44935790590842606,-3.435010179178022
646.0000000000084,69.58705752081563,0.45594765794704006,-3.435010179801385
647.0000000000085,69.6877952814878,0.4637388190775868,-3.433698507409287
648.0000000000085,69.78827379839188,0.4658148483344598,-3.435338454387699
649.0000000000085,69.889264270619,0.47081889188700693,-3.4353401807679655
650.0000000000085,69.98998108059584,0.4765580014717889,-3.4348901300323136