File: 01_Data/Cotton_Sheet/STA/N2/10K_min/Cotton_Sheet_STA_N2_10KData_220719_R3.csv
##Temp./Â°C,Time/min,DSC/(mW/mg),Mass loss/mg
50.0,10.670197122273487,-1.3649317759889694,-0.052108374906775445
51.000000000000014,10.986953910064774,-1.2686268122762745,-0.05262709462091575
52.00000000000003,11.197362865500844,-1.2089821108978231,-0.05516559622798578
53.00000000000004,11.368649550689451,-1.162579232834338,-0.05418251621896086
54.00000000000006,11.518917900353493,-1.127206985885828,-0.05346027494790473
55.00000000000007,11.656653663225546,-1.0996227717801708,-0.055462115825529956
56.000000000000085,11.78677225755425,-1.0756473146741725,-0.056147796945519524
57.0000000000001,11.911319269591447,-1.0556887246397682,-0.05698922790603422
58.000000000000114,12.030232218037703,-1.038698671329572,-0.056378502608450454
59.00000000000013,12.148330000000012,-1.0233299999999965,-0.056000568390365046
60.00000000000014,12.263822732469764,-1.010007810469404,-0.057378284322116
61.000000000000156,12.37569064384726,-0.9986679948688735,-0.0575295162385876
62.00000000000017,12.487872818408274,-0.9876472823012483,-0.058750121314187
63.000000000000185,12.600447257001896,-0.9759539232692693,-0.05874602983640731
64.0000000000002,12.707603331975086,-0.9656987308505129,-0.05863252737879243
65.00000000000021,12.81980046889692,-0.9555523970918016,-0.06003416982841614
66.00000000000023,12.926427654390768,-0.945832743964117,-0.06091489431235342
67.00000000000024,13.035651872004228,-0.9361049864568798,-0.06224797270060467
68.00000000000026,13.141190980465398,-0.9258726906914576,-0.06269326802773456
69.00000000000027,13.249128403709618,-0.9179315967799102,-0.06400351107445434
70.00000000000028,13.355481825327828,-0.908940121798575,-0.06427093991396582
71.0000000000003,13.461581777498141,-0.9006780578937124,-0.06532080379206118
72.00000000000031,13.56798829880793,-0.8913307417424973,-0.06632875378830327
73.00000000000033,13.673862535723103,-0.8830467874838026,-0.06664316038831597
74.00000000000034,13.77871448922454,-0.8742627110213816,-0.06728984863477283
75.00000000000036,13.884142378553898,-0.8670762197785153,-0.06728523519567986
76.00000000000037,13.988800763182239,-0.8582248063045248,-0.0679770212565245
77.00000000000038,14.091882358474429,-0.8495699245671987,-0.07060946181645189
78.0000000000004,14.196350569138176,-0.8446483262226618,-0.07005040115183636
79.00000000000041,14.30043619912001,-0.8365677937895275,-0.07058995015172176
80.00000000000043,14.402370109610878,-0.8314402400301635,-0.07193019117532806
81.00000000000044,14.506153016853194,-0.8259813309009674,-0.0725787045558759
82.00000000000045,14.609201225605588,-0.8199147871164822,-0.07299852124944195
83.00000000000047,14.71082912000804,-0.8133883655749072,-0.07338961941587652
84.00000000000048,14.813422253921981,-0.8090256093729095,-0.07486225567126015
85.0000000000005,14.914646545295339,-0.8047295771393087,-0.07513376107323344
86.00000000000051,15.015382513235082,-0.7981460535710979,-0.07588348949028711
87.00000000000053,15.116689128603209,-0.7941139179709173,-0.07718005863233479
88.00000000000054,15.215240160596155,-0.7916974118925906,-0.0784892243070594
89.00000000000055,15.317626922998011,-0.7871817409447152,-0.07846030437463059
90.00000000000057,15.417700121109608,-0.7841759704749217,-0.07872919350933483
91.00000000000058,15.517667573035165,-0.7807396351670949,-0.0798073186981143
92.0000000000006,15.61713327771963,-0.7777868122042066,-0.08168971239636269
93.00000000000061,15.715209215899758,-0.7775393762198028,-0.08243617448622809
94.00000000000063,15.815473332560012,-0.7753707367254152,-0.08241768775968161
95.00000000000064,15.914815026223202,-0.7731476168542918,-0.08376017761662036
96.00000000000065,16.013242369261697,-0.7714433382242116,-0.08441357444745945
97.00000000000067,16.110296080141264,-0.7696673455961676,-0.0845237584266445
98.00000000000068,16.211630555773187,-0.768440199025091,-0.08500784930059213
99.0000000000007,16.310882701675066,-0.767066435652167,-0.08639932258424565
100.00000000000071,16.408008161874303,-0.7641495352931869,-0.08640008864786086
101.00000000000072,16.50661590655884,-0.7623193003849759,-0.0873917846536374
102.00000000000074,16.603091005761293,-0.7610823191412843,-0.08725897026568097
103.00000000000075,16.703456910201254,-0.7578398284571335,-0.0891193286827403
104.00000000000077,16.800675355376498,-0.7570718912300192,-0.08904017795656483
105.00000000000078,16.8982329016856,-0.7552161206982378,-0.08837895257372974
106.0000000000008,16.99373762768354,-0.7523198894685115,-0.08904785984488539
107.00000000000081,17.093040620257202,-0.7514415720702466,-0.08771207066504916
108.00000000000082,17.190523133653866,-0.7503818201640149,-0.08851359964127026
109.00000000000084,17.28862950246631,-0.7476263973201991,-0.08969997386187689
110.00000000000085,17.385963571806677,-0.7458817714843511,-0.08940057014587888
111.00000000000087,17.483769808032292,-0.7427585081899954,-0.09175781118952253
112.00000000000088,17.580889691948027,-0.7403548377864555,-0.0912344930344724
113.0000000000009,17.677218712870122,-0.7382342529981147,-0.09123994980450956
114.00000000000091,17.775682495053747,-0.7366557216182757,-0.0898742391371985
115.00000000000092,17.872271024971905,-0.7325320897130069,-0.08987426542485277
116.00000000000094,17.96945693512308,-0.7305273087632683,-0.09057105736688387
117.00000000000095,18.068435771780628,-0.7266955084109538,-0.09193190653013072
118.00000000000097,18.16299635616548,-0.7253251933877176,-0.09189281048168585
119.00000000000098,18.263667764660088,-0.7204123092514615,-0.09123100702547315
120.000000000001,18.361360157810516,-0.7168052743453902,-0.09216738249715029
121.00000000000101,18.457691290237353,-0.7126377254588068,-0.09218361382052498
122.00000000000102,18.55527363861529,-0.7097067496685892,-0.09182830890343396
123.00000000000104,18.65274955877306,-0.7056278476704393,-0.09249547913286049
124.00000000000105,18.749573820982,-0.7026211242425915,-0.09337112498565991
125.00000000000107,18.84618060623962,-0.6989853680918325,-0.09387010605500956
126.00000000000108,18.943924858725644,-0.6949876850353703,-0.09254079637668422
127.0000000000011,19.038433756848477,-0.6909546319475269,-0.09254921246229131
128.0000000000011,19.139251841153904,-0.6885568662809929,-0.09254670008731214
129.00000000000114,19.23476354358312,-0.684544967606157,-0.09385989715512011
130.00000000000114,19.330835025725996,-0.6789646071434909,-0.09376052939862456
131.00000000000114,19.427459025254187,-0.6745695425797071,-0.092536363171424
132.00000000000117,19.52542396854209,-0.6723047921424358,-0.09484632597643738
133.0000000000012,19.622203723312,-0.6677229447937955,-0.09388624152427161
134.0000000000012,19.71805050679527,-0.6644709333592234,-0.09386245200058108
135.0000000000012,19.814358552685615,-0.6609872831557179,-0.09386987878310205
136.00000000000122,19.909680922914124,-0.6570551016308828,-0.09519007271952562
137.00000000000125,20.007372636792052,-0.6547691662729951,-0.09518987205525642
138.00000000000125,20.103602968903598,-0.649021270421441,-0.0939401755570235
139.00000000000125,20.199774366620037,-0.6469920423367989,-0.09517995141003865
140.00000000000128,20.296143529002258,-0.6421274551367115,-0.09388415911313608
141.0000000000013,20.39390740068952,-0.6381896212863604,-0.09510880613153017
142.0000000000013,20.489722493108776,-0.6339999072880882,-0.09518006869588813
143.0000000000013,20.584954145838772,-0.6307776727746625,-0.09518007790143157
144.00000000000134,20.681435969045218,-0.6277018216585724,-0.0964977085487333
145.00000000000136,20.7785309098663,-0.6238999025710755,-0.09650007000661365
146.00000000000136,20.875004238576704,-0.6190709063325991,-0.09517001375064194
147.00000000000136,20.97108796473283,-0.6142956797324561,-0.09519008981752464
148.0000000000014,21.067648680474065,-0.6114683632349538,-0.09519003498819956
149.00000000000142,21.16317852788807,-0.606731601196613,-0.09518278636486466
150.00000000000142,21.25784103503956,-0.6041250647047594,-0.09615264002363544
151.00000000000142,21.35460932614106,-0.5997682758692461,-0.09589059896097352
152.00000000000145,21.451251745934158,-0.5938950289504649,-0.09648861459853553
153.00000000000148,21.546826636470705,-0.5910137238684743,-0.09650015815349455
154.00000000000148,21.642699208328626,-0.5875558279528981,-0.09518184119652506
155.00000000000148,21.738232594920664,-0.5844100204353919,-0.09518309631544142
156.0000000000015,21.83435257238685,-0.5786482167863868,-0.09649984245848753
157.00000000000153,21.92882740837078,-0.5755422124185446,-0.09649930521112937
158.00000000000153,22.025704068755267,-0.5732546926773944,-0.09779654656995396
159.00000000000153,22.12077483521162,-0.5684562959019517,-0.09649990020156185
160.00000000000156,22.217312575568297,-0.5645296449034984,-0.0977979475010251
161.0000000000016,22.31304001158081,-0.5599513069212463,-0.09780992505765074
162.0000000000016,22.408776889759704,-0.5574062943780338,-0.09782239195714393
163.0000000000016,22.502566237289624,-0.5529473937511961,-0.09783842706525903
164.00000000000162,22.60087150616323,-0.5482573500562595,-0.09749089238056774
165.00000000000165,22.69546918466754,-0.546326074641153,-0.09749018297764955
166.00000000000165,22.79073316809371,-0.5408667950890933,-0.09881633993722438
167.00000000000165,22.886740693786727,-0.5368541104349995,-0.09889917668332515
168.00000000000168,22.982718823932824,-0.534532918759012,-0.09815880493566187
169.0000000000017,23.077676102435152,-0.5301926641609761,-0.09715978305472284
170.0000000000017,23.174535783129866,-0.5263075594821365,-0.09715998999897879
171.0000000000017,23.266679254525105,-0.5227066529844729,-0.09716183579475679
172.00000000000173,23.365698595605654,-0.5193834906325006,-0.09846880628460664
173.00000000000176,23.46236047822162,-0.515151936664278,-0.09765492763412364
174.00000000000176,23.557498194699278,-0.512902500147449,-0.09847985789374336
175.00000000000176,23.65200859367507,-0.5085250606915059,-0.09847993391694754
176.0000000000018,23.74823465897813,-0.505751727115635,-0.09980102030854754
177.00000000000182,23.8443779252504,-0.5017634354164296,-0.09913695098289921
178.00000000000182,23.940429835007038,-0.4981128064897615,-0.09783250742414396
179.00000000000182,24.03654266701945,-0.4936764113556723,-0.09840882345493229
180.00000000000185,24.128455102754863,-0.4913928454154843,-0.09914011088509689
181.00000000000188,24.227450240081176,-0.4890898025521483,-0.09881118358213214
182.00000000000188,24.32119388072291,-0.4851820934030429,-0.09979990713039522
183.00000000000188,24.416309759682765,-0.4831340979639168,-0.09801196772688625
184.0000000000019,24.511975742702955,-0.48056656950269755,-0.09847620299585813
185.00000000000193,24.609048287173447,-0.4771750461678416,-0.09913227593277885
186.00000000000193,24.70387407551005,-0.4745987589310952,-0.09913992407781924
187.00000000000193,24.799391970087783,-0.47078011664956554,-0.09781980521989064
188.00000000000196,24.895191023506626,-0.46850241516608493,-0.09889694776945301
189.000000000002,24.990668145438537,-0.46341855375371444,-0.09962354792170158
190.000000000002,25.0857491219222,-0.46092406643707046,-0.10126095830522219
191.000000000002,25.18085674180572,-0.4570118558981573,-0.09891370944971012
192.00000000000202,25.273815774643044,-0.4542725170401126,-0.09890989856678312
193.00000000000205,25.372413942118712,-0.4514727798007645,-0.10023016006099628
194.00000000000205,25.46754553972499,-0.4466714916384903,-0.10023015372214861
195.00000000000205,25.56363389688228,-0.44459571839565937,-0.09880438201912511
196.00000000000207,25.65833000000021,-0.441119999999999,-0.09956999881487683
197.0000000000021,25.752930945280514,-0.43778264319220617,-0.1016017416134285
198.0000000000021,25.84823751668141,-0.43321463175288705,-0.1028521680759682
199.0000000000021,25.94301426207481,-0.43145811219444713,-0.10287378384901613
200.00000000000213,26.03882465876956,-0.42767235438690543,-0.10156004026957888
201.00000000000216,26.13272294481326,-0.4248177954255007,-0.10156002099949735
202.00000000000216,26.228035890885565,-0.42139638304888277,-0.10156002100000006
203.00000000000216,26.323828823915765,-0.41800018872662636,-0.10156002101778805
204.0000000000022,26.41871874448997,-0.4145652754826877,-0.10157018153347641
205.00000000000222,26.514054973505576,-0.4126058316348422,-0.10286999675648678
206.00000000000222,26.60850901635589,-0.409019669003936,-0.10287002099974307
207.00000000000222,26.704679385233746,-0.40629003327344526,-0.10286996237238943
208.00000000000225,26.80014238937467,-0.4030725949074904,-0.1041900589225686
209.00000000000227,26.89449767450858,-0.4017784882346945,-0.10418988721394484
210.00000000000227,26.989353790602106,-0.39756959424869714,-0.10320011188747547
211.00000000000227,27.081232348946667,-0.39378054219223496,-0.10450087132912378
212.0000000000023,27.179702229758327,-0.3908436736028774,-0.10452002035895713
213.00000000000233,27.27536429051684,-0.38872060993679797,-0.1045200210000008
214.00000000000233,27.37081540671818,-0.38466668654904207,-0.10452002082192546
215.00000000000233,27.465519169778727,-0.38148100509481864,-0.10452292585048051
216.00000000000236,27.56026853947786,-0.3793809357500711,-0.10584075453900033
217.0000000000024,27.655443876130274,-0.37503313158662566,-0.10646844725026083
218.0000000000024,27.750919670576582,-0.3727248014144467,-0.10780000159680192
219.0000000000024,27.845922443593068,-0.3686170442743203,-0.10780000005561785
220.00000000000242,27.941402090901416,-0.3670168629438584,-0.10872465714562685
221.00000000000244,28.036387574927467,-0.3640489284491917,-0.10847003025168878
222.00000000000244,28.131183899679673,-0.36206879147140625,-0.10749401815740667
223.00000000000244,28.226589594330505,-0.358334996691186,-0.1074800210140685
224.00000000000247,28.321807079636766,-0.3561635331236157,-0.10748115637243938
225.0000000000025,28.417744329852997,-0.35251489719574874,-0.10880018944262293
226.0000000000025,28.51254340785476,-0.3490108894747498,-0.10880002099828978
227.0000000000025,28.60750624002873,-0.3472958517761262,-0.10880005503278589
228.00000000000253,28.703086715799703,-0.34328996428664393,-0.10978165768723613
229.00000000000256,28.798586505308915,-0.34086261145002394,-0.11143038474312972
230.00000000000256,28.892925810558896,-0.33830824552833644,-0.1114301540214635
231.00000000000256,28.988330000000225,-0.33650999999999215,-0.11143010195659597
232.0000000000026,29.083665211293976,-0.3325964823902636,-0.11308109612359063
233.00000000000261,29.179042048512013,-0.3309775920026934,-0.11307990100529075
234.00000000000261,29.274640780897496,-0.3288503516692856,-0.11307990100006116
235.00000000000261,29.3692311180136,-0.32535515946294574,-0.11307990647556565
236.00000000000264,29.465410849670626,-0.3229614261847257,-0.11374332288008082
237.00000000000267,29.55939608590081,-0.3203818589578403,-0.11407218077370329
238.00000000000267,29.655236218891396,-0.31915243775763036,-0.11539028023634623
239.00000000000267,29.750151435624275,-0.31561332234058403,-0.11611607559938397
240.0000000000027,29.84611015509249,-0.3131202956775854,-0.1160398017444284
241.00000000000273,29.941036221696358,-0.31026349136860454,-0.11603980049956464
242.00000000000273,30.03423604300589,-0.30654585386597194,-0.11660476324874747
243.00000000000273,30.13115740615912,-0.30495259709624195,-0.11736011008488134
244.00000000000276,30.22595064222456,-0.3010207597450327,-0.11736010999980184
245.00000000000279,30.3212817666896,-0.2999909879046629,-0.11736171592598987
246.00000000000279,30.41698206082029,-0.29700371313402263,-0.11868011106576537
247.00000000000279,30.51167347928155,-0.294975687480987,-0.11930950082829206
248.0000000000028,30.607535364112266,-0.29271887911067274,-0.11905909576463536
249.00000000000284,30.703768228821065,-0.2900087854982441,-0.1193298729897374
250.00000000000284,30.79753268994906,-0.28835517658081633,-0.11932669607552793
251.00000000000284,30.894230529483742,-0.2854196015637063,-0.12131010566519862
252.00000000000287,30.98833000000029,-0.2821800000000031,-0.12131014636531168
253.0000000000029,31.083968579332613,-0.28096556751649326,-0.12131024707481908
254.0000000000029,31.177883398299652,-0.2784488196707119,-0.12262870958568417
255.0000000000029,31.275030160305064,-0.27754661807859676,-0.1237860666327153
256.00000000000296,31.369980659308073,-0.27497541233517087,-0.12394990714606369
257.00000000000296,31.461902137511135,-0.27384063428098554,-0.1252703661622223
258.00000000000296,31.5606734462572,-0.2701852165714322,-0.12522831858129635
259.00000000000296,31.65533098353145,-0.2681193580608456,-0.12810164049824424
260.00000000000296,31.75172295486136,-0.2664974605064846,-0.1281801731905574
261.000000000003,31.84709018769475,-0.26337206568922666,-0.12941308747974656
262.000000000003,31.941073888665063,-0.26184443735785995,-0.13074987188445686
263.000000000003,32.036149109802345,-0.2601427904861738,-0.130749880901599
264.00000000000307,32.13229674050111,-0.25830755838789254,-0.13067950524019967
265.00000000000307,32.22659923827251,-0.25689096312980797,-0.1307464652155632
266.00000000000307,32.323128580540526,-0.2546249425145089,-0.13201719682715263
267.00000000000307,32.4178890728846,-0.2514389600216731,-0.13338005458264846
268.00000000000307,32.514065917175635,-0.24866330967812422,-0.1347047146677145
269.0000000000031,32.60924890495876,-0.24689030283573768,-0.13470408403735412
270.0000000000031,32.70503627881536,-0.24455997849394315,-0.1360200483348626
271.0000000000031,32.8001454176968,-0.24036484106003408,-0.13734053730089713
272.0000000000032,32.89547557617304,-0.23843481399943328,-0.13734216537687027
273.0000000000032,32.99046645932753,-0.23408067071805827,-0.13865061030749048
274.0000000000032,33.087127136241286,-0.23209321309636327,-0.14030664404576854
275.0000000000032,33.18145678861757,-0.2275821531967537,-0.14199422018967844
276.0000000000032,33.277596244659705,-0.2245403679944144,-0.14195498889810798
277.00000000000324,33.373146954965186,-0.22114598941093436,-0.14326968338411872
278.00000000000324,33.47021023651253,-0.21575334413133831,-0.1453028859800698
279.00000000000324,33.564848973906024,-0.2137151580235852,-0.14784631363204426
280.0000000000033,33.66005964621003,-0.20952423305098483,-0.14921010393947798
281.0000000000033,33.75599840188236,-0.2050668712171915,-0.15053105197737038
282.0000000000033,33.851065341757234,-0.20029236778230408,-0.1528003816863599
283.0000000000033,33.947022822104024,-0.19463019170000678,-0.15545906993165115
284.0000000000033,34.04285632493588,-0.19026112869382866,-0.15780568054519062
285.00000000000335,34.13756765884107,-0.1855504865027089,-0.16070097684502915
286.00000000000335,34.23342563890039,-0.17997381958099667,-0.16324637566843014
287.00000000000335,34.32909710548069,-0.17503368844188383,-0.16532913922221093
288.0000000000034,34.42435552238856,-0.16881759459522816,-0.16816909711563266
289.0000000000034,34.519582981359044,-0.16423825024477418,-0.17301180357026347
290.0000000000034,34.61526498772484,-0.15667794823341083,-0.17453880756499185
291.0000000000034,34.71030510007276,-0.1534207407699893,-0.1783709871702892
292.0000000000034,34.80623066491422,-0.14812197838364827,-0.18302643641650507
293.00000000000347,34.902608481939836,-0.14083853358195508,-0.18571731514165757
294.00000000000347,34.99833000000034,-0.1352199999999772,-0.1883901000733923
295.00000000000347,35.092338833114866,-0.12981305216560163,-0.19529202020174496
296.0000000000035,35.18782783591471,-0.12261933415136808,-0.19968031887497784
297.0000000000035,35.28414932146668,-0.1173205850256581,-0.20462011010184655
298.0000000000035,35.37971502585383,-0.11006873452838248,-0.20895126479969095
299.0000000000035,35.47812586837776,-0.10305547436003372,-0.21550580221891424
300.0000000000035,35.57127383473796,-0.09597627624418477,-0.2201061318894859
301.0000000000036,35.66833000000031,-0.08727399999998367,-0.22648010800002405
302.0000000000036,35.76322897464194,-0.08084694903339716,-0.2318699325174718
303.0000000000036,35.8588300533872,-0.07279580128630198,-0.2385879031572382
304.00000000000364,35.954375169370515,-0.06530070306269219,-0.24531027374145387
305.00000000000364,36.05046287258706,-0.05633266959792211,-0.25347623614298165
306.00000000000364,36.14608112180376,-0.04566261713884597,-0.2612644418091068
307.00000000000364,36.24291862378249,-0.0368067519771804,-0.26827590059014517
308.00000000000364,36.33785956072104,-0.028089665035411743,-0.2766050204716559
309.0000000000037,36.43363894270339,-0.017322892203833585,-0.28760811082284476
310.0000000000037,36.5300778255952,-0.006163928799919054,-0.2969766931313278
311.0000000000037,36.626004352716784,0.004062595059758619,-0.3059809292757203
312.00000000000375,36.721857384217486,0.014883375209046106,-0.31579994261973754
313.00000000000375,36.81724522631569,0.026457975969669464,-0.32863065628854393
314.00000000000375,36.9136129821204,0.03874159261154383,-0.3400622144076251
315.00000000000375,37.010209462522404,0.0553103511629016,-0.3521384280206319
316.00000000000375,37.10594716907961,0.06655178611564806,-0.36634245279984645
317.0000000000038,37.202721101914946,0.08143255501150298,-0.38021514344615603
318.0000000000038,37.29967225249381,0.09407952857814612,-0.39555506266009743
319.0000000000038,37.394233991890445,0.11026080448394573,-0.4096381590991469
320.00000000000387,37.49037495497244,0.12563443904942656,-0.4268280439590675
321.00000000000387,37.587529297300364,0.1409237049506638,-0.4429356234062283
322.00000000000387,37.68327332621324,0.1598443200695404,-0.4589373192515547
323.00000000000387,37.77925820698047,0.1752234121252803,-0.4792233158821393
324.00000000000387,37.87533665446739,0.19334009173899977,-0.49860740658102376
325.0000000000039,37.97064767004051,0.2125090980252812,-0.5198908065596326
326.0000000000039,38.06726520698815,0.23131884037124767,-0.5401992372003757
327.0000000000039,38.16318179814244,0.25033867057848525,-0.5619037556177298
328.000000000004,38.26060685889283,0.2709358463764794,-0.5862978885977483
329.000000000004,38.356829060000436,0.29003837027809665,-0.6099113916955843
330.000000000004,38.45270365612109,0.31270950053875524,-0.636482187522994
331.000000000004,38.54861861916161,0.3323871432093963,-0.6626084779498438
332.000000000004,38.64595367500726,0.35507592906718305,-0.6894870788050627
333.00000000000404,38.74066997847905,0.3784856014779621,-0.7210115293791008
334.00000000000404,38.839820323278566,0.4015137733937839,-0.7507035381450424
335.00000000000404,38.9356356557768,0.42633311957394343,-0.7823219700136468
336.0000000000041,39.03255356819491,0.4515138557425016,-0.8164015428686473
337.0000000000041,39.12947700260765,0.47686386433614975,-0.8505407953870359
338.0000000000041,39.22604080270838,0.5039517643359989,-0.8864598166409232
339.0000000000041,39.32302107073971,0.5323961771412982,-0.9252988578452581
340.0000000000041,39.41948829739715,0.5592375809416792,-0.9643846646657921
341.00000000000415,39.515874005910305,0.5890241982876754,-1.0043228078367181
342.00000000000415,39.61241292585067,0.6166628543394636,-1.0481988056771372
343.00000000000415,39.70953581815861,0.6475064236377452,-1.0921607843806043
344.0000000000042,39.806483138422834,0.6780098305133463,-1.1386727986529648
345.0000000000042,39.9039014343174,0.7115150344292857,-1.1873470018488645
346.0000000000042,40.001084374314395,0.7434559715849803,-1.2366459429376353
347.0000000000042,40.09753241286967,0.7758606720918056,-1.2878975710339944
348.0000000000042,40.19527062020547,0.8122918289544133,-1.3432605462762894
349.00000000000426,40.291665479972295,0.8466449926219216,-1.4010398118156817
350.00000000000426,40.38887737199719,0.8816336618023684,-1.458447036190452
351.00000000000426,40.48608810571619,0.9185013295948419,-1.5154152709477438
352.0000000000043,40.583706557557974,0.9531697391374078,-1.5818260223363287
353.0000000000043,40.68026828884849,0.9861278198475678,-1.6443384413385131
354.0000000000043,40.77813037028022,1.0215507175133527,-1.7143364558650167
355.0000000000043,40.87533545679075,1.0553189974314687,-1.7786527222573527
356.0000000000043,40.97296998148647,1.085543975795079,-1.8506456168877259
357.0000000000044,41.069098544938804,1.114524850076704,-1.9207156861412016
358.0000000000044,41.16675578966622,1.139839001156058,-1.993939753627974
359.0000000000044,41.2639039433744,1.1611647980234185,-2.0695880087621252
360.00000000000443,41.35965094459619,1.1758470102190222,-2.1432135269555754
361.00000000000443,41.457576272267616,1.185331875348499,-2.2218409179078873
362.00000000000443,41.5548792931478,1.1892891108458015,-2.2984569101951102
363.00000000000443,41.65055584623611,1.1839646383643458,-2.3748115670116987
364.00000000000443,41.749425815428346,1.1708428169621556,-2.451971604048122
365.0000000000045,41.846434251773665,1.1514748221703535,-2.528428269781122
366.0000000000045,41.94448976089431,1.1214915997298311,-2.603528566606621
367.0000000000045,42.0412470782067,1.0854514957921297,-2.6738818247859
368.00000000000455,42.13496199067476,1.043125557246629,-2.7429867585045207
369.00000000000455,42.234255082564374,0.9918274486109135,-2.81055148112109
370.00000000000455,42.33051623524749,0.9382875903631513,-2.8723314281031227
371.00000000000455,42.42678869227316,0.8748408868877297,-2.9338888299290184
372.00000000000455,42.523006532236074,0.8076377453572828,-2.9951752413718307
373.0000000000046,42.619740989175604,0.7356043954060384,-3.0535161189300433
374.0000000000046,42.71381657578816,0.6579561128502179,-3.1033643265842903
375.0000000000046,42.81213040559306,0.5722910138830141,-3.1528632917615074
376.00000000000466,42.90699095065378,0.48480833169201354,-3.1965631817179285
377.00000000000466,43.00368400531731,0.39587376105965927,-3.234613388310367
378.00000000000466,43.09957086769668,0.3051535679496006,-3.268843266092148
379.00000000000466,43.195881806753476,0.21680183619105792,-3.2983465861535235
380.00000000000466,43.29209914198482,0.1313890770664342,-3.323327152610587
381.0000000000047,43.38852940369394,0.049073003794003846,-3.346118780418338
382.0000000000047,43.48283494093261,-0.020388909599284025,-3.3634005328154233
383.0000000000047,43.579117716495446,-0.08576781885873339,-3.3751590816427592
384.0000000000048,43.67538662835682,-0.13904533447315717,-3.385488276422734
385.0000000000048,43.77181125844056,-0.18076529000496117,-3.3930629141821576
386.0000000000048,43.868034282115794,-0.21473025383503225,-3.3990912123065105
387.0000000000048,43.963594091423204,-0.237877837520698,-3.4035305688816613
388.0000000000048,44.06130159872767,-0.25442631895117634,-3.4084844579075813
389.00000000000483,44.15661481983914,-0.2635324309364567,-3.4103866833588556
390.00000000000483,44.25442298958914,-0.2663806012106044,-3.412955352205671
391.00000000000483,44.35056282832311,-0.26913356034805996,-3.4134857458506067
392.0000000000049,44.446604632718646,-0.2673479475828433,-3.4169043330111246
393.0000000000049,44.54408721315568,-0.26078971351230745,-3.419499817238085
394.0000000000049,44.639831417284235,-0.25176601985463215,-3.4207925537675794
395.0000000000049,44.73687692529454,-0.24377105314452105,-3.4208508988254227
396.0000000000049,44.83306591276043,-0.2373636618999922,-3.423468024380535
397.00000000000495,44.93059813707845,-0.23499011458939842,-3.4243317286294728
398.00000000000495,45.02684393410502,-0.2326979917583387,-3.4248102020574356
399.00000000000495,45.125429651870824,-0.23084112768047943,-3.4261201761104174
400.000000000005,45.22171393974205,-0.2286667055574178,-3.426053922802749
401.000000000005,45.31776653359863,-0.2254731169976501,-3.4287259007898876
402.000000000005,45.41767206898368,-0.2253013165312728,-3.4309975318958985
403.000000000005,45.5146015215292,-0.22403576963922822,-3.4333260542779622
404.000000000005,45.61202741255256,-0.21993658458271143,-3.432618930173597
405.00000000000506,45.709978731458776,-0.21833243396321267,-3.4335044296692927
406.00000000000506,45.80803909022597,-0.21674142688632766,-3.4340200349352092
407.00000000000506,45.904264193199,-0.21612047179721838,-3.4353039553828175
408.0000000000051,46.00327481371046,-0.2147432190313326,-3.4379923389650378
409.0000000000051,46.100499026391134,-0.21455479822241383,-3.4379765479729723
410.0000000000051,46.19803239389151,-0.21263321490412357,-3.4393000639819706
411.0000000000051,46.294706096516855,-0.21044481898559686,-3.440610790409636
412.0000000000051,46.39263800858641,-0.2091811711587786,-3.4412704789773967
413.0000000000052,46.49137565246523,-0.20716518406114753,-3.442576679676245
414.0000000000052,46.58803374001374,-0.2057740538813162,-3.443902953953298
415.0000000000052,46.684003484551454,-0.20559012265960402,-3.4435560598121837
416.00000000000523,46.780769633782604,-0.20436725988478102,-3.4447350448913667
417.00000000000523,46.88081179580993,-0.20280935147367327,-3.4458816138025754
418.00000000000523,46.979474697433155,-0.1998900191775967,-3.448520222647991
419.00000000000523,47.07693014526775,-0.1992857480207417,-3.4497882532942272
420.00000000000523,47.174599517379804,-0.19674185338285705,-3.449839115503983
421.0000000000053,47.27239155659762,-0.19426749244910926,-3.4498302786972284
422.0000000000053,47.370434515823675,-0.19128006464443836,-3.4511545699462975
423.0000000000053,47.46854147964586,-0.19139399254459297,-3.4524701443044608
424.00000000000534,47.56576750132452,-0.18916707604135108,-3.454786123286909
425.00000000000534,47.664386753535744,-0.18828466307286496,-3.4543840528550454
426.00000000000534,47.762103533459225,-0.18632889618538848,-3.455434453254459
427.00000000000534,47.859998581323545,-0.1837049983339622,-3.4567473834427047
428.00000000000534,47.95843190899115,-0.18390404208043787,-3.457408767707285
429.0000000000054,48.05554227005939,-0.18123007206848,-3.4560381025121316
430.0000000000054,48.15475798776471,-0.1800762989707477,-3.460031033159071
431.0000000000054,48.252161200130786,-0.17643783751039277,-3.460051299465998
432.00000000000546,48.349698852714305,-0.17493412326120258,-3.4613599492423734
433.00000000000546,48.44852785140752,-0.17445744812754896,-3.4626771268681265
434.00000000000546,48.547084365944166,-0.1721379610221281,-3.463976226287054
435.00000000000546,48.64519082349946,-0.17161667304936795,-3.464936601763503
436.00000000000546,48.74258745211231,-0.16890881234827365,-3.4649426473212155
437.0000000000055,48.840302876946495,-0.16737273020197133,-3.466300193263079
438.0000000000055,48.93783556671098,-0.16601430353960078,-3.4676187097923767
439.0000000000055,49.03658830758038,-0.16456413247236357,-3.469156491445373
440.00000000000557,49.134487813581934,-0.16321003586825983,-3.4691515729891176
441.00000000000557,49.23246945810325,-0.1591220965486232,-3.4704701580115325
442.00000000000557,49.33053574168846,-0.15756146339782945,-3.471789597541212
443.00000000000557,49.428330000000535,-0.15661999999998674,-3.4724498855063772
444.00000000000557,49.52664239049126,-0.15285738815493435,-3.4717912167941694
445.0000000000056,49.62440069273083,-0.15296836914836076,-3.4730885359766908
446.0000000000056,49.72201997327033,-0.14958298123689423,-3.47446873474408
447.0000000000056,49.820434724179194,-0.14707996734707787,-3.475751651733278
448.0000000000057,49.918330000000545,-0.14652000000005255,-3.4783736725800507
449.0000000000057,50.01671378990162,-0.14423922711648804,-3.477061118306108
450.0000000000057,50.11450940156442,-0.14237691753932366,-3.4785006322022864
451.0000000000057,50.212986760663306,-0.14041373961442796,-3.4803540851850507
452.0000000000057,50.311696456579206,-0.13729513785426034,-3.481670085117196
453.00000000000574,50.408796967202925,-0.1348066901195608,-3.480361116916858
454.00000000000574,50.50623971392456,-0.13343951675637214,-3.4816700805956646
455.00000000000574,50.60574446538336,-0.12964355894901256,-3.484359979803247
456.0000000000058,50.70393554833748,-0.12871988738622714,-3.485627529675239
457.0000000000058,50.80244220216835,-0.12696074637455645,-3.486946901833314
458.0000000000058,50.900310744018704,-0.12566011787222026,-3.4856196782613633
459.0000000000058,50.99843355058015,-0.12422447862651943,-3.486930121823568
460.0000000000058,51.093593169558936,-0.12262790739469297,-3.4882611999476083
461.00000000000585,51.1953975186669,-0.12093738137165479,-3.48955963650562
462.00000000000585,51.29283224149279,-0.11764274601411102,-3.489569430282295
463.00000000000585,51.39185615654338,-0.11614096242002159,-3.490889792316717
464.0000000000059,51.4895660011368,-0.11424430464138606,-3.4922091111285405
465.0000000000059,51.58843973034394,-0.11069446653952389,-3.494190269106836
466.0000000000059,51.68717997011499,-0.11037569295587428,-3.49549734147855
467.0000000000059,51.78502415664678,-0.10653710176292963,-3.4959144481748226
468.0000000000059,51.88382241571132,-0.10300277242335105,-3.4955001028294417
469.00000000000597,51.98171880076186,-0.10218210249344024,-3.4954388902233897
470.00000000000597,52.08003255886875,-0.0990077210198534,-3.496824957345758
471.00000000000597,52.17892120094403,-0.09785003797010693,-3.498125515528855
472.000000000006,52.276917140426775,-0.09603578282324125,-3.4994500231913266
473.000000000006,52.37614213001728,-0.09408088784699578,-3.500769121861376
474.000000000006,52.473812277172506,-0.09372517310769976,-3.5012909385852806
475.000000000006,52.572981975112484,-0.09056451593147262,-3.500761768058233
476.000000000006,52.67142637335463,-0.08878960678679886,-3.5020886504376865
477.0000000000061,52.769674566477725,-0.08848187664514474,-3.502406605511424
478.0000000000061,52.86520760406951,-0.08707251234560573,-3.5033999387935433
479.0000000000061,52.96694444561926,-0.08469391469957388,-3.50472319187781
480.00000000000614,53.06528113481493,-0.08162564843023203,-3.504092834239463
481.00000000000614,53.16375674132978,-0.08199272455475141,-3.506045214414494
482.00000000000614,53.26257691833628,-0.07924507774352152,-3.504277220044492
483.00000000000614,53.36103183172666,-0.07681796755428558,-3.506675455343099
484.00000000000614,53.46025579415859,-0.07532580146831881,-3.5093299580646824
485.0000000000062,53.55872524973684,-0.07357649664724132,-3.510646553394542
486.0000000000062,53.65681583533534,-0.07098224390682943,-3.5106498642505874
487.0000000000062,53.75706357993769,-0.06904951161245673,-3.5119177863967863
488.00000000000625,53.85501239035155,-0.06823281533822767,-3.5119701361127618
489.00000000000625,53.95406355259504,-0.06463168054849701,-3.511969869793506
490.00000000000625,54.05274218508748,-0.06390503504329502,-3.5119698979102587
491.00000000000625,54.15109589865137,-0.06092833300621495,-3.5128593100600733
492.00000000000625,54.24969220583602,-0.06037891629320545,-3.5132898281833644
493.0000000000063,54.34933053101857,-0.05933315697243865,-3.5146117820743026
494.0000000000063,54.447250535350676,-0.05731606044741697,-3.5146100989316835
495.0000000000063,54.54692143777576,-0.05570043280681983,-3.514609920773278
496.00000000000637,54.64649161805504,-0.054950539963278304,-3.5146101156267933
497.00000000000637,54.74524598888219,-0.05234387608817298,-3.5159203842514666
498.00000000000637,54.84319635205233,-0.05185545444705953,-3.517238436963651
499.00000000000637,54.94387029454866,-0.050333972359121966,-3.518446579234144
500.00000000000637,55.04176487275914,-0.04994598429775668,-3.5175699889137295
501.0000000000064,55.14130532841538,-0.04958772071872556,-3.5188899840317984
502.0000000000064,55.240107378052095,-0.04850090996302813,-3.520709710460137
503.0000000000064,55.33810130395514,-0.049509559733173794,-3.5202106409131844
504.0000000000065,55.438427831894096,-0.049116456641081954,-3.5212113698623853
505.0000000000065,55.53664745782795,-0.04677457483776892,-3.5225099467592424
506.0000000000065,55.63615067917813,-0.04623625386676403,-3.5238300456483027
507.0000000000065,55.735685160390894,-0.04780964446180938,-3.5243398643185113
508.0000000000065,55.83492273002068,-0.047839723938616456,-3.5251393844772343
509.00000000000654,55.93339797860814,-0.04677873713206928,-3.5251501855105287
510.00000000000654,56.03352969487835,-0.045240664291947244,-3.5258571413016724
511.00000000000654,56.13189676136941,-0.04340208278504965,-3.5259685324096686
512.0000000000066,56.230726814190284,-0.045060501857296216,-3.5251499756172495
513.0000000000066,56.33006555832892,-0.04383530158069347,-3.526459126136784
514.0000000000066,56.42938051404494,-0.0425571836426674,-3.52645282349701
515.0000000000066,56.52864216345704,-0.04323691902623461,-3.528440073934566
516.0000000000066,56.62822159455683,-0.043727754543742586,-3.527117916948305
517.0000000000066,56.72646572467037,-0.04367210002339399,-3.5273834933422066
518.0000000000066,56.821977434534105,-0.043817622640448195,-3.5287700215102964
519.0000000000066,56.92454892393954,-0.04422135343768762,-3.5292567011425424
520.0000000000067,57.023715631205384,-0.04238833480268791,-3.5287699243283837
521.0000000000067,57.12251440404287,-0.04008808320334996,-3.528769924051831
522.0000000000067,57.221695227185904,-0.03867515760701526,-3.528803483121695
523.0000000000067,57.321674898587325,-0.036926449821149905,-3.5300753610152857
524.0000000000067,57.420560345014216,-0.03588751442378701,-3.5313999513141665
525.0000000000068,57.5202271030095,-0.03402816056254231,-3.5300726374458176
526.0000000000068,57.61993134749066,-0.03169733851425178,-3.532732037150977
527.0000000000068,57.71842971876198,-0.028473329174123478,-3.5322149625327186
528.0000000000068,57.81833000000064,-0.027577269999909178,-3.5333801673409724
529.0000000000068,57.917819035187215,-0.025298196025995447,-3.5346827882290617
530.0000000000068,58.01693266215499,-0.022115865598395745,-3.5340312490602193
531.0000000000068,58.11572680272141,-0.021192698879049406,-3.535181548291029
532.0000000000068,58.21658813060844,-0.017971049094046457,-3.535350200793725
533.0000000000068,58.315361893894796,-0.016812094544339195,-3.5353502016707274
534.0000000000068,58.414505422334635,-0.013630705882643278,-3.535953304423953
535.0000000000068,58.51383722843552,-0.011100445514127451,-3.536670102170606
536.0000000000069,58.61333115975923,-0.009035027412845434,-3.5366701045907547
537.0000000000069,58.7130907142495,-0.006118977182729522,-3.537362159654876
538.0000000000069,58.81267292556675,-0.004317394120816634,-3.5373298471683334
539.0000000000069,58.912066201703844,-0.0005755892862084435,-3.5380597913489034
540.0000000000069,59.01060127112961,0.0012555552841377814,-3.53667979785504
541.000000000007,59.11064060675027,0.003793426208369941,-3.5379987718257695
542.000000000007,59.210334745558136,0.009430543150083558,-3.5383200030575734
543.000000000007,59.309700867475065,0.011014120274596188,-3.539610980555644
544.000000000007,59.409399677472685,0.01470487089256512,-3.5396316016453175
545.000000000007,59.50923975522421,0.016209364243164888,-3.5399600354618075
546.000000000007,59.60833000000072,0.01888839999999784,-3.539960037000686
547.000000000007,59.70873805319196,0.02226520348545926,-3.541280356506132
548.000000000007,59.80791129361081,0.023681747014459194,-3.5419409404883684
549.000000000007,59.90739713693836,0.026189205524602324,-3.5406299677071877
550.000000000007,60.00745933390071,0.0296254693455218,-3.5419400482103143
551.000000000007,60.10697018294458,0.03130796077657906,-3.541880491766794
552.0000000000072,60.20653848813821,0.035184152429762944,-3.5426717157440972
553.0000000000072,60.30689267479271,0.03749752746224647,-3.5422701531038627
554.0000000000072,60.405863495822715,0.04023251735200787,-3.5432603416983377
555.0000000000072,60.506380437497945,0.041869205114300756,-3.5436018508784253
556.0000000000072,60.60564321874954,0.044649323641043015,-3.544896641981026
557.0000000000073,60.70668191171873,0.0491542007018492,-3.5449102335613323
558.0000000000073,60.80648372517558,0.050448381794341156,-3.543258814000147
559.0000000000073,60.90619766790738,0.05520419953817404,-3.544580200770018
560.0000000000073,61.00514322390183,0.05777395764439928,-3.5439515943430884
561.0000000000073,61.10562432056054,0.060060431344986995,-3.5448998243282093
562.0000000000073,61.2055560963794,0.06384574794731881,-3.5449084827252566
563.0000000000073,61.30483602798415,0.06708511872886411,-3.546225408304935
564.0000000000073,61.40465525419834,0.0719954224295403,-3.546551639983491
565.0000000000073,61.503853392829264,0.07166032985845205,-3.5465498079897433
566.0000000000073,61.60407189917243,0.07764749651579782,-3.546542344845722
567.0000000000074,61.70349863760396,0.08150485894988678,-3.5478701105891237
568.0000000000074,61.803070142342044,0.08442228071302417,-3.5478701159999884
569.0000000000074,61.90299478394307,0.09034388768578021,-3.5478701160000012
570.0000000000074,62.00327355408302,0.09348814132378752,-3.547870116505506
571.0000000000074,62.10275317268588,0.09705489428233213,-3.5481496391684173
572.0000000000074,62.20218994589506,0.10087626100180902,-3.5485171635420776
573.0000000000074,62.30213747256058,0.10310928924607586,-3.54819111764038
574.0000000000075,62.401890661501696,0.10813179953009909,-3.5498169617075166
575.0000000000075,62.50192543433086,0.11068555730472497,-3.550618774075142
576.0000000000075,62.60175502709266,0.11447836271217386,-3.551489867396722
577.0000000000075,62.70149546545657,0.11951353417578227,-3.550086229203802
578.0000000000075,62.800613019148805,0.1227614485047459,-3.5501806161694383
579.0000000000075,62.90081538028514,0.1273562639707004,-3.552480485096024
580.0000000000075,63.00038897517631,0.13283224281220943,-3.5517906350773414
581.0000000000075,63.10036957860045,0.13660744516777987,-3.551121737988936
582.0000000000075,63.20024340009352,0.14051152426189326,-3.5524676155797255
583.0000000000076,63.300600545168514,0.14400869604088462,-3.5528011069884915
584.0000000000076,63.39944486749399,0.15022610239993422,-3.552799739940001
585.0000000000076,63.49833000000089,0.1547900000000077,-3.5527998319999656
586.0000000000076,63.59937362749805,0.15898598284900178,-3.5528000470065497
587.0000000000076,63.70035925479011,0.1635060734821122,-3.5531527209005382
588.0000000000076,63.80002807596633,0.16819162547590027,-3.5531401400270877
589.0000000000076,63.899693147815036,0.17094217948767532,-3.5531385645516114
590.0000000000077,63.99996296883791,0.17508373549978415,-3.5544600037951786
591.0000000000077,64.10051613630972,0.1812018516395929,-3.554457220643325
592.0000000000077,64.20104946823491,0.1847468714033624,-3.5557697107397916
593.0000000000077,64.29948813599114,0.1892112677508739,-3.556463624233543
594.0000000000077,64.40038658846129,0.19429296809108365,-3.5557799426864567
595.0000000000077,64.5004826184157,0.19973456613590337,-3.556944737096928
596.0000000000077,64.59909189042766,0.20301181917318106,-3.5580869752673525
597.0000000000077,64.70002381385636,0.20840766602016006,-3.557090496059933
598.0000000000077,64.79946931203246,0.2119907003340173,-3.5570899956821425
599.0000000000078,64.89998736589632,0.21787564059350928,-3.5580798010889425
600.0000000000078,65.0002428740354,0.2211316127981558,-3.558409189051255
601.0000000000078,65.1002343460272,0.2268536301080028,-3.561036746044023
602.0000000000078,65.20028654301807,0.23169892195883182,-3.561039864055345
603.0000000000078,65.3015764868922,0.2362990686676843,-3.5597255495340367
604.0000000000078,65.40137618017683,0.24237887404498754,-3.559729719198428
605.0000000000078,65.50140799837666,0.24358146260530675,-3.5610495348835247
606.000000000008,65.6014542065129,0.2517132691361209,-3.5620301051512655
607.000000000008,65.70145621413937,0.25691090703280633,-3.562030184997992
608.000000000008,65.80206040259257,0.26066322660961905,-3.5620293010573816
609.000000000008,65.9019755257351,0.2660115723646761,-3.5620324934432044
610.000000000008,66.00137362141238,0.2698563072923757,-3.562034847620681
611.000000000008,66.10284511741986,0.2741058741404746,-3.560708896400183
612.000000000008,66.20215351814463,0.2794528982964586,-3.5633496930829915
613.000000000008,66.30232352024339,0.28469190657931615,-3.5633486770289906
614.000000000008,66.4021802821207,0.28817780849789204,-3.5620297803190897
615.0000000000081,66.50237402377995,0.2932483826450026,-3.5620298130831913
616.0000000000081,66.60151883088734,0.2996239934213037,-3.5626268696773224
617.0000000000081,66.7016577902926,0.30390870067192344,-3.5640107957469755
618.0000000000081,66.80018118952137,0.31013266087579056,-3.564998880927142
619.0000000000081,66.90321733410839,0.31346875084349773,-3.563679904931732
620.0000000000081,67.00197142760955,0.31875670764522607,-3.5636799931363576
621.0000000000081,67.10146968854404,0.3243443096340712,-3.562691227253033
622.0000000000082,67.20174494115939,0.3296378086143648,-3.5630117295723087
623.0000000000082,67.30274682450337,0.3341653258165239,-3.5645432561252712
624.0000000000082,67.40144894293108,0.3383633197042669,-3.564658563483085
625.0000000000082,67.50214848990684,0.3445162988075219,-3.5649026337200387
626.0000000000082,67.60362862410066,0.3489029316514169,-3.5636174797420868
627.0000000000082,67.7028383656815,0.3538683750279285,-3.5663002888768407
628.0000000000082,67.80258325339544,0.35851839120998946,-3.56496126683452
629.0000000000082,67.90447214926168,0.36409024868005363,-3.5649900381301878
630.0000000000082,68.00386796574236,0.36935147551593184,-3.566304374491362
631.0000000000083,68.10471989593022,0.3739288369201528,-3.567638787957424
632.0000000000083,68.20537680537791,0.376674952011881,-3.5676300900464897
633.0000000000083,68.30597182780039,0.38332584565152705,-3.5663108139865054
634.0000000000083,68.40537900090779,0.3894710521926278,-3.5663401469084217
635.0000000000083,68.50584997330682,0.39203253746411904,-3.5676323744540905
636.0000000000083,68.60719173620326,0.39846896268369014,-3.56697878828422
637.0000000000083,68.70705055992816,0.4044747108243284,-3.5669809223810423
638.0000000000084,68.80774062391552,0.41146133514487643,-3.5682899971817914
639.0000000000084,68.9082339571786,0.41560588504933726,-3.56828999000008
640.0000000000084,69.0090453655946,0.4205698921277602,-3.568289649342822
641.0000000000084,69.11074747071441,0.42526428677507955,-3.569608201952034
642.0000000000084,69.21087245642538,0.43006046022219635,-3.569296525080682
643.0000000000084,69.31132262330576,0.4355420371198712,-3.5702816821303864
644.0000000000084,69.41232798614456,0.4410177766537512,-3.5689511220468226
645.0000000000084,69.51229578967151,0.4453592314422376,-3.568289890482377
646.0000000000084,69.61288713870216,0.45108942501027166,-3.5678798898961928
647.0000000000085,69.71305411624961,0.45738220898059795,-3.5682259438949635
648.0000000000085,69.81353075518422,0.46432117653404853,-3.5689506586636104
649.0000000000085,69.91446783533321,0.46859068702650497,-3.567916270330201