File: 01_Data/Basswood_Panel/STA/N2/10K_min/Basswood_Panel_STA_N2_10KData_220314_R2.csv
##Temp./Â°C,Time/min,DSC/(mW/mg),Mass loss/mg
50.0,10.57,-1.12359,-0.0665943857685285
51.100000000000016,10.95704875780445,-0.9853014818542942,-0.06527369245575931
52.20000000000003,11.185496312021382,-0.8990469036423442,-0.0641131144903544
53.30000000000005,11.368104119812674,-0.8368492049875017,-0.06456455903687486
54.40000000000006,11.530971181614595,-0.7856164508883807,-0.06587311155007303
55.50000000000008,11.681748836618217,-0.7455520499379479,-0.06511668530123282
56.600000000000094,11.821208989475354,-0.7133604393601706,-0.06714940897973243
57.70000000000011,11.956899912639344,-0.6870198987612393,-0.06727130058972941
58.800000000000125,12.087320936717347,-0.6641525141989455,-0.06844165824338644
59.90000000000014,12.214229395196515,-0.6419582578175252,-0.06865359130697968
61.000000000000156,12.340373715924626,-0.624657590387849,-0.0683613059803041
62.10000000000017,12.463515928447139,-0.6099625663204904,-0.06881457460228768
63.20000000000019,12.587532566926296,-0.5950548434751058,-0.06866027698718558
64.30000000000021,12.709250453935839,-0.5809900870113401,-0.06887631187403098
65.40000000000022,12.830352322758909,-0.5701779879648012,-0.07020603694158112
66.50000000000023,12.946769957926287,-0.5587662271920473,-0.06905392494021179
67.60000000000025,13.068451513675225,-0.5454178024281495,-0.07019763675423585
68.70000000000027,13.187959624059994,-0.5343076641872743,-0.07264664907275087
69.80000000000028,13.304995437785841,-0.5229173813838227,-0.07281462918431636
70.90000000000029,13.422903976531902,-0.5119208652778879,-0.07421883633812776
72.00000000000031,13.540110946075837,-0.501014144284127,-0.07282976163418375
73.10000000000034,13.657140975851803,-0.49122383282001714,-0.07483402868822386
74.20000000000034,13.774125257423979,-0.47890173923820406,-0.07415673450236282
75.30000000000035,13.890095660433554,-0.46922093254766656,-0.07518566049777187
76.40000000000038,14.003535408132388,-0.45910807460080444,-0.07678879555820783
77.5000000000004,14.119391223274281,-0.45050540656033716,-0.07678652970218991
78.6000000000004,14.234347032575617,-0.4413661176434073,-0.07809880287064708
79.70000000000041,14.349439177586673,-0.43240703133595765,-0.07809854981765607
80.80000000000044,14.462420209100289,-0.42290023856608555,-0.07852046794203105
81.90000000000046,14.57437326873999,-0.4132876373152544,-0.08063349154899324
83.00000000000047,14.684883204867447,-0.40533456581266736,-0.08202936090607471
84.10000000000048,14.799784473736386,-0.3974119592895695,-0.08302958832332896
85.2000000000005,14.91285038011059,-0.39136926430324903,-0.08205137846089494
86.30000000000052,15.023101184071548,-0.38442547578939346,-0.08336351814201359
87.40000000000053,15.135021101355841,-0.37759864097059004,-0.0843272678279634
88.50000000000054,15.243956014511664,-0.37027897036490914,-0.08610751801715688
89.60000000000056,15.355103043897424,-0.3636934574403983,-0.08736040370485476
90.70000000000059,15.463418770752797,-0.35898847021206803,-0.08731745092466037
91.8000000000006,15.575995611132164,-0.3534595276626636,-0.0863301251206452
92.9000000000006,15.685587617756514,-0.3487784608388597,-0.08764109189880731
94.00000000000063,15.794844621445254,-0.34401041161557416,-0.09049601154408293
95.10000000000065,15.904295020503673,-0.3394638115033441,-0.088850832145277
96.20000000000066,16.01384087331242,-0.3353961625655876,-0.0879808037165768
97.30000000000067,16.122394774580503,-0.33069343468680357,-0.09048934684063026
98.40000000000069,16.231887804018246,-0.3268959493352276,-0.09101592051317331
99.50000000000071,16.3392649041376,-0.32203096969093614,-0.08928369523303514
100.60000000000072,16.44771254405137,-0.3185246071850863,-0.09059995966662893
101.70000000000073,16.55540343880431,-0.3133015241237802,-0.0905999599999987
102.80000000000075,16.663458235608303,-0.30627361223174293,-0.09191994449464502
103.90000000000077,16.772179620090803,-0.3035638914493243,-0.09318812598803206
105.00000000000078,16.881052784062042,-0.29804595703082404,-0.09156099285139918
106.10000000000079,16.987842565582547,-0.2920132733363878,-0.09291330332545744
107.20000000000081,17.09210053199923,-0.2877358553069456,-0.09286679506242024
108.30000000000084,17.202803438650683,-0.28259527922596317,-0.09506976489296015
109.40000000000084,17.311432167177117,-0.276182816564409,-0.09389837852024963
110.50000000000085,17.419599604732962,-0.27172808810824656,-0.0952194118833507
111.60000000000088,17.527930634528836,-0.2665193368469805,-0.09389998096668428
112.7000000000009,17.634909649106138,-0.26059600372478176,-0.09390266113516077
113.8000000000009,17.742517736036934,-0.2527841263394478,-0.09518615064283509
114.90000000000092,17.850211376366556,-0.24813395327032006,-0.09636081189985735
116.00000000000094,17.9575174796266,-0.24041780583507485,-0.0962834100340646
117.10000000000096,18.06545793238453,-0.23596390896799785,-0.09752020364942293
118.20000000000097,18.173643341392154,-0.22875422431563044,-0.09750931396464058
119.30000000000098,18.280614020699595,-0.22377376161671736,-0.09849984052030081
120.400000000001,18.387639110065283,-0.2182919884233687,-0.09883373970045373
121.50000000000102,18.496273753310746,-0.21054018986857362,-0.09883200314054363
122.60000000000103,18.601240343886168,-0.20548194516889898,-0.09846643622933904
123.70000000000104,18.708818521502053,-0.1981056235298893,-0.09763430791443195
124.80000000000106,18.815806619912536,-0.19366343244974182,-0.09919248175620421
125.90000000000109,18.92135334280706,-0.18786982177184922,-0.09904963141978929
127.0000000000011,19.028885634357284,-0.17938659798110795,-0.10032098199273554
128.1000000000011,19.13622701936971,-0.17459161427649614,-0.10038282570902934
129.20000000000113,19.242743305231887,-0.16862839073465044,-0.1013510733643761
130.30000000000115,19.348254945235052,-0.163055288718227,-0.10365927456649526
131.40000000000117,19.45542214937516,-0.15692163946223625,-0.10241885231870285
132.50000000000117,19.563684107253106,-0.1518045631769488,-0.1033322252531832
133.6000000000012,19.668162505029358,-0.14743160220950177,-0.10299364064267857
134.7000000000012,19.776076033496103,-0.14033654686296768,-0.10430324984839956
135.8000000000012,19.88239570518964,-0.1338006425871044,-0.10480426352366567
136.90000000000123,19.989121477909617,-0.12828351870515395,-0.10497202658284
138.00000000000125,20.09500357654932,-0.1232308934068409,-0.10496847068969473
139.10000000000127,20.20232937391981,-0.11685100522608423,-0.1043620177276976
140.2000000000013,20.30877391455864,-0.11111452531794784,-0.1052963561353053
141.3000000000013,20.41377676887512,-0.10469986404878884,-0.10497027749631105
142.4000000000013,20.52062298533868,-0.09860799419631865,-0.10497044406305722
143.50000000000134,20.62594277170946,-0.0932204136463686,-0.1074247009450695
144.60000000000133,20.73147150920779,-0.08653456273537458,-0.10662009609108347
145.70000000000135,20.840288540788524,-0.07962905684324172,-0.10662048456019413
146.80000000000138,20.94435105730947,-0.0728337247276861,-0.10782963702541437
147.9000000000014,21.050522543891173,-0.06760770493924674,-0.10651004719267076
149.00000000000142,21.156723128840476,-0.06257048538287982,-0.10914432520886042
150.10000000000142,21.2632658508871,-0.05608479950802,-0.1091407576502359
151.20000000000144,21.368717457317338,-0.05159062119837245,-0.10979918931771326
152.30000000000146,21.473200359523968,-0.046299720659103996,-0.10913969378883515
153.40000000000146,21.57916842131465,-0.039576377798319344,-0.1098003991490546
154.50000000000148,21.684805662715554,-0.03323582827331878,-0.11046010675145634
155.6000000000015,21.79117091141193,-0.027178260611683103,-0.11138721993795153
156.70000000000152,21.89619712976702,-0.02149517461652665,-0.11111349521976255
157.80000000000155,22.004261003032777,-0.016798223840792676,-0.11045996629622046
158.90000000000154,22.1064014624186,-0.010197025300849615,-0.11038865120869623
160.00000000000156,22.21411698133767,-0.0047733490803506815,-0.11176996884079271
161.1000000000016,22.31990843964876,5.840653025838452e-07,-0.11243449313700982
162.20000000000158,22.425326607338288,0.006972644385276083,-0.11242974858649113
163.3000000000016,22.53018499714299,0.01114410070001034,-0.11374026095066903
164.40000000000163,22.636401895919775,0.01604839446703738,-0.11505800994337534
165.50000000000165,22.74239455278969,0.023008963062200516,-0.11638008778864162
166.60000000000167,22.847694527908953,0.030010544557500487,-0.11638009600000698
167.70000000000167,22.95332073340193,0.032891479781303495,-0.1163800964448134
168.8000000000017,23.059191138603698,0.03820740190945252,-0.11510830015990825
169.9000000000017,23.16503596678694,0.04485904620824088,-0.11637544978647663
171.0000000000017,23.270184578837863,0.04917939037836931,-0.11893545296052865
172.10000000000173,23.37564730101294,0.05620895121751011,-0.11869525417942395
173.20000000000175,23.482013927993886,0.06128875376401158,-0.11768206109640289
174.30000000000177,23.58655775188082,0.06602903330421071,-0.11768523504483763
175.4000000000018,23.692791898446778,0.06984462429646725,-0.11900997224772158
176.5000000000018,23.79847343126319,0.07678741855136678,-0.11966518616772959
177.6000000000018,23.90367999130479,0.07971496967041343,-0.11962286240414066
178.70000000000184,24.00888307305425,0.08656336432498678,-0.12098996807644236
179.80000000000183,24.11449636988158,0.09067849240102258,-0.12098987523382343
180.90000000000185,24.22028581475374,0.09716437907479006,-0.12205692458349304
182.00000000000188,24.32605298962313,0.10276229611298554,-0.12296213142989121
183.1000000000019,24.430449816550535,0.1078350178829996,-0.12552190136869212
184.20000000000192,24.535073715942715,0.11378871313695316,-0.12428015525366032
185.30000000000192,24.640959523043847,0.1158936474956375,-0.12558993850020217
186.40000000000194,24.74696686014524,0.12449217616079021,-0.12559247629287107
187.50000000000196,24.850368270673783,0.1283087976332768,-0.12560174563754467
188.60000000000196,24.956416345863556,0.13495474477978772,-0.1282206045195684
189.70000000000198,25.061118428511726,0.13945113322651725,-0.1295385183868123
190.800000000002,25.167658740113996,0.1449455112317177,-0.12856007450942997
191.90000000000202,25.272090774858544,0.15155552264999236,-0.129875689585782
193.00000000000205,25.37710954326476,0.1566863094071344,-0.1298700885659323
194.10000000000204,25.47988014661229,0.16247617936151937,-0.13119120992907662
195.20000000000206,25.586611944949645,0.16963298666165053,-0.13118978879800647
196.3000000000021,25.6919281014682,0.17787515651827493,-0.1325144150410913
197.40000000000208,25.79678231611451,0.18255246531126565,-0.13236250811662753
198.5000000000021,25.901809316750366,0.18792749644328438,-0.13382002184943254
199.60000000000213,26.00691360474985,0.19447796189092306,-0.13512887973935195
200.70000000000215,26.112854116420316,0.19988102542955005,-0.13776768075225343
201.80000000000217,26.217610498719004,0.20467690677131223,-0.14062100412564815
202.90000000000217,26.322195862061644,0.2094467897682209,-0.13943156590562866
204.0000000000022,26.427519780179868,0.21689853500874592,-0.13940981657385398
205.1000000000022,26.53221749069088,0.2206631986866625,-0.14205620791835116
206.2000000000022,26.637326246384557,0.2264406695627299,-0.14195279738032696
207.30000000000223,26.743792131388837,0.23183343310169655,-0.1434150496776856
208.40000000000225,26.848258298771757,0.2379813723732264,-0.14599671183320373
209.50000000000227,26.95280103315864,0.24367395309224632,-0.14765912082472088
210.6000000000023,27.05858158750414,0.2504891070325663,-0.14994176022133754
211.7000000000023,27.164144518006715,0.2551191222727899,-0.15126090515899904
212.8000000000023,27.269375801031284,0.2592340380423527,-0.1539001492306613
213.90000000000234,27.37353782907816,0.26464067612735165,-0.15521632833873156
215.00000000000233,27.479705727407108,0.26910217661489977,-0.15584524866184157
216.10000000000235,27.584478925810277,0.2722583689025505,-0.1565755716779984
217.20000000000238,27.690812011316147,0.2757059275554118,-0.1591714396928947
218.3000000000024,27.795675711936084,0.2791230949930183,-0.16178984159511023
219.40000000000242,27.900913042037963,0.28494069691025903,-0.16442313660682562
220.50000000000242,28.00545653472404,0.2873315420279359,-0.16576753377531617
221.60000000000244,28.110810701728354,0.29157270879487884,-0.16744544655379734
222.70000000000246,28.21510374391725,0.29694689800155344,-0.1706273445607418
223.80000000000246,28.317825686614896,0.3016710426350446,-0.17264196686590338
224.90000000000248,28.42469631235932,0.3051433756584077,-0.17500215075046732
226.0000000000025,28.52949098916842,0.30692161786901845,-0.17726873258455544
227.10000000000252,28.63422023490661,0.3128905305669792,-0.18123515261515033
228.20000000000255,28.739898434407383,0.31601028206746185,-0.18252024083735474
229.30000000000254,28.842043864078274,0.31739347732100576,-0.18656161745124722
230.40000000000256,28.949378754625936,0.32153532145466057,-0.18909858659677736
231.5000000000026,29.05374807581727,0.326028857265152,-0.19041880217080287
232.60000000000258,29.158413012581935,0.32804148251585663,-0.1917408966395251
233.7000000000026,29.263500017074893,0.330353992418402,-0.19441938024009753
234.80000000000263,29.368015078051798,0.33401574172373205,-0.19800222258624522
235.90000000000265,29.473497754778702,0.3361558324696597,-0.20093756666246954
237.00000000000267,29.578072508443853,0.3391988619673456,-0.20360258620715754
238.10000000000267,29.683013869407823,0.3415129810289269,-0.2087024385414571
239.2000000000027,29.78784156034741,0.34411760451447454,-0.21156591481123455
240.3000000000027,29.89271012110532,0.34852138456674914,-0.21420330631764095
241.4000000000027,29.998193467270866,0.3502875181728607,-0.21548046229999507
242.50000000000273,30.10226783762815,0.35251598384177496,-0.21956799907981317
243.60000000000275,30.20636229700695,0.354744456394618,-0.22212002077458148
244.70000000000277,30.311817812946423,0.3591850928007271,-0.2264964111069916
245.8000000000028,30.416548130069888,0.36307716769919396,-0.22974064058416488
246.9000000000028,30.52108098112443,0.3649482198448323,-0.23372063636600826
248.0000000000028,30.625951659753802,0.36851660817805915,-0.23874083603343266
249.10000000000284,30.731909941301932,0.3755107720399124,-0.24173135951861813
250.20000000000283,30.8356083007772,0.3781476321344359,-0.2454245547112941
251.30000000000285,30.94017080013726,0.38167481431416267,-0.2509016376524231
252.40000000000288,31.04493331426184,0.38600765816231447,-0.2547426656350442
253.5000000000029,31.149140256132434,0.3900442791308457,-0.25859154598810097
254.60000000000292,31.253971004819444,0.39280123712956916,-0.26265878850792923
255.70000000000292,31.35840083640335,0.396334753208778,-0.26893643942458434
256.8000000000029,31.463432024862556,0.39787648184211843,-0.2734521788748214
257.90000000000293,31.568542439081817,0.3977216039372001,-0.27697526036290654
259.00000000000296,31.673857886873847,0.3980597276677951,-0.283385839773286
260.100000000003,31.777804425966988,0.4017673781767348,-0.2893225434834994
261.200000000003,31.883350976291432,0.40526934096744716,-0.2937434295234569
262.300000000003,31.987554384339674,0.4065334674517004,-0.2999768876755704
263.40000000000305,32.09299331391855,0.4095518347233989,-0.3070271201164725
264.50000000000307,32.19669285010586,0.4144207989540562,-0.3135527300732166
265.6000000000031,32.303096438561035,0.4179025482612972,-0.3198400443629055
266.7000000000031,32.40779251644255,0.4203397751747123,-0.3265711999597358
267.8000000000031,32.51250011071901,0.42446747454781475,-0.33439326640120726
268.9000000000031,32.61702543349981,0.4282065034928537,-0.3427295897900722
270.0000000000031,32.721652790860155,0.4303788465494004,-0.3497079468682447
271.10000000000315,32.825886105333694,0.434633886451333,-0.35831212299585014
272.2000000000032,32.93220126149787,0.4361716157801525,-0.3661976472312394
273.30000000000314,33.03680924177989,0.44178677717462933,-0.3767645850326997
274.40000000000316,33.141648211855674,0.44378832062458573,-0.38683018313416273
275.5000000000032,33.246069653371784,0.4465233687071508,-0.3971505129606938
276.6000000000032,33.350580908723416,0.44767043963995623,-0.4076680045173995
277.70000000000323,33.455920159043295,0.4480438794166997,-0.41835663898042164
278.80000000000325,33.56128074468175,0.45077828766286454,-0.4300243091060221
279.9000000000033,33.66728557539796,0.4513696316564436,-0.44354502625182946
281.0000000000033,33.77110243697955,0.45439359368119886,-0.45488746850592365
282.1000000000033,33.87456789658653,0.4555985296582278,-0.4693934416725254
283.20000000000334,33.97976975377182,0.4561308185283399,-0.4823812015790243
284.30000000000337,34.086833623423544,0.45682449395251234,-0.498646586043483
285.40000000000333,34.19232444781662,0.456841529944976,-0.5137644505777392
286.50000000000335,34.29707827496758,0.4583619504078878,-0.5284154224281066
287.6000000000034,34.40237454241246,0.45838162671120347,-0.5437722397725158
288.7000000000034,34.50889010863836,0.4597871815327578,-0.5616673121642664
289.8000000000034,34.61440043196283,0.4586355192175626,-0.5789167646239148
290.9000000000034,34.71928035528364,0.4601211635415605,-0.5947481827264816
292.0000000000034,34.82390793958948,0.4611537913695467,-0.6125702014656915
293.10000000000343,34.92904851352677,0.46356843199492603,-0.631166703326941
294.20000000000346,35.034696071939564,0.4631716758763664,-0.650318684226797
295.3000000000035,35.13939340764165,0.4632279204670618,-0.6681152679536906
296.4000000000035,35.24489315243386,0.4660090449341742,-0.6868686986794605
297.5000000000035,35.349904377055225,0.4653963365443185,-0.7084248999711802
298.60000000000355,35.45475713519413,0.4694489592156921,-0.7275686636883023
299.70000000000357,35.56096953264151,0.4700854726523267,-0.7473794219051211
300.8000000000036,35.66671387429525,0.47062701892732356,-0.7674354280612175
301.9000000000036,35.77220709858196,0.4735127520568474,-0.787343901948625
303.0000000000036,35.87853037705459,0.4763916349899675,-0.8074122617888544
304.1000000000036,35.98392523219091,0.47933458238378723,-0.8276145813997369
305.2000000000036,36.08897579230308,0.48249626437857757,-0.8500312767240747
306.30000000000365,36.19344169616979,0.4859911441055074,-0.8692730398972852
307.4000000000037,36.30008811548434,0.4910228607352532,-0.8908931792503405
308.5000000000037,36.4060459884225,0.49512086241951836,-0.9109304265518174
309.60000000000366,36.51247013364176,0.4987726029141076,-0.9336206951094104
310.7000000000037,36.617440837632785,0.5055623291067082,-0.9535549647328239
311.8000000000037,36.72297587706142,0.5100418517862576,-0.9734578212581568
312.90000000000373,36.82763372163535,0.5164636624652014,-0.9936048787776599
314.00000000000375,36.934709537541444,0.5210707688689417,-1.0155398718481732
315.1000000000038,37.040666416496066,0.528046178765067,-1.0366489095769489
316.2000000000038,37.14652591395897,0.5304192834688136,-1.0562898066810842
317.3000000000038,37.25151538766722,0.535959632469455,-1.0778078306880308
318.40000000000384,37.35857613978137,0.5422629958710659,-1.100772974467707
319.5000000000038,37.464711547582866,0.5488317718266998,-1.1209605925211084
320.60000000000383,37.570090852886686,0.556545581571304,-1.1430162273981903
321.70000000000385,37.67624227730306,0.5662966803482647,-1.1639774651079202
322.8000000000039,37.78226722355819,0.5722025055469432,-1.1859137646985856
323.9000000000039,37.88724273064621,0.5800753416402453,-1.208364602917138
325.0000000000039,37.99376239449655,0.5870293573617797,-1.2320488495725703
326.10000000000394,38.10021575331302,0.5965933896003419,-1.2550919786433403
327.2000000000039,38.2063903767977,0.6062937170762647,-1.2791209746074403
328.30000000000393,38.31324061626781,0.6136878210055976,-1.3018238495332222
329.40000000000396,38.419477717129624,0.6256235720014686,-1.3273066145696077
330.500000000004,38.5258988393235,0.6351897725961211,-1.3521385262255468
331.600000000004,38.63290749857925,0.6418835081537576,-1.375302068661309
332.700000000004,38.73982249273229,0.6576037460859739,-1.401748225434499
333.80000000000405,38.84554490992401,0.6684038771182743,-1.4280337970317616
334.90000000000407,38.952181076323505,0.6783321885777106,-1.4540824915584163
336.0000000000041,39.058747213082405,0.6900302554443635,-1.4822239112269768
337.10000000000406,39.16584704696518,0.7023563670371379,-1.510741441196247
338.2000000000041,39.272449440283744,0.7157650246923204,-1.539287666687608
339.3000000000041,39.38009769544961,0.7287491928489878,-1.5686714603077392
340.4000000000041,39.485618355627736,0.7413443757663488,-1.600600392752261
341.50000000000415,39.5925815712353,0.7580274676306148,-1.6325883619363228
342.6000000000042,39.6987728634189,0.7692212037694218,-1.6628918402965809
343.7000000000042,39.805369738347565,0.7831309993756248,-1.6968981331371848
344.80000000000416,39.91074851915737,0.7997675376585288,-1.7326135190783116
345.9000000000042,40.01806692105183,0.8104577914263844,-1.7688097537439074
347.0000000000042,40.12505330945524,0.8253639937260906,-1.8046740888109456
348.10000000000423,40.23029273246625,0.8381664255495033,-1.8431614737846616
349.20000000000425,40.335877284064935,0.853276184795793,-1.8803649090013232
350.3000000000043,40.44311901154018,0.8647182121350241,-1.92064960026249
351.4000000000043,40.54928928252918,0.8779943751541293,-1.961883343205037
352.5000000000043,40.65604372714291,0.8872586685311752,-2.00296963066738
353.60000000000434,40.76229578561831,0.8986811560864474,-2.0455478303753942
354.7000000000043,40.86896941966983,0.907057484600864,-2.090630856885624
355.80000000000433,40.97552758900283,0.914026971807698,-2.135172510740128
356.90000000000435,41.08157614913418,0.9178361734523118,-2.1800215633102393
358.0000000000044,41.18800023761978,0.9201585269054324,-2.2261355681606574
359.1000000000044,41.29433192138323,0.9213731552066305,-2.271382890594556
360.2000000000044,41.40072436366131,0.9187520480659932,-2.3177142197780647
361.30000000000445,41.507096310011015,0.9134737890443979,-2.365761877512387
362.4000000000044,41.61360880452787,0.9049086141140749,-2.4101311002577237
363.50000000000443,41.72027475957396,0.8913125204758522,-2.4571808278381058
364.60000000000446,41.82709089873815,0.877048570005603,-2.5002149355999412
365.7000000000045,41.9326997055093,0.8568644343411128,-2.546906541580318
366.8000000000045,42.039512288907574,0.832665252847781,-2.590629299731671
367.9000000000045,42.146467690466594,0.8030054657595219,-2.631021788383797
369.00000000000455,42.252722560842905,0.7699684691479942,-2.6681642602298536
370.10000000000457,42.359238316647755,0.7358362733738325,-2.7055427699464873
371.2000000000046,42.46527116405296,0.6951865536816425,-2.739567087839809
372.30000000000456,42.57237107892426,0.6559163814690127,-2.7708440080974928
373.4000000000046,42.674653405833624,0.6142948591233663,-2.796670065057482
374.5000000000046,42.78457312944916,0.5715032187643733,-2.8226635775741133
375.6000000000046,42.89066623033139,0.5324922163544523,-2.844302289157582
376.70000000000465,42.9963276576718,0.49498971106238926,-2.8626562730927336
377.8000000000047,43.1022135629236,0.46220528384946363,-2.877931450975144
378.9000000000047,43.20824684973523,0.4364075868603842,-2.8904441752327403
380.00000000000466,43.31437281667822,0.4122782667893388,-2.900861583457689
381.1000000000047,43.42139385523151,0.3933369383740568,-2.9098809140356505
382.2000000000047,43.525912411966374,0.38187995715877077,-2.9176411853948765
383.30000000000473,43.63424198330986,0.3722822436643136,-2.9234720568935524
384.40000000000475,43.74138385925142,0.36672908066396526,-2.930560165156624
385.5000000000048,43.84736507446029,0.36022327761825396,-2.936642186405827
386.6000000000048,43.95531865691415,0.35756192664885,-2.942298249033169
387.7000000000048,44.06181244068107,0.3542628322164789,-2.9460244259526114
388.80000000000484,44.16917452334279,0.35364029591903395,-2.9511651812323665
389.9000000000048,44.27618499541669,0.35117523263158595,-2.9541897772720067
391.00000000000483,44.38384053217199,0.34959937491134613,-2.958379643905592
392.10000000000485,44.49074468586141,0.35025669344208776,-2.9630235707599413
393.2000000000049,44.59831470938227,0.34887870510356267,-2.966380620190048
394.3000000000049,44.70543044728211,0.3486719841359594,-2.971467956041403
395.4000000000049,44.813087659976205,0.349334024566637,-2.9782602617980465
396.50000000000495,44.92008700620567,0.350189006105367,-2.98084141404349
397.6000000000049,45.02786738866124,0.3476313338825752,-2.983546535522877
398.70000000000493,45.135084279880246,0.3485968947747056,-2.9875114432386307
399.80000000000496,45.242640773835355,0.34821221682999415,-2.990763281609609
400.900000000005,45.350285208213634,0.34857255624821926,-2.993195961591588
402.000000000005,45.458595360716664,0.34946420959640456,-2.997508624800694
403.100000000005,45.566188715651855,0.35086635713362846,-3.002238448306948
404.20000000000505,45.673672861707054,0.34949170894966775,-3.0047788046062216
405.30000000000507,45.782007590536864,0.349849102125823,-3.0089045932679044
406.4000000000051,45.890103592547206,0.35109635288251967,-3.011658923083318
407.50000000000506,45.99754465502393,0.35139182397330415,-3.015760693601374
408.6000000000051,46.10510754360503,0.35470639018027245,-3.018622282251364
409.7000000000051,46.21096488483004,0.35636726451091305,-3.0225296142649896
410.8000000000051,46.32072589394835,0.3566245221001886,-3.0251538585779865
411.90000000000515,46.428249322480944,0.35769041577544514,-3.0288662227965473
413.0000000000052,46.536810096211426,0.362379709955685,-3.031488465023975
414.1000000000052,46.64499091449976,0.3627459245547713,-3.0348556916739087
415.20000000000516,46.75297799603032,0.36699404387600054,-3.0380077035312576
416.3000000000052,46.860428527785935,0.3658071658856021,-3.041776394445559
417.4000000000052,46.96944280710118,0.3696067492071068,-3.0456070992253954
418.50000000000523,47.076856702815284,0.37431212742242403,-3.0461428139046522
419.60000000000525,47.18480392785968,0.37392295591323493,-3.0500843506584996
420.7000000000053,47.29249798722875,0.3793621676196302,-3.0527874205706658
421.8000000000053,47.40038126194041,0.3837134438278158,-3.058282048018441
422.9000000000053,47.50853011106923,0.38566095531701317,-3.0600804855267594
424.00000000000534,47.61598696816909,0.3919617074733303,-3.0624411449310145
425.1000000000053,47.723623712787784,0.39330790878980093,-3.0665046689734927
426.20000000000533,47.83149368849672,0.3970894327497116,-3.0704432898135128
427.30000000000535,47.939409137820775,0.40175570905587465,-3.071863759441749
428.4000000000054,48.04728585918676,0.40527226644299175,-3.0755788817828615
429.5000000000054,48.155764764887095,0.4095337599204533,-3.0777584991401006
430.6000000000054,48.26347888370878,0.4152829288273743,-3.079393932912143
431.70000000000545,48.371276042164965,0.41768537553300344,-3.0835042795370122
432.8000000000054,48.47847500446102,0.42166200622022026,-3.0856683628756567
433.90000000000543,48.586612257116606,0.42758862051870217,-3.0882961237029547
435.00000000000546,48.693717966120694,0.4284386925264954,-3.091231971055633
436.1000000000055,48.80176909282524,0.4349230680400072,-3.093787083283069
437.2000000000055,48.908952754436356,0.4382832761401067,-3.0964438064481286
438.3000000000055,49.01766727944046,0.4446119877102744,-3.0984614588029964
439.40000000000555,49.12602059161199,0.4496592902675138,-3.101063285872753
440.50000000000557,49.234177676899364,0.4513416660703652,-3.103049145490118
441.6000000000056,49.34200614491788,0.45728851707232937,-3.1057432770320066
442.70000000000556,49.44959929538566,0.46136791833728796,-3.109597053275798
443.8000000000056,49.55806999031945,0.46676464271750123,-3.1114928577831122
444.9000000000056,49.66646998101924,0.47024083031633507,-3.1142445097927203
446.0000000000056,49.774190902984145,0.4766610646854437,-3.1155924089873137
447.10000000000565,49.88177419167459,0.48339904551295193,-3.11692592794866
448.2000000000057,49.98999898622781,0.48609994001731976,-3.119479909207668
449.3000000000057,50.098203680228075,0.4903727555688423,-3.1235585430957657
450.40000000000566,50.20696203248989,0.4953646728185865,-3.126209833933422
451.5000000000057,50.31490722850459,0.49723371407927797,-3.1261701577178305
452.6000000000057,50.4225763640181,0.501514551251666,-3.1275038047480557
453.70000000000573,50.528802423291694,0.5092262072031549,-3.1301279880071244
454.80000000000575,50.63939288010738,0.5105178346505613,-3.132736302789864
455.9000000000058,50.748752145299676,0.516770231998198,-3.134070612320091
457.0000000000058,50.85645442630425,0.520350484436161,-3.1380281327483335
458.1000000000058,50.96482696155555,0.5236391007761546,-3.1393103409322127
459.20000000000584,51.07352767528553,0.5297887887486956,-3.141940013960488
460.3000000000058,51.182354176920725,0.5338438296116667,-3.1432800896247466
461.40000000000583,51.29009519998811,0.5379829076051087,-3.1445999542188527
462.50000000000585,51.398129087955816,0.5411084554728995,-3.1455127282254747
463.6000000000059,51.50680211926658,0.5459478454605523,-3.1472219174618674
464.7000000000059,51.615712975143474,0.5492829004457648,-3.149627503187798
465.8000000000059,51.724275054023394,0.5533505963240617,-3.152548316312095
466.90000000000595,51.83346671240596,0.5577849405271694,-3.15248166318616
468.0000000000059,51.94258438999578,0.5623448414037769,-3.1528834065236917
469.10000000000593,52.05009604750833,0.5637545204221841,-3.1544786655485746
470.20000000000596,52.159324254730215,0.5696860489128805,-3.1554203721068044
471.300000000006,52.266464245653,0.5738724858225718,-3.1567708969869606
472.400000000006,52.37576057082912,0.5772791133765457,-3.1580918471813146
473.500000000006,52.48434841015716,0.5806710610831926,-3.1596227758341673
474.60000000000605,52.5934197517586,0.5849165930679014,-3.1629743211492523
475.70000000000607,52.70201155399708,0.5891099918228667,-3.1646723134298234
476.8000000000061,52.81117743831806,0.593412140761725,-3.164658587829759
477.90000000000606,52.92032023508699,0.5944048171016418,-3.164675166338336
479.0000000000061,53.02799196971219,0.6007900325918226,-3.1673006132380976
480.1000000000061,53.13643418917034,0.6033206216297817,-3.168605027848216
481.2000000000061,53.24608754777582,0.6094016858029373,-3.1712485219185234
482.30000000000615,53.35360937862811,0.613478186876842,-3.1739396361766765
483.4000000000062,53.46351296172746,0.6160399837103234,-3.172428993988577
484.5000000000062,53.571561933284556,0.6180768041265078,-3.17578413936796
485.60000000000616,53.6806554162743,0.6247852652576553,-3.176729405248674
486.7000000000062,53.78898446723096,0.6238447096678708,-3.1780531087601775
487.8000000000062,53.89751459354263,0.6307756926572077,-3.1807393866351363
488.90000000000623,54.006663465387355,0.632996650577993,-3.180819465832889
490.00000000000625,54.11452418621534,0.6353591003643322,-3.180680257002785
491.1000000000063,54.223240189033255,0.6410760374039463,-3.1820612489539757
492.2000000000063,54.33242520497574,0.6447783885658539,-3.183541028406487
493.3000000000063,54.440995020707135,0.6467818509204718,-3.1840798086106297
494.40000000000634,54.54925485397896,0.6521282868794989,-3.1886661028177876
495.5000000000063,54.65821091120367,0.6565559983009566,-3.1900098484034594
496.60000000000633,54.76631310803991,0.6678817384200633,-3.1894128459933038
497.70000000000636,54.87536308915475,0.6823446807016889,-3.1899991047933858
498.8000000000064,54.98335251632596,0.6880932711134033,-3.1930142622311717
499.9000000000064,55.09219910450423,0.6975737401906132,-3.1936106821612533
501.0000000000064,55.19968472860509,0.7012066785696551,-3.1936200239024037
502.10000000000645,55.309470003822184,0.7075003462189938,-3.1942837333144043
503.2000000000064,55.41947673717213,0.709393280284865,-3.1939499179791664
504.30000000000643,55.527398738501034,0.7161206584580576,-3.1952749201217676
505.40000000000646,55.63642436318373,0.7211637347934335,-3.1959210030553593
506.5000000000065,55.74565562280893,0.7269417505878227,-3.196515178168939
507.6000000000065,55.85595448854585,0.7321329808830648,-3.197828581931931
508.7000000000065,55.96433197277587,0.7358748662072442,-3.200540604996113
509.80000000000655,56.0730386503309,0.7438464909721254,-3.2019049376646915
510.90000000000657,56.181437244732265,0.7479582321446604,-3.201848422044839
512.0000000000066,56.290815787810196,0.7539809934638269,-3.2031603818162857
513.1000000000065,56.40000200032175,0.7587102148391207,-3.2031612418950193
514.2000000000066,56.508851577278904,0.7628012741005564,-3.2044847013588047
515.3000000000065,56.61722765482004,0.7677919494160119,-3.205824331220775
516.4000000000067,56.72574303298157,0.7742739501365735,-3.2084666053015076
517.5000000000066,56.83506278277087,0.7786844425677412,-3.209727866364508
518.6000000000067,56.94325735715334,0.7824215141749694,-3.2110788355344484
519.7000000000066,57.05220013316797,0.7858079019282186,-3.210076300747107
520.8000000000067,57.16000106024052,0.7901401824884495,-3.2127100879046537
521.9000000000067,57.27041058520634,0.7922865249680942,-3.2127100960016417
523.0000000000067,57.37897448255334,0.7953602581347204,-3.212710093735136
524.1000000000067,57.487385466951594,0.7984262567315273,-3.2140327249877743
525.2000000000068,57.59669273018679,0.7990955834812143,-3.2153498552366
526.3000000000068,57.70571994543324,0.7944680377205955,-3.2166585264434717
527.4000000000068,57.81544779854414,0.7840860533010755,-3.215997137163988
528.5000000000068,57.92531930738955,0.7805909469910215,-3.2160290156655806
529.6000000000068,58.03463557623812,0.7778243599622972,-3.2173622063496454
530.7000000000069,58.1438724501463,0.7776135191802962,-3.2186415512646716
531.8000000000068,58.25228507366828,0.7794650212021546,-3.2200271844142976
532.9000000000069,58.362434888248494,0.7823781416247564,-3.220610500768256
534.0000000000068,58.471547074579185,0.7831640872399853,-3.222598855813674
535.100000000007,58.581209765111126,0.7857517886748528,-3.222577489058062
536.2000000000069,58.69057226140757,0.7851326037263183,-3.222682710591604
537.300000000007,58.799591520772594,0.7894896789290105,-3.2225799793346592
538.4000000000069,58.90959677065072,0.7916755841606546,-3.2265374289345004
539.5000000000069,59.019498536407326,0.7948849020345099,-3.2266255061605973
540.600000000007,59.12910875789174,0.7989009872605913,-3.226529936201975
541.700000000007,59.23810564751074,0.801169190977981,-3.2281809903348178
542.800000000007,59.3474197180948,0.8045684389316335,-3.2286874910894703
543.900000000007,59.45705197813551,0.8056822609771378,-3.2288303680109154
545.000000000007,59.56624462908949,0.8088330581571069,-3.22984785845136
546.1000000000071,59.67512417816797,0.8112749207327644,-3.2317992847534285
547.2000000000071,59.78510985983348,0.8149429031156004,-3.2319600523758636
548.300000000007,59.895031636384566,0.8155289248744468,-3.2324202053901847
549.4000000000071,60.00506860942624,0.8145865378506911,-3.23213050474544
550.500000000007,60.114203392902674,0.8164995547881282,-3.2334398952396195
551.6000000000072,60.22450421828414,0.8182549957330836,-3.2331086522347543
552.7000000000071,60.33328312707341,0.8204303153281174,-3.234091296280644
553.8000000000072,60.443241116764455,0.8214510252561872,-3.234100120073088
554.9000000000071,60.55272845070314,0.8232381603750996,-3.234762379393902
556.0000000000072,60.663055834366524,0.8243762633477493,-3.2354945112309905
557.1000000000072,60.77221031046548,0.825106137021766,-3.2380481993710837
558.2000000000072,60.88259684256203,0.827856476263666,-3.238049951161511
559.3000000000072,60.99150655684545,0.8286481029456376,-3.2374124718317603
560.4000000000073,61.10220905468249,0.832896673430969,-3.2380482890816364
561.5000000000073,61.21238707675253,0.8338541558935894,-3.241243266347891
562.6000000000073,61.32228936085986,0.8385041445311938,-3.2405839516964887
563.7000000000073,61.43214565251874,0.8393007344149609,-3.2413493788810643
564.8000000000073,61.54216607361035,0.8414793269384604,-3.241016742125921
565.9000000000074,61.65203732901791,0.8458523997329344,-3.2433154464253247
567.0000000000074,61.76183136512007,0.8462462364836434,-3.2446302184112596
568.1000000000074,61.87221817570818,0.8506054597397569,-3.243309773682104
569.2000000000073,61.98299890349266,0.8538524069470015,-3.2446331329379667
570.3000000000073,62.09185363133676,0.8569979733631838,-3.2472718697410388
571.4000000000074,62.20268604115396,0.861713687825582,-3.245923074736211
572.5000000000074,62.31152591984583,0.8637957893805353,-3.245949946953856
573.6000000000074,62.422935661764036,0.8689153038765041,-3.2459404026442975
574.7000000000074,62.53200249604335,0.8748358519728174,-3.2459401759995323
575.8000000000075,62.642117761682364,0.8765008113078678,-3.2459409844646454
576.9000000000075,62.7529554188506,0.8809811978073229,-3.2472293469138105
578.0000000000075,62.86190416578972,0.8851014704160002,-3.2485707418625562
579.1000000000075,62.97153310159026,0.8887520864050527,-3.249668706273754
580.2000000000075,63.08304518980327,0.8939988186703844,-3.2508794798088276
581.3000000000076,63.19317030660166,0.8951181494291847,-3.25185966886171
582.4000000000076,63.303349192093926,0.902069713639389,-3.2521904952266754
583.5000000000076,63.415219680512344,0.9040150717265923,-3.2535091614688425
584.6000000000076,63.5244361916573,0.9071964523208316,-3.2525292285151863
585.7000000000077,63.634512583400124,0.9130434073584667,-3.2538299651674727
586.8000000000077,63.74371881936208,0.9180522976204646,-3.2538398240403157
587.9000000000076,63.85482251364483,0.9203127053867977,-3.2537448572224856
589.0000000000076,63.96537967964438,0.9246197060129002,-3.2564804399533527
590.1000000000076,64.0762588079058,0.926951144592006,-3.255149388153911
591.2000000000077,64.18470528750738,0.9332540258411284,-3.2552240816400193
592.3000000000077,64.2956852268263,0.9379531225215313,-3.2564700073160573
593.4000000000077,64.40568681121493,0.9415658466711875,-3.2567804889784115
594.5000000000077,64.51636528647425,0.9464448373145882,-3.2587803460081846
595.6000000000078,64.62603746074872,0.9516695620254227,-3.2587798720037195
596.7000000000078,64.73736408193322,0.9560362431516746,-3.2587717559676457
597.8000000000078,64.84741586813689,0.960347100554464,-3.260036148493042
598.9000000000078,64.95836380045847,0.965678475270506,-3.2600901920256207
600.0000000000078,65.06885365424633,0.9691193427945656,-3.2600884725012804
601.1000000000079,65.18020919528512,0.9763931782193588,-3.261410054744344
602.2000000000079,65.2892609080988,0.9816501301506286,-3.262399508369592
603.3000000000079,65.40081501802655,0.9833369019509725,-3.2623998543056603
604.4000000000078,65.51152414276311,0.989023519126361,-3.263510297428846
605.5000000000078,65.62184727426705,0.9960961037880186,-3.2640369481844207
606.6000000000079,65.73255373754246,1.0003948865532064,-3.2653598476058727
607.7000000000079,65.84404534107341,1.0070070002045821,-3.2646999175850553
608.8000000000079,65.95412561345479,1.0117929789909443,-3.2643678742767452
609.9000000000079,66.06494326565986,1.0177030978541972,-3.2656762833190847
611.000000000008,66.17411141339232,1.0211042967963633,-3.2656799120635194
612.100000000008,66.28409481166443,1.0276101879274735,-3.266442590786786
613.200000000008,66.39385758339432,1.034041664347002,-3.2670141472704857
614.300000000008,66.50524529306324,1.0403882218238436,-3.2683558582526917
615.400000000008,66.61537776026094,1.0457520263766906,-3.2696300873615765
616.5000000000081,66.72454675523029,1.0515581954629087,-3.269046414649205
617.6000000000081,66.83550885886217,1.0590544657583194,-3.268981730567078
618.7000000000081,66.9448726433257,1.0650064534592467,-3.27030007798452
619.8000000000081,67.05536898665723,1.0702800823395981,-3.2696394481682365
620.9000000000082,67.16556596122393,1.076173355364325,-3.270943130527957
622.0000000000082,67.27557627387479,1.0814829404317918,-3.2722703527484325
623.1000000000081,67.38550900476226,1.089435372436908,-3.2696308418242284
624.2000000000081,67.49627439430775,1.096795812559062,-3.2709505078673375
625.3000000000081,67.60595047962171,1.1040868275650693,-3.2712800323034372
626.4000000000082,67.7166371618732,1.1100914867046248,-3.2726047988389793
627.5000000000082,67.82526629683373,1.115787279540734,-3.2738540785484176
628.6000000000082,67.93835540158604,1.1233955840332581,-3.274564476681776
629.7000000000082,68.04946720707059,1.1301632877756744,-3.2736629146880967
630.8000000000083,68.16048418753014,1.137988385436629,-3.2746803822415114
631.9000000000083,68.26962460053846,1.1438498908140897,-3.276000090050493
633.0000000000083,68.3808565163814,1.1522579659613403,-3.276652019744512
634.1000000000083,68.49202687456084,1.1567438857918537,-3.2761778149221534
635.2000000000083,68.60253236024789,1.1596611401339016,-3.275674376635119
636.3000000000084,68.71411342665724,1.1709897219411693,-3.27437649245473
637.4000000000084,68.82472305588091,1.176623474958278,-3.2756700868039674
638.5000000000084,68.93511105225159,1.1806888624637546,-3.275670086666492
639.6000000000083,69.0465579136236,1.1867341404240248,-3.2770165974261585
640.7000000000083,69.15690485915498,1.1914851982033374,-3.2768874529130034
641.8000000000084,69.26652811719454,1.1973259697998102,-3.277627861214133
642.9000000000084,69.37806140106592,1.2020926775634388,-3.2789598221026934
644.0000000000084,69.48859418837156,1.2082120311446727,-3.2803042390278283
645.1000000000084,69.60046992565972,1.214243344156622,-3.2799079470374495
646.2000000000085,69.71104881488476,1.218248163963917,-3.2802789314194554
647.3000000000085,69.82361659196366,1.2221994903417863,-3.280280145329772
648.4000000000085,69.93383275471103,1.226766301467389,-3.279950126774396
649.5000000000085,70.04509611378037,1.2315334869829753,-3.281262477701787
650.6000000000085,70.15643160604343,1.23798625126049,-3.2809451961997507
651.7000000000086,70.26890234139827,1.2413662832976489,-3.2796275804254154
652.8000000000086,70.37974408815724,1.2479993349099183,-3.279280130012636
653.9000000000086,70.49125809070885,1.254195127625485,-3.2805996224333533
655.0000000000086,70.601770721698,1.2582442745545723,-3.281593714937702
656.1000000000087,70.7125607337878,1.268036773278105,-3.2820251258147906
657.2000000000087,70.8222489351862,1.2730731191847207,-3.2812704009831535
658.3000000000086,70.9342388493097,1.2767452386482994,-3.282249928043635
659.4000000000086,71.04438786100049,1.2827579364692072,-3.2822098801496433
660.5000000000086,71.15497775629784,1.2887397150293518,-3.284550101329868
661.6000000000087,71.26530201740799,1.293236341378564,-3.2832399920622635
662.7000000000087,71.37602073416645,1.3002631015026511,-3.2859720665879895
663.8000000000087,71.48650516100207,1.303472943905388,-3.284530900441929
664.9000000000087,71.59658274183894,1.3083998072518108,-3.2844500479660157
666.0000000000088,71.70683368579878,1.3150352275413557,-3.2844500479998633
667.1000000000088,71.81768229281221,1.3242435493171938,-3.2844503737379496
668.2000000000088,71.92899735466617,1.3288670435612016,-3.2834571354571827
669.3000000000088,72.03881308167476,1.3338593511129118,-3.284770112478998
670.4000000000088,72.15113059112969,1.3406388423438078,-3.284434363088957
671.5000000000089,72.26218018471636,1.3466964579046974,-3.285758410339415
672.6000000000089,72.37344411424671,1.3528166168155746,-3.2870499018106347
673.7000000000089,72.48432512432582,1.3572690345331118,-3.2860900597079334
674.8000000000088,72.59515616604449,1.3609487423222966,-3.286332404127421
675.9000000000088,72.70620699856222,1.3695049580254806,-3.2873499204191674
677.0000000000089,72.81846288512001,1.3752247496238006,-3.287400040006431
678.1000000000089,72.92949566413807,1.3820986647153026,-3.2874032424725317
679.2000000000089,73.04010349143446,1.3877226990518114,-3.286750224350132
680.3000000000089,73.1509472912444,1.392209118754291,-3.286089097163428
681.400000000009,73.26204280367688,1.3976119859385796,-3.2887338766094745
682.500000000009,73.37372479335467,1.4062204274180148,-3.2875081765661496
683.600000000009,73.48433255452653,1.411947678498666,-3.289074238489029
684.700000000009,73.59567543044346,1.4172316324314413,-3.2893797958446784
685.800000000009,73.70722328545484,1.4251475567359286,-3.2880655903790714
686.9000000000091,73.81918157190303,1.431007916371694,-3.289380086632298
688.0000000000091,73.93000000000089,1.436020000000011,-3.2906999519999927
689.1000000000091,74.04101257115478,1.44287741040795,-3.2906999520036817
690.2000000000091,74.15191690326833,1.4483793433442937,-3.2906999519996125
691.3000000000092,74.26343343927847,1.456742370710661,-3.29070135639833
692.4000000000092,74.37378795524144,1.4599133003216953,-3.29035508223091
693.5000000000091,74.48473339736377,1.4685757757460198,-3.2898514649501887
694.6000000000091,74.59589565491714,1.4756908122192824,-3.289709951985564
695.7000000000091,74.70598345436466,1.4844293714989816,-3.289709952001335
696.8000000000092,74.81751322679723,1.4879410016494978,-3.2897076985727787
697.9000000000092,74.92791931983962,1.4954920900684965,-3.2908642710363667
699.0000000000092,75.03924375227865,1.501869522734286,-3.290688883293857
700.1000000000092,75.15072871693454,1.5073625599781413,-3.2907049578861916
701.2000000000093,75.25960234822415,1.5137653673566682,-3.291389888360812
702.3000000000093,75.37084905822303,1.5182480517501145,-3.2919983970317306
703.4000000000093,75.48465941824638,1.5238470217501632,-3.292010010958582
704.5000000000093,75.59658418831145,1.533146776810434,-3.2933444313594
705.6000000000093,75.70748057210898,1.5387140655380798,-3.293330070506534
706.7000000000094,75.81897881225044,1.5436998178116517,-3.294221214617991
707.8000000000094,75.9306101601174,1.553606738490761,-3.2933300961313052
708.9000000000094,76.04099254527016,1.55506689632493,-3.2933300633077423
710.0000000000093,76.15234895888035,1.565823536657615,-3.2946462644113232
711.1000000000093,76.26404499586273,1.5716629411465002,-3.293241563008555
712.2000000000094,76.3746498104653,1.5776479843807343,-3.2946399543155485
713.3000000000094,76.48641023171487,1.5849140731682199,-3.2936946580805193
714.4000000000094,76.59573760051234,1.5916877555008349,-3.294646157624397
715.5000000000094,76.7096180209974,1.5970222350272438,-3.295969857240835
716.6000000000095,76.82075875934144,1.6051265826552035,-3.295969855999984
717.7000000000095,76.93244565949577,1.6108131609737544,-3.2959699982521684
718.8000000000095,77.04392982435068,1.616959867977117,-3.296937102443895
719.9000000000095,77.1552527427583,1.624670776172585,-3.2942350421692588
721.0000000000095,77.26575689778143,1.6291043673755532,-3.2982670103405685
722.1000000000096,77.37854106393279,1.6382463301487928,-3.2960845638036522
723.2000000000096,77.48935883683227,1.645264793619477,-3.2971398618026813
724.3000000000096,77.60102770946816,1.6547140682245478,-3.29848997162988
725.4000000000096,77.71312165569923,1.659723487038668,-3.2998272597504785
726.5000000000097,77.82452868187599,1.6669238166155798,-3.2991400399135746
727.6000000000097,77.93596680828524,1.6749763625642153,-3.2991400400049615
728.7000000000096,78.04864279077556,1.6836107039085444,-3.299110794173477
729.8000000000096,78.15959195512028,1.68629360866326,-3.299800593481467
730.9000000000096,78.27077318610174,1.695259332729677,-3.2992208032682044
732.0000000000097,78.38211345522832,1.7029805378970047,-3.298489570583457
733.1000000000097,78.49395196279285,1.7069810004153583,-3.3011397527465833
734.2000000000097,78.60455842562499,1.7161845283193324,-3.3024060368672767
735.3000000000097,78.71669199767558,1.7249990524731684,-3.2997992019946
736.4000000000098,78.8282354738999,1.730895953467549,-3.300449932263059
737.5000000000098,78.93906637877156,1.73930961194326,-3.2978323769804367
738.6000000000098,79.05079772884166,1.7435466061337668,-3.3004474741436103
739.7000000000098,79.16351842341524,1.752723301241628,-3.3010923219705703
740.8000000000098,79.27472720860874,1.7582561657772593,-3.302160544655482
741.9000000000099,79.3858603709067,1.7662611824448644,-3.302110087976457
743.0000000000099,79.49812753488644,1.7727568579429867,-3.3021142400175814
744.1000000000099,79.6100021194908,1.781979934742648,-3.302120235130254
745.2000000000098,79.72137201450239,1.7891447050424256,-3.3017700282324225
746.3000000000098,79.83305989889475,1.7942653274127125,-3.30309006874086
747.0000000000099,79.90346603139402,1.7983185894334839,-3.3028994351794863