File: 01_Data/Basswood_Panel/STA/N2/10K_min/Basswood_Panel_STA_N2_10KData_220315_R3.csv
##Temp./Â°C,Time/min,DSC/(mW/mg),Mass loss/mg
50.0,10.640334912528497,-1.0745054804903325,-0.03481968491404208
51.100000000000016,10.99145560733999,-0.9408209012759889,-0.03664501665521325
52.20000000000003,11.210000000000008,-0.8563199999999977,-0.03651801116776765
53.30000000000005,11.389854481537306,-0.7928926317897722,-0.03717220917881914
54.40000000000006,11.550403409636322,-0.742698227124453,-0.03773113282770657
55.50000000000008,11.697452217398775,-0.7014711411672708,-0.03756275163996836
56.600000000000094,11.836425385258803,-0.6673663622745755,-0.03784915667651889
57.70000000000011,11.971131521771097,-0.6385217912910975,-0.03867426712271893
58.800000000000125,12.099630960259042,-0.6152974176020416,-0.03796670400509061
59.90000000000014,12.226803600785638,-0.5939587021254081,-0.03825353817624677
61.000000000000156,12.352676787836376,-0.5775128084927035,-0.04028049416683244
62.10000000000017,12.476746074707336,-0.5612915175964934,-0.03905764554735702
63.20000000000019,12.598368604578248,-0.5458979406107277,-0.03909951826587088
64.30000000000021,12.718957327647702,-0.531987629236178,-0.04169268901001999
65.40000000000022,12.838526812532972,-0.5199535530314624,-0.04131269409825489
66.50000000000023,12.957392165541384,-0.5052623371868299,-0.041663013772535784
67.60000000000025,13.07667492827158,-0.49402553318243014,-0.04167014706470962
68.70000000000027,13.194486820454093,-0.48137051471587344,-0.041677928922982055
69.80000000000028,13.310202777050916,-0.4706983005872099,-0.04211764288772901
70.90000000000029,13.428087452129366,-0.4577810027039601,-0.04298252280283332
72.00000000000031,13.544703666494476,-0.44809385461730905,-0.04296509786571612
73.10000000000034,13.660332141933523,-0.4372864333185214,-0.043102256754822044
74.20000000000034,13.776359651364976,-0.426578280002114,-0.04464041783253325
75.30000000000035,13.89281355966989,-0.41531388754496484,-0.045034253415038084
76.40000000000038,14.006460799743367,-0.40508170365782764,-0.045654381462066684
77.5000000000004,14.121099919546268,-0.3956897415184943,-0.04562027593166729
78.6000000000004,14.236061567208665,-0.3859956084476559,-0.04694107550519444
79.70000000000041,14.349430055746058,-0.3780821777376028,-0.04693947573084278
80.80000000000044,14.462562795114836,-0.3682251026574365,-0.04693133325245569
81.90000000000046,14.576589218788474,-0.35847738954032443,-0.04825007514615365
83.00000000000047,14.690561839096597,-0.34810784584390997,-0.048268245719358394
84.10000000000048,14.801467157334944,-0.34157582355202726,-0.04951639292985366
85.2000000000005,14.91438221951618,-0.3315053092994321,-0.04955495778075525
86.30000000000052,15.02514899832999,-0.32400121420858635,-0.0497635098081326
87.40000000000053,15.13683479870802,-0.31559094854148645,-0.049794071807704565
88.50000000000054,15.247480694365269,-0.3098609476179585,-0.05122109570609057
89.60000000000056,15.357166140415842,-0.3034824592170027,-0.052173726172527246
90.70000000000059,15.46726049149093,-0.2966511862929471,-0.05153973358601238
91.8000000000006,15.577401146153303,-0.29094712859700966,-0.05222026882054953
92.9000000000006,15.68662294437818,-0.2864489085301631,-0.053181201938703015
94.00000000000063,15.798096829584901,-0.2814374926281667,-0.05352006597661063
95.10000000000065,15.90617632571408,-0.2757663662594719,-0.053514460752872584
96.20000000000066,16.01591694726603,-0.2706790094292848,-0.05477792940621207
97.30000000000067,16.12633427920683,-0.26760593544350886,-0.05546180842648418
98.40000000000069,16.234116377273136,-0.26034454348599345,-0.055494682818146845
99.50000000000071,16.343533159123126,-0.25380160775937316,-0.0561973827914346
100.60000000000072,16.451971170860567,-0.24938276144906976,-0.05493526732613052
101.70000000000073,16.56040016369818,-0.24441299066532896,-0.05614620900272982
102.80000000000075,16.668838425387293,-0.23857045875347505,-0.05649416429247722
103.90000000000077,16.775844126229746,-0.23223307452604777,-0.0573829301185631
105.00000000000078,16.885017187288994,-0.22677683070317173,-0.05812766902659883
106.10000000000079,16.99182466772058,-0.2200774994882211,-0.05812965215925869
107.20000000000081,17.100878027041162,-0.21341466267468626,-0.05814879584454724
108.30000000000084,17.20988519456604,-0.21004257186078254,-0.05943997402467538
109.40000000000084,17.316889942448736,-0.2048252596032845,-0.05940157438634275
110.50000000000085,17.424524529138612,-0.1979537114315786,-0.05943991462991205
111.60000000000088,17.53210373064074,-0.19034714025919683,-0.059839769061368564
112.7000000000009,17.639309494541756,-0.18485472152249743,-0.05943994492189297
113.8000000000009,17.74778607368657,-0.17852301218672237,-0.0607595481694827
114.90000000000092,17.854445002626065,-0.1727660902229277,-0.06028338399666611
116.00000000000094,17.96239826972484,-0.16456633135528226,-0.06206788799790308
117.10000000000096,18.069609573306998,-0.1611395941328664,-0.06206982756878077
118.20000000000097,18.17710927062688,-0.1527295032473502,-0.060752687640892145
119.30000000000098,18.283888741847015,-0.1460770344361397,-0.062080111586214404
120.400000000001,18.39194823654839,-0.13994145500854996,-0.06073482508873029
121.50000000000102,18.498385054184993,-0.1325284290712413,-0.06207414444965309
122.60000000000103,18.604927003092957,-0.1268893177870534,-0.06102390885361375
123.70000000000104,18.71227136721466,-0.11961547245945363,-0.06121089008168301
124.80000000000106,18.818976453466277,-0.11300724746986385,-0.06041607301306273
125.90000000000109,18.926365096526286,-0.10878631833425713,-0.06194941316659541
127.0000000000011,19.03346760986152,-0.10175921932708636,-0.06207703208573978
128.1000000000011,19.14035889289198,-0.09711632918393515,-0.06338999709704574
129.20000000000113,19.246827002492278,-0.08997419907575335,-0.06239881252717039
130.30000000000115,19.353954174867386,-0.08530244770232435,-0.06174378442430761
131.40000000000117,19.45980738612584,-0.07777829650435852,-0.06321687419063826
132.50000000000117,19.567728981747322,-0.07134261959878875,-0.06305991057106697
133.6000000000012,19.674016478647435,-0.06489528485834992,-0.06305992152901574
134.7000000000012,19.78187239874311,-0.06161001907622075,-0.06434556336004738
135.8000000000012,19.887432352574788,-0.053018144203815905,-0.06418129941464867
136.90000000000123,19.994245427315096,-0.04715558186137393,-0.06437976845660653
138.00000000000125,20.100302983243047,-0.041407882489334656,-0.06437582903737127
139.10000000000127,20.207204097715955,-0.03558105139741696,-0.0656995182131821
140.2000000000013,20.313628482211328,-0.02793095026246704,-0.06705514009730695
141.3000000000013,20.421555071072365,-0.02282097783805983,-0.06587486097773043
142.4000000000013,20.527068941445464,-0.016137500053906902,-0.06733933961347072
143.50000000000134,20.633081216626273,-0.009436430364382312,-0.06697717285458227
144.60000000000133,20.73931902246487,-0.002734741248303063,-0.06833019587084221
145.70000000000135,20.845047798843055,0.003509705024650092,-0.06707541107689785
146.80000000000138,20.950742960168537,0.009274651207423129,-0.06702127091150212
147.9000000000014,21.056508230226438,0.013628013249669448,-0.06833009157694381
149.00000000000142,21.163170270269614,0.021753252537054384,-0.06833009332372741
150.10000000000142,21.268241048063985,0.02480439559762269,-0.06900609186385731
151.20000000000144,21.373600731396113,0.031535693240314286,-0.06921002205214455
152.30000000000146,21.48000000000015,0.04022157000000155,-0.06964006815138113
153.40000000000146,21.585560443233533,0.04546380215661869,-0.06964006800001155
154.50000000000148,21.692196726264847,0.05089650011350592,-0.06964004890325359
155.6000000000015,21.79694112567028,0.0565284370501695,-0.07095964725364245
156.70000000000152,21.902291489085165,0.062031675742772484,-0.06964200575813173
157.80000000000155,22.008597846518636,0.06907009737889311,-0.07161989425424942
158.90000000000154,22.11325630472329,0.0743206305811707,-0.07164267896988141
160.00000000000156,22.21924309875311,0.07819882323645193,-0.07292985581671196
161.1000000000016,22.325296631918178,0.08482079313660273,-0.07289779036198363
162.20000000000158,22.43009195577551,0.09028971172850728,-0.07289868246301312
163.3000000000016,22.536654265900065,0.0948461540035063,-0.07326013591559555
164.40000000000163,22.643055628726508,0.09920127299036269,-0.0732649913418304
165.50000000000165,22.748024938153712,0.10579247582390269,-0.07458013502032212
166.60000000000167,22.854536781071527,0.11250065822628234,-0.07458013599389135
167.70000000000167,22.96036813779972,0.11687821002449632,-0.0745852804273599
168.8000000000017,23.06624190361093,0.12171256273976253,-0.07585030632950485
169.9000000000017,23.171904525255535,0.1294840692488158,-0.07688013664521343
171.0000000000017,23.277716876507395,0.13380205939261128,-0.07714447873332819
172.10000000000173,23.382810088357,0.13958299087685624,-0.07721013605946414
173.20000000000175,23.488383516568586,0.14561728472598484,-0.07721013969973312
174.30000000000177,23.593042800998017,0.15158061724290897,-0.07851842222826733
175.4000000000018,23.70000093200921,0.1572301071569121,-0.07885013627934212
176.5000000000018,23.80488301017272,0.16363534612544242,-0.07984019013167121
177.6000000000018,23.909808016009613,0.1682418451966497,-0.07984013600006623
178.70000000000184,24.01483945260685,0.17378632177277759,-0.07984010815169418
179.80000000000183,24.120270822770387,0.17874772213779114,-0.08116034030551411
180.90000000000185,24.2224220664553,0.18385018335754294,-0.08248022044982273
182.00000000000188,24.330489122160877,0.18882006777854726,-0.08308985069089303
183.1000000000019,24.436308864132346,0.1956249684510818,-0.08379052105738571
184.20000000000192,24.541591213578556,0.20115703265888274,-0.08379016100048897
185.30000000000192,24.646931073238257,0.20544117381192462,-0.08379228997311072
186.40000000000194,24.751809299138305,0.21084613684793935,-0.0851087169253848
187.50000000000196,24.856739603949652,0.21634259267439235,-0.08643183746075733
188.60000000000196,24.962031805323758,0.22454244735215212,-0.08642822071749556
189.70000000000198,25.066885687430005,0.22649180570639468,-0.08775018415269908
190.800000000002,25.17229254053095,0.23262906962973934,-0.08775018947107904
191.90000000000202,25.27634928589045,0.23829961473972955,-0.08839662436016704
193.00000000000205,25.38235731283223,0.24515934295909841,-0.09036977106171795
194.10000000000204,25.487744562940232,0.2514233245928768,-0.09036989603633883
195.20000000000206,25.592684041450866,0.2576805887123213,-0.09136613081263834
196.3000000000021,25.69806573775033,0.26298684231594566,-0.09267741589745393
197.40000000000208,25.802653146667517,0.2690766871455674,-0.0944062471883913
198.5000000000021,25.908712500398167,0.2745734378030923,-0.09429230813080602
199.60000000000213,26.01368607887428,0.27999217795367126,-0.09666749456251189
200.70000000000215,26.11910757273297,0.2851531707686346,-0.09662003901420801
201.80000000000217,26.22344032691488,0.29097678908414654,-0.09661770030965178
202.90000000000217,26.33020620638436,0.29723024905179524,-0.09827048461211163
204.0000000000022,26.434108444272585,0.3038909777900382,-0.09955708381859196
205.1000000000022,26.540718484479463,0.3103811515317291,-0.10191941694532147
206.2000000000022,26.642652267367016,0.3165741802612037,-0.10187563742910433
207.30000000000223,26.749434735597724,0.3226475046954044,-0.10250581396794667
208.40000000000225,26.85571073060871,0.32973391358551574,-0.10538391974090988
209.50000000000227,26.960913533579905,0.33326327466207756,-0.10484988814422236
210.6000000000023,27.065168183517944,0.3393566087628851,-0.10758048745760806
211.7000000000023,27.169064673532365,0.34569287823722017,-0.10880971467393197
212.8000000000023,27.275150859018943,0.35350389020642176,-0.11144041642886737
213.90000000000234,27.379496111042215,0.35841366694980187,-0.11275011503654353
215.00000000000233,27.483996991039803,0.3632445643414723,-0.1153791523996639
216.10000000000235,27.58807756845061,0.3690796346119085,-0.116699922064194
217.20000000000238,27.693833245837407,0.37457631247940837,-0.1192526313496276
218.3000000000024,27.798226523856453,0.37854643989194814,-0.1206502484507519
219.40000000000242,27.90314810106541,0.3833831099509113,-0.12328662649562183
220.50000000000242,28.008138562309274,0.3865278909575379,-0.12512865518773664
221.60000000000244,28.11315135955785,0.39074485673484655,-0.12618106668999607
222.70000000000246,28.217685727349284,0.3914032026300135,-0.1279136436832795
223.80000000000246,28.322017597402386,0.3954243930596545,-0.1310770746799852
224.90000000000248,28.428699037313574,0.39716272156811094,-0.1338124971400001
226.0000000000025,28.533048016790723,0.40053365106037525,-0.13512846609062779
227.10000000000252,28.638261912336404,0.402679292902138,-0.1372688267895641
228.20000000000255,28.743350555717374,0.4046989807463833,-0.14104481297633287
229.30000000000254,28.84922439631834,0.40841413595352277,-0.14274986340980522
230.40000000000256,28.953390140276273,0.40980611954497936,-0.14640313034513897
231.5000000000026,29.058662021350216,0.41246842461913347,-0.1487469707273137
232.60000000000258,29.163710776603228,0.4154552310902561,-0.15100042532424007
233.7000000000026,29.269176626748163,0.41909284683546905,-0.15444869715732334
234.80000000000263,29.374092148363793,0.42079148057124316,-0.15701968115491027
235.90000000000265,29.479241731249157,0.4254480103075516,-0.1607890354407724
237.00000000000267,29.585043206659115,0.428323475341714,-0.16351002192719521
238.10000000000267,29.69029890190129,0.4295821152629918,-0.16617118102961692
239.2000000000027,29.794816967968625,0.4331335206909717,-0.16973970629285118
240.3000000000027,29.900281641852587,0.4380142423156012,-0.17285773068742216
241.4000000000027,30.005144252785698,0.43980699278024493,-0.1754755902952354
242.50000000000273,30.110000000000227,0.4433800000000542,-0.1784498858248944
243.60000000000275,30.212224516837946,0.44635461292673806,-0.18232918982343183
244.70000000000277,30.319302686582432,0.4513465695171931,-0.18535743784386227
245.8000000000028,30.42511350124869,0.4532154129437875,-0.18834223872232903
246.9000000000028,30.52936185039245,0.4559920269535947,-0.19336004714751187
248.0000000000028,30.63550045909205,0.46045339251194667,-0.196851641381659
249.10000000000284,30.740286134057673,0.46383503458474573,-0.20073679711064463
250.20000000000283,30.845193976315244,0.4682594333615829,-0.20562792297767585
251.30000000000285,30.947714587976886,0.46944276145088476,-0.20873914489658896
252.40000000000288,31.054292111145443,0.47527418486214257,-0.2126899936639166
253.5000000000029,31.159914799234183,0.4777761703188287,-0.2188170587979763
254.60000000000292,31.264985298280767,0.4821341763993107,-0.22210481720967712
255.70000000000292,31.369904625476888,0.4880271401475042,-0.22768667676221144
256.8000000000029,31.47426487982023,0.48998055429261084,-0.23182148212354559
257.90000000000293,31.579708627094384,0.4935461608123241,-0.23634570213356376
259.00000000000296,31.6841635678398,0.4975849739569761,-0.24115253901384914
260.100000000003,31.789364597859304,0.5030192762816114,-0.24863216063282456
261.200000000003,31.894981715664503,0.5076714913447086,-0.25232430581811016
262.300000000003,31.99849439721157,0.51107065532764,-0.25806403056741534
263.40000000000305,32.103720743681365,0.5143679771094639,-0.2659123350137311
264.50000000000307,32.20735777590451,0.5191380772942183,-0.271551299622089
265.6000000000031,32.311975638862656,0.5231076296208843,-0.27808145153230024
266.7000000000031,32.41716460466639,0.5260475422271322,-0.2858584791768237
267.8000000000031,32.522036769572004,0.5298400809774975,-0.2947487020591386
268.9000000000031,32.62639112874739,0.5331332621842826,-0.30117249811616364
270.0000000000031,32.73167039586354,0.5364233227691244,-0.31031131712538906
271.10000000000315,32.83633357582591,0.5364640216993899,-0.31859100506168403
272.2000000000032,32.94071937529228,0.5414152920404941,-0.3282091742684776
273.30000000000314,33.04621096512363,0.5429042108725702,-0.3371625880299156
274.40000000000316,33.15106187226282,0.5451622388774745,-0.3480216594618488
275.5000000000032,33.25645462309279,0.5464615758056562,-0.3579588027194536
276.6000000000032,33.36199783260614,0.5495679220992933,-0.37001724612053577
277.70000000000323,33.46707547590565,0.5524035946243369,-0.3806982149929965
278.80000000000325,33.573232935942855,0.5521340735604404,-0.3927032132375379
279.9000000000033,33.67778956737801,0.5536018467874004,-0.4037853640007758
281.0000000000033,33.783090685161895,0.5544900752875617,-0.4190822466938364
282.1000000000033,33.88789437382793,0.5574034239977975,-0.43261818988000567
283.20000000000334,33.99365090221749,0.5571170966973678,-0.44536571890868704
284.30000000000337,34.09846955928674,0.5575507183241849,-0.46095052699052497
285.40000000000333,34.20366143693769,0.5601221959246195,-0.47521947787740526
286.50000000000335,34.309681093751756,0.5626917220472634,-0.49058273849676715
287.6000000000034,34.414036988663156,0.563495860815284,-0.5067092102850084
288.7000000000034,34.520184316410635,0.5644103383095896,-0.5239964647970852
289.8000000000034,34.62505372552405,0.5624018637821566,-0.5409445076439536
290.9000000000034,34.72965177602923,0.5631249666760807,-0.5582447307778784
292.0000000000034,34.8342231210868,0.5636331488671514,-0.5768361952806806
293.10000000000343,34.94112196971324,0.5630511790786275,-0.5961898217572759
294.20000000000346,35.0452815840329,0.5660469950502132,-0.6144548720316139
295.3000000000035,35.15102531895745,0.5676074277909765,-0.6343862521746413
296.4000000000035,35.25653685658763,0.5690473900545363,-0.652644597300609
297.5000000000035,35.36237268239699,0.5669411211516363,-0.6711475626222381
298.60000000000355,35.46677907510609,0.5688840880605329,-0.6921344825120661
299.70000000000357,35.57275013209527,0.569479285173095,-0.7130194937023107
300.8000000000036,35.67890848002831,0.5731300557820197,-0.7339648371174055
301.9000000000036,35.785032022975116,0.5740825364750618,-0.7539535030637854
303.0000000000036,35.8905838373577,0.5783897625931578,-0.7739626467869094
304.1000000000036,35.99724165487786,0.5809913009123692,-0.7952144389480194
305.2000000000036,36.10217898092967,0.5857755068875303,-0.8172465328151044
306.30000000000365,36.208262474752495,0.5891633692501903,-0.8370078891236363
307.4000000000037,36.31366641386221,0.5944780059906652,-0.8576471175078213
308.5000000000037,36.41938182805558,0.598463467673328,-0.8803020966649582
309.60000000000366,36.5245571887963,0.6024924931962022,-0.9005026212283918
310.7000000000037,36.63057677873468,0.6076364312103432,-0.9208843367484416
311.8000000000037,36.736735854055084,0.6131189139912748,-0.9417876219827539
312.90000000000373,36.841972439339784,0.6195702356138765,-0.9633214501173124
314.00000000000375,36.94738203882102,0.6270088190882497,-0.9843596410388389
315.1000000000038,37.05290446155148,0.6331854368832971,-1.0047528609451457
316.2000000000038,37.158926697184846,0.6395070170479051,-1.0255772780797119
317.3000000000038,37.26434929993389,0.6458595895953811,-1.046785293884398
318.40000000000384,37.37062816357157,0.6511261371616031,-1.0685542120089178
319.5000000000038,37.47635492284029,0.6596821441307374,-1.0904476278109647
320.60000000000383,37.58315617094093,0.6669692387683206,-1.112654431795502
321.70000000000385,37.688061479161604,0.6750457570510714,-1.1363301153701197
322.8000000000039,37.79401379563384,0.6845227334773055,-1.1576951067625467
323.9000000000039,37.90103327787585,0.6922078325150792,-1.1794645370591175
325.0000000000039,38.00642326671649,0.7009137580328839,-1.202859160887761
326.10000000000394,38.114147815797885,0.7118511777128401,-1.2271431415960303
327.2000000000039,38.21890407232801,0.7232334339765067,-1.250898298643302
328.30000000000393,38.3254281064386,0.7313548098126222,-1.2754279918638138
329.40000000000396,38.4316061791921,0.7419612242812452,-1.2986255537682498
330.500000000004,38.53801949656483,0.7530246586119745,-1.3240728772198005
331.600000000004,38.64329995538685,0.7639499304457501,-1.349022989387319
332.700000000004,38.75105942517733,0.7747368814239763,-1.374366793578432
333.80000000000405,38.85672014079631,0.7859772438687226,-1.4013941497036861
334.90000000000407,38.9638105474451,0.7969097697380463,-1.4286418298360952
336.0000000000041,39.070307308240196,0.8088558294402068,-1.455833438594334
337.10000000000406,39.17747685250919,0.8219613703088715,-1.4866314417863067
338.2000000000041,39.28357726001849,0.8335793319776758,-1.5161506993165204
339.3000000000041,39.38974772392088,0.8464268687729006,-1.5452919691180727
340.4000000000041,39.4963012855133,0.860974647911995,-1.5789540030374116
341.50000000000415,39.60310927172978,0.8725932320974539,-1.610464965532591
342.6000000000042,39.708600044534066,0.8853218159029765,-1.6419897626216415
343.7000000000042,39.81551919743809,0.9006598937760277,-1.6758160983875388
344.80000000000416,39.92280121499347,0.9144603733338486,-1.7124047941857885
345.9000000000042,40.02942580940775,0.9276375984336668,-1.748402496736484
347.0000000000042,40.13662803185892,0.940676044466996,-1.7870262082426023
348.10000000000423,40.24314317752972,0.9534511141231361,-1.8234547769629725
349.20000000000425,40.348803655125145,0.9665714676786287,-1.8637742563235875
350.3000000000043,40.45607580498969,0.9799008110599892,-1.905116109850082
351.4000000000043,40.56271224734653,0.991165788549727,-1.9469602324640731
352.5000000000043,40.66990595325315,1.0028902074537271,-1.9892224145969086
353.60000000000434,40.77544749077214,1.0132996257655844,-2.0330387632622555
354.7000000000043,40.88155979104247,1.0221650302992205,-2.076624701535942
355.80000000000433,40.988666819436915,1.0284235287287544,-2.1211863812459306
356.90000000000435,41.09456826973024,1.032879135899575,-2.168560172035435
358.0000000000044,41.2012745961157,1.0366222450381697,-2.21555451987396
359.1000000000044,41.30849264353299,1.0369560128117983,-2.262154949894448
360.2000000000044,41.415462654932284,1.0314245574698244,-2.3096657738968602
361.30000000000445,41.52214715782252,1.0263632908147629,-2.357059742942638
362.4000000000044,41.62826454203645,1.0169854370057376,-2.4032847129383206
363.50000000000443,41.73539574690603,1.0043454070243119,-2.4508047178272996
364.60000000000446,41.84280171783268,0.9856753648422207,-2.496146143906902
365.7000000000045,41.949612801617974,0.9638368937952585,-2.5401685727988315
366.8000000000045,42.05514426405336,0.9391207208915285,-2.584628934487153
367.9000000000045,42.161548383651066,0.9086076432805223,-2.6249457411500847
369.00000000000455,42.26768862203357,0.8767716138596118,-2.663897651543243
370.10000000000457,42.37489547656862,0.8396112100246895,-2.7014750426365453
371.2000000000046,42.48066612947249,0.801541161778157,-2.733615430557871
372.30000000000456,42.5874524807806,0.7589751628839919,-2.7623980940402832
373.4000000000046,42.69212118914912,0.7159259918185734,-2.79131386103042
374.5000000000046,42.7982961048365,0.6733927325951884,-2.8166002594471413
375.6000000000046,42.90347626328234,0.6346582081852714,-2.8380442534502257
376.70000000000465,43.0122163667904,0.5988563084413469,-2.853912581289269
377.8000000000047,43.115789356408754,0.5648399459097136,-2.8698182572827737
378.9000000000047,43.22413928621957,0.5377841712370014,-2.8842629439318044
380.00000000000466,43.33108043123802,0.5164239768401071,-2.8930233528258142
381.1000000000047,43.43738443686527,0.49854808956922697,-2.9037312917073326
382.2000000000047,43.543945924450185,0.48563896439305615,-2.909306676000288
383.30000000000473,43.65106276324199,0.4782945494352693,-2.917044683572438
384.40000000000475,43.75703830032641,0.47157567391723443,-2.922861168030274
385.5000000000048,43.864229506662525,0.46803305660744343,-2.9283943349537624
386.6000000000048,43.970707218791766,0.4622970801478919,-2.9339797621948533
387.7000000000048,44.0786552688982,0.461978640434467,-2.938594286333169
388.80000000000484,44.185225909674344,0.4591381827134615,-2.9434930380965296
389.9000000000048,44.29190191606375,0.4574278108501679,-2.9471725256768013
391.00000000000483,44.39731673867101,0.4562912391286325,-2.951616975692539
392.10000000000485,44.50590418940385,0.4558193900708912,-2.955854770388733
393.2000000000049,44.61076674725186,0.4558407998546507,-2.9605697448537844
394.3000000000049,44.720102342570165,0.4558606191948184,-2.962615185959138
395.4000000000049,44.827079987849686,0.4549767797305545,-2.9666566402592505
396.50000000000495,44.934146731491886,0.45472139039992227,-2.9714649962161728
397.6000000000049,45.0414628719808,0.4539996472584831,-2.975651400338081
398.70000000000493,45.14744238525586,0.45587273393481975,-2.9791543667291025
399.80000000000496,45.25225437620607,0.4562197802995647,-2.982382990834308
400.900000000005,45.36322171681681,0.4548247085666677,-2.986712232794125
402.000000000005,45.470000000000496,0.4565699999999762,-2.9908104484363673
403.100000000005,45.57720169811789,0.4541352929738869,-2.9934801370867508
404.20000000000505,45.685500634186006,0.45680284487908523,-2.9981668025293677
405.30000000000507,45.79237397627818,0.4556944621214348,-3.0009070511097367
406.4000000000051,45.89968369005843,0.4563889013129498,-3.003532670548001
407.50000000000506,46.007155330760234,0.4608775950461138,-3.0088720810370075
408.6000000000051,46.11475730804251,0.4632890851214382,-3.0117973048838445
409.7000000000051,46.22272166098025,0.4613564687925542,-3.0168019258063263
410.8000000000051,46.33035083676204,0.46457292684323265,-3.0176014324991263
411.90000000000515,46.4376372232313,0.46779976803381257,-3.0217002116221847
413.0000000000052,46.54570338828384,0.4705836690213302,-3.025793473978201
414.1000000000052,46.65209014736387,0.4728857781016706,-3.028714542496636
415.20000000000516,46.75939502755198,0.4743537379124159,-3.03287393364625
416.3000000000052,46.86740648721152,0.477021193011361,-3.0354839576487924
417.4000000000052,46.97470667896482,0.47980491586183666,-3.0381536896676784
418.50000000000523,47.07870023310201,0.4823441131852776,-3.040027992500672
419.60000000000525,47.18891052989772,0.48808305775376,-3.0440014625174463
420.7000000000053,47.29617342720995,0.488274215995864,-3.0465801964073274
421.8000000000053,47.40408063501187,0.4901620847566883,-3.0518098366408113
422.9000000000053,47.51143555460237,0.49539122892390364,-3.053321920980071
424.00000000000534,47.61866516119399,0.4977219945904658,-3.055962263526022
425.1000000000053,47.72569936029734,0.5001941965407176,-3.0595679488498333
426.20000000000533,47.834030297574564,0.5040570405554797,-3.0633319253203686
427.30000000000535,47.94193793433955,0.5094679372416985,-3.0659068384822454
428.4000000000054,48.05034096223183,0.5108350890532629,-3.069370232026471
429.5000000000054,48.15886216302227,0.5137365303982453,-3.0713058271300806
430.6000000000054,48.267278213906565,0.5180681831671397,-3.0739510811768143
431.70000000000545,48.37508499165203,0.5231019740653681,-3.0762629857966624
432.8000000000054,48.482546915224255,0.5274249959223429,-3.078779829587469
433.90000000000543,48.5912270007396,0.5299595664064816,-3.082505812933758
435.00000000000546,48.70046249285993,0.5320364843397885,-3.0853902054794835
436.1000000000055,48.80802353201705,0.5356307733601892,-3.0872374618271197
437.2000000000055,48.91600635533096,0.5422064364255572,-3.089989848348595
438.3000000000055,49.025201029849256,0.5459182155508707,-3.0925052382412437
439.40000000000555,49.132891430652414,0.5529122175633135,-3.0967401774620678
440.50000000000557,49.241463534571146,0.5584215607662912,-3.0979738004402844
441.6000000000056,49.34809371523868,0.5594550221046272,-3.0993186777946744
442.70000000000556,49.45643469861322,0.56646066789957,-3.102060006095825
443.8000000000056,49.56499851666173,0.5704094030956645,-3.105625568050179
444.9000000000056,49.67312235685771,0.5757618198379875,-3.1081268283578476
446.0000000000056,49.78140792869724,0.5809314036376366,-3.1103650243794236
447.10000000000565,49.88875711363435,0.5858958971670254,-3.1121837251651296
448.2000000000057,49.99761273022934,0.5902335546580917,-3.115195454575855
449.3000000000057,50.10312658634848,0.5942895114675962,-3.11788326314355
450.40000000000566,50.21227769997176,0.598884089126919,-3.119139786890849
451.5000000000057,50.31990431271081,0.6016279174641962,-3.120790745542873
452.6000000000057,50.42601265783531,0.607338278753784,-3.12231420244587
453.70000000000573,50.535676062306756,0.60974877763249,-3.125057030248584
454.80000000000575,50.64409564714211,0.6138737709142066,-3.1267019045367066
455.9000000000058,50.752512859609205,0.617874967083291,-3.1285500760768947
457.0000000000058,50.86108440393406,0.6223998278420905,-3.130976585210217
458.1000000000058,50.969059036875095,0.6270311321505494,-3.133591145017902
459.20000000000584,51.077339611961335,0.6297924174607483,-3.1362406226685215
460.3000000000058,51.18642561133662,0.6336815494824088,-3.1389109010136886
461.40000000000583,51.29511361236008,0.6387546963069882,-3.1388737838806535
462.50000000000585,51.40387316788916,0.6405055011985635,-3.139536883880229
463.6000000000059,51.51297157352694,0.6474178251445653,-3.1422283318228756
464.7000000000059,51.621907623657,0.6523388157185448,-3.1448526673965156
465.8000000000059,51.73117608833102,0.6531414603654598,-3.1454580642685253
466.90000000000595,51.83980511383011,0.6576361914475058,-3.1468234131678927
468.0000000000059,51.94825211538826,0.6629562765591643,-3.1490890134498053
469.10000000000593,52.057245423248155,0.666806816376162,-3.1517143473664975
470.20000000000596,52.16624570515803,0.6710745592278327,-3.1523652802500473
471.300000000006,52.275230441174855,0.674464798163469,-3.1545531985074553
472.400000000006,52.38344629701562,0.6790438182079621,-3.156318993275473
473.500000000006,52.49267376260885,0.6817282930170835,-3.1570875947946
474.60000000000605,52.59940937759987,0.6840858937430032,-3.1596099900426946
475.70000000000607,52.71009587914996,0.6909885782436467,-3.160930146808333
476.8000000000061,52.81858513929274,0.6932236514892208,-3.1622699583865503
477.90000000000606,52.92773045035911,0.696223300178582,-3.162590800982872
479.0000000000061,53.03575473770059,0.700263825775251,-3.1650774539973225
480.1000000000061,53.14513870007018,0.7041464095530807,-3.1665793938580613
481.2000000000061,53.2539029950195,0.7067025856620817,-3.1665336872580956
482.30000000000615,53.3629043565925,0.7108957122120768,-3.1691495933098928
483.4000000000062,53.471032935105676,0.713186339536512,-3.1714599895551836
484.5000000000062,53.58045586620791,0.7175584647065891,-3.1717902013660613
485.60000000000616,53.68920287467193,0.7236271993438594,-3.1727662510283654
486.7000000000062,53.7974170880479,0.726451306129267,-3.174253956289979
487.8000000000062,53.907373585136206,0.7286405964132073,-3.1766182093531476
488.90000000000623,54.01574870534258,0.7327679996859171,-3.176718511380638
490.00000000000625,54.12423680314668,0.7374654334700583,-3.1780404244876768
491.1000000000063,54.23286901867367,0.7481906097219245,-3.1789444720703313
492.2000000000063,54.340949531597914,0.7603659937890157,-3.1806702171522403
493.3000000000063,54.45031412829777,0.7676493274305359,-3.1826568642345965
494.40000000000634,54.55961089097468,0.7762993831910713,-3.1839635256153995
495.5000000000063,54.668000872584166,0.7828286853625841,-3.1828466097602455
496.60000000000633,54.775968803920684,0.7887806958278417,-3.1852805273292923
497.70000000000636,54.88433626277755,0.7941697650077706,-3.1865973756296313
498.8000000000064,54.99330774712243,0.8002228907680556,-3.1879082713976903
499.9000000000064,55.10135322645251,0.8077482027877818,-3.18922641032584
501.0000000000064,55.20971243825933,0.8126910887441897,-3.1905388771601917
502.10000000000645,55.318009258320814,0.8149379727895557,-3.190542280025514
503.2000000000064,55.428027665854714,0.8194736744173836,-3.1918687525419864
504.30000000000643,55.53679349368042,0.8229297142106579,-3.193292831068052
505.40000000000646,55.645241481149284,0.8302507321480426,-3.194489870583502
506.5000000000065,55.75465309306385,0.8334633462250816,-3.1954966450801803
507.6000000000065,55.863391204061585,0.83766193806921,-3.1961154441934663
508.7000000000065,55.97246560728596,0.8430397690555195,-3.1971315169137204
509.80000000000655,56.08116663514954,0.8494550344080039,-3.198852230154508
510.90000000000657,56.190289478295185,0.8556570835201363,-3.199091158256709
512.0000000000066,56.29854811822503,0.8604088487757287,-3.199759669411331
513.1000000000065,56.40646445668238,0.8647912460001358,-3.201082227694063
514.2000000000066,56.51587941453359,0.8674819341824848,-3.203772027789272
515.3000000000065,56.62436053012515,0.8692456461491842,-3.203709323584533
516.4000000000067,56.733856723148776,0.8739484887260296,-3.2037182415392804
517.5000000000066,56.84261303768911,0.8753709937005172,-3.205029740184596
518.6000000000067,56.951269157793085,0.876615524708196,-3.206339293893855
519.7000000000066,57.06076281719241,0.8791998124031299,-3.2086326134634344
520.8000000000067,57.17020600378662,0.8780898989490415,-3.2086372682094844
521.9000000000067,57.279049482137566,0.875890751720124,-3.2095763537627304
523.0000000000067,57.38928615539813,0.8672344965695064,-3.2099598352719623
524.1000000000067,57.497936500321096,0.8632331599202924,-3.211198219109516
525.2000000000068,57.608232049985865,0.8564593048677552,-3.2125802917719866
526.3000000000068,57.7171929762138,0.8559680225944628,-3.2138939658664825
527.4000000000068,57.827195656138684,0.8549199812566998,-3.213909985046073
528.5000000000068,57.93608204837195,0.8548443983312332,-3.2138061342393063
529.6000000000068,58.046675629222015,0.8549270483435532,-3.2152301522288593
530.7000000000069,58.15609263361219,0.8591082292156432,-3.2158802518325387
531.8000000000068,58.26526270917947,0.8596397325943813,-3.2171966525494264
532.9000000000069,58.375927670575024,0.8589064790211197,-3.218509840076669
534.0000000000068,58.48365717527503,0.8614815380467253,-3.2191634404776597
535.100000000007,58.59523110414132,0.8621904622896794,-3.219829812963618
536.2000000000069,58.70301181078259,0.8676535934318564,-3.2211502916823855
537.300000000007,58.813600310201295,0.8669031028995756,-3.2220993457937617
538.4000000000069,58.92394861384751,0.86913970746188,-3.2218856908893567
539.5000000000069,59.033011419768926,0.867394303906714,-3.2231184930537635
540.600000000007,59.14280132149328,0.8714630618914007,-3.2257503523950852
541.700000000007,59.252223693012766,0.8718230094185027,-3.225749999006206
542.800000000007,59.36233185877354,0.8697466862491325,-3.225762381811516
543.900000000007,59.47134987656508,0.8697885307512098,-3.2270701649942177
545.000000000007,59.58020777385677,0.868444238354291,-3.228420748528663
546.1000000000071,59.69067282140363,0.8684339135870768,-3.2270970783217767
547.2000000000071,59.79970117547362,0.8685554292861358,-3.2289275012268095
548.300000000007,59.90932644992967,0.8689099919438708,-3.230689917313509
549.4000000000071,60.019316353515364,0.871904619218073,-3.230643734857214
550.500000000007,60.12833009365405,0.8716102377899673,-3.2306900159751675
551.6000000000072,60.23838591254916,0.8725690506651558,-3.2320398077658368
552.7000000000071,60.34775492808145,0.8759135361864658,-3.2320111576636315
553.8000000000072,60.45756055537457,0.8739395403467594,-3.2333201434873433
554.9000000000071,60.56777261221964,0.8769745715896056,-3.233963503512798
556.0000000000072,60.67744919232052,0.8773963213765883,-3.2346356466699424
557.1000000000072,60.78725772588451,0.879548180553332,-3.2359601991336864
558.2000000000072,60.89770338728224,0.8809891479374362,-3.2359529954985846
559.3000000000072,61.0077589806219,0.8825733501562465,-3.2370920658291693
560.4000000000073,61.116883816857246,0.8838425278516573,-3.237270907913642
561.5000000000073,61.22732233145062,0.8844153934894742,-3.2395798839384318
562.6000000000073,61.33585665557836,0.8894788604918108,-3.2395799448407887
563.7000000000073,61.44580872813985,0.8925476974143176,-3.2408605151451892
564.8000000000073,61.55664067071342,0.8944583804776651,-3.2396966697362415
565.9000000000074,61.66667878815508,0.8981090289533938,-3.2408918945538767
567.0000000000074,61.77603421306024,0.9009951751910424,-3.242193079288157
568.1000000000074,61.886051365199904,0.9027601822649638,-3.242860160994275
569.2000000000073,61.99683664489221,0.9070519135544497,-3.2427670129025037
570.3000000000073,62.10710744562099,0.9090469620620654,-3.2442242737953864
571.4000000000074,62.21705864676434,0.9115294929659726,-3.244179821966415
572.5000000000074,62.32754677975824,0.9144806008987004,-3.244349620184671
573.6000000000074,62.437423962231584,0.9189032124822387,-3.247655107471508
574.7000000000074,62.547925891686276,0.9211123323120104,-3.2464799606347663
575.8000000000075,62.657818121100554,0.9252848187381879,-3.247137399014356
576.9000000000075,62.768133442271406,0.9276466203556356,-3.2487914471092956
578.0000000000075,62.878305532278176,0.930091538870887,-3.2501354637110658
579.1000000000075,62.98833922182833,0.9362374488909195,-3.2487807890172467
580.2000000000075,63.09784911974292,0.9400361094722451,-3.2501005075063327
581.3000000000076,63.20848248667341,0.9431158856366757,-3.251420254183014
582.4000000000076,63.317924271984865,0.9482529953711125,-3.251418969199367
583.5000000000076,63.4296719837577,0.9512976547333032,-3.2540490941082476
584.6000000000076,63.53946150116899,0.9561933891416666,-3.2533893635714124
585.7000000000077,63.6487747848945,0.9620579545196387,-3.254049848409972
586.8000000000077,63.75888348585355,0.962704600268986,-3.2540500346053056
587.9000000000076,63.869997911769964,0.9671001308434876,-3.2566906712142782
589.0000000000076,63.98028118995329,0.9713070520239833,-3.2566799683061673
590.1000000000076,64.09042371334397,0.9758395258621485,-3.2566799750041446
591.2000000000077,64.20169830966516,0.9794536006062158,-3.2571666841919518
592.3000000000077,64.31059384956666,0.9838453253687756,-3.2580000005449192
593.4000000000077,64.42302810886538,0.9892939321044609,-3.2566971665156217
594.5000000000077,64.53197440558196,0.9947559009962949,-3.2569996907013077
595.6000000000078,64.64290506410609,0.9997692900165475,-3.2596488604653815
596.7000000000078,64.75422824122316,1.0038476105718144,-3.260960133450867
597.8000000000078,64.86389300414055,1.0102839410511515,-3.262261417893269
598.9000000000078,64.97410737592483,1.013059928135992,-3.2596390349172104
600.0000000000078,65.08401948885614,1.0192472623292088,-3.260960184502277
601.1000000000079,65.19460207807165,1.0226284977625832,-3.2619481611988386
602.2000000000079,65.30560791641342,1.026475141091423,-3.262279874381398
603.3000000000079,65.41524337803241,1.0324180021114087,-3.2623027288774473
604.4000000000078,65.5260521505853,1.0398443287199417,-3.2635899769797283
605.5000000000078,65.63618663687268,1.0444815518665378,-3.2634754280715823
606.6000000000079,65.74629426709848,1.0487960032898047,-3.264910003169735
607.7000000000079,65.85631876729964,1.053967438605004,-3.264858682024207
608.8000000000079,65.96647925486891,1.0590698521686996,-3.2649100160490696
609.9000000000079,66.07701043357916,1.0660324297429344,-3.264926968168925
611.000000000008,66.18703654616365,1.072718072974972,-3.265901044817572
612.100000000008,66.29659979709461,1.077863004741267,-3.2662195196756194
613.200000000008,66.40722287184867,1.0813463309231441,-3.2675346849950495
614.300000000008,66.51593166792121,1.0893775508257657,-3.2682003277073943
615.400000000008,66.62847488017326,1.0919156152151628,-3.2683331658743455
616.5000000000081,66.73854951903752,1.0975640499633161,-3.2692027589444694
617.6000000000081,66.84989198159182,1.1046313347626935,-3.2695641435660523
618.7000000000081,66.96080352667859,1.1104606633813094,-3.269189972168047
619.8000000000081,67.07204210228578,1.1167419841129347,-3.2695180040276295
620.9000000000082,67.18195901250861,1.1214122633569183,-3.2708326644255328
622.0000000000082,67.29342987694304,1.1237846996353167,-3.2734727594241715
623.1000000000081,67.40446942196115,1.1288912563290987,-3.27247978840684
624.2000000000081,67.51499878434579,1.1369648967020107,-3.2719521545080705
625.3000000000081,67.62596275238509,1.1443556410644362,-3.272150032862096
626.4000000000082,67.73676634652696,1.1510127605732565,-3.274793348580368
627.5000000000082,67.84800181600309,1.1554546398535073,-3.274788512646434
628.6000000000082,67.9588794833834,1.1631485062715015,-3.273773116580758
629.7000000000082,68.0687604360531,1.169365847726109,-3.2747801553358244
630.8000000000083,68.17968801620731,1.17439165344467,-3.2747801205338147
631.9000000000083,68.28950252140004,1.1799097070852453,-3.2774248531190464
633.0000000000083,68.40138044227217,1.1871114022824887,-3.277420172861915
634.1000000000083,68.51149218245872,1.1955512274366482,-3.2781767989522423
635.2000000000083,68.61867241024869,1.200540891171079,-3.277409883996783
636.3000000000084,68.73188649413903,1.2071548429839125,-3.277879368393708
637.4000000000084,68.84180522508389,1.2145752862573578,-3.2783076770387334
638.5000000000084,68.95185638336737,1.2202845704013556,-3.2800495180158054
639.6000000000083,69.06205579968731,1.229252854244192,-3.2800480958788336
640.7000000000083,69.1726544974046,1.236206121119335,-3.278730077448948
641.8000000000084,69.28330427466102,1.2424104285272628,-3.281360045103421
642.9000000000084,69.3935280744211,1.2511008182014518,-3.2813614921079575
644.0000000000084,69.50418648363366,1.259273906814576,-3.282680311243268
645.1000000000084,69.61615989187204,1.2673047155033426,-3.281282668639916
646.2000000000085,69.72588054861419,1.2752258074023075,-3.28136005653984
647.3000000000085,69.83603586789198,1.2800504126413432,-3.2826846428794925
648.4000000000085,69.94702703358277,1.2872710650137302,-3.2826803246004697
649.5000000000085,70.05725394228722,1.2940294311338054,-3.2826035158732543
650.6000000000085,70.16934170236345,1.299551414721582,-3.282681206689917
651.7000000000086,70.2788495777681,1.3067656030967985,-3.283736663966068
652.8000000000086,70.39140653996596,1.3103224279218708,-3.2849799040586563
653.9000000000086,70.5023930394567,1.318715592561578,-3.285344259086706
655.0000000000086,70.61210902522339,1.3255493476776519,-3.283996307833104
656.1000000000087,70.72303571887117,1.3304351074649514,-3.285483182919094
657.2000000000087,70.83463762538257,1.3339518922410336,-3.2856399125530675
658.3000000000086,70.94429664152503,1.3403796545044746,-3.2868553701269008
659.4000000000086,71.05626946316045,1.3433263156850737,-3.2869599370228357
660.5000000000086,71.16651603700986,1.349122218429738,-3.2869600966649744
661.6000000000087,71.27810828627895,1.353432560897221,-3.2882762499851044
662.7000000000087,71.38937502718122,1.3592536970286369,-3.288242012791546
663.8000000000087,71.49990038064007,1.3630204688659737,-3.2876198339931793
664.9000000000087,71.61031347603554,1.3705022784775136,-3.2876199623237183
666.0000000000088,71.72146995814393,1.3740709273953506,-3.2870079837730546
667.1000000000088,71.83230417032132,1.381108005184531,-3.2872800617481936
668.2000000000088,71.94306033924245,1.3857436756320143,-3.2872800624224854
669.3000000000088,72.0541053687057,1.3893758255982365,-3.288505710086642
670.4000000000088,72.16519655664773,1.3935463008025335,-3.2885690034703012
671.5000000000089,72.27689765464373,1.3992822496812816,-3.2910507232208053
672.6000000000089,72.3885914015578,1.4017916618422972,-3.290169083173373
673.7000000000089,72.4984809465604,1.4087877429129678,-3.2912479083633164
674.8000000000088,72.60960227091523,1.4119444325231947,-3.2912299423349998
675.9000000000088,72.72071205387498,1.4197469071054796,-3.291204584727865
677.0000000000089,72.83169626803613,1.425802213446046,-3.2928797978639563
678.1000000000089,72.94232201139023,1.4310753728472636,-3.292219746041588
679.2000000000089,73.05201759497149,1.4348053959047706,-3.2912744098388194
680.3000000000089,73.16497330194706,1.441404285213026,-3.2909100832346017
681.400000000009,73.27600639668609,1.4450590886812256,-3.2922293491280383
682.500000000009,73.38682933280803,1.4491198269344596,-3.292889624979537
683.600000000009,73.49795265442431,1.4530045781314374,-3.2915599150959354
684.700000000009,73.60901648601191,1.4561417958348672,-3.293217991077735
685.800000000009,73.72029348455851,1.4648527304970866,-3.2935405838166822
686.9000000000091,73.83155253677354,1.470146761200416,-3.2935382181356263
688.0000000000091,73.94094991528027,1.473983604191991,-3.293624789259308
689.1000000000091,74.05371088157918,1.4784378333254222,-3.293540176302068
690.2000000000091,74.16530518318677,1.4840722644886597,-3.2946239081500797
691.3000000000092,74.27582834631997,1.490677528738181,-3.2948691746613274
692.4000000000092,74.38623310310929,1.4964830869153554,-3.2954766819211203
693.5000000000091,74.4963085408328,1.5047121771244782,-3.296194578276505
694.6000000000091,74.60852829004445,1.510540596754302,-3.2961699039950476
695.7000000000091,74.7181583277778,1.5170166025131424,-3.2961699027312856
696.8000000000092,74.82958078676245,1.52336025990835,-3.2974897811664516
697.9000000000092,74.93979338782434,1.5309464227445326,-3.2972249490734438
699.0000000000092,75.0501902874732,1.5310528995293948,-3.297150141882792
700.1000000000092,75.1610583852594,1.5355751150760095,-3.29748886428956
701.2000000000093,75.27194552169378,1.5440153036839743,-3.2984439226274365
702.3000000000093,75.38442893009312,1.548459713080633,-3.2984701470164657
703.4000000000093,75.49631224489751,1.5530493024810703,-3.2984701473542244
704.5000000000093,75.60656754188275,1.5596984254270545,-3.299634848376005
705.6000000000093,75.71779823947762,1.565796064902163,-3.299790170181649
706.7000000000094,75.8296824279202,1.5726495991554483,-3.3011006174600848
707.8000000000094,75.94139821688752,1.5771434718224442,-3.2997898717655882
708.9000000000094,76.0526346278857,1.5824688999833525,-3.2997898475491976
710.0000000000093,76.16423146968607,1.5869194752567795,-3.3011103741537977
711.1000000000093,76.27625833079884,1.593051224458033,-3.300445383949331
712.2000000000094,76.38756609129813,1.598001555562777,-3.299789942947709
713.3000000000094,76.49915822447792,1.6017582131857822,-3.299789713738723
714.4000000000094,76.6107507886691,1.6075283679751566,-3.302251693936892
715.5000000000094,76.72124713325553,1.61527202342593,-3.3024299168828968
716.6000000000095,76.83271645221944,1.6184828391184767,-3.30374323870622
717.7000000000095,76.94381508591358,1.6235014353337247,-3.302420024990653
718.8000000000095,77.05486321490848,1.6301134883846577,-3.302420041349363
719.9000000000095,77.16594602804146,1.6344366391725877,-3.3033880451981688
721.0000000000095,77.2771553569375,1.64319437802764,-3.3023788462618575
722.1000000000096,77.38904205852458,1.6469580810792546,-3.3037379544560803
723.2000000000096,77.49887601299861,1.6513143538906618,-3.3027499372829245
724.3000000000096,77.61168521289659,1.658115146047824,-3.3053307974513717
725.4000000000096,77.72239529204938,1.6668349211187583,-3.305380130296288
726.5000000000097,77.83446545081301,1.673912706987389,-3.3053786575923496
727.6000000000097,77.94612468027434,1.6788677592298245,-3.3040827716645063
728.7000000000096,78.0580383137138,1.6840392883982351,-3.3040701731493014
729.8000000000096,78.16890737789754,1.6895222874723335,-3.305391287003939
730.9000000000096,78.28202437992064,1.696682280005724,-3.3053896963641556
732.0000000000097,78.39371639208895,1.7002941143126953,-3.308010198760136
733.1000000000097,78.50607841169388,1.707968640812928,-3.3060398076231765
734.2000000000097,78.61826965541574,1.7155431377195627,-3.3060504754353257
735.3000000000097,78.73080886789464,1.7202940069357162,-3.307360114761053
736.4000000000098,78.84314107323975,1.7264729406409285,-3.3073602186819007
737.5000000000098,78.9545134875633,1.7304097296679657,-3.3090340144431423
738.6000000000098,79.06611162186024,1.7386999656002553,-3.30901013900091
739.7000000000098,79.1799000675572,1.7427837115525022,-3.3088903166510404
740.8000000000098,79.29144659943974,1.7474873847879016,-3.3076602259347982
741.9000000000099,79.4034181221488,1.7534571950288107,-3.30801082136109
743.0000000000099,79.51572068580064,1.7593752738709707,-3.308009841999149
744.1000000000099,79.62660794803917,1.763314616681776,-3.3080107639535683
745.2000000000098,79.73934262407684,1.7734518355007114,-3.31069838304032
746.3000000000098,79.85229166358786,1.7769964810314252,-3.310623303343607
747.0000000000099,79.92236445402722,1.7824827411795716,-3.310656636375736