File: 01_Data/Basswood_Panel/STA/N2/10K_min/Basswood_Panel_STA_N2_10KData_220314_R1.csv
##Temp./Â°C,Time/min,DSC/(mW/mg),Mass loss/mg
50.0,10.538038110078384,-1.1186311559391067,0.016795034950807697
51.100000000000016,10.952880685529832,-0.9803891517346511,0.011621480428906317
52.20000000000003,11.185760858816648,-0.8953354072509857,0.013041101422703427
53.30000000000005,11.372169040880259,-0.8344485396414838,0.01151262031907141
54.40000000000006,11.531865002843846,-0.7873784882993374,0.011469341828785673
55.50000000000008,11.68174117519672,-0.7461939660498906,0.012166486367759077
56.600000000000094,11.82257131992079,-0.7145493659311619,0.012040976985068674
57.70000000000011,11.957155037517195,-0.6876214071166276,0.01046047646494408
58.800000000000125,12.087329700840035,-0.6658972265313978,0.011954310956411085
59.90000000000014,12.213897597695224,-0.6457096217932593,0.011362453453049426
61.000000000000156,12.339448529071419,-0.626712724008317,0.010757193436908175
62.10000000000017,12.463294646726759,-0.6125686276948556,0.011877132066467233
63.20000000000019,12.587041722998359,-0.5984114972549395,0.01091664945143922
64.30000000000021,12.706258570805895,-0.584962871353383,0.011108166732155311
65.40000000000022,12.826970774645428,-0.5727824390815314,0.011875172378144505
66.50000000000023,12.946585412109645,-0.5600333645776745,0.01063495921457669
67.60000000000025,13.06548066075039,-0.5497461265844202,0.010520087548332668
68.70000000000027,13.179654959533574,-0.5379318176512329,0.0105279352484704
69.80000000000028,13.302341035132363,-0.5262106519782485,0.01060700027233974
70.90000000000029,13.419161615930733,-0.5168695201575534,0.010522302156533492
72.00000000000031,13.536520794476289,-0.5058385746071743,0.010518765624244253
73.10000000000034,13.651124955261382,-0.49548321330901207,0.010520064136661844
74.20000000000034,13.767286706709395,-0.4848335073443155,0.010543561617762265
75.30000000000035,13.883249159935687,-0.4750593514291005,0.010561147430642848
76.40000000000038,13.997888988609589,-0.46511344489821865,0.009928890244836452
77.5000000000004,14.111371288636754,-0.45540142707093617,0.00920354435170001
78.6000000000004,14.22589317516614,-0.4455034926707191,0.010530629081451082
79.70000000000041,14.339578387536427,-0.43799634431699025,0.009210074424613524
80.80000000000044,14.452509401963612,-0.4304188289192736,0.009211348927988361
81.90000000000046,14.567895469483474,-0.4215925814257715,0.009034896334684461
83.00000000000047,14.679481615350255,-0.41539607511755117,0.009172876931536678
84.10000000000048,14.792600859379002,-0.40656532685537067,0.009202678559165456
85.2000000000005,14.903641827154033,-0.39909988099586063,0.007889178139436126
86.30000000000052,15.0166752473148,-0.3916380426317973,0.006708616826903935
87.40000000000053,15.123826528744985,-0.3857139473933116,0.007886876055158254
88.50000000000054,15.238896067195858,-0.38027613906504915,0.0065699509791175
89.60000000000056,15.349063619723951,-0.3736604405286732,0.007890745709592473
90.70000000000059,15.459370570469513,-0.36974608955791216,0.006580030158868766
91.8000000000006,15.56795944927796,-0.36268100250954016,0.005266654204591603
92.9000000000006,15.677942631365164,-0.35785683262565954,0.006554430835536529
94.00000000000063,15.787609235859055,-0.3537899731688105,0.005260114567457563
95.10000000000065,15.897912451146015,-0.34759157485777475,0.006575193439970484
96.20000000000066,16.00497307486861,-0.34433087301189197,0.007887888184508363
97.30000000000067,16.114605963132227,-0.3381204181347394,0.0053123790336302434
98.40000000000069,16.22358683792206,-0.33269933006533253,0.006570239885778761
99.50000000000071,16.332310068806947,-0.32796307549888193,0.005581675164417987
100.60000000000072,16.440705547049614,-0.3233579589211034,0.005978374595771996
101.70000000000073,16.548355206809592,-0.3183149747368705,0.006222924645285843
102.80000000000075,16.65649659483633,-0.3127589657509318,0.006560087159826367
103.90000000000077,16.76482100210561,-0.3101734248425596,0.005255607626349246
105.00000000000078,16.873226361493845,-0.3032654291102552,0.005588449757217617
106.10000000000079,16.981827843324762,-0.29744920460119,0.005589669596392177
107.20000000000081,17.08715026271831,-0.29221357036862533,0.006574455133550039
108.30000000000084,17.19502948543664,-0.28608841260495893,0.005259920750860125
109.40000000000084,17.30334071092583,-0.28219097927061637,0.005259997239492442
110.50000000000085,17.410589289487426,-0.2757589480488808,0.006570920291199656
111.60000000000088,17.51822523300656,-0.2711842517712898,0.005265699279209279
112.7000000000009,17.625973197196465,-0.26332733228016836,0.004587749889850556
113.8000000000009,17.7340540479413,-0.25860756535683277,0.005262730938666138
114.90000000000092,17.841040745454993,-0.2516574380967514,0.005260090389767491
116.00000000000094,17.948427983724077,-0.24541120691293453,0.00652293521998093
117.10000000000096,18.055305978703164,-0.23996973979610187,0.005259827614671586
118.20000000000097,18.159535600222746,-0.23437960614436382,0.005227785045085476
119.30000000000098,18.270641978189246,-0.22804288838241007,0.005259916006262522
120.400000000001,18.377815643283732,-0.22385837619503923,0.005259920593612577
121.50000000000102,18.483579257904346,-0.21695871954346962,0.004316481274257988
122.60000000000103,18.59130431598154,-0.20991317144444707,0.0036367798735899015
123.70000000000104,18.69760703962999,-0.20402949735083475,0.0036100915777188547
124.80000000000106,18.80613421527258,-0.1975423537904074,0.004867344351780822
125.90000000000109,18.91261843909115,-0.19018119887850946,0.006254377080106011
127.0000000000011,19.018839293713935,-0.18600095603554465,0.003940016477635311
128.1000000000011,19.126186129134563,-0.17960277867043423,0.006251444162198361
129.20000000000113,19.232513596691202,-0.17260963046378613,0.0062379709909734515
130.30000000000115,19.338452327730362,-0.16696650376618946,0.006242844642145862
131.40000000000117,19.444801285764886,-0.1609572309516489,0.004929839910388978
132.50000000000117,19.552285876385078,-0.15372280801767088,0.005661221061720845
133.6000000000012,19.658422986513273,-0.14911012036351415,0.004272265985773238
134.7000000000012,19.76545611667005,-0.1445309674204899,0.0049303608532689225
135.8000000000012,19.87264858777491,-0.13928320680713993,0.004936490745224731
136.90000000000123,19.978529130320776,-0.1326638391786187,0.003819634880804834
138.00000000000125,20.085609122559557,-0.12819609363849627,0.004919996343092592
139.10000000000127,20.190461359930428,-0.12176140672401861,0.004920600756758375
140.2000000000013,20.298335967727127,-0.11515126306135115,0.0035802476463882016
141.3000000000013,20.405396889209577,-0.10945230436584029,0.003940019795003025
142.4000000000013,20.510626381813946,-0.10371509196989845,0.00393413238654805
143.50000000000134,20.617636545630806,-0.09952176269474299,0.0032666994055672305
144.60000000000133,20.723095926520728,-0.09248624209246978,0.00361121517229801
145.70000000000135,20.829411089682242,-0.08760692086495328,0.004930186035377204
146.80000000000138,20.93532758172802,-0.08214729454562887,0.004940380765424912
147.9000000000014,21.041085980232978,-0.07578346224340862,0.003620166272484404
149.00000000000142,21.14826871104008,-0.07037446836033287,0.003638271716879693
150.10000000000142,21.25423113489724,-0.06348556419032457,0.004929774073797688
151.20000000000144,21.358999311838268,-0.05612259033665734,0.0036510434764904787
152.30000000000146,21.4667923133761,-0.05025020338100032,0.0029599431941225163
153.40000000000146,21.571448130183974,-0.04651512016785694,0.0033976488710756314
154.50000000000148,21.67806569628895,-0.039723823358614976,0.0022898394845105585
155.6000000000015,21.782379050286966,-0.03487956239895736,0.0028591147585217414
156.70000000000152,21.888507324907934,-0.027540605125742867,0.001971117683171819
157.80000000000155,21.994479108958295,-0.021462102738952164,0.001969931096272859
158.90000000000154,22.10092513032877,-0.015112395710466495,0.0006473203934778127
160.00000000000156,22.205784574674624,-0.00909183187169116,0.0010373772975160733
161.1000000000016,22.310909449505335,-0.004539775897693769,0.0026168450683750066
162.20000000000158,22.41736089158074,0.0021386925460592835,0.0012741737147843324
163.3000000000016,22.522446856511316,0.007110721754771379,0.001305012620489876
164.40000000000163,22.627832220915916,0.012493884909913811,0.0003199912367657376
165.50000000000165,22.732996846536352,0.018483344710348817,0.0003245844035113521
166.60000000000167,22.838236020166445,0.02383444410335174,0.0006500069914041617
167.70000000000167,22.9433685797811,0.02971220019898333,0.0006295897690664631
168.8000000000017,23.05000000000017,0.033769310000027794,-0.0009708458626702665
169.9000000000017,23.155548864875108,0.04047598083800542,0.0003223797251212801
171.0000000000017,23.259258997565784,0.046460290454229,0.000320075000670883
172.10000000000173,23.366482382364325,0.04888099766063403,0.0003200750038825362
173.20000000000175,23.47171144128064,0.05401551622702967,0.0003238067681747836
174.30000000000177,23.577657584811675,0.05953480239334859,-0.000669930951601394
175.4000000000018,23.68267921334506,0.06424488435348688,-0.0006440461607857273
176.5000000000018,23.789793020872196,0.06835103072422198,-0.0009598280180567187
177.6000000000018,23.89474747702293,0.07470010258972731,-0.002309926319660427
178.70000000000184,24.001101184801414,0.07950616869745183,-0.0023099250001363814
179.80000000000183,24.104518080644073,0.08389259142718974,-0.0023099461640923025
180.90000000000185,24.21183479598284,0.08966011921856451,-0.0036293863042020647
182.00000000000188,24.317221047669843,0.09533054632475366,-0.004940113404211743
183.1000000000019,24.422159617675792,0.10193784891772516,-0.00494006307935102
184.20000000000192,24.52825668783856,0.10451617224122052,-0.00529372663806793
185.30000000000192,24.632444894528387,0.1109276198377113,-0.00592996868270923
186.40000000000194,24.736648935574337,0.1174415894403079,-0.005929968789392781
187.50000000000196,24.843056181211576,0.12167443586643137,-0.005946911498742935
188.60000000000196,24.948528344637616,0.12906117168559195,-0.007247061924573472
189.70000000000198,25.053622261149748,0.13318913762706755,-0.008548408577844668
190.800000000002,25.15951126406845,0.1389086364113536,-0.008586887846971258
191.90000000000202,25.26473382657514,0.14412747984175212,-0.009880595517180346
193.00000000000205,25.368518095032975,0.1512849201526511,-0.009850693656237475
194.10000000000204,25.474526227616128,0.15508539357188297,-0.009799705900570999
195.20000000000206,25.579394175006996,0.16161910941112811,-0.011518373641910884
196.3000000000021,25.684750235392396,0.16815043989634787,-0.011521540093178295
197.40000000000208,25.789371678174795,0.1701427122001326,-0.012839757233834348
198.5000000000021,25.895025490615982,0.17806889445636434,-0.013628348135740431
199.60000000000213,26.00066879099214,0.1837237329334849,-0.014160053987280818
200.70000000000215,26.105636106554037,0.19025928991185578,-0.01592792459942327
201.80000000000217,26.210775420261534,0.19706056226719637,-0.016141689358313727
202.90000000000217,26.3166189824871,0.20382640956432288,-0.017430076852314347
204.0000000000022,26.419788573261904,0.20849636006290434,-0.01942017336998214
205.1000000000022,26.525906093537337,0.21508273568058003,-0.01936086737473941
206.2000000000022,26.630748737750576,0.22229080014121416,-0.02178052018901111
207.30000000000223,26.734778627351385,0.2273190558305754,-0.02228916474742526
208.40000000000225,26.840175797642548,0.23347797899065303,-0.0233813562557752
209.50000000000227,26.945046799958902,0.2385362965991196,-0.024681938588959618
210.6000000000023,27.049602985722878,0.2442291213998899,-0.025669229629885493
211.7000000000023,27.15502730229788,0.24880957244020788,-0.026965254390365345
212.8000000000023,27.25907285291045,0.25473643261060935,-0.02963221200651356
213.90000000000234,27.36464422857108,0.2606127181903053,-0.030653152275478934
215.00000000000233,27.4699011167519,0.2669060076169655,-0.03357011787874331
216.10000000000235,27.573783650111356,0.2691450281398,-0.03356722524908795
217.20000000000238,27.68009307904262,0.27219924399297496,-0.035557360963851536
218.3000000000024,27.7831724861263,0.27463643714621633,-0.03780445430995805
219.40000000000242,27.89021922195097,0.27889871447363934,-0.04015086749441732
220.50000000000242,27.99233645953708,0.28294654801555164,-0.041563834237568376
221.60000000000244,28.098949487038876,0.2842184154061174,-0.0427806248493372
222.70000000000246,28.203127515071372,0.2881962473667715,-0.0441028260696239
223.80000000000246,28.30863660563018,0.29309499493870717,-0.04805195572779564
224.90000000000248,28.41453905815321,0.2974861828967115,-0.05065301444973436
226.0000000000025,28.51942735534108,0.3002644953696671,-0.052000170023236425
227.10000000000252,28.623749082931777,0.30249883943888134,-0.054590535072264856
228.20000000000255,28.729121941567385,0.3068938556007654,-0.05785790705076188
229.30000000000254,28.83412122436961,0.309417398148855,-0.06011950677456479
230.40000000000256,28.940390914193557,0.3115399407103668,-0.06289311850134283
231.5000000000026,29.04367556332974,0.31497794742326274,-0.06509800070709248
232.60000000000258,29.14936442254895,0.31926333467400386,-0.06764476169250866
233.7000000000026,29.254487257461633,0.3219747320961022,-0.07020659202581303
234.80000000000263,29.359724070796084,0.3266513451517936,-0.07327170364402358
235.90000000000265,29.464164933224293,0.3278226964944761,-0.07592025891799148
237.00000000000267,29.568741933204535,0.3314292840633623,-0.0799683999858809
238.10000000000267,29.67411127747729,0.3343104588607586,-0.08118937909172175
239.2000000000027,29.779137073859378,0.33501173752392427,-0.08535307032842132
240.3000000000027,29.88412802136855,0.33935608469766676,-0.08797105246739712
241.4000000000027,29.989080070572456,0.34220754833315276,-0.09211006658847953
242.50000000000273,30.094533258381908,0.3459592539146867,-0.09628590057236153
243.60000000000275,30.19940246258848,0.34825201042343085,-0.0990196160987038
244.70000000000277,30.303465864725432,0.34933185715832876,-0.10200615471992025
245.8000000000028,30.408684253031257,0.3539259606285524,-0.10455945944951495
246.9000000000028,30.513760475055786,0.35572370214234833,-0.11027980738216403
248.0000000000028,30.619150881491606,0.3597801002753316,-0.11429413775067854
249.10000000000284,30.724427131405445,0.36365188061429193,-0.11695982779716152
250.20000000000283,30.82625150629923,0.36708579224547,-0.12218219588088353
251.30000000000285,30.934084141298687,0.3701093370023126,-0.12677182596352132
252.40000000000288,31.038096348649237,0.3762961054935192,-0.13091512796400506
253.5000000000029,31.14318775310858,0.3802560060374716,-0.1338481413785133
254.60000000000292,31.247664924116577,0.3846971042185504,-0.1382543826311733
255.70000000000292,31.353012004638323,0.3872483488084182,-0.1427803814804638
256.8000000000029,31.45707264875702,0.39307982358121457,-0.1480878269439212
257.90000000000293,31.56126737803709,0.39733641536027714,-0.15345208488094864
259.00000000000296,31.666634814137403,0.40201974967202436,-0.15775246997833436
260.100000000003,31.77036857639581,0.4056868461744521,-0.1639017997527481
261.200000000003,31.873577314429756,0.41097641679913943,-0.16835176123782958
262.300000000003,31.980187876833902,0.4104823687509919,-0.17573079584218254
263.40000000000305,32.085654089107,0.41491750142916656,-0.18318400155280923
264.50000000000307,32.19008715646542,0.4198081279943972,-0.18867778071532282
265.6000000000031,32.2944182430648,0.42226606992485904,-0.19571405803531183
266.7000000000031,32.39896674819211,0.4259473747820273,-0.20237075730320386
267.8000000000031,32.50494085612266,0.4274657454276847,-0.2101480728355538
268.9000000000031,32.61073562377494,0.43029124781415656,-0.218088876964476
270.0000000000031,32.714781920346894,0.43400628831607213,-0.22662122385082517
271.10000000000315,32.82113925451514,0.4359689125659143,-0.2344553168275021
272.2000000000032,32.924981286583765,0.4401161306800104,-0.2433672475834685
273.30000000000314,33.0300955383218,0.4431366110675734,-0.2555786181010369
274.40000000000316,33.13514980251989,0.44432846159583794,-0.2637330913201419
275.5000000000032,33.24089552089712,0.44624298324213524,-0.2746220039228482
276.6000000000032,33.344091839519436,0.450397217170542,-0.28472797026429175
277.70000000000323,33.45118405053084,0.4515251190817978,-0.2964054071807358
278.80000000000325,33.55626622616315,0.45278822009763486,-0.31058619218721484
279.9000000000033,33.66097770722956,0.4544749830727186,-0.32040278313581094
281.0000000000033,33.7641057651158,0.45574807532056,-0.33407879453104794
282.1000000000033,33.871899561943025,0.4578379760424046,-0.3492014053508461
283.20000000000334,33.97721525728491,0.4590959115736081,-0.3627542800799981
284.30000000000337,34.081718430604546,0.4608381114633079,-0.3754379332450828
285.40000000000333,34.186331309169276,0.4617196589846189,-0.3919136223069932
286.50000000000335,34.292542002981506,0.4610373993534138,-0.40750843158773176
287.6000000000034,34.396690275694766,0.4637200178146734,-0.42312332276072917
288.7000000000034,34.50217316357295,0.46359155496427973,-0.43916229339572377
289.8000000000034,34.60737470968689,0.46430040167050596,-0.4561363494160089
290.9000000000034,34.71263031452776,0.46578839297496927,-0.4739771099611496
292.0000000000034,34.818107357143255,0.4638398079632516,-0.49184401915422393
293.10000000000343,34.92357306589425,0.46529245967254973,-0.5117965362524162
294.20000000000346,35.02874103264768,0.4656114893303651,-0.5320949852445618
295.3000000000035,35.13280996810414,0.4663016456268393,-0.5502787557911692
296.4000000000035,35.23944782116697,0.466542888299959,-0.570895254940929
297.5000000000035,35.34459295358369,0.46872247051041205,-0.5904986789058069
298.60000000000355,35.4499989436381,0.46966994308041177,-0.6097499020866666
299.70000000000357,35.555779249842765,0.4731005633461897,-0.6311395621911116
300.8000000000036,35.66142440844312,0.4758453028786829,-0.6502805247290393
301.9000000000036,35.76664512278494,0.47907283329499256,-0.6721348411703816
303.0000000000036,35.87206319322362,0.48127906377721713,-0.6918397915226859
304.1000000000036,35.97636992288674,0.4850881770245564,-0.7121730898584651
305.2000000000036,36.08290785599975,0.48634797745503866,-0.734493303705948
306.30000000000365,36.18763984755232,0.49151379789224653,-0.7562920943813607
307.4000000000037,36.29324151545401,0.4932091979557096,-0.7769665186997399
308.5000000000037,36.39990380007121,0.49843891088148085,-0.7973155654307478
309.60000000000366,36.50519377284516,0.5014845551490408,-0.8196465859311846
310.7000000000037,36.61095186624873,0.505888843023362,-0.840624594358311
311.8000000000037,36.71614890478563,0.5129221273129944,-0.8601112539468434
312.90000000000373,36.82229691174633,0.5159539537355597,-0.8825469573439895
314.00000000000375,36.926912758725265,0.5208863179177411,-0.9031781791683784
315.1000000000038,37.0336826565764,0.5277954850238916,-0.9268978481803218
316.2000000000038,37.138587471392206,0.5342109696272761,-0.9476763798337076
317.3000000000038,37.245036360595904,0.5399129655299523,-0.9695782096867647
318.40000000000384,37.350579702005696,0.5488870651439002,-0.9905172379996201
319.5000000000038,37.45739632842957,0.5564957920346536,-1.0129170132505974
320.60000000000383,37.56228819444988,0.5640017432056235,-1.0347195161147278
321.70000000000385,37.668854896434055,0.5719437741502126,-1.0569901861943922
322.8000000000039,37.774968746976654,0.5812652196756357,-1.079519846542401
323.9000000000039,37.88107860455211,0.590149680961744,-1.1016884285938602
325.0000000000039,37.98705706881269,0.5992251404699543,-1.1267451291150432
326.10000000000394,38.09178659150815,0.6106578873610097,-1.149959736687534
327.2000000000039,38.199094822429316,0.6203632339547474,-1.1742650306798197
328.30000000000393,38.30470274095709,0.6296396785864703,-1.1984816396592581
329.40000000000396,38.411700098487266,0.6405870831645266,-1.2234508620021276
330.500000000004,38.51671930426738,0.649941869018062,-1.2481178290447419
331.600000000004,38.6225331071453,0.6613640579919609,-1.2746693782829532
332.700000000004,38.73051888608243,0.6731083416699033,-1.3007843969296742
333.80000000000405,38.83560368953859,0.6847334906508876,-1.327941531419147
334.90000000000407,38.94304673273473,0.693968110939603,-1.3549377617553828
336.0000000000041,39.049467353208044,0.7079866554639341,-1.383396614248391
337.10000000000406,39.154326003713514,0.7194303187046817,-1.412813180503207
338.2000000000041,39.26283825415661,0.7336223059417826,-1.4452732177773315
339.3000000000041,39.3688109150466,0.7469992096270772,-1.4753876186104775
340.4000000000041,39.47603708428444,0.7610024049960402,-1.5070106647377486
341.50000000000415,39.58179873271701,0.7740962039235656,-1.5389916252330957
342.6000000000042,39.68836294656744,0.7879555489148964,-1.5734031611769286
343.7000000000042,39.7949726334753,0.8013223967660393,-1.6087731258055884
344.80000000000416,39.90117272171563,0.8157658866331671,-1.6449819503454268
345.9000000000042,40.00849294164817,0.8296626336168409,-1.6813382221058943
347.0000000000042,40.11488789186381,0.8446973119640927,-1.7194857216336694
348.10000000000423,40.22091119442531,0.857412408932307,-1.7594877206764452
349.20000000000425,40.328356248176334,0.8689491453101532,-1.7992863723185502
350.3000000000043,40.4345883718666,0.8824442276978568,-1.840581378733677
351.4000000000043,40.541783776954965,0.8920191521535203,-1.8837768445047889
352.5000000000043,40.6477178038403,0.903167733533644,-1.925283791143809
353.60000000000434,40.75522304743594,0.9138451423536731,-1.9713532208683984
354.7000000000043,40.861911329200325,0.9215379139395828,-2.0183112687306304
355.80000000000433,40.96909379306851,0.9275752463078369,-2.0632087801458248
356.90000000000435,41.07394581032643,0.9321326377909415,-2.108331510252256
358.0000000000044,41.18072030197697,0.9338429253476894,-2.1559645148445576
359.1000000000044,41.28804081761256,0.9333177275758212,-2.204247530968958
360.2000000000044,41.395010479009855,0.9285570083972772,-2.251220490501594
361.30000000000445,41.50213362759871,0.9217193513301043,-2.300838044799164
362.4000000000044,41.60777853588759,0.9109656351895979,-2.347945221865772
363.50000000000443,41.715519332322394,0.8961121432088643,-2.394481474412286
364.60000000000446,41.82205004814157,0.8796709214200402,-2.4416425113867657
365.7000000000045,41.92863537486222,0.8559163647301684,-2.4848538927656496
366.8000000000045,42.0359351891873,0.8299693027459194,-2.529812999151152
367.9000000000045,42.141949439835464,0.8013780221846418,-2.5716717505243833
369.00000000000455,42.24973354005234,0.7658508371482993,-2.6111857807381686
370.10000000000457,42.35698548208623,0.7276156997868541,-2.6456091451163033
371.2000000000046,42.463533822400066,0.6851065061009975,-2.6807085186561874
372.30000000000456,42.57071992961252,0.6442823356278812,-2.7108266652797846
373.4000000000046,42.67759034403472,0.601163864573013,-2.737692017052268
374.5000000000046,42.784405062391905,0.5602374893804772,-2.763010133700421
375.6000000000046,42.891329478320664,0.5212631494043815,-2.783211888583159
376.70000000000465,42.99698850159345,0.4837398162563724,-2.8008005245774994
377.8000000000047,43.1037971340019,0.45496715643878577,-2.816357648162067
378.9000000000047,43.210000945211945,0.42962979932840817,-2.8282302097601977
380.00000000000466,43.31734695621182,0.40814582688573914,-2.8376472142085296
381.1000000000047,43.42297963565016,0.3931913317622445,-2.8449541944404744
382.2000000000047,43.52798741829966,0.38365486370292223,-2.851666276964173
383.30000000000473,43.636671869093306,0.3760284815678874,-2.8581610068768213
384.40000000000475,43.74292571517966,0.3716506360465534,-2.8654672091521194
385.5000000000048,43.85000000000045,0.3649199999999587,-2.8701598740000307
386.6000000000048,43.956855059799466,0.36347536844341677,-2.8746474324299225
387.7000000000048,44.063199833950854,0.36068457384695307,-2.8794051719103937
388.80000000000484,44.17009957414137,0.3620646843710605,-2.885414352187639
389.9000000000048,44.2774911462109,0.36000892002118556,-2.888840289670976
391.00000000000483,44.383987966644966,0.3577987765507938,-2.8938089570813417
392.10000000000485,44.49118458590717,0.35818672239741295,-2.898243585498511
393.2000000000049,44.597910073498014,0.3560122370532985,-2.901088537446718
394.3000000000049,44.70437682278403,0.35482058225713375,-2.9052504302662956
395.4000000000049,44.81209761584542,0.3547258684780412,-2.9093877652093134
396.50000000000495,44.91863418410669,0.3539022387815236,-2.9131435726698105
397.6000000000049,45.025678354782634,0.35608564188956415,-2.9152126401087797
398.70000000000493,45.13344525252017,0.3551645529065577,-2.9191530242103028
399.80000000000496,45.240000969299025,0.3560398968047855,-2.9233601913129283
400.900000000005,45.347073029065236,0.3553509948649943,-2.9278980077897847
402.000000000005,45.45455768604286,0.35491149621788004,-2.9306684706473014
403.100000000005,45.56188674561843,0.35817243844265156,-2.933960491519223
404.20000000000505,45.66911953739609,0.357676735454141,-2.9377372082995623
405.30000000000507,45.77600524822875,0.35889772843426276,-2.9406624377802677
406.4000000000051,45.883730788100124,0.3615115335773016,-2.94471192599198
407.50000000000506,45.99133908756896,0.36321495580352203,-2.9482113552210416
408.6000000000051,46.09828641059398,0.3626422834326969,-2.950893575542285
409.7000000000051,46.20603293219538,0.3642155288795776,-2.954642511029652
410.8000000000051,46.31367484257067,0.3661973847832196,-2.95850674744168
411.90000000000515,46.421986778240694,0.3692319221534665,-2.9615811688393974
413.0000000000052,46.52870441653416,0.3672976943974641,-2.965784335042793
414.1000000000052,46.636558405786154,0.37284289871590764,-2.9673403601003496
415.20000000000516,46.74414449393989,0.37643248131170975,-2.971257060565592
416.3000000000052,46.851835701967445,0.3797515408020083,-2.973935741813768
417.4000000000052,46.95863297269241,0.37947092655212966,-2.9767724854741964
418.50000000000523,47.06665317174005,0.3835908383034108,-2.980656427274008
419.60000000000525,47.17432027323248,0.3869734740050054,-2.983169690027066
420.7000000000053,47.27968456874121,0.38844994650882153,-2.9882508617003225
421.8000000000053,47.38990732636378,0.3941107649624181,-2.990159002741721
422.9000000000053,47.49818468968138,0.39543121765341976,-2.9934509881302414
424.00000000000534,47.60549530583541,0.39973789452865816,-2.997470269736268
425.1000000000053,47.71287956664764,0.4041773304929761,-2.9994374849823693
426.20000000000533,47.821609450252176,0.4072860534961185,-3.0025578923272436
427.30000000000535,47.929250414089,0.41059151906322633,-3.0056916931068685
428.4000000000054,48.03778081496159,0.41489316720138514,-3.008197221418381
429.5000000000054,48.145350034162576,0.4192597965059159,-3.010093402947242
430.6000000000054,48.253236534903536,0.42402947964381016,-3.0136128536197546
431.70000000000545,48.36117481203698,0.42673368781216664,-3.0181626116642173
432.8000000000054,48.46856623987668,0.43311303489836983,-3.019440265471272
433.90000000000543,48.576173492003996,0.43648872026777086,-3.02212942259467
435.00000000000546,48.68391031182471,0.4408037943094133,-3.023579210944991
436.1000000000055,48.791888631418246,0.4438787748250013,-3.0265002484540835
437.2000000000055,48.89912270623756,0.4489151852037787,-3.0300907940507757
438.3000000000055,49.00702544281479,0.4514546908986983,-3.0336950293644276
439.40000000000555,49.11597334368318,0.4566220717046829,-3.0363411125879205
440.50000000000557,49.223624782984125,0.46175219264024425,-3.039033013793605
441.6000000000056,49.33150891505856,0.4654270430411512,-3.0411720806500506
442.70000000000556,49.43948470711908,0.47031489075451127,-3.0430109789169566
443.8000000000056,49.54747371205079,0.47474784808560294,-3.04532342448353
444.9000000000056,49.65602620644708,0.4791587802496708,-3.0465993993054563
446.0000000000056,49.763675799147066,0.48504480039601794,-3.0492790031963324
447.10000000000565,49.872190052388355,0.48704331688239794,-3.052074050808025
448.2000000000057,49.97932893423479,0.4936032115231286,-3.053957835839907
449.3000000000057,50.087353434951055,0.49902771132372836,-3.057112165253061
450.40000000000566,50.19439455494033,0.502397463201899,-3.0592539095363627
451.5000000000057,50.302936830778165,0.5083630798889268,-3.061903721188226
452.6000000000057,50.41099525707344,0.512327384949376,-3.0645198620525687
453.70000000000573,50.51886686613429,0.5175647385834424,-3.065950738275296
454.80000000000575,50.626978351146136,0.5230763586722679,-3.0672715751757185
455.9000000000058,50.73551565642862,0.5259963399383967,-3.0689644851499343
457.0000000000058,50.843717104030226,0.5312794456536917,-3.0702397638861987
458.1000000000058,50.95149165559161,0.5373681438054144,-3.0738553803359387
459.20000000000584,51.05789186223399,0.5373798724647999,-3.0751888920582875
460.3000000000058,51.16925335172423,0.5430465527682787,-3.076495853439507
461.40000000000583,51.27782083110579,0.5472682408547529,-3.077799116436379
462.50000000000585,51.38644651248508,0.550780023478742,-3.0791136499133063
463.6000000000059,51.49511519973375,0.5557599276487603,-3.0817572691584414
464.7000000000059,51.60366372281744,0.5603142734389304,-3.083068067381952
465.8000000000059,51.71155896440492,0.5650495673851985,-3.084357792978576
466.90000000000595,51.82010333458283,0.5686855299792172,-3.0860281264466876
468.0000000000059,51.929692157122034,0.5724590579063286,-3.0885999322171593
469.10000000000593,52.03813170786239,0.5780780006068794,-3.0898901561995515
470.20000000000596,52.146539791347905,0.5808503432012769,-3.0912362080683247
471.300000000006,52.25533385473514,0.5846272613774669,-3.094001802966571
472.400000000006,52.36433182164416,0.5884612342012219,-3.09428759467282
473.500000000006,52.47321137146108,0.5951691058005204,-3.095594837109465
474.60000000000605,52.58221075616504,0.5958874185483327,-3.0980678496097784
475.70000000000607,52.691335000973666,0.598879441197621,-3.100163646330502
476.8000000000061,52.80059455992783,0.602849698258719,-3.1015001888415483
477.90000000000606,52.908763410426054,0.6048437811158646,-3.1028096257287157
479.0000000000061,53.01743740099053,0.6103990369071598,-3.1041299126277684
480.1000000000061,53.127400701192464,0.6147780571620305,-3.105466622735176
481.2000000000061,53.23742689629005,0.6191692437153002,-3.1069428018119045
482.30000000000615,53.3453131527344,0.6208636741843051,-3.1071005836710364
483.4000000000062,53.45479571717289,0.6275856003107738,-3.1084008179181213
484.5000000000062,53.562407053018866,0.6304942304942875,-3.1097208380424655
485.60000000000616,53.671324951993036,0.6345390373752648,-3.1110457017834374
486.7000000000062,53.77999901636893,0.6383800913224347,-3.1130100864388264
487.8000000000062,53.88867249842424,0.6429603709955886,-3.113667657441586
488.90000000000623,53.99810455163081,0.6462403782520844,-3.1149798776089415
490.00000000000625,54.105809128635244,0.6496884897159229,-3.1162984807014045
491.1000000000063,54.21460847895235,0.65225937123571,-3.1176205083470565
492.2000000000063,54.323431470402014,0.6581735081437312,-3.118930703637017
493.3000000000063,54.43196436616705,0.6592058521402581,-3.1202487225560533
494.40000000000634,54.54115869060218,0.6641865275352721,-3.12156987319453
495.5000000000063,54.6501922286112,0.6692101212662289,-3.1228797762467257
496.60000000000633,54.75894998090251,0.6719440158138694,-3.1238390957013182
497.70000000000636,54.86758471283411,0.6857703212549188,-3.1245219445080172
498.8000000000064,54.9765985491154,0.6954708968092671,-3.125754882825209
499.9000000000064,55.085503715087256,0.7025667952147069,-3.126740723615689
501.0000000000064,55.1940282576687,0.7120441082905228,-3.12867690741061
502.10000000000645,55.30193697429397,0.7160690407382798,-3.1297740851585627
503.2000000000064,55.41195471553048,0.720915100730071,-3.1305139853564654
504.30000000000643,55.519583309766006,0.7251548333729274,-3.1311090378864526
505.40000000000646,55.62946718844336,0.7331523465761351,-3.133746555721405
506.5000000000065,55.73700449088277,0.7384923688461654,-3.1324197895565122
507.6000000000065,55.846014342619036,0.7438503206113657,-3.13472678426697
508.7000000000065,55.95459683362363,0.7478594134106604,-3.1370616023743674
509.80000000000655,56.06400273401416,0.7526025340222149,-3.13669992522677
510.90000000000657,56.172355548620025,0.7573320390482474,-3.1373509319129327
512.0000000000066,56.28068426757729,0.7638968955582734,-3.1373631416197623
513.1000000000065,56.39047546131314,0.7673085397790441,-3.1386685091332702
514.2000000000066,56.499697137962876,0.772102393478156,-3.1406499116951503
515.3000000000065,56.60836246263484,0.7766205066358478,-3.1419739974929004
516.4000000000067,56.71639803257105,0.7814218425420288,-3.14194298422687
517.5000000000066,56.826031155506904,0.7856435563443074,-3.1419610724996
518.6000000000067,56.93511250133852,0.7886515056343756,-3.1432816791313463
519.7000000000066,57.044142376764206,0.7964402667345666,-3.1445898329408175
520.8000000000067,57.15394375246307,0.7982216370639388,-3.1459083248888486
521.9000000000067,57.263546925802856,0.8039886540771172,-3.1468995448329826
523.0000000000067,57.37321840052091,0.8068913255373306,-3.147237198180772
524.1000000000067,57.48183916280992,0.8119027850992507,-3.1495748423601766
525.2000000000068,57.591362211940144,0.8132411002027118,-3.14986023476156
526.3000000000068,57.699894842527755,0.8181964399218541,-3.151833308494684
527.4000000000068,57.810451416987775,0.821722458719896,-3.1535080510272055
528.5000000000068,57.91927098672653,0.824120150504027,-3.151699218202052
529.6000000000068,58.027799683216706,0.8261202129012,-3.1528189133862616
530.7000000000069,58.13796319131741,0.8269920616181651,-3.154139739407226
531.8000000000068,58.24791161023768,0.8192341908616768,-3.1541381953667917
532.9000000000069,58.35747095193788,0.8169332255832175,-3.1561243348836823
534.0000000000068,58.4674762282338,0.814444571333767,-3.1564401871732044
535.100000000007,58.57678846622763,0.8152614594849847,-3.1564649793995825
536.2000000000069,58.685354142256905,0.8133579057214786,-3.157805552880281
537.300000000007,58.79544366888845,0.8139748818242709,-3.1590583846509452
538.4000000000069,58.906411089640166,0.8140066778124241,-3.158989215045415
539.5000000000069,59.014429283098664,0.8153904602319687,-3.1590735803289625
540.600000000007,59.124712803032736,0.818237706225431,-3.1604010145127734
541.700000000007,59.23394683342753,0.8191551089803294,-3.1617101360629785
542.800000000007,59.343922208190875,0.8220911016005479,-3.161746545179037
543.900000000007,59.45369155169486,0.8223300032700991,-3.163029882957579
545.000000000007,59.563349319762175,0.8284782376471237,-3.1620411720753174
546.1000000000071,59.672341071259794,0.8278327412075408,-3.1633499588508123
547.2000000000071,59.78210956289809,0.8299611798684567,-3.163349977636427
548.300000000007,59.89122841840069,0.8344705174307111,-3.1646693179876264
549.4000000000071,60.00090755119398,0.8365745738337217,-3.1657011439766336
550.500000000007,60.11000000000077,0.839519999999947,-3.1672271419997973
551.6000000000072,60.21913870599218,0.8421117922599726,-3.16730042769965
552.7000000000071,60.32892458538076,0.8434138174322887,-3.1686213878534017
553.8000000000072,60.437963552748876,0.8430938130817813,-3.1686198979887026
554.9000000000071,60.547719795914595,0.8425053727707078,-3.1686385308931495
556.0000000000072,60.657302118262784,0.8434894071916874,-3.1699400083142164
557.1000000000072,60.7667482568401,0.8465841687390074,-3.1702830582238617
558.2000000000072,60.875558586394405,0.8451838866290975,-3.171250172291395
559.3000000000072,60.985783255372866,0.8485709223007264,-3.1739605711223673
560.4000000000073,61.09604263116576,0.8499027090313643,-3.173226846430423
561.5000000000073,61.20609193516876,0.8526284485439561,-3.17454032075042
562.6000000000073,61.316722837134016,0.8550169020733845,-3.173890899174761
563.7000000000073,61.4259203420495,0.8569499192071897,-3.17454746664293
564.8000000000073,61.536279523414585,0.8582840306450824,-3.1763339721479813
565.9000000000074,61.647016519931384,0.8605760739424305,-3.175774088829736
567.0000000000074,61.7542268148089,0.8640832077844758,-3.1761799463419704
568.1000000000074,61.86738943500534,0.8665138437044273,-3.1775018898915253
569.2000000000073,61.97745976048123,0.8702786124127825,-3.177500161746153
570.3000000000073,62.08797165086111,0.8726901743812769,-3.17880277238829
571.4000000000074,62.19736091976116,0.8781937022190522,-3.178483794924194
572.5000000000074,62.30806113727682,0.8827451950762819,-3.1788198892230453
573.6000000000074,62.41819163315172,0.8831850330673116,-3.18146893088647
574.7000000000074,62.527632593107064,0.8864526329780101,-3.1827604944580177
575.8000000000075,62.63794347240087,0.8869509796634897,-3.181450076589688
576.9000000000075,62.74823554638724,0.8937349178922009,-3.182759217410491
578.0000000000075,62.855767716658306,0.8980903587275616,-3.184058207884461
579.1000000000075,62.967548301310735,0.9019370994858643,-3.1840889853125423
580.2000000000075,63.07628335559969,0.9060806756499284,-3.1854030378180327
581.3000000000076,63.185917877816536,0.9125188262191849,-3.185456855708218
582.4000000000076,63.29670380654651,0.9159823354345143,-3.1853999390049985
583.5000000000076,63.40749094985795,0.9209235189961544,-3.1854295778233994
584.6000000000076,63.51665304155415,0.9241133407619351,-3.1856555693488913
585.7000000000077,63.626958124929466,0.9303965694017247,-3.1880301057844127
586.8000000000077,63.73587143451281,0.9333278098239423,-3.18902633406363
587.9000000000076,63.84530287670373,0.9359513444664258,-3.190377786749867
589.0000000000076,63.95657254483474,0.9402613367455015,-3.1903968601062798
590.1000000000076,64.06647007651563,0.9470200434463971,-3.190673371408981
591.2000000000077,64.17774008764815,0.9497192981127872,-3.190669866975636
592.3000000000077,64.28804623049976,0.9557394357685326,-3.1918167132513426
593.4000000000077,64.39704231153947,0.9591349407655301,-3.1920077216511684
594.5000000000077,64.50784412157323,0.9645326239883609,-3.193186043085843
595.6000000000078,64.61753797944002,0.9689916332919718,-3.1919799809876475
596.7000000000078,64.72753542247281,0.9738864635298133,-3.1933020893520436
597.8000000000078,64.83788043145083,0.9791120630993526,-3.1926396011126577
598.9000000000078,64.9481537974993,0.9847030696887115,-3.1939501397069594
600.0000000000078,65.05910241870194,0.9901183644207312,-3.193950139457083
601.1000000000079,65.16932802265384,0.9956042313405717,-3.196399947301038
602.2000000000079,65.27942657590374,1.0001129469705634,-3.1952654541267314
603.3000000000079,65.38968330100047,1.0045385569825873,-3.196589800002709
604.4000000000078,65.50159716118246,1.0131568146358316,-3.197393105462603
605.5000000000078,65.61203603498387,1.0168496756195429,-3.1962514078977184
606.6000000000079,65.7213956573967,1.0205879555774484,-3.196296904467737
607.7000000000079,65.83145896283008,1.0264359432801502,-3.1979478850028062
608.8000000000079,65.94143005423987,1.0343827103549372,-3.1985340322406626
609.9000000000079,66.052746238255,1.0368519611508626,-3.199881223888263
611.000000000008,66.16373695765411,1.0457800097609478,-3.198670066723411
612.100000000008,66.27407478535966,1.049328615217135,-3.201189804095378
613.200000000008,66.38483139026526,1.0548878166276132,-3.2008546835343155
614.300000000008,66.49538141500608,1.0614328021999888,-3.202178949591525
615.400000000008,66.60627453610941,1.0681353604668606,-3.202509780554659
616.5000000000081,66.71652049876197,1.0751465175236674,-3.2022445395840853
617.6000000000081,66.82808445683631,1.083930215410377,-3.20349685744879
618.7000000000081,66.93805061064025,1.0899817533015053,-3.2048648532230435
619.8000000000081,67.04958435512219,1.0977952598758136,-3.203500855462525
620.9000000000082,67.1598056810099,1.1020177284761465,-3.203500089731232
622.0000000000082,67.27067944910277,1.1104451015211003,-3.204817305310331
623.1000000000081,67.38028724115708,1.1154639687514407,-3.203854617511799
624.2000000000081,67.49062622946353,1.1192170125546492,-3.2052528404069647
625.3000000000081,67.60119414418703,1.128477165169115,-3.2057998479536165
626.4000000000082,67.71164368880524,1.1346582812321035,-3.2058002360502833
627.5000000000082,67.82166839031386,1.1414795978585885,-3.2074433509842795
628.6000000000082,67.93260974936159,1.1455958632490297,-3.2061310404073398
629.7000000000082,68.04305437041445,1.1517609306558525,-3.2061333128523857
630.8000000000083,68.15219252998338,1.1588198107391998,-3.207332662947089
631.9000000000083,68.26349011021878,1.1639192430263245,-3.2061495185734414
633.0000000000083,68.37432826370868,1.1691112254688136,-3.2081003689173926
634.1000000000083,68.4845369412086,1.1734717228723375,-3.208099593736879
635.2000000000083,68.59538405858507,1.1731486094199455,-3.2093657165289455
636.3000000000084,68.70644170414342,1.178754308650026,-3.207562540067381
637.4000000000084,68.81684057660617,1.1854729423590227,-3.208880226375666
638.5000000000084,68.92809191627916,1.1887010844443406,-3.210190904603631
639.6000000000083,69.03938981612875,1.1935401341867866,-3.211509838489109
640.7000000000083,69.14950888454626,1.197136684991576,-3.21150984594685
641.8000000000084,69.26129270933873,1.2005128562993352,-3.2111543427609672
642.9000000000084,69.37276537944989,1.2037337121609744,-3.2113945670116673
644.0000000000084,69.48389996390715,1.2102037376082535,-3.2121993423337405
645.1000000000084,69.5938753181059,1.2134161272400026,-3.2117421139428988
646.2000000000085,69.70411468622922,1.2184113337424693,-3.210313891754759
647.3000000000085,69.81452170248375,1.2245944802510846,-3.2116208443344734
648.4000000000085,69.92464859075905,1.2285152156268984,-3.212929942435139
649.5000000000085,70.03428667604722,1.2341328564318104,-3.213909553081493
650.6000000000085,70.14605445920172,1.241800379980787,-3.21392000514439
651.7000000000086,70.25643499180329,1.2462246094255032,-3.214725806755644
652.8000000000086,70.36747769490353,1.2521756911728013,-3.213590084270095
653.9000000000086,70.4768208875866,1.254529056973321,-3.2136017607611924
655.0000000000086,70.58829816298757,1.2590733347991372,-3.2152303443385946
656.1000000000087,70.69989815756865,1.264859956340252,-3.2152296820450417
657.2000000000087,70.80893990133944,1.268695471054131,-3.2152301622533703
658.3000000000086,70.92098878743148,1.2731935811902522,-3.2166397090029886
659.4000000000086,71.03280291638987,1.279146438374912,-3.2152398549762213
660.5000000000086,71.14254474936372,1.2840127454665236,-3.2152398549481287
661.6000000000087,71.25332084449366,1.2890777859514673,-3.2155845983394027
662.7000000000087,71.36490101210764,1.2939389908759644,-3.2172099447865934
663.8000000000087,71.47674938777446,1.3000923531139699,-3.2172000011215416
664.9000000000087,71.58830325745866,1.3075432687278497,-3.2158999479832975
666.0000000000088,71.69866864558134,1.3130043864801768,-3.215900526854807
667.1000000000088,71.80868982637092,1.3190453977605203,-3.217209997491085
668.2000000000088,71.92061873160455,1.3216835375407239,-3.217210014310332
669.3000000000088,72.0322191257276,1.3277367178149557,-3.2185286149283905
670.4000000000088,72.14317978450312,1.3341775814044696,-3.2175391283371386
671.5000000000089,72.25497974045868,1.336813878744819,-3.2179068328366993
672.6000000000089,72.36471712339198,1.34288472321507,-3.219190157480993
673.7000000000089,72.47620253592801,1.3502630321378906,-3.2188666770171697
674.8000000000088,72.58885479380919,1.354984717553112,-3.2201698788036826
675.9000000000088,72.699263610917,1.3640817420680365,-3.217272897382281
677.0000000000089,72.81076019243397,1.3700970847034257,-3.2202824679855397
678.1000000000089,72.92170916400921,1.374146242943536,-3.218970158139924
679.2000000000089,73.031589828516,1.3799947377071842,-3.220074491508922
680.3000000000089,73.14318672769595,1.386727280117984,-3.221269852995257
681.400000000009,73.25353535117974,1.391426287382351,-3.221270240973099
682.500000000009,73.36518698297114,1.3985002708351912,-3.219959818057161
683.600000000009,73.47505617480066,1.4049984059901233,-3.2198929011593154
684.700000000009,73.58624060453614,1.4101388962083352,-3.221265247217338
685.800000000009,73.69767718570063,1.4165048661964537,-3.22224992328953
686.9000000000091,73.80782544361358,1.4209305042922828,-3.2222478410239885
688.0000000000091,73.91861797251767,1.4251607268787296,-3.2209497292489155
689.1000000000091,74.02990183643537,1.4344702091807122,-3.222260011904474
690.2000000000091,74.13957486603266,1.4362694431094127,-3.2235479967573504
691.3000000000092,74.25244299076334,1.4440195549605614,-3.222252130295845
692.4000000000092,74.36374717328536,1.4496982814600639,-3.2222442538632174
693.5000000000091,74.47416578413207,1.4572239072892073,-3.224559211596251
694.6000000000091,74.58618591235494,1.4597030405406095,-3.2242306372754435
695.7000000000091,74.69740788310463,1.468844028192835,-3.22324023652589
696.8000000000092,74.80811520072947,1.4742074538806138,-3.223214672397118
697.9000000000092,74.91999794852006,1.4798901642632092,-3.223568588117999
699.0000000000092,75.03084219487273,1.4859356559633228,-3.223557560173834
700.1000000000092,75.1422934441879,1.4922626397618792,-3.2262052153820533
701.2000000000093,75.25345399441504,1.4994166464657377,-3.224892790154311
702.3000000000093,75.36497373795706,1.5042567378772884,-3.2248799292010237
703.4000000000093,75.47600444286553,1.5091523222926098,-3.2242796991286062
704.5000000000093,75.58763947730391,1.5167546147967585,-3.2239000625816123
705.6000000000093,75.6990399833173,1.5211314252493504,-3.2252108820394345
706.7000000000094,75.81010680662231,1.5280614181229322,-3.225226125815218
707.8000000000094,75.9212336224569,1.5334848443534286,-3.225225424044587
708.9000000000094,76.03330478844299,1.5394024995092774,-3.226532414311765
710.0000000000093,76.14381212090106,1.5480467057406242,-3.227200136495134
711.1000000000093,76.25640230826183,1.5502680324889666,-3.2263320223493976
712.2000000000094,76.36677222436855,1.5574968014134847,-3.2275862560202153
713.3000000000094,76.4786677887731,1.562893473695183,-3.227532069086257
714.4000000000094,76.58989534341119,1.5707948530745117,-3.228839826356095
715.5000000000094,76.70099894246339,1.5768399291527848,-3.227290239896723
716.6000000000095,76.81256869041412,1.585096096340704,-3.2288399179289744
717.7000000000095,76.92455439863052,1.5905454683741698,-3.229856117162132
718.8000000000095,77.0358481696656,1.5955996141286735,-3.2304800783681342
719.9000000000095,77.14863585603572,1.6033957448698126,-3.231799999575819
721.0000000000095,77.25946110786967,1.6080448239527318,-3.230476457216559
722.1000000000096,77.37093953757461,1.6146291703877764,-3.2305021060764236
723.2000000000096,77.48296714397516,1.6222525387509232,-3.2316367707938696
724.3000000000096,77.59516984798813,1.6284311532848565,-3.2309204470584927
725.4000000000096,77.70584221747227,1.6364654508382441,-3.2295311512696125
726.5000000000097,77.8166398310089,1.643020698083671,-3.2321302490491544
727.6000000000097,77.92782863363622,1.648699015409247,-3.232130258951799
728.7000000000096,78.0383562726505,1.656360696448945,-3.23310971441589
729.8000000000096,78.15071457017345,1.6649028355180844,-3.2335971930975096
730.9000000000096,78.2616724201649,1.6702729835283983,-3.233112243411482
732.0000000000097,78.37311856555996,1.6746425397605549,-3.234742957230028
733.1000000000097,78.484913979416,1.6856713647026045,-3.233426017507565
734.2000000000097,78.59588962132864,1.6901656969278254,-3.234216030942523
735.3000000000097,78.70685062110319,1.6961167011222595,-3.2360687716821213
736.4000000000098,78.81780533532378,1.70388116580816,-3.2347608662699683
737.5000000000098,78.92850603128028,1.7106250354016939,-3.2347599929915445
738.6000000000098,79.04072872913487,1.7151697824681564,-3.2351521988892444
739.7000000000098,79.15117729533785,1.7240092041791912,-3.2360800850993545
740.8000000000098,79.26288241006772,1.7313526800807846,-3.23608008821279
741.9000000000099,79.37448984843483,1.7364742461422555,-3.237041996705963
743.0000000000099,79.48533826580909,1.7434357341473832,-3.2374001783813706
744.1000000000099,79.59677039156905,1.7502966616628641,-3.23675517699495
745.2000000000098,79.7091638539801,1.7592753995715598,-3.2377007069882424
746.3000000000098,79.81948859988502,1.7623791441655514,-3.23672808024056
747.4000000000099,79.93163551958465,1.772367443863888,-3.2380488585524554
747.9000000000099,79.98222839515019,1.7751289842867957,-3.2380498911470497