File: 01_Data/Vinyl_Tile/STA/N2/30K_min/Vinyl_Tile_STA_N2_30KData_220505_R1.csv
##Temp./Â°C,Time/min,DSC/(mW/mg),Mass loss/mg
49.0,10.479391623071074,-1.2244567470395231,-0.007825242679493805
50.100000000000016,10.699555382454795,-1.0933439392191526,-0.007303426562543791
51.20000000000003,10.82814180594666,-1.001727754697823,-0.006528584371287671
52.30000000000005,10.927828881478142,-0.9261085325520354,-0.005982817754151881
53.40000000000006,11.011299730461559,-0.8651184938798874,-0.007408408122583587
54.50000000000008,11.084813608747577,-0.809629624302272,-0.00865572214615895
55.600000000000094,11.152985446606976,-0.7591210264491357,-0.007283721724598458
56.70000000000011,11.217139299660062,-0.7125204128620036,-0.006789150977093428
57.800000000000125,11.275463499742438,-0.6710051449614484,-0.007408126976821805
58.90000000000014,11.331441818005107,-0.6329789517800068,-0.006894444982989079
60.000000000000156,11.385304281759112,-0.597107670708729,-0.006754411991538589
61.10000000000017,11.4369376281842,-0.5635431900028263,-0.0067465212219435244
62.20000000000019,11.486346853357508,-0.5336097618402229,-0.006300936973849147
63.3000000000002,11.534955299254925,-0.5037046004031088,-0.006910269615449494
64.40000000000022,11.58224401137815,-0.4772649915235493,-0.007075378431614432
65.50000000000023,11.628488273491373,-0.45000420014084025,-0.006659136922310793
66.60000000000025,11.67380644028367,-0.42813708666083744,-0.008070810807269346
67.70000000000027,11.719147327059456,-0.4054081203625905,-0.007517787597490333
68.80000000000028,11.762596745754292,-0.3842210489037251,-0.007531430899283542
69.90000000000029,11.805586421076578,-0.36445499556252337,-0.006693985603591024
71.00000000000031,11.84778759945657,-0.3440416784428205,-0.007514241021224777
72.10000000000034,11.889978984000978,-0.32722246542277444,-0.00839342081431571
73.20000000000034,11.93216195906775,-0.30698783586110756,-0.008361759723806372
74.30000000000035,11.973206281188824,-0.29312173542657394,-0.008218188286013728
75.40000000000038,12.013765179387393,-0.27635795059251955,-0.0071138932975376434
76.5000000000004,12.054797701331447,-0.25992704483522,-0.00725082241990993
77.6000000000004,12.094916350450191,-0.2440254530346296,-0.007938003371759983
78.70000000000041,12.134854413187902,-0.22998461136564086,-0.007634194774401415
79.80000000000044,12.174538701447029,-0.21664063570108869,-0.007678766563181227
80.90000000000046,12.214519821173438,-0.20218617233710717,-0.007295117741044521
82.00000000000047,12.253556062281735,-0.18870881555152344,-0.007897137921751174
83.10000000000048,12.292341792191213,-0.17583818589585867,-0.00823369810925012
84.2000000000005,12.331602298455817,-0.16445646141693082,-0.009096360456692487
85.30000000000052,12.37032542297506,-0.15235709356419339,-0.009757425846631307
86.40000000000053,12.408519692022146,-0.14215191677332187,-0.009602453968983404
87.50000000000054,12.446966221572252,-0.12973086171487822,-0.008148719708875873
88.60000000000056,12.484602378742636,-0.11863223728845217,-0.008112075925052586
89.70000000000059,12.522578082535553,-0.1099326116657754,-0.008110885869117013
90.8000000000006,12.560775768597154,-0.09885464718446337,-0.008126288897630118
91.9000000000006,12.598565688629078,-0.08668789105682304,-0.0093860958093952
93.00000000000063,12.63622696616268,-0.07800678148787779,-0.00898309198630809
94.10000000000065,12.673282046016835,-0.06915219960482842,-0.009547152371416345
95.20000000000066,12.71082535254522,-0.05957421975924479,-0.009548504813617242
96.30000000000067,12.74770352701418,-0.049734151847758826,-0.008556785979281223
97.40000000000069,12.784378252510638,-0.042258252215199965,-0.009535449504343596
98.50000000000071,12.821641375437716,-0.0321678061869692,-0.009541243216638406
99.60000000000072,12.858722258921045,-0.023901051978946958,-0.008205030260928226
100.70000000000073,12.895898238019702,-0.015176047203322997,-0.009575991867243339
101.80000000000075,12.932469144680573,-0.007496304582065069,-0.009532521173092334
102.90000000000077,12.969709620149706,0.0005220876403868849,-0.008700010702932914
104.00000000000078,13.007044105671424,0.009409992933803207,-0.009539718451997636
105.10000000000079,13.043975261726493,0.019183742144105263,-0.00953175499552561
106.20000000000081,13.080651112748617,0.027192194008573506,-0.009517935142659084
107.30000000000084,13.117472781770507,0.03500602238415816,-0.009540451393860394
108.40000000000084,13.153963104049394,0.044102623463059494,-0.009946672884487029
109.50000000000085,13.1909643670697,0.05054013072051185,-0.009540277438278899
110.60000000000088,13.227657622765465,0.060220365072245555,-0.00953992448675045
111.7000000000009,13.264775100898744,0.06728739074076907,-0.010895816838072836
112.8000000000009,13.302122110028758,0.07717186908633708,-0.010540869626551874
113.90000000000092,13.338887332310657,0.08615498769946554,-0.010900291703100251
115.00000000000094,13.374629745133106,0.09279598467947879,-0.010859241694295196
116.10000000000096,13.411198403956096,0.10076461112208193,-0.009565860381036906
117.20000000000097,13.447833652379352,0.10807056931439132,-0.010851186233010957
118.30000000000098,13.484165828682858,0.1143159900492558,-0.010856672109728738
119.400000000001,13.521397376800326,0.12372644501969524,-0.009545990958293338
120.50000000000102,13.557603231767835,0.1312299835789472,-0.009539852979977503
121.60000000000103,13.593912603155895,0.1377594640104838,-0.009526125433322541
122.70000000000104,13.630280712763154,0.14475192885023744,-0.010860896239788254
123.80000000000106,13.666849328908704,0.1525457797298033,-0.010859843103147249
124.90000000000109,13.70261849358425,0.15864940934336427,-0.010861802399293019
126.0000000000011,13.73899769332332,0.16638926077913352,-0.012153902309626652
127.1000000000011,13.775118819739362,0.172434539523895,-0.01190055349272523
128.20000000000113,13.811040429719377,0.1792511444820508,-0.010860396581343412
129.30000000000115,13.847032501246803,0.186996944053211,-0.010811007246712911
130.40000000000117,13.883129846476344,0.19206541228469082,-0.011854945856501597
131.50000000000117,13.918798527310924,0.19837290157134044,-0.011850164027545684
132.6000000000012,13.954315220319389,0.20369041390762713,-0.011780956379707774
133.7000000000012,13.990275640190417,0.21237843873705167,-0.01084390826158188
134.8000000000012,14.025844849224498,0.21974097374705936,-0.012173297340705158
135.90000000000123,14.061388924106481,0.22585425402926004,-0.012170080704430042
137.00000000000125,14.0970201639253,0.23277782406247108,-0.012170082005104277
138.10000000000127,14.132709296066913,0.23903171013428826,-0.012170058355310598
139.2000000000013,14.16826624295251,0.24393730514976553,-0.01218578401011472
140.3000000000013,14.203327681279783,0.25168460365961887,-0.013491662034065932
141.4000000000013,14.238361567509099,0.25904622644088315,-0.01349007555645132
142.50000000000134,14.273661296439755,0.265492986434675,-0.012949832920798432
143.60000000000133,14.308595277594891,0.272181215287937,-0.01249911592263242
144.70000000000135,14.343863578715235,0.2800628736161331,-0.012157496308120574
145.80000000000138,14.379118761036613,0.28623344384648214,-0.013548499026832861
146.9000000000014,14.414323832317875,0.2923461740035091,-0.013489944264248432
148.00000000000142,14.448885546015681,0.2966362716992625,-0.013489987993080543
149.10000000000142,14.484153836959274,0.3024150045370669,-0.013490846388636513
150.20000000000144,14.519005270807263,0.3110131214427234,-0.012168032087940706
151.30000000000146,14.553520050375264,0.31525791401961467,-0.012179951435467906
152.40000000000146,14.588633217240455,0.3228233118143394,-0.01217992827985137
153.50000000000148,14.623219153222689,0.3266580228751574,-0.012180311343545469
154.6000000000015,14.657978902863006,0.3336879124471796,-0.013477080535968078
155.70000000000152,14.69235257834338,0.3377065499770809,-0.013489940153957214
156.80000000000155,14.727451853790269,0.3444801685959569,-0.013489922926324116
157.90000000000154,14.761942925978518,0.3521325548312121,-0.013489954373831381
159.00000000000156,14.796832401482993,0.3564198115281589,-0.013494857112234193
160.1000000000016,14.831637564451041,0.36256261322583705,-0.014149531387171788
161.20000000000158,14.865783406061514,0.3668642022255905,-0.014155242816454194
162.3000000000016,14.900119801548168,0.3733281641619254,-0.014803617192535867
163.40000000000163,14.93474915897905,0.3798721888085171,-0.014809928011846107
164.50000000000165,14.969192139001514,0.3853858944535002,-0.014809922997577996
165.60000000000167,15.003841310401793,0.38918381017407055,-0.014809922776127138
166.70000000000167,15.038173627782687,0.39663964332767365,-0.014810471990278629
167.8000000000017,15.072797058456553,0.40417217363190383,-0.015796054138701443
168.9000000000017,15.106969964934802,0.4082788194356037,-0.016131244247163057
170.0000000000017,15.141101219295425,0.41317032325578407,-0.015445330042680006
171.10000000000173,15.1755095454389,0.41925987217119526,-0.015469905439395859
172.20000000000175,15.209718604629963,0.42285809366405747,-0.015469876970048091
173.30000000000177,15.243943323862522,0.43078650930803936,-0.015469877000019228
174.4000000000018,15.278069169454401,0.4347532384139558,-0.015469877000001464
175.5000000000018,15.311888564455947,0.4424337215589295,-0.015469877000465981
176.6000000000018,15.346289794700747,0.4462090123857023,-0.015469874715733578
177.70000000000184,15.380499669729033,0.4516986105657079,-0.015472824986853428
178.80000000000183,15.414592834422631,0.45657216827852193,-0.016439054252684215
179.90000000000185,15.44859597300842,0.461103426859247,-0.017447737368895933
181.00000000000188,15.48260613040349,0.46749933532570465,-0.017439941267289427
182.1000000000019,15.516631823053919,0.4719860612593381,-0.017439946004327744
183.20000000000192,15.550621545263672,0.47684148733879866,-0.017439947488401497
184.30000000000192,15.584244530789556,0.4808746468418019,-0.017430818967851813
185.40000000000194,15.61783961678379,0.48657478206133614,-0.01776948896712849
186.50000000000196,15.651547538526117,0.4898251914857002,-0.017769946707646422
187.60000000000196,15.685453446519126,0.49393933545615737,-0.017769962412108153
188.70000000000198,15.71874491728656,0.49902811528439817,-0.017756939951801165
189.800000000002,15.752753578383881,0.5020030574578198,-0.019084152922674846
190.90000000000202,15.78675352549753,0.5068696844528345,-0.019089952883143635
192.00000000000205,15.820168844143002,0.5109000225019164,-0.019089946020975468
193.10000000000204,15.853782358847463,0.5160402399906879,-0.019089922824562233
194.20000000000206,15.887548637491893,0.5181163096473081,-0.019106908651719934
195.3000000000021,15.921306102839981,0.522929889592466,-0.018064916842935652
196.40000000000208,15.954753983452127,0.5260401754781946,-0.018425871079338574
197.5000000000021,15.988444688425655,0.5302531282445471,-0.019790229977324714
198.60000000000213,16.02202083263581,0.5348359070527273,-0.01974085437158246
199.70000000000215,16.05542699350449,0.5399738753329989,-0.020952954055476702
200.80000000000217,16.088661074696944,0.5410851476819595,-0.022420110700734686
201.90000000000217,16.122407508131122,0.5465089889056867,-0.022380081290755083
203.0000000000022,16.15584835857887,0.5506399658958034,-0.022380127975128783
204.1000000000022,16.18953911632155,0.5548401949956521,-0.0223801895611353
205.2000000000022,16.22292247403642,0.5568758413899647,-0.022331033879001705
206.30000000000223,16.25650768259881,0.5621153444770457,-0.023692421226535476
207.40000000000225,16.289690907634256,0.5653603785784711,-0.023690185408245856
208.50000000000227,16.323410597928614,0.5669034663221159,-0.023694075958526017
209.6000000000023,16.35652852324811,0.5706357887930756,-0.02501870399258399
210.7000000000023,16.39039734309038,0.575197557825097,-0.025012761057257915
211.8000000000023,16.423277581538205,0.5789924263307229,-0.026338521137836413
212.90000000000234,16.456948356492013,0.58187200060795,-0.026329968727142106
214.00000000000233,16.490395096701274,0.5855414881567493,-0.026329897589455253
215.10000000000235,16.523664140960015,0.5877647053079983,-0.026559124511398746
216.20000000000238,16.556878910830743,0.5911830452974628,-0.0276414039739028
217.3000000000024,16.590480227156544,0.5939384329118326,-0.02888850761779782
218.40000000000242,16.623906227003392,0.5944958881705498,-0.02895222123239538
219.50000000000242,16.657416474290628,0.5988235978286838,-0.030207162166457024
220.60000000000244,16.690346474281895,0.6005695449964943,-0.031590289817499784
221.70000000000246,16.723842240296225,0.6017852553316442,-0.032096568425824756
222.80000000000246,16.757353560898835,0.6042030686454614,-0.03288835579442839
223.90000000000248,16.790194653802033,0.6061476106815127,-0.03314494458045303
225.0000000000025,16.824031071333323,0.6113836886721963,-0.03416921059650946
226.10000000000252,16.857230240814957,0.6119934405620941,-0.034230066736502085
227.20000000000255,16.890635402936592,0.6146429134945461,-0.036503778032157985
228.30000000000254,16.92357306102143,0.6166617626147513,-0.037005585210203584
229.40000000000256,16.95719689205399,0.6201513669150259,-0.037836844847927154
230.5000000000026,16.990367515428705,0.6236407453326447,-0.03917006965517267
231.60000000000258,17.023901019067157,0.6270409345524669,-0.03965968343519588
232.7000000000026,17.056750213899626,0.6291114462451618,-0.040774990213176654
233.80000000000263,17.09030321068199,0.6318212056780158,-0.04206975906841803
234.90000000000265,17.12342890013675,0.6357688159488573,-0.043538515385858734
236.00000000000267,17.156793799316084,0.637331500158318,-0.04488669018894065
237.10000000000267,17.190215951918137,0.6422245988905146,-0.04639438853456701
238.2000000000027,17.223462173254546,0.6442953691535628,-0.04799403467819596
239.3000000000027,17.256720806111193,0.6491279974970807,-0.04978283793895821
240.4000000000027,17.28975453287532,0.6535228486996393,-0.05095302766674692
241.50000000000273,17.32311183849729,0.6549102111492405,-0.05238082134998612
242.60000000000275,17.35628524604913,0.658854656109547,-0.054025462193433516
243.70000000000277,17.389687314173848,0.6634250864880308,-0.05557218222623783
244.8000000000028,17.422625547824556,0.6649750510199017,-0.058091581121179736
245.9000000000028,17.455874482336622,0.6691060781034206,-0.06124655221125508
247.0000000000028,17.4891832743951,0.6725783823759092,-0.06442270378754822
248.10000000000284,17.522513545571208,0.675057435205147,-0.06631462708236091
249.20000000000283,17.55557267769654,0.677797677933973,-0.06810973937678622
250.30000000000285,17.588802684293235,0.6812887321138452,-0.07129026041837827
251.40000000000288,17.622173935258903,0.6853817721354253,-0.0736035305097551
252.5000000000029,17.655171079810895,0.6871613029403952,-0.07522076518328635
253.60000000000292,17.688679839318628,0.6898064356998063,-0.07817898010203317
254.70000000000292,17.72179607679254,0.6910437857526592,-0.08084563093693697
255.80000000000294,17.755015665017744,0.6959647711457172,-0.08452555496997194
256.90000000000293,17.78811742495696,0.6968111733265947,-0.08650489884976098
258.00000000000296,17.821424791820032,0.6994796654093256,-0.09122042762302662
259.100000000003,17.854415724069433,0.7038064743936281,-0.09394548113632695
260.200000000003,17.88781635992609,0.7076077406739766,-0.09712975642922039
261.300000000003,17.920703536091356,0.7122601044029928,-0.10108891976257439
262.40000000000305,17.95417222472295,0.7148173554009559,-0.10471170227308013
263.50000000000307,17.987032308455433,0.7191265168372442,-0.10841858973632545
264.6000000000031,18.020467188099996,0.7216907111708296,-0.11338074681150934
265.7000000000031,18.053458030537335,0.7252840559818502,-0.11714372775524717
266.8000000000031,18.086726367098336,0.7279914142786318,-0.12234671370695738
267.9000000000031,18.120100084381583,0.7301457233738442,-0.12627783592735797
269.0000000000031,18.15284546730188,0.7325588830625889,-0.130171801809285
270.10000000000315,18.18652746329738,0.7369389868402658,-0.1349720224880664
271.2000000000032,18.219662421476826,0.7380509260574136,-0.1399910329175511
272.30000000000314,18.252680830878045,0.7381009246163589,-0.14465846046652375
273.40000000000316,18.285924065253756,0.7376688974957413,-0.14948455162547747
274.5000000000032,18.319066082213215,0.7386707761413257,-0.15440780068694027
275.6000000000032,18.352170781032562,0.7388132667506564,-0.16009508311073484
276.70000000000323,18.38538518125353,0.7368401897939447,-0.16545281006778856
277.80000000000325,18.41830027405205,0.7367936285599361,-0.1708863042282025
278.9000000000033,18.451970858066044,0.7344910693392044,-0.17586259650257707
280.0000000000033,18.4850000000001,0.7318500000000069,-0.18186016700001817
281.1000000000033,18.518179829479347,0.7303778179802707,-0.18949822104802516
282.20000000000334,18.551265500563396,0.7245300149159328,-0.19572287808960054
283.30000000000337,18.584788247790616,0.7223811198004971,-0.20144985402031557
284.40000000000333,18.617988026363406,0.7157273590084996,-0.20875349698926415
285.50000000000335,18.651328440383853,0.712506695370977,-0.2151543430856795
286.6000000000034,18.684346760918707,0.7075848250864317,-0.2219031855449125
287.7000000000034,18.71765453938672,0.7006620391775152,-0.22958442344765606
288.8000000000034,18.750823779122502,0.6931565326157316,-0.2369164069606975
289.9000000000034,18.784134990712673,0.6865837398263105,-0.2443957769260714
291.0000000000034,18.8174604450396,0.6800299428678384,-0.2540852752945413
292.10000000000343,18.850666169006907,0.6750888188447404,-0.26215002574782487
293.20000000000346,18.88355125961528,0.6684209713883688,-0.2717358788540998
294.3000000000035,18.91707386411568,0.6625263928689596,-0.28116819566883944
295.4000000000035,18.950076687366824,0.6614352331496285,-0.29089252742773963
296.5000000000035,18.983474048152544,0.6611395901361549,-0.30070452734029596
297.60000000000355,19.016510139629496,0.6630689273573386,-0.3122631422930402
298.70000000000357,19.049974766004386,0.6718154804980379,-0.32302971233518996
299.8000000000036,19.083090799781406,0.6836237192443244,-0.3345858254068532
300.9000000000036,19.116773499577945,0.7017036994839051,-0.347654161750623
302.0000000000036,19.14961328143096,0.7230669544516924,-0.36111174669875545
303.1000000000036,19.182980881624978,0.7480514376519466,-0.3750058100596503
304.2000000000036,19.21644736816966,0.7766797258060759,-0.38973825889296787
305.30000000000365,19.250000096203994,0.8072014255656836,-0.40092592861262455
306.4000000000037,19.28356302521292,0.8360809778738175,-0.4154863834763165
307.5000000000037,19.31636875633919,0.8640563760395442,-0.4284120131276121
308.60000000000366,19.350101379312083,0.8913047014516546,-0.4441530566637688
309.7000000000037,19.3834158226724,0.9156317418946887,-0.4567105532060669
310.8000000000037,19.41650568520976,0.9308926725673148,-0.47027146966750566
311.90000000000373,19.4500459599427,0.9458433511917184,-0.4850761033659694
313.00000000000375,19.483320873831484,0.951244246319642,-0.49863206695119633
314.1000000000038,19.516797641529248,0.9523273901041966,-0.5100277988376258
315.2000000000038,19.550414428263604,0.9457019698047103,-0.5226776023505
316.3000000000038,19.583760322601545,0.9344936574235696,-0.533173065807619
317.40000000000384,19.61705991979986,0.9201384334748606,-0.5448640651848469
318.5000000000038,19.650785253139247,0.9013211351994274,-0.55469151493718
319.60000000000383,19.68406347912337,0.8791561964138301,-0.5641583180411645
320.70000000000385,19.717672058469724,0.850356796470355,-0.573147929689831
321.8000000000039,19.75087220896895,0.8240919409987766,-0.583368781055206
322.9000000000039,19.784208404257217,0.7955139378605117,-0.5904433570531262
324.0000000000039,19.81765095442602,0.7631600871847272,-0.5980349834117931
325.10000000000394,19.850745611938304,0.7344663180360984,-0.6048357740658394
326.2000000000039,19.884274654881526,0.7073838101638219,-0.6109854511993844
327.30000000000393,19.917724462363058,0.6760895022157007,-0.6154623926692162
328.40000000000396,19.951077477306487,0.6494720299601304,-0.6214169032546066
329.500000000004,19.984787573248372,0.6216137851638784,-0.6263917774259524
330.600000000004,20.018154327016177,0.5946630264512544,-0.6314121053565316
331.700000000004,20.051669699572347,0.5706701899819723,-0.6370635985233957
332.80000000000405,20.084695204430044,0.5451452131003813,-0.641518928034245
333.90000000000407,20.118451220201056,0.5236484387262006,-0.64606058552401
335.0000000000041,20.151670000000113,0.5018399999999288,-0.6501098029999972
336.10000000000406,20.185571473379426,0.4818464893524708,-0.6538294067311043
337.2000000000041,20.218585267732585,0.4605796171750144,-0.6571595445801268
338.3000000000041,20.252207313890995,0.44139540037328956,-0.6603333914034524
339.4000000000041,20.28549526082942,0.42272643367669854,-0.6640134560591879
340.50000000000415,20.319222348672508,0.40384748264337106,-0.6669825508262117
341.6000000000042,20.35294423479542,0.3881349354587793,-0.6702328016699428
342.7000000000042,20.38636186667187,0.3714136737393742,-0.6739898443935033
343.80000000000416,20.419995539355906,0.3543733809195968,-0.6764044137420893
344.9000000000042,20.45320329246919,0.3394427325988574,-0.6776447304582489
346.0000000000042,20.486667132146657,0.3226741715572725,-0.680444323693961
347.10000000000423,20.520428094661735,0.3090749884500984,-0.6823725839380517
348.20000000000425,20.554137281637814,0.29492645661718536,-0.6852742904254145
349.3000000000043,20.58773207350255,0.28126120007577804,-0.6863761819485736
350.4000000000043,20.621054653622245,0.2677290249022304,-0.6885370934125041
351.5000000000043,20.654776893654656,0.256695906882635,-0.6902871731691484
352.60000000000434,20.68885454782425,0.24411292887770242,-0.6917589461309848
353.7000000000043,20.722256415273993,0.23022963937901803,-0.6935020673316892
354.80000000000433,20.755962562127063,0.22093170732378573,-0.6949384687985072
355.90000000000435,20.7896124178949,0.2121397061331016,-0.6964989808530238
357.0000000000044,20.823130302500537,0.19857536819116328,-0.6989490366487834
358.1000000000044,20.856956514760522,0.1881267858473915,-0.7002626305575936
359.2000000000044,20.890348705122555,0.1789956236973832,-0.7007123409703824
360.30000000000445,20.92426485454528,0.17010495324660257,-0.7023255550124117
361.4000000000044,20.958173869927883,0.16243470674999125,-0.7033094666767812
362.50000000000443,20.991733719052238,0.15294406220621778,-0.7046194872994662
363.60000000000446,21.02544304364751,0.14549771183891078,-0.7053347487642836
364.7000000000045,21.059444404677794,0.13668912693183277,-0.7060047215678749
365.8000000000045,21.092941240784977,0.1301226812840351,-0.7072595436831115
366.9000000000045,21.127006185357494,0.12248180694153625,-0.7081609680005361
368.00000000000455,21.160857174495888,0.11510640102077546,-0.7085681109028061
369.10000000000457,21.194136130627374,0.10950642998585312,-0.7072584165291742
370.2000000000046,21.228287444878404,0.10040680678007062,-0.7086681677877964
371.30000000000456,21.261956324000863,0.09257842324530736,-0.7102308236696837
372.4000000000046,21.29595659576724,0.08248460555480498,-0.7103683749065457
373.5000000000046,21.330054078682494,0.07198660406619742,-0.7115271830967256
374.6000000000046,21.36375941211559,0.0580672677891219,-0.7128685953126408
375.70000000000465,21.397904680216673,0.045174918408084,-0.712849449914911
376.8000000000047,21.43167030747395,0.028344729118153562,-0.7141600033018172
377.9000000000047,21.465519308039436,0.013772329182070149,-0.7145356280699664
379.00000000000466,21.49943602725927,0.004251232647774168,-0.7154799027994843
380.1000000000047,21.533387956704214,-0.006148745215236707,-0.7159753139938161
381.2000000000047,21.56718355856551,-0.009911313983588682,-0.7167905297056967
382.30000000000473,21.60109965644385,-0.01397292840773176,-0.7177853944531605
383.40000000000475,21.63530648581403,-0.014908620969824761,-0.7180923250798648
384.5000000000048,21.669238539388957,-0.01862146574254115,-0.7194260525664111
385.6000000000048,21.70325757580697,-0.018527478939339644,-0.7198748697674446
386.7000000000048,21.737225502353574,-0.01874827306400698,-0.7207431944201161
387.80000000000484,21.77120006322337,-0.019933625135073168,-0.7220830392663986
388.9000000000048,21.80549990837351,-0.022116838572887897,-0.7207630950885968
390.00000000000483,21.83932922363514,-0.021518961556531716,-0.7220709031365091
391.10000000000485,21.87345366014928,-0.021352432531628322,-0.7227009644219793
392.2000000000049,21.907612840123793,-0.023067111318216073,-0.724679961208146
393.3000000000049,21.941415900990467,-0.022764987013767547,-0.7260070232071931
394.4000000000049,21.975584356063468,-0.020820261890691295,-0.7271278765312776
395.50000000000495,22.00988467036431,-0.021688184087041474,-0.727319897145545
396.6000000000049,22.044090494732128,-0.018481826967100982,-0.7266686694834892
397.70000000000493,22.078205575810593,-0.016163458341297097,-0.7273309521777778
398.80000000000496,22.11243160846769,-0.014975153101930847,-0.72732600528883
399.900000000005,22.146573081507263,-0.009709633779063592,-0.728645468002282
401.000000000005,22.180720769780578,-0.006256401076887116,-0.7287245858723614
402.100000000005,22.215001868673603,-0.0007667909021936595,-0.7312704282318507
403.20000000000505,22.249275919437018,0.004853457879939272,-0.7312703104856757
404.30000000000507,22.283392108172976,0.009827876075571052,-0.7321113347129029
405.4000000000051,22.317985864762345,0.01771011543782495,-0.7325968392383766
406.50000000000506,22.352082381103994,0.022514455140679925,-0.7325692531203742
407.6000000000051,22.386356376027035,0.028850089873733883,-0.7339265587207318
408.7000000000051,22.420633407532392,0.03374886872486557,-0.735224313570912
409.8000000000051,22.455045019124853,0.03711873876746636,-0.7353340675549065
410.90000000000515,22.48889591995152,0.04145865578608321,-0.7365409548814759
412.0000000000052,22.523223925765606,0.04693886426482353,-0.7367338660007166
413.1000000000052,22.557598414622433,0.050029910351097356,-0.7378506939189062
414.20000000000516,22.59213918982646,0.0539164038786756,-0.7391881593504404
415.3000000000052,22.626588826492423,0.056640510441312755,-0.7400284194808844
416.4000000000052,22.660742592477135,0.06318380032941535,-0.7410438296427633
417.50000000000523,22.695289161914495,0.0655732357861297,-0.7426503497395669
418.60000000000525,22.729841996999426,0.06728047944185313,-0.7434015762982407
419.7000000000053,22.76426621516798,0.06861458586964884,-0.744759018244955
420.8000000000053,22.79872933147715,0.07165623404782627,-0.7460751250065698
421.9000000000053,22.833050647076345,0.07571880173524778,-0.7460865183709546
423.00000000000534,22.867828603790425,0.08028108075634888,-0.7473876914296498
424.1000000000053,22.90198704866234,0.08056214351346284,-0.7480794779908164
425.20000000000533,22.93631135226198,0.08313733577621758,-0.7488205606731002
426.30000000000535,22.971107695922832,0.0855180728686248,-0.7501096433386332
427.4000000000054,23.005597811129682,0.08962993775330545,-0.7508748328708554
428.5000000000054,23.0401791067687,0.09025816526196212,-0.7519635315260214
429.6000000000054,23.074587451281673,0.09164034085175957,-0.7554165905626498
430.70000000000545,23.109171007349243,0.09424369080271623,-0.7571285516351614
431.8000000000054,23.143702685039443,0.09622314564943889,-0.7586216607546814
432.90000000000543,23.178168165238866,0.09764263287476616,-0.7593382667946811
434.00000000000546,23.2131406857714,0.10013250008472457,-0.7609767584631455
435.1000000000055,23.247465457117297,0.09942330486569471,-0.7631561936283013
436.2000000000055,23.281831954168716,0.10179292874498005,-0.7643052569685547
437.3000000000055,23.31659611793387,0.10321856894720081,-0.7652863408968842
438.40000000000555,23.351191844235633,0.10596177564528855,-0.7661454892789785
439.50000000000557,23.385869358184628,0.10668169585542094,-0.767673540604914
440.6000000000056,23.420263729771925,0.1078162911924092,-0.7691136470799287
441.70000000000556,23.45490975920881,0.11030431836003558,-0.7706651719907529
442.8000000000056,23.489921549646702,0.11156363838413956,-0.7727628845992087
443.9000000000056,23.524355773857252,0.11565807286760574,-0.7769103310032985
445.0000000000056,23.558975146270328,0.11889664464685895,-0.7784266245244891
446.10000000000565,23.59356908110852,0.12119443830447427,-0.7800302850761862
447.2000000000057,23.628477652943644,0.12311363471183488,-0.7822307637191654
448.3000000000057,23.663196255036326,0.1266678458322645,-0.7847185633529699
449.40000000000566,23.697644334365613,0.13073051559588464,-0.7865600214679085
450.5000000000057,23.732620381571365,0.13418643429692176,-0.7892410034602881
451.6000000000057,23.767407906752233,0.1394401564268898,-0.791970836722236
452.70000000000573,23.802031036447655,0.1427933949589836,-0.7954790455312972
453.80000000000575,23.836656408233672,0.14624796218121577,-0.7984958969218869
454.9000000000058,23.87206095690704,0.1558997424296658,-0.8009227048728609
456.0000000000058,23.90641910151605,0.15942687084100166,-0.8025123039325455
457.1000000000058,23.941148775780277,0.16654459274357683,-0.8055559787778361
458.20000000000584,23.976106252784952,0.17583476704716633,-0.8091447305192316
459.3000000000058,24.01081223912737,0.1821578909642243,-0.8127489399029737
460.40000000000583,24.045867363748858,0.1889235570697437,-0.8155873749122171
461.50000000000585,24.080508067977622,0.19769820707306013,-0.8211031175226484
462.6000000000059,24.115515679122808,0.2069865231213729,-0.8253481498476889
463.7000000000059,24.15040704252467,0.21614574107458237,-0.8290003456865609
464.8000000000059,24.184969779362703,0.22880838382780133,-0.8329582558414828
465.90000000000595,24.220169795794867,0.23894994599167724,-0.8365000116610988
467.0000000000059,24.25496638428042,0.24924990004629208,-0.8402406750468892
468.10000000000593,24.289624323194236,0.2630796906456065,-0.8451152668589041
469.20000000000596,24.32426796988628,0.27451879541626495,-0.8486814495512829
470.300000000006,24.359386036043244,0.28673387088462443,-0.8528300295600628
471.400000000006,24.394422706874074,0.2985884578454361,-0.8580490159102991
472.500000000006,24.42944600786775,0.30883340820104865,-0.8620494958385314
473.60000000000605,24.464411227553914,0.32213423310655565,-0.8665921985403906
474.70000000000607,24.4992222016493,0.33388113404142905,-0.8706717910307771
475.8000000000061,24.534365846965393,0.3445647968005606,-0.8752607870950397
476.90000000000606,24.56932626665589,0.3554556520610621,-0.8801803892792108
478.0000000000061,24.604834456113046,0.3663319601279238,-0.8843716665565395
479.1000000000061,24.639978570696115,0.3762883725946467,-0.8888816569866305
480.2000000000061,24.674904031084385,0.38616426301811685,-0.8933888419324032
481.30000000000615,24.71004842088605,0.396736629594726,-0.8980648867583749
482.4000000000062,24.745219107910536,0.40523699118149376,-0.901988364432238
483.5000000000062,24.78005478735922,0.41730233110856346,-0.9057205898436926
484.60000000000616,24.815317121053184,0.4237342759889032,-0.9102844172454558
485.7000000000062,24.850652349538002,0.4352553269699347,-0.9153431550075748
486.8000000000062,24.885721655702646,0.44272816580110236,-0.9186532155257554
487.90000000000623,24.920356190870514,0.45228170334700696,-0.9235304566385212
489.00000000000625,24.955585923322914,0.4624421480483012,-0.9260793779618433
490.1000000000063,24.99096468023326,0.47121316774316735,-0.9295318806716475
491.2000000000063,25.025819632550853,0.4801656764135316,-0.9331407133713268
492.3000000000063,25.061168619338446,0.49020641598820697,-0.9376776852677957
493.40000000000634,25.096219520986075,0.5020384421247872,-0.9422177208056817
494.5000000000063,25.131296445538325,0.5079397250337188,-0.9459643907243844
495.60000000000633,25.166482322608513,0.5197766895969492,-0.9492392518051904
496.70000000000636,25.20175309916303,0.5298165829321034,-0.9515240637689826
497.8000000000064,25.237161566136372,0.5416287955843204,-0.9546009887717988
498.9000000000064,25.272324677378432,0.5526479174094684,-0.9585959372218493
500.0000000000064,25.307472106530987,0.563650068022734,-0.9611884339491192
501.10000000000645,25.34253162419764,0.576677917751895,-0.9643981143122851
502.2000000000064,25.378004751508556,0.5875909399874386,-0.9679715806089066
503.30000000000643,25.41317851143655,0.5981465620579896,-0.9691973305986714
504.40000000000646,25.448396798286375,0.6130878433179193,-0.9719899267676255
505.5000000000065,25.48347111168529,0.6219611857902384,-0.9739216510885056
506.6000000000065,25.51894773550164,0.6356699496908366,-0.9781743528196616
507.7000000000065,25.55415414002863,0.6467997961618082,-0.9798906007763821
508.80000000000655,25.589247975924774,0.6588579690648527,-0.9814227420522004
509.90000000000657,25.62460433364251,0.670022785773204,-0.9836056334290331
511.0000000000066,25.65988700851975,0.6800522017160804,-0.9864231133761026
512.1000000000065,25.69531099416768,0.6895341321942257,-0.9880806772154256
513.2000000000066,25.73064707423328,0.7011767615910133,-0.9892322989283238
514.3000000000065,25.76588179081412,0.7115637335935336,-0.9908398146070496
515.4000000000067,25.801000060477236,0.7211981277024732,-0.9922937578705375
516.5000000000066,25.836417151771908,0.7338846811096967,-0.9940155430931439
517.6000000000067,25.87196461281108,0.7398450273126831,-0.9945640206587947
518.7000000000066,25.90739056688529,0.7493671499034269,-0.9965695045155858
519.8000000000067,25.942398615392836,0.75997174022592,-0.9988816344059268
520.9000000000067,25.978099636621792,0.7705257054774581,-0.9994563140672161
522.0000000000067,26.013327302590714,0.7807273460379923,-1.0007813202471714
523.1000000000067,26.04902108140975,0.7903034774783279,-1.0011378246262579
524.2000000000068,26.08421014183886,0.7987007424007324,-1.0010958057498716
525.3000000000068,26.11967912538717,0.8089487125106459,-1.0025681584035802
526.4000000000068,26.155273946609665,0.8183389916038133,-1.0040875608320645
527.5000000000068,26.190631449094006,0.8303002029366003,-1.005235783859633
528.6000000000068,26.225382637311526,0.8377689187239418,-1.006611467562176
529.7000000000069,26.261573491057785,0.8506829203025841,-1.007909406327891
530.8000000000068,26.29701060614304,0.8598164823907031,-1.0087689393319166
531.9000000000069,26.332372373540036,0.8736330932643702,-1.00925947282472
533.0000000000068,26.367892819284464,0.8852505780341628,-1.0107522676439622
534.100000000007,26.40340017176777,0.8960059427268466,-1.012788823568977
535.2000000000069,26.438685918631478,0.9099894979766547,-1.0140948455450376
536.300000000007,26.474251762380366,0.9249798600243109,-1.0147141419096268
537.4000000000069,26.50977397443169,0.940707219950036,-1.0160305349871548
538.5000000000069,26.545290289908635,0.9554532914645983,-1.0160335603983501
539.600000000007,26.58082556224826,0.969173139252714,-1.0175087692434017
540.700000000007,26.616460026675295,0.9843820821820928,-1.0191663417230883
541.800000000007,26.652399165815762,0.9957123723748179,-1.0212861347470463
542.900000000007,26.687645100096866,1.0132408449883203,-1.0232691284621223
544.000000000007,26.723132809042895,1.0245693925502835,-1.024757021022194
545.1000000000071,26.758766118248865,1.0393855142249504,-1.026243917943317
546.2000000000071,26.794250707338946,1.0527785111207904,-1.0277978975082185
547.300000000007,26.829862977147958,1.0640981160701755,-1.029289851418198
548.4000000000071,26.86581845003692,1.0773302597717063,-1.030642508658084
549.500000000007,26.901124015108287,1.0897595395648434,-1.0316006963966982
550.6000000000072,26.936880685060565,1.1009714607031544,-1.0332835520960764
551.7000000000071,26.97230299054185,1.107763891493022,-1.035414293142893
552.8000000000072,27.008414810511642,1.1169905970160932,-1.0375843367174031
553.9000000000071,27.04366975092322,1.1284924592127543,-1.039116898315184
555.0000000000072,27.079196792998008,1.1351254011719798,-1.0394022855547647
556.1000000000072,27.11523876456195,1.1441097863204017,-1.0410141779416628
557.2000000000072,27.15094165245609,1.153604872808072,-1.0429470073743596
558.3000000000072,27.186757029111167,1.161294171982365,-1.0450117224820135
559.4000000000073,27.222276405026747,1.1714514276799284,-1.0479474659979235
560.5000000000073,27.258009700905685,1.1839394108682173,-1.0496895310544643
561.6000000000073,27.293769958502356,1.1928765312659126,-1.051479944980715
562.7000000000073,27.32938155679719,1.2030446221214084,-1.0539710313050974
563.8000000000073,27.36533234306642,1.2168383857730831,-1.0553388812489097
564.9000000000074,27.400942219716935,1.2313498938467342,-1.0562435881348358
566.0000000000074,27.436534711049998,1.2476528272116054,-1.057473629304397
567.1000000000074,27.47242242198971,1.2636633791870624,-1.059057070523561
568.2000000000073,27.508459050305515,1.285605307733293,-1.0617291704395386
569.3000000000073,27.54419157426692,1.3069201556524723,-1.0636464796127987
570.4000000000074,27.580076260453833,1.3307511137388044,-1.0650893071501688
571.5000000000074,27.615728154418584,1.3528941728765997,-1.0667422819046664
572.6000000000074,27.65167066223115,1.379910280969925,-1.0692201618445512
573.7000000000074,27.687807527601223,1.4035301030338672,-1.0717165014620909
574.8000000000075,27.723168252518388,1.430878629951739,-1.0734340635624884
575.9000000000075,27.75918889121212,1.4596534654252131,-1.0754869013664416
577.0000000000075,27.795281206222683,1.4876466838734923,-1.0777321995979325
578.1000000000075,27.831069796906842,1.5169388354839148,-1.0791974723222806
579.2000000000075,27.867065128627672,1.548011501082385,-1.081092242578587
580.3000000000076,27.903158294961198,1.5800194835417307,-1.0832512962305696
581.4000000000076,27.9389681777107,1.6120874131817393,-1.08578233500696
582.5000000000076,27.97467564024118,1.6495130191989587,-1.0869150042050335
583.6000000000076,28.010671146229942,1.68758969635991,-1.0888265676976068
584.7000000000077,28.046773703042202,1.7313292158732376,-1.0912762790896529
585.8000000000077,28.083006065252327,1.7774140169000727,-1.0949089921745778
586.9000000000076,28.11875176954633,1.8276195830234847,-1.0978505276229642
588.0000000000076,28.15488047026742,1.8818732856695244,-1.1009835008194009
589.1000000000076,28.19099136931176,1.9379534858658412,-1.1030085649540888
590.2000000000077,28.226848249931297,1.9976201770101603,-1.1052862571480784
591.3000000000077,28.262952972160416,2.0587837399641593,-1.1079786327077379
592.4000000000077,28.299170132049795,2.121920419561553,-1.110266616196943
593.5000000000077,28.335239060775997,2.1816178032518088,-1.1128358434131953
594.6000000000078,28.371441664418736,2.235680978569992,-1.1160257022156785
595.7000000000078,28.407594739416208,2.2853967337661043,-1.1190298477041907
596.8000000000078,28.443531334803016,2.321521849709678,-1.121963218595181
597.9000000000078,28.47968134130342,2.3350161760422528,-1.1255256913546399
599.0000000000078,28.515990888842207,2.30139116335445,-1.1298405997318905
600.1000000000079,28.551924709841114,2.218653845268706,-1.1337582335066156
601.2000000000079,28.588187715962587,2.0984331195541714,-1.1371043187296226
602.3000000000079,28.624063236381765,1.9670575034626716,-1.140320237817507
603.4000000000078,28.659957937218625,1.8431384900476437,-1.1440572654297512
604.5000000000078,28.69599629502125,1.734317698007791,-1.1478595485300693
605.6000000000079,28.73194583143431,1.6419459777266656,-1.1507322477423698
606.7000000000079,28.76800969763303,1.5593521620401352,-1.1543750168042974
607.8000000000079,28.804116294927763,1.4876463053506077,-1.1571393902740872
608.9000000000079,28.84018618413975,1.4236876475965021,-1.1591498440091206
610.000000000008,28.87615698451439,1.3710946953702816,-1.1625995284293111
611.100000000008,28.91218153808952,1.3312558061317383,-1.1644865396327941
612.200000000008,28.948061558418495,1.3089170531242988,-1.1672661502611166
613.300000000008,28.984209783871986,1.3031393236043103,-1.1703600380972619
614.400000000008,29.020127517358272,1.308329381948631,-1.171880333642204
615.5000000000081,29.05646562589748,1.3088057162679885,-1.173531372521924
616.6000000000081,29.091163717750476,1.3037851006420604,-1.1748482983430253
617.7000000000081,29.12875105551267,1.2983402506296715,-1.1746909443624594
618.8000000000081,29.164966126877076,1.2896306254280316,-1.1748503814635072
619.9000000000082,29.20089734214818,1.285270603556141,-1.1762705299361809
621.0000000000082,29.237045146605567,1.2788635292467139,-1.1755046055943348
622.1000000000081,29.27318976261783,1.2768968309152293,-1.1765997054824218
623.2000000000081,29.309285436169517,1.273999971362642,-1.1766010538422398
624.3000000000081,29.34540068186053,1.273644555747489,-1.1779112352725156
625.4000000000082,29.38160697649387,1.2770221427225308,-1.179003213106335
626.5000000000082,29.417520109514044,1.28279981090987,-1.1802205293649672
627.6000000000082,29.453674866304993,1.2955141920335396,-1.180361191806412
628.7000000000082,29.489782887986113,1.302812851381211,-1.181539338501592
629.8000000000083,29.526037846786977,1.3121597026760417,-1.1815399669342206
630.9000000000083,29.56206801694155,1.3236417837474834,-1.1822385817338223
632.0000000000083,29.598330000000264,1.3352900000001047,-1.1828499320000119
633.1000000000083,29.634287220836995,1.349646469040772,-1.1841731712453503
634.2000000000083,29.670546193975966,1.3660210063152676,-1.185496165270648
635.3000000000084,29.706749130475146,1.381457299634517,-1.1859858288096046
636.4000000000084,29.742996767103975,1.40078271613212,-1.1864579523114172
637.5000000000084,29.779068258510335,1.4192044413739162,-1.187464902740111
638.6000000000083,29.81528833507746,1.4431392644021823,-1.1888220966134204
639.7000000000083,29.85119088274495,1.4655511474668619,-1.1890603713991101
640.8000000000084,29.887562749524243,1.4912192189170308,-1.1900872945928325
641.9000000000084,29.923973609850787,1.518426700642208,-1.1915387513699405
643.0000000000084,29.960082115517217,1.5446011957967314,-1.1930759564963411
644.1000000000084,29.996542893635915,1.5761902906431708,-1.1943242677109285
645.2000000000085,30.032408938194596,1.604702839259038,-1.1951212733520231
646.3000000000085,30.068792629006193,1.6413420183307303,-1.195980419003209
647.4000000000085,30.104999372663357,1.673379388571667,-1.1988698840740537
648.5000000000085,30.14138264685603,1.7099911587090364,-1.2006894457250956
649.6000000000085,30.177757557101152,1.7504950894979705,-1.2025552457661806
650.7000000000086,30.21395778759852,1.7907156710834882,-1.2042685363584584
651.8000000000086,30.25026831393692,1.8316554050507476,-1.2067070346623652
652.9000000000086,30.286417803533276,1.8740649234738536,-1.2081719383983343
654.0000000000086,30.322940638416032,1.9169308020445373,-1.2098996529839212
655.1000000000087,30.359280218584352,1.9599876399500435,-1.2123598598130032
656.2000000000087,30.395402516505495,2.001613211046127,-1.2138308251862813
657.3000000000086,30.43186203524431,2.0435058668791792,-1.216120326490545
658.4000000000086,30.468461791524703,2.0869912894381972,-1.2185540744982957
659.5000000000086,30.50503254119291,2.129096003703843,-1.2208056353270527
660.6000000000087,30.54110440767074,2.1699884550815978,-1.2237520532283064
661.7000000000087,30.577468031298707,2.210945447948954,-1.2268117196241906
662.8000000000087,30.613676331458446,2.2568206864249047,-1.230029694153484
663.9000000000087,30.65004750185662,2.299818145901959,-1.2328446646544475
665.0000000000088,30.68654420562673,2.3405313618307457,-1.2361363266226904
666.1000000000088,30.72293499383539,2.3845242397651547,-1.2386029108245387
667.2000000000088,30.75932044952168,2.4368957623201806,-1.24237118974197
668.3000000000088,30.79543599737191,2.4886220149675644,-1.24402221205185
669.4000000000088,30.83193242446893,2.5407328766876196,-1.2481248405446124
670.5000000000089,30.868160655082896,2.5985419746662273,-1.2514706749217717
671.6000000000089,30.90461003793479,2.663274175325832,-1.254760128392289
672.7000000000089,30.94114915185321,2.731935681790013,-1.2580434315353548
673.8000000000088,30.977324275783957,2.8058957114293896,-1.2614002965122015
674.9000000000088,31.01392979244368,2.8889136487268168,-1.2658862310693046
676.0000000000089,31.05035202306832,2.97721018317578,-1.270418468792867
677.1000000000089,31.086985617603563,3.074032969313788,-1.2742806566832678
678.2000000000089,31.123414136914207,3.1824137820291143,-1.277118487719271
679.3000000000089,31.159862138821108,3.2991757900115855,-1.2819041414856764
680.400000000009,31.196440376039963,3.424710846704048,-1.2876719703378114
681.500000000009,31.23305475345949,3.560195310006409,-1.2936779782815906
682.600000000009,31.269305651977295,3.7067398735151955,-1.297648084571692
683.700000000009,31.306076858432387,3.865407066406878,-1.3025448505822887
684.800000000009,31.34252295500224,4.025621043857386,-1.3079021449904094
685.9000000000091,31.379133030960613,4.146973136552048,-1.3144281517190177
687.0000000000091,31.416050501306515,4.154203921557788,-1.320382797786464
688.1000000000091,31.45243310833856,4.05218575920558,-1.325067673563256
689.2000000000091,31.489018375139523,3.9618460897706202,-1.3302734155677371
690.3000000000092,31.5251623726562,3.921890204936157,-1.336134835964908
691.4000000000092,31.56156799872019,3.920859244003626,-1.3432789931369191
692.5000000000091,31.598233296611358,3.9472861956993883,-1.3497775819805473
693.6000000000091,31.63457304934059,3.9919495460169085,-1.3562381862056392
694.7000000000091,31.67120122998672,4.049342697596789,-1.3637809372461924
695.8000000000092,31.707661398043868,4.11925760686485,-1.3714358418330992
696.9000000000092,31.74418054460593,4.1918735114355865,-1.3789361215027247
698.0000000000092,31.78071537030052,4.271272274276414,-1.384486513157447
699.1000000000092,31.81712673712571,4.356723005583057,-1.3918483451719696
700.2000000000093,31.853703894230758,4.444335059396568,-1.3988764797854962
701.3000000000093,31.89049648106638,4.539362362167726,-1.4071355710582685
702.4000000000093,31.927015660713135,4.631649064487789,-1.417416356452136
703.5000000000093,31.963802153881044,4.7306876852020645,-1.4265996269262686
704.6000000000093,32.00042052431952,4.827291115391218,-1.4351084668182446
705.7000000000094,32.03713696617061,4.929350137684117,-1.4438384208356894
706.8000000000094,32.07369756291225,5.033039274543782,-1.4529837206440783
707.9000000000094,32.11017735917513,5.136184909058599,-1.4620768141918354
709.0000000000093,32.1469347937532,5.244932253392362,-1.471562568410588
710.1000000000093,32.18361720584925,5.354066173942458,-1.4812659687558876
711.2000000000094,32.220322012870824,5.466053738376922,-1.4915790186715396
712.3000000000094,32.257280157156885,5.579074709401153,-1.5024553460907728
713.4000000000094,32.29395039540969,5.6917243261962716,-1.5128180659760306
714.5000000000094,32.330739227968785,5.811129329068361,-1.5226435359453379
715.6000000000095,32.367501323722124,5.927723135616015,-1.5349440993425407
716.7000000000095,32.40425459751484,6.048400308720938,-1.5469670825695032
717.8000000000095,32.44076109142202,6.165227118645481,-1.5581356369592885
718.9000000000095,32.477802111039324,6.292024558001871,-1.5700062581908973
720.0000000000095,32.51462469520164,6.4140455616250325,-1.5825598361252364
721.1000000000096,32.551259926156106,6.535834710245684,-1.5947923153010848
722.2000000000096,32.58832865395717,6.664984060488326,-1.6061686618619908
723.3000000000096,32.62439740659367,6.787318438530376,-1.6196298569161005
724.4000000000096,32.66128519993189,6.914735994037595,-1.6342735578051042
725.5000000000097,32.69836419519522,7.04804133306575,-1.6483735017614927
726.6000000000097,32.73474227100571,7.175115094045096,-1.6617293891291727
727.7000000000096,32.7719331126374,7.3045487491998085,-1.6757927541225808
728.8000000000096,32.80910948098315,7.427337495427862,-1.6914549262915957
729.9000000000096,32.84576556816138,7.553130622403763,-1.7069879487125186
731.0000000000097,32.88273814187827,7.677896318818705,-1.722376221962259
732.1000000000097,32.91960066471021,7.7996400621009485,-1.7362303912647539
733.2000000000097,32.9567745512864,7.920217255719415,-1.7524220172784988
734.3000000000097,32.993541358108736,8.033480423704443,-1.7697744999446088
735.4000000000098,33.030497873487256,8.144061746995229,-1.7860905859239038
736.5000000000098,33.067397249326554,8.248323861486252,-1.8025765260244895
737.6000000000098,33.104021917523006,8.342630191462936,-1.8190684487431765
738.7000000000098,33.14106533106389,8.424354605171025,-1.837036179243532
739.8000000000098,33.17810000307376,8.493282067212899,-1.8551202953442525
740.9000000000099,33.21510472155678,8.539952981029385,-1.8715923659489482
742.0000000000099,33.25177025723783,8.560676548861748,-1.8890557360216387
743.1000000000099,33.288823344173274,8.552792491599396,-1.9067601536211067
744.0000000000099,33.31884015532731,8.518623861928402,-1.9199773303112524