File: 01_Data/Vinyl_Tile/STA/N2/30K_min/Vinyl_Tile_STA_N2_30KData_220506_R2.csv
##Temp./Â°C,Time/min,DSC/(mW/mg),Mass loss/mg
49.0,10.374422733789466,-1.2724118075725945,0.019103812193115743
50.100000000000016,10.659826528525599,-1.1082201807104386,0.021021709270215183
51.20000000000003,10.799036189588694,-0.9923287167307296,0.021826002014887713
52.30000000000005,10.903001672860809,-0.8995902287296569,0.02179012557957183
53.40000000000006,10.989369012223271,-0.8189932105159412,0.021856866908041006
54.50000000000008,11.06602921861144,-0.7478830750772655,0.023150450385617027
55.600000000000094,11.13584236801178,-0.6829300879892273,0.023059961506316284
56.70000000000011,11.199202238766198,-0.6260101203527083,0.023444316844359214
57.800000000000125,11.259622447292594,-0.569728021730839,0.022524753540233533
58.90000000000014,11.316812924644626,-0.5201373092770954,0.022363614737467508
60.000000000000156,11.370329535037383,-0.47289371975093736,0.022974616028560213
61.10000000000017,11.423078497681482,-0.4294161621905902,0.0243639592417475
62.20000000000019,11.473020371303061,-0.3881501229905234,0.02365732435246848
63.3000000000002,11.522080518042975,-0.34873230329634014,0.022557527596352323
64.40000000000022,11.569873778936051,-0.313028718908917,0.023225607523122527
65.50000000000023,11.61641052722978,-0.2781538595971207,0.02370572271138016
66.60000000000025,11.662556782917997,-0.24642314498881943,0.023464557594470747
67.70000000000027,11.706973303877692,-0.21598067180013086,0.02451545254632137
68.80000000000028,11.751074479745986,-0.18726144104664635,0.024582499221490473
69.90000000000029,11.794456559015067,-0.1600089177695568,0.024503646688694758
71.00000000000031,11.837328452658195,-0.1335847371746559,0.02298925518417505
72.10000000000034,11.880038867924187,-0.10920381113851922,0.024046700445890856
73.20000000000034,11.921786563883668,-0.08620540858258362,0.024307414527197757
74.30000000000035,11.963335904568606,-0.06346325635951179,0.024517548701136427
75.40000000000038,12.004345491567312,-0.041196193642416945,0.023897066808170386
76.5000000000004,12.045679579784125,-0.019977754896794514,0.024226378817645333
77.6000000000004,12.085864797452587,-0.0010064710500429222,0.024768813738961448
78.70000000000041,12.126776024288409,0.020118814803626893,0.023606912180307305
79.80000000000044,12.166088034282332,0.037653099523642625,0.023361773893924465
80.90000000000046,12.20606247961771,0.05664254810267976,0.024663688656027638
82.00000000000047,12.2458066419332,0.07428608468688061,0.024229375502152095
83.10000000000048,12.284894536406888,0.09271899597427882,0.02324317202048043
84.2000000000005,12.323837373171852,0.10907593032270875,0.0243334753873512
85.30000000000052,12.36314440386824,0.12525836479308866,0.024910761562522588
86.40000000000053,12.401670542395324,0.1423642069945297,0.02414832969930103
87.50000000000054,12.439685458575651,0.1577435511279441,0.023339898332548792
88.60000000000056,12.478143406624582,0.17328191140788876,0.024057995808582255
89.70000000000059,12.51660315599132,0.19000400007341228,0.02444116564328791
90.8000000000006,12.55443027756175,0.20357274178772475,0.023112765479230468
91.9000000000006,12.592315525504395,0.21853631646044552,0.024503812820602988
93.00000000000063,12.62966698807552,0.2317961107530788,0.023087731997682326
94.10000000000065,12.667756740975019,0.24530182656885405,0.023423529750108862
95.20000000000066,12.705318497896023,0.2598515788578884,0.02456705258210512
96.30000000000067,12.743063908185773,0.2740026129759788,0.024570325121531233
97.40000000000069,12.780225870550263,0.2857497205547531,0.02396053154489053
98.50000000000071,12.818078632757084,0.2984152328708351,0.02337206316074969
99.60000000000072,12.855019922796206,0.3113029957001945,0.02375021367165786
100.70000000000073,12.892316162892316,0.32271579022850405,0.02325057849811074
101.80000000000075,12.929309483224918,0.3356369691341658,0.022135398834535636
102.90000000000077,12.966141591977298,0.3499901446771374,0.02324215948472652
104.00000000000078,13.003390693667736,0.3614308254002872,0.024565954746611496
105.10000000000079,13.040273333119694,0.3728256777947777,0.023266921223671133
106.20000000000081,13.077175958960206,0.38507072159301386,0.023259888373083015
107.30000000000084,13.114087262358362,0.396784601392204,0.023262869608283943
108.40000000000084,13.150905521088655,0.4082919634026249,0.024560298102950462
109.50000000000085,13.187905025794478,0.4214184110342276,0.02538401885825259
110.60000000000088,13.224742350967828,0.43253700912378956,0.024583197532278334
111.7000000000009,13.261355226023676,0.44461562558573337,0.024623700647881108
112.8000000000009,13.298343643705898,0.45746551886196835,0.024560173507781613
113.90000000000092,13.335244408116296,0.46939478666239204,0.02456020881662191
115.00000000000094,13.371860705400659,0.48056859848550043,0.02357540165577987
116.10000000000096,13.408574441894991,0.49183624773671497,0.023250051440806274
117.20000000000097,13.44481944988479,0.5038639581148636,0.02324853717888775
118.30000000000098,13.481298094646426,0.5167617559024321,0.0245859459281057
119.400000000001,13.51757592240022,0.5258492649639467,0.024560130942526293
120.50000000000102,13.554300368941188,0.5380472223987998,0.02325556485355129
121.60000000000103,13.590279448656325,0.5471729256749859,0.023251156818410834
122.70000000000104,13.62693095916022,0.557366227337459,0.02457631149344497
123.80000000000106,13.662949268858334,0.5695428588666187,0.02326201074179224
124.90000000000109,13.699353306382246,0.5786495806641245,0.023259882207075755
126.0000000000011,13.735265208421314,0.5882809271895895,0.0232598870010845
127.1000000000011,13.771536216497083,0.5993489342253621,0.023259886106790972
128.20000000000113,13.807631222785911,0.6099988886754407,0.023259201904995308
129.30000000000115,13.8435733030945,0.6206909597944427,0.023568769591951977
130.40000000000117,13.879440208574563,0.6293518247716845,0.02446179201370846
131.50000000000117,13.914947194613998,0.6413452373514423,0.02323970709564005
132.6000000000012,13.950733479706983,0.6515930115726565,0.024243294778173663
133.7000000000012,13.986239126058976,0.6630456024632251,0.024240022389340865
134.8000000000012,14.022443164538613,0.6735605728760032,0.024240023025758006
135.90000000000123,14.057984366846101,0.6825728123443344,0.024240156362445475
137.00000000000125,14.093652709590726,0.693967363588505,0.023931389646077328
138.10000000000127,14.128968127672785,0.703556511966742,0.022920172466729838
139.2000000000013,14.16418865029271,0.7138165303982055,0.02292002233717838
140.3000000000013,14.199832341542075,0.7236825416252842,0.02292012169490576
141.4000000000013,14.234947255205725,0.7337905862422512,0.023240277459097847
142.50000000000134,14.269887049008409,0.7431661875095452,0.023251088305041634
143.60000000000133,14.305167984972798,0.7552199350338885,0.02447876446711028
144.70000000000135,14.340343666495897,0.7643636673845191,0.024570117810917225
145.80000000000138,14.375793064227036,0.7739310654158633,0.02457013809767883
146.9000000000014,14.41033622737536,0.7839754168654175,0.02457013799975183
148.00000000000142,14.445500607684748,0.7932417359427818,0.024570139038615046
149.10000000000142,14.480269257565743,0.8033132018925008,0.024568914361021044
150.20000000000144,14.51543168468496,0.8127566921075391,0.024740232308396948
151.30000000000146,14.55027446074585,0.8232752725481011,0.024899874917032605
152.40000000000146,14.585195901669486,0.8327674392596348,0.0249148402967716
153.50000000000148,14.619906841612178,0.8415611310116682,0.023590261531215795
154.6000000000015,14.654517471299023,0.8501287511804142,0.023590489677104642
155.70000000000152,14.689637410581923,0.8616087109800394,0.024596944665687737
156.80000000000155,14.724279283470437,0.87051599328475,0.024576669811203544
157.90000000000154,14.759129612856873,0.8789950449893573,0.024011443006842548
159.00000000000156,14.79329577042077,0.8897377372351727,0.022593584279088752
160.1000000000016,14.828248856559705,0.8984498223853018,0.022260043032980903
161.20000000000158,14.862616569168019,0.9073893821106901,0.022260130030515413
162.3000000000016,14.897062106130791,0.9167875582405179,0.022266080640195973
163.40000000000163,14.932017724144304,0.9270432248803001,0.02353547317948479
164.50000000000165,14.966484193424527,0.93576994626272,0.02225831362424735
165.60000000000167,15.000791312037347,0.945988510756691,0.022956409967790137
166.70000000000167,15.035238973613476,0.9546113345461136,0.022919777754485615
167.8000000000017,15.06951261000019,0.9638117498323231,0.022919873126711288
168.9000000000017,15.104218937292659,0.9740259334104087,0.022919872979081823
170.0000000000017,15.138652877378497,0.9816080668718923,0.02291990992434023
171.10000000000173,15.173236240669095,0.9902130540150744,0.022882603531128254
172.20000000000175,15.207198742660735,1.0007535434309789,0.02424371505651912
173.30000000000177,15.241594091564686,1.0094813795227544,0.02423986918966481
174.4000000000018,15.275931400216432,1.0194648394787922,0.024239872991637768
175.5000000000018,15.309990681647731,1.0262793666903025,0.024239881103629735
176.6000000000018,15.34388969057412,1.034804566638702,0.024232496976721585
177.70000000000184,15.37832608914275,1.0447322395142544,0.02358387855484345
178.80000000000183,15.412575371551013,1.054730931868373,0.023611940875583493
179.90000000000185,15.446607453672476,1.0618205798284048,0.022255964898767466
181.00000000000188,15.480625991874637,1.071840680972879,0.02225982535925297
182.1000000000019,15.51437241086541,1.0783412512911548,0.022268365210176277
183.20000000000192,15.548517393607776,1.0870194142372334,0.021598343386737717
184.30000000000192,15.58238476604081,1.0960894262420835,0.02160018467871261
185.40000000000194,15.616224809396172,1.1056354181147199,0.02160018199637026
186.50000000000196,15.650180111819157,1.1155380335121137,0.02160018200000291
187.60000000000196,15.683854310828885,1.122018501392377,0.02160018200267455
188.70000000000198,15.717807150609888,1.1282134674235993,0.021600180151568615
189.800000000002,15.751640164413033,1.1378233542361145,0.02160135964762855
190.90000000000202,15.785285700787835,1.1448458857148376,0.020321756566088034
192.00000000000205,15.81886071335027,1.153216017337912,0.020290085190320717
193.10000000000204,15.852527783174633,1.1601553934174644,0.020290115028621436
194.20000000000206,15.886175705413315,1.1680046498790497,0.020290115211343718
195.3000000000021,15.919637777125295,1.1760292067854803,0.020290003828533187
196.40000000000208,15.95345543137579,1.1826223379705745,0.02094769179168754
197.5000000000021,15.986882982570268,1.190879918310622,0.020940118125427176
198.60000000000213,16.020566938998996,1.1991596964459639,0.020940084107527568
199.70000000000215,16.053939988664528,1.2050754002824684,0.0205664734520985
200.80000000000217,16.087664287286156,1.2130137703034665,0.019631426589425516
201.90000000000217,16.121174170050992,1.220781217605064,0.018268677072423856
203.0000000000022,16.15478241618137,1.229289830054839,0.018310041614489236
204.1000000000022,16.188360070054383,1.236080603112176,0.01830997689450964
205.2000000000022,16.22189610304924,1.2434307759327674,0.018309991273443238
206.30000000000223,16.2550974036071,1.250178547515199,0.018300122251722506
207.40000000000225,16.288882422278174,1.2583137125816326,0.01764449976623972
208.50000000000227,16.322041431959843,1.264496079761328,0.017196090311727197
209.6000000000023,16.35565720379398,1.2714253513697402,0.016998617741464273
210.7000000000023,16.388790802431572,1.2792795237651935,0.016044140935616902
211.8000000000023,16.422194184192687,1.2847455820249274,0.016016136624632082
212.90000000000234,16.455903509583653,1.2928942378898687,0.014680108740200204
214.00000000000233,16.489415433003302,1.2991286152919745,0.014699840318265878
215.10000000000235,16.522781206657413,1.3068508816148414,0.01470300428044169
216.20000000000238,16.555452860493705,1.313313178690654,0.013334115105800848
217.3000000000024,16.589243478218094,1.3202854317746127,0.013376562498311984
218.40000000000242,16.62285211052217,1.327012737569587,0.012050674737325906
219.50000000000242,16.656131736359338,1.33474486231972,0.012070158920727714
220.60000000000244,16.689503759538272,1.3398383805285592,0.011994224838362655
221.70000000000246,16.72288985311322,1.346702643750804,0.011727366742666945
222.80000000000246,16.756133968408687,1.352900215299175,0.011126294625159794
223.90000000000248,16.789572974112392,1.3586756320369777,0.01042844968247536
225.0000000000025,16.82281915583023,1.366605363549076,0.00910504543427848
226.10000000000252,16.855985986572115,1.3700626795194828,0.009099819299771994
227.20000000000255,16.889218183941665,1.3773838733681396,0.009087906704078996
228.30000000000254,16.92262904514654,1.3814230719301483,0.007788838686871635
229.40000000000256,16.956050525707813,1.3883818837831452,0.00632447301087069
230.5000000000026,16.989333371491412,1.3952254536099062,0.005180640159005989
231.60000000000258,17.022483284060357,1.4025298200962035,0.004860567759748413
232.7000000000026,17.055963287695665,1.4066198564233554,0.0034182392145094553
233.80000000000263,17.089599391977924,1.4146219264775353,0.0009963202074843025
234.90000000000265,17.122445252444017,1.4197334523797316,-0.00017602433412822194
236.00000000000267,17.155448042182428,1.4262988530759995,-0.0008861309594569988
237.10000000000267,17.189190526447206,1.4300361605338678,-0.0017211352367745292
238.2000000000027,17.222284600082418,1.4386429447017632,-0.002398256510344865
239.3000000000027,17.255373752862777,1.4428534496828798,-0.0037217199436083703
240.4000000000027,17.28856714601769,1.4508281670646637,-0.005209045795855793
241.50000000000273,17.321866650932932,1.4570855895240378,-0.00661193356049683
242.60000000000275,17.35512001002464,1.4630634591721725,-0.0077031229020132486
243.70000000000277,17.38807938445234,1.4698419120454107,-0.009242538565345626
244.8000000000028,17.42148768921898,1.4752788244494837,-0.011144406609688406
245.9000000000028,17.454487144581144,1.484155920057903,-0.01254408889940617
247.0000000000028,17.48801373448258,1.4899275540529426,-0.013956703478462895
248.10000000000284,17.520955231235874,1.4956671250659324,-0.015398172067869087
249.20000000000283,17.554312108281568,1.5022307814844724,-0.016245468550659226
250.30000000000285,17.587773815473295,1.5073586771105754,-0.01832055383111708
251.40000000000288,17.620750129129082,1.512369343886911,-0.020607632231065764
252.5000000000029,17.6541638217657,1.520949574892023,-0.023289434960879873
253.60000000000292,17.686700135631003,1.52545430312228,-0.026334122911660263
254.70000000000292,17.720241964073534,1.5314510605739633,-0.02865040179956857
255.80000000000294,17.75333000000009,1.5380400000000216,-0.030069503739857062
256.90000000000293,17.786639552731877,1.5434692244289765,-0.03158961845934405
258.00000000000296,17.820000000000093,1.5483100000000063,-0.03422986801847472
259.100000000003,17.852915324149365,1.5554245374606084,-0.03718504346645535
260.200000000003,17.886211187597162,1.563798458564178,-0.040762795972551835
261.300000000003,17.919253795058367,1.5709552128021238,-0.04341122469047409
262.40000000000305,17.95223959866044,1.5791545096322002,-0.04658849800222509
263.50000000000307,17.98581633261717,1.5853197751880923,-0.049199460729855815
264.6000000000031,18.019025901302275,1.592584005620188,-0.052782039051936014
265.7000000000031,18.05223907893381,1.6010275008213317,-0.05588671404540868
266.8000000000031,18.084952617778594,1.6074131835174854,-0.06011099491697047
267.9000000000031,18.11819324054674,1.6143135030770335,-0.064430409594042
269.0000000000031,18.15174136390347,1.621308801277639,-0.06969889087627834
270.10000000000315,18.184824924652997,1.6253749203680887,-0.07345285283633851
271.2000000000032,18.21784020261261,1.6310328053242407,-0.07690136766588296
272.30000000000314,18.25107777906653,1.636867315550183,-0.08072968597444596
273.40000000000316,18.284047668331677,1.6416994549230581,-0.08542567911505072
274.5000000000032,18.317326128492304,1.6466752359176324,-0.08960019028073818
275.6000000000032,18.35065155582883,1.6502529076511014,-0.09406355925583076
276.70000000000323,18.383888254606653,1.6550349746065645,-0.0986590351463601
277.80000000000325,18.417193755262296,1.6576469468093002,-0.10450011421136995
278.9000000000033,18.450329397310952,1.6594891790974986,-0.10978313562433417
280.0000000000033,18.483528201505692,1.6615854327904203,-0.11530773708753461
281.1000000000033,18.51641942446356,1.6643872967952384,-0.12126094901739659
282.20000000000334,18.54981913036456,1.6662436528759856,-0.12653679664785944
283.30000000000337,18.582833477576735,1.6664950371644824,-0.13274876199922847
284.40000000000333,18.616160913493747,1.6671188474208996,-0.13994167024108695
285.50000000000335,18.649364628751687,1.6653103420871116,-0.14562242356752897
286.6000000000034,18.682684078825694,1.6651902998695844,-0.15188778408452652
287.7000000000034,18.715696333953616,1.662460304472531,-0.1589961220405227
288.8000000000034,18.748928488058596,1.6612963757875283,-0.1668038308920856
289.9000000000034,18.782373298531986,1.6575237789190598,-0.17559811908229506
291.0000000000034,18.81548531359761,1.6547301382006454,-0.1826849392448402
292.10000000000343,18.848691747419448,1.6542504277055048,-0.19215053278299532
293.20000000000346,18.881755806282957,1.6503838489405176,-0.20124387135742605
294.3000000000035,18.91532148255185,1.6501448645879548,-0.21057697308894419
295.4000000000035,18.948279450822923,1.648236690391343,-0.22084654300626738
296.5000000000035,18.981681596681895,1.6473076282676435,-0.23096295294250613
297.60000000000355,19.015025627817785,1.6499443567785255,-0.24142096510773792
298.70000000000357,19.04780976780958,1.6592570018854342,-0.25351224617706825
299.8000000000036,19.081074379211437,1.6702404254131926,-0.26516171922836484
300.9000000000036,19.1144920920804,1.6880268528617637,-0.27829897590676245
302.0000000000036,19.147695981265553,1.711941287134058,-0.2922783637723607
303.1000000000036,19.180835808483167,1.7374689459849315,-0.3078521853115981
304.2000000000036,19.21432234008451,1.7727151295903383,-0.3207465371211793
305.30000000000365,19.24737217971174,1.8048270606028567,-0.33525579925369
306.4000000000037,19.280795846206804,1.8426131260620224,-0.3496662286230867
307.5000000000037,19.314287043849646,1.8781441286917224,-0.3665521971300203
308.60000000000366,19.347396155807708,1.9116330808252262,-0.38338500895021754
309.7000000000037,19.380544468116415,1.944202308473338,-0.4001300326484256
310.8000000000037,19.41408733036528,1.9717545613384038,-0.4140751998302683
311.90000000000373,19.447420623449588,1.9930842338094006,-0.42894963827403076
313.00000000000375,19.481059064444285,2.010602705168688,-0.4424205729536923
314.1000000000038,19.514169759210255,2.020755694286416,-0.45692776276000036
315.2000000000038,19.54768921752954,2.026445090135976,-0.4700402452482302
316.3000000000038,19.58114266182195,2.024772452945533,-0.484425378954894
317.40000000000384,19.614611992992206,2.0163928663567776,-0.4959795775115001
318.5000000000038,19.648016298168358,2.0039342682751418,-0.5079878242370781
319.60000000000383,19.68170875032926,1.9850463078360723,-0.5178585633687036
320.70000000000385,19.7147193299383,1.9646454155315918,-0.5283586054620808
321.8000000000039,19.747980204925888,1.9413211146807707,-0.5371345048542255
322.9000000000039,19.781903116994144,1.9145146413672203,-0.5467432521238282
324.0000000000039,19.815219182165546,1.8849166452138653,-0.5544762167870876
325.10000000000394,19.848474625841853,1.8566790322499558,-0.5622623046686641
326.2000000000039,19.882042703776463,1.8276835979791235,-0.5698486071723856
327.30000000000393,19.91541556038218,1.7978409153001946,-0.5768478787264928
328.40000000000396,19.94880414461883,1.7708172550420667,-0.5827304568634384
329.500000000004,19.98204773440846,1.7436373441325597,-0.5879318837042633
330.600000000004,20.01563451842797,1.7194966818021202,-0.5931680774653545
331.700000000004,20.04915770272919,1.693587322462982,-0.5988854368340912
332.80000000000405,20.08234736663559,1.6717950690429138,-0.6038633214677822
333.90000000000407,20.115771706880484,1.6476104965351113,-0.608742420311918
335.0000000000041,20.14932801412264,1.6255181320372072,-0.613657978938901
336.10000000000406,20.18251330454094,1.6058180671989,-0.6174152165160187
337.2000000000041,20.21617388594878,1.5868435467219195,-0.6216662354247942
338.3000000000041,20.249496607029606,1.5676528975792796,-0.6256802570104432
339.4000000000041,20.283185476091628,1.5507373904776904,-0.6292510358532533
340.50000000000415,20.316868541964165,1.5315300453658074,-0.6335671319495031
341.6000000000042,20.35002791055001,1.5161018424698534,-0.6369642266322031
342.7000000000042,20.38361219050602,1.4995190080927958,-0.6390167236947262
343.80000000000416,20.417131550906948,1.4850442081852848,-0.6419169180256885
344.9000000000042,20.450526284649374,1.4687214264910045,-0.6431462935030239
346.0000000000042,20.484189513990433,1.4559472282182029,-0.6451219392266725
347.10000000000423,20.518117752700178,1.4439089656358082,-0.6482789101460575
348.20000000000425,20.551504604904675,1.4312468005289973,-0.650143644910822
349.3000000000043,20.585015094555686,1.4177112143476889,-0.6523863661386051
350.4000000000043,20.618732702601953,1.4068765144658733,-0.6566715914711954
351.5000000000043,20.652344144923017,1.395792509540794,-0.6582466668751037
352.60000000000434,20.685917043902986,1.3843753780288166,-0.6598785797857079
353.7000000000043,20.719593013832302,1.37485369885332,-0.6611943530892233
354.80000000000433,20.753151654306443,1.3642895891510194,-0.662734643154915
355.90000000000435,20.786825893364377,1.3561719604056857,-0.663240012017297
357.0000000000044,20.820650520420134,1.347807043618757,-0.6646971417676362
358.1000000000044,20.854226465147534,1.337525495723508,-0.6662572534939497
359.2000000000044,20.888169060248927,1.3307262843612628,-0.6676883892719983
360.30000000000445,20.921884128196357,1.3254171041020337,-0.6701236473439471
361.4000000000044,20.955418597077937,1.3167551216930826,-0.6717676938845396
362.50000000000443,20.989347187538687,1.3096567360411182,-0.6716775082145294
363.60000000000446,21.023020403115737,1.3050801229712965,-0.6730416332970366
364.7000000000045,21.05677022642661,1.2994591308084698,-0.6734408326059711
365.8000000000045,21.0908504000009,1.2950794972119812,-0.6734820402221784
366.9000000000045,21.124435285303573,1.290411303889191,-0.6748468512333634
368.00000000000455,21.158298337516186,1.286252696297478,-0.6760005312043598
369.10000000000457,21.19202180976574,1.2822304236793505,-0.676000009236422
370.2000000000046,21.22587449648922,1.2787545481096643,-0.6759724944867176
371.30000000000456,21.259937967830002,1.275593592809312,-0.6774022723761437
372.4000000000046,21.29357280157219,1.2747157531038136,-0.6797315106558957
373.5000000000046,21.327489552713537,1.2732218923692749,-0.6804926011643335
374.6000000000046,21.361161477608075,1.2704920031152716,-0.6810498490691121
375.70000000000465,21.395298708005356,1.26991213571764,-0.6821749098286918
376.8000000000047,21.42929589271608,1.2664977079629491,-0.6810536233283124
377.9000000000047,21.463218375830046,1.2676140138668184,-0.6810524149066479
379.00000000000466,21.496958729098125,1.2636481410985487,-0.6823450790144401
380.1000000000047,21.53086980684895,1.2648817330996702,-0.6825186618294565
381.2000000000047,21.565080110794145,1.2653974107697512,-0.6836741206693571
382.30000000000473,21.599011515992544,1.2639250863484874,-0.6849953742750792
383.40000000000475,21.632826291081113,1.2621028001585821,-0.6849919462825307
384.5000000000048,21.666859735651144,1.2598489839106992,-0.6860223472747462
385.6000000000048,21.70115440858028,1.2584356633663156,-0.685013982023261
386.7000000000048,21.734846942247206,1.257226512408383,-0.6863011769088354
387.80000000000484,21.769026059272857,1.2545076220985814,-0.6862922773435045
388.9000000000048,21.80324225649581,1.2524601417672132,-0.6876152526333823
390.00000000000483,21.83720257395632,1.2513661276471866,-0.6875631150574288
391.10000000000485,21.871534829164347,1.2486024562073936,-0.6889384838441317
392.2000000000049,21.90536009496352,1.2466983254117405,-0.6902816210074407
393.3000000000049,21.939453388514963,1.2441800904279383,-0.6902603598869104
394.4000000000049,21.97388095959498,1.2421024727225958,-0.6915897954845782
395.50000000000495,22.007754661105476,1.2384571014559613,-0.692873890935866
396.6000000000049,22.04215318295982,1.23463870796137,-0.6942141625325928
397.70000000000493,22.076107639568253,1.2320897322235116,-0.6930714778107925
398.80000000000496,22.11045903492146,1.229123207283236,-0.6930276418727637
399.900000000005,22.144641207255837,1.2243872812473315,-0.6942011685410181
401.000000000005,22.178673436930723,1.2215115438066302,-0.6941872591643361
402.100000000005,22.212722960096592,1.2167683987619176,-0.6931650216476481
403.20000000000505,22.246993269579708,1.2111580227286116,-0.6941984502272116
404.30000000000507,22.280958920396245,1.2070256629265306,-0.6955134257415199
405.4000000000051,22.31532346954567,1.202553313651753,-0.6981953483807226
406.50000000000506,22.34952833019983,1.1966912958282372,-0.6981502874310723
407.6000000000051,22.383884356219323,1.1875768914437674,-0.6988679492846499
408.7000000000051,22.418155822122582,1.183661754476263,-0.6994699084464129
409.8000000000051,22.452560988472626,1.1768054155093888,-0.6994692994522214
410.90000000000515,22.486766221742947,1.169837758982131,-0.7007914207746846
412.0000000000052,22.520652016903934,1.1636910021985931,-0.7008292155066176
413.1000000000052,22.555203251791852,1.155167113619361,-0.7022138168859011
414.20000000000516,22.589669730791915,1.150814673657863,-0.7041894798889379
415.3000000000052,22.623603615535856,1.1434037435261375,-0.7067240103885437
416.4000000000052,22.65836779773614,1.1365803295190324,-0.7073702902080425
417.50000000000523,22.69289813883899,1.1320227076592733,-0.7083212743558889
418.60000000000525,22.727048157175396,1.1257635604999532,-0.7086882014199416
419.7000000000053,22.761387014533174,1.1199592215705068,-0.709994031907252
420.8000000000053,22.796002875844884,1.1126793053064201,-0.7115035850118101
421.9000000000053,22.829990518779958,1.1079696701638482,-0.7113851714364734
423.00000000000534,22.86431421275974,1.1022277458200576,-0.7117497837242097
424.1000000000053,22.898809184886968,1.0974428563518723,-0.7126324223196154
425.20000000000533,22.93342401694461,1.0949485621502022,-0.7130744114863905
426.30000000000535,22.96811232833971,1.0904295786831049,-0.7145721893360655
427.4000000000054,23.00241417547676,1.0869527898205456,-0.7161887121403057
428.5000000000054,23.03686025652737,1.0836741361145896,-0.7174127370006409
429.6000000000054,23.071405500832793,1.0808357239042303,-0.7201021851781384
430.70000000000545,23.1057306355751,1.080055003272566,-0.7214914572259854
431.8000000000054,23.140246651262864,1.0765594102072278,-0.722849773413587
432.90000000000543,23.17484808509687,1.0733219126928124,-0.7228461157231054
434.00000000000546,23.209544480696646,1.0712262917848725,-0.7242261842611617
435.1000000000055,23.244138295373993,1.0694547013767555,-0.7259341765461684
436.2000000000055,23.278699620277656,1.0700415463214252,-0.7278085334545077
437.3000000000055,23.313230454530434,1.0679715184591836,-0.7291913282642071
438.40000000000555,23.347833393160368,1.0675159326159425,-0.7304555296136757
439.50000000000557,23.38211555217454,1.0657957814143733,-0.7320629171056172
440.6000000000056,23.416807706067438,1.0658146703234448,-0.7337295724967103
441.70000000000556,23.451492802589346,1.067403143067377,-0.7351997942380013
442.8000000000056,23.485804543298872,1.0674134678965936,-0.7374383818300192
443.9000000000056,23.520874505608194,1.068585165419305,-0.7395588702059834
445.0000000000056,23.5552776519309,1.0695454531960975,-0.7411607578192445
446.10000000000565,23.59009185022745,1.0713697492114242,-0.7430083418559694
447.2000000000057,23.62490777256396,1.0744149755863686,-0.7449250844326696
448.3000000000057,23.65933491073912,1.0764046080767162,-0.7464888578842976
449.40000000000566,23.694016277386776,1.0758564678818952,-0.7495762419527514
450.5000000000057,23.72869153520787,1.0765515799351417,-0.7518138253009061
451.6000000000057,23.763622165175814,1.079767846859885,-0.7544119529298472
452.70000000000573,23.798266432108417,1.0816863610795475,-0.7581966937730424
453.80000000000575,23.83304316401619,1.0846323946147451,-0.7605341318476202
454.9000000000058,23.867829649342426,1.0883517126950895,-0.7642078640011651
456.0000000000058,23.90264492346962,1.093588171354954,-0.7691269840449921
457.1000000000058,23.9376284139028,1.0986197427608881,-0.771486874735539
458.20000000000584,23.972193947796747,1.1027128168986025,-0.7745462538503292
459.3000000000058,24.00706947740352,1.1091723450205628,-0.7782179597295134
460.40000000000583,24.04194722594796,1.1140994857658428,-0.7826462906972078
461.50000000000585,24.0767155988403,1.1184656453165343,-0.7871345696533614
462.6000000000059,24.111733585097934,1.1271522642990028,-0.7923033755462905
463.7000000000059,24.14631594955916,1.1348636145934443,-0.7965868413376977
464.8000000000059,24.18144632801244,1.1413356487393034,-0.8001581915070135
465.90000000000595,24.216009175302762,1.1494161313344082,-0.804408779725704
467.0000000000059,24.251210981163215,1.1583767595240198,-0.8089023722877351
468.10000000000593,24.286146902490746,1.1666210526445209,-0.8121859948634467
469.20000000000596,24.320884797424114,1.1773627823289976,-0.8166960816235145
470.300000000006,24.355854127367,1.1874824452988553,-0.8200642076078926
471.400000000006,24.39067288900494,1.196280391098663,-0.8237307880750033
472.500000000006,24.42582471575788,1.206503055804749,-0.8270768635605021
473.60000000000605,24.460577683633343,1.21667702090005,-0.8315772711117044
474.70000000000607,24.495753752072932,1.2235337358875507,-0.8361158356130063
475.8000000000061,24.53069821406959,1.2325010289630038,-0.8404382272537654
476.90000000000606,24.565682290441426,1.242807120610533,-0.8441297072306475
478.0000000000061,24.60038313868232,1.2504462619959935,-0.8498208366489557
479.1000000000061,24.635921642131922,1.2569686614411366,-0.853891147181566
480.2000000000061,24.670650656266996,1.2649578674010926,-0.8578590906384989
481.30000000000615,24.705788702433306,1.2754925378811843,-0.8621519479874502
482.4000000000062,24.740909123311756,1.2827966678470215,-0.8648776732035115
483.5000000000062,24.775928946180773,1.2865216987793113,-0.86908628912267
484.60000000000616,24.811240711319382,1.2929890516273514,-0.8724245274651188
485.7000000000062,24.846086620314217,1.3006540491107181,-0.8773752025226269
486.8000000000062,24.881632132640558,1.3051013951320058,-0.8815739775283205
487.90000000000623,24.916680976190662,1.3117508693695075,-0.8856682796651407
489.00000000000625,24.95166385538131,1.3164366168029513,-0.8898938874703584
490.1000000000063,24.98670287690217,1.3217099872822582,-0.89394527848992
491.2000000000063,25.021847850782333,1.3280317808655258,-0.8988332402611228
492.3000000000063,25.05679200429391,1.3308331667934499,-0.902723040912528
493.40000000000634,25.0920929312544,1.336140858184942,-0.9056224324247095
494.5000000000063,25.127266703397684,1.3402357658296133,-0.9097529096457713
495.60000000000633,25.16222050389358,1.3471829195800613,-0.9129861823202496
496.70000000000636,25.197430060940174,1.3505066673753732,-0.916132474790027
497.8000000000064,25.232518349914947,1.3569017253589222,-0.918922829543336
498.9000000000064,25.267630914446524,1.3619819140610074,-0.9228272298874791
500.0000000000064,25.30293800399057,1.366896191713563,-0.9267917114482058
501.10000000000645,25.337927332663508,1.3728421825257644,-0.9293019226029084
502.2000000000064,25.37348780948282,1.3785880048703638,-0.9315863498521129
503.30000000000643,25.408375604802217,1.3849838669812813,-0.9350320485710197
504.40000000000646,25.443636647629702,1.3906436230609458,-0.938125027094546
505.5000000000065,25.47861437820328,1.3980188790568417,-0.9400832433451858
506.6000000000065,25.51432334282829,1.4028827216229307,-0.9433179324460288
507.7000000000065,25.549611509378686,1.40728241319024,-0.9477738702964236
508.80000000000655,25.584946593496074,1.4145869913328566,-0.9496315580098367
509.90000000000657,25.619877103319038,1.4194259109269092,-0.9499937735290316
511.0000000000066,25.655104310293822,1.423809363863664,-0.9516308977483554
512.1000000000065,25.690360964124626,1.4303872344439013,-0.9544473114473102
513.2000000000066,25.725712321801886,1.4354735310551008,-0.9563412953074919
514.3000000000065,25.761228343739333,1.439908831806456,-0.9578724085777055
515.4000000000067,25.796416033098602,1.44255042430301,-0.959304023093055
516.5000000000066,25.83178359245006,1.4490061103817815,-0.9623377182712263
517.6000000000067,25.86713644216972,1.4523377790564165,-0.9638154256575842
518.7000000000066,25.902470734139676,1.4555376699946359,-0.9648541277388194
519.8000000000067,25.937728040578428,1.4613075036420817,-0.9668066799192312
520.9000000000067,25.973231631273972,1.465823853231253,-0.9668904539808278
522.0000000000067,26.008430021751845,1.4666076313286642,-0.967878814342022
523.1000000000067,26.043812901723538,1.4711125274237393,-0.9682147965810373
524.2000000000068,26.07948519577925,1.475579090091469,-0.9697392967897178
525.3000000000068,26.114716356074123,1.4804807723547098,-0.971055008911256
526.4000000000068,26.150111487615735,1.4833860566255195,-0.9723267818901116
527.5000000000068,26.185389545062243,1.4883579436410164,-0.9739821951129786
528.6000000000068,26.22087596801723,1.4935162271225335,-0.9753623976350245
529.7000000000069,26.256049402558343,1.4998252545552762,-0.975064744140353
530.8000000000068,26.291726398898277,1.50625083115636,-0.9760794886729021
531.9000000000069,26.327094979562677,1.514241332522096,-0.9776545537855896
533.0000000000068,26.36285904527648,1.520487456765889,-0.9799852811678775
534.100000000007,26.39817418225794,1.5305106714238683,-0.9808197731294865
535.2000000000069,26.433879846669686,1.5377534975678402,-0.9813966157606173
536.300000000007,26.469120360943844,1.5449359426315985,-0.9834009227692118
537.4000000000069,26.504428542528306,1.5565844851812605,-0.9851418653878254
538.5000000000069,26.54006475094957,1.5688129387016,-0.9865493680703077
539.600000000007,26.5756175803248,1.5817158529223359,-0.9865298313653366
540.700000000007,26.611173574313785,1.5920282613760277,-0.9878275341285834
541.800000000007,26.64647910913744,1.6054110236830728,-0.9891529180702969
542.900000000007,26.682057881166845,1.6171576273092423,-0.990639530542174
544.000000000007,26.71782080955877,1.628439919053255,-0.992151614797121
545.1000000000071,26.753422089915453,1.640185567492835,-0.9941960802399681
546.2000000000071,26.78913781170719,1.6538255760551914,-0.9964720325740029
547.300000000007,26.824508523729154,1.6652444114162166,-0.9979374461660506
548.4000000000071,26.860032012121387,1.6790624191034802,-0.9979790041367207
549.500000000007,26.89591888317746,1.6894335238183606,-0.9992995456928782
550.6000000000072,26.931455083452832,1.7022028415240527,-1.001375713559268
551.7000000000071,26.966863308852666,1.7119931554055787,-1.0028579648050422
552.8000000000072,27.00263072655351,1.7199347340462183,-1.0039549749419194
553.9000000000071,27.038348949341422,1.7288714585761895,-1.0052776534951584
555.0000000000072,27.07387001571311,1.7337536867789625,-1.0063179432975038
556.1000000000072,27.109636734914595,1.740933832258188,-1.0081042329413665
557.2000000000072,27.14505949623306,1.7464758194817793,-1.0108323445525076
558.3000000000072,27.18094538905796,1.7528835143251555,-1.012531917853119
559.4000000000073,27.21678943518837,1.7572062664014745,-1.0138722246235106
560.5000000000073,27.252363706425452,1.762298869299308,-1.0164511658822732
561.6000000000073,27.288264244090914,1.7680209285144364,-1.0177023597564974
562.7000000000073,27.32391687840644,1.7738598143409607,-1.0191972526856174
563.8000000000073,27.35969633182863,1.779716135258352,-1.0206250300148705
564.9000000000074,27.3951735065408,1.7861027621104568,-1.0233360808601022
566.0000000000074,27.430964070372937,1.7957320290492564,-1.0251342237385308
567.1000000000074,27.466670663164454,1.8036202946069262,-1.0262357879427682
568.2000000000073,27.502721303375413,1.8154070310242871,-1.0285826215272347
569.3000000000073,27.538320782015564,1.8264299538873496,-1.0300629528432914
570.4000000000074,27.574166252003632,1.8396585310224562,-1.031598507294472
571.5000000000074,27.610189918290573,1.8555905763861564,-1.0328959405505005
572.6000000000074,27.64594677380168,1.868438346797129,-1.035347646685297
573.7000000000074,27.68182162847162,1.8852284098143963,-1.0374363277549379
574.8000000000075,27.717460149960573,1.9002303491594281,-1.039773747279272
575.9000000000075,27.75306956873037,1.9199134004691463,-1.039472179273035
577.0000000000075,27.78915076859459,1.9400145157348638,-1.0425576621078751
578.1000000000075,27.824695182790897,1.961097663303343,-1.0439834779265604
579.2000000000075,27.860734909621343,1.983186168973512,-1.0454288104169844
580.3000000000076,27.896716650194918,2.007474672678898,-1.0486382842375677
581.4000000000076,27.93286688292312,2.0348449208677954,-1.0509953969373074
582.5000000000076,27.968543789140377,2.0627974529413984,-1.0541968640515673
583.6000000000076,28.004421024641818,2.0928159644366517,-1.0561713767110938
584.7000000000077,28.040612878248673,2.126580227409636,-1.0577384192617862
585.8000000000077,28.07616306964049,2.15631513971397,-1.0607673963050606
586.9000000000076,28.112121485432255,2.1914039859391172,-1.0628604998588487
588.0000000000076,28.148260182771736,2.2300747387138404,-1.064382310511713
589.1000000000076,28.184494282904957,2.2723144267515702,-1.0669843549601183
590.2000000000077,28.220371616483956,2.3156055957016517,-1.0693273105440197
591.3000000000077,28.256444355297713,2.3670469501023055,-1.072157497875244
592.4000000000077,28.292684536457436,2.425099374106762,-1.074763297741173
593.5000000000077,28.328502453520475,2.484344782516154,-1.07819524871858
594.6000000000078,28.364692871644582,2.5496231605064708,-1.0800088842481363
595.7000000000078,28.40068492729951,2.617333847319342,-1.0833011511630533
596.8000000000078,28.436832764515007,2.687679797437627,-1.084777673569124
597.9000000000078,28.472910439941668,2.754528327542053,-1.0876047731396068
599.0000000000078,28.509162436667207,2.818923371906986,-1.089834832434089
600.1000000000079,28.54539096548762,2.865208063431084,-1.0929435291446992
601.2000000000079,28.581523499151647,2.878097813653535,-1.0956290550252197
602.3000000000079,28.617890526364977,2.8351315414372147,-1.0994083865141429
603.4000000000078,28.65379347705843,2.732964278766945,-1.1049214374805243
604.5000000000078,28.689987101132974,2.6176486955420466,-1.106829059789895
605.6000000000079,28.725814680585643,2.5003654120000838,-1.1102763102299495
606.7000000000079,28.761991051903788,2.385529474450091,-1.1136851877823384
607.8000000000079,28.797813557639866,2.2895012268504766,-1.1164205002942662
608.9000000000079,28.833969825488232,2.210602740762359,-1.1186005113651407
610.000000000008,28.870051616264647,2.136592929240714,-1.121977564178545
611.100000000008,28.906234752467604,2.0781549484079678,-1.1249759212170818
612.200000000008,28.94222222416541,2.0208203582446957,-1.1276939607132777
613.300000000008,28.978235464531522,1.9681939883638289,-1.1316955823303783
614.400000000008,29.014367912819992,1.9219093244434786,-1.134607603541645
615.5000000000081,29.050337770525637,1.8766647064624111,-1.1371999309350662
616.6000000000081,29.08640538474428,1.8376601258094711,-1.1391251483516256
617.7000000000081,29.12282981785687,1.8018847661701827,-1.1422735052867172
618.8000000000081,29.158498948837735,1.7664043974261576,-1.144605075911806
619.9000000000082,29.194896291247908,1.7429303261346296,-1.1459948474846673
621.0000000000082,29.230873935842435,1.7222750960252378,-1.1475683684203037
622.1000000000081,29.26700461786345,1.707503823205857,-1.150850019242005
623.2000000000081,29.30328103789391,1.7062332298694862,-1.1517310618557888
624.3000000000081,29.339327204705405,1.7069564260783825,-1.1532577514151878
625.4000000000082,29.375641961474134,1.7152006041806032,-1.154670770905812
626.5000000000082,29.411565846574213,1.7255516134926119,-1.1559714828727667
627.6000000000082,29.447921311905052,1.7337761648576437,-1.1573153157504557
628.7000000000082,29.484180343577133,1.74062594854817,-1.157299703457829
629.8000000000083,29.51996686279412,1.7428929904455237,-1.1576270075702007
630.9000000000083,29.556457945851314,1.7476613280584001,-1.1587403219956864
632.0000000000083,29.59268564679835,1.7508006302350303,-1.1600378020590072
633.1000000000083,29.628967394103377,1.75543034601494,-1.1614145179990554
634.2000000000083,29.665093352447247,1.7594298178166754,-1.1603409651930554
635.3000000000084,29.701206080948957,1.764041961965371,-1.1616792850092326
636.4000000000084,29.737430781830373,1.7723987656769118,-1.1616124825161203
637.5000000000084,29.77389565087813,1.7817473081622643,-1.1626643525016434
638.6000000000083,29.809768837854776,1.7940202170252928,-1.1629200554710568
639.7000000000083,29.84618150847332,1.8070792885427605,-1.1639816660930307
640.8000000000084,29.88248537031409,1.8236402950646196,-1.1646393714434229
641.9000000000084,29.918860613546126,1.8380068051153229,-1.1646274635333764
643.0000000000084,29.954918796690567,1.8525945752266968,-1.1659610300983165
644.1000000000084,29.991323687157315,1.87014033854022,-1.166143968374071
645.2000000000085,30.027448365476435,1.8870277831811153,-1.1673217130045295
646.3000000000085,30.063744574361476,1.9044698554998283,-1.169415713893788
647.4000000000085,30.099932316287962,1.9243733201875477,-1.1712301215711527
648.5000000000085,30.136147832226943,1.9508669063037751,-1.1725146087412317
649.6000000000085,30.17260978931116,1.9763444381090656,-1.172599949335082
650.7000000000086,30.208617216929415,2.0025636745115434,-1.173164204382756
651.8000000000086,30.245217360791095,2.0325318352360817,-1.1754754586163583
652.9000000000086,30.28128090149066,2.0633135741069317,-1.1764260191930611
654.0000000000086,30.318025023205976,2.1023217494265602,-1.1783804532246887
655.1000000000087,30.3542430025698,2.140777626571791,-1.1800850253588075
656.2000000000087,30.390505224564134,2.1789150733695144,-1.18193956757198
657.3000000000086,30.42680396487527,2.2223453456095883,-1.1847284018611526
658.4000000000086,30.463087577735656,2.2684703562887982,-1.1860616932177654
659.5000000000086,30.49959608721169,2.314094769120493,-1.1860227944724713
660.6000000000087,30.53611357025853,2.3597451931672384,-1.1875921680391484
661.7000000000087,30.57231979363628,2.4054205628245553,-1.1894031424894993
662.8000000000087,30.608818950097294,2.451028444438396,-1.1909084747033583
663.9000000000087,30.64510084986461,2.4986721938667964,-1.1933193162153777
665.0000000000088,30.681363896238533,2.5437831512595954,-1.195722099097047
666.1000000000088,30.71785253179479,2.5892609332944923,-1.1972011222460228
667.2000000000088,30.754458625797437,2.6365967164750823,-1.1997343432760172
668.3000000000088,30.7909125517164,2.685186754617499,-1.2014500383701803
669.4000000000088,30.82728212390332,2.7311953796589536,-1.2046859475757428
670.5000000000089,30.863796024460743,2.7813693296026907,-1.2065676962684018
671.6000000000089,30.900164425553374,2.834409192247893,-1.2098527533581787
672.7000000000089,30.936888482445923,2.8916811514090877,-1.211992929944758
673.8000000000088,30.973261226667645,2.9536410567419247,-1.215096486123333
674.9000000000088,31.009515374387423,3.0215100210983716,-1.2186401575381156
676.0000000000089,31.04609030675485,3.099872539373507,-1.22245460546119
677.1000000000089,31.08260481433564,3.1807401434240608,-1.2253448893894414
678.2000000000089,31.118956494560788,3.2699160705286086,-1.2281787987028983
679.3000000000089,31.155529383677976,3.3702804119792567,-1.2319737518272262
680.400000000009,31.19220730059574,3.47830589245432,-1.2366691718967209
681.500000000009,31.22846304438801,3.5966668122925105,-1.2406464480824702
682.600000000009,31.265074248737537,3.7257968030027455,-1.2432519881326716
683.700000000009,31.30201112759929,3.8616780046326378,-1.2468861517463665
684.800000000009,31.338357265099027,3.9952179752830173,-1.2513725183412117
685.9000000000091,31.374889344304865,4.101544857573598,-1.2561440051217763
687.0000000000091,31.411418282256623,4.133998599007502,-1.2612820274634258
688.1000000000091,31.448244711160616,4.054968051982508,-1.2654270998786594
689.2000000000091,31.484781319220293,3.9423830537916085,-1.2705007064118643
690.3000000000092,31.521160797131188,3.8738815569949696,-1.2748913073636694
691.4000000000092,31.557521963120863,3.8484373146381823,-1.2797131321277875
692.5000000000091,31.594092761654522,3.8523403992063567,-1.2853267512005475
693.6000000000091,31.630483691920492,3.879961159879143,-1.2907093170266526
694.7000000000091,31.666942014702993,3.921440138764587,-1.2958552745414997
695.8000000000092,31.703354134281774,3.9736585017630643,-1.3010951256723362
696.9000000000092,31.73969127595935,4.033989720098181,-1.3067290277785917
698.0000000000092,31.77620945705965,4.100502067804161,-1.3135910521034289
699.1000000000092,31.812835498528344,4.172190042492311,-1.3209710060073139
700.2000000000093,31.84956039718957,4.247061133232157,-1.3268747268305265
701.3000000000093,31.8858819102901,4.3264093581358285,-1.3327117551929395
702.4000000000093,31.922604996552767,4.4085952588386474,-1.3393217501773105
703.5000000000093,31.95907761881099,4.49177121115153,-1.3458268879987338
704.6000000000093,31.99568407708758,4.580729117179609,-1.352593141569196
705.7000000000094,32.03220607761304,4.672354484564498,-1.3596155601237183
706.8000000000094,32.0688998658241,4.764951522785454,-1.3677111515960587
707.9000000000094,32.10537492961115,4.859239843944009,-1.3748678816624036
709.0000000000093,32.1418580462401,4.954010705360177,-1.3818298278985024
710.1000000000093,32.17877323636734,5.054697627770929,-1.390717634997766
711.2000000000094,32.21534394608325,5.157086435478171,-1.398522046271061
712.3000000000094,32.251727160319746,5.258600621750053,-1.405676149302574
713.4000000000094,32.28875086076731,5.364279066349931,-1.4135362427641849
714.5000000000094,32.325115470925034,5.472627172198133,-1.4226018075801288
715.6000000000095,32.36185991443139,5.579966041212198,-1.4332420956805056
716.7000000000095,32.39841025673465,5.692083267088624,-1.4428620230899418
717.8000000000095,32.435285323351756,5.806457270341813,-1.4514524504468023
718.9000000000095,32.471892137784344,5.9244161210323485,-1.461212746797083
720.0000000000095,32.508548994123466,6.04140284174972,-1.4708453537832664
721.1000000000096,32.54525904821589,6.162439096504576,-1.480916108571456
722.2000000000096,32.58195696630084,6.283488888399167,-1.4915049298699423
723.3000000000096,32.61920777613449,6.411948682904348,-1.5019212151798635
724.4000000000096,32.655699388711916,6.534459017993076,-1.5120418576001238
725.5000000000097,32.692703518241444,6.662366330905321,-1.523493736098683
726.6000000000097,32.729496261156726,6.793832309695312,-1.535282021375
727.7000000000096,32.766334012849576,6.924760004239427,-1.5466786983022955
728.8000000000096,32.802915859737006,7.0565366998751715,-1.5597674531945342
729.9000000000096,32.8396348833031,7.188250201948758,-1.5709568357197505
731.0000000000097,32.876718382609724,7.328552064068197,-1.5832369148915655
732.1000000000097,32.91336374994159,7.461931087054895,-1.5962828601393033
733.2000000000097,32.950211043096644,7.599692495072425,-1.609491855905282
734.3000000000097,32.986931569633526,7.735287055536085,-1.623132195529235
735.4000000000098,33.02408443104527,7.8758159694370695,-1.6379176291107802
736.5000000000098,33.06093142657277,8.013242947358759,-1.6506937862202333
737.6000000000098,33.09766605181516,8.147097805305837,-1.6648351517144104
738.7000000000098,33.13485056761178,8.286223742064738,-1.6791078972522469
739.8000000000098,33.17143529506469,8.418281313450322,-1.6942689892269867
740.9000000000099,33.20812034231242,8.55021306415873,-1.7099915503131733
742.0000000000099,33.24517205200296,8.679995068172008,-1.7264611808631125
743.1000000000099,33.28215947872764,8.806772645892684,-1.7437655831702497
744.0000000000099,33.31209624308634,8.903083731415409,-1.7574211182089954