File: 01_Data/EIFS_Coating/STA/N2/10K_min/EIFS_Coating_STA_N2_10KData_230918_R2.csv
##Temp./Â°C,Time/min,DSC/(mW/mg),Mass loss/mg
41.0,10.815963614256452,-2.3127175400251807,0.0014275102701626352
42.40000000000002,11.165645383429116,-2.237270691615272,0.0022559614349599855
43.80000000000004,11.412589467609154,-2.185248921021665,0.0012955070779945288
45.20000000000006,11.617683050593378,-2.1492659293395344,0.0007206822158911663
46.60000000000008,11.803378024592979,-2.1166271500723126,-0.00029260951442999783
48.0000000000001,11.979686271350655,-2.093361278883789,-0.000130072470893694
49.40000000000012,12.147077690347919,-2.0723626132504593,-0.0005550482272278501
50.80000000000014,12.309774005179046,-2.056419818050844,0.0001048482028869202
52.20000000000016,12.467193263063749,-2.040768182807853,-0.0010754023375829647
53.60000000000018,12.625599810247296,-2.0313480490392064,-0.0025267566022986188
55.0000000000002,12.780463521102265,-2.0215839812902265,-0.0025250179625855296
56.40000000000022,12.933902013844245,-2.012424503031882,-0.0024074059484515686
57.80000000000024,13.086895668664061,-2.003895850220129,-0.0024774302061647546
59.20000000000026,13.23817377075692,-1.9979944508194065,-0.0036903344502512425
60.60000000000028,13.386843953506178,-1.9930318431887768,-0.0012120859726287847
62.0000000000003,13.536230692592335,-1.9859333836010442,-0.0020868334140748956
63.40000000000032,13.684960893945375,-1.980991114060585,-0.002507585068266316
64.80000000000034,13.833255335240432,-1.9744642604169762,-0.004060086577197808
66.20000000000036,13.978841453883332,-1.9683830684288397,-0.0031250271948639607
67.60000000000038,14.123233817104317,-1.9635162679762916,-0.00538469341239356
69.0000000000004,14.26917000000004,-1.959010000000001,-0.005369944820109218
70.40000000000042,14.411214867450724,-1.951825842104683,-0.005380444298644704
71.80000000000044,14.556323039228507,-1.948265634633054,-0.006278712389955032
73.20000000000046,14.6999323684167,-1.942519390023045,-0.005158968562509081
74.60000000000048,14.84132674711578,-1.9374652952660907,-0.00920869070790964
76.0000000000005,14.983343545252703,-1.9300632839676266,-0.010488823565036665
77.40000000000052,15.125902693624015,-1.9236441569330442,-0.009277910247295296
78.80000000000054,15.266327925287857,-1.9140619538705888,-0.010540148110143477
80.20000000000056,15.404271594251151,-1.9064030631495252,-0.01040186868153059
81.60000000000058,15.546131438293498,-1.8944402868490593,-0.01451560107628902
83.0000000000006,15.685893708859096,-1.879238764074409,-0.013389901655579184
84.40000000000062,15.822827333639903,-1.8603460327237549,-0.014742520169967133
85.80000000000064,15.961775438808726,-1.8442622762779899,-0.01437961850697178
87.20000000000066,16.10140071136648,-1.8283202896878248,-0.013060209399784473
88.60000000000068,16.237998609142203,-1.8148914721223544,-0.011720433677635977
90.0000000000007,16.377004902864027,-1.804087814066075,-0.014699490500125645
91.40000000000072,16.513479165806547,-1.7933294491783287,-0.016020097931360944
92.80000000000074,16.649778289860055,-1.7852404740858858,-0.01668344513104536
94.20000000000076,16.785786539197446,-1.7750713803440965,-0.016377254973915623
95.60000000000078,16.92365675256322,-1.7666853609370219,-0.01601998198884047
97.0000000000008,17.06163004683595,-1.7592414352910306,-0.0160092472730895
98.40000000000082,17.19812873389112,-1.7521013012667275,-0.0160133497108208
99.80000000000084,17.335022820050114,-1.744636983496248,-0.015447564886533538
101.20000000000086,17.471258429092813,-1.7380103807765088,-0.016020196259362685
102.60000000000088,17.60731680965737,-1.7305574938604757,-0.016696249670956842
104.0000000000009,17.742884847402134,-1.72467975064177,-0.016691602190491928
105.40000000000092,17.879955781865533,-1.719072818210967,-0.017360663914379515
106.80000000000094,18.014609673665824,-1.7139659592878098,-0.01804921585595798
108.20000000000095,18.14935565874305,-1.7063343988590047,-0.017009900368178066
109.60000000000097,18.28565359288971,-1.7005035218400955,-0.017010090059280447
111.000000000001,18.42201735744062,-1.690128212401028,-0.018398830427312163
112.40000000000101,18.555795863991424,-1.6820351191863985,-0.017339956835452863
113.80000000000103,18.692427671220457,-1.6729144483131995,-0.01861618758286676
115.20000000000105,18.827256484250256,-1.6649276277072524,-0.01862725632176332
116.60000000000107,18.960549909326858,-1.6591168045062887,-0.02015727219451735
118.0000000000011,19.097717233397088,-1.6518733700007766,-0.019319835000063623
119.40000000000111,19.2322879691163,-1.643526402859988,-0.01931674026450292
120.80000000000113,19.367794662984693,-1.638017992271032,-0.019318599459231756
122.20000000000115,19.50458269434976,-1.6333530599730555,-0.01833390884028452
123.60000000000117,19.638578327347183,-1.6273815346435365,-0.01832089088779343
125.0000000000012,19.774642604034664,-1.6188619750479851,-0.019649387816297548
126.40000000000121,19.909082177034044,-1.6127290033900012,-0.018331556787121173
127.80000000000123,20.043238113719678,-1.6082803619330297,-0.01731260562240733
129.20000000000124,20.17797590676539,-1.6010931279576364,-0.018659942537892604
130.60000000000127,20.310091301379412,-1.5973043312135813,-0.01965034464538995
132.0000000000013,20.44819841238717,-1.591203060522851,-0.019647220053615744
133.4000000000013,20.5814627022302,-1.5871267599327354,-0.017672037028363174
134.80000000000132,20.715583581675673,-1.57978903150421,-0.01799981464486633
136.20000000000135,20.849483882516033,-1.5750900793096352,-0.01931980161662139
137.6000000000014,20.984515966960377,-1.569160474343459,-0.018660262721479803
139.0000000000014,21.115355907416678,-1.5645452457844666,-0.020965461739276048
140.4000000000014,21.252717731568655,-1.5586912068875498,-0.01999090827320371
141.80000000000143,21.38602738520606,-1.5552239350240284,-0.020960000151181823
143.20000000000147,21.52108547708862,-1.5492785582280066,-0.020299882212813092
144.60000000000147,21.652776656526218,-1.544462691126619,-0.019640044171655546
146.00000000000148,21.78811719544419,-1.5402831631651104,-0.019640076496803438
147.4000000000015,21.9227630011845,-1.5353363414621486,-0.02096033450387491
148.80000000000155,22.053870023366382,-1.5314105329883405,-0.01833036477700478
150.20000000000155,22.190897640292977,-1.5263658923847605,-0.01967779488916399
151.60000000000156,22.32500483160352,-1.520841933507062,-0.01844230359770549
153.0000000000016,22.460387110400315,-1.5151452882685281,-0.01900342167299529
154.40000000000163,22.591579354841613,-1.5116222928663308,-0.018360427686969327
155.80000000000163,22.726415033877725,-1.5057620969884664,-0.018330232149392778
157.20000000000164,22.859170000000162,-1.5012699999999963,-0.01932017749909143
158.60000000000167,22.99198530783424,-1.4968075142194346,-0.01994609601049735
160.0000000000017,23.127294410330162,-1.4930221904938743,-0.020639972901445702
161.4000000000017,23.259395993999387,-1.4866324076267432,-0.02063015789774747
162.80000000000172,23.392046315402432,-1.4860816241668802,-0.02063016800000561
164.20000000000175,23.526865533817894,-1.4808556850052599,-0.020630167997614635
165.60000000000178,23.660225202872958,-1.4755188583343546,-0.021240166719344256
167.0000000000018,23.794782713158753,-1.471632202732816,-0.02060090450676988
168.4000000000018,23.928731688504904,-1.467984849395223,-0.021949984334275197
169.80000000000183,24.061232659136593,-1.4654427398196026,-0.02096007234138142
171.20000000000186,24.194751358674573,-1.4609301779172383,-0.021961845610177555
172.60000000000187,24.32858070076252,-1.456216887172534,-0.02228008194857889
174.00000000000188,24.462289250471546,-1.4516863309088448,-0.02097005678748909
175.4000000000019,24.59552495769618,-1.4461929799923219,-0.019650000794914746
176.80000000000194,24.72996256165656,-1.4441036032689085,-0.02162950874250713
178.20000000000195,24.862731106234065,-1.4408581345555629,-0.022280221542597012
179.60000000000196,24.995406442731635,-1.4359758531775069,-0.02095926884131938
181.000000000002,25.12966021662445,-1.4334348643361499,-0.02227993228281111
182.40000000000202,25.263004249195205,-1.4293536796142399,-0.020961501785091485
183.80000000000203,25.395141398736598,-1.425838616095074,-0.021212899722885314
185.20000000000203,25.528577443422925,-1.4225062518337577,-0.02095983072374663
186.60000000000207,25.662413338514494,-1.4201912546209614,-0.02232848572030477
188.0000000000021,25.795157287350698,-1.416831050511651,-0.022279631214858764
189.4000000000021,25.92798350417182,-1.4136440320432075,-0.02227982451373478
190.80000000000211,26.060427893171113,-1.409537395330307,-0.02360175096829842
192.20000000000215,26.19439299190864,-1.4100375554089708,-0.022610154690833273
193.60000000000218,26.32907801762717,-1.4053833297907758,-0.02261015699999902
195.0000000000022,26.46072395414338,-1.4025891500068277,-0.022610157026051958
196.4000000000022,26.594372970037156,-1.3994925260386828,-0.02377876356162778
197.80000000000223,26.72705834454891,-1.3955792866284364,-0.023583939175635837
199.20000000000226,26.86007384474397,-1.3937959929297858,-0.021289327474317332
200.60000000000227,26.99311123844225,-1.3921510350237174,-0.022925740156349406
202.00000000000227,27.12703242795691,-1.3883668426528244,-0.023270112899957063
203.4000000000023,27.26025227504913,-1.382343775511693,-0.023922974126800334
204.80000000000234,27.393513930554256,-1.3801131847766286,-0.023895575194344598
206.20000000000235,27.526506757964455,-1.3782587386923468,-0.023932549966370953
207.60000000000235,27.658692194840505,-1.3764470208315844,-0.022609953285274376
209.0000000000024,27.791636944416272,-1.3730039989844642,-0.023930640887498633
210.40000000000242,27.92413002189786,-1.3698489313322788,-0.024919865798972207
211.80000000000243,28.058773347647918,-1.3697966443807987,-0.022609985775538632
213.20000000000243,28.19165615663145,-1.366672102232981,-0.023917820599752115
214.60000000000247,28.32427385648869,-1.362938497975939,-0.023618910015169803
216.0000000000025,28.455685881197848,-1.36168821830167,-0.02326997543234466
217.4000000000025,28.590429689555396,-1.3594084522369885,-0.02459166138993396
218.8000000000025,28.724896244953953,-1.3552267367637443,-0.023702945247212615
220.20000000000255,28.85747533073884,-1.35128880342344,-0.024589974112098734
221.60000000000258,28.99024307968026,-1.3490330025782828,-0.026115146619575036
223.0000000000026,29.122837263910707,-1.3477708271273905,-0.024589975099830852
224.4000000000026,29.255166478501938,-1.3441449528519405,-0.024589363275062226
225.80000000000263,29.388975924447372,-1.341526023779624,-0.02457959487278094
227.20000000000266,29.522451996725053,-1.3407271261021825,-0.025248838143828944
228.60000000000267,29.654673238984977,-1.3367644960758724,-0.02392962916361574
230.00000000000267,29.786624837388405,-1.3356990898656977,-0.025239915297735394
231.4000000000027,29.920071025968937,-1.3347953820120433,-0.025899932757150523
232.80000000000274,30.052873784168703,-1.3334881768393771,-0.025899928999992383
234.20000000000275,30.18692403334319,-1.3304244557727403,-0.02590020252084768
235.60000000000275,30.3196848909672,-1.3301170773807196,-0.02457983722349022
237.00000000000279,30.45301676873962,-1.3284938332986052,-0.024549455598255943
238.40000000000282,30.58570440170346,-1.3260000787855986,-0.02590044505344835
239.80000000000283,30.718973489133084,-1.3246030116103433,-0.027219925663382494
241.20000000000283,30.85203473688373,-1.3231109266136223,-0.025243814934332143
242.60000000000286,30.985347235890753,-1.322696160255434,-0.02523983608684066
244.0000000000029,31.118304627332623,-1.3202756449342725,-0.025580675855133794
245.4000000000029,31.251950994471226,-1.3197653591856964,-0.026559859943831476
246.8000000000029,31.38476797585738,-1.317433179512279,-0.02655985999999988
248.20000000000294,31.517579115225175,-1.3138450940721051,-0.02655986000621091
249.60000000000298,31.650316926029227,-1.3130161659039847,-0.025177221078305667
251.00000000000298,31.784155149498577,-1.3108500199090576,-0.025252559755444715
252.400000000003,31.917177766469813,-1.3103367471103475,-0.02655987704684959
253.80000000000302,32.04977753047191,-1.3077700736074374,-0.024062903822407833
255.20000000000306,32.18264951741119,-1.307605929630578,-0.02525041334314526
256.6000000000031,32.316625398358106,-1.306632504653664,-0.02657584347437325
258.00000000000307,32.44713368177682,-1.304781328953165,-0.025899813975599706
259.4000000000031,32.58306752176646,-1.3042498014104342,-0.025899814000101884
260.80000000000314,32.716798862403664,-1.3038400307251168,-0.025896396610844974
262.2000000000031,32.84828548711721,-1.302682535382194,-0.02719761005678123
263.60000000000315,32.98307099354863,-1.302194184091484,-0.028538579905854178
265.0000000000032,33.11590989743953,-1.3013969396028302,-0.027236363612790804
266.4000000000032,33.25092173545412,-1.2993015231254683,-0.02721924222838057
267.80000000000325,33.38448113828688,-1.2984506810732888,-0.02597978622223085
269.20000000000323,33.51752708901496,-1.297319281805898,-0.02525019403140316
270.60000000000326,33.6512589771253,-1.296994017099432,-0.027556439890981554
272.0000000000033,33.78266218756963,-1.296507077246009,-0.027549859999769666
273.4000000000033,33.91845796355335,-1.2949221618670674,-0.027549822603899266
274.8000000000033,34.04944582939075,-1.2943213482302178,-0.027879856908812783
276.20000000000334,34.185143166064876,-1.2923403559818993,-0.02787986000000009
277.6000000000034,34.31778811703401,-1.293466277478636,-0.027879859997209433
279.0000000000034,34.45160495335899,-1.2922385439373192,-0.02823864672879184
280.4000000000034,34.5849591503579,-1.292508984367936,-0.028868090303526994
281.8000000000034,34.71947133869426,-1.2939054998252835,-0.02754983699007907
283.20000000000346,34.85286779556696,-1.290530953410801,-0.027549836997915023
284.60000000000343,34.98722739778027,-1.2915465007519735,-0.027879818581698856
286.00000000000347,35.12078603928667,-1.2899484021832597,-0.0278798369990092
287.4000000000035,35.25489150546215,-1.2919199815210483,-0.027879490421531816
288.80000000000354,35.388170516074965,-1.2908581114281554,-0.02853988177940847
290.20000000000357,35.52192592878014,-1.2903687379897884,-0.028539882999874422
291.60000000000355,35.65690196222722,-1.2890644048367832,-0.028536241052822042
293.0000000000036,35.79050173769458,-1.28959318138719,-0.029251533868783763
294.4000000000036,35.924305525749034,-1.2885928227467567,-0.030520060092258827
295.8000000000036,36.056472027561774,-1.2884392577096306,-0.030456482247764427
297.2000000000036,36.19170787168644,-1.2897610293149766,-0.03151019990934012
298.60000000000366,36.32507755918153,-1.2884773889629082,-0.02890865790363506
300.0000000000037,36.460037960069734,-1.2896626011179242,-0.029223005119086043
301.40000000000373,36.59338069569534,-1.288569292582238,-0.029859996203699612
302.8000000000037,36.7244672759967,-1.2890357885504387,-0.02985189911160857
304.20000000000374,36.862197010266456,-1.28940124672862,-0.031172768656521743
305.6000000000038,36.99569812153957,-1.2904524777971282,-0.03248237515624197
307.00000000000375,37.13075982758789,-1.2900697534860104,-0.032170113109164955
308.4000000000038,37.264396749651446,-1.2915445894696491,-0.03217011286634586
309.8000000000038,37.3986304303508,-1.2928713655113622,-0.030849782850578933
311.20000000000385,37.53316238684603,-1.2941659639245255,-0.030850112517590844
312.6000000000039,37.66839912868041,-1.2935635421785157,-0.03148639089952887
314.00000000000387,37.80212973747615,-1.2941451550118273,-0.03216060688858802
315.4000000000039,37.93684751644723,-1.2953256016820751,-0.03479420552764623
316.80000000000393,38.070312917455404,-1.296948787156317,-0.03352189873702427
318.2000000000039,38.20431775387309,-1.2994216849893272,-0.03347817305816436
319.60000000000394,38.33980706473442,-1.299883314724042,-0.034139916922980795
321.000000000004,38.47508750473921,-1.3016229299955218,-0.03413991719096021
322.400000000004,38.6092551424828,-1.3046837907458553,-0.0348000660949781
323.80000000000405,38.74421907843042,-1.3059080806035408,-0.036119859265765
325.200000000004,38.8787019397603,-1.3070347212684892,-0.036129640896268356
326.60000000000406,39.013716164514335,-1.309949331386977,-0.03480329802151205
328.0000000000041,39.14942698646245,-1.3124171104739422,-0.03480097949646144
329.40000000000407,39.28380853769189,-1.311800483888126,-0.03612005496122572
330.8000000000041,39.41897564562617,-1.3132327583876509,-0.03742181807985778
332.20000000000414,39.550947393622444,-1.315421947972375,-0.0371768605926146
333.6000000000042,39.68849586361831,-1.3162785379370923,-0.03841722972230954
335.0000000000042,39.82315668610486,-1.317969196063368,-0.03973990495818214
336.4000000000042,39.95789176509135,-1.319927743843927,-0.03973990500097635
337.8000000000042,40.09366686339337,-1.3205573192977373,-0.039968723278763996
339.20000000000425,40.22887968825928,-1.3219120820992547,-0.040404956598482755
340.60000000000423,40.36234478194597,-1.324150884490348,-0.04006131822975867
342.00000000000426,40.49806801896234,-1.3275905669549284,-0.04138044155324705
343.4000000000043,40.63362283696598,-1.3314457493887615,-0.042700040239340264
344.80000000000433,40.769077678038386,-1.3327203297201957,-0.042034794220329186
346.20000000000437,40.90479757927135,-1.33523884376494,-0.043360178997107646
347.60000000000434,41.03812760452474,-1.3384888048283448,-0.04336017900000044
349.0000000000044,41.174083955084505,-1.3404302270424222,-0.04336014596953541
350.4000000000044,41.30906488478837,-1.3398856452864356,-0.045655574406890054
351.8000000000044,41.445344721294994,-1.3421611140605758,-0.04698002796799372
353.2000000000044,41.577876593422225,-1.3434675526583808,-0.048302665268685985
354.60000000000446,41.714977014142306,-1.3474695665651202,-0.0470054137267768
356.0000000000045,41.850995270575496,-1.3479031232076855,-0.0497298722904409
357.4000000000045,41.986913521176994,-1.3485443410729059,-0.051040154953657435
358.8000000000045,42.12275746340472,-1.3496948513863647,-0.051705443096031534
360.20000000000454,42.258294322614745,-1.3497269778120027,-0.051698724588225886
361.60000000000457,42.393451390585966,-1.3486347071830207,-0.0537269722503364
363.00000000000455,42.52898675626805,-1.3483658938030618,-0.05499917949015032
364.4000000000046,42.66538376746429,-1.3489591540384318,-0.05499347003225541
365.8000000000046,42.800802249731916,-1.348744878956213,-0.056307793745574486
367.20000000000465,42.93720678476737,-1.3511804606109588,-0.060295107387703606
368.6000000000047,43.07465588432234,-1.35200451115977,-0.06035594402666922
370.00000000000466,43.20777690894314,-1.3547130516206767,-0.0643390709190026
371.4000000000047,43.346083356410446,-1.3573577236553498,-0.06602307871235213
372.80000000000473,43.48190065234456,-1.3592768908149353,-0.06872710375845292
374.2000000000047,43.61809037411078,-1.3617160579083878,-0.0726671394930527
375.60000000000474,43.7561282201501,-1.3622358365793679,-0.0755269600356181
377.0000000000048,43.892459083897016,-1.3634258207082133,-0.07816736203105323
378.4000000000048,44.02964070746877,-1.3693375292944587,-0.08212661267864751
379.80000000000484,44.164854731112534,-1.3690139313429401,-0.08475215452490747
381.2000000000048,44.30150970815591,-1.3719568666016195,-0.08902369896621565
382.60000000000485,44.437783888857986,-1.375729508867948,-0.09497129486109257
384.0000000000049,44.575307162814276,-1.377766320201715,-0.09992277413923256
385.40000000000487,44.71088320139992,-1.3783546858413207,-0.10554377090857114
386.8000000000049,44.848642890400725,-1.3813596343710581,-0.11028588628479596
388.20000000000493,44.985285424734116,-1.3846813305797316,-0.12100059673909458
389.60000000000497,45.12184916542983,-1.3859845183426276,-0.12529258976626556
391.000000000005,45.259274009496174,-1.3892638838373976,-0.1328519460028792
392.400000000005,45.39502047263229,-1.3892799443161536,-0.14196707622969607
393.800000000005,45.532133815457534,-1.3882978090540532,-0.15002982282221655
395.20000000000505,45.66845006503707,-1.385834154026931,-0.1552645998247426
396.600000000005,45.80359103504277,-1.3859605028787385,-0.16107959913846814
398.00000000000506,45.94162786124634,-1.3798361196386646,-0.17058444642615145
399.4000000000051,46.07753920650315,-1.3736193357232844,-0.17909731821882113
400.8000000000051,46.214952062333005,-1.3653672742817555,-0.18655389860343297
402.20000000000516,46.35217943122137,-1.3590970604188266,-0.1915331691142983
403.60000000000514,46.48769122781586,-1.3506488784768034,-0.1978781365738458
405.0000000000052,46.62373149005745,-1.340277962412413,-0.20351072637159184
406.4000000000052,46.75945262060394,-1.331185422167117,-0.20670989126498984
407.8000000000052,46.89675225656157,-1.3219192081920217,-0.21173189112037116
409.2000000000052,47.03358752469864,-1.3123025116271254,-0.21496621096304658
410.60000000000525,47.16986342953153,-1.3061736034354963,-0.21760620473993342
412.0000000000053,47.30576891463059,-1.300891524621801,-0.22022019735735388
413.4000000000053,47.44295992619618,-1.2942223859949056,-0.22156474485462896
414.8000000000053,47.579170978867786,-1.2931800717603932,-0.2228436654834396
416.20000000000533,47.716482954234316,-1.2919235704184113,-0.22551171796348957
417.60000000000537,47.85403790252056,-1.2895400550118423,-0.2254899113899831
419.00000000000534,47.99101508157603,-1.2888036026062115,-0.22646858823179317
420.4000000000054,48.12797866034116,-1.2913289502328607,-0.2264519750292786
421.8000000000054,48.26657440731585,-1.2907640395614044,-0.22812033513428265
423.20000000000545,48.402558498690084,-1.2914319986930507,-0.2268946224080679
424.6000000000055,48.53954732861364,-1.2908311932160415,-0.22909591141121233
426.00000000000546,48.67614396174255,-1.293705137053083,-0.23043014491912306
427.4000000000055,48.81371523116685,-1.2915180621090643,-0.23042830243278578
428.8000000000055,48.95105136463328,-1.2937697902061167,-0.2317501865716345
430.2000000000055,49.08842421738046,-1.297070522878196,-0.23076039039645924
431.60000000000554,49.227104028855734,-1.3023473982761649,-0.23208468808032423
433.00000000000557,49.36448985105234,-1.3083814119385557,-0.23323081042885407
434.4000000000056,49.501332106139145,-1.3139755713924393,-0.23338990803678428
435.80000000000564,49.639265905039814,-1.3152053472921335,-0.23438038683099727
437.2000000000056,49.77773308172547,-1.3176662869414786,-0.23569969689811732
438.60000000000565,49.915947426275146,-1.3226277043990469,-0.2353699275790384
440.0000000000057,50.05165670439788,-1.3245978829652463,-0.23570009990863783
441.40000000000566,50.189570791627645,-1.331411700497524,-0.2370198026099426
442.8000000000057,50.32888639655634,-1.3326337689451098,-0.23700729668166698
444.20000000000573,50.46738071687904,-1.3334235576129043,-0.2380013547766855
445.60000000000576,50.60504646841456,-1.335047068744269,-0.23931996604236794
447.0000000000058,50.74215318278174,-1.3370393498934459,-0.23932611094158496
448.4000000000058,50.88113909355467,-1.3388224195071938,-0.23799995510209504
449.8000000000058,51.01898708010627,-1.3393782726484948,-0.238989752675566
451.20000000000584,51.157045220213654,-1.3433590449935924,-0.24060630440353137
452.6000000000058,51.293573208558186,-1.3456114048431376,-0.2406397360786694
454.00000000000585,51.43299165025315,-1.347553272421383,-0.24063984631433222
455.4000000000059,51.57003606896331,-1.351813189751637,-0.23965823949642306
456.8000000000059,51.7086601680559,-1.3525001065466766,-0.24229015074675653
458.20000000000596,51.84717075489889,-1.3558185499025,-0.2436069113724595
459.60000000000593,51.98521411641609,-1.3570239170006193,-0.2436081373693737
461.00000000000597,52.12164432013682,-1.3613042696313469,-0.24393769826014378
462.400000000006,52.26185799265135,-1.365276758908058,-0.24436998497205842
463.800000000006,52.399170930145495,-1.3653500479356837,-0.24569007695030498
465.200000000006,52.537733417076836,-1.366571342647057,-0.24690836324161003
466.60000000000605,52.67686116726763,-1.3658049798067424,-0.24665432716162394
468.0000000000061,52.8146972228203,-1.3661661591663055,-0.24799986014724773
469.4000000000061,52.952281249199224,-1.3689468825110056,-0.24859018736448935
470.8000000000061,53.090781598788354,-1.3696641863208423,-0.24769922334784056
472.2000000000061,53.229267937928086,-1.3737729805397616,-0.24798986673284285
473.60000000000616,53.36713296336901,-1.3721007726764818,-0.24883574800333053
475.00000000000614,53.504715105714105,-1.3723465873240983,-0.2480659075453988
476.4000000000062,53.643984726333855,-1.3755440958083933,-0.25117787878268993
477.8000000000062,53.78220410588424,-1.375938974792678,-0.25117992799998046
479.20000000000624,53.92209209604408,-1.378133268118862,-0.25117992800191935
480.6000000000063,54.06048205800653,-1.3791252714525777,-0.25126460837063647
482.00000000000625,54.19894799510476,-1.3821999757703984,-0.2531323331283213
483.4000000000063,54.33917103154498,-1.383640011959168,-0.25315011843610025
484.8000000000063,54.47702087270112,-1.385135458989176,-0.2525007854702359
486.2000000000063,54.61702042852154,-1.3853351957423272,-0.25382220732903793
487.60000000000633,54.75620313203418,-1.3863040700023193,-0.25480984646975946
489.00000000000637,54.896327621717354,-1.3889673532056763,-0.25480985212396456
490.4000000000064,55.03313275917809,-1.3899007203142941,-0.2541593739921377
491.80000000000643,55.173937238990376,-1.387580137691478,-0.2544794788082352
493.2000000000064,55.313623367123725,-1.3886633785724138,-0.2557901088945158
494.60000000000645,55.45097036081873,-1.3849576687593468,-0.2556354687584652
496.0000000000065,55.590709213573625,-1.3793662579370976,-0.25711007262959606
497.40000000000646,55.72667459771559,-1.373301344743224,-0.25579004760681734
498.8000000000065,55.86695566223355,-1.3699782514161742,-0.25711014315196
500.2000000000065,56.007009885371346,-1.371404171258359,-0.2571101210000011
501.60000000000656,56.146193678506066,-1.3731254170069203,-0.25711012099991315
503.0000000000066,56.284942963164575,-1.3731651502436357,-0.25709950869745635
504.40000000000657,56.424816911459146,-1.3784883720726349,-0.25710982301814234
505.8000000000066,56.564091993229134,-1.3805739747497028,-0.2571107110910402
507.20000000000664,56.70315121883158,-1.3801667454470525,-0.2584198806490887
508.6000000000066,56.84239309007352,-1.3787578931143574,-0.25841987053678483
510.00000000000665,56.981552850453944,-1.3790512950975784,-0.2584666776690794
511.4000000000067,57.120705926476944,-1.3800380272420738,-0.2584199802036107
512.8000000000068,57.26053004790195,-1.3791066361236524,-0.25914737220643413
514.2000000000068,57.39906407289708,-1.3782840170873376,-0.2597400624382935
515.6000000000067,57.537089377437255,-1.375311052139577,-0.2587500462581569
517.0000000000068,57.67782788954081,-1.375306704416175,-0.2576963929852085
518.4000000000068,57.817618374126184,-1.3731241271337102,-0.2590900859864087
519.8000000000068,57.95617440875803,-1.374754662209925,-0.2590846512636653
521.2000000000069,58.09625791381651,-1.376265565479866,-0.2604001483849889
522.6000000000068,58.234880164304194,-1.3764899486188957,-0.2600703853013835
524.0000000000068,58.374738880153565,-1.3820761281605605,-0.2600738006204555
525.4000000000069,58.513894010515905,-1.3825279607594263,-0.2611911140270413
526.8000000000069,58.65365287594511,-1.3868049353126695,-0.25940463254883994
528.2000000000069,58.79313498881377,-1.3902265785136398,-0.2595923256575001
529.600000000007,58.93146847690354,-1.3960397800170823,-0.2620954466777987
531.0000000000069,59.072571766036106,-1.4000744134816927,-0.26072998201454833
532.4000000000069,59.2130739718306,-1.4011292822344437,-0.26072841520486545
533.800000000007,59.35292719703026,-1.405516228661856,-0.26071829503980215
535.2000000000071,59.4921881748611,-1.4072925228682487,-0.26072998476359244
536.6000000000071,59.63274283863199,-1.4109910491122326,-0.26204903689997083
538.000000000007,59.77186537353337,-1.41243331563766,-0.26007991047866463
539.4000000000071,59.91224357536699,-1.4182786042021935,-0.26105707976202686
540.8000000000071,60.05272499817224,-1.4211651275855712,-0.2610608093336504
542.2000000000071,60.193614963778785,-1.4228172283660117,-0.2610631078394734
543.6000000000072,60.33303028487613,-1.4255339093537136,-0.2623804889422616
545.0000000000072,60.47338420549833,-1.4302966153016263,-0.2610812992809337
546.4000000000071,60.61455428420384,-1.4320370543830983,-0.26170764278047853
547.8000000000072,60.75448219551826,-1.4353190416728971,-0.2617201857226559
549.2000000000072,60.89362623285884,-1.438341104173953,-0.26138468962550654
550.6000000000072,61.03408556338598,-1.440872851900086,-0.26270987794412104
552.0000000000073,61.17480191329533,-1.4448345548945383,-0.2623775760572702
553.4000000000073,61.31483516310725,-1.4483971188523992,-0.26369996953864794
554.8000000000073,61.45558778553996,-1.4507272770871233,-0.2623878330942464
556.2000000000073,61.59639114714161,-1.4531274470657234,-0.26503399218309553
557.6000000000073,61.73564321931942,-1.4563178058665913,-0.2646921003831695
559.0000000000074,61.875969986813736,-1.4578481669121521,-0.2646766529977107
560.4000000000074,62.01615163748738,-1.4613706337614505,-0.26469274520326014
561.8000000000075,62.15703435177316,-1.4637012143941028,-0.2646400300340863
563.2000000000074,62.2963583533853,-1.4679855032180873,-0.26435017502929625
564.6000000000074,62.437862162505645,-1.4730161308110739,-0.26431670264156315
566.0000000000075,62.57801534354663,-1.476381075096396,-0.2636917034730719
567.4000000000075,62.71830173229735,-1.4767193685955267,-0.2651895026658879
568.8000000000075,62.85710527346204,-1.4817008687490647,-0.2647157665022246
570.2000000000075,63.00001027898024,-1.4869553720850182,-0.26730901937480134
571.6000000000075,63.14030452141013,-1.4919851017575474,-0.26599997287879384
573.0000000000075,63.280700021218614,-1.5139922506308494,-0.2659999119998462
574.4000000000076,63.421965173454936,-1.5429128866749333,-0.2659678663916867
575.8000000000076,63.5617864757219,-1.5033831026171984,-0.2673214222969911
577.2000000000077,63.70238076465142,-1.4931161560380666,-0.26599997855650237
578.6000000000076,63.84285318621993,-1.4928542652388508,-0.2659999686850072
580.0000000000076,63.98300985364148,-1.4939634305872143,-0.2673199838303195
581.4000000000077,64.1246463026881,-1.4947194640978547,-0.26732006794520435
582.8000000000077,64.26571365587849,-1.4970305074926908,-0.2673192181531645
584.2000000000078,64.40599029407332,-1.4990421085912216,-0.2673202759779163
585.6000000000078,64.54536426489497,-1.501592956901049,-0.26801455130118157
587.0000000000077,64.68770943166358,-1.5036169537967257,-0.2669888701009566
588.4000000000078,64.82885465606608,-1.5050342700118906,-0.2682991885774859
589.8000000000078,64.96827737937167,-1.5088611799302902,-0.2692734560316805
591.2000000000078,65.11152526579095,-1.5074846902888157,-0.26962595312524584
592.6000000000079,65.25201437602146,-1.511391371590066,-0.2696207418845189
594.0000000000078,65.39236011283461,-1.512162708453709,-0.26962041184574037
595.4000000000078,65.53315758620239,-1.5156259085165686,-0.27094791063408774
596.8000000000079,65.6748754578668,-1.5169228993841901,-0.26962010333682684
598.2000000000079,65.81546903246789,-1.522161803676499,-0.26810873876129726
599.600000000008,65.95592681798851,-1.5261168544267276,-0.27071959772306675
601.000000000008,66.09655227128243,-1.5282047841811057,-0.271050250749552
602.4000000000079,66.23853523082377,-1.5310962504937826,-0.2707167098679255
603.800000000008,66.38005243386078,-1.5377951012132818,-0.2710501183414551
605.200000000008,66.5200511876981,-1.5433519509782585,-0.2713780727528592
606.6000000000081,66.66180770744786,-1.543005608454542,-0.2713807950656677
608.0000000000081,66.8019354461626,-1.5495862660489672,-0.2746783697623427
609.400000000008,66.94442841938367,-1.5561781794230174,-0.27379996166152587
610.8000000000081,67.08541430522887,-1.562423408048717,-0.27367426626831204
612.2000000000081,67.22663125620457,-1.571140888036527,-0.27510990800014623
613.6000000000081,67.36835611242417,-1.578360890737363,-0.2751097465062582
615.0000000000082,67.51056928158621,-1.584766820011777,-0.2760834765816087
616.4000000000082,67.65065953663058,-1.5887902036457753,-0.2764300918699605
617.8000000000081,67.79239395814982,-1.5906572403799646,-0.27739975641723236
619.2000000000082,67.9327658981198,-1.593830302697495,-0.2777529781180834
620.6000000000082,68.0742761787363,-1.6033231888215693,-0.27757736398830746
622.0000000000083,68.21598003724753,-1.6093489030512047,-0.2790616480246686
623.4000000000083,68.35711291602851,-1.6179664337992912,-0.279581895655562
624.8000000000083,68.49967402854,-1.6260510379183342,-0.2803799888834977
626.2000000000083,68.64148129913636,-1.633709057581207,-0.2817173295828588
627.6000000000083,68.78459669071962,-1.6437272873512931,-0.28301109646560985
629.0000000000084,68.92487932489256,-1.654897361491405,-0.2829955036424714
630.4000000000084,69.06710739967856,-1.6626016158231298,-0.285137759718435
631.8000000000084,69.20966493974738,-1.6746952280537173,-0.2869625149415702
633.2000000000085,69.35127345636826,-1.6841675654449493,-0.28697615288047995
634.6000000000084,69.493611984806,-1.6935929876968967,-0.28961577880236655
636.0000000000084,69.63542269662288,-1.7029625547571356,-0.28995215858266166
637.4000000000085,69.77659923353389,-1.7105986377184221,-0.29123581069015936
638.8000000000085,69.91773091854961,-1.7184152946098683,-0.2927713239679157
640.2000000000085,70.06000360981047,-1.72649556423072,-0.29387831436885437
641.6000000000085,70.20194096054658,-1.7361346993309186,-0.2965197559159827
643.0000000000085,70.3436592596663,-1.7518763379278184,-0.2991523570973311
644.4000000000086,70.48523771711524,-1.762312390502541,-0.2991493205752356
645.8000000000086,70.62755472137205,-1.7774218506771362,-0.3004715926188868
647.2000000000086,70.76906349515495,-1.7905640672842784,-0.3018214784218407
648.6000000000087,70.91025257029067,-1.8100591811632203,-0.30527615612697856
650.0000000000086,71.05160952129211,-1.8257960653333398,-0.3071773727672724
651.4000000000087,71.19402662320655,-1.842548563531612,-0.3111255957934027
652.8000000000087,71.33642442186479,-1.8600380361447058,-0.31246440681089505
654.2000000000087,71.47835373504995,-1.8796898686199894,-0.3164966456958864
655.6000000000088,71.62055826824503,-1.8961849231772991,-0.31847611935651843
657.0000000000088,71.76323356772109,-1.9156194158531374,-0.32064834668612674
658.4000000000087,71.90613233484702,-1.9324851545671242,-0.32438801324624933
659.8000000000088,72.04805116759816,-1.9516457850887605,-0.32933956753354865
661.2000000000088,72.19165095478225,-1.9732454192318303,-0.332519584543415
662.6000000000088,72.33327638951887,-1.9974538368459975,-0.3354979614809803
664.0000000000089,72.47670940310586,-2.017311522235328,-0.3381842187250217
665.4000000000088,72.61916806839085,-2.039849304869258,-0.34218981749517274
666.8000000000089,72.7613636425938,-2.0635287169340457,-0.3463712553275218
668.2000000000089,72.90370332613547,-2.0895056108070937,-0.3527620461997705
669.6000000000089,73.04634350487773,-2.113957819359482,-0.35483333500070025
671.000000000009,73.189170000001,-2.141170000000065,-0.3597655257530268
672.400000000009,73.33167304845658,-2.167434585161663,-0.3674058824143507
673.800000000009,73.47453022068476,-2.19297257840443,-0.3725906231270959
675.200000000009,73.61752457141836,-2.2189233301699107,-0.37770478359062665
676.600000000009,73.76061113690956,-2.2504144181498282,-0.38325339649911694
678.0000000000091,73.90407363927626,-2.2831268773741926,-0.3902178535092524
679.4000000000091,74.04647322202109,-2.310818487333887,-0.39613868774076755
680.800000000009,74.18805449642726,-2.337751689082848,-0.40333664516489254
682.2000000000091,74.33045341561336,-2.3735827145437254,-0.40882527199570307
683.6000000000091,74.47509049661429,-2.4048442128591723,-0.41750483495913127
685.0000000000091,74.61742308498098,-2.441900322808984,-0.42129837756417166
686.4000000000092,74.76080282220579,-2.479458720681482,-0.4333261584798471
687.8000000000092,74.90355625305871,-2.518931739912958,-0.4433782204222618
689.2000000000093,75.04635478571775,-2.556245859573187,-0.45050133231686207
690.6000000000092,75.18927182391658,-2.591390245084067,-0.45835385668538287
692.0000000000092,75.3332886090524,-2.6366903002632105,-0.46827298286119623
693.4000000000093,75.47703530072961,-2.6774078361771667,-0.4787206851186365
694.8000000000093,75.62008660326902,-2.719338415657952,-0.48971169720763275
696.2000000000094,75.76335168621766,-2.7678898338450217,-0.5009249241655964
697.6000000000093,75.90600583331089,-2.811084509562078,-0.5115196090042513
699.0000000000093,76.05087224576965,-2.861196455566968,-0.5222454424214744
700.4000000000094,76.19443330845658,-2.9062646355115924,-0.5363750195807686
701.8000000000094,76.33927490235233,-2.955321270930129,-0.5476096589067976
703.2000000000094,76.48352420644545,-3.008734683348392,-0.5591972940771481
704.6000000000095,76.62751982225652,-3.0665135602679037,-0.5727443458558379
706.0000000000094,76.77149222617422,-3.1130605357412557,-0.586820487074112
707.4000000000094,76.91499619440248,-3.1660322965830243,-0.6012742702859288
708.8000000000095,77.05878739121566,-3.2188890690622007,-0.6155044021935274
710.2000000000095,77.20352346027578,-3.269894293443981,-0.6314764241171527
711.6000000000096,77.34767107692954,-3.324071000134088,-0.6464582584185155
713.0000000000095,77.4914876243435,-3.3800587480434165,-0.6640829735880796
714.4000000000095,77.63606823263069,-3.428437253143862,-0.6800901281595646
715.8000000000096,77.78016839846612,-3.476666189068009,-0.6980777790870469
717.2000000000096,77.92387098651449,-3.5231950436801682,-0.7149386069146737
718.6000000000097,78.06764378675129,-3.5718900823613895,-0.7320170450135852
720.0000000000097,78.21241156189035,-3.6181417124747,-0.7526134849983555
721.4000000000096,78.35399376419818,-3.6608318143041627,-0.7728005892140084
722.8000000000097,78.49896502512608,-3.7186933299901206,-0.7931478406740098
724.2000000000097,78.6420565091483,-3.7764490696660813,-0.8137627931144524
725.6000000000097,78.784509170507,-3.83434774386513,-0.8344669858490334
727.0000000000098,78.92981904191993,-3.8941445329282094,-0.8554942222794653
728.4000000000098,79.07147618018317,-3.9500780686813486,-0.8783801503429376
729.8000000000097,79.21752249067443,-4.005582985947578,-0.8998803871994965
731.2000000000098,79.3609821629873,-4.061446671700567,-0.9260299645541137
732.6000000000098,79.5047408766186,-4.112149732865836,-0.9495275808500816
734.0000000000099,79.64943004753607,-4.1609420435444715,-0.97485212478849
735.4000000000099,79.79147942530984,-4.198388277025758,-0.9972535574727144
736.8000000000098,79.93657204104889,-4.228580426829064,-1.0204607552950753
738.2000000000099,80.07948019248106,-4.242363810069139,-1.0440772278721746
739.6000000000099,80.22159933783841,-4.249953689210852,-1.0732773800160271
741.00000000001,80.3644760797468,-4.241746152594189,-1.096720079868668
742.40000000001,80.50640333259224,-4.21839028480097,-1.121268402478322
743.80000000001,80.64790286764112,-4.1714488139180865,-1.1464042614364955
745.20000000001,80.78826391255711,-4.094767715006278,-1.171757017802502
746.60000000001,80.92838266681443,-3.97893627003215,-1.1935328590116123
748.00000000001,81.06723609208649,-3.8136266865241106,-1.2157256412409851
749.4000000000101,81.20244212565191,-3.5823819641714,-1.2342538859375543
750.8000000000101,81.33733051990755,-3.2698975880470984,-1.2507004630473646
752.20000000001,81.47126117546064,-2.9084324180273886,-1.2655881609550756
753.6000000000101,81.60427750230605,-2.5568751085443213,-1.2736943797533327
755.0000000000101,81.73973750913434,-2.256909611260343,-1.2822199800443128
756.4000000000102,81.87729460313506,-2.031345078310908,-1.288342502919115
757.8000000000102,82.01484679556921,-1.8836632455042204,-1.2912945709902535
759.2000000000102,82.15649641793398,-1.7870200864184402,-1.291932150160234
760.6000000000103,82.2977643268418,-1.7257487189213414,-1.2945873114972573
762.0000000000102,82.44004181430248,-1.6940776028468807,-1.2939004552809665
763.4000000000103,82.58089006120369,-1.6732567240385734,-1.2947060779790576
764.8000000000103,82.72366266018904,-1.6644839025931302,-1.296087448786405
766.2000000000103,82.86659383665045,-1.660903499536301,-1.2952174479982919
767.6000000000104,83.00953074696586,-1.6599469067981178,-1.2965398870262566
769.0000000000103,83.15123293780492,-1.6616858179323528,-1.2965396954708455
770.4000000000103,83.2948807837989,-1.6619577172161035,-1.297828371121461
771.8000000000104,83.43800818583499,-1.6659513841996734,-1.295549910018769
773.2000000000104,83.58063327165428,-1.6657752031477082,-1.298301429886092
774.6000000000104,83.72390349040361,-1.669320203322166,-1.2968599814900532
776.0000000000105,83.86656871599746,-1.6660171717526204,-1.296859977000028
777.4000000000104,84.0101190193202,-1.6683231731881898,-1.296867007172882
778.8000000000105,84.15317511599697,-1.6657121905583911,-1.2965400414544939
780.2000000000105,84.29584312910636,-1.670721879863447,-1.2965399449945307
781.6000000000105,84.4377873492605,-1.6773989473514677,-1.2958801175873145
783.0000000000106,84.58056922125341,-1.677097230775651,-1.2983399466758034
784.4000000000106,84.72321737050594,-1.6830014357658212,-1.2984866362697964
785.8000000000106,84.86553100300851,-1.6838636436261347,-1.2972002430133913
787.2000000000106,85.00797050172213,-1.686683424101969,-1.2972001839975378
788.6000000000106,85.15317107593437,-1.6874435197265851,-1.297191759347144
790.0000000000107,85.2955333171776,-1.6875094968841626,-1.2962100248429014
791.4000000000107,85.44033893990985,-1.6872288850360908,-1.2950077232213935
792.8000000000106,85.58285702280439,-1.687174773088144,-1.2966401713913625
794.2000000000107,85.72677671696114,-1.689152743700135,-1.2966401710003086
795.6000000000107,85.87050552503469,-1.687812893188073,-1.2971224077278998
797.0000000000107,86.01403210489065,-1.6912065714250293,-1.297309843054407
798.4000000000108,86.15632949948571,-1.6964334631527793,-1.2966498857989959
799.8000000000108,86.29985360383269,-1.6963273774232996,-1.297639930716377
801.2000000000108,86.44287544128743,-1.6988524763375754,-1.2963075303775424
802.6000000000108,86.58560603398448,-1.70390076997781,-1.2961630031255882
804.0000000000108,86.72982826222751,-1.7106246860197754,-1.2969837022432196
805.4000000000109,86.87332391232236,-1.7127242072296798,-1.29433901145131
806.8000000000109,87.01751218874338,-1.7148360352490537,-1.2956550692113233
808.200000000011,87.16070661028857,-1.711068886504643,-1.296296206001962
809.6000000000109,87.30320948444492,-1.7118849677056198,-1.294321269786364
811.0000000000109,87.44713186035858,-1.7132560697118806,-1.2962940774668965
812.400000000011,87.590839045315,-1.7125140097212788,-1.2976300245713812
813.800000000011,87.73357023338734,-1.7201750386475823,-1.296368428231116
815.200000000011,87.87721173125121,-1.7241050464625807,-1.2963199513289525
816.600000000011,88.02094999393742,-1.7266876983982227,-1.2969873324166135
818.000000000011,88.16381128163891,-1.7292825880032938,-1.2976398825331321
819.400000000011,88.30686990264584,-1.7282143850660736,-1.2963198256262727
820.8000000000111,88.44990341012583,-1.7283365659146714,-1.2963198618622522
822.2000000000111,88.59350927227653,-1.7348286184531532,-1.2963199372686822
823.6000000000112,88.73552993701207,-1.7357242566031537,-1.2976398243630096
825.0000000000111,88.88020152058385,-1.7359960574049185,-1.2956714251686128
826.4000000000111,89.02286397964049,-1.7413927834661982,-1.294351030808155
827.8000000000112,89.16615987991852,-1.7444588714720712,-1.2966401130747562
829.2000000000112,89.310304430785,-1.7458023905143114,-1.297959586927973
830.6000000000113,89.45412747890713,-1.7448007306443885,-1.297958814645361
832.0000000000113,89.59687576254407,-1.7485525238570858,-1.2966400320341855
833.4000000000112,89.74099395016063,-1.7514528326145793,-1.2967711104631778
834.8000000000113,89.88382476143535,-1.7561070869515099,-1.2966636438050085
836.2000000000113,90.02773515953947,-1.7590853940986906,-1.296650124310771
837.6000000000113,90.17047471473677,-1.7593896684205566,-1.297969323409657
839.0000000000114,90.31320846962353,-1.759938032673755,-1.2979698148595218
840.4000000000113,90.45738117379716,-1.7615278652100144,-1.2956581913721426
841.8000000000113,90.60065758765393,-1.7617083942569518,-1.295660161685066
843.2000000000114,90.74427191701166,-1.764723753433885,-1.296889394924488
844.6000000000114,90.88720627129906,-1.7662379840244082,-1.2961558260226198
846.0000000000115,91.03120733928914,-1.7711898196491884,-1.2969699049981491
847.4000000000115,91.17511223072033,-1.7754879641766825,-1.296969904992617
848.8000000000114,91.31838455348029,-1.779888010186401,-1.2982860430862964
850.2000000000115,91.46072322049964,-1.7885624884256521,-1.2974505850382578
851.6000000000115,91.60537531041977,-1.7899189447074926,-1.296282744794361
853.0000000000116,91.74823337721243,-1.793138260406739,-1.2990599211209535
854.4000000000116,91.89181788586832,-1.795142980672011,-1.2967619049288346
855.8000000000116,92.03529830079404,-1.7987705445965503,-1.2980780206368685
857.2000000000116,92.17864061109297,-1.8016978211853503,-1.300718426516097
858.6000000000116,92.32208196532119,-1.8021358973710844,-1.2990607265998353
860.0000000000116,92.46556771458458,-1.8027219568525292,-1.2980136435030425
861.4000000000117,92.60916770143291,-1.8067600509651986,-1.2975988523890063
862.8000000000117,92.75397018203007,-1.8114152291787518,-1.2964200760035096
864.2000000000116,92.89756218735164,-1.8117849805567259,-1.295161954768394
865.6000000000117,93.04079732128065,-1.8146461998380112,-1.2972248493695773
867.0000000000117,93.18482586736273,-1.8148628484470166,-1.2977498589984684
868.4000000000118,93.32958210443665,-1.8194370483973243,-1.2977498565440229
869.8000000000118,93.47288796409498,-1.8187777636805835,-1.299069981035466
871.2000000000118,93.6169760235144,-1.8224751254447629,-1.297749951705479
872.6000000000118,93.76029214742621,-1.8233739020398152,-1.2977500623743867
874.0000000000118,93.90508842396939,-1.8314575749920148,-1.296525511441787
875.4000000000119,94.04815756814197,-1.8365382909976458,-1.2977399979798685
876.8000000000119,94.19262946889233,-1.8429091477220145,-1.2990601114738056
878.2000000000119,94.33529100834127,-1.8479098606231044,-1.2990601100805002
879.600000000012,94.47762512847375,-1.8502050071841216,-1.2992968551678685
881.0000000000119,94.62343955187215,-1.851208248670244,-1.2987302262680362
882.4000000000119,94.7670422168726,-1.8529083539202893,-1.2977501600536288
883.800000000012,94.91076407154256,-1.8607556314747107,-1.2980701315849439
885.200000000012,95.05408419527762,-1.8636248570991316,-1.2980702844440812
886.600000000012,95.19773163404719,-1.8686228641756588,-1.2969921398893143
888.000000000012,95.3412875785037,-1.877666002245249,-1.2970898699996476
889.400000000012,95.48642494927122,-1.8840054079670052,-1.2970898671606874
890.8000000000121,95.62831544670661,-1.8859499367000505,-1.298155830637414
892.2000000000121,95.77169995494447,-1.889441772923951,-1.29674993701315
893.6000000000121,95.91788069066926,-1.8935727602718155,-1.2980851114186067
894.0000000000122,95.95848901568557,-1.8926023486688788,-1.2980005383480417