File: 01_Data/EIFS_Coating/STA/N2/10K_min/EIFS_Coating_STA_N2_10KData_230915_R1.csv
##Temp./Â°C,Time/min,DSC/(mW/mg),Mass loss/mg
41.0,10.840596034465833,-2.3777022796251908,0.04489456073917486
42.40000000000002,11.17896475252816,-2.308481397506299,0.04477316702892642
43.80000000000004,11.419771587354218,-2.2605710938469215,0.04313742767434636
45.20000000000006,11.623032953698136,-2.223359569952896,0.043763065238874965
46.60000000000008,11.810244874828271,-2.1930249005092786,0.04379479204022774
48.0000000000001,11.984863293808575,-2.171284634247532,0.04367229228562275
49.40000000000012,12.150106429072874,-2.1520322053087875,0.04401277117303204
50.80000000000014,12.312352327394915,-2.137046137532467,0.04392320014659479
52.20000000000016,12.470545847599924,-2.1233471338890446,0.04370295629647325
53.60000000000018,12.626703678397382,-2.112217011034998,0.04418440036446336
55.0000000000002,12.78012423608028,-2.10458059309892,0.04318206558774218
56.40000000000022,12.934055090713882,-2.0962170295482614,0.04239976729131101
57.80000000000024,13.086724033187885,-2.087957300171457,0.04335935040469607
59.20000000000026,13.235803989802392,-2.0809557946795225,0.044076152775428756
60.60000000000028,13.385867068229901,-2.07442140788022,0.04464985002348687
62.0000000000003,13.534557970068299,-2.0695501936042584,0.043700121245600076
63.40000000000032,13.683036166722927,-2.063126844503987,0.04374108025233614
64.80000000000034,13.82884331762572,-2.0579161941254815,0.04370007501047457
66.20000000000036,13.973405954995062,-2.0518381753280175,0.04373651778071519
67.60000000000038,14.120060994762559,-2.049106458854076,0.043700478058071646
69.0000000000004,14.263437515710976,-2.043826663833409,0.04370581172770471
70.40000000000042,14.408791039914595,-2.0393805808045777,0.043699905326094246
71.80000000000044,14.551808610910586,-2.034459455918735,0.04237485675901764
73.20000000000046,14.693460711343958,-2.0287388582995836,0.041392396559463585
74.60000000000048,14.835867291219152,-2.023940381027476,0.0410686802724709
76.0000000000005,14.978625409981234,-2.0194352256650014,0.041056194408838564
77.40000000000052,15.11874108831506,-2.0110103621066187,0.04107187853611327
78.80000000000054,15.257223725262696,-2.0050318170573154,0.04006979304846414
80.20000000000056,15.400184158007939,-1.9941001994932068,0.03969925500289673
81.60000000000058,15.541485060395496,-1.9822167925675227,0.03917717248432995
83.0000000000006,15.678974422263007,-1.968692320123401,0.03809888399437433
84.40000000000062,15.818892210802089,-1.9525744923995867,0.038431946054027666
85.80000000000064,15.957445466080644,-1.9368614079598996,0.03843130954044849
87.20000000000066,16.095766688780504,-1.922308021662789,0.03876241065492625
88.60000000000068,16.23437536561884,-1.9121829643198547,0.038742711065160584
90.0000000000007,16.372034208529385,-1.9021799179358103,0.03776823104943894
91.40000000000072,16.508326993472068,-1.892474219768957,0.03777041421422256
92.80000000000074,16.647306257733312,-1.883976129381018,0.03892859947653182
94.20000000000076,16.78371713067212,-1.8748855688336794,0.03840315973276587
95.60000000000078,16.92037725674941,-1.8665534316753003,0.037448704183724146
97.0000000000008,17.0581610588503,-1.8575065447453634,0.037781472936079474
98.40000000000082,17.19443361838911,-1.8495648552151656,0.03843079538395244
99.80000000000084,17.332463879768024,-1.84334273188313,0.03842860262351344
101.20000000000086,17.467949469613053,-1.8371865992023846,0.03743989677426729
102.60000000000088,17.604315199705894,-1.829293671725881,0.0387597286096546
104.0000000000009,17.740370664646523,-1.8263889096011163,0.03926190347673675
105.40000000000092,17.87456484338375,-1.8194361274524034,0.0397533121410536
106.80000000000094,18.013130476082473,-1.8126455462900175,0.038429799364887884
108.20000000000095,18.147435042431354,-1.8068566417150005,0.03695547057326598
109.60000000000097,18.281164028834205,-1.7995461529936885,0.0360157899219935
111.000000000001,18.419361328739676,-1.7918737352752305,0.03777403154676762
112.40000000000101,18.5539094035946,-1.785160473461637,0.037110036177761874
113.80000000000103,18.69056702832868,-1.77675627375456,0.035784174369859034
115.20000000000105,18.82500755435009,-1.770128025798672,0.03842644159860553
116.60000000000107,18.960003914167864,-1.7636115284859917,0.03710998288573908
118.0000000000011,19.097020354521813,-1.757286444842005,0.03842995876690747
119.40000000000111,19.23142804503005,-1.7530211082619453,0.03824240321156491
120.80000000000113,19.366500757735857,-1.7451987522858823,0.038429816287067986
122.20000000000115,19.499028873984273,-1.7395368128414321,0.039762774191897776
123.60000000000117,19.637260879092928,-1.7343350247907907,0.03842799305260769
125.0000000000012,19.772379256051003,-1.7299016066724262,0.03843020985794654
126.40000000000121,19.906444881839846,-1.7251172572998053,0.03974880348983412
127.80000000000123,20.04103639576275,-1.720689641648841,0.039727058646807034
129.20000000000124,20.175865171519728,-1.714489384440584,0.03815511989477249
130.60000000000127,20.310405401104973,-1.7095713471254308,0.039085846185216155
132.0000000000013,20.445522150916265,-1.7015369856082045,0.03777012624900111
133.4000000000013,20.580934438041997,-1.6971409469759016,0.03777201531500518
134.80000000000132,20.716280877016366,-1.6911214028854338,0.03875028359873722
136.20000000000135,20.85010408352625,-1.6874341418333874,0.04007009230346448
137.6000000000014,20.98436195193412,-1.6837717138195893,0.039143661130072616
139.0000000000014,21.118556015117147,-1.6803207356930119,0.037770832208873895
140.4000000000014,21.25280387707983,-1.6748351330432951,0.03908992006538048
141.80000000000143,21.385186901274682,-1.6720026402050274,0.04035691513000206
143.20000000000147,21.52142339639576,-1.666378022447685,0.03949922502585945
144.60000000000147,21.654432815325983,-1.6618130191633287,0.0390876323881586
146.00000000000148,21.788598917338042,-1.6572919145263818,0.039097317072131155
147.4000000000015,21.92264854055309,-1.6538972545436024,0.040074941998318625
148.80000000000155,22.055853956437936,-1.6481067796228508,0.03787683788099372
150.20000000000155,22.190314136227983,-1.6436634132459609,0.03876224928487915
151.60000000000156,22.323849327238992,-1.6405297362551414,0.04073036453002743
153.0000000000016,22.456473763673298,-1.6364091442330926,0.04072996800003592
154.40000000000163,22.589832347054177,-1.6321013608995294,0.0407288544342026
155.80000000000163,22.72331828287979,-1.6302053786661146,0.04137483384364149
157.20000000000164,22.854350016956975,-1.6240892143675132,0.03908937005923452
158.60000000000167,22.991029736355173,-1.6211484544432917,0.039090185966308866
160.0000000000017,23.123889315687578,-1.6173734113204432,0.037769927640879164
161.4000000000017,23.25596794354418,-1.6120777430267166,0.03908984766601575
162.80000000000172,23.390175478871885,-1.6104802247237469,0.03908803970112862
164.20000000000175,23.524374680197543,-1.6070566275344165,0.040374243554393896
165.60000000000178,23.65704961024755,-1.604482397232769,0.03907996000988723
167.0000000000018,23.791075029454348,-1.5992604458727682,0.039760098464745486
168.4000000000018,23.92387491745553,-1.5968579032097954,0.040399812660360634
169.80000000000183,24.05750810675737,-1.5927240850694093,0.04007978510424026
171.20000000000186,24.191093585216525,-1.5904291206689503,0.04041000582302656
172.60000000000187,24.324517781481077,-1.587501710994385,0.03942009010578129
174.00000000000188,24.459694744321695,-1.5852841683141425,0.03942008000000019
175.4000000000019,24.58935641633368,-1.5826189914540756,0.03942003338208533
176.80000000000194,24.724046205080228,-1.5784312088956491,0.04048731315991949
178.20000000000195,24.86009300003142,-1.5759742881000205,0.039419917956595274
179.60000000000196,24.992826991853924,-1.573651527629343,0.03941994400000137
181.000000000002,25.126030362387244,-1.5717823610842896,0.03941994376012836
182.40000000000202,25.260275749945055,-1.569648704639044,0.03909070044043084
183.80000000000203,25.394563314517324,-1.564798836209424,0.03974613132705773
185.20000000000203,25.526201700528706,-1.5622453826181049,0.03907347137838579
186.60000000000207,25.66208981221315,-1.5623055485091857,0.040399871823126876
188.0000000000021,25.794439901217018,-1.5577958591473615,0.03956689410790881
189.4000000000021,25.926943444361406,-1.5560695113456093,0.04008204646860403
190.80000000000211,26.061008873248753,-1.5549040048456586,0.040079904591331594
192.20000000000215,26.193673675138506,-1.5513477207649737,0.038759877496498785
193.60000000000218,26.327035571337923,-1.548937530784406,0.038087556728481076
195.0000000000022,26.461073349161108,-1.5468633432186503,0.03941916220239383
196.4000000000022,26.594625351514217,-1.5459281555000515,0.03877942028727821
197.80000000000223,26.727146248079897,-1.5444148594889444,0.03959738034454219
199.20000000000226,26.860548036273368,-1.5402345998053832,0.038099993339105076
200.60000000000227,26.991916917455338,-1.5413051091442898,0.03964217011370419
202.00000000000227,27.1266608469607,-1.5370545442770838,0.03996160141668703
203.4000000000023,27.259637168141026,-1.5339182293920606,0.039419992033081996
204.80000000000234,27.392846200328727,-1.5338574017247686,0.03941999241303318
206.20000000000235,27.525423653173487,-1.5312004886552324,0.04008372555206341
207.60000000000235,27.658992496903828,-1.531023829854991,0.038760051762356085
209.0000000000024,27.791419066104748,-1.528551383792967,0.04007017698751181
210.40000000000242,27.924444872383265,-1.5262042221219574,0.0400701046137808
211.80000000000243,28.057231893713908,-1.5235358631078917,0.03891827215086563
213.20000000000243,28.190875106837094,-1.5242666115869203,0.0380911880938668
214.60000000000247,28.32294908308163,-1.52289959333469,0.03942698736171879
216.0000000000025,28.45575279062823,-1.5218173588188044,0.03941985600016684
217.4000000000025,28.589770375899214,-1.5191313851244324,0.039422956245829255
218.8000000000025,28.722661836648346,-1.5200180176201064,0.03942000360380815
220.20000000000255,28.85593910769551,-1.5174546172234602,0.03869848003415344
221.60000000000258,28.988261362947068,-1.5179588151889427,0.03746054478222893
223.0000000000026,29.121079003263887,-1.514744777670525,0.03744019835188217
224.4000000000026,29.254091458374123,-1.5136501514638256,0.036151563863696
225.80000000000263,29.38528583030021,-1.512489219314183,0.03876004812400735
227.20000000000266,29.520786299243248,-1.5121966790565688,0.03876004687491408
228.60000000000267,29.653446943752666,-1.5129738296053368,0.04008185170430467
230.00000000000267,29.787419590534775,-1.5121522888318002,0.03776931674910733
231.4000000000027,29.920926914483736,-1.5109116397524047,0.03641841843096527
232.80000000000274,30.053587372477516,-1.5098886768940936,0.03777011202188696
234.20000000000275,30.18605726867509,-1.5094758384575446,0.03639476824261667
235.60000000000275,30.31811425314073,-1.5062263041543331,0.036460493628561075
237.00000000000279,30.45187179449844,-1.5066216577508753,0.03777011481440917
238.40000000000282,30.585379568119237,-1.5077248501696825,0.036476448504275893
239.80000000000283,30.71725650484274,-1.5076701000198287,0.039100820855392904
241.20000000000283,30.85129956687024,-1.5054611130666495,0.03777040424137601
242.60000000000286,30.983971249361947,-1.5065433980714773,0.03777001813320613
244.0000000000029,31.11714147979381,-1.5092365152571274,0.03644592752986231
245.4000000000029,31.250477696115563,-1.5061123414121758,0.038881494277907436
246.8000000000029,31.383632244450524,-1.5049562472599716,0.038430070614709155
248.20000000000294,31.51667722166988,-1.5048093888458185,0.03696118761872791
249.60000000000298,31.649628847657088,-1.5028086516450645,0.035807866839375535
251.00000000000298,31.78236869168932,-1.5044784646285945,0.03476694857419771
252.400000000003,31.916085971717585,-1.5047514772774695,0.03714642884117092
253.80000000000302,32.049375481666615,-1.5037977029315683,0.03843004000032835
255.20000000000306,32.18308040971573,-1.5050271138585962,0.038486070742679956
256.6000000000031,32.31622839497719,-1.5051379908852245,0.036130650551103205
258.00000000000307,32.44945702529801,-1.5068480809890117,0.03612997885137714
259.4000000000031,32.583674090063454,-1.5071555929559792,0.038769392027133254
260.80000000000314,32.716086882619955,-1.5081815158630183,0.036038961619046184
262.2000000000031,32.84962100826401,-1.506932939791428,0.03579590778521613
263.60000000000315,32.984238298291466,-1.5072807099033014,0.03449142510560543
265.0000000000032,33.11620005960038,-1.5088981201707847,0.03579997559838688
266.4000000000032,33.2504235044907,-1.510733597245143,0.036863457441626224
267.80000000000325,33.38319257050478,-1.5106991208878764,0.03578998372538811
269.20000000000323,33.51647372192713,-1.5100242639809025,0.03546034086775762
270.60000000000326,33.649168967072086,-1.5093999435781031,0.03678016690828745
272.0000000000033,33.78377694378821,-1.509029521857485,0.03547010375010062
273.4000000000033,33.91807446644941,-1.5106124409851234,0.03545512436753251
274.8000000000033,34.05099910885305,-1.5114890757217316,0.03279135170966274
276.20000000000334,34.1847748002965,-1.512252097645853,0.03383099300460568
277.6000000000034,34.31871389029584,-1.5128094079434053,0.03474451309184534
279.0000000000034,34.45072914477966,-1.517073632108571,0.03382008320471108
280.4000000000034,34.58618410767391,-1.5159584000761892,0.03452765528830559
281.8000000000034,34.7202910469752,-1.5183485575746754,0.03514010403110612
283.20000000000346,34.85467534143847,-1.5185565386674442,0.03514694945047747
284.60000000000343,34.988532907809855,-1.5194943167176975,0.033824386727844935
286.00000000000347,35.122072175478145,-1.5210526824174044,0.03249975128998095
287.4000000000035,35.25704365404053,-1.5240401217323751,0.03498792984257104
288.80000000000354,35.39040830458099,-1.5252586062089106,0.03384785606522245
290.20000000000357,35.524378696820904,-1.5270287445043833,0.03283231772157347
291.60000000000355,35.65859531346734,-1.5289365071000658,0.031445176403221975
293.0000000000036,35.79120562360929,-1.5299235359937347,0.033490276275788045
294.4000000000036,35.92673959189007,-1.5319207196183744,0.03480991485972229
295.8000000000036,36.06132739443714,-1.5334507334294736,0.032445831655623536
297.2000000000036,36.19567897537265,-1.5351575396566222,0.033699957638150924
298.60000000000366,36.3303665344558,-1.5353862177576545,0.0328027854945665
300.0000000000037,36.46486912263667,-1.5348441744227455,0.031561382296021456
301.40000000000373,36.59899839442703,-1.539091776688559,0.031179983999551908
302.8000000000037,36.733072460720784,-1.540982466634093,0.03117998399999866
304.20000000000374,36.86808848075445,-1.5417373852391143,0.03118003840619732
305.6000000000038,37.00221495599688,-1.545845899385605,0.03184010551723171
307.00000000000375,37.137392181562284,-1.5477459591005536,0.03184005399250989
308.4000000000038,37.27187575531677,-1.549022923723793,0.03182919121635841
309.8000000000038,37.407164488264954,-1.5523765169616452,0.030027703987169474
311.20000000000385,37.54071032109637,-1.5538528645507192,0.02948250187590329
312.6000000000039,37.6753185576198,-1.5562802669855063,0.03018999201194239
314.00000000000387,37.80978480638954,-1.558518470613442,0.030189758170758196
315.4000000000039,37.944451813830696,-1.5614049129297989,0.02789326225456179
316.80000000000393,38.07824340695648,-1.564406974284664,0.02920001039319242
318.2000000000039,38.21301478446449,-1.5680578835793337,0.02788993273197038
319.60000000000394,38.34719474602216,-1.5703501898121526,0.02788965395347409
321.000000000004,38.48143109165399,-1.574933163113473,0.02921003776712583
322.400000000004,38.61602104681607,-1.5759487795423557,0.02789017528006532
323.80000000000405,38.75042783207606,-1.5792437847518872,0.027890197330880717
325.200000000004,38.88547691444517,-1.5836736252747017,0.02822077051951677
326.60000000000406,39.01907421818584,-1.5862731228691371,0.026900132357737583
328.0000000000041,39.152631383049375,-1.5893711939910378,0.02557987925676919
329.40000000000407,39.289477161774066,-1.5939474925908086,0.025579873525655383
330.8000000000041,39.42480890895297,-1.5953295107475118,0.024241670331373033
332.20000000000414,39.55900866947831,-1.5990120367760219,0.02491997874080809
333.6000000000042,39.69465572010043,-1.605619760460177,0.02245412683483483
335.0000000000042,39.82969602154723,-1.6081911851094624,0.02360853169733712
336.4000000000042,39.964846069777636,-1.6133410467695748,0.023609944000176686
337.8000000000042,40.10011439539642,-1.6180889422623135,0.023609929093908022
339.20000000000425,40.235968531134276,-1.6209418867545842,0.02229047847701393
340.60000000000423,40.37079133610948,-1.6235869166116814,0.02320902695613425
342.00000000000426,40.5062316648825,-1.6281840299073957,0.020639970207924296
343.4000000000043,40.64088370138933,-1.633999229675893,0.018835325075626574
344.80000000000433,40.77567402635025,-1.6367888238448243,0.018008584495515123
346.20000000000437,40.91182055331737,-1.6426455225749725,0.018001231752101443
347.60000000000434,41.04794783100904,-1.6471933756502748,0.018010031629980716
349.0000000000044,41.18277461315901,-1.6524487064083067,0.017018413450145875
350.4000000000044,41.31937747980904,-1.6558445342446988,0.017331395649193837
351.8000000000044,41.45442356254338,-1.6595494597062717,0.01482015450187868
353.2000000000044,41.5903241110259,-1.6617239557922794,0.014842479741475234
354.60000000000446,41.72630396070259,-1.6670169522934142,0.014498464055989757
356.0000000000045,41.86204696559104,-1.670349213154516,0.012556139379690023
357.4000000000045,41.99782922242416,-1.671474874173677,0.011860007994204391
358.8000000000045,42.13436254405443,-1.676904748328065,0.01139504429230831
360.20000000000454,42.26945967984811,-1.6760576200592272,0.009246681102354604
361.60000000000457,42.40728587166789,-1.6792088500933187,0.007830074001758724
363.00000000000455,42.54329202074624,-1.6835748018361167,0.005600061540859791
364.4000000000046,42.67845786488318,-1.6857485102295875,0.004290206862914037
365.8000000000046,42.81539365980339,-1.6888425711052297,0.0039527235515239845
367.20000000000465,42.951589693771425,-1.6913601372069182,0.0028706616253346695
368.6000000000047,43.086133963029354,-1.6942332983852622,-0.0013366142993391783
370.00000000000466,43.22437297976025,-1.695389755312579,-0.0032712571985116234
371.4000000000047,43.36081125514378,-1.7004352579598134,-0.005298489036408949
372.80000000000473,43.49598836375476,-1.7031547968511282,-0.007122859091211797
374.2000000000047,43.63246914941526,-1.7055757950309238,-0.010415587080220945
375.60000000000474,43.768866830785626,-1.7132358737661444,-0.013711294587031908
377.0000000000048,43.90410715771302,-1.7168603830320417,-0.018668172142290995
378.4000000000048,44.04124720247268,-1.7241782868933098,-0.021983625294926146
379.80000000000484,44.17801205512468,-1.7285964144755088,-0.027890340009043335
381.2000000000048,44.314827709106126,-1.7328987879132665,-0.031583304557663894
382.60000000000485,44.4518209273137,-1.7375951668222978,-0.03556614318903728
384.0000000000049,44.5892674420198,-1.7429442596394757,-0.040722086464611174
385.40000000000487,44.72538464307575,-1.7471102101892668,-0.048675707823740755
386.8000000000049,44.86224124365929,-1.7528686931050832,-0.056095677929031584
388.20000000000493,44.9998164166797,-1.7588169658731776,-0.060519367311806516
389.60000000000497,45.13595235614516,-1.7636883331479172,-0.06634371023326313
391.000000000005,45.27343065708812,-1.7680051691732803,-0.07611391438936366
392.400000000005,45.409634224046044,-1.7680810850413942,-0.08521414385629811
393.800000000005,45.546186414188234,-1.7683881725911412,-0.0917449920248048
395.20000000000505,45.68216781849942,-1.7713021487474687,-0.09807732141046888
396.600000000005,45.82034328545639,-1.7692917293459567,-0.10775632814722957
398.00000000000506,45.956268060171354,-1.7676133185716483,-0.11609171124613127
399.4000000000051,46.09121076096634,-1.7641114567361642,-0.12219690798696448
400.8000000000051,46.22908098793845,-1.7581779470853593,-0.1305232178473319
402.20000000000516,46.365841519367244,-1.7545844993109139,-0.13668381945221109
403.60000000000514,46.501813044317025,-1.7466987045834623,-0.1438343721735711
405.0000000000052,46.639363667252354,-1.7372132841760177,-0.15074603066608905
406.4000000000052,46.77566642689514,-1.7296688459871588,-0.1548629487017994
407.8000000000052,46.91196070983166,-1.7237436072067234,-0.15740878225910304
409.2000000000052,47.0484510961611,-1.7160309874251853,-0.16159350748702073
410.60000000000525,47.18469712155788,-1.7118448099170676,-0.16424460709320243
412.0000000000053,47.32007248079715,-1.7070112755076943,-0.16819266324003035
413.4000000000053,47.45837273961136,-1.7041922615558613,-0.17081965292398316
414.8000000000053,47.59579243167489,-1.7045617545381622,-0.17081965017846334
416.20000000000533,47.732672681525486,-1.704367961562213,-0.17421968633549145
417.60000000000537,47.86835568026783,-1.7038006715661118,-0.17313676181933557
419.00000000000534,48.007019826940855,-1.7063076395896781,-0.1744421356567627
420.4000000000054,48.14417469010568,-1.7092109601030825,-0.1770498822886366
421.8000000000054,48.281063454258444,-1.709868205746082,-0.1770807666815899
423.20000000000545,48.418402404594914,-1.7107539693035103,-0.17839018390644323
424.6000000000055,48.555742474918176,-1.7160714990732822,-0.1783925158622086
426.00000000000546,48.69279227321588,-1.7203752017583744,-0.17856735194789009
427.4000000000055,48.82999573926325,-1.7277372426739854,-0.1797065702036318
428.8000000000055,48.96800673338704,-1.7357104686020086,-0.18036983850104082
430.2000000000055,49.10594943858805,-1.7421108061435548,-0.1816797648967663
431.60000000000554,49.24367653772333,-1.7494266120692352,-0.18032797903921116
433.00000000000557,49.381118194978036,-1.755603686112225,-0.18167983431096335
434.4000000000056,49.519828056087256,-1.762443689711137,-0.18332304538048527
435.80000000000564,49.65660210776898,-1.7682286748520575,-0.18333011118704734
437.2000000000056,49.79471156895716,-1.773850844672835,-0.18453936263038084
438.60000000000565,49.930169494912136,-1.7806456570372,-0.18595930877905698
440.0000000000057,50.0703960452535,-1.7857262063763852,-0.18498002425697946
441.40000000000566,50.208518266131904,-1.7874939947998745,-0.18628857509200092
442.8000000000057,50.346293346100914,-1.7916001607216456,-0.1876099501894508
444.20000000000573,50.48445449496534,-1.7956686808203433,-0.18759381845234646
445.60000000000576,50.62289716681857,-1.8011562845340128,-0.1889380136989507
447.0000000000058,50.76018698641865,-1.805606051418605,-0.1876197464951992
448.4000000000058,50.8987214503873,-1.810169600271319,-0.19022023871039018
449.8000000000058,51.03664880859212,-1.8153117809710304,-0.19025013599730967
451.20000000000584,51.173860975521805,-1.8188637405914703,-0.19014899417047992
452.6000000000058,51.312988890178175,-1.8245504892666777,-0.1902499748068145
454.00000000000585,51.45048173082548,-1.8294719616567896,-0.19155551552589145
455.4000000000059,51.58863252844338,-1.8295467929290226,-0.19255996514288354
456.8000000000059,51.72679563498315,-1.8367933058754313,-0.19255670465646801
458.20000000000596,51.86570287382607,-1.8440527109066929,-0.19387004716873202
459.60000000000593,52.0040651204994,-1.8476141618198019,-0.19571271266020585
461.00000000000597,52.141912583598504,-1.8508477790754512,-0.19497669143784657
462.400000000006,52.279457461698044,-1.8553921987496083,-0.19518960988358103
463.800000000006,52.417707598247105,-1.8614551639038126,-0.1951565425171662
465.200000000006,52.556207465668884,-1.862926505519226,-0.1965242538330485
466.60000000000605,52.69479424705121,-1.8687364479489308,-0.19718721938011985
468.0000000000061,52.83481135451156,-1.874210891704502,-0.19865498734259468
469.4000000000061,52.972803199320666,-1.877510160720202,-0.19982603518096687
470.8000000000061,53.111513649318155,-1.8811160060007521,-0.20045775520926634
472.2000000000061,53.24978679226887,-1.8828859857523268,-0.19913973869262103
473.60000000000616,53.388347907031466,-1.888702155117608,-0.19914021116818503
475.00000000000614,53.52736146723062,-1.8921634726814327,-0.20039404172133413
476.4000000000062,53.666541138949626,-1.8944860812050082,-0.20308987668828493
477.8000000000062,53.805071050126784,-1.898991315851709,-0.2034206782729262
479.20000000000624,53.94381511124922,-1.9007466716264634,-0.20459786804573632
480.6000000000063,54.08202257197719,-1.9025798708389876,-0.2041089542156489
482.00000000000625,54.22120857965897,-1.9076327955680756,-0.20407994399930773
483.4000000000063,54.360135875945176,-1.9108583151200127,-0.20366163396057013
484.8000000000063,54.498189480685596,-1.919670281289465,-0.20375873405694822
486.2000000000063,54.637362216935486,-1.9270880254907903,-0.2054245203403644
487.60000000000633,54.77690857880974,-1.927629557383484,-0.2063866642571508
489.00000000000637,54.91508560387131,-1.9326797978739008,-0.20507005577779802
490.4000000000064,55.05423427254296,-1.937469182147733,-0.20768805949105662
491.80000000000643,55.193425216745766,-1.9390408975377527,-0.2077099457402527
493.2000000000064,55.33281210780022,-1.9402730194001678,-0.20736395787409645
494.60000000000645,55.47264360767123,-1.9420281783854414,-0.2077098666172823
496.0000000000065,55.60957535972897,-1.940972208416984,-0.20708263127124305
497.40000000000646,55.75096813181721,-1.9386150563144737,-0.20771011999826827
498.8000000000065,55.88988634764786,-1.937351348849416,-0.20769768423469337
500.2000000000065,56.02807153143105,-1.9381127862706862,-0.2077001837835808
501.60000000000656,56.168191886751636,-1.9395577835523357,-0.2090187148764202
503.0000000000066,56.30650860545018,-1.9416395398596689,-0.21037439851492312
504.40000000000657,56.44591873930032,-1.9439824732895479,-0.2090200067921928
505.8000000000066,56.58541202821395,-1.9482701809179166,-0.21033990480851772
507.20000000000664,56.72259423873188,-1.9528097216201405,-0.21104173224437872
508.6000000000066,56.86402626658695,-1.9501482265945242,-0.2102335061896632
510.00000000000665,57.002595776625775,-1.952459623070855,-0.20892008481027213
511.4000000000067,57.1418916008451,-1.956683524233646,-0.21158535049760818
512.8000000000068,57.28013549648534,-1.9611794330074004,-0.2115398400002202
514.2000000000068,57.41975514530873,-1.9605637739210318,-0.21153984000516424
515.6000000000067,57.55946400570013,-1.961269190238004,-0.21286464499463076
517.0000000000068,57.69896048277034,-1.9658806504346806,-0.21155928890036524
518.4000000000068,57.838503685844806,-1.9670941256913008,-0.2118699033959186
519.8000000000068,57.977665287937654,-1.9732225756508537,-0.21291234802417858
521.2000000000069,58.11610659660059,-1.975359779077647,-0.21320738365911795
522.6000000000068,58.25672021529998,-1.9798794080481898,-0.21188002396401595
524.0000000000068,58.39651022321309,-1.982338320088261,-0.21122421782592538
525.4000000000069,58.53650922869209,-1.9883780481015592,-0.2112100225605653
526.8000000000069,58.67553272032982,-1.993718812851078,-0.21254114064527796
528.2000000000069,58.816115865873996,-2.0014142939111155,-0.21516272469919118
529.600000000007,58.95629788631434,-2.0074391194654857,-0.21417995210332474
531.0000000000069,59.09580216282614,-2.0147963137124525,-0.21417995200000295
532.4000000000069,59.23542275199346,-2.020278680742755,-0.21418028642482678
533.800000000007,59.375745421288094,-2.026294629084474,-0.21188034163403113
535.2000000000071,59.51587735244489,-2.0338746550796287,-0.21318534406898726
536.6000000000071,59.65558167000751,-2.0376245487729787,-0.2145103840992828
538.000000000007,59.79487737646648,-2.044319857225807,-0.21318965350259989
539.4000000000071,59.93289479957728,-2.05040512203923,-0.21450993969518617
540.8000000000071,60.073704685290316,-2.0558352025422417,-0.21319962836462691
542.2000000000071,60.21529649465063,-2.0602454268369854,-0.21366029255536123
543.6000000000072,60.35549960922438,-2.065504050506362,-0.21319898719411245
545.0000000000072,60.49682803409122,-2.0723618186187918,-0.2141913487947682
546.4000000000071,60.636761136772726,-2.0761241577804936,-0.2141879371367077
547.8000000000072,60.776295410603545,-2.0832039818661956,-0.21600449149867096
549.2000000000072,60.917988545614456,-2.0898795505402914,-0.21483997617751216
550.6000000000072,61.05806135875662,-2.0933897711013216,-0.21384998893336338
552.0000000000073,61.19937115440941,-2.099966991806163,-0.21450983115667688
553.4000000000073,61.339866535884035,-2.1039306835326492,-0.21478428492977253
554.8000000000073,61.4772631309678,-2.1116330212660737,-0.21812810452657594
556.2000000000073,61.620186089643134,-2.11329613401092,-0.21550045500227855
557.6000000000073,61.76067215137123,-2.1184839446400656,-0.21608296177867636
559.0000000000074,61.90099478180056,-2.124204305251966,-0.21418066408346137
560.4000000000074,62.04161382083049,-2.1279260150563593,-0.2154999921960754
561.8000000000075,62.18027964796813,-2.1329518202522637,-0.21625427040510337
563.2000000000074,62.32084931152824,-2.1412008595151426,-0.21745763387702777
564.6000000000074,62.462036694253335,-2.1463724510358198,-0.2187901773643821
566.0000000000075,62.60144375490322,-2.1508620646031766,-0.21879020093988766
567.4000000000075,62.742577516007245,-2.157608839243164,-0.2201037189614623
568.8000000000075,62.883456362317474,-2.1651807912387766,-0.22075818110848733
570.2000000000075,63.02374055264536,-2.172373262159937,-0.21880004073355686
571.6000000000075,63.164352491922486,-2.182878845446438,-0.22011171675523267
573.0000000000075,63.3057320061144,-2.203693506304055,-0.22011022644010225
574.4000000000076,63.44786847116236,-2.2397529308297766,-0.2201096087046932
575.8000000000076,63.586984036808886,-2.2033725062661453,-0.22110003267615141
577.2000000000077,63.726290743657366,-2.196019140033747,-0.22110207536243287
578.6000000000076,63.86844328204852,-2.1974012301965775,-0.21974600114111809
580.0000000000076,64.0093784771875,-2.202015294762752,-0.2207157049756261
581.4000000000077,64.14976866046015,-2.2072806002661967,-0.21846001761121236
582.8000000000077,64.28952785880414,-2.2134947382414842,-0.21857620497289343
584.2000000000078,64.42994108210326,-2.217313568856903,-0.2191803159670629
585.6000000000078,64.57279985980992,-2.2217025935027266,-0.22044002422797027
587.0000000000077,64.71377796051193,-2.2264428520831583,-0.22036275265665894
588.4000000000078,64.85527449764285,-2.231593349617393,-0.22046709940319786
589.8000000000078,64.9955437941163,-2.234304220941011,-0.22304863664888508
591.2000000000078,65.13655315870845,-2.2419394699450974,-0.2230713708441474
592.6000000000079,65.27741555468884,-2.2464411187234603,-0.2243900803962413
594.0000000000078,65.41773344961379,-2.254434100786626,-0.22330476957911793
595.4000000000078,65.55823418704696,-2.2596177661476506,-0.221757361749237
596.8000000000079,65.69989106218661,-2.261565931882424,-0.2207683664385378
598.2000000000079,65.84106708871553,-2.2699959388131017,-0.2220924441886276
599.600000000008,65.98083424229979,-2.276041194531461,-0.22472924517598836
601.000000000008,66.12336003140786,-2.2765009809495975,-0.2247195496360188
602.4000000000079,66.26484238142973,-2.285349191640716,-0.2240552637306572
603.800000000008,66.40352946654238,-2.2921439977564253,-0.22471987212708466
605.200000000008,66.546266145545,-2.296888865412267,-0.22474063343448947
606.6000000000081,66.68708715534794,-2.3021559444322395,-0.2260419222126835
608.0000000000081,66.82748099076721,-2.310410825927966,-0.22735996938135816
609.400000000008,66.96793224386715,-2.318299172159476,-0.22669673714294003
610.8000000000081,67.11002330824789,-2.3270573541281534,-0.22736215062649334
612.2000000000081,67.25074084169455,-2.336830742910528,-0.22873556866552303
613.6000000000081,67.3939351912856,-2.344292281774806,-0.22995404634071415
615.0000000000082,67.53528441639602,-2.3522171961377283,-0.22886006255147207
616.4000000000082,67.67639313878085,-2.3623833036792132,-0.2303203193338308
617.8000000000081,67.81835758820112,-2.3673688711002114,-0.22900014707452332
619.2000000000082,67.95846345520128,-2.377929974338557,-0.22898316685985165
620.6000000000082,68.10164673414829,-2.3865727123524456,-0.2305759402876819
622.0000000000083,68.24162304036705,-2.3948672632144077,-0.23163990774277599
623.4000000000083,68.38423412324671,-2.4016400828379356,-0.23203779930118573
624.8000000000083,68.52616165343055,-2.4142998976992054,-0.23295029228984143
626.2000000000083,68.6676542223692,-2.4218739935126026,-0.23336193110108017
627.6000000000083,68.80937037598488,-2.432863179026285,-0.23427008293243734
629.0000000000084,68.95108953048538,-2.4423373255730843,-0.23689961363931822
630.4000000000084,69.09236079927074,-2.452840725146074,-0.2361582357399592
631.8000000000084,69.23347501498397,-2.460996019143388,-0.23691386069686526
633.2000000000085,69.37434860068512,-2.4718129595727043,-0.23779173466129677
634.6000000000084,69.51635129038804,-2.483924527830504,-0.2395400203766691
636.0000000000084,69.65944152104444,-2.498079222495258,-0.2408599281949706
637.4000000000085,69.80057493758976,-2.5106836096440404,-0.24217940474949007
638.8000000000085,69.94163654132451,-2.523108176223559,-0.24176169989150464
640.2000000000085,70.08263854721432,-2.5348436553768003,-0.24383951593278175
641.6000000000085,70.22469457220565,-2.547367567824113,-0.2474365437379813
643.0000000000085,70.36481450734045,-2.564349060098824,-0.24633981096316138
644.4000000000086,70.50837379901331,-2.5798098820874658,-0.24765992053197072
645.8000000000086,70.65128660310455,-2.59541932095929,-0.25027909332207
647.2000000000086,70.79273016153456,-2.6144527509258992,-0.25095909678505235
648.6000000000087,70.93600312264758,-2.6294329218452113,-0.2550755747616118
650.0000000000086,71.07728450901428,-2.647175351738025,-0.2556800628608342
651.4000000000087,71.2170273916768,-2.6661198684229186,-0.2584206103910578
652.8000000000087,71.36200914456488,-2.6832714079271214,-0.2597416712613523
654.2000000000087,71.50449685746706,-2.699037658602017,-0.26284964303097835
655.6000000000088,71.64603605795622,-2.718528444244833,-0.2665762603467252
657.0000000000088,71.7881963152834,-2.7374616628181796,-0.26964037578202316
658.4000000000087,71.93007875364363,-2.75532287906534,-0.27518443342522625
659.8000000000088,72.07299889616601,-2.776314997203292,-0.2769971155215232
661.2000000000088,72.21408611990967,-2.797433851150899,-0.27976825618561163
662.6000000000088,72.35756597327614,-2.823482237425016,-0.2816762889101523
664.0000000000089,72.50084951487233,-2.8417899515203193,-0.2878554056341196
665.4000000000088,72.64384205176054,-2.865080074547539,-0.29088532961366775
666.8000000000089,72.78530766491465,-2.89172794503454,-0.2942394763906959
668.2000000000089,72.92865325130406,-2.9154192846648055,-0.2980433538910483
669.6000000000089,73.07183216146862,-2.941018128634147,-0.300149597990945
671.000000000009,73.21489426792735,-2.9689799052749137,-0.30502129099857145
672.400000000009,73.35739374724594,-2.9915471018398123,-0.3072566638583547
673.800000000009,73.49984876533294,-3.0217853812652913,-0.31400061063010964
675.200000000009,73.64286254897384,-3.0472333880899227,-0.32146993509293065
676.600000000009,73.78507302656324,-3.0743799225252215,-0.32618631433621337
678.0000000000091,73.92759653964708,-3.1014231474746623,-0.3323007384404888
679.4000000000091,74.06989143642582,-3.1344255320487875,-0.33780390917870307
680.800000000009,74.21334139169223,-3.165120870621449,-0.3443171851187934
682.2000000000091,74.35570668674679,-3.195928603339255,-0.3506342069828974
683.6000000000091,74.49823655347808,-3.2308210866364777,-0.35491909264699073
685.0000000000091,74.64136997022318,-3.266199637421989,-0.36195679098374134
686.4000000000092,74.78429772741967,-3.3005045010042595,-0.36954710648507794
687.8000000000092,74.92629317019099,-3.336848940374847,-0.3769933928161704
689.2000000000093,75.06843897415116,-3.377040124091172,-0.3836762707690742
690.6000000000092,75.21339150230499,-3.412871157173014,-0.3936007346104802
692.0000000000092,75.3561307092593,-3.451380775801228,-0.4017891871803685
693.4000000000093,75.49895054526009,-3.491301064742996,-0.4130930349785049
694.8000000000093,75.64132914624305,-3.5295843463907195,-0.4199220009622415
696.2000000000094,75.7849895944796,-3.5713891733491114,-0.42998758663387227
697.6000000000093,75.92802407172627,-3.6156328402601496,-0.4408818846240039
699.0000000000093,76.07067018413552,-3.65922108801853,-0.45058855863384784
700.4000000000094,76.21283864796465,-3.7047408711585232,-0.46157103279666245
701.8000000000094,76.35625658563751,-3.7515348436467093,-0.4738420058644244
703.2000000000094,76.49938593602516,-3.801964139246657,-0.48660753227055675
704.6000000000095,76.6416213081574,-3.8521895269559976,-0.4941132629908682
706.0000000000094,76.78563193347465,-3.9017462418414883,-0.5082169933411023
707.4000000000094,76.92868650649334,-3.954845896539669,-0.5215711231138562
708.8000000000095,77.07198782227434,-4.002350367968697,-0.5350224992402115
710.2000000000095,77.21599707671191,-4.056738347675649,-0.5477099381602253
711.6000000000096,77.35858363659328,-4.110526380656252,-0.5602670873124298
713.0000000000095,77.50299832550878,-4.1641854102069225,-0.5758857781743147
714.4000000000095,77.64736660393935,-4.215004627897787,-0.5933297802383852
715.8000000000096,77.78951374937947,-4.271473266530869,-0.6093241282665782
717.2000000000096,77.93512621207127,-4.324770747567321,-0.6258803504827486
718.6000000000097,78.07886407443343,-4.375323055360596,-0.6418425369308394
720.0000000000097,78.22293761882578,-4.429303394595731,-0.6570065624387551
721.4000000000096,78.3667958632461,-4.4811054029780255,-0.6765299098901565
722.8000000000097,78.51122126516978,-4.53420231819377,-0.6940579691301312
724.2000000000097,78.65375231590461,-4.584183533107285,-0.7135938290916775
725.6000000000097,78.79711670619012,-4.636536043003077,-0.7349475667496299
727.0000000000098,78.93895754620318,-4.689509724726684,-0.7540634233246304
728.4000000000098,79.08551066751093,-4.7439294628909945,-0.7730490843831035
729.8000000000097,79.22886383593642,-4.794883702130562,-0.7929775023947894
731.2000000000098,79.37209287497072,-4.844937521739203,-0.8143691105971729
732.6000000000098,79.51721272736557,-4.893492437125086,-0.8355999612031013
734.0000000000099,79.65948261897805,-4.946035274093157,-0.8608598311522262
735.4000000000099,79.80341567115939,-4.986657015979517,-0.8817015952128946
736.8000000000098,79.9485540802741,-5.026774465983339,-0.9038294047215047
738.2000000000099,80.09198295403002,-5.058840176815421,-0.9258648046280817
739.6000000000099,80.23481413197949,-5.089371345865302,-0.9506082389853168
741.00000000001,80.378061976105,-5.110963902429524,-0.975550815929163
742.40000000001,80.52112533263622,-5.122059260547499,-0.998962842844163
743.80000000001,80.6624316732359,-5.121953323354512,-1.0251042624375892
745.20000000001,80.80461644750697,-5.107618909084263,-1.0465087825945334
746.60000000001,80.94620915013208,-5.075256992906839,-1.0705193659798353
748.00000000001,81.0882132724128,-5.022510826939895,-1.0966336821277065
749.4000000000101,81.22804182240014,-4.941739065084862,-1.1176982372519917
750.8000000000101,81.36827670462198,-4.828829126489275,-1.138641184130393
752.20000000001,81.50714036449898,-4.671246761381013,-1.1574030454959976
753.6000000000101,81.64413983859791,-4.458106691736262,-1.1750749808043204
755.0000000000101,81.77956801492608,-4.1863577524854225,-1.1906285551442353
756.4000000000102,81.9130443302908,-3.877797653211968,-1.2029110296629049
757.8000000000102,82.04937644428482,-3.5572927363947673,-1.2162984595377235
759.2000000000102,82.18539114710866,-3.291769881790184,-1.2226364613104441
760.6000000000103,82.32230957680456,-3.089759513476988,-1.2268660690673334
762.0000000000102,82.46216962187404,-2.951900853677917,-1.2299950506634447
763.4000000000103,82.60313339583624,-2.8575203968811254,-1.2328408807056328
764.8000000000103,82.74384720997163,-2.797264903596952,-1.2328252031695155
766.2000000000103,82.88730491819788,-2.7695108049363046,-1.235365615274572
767.6000000000104,83.02927227657567,-2.753039119733434,-1.2341801197252198
769.0000000000103,83.17189761450041,-2.7457137358800914,-1.2354960524806264
770.4000000000103,83.31499724280219,-2.7393089761363547,-1.2341743111865902
771.8000000000104,83.45659329672142,-2.734615431390299,-1.2347175721434693
773.2000000000104,83.60107185403437,-2.739158713397126,-1.2369043200008112
774.6000000000104,83.74296283889102,-2.741529498028906,-1.2368199039838097
776.0000000000105,83.8860200523858,-2.743661044086819,-1.2362556164388963
777.4000000000104,84.03023648839813,-2.7468392077233053,-1.2348595808723677
778.8000000000105,84.17316621749517,-2.751979924210404,-1.238789146933958
780.2000000000105,84.31694135296863,-2.7557270110165257,-1.23780330032139
781.6000000000105,84.46016922310926,-2.759917618773942,-1.2361503553574678
783.0000000000106,84.60374597311275,-2.762427427103277,-1.2358209529247595
784.4000000000106,84.74672642047908,-2.7682705307907294,-1.2371609757286262
785.8000000000106,84.8902804085052,-2.7745260087391332,-1.237139563563165
787.2000000000106,85.03287081883329,-2.7809314884407303,-1.2358301474593238
788.6000000000106,85.17716654412531,-2.7829337825641347,-1.2354963576792666
790.0000000000107,85.32012824017399,-2.783053629123713,-1.2368780265091197
791.4000000000107,85.46294854042054,-2.786551377462778,-1.2345008771790251
792.8000000000106,85.60606119693267,-2.790524040758119,-1.237145205620843
794.2000000000107,85.7491689378878,-2.7939701937522075,-1.2358296970428184
795.6000000000107,85.89196213328694,-2.7955908964082994,-1.2371414243643999
797.0000000000107,86.03577327927697,-2.8019805837812872,-1.2368096533657216
798.4000000000108,86.17820397338296,-2.805926550818243,-1.2377997256267577
799.8000000000108,86.32136221831425,-2.805436413008306,-1.238130670457529
801.2000000000108,86.46371799380371,-2.8090792005987364,-1.2368098802920722
802.6000000000108,86.60884052772221,-2.8181861135723802,-1.2368026161556576
804.0000000000108,86.75086730922281,-2.8214484733076803,-1.2364804438241994
805.4000000000109,86.89480939620628,-2.8258866915066165,-1.2351600797882898
806.8000000000109,87.0388411788166,-2.829286549728265,-1.2351600847509312
808.200000000011,87.18009679403303,-2.831272177789066,-1.2378004183923967
809.6000000000109,87.32478008438619,-2.8318779590741823,-1.238790457258831
811.0000000000109,87.46782958937665,-2.8396457231469214,-1.2367844892982554
812.400000000011,87.61223287067537,-2.8411006039593225,-1.2348397130065023
813.800000000011,87.7538907125672,-2.849508268940994,-1.2351695598894672
815.200000000011,87.89950506953208,-2.8511090073142986,-1.23517016340696
816.600000000011,88.04303987836927,-2.853611940608762,-1.2365318488109152
818.000000000011,88.18698807971897,-2.857757167677,-1.2378366846046354
819.400000000011,88.3296439168309,-2.86145322122473,-1.2364805745124174
820.8000000000111,88.47308021510196,-2.862304178047023,-1.237780208880193
822.2000000000111,88.61631947733436,-2.8679872629985392,-1.2364730562604436
823.6000000000112,88.75890135388426,-2.873976646383331,-1.237793936196112
825.0000000000111,88.90084297667258,-2.8770600854050477,-1.2389797357913914
826.4000000000111,89.04615360946816,-2.8816308792993914,-1.2365257949998782
827.8000000000112,89.19050930758064,-2.885337023038921,-1.237799280723359
829.2000000000112,89.33425907062775,-2.8880740787362083,-1.2351351602797638
830.6000000000113,89.47799164252285,-2.894447677437229,-1.2351710771062603
832.0000000000113,89.62244882411876,-2.900982083541123,-1.237816955062851
833.4000000000112,89.76494219129597,-2.907166358933548,-1.2377867593086438
834.8000000000113,89.9088624273404,-2.908222285587811,-1.2391246094399588
836.2000000000113,90.0538670404517,-2.912780148253911,-1.237799415223754
837.6000000000113,90.19580954744536,-2.912418462782802,-1.2364849234224198
839.0000000000114,90.33978470019983,-2.915344758695326,-1.2348300504044323
840.4000000000113,90.48306997115263,-2.9195095046321495,-1.2348300479191652
841.8000000000113,90.62657298645107,-2.926849120535323,-1.2353134953716078
843.2000000000114,90.77018045709428,-2.9298408562257388,-1.235827320447243
844.6000000000114,90.9133990911785,-2.9320965219285546,-1.2355001556119767
846.0000000000115,91.0578135287781,-2.932475214163492,-1.2368105939695728
847.4000000000115,91.2002949992385,-2.93958450461864,-1.2354996006029033
848.8000000000114,91.34476569493063,-2.945642958883482,-1.236457832195136
850.2000000000115,91.4875028723176,-2.947115632659209,-1.2370992019824283
851.6000000000115,91.63090941321765,-2.9493183948262875,-1.2384579875053334
853.0000000000116,91.77338291838531,-2.9539112090637705,-1.2378338992465636
854.4000000000116,91.91723818968882,-2.956757227270179,-1.2361543885912507
855.8000000000116,92.06097298416235,-2.9608408165199536,-1.2330813157995428
857.2000000000116,92.20454783951737,-2.960037009567705,-1.2361016378174763
858.6000000000116,92.3480657949817,-2.9614013468253755,-1.2371386672366897
860.0000000000116,92.49232216195787,-2.9642426179141914,-1.2358200418614773
861.4000000000117,92.63648908365604,-2.9696797752833595,-1.237800294697247
862.8000000000117,92.77966625015411,-2.968900558920904,-1.2384601802934356
864.2000000000116,92.92364364201373,-2.97517754713513,-1.2384607000264127
865.6000000000117,93.0670769335484,-2.977811592543969,-1.2374701658878937
867.0000000000117,93.21086921749819,-2.9818377418509368,-1.2374798160000253
868.4000000000118,93.35474194026376,-2.983588745632836,-1.2374798160001523
869.8000000000118,93.49760560144757,-2.988335821710678,-1.2374903044532926
871.2000000000118,93.6406932510365,-2.9942882462148974,-1.2377386616752348
872.6000000000118,93.78533133717636,-2.9916310824061725,-1.2368099440035385
874.0000000000118,93.92868281618088,-2.994648472173146,-1.2367934610069775
875.4000000000119,94.07315408443796,-2.9990528722983494,-1.2387898021171546
876.8000000000119,94.2157838575634,-3.0046302728086816,-1.239781529807222
878.2000000000119,94.36013607314268,-3.010246911071047,-1.238060282434669
879.600000000012,94.5027951408616,-3.0173625353921225,-1.2367149469190317
881.0000000000119,94.64751036444437,-3.0227040843396256,-1.236179304336519
882.4000000000119,94.79050737728598,-3.027844884299871,-1.2358301119332014
883.800000000012,94.93317117946249,-3.0317803265866266,-1.2381301187220481
885.200000000012,95.07591742774875,-3.039344693546282,-1.2394500913252875
886.600000000012,95.21990986761223,-3.0425314534452803,-1.2397798997308929
888.000000000012,95.36405601730443,-3.0482381168537227,-1.2384748667913357
889.400000000012,95.50758403823569,-3.0485577582708014,-1.2410998174905625
890.8000000000121,95.6520889307762,-3.052806936887423,-1.2384538276581387
892.2000000000121,95.79533151493496,-3.0543164794438367,-1.2371499840330107
893.6000000000121,95.93874966066704,-3.0594632959045667,-1.2371499840000006
894.0000000000122,95.97841389368772,-3.05885626396876,-1.2371499840000002