File: 01_Data/EIFS_Coating/STA/N2/10K_min/EIFS_Coating_STA_N2_10KData_230918_R3.csv
##Temp./Â°C,Time/min,DSC/(mW/mg),Mass loss/mg
41.0,10.823453023560283,-2.3328623118117484,-0.0011151632296551028
42.40000000000002,11.178916322994514,-2.2665724809885015,-0.00020531965756553916
43.80000000000004,11.421037777536272,-2.220948295337452,0.0013289454356968378
45.20000000000006,11.627800652005904,-2.184762665075954,0.0005169909503131009
46.60000000000008,11.81451592989881,-2.1584978184704933,0.001093059278121089
48.0000000000001,11.988221052865331,-2.136177034992923,0.0018411497239343433
49.40000000000012,12.156160008779421,-2.1184777237684504,0.0017349406623301533
50.80000000000014,12.31817690254618,-2.1057924883648043,0.0005017335918493515
52.20000000000016,12.476431432545438,-2.0955416018874997,-0.0006605362620528688
53.60000000000018,12.633190235006527,-2.085211744990807,-0.0020575479367499483
55.0000000000002,12.789430989405458,-2.076892551947194,-0.002026123334511354
56.40000000000022,12.942613479010557,-2.0723652645185977,-0.00200760459810434
57.80000000000024,13.092931666109587,-2.06514241872344,-0.002077580313122329
59.20000000000026,13.245077175328447,-2.0585546584546495,-0.0007077799085823955
60.60000000000028,13.395015590576124,-2.0532750350257425,-0.001984480876356276
62.0000000000003,13.543825629661214,-2.048502028120975,-0.002007045186717793
63.40000000000032,13.693068774072369,-2.042589431943963,-0.0017823534377119366
64.80000000000034,13.837712044565048,-2.0378669179111357,-0.0007412425772224118
66.20000000000036,13.984697782010823,-2.0319910434452257,-0.0019772226305483365
67.60000000000038,14.130000000000042,-2.0301999999999976,-0.004290063338605599
69.0000000000004,14.2746399634993,-2.025875730862432,-0.004792201004367946
70.40000000000042,14.418489420081345,-2.0237648844545277,-0.0055208177178656115
71.80000000000044,14.562313580856149,-2.0188929756921303,-0.007384598519192487
73.20000000000046,14.706058963694831,-2.015582144145925,-0.005940060451145701
74.60000000000048,14.848804690741582,-2.0110999817686146,-0.00860743445495471
76.0000000000005,14.990192818153126,-2.0072621140286904,-0.007250027928343172
77.40000000000052,15.13178512926575,-1.9997534371683146,-0.008570001101495972
78.80000000000054,15.273280110457844,-1.9922411998855043,-0.009889999999999066
80.20000000000056,15.411453992840054,-1.9850462949646694,-0.011199895076351662
81.60000000000058,15.552675645216313,-1.9735065891681507,-0.011184087074281646
83.0000000000006,15.6915827715724,-1.9616641715309278,-0.012520068976805021
84.40000000000062,15.830934148300912,-1.944912693701742,-0.013840001679222613
85.80000000000064,15.96938266706835,-1.9260455949745061,-0.014843603182218335
87.20000000000066,16.10654582859559,-1.9118691740141485,-0.015186076323448372
88.60000000000068,16.24498390091633,-1.898371558876113,-0.015159999950309366
90.0000000000007,16.38195941313301,-1.8871210733248198,-0.013810978012079644
91.40000000000072,16.51733509773776,-1.8782286419631604,-0.016366373371355714
92.80000000000074,16.65640242243479,-1.8681480458244473,-0.015159999279116487
94.20000000000076,16.794320317813625,-1.8592756602291667,-0.016468778205502854
95.60000000000078,16.930792825178248,-1.8523139631944037,-0.017426509161898807
97.0000000000008,17.068071081704915,-1.8433936410097247,-0.01779000850641843
98.40000000000082,17.203683824581713,-1.8386978659762665,-0.017795274488964452
99.80000000000084,17.341314548176555,-1.8318847418443684,-0.01647963724457524
101.20000000000086,17.47676158543059,-1.8248735620970247,-0.016481553256137538
102.60000000000088,17.612695704914266,-1.8192098103429235,-0.01758485702289958
104.0000000000009,17.748501183007303,-1.813742467238057,-0.016477756590195458
105.40000000000092,17.88513344051992,-1.808482633837173,-0.01911028129267711
106.80000000000094,18.019808944003056,-1.8013979119479204,-0.019118378119452384
108.20000000000095,18.156811330823633,-1.7966293032383267,-0.017818082560088655
109.60000000000097,18.289494048232864,-1.7897695356857357,-0.019111945580029488
111.000000000001,18.42774682680229,-1.7814259615461019,-0.020033540913885428
112.40000000000101,18.563298823543878,-1.7753133906210374,-0.019111768045756428
113.80000000000103,18.698353198506005,-1.765665622676701,-0.019435756077742283
115.20000000000105,18.832532836527363,-1.7591214276203038,-0.018590272070002634
116.60000000000107,18.968498412032638,-1.7517971122036702,-0.01944242641245575
118.0000000000011,19.102795950710792,-1.7474010595510763,-0.019428799564746413
119.40000000000111,19.238135155899045,-1.7402037958311662,-0.020767480177546815
120.80000000000113,19.373840647339385,-1.7361804929136857,-0.023063672753012465
122.20000000000115,19.508707178101666,-1.729906269141602,-0.021740372503837424
123.60000000000117,19.644121260886433,-1.7248881543645842,-0.02042999980683513
125.0000000000012,19.778760788804195,-1.7194612621903076,-0.02052766339445533
126.40000000000121,19.912202007523412,-1.71511049690713,-0.02077606743090854
127.80000000000123,20.049300592074523,-1.7102759567823311,-0.02175030625942176
129.20000000000124,20.1831362149296,-1.7052541603720104,-0.021800460192565208
130.60000000000127,20.316808376434032,-1.6990635300575843,-0.020757879694684345
132.0000000000013,20.45201387271966,-1.6950718493635417,-0.02240716375222851
133.4000000000013,20.585690564189495,-1.6901822048667616,-0.022420975922887276
134.80000000000132,20.72000000000014,-1.685829999999988,-0.022414308843060837
136.20000000000135,20.852999801091585,-1.681172421928756,-0.022722282965065066
137.6000000000014,20.987787382008264,-1.6774278582666395,-0.021409997222667787
139.0000000000014,21.12217445092374,-1.6746587068601053,-0.021985060916079657
140.4000000000014,21.255228768898373,-1.6694201122993484,-0.021420707499401725
141.80000000000143,21.390588127569835,-1.6655515847039233,-0.02273735352224504
143.20000000000147,21.523785742920612,-1.6595973893442653,-0.021420001301049485
144.60000000000147,21.657222125420677,-1.6562385439875285,-0.022399795731528283
146.00000000000148,21.791214021026633,-1.6517370373186686,-0.022725754537876508
147.4000000000015,21.92590609979294,-1.6490475656825967,-0.021346594519124462
148.80000000000155,22.05868848503537,-1.6441686374573796,-0.022730000001355055
150.20000000000155,22.193611323529456,-1.640608400816216,-0.022729269656361684
151.60000000000156,22.326126482959893,-1.635898774311463,-0.02141095460846243
153.0000000000016,22.46143306373779,-1.6320803236300563,-0.024050310514156514
154.40000000000163,22.59423004597598,-1.62901827097659,-0.022730100046516988
155.80000000000163,22.72912367877264,-1.6254863571317069,-0.023394531345279912
157.20000000000164,22.863531071448755,-1.6208043671572938,-0.02284187227477652
158.60000000000167,22.99684694589337,-1.6172228438514253,-0.02414351827043859
160.0000000000017,23.131191124989776,-1.613664203280906,-0.02404999999999813
161.4000000000017,23.263759459722507,-1.6112073467128611,-0.024039008681912666
162.80000000000172,23.39759278100771,-1.605639209419044,-0.024049946568664105
164.20000000000175,23.531788503761895,-1.6021439288789607,-0.02379498378158207
165.60000000000178,23.664567616945213,-1.598598561765957,-0.02471000001557444
167.0000000000018,23.79760566443954,-1.5947827289987218,-0.02424789925547044
168.4000000000018,23.931846873628892,-1.5930496393390887,-0.024709972090104504
169.80000000000183,24.065022867983007,-1.5875309978566816,-0.023390709272221866
171.20000000000186,24.199369262046513,-1.5839880312631907,-0.02326877205974487
172.60000000000187,24.333137120638646,-1.582625993922725,-0.02483065705688947
174.00000000000188,24.46495461938607,-1.5766766101894711,-0.024710000000080168
175.4000000000019,24.59929819093192,-1.5738500475899198,-0.02470999999999357
176.80000000000194,24.732776888164384,-1.5710959077135858,-0.024708905001253
178.20000000000195,24.866356125250356,-1.568941761634383,-0.023583065013810245
179.60000000000196,24.999330819193943,-1.5664168914566365,-0.024380755690383893
181.000000000002,25.13213355742195,-1.5640388138809613,-0.023389819783178556
182.40000000000202,25.2657714115306,-1.5604985932111695,-0.024753573392539696
183.80000000000203,25.39860873516933,-1.5571881552583924,-0.02504000431501474
185.20000000000203,25.532296366503417,-1.5550306747274696,-0.02635950558192368
186.60000000000207,25.663046600504934,-1.5518309338836298,-0.026360000894404045
188.0000000000021,25.79846679055376,-1.549338462692832,-0.025039017373027495
189.4000000000021,25.93146199788171,-1.547070155272833,-0.024892686229832872
190.80000000000211,26.06403818322474,-1.543281850040726,-0.024709974243362076
192.20000000000215,26.196860805022823,-1.5405155387873006,-0.02602999373000392
193.60000000000218,26.329903393147372,-1.5384113949708929,-0.026030000145014665
195.0000000000022,26.462698413935172,-1.5372753333016018,-0.024993655691037286
196.4000000000022,26.594402478478752,-1.5336456975026493,-0.026020041261541227
197.80000000000223,26.728304401027437,-1.5315409355223484,-0.0273400857940449
199.20000000000226,26.86138178834374,-1.5286335999687464,-0.027326842417750186
200.60000000000227,26.994471551228425,-1.5264247990898747,-0.027669897783800135
202.00000000000227,27.124831962921377,-1.526014142464845,-0.027340003994306805
203.4000000000023,27.259568397841875,-1.5211679257084252,-0.02734000024885086
204.80000000000234,27.391231249503544,-1.5182808741485116,-0.027015061834588572
206.20000000000235,27.524193865950508,-1.5183630522287874,-0.026019991658984498
207.60000000000235,27.656635601222803,-1.515806607196628,-0.02771339089602165
209.0000000000024,27.789617324422196,-1.514237532839871,-0.026349641051356176
210.40000000000242,27.92344820283671,-1.514353416808274,-0.027012258653888566
211.80000000000243,28.055242020427478,-1.51108924995924,-0.027009999999942913
213.20000000000243,28.19000000000023,-1.5088200000000402,-0.027010000004656032
214.60000000000247,28.32076228284236,-1.5075018654787997,-0.027701228779041465
216.0000000000025,28.454864365168667,-1.505885333227234,-0.026351431484875842
217.4000000000025,28.58749826866678,-1.5032795950743516,-0.027662340020802034
218.8000000000025,28.719632027710617,-1.503305761987665,-0.027670000000039607
220.20000000000255,28.85173385820344,-1.5000298127899352,-0.02905676970685711
221.60000000000258,28.98639597480228,-1.498930024749148,-0.02764824693098511
223.0000000000026,29.11909310032226,-1.4968088842213558,-0.027679998572434528
224.4000000000026,29.253105458617245,-1.4959357428265285,-0.028989865239509083
225.80000000000263,29.386114209131613,-1.4944895869352144,-0.028986224308932496
227.20000000000266,29.51703776012699,-1.4923195928122392,-0.03163412888646144
228.60000000000267,29.65187579624568,-1.4920537393539755,-0.030309735501710122
230.00000000000267,29.784369406918668,-1.4887554300742372,-0.030362848818180854
231.4000000000027,29.9181280985516,-1.487884348852617,-0.028989999961293034
232.80000000000274,30.05067236624914,-1.486552059190417,-0.028990000000023386
234.20000000000275,30.183279582093867,-1.4853825377601204,-0.028987804401128248
235.60000000000275,30.315338094124417,-1.483652510731797,-0.03038663143929954
237.00000000000279,30.447571945856435,-1.482723350022369,-0.029006889025340765
238.40000000000282,30.58407764722594,-1.480820769645368,-0.030967669282936594
239.80000000000283,30.716623875881776,-1.4785771016300078,-0.031035681388126513
241.20000000000283,30.850983586077877,-1.4788138618481121,-0.031613374766573
242.60000000000286,30.98314893929425,-1.478770696163383,-0.03163017127945533
244.0000000000029,31.116557126733753,-1.4753776700657146,-0.03024999201598444
245.4000000000029,31.249909210708093,-1.473752909141239,-0.030969935737804377
246.8000000000029,31.383519126931834,-1.4735038634729283,-0.03096999999490091
248.20000000000294,31.517452924295732,-1.4721268961746956,-0.029852956647229423
249.60000000000298,31.65090586524781,-1.4709065360357512,-0.030970014534270174
251.00000000000298,31.784066406587,-1.4718820508672072,-0.029650193327512397
252.400000000003,31.915463804479486,-1.471727476924686,-0.03228989270190086
253.80000000000302,32.050302241899416,-1.470624214336232,-0.03130071393432532
255.20000000000306,32.18338709080819,-1.4682458676141998,-0.03129999999981958
256.6000000000031,32.31643869366857,-1.4663924577781544,-0.031299999999048644
258.00000000000307,32.45009940152186,-1.4663357581782166,-0.03129858197539459
259.4000000000031,32.58280134990355,-1.465561490476662,-0.03262000004770904
260.80000000000314,32.71600236434235,-1.463249870678482,-0.033274890764138476
262.2000000000031,32.84734742493261,-1.4634904820508574,-0.033279999990899256
263.60000000000315,32.982407032764044,-1.464125796469677,-0.033980996354054493
265.0000000000032,33.11741590318832,-1.4626488044487445,-0.03392987670477332
266.4000000000032,33.25055182970224,-1.4616333094033074,-0.03261999829463136
267.80000000000325,33.38305119219605,-1.4619711214100612,-0.034149936269312064
269.20000000000323,33.51683085001952,-1.4627570211579406,-0.03415010435319488
270.60000000000326,33.65101713949864,-1.4602087093530836,-0.03382000172398403
272.0000000000033,33.78359542795521,-1.459736216949728,-0.03382000000136909
273.4000000000033,33.917349810477475,-1.4597133359709855,-0.03376695875877367
274.8000000000033,34.050751293436065,-1.4625816270229148,-0.03512999999084876
276.20000000000334,34.18478641792338,-1.4592334571038148,-0.03512999999999877
277.6000000000034,34.31891446266718,-1.45653227098892,-0.03512999999999966
279.0000000000034,34.4527612471304,-1.4587848549577402,-0.03512999999999833
280.4000000000034,34.58727288524664,-1.4584035226488938,-0.035129856866946696
281.8000000000034,34.72067363974366,-1.458264034342142,-0.03545999643702835
283.20000000000346,34.853531316801615,-1.456152754813055,-0.03578637253983041
284.60000000000343,34.98786412507797,-1.4577932545075074,-0.03645000652892705
286.00000000000347,35.12202260921156,-1.4572854153667054,-0.03382091122823283
287.4000000000035,35.255477046532796,-1.457453299913819,-0.035856497994927405
288.80000000000354,35.39009173280533,-1.457714756849474,-0.03448711018843564
290.20000000000357,35.52286049402623,-1.458688005599068,-0.03887799376281986
291.60000000000355,35.656479002141545,-1.45721897188978,-0.03920000117156697
293.0000000000036,35.790755890844785,-1.4573746999128483,-0.03953008069565733
294.4000000000036,35.92500849166397,-1.4574348385800393,-0.03952640070496072
295.8000000000036,36.05817765841217,-1.4573775798299882,-0.036844981879227134
297.2000000000036,36.19155065948441,-1.4565029695807081,-0.038210026605120184
298.60000000000366,36.32670963033344,-1.456029373739095,-0.03820999999999852
300.0000000000037,36.46009335897848,-1.4580264517091872,-0.038209999975361786
301.40000000000373,36.59416845602642,-1.4570096710605172,-0.04052785521471369
302.8000000000037,36.726952808120174,-1.4577516613358013,-0.040519999789281336
304.20000000000374,36.86124991125134,-1.458300148833304,-0.03919784180751318
305.6000000000038,36.99553281479057,-1.4587592584035027,-0.03919999989085676
307.00000000000375,37.12934901468598,-1.458604399358403,-0.040518540556029325
308.4000000000038,37.26371097321235,-1.4579885013090486,-0.03986049926061064
309.8000000000038,37.398181369655546,-1.4595806451945528,-0.03986005230371692
311.20000000000385,37.53154529012191,-1.4604489384306207,-0.0418292349495597
312.6000000000039,37.66657921497567,-1.4608591330840974,-0.040531922118468344
314.00000000000387,37.79962234821039,-1.463751893988969,-0.04037109483023649
315.4000000000039,37.934351860988784,-1.4653180980494003,-0.0401859285941244
316.80000000000393,38.068488990461354,-1.4669521822141047,-0.04282000277652198
318.2000000000039,38.202879986307366,-1.4703309833713143,-0.042440928808190836
319.60000000000394,38.33804570137542,-1.4704986917323202,-0.04248999999560299
321.000000000004,38.47434663328446,-1.474458612186262,-0.04345490249212247
322.400000000004,38.60826672087424,-1.4773105767727346,-0.044148561608625236
323.80000000000405,38.743355100762535,-1.479874311211718,-0.04479373678460874
325.200000000004,38.87800455651674,-1.4819477124795526,-0.0461200295456079
326.60000000000406,39.01261396597622,-1.485168681756673,-0.044833144249544876
328.0000000000041,39.14770369965585,-1.485697431717533,-0.04479617819760229
329.40000000000407,39.280574244434916,-1.4863709881007876,-0.04711060679204282
330.8000000000041,39.41707285177235,-1.4903604256511829,-0.045790087745967156
332.20000000000414,39.552552503840815,-1.493737369308439,-0.04615558667663011
333.6000000000042,39.68699354455759,-1.4948780111350775,-0.047430012183552694
335.0000000000042,39.820941138586626,-1.4990293035731117,-0.047502630785346334
336.4000000000042,39.957923513875784,-1.4989932735146345,-0.0487490625358622
337.8000000000042,40.092169706077634,-1.500667068418054,-0.049083248589179895
339.20000000000425,40.22707562211034,-1.5055919471868147,-0.049408311113272596
340.60000000000423,40.36110760883527,-1.5084413268297914,-0.05072993953834404
342.00000000000426,40.497436486330436,-1.5084721472091767,-0.05072999998784189
343.4000000000043,40.63242760787728,-1.5110347529019206,-0.05202048250843161
344.80000000000433,40.76781827853626,-1.5138254628167704,-0.05335479163162793
346.20000000000437,40.902982820702725,-1.5163406979429521,-0.054678102414240204
347.60000000000434,41.037526148099836,-1.5197598357298858,-0.05468000000006512
349.0000000000044,41.17339525804398,-1.522107679740529,-0.054682448966327346
350.4000000000044,41.30878789807807,-1.526053208439083,-0.05567069510451672
351.8000000000044,41.44348319731524,-1.527056507386078,-0.05600322937746416
353.2000000000044,41.579588787678304,-1.5272729971141572,-0.057309999261847544
354.60000000000446,41.714964604390794,-1.5296498885029466,-0.058629963577465194
356.0000000000045,41.851338337549585,-1.5299205646140126,-0.059950013617137365
357.4000000000045,41.98653833557588,-1.5322929308704376,-0.06126987011716967
358.8000000000045,42.12253694956132,-1.5344021380951816,-0.05995117496324287
360.20000000000454,42.25821922111641,-1.5407408062707297,-0.06357087549427298
361.60000000000457,42.39495305408672,-1.5404258807295068,-0.0639448254869861
363.00000000000455,42.53048598351466,-1.5394697500696617,-0.06653878033770777
364.4000000000046,42.66562160527572,-1.5426407780982205,-0.06899446427349787
365.8000000000046,42.80224407685471,-1.5432174422420222,-0.06916936947006436
367.20000000000465,42.93954062975241,-1.5439312799576748,-0.07078425591219739
368.6000000000047,43.07531228023381,-1.5452155362825393,-0.07307198883452459
370.00000000000466,43.21127877502635,-1.5469637344011415,-0.07576488023132777
371.4000000000047,43.34798888505228,-1.5475695291991096,-0.07709426579697709
372.80000000000473,43.48369030459977,-1.551062449683254,-0.07839129141740253
374.2000000000047,43.62040717547171,-1.5505558837157603,-0.08103165483641117
375.60000000000474,43.75718995117224,-1.55632892199414,-0.08360757627463267
377.0000000000048,43.89374219765329,-1.5593304870317368,-0.08939370379414502
378.4000000000048,44.02980108789085,-1.5615633395572852,-0.09232983047892818
379.80000000000484,44.164770778254656,-1.5648717305521094,-0.09711891971567344
381.2000000000048,44.30240891713272,-1.5690763515444492,-0.102402068670433
382.60000000000485,44.438917246523104,-1.5743907809572948,-0.10619535936890756
384.0000000000049,44.57580365178744,-1.574464060894788,-0.1132356833624728
385.40000000000487,44.71278884653825,-1.5782476803991956,-0.11933964473722991
386.8000000000049,44.848843009357196,-1.580424013083203,-0.12452173486208196
388.20000000000493,44.986005497278015,-1.581971678212067,-0.13172606423157074
389.60000000000497,45.12268769064783,-1.586571262813656,-0.13978170622298514
391.000000000005,45.25926505017402,-1.587995972278945,-0.1451230830540471
392.400000000005,45.396481563951546,-1.5868303520854883,-0.15213809893371977
393.800000000005,45.53238927284783,-1.5869073971909984,-0.1624292227834192
395.20000000000505,45.66978807915579,-1.5849838290135208,-0.1692683023267847
396.600000000005,45.8055715412838,-1.5810728302890082,-0.17708841566774725
398.00000000000506,45.94309429445724,-1.575293844072043,-0.18699927339620004
399.4000000000051,46.07880738788509,-1.5703509879209099,-0.19255636738420456
400.8000000000051,46.21410326402069,-1.5636101121109884,-0.19925683801820515
402.20000000000516,46.3501906643186,-1.556562225812758,-0.20642186739712365
403.60000000000514,46.486977839012766,-1.5495608857950516,-0.21212015957416774
405.0000000000052,46.62297413177252,-1.5366839186101133,-0.218896416271817
406.4000000000052,46.75834866311891,-1.5267229975096495,-0.22286469096040484
407.8000000000052,46.89539139947947,-1.5184119637852376,-0.22818189421153434
409.2000000000052,47.03148717028723,-1.5085263374199225,-0.2307423235602517
410.60000000000525,47.1678587635275,-1.5016952802518704,-0.23473976759505977
412.0000000000053,47.30366868956656,-1.4955994292924601,-0.23600896583835462
413.4000000000053,47.44104054607659,-1.492584124057766,-0.23743353788726296
414.8000000000053,47.57777485165025,-1.4907651721964088,-0.23735380221772662
416.20000000000533,47.71286827980282,-1.4892720510719422,-0.23869486924071914
417.60000000000537,47.85206935562096,-1.4904636231081831,-0.24008584040996706
419.00000000000534,47.98834947747825,-1.488260776138211,-0.24229646431852014
420.4000000000054,48.1263081404247,-1.489581488107438,-0.24460927411802968
421.8000000000054,48.26343182604417,-1.4900387286722818,-0.24525752496452125
423.20000000000545,48.399689161128386,-1.4918857209674352,-0.24560941985040863
424.6000000000055,48.53766868477081,-1.4947854011503003,-0.24559961098694938
426.00000000000546,48.67564582434511,-1.4955373987529206,-0.24690999994531948
427.4000000000055,48.810808692577375,-1.5029325698412828,-0.2482302220528636
428.8000000000055,48.9493002013503,-1.5086902762008407,-0.24951173286754713
430.2000000000055,49.086440540268114,-1.514612254810358,-0.24894407403942376
431.60000000000554,49.22314735496854,-1.5210368564205716,-0.24920786151991292
433.00000000000557,49.36156996755938,-1.5283913672786864,-0.25053001266381836
434.4000000000056,49.498445367770174,-1.5316977775356613,-0.2518524526966148
435.80000000000564,49.635346326649,-1.5345419978949604,-0.25052693870371323
437.2000000000056,49.77415221748805,-1.53658815265158,-0.2531876687799799
438.60000000000565,49.912053152029685,-1.539283498640733,-0.2531701305595826
440.0000000000057,50.04913213687606,-1.5400786190782607,-0.2544937302314292
441.40000000000566,50.188023553496365,-1.54433183068274,-0.25448993391281016
442.8000000000057,50.32581225557224,-1.5453861476327417,-0.25588004499249273
444.20000000000573,50.46368622227875,-1.5479227546783747,-0.2557995421839512
445.60000000000576,50.60141095438303,-1.5503403265312368,-0.2575687430731848
447.0000000000058,50.74020626278491,-1.5511440458142884,-0.2567900206487703
448.4000000000058,50.87781430279119,-1.5553690435746865,-0.25815855506635677
449.8000000000058,51.01515251622043,-1.5582418036728782,-0.2604442766219379
451.20000000000584,51.152892911808124,-1.561010532870294,-0.26075000000143955
452.6000000000058,51.29051030426526,-1.5640646917656427,-0.2594297124876661
454.00000000000585,51.42798952937846,-1.564412628910059,-0.260410876996338
455.4000000000059,51.56611154888607,-1.5658624690810412,-0.2617259147861204
456.8000000000059,51.70462892702228,-1.5701138491472095,-0.2630607455339087
458.20000000000596,51.842621447465966,-1.5732786393108757,-0.26339081860090996
459.60000000000593,51.98070157108122,-1.5752979812538521,-0.26407227895597973
461.00000000000597,52.11848215828152,-1.5788950791294147,-0.26470005730437496
462.400000000006,52.25723265929492,-1.5818641670446345,-0.2660098720053896
463.800000000006,52.39525047038043,-1.5826381099565687,-0.2653298736635472
465.200000000006,52.53324790047552,-1.5829714747142398,-0.2666690296355809
466.60000000000605,52.670796840384426,-1.585345692293541,-0.2689799549987293
468.0000000000061,52.80892781434707,-1.5879910498315026,-0.268919289146373
469.4000000000061,52.948220474240706,-1.5886855188208857,-0.2677207944530591
470.8000000000061,53.08653033834385,-1.5886387152706505,-0.2681881487880977
472.2000000000061,53.22512748896824,-1.5905540186608247,-0.268884746841235
473.60000000000616,53.36396228733897,-1.592919170000013,-0.27018000000309117
475.00000000000614,53.50275175550765,-1.594102070219859,-0.2701804457457766
476.4000000000062,53.640829726545434,-1.5949309379811993,-0.2714999477250859
477.8000000000062,53.77903182411377,-1.596063958869276,-0.2751702547894248
479.20000000000624,53.918962569940916,-1.5951800074171798,-0.27256973480445135
480.6000000000063,54.05772403621338,-1.5991141551428791,-0.27188034693021024
482.00000000000625,54.196310997047036,-1.6014107995930198,-0.2745845301573979
483.4000000000063,54.33452873863349,-1.6062115836321202,-0.27458011896985113
484.8000000000063,54.473751034692846,-1.6072628797261888,-0.27590023581968337
486.2000000000063,54.612238487930696,-1.6069071262017973,-0.2759020324373571
487.60000000000633,54.74896229870933,-1.6071724256022595,-0.2765499798006914
489.00000000000637,54.89027544972841,-1.6103380246906298,-0.27654999999999985
490.4000000000064,55.029239497282504,-1.609857670324364,-0.2765499956132236
491.80000000000643,55.167836203568086,-1.6110625840276183,-0.27688181276128043
493.2000000000064,55.30693648216002,-1.6093549038194217,-0.27688025095260027
494.60000000000645,55.442313678519305,-1.602494625116161,-0.27874724720649535
496.0000000000065,55.58332877743029,-1.5995612317389816,-0.278091961442958
497.40000000000646,55.72250447219695,-1.5959200373285982,-0.27808999030095594
498.8000000000065,55.86058245842718,-1.5913548241571016,-0.27940998156059216
500.2000000000065,55.99960304048546,-1.5901495525240028,-0.27940999991473126
501.60000000000656,56.13910396721319,-1.588158426310484,-0.28038980792770873
503.0000000000066,56.27809890884156,-1.592905404502326,-0.2800020221055015
504.40000000000657,56.41743724997752,-1.5927730404882763,-0.2800609400265839
505.8000000000066,56.556610858373325,-1.5932610168807946,-0.2813785971027838
507.20000000000664,56.69568569041363,-1.5926411036700685,-0.28072292558609524
508.6000000000066,56.834390804302245,-1.5912740036217707,-0.2813804261495889
510.00000000000665,56.97383911732625,-1.589055980343662,-0.2815776546998361
511.4000000000067,57.112986977533645,-1.588832675290627,-0.2840188028955515
512.8000000000068,57.25225058558174,-1.5895793175004047,-0.2827064187830586
514.2000000000068,57.39117642215847,-1.5870219113697988,-0.2826994706988577
515.6000000000067,57.53116028999766,-1.5888799801528997,-0.2827000001697466
517.0000000000068,57.671191050493476,-1.592781111353147,-0.28367874497176615
518.4000000000068,57.80841739645606,-1.5938923652720804,-0.2839753720773128
519.8000000000068,57.94852378833071,-1.5954714228105782,-0.28401000717140157
521.2000000000069,58.08858474040005,-1.5991568760978032,-0.28430726676019535
522.6000000000068,58.22819079675768,-1.6043943257300688,-0.28471998247049735
524.0000000000068,58.367443516012344,-1.6092527500690488,-0.2850521918192772
525.4000000000069,58.50733161246041,-1.6136554312305866,-0.2849437003557935
526.8000000000069,58.64706746832446,-1.6137961709166788,-0.28587204516585984
528.2000000000069,58.78666585006492,-1.6177432084024892,-0.2856702843149259
529.600000000007,58.927535300009716,-1.622161063610267,-0.2856695371077138
531.0000000000069,59.06719042747433,-1.6272542959522278,-0.28561183180538263
532.4000000000069,59.206357777428295,-1.6324999227194952,-0.2870128471589384
533.800000000007,59.34677528022364,-1.636788540815676,-0.2869937900691699
535.2000000000071,59.48574004043959,-1.6396993616738447,-0.28560336844955625
536.6000000000071,59.62704912586401,-1.6448680189062783,-0.2876592118799839
538.000000000007,59.76666288342011,-1.6482191299696158,-0.28631999624512616
539.4000000000071,59.90642216022703,-1.6521841965059378,-0.2863200002719939
540.8000000000071,60.04676861069077,-1.6525405580497954,-0.2866615333983975
542.2000000000071,60.18744857036854,-1.6589619062130956,-0.28797000005366513
543.6000000000072,60.32733181834707,-1.6609279421150207,-0.2879942956963424
545.0000000000072,60.46795161327715,-1.665595024131794,-0.2892900037687034
546.4000000000071,60.60815113208892,-1.6698925108196476,-0.2886304939998938
547.8000000000072,60.747681920177875,-1.6745591956538037,-0.28896083435434683
549.2000000000072,60.88668123514059,-1.6775471773309587,-0.28731078183760905
550.6000000000072,61.02864664833019,-1.6817074356394546,-0.2873078880802278
552.0000000000073,61.1689014486966,-1.6833108774609897,-0.2879598285534586
553.4000000000073,61.3105740149324,-1.6890483399936407,-0.2892800003191134
554.8000000000073,61.449805065292324,-1.6921570808731303,-0.28828973160891325
556.2000000000073,61.589213814063186,-1.6927678516147298,-0.28961100810176177
557.6000000000073,61.73000195593009,-1.6991900864392457,-0.28961000000000015
559.0000000000074,61.87039318338765,-1.6999870467407712,-0.28960999999754344
560.4000000000074,62.009997706518156,-1.703010301188195,-0.28961432907230034
561.8000000000075,62.15048512898146,-1.7035235434252571,-0.28961999999991805
563.2000000000074,62.29176293519637,-1.7076999814134834,-0.2896153713130052
564.6000000000074,62.43085013838752,-1.709653759591516,-0.2909292737457312
566.0000000000075,62.57151616319524,-1.7117976927764684,-0.29021121815724005
567.4000000000075,62.71146344537316,-1.7162573915295634,-0.29027974963730196
568.8000000000075,62.85189891090004,-1.7205157889200096,-0.2909311389423612
570.2000000000075,62.99279876807136,-1.7274489217993325,-0.2922503011448172
571.6000000000075,63.13285090573257,-1.7354370285454392,-0.2909292801973917
573.0000000000075,63.27423975186201,-1.7563239497693257,-0.2919198655802613
574.4000000000076,63.416221197417045,-1.7852398731205092,-0.2909242729586281
575.8000000000076,63.5558475639537,-1.7470414475160683,-0.2919368950833827
577.2000000000077,63.69643865903269,-1.7361336088305233,-0.2925672074038079
578.6000000000076,63.83716947988272,-1.7360048181029943,-0.2912600630051956
580.0000000000076,63.977532087493515,-1.7352927862812253,-0.2939252238959016
581.4000000000077,64.11807960823309,-1.7403132815216744,-0.29608321558443196
582.8000000000077,64.25944871910303,-1.7410510673312416,-0.2936666192919648
584.2000000000078,64.40039318414672,-1.7465106828592123,-0.29333099812905017
585.6000000000078,64.54130974722365,-1.7484870486986006,-0.2936641917435243
587.0000000000077,64.68073610967647,-1.748003675748849,-0.29369815202693994
588.4000000000078,64.82124763045782,-1.7525584525668527,-0.29499000044632284
589.8000000000078,64.96039351897508,-1.7514087639967275,-0.2959800821422891
591.2000000000078,65.10362475196035,-1.7552451655109387,-0.29630999626008236
592.6000000000079,65.24366848924495,-1.7617200960455235,-0.2962880928653031
594.0000000000078,65.38513123385576,-1.7653956464813048,-0.29565780285925003
595.4000000000078,65.52594152566385,-1.7675052200095709,-0.294580378209472
596.8000000000079,65.66656362142459,-1.7718119044608909,-0.2969505529321159
598.2000000000079,65.80816583740838,-1.773755833703041,-0.2969699999999733
599.600000000008,65.94830133163715,-1.7775667079041297,-0.29697000000148677
601.000000000008,66.08990344271116,-1.779066148627389,-0.297978266115448
602.4000000000079,66.23073191433363,-1.7813317683598218,-0.2992799603846432
603.800000000008,66.37151310030336,-1.783865889791577,-0.2992900480783023
605.200000000008,66.51285469112199,-1.7917181088803331,-0.2992799999995359
606.6000000000081,66.65394287618557,-1.7937595854465185,-0.2978674392583365
608.0000000000081,66.79411209482642,-1.7968590749140285,-0.29926999940936705
609.400000000008,66.93546398478036,-1.8018388140806754,-0.29927000960493455
610.8000000000081,67.07649472910165,-1.8088042204745207,-0.3005900299095763
612.2000000000081,67.21786550996914,-1.8127533193149277,-0.301910251932485
613.6000000000081,67.3584053220609,-1.8201049568517735,-0.30321448401607753
615.0000000000082,67.49885943910654,-1.8250394290595244,-0.3032300295213992
616.4000000000082,67.64097187614938,-1.8338164648898607,-0.3031636348816842
617.8000000000081,67.7839550821524,-1.8428533717962916,-0.30455243007689115
619.2000000000082,67.92524068369838,-1.849219442207573,-0.3045514647781338
620.6000000000082,68.06623084131127,-1.8581913477478686,-0.3058700009954034
622.0000000000083,68.20701012100828,-1.8599597996547323,-0.3071902270226312
623.4000000000083,68.35030130299386,-1.8675289433588953,-0.308195539966972
624.8000000000083,68.49131829765226,-1.8753123135526937,-0.30751586017727206
626.2000000000083,68.63279284858292,-1.880167567481455,-0.31015183134491187
627.6000000000083,68.77462103706216,-1.8880599540519118,-0.3085330920523299
629.0000000000084,68.91607257793652,-1.895331885708833,-0.31126291551386664
630.4000000000084,69.05811354867959,-1.9028465770243006,-0.3138747163877773
631.8000000000084,69.19824772667252,-1.9109854472972343,-0.3138797233745865
633.2000000000085,69.3401050843126,-1.9178743114472074,-0.31388206604947744
634.6000000000084,69.4822968660179,-1.9237233976632369,-0.31452978618035576
636.0000000000084,69.62462797082141,-1.9338943063000962,-0.31795784275817685
637.4000000000085,69.76607183447823,-1.9430486147066752,-0.31896691635318275
638.8000000000085,69.9079431559427,-1.9528884013444268,-0.3213872803114337
640.2000000000085,70.04795578684617,-1.969472643173663,-0.321548769587511
641.6000000000085,70.19083554232726,-1.9834218561332477,-0.3228816121082705
643.0000000000085,70.33381899704136,-1.9959945958418364,-0.32561581665878103
644.4000000000086,70.47490689792987,-2.01668454482061,-0.32727239749953485
645.8000000000086,70.61719203078235,-2.0342501667549278,-0.32924777990020004
647.2000000000086,70.75989675648688,-2.053525615897999,-0.3322210351293542
648.6000000000087,70.90030053169134,-2.071650858422416,-0.3351838135276548
650.0000000000086,71.04452201059202,-2.0871484910580422,-0.33753538745706546
651.4000000000087,71.18674007896087,-2.104570709581819,-0.33879354248227855
652.8000000000087,71.32882635502683,-2.119313580653151,-0.3439500713182113
654.2000000000087,71.47104103115255,-2.1355962384998692,-0.3442841254180542
655.6000000000088,71.61173879821779,-2.152483432163235,-0.34689848174199156
657.0000000000088,71.75624133519274,-2.1720457812564424,-0.35181147923555134
658.4000000000087,71.89872941525638,-2.190746930430232,-0.35166055772003935
659.8000000000088,72.04171751485266,-2.2145654639499224,-0.35568905878332524
661.2000000000088,72.18367604216236,-2.232098429623041,-0.35970088071000417
662.6000000000088,72.3256743579325,-2.255147563981522,-0.3663724889866775
664.0000000000089,72.4675204988026,-2.2765090074410628,-0.36895634006052624
665.4000000000088,72.61097036980362,-2.300596278020154,-0.37543657416765885
666.8000000000089,72.75314745599293,-2.321655325614355,-0.37725567739191757
668.2000000000089,72.89523984598648,-2.343342610196127,-0.38269627495317415
669.6000000000089,73.03829652832151,-2.3681346945141892,-0.3879212725794301
671.000000000009,73.18065166749322,-2.39142476976063,-0.3928139363058136
672.400000000009,73.32370993748027,-2.4194905814846477,-0.3972394845534417
673.800000000009,73.46536367402004,-2.4463744161927417,-0.40283340789566413
675.200000000009,73.6082603705141,-2.4748765282257064,-0.4099568470340662
676.600000000009,73.75092941192766,-2.507401103286102,-0.4150520828040758
678.0000000000091,73.89424205909177,-2.537402528110751,-0.42268343163335365
679.4000000000091,74.03615268861829,-2.5664084035960477,-0.4280304109852797
680.800000000009,74.17949252091839,-2.59918979960881,-0.434836891078322
682.2000000000091,74.32170025616772,-2.6354594940638556,-0.4425603927697144
683.6000000000091,74.46438730354181,-2.6656478894737434,-0.4504411476438528
685.0000000000091,74.60734198413131,-2.7031907316782777,-0.4551543326787937
686.4000000000092,74.74962334344656,-2.736609847397286,-0.4627166877627418
687.8000000000092,74.89326864501646,-2.7712351430425803,-0.473822302964817
689.2000000000093,75.03576982876226,-2.807578722032417,-0.4832480170494997
690.6000000000092,75.17852346069742,-2.84108731676838,-0.4917612515865928
692.0000000000092,75.32186299774413,-2.8814600851164083,-0.5002930374638836
693.4000000000093,75.4614718755991,-2.919851452359815,-0.5102861451914302
694.8000000000093,75.60742679642956,-2.958156334865897,-0.5211880308191956
696.2000000000094,75.749787986387,-2.9972085701915043,-0.5317805623462375
697.6000000000093,75.89383626076703,-3.0389672871311917,-0.5412565634421518
699.0000000000093,76.03701550310949,-3.0833403372434964,-0.5536889965342424
700.4000000000094,76.17954417549947,-3.131474728997776,-0.5670033855376766
701.8000000000094,76.32274310626487,-3.1789716666917096,-0.5804957833371449
703.2000000000094,76.46653300759023,-3.227290167869428,-0.5924832065914698
704.6000000000095,76.60949777204615,-3.277614781176604,-0.603010757551067
706.0000000000094,76.75319879335316,-3.3266207213738195,-0.616955492154879
707.4000000000094,76.89655409263219,-3.3810290639578686,-0.6307770127314867
708.8000000000095,77.0407232171736,-3.4338645496780873,-0.6485638317686706
710.2000000000095,77.1846819984965,-3.4882051014154576,-0.6644380089240518
711.6000000000096,77.33010375167852,-3.5436448655270003,-0.6816320307556305
713.0000000000095,77.473608342932,-3.6056724240127482,-0.6972854884782191
714.4000000000095,77.61791996426514,-3.6605707985057374,-0.7136331447800486
715.8000000000096,77.76439542723973,-3.716723293311645,-0.733527372914903
717.2000000000096,77.9066214284136,-3.7760501237173747,-0.7478835173418079
718.6000000000097,78.05040532553403,-3.8332986856924363,-0.7653140776470608
720.0000000000097,78.19512519664583,-3.8928081704819797,-0.7850943985737486
721.4000000000096,78.3377059970308,-3.952549366511623,-0.8057686470164853
722.8000000000097,78.48431334055789,-4.009895542362231,-0.8249995694354726
724.2000000000097,78.62786138242475,-4.071586645449706,-0.8491013271753927
725.6000000000097,78.77256773911695,-4.130109480990589,-0.8691614588668446
727.0000000000098,78.91597501574516,-4.18965428028143,-0.8889527993658182
728.4000000000098,79.06115081410162,-4.245826950772817,-0.911452653459984
729.8000000000097,79.204474053443,-4.301995915927039,-0.93538079576693
731.2000000000098,79.3489348756047,-4.353721726365987,-0.9581416261089943
732.6000000000098,79.49266932517097,-4.405116145601954,-0.9825539569621657
734.0000000000099,79.63583982300898,-4.454197936004815,-1.0052557486256242
735.4000000000099,79.77966593396563,-4.495651414029526,-1.0310188025028126
736.8000000000098,79.92334242091556,-4.533196718441454,-1.053166311808254
738.2000000000099,80.06672637024622,-4.5587419924441015,-1.0807782186688324
739.6000000000099,80.21000204639098,-4.5745003789245064,-1.106137782508395
741.00000000001,80.35352362507905,-4.575622227585556,-1.1306079316555544
742.40000000001,80.49587935578414,-4.55745557884922,-1.1554097990551888
743.80000000001,80.6369175473933,-4.5232106446278335,-1.1815717498522638
745.20000000001,80.77814750113572,-4.460109540794739,-1.2076716878992557
746.60000000001,80.91834337538903,-4.367284957669115,-1.2304478571276403
748.00000000001,81.05647031324811,-4.234570698591905,-1.2511623075699019
749.4000000000101,81.1947204072513,-4.049845848858849,-1.271297762082317
750.8000000000101,81.33175934185172,-3.8052386772520608,-1.2909167688589127
752.20000000001,81.46620278434206,-3.4843647002709734,-1.3076711063776747
753.6000000000101,81.5981594028742,-3.106722345128672,-1.3234242802304337
755.0000000000101,81.73217251864739,-2.7152328446578045,-1.3275099231351009
756.4000000000102,81.86728948319629,-2.407667302011314,-1.3338353661218538
757.8000000000102,82.00371301858512,-2.2096146882101206,-1.3373760272497828
759.2000000000102,82.1436982788376,-2.087995585624076,-1.3414667570577312
760.6000000000103,82.28407971632444,-2.0192275747607424,-1.342860479242332
762.0000000000102,82.426057437066,-1.980657193738591,-1.3445554400602506
763.4000000000103,82.56892939591538,-1.95213277533839,-1.3447568587005216
764.8000000000103,82.71192789477725,-1.9424177017873012,-1.3437167083383659
766.2000000000103,82.85379906016675,-1.9310360551909547,-1.3457400001342683
767.6000000000104,82.99574612281022,-1.9307158228576509,-1.3455575464290397
769.0000000000103,83.13976963869948,-1.9284150611182187,-1.3455653649587123
770.4000000000103,83.28244233989291,-1.9288972798272248,-1.3470491428904916
771.8000000000104,83.42486700323877,-1.926218548624641,-1.3457299825503442
773.2000000000104,83.56723016940768,-1.9286610568971352,-1.3447400022843214
774.6000000000104,83.71103526352793,-1.9296249502047083,-1.3450941108858925
776.0000000000105,83.85458658813802,-1.9309162619279416,-1.3474176892907606
777.4000000000104,83.99734004701557,-1.9362505822790006,-1.345370147362892
778.8000000000105,84.14150277648801,-1.936154741365605,-1.3427687774923562
780.2000000000105,84.28469755795174,-1.9357520247303461,-1.3454098664720284
781.6000000000105,84.42734735775319,-1.937708555149779,-1.347257874038708
783.0000000000106,84.571570718319,-1.937640309006478,-1.3469456058365683
784.4000000000106,84.71341620689319,-1.9424677127949175,-1.345620649215355
785.8000000000106,84.85731638316707,-1.9431085278950613,-1.3470288522547018
787.2000000000106,84.99961631160414,-1.94530308172174,-1.3452898269218116
788.6000000000106,85.14294918058653,-1.9469862721935987,-1.3452881846525409
790.0000000000107,85.28583625548109,-1.9477130157121034,-1.345289948292534
791.4000000000107,85.43008208638479,-1.9514656480952925,-1.3449600043773655
792.8000000000106,85.57309302270632,-1.953682368923534,-1.3452900339659983
794.2000000000107,85.71677348585412,-1.9555399098447366,-1.3445951100546418
795.6000000000107,85.86000216204455,-1.9605104811649947,-1.345999594648149
797.0000000000107,86.0029743213283,-1.9595388573741392,-1.3460379845843824
798.4000000000108,86.1456877322699,-1.961992092179801,-1.3462800000007067
799.8000000000108,86.28804589595754,-1.9627950922380812,-1.344976142025378
801.2000000000108,86.4324073697722,-1.96306453163678,-1.346281589089318
802.6000000000108,86.57469477852344,-1.9639790824898562,-1.345089371490305
804.0000000000108,86.71784632506876,-1.9643094686612452,-1.3472698856598981
805.4000000000109,86.86052021601218,-1.965899746823493,-1.3471423576556396
806.8000000000109,87.003891503943,-1.9661886736195302,-1.3474743959421795
808.200000000011,87.147512999487,-1.9720193203701273,-1.3451900924117641
809.6000000000109,87.29000206785628,-1.9736101062459759,-1.3468308441049057
811.0000000000109,87.43315229110057,-1.9773793695140263,-1.3446281931977464
812.400000000011,87.57625657977059,-1.9772826215113117,-1.3431984738098501
813.800000000011,87.71968763953082,-1.9806660000037033,-1.344633488252314
815.200000000011,87.8633628046018,-1.9798408152142004,-1.3433184694928677
816.600000000011,88.00746453847105,-1.9825755201390158,-1.3466841461412415
818.000000000011,88.15077710969781,-1.9851840232451265,-1.3472732437746
819.400000000011,88.29478945071013,-1.985675948021973,-1.3459500907363262
820.8000000000111,88.43795149380273,-1.9866556885437956,-1.3461948913729307
822.2000000000111,88.58099322996351,-1.9894660992518385,-1.3469400000102993
823.6000000000112,88.72415506045188,-1.9920101800546095,-1.3459649629584556
825.0000000000111,88.86787305851871,-1.9906630390113698,-1.3469399404884346
826.4000000000111,89.01146188606567,-1.9948535484222798,-1.3470393478665774
827.8000000000112,89.15411356694453,-1.995079544454596,-1.3455105509116034
829.2000000000112,89.29860849249725,-1.998612475233517,-1.3455099999620552
830.6000000000113,89.44228081724796,-1.997934463961445,-1.3458395243539458
832.0000000000113,89.58532353335296,-2.0035785057488487,-1.3471605034783334
833.4000000000112,89.72923687181763,-2.005515405781304,-1.347163216204987
834.8000000000113,89.87292978543618,-2.0091750834245605,-1.3484523953339687
836.2000000000113,90.0168589204238,-2.014222408879795,-1.3471643135281046
837.6000000000113,90.16100230588086,-2.011867819531369,-1.3451976662620622
839.0000000000114,90.30503218115605,-2.0130401326868337,-1.3451756665163965
840.4000000000113,90.44831904123913,-2.01659075232285,-1.347820248031744
841.8000000000113,90.59095905091861,-2.0183945252793714,-1.3478200011748016
843.2000000000114,90.735338784672,-2.0215074556146573,-1.3464998368279666
844.6000000000114,90.8792111357174,-2.0196935540354835,-1.3491695509638202
846.0000000000115,91.02251910420027,-2.0262126479589417,-1.3464990724646206
847.4000000000115,91.16577217407843,-2.027637703366738,-1.3465299071564871
848.8000000000114,91.3091794472374,-2.034974875247211,-1.3491101819905862
850.2000000000115,91.45353705134215,-2.0360852905624265,-1.3504591875861176
851.6000000000115,91.59573063845728,-2.039938804957922,-1.3484085556692484
853.0000000000116,91.74055819164286,-2.0453258554108236,-1.3450781120117266
854.4000000000116,91.88374296820629,-2.043515942810299,-1.3443656968241147
855.8000000000116,92.02721451243892,-2.0467534057073107,-1.3486466508007031
857.2000000000116,92.17173314865676,-2.045482231680585,-1.342549763237606
858.6000000000116,92.31532975243509,-2.0495827738473955,-1.348020857603132
860.0000000000116,92.45876004519829,-2.04926201547907,-1.3494749440750682
861.4000000000117,92.60267831406452,-2.053110581341419,-1.3471609886178975
862.8000000000117,92.7466205365938,-2.050653153046659,-1.3493873596077735
864.2000000000116,92.88999892335909,-2.0524899474280547,-1.34904179786784
865.6000000000117,93.03391499838276,-2.0557335361847526,-1.346930171465091
867.0000000000117,93.17791035322993,-2.059291356732001,-1.3475076969505193
868.4000000000118,93.32085170208506,-2.0627574679080887,-1.3468935425673667
869.8000000000118,93.46491851271341,-2.0592647685259733,-1.3484309874416511
871.2000000000118,93.60949632171486,-2.0615217048726313,-1.3495410321686871
872.6000000000118,93.75188789625776,-2.065629996750893,-1.3482601524337134
874.0000000000118,93.89548184458585,-2.061229727949407,-1.3469420423836027
875.4000000000119,94.03999800512558,-2.0700796326208724,-1.3482600000506935
876.8000000000119,94.18274264341913,-2.0686111196514365,-1.3482598291863805
878.2000000000119,94.32560887954365,-2.06918338342758,-1.3496490246153452
879.600000000012,94.46989449385738,-2.0711801421793474,-1.3498997987750605
881.0000000000119,94.61338210757557,-2.0738657843425368,-1.3485800907921384
882.4000000000119,94.7577654865022,-2.075853655817269,-1.348967415768311
883.800000000012,94.90070691311938,-2.0836366451277146,-1.3489200363923008
885.200000000012,95.04548424386127,-2.084762841541108,-1.3499423788880693
886.600000000012,95.18990002207963,-2.0850912605619403,-1.3512200020378748
888.000000000012,95.33376746080472,-2.0869456738161176,-1.3499100079241169
889.400000000012,95.47798998108281,-2.0950899387864834,-1.3515592983523974
890.8000000000121,95.62154525518432,-2.100029956033123,-1.349580073460403
892.2000000000121,95.76558850467136,-2.10460010581277,-1.3502399051289795
893.6000000000121,95.90781965392227,-2.105928259142056,-1.35286000062933
894.0000000000122,95.9502258206034,-2.1092906575035935,-1.3528600002383304