File: 01_Data/Cinder_Block/STA/N2/30K_min/Cinder_Block_STA_N2_30KData_230825_R3.csv
##Temp./Â°C,Time/min,DSC/(mW/mg),Mass loss/mg
28.1,15.397620630527884,-2.3233092812224045,0.014270320494635946
29.50000000000002,15.731745023161944,-2.217680761951566,0.010944481208202461
30.90000000000004,15.893684915659442,-2.145813294804371,0.010334135267782152
32.30000000000006,16.009918362472472,-2.0896112770878568,0.01003962319735141
33.70000000000008,16.10969474827058,-2.038876727718963,0.010855316689166727
35.1000000000001,16.197289290671613,-1.9941690122397897,0.009003395911093115
36.50000000000012,16.277742843512552,-1.9497042727362912,0.009526789487356968
37.90000000000014,16.35186447414159,-1.910660555272954,0.008547286570690371
39.30000000000016,16.422288986886706,-1.8701104761828298,0.008550043912530558
40.70000000000018,16.488895927804034,-1.8365908158068969,0.008758453056331383
42.1000000000002,16.553268179175202,-1.801858187354897,0.008247652756809831
43.50000000000022,16.61544111409903,-1.7695954126234825,0.007324008261893056
44.90000000000024,16.67485172647736,-1.7406446669526687,0.008206949728773782
46.30000000000026,16.734626216035096,-1.710433610051294,0.006681205026739079
47.70000000000028,16.79250453242387,-1.6845008482167596,0.007307315414910587
49.1000000000003,16.849041750168414,-1.6588945024850377,0.006930110923042854
50.50000000000032,16.903951432362373,-1.6363822486762871,0.006538222112564274
51.90000000000034,16.959179488623654,-1.6131049135259241,0.006309138032627448
53.30000000000036,17.011929318117033,-1.5930087843521756,0.005771920208680115
54.70000000000038,17.065879720547848,-1.5718845654963067,0.004629482173088562
56.1000000000004,17.119341656190358,-1.5528604339947716,0.0035856661943474144
57.50000000000042,17.17137985411734,-1.5374301922522486,0.003285064341713717
58.90000000000044,17.222972947785696,-1.5204300226877854,0.00378503450033163
60.30000000000046,17.274180221303485,-1.504961099686996,0.0036627221102332186
61.70000000000048,17.325189014587004,-1.4906035696858413,0.002319440406285622
63.1000000000005,17.375759989008284,-1.4762122624020593,0.0016781990173146966
64.50000000000051,17.426162869263234,-1.460654646834649,0.0016750535836282943
65.90000000000055,17.47590521329321,-1.4478892529712795,0.0019537158444649094
67.30000000000055,17.525846878466822,-1.4323383287699598,0.001851042902056399
68.70000000000059,17.57512836136586,-1.4202277731891286,0.0012869966658142218
70.10000000000059,17.624504718538276,-1.4049707591131615,-0.001121130158920458
71.50000000000063,17.67364975843985,-1.3894421265353674,-0.00252183310638765
72.90000000000063,17.722947011852995,-1.374276960993366,-0.001731568826730534
74.30000000000067,17.772200192204572,-1.3603260098978807,-0.0011047003402127054
75.70000000000067,17.820673420911486,-1.3452608413918692,-0.002372993329324391
77.1000000000007,17.86977706362874,-1.3304404809186212,-0.002436135890418356
78.50000000000071,17.918475039009987,-1.314845996692412,-0.0037241205624418683
79.90000000000074,17.966906313094523,-1.3013257723679614,-0.0035638462797660253
81.30000000000075,18.015076379291408,-1.2878880041462069,-0.0051553115547005035
82.70000000000078,18.063509478965997,-1.2726547608660614,-0.005101896361988878
84.10000000000079,18.111483840120897,-1.2602732101184024,-0.005035772950744644
85.50000000000082,18.159535889904873,-1.247437232839645,-0.005046648398400411
86.90000000000083,18.206906455693517,-1.2330230187980726,-0.0050335860638792695
88.30000000000086,18.254559847426744,-1.2205496853367979,-0.006500860779576456
89.70000000000087,18.30209191833991,-1.2072238509129236,-0.0065803287484311745
91.1000000000009,18.34962640130601,-1.1950786123702752,-0.007800041636789157
92.50000000000091,18.39661678108354,-1.1820477238664362,-0.006597301810351119
93.90000000000094,18.444234931441663,-1.1714035819089015,-0.007803701426743359
95.30000000000095,18.490664122231887,-1.156818114243026,-0.0078001577942283795
96.70000000000098,18.537478719328398,-1.1443841761059674,-0.00849461673821894
98.10000000000099,18.584492251455078,-1.1315963462292458,-0.009115127307047555
99.50000000000102,18.630907324458764,-1.1182184272574247,-0.011121475805451642
100.90000000000103,18.67769493020487,-1.1058001658412127,-0.011090315096912384
102.30000000000106,18.724045935972093,-1.0933249159801284,-0.011115137611965142
103.70000000000107,18.770482201467672,-1.0812810599217018,-0.012410557556679969
105.1000000000011,18.81705000316993,-1.0680130444948386,-0.012396604707347603
106.50000000000111,18.863021602751626,-1.0561829646586134,-0.011113216057630382
107.90000000000114,18.909117027046136,-1.0434975382982803,-0.011099932505802101
109.30000000000115,18.955543564013446,-1.0311554577368294,-0.011006037131073398
110.70000000000118,19.00181882343662,-1.0185808411373427,-0.012410049079939256
112.10000000000119,19.047929087185178,-1.0055785090985156,-0.012409580176095503
113.50000000000122,19.09388639855976,-0.9907892590414291,-0.012479995169194513
114.90000000000123,19.139603585265153,-0.9825031366607959,-0.012409895363464596
116.30000000000126,19.18588536766428,-0.9689167381256882,-0.012409923658856403
117.70000000000127,19.231960330508574,-0.9563047104303285,-0.012417283273545188
119.1000000000013,19.277346623870876,-0.9447220013018183,-0.015114416265354258
120.50000000000131,19.322837726611947,-0.93406911259492,-0.01505370604115841
121.90000000000134,19.36833074418531,-0.9203757617302228,-0.01373836261414052
123.30000000000135,19.414094567305124,-0.9100312979096218,-0.013729918867075419
124.70000000000138,19.45941226071318,-0.8969822040317179,-0.013729824116420986
126.10000000000139,19.503978229348608,-0.8867117003418001,-0.01396720046512634
127.50000000000142,19.549308964935513,-0.8750673271852252,-0.016345019769201663
128.90000000000143,19.594422066014964,-0.8635453526537007,-0.016370041057715667
130.30000000000146,19.638913448041233,-0.8524395604230796,-0.016363640545691727
131.70000000000147,19.68467744337671,-0.8402935346311654,-0.015019377032986725
133.1000000000015,19.729448448690476,-0.8295422800677983,-0.01635862227768481
134.5000000000015,19.77400192062476,-0.8172871576469833,-0.01635997930422395
135.90000000000154,19.818618964478787,-0.8045126312748692,-0.01635995900605325
137.30000000000155,19.8632709682716,-0.7958634286787389,-0.016359959042830496
138.70000000000158,19.907787366647312,-0.7840814072680142,-0.016359967585164448
140.1000000000016,19.95197224849357,-0.7731981630711577,-0.01635596310595755
141.50000000000162,19.995719239815706,-0.7617330646801281,-0.018472302638844695
142.90000000000163,20.0402747426923,-0.7505564882201049,-0.018669998135670607
144.30000000000166,20.084252779731234,-0.7414168438615257,-0.01866987944010079
145.70000000000167,20.12869058696597,-0.7304326122244287,-0.018669878004260898
147.1000000000017,20.172407488447828,-0.7184392752022984,-0.018669971304726474
148.5000000000017,20.215569161861026,-0.7082160233464206,-0.01868973913111649
149.90000000000174,20.26050054766184,-0.6969724346983222,-0.019666506474737666
151.30000000000175,20.30407046196164,-0.6885807129195883,-0.019659959868312704
152.70000000000178,20.347909498961705,-0.6758557157895858,-0.019661288329053228
154.10000000000178,20.391259464773793,-0.6661125726961549,-0.019992552447749112
155.50000000000182,20.43533134932422,-0.6559405458763745,-0.01998988394214951
156.90000000000182,20.47896673481072,-0.6464751661179629,-0.0199899011201925
158.30000000000186,20.52258642217194,-0.6378073643945248,-0.019973881617096456
159.70000000000186,20.565863812024155,-0.6273635224457154,-0.020321497934032706
161.1000000000019,20.60922418135072,-0.6176019039396081,-0.02030361676303727
162.5000000000019,20.652606232808775,-0.6082032463456511,-0.021048334849115058
163.90000000000194,20.6963067142196,-0.5997401027728165,-0.021309635596909793
165.30000000000194,20.740000000000062,-0.5884499999999857,-0.021310168997053847
166.70000000000198,20.783302090227377,-0.5785055279653346,-0.02131016809136277
168.10000000000198,20.826812488894234,-0.5704254233024915,-0.021310198958235382
169.50000000000202,20.870062390035667,-0.5612326079338295,-0.021408740285847383
170.90000000000202,20.913426840456193,-0.5510429668708008,-0.021639814685672665
172.30000000000206,20.956919992121453,-0.544003079345162,-0.02164016929919832
173.70000000000206,21.000272889852642,-0.5356050680010482,-0.021640169004576215
175.1000000000021,21.042954297012674,-0.5264912023584901,-0.021640169000011422
176.5000000000021,21.0864704408941,-0.5204715706492565,-0.02164016900000032
177.90000000000214,21.129632259491256,-0.5101457282555593,-0.021640169000018084
179.30000000000214,21.172639301556053,-0.5040639369779328,-0.02164016896635257
180.70000000000218,21.21556558200465,-0.49450684693966174,-0.021640156354684414
182.10000000000218,21.258679230081253,-0.48634856676528837,-0.02163872804468081
183.50000000000222,21.301480269551416,-0.47754787845194313,-0.021954072020340387
184.90000000000222,21.344465972998435,-0.47098900967589036,-0.02196037449057764
186.30000000000226,21.386645707375123,-0.4630952815096265,-0.022120803035840186
187.70000000000226,21.429601154855455,-0.45586280136147095,-0.023243441294882317
189.1000000000023,21.4723177038886,-0.44791813286920434,-0.024259061861235498
190.5000000000023,21.515365651061238,-0.43986065537371843,-0.02427001591616751
191.90000000000234,21.557851203087743,-0.43270126787879315,-0.024270060446279107
193.30000000000234,21.601199381081056,-0.42791374533228266,-0.0242704664746225
194.70000000000238,21.643992921005246,-0.4191110889605011,-0.024297127508295713
196.10000000000238,21.68624110888865,-0.4125279932808608,-0.023603858396185284
197.50000000000242,21.72931059165805,-0.4070149702154988,-0.022965619648977587
198.90000000000242,21.77192261169572,-0.3994452188668107,-0.02296122717496063
200.30000000000246,21.814342344884032,-0.3919235040383525,-0.024288232905378404
201.70000000000246,21.856425310072186,-0.3861005694092115,-0.025629650330117215
203.1000000000025,21.89874955843203,-0.3806816768246628,-0.025591717007651837
204.5000000000025,21.94203083498273,-0.373887484198895,-0.025807097546460156
205.90000000000254,21.98478209847966,-0.3686562974559308,-0.02559005913741652
207.30000000000254,22.027514160940946,-0.3612179978041199,-0.02558995079162596
208.70000000000258,22.06984719434633,-0.3553321458141403,-0.025589950997354727
210.10000000000258,22.112373283964615,-0.3479099199120705,-0.02558995100003081
211.50000000000261,22.155096928238915,-0.3444441824333586,-0.025589950991574018
212.90000000000262,22.19737819716671,-0.33771665389066774,-0.025589944054361435
214.30000000000265,22.239970348239286,-0.33338357468607094,-0.025588075105484887
215.70000000000266,22.282709310596193,-0.32505824776781217,-0.024251353587725344
217.1000000000027,22.324761794882743,-0.3210317515423306,-0.025597129360031445
218.5000000000027,22.367598930813504,-0.31542525050059084,-0.025590314456042762
219.90000000000273,22.4096653487195,-0.3102941567524299,-0.024283121395551444
221.30000000000274,22.451959759433674,-0.30527134059074384,-0.025581014986405304
222.70000000000277,22.494432805158162,-0.30008211687143765,-0.026883418547309024
224.10000000000278,22.537118261483627,-0.2969750196496533,-0.026909759635176833
225.5000000000028,22.579110954807305,-0.2901770638716702,-0.02690984289210796
226.90000000000282,22.6220115269144,-0.2871580773657295,-0.026909843000765044
228.30000000000285,22.663747340873933,-0.28147973204742593,-0.026909843000057165
229.70000000000286,22.706244227765577,-0.2761266454401383,-0.026909843077792317
231.1000000000029,22.74871662110926,-0.2724889256964723,-0.026909867201654336
232.5000000000029,22.790732380706782,-0.2658899195189416,-0.026913882675258627
233.90000000000293,22.83316557660287,-0.26338716896845504,-0.026253837299805127
235.30000000000294,22.875307249474886,-0.2581811798565654,-0.02624628410456964
236.70000000000297,22.917503930118222,-0.25311280678039405,-0.027457790564567652
238.10000000000298,22.960088163901272,-0.25065435256400004,-0.027560216795313952
239.500000000003,23.002536208969495,-0.2468886831347816,-0.027608145741836232
240.90000000000302,23.044569818407805,-0.24173371374688182,-0.026906286222851072
242.30000000000305,23.08658993632371,-0.23804191261647448,-0.026902949144908206
243.70000000000306,23.128790362396305,-0.2342432616859062,-0.02821388045035844
245.1000000000031,23.171273478389313,-0.2307179221614387,-0.0282201804371649
246.5000000000031,23.21316780871067,-0.22632382685186408,-0.0282201580108854
247.90000000000313,23.255601565379635,-0.22288731440912105,-0.028219817482485254
249.30000000000314,23.297790677989024,-0.22028518798712188,-0.028162089803048573
250.70000000000317,23.339791094484628,-0.2169820181097219,-0.028880278809044313
252.10000000000318,23.38215571068046,-0.2129638259654162,-0.028880099107511548
253.5000000000032,23.424529954707367,-0.2121630680769811,-0.028880104964104092
254.90000000000322,23.466419341375335,-0.20821097439085814,-0.02888010499985949
256.30000000000325,23.50873686726743,-0.2061308129764327,-0.02888010499957705
257.70000000000323,23.551277200897772,-0.20290358826300725,-0.028880105118532562
259.1000000000033,23.592749542451934,-0.19989697825858715,-0.02888015527104848
260.5000000000033,23.635620755990765,-0.1982887163141686,-0.02889959331564107
261.90000000000333,23.677572916732483,-0.19561361329778582,-0.029531901163928787
263.30000000000337,23.71962373931897,-0.1924646972046471,-0.02954004529637455
264.70000000000334,23.76223906214397,-0.19085827057462787,-0.029540051041304416
266.1000000000034,23.80434401921376,-0.18958705737272313,-0.029540022891862527
267.5000000000034,23.846546847271018,-0.18723553563799297,-0.029533857523780238
268.9000000000034,23.888756376443556,-0.1853421214173965,-0.030853788504939583
270.3000000000035,23.93077580527629,-0.1832574893890605,-0.030859957405412697
271.70000000000346,23.97322859811207,-0.18013573148356007,-0.030859942107420935
273.1000000000035,24.015267847453515,-0.17936286609530178,-0.030859225573292903
274.5000000000035,24.057400015221113,-0.17776190065561895,-0.03054869275833827
275.9000000000035,24.09967224111029,-0.17704614724082707,-0.0298693892095665
277.30000000000354,24.14181278573073,-0.17596139529407204,-0.029869996912641472
278.70000000000357,24.183905564925617,-0.17363598462866545,-0.03126633893820063
280.10000000000355,24.226243217172378,-0.173732367100868,-0.031180451588823654
281.50000000000364,24.26857284788725,-0.1714462508726986,-0.031179944425368422
282.9000000000036,24.31113633714235,-0.1708160062488606,-0.031179943002160204
284.30000000000365,24.352850026521917,-0.16801847871014813,-0.031179942999988608
285.7000000000037,24.39542627107389,-0.16783980921547764,-0.031179943000232857
287.10000000000366,24.437872483865938,-0.16692909506168643,-0.03117994304125249
288.5000000000037,24.480157613444316,-0.16590390414256634,-0.031179942158105156
289.90000000000373,24.52199381283842,-0.16425319484212922,-0.031177189850802645
291.30000000000376,24.564454140563914,-0.16332000314402756,-0.032418017242647146
292.70000000000374,24.607164485054344,-0.16088086223277462,-0.03249975834389707
294.1000000000038,24.648988566854726,-0.1606944577247621,-0.032499856422774975
295.5000000000038,24.691489841160934,-0.160231577994148,-0.032498459256827594
296.90000000000384,24.73374407223317,-0.1591760422647895,-0.031867226221073075
298.3000000000038,24.776254132473184,-0.15761769722417457,-0.03184992802560105
299.70000000000385,24.81874701724187,-0.1575250152248101,-0.03184983529500318
301.1000000000039,24.86112217563995,-0.15695637578894772,-0.03184983555146559
302.5000000000039,24.903697837029608,-0.15628210328830983,-0.03185195977146371
303.9000000000039,24.946047876806634,-0.15489163723576468,-0.032887494216103264
305.30000000000393,24.988168309485026,-0.1545706721212688,-0.03318021924249681
306.70000000000397,25.030974051975107,-0.15326465855258592,-0.03315917508655941
308.100000000004,25.073176004967234,-0.15315822767617562,-0.034081572987802566
309.500000000004,25.11580249626506,-0.15226741212318295,-0.03446944960765608
310.900000000004,25.158190689952047,-0.1512536866149787,-0.034470148934545364
312.30000000000405,25.201028393404673,-0.15244821586841853,-0.03447022742461314
313.7000000000041,25.243428762484605,-0.15219015817979137,-0.033791520753241766
315.10000000000406,25.28604434771766,-0.15265148639705514,-0.03316150206528201
316.5000000000041,25.328427943615733,-0.15243382149727158,-0.033176657249606833
317.9000000000041,25.370834689221848,-0.1529300536403278,-0.03446902485087833
319.30000000000416,25.41360663757933,-0.1519129016042627,-0.03445783202217312
320.70000000000414,25.456206049077863,-0.15126911403004897,-0.033153691040390676
322.1000000000042,25.498816852793716,-0.15100894758003897,-0.033161980573872984
323.5000000000042,25.5415080138393,-0.15085105916896804,-0.034473962544947945
324.90000000000424,25.58404889598189,-0.15207063458210313,-0.034470025680493954
326.3000000000042,25.625989485024874,-0.15104450000668557,-0.03447015034749734
327.70000000000425,25.66938286517643,-0.15177674809193048,-0.03447015099497808
329.1000000000043,25.71215747343196,-0.15253419121105866,-0.03447015095903172
330.5000000000043,25.75472868004466,-0.15155102460838626,-0.03447038315309037
331.9000000000043,25.797418114576363,-0.15206510980182392,-0.03347834624355617
333.30000000000433,25.840417184054413,-0.15194343921680914,-0.033502085697074246
334.70000000000437,25.882884514387236,-0.15195382300794702,-0.03543277470554207
336.1000000000044,25.92557069046787,-0.15314254689564,-0.03545996503630322
337.5000000000044,25.968406867692273,-0.15219057067511693,-0.035466714567861324
338.9000000000044,26.011412459537553,-0.15377559455857315,-0.03579169627047829
340.30000000000445,26.054396432322882,-0.15433503337171792,-0.03579342790904727
341.7000000000045,26.09715630350174,-0.15519752546159743,-0.034502799247650984
343.10000000000446,26.139908930503847,-0.15760471603860352,-0.034473580262424974
344.5000000000045,26.182879052410872,-0.15749233703217208,-0.035793190936216135
345.9000000000045,26.22556004741004,-0.15813395996751495,-0.03579007286170066
347.30000000000456,26.26897975464129,-0.1578070411877508,-0.03578991756646399
348.70000000000454,26.311900340128336,-0.15915736824016394,-0.0354874565326746
350.10000000000457,26.354894354986758,-0.158991921879005,-0.034481548129375206
351.5000000000046,26.398003603772597,-0.15955412895251805,-0.03537716426335269
352.90000000000464,26.440928390643144,-0.16026978234336034,-0.035789486623575506
354.3000000000046,26.483979978259725,-0.1628033534484456,-0.03579004475227565
355.70000000000465,26.52718069973986,-0.16293063027446164,-0.035790042829650925
357.1000000000047,26.570062368371353,-0.16341923471466832,-0.03579004439182354
358.5000000000047,26.613059020269354,-0.16387717637807256,-0.035816627796076084
359.9000000000047,26.655575563803513,-0.16669219666581356,-0.03711579413610977
361.30000000000473,26.699547584370855,-0.1657429890309526,-0.03710993765830217
362.70000000000476,26.74266962372212,-0.16721380102814803,-0.03711020239057028
364.1000000000048,26.786044242844266,-0.16746901115624216,-0.03720852836805921
365.5000000000048,26.828928954180654,-0.16749982780938974,-0.03579031882122008
366.9000000000048,26.871903941807098,-0.16787413473097243,-0.03578234458686902
368.30000000000484,26.915406135235678,-0.17028324048861007,-0.03674279955183746
369.7000000000049,26.958776322769758,-0.17004780577053072,-0.03582384599613775
371.10000000000485,27.002145188831967,-0.17155825359097812,-0.035799972478158804
372.5000000000049,27.04548582322225,-0.17410531408079372,-0.03579993484887334
373.9000000000049,27.08855587171308,-0.17496496652190016,-0.03579994009322407
375.30000000000496,27.131756529053273,-0.17685677000797548,-0.03580071704543286
376.70000000000493,27.175234013997752,-0.17802243238938292,-0.036586266841649895
378.10000000000497,27.21835467607671,-0.17930471225546932,-0.037109768406621946
379.500000000005,27.26193336498131,-0.18111958499577818,-0.03793290074613331
380.90000000000504,27.30500494934699,-0.1827408175374054,-0.03842901929545617
382.300000000005,27.34812836357143,-0.1863473526259668,-0.03842982536807327
383.70000000000505,27.39202742084083,-0.18838184228503857,-0.03842982368625325
385.1000000000051,27.43513768025789,-0.189860309589096,-0.03842827093412815
386.5000000000051,27.478924311552674,-0.19022229866535706,-0.0370900757141972
387.9000000000051,27.522090251539645,-0.1932420519856352,-0.037110044346787774
389.3000000000051,27.565496684108556,-0.19532980639661238,-0.03710994527105216
390.70000000000516,27.608674492302203,-0.1951237140542201,-0.0371111305445857
392.1000000000052,27.652314695342994,-0.1977622161062016,-0.038408694084421935
393.5000000000052,27.695522947405884,-0.1999020301174821,-0.039151820921079494
394.9000000000052,27.73921453937658,-0.20434962349339203,-0.03909015850157482
396.30000000000524,27.78277487318158,-0.20252691887132385,-0.039089827176880476
397.7000000000053,27.825969980514582,-0.20280044797595675,-0.03908982699757857
399.10000000000525,27.869783980908878,-0.20514042175889746,-0.03908982700042296
400.5000000000053,27.91297563301615,-0.20602744312127985,-0.03908982548768947
401.9000000000053,27.95671452372653,-0.20836509862697297,-0.03908933540136328
403.30000000000535,28.000315155862474,-0.2110301979179261,-0.039108433960064026
404.70000000000533,28.043754439002992,-0.21248015401022774,-0.04040056061875319
406.10000000000537,28.087512768033612,-0.21564111920028523,-0.040387437021729866
407.5000000000054,28.131059627799498,-0.21811334128658863,-0.039096225901250836
408.90000000000543,28.17477289029096,-0.21977091311423883,-0.03909153513741703
410.3000000000054,28.2184750670908,-0.22151658852349523,-0.03992342089841294
411.70000000000545,28.262221070862175,-0.22626862554522734,-0.04107259228988136
413.1000000000055,28.305669683715976,-0.2277754547868349,-0.041060050307364815
414.5000000000055,28.349437772868605,-0.23139382052261598,-0.0410601426605548
415.9000000000055,28.393061025103883,-0.2334261876573817,-0.04106014300016669
417.3000000000055,28.43713805819858,-0.23893649249497045,-0.04106014299916172
418.70000000000556,28.480582896666466,-0.24184660705209712,-0.041060143072741084
420.1000000000056,28.52452319438532,-0.24344968066988074,-0.04106025464513596
421.50000000000557,28.568304827407875,-0.24818297270553333,-0.04107683636589998
422.9000000000056,28.611988092936844,-0.2542632264171158,-0.041759259073783195
424.30000000000564,28.655841271217675,-0.2576011361962539,-0.041719691259207714
425.7000000000057,28.69971649498132,-0.2618413167501119,-0.04171978165443546
427.10000000000565,28.743685535370425,-0.2681128293096322,-0.04174642472521706
428.5000000000057,28.787127751175195,-0.2725807834802884,-0.04304394293493008
429.9000000000057,28.831540292313406,-0.27719478507776063,-0.043040040601381335
431.30000000000575,28.87538614663231,-0.28173436614194863,-0.043040034980427855
432.70000000000573,28.91920447852591,-0.285008629485856,-0.043040035285021094
434.10000000000576,28.96316006564855,-0.28683399469941373,-0.04303971547039698
435.5000000000058,29.007318435426356,-0.28707255937389653,-0.04296036685639937
436.90000000000583,29.050848841171785,-0.28654935203239634,-0.04436020407600916
438.3000000000058,29.09448452885534,-0.2878969855375433,-0.04435993025416085
439.70000000000584,29.139178306050205,-0.28898071686249777,-0.04435992640584363
441.1000000000059,29.183288477478936,-0.2888163610472487,-0.04436064061178158
442.5000000000059,29.227382319602455,-0.28894427215181295,-0.044805202433418234
443.9000000000059,29.271404071073036,-0.29007046136165865,-0.0456791920248083
445.3000000000059,29.31536327275549,-0.2913708692440426,-0.04567999273103762
446.70000000000596,29.35938195331147,-0.2918220626256732,-0.045690760957591614
448.100000000006,29.40361481278336,-0.2949050811727504,-0.04534951976000423
449.50000000000597,29.4478075243277,-0.29739950514097835,-0.044812694460648395
450.900000000006,29.491924677077538,-0.30168661276668984,-0.04468964308263246
452.30000000000604,29.536251031686653,-0.3031493292269064,-0.04470517866681423
453.70000000000607,29.580435903688613,-0.3069486872394947,-0.04599660873408018
455.10000000000605,29.624877297440005,-0.3115110940224413,-0.04600409588930887
456.5000000000061,29.66920363383616,-0.3140901598955914,-0.04735965368780626
457.9000000000061,29.713408761756757,-0.3183812970645695,-0.04731981338172453
459.30000000000615,29.75809563303128,-0.32184820049834667,-0.04731980671788749
460.7000000000061,29.80260724307163,-0.3264745295261277,-0.04731962980870019
462.10000000000616,29.846871457143727,-0.3314264480476417,-0.046814999957063286
463.5000000000062,29.891333638781177,-0.33534097894646614,-0.047320105071087415
464.90000000000623,29.935761210308733,-0.3399643370772946,-0.04731209482081944
466.3000000000062,29.98009757190132,-0.3474012150775145,-0.0459947799488738
467.70000000000624,30.02517883945814,-0.3510274857159429,-0.04736512648167679
469.1000000000063,30.06955546802481,-0.3559071712312958,-0.04732001992612167
470.5000000000063,30.114532736139683,-0.3644402080223282,-0.047320035549095696
471.9000000000063,30.159036638821377,-0.37003675038382017,-0.04728241551823631
473.3000000000063,30.203687541940827,-0.3745810281240288,-0.04863516812284718
474.70000000000636,30.248579512876113,-0.38148886921949376,-0.04863982167746528
476.1000000000064,30.292867120920906,-0.3860634304041116,-0.048776636459625156
477.50000000000637,30.338066909370994,-0.39443923419237403,-0.04996128875442585
478.9000000000064,30.382542924188666,-0.40023714188187365,-0.04995988785257799
480.30000000000643,30.427401604167184,-0.4083367598339902,-0.049959892333867106
481.70000000000647,30.472555839559423,-0.4125456777104541,-0.04995975635550032
483.10000000000645,30.51711220945107,-0.4178042215281512,-0.04991164586058705
484.5000000000065,30.561916657251416,-0.4222034547740609,-0.05127256506595668
485.9000000000065,30.606775422029315,-0.4279400799559179,-0.05126982060700502
487.30000000000655,30.65131396310222,-0.4338416882213477,-0.0512698090210284
488.7000000000065,30.696468940761953,-0.4391405432405069,-0.0512698160083338
490.10000000000656,30.741396227874645,-0.4458117666773727,-0.05126533122541099
491.5000000000066,30.78651243458224,-0.4521253257427855,-0.05257222927758898
492.9000000000066,30.831311825370552,-0.45845119419568375,-0.05394508739640136
494.3000000000066,30.87644150411277,-0.4612712854763464,-0.05391873126317215
495.70000000000664,30.92147789647919,-0.4693755348802264,-0.052392471061524226
497.1000000000067,30.966305637879902,-0.47457957101316905,-0.05299195022270853
498.5000000000067,31.01116100230239,-0.4786207524475611,-0.05236538217424691
499.9000000000067,31.056629251510092,-0.48404717323928015,-0.05236970858672896
501.3000000000067,31.101542943024292,-0.48872679240163003,-0.05242535166097273
502.70000000000675,31.146635376867113,-0.4933368581409946,-0.05497688569492354
504.1000000000068,31.191434503479904,-0.49720335533379806,-0.05500989133453249
505.50000000000676,31.236618137615388,-0.5030462957119012,-0.055009883917233715
506.9000000000068,31.281619755202303,-0.5059120359740138,-0.05500992424161755
508.30000000000683,31.326707949605336,-0.5104019969834412,-0.0550342726925952
509.70000000000687,31.37172262682664,-0.5140220928193029,-0.056323120795707116
511.10000000000684,31.416918955478042,-0.5171991148111091,-0.05800405929648367
512.5000000000068,31.462051531130115,-0.5210885115483599,-0.057970033264961085
513.9000000000069,31.507264005325965,-0.5235817142689253,-0.0579700922059696
515.300000000007,31.552298395374276,-0.5274383433951366,-0.05796994326780247
516.7000000000069,31.597467371744575,-0.5299633124405277,-0.059091163882512454
518.100000000007,31.64235143298322,-0.5323851338368591,-0.059290428506263204
519.500000000007,31.687781750915665,-0.53637327615622,-0.05928407892605403
520.900000000007,31.733037463642987,-0.5360738539484504,-0.060616404472694896
522.300000000007,31.77822911532488,-0.537987187727431,-0.06060846149182719
523.7000000000071,31.8232040115923,-0.5405441501719312,-0.059269781940149535
525.1000000000071,31.86842296264203,-0.5423187810388843,-0.05903466565773474
526.500000000007,31.913870401110497,-0.5447936891675085,-0.06156227465607067
527.9000000000071,31.958818340816748,-0.5475369291413701,-0.062139633874069844
529.3000000000071,32.00418240774688,-0.551158898518,-0.06216108647546559
530.7000000000071,32.0495341222455,-0.5550135427801762,-0.06346044900390924
532.1000000000072,32.09448010565822,-0.5594799033506473,-0.06345930680143219
533.5000000000072,32.13987041429344,-0.562292554805212,-0.06275514236513802
534.9000000000071,32.18523942478051,-0.5673048919198299,-0.06379596255935338
536.3000000000072,32.23044641471029,-0.5693246822861903,-0.06378996585088137
537.7000000000073,32.27580296097213,-0.5741695248472442,-0.065190519714311
539.1000000000072,32.3212399559376,-0.5797900270627081,-0.06511003513069946
540.5000000000073,32.366203945191515,-0.5854675856502932,-0.06511009414923441
541.9000000000073,32.41171831790428,-0.5904191299290558,-0.0651052354926085
543.3000000000073,32.45699347426135,-0.5934260914457073,-0.06646245600832312
544.7000000000073,32.50228031819887,-0.5969827168982483,-0.06773824208364987
546.1000000000074,32.54801037717195,-0.6027125077351791,-0.06769321419360885
547.5000000000074,32.5932525497623,-0.606525514777901,-0.06840050614128668
548.9000000000074,32.63842615123168,-0.6117236373858802,-0.06839991781055144
550.3000000000075,32.68398090354687,-0.6162477649347419,-0.06840004266374189
551.7000000000074,32.72930658753188,-0.6232790490742874,-0.06867595733739362
553.1000000000074,32.7746259208726,-0.63006584297618,-0.06973018544135634
554.5000000000075,32.82046179480816,-0.6364302744872166,-0.0710367434432575
555.9000000000075,32.86580737676451,-0.6406444330753285,-0.07197658124522377
557.3000000000076,32.91124152163883,-0.6477268696756555,-0.07234877528948758
558.7000000000075,32.95663112116099,-0.6525182794203677,-0.07365165899780646
560.1000000000075,33.00220659952522,-0.6566462761368156,-0.07366994877676625
561.5000000000076,33.04741239743626,-0.6611819159609185,-0.0736699260055369
562.9000000000076,33.093155838164115,-0.6699745090092972,-0.07366541856294262
564.3000000000076,33.138273824796265,-0.6750883857264534,-0.07497966143637713
565.7000000000077,33.18403672091391,-0.6829377919766196,-0.07519386170031161
567.1000000000076,33.229400078646584,-0.6879933878398911,-0.0763004847599289
568.5000000000077,33.275208971012944,-0.6941720845943201,-0.0763015150298858
569.9000000000077,33.320279260946634,-0.703819062225633,-0.07704104865691175
571.3000000000077,33.366343397100636,-0.7100271655214355,-0.07697409100842556
572.7000000000078,33.41183129437838,-0.7179283190198481,-0.07826911586132912
574.1000000000078,33.457719197385686,-0.7281100416810219,-0.07904618689883058
575.5000000000077,33.503612761113786,-0.7362192231173279,-0.07959967010555768
576.9000000000078,33.54899806080554,-0.7424802622350691,-0.07959979702791253
578.3000000000078,33.59499100303886,-0.7484824721781355,-0.07966019877725294
579.7000000000079,33.6405671626253,-0.7538838902595014,-0.07959818019094733
581.1000000000079,33.68634116844152,-0.7594872617580883,-0.08090592511788985
582.5000000000078,33.732216862540966,-0.7662456227942893,-0.08223507386226725
583.9000000000079,33.77793972192703,-0.7772941693745339,-0.08474593935683483
585.3000000000079,33.823648509801444,-0.7835272014931709,-0.08518772203620761
586.7000000000079,33.86986847047586,-0.7904216209268626,-0.08618008202681393
588.100000000008,33.91585255242378,-0.7989525167902873,-0.08673489538601453
589.500000000008,33.961770963769915,-0.8055797263235005,-0.08686034222737682
590.900000000008,34.007655593323456,-0.8156908778694016,-0.08740486013479698
592.300000000008,34.05355918424791,-0.8244760620575387,-0.08749263333806523
593.700000000008,34.09976911288241,-0.8342175564112188,-0.09009334886253262
595.1000000000081,34.145841461829974,-0.8414295929457398,-0.09168450600215072
596.5000000000081,34.19184251077277,-0.8506585960939238,-0.09149905718779783
597.900000000008,34.23761422569322,-0.8599823821216044,-0.09119351244220208
599.3000000000081,34.28415518177173,-0.8652922577062041,-0.09165412243118709
600.7000000000081,34.3303873409726,-0.8765243856870144,-0.09276963518833004
602.1000000000082,34.37616189540373,-0.8827952104840945,-0.09376311473303245
603.5000000000082,34.42232522611719,-0.8925446761136817,-0.09493223818900542
604.9000000000082,34.468518210063785,-0.8993433921354806,-0.09539931885471242
606.3000000000083,34.51459745948997,-0.9052922815258327,-0.09680617167443772
607.7000000000082,34.56099612906717,-0.9107432013690092,-0.09713749326909804
609.1000000000082,34.60708837573595,-0.9174821648655482,-0.09803153506701223
610.5000000000083,34.65332851968877,-0.9220974617777193,-0.09936822638903342
611.9000000000083,34.699549276362234,-0.9265395535222987,-0.10030132218955279
613.3000000000084,34.74573649077062,-0.9303073431529951,-0.10230987914916767
614.7000000000083,34.79144872502594,-0.9329997647886993,-0.10299116514933715
616.1000000000083,34.838092066524275,-0.9366101639204121,-0.10352470166310557
617.5000000000084,34.88415726263479,-0.9395065751884204,-0.10489783019520038
618.9000000000084,34.93033851029026,-0.941049415885376,-0.10484499556637328
620.3000000000084,34.97631940097602,-0.9452036070848042,-0.10620958794040236
621.7000000000085,35.0229046547772,-0.949988351942989,-0.10767614214258225
623.1000000000084,35.06920082325448,-0.9547426792925944,-0.11076170690528198
624.5000000000085,35.115352496106375,-0.9578377043246952,-0.11284548211267431
625.9000000000085,35.161380025101224,-0.9618733471616704,-0.11006719879583793
627.3000000000085,35.2079649899988,-0.9654047279020809,-0.11044907126029324
628.7000000000086,35.25435868914268,-0.9730061326064643,-0.11177122002836315
630.1000000000085,35.3004861791829,-0.9785612098293267,-0.113081750755335
631.5000000000085,35.34654742402659,-0.9874133041361336,-0.11307602414917595
632.9000000000086,35.392834793202155,-0.9946570462441,-0.11444537093318186
634.3000000000086,35.43950114912673,-1.0058543102145212,-0.11469872365183198
635.7000000000087,35.485673762225105,-1.0124061073809725,-0.116974253796708
637.1000000000087,35.532030314479755,-1.0179601041455588,-0.11843290626301473
638.5000000000086,35.57818318351372,-1.0265667959144864,-0.12070517521430446
639.9000000000087,35.62459780145074,-1.0372455370607125,-0.12123503729808016
641.3000000000087,35.67100740048715,-1.0480751781582203,-0.12135471595219327
642.7000000000087,35.717284374845974,-1.0562756120483592,-0.12264596319240484
644.1000000000088,35.763647180276834,-1.065864100807243,-0.12524986784437075
645.5000000000088,35.80975284123072,-1.0757522335071121,-0.1265926913521187
646.9000000000088,35.856471321451686,-1.0838110850112483,-0.12784190745402135
648.3000000000088,35.90290316364676,-1.0911473779292105,-0.12825552181468947
649.7000000000088,35.94898607337124,-1.0996629493541503,-0.12955702959117854
651.1000000000089,35.99523824903264,-1.107977518198036,-0.13088162955720906
652.5000000000089,36.0419025661288,-1.1177470757305525,-0.13219413362258692
653.9000000000088,36.088308706427206,-1.1287924577416644,-0.13357557202691428
655.3000000000089,36.13452456862874,-1.1392416531381426,-0.1351464937404745
656.7000000000089,36.18091605298284,-1.1536357436148241,-0.13753750221286776
658.100000000009,36.22756048427845,-1.1640413171845285,-0.13925669633485915
659.500000000009,36.273984259150986,-1.1742880392528825,-0.14003793968316103
660.900000000009,36.3203648036494,-1.1877394464140982,-0.14119941545045966
662.300000000009,36.36709785100741,-1.1995124332534648,-0.14256333718524594
663.700000000009,36.41361818357724,-1.2140806007461915,-0.14394013245565773
665.100000000009,36.460136242736915,-1.2292386654627283,-0.14788543905762186
666.5000000000091,36.50646064957142,-1.2468288022772447,-0.14841408741825024
667.9000000000091,36.553135104442795,-1.2650487848180367,-0.14808884916697762
669.3000000000092,36.599865928641705,-1.288135527655022,-0.14952962713251283
670.7000000000091,36.64674784464853,-1.3080993487934685,-0.15093964284695893
672.1000000000091,36.69319520714054,-1.3305000153835647,-0.1535638815648932
673.5000000000092,36.73983025104361,-1.3563127263770263,-0.15545711105698246
674.9000000000092,36.78683052849559,-1.3803642306001929,-0.15813120315598805
676.3000000000092,36.83346150411974,-1.4054008506052835,-0.1596781562664309
677.7000000000093,36.8800649348357,-1.4335301931894597,-0.16138462999766556
679.1000000000092,36.92717162977571,-1.4624205677392779,-0.1645634747478737
680.5000000000093,36.9737723206955,-1.4915434277641666,-0.16696313945968377
681.9000000000093,37.02033016947186,-1.5225921621919103,-0.16896193847280028
683.3000000000093,37.06668402897906,-1.5513785389353618,-0.16942941051863736
684.7000000000094,37.114422105346044,-1.5832486984321066,-0.17228790229054347
686.1000000000093,37.161122262856274,-1.6124465466066418,-0.17534655894635076
687.5000000000093,37.20769059689746,-1.6476824186001822,-0.1786038333687867
688.9000000000094,37.25422082346155,-1.6808208746990743,-0.18189305222171814
690.3000000000094,37.30154024817987,-1.7139713980644662,-0.18472532579236756
691.7000000000095,37.34890934569679,-1.7529217939077193,-0.1871736773121757
693.1000000000095,37.39570609936166,-1.7848255052577358,-0.1908824949810981
694.5000000000094,37.442695748482265,-1.8221623747652549,-0.19400848852992159
695.9000000000095,37.489763915124904,-1.8566331526704638,-0.19771168834335429
697.3000000000095,37.53628876619852,-1.8927425512112215,-0.20180815300818278
698.7000000000095,37.58359773168039,-1.9358421104360541,-0.2063713827315934
700.1000000000096,37.63080017415142,-1.9746467309860969,-0.21094331586199822
701.5000000000095,37.67749408005189,-2.0157057404635195,-0.2135786080387314
702.9000000000096,37.724574527453626,-2.058545286692794,-0.21712791412054377
704.3000000000096,37.771487010832786,-2.1069173710897653,-0.22117088876049218
705.7000000000096,37.81856345394688,-2.155745339833203,-0.22429316811174882
707.1000000000097,37.86559861040979,-2.204437884664644,-0.2288906332319507
708.5000000000097,37.9128518077434,-2.2597197920490495,-0.234084228823503
709.9000000000096,37.95979839689966,-2.310743115707859,-0.2376698005053064
711.3000000000097,38.007228950039945,-2.3675214317100646,-0.24248878835345566
712.7000000000097,38.054272973308,-2.426922769635635,-0.24804160476707615
714.1000000000098,38.10141904043096,-2.4881319817444605,-0.25435753580615206
715.5000000000098,38.14844947807621,-2.548154428757138,-0.25854650161626846
716.9000000000098,38.195629917061815,-2.612690437942504,-0.2641956228039555
718.3000000000098,38.24289327832487,-2.6775537911881715,-0.27019203143153714
719.7000000000098,38.29026469579063,-2.7472308812297035,-0.27614195528132646
721.1000000000098,38.337374809479606,-2.8218007919895647,-0.28181796345715115
722.5000000000099,38.38499107446007,-2.8977766410163825,-0.2915452425368539
723.9000000000099,38.43251097990118,-2.974312044685918,-0.29811676837511136
725.30000000001,38.48000033956768,-3.054480587467276,-0.30311718086562767
726.7000000000099,38.5271680543273,-3.142359306537321,-0.30990303557406085
728.1000000000099,38.574859708544665,-3.235980041728503,-0.31862534330846026
729.50000000001,38.622511121297535,-3.326930103441005,-0.3246615249339855
730.90000000001,38.669630979604804,-3.419168891388202,-0.3327139355816242
732.30000000001,38.71803756995153,-3.5221601043435875,-0.3416197814799533
733.70000000001,38.765617291263844,-3.625967345348085,-0.3504054892146202
735.10000000001,38.813260263756554,-3.7344801063207624,-0.35988594787230443
736.5000000000101,38.86113706494684,-3.841467067170215,-0.3694241386159929
737.9000000000101,38.908637515863475,-3.959133458517593,-0.3799172989427735
739.3000000000101,38.95631518046258,-4.0804855302432355,-0.3896277471020113
740.7000000000102,39.005136366379205,-4.206402450750288,-0.3999795628742979
742.1000000000101,39.05305731778751,-4.336993537138342,-0.40926964154381906
743.5000000000101,39.101044538307,-4.466936067881957,-0.41981427127363125
744.9000000000102,39.14908678659827,-4.603506846242504,-0.4324758497216332
746.3000000000102,39.19669387973698,-4.737803912797576,-0.444570987674632
747.7000000000103,39.24519082196969,-4.881050417254876,-0.45797936900511393
749.1000000000103,39.29322327380709,-5.024430189273343,-0.4709701686929413
750.5000000000102,39.34173163746591,-5.1759630175420535,-0.48371007559302326
751.9000000000103,39.39003522728654,-5.327748003668497,-0.4976534784107369
753.3000000000103,39.43815208814287,-5.482217624651095,-0.5115477110303361
754.7000000000103,39.48635022192685,-5.638170230911577,-0.5265019410358645
756.1000000000104,39.53454411902373,-5.801273103041919,-0.5421743366590972
757.5000000000103,39.58333192786157,-5.970647206691148,-0.5582491513774324
758.9000000000104,39.631592138091925,-6.140464993345335,-0.5734628729525806
760.3000000000104,39.680308493873,-6.311834713435281,-0.591309528913325
761.7000000000104,39.728536485178545,-6.488513582401841,-0.6086418985115225
763.1000000000105,39.77716151123172,-6.668948210567322,-0.6265464771720297
764.5000000000105,39.82562389476979,-6.847762737493402,-0.6455851703893045
765.9000000000104,39.874302255719115,-7.031310320294779,-0.6652196247308653
767.3000000000105,39.923054407357405,-7.214168986522619,-0.6851481835332924
768.7000000000105,39.97170498023133,-7.402662494814294,-0.7042031039881018
770.1000000000106,40.0202394970966,-7.584992429771436,-0.7240173867156332
771.5000000000106,40.06827431536252,-7.763947195927038,-0.744944851432082
772.9000000000106,40.11725358271233,-7.953436802083193,-0.7686245083342511
774.3000000000106,40.165995866976886,-8.139539641726689,-0.7911409884267684
775.7000000000106,40.21441170700337,-8.317562884472869,-0.8133872701657618
777.1000000000106,40.26301238854687,-8.494526567839694,-0.836678696638947
778.5000000000107,40.311623088046524,-8.667244528894093,-0.8622516893463081
779.9000000000107,40.359729424052134,-8.82577183781449,-0.8877790321828725
781.3000000000108,40.40817932521274,-8.978222656076447,-0.912983478056991
782.7000000000107,40.456486686888965,-9.118771858911014,-0.9376286389824129
784.1000000000107,40.50450008818354,-9.24444140872869,-0.9629391030746706
785.5000000000108,40.55238551094594,-9.351929086465613,-0.9900318059184241
786.9000000000108,40.59999931855644,-9.43547914676241,-1.0177772686772455
788.3000000000108,40.64768389020067,-9.490571108377894,-1.0430023253914849
789.7000000000108,40.695113531120946,-9.509664925627188,-1.068661900567721
791.1000000000108,40.741947580762776,-9.481758777074274,-1.0943355817074192
792.5000000000109,40.788330143000586,-9.406891500515696,-1.1215777286041186
793.9000000000109,40.83439952611202,-9.278918383468548,-1.1478852571301559
795.3000000000109,40.88000032364387,-9.084708395253736,-1.173700293166854
796.700000000011,40.924918291259935,-8.818626764847801,-1.1966765656245246
798.1000000000109,40.96914914641606,-8.461979051661924,-1.2193339057198114
799.5000000000109,41.012697563244814,-7.980852412302554,-1.2405030764027254
800.900000000011,41.0547955479319,-7.337434125236571,-1.2587828125711131
802.300000000011,41.09495633781585,-6.488657807060878,-1.2756649075213535
803.7000000000111,41.13389057494861,-5.418661259122935,-1.2880663361148028
805.100000000011,41.17185470926673,-4.234104953735425,-1.298945742115802
806.500000000011,41.21058923988122,-3.1511669244402114,-1.3080387383388445
807.9000000000111,41.25076820007973,-2.3006572680545885,-1.3136115360780098
809.3000000000111,41.29294468795839,-1.7119419499652417,-1.316030470616468
810.7000000000111,41.33694391097383,-1.353368459279913,-1.31778852096225
812.1000000000112,41.38225016119691,-1.15426951277062,-1.3170797081664718
813.5000000000111,41.42824368181848,-1.0602560215123424,-1.3184224174339185
814.9000000000112,41.47475477451092,-1.0196054078488697,-1.3183899457405461
816.3000000000112,41.52155796332148,-1.003368629789708,-1.3183900697714526
817.7000000000112,41.56882068880661,-1.003053164939904,-1.318363850983061
819.1000000000113,41.61563884773099,-1.005304217941132,-1.3180010179660209
820.5000000000113,41.662631874846255,-1.0107817566196413,-1.3183914101248262
821.9000000000112,41.70989965405246,-1.0137488392575047,-1.3193711864797244
823.3000000000113,41.75681697778932,-1.0184475078045367,-1.3197097838338676
824.7000000000113,41.803961181985585,-1.0217088943389696,-1.3197098764373538
826.1000000000114,41.85153196573496,-1.0235426250854573,-1.3197031265084163
827.5000000000114,41.89846799204176,-1.0271900489634078,-1.3183950412359402
828.9000000000113,41.945378051547095,-1.0309678587701347,-1.31976957885644
830.3000000000114,41.9927926199804,-1.0351263425613944,-1.3197173307996017
831.7000000000114,42.04013388815962,-1.0379830341707428,-1.3187360870108749
833.1000000000114,42.087276406050044,-1.0405290763352293,-1.3187299118661997
834.5000000000115,42.134651505764566,-1.0422593094450674,-1.3189661784767543
835.9000000000115,42.18197670922545,-1.044788314427783,-1.3200392904668918
837.3000000000116,42.22904825942342,-1.0481182952160817,-1.3200400524608265
838.7000000000115,42.276565002820064,-1.0526650353336793,-1.3200330354191654
840.1000000000115,42.3238680840129,-1.0562729449075041,-1.3196242605518274
841.5000000000116,42.37115352004332,-1.059448541402174,-1.320696713015268
842.9000000000116,42.41842159420863,-1.063587425270361,-1.3203678863560229
844.3000000000116,42.46580762114002,-1.0660341184366555,-1.319697820547467
845.7000000000116,42.513444283582665,-1.0713269189755805,-1.3199920880282376
847.1000000000116,42.56067109956785,-1.07603024943232,-1.3210297996038718
848.5000000000117,42.608185516862854,-1.0834478851397251,-1.3210298378831489
849.9000000000117,42.65566804687823,-1.0880690500890569,-1.3210317024478244
851.3000000000117,42.70309658353873,-1.0896935653970705,-1.322221644948233
852.7000000000118,42.7506593232439,-1.0948360320644563,-1.321023359854502
854.1000000000117,42.79791774205445,-1.0922511568959146,-1.321032932575105
855.5000000000117,42.84513503836191,-1.095512523743119,-1.3219608823451239
856.9000000000118,42.89274073501121,-1.0985228468969046,-1.3223529022779248
858.3000000000118,42.9401016525434,-1.097633245554522,-1.3236597643112629
859.7000000000119,42.98785950696422,-1.0988270617789209,-1.3236710482899214
861.1000000000118,43.03529661724662,-1.1006770627526292,-1.3223539579742831
862.5000000000118,43.08266975028534,-1.1029604938351747,-1.3223361821432182
863.9000000000119,43.13021889007337,-1.1056613919608507,-1.3210443433925567
865.3000000000119,43.17778974879886,-1.1056907527107362,-1.3220193047302944
866.7000000000119,43.22527923566027,-1.107548749677024,-1.3236696202482894
868.100000000012,43.27272407811212,-1.107583559849567,-1.3222934896352676
869.5000000000119,43.32036910833248,-1.1057244224567426,-1.3227116159479557
870.900000000012,43.36777728242464,-1.1063160449726857,-1.3236693178250785
872.300000000012,43.415420650839785,-1.1074044043443303,-1.323671875189909
873.700000000012,43.462703742474304,-1.1078130264871966,-1.3248263448174007
875.1000000000121,43.510418865108456,-1.104853106365521,-1.3249860853363482
876.500000000012,43.55763676297239,-1.1058735707085816,-1.323652506117591
877.900000000012,43.605204124150156,-1.1090008382412075,-1.3236884463106926
879.3000000000121,43.652826364420086,-1.1140827053334157,-1.3250224362826062
880.7000000000121,43.70036747363675,-1.1096515618479157,-1.3249872290402598
882.1000000000122,43.7477147117361,-1.1070476659708315,-1.3236517254931326
883.5000000000122,43.79503024573597,-1.1097778864539465,-1.3225757020546256
884.9000000000121,43.84281756050966,-1.1110806873355668,-1.322357746179362
886.3000000000122,43.890343036716146,-1.106257003933943,-1.3236671902970292
887.7000000000122,43.937578631891625,-1.1086842602129123,-1.3236706726469687
889.1000000000122,43.98538161145421,-1.1102316580451732,-1.3247480132363556
890.5000000000123,44.032836837599454,-1.1107394329508111,-1.3249809547508646
891.9000000000123,44.08027004644865,-1.1051386894236004,-1.3256617896847156
892.0000000000123,44.08368491605899,-1.105024180039088,-1.325924521842201