File: 01_Data/Cinder_Block/STA/N2/30K_min/Cinder_Block_STA_N2_30KData_230824_R2.csv
##Temp./Â°C,Time/min,DSC/(mW/mg),Mass loss/mg
29.0,15.639808498850805,-2.2803700044161785,-0.005786709723464956
30.40000000000002,15.832166106388785,-2.2039985456887816,-0.006283131612261794
31.80000000000004,15.962326878043813,-2.1461128011981794,-0.006407112659670755
33.20000000000006,16.068562839100483,-2.095043950874591,-0.007166382550523931
34.60000000000008,16.160637812828227,-2.047503660646952,-0.0044115707486769296
36.0000000000001,16.243268875131577,-2.003426042039473,-0.00590849338379007
37.40000000000012,16.319302680133205,-1.962470327593901,-0.007187600143875983
38.80000000000014,16.390860006401955,-1.924756353618405,-0.008097735207259316
40.20000000000016,16.45955580007413,-1.888519835961233,-0.006002539605135748
41.60000000000018,16.524469848064065,-1.8543431791605802,-0.007611719235943504
43.0000000000002,16.587454095708654,-1.8227937360822402,-0.0060856182970496775
44.40000000000022,16.648258163281454,-1.7909296394273548,-0.005763437461286713
45.80000000000024,16.708370791479844,-1.7625976319842176,-0.006581334713327003
47.20000000000026,16.766535774169324,-1.735718640774038,-0.005945703279095937
48.60000000000028,16.823055907415306,-1.7117600669159412,-0.006239289860507924
50.0000000000003,16.879007378007852,-1.6887206126296024,-0.007194872929374263
51.40000000000032,16.934183480033163,-1.6667158621606903,-0.007233646615367295
52.80000000000034,16.98790996629354,-1.6456008564265552,-0.007627687672870032
54.20000000000036,17.04193333064971,-1.6280404961994528,-0.008028342271989786
55.60000000000038,17.09438195159123,-1.6080488693850945,-0.009016857023230074
57.0000000000004,17.146986460520598,-1.5911586420579067,-0.009439687148353748
58.40000000000042,17.198770168830603,-1.5762791924736932,-0.009355919528416301
59.80000000000044,17.249932098878897,-1.559911529184112,-0.010076644399520607
61.20000000000046,17.30100957637671,-1.5462144581512562,-0.009535963323173302
62.60000000000048,17.35217761431544,-1.533224373739046,-0.010832164051578275
64.0000000000005,17.401942009940402,-1.5205668543744897,-0.010995477757922423
65.40000000000052,17.452085547551142,-1.507091437097799,-0.011372519549269988
66.80000000000054,17.502756048546864,-1.493653955737667,-0.01254841886743785
68.20000000000056,17.552184807239218,-1.481435519081518,-0.012521518755812977
69.60000000000058,17.601660014611273,-1.4686993087833082,-0.012298530120693929
71.0000000000006,17.651231339509334,-1.455327942167013,-0.012273277575860497
72.40000000000062,17.700354603232228,-1.4432507351563577,-0.012732165279466745
73.80000000000064,17.74989783818781,-1.4299893762655076,-0.012806696914389626
75.20000000000066,17.798224374694033,-1.4171544143826371,-0.014190916200482295
76.60000000000068,17.847083585726576,-1.4037819356106458,-0.01545830849045382
78.0000000000007,17.895895482191182,-1.3925453185315295,-0.01682328486472784
79.40000000000072,17.94438407243139,-1.3783686174451275,-0.016794516918179347
80.80000000000074,17.99272592760385,-1.3656057556452408,-0.017926674882757787
82.20000000000076,18.041401205157843,-1.3521267835578412,-0.01819447006875219
83.60000000000078,18.089221642324542,-1.339525626011258,-0.016714421103261934
85.0000000000008,18.13660069916325,-1.327607690770825,-0.01811010785648204
86.40000000000082,18.185004867674294,-1.316538829142641,-0.018130728615001868
87.80000000000084,18.23187501370697,-1.3036969450749318,-0.019420591645293417
89.20000000000086,18.28013792819427,-1.2915614476665807,-0.01806317889619491
90.60000000000088,18.327709554843274,-1.2785463228946912,-0.01944988130183889
92.0000000000009,18.37510195997301,-1.267420357065963,-0.02075591278363964
93.40000000000092,18.421738385281735,-1.256847650685712,-0.019954769362813707
94.80000000000094,18.46893003427949,-1.244965429170722,-0.019810515418962282
96.20000000000095,18.516228023993964,-1.2313105073564838,-0.02074983588185253
97.60000000000097,18.562876186255224,-1.2184149086428124,-0.021904438152377192
99.000000000001,18.60947102164952,-1.2072163624129517,-0.022070492406331965
100.40000000000101,18.656177235076953,-1.1952688228722113,-0.022068833519583553
101.80000000000103,18.702573667820364,-1.1832734664827154,-0.023274247753780397
103.20000000000105,18.748764938853803,-1.1717559248967968,-0.023390343341626263
104.60000000000107,18.795001617156373,-1.1595912539575608,-0.0233892733365626
106.0000000000011,18.841026079351078,-1.147225270855234,-0.024679259595388636
107.40000000000111,18.887544341085206,-1.137844260161672,-0.023724136760403525
108.80000000000113,18.93398125691664,-1.124104063127531,-0.02371002202490935
110.20000000000115,18.980464014007453,-1.1107577843186038,-0.024618431671712848
111.60000000000117,19.025416633850213,-1.0999469932580022,-0.025027657573931883
113.0000000000012,19.072250734243585,-1.0885940696405083,-0.026336947200362726
114.40000000000121,19.117856190077585,-1.0769377095700547,-0.026341944685925434
115.80000000000123,19.164545866989627,-1.0652206138170046,-0.026017472502500638
117.20000000000125,19.210063465987673,-1.0542350982410764,-0.026020148143053312
118.60000000000127,19.25592744836385,-1.0411403464628497,-0.026020147959139983
120.0000000000013,19.301335626556746,-1.0312960067750796,-0.026020105832676776
121.40000000000131,19.347086064487513,-1.0204949674970176,-0.026042024125692897
122.80000000000133,19.392185546562132,-1.009343267864548,-0.027342172651603658
124.20000000000135,19.438182461959705,-0.9972455348962379,-0.0273401240283091
125.60000000000137,19.483387941732648,-0.9869560428612191,-0.027338506237791993
127.00000000000139,19.52841690731192,-0.9750683773927687,-0.028697847376823127
128.4000000000014,19.57380716477944,-0.9640983263786279,-0.028650061768745072
129.80000000000143,19.618932620557327,-0.9526083940572614,-0.02863646749970794
131.20000000000147,19.66430558756103,-0.9435123013396602,-0.027332039883610548
132.60000000000147,19.708748847967083,-0.9324117284391532,-0.028349700824791935
134.00000000000148,19.753506490965393,-0.9213508385100169,-0.029967662793356276
135.4000000000015,19.798412813413695,-0.9113793943453687,-0.02997014628847916
136.80000000000155,19.842903949302798,-0.8997473920188634,-0.02997025008993326
138.20000000000155,19.887286971743684,-0.889835177953979,-0.029919136728178586
139.60000000000156,19.93187305100616,-0.880314325696355,-0.03128926288500189
141.0000000000016,19.976205545969535,-0.8703435152167505,-0.03129027967227982
142.40000000000163,20.02040884540846,-0.8615119974626457,-0.03128343424156199
143.80000000000163,20.064805490666764,-0.8509719367857597,-0.032608307964786754
145.20000000000164,20.10799145860755,-0.8401130345069332,-0.03261011592700935
146.60000000000167,20.152803405745185,-0.8296423605822729,-0.03282246441461867
148.0000000000017,20.197167913816866,-0.8209948911972589,-0.03392872031780936
149.4000000000017,20.241231189299274,-0.8114757779498849,-0.03393172888003315
150.80000000000172,20.284643134830976,-0.8012935445314305,-0.032634009286304444
152.20000000000175,20.328769614911135,-0.7937121066154849,-0.03261017823563783
153.60000000000178,20.37242586660699,-0.7838360163983443,-0.03261002004435509
155.0000000000018,20.416504418310353,-0.7735750089308587,-0.032560264263875816
156.4000000000018,20.460464323691586,-0.765620412634609,-0.03393194083226314
157.80000000000183,20.504155192435157,-0.7558970360636023,-0.034502319841552165
159.20000000000186,20.54771540867255,-0.7464598004216053,-0.03523920139905545
160.60000000000187,20.591364660398682,-0.7368229009756578,-0.035240013167733064
162.00000000000188,20.63477237579016,-0.728519505218452,-0.03524045552502475
163.4000000000019,20.678147363359415,-0.7185118310576297,-0.03549429889282596
164.80000000000194,20.721813517402296,-0.7116016131470708,-0.035807280422015086
166.20000000000195,20.765166275081874,-0.703542963013201,-0.03722039238423047
167.60000000000196,20.809010411569414,-0.6948872082482861,-0.03722543326399608
169.000000000002,20.852473643278575,-0.6855096603527719,-0.0359173854349093
170.40000000000202,20.89606736290547,-0.6778824491942812,-0.03590013381210522
171.80000000000203,20.939504189294976,-0.6676215839457665,-0.03590014782264106
173.20000000000203,20.982320703853944,-0.660761941835518,-0.03590013581338569
174.60000000000207,21.026273709364816,-0.6514975297924193,-0.035895064264945375
176.0000000000021,21.069313625478337,-0.6433634877130314,-0.0365676873351366
177.4000000000021,21.113107298973418,-0.6356920026055156,-0.03772192487366777
178.80000000000211,21.15567268376805,-0.6276599750025562,-0.03883334149176054
180.20000000000215,21.19879372764849,-0.6197257653241601,-0.03885995066367087
181.60000000000218,21.242272726922238,-0.6128960598242019,-0.038859984202304076
183.0000000000022,21.285222205116625,-0.6051224552770026,-0.038859984001209824
184.4000000000022,21.328150730074256,-0.5975746511942965,-0.038859984000002346
185.80000000000223,21.371182942949357,-0.5894301121987339,-0.038859984000000125
187.20000000000226,21.414154691588163,-0.5830680884342153,-0.038859984000000125
188.60000000000227,21.45640822133618,-0.5750900646275119,-0.03885998399999924
190.00000000000227,21.499881931282644,-0.5688002634760072,-0.03885998399997259
191.4000000000023,21.54256074240156,-0.5602585302647277,-0.03885998413178582
192.80000000000234,21.58518753182842,-0.552683657378916,-0.03886003526547732
194.20000000000235,21.627933049844803,-0.5472155976245454,-0.03886838500096923
195.60000000000235,21.67073467747796,-0.5401626738206184,-0.03919086782878134
197.0000000000024,21.71363162818819,-0.532813907584319,-0.03918986579917938
198.40000000000242,21.756128822032352,-0.5267688384659873,-0.03918995374053669
199.80000000000243,21.79771968451266,-0.5207763319601112,-0.03922953615049751
201.20000000000243,21.841117930912844,-0.5134311796258522,-0.037878256476135075
202.60000000000247,21.883565235601292,-0.5072868387858143,-0.037870121801443446
204.0000000000025,21.92599328739525,-0.5015693765412438,-0.03916750234458721
205.4000000000025,21.96877395096274,-0.495460757733969,-0.039189727223794435
206.8000000000025,22.01163363844467,-0.4899156880716262,-0.03918985165026534
208.20000000000255,22.05399193005528,-0.4835533700583555,-0.039189834498760234
209.60000000000258,22.096589365700208,-0.47779885791972904,-0.039185665556798366
211.0000000000026,22.138809526198287,-0.4720714681965751,-0.04016682273698047
212.4000000000026,22.18142115171217,-0.46459771745211426,-0.040217077545598556
213.80000000000263,22.224111189937098,-0.46161534563954376,-0.04052919185584525
215.20000000000266,22.265988274407597,-0.4555523623124705,-0.04116885055935571
216.60000000000267,22.309041166840856,-0.4476768046941925,-0.04117011004260007
218.00000000000267,22.351550988489233,-0.4436355164502063,-0.04117013444717976
219.4000000000027,22.39395899362468,-0.4383717832830083,-0.04117066340541342
220.80000000000274,22.436300613741153,-0.42995910082214567,-0.04041547242753385
222.20000000000275,22.478644930823393,-0.42671814076724585,-0.04116989036733498
223.60000000000275,22.520954738839645,-0.42378622034243535,-0.041169982928279225
225.00000000000279,22.56310331756432,-0.4167742622855748,-0.04116998398931804
226.40000000000282,22.60575336098295,-0.4127615738377492,-0.04117001492377437
227.80000000000283,22.647754986905323,-0.40980784864406905,-0.04118244457587794
229.20000000000283,22.69036842481317,-0.40252340877253984,-0.042521601347514704
230.60000000000286,22.732571544484802,-0.3991082743936005,-0.04249001609628378
232.0000000000029,22.775046265648516,-0.394609915506289,-0.04248329169932008
233.4000000000029,22.817228533970532,-0.3892756508426517,-0.04378551378064177
234.8000000000029,22.859428238901867,-0.3866679462885405,-0.043888887484516914
236.20000000000294,22.90186923515241,-0.38181784769698235,-0.041823260994289235
237.60000000000298,22.94402641333769,-0.3793476853285399,-0.04182992444495515
239.00000000000298,22.98628096339171,-0.3747474329768226,-0.04182284661458269
240.400000000003,23.028653827673097,-0.37013916414305903,-0.043143180891684896
241.80000000000302,23.07094770961168,-0.36660914346910917,-0.043149869059786905
243.20000000000306,23.113146658132784,-0.36298432510856904,-0.04314985226734924
244.60000000000306,23.15546240618746,-0.35889881515368743,-0.04314987581731433
246.00000000000307,23.197379250505207,-0.35579547403956036,-0.04315353898960872
247.4000000000031,23.2398517389759,-0.3514475181054208,-0.04218204382414603
248.80000000000314,23.282035517545125,-0.34946029672815015,-0.042123099464772995
250.20000000000314,23.324311815292454,-0.34536495974361137,-0.04347739238289661
251.60000000000315,23.366197104811985,-0.3440317120942086,-0.04347984186743492
253.00000000000318,23.408686374462018,-0.34091902201399005,-0.04347985198316273
254.40000000000322,23.450542097147714,-0.33728330333895157,-0.04347985198169724
255.80000000000322,23.493033451232915,-0.3339188834024454,-0.04347982885026802
257.20000000000323,23.53551460533329,-0.33155847221151163,-0.043472558179184606
258.60000000000326,23.577650226709803,-0.32903687764650497,-0.044778057260273396
260.0000000000033,23.619512119860598,-0.3268782376218321,-0.044789813789427146
261.4000000000033,23.661998743263013,-0.32317316466217877,-0.04478981804705473
262.8000000000033,23.70350564669316,-0.3210017098005543,-0.04479086683067246
264.20000000000334,23.745811222385015,-0.31819032092793526,-0.04397401496854414
265.6000000000034,23.788678464447216,-0.31465979965215773,-0.043800247725507724
267.0000000000034,23.830492788687703,-0.31341912999479815,-0.04396043806923222
268.4000000000034,23.8731810789476,-0.30983888617699135,-0.045119552305421085
269.8000000000034,23.91512645584183,-0.3085922403809155,-0.0451198109299753
271.20000000000346,23.957108866792915,-0.30702364233072155,-0.04511981994809622
272.60000000000343,23.999358496845694,-0.30473372396668963,-0.04511981999983661
274.00000000000347,24.041616659925932,-0.30411051050444615,-0.04511982000039971
275.4000000000035,24.083685995072205,-0.30249907034370194,-0.04511982018933214
276.80000000000354,24.126028588267395,-0.3005267522008133,-0.045119868485850034
278.20000000000357,24.16848987736423,-0.29817562880944753,-0.04512598977340243
279.60000000000355,24.210773083636493,-0.2971239047142608,-0.04545108902412931
281.0000000000036,24.252646842970908,-0.2954532619140706,-0.045450110204763305
282.4000000000036,24.29475213596779,-0.29368871311720635,-0.04546601650421023
283.8000000000036,24.33761269889898,-0.292675767907933,-0.04511547681556394
285.2000000000036,24.37993875073119,-0.2921061103052033,-0.045450282784092355
286.60000000000366,24.421943763130987,-0.29034931624806726,-0.04544991414126143
288.0000000000037,24.464680594445568,-0.2903190969673369,-0.04544995402542362
289.40000000000373,24.506761812777185,-0.28763334217752506,-0.04545044765368145
290.8000000000037,24.548907902142133,-0.28643372684444157,-0.04573506970879837
292.20000000000374,24.591225092307205,-0.28515059159168277,-0.04610977799801308
293.6000000000038,24.633793315205114,-0.2847975573550871,-0.04611008137150652
295.00000000000375,24.676013472076978,-0.28400337545353754,-0.046110083988176065
296.4000000000038,24.718524953038113,-0.28253039836043037,-0.046110083923214695
297.8000000000038,24.760865891643704,-0.28251259497911496,-0.04611009492011675
299.20000000000385,24.803608738840474,-0.2825964352135232,-0.046120888672626315
300.6000000000039,24.84555398100574,-0.2813842479124824,-0.04762023360607692
302.00000000000387,24.888063041739013,-0.2802152380026164,-0.04875302042056395
303.4000000000039,24.930485270067194,-0.2798597168594508,-0.048749894139024974
304.80000000000393,24.973196872245797,-0.27812372260240903,-0.048751190890967244
306.2000000000039,25.015562675903407,-0.2784608743517269,-0.047445058362281856
307.60000000000394,25.05809254370771,-0.2775375229460609,-0.04743440195686199
309.000000000004,25.100272894517108,-0.2750220880444953,-0.04612503433672854
310.400000000004,25.142674652259394,-0.27650789385219837,-0.04677188552298528
311.80000000000405,25.185243648992216,-0.27510701251726366,-0.04677223602254399
313.200000000004,25.22784836948797,-0.2729001609642781,-0.04812922992974489
314.60000000000406,25.270654823750696,-0.27435144436370834,-0.04808990835033988
316.0000000000041,25.312775606445737,-0.2734113274244919,-0.048089951268026176
317.40000000000407,25.35553916661697,-0.2733518166074643,-0.04808986808602045
318.8000000000041,25.397987758009734,-0.27344902275331545,-0.04806438841724825
320.20000000000414,25.440726225879047,-0.27437367640003707,-0.0487478187282111
321.6000000000042,25.48348729531033,-0.2724398407504379,-0.048749956419085194
323.0000000000042,25.52553920250192,-0.27200756842665225,-0.048749952047318246
324.4000000000042,25.5684655076916,-0.27214883020924674,-0.04874995200019949
325.8000000000042,25.611033221591946,-0.2708606592395689,-0.04874995200004095
327.20000000000425,25.65356678898579,-0.2700392936866026,-0.048749952032842714
328.60000000000423,25.696186074153456,-0.27051465614547704,-0.048749960922635616
330.00000000000426,25.739116181975717,-0.27072584700544833,-0.048750681143137964
331.4000000000043,25.781889592223983,-0.27081616137237385,-0.05003997397664017
332.80000000000433,25.82380662932582,-0.2704915389363227,-0.05004772798683099
334.20000000000437,25.867142003177864,-0.2703835600697597,-0.048734601429041735
335.60000000000434,25.90987792459755,-0.2694184396455731,-0.048732832169684936
337.0000000000044,25.952383667423245,-0.2705435818439081,-0.05006332086015197
338.4000000000044,25.995541043741255,-0.27091755175710924,-0.05005995548826725
339.8000000000044,26.03772181184086,-0.2710795832990357,-0.05005992013594396
341.2000000000044,26.081003647511448,-0.2705921787258378,-0.050059920009302594
342.60000000000446,26.123939648810918,-0.2719013751171379,-0.050059927498071755
344.0000000000045,26.16617281220801,-0.2726109389133889,-0.05006208771315279
345.4000000000045,26.20943435124072,-0.2718101535544676,-0.05100155709969423
346.8000000000045,26.25227820956733,-0.27255188305146183,-0.051371716425133496
348.20000000000454,26.295382445050773,-0.27365903775341427,-0.052045345583252356
349.60000000000457,26.338270440557565,-0.27477198892137006,-0.05204020097466344
351.00000000000455,26.381030642404554,-0.27440448274011753,-0.05204018305627134
352.4000000000046,26.424231120360194,-0.2759261039653985,-0.05204293746470734
353.8000000000046,26.4667918769068,-0.27668471257098776,-0.05131835565951626
355.20000000000465,26.509906446499258,-0.2759583455092742,-0.05138007085220453
356.6000000000047,26.552871912217636,-0.2778446464616782,-0.0513801843345747
358.00000000000466,26.59591015331468,-0.27955236302841446,-0.05138018321961324
359.4000000000047,26.639118694691373,-0.27987479224158884,-0.051380116235193896
360.80000000000473,26.681508772295487,-0.28089022939151825,-0.05141135643351369
362.2000000000047,26.724929719087797,-0.2833205829460488,-0.05038286003055292
363.60000000000474,26.768326806604406,-0.2847240569368413,-0.05039017279026359
365.0000000000048,26.811440371162803,-0.2837387646120275,-0.05039015948058578
366.4000000000048,26.85384571166944,-0.2851292483293893,-0.050956116100300264
367.80000000000484,26.897542157855305,-0.2855179154509231,-0.052686984407027015
369.2000000000048,26.940811768748045,-0.2864976215898121,-0.0530258747541108
370.60000000000485,26.983712606784405,-0.28796206768769594,-0.05303022096038035
372.0000000000049,27.026710428533153,-0.2902683987663292,-0.05303005274717343
373.40000000000487,27.069907107101432,-0.2912850920003349,-0.05303005200068078
374.8000000000049,27.11343189695847,-0.2921046045946453,-0.05303005199992139
376.20000000000493,27.156438562170944,-0.29189326850340086,-0.05303005197429567
377.60000000000497,27.199729349093495,-0.2946085416412385,-0.053030050417882
379.000000000005,27.243072236118476,-0.2972525028846738,-0.05303202126015183
380.400000000005,27.286489471267537,-0.29836677501938974,-0.05193380355353927
381.800000000005,27.3289949547427,-0.3013818840257694,-0.05169070086794214
383.20000000000505,27.373109699111453,-0.3018703103095543,-0.0520891783741706
384.600000000005,27.416527447453205,-0.30390079321066865,-0.0530280540052801
386.00000000000506,27.45965136775392,-0.30442841685367833,-0.05434276243018443
387.4000000000051,27.50312053028763,-0.30638831139107686,-0.05330372830946528
388.8000000000051,27.546091142588875,-0.30819534399173676,-0.052957944683352576
390.20000000000516,27.590246556415007,-0.30965339163675387,-0.0543388437390826
391.60000000000514,27.63256201365953,-0.31188939140532607,-0.05434007143340658
393.0000000000052,27.676838100942987,-0.31430207916024333,-0.0543406802320785
394.4000000000052,27.72025418537336,-0.3150823059548355,-0.05468102734009861
395.8000000000052,27.763733546642776,-0.31703971894451616,-0.05430368657184381
397.2000000000052,27.806747670706663,-0.3189835532156925,-0.05434000966018715
398.60000000000525,27.85044520479342,-0.32232818091148596,-0.054337391480439035
400.0000000000053,27.894130841353025,-0.3236562155870215,-0.05466648264207219
401.4000000000053,27.93789720510358,-0.3277106343794099,-0.05570148921691853
402.8000000000053,27.980693045304903,-0.32898879321639546,-0.05565987371908321
404.20000000000533,28.024810768203356,-0.32956751080261976,-0.05565995143519231
405.60000000000537,28.06828758996469,-0.33413604553673887,-0.05566415104298539
407.00000000000534,28.112220922059723,-0.33790596479355933,-0.05631334215259498
408.4000000000054,28.155674693932497,-0.33990691046565447,-0.056319892783314174
409.8000000000054,28.19945461343473,-0.3415733439556756,-0.05631991998841501
411.20000000000545,28.242799572931197,-0.34595550823712345,-0.05631992000024866
412.6000000000055,28.28645983784506,-0.34638797649247144,-0.056319920000000856
414.00000000000546,28.330425053633864,-0.35024364729331947,-0.056319919999972434
415.4000000000055,28.37397543159752,-0.35307902705026867,-0.056319919943558894
416.8000000000055,28.417750707464567,-0.35544295152166955,-0.056319907983694684
418.2000000000055,28.4613400316886,-0.35964530810981116,-0.056322338229954916
419.60000000000554,28.505265162613288,-0.3635302159270103,-0.056641115492779726
421.00000000000557,28.54904390333053,-0.36659729156210286,-0.056650175106335965
422.4000000000056,28.593089724394137,-0.373796448306918,-0.05665018406878897
423.80000000000564,28.63689435929563,-0.3752818921781748,-0.05665018400021715
425.2000000000056,28.68058795162385,-0.3823845990152812,-0.056650184000042625
426.60000000000565,28.72470116928379,-0.3872624760701657,-0.05665018403366018
428.0000000000057,28.768532220345072,-0.3931836612934625,-0.056650188162314485
429.40000000000566,28.812409393694356,-0.39824890165263543,-0.05664743309829401
430.8000000000057,28.856097546436843,-0.4027228755673485,-0.057353167272945704
432.20000000000573,28.90018350453593,-0.40446182480930687,-0.057310167917838495
433.60000000000576,28.94423157669821,-0.40711485028547245,-0.057518305515835255
435.0000000000058,28.98808403628613,-0.4106017565455784,-0.05862147669009987
436.4000000000058,29.03193657515321,-0.41011612198556063,-0.05862014806291782
437.8000000000058,29.075944749214717,-0.4114951006829483,-0.058620151977417656
439.20000000000584,29.120030553452352,-0.412248461056943,-0.05862015200000048
440.6000000000058,29.163878522342053,-0.41198040997232527,-0.05862015199999959
442.00000000000585,29.207522932129073,-0.41058995838853923,-0.05862015199999959
443.4000000000059,29.251899238312035,-0.4129389701710101,-0.05862015200000048
444.8000000000059,29.295911009606233,-0.41413561002748445,-0.05862015199999959
446.20000000000596,29.339706170394223,-0.41507156859591854,-0.05862015200000048
447.60000000000593,29.383550858788283,-0.4170906505521975,-0.05862015199999737
449.00000000000597,29.428263248438217,-0.42054962759366493,-0.05862015199964743
450.400000000006,29.47249045171375,-0.42430160012739376,-0.058620152177566
451.800000000006,29.516856549900385,-0.42766354327517425,-0.05862021960269814
453.200000000006,29.560412813727908,-0.4303525035686511,-0.058616706564955656
454.60000000000605,29.60518093427456,-0.4342619649972208,-0.059926744533036036
456.0000000000061,29.649287938470405,-0.4364473765670013,-0.05994001086901468
457.4000000000061,29.69378960031422,-0.4408818085436159,-0.05994011658658449
458.8000000000061,29.73771046349553,-0.4433508012839619,-0.05996431868139629
460.2000000000061,29.78276915379534,-0.4482905920001016,-0.06125784794753919
461.60000000000616,29.827002770403297,-0.45169326074548005,-0.06125988144799166
463.00000000000614,29.87130201835855,-0.4558875333743796,-0.06125988800923343
464.4000000000062,29.91582577957628,-0.46086585287212894,-0.06125988800387949
465.8000000000062,29.96032530985985,-0.46475968107476984,-0.06125988610481592
467.20000000000624,30.004612041420653,-0.4701470873074724,-0.06125919710520966
468.6000000000063,30.049454890835698,-0.476227252413115,-0.06263286077233099
470.00000000000625,30.093816213496794,-0.4802993010155274,-0.06258025776709486
471.4000000000063,30.138408214384235,-0.4838475574042966,-0.06257988775987133
472.8000000000063,30.182971445823764,-0.4902575135786179,-0.06257993163149367
474.2000000000063,30.227152063453826,-0.495996341255205,-0.06259292545360395
475.60000000000633,30.272314064143874,-0.5017447451523189,-0.06388775526499879
477.00000000000637,30.317142724975046,-0.5083796252407426,-0.06390010855067496
478.4000000000064,30.361799483744203,-0.5156127028724249,-0.06390060192991198
479.80000000000643,30.406031090535702,-0.5212209753437287,-0.06430675494051163
481.2000000000064,30.450460015580703,-0.5258203013994992,-0.06457167520876927
482.60000000000645,30.49597405559674,-0.5327823379644073,-0.06520895700929641
484.0000000000065,30.540995940294007,-0.5380640354320452,-0.06521012099707812
485.40000000000646,30.585553594611557,-0.5436745653025605,-0.0652101198244055
486.8000000000065,30.63003207747453,-0.5506832700962457,-0.06521012071824517
488.2000000000065,30.67468056327539,-0.5553371041790068,-0.06523545635499728
489.60000000000656,30.71980250670972,-0.5625085689347322,-0.06652996369345132
491.0000000000066,30.764278934395637,-0.568265590359176,-0.06689332960720806
492.40000000000657,30.809273408055105,-0.5716935668350013,-0.06685996069472555
493.8000000000066,30.854283532285127,-0.5806098603649946,-0.06679688219208746
495.20000000000664,30.899181348884596,-0.5869269131958428,-0.06750580467431799
496.6000000000066,30.94410580797377,-0.5894771050827934,-0.06743287476432425
498.00000000000665,30.988964174719055,-0.594237723870566,-0.06751387012865706
499.4000000000067,31.033984914500355,-0.6000197551652958,-0.06627024919948399
500.8000000000067,31.078654700645505,-0.6052936246107474,-0.0672156660100951
502.20000000000675,31.123443280780172,-0.6081328575166436,-0.06829711287021833
503.60000000000673,31.16741960869121,-0.6115666683035313,-0.06850882923765145
505.00000000000676,31.2130032571075,-0.6152802967651899,-0.0685157980227249
506.4000000000068,31.25843933146091,-0.6192158548928951,-0.06883389326886835
507.8000000000068,31.303078928199685,-0.6232843055648548,-0.07015677712995316
509.2000000000068,31.34780169072001,-0.6253879416070777,-0.0701494039467292
510.60000000000684,31.39271797686325,-0.6280504960486331,-0.07180029582615477
512.0000000000068,31.43774688266909,-0.6307023239157286,-0.07245707959512293
513.4000000000069,31.482934830518076,-0.6329041328195233,-0.07278066152407625
514.8000000000069,31.527642968549294,-0.6348762245898771,-0.07274598637847562
516.2000000000069,31.572460979872293,-0.6379846497739592,-0.07406806949031086
517.600000000007,31.617514401212564,-0.6400901465829048,-0.07294949563331699
519.0000000000069,31.66246624744202,-0.6438672547291234,-0.07410832422171598
520.4000000000069,31.707450358653524,-0.6468330608055484,-0.07411022170809067
521.800000000007,31.75259931254393,-0.6469607305992034,-0.07542708668923392
523.2000000000071,31.797653285580807,-0.6512935518951274,-0.07598439585722705
524.6000000000071,31.842773020128977,-0.6544776610423483,-0.07540493915051627
526.000000000007,31.888038562344498,-0.6592836370519222,-0.07541822338633075
527.4000000000071,31.93306589568008,-0.6621047174399862,-0.07574157068882892
528.8000000000071,31.97830780970137,-0.6667515711929834,-0.07710120121673336
530.2000000000071,32.02321584562131,-0.6690503577849004,-0.07706843593909918
531.6000000000072,32.06837108906065,-0.6739276934142883,-0.078088788360128
533.0000000000072,32.11380282308192,-0.6770082237242345,-0.07808046109486977
534.4000000000071,32.15866561728778,-0.6804035014516092,-0.07938113526508195
535.8000000000072,32.20395004516519,-0.6872246195057804,-0.0793797580729323
537.2000000000072,32.249312326651285,-0.6942457145676175,-0.08064748781547282
538.6000000000072,32.29453581902942,-0.6956676129312135,-0.08069078869611124
540.0000000000073,32.3397735274106,-0.7001116421579783,-0.08069341771298033
541.4000000000073,32.38494348066549,-0.7067795171130037,-0.08200801570622929
542.8000000000073,32.430527151432834,-0.7112495136769605,-0.08204320705910817
544.2000000000073,32.475744237729,-0.7176203934217327,-0.08101320888513897
545.6000000000073,32.52096112728343,-0.7217590094024267,-0.08200939279564778
547.0000000000074,32.56667653739279,-0.728036504639723,-0.08201090594053007
548.4000000000074,32.61217174035587,-0.7321712028818756,-0.08285006234260894
549.8000000000075,32.65741647303742,-0.738701838814507,-0.08332966593256108
551.2000000000074,32.70286689843703,-0.7445344058815194,-0.08333115357037402
552.6000000000074,32.74837854971601,-0.7476862943700042,-0.08416650967380424
554.0000000000075,32.79409477668469,-0.7558355064594379,-0.08464081554531822
555.4000000000075,32.83948971715465,-0.7636336282346659,-0.08525686806800303
556.8000000000075,32.88484263354738,-0.7686508064083468,-0.08596918942333964
558.2000000000075,32.93042813333008,-0.7744323018749343,-0.08694514206332027
559.6000000000075,32.97571839583155,-0.7816600689961812,-0.08824877625442396
561.0000000000075,33.02145098750034,-0.788071296448708,-0.08793257522835995
562.4000000000076,33.06697512231054,-0.7921260358872373,-0.08825637231165606
563.8000000000076,33.112537471788514,-0.7973102168284315,-0.08941927048137943
565.2000000000077,33.1584467492669,-0.8037861365192619,-0.09099071529722291
566.6000000000076,33.2041050619374,-0.809620502177609,-0.0908998026672565
568.0000000000076,33.24970783919738,-0.8171365449750068,-0.09220222365214514
569.4000000000077,33.295330799859975,-0.8243266094503453,-0.0922199787079876
570.8000000000077,33.341145540868354,-0.833384936948509,-0.09359051401673923
572.2000000000078,33.38683561736266,-0.8407154358437633,-0.09354015455410547
573.6000000000078,33.4325154041365,-0.8485161966746679,-0.09353800439337423
575.0000000000077,33.47861896649628,-0.8565567658193659,-0.0948064133445925
576.4000000000078,33.52413792814879,-0.8629727039467386,-0.094882777845958
577.8000000000078,33.56993567830364,-0.865246070867239,-0.09617012738230768
579.2000000000078,33.61588531172618,-0.872450032711157,-0.09615751961495889
580.6000000000079,33.661975572462865,-0.8776610603559137,-0.09749498474914864
582.0000000000078,33.70770952143802,-0.8853013043592791,-0.09766740652868178
583.4000000000078,33.75383187413538,-0.8928690440125588,-0.09881823820668023
584.8000000000079,33.799709952691906,-0.8977485067854163,-0.10013272448171628
586.2000000000079,33.845600386665986,-0.9058388528193845,-0.1004302426701309
587.600000000008,33.89142629564095,-0.9121214810364516,-0.10143936810187704
589.000000000008,33.93733649947743,-0.9201177025816706,-0.10144194349053759
590.4000000000079,33.98318192513753,-0.9263669567962987,-0.10143257923957094
591.800000000008,34.02932281645354,-0.9338440920104367,-0.10143968008614168
593.200000000008,34.075566847586295,-0.9409348131666303,-0.10195643102341023
594.6000000000081,34.1215387195219,-0.9481702858068037,-0.1028209012595398
596.0000000000081,34.16734693888924,-0.9570384956808211,-0.10407525428461994
597.400000000008,34.21340892491205,-0.9652221407564712,-0.10539629995482569
598.8000000000081,34.25949314107214,-0.9732177387773191,-0.10538185468233108
600.2000000000081,34.305962967688735,-0.9811849252605412,-0.10635441283419178
601.6000000000081,34.35191857843872,-0.9913118637158899,-0.10672240667366095
603.0000000000082,34.39806307177027,-0.999255365919062,-0.10802993361960445
604.4000000000082,34.44428357246624,-1.0043165046237037,-0.10935483637818644
605.8000000000081,34.49049296590195,-1.0132826245923263,-0.11065250185482967
607.2000000000082,34.53685803526973,-1.018262629311224,-0.11195059987264289
608.6000000000082,34.58252680572378,-1.024013428200762,-0.11242251103765444
610.0000000000083,34.62908338475048,-1.0324438913851732,-0.11195690931603863
611.4000000000083,34.675259131722875,-1.0362327708692178,-0.11329265082651441
612.8000000000083,34.721472100497536,-1.0395938428969804,-0.11339755096949888
614.2000000000083,34.767680114179996,-1.043062306871714,-0.11505075237276996
615.6000000000083,34.813705588802016,-1.0464267149157302,-0.11695840291991422
617.0000000000084,34.86000000000026,-1.0483900000000086,-0.11824006410793686
618.4000000000084,34.906382619220054,-1.0528192303202921,-0.11954174382495353
619.8000000000084,34.95253261756932,-1.0555181003590433,-0.12084337872230044
621.2000000000085,34.99892462477939,-1.0627821938384072,-0.1221507758865159
622.6000000000084,35.04494595141955,-1.0646055007732314,-0.12263570869428753
624.0000000000084,35.090942588768925,-1.0688830198661543,-0.12351430844469746
625.4000000000085,35.13775964306762,-1.0742484026802666,-0.12482362899460364
626.8000000000085,35.184110264670196,-1.0766804485938923,-0.1248410128860975
628.2000000000085,35.230355498206215,-1.083922202575506,-0.1261405936678619
629.6000000000085,35.27637102045154,-1.089414328534546,-0.12649191926024983
631.0000000000085,35.32306309321374,-1.0957917643493094,-0.12784213241601394
632.4000000000086,35.36912940430958,-1.1002698355360183,-0.1286933106994499
633.8000000000086,35.415508523071146,-1.1056689543866396,-0.1294055219118868
635.2000000000086,35.461902099834354,-1.1147476232835003,-0.1309446554804179
636.6000000000087,35.50800739185282,-1.1191364840061047,-0.1330349604004697
638.0000000000086,35.55464058866802,-1.127400494269035,-0.13315270231368048
639.4000000000087,35.600829254317745,-1.1327664205022276,-0.1344184601660996
640.8000000000087,35.6474704879817,-1.138547297366475,-0.1336686666744793
642.2000000000087,35.69413010475461,-1.1494708825426776,-0.13501638132523652
643.6000000000088,35.73993324912482,-1.158529359337956,-0.13657056010084467
645.0000000000088,35.78580960514919,-1.1660666541504674,-0.13793222740635303
646.4000000000087,35.833102792972525,-1.172754516491687,-0.13907844789958768
647.8000000000088,35.87957550832424,-1.1822692274836246,-0.14016261465692192
649.2000000000088,35.9262709669993,-1.1936080653320555,-0.14166501453208857
650.6000000000088,35.972369116011684,-1.2005007651252944,-0.14271635390667647
652.0000000000089,36.01888349775808,-1.2082122941592357,-0.1440568239636919
653.4000000000088,36.06550115281368,-1.2177186209843776,-0.1460799961245991
654.8000000000089,36.11175711983316,-1.2284973970829642,-0.14625555119821154
656.2000000000089,36.15802918145083,-1.2368667921058691,-0.14739663245908474
657.6000000000089,36.20439516976815,-1.2460802485886315,-0.14878476667071272
659.000000000009,36.25106573078282,-1.2574011579560118,-0.15008111492853526
660.400000000009,36.29740375803953,-1.2661644928609126,-0.15223566000776145
661.800000000009,36.34427302064922,-1.2753423396842065,-0.15449067417272255
663.200000000009,36.39037721534567,-1.2871713621168983,-0.15589712239889186
664.600000000009,36.43703695321852,-1.301013659291958,-0.15755571169425142
666.0000000000091,36.48363705523241,-1.3143833689057662,-0.15760375420610462
667.4000000000091,36.53033591822082,-1.3286005162407863,-0.1603111174125802
668.800000000009,36.576727052629636,-1.3473413721867422,-0.16182331699212638
670.2000000000091,36.623181712521614,-1.3628276619188275,-0.16364884796968182
671.6000000000091,36.669736409316855,-1.381122324220324,-0.1658576373299372
673.0000000000091,36.71653261832512,-1.4033286231656439,-0.1678409760632933
674.4000000000092,36.76307364140117,-1.4214962958413235,-0.16917197552303342
675.8000000000092,36.80947481278999,-1.4442255617433934,-0.17061419140059364
677.2000000000093,36.85563631317095,-1.4674200573392295,-0.17269172824983237
678.6000000000092,36.90266130575071,-1.4926945632909185,-0.1740788488923397
680.0000000000092,36.949056109954455,-1.5195567987201613,-0.175190276732347
681.4000000000093,36.99591880429124,-1.5505988027358344,-0.1777281103240247
682.8000000000093,37.0427290650229,-1.576460824618088,-0.17970202591208917
684.2000000000094,37.08945788841347,-1.6061227736679256,-0.1822905553073313
685.6000000000093,37.136049416228566,-1.6384316751128158,-0.18481737056882652
687.0000000000093,37.18266748803042,-1.670085069908773,-0.18796445092753133
688.4000000000094,37.22929384267086,-1.6993122952591602,-0.1908030236686682
689.8000000000094,37.27615391395403,-1.7347235121571158,-0.1931550856485873
691.2000000000094,37.32280787468828,-1.7668750700131945,-0.19605788187511797
692.6000000000095,37.36957394462656,-1.80411340191322,-0.199242273932136
694.0000000000094,37.41637796153411,-1.8366898680415795,-0.2027725938016629
695.4000000000094,37.463126109633684,-1.8715406389138192,-0.20618511891502855
696.8000000000095,37.509900523832684,-1.9071624263045788,-0.20946292757978524
698.2000000000095,37.55637388565389,-1.946687444727349,-0.21297123088928283
699.6000000000096,37.60322208965796,-1.9856141958015028,-0.21619573014101068
701.0000000000095,37.64986552652444,-2.024479971112195,-0.21739355361274937
702.4000000000095,37.69682774266414,-2.064173214985228,-0.22195809536164557
703.8000000000096,37.743696287356805,-2.1089280280581435,-0.22599345600894827
705.2000000000096,37.79056919460261,-2.1527150496510896,-0.22973989527573258
706.6000000000097,37.837175404003574,-2.2004199303401784,-0.23444120783651812
708.0000000000097,37.88403915062372,-2.249322286136945,-0.23874283013766906
709.4000000000096,37.931298926639926,-2.299491344830815,-0.2427201319323542
710.8000000000097,37.977886498257035,-2.353173171832719,-0.24667135532888507
712.2000000000097,38.024892770461406,-2.4073305036072976,-0.25116251654725374
713.6000000000097,38.0720281288813,-2.460105032274799,-0.2565338432530666
715.0000000000098,38.11903191711744,-2.5187769315862854,-0.2615521655689097
716.4000000000098,38.16606774035046,-2.5811649420794196,-0.26680303931072835
717.8000000000097,38.21227331720304,-2.6376686428641083,-0.27240763220917064
719.2000000000098,38.259898906679844,-2.704702134089187,-0.2778418760352608
720.6000000000098,38.306902951119525,-2.771671004266538,-0.28488839281839207
722.0000000000099,38.35437337124983,-2.8430191627360752,-0.29164203175432757
723.4000000000099,38.401448638427354,-2.9162893967036148,-0.2962433688932009
724.8000000000098,38.44888897016504,-2.986689205383541,-0.3006796073663165
726.2000000000099,38.495840241100254,-3.061499756665875,-0.30697923508603964
727.6000000000099,38.54327671114623,-3.14766496338236,-0.31428394065045895
729.00000000001,38.590877534119514,-3.23094070468145,-0.3231574131678978
730.40000000001,38.638188296010874,-3.3157797279638968,-0.329796863703677
731.80000000001,38.68548876111264,-3.4087722354720267,-0.3368548058018819
733.20000000001,38.73289262329838,-3.50186054218052,-0.3450103351954499
734.60000000001,38.78064313788104,-3.6085730499452975,-0.3530227716580563
736.00000000001,38.828142520083006,-3.710230144908644,-0.3611163755280886
737.4000000000101,38.876101165408556,-3.818376352860874,-0.3724528001811027
738.8000000000101,38.92370116271242,-3.935813647390875,-0.38257158289145643
740.20000000001,38.97137525151014,-4.055053671025408,-0.3904475349175227
741.6000000000101,39.019287198581644,-4.179483487763159,-0.40044268997469734
743.0000000000101,39.0674233120631,-4.304537580623293,-0.41051383149528053
744.4000000000102,39.11529174234779,-4.431963402616366,-0.42190359621706097
745.8000000000102,39.1630089477688,-4.5619549637321315,-0.43362608350123644
747.2000000000102,39.210761512319316,-4.6955977820302675,-0.4446855455474914
748.6000000000103,39.25899805090215,-4.834373552191797,-0.4572678249227362
750.0000000000102,39.306908220070824,-4.977236693538019,-0.4694705932232943
751.4000000000103,39.35520181399865,-5.122157969802485,-0.48267924935589246
752.8000000000103,39.40328333076549,-5.272588401468534,-0.49424043611237956
754.2000000000103,39.45097576614199,-5.427765837653239,-0.5079211186193078
755.6000000000104,39.49935331896618,-5.582036319041659,-0.5227534195162242
757.0000000000103,39.54803001015936,-5.7453027218770325,-0.5386808311757774
758.4000000000103,39.59604950109824,-5.9094890273242315,-0.5534754855946029
759.8000000000104,39.64452688601317,-6.078103689320981,-0.5680445130577776
761.2000000000104,39.693042025281365,-6.248014297976309,-0.5827493200005347
762.6000000000104,39.74146155846661,-6.422932047746836,-0.5998067870084851
764.0000000000105,39.78954999528045,-6.601303386184815,-0.6183458788739746
765.4000000000104,39.83750174080961,-6.777139644654123,-0.6358536387672102
766.8000000000105,39.88648676612792,-6.9605795065225,-0.6527803690788012
768.2000000000105,39.93522271655498,-7.141147093280789,-0.6725489454323936
769.6000000000105,39.983482369465094,-7.325890515887788,-0.6922211967161678
771.0000000000106,40.03187921668277,-7.513636224063236,-0.7131397179523211
772.4000000000106,40.08066787285524,-7.697966563118461,-0.7343790952327129
773.8000000000106,40.12904736063985,-7.8835169021432545,-0.7545837781029205
775.2000000000106,40.17795998244435,-8.072849286871342,-0.7765353837211695
776.6000000000106,40.226198862100354,-8.25715620735595,-0.8001294057596606
778.0000000000107,40.27472000319096,-8.43607254763313,-0.8233294050497766
779.4000000000107,40.323570234334426,-8.616126715195502,-0.8465158398686619
780.8000000000106,40.37210556930706,-8.787561611228572,-0.8705054104557837
782.2000000000107,40.42024456234653,-8.947628634821928,-0.8942246980573616
783.6000000000107,40.46881870179448,-9.106663532281804,-0.9212961045599797
785.0000000000107,40.51707810317693,-9.248241134524903,-0.9450610416541223
786.4000000000108,40.56531544298824,-9.378502366283753,-0.9722599818848203
787.8000000000108,40.61338911764637,-9.488415198863573,-0.9981550040354548
789.2000000000108,40.66117220691522,-9.57447266301103,-1.023262783441628
790.6000000000108,40.70875747124627,-9.633977985477983,-1.0511725366784503
792.0000000000108,40.756075228078856,-9.652015641398574,-1.0755269870399364
793.4000000000109,40.80308939267916,-9.63668528155545,-1.100470618056539
794.8000000000109,40.849634779180526,-9.558128806923511,-1.1263831994524143
796.200000000011,40.89584267369843,-9.427912384955889,-1.153340940956082
797.6000000000109,40.94140363497815,-9.231174315043335,-1.1777600262714416
799.0000000000109,40.98616025094013,-8.961693080934527,-1.201363137296485
800.400000000011,41.03071269617503,-8.598247601309723,-1.2226837688467072
801.800000000011,41.07406134829033,-8.104292247125606,-1.2438113381465077
803.200000000011,41.11551929485359,-7.412681034777855,-1.2635103975002955
804.600000000011,41.15583270504325,-6.473282630416683,-1.2796973709422121
806.000000000011,41.193731143437745,-5.321644096291959,-1.2910860142489664
807.400000000011,41.23195557144617,-4.062619429902786,-1.3021094705538552
808.8000000000111,41.27104463465908,-2.982794053391137,-1.3090324550941657
810.2000000000111,41.31196711393849,-2.189989433555065,-1.3122883132837901
811.6000000000112,41.35521665246024,-1.6706505001413021,-1.3150539520701439
813.0000000000111,41.39968111895524,-1.369438961076857,-1.3165228578416013
814.4000000000111,41.44501293405479,-1.205896590021624,-1.3178274588984893
815.8000000000112,41.49131297946373,-1.1217646236727565,-1.317840127507484
817.2000000000112,41.537968036509945,-1.0893581913208612,-1.318023986413146
818.6000000000113,41.584491295893066,-1.0736539218421501,-1.3191580264508822
820.0000000000113,41.63229032903945,-1.0729530668885132,-1.319150527323214
821.4000000000112,41.678862166689875,-1.0769613094945674,-1.3188271904892424
822.8000000000113,41.7268282996746,-1.075872470222596,-1.3194864157435928
824.2000000000113,41.77377681103768,-1.0799271982161804,-1.3194078559336804
825.6000000000113,41.82141290236967,-1.0828576011993196,-1.3192896981039048
827.0000000000114,41.868605241901264,-1.0860698790924341,-1.3200753476913958
828.4000000000113,41.9155769617154,-1.0888175138786267,-1.3188296712970495
829.8000000000113,41.96299895688161,-1.090116886109611,-1.31883024617935
831.2000000000114,42.01016613456373,-1.092392936671509,-1.3188286817115706
832.6000000000114,42.057711582456754,-1.0973338219429285,-1.320144177261401
834.0000000000115,42.104423157140516,-1.1020376798273008,-1.3201500811092588
835.4000000000115,42.15267505317265,-1.1066766897051488,-1.3201500639921133
836.8000000000114,42.2000328481648,-1.1115831384505497,-1.3201500648003583
838.2000000000115,42.247288100372806,-1.1173062578785065,-1.3201458057458786
839.6000000000115,42.29476677338987,-1.1221651439120222,-1.3206491967866363
841.0000000000116,42.34224103604409,-1.1255556882408562,-1.3201526967397657
842.4000000000116,42.38993388266506,-1.1278468770778314,-1.321466292832283
843.8000000000116,42.43769412151926,-1.129972615818483,-1.3214704334003677
845.2000000000116,42.48493239065073,-1.1308850352847073,-1.3214704206966896
846.6000000000116,42.53266500989828,-1.1353416001343537,-1.3211963250899692
848.0000000000116,42.57922083418959,-1.1390076178716044,-1.3201511696295003
849.4000000000117,42.62769183367674,-1.1408811950067246,-1.3201485699595583
850.8000000000117,42.674927955955184,-1.1459618010906487,-1.3208248865345404
852.2000000000116,42.72186114512767,-1.1516463259625416,-1.320119980865127
853.6000000000117,42.77033565547133,-1.1547997715901532,-1.321475721974065
855.0000000000117,42.818276799652146,-1.1578837006985268,-1.3224491050248557
856.4000000000118,42.866215396882616,-1.1597442471045583,-1.3234407619113941
857.8000000000118,42.9143066086001,-1.1618780383807361,-1.3237758607387788
859.2000000000118,42.96232809232308,-1.1668396300487802,-1.322443903340174
860.6000000000118,43.01036631145559,-1.1710587975487747,-1.32244990569332
862.0000000000118,43.05799292260529,-1.1739304362304612,-1.3226353839200633
863.4000000000119,43.10661949750441,-1.1809656983949406,-1.3237688792478672
864.8000000000119,43.15471615499673,-1.1839843167623108,-1.3237701835651388
866.2000000000119,43.20257471545043,-1.1875891342507296,-1.3237670979729814
867.600000000012,43.25064143608178,-1.1893696008777617,-1.322496473195991
869.0000000000119,43.29875810311425,-1.189229525122045,-1.323770235257999
870.4000000000119,43.346741340725025,-1.191674581527409,-1.3237701316372528
871.800000000012,43.39445027749433,-1.1956065617887797,-1.3237701094739265
873.200000000012,43.44263551476397,-1.193359761207118,-1.3237860921990854
874.600000000012,43.49034254425781,-1.1947176900765069,-1.3250896394794962
876.000000000012,43.53796141862854,-1.194756671669006,-1.3250830751431795
877.400000000012,43.58627300435624,-1.1903117212861902,-1.3264152391888615
878.8000000000121,43.63432471959491,-1.1882767840894313,-1.3264134380087733
880.2000000000121,43.681900266238124,-1.1890658240979095,-1.3251228878215349
881.6000000000121,43.729457624991035,-1.1895614070473826,-1.3264002364968444
883.0000000000122,43.7770318058994,-1.1866085802332362,-1.3274838830705118
884.4000000000121,43.82524196695445,-1.1854690496162397,-1.3277205442170663
885.8000000000122,43.872847725345096,-1.1829142189552766,-1.3277200372281
887.2000000000122,43.92016901605108,-1.1780205145271512,-1.3271715680775635
888.6000000000122,43.968006798603106,-1.1778479373937913,-1.327719731270018
890.0000000000123,44.01558490111249,-1.1719891181138646,-1.3277193635605609
891.4000000000123,44.063264412120745,-1.1696792335310555,-1.328126911795835
892.0000000000123,44.08355538669647,-1.1680539639187006,-1.3291895551764723