File: 01_Data/Cinder_Block/STA/N2/30K_min/Cinder_Block_STA_N2_30KData_230823_R1.csv
##Temp./Â°C,Time/min,DSC/(mW/mg),Mass loss/mg
28.1,15.38327326636095,-2.301692284350022,0.011145594547104842
29.50000000000002,15.731672630035225,-2.2076298549862154,0.0068615823278346255
30.90000000000004,15.891755063561263,-2.1510352732413733,0.007031516349493394
32.30000000000006,16.00911989874432,-2.1032248733011403,0.007932496992221871
33.70000000000008,16.10910315276822,-2.059599795821969,0.005428579762583929
35.1000000000001,16.196558729239,-2.0204528353473172,0.008554821220768005
36.50000000000012,16.276262361308547,-1.9826771377570342,0.0057732150228231305
37.90000000000014,16.350964713652488,-1.9476812165149142,0.006242862652507952
39.30000000000016,16.421123576496345,-1.91378460315394,0.006036799832850548
40.70000000000018,16.487887013492404,-1.8853771605586458,0.006343007369982168
42.1000000000002,16.55269822445686,-1.8540826950297775,0.00569292971443236
43.50000000000022,16.614542669448443,-1.826960537730046,0.007586683783547876
44.90000000000024,16.675070943930674,-1.8007561287317015,0.0036681651011996053
46.30000000000026,16.734190010945216,-1.7762674801262353,0.004555475819294941
47.70000000000028,16.791073555431616,-1.7534769697012544,0.004472908670722475
49.1000000000003,16.8478975690954,-1.7323748767297715,0.004705103581717829
50.50000000000032,16.903558805525638,-1.7128946283769408,0.004056361879311687
51.90000000000034,16.957751983046247,-1.6937579914513032,0.0037957435988076327
53.30000000000036,17.0116190436584,-1.6763548325261612,0.004047163869865145
54.70000000000038,17.065074185999773,-1.6620100397867428,0.0037845253203352414
56.1000000000004,17.117870451268498,-1.6451065872367188,0.0037235285012755526
57.50000000000042,17.169741067191968,-1.6321390783045602,0.002016603466952205
58.90000000000044,17.221635739847674,-1.6158021366004123,0.0043575682042291675
60.30000000000046,17.2727955775428,-1.603812278314051,0.003605861066927396
61.70000000000048,17.323564004191812,-1.5935559484308657,0.0025195047109800583
63.1000000000005,17.37415924766756,-1.5810268378055654,0.0021923308020053156
64.50000000000051,17.424765508945377,-1.5701380443177053,0.0019550103852310485
65.90000000000055,17.474608161494917,-1.5588965304748756,0.0016323123455208588
67.30000000000055,17.523920448658384,-1.547926361834516,0.00045404908993962323
68.70000000000059,17.57383368972377,-1.536176206491806,0.0004704531691857028
70.10000000000059,17.62317509812936,-1.5243486513614444,-0.002678664138618281
71.50000000000063,17.67198320163622,-1.51242065451098,-0.0034164867325925385
72.90000000000063,17.72131730420687,-1.5008662432207327,-0.00257619193609937
74.30000000000067,17.770312267215186,-1.48808651468342,-0.002688791214284336
75.70000000000067,17.820000000000025,-1.476909999999999,-0.0026752832058205556
77.1000000000007,17.867636530996872,-1.4645318244613,-0.004063923271362846
78.50000000000071,17.917241607406496,-1.4536185566481175,-0.00403192042018663
79.90000000000074,17.965202215078083,-1.4390107296718575,-0.004073593865244085
81.30000000000075,18.01400898515732,-1.4274113184811643,-0.004401951971614082
82.70000000000078,18.061768325117736,-1.4164439721782376,-0.005512483880285579
84.10000000000079,18.11000000000003,-1.403359999999989,-0.006806896534733653
85.50000000000082,18.158003516150682,-1.3930830720330243,-0.005577195815538616
86.90000000000083,18.205647645863795,-1.3814366272014964,-0.006799714778775723
88.30000000000086,18.253003959779388,-1.3692828334372869,-0.006812336588948753
89.70000000000087,18.30063970348219,-1.3576622959010312,-0.008106004295024505
91.1000000000009,18.348033212773085,-1.3466877741942742,-0.008118182465761237
92.50000000000091,18.3952113025499,-1.3346161231212548,-0.00941258733836392
93.90000000000094,18.442031410910648,-1.324591086953401,-0.010433975691857
95.30000000000095,18.489072505012814,-1.3107293149550314,-0.009431626662413706
96.70000000000098,18.53637802904624,-1.2983493794832706,-0.010756673094372005
98.10000000000099,18.582842814269604,-1.2860254225608487,-0.011479944326825198
99.50000000000102,18.629289605216275,-1.2743193960799613,-0.011410696855415736
100.90000000000103,18.67606161570652,-1.262048664414165,-0.012030548871377889
102.30000000000106,18.72196047069385,-1.2502686458447205,-0.012729331075200356
103.70000000000107,18.768275475192567,-1.238448823529153,-0.012742905964115536
105.1000000000011,18.815386820884253,-1.2263284370177316,-0.012009355549784217
106.50000000000111,18.86123567635725,-1.2128577487211698,-0.013041224967500042
107.90000000000114,18.907758972443855,-1.2019341296636088,-0.014374648919744715
109.30000000000115,18.953744982131347,-1.1893397401949184,-0.014368489800967055
110.70000000000118,18.99990246317529,-1.1775771847255614,-0.015023103137715488
112.10000000000119,19.045696878602257,-1.1666803344383505,-0.016351586500210402
113.50000000000122,19.091761106382165,-1.153731248516439,-0.016341150477014565
114.90000000000123,19.1381424775254,-1.141510371553192,-0.01767600906055211
116.30000000000126,19.182910890357114,-1.1296747527779587,-0.017659688216278724
117.70000000000127,19.22942232364986,-1.1174096641308902,-0.01636000089641243
119.1000000000013,19.275501320514362,-1.1061216593107588,-0.01766390337709467
120.50000000000131,19.320557777335395,-1.096218967163748,-0.017670079544637396
121.90000000000134,19.36685450439104,-1.0841689620840893,-0.017699095376833007
123.30000000000135,19.411997521834685,-1.0731245526049324,-0.017999785345240937
124.70000000000138,19.45747338131617,-1.0626005205392255,-0.01796913262397659
126.10000000000139,19.50283470925738,-1.0495191148712448,-0.018984666667900107
127.50000000000142,19.54782525903809,-1.0405070011840856,-0.01898000696648161
128.90000000000143,19.593125790231525,-1.0289870306464959,-0.018980149715901895
130.30000000000146,19.638011755928808,-1.016797984295509,-0.018920674988207153
131.70000000000147,19.682587366633978,-1.0052258347330167,-0.020299379746085755
133.1000000000015,19.727128487153156,-0.9944201725259063,-0.02030001883910515
134.5000000000015,19.77135617985773,-0.9841945607374649,-0.020300009361361226
135.90000000000154,19.816959919113728,-0.9737915918122463,-0.020295633833090854
137.30000000000155,19.861275659570516,-0.9623438589157521,-0.020950441691413246
138.70000000000158,19.906043979677012,-0.953037616078597,-0.02096853079392691
140.1000000000016,19.94990636948612,-0.9425873404935365,-0.02228609368762413
141.50000000000162,19.99442195859566,-0.931463809979041,-0.022280148269686606
142.90000000000163,20.038596446065498,-0.9226091172784668,-0.02228015194465538
144.30000000000166,20.08281530480956,-0.9119275782797824,-0.02228015200007416
145.70000000000167,20.126686792513052,-0.9012596631902509,-0.02228015203757927
147.1000000000017,20.17080755959565,-0.8924357875491442,-0.022280147983107845
148.5000000000017,20.214858142164662,-0.8816575100075128,-0.022275407970706596
149.90000000000174,20.2584290428261,-0.8728390488135721,-0.02360659552637223
151.30000000000175,20.302355567228375,-0.8639725489300338,-0.024922454507272818
152.70000000000178,20.34624334086132,-0.8515095012574936,-0.02491995052934204
154.10000000000178,20.388992000580735,-0.8441480963601127,-0.024920021178659546
155.50000000000182,20.43325307171496,-0.8340588476702469,-0.02491970722057868
156.90000000000182,20.47755637676407,-0.8253470587500435,-0.024618483119001944
158.30000000000186,20.52091779144563,-0.8140879812184765,-0.022279644297567458
159.70000000000186,20.5645968600636,-0.8051326201844272,-0.023279541395368142
161.1000000000019,20.60775067626095,-0.7977935493784964,-0.024907392458347388
162.5000000000019,20.651677070259435,-0.7881465943112452,-0.024917760612724216
163.90000000000194,20.695060010945454,-0.7785022085732967,-0.02617045732598644
165.30000000000194,20.738640350520715,-0.7696425154745828,-0.026239844300346427
166.70000000000198,20.781351267809924,-0.7591862790318883,-0.026239888151208923
168.10000000000198,20.82556813728196,-0.7511029587935218,-0.02623988800099486
169.50000000000202,20.86858380636472,-0.7435539758562169,-0.026239888000074707
170.90000000000202,20.912287198667943,-0.7354610686719234,-0.026239887983473764
172.30000000000206,20.955253476286174,-0.7272761781899483,-0.026239876170752297
173.70000000000206,20.998850027379074,-0.7199671668111501,-0.026238121826428262
175.1000000000021,21.04171284536548,-0.7116911328752453,-0.02655381392693812
176.5000000000021,21.08544179159277,-0.7014860300455541,-0.026561017417310318
177.90000000000214,21.127936931505563,-0.6957437755937435,-0.02707255450498014
179.30000000000214,21.170933120960527,-0.6875622149653855,-0.02828094278485782
180.70000000000218,21.214036368733275,-0.6801269805222017,-0.02889641134198584
182.10000000000218,21.257251794175865,-0.6734626159507923,-0.02886015992483415
183.50000000000222,21.30021965044228,-0.6663142859968371,-0.028860059969661123
184.90000000000222,21.3428369200033,-0.6585498028623235,-0.02886006001334973
186.30000000000226,21.385828578787663,-0.6503814093255028,-0.028860064660230833
187.70000000000226,21.428781512801415,-0.6454255706259671,-0.028860605622959667
189.1000000000023,21.47172628078638,-0.63843398843465,-0.029663913535551423
190.5000000000023,21.514431188948667,-0.6314463395723289,-0.03017890247165589
191.90000000000234,21.557151399424022,-0.6248261319404803,-0.030179940667462546
193.30000000000234,21.599907663211212,-0.6183691076047615,-0.030177161433492472
194.70000000000238,21.642616060873802,-0.612770264654981,-0.031152688273686557
196.10000000000238,21.685240197722674,-0.6070474713068267,-0.03116986463347171
197.50000000000242,21.727738999204693,-0.6008482780136275,-0.031169927927651386
198.90000000000242,21.770217190163297,-0.5940877584520913,-0.031169945779308428
200.30000000000246,21.81284273336858,-0.5902584809888495,-0.031176350044541223
201.70000000000246,21.854623567057843,-0.5836117231094994,-0.030127085055018377
203.1000000000025,21.897467899763306,-0.579848212675839,-0.0309129690511174
204.5000000000025,21.94061793170629,-0.5720250370109774,-0.03150016440173786
205.90000000000254,21.983105783738473,-0.566781725304939,-0.031500199822944275
207.30000000000254,22.0257578417314,-0.5626309830511341,-0.03150026031566178
208.70000000000258,22.068341295891837,-0.5563587614619282,-0.03150334266042343
210.10000000000258,22.110735040253353,-0.5526042071731807,-0.03280667750007016
211.50000000000261,22.153138138146314,-0.5463248240459462,-0.03281917944958135
212.90000000000262,22.19552974922683,-0.541105733208542,-0.03232858479511069
214.30000000000265,22.237858558907313,-0.5376499605072362,-0.03150006601479749
215.70000000000266,22.280515098779222,-0.5321399535371821,-0.03150020574077317
217.1000000000027,22.323092425457386,-0.5259209387825181,-0.03150157824307609
218.5000000000027,22.365339791602207,-0.5215154788583061,-0.03205749829246951
219.90000000000273,22.407918890798392,-0.5181325034620302,-0.03314982867662142
221.30000000000274,22.45045308308723,-0.5130496896376046,-0.033150024670119294
222.70000000000277,22.492719012760073,-0.5087132710612856,-0.0331500001425189
224.10000000000278,22.53520603381913,-0.5039727280822216,-0.03314999987483791
225.5000000000028,22.57676286102534,-0.4988396578957323,-0.03314999951931963
226.90000000000282,22.61993878319824,-0.4928643118005013,-0.03315948921885514
228.30000000000285,22.66234282902554,-0.4896117094713187,-0.03379178736557886
229.70000000000286,22.704683885157966,-0.48483772286807875,-0.03381054577589282
231.1000000000029,22.746714098402958,-0.4816787926488483,-0.03404062961801824
232.5000000000029,22.789308536361197,-0.47694262794016473,-0.03413998827476927
233.90000000000293,22.83126784202617,-0.47148269902893014,-0.0341403915483216
235.30000000000294,22.87386786418168,-0.46898562301373714,-0.03313729509504526
236.70000000000297,22.9160561702414,-0.46384421185911534,-0.03282036522075771
238.10000000000298,22.95832442513413,-0.46007233764020455,-0.03282014089540297
239.500000000003,23.000433697772532,-0.4554347036938057,-0.03286159150049528
240.90000000000302,23.042814184998655,-0.45225593199920133,-0.03542686116611726
242.30000000000305,23.08518523402604,-0.44817166077590814,-0.03544971382609052
243.70000000000306,23.1271739371872,-0.4440813844494026,-0.03544983555874115
245.1000000000031,23.16928041199298,-0.44051859862305454,-0.0354498359987776
246.5000000000031,23.211184598299386,-0.4381587603080312,-0.03544983585315986
247.90000000000313,23.25370467761982,-0.4342922739633176,-0.03544980560987465
249.30000000000314,23.29635098488795,-0.4323523199865058,-0.03544934650081366
250.70000000000317,23.338222627791957,-0.42865872120942783,-0.03677650883197714
252.10000000000318,23.380439252245353,-0.4251105447621927,-0.0367675829355969
253.5000000000032,23.422329574381926,-0.4229525745692002,-0.035396303517058136
254.90000000000322,23.464979061028455,-0.4190597534261832,-0.036813769810369656
256.30000000000325,23.50709630942544,-0.417572757797381,-0.03677000414671028
257.70000000000323,23.54934768970846,-0.4152251015588929,-0.03659379757639414
259.1000000000033,23.591641943060896,-0.4128757896867124,-0.03544712705464814
260.5000000000033,23.633451894467946,-0.40951477156053095,-0.03544466578549166
261.90000000000333,23.67581755484956,-0.4052785829461007,-0.03677307405471719
263.30000000000337,23.7181054366667,-0.4029612902102498,-0.0375839039833501
264.70000000000334,23.760594193564508,-0.40083340812665147,-0.038089925748752584
266.1000000000034,23.80271048616179,-0.39849117281529073,-0.03808996837547962
267.5000000000034,23.84463079300886,-0.3963314349457259,-0.03808940275978667
268.9000000000034,23.88690501493661,-0.39401400643334245,-0.03737881474617932
270.3000000000035,23.92919332856952,-0.39192465411351474,-0.037429601980314864
271.70000000000346,23.97118883460635,-0.3905233726088236,-0.037429974704596525
273.1000000000035,24.013508630726363,-0.3868875917241895,-0.03743010528644852
274.5000000000035,24.05576035344598,-0.3857988467277045,-0.03746397442722316
275.9000000000035,24.097931420946185,-0.38399277116889563,-0.037094807866792756
277.30000000000354,24.140092275429087,-0.38092755992624105,-0.03835857410816956
278.70000000000357,24.182331519112328,-0.3811051927639522,-0.038419872386273646
280.10000000000355,24.2245630074212,-0.3784961939498859,-0.038433669311458196
281.50000000000364,24.267111143195407,-0.37743009319946386,-0.039419468699036564
282.9000000000036,24.309133319329824,-0.3758497035609334,-0.039496965671751205
284.30000000000365,24.351622193950956,-0.37379272464673,-0.03809135781678297
285.7000000000037,24.39361375270657,-0.37324758941008457,-0.03809010449467909
287.10000000000366,24.436187942351157,-0.3720426230781797,-0.03809863002544045
288.5000000000037,24.47844832945676,-0.3701312106661175,-0.039416944084732286
289.90000000000373,24.520945330685922,-0.36770249197153176,-0.03941013471965693
291.30000000000376,24.563197348104033,-0.3660353025002703,-0.03941010337575879
292.70000000000374,24.60525889241506,-0.3661358508224102,-0.03940767216660657
294.1000000000038,24.64764605378599,-0.36596413363740693,-0.03975706269948187
295.5000000000038,24.690317226201955,-0.3635136448239906,-0.040417052109955165
296.90000000000384,24.73281576633163,-0.3622507429802901,-0.04104558342967035
298.3000000000038,24.774817192622816,-0.3605403648941382,-0.040068406040718596
299.70000000000385,24.81749973410248,-0.3599567011441122,-0.040060033463605205
301.1000000000039,24.85990859127775,-0.35946339802585325,-0.04005994836390414
302.5000000000039,24.90210020568602,-0.35786856320533844,-0.040059948000873646
303.9000000000039,24.944460144187545,-0.35681131993933873,-0.04005994799999879
305.30000000000393,24.987019616824668,-0.3585133239099677,-0.04005994800000012
306.70000000000397,25.029091328801968,-0.3562443820104492,-0.04005994799999657
308.100000000004,25.071940003387777,-0.3549502055370392,-0.04005994800137325
309.500000000004,25.114236722242598,-0.3559976177143289,-0.040059948613851315
310.900000000004,25.156605308662588,-0.3538390455390035,-0.04006008907352898
312.30000000000405,25.19922183065284,-0.3528534580971677,-0.04007069618812098
313.7000000000041,25.241584036017137,-0.35199520287730646,-0.041378721566743604
315.10000000000406,25.28382277276621,-0.3513371955411514,-0.04137980838825461
316.5000000000041,25.326720972165944,-0.35216001645482836,-0.04137981597255047
317.9000000000041,25.368934843758016,-0.352403773527335,-0.041379815999955216
319.30000000000416,25.411791047700863,-0.35194334519992126,-0.04137981599999785
320.70000000000414,25.45431112869109,-0.35199673127435027,-0.041379815999935676
322.1000000000042,25.49676418043994,-0.35128757408833294,-0.041379815985386426
323.5000000000042,25.53929482878936,-0.35024320565275274,-0.04137981496825294
324.90000000000424,25.581868749161984,-0.3490684014682225,-0.04138057532881145
326.3000000000042,25.624146315160218,-0.3506928661801151,-0.04177300251991056
327.70000000000425,25.667000768784746,-0.350673925276558,-0.04236882980842349
329.1000000000043,25.709504978536245,-0.3495304161481479,-0.042372165859456246
330.5000000000043,25.75206412746322,-0.3501633035316696,-0.04369350005318129
331.9000000000043,25.79500684619159,-0.3518860960157575,-0.043689933845457496
333.30000000000433,25.83755661312917,-0.3518543980757996,-0.043704966060619466
334.70000000000437,25.880437029336232,-0.35302345728907647,-0.042707442096825865
336.1000000000044,25.922907146673285,-0.3523164866104718,-0.042700009346516854
337.5000000000044,25.965719934261177,-0.35366446795434986,-0.04269758587101746
338.9000000000044,26.008418004547146,-0.3538477997181001,-0.04304047937644917
340.30000000000445,26.05152790657931,-0.35467551163437744,-0.04303004352182782
341.7000000000045,26.09398272567506,-0.35558115235225046,-0.04302405326594716
343.10000000000446,26.136867046374217,-0.35553372153992974,-0.04433230496708784
344.5000000000045,26.17972675105833,-0.3557973260712757,-0.044944709143219796
345.9000000000045,26.222349784922624,-0.3557933021462516,-0.045009935488910635
347.30000000000456,26.265442548921037,-0.3570036888666535,-0.04499674434799017
348.70000000000454,26.308475038913024,-0.35798545177637053,-0.04367380632578044
350.10000000000457,26.35122418737673,-0.3578325424199482,-0.04369012118693805
351.5000000000046,26.394196578024932,-0.35794589707100294,-0.04368321270577358
352.90000000000464,26.437052027181046,-0.3596287308134319,-0.044994670850167395
354.3000000000046,26.479939142988467,-0.3596215395837761,-0.045008348575070745
355.70000000000465,26.522980606194285,-0.35973478135294906,-0.045696538724100844
357.1000000000047,26.565926586408253,-0.3606205355675491,-0.04662686215846934
358.5000000000047,26.609315376919014,-0.35896144838732463,-0.04665004275272144
359.9000000000047,26.652215761938095,-0.3599000211513089,-0.04665006016549267
361.30000000000473,26.69543187550966,-0.35916966882215556,-0.04665006000085192
362.70000000000476,26.73825051067273,-0.36121121384657867,-0.04665005999670058
364.1000000000048,26.780981088428643,-0.3625747748303012,-0.0466500606312632
365.5000000000048,26.824508950194556,-0.36424043864334416,-0.046650648587525545
366.9000000000048,26.86778570422339,-0.3657296234436277,-0.046910413569759335
368.30000000000484,26.91087716541545,-0.3675463697644023,-0.048291609265048496
369.7000000000049,26.95395158757877,-0.3673405217936824,-0.04829407335331748
371.10000000000485,26.99741092981088,-0.3689280553301111,-0.04933400938133348
372.5000000000049,27.040339821129383,-0.37201477607089595,-0.048298704842004714
373.9000000000049,27.083407789378096,-0.37189835142113264,-0.048299999216408374
375.30000000000496,27.126933279679214,-0.37392706615156907,-0.04829999602642987
376.70000000000493,27.170095538657797,-0.3760306935513205,-0.0482999960000603
378.10000000000497,27.212987191803286,-0.37692887151391574,-0.048299996000000345
379.500000000005,27.25656149982074,-0.3799187064714361,-0.04829999599999857
380.90000000000504,27.299844167132868,-0.38117059782248836,-0.048299996000000345
382.300000000005,27.343262838487583,-0.38197293633677454,-0.04829999599999901
383.70000000000505,27.38650768379878,-0.38553818166989323,-0.048299996000000345
385.1000000000051,27.42993766888056,-0.38827373054324604,-0.04829999600011803
386.5000000000051,27.47335290291947,-0.3876165074057652,-0.04829999597552259
387.9000000000051,27.51683152012914,-0.3909797570068881,-0.04829997818537635
389.3000000000051,27.560151175311596,-0.39287965262034036,-0.04829743916868168
390.70000000000516,27.60340256807791,-0.3962774761911127,-0.0496261071848183
392.1000000000052,27.646975872648007,-0.3952799689964135,-0.05002938930269529
393.5000000000052,27.69048382623229,-0.39838883332692576,-0.05093958748433636
394.9000000000052,27.733930946273443,-0.4015323829682962,-0.05093985877912566
396.30000000000524,27.777367794094573,-0.40313749338190635,-0.05093986398615913
397.7000000000053,27.821108232096915,-0.405511128251566,-0.050939864000020485
399.10000000000525,27.864419741980505,-0.40788496997696394,-0.05093986400000006
400.5000000000053,27.90823128651535,-0.41074087667727904,-0.050939863999996504
401.9000000000053,27.951652662612926,-0.4129008618395503,-0.050939864001093405
403.30000000000535,27.99520131888745,-0.4157087810781315,-0.050939864613175345
404.70000000000533,28.038874596555488,-0.4192439261872763,-0.05093993367163652
406.10000000000537,28.082390834368915,-0.42121017326874727,-0.05089615393575153
407.5000000000054,28.126119266122593,-0.4252649285464487,-0.05224882631057515
408.90000000000543,28.169807511516105,-0.4283681039478165,-0.05226297713165007
410.3000000000054,28.21364339330393,-0.43108660657076014,-0.05214678975632747
411.70000000000545,28.257294217968493,-0.4339698806205562,-0.05224615391144338
413.1000000000055,28.300707765341816,-0.4361530441046057,-0.05357660095414296
414.5000000000055,28.344902487960006,-0.44059425339763725,-0.052275479739317454
415.9000000000055,28.388454733902634,-0.4432199665110962,-0.05225009585667495
417.3000000000055,28.432539457406754,-0.4489988159752956,-0.05225003854907895
418.70000000000556,28.476513781643334,-0.45033194635392754,-0.05225108262653233
420.1000000000056,28.520287750087366,-0.45454248037526906,-0.05293401138918297
421.50000000000557,28.563903760878905,-0.45977993331557915,-0.053568919505841084
422.9000000000056,28.608033554995256,-0.4652107324998912,-0.05357016874599552
424.30000000000564,28.652028367960103,-0.46671015818388095,-0.053976549190912326
425.7000000000057,28.695867562773582,-0.4726121126760742,-0.05454890437269899
427.10000000000565,28.74018539613063,-0.47775067386953846,-0.054549903170299174
428.5000000000057,28.78384852888333,-0.4838480620501712,-0.054549900690839426
429.9000000000057,28.8279890492198,-0.49074032756956154,-0.05454895503412338
431.30000000000575,28.872146738441508,-0.4950658321770217,-0.053797282500544163
432.70000000000573,28.916026809967793,-0.5006094651545587,-0.05313245171249914
434.10000000000576,28.960226274837495,-0.503621212528628,-0.054229831522096816
435.5000000000058,29.004388715730904,-0.5084990468754409,-0.05426699567361082
436.90000000000583,29.047573401900607,-0.5122005625970815,-0.05586944913894154
438.3000000000058,29.091882020022037,-0.5140275428618335,-0.05587017860531285
439.70000000000584,29.136470647021543,-0.5165767190618393,-0.0558700782766306
441.1000000000059,29.180316600397568,-0.5174798943530645,-0.055873810813142466
442.5000000000059,29.22497421925424,-0.5194875995442316,-0.05702455118734484
443.9000000000059,29.269020785617023,-0.520739006834799,-0.057189926176560046
445.3000000000059,29.313016826000876,-0.5237720536223927,-0.05719004374509318
446.70000000000596,29.35723938086337,-0.5262515132467137,-0.05718969505432092
448.100000000006,29.401609447082468,-0.5280026420272297,-0.05727410859239779
449.50000000000597,29.44495804737015,-0.5297240788158009,-0.05784885498827341
450.900000000006,29.489772426645228,-0.5336091896099228,-0.0578501805857492
452.30000000000604,29.533965825066435,-0.5378865781442144,-0.05784625275291333
453.70000000000607,29.57859925236252,-0.5440865606189665,-0.058541432567192686
455.10000000000605,29.6226305276925,-0.546876331976176,-0.057838204138644045
456.5000000000061,29.6671126758258,-0.5497505363752426,-0.057839805361350916
457.9000000000061,29.7111303830618,-0.5561449034131355,-0.057839812007700164
459.30000000000615,29.755687137347078,-0.5616103348071583,-0.05783981237464175
460.7000000000061,29.799906052900347,-0.5659105713391891,-0.057839816022778656
462.10000000000616,29.84379863323772,-0.5705592154284097,-0.05857170686022206
463.5000000000062,29.888578207783485,-0.5748995679602787,-0.05940884076205988
464.90000000000623,29.932622024784006,-0.5800797814099917,-0.06014897676461217
466.3000000000062,29.977199887929277,-0.5855098042894012,-0.06015112777955034
467.70000000000624,30.021486279601273,-0.591502455941134,-0.06093291967986625
469.1000000000063,30.06584359670742,-0.5954258424847433,-0.05983161508851875
470.5000000000063,30.11048023829799,-0.6016797062973842,-0.059828846559673465
471.9000000000063,30.15450231074371,-0.6067987244565618,-0.06073455055525301
473.3000000000063,30.19911512630868,-0.6124877968912443,-0.06081019999073245
474.70000000000636,30.24329313927329,-0.6176250720694954,-0.0611771419105942
476.1000000000064,30.287912772262672,-0.622139248475506,-0.061323250498989346
477.50000000000637,30.33232325516714,-0.6270380693743356,-0.06245818396170133
478.9000000000064,30.377142650217717,-0.6305509060267774,-0.062459813678505505
480.30000000000643,30.421595181932755,-0.6369789073304007,-0.06245998543096043
481.70000000000647,30.46613767146729,-0.6397705047281745,-0.06263893235052542
483.10000000000645,30.51080693100333,-0.6442223564160118,-0.06376699921308582
484.5000000000065,30.55501167410032,-0.6503697477508268,-0.06376995411419584
485.9000000000065,30.599873970109385,-0.6590789941365476,-0.0637699918924639
487.30000000000655,30.644084762396027,-0.6623171304640855,-0.06377080690186254
488.7000000000065,30.689550689333633,-0.6679033505678641,-0.06439271945148839
490.10000000000656,30.73440263184345,-0.6747786761063423,-0.0650888323959471
491.5000000000066,30.779056796171574,-0.6803232948025189,-0.06508806080198237
492.9000000000066,30.823794273238335,-0.6867692559496091,-0.06646125927524871
494.3000000000066,30.86852811247662,-0.6946077065196833,-0.06640986598146004
495.70000000000664,30.91355838389617,-0.6986235756204446,-0.06671170903188006
497.1000000000067,30.958458182216,-0.7022337650055848,-0.06773015683878558
498.5000000000067,31.00337714192241,-0.7047707907240107,-0.06772997393632263
499.9000000000067,31.048317049776955,-0.7097937396323359,-0.06772440371433497
501.3000000000067,31.093505993118335,-0.7151129667244637,-0.06868244771593002
502.70000000000675,31.13808853472425,-0.7175805716487316,-0.06899006645400974
504.1000000000068,31.183112160235186,-0.7221710524599225,-0.0690415279469967
505.50000000000676,31.228245407064968,-0.7246494622535997,-0.06986075772695699
506.9000000000068,31.27327126983687,-0.7290756327822049,-0.07035990805518466
508.30000000000683,31.31804122815713,-0.7325733975564603,-0.07035963316317062
509.70000000000687,31.36347115173734,-0.7363977295725351,-0.07065263479506179
511.10000000000684,31.408576933725772,-0.738479156602524,-0.07168004053786392
512.5000000000068,31.45355010804039,-0.7416847403931468,-0.07171120587196
513.9000000000069,31.498866926446862,-0.7440980206015153,-0.07300162457001447
515.300000000007,31.543811547575466,-0.7468554771271101,-0.07300016839156331
516.7000000000069,31.589026247838987,-0.7496079446608064,-0.07299995760019051
518.100000000007,31.634308391283955,-0.7533915236214642,-0.07337068440953542
519.500000000007,31.679078642933103,-0.7573181108056345,-0.07431010647273473
520.900000000007,31.724431007970956,-0.7608204560408045,-0.07510377792333411
522.300000000007,31.769032559217244,-0.7650916035922405,-0.07562949821474962
523.7000000000071,31.814870580921127,-0.7689344547799888,-0.07562046465851102
525.1000000000071,31.86032755364235,-0.772390242057695,-0.07695168944945019
526.500000000007,31.90560943795969,-0.7755226874925497,-0.07723308899260228
527.9000000000071,31.950740457833014,-0.7785024592357419,-0.07728028055495262
529.3000000000071,31.99620947849798,-0.7818662431177897,-0.07738370308738807
530.7000000000071,32.04161668737585,-0.7875389267475582,-0.07866429098588634
532.1000000000072,32.08685764838907,-0.7943887891310054,-0.07925351789275314
533.5000000000072,32.13203520161081,-0.7983335650232067,-0.07925011895230805
534.9000000000071,32.177532238905194,-0.8047007756129418,-0.07924641071610239
536.3000000000072,32.223154470138404,-0.8075071943164261,-0.08061894468276476
537.7000000000073,32.268747333890836,-0.8142698472963434,-0.08057005801109796
539.1000000000072,32.314230806451775,-0.8182456806014775,-0.08057185818129309
540.5000000000073,32.35953518038964,-0.8221195862829805,-0.08147070894468555
541.9000000000073,32.404888172811965,-0.8278852220554695,-0.08123287013234082
543.3000000000073,32.45026534803154,-0.8345009552361001,-0.08255097410338585
544.7000000000073,32.496018680465006,-0.8397160703919174,-0.082540892844718
546.1000000000074,32.54164209813294,-0.844218426509057,-0.083980927392858
547.5000000000074,32.587011874758595,-0.8500816944056696,-0.08517379066963882
548.9000000000074,32.63254565598146,-0.8558143453745726,-0.08654199034739074
550.3000000000075,32.67799385040497,-0.8607793981144429,-0.08515282596731977
551.7000000000074,32.72362458615929,-0.8683615981445745,-0.08651384193432943
553.1000000000074,32.76912200133781,-0.8770404459138861,-0.08652291180534322
554.5000000000075,32.814630729956804,-0.8820966227783107,-0.08747685008575656
555.9000000000075,32.86042110924742,-0.8885996120124608,-0.08851574597992373
557.3000000000076,32.90595595302554,-0.8956433180284965,-0.08969658023190297
558.7000000000075,32.951072444269286,-0.89927243336335,-0.09044925264273251
560.1000000000075,32.99703488117247,-0.9075090015742687,-0.09163347302697344
561.5000000000076,33.04259505329882,-0.9154770593229232,-0.09176659914990903
562.9000000000076,33.08837940846283,-0.9193103477784194,-0.09308043250331455
564.3000000000076,33.133902214666364,-0.9309327866556097,-0.09308981221690349
565.7000000000077,33.178998662722634,-0.93735845048482,-0.09308483213263319
567.1000000000076,33.22498984035461,-0.9430503879570878,-0.09441754973683825
568.5000000000077,33.270813707003754,-0.9489952193733009,-0.09584805651366501
569.9000000000077,33.31691433707734,-0.957119371476813,-0.09803349863824451
571.3000000000077,33.36232101694621,-0.9669579358101194,-0.09923445860084534
572.7000000000078,33.40765615159033,-0.9745708213567091,-0.09925061833145632
574.1000000000078,33.45355842416153,-0.985337496844837,-0.1005363887694144
575.5000000000077,33.499750744218346,-0.9904430762620405,-0.1005500843010192
576.9000000000078,33.54482878351901,-0.9954444025895417,-0.10052498359071915
578.3000000000078,33.59099671509498,-1.001858631836365,-0.09924159077167749
579.7000000000079,33.63688857563419,-1.0078182000881648,-0.0992401570177277
581.1000000000079,33.68239240775591,-1.0144662835579823,-0.09921544087846534
582.5000000000078,33.728530738140286,-1.0222236825313085,-0.10066597329548177
583.9000000000079,33.77420163478112,-1.0322768790081585,-0.10196219186207856
585.3000000000079,33.820259786291366,-1.0393945202702655,-0.10199124617431199
586.7000000000079,33.865799642520706,-1.0480149082782924,-0.10330516650869459
588.100000000008,33.91174658320202,-1.0543434853832236,-0.10469138202504258
589.500000000008,33.95736125051005,-1.0620637404879367,-0.10582305102338374
590.900000000008,34.0033303340476,-1.071039320174305,-0.10738802480965948
592.300000000008,34.04926900215251,-1.0812886315845314,-0.1087913131542333
593.700000000008,34.0949801047484,-1.0899612689636062,-0.1100159808601191
595.1000000000081,34.14098528639787,-1.0966363978245008,-0.1119612932656242
596.5000000000081,34.18702062343094,-1.1050915763190525,-0.11287686993543034
597.900000000008,34.23306343445834,-1.1129078125431204,-0.11282612350610943
599.3000000000081,34.27911379724886,-1.12174437356455,-0.11416539949391868
600.7000000000081,34.324956000555005,-1.1290254928732562,-0.11586511746279404
602.1000000000082,34.371083527432184,-1.140716784014518,-0.11781507787337953
603.5000000000082,34.416341131462396,-1.1468589999817236,-0.11880101795832587
604.9000000000082,34.46303972646513,-1.1579044206384772,-0.11924448449149239
606.3000000000083,34.50925288653032,-1.1663774946451748,-0.12042790568463957
607.7000000000082,34.555167943943886,-1.1753018232775205,-0.1217558675049526
609.1000000000082,34.60128676932831,-1.1832446716052505,-0.12174350810228729
610.5000000000083,34.647526164325676,-1.187959973068527,-0.12239896253228189
611.9000000000083,34.69343092814547,-1.1965751992181515,-0.12361093906972798
613.3000000000084,34.74006721663222,-1.2035508827291468,-0.1249308069792181
614.7000000000083,34.78568780242085,-1.2097211938063572,-0.12625789571719404
616.1000000000083,34.8320501956813,-1.2172438362852203,-0.1272807625410417
617.5000000000084,34.87784330258959,-1.2211841371877956,-0.12771701378686684
618.9000000000084,34.92438254821069,-1.2270387478483211,-0.1289399354419225
620.3000000000084,34.9697047601027,-1.2322346049649606,-0.13083482243723665
621.7000000000085,35.016144061954215,-1.2386623956122493,-0.1321746305173077
623.1000000000084,35.06275611805229,-1.2450060270214203,-0.1326202704116004
624.5000000000085,35.109002326323754,-1.254161568107643,-0.13382760706326824
625.9000000000085,35.15470041946325,-1.2580519052705632,-0.13405553468867293
627.3000000000085,35.201391475114036,-1.264678344025172,-0.13592125173651137
628.7000000000086,35.247806135637305,-1.2748000983535774,-0.13669597168524739
630.1000000000085,35.29411795994511,-1.2818942901217711,-0.13840785600776995
631.5000000000085,35.34033312027675,-1.2910131540346368,-0.13976198638414683
632.9000000000086,35.38659473498366,-1.2988549032285541,-0.1410905191119145
634.3000000000086,35.43289464162704,-1.3050812037496722,-0.1424034413035713
635.7000000000087,35.47927008872988,-1.3143892889384987,-0.14369900242133626
637.1000000000087,35.525464843723846,-1.3233862668711247,-0.14493074639849546
638.5000000000086,35.57200494013208,-1.331108067347257,-0.14589396238705987
639.9000000000087,35.618268510461185,-1.3384161716240097,-0.1476698823780218
641.3000000000087,35.66443800429159,-1.3465067793871546,-0.14904454894023633
642.7000000000087,35.7107933974937,-1.3558373605931564,-0.1504203416569685
644.1000000000088,35.757192883285335,-1.3643930000864193,-0.15211935858270742
645.5000000000088,35.8036045055235,-1.375133453285061,-0.1552143473177301
646.9000000000088,35.85013458435974,-1.384686413849515,-0.1566480787996718
648.3000000000088,35.89631826883161,-1.390310303694798,-0.15797431289933828
649.7000000000088,35.943013706255016,-1.4026066031909716,-0.15938345741599624
651.1000000000089,35.98868850502112,-1.4100227029923125,-0.16051878948272247
652.5000000000089,36.03588366923606,-1.4191565485865087,-0.16074607694030618
653.9000000000088,36.08217596999206,-1.429495569233457,-0.16195940696974542
655.3000000000089,36.12875783600402,-1.4379019314034291,-0.16310378857223595
656.7000000000089,36.17511131350395,-1.449527765248425,-0.16517587892192465
658.100000000009,36.2215713179096,-1.4584027735925362,-0.16664398423192406
659.500000000009,36.26794583523009,-1.4696959190974952,-0.16926397510111846
660.900000000009,36.31444970727971,-1.4799739333916355,-0.1706803033482247
662.300000000009,36.36114569859774,-1.4931036671030307,-0.17204272605741977
663.700000000009,36.407790178349586,-1.5050189586701734,-0.1749845739132514
665.100000000009,36.454256974454374,-1.5168685364340628,-0.1765484174997538
666.5000000000091,36.50091677787123,-1.5294696845475118,-0.17780453178459554
667.9000000000091,36.54748745050374,-1.5455593780830021,-0.18041621632200844
669.3000000000092,36.59369165402758,-1.5576857399789399,-0.18180051165499833
670.7000000000091,36.640758210521696,-1.5748255458284863,-0.1832223178177821
672.1000000000091,36.68740518398437,-1.5957266293893675,-0.1846550512534737
673.5000000000092,36.73417903032744,-1.614141132499583,-0.1871468388333244
674.9000000000092,36.78061959288807,-1.6366648550532636,-0.18937545990649607
676.3000000000092,36.827367928023946,-1.6577352832290742,-0.1911048848993966
677.7000000000093,36.87382788420405,-1.6811083377320808,-0.1925256393264103
679.1000000000092,36.920599747209565,-1.7069671923461,-0.19422707653614113
680.5000000000093,36.96745950872939,-1.7335907220234912,-0.19773894663969482
681.9000000000093,37.01423426572172,-1.7624484850788555,-0.20085457443147714
683.3000000000093,37.060891758455035,-1.7926766912356473,-0.20440300282909352
684.7000000000094,37.10790634324855,-1.826297145179241,-0.20635948370288792
686.1000000000093,37.15466165998809,-1.856204556014446,-0.2089534758057301
687.5000000000093,37.20070993323747,-1.8900997029958202,-0.21063708522465419
688.9000000000094,37.24816935927231,-1.924816341269457,-0.21313395960806103
690.3000000000094,37.295012937408266,-1.957213594686587,-0.21637058093730932
691.7000000000095,37.341837033413675,-1.9951476833828061,-0.21942514500319632
693.1000000000095,37.38889527873039,-2.03232401685337,-0.22259015817817351
694.5000000000094,37.43527742345935,-2.0682230945664526,-0.22675527035256593
695.9000000000095,37.482350656875745,-2.106141291738223,-0.23064984708074254
697.3000000000095,37.529291806357236,-2.147316811188823,-0.23507242512177262
698.7000000000095,37.57629009682667,-2.188949571024985,-0.23891645849700227
700.1000000000096,37.6229721782425,-2.2333848469806177,-0.2424388770555863
701.5000000000095,37.67006787851674,-2.2750526258816803,-0.24623667287402418
702.9000000000096,37.71705347533361,-2.3183589088638157,-0.25138787041231314
704.3000000000096,37.76403800569986,-2.36632284018698,-0.25574233155213877
705.7000000000096,37.81093579201412,-2.4160550833481333,-0.25979448428712626
707.1000000000097,37.857890579026424,-2.463621244957728,-0.2648377256717507
708.5000000000097,37.90530977915401,-2.517573515283321,-0.26891611927109516
709.9000000000096,37.952347006741185,-2.5719344094158396,-0.27391790534293614
711.3000000000097,37.999792930494564,-2.629627513626713,-0.27948200747329777
712.7000000000097,38.04627910007823,-2.6885492325124547,-0.2841107656561035
714.1000000000098,38.094190644647675,-2.7474552358046287,-0.28823829313270455
715.5000000000098,38.14128305790102,-2.816330164738422,-0.29436535412375164
716.9000000000098,38.18877458111538,-2.88061761077499,-0.30125949653274287
718.3000000000098,38.235880135796265,-2.94696324665213,-0.3073077771010855
719.7000000000098,38.28336252999041,-3.0207891204784363,-0.31364121607218287
721.1000000000098,38.33086310802553,-3.0915513137304056,-0.3206020321724252
722.5000000000099,38.378085771940505,-3.167768677617413,-0.327600571655442
723.9000000000099,38.42633276894751,-3.249827005841218,-0.33576499090456613
725.30000000001,38.47337691394417,-3.3324895571517668,-0.34302734071043384
726.7000000000099,38.52106624228144,-3.4157236829605457,-0.35001543692996107
728.1000000000099,38.5687772338406,-3.5048444554478273,-0.35762579221843893
729.50000000001,38.6167072210157,-3.598720333628375,-0.3667672981265757
730.90000000001,38.664263904293556,-3.695876146205456,-0.37505093969667236
732.30000000001,38.712382806857136,-3.793125510170176,-0.38366183911331264
733.70000000001,38.760168650790746,-3.900671150464424,-0.39284347093371697
735.10000000001,38.808111421676266,-4.010682902008469,-0.403365693020048
736.5000000000101,38.855930320752904,-4.122442496066674,-0.41219872071992736
737.9000000000101,38.90391111622039,-4.242075183010245,-0.4209706163648921
739.3000000000101,38.95233115235855,-4.361746995560176,-0.43160178321760867
740.7000000000102,39.000207440681564,-4.491580987911899,-0.44413024787329336
742.1000000000101,39.0486292717354,-4.623486869725107,-0.4565614956306532
743.5000000000101,39.09632909105829,-4.7546324691186035,-0.4674355646185706
744.9000000000102,39.14486915803608,-4.8910529545010535,-0.4805926736507282
746.3000000000102,39.19317834936285,-5.029285660296644,-0.49321323972188047
747.7000000000103,39.24106950525491,-5.171826454807786,-0.5064406153193421
749.1000000000103,39.28993234453983,-5.320023046726353,-0.5183547789621157
750.5000000000102,39.33841142126772,-5.469477274463227,-0.5312757631557372
751.9000000000103,39.386220489468194,-5.623676067293169,-0.5457948132186043
753.3000000000103,39.435018216111814,-5.783101409317598,-0.5610202211078792
754.7000000000103,39.483674792251946,-5.943689525468087,-0.5769758543413337
756.1000000000104,39.532171752596184,-6.114001594217211,-0.593714678573793
757.5000000000103,39.58067288069862,-6.280780994064706,-0.6104750207627991
758.9000000000104,39.628772481922084,-6.450868677831832,-0.625847494192231
760.3000000000104,39.677516092918886,-6.627176060307261,-0.6442147898997859
761.7000000000104,39.72597823410575,-6.805845194918002,-0.6625650030769132
763.1000000000105,39.77488543446725,-6.987412559408133,-0.6818886188674957
764.5000000000105,39.82317132409123,-7.166669069769769,-0.7006131835328446
765.9000000000104,39.87168563229568,-7.354852819542862,-0.71969378839262
767.3000000000105,39.92040456113332,-7.541115993729198,-0.7412243957119191
768.7000000000105,39.96889424362246,-7.7266565773628955,-0.7627190201108336
770.1000000000106,40.01747367492002,-7.911744178702452,-0.7836585122770199
771.5000000000106,40.06628636538596,-8.097384778980281,-0.805078615193568
772.9000000000106,40.114737617442266,-8.282020478585403,-0.8286404548650719
774.3000000000106,40.16333566752024,-8.4619482911189,-0.8516486835787624
775.7000000000106,40.21176463753202,-8.63950261651849,-0.8762642964430825
777.1000000000106,40.26028397538232,-8.813355657262163,-0.9001236041151088
778.5000000000107,40.3085606293719,-8.978224638699135,-0.9246796125381809
779.9000000000107,40.357268705603985,-9.134724664381839,-0.9499369653302376
781.3000000000108,40.405393917104405,-9.277074459967208,-0.9768362780673594
782.7000000000107,40.45343727509495,-9.404019702298381,-1.0027965390195503
784.1000000000107,40.500756378642286,-9.510443753966985,-1.0285665413674057
785.5000000000108,40.54917541389124,-9.595228758513684,-1.0546625010641457
786.9000000000108,40.596006853824875,-9.643500195796745,-1.0808701417061264
788.3000000000108,40.643968593457735,-9.660452215776766,-1.1080620273058304
789.7000000000108,40.69077519953717,-9.634074216872888,-1.135370872370018
791.1000000000108,40.737092885285676,-9.547288544473195,-1.1609485674036777
792.5000000000109,40.78298264901873,-9.392005155247718,-1.188360236686575
793.9000000000109,40.828584569274945,-9.15621515993845,-1.2116209783033778
795.3000000000109,40.87239662913024,-8.831570719252934,-1.2331291755758507
796.700000000011,40.916322900498855,-8.384194886222103,-1.255271893044343
798.1000000000109,40.958215124569215,-7.773484770809388,-1.2753270350153154
799.5000000000109,40.99829151006347,-6.874631875970488,-1.291952957709844
800.900000000011,41.03590425288186,-5.717552162719676,-1.3047629999954982
802.300000000011,41.07327065936716,-4.420717817058512,-1.3144316978269681
803.7000000000111,41.11149899995652,-3.2814941168764724,-1.3226614466620439
805.100000000011,41.151768233070726,-2.4295960604444407,-1.325206670725957
806.500000000011,41.193684106821316,-1.8774309835271743,-1.3265505431407316
807.9000000000111,41.23845082097208,-1.5366673328209455,-1.3287909325600156
809.3000000000111,41.28346479464283,-1.3590859481636541,-1.3295988382664627
810.7000000000111,41.32989806167676,-1.2674045175224355,-1.3309002629788145
812.1000000000112,41.37656702659369,-1.2351860348955634,-1.3309001833979197
813.5000000000111,41.423362462552944,-1.2210365943172474,-1.3309003262512804
814.9000000000112,41.47075883301944,-1.2199335467117882,-1.3308538434090713
816.3000000000112,41.51723555748991,-1.2164284972643764,-1.3312871005980735
817.7000000000112,41.56477092148368,-1.221237092195098,-1.3309135473025822
819.1000000000113,41.61187764394763,-1.222552956040233,-1.3322103022654055
820.5000000000113,41.65922764770089,-1.2233576771359607,-1.3318894211800196
821.9000000000112,41.70624821969567,-1.2273376503729014,-1.3331892773756864
823.3000000000113,41.75363437948765,-1.2312739147758058,-1.3332001161288942
824.7000000000113,41.800943481141765,-1.236331594761746,-1.3332000898743295
826.1000000000114,41.84820721542892,-1.2392351443581084,-1.3331942206870453
827.5000000000114,41.89526680445885,-1.2424948870421877,-1.333711885915712
828.9000000000113,41.94263741181024,-1.2467856284099286,-1.3328807314504867
830.3000000000114,41.99000034760435,-1.248280016512799,-1.3328799019396564
831.7000000000114,42.03722959839466,-1.2499272945775028,-1.3332106539690023
833.1000000000114,42.08454896266822,-1.2526607082331778,-1.3330207223375137
834.5000000000115,42.13205697451891,-1.2567372418077427,-1.3328691963331964
835.9000000000115,42.17960860784979,-1.2588956659107158,-1.3329739197013297
837.3000000000116,42.22710859344112,-1.258177282682471,-1.3344354848851223
838.7000000000115,42.27437863793972,-1.2587587198636137,-1.3344859987676676
840.1000000000115,42.3220482156857,-1.2574257008100342,-1.3345165099988066
841.5000000000116,42.3692189705932,-1.2602230294177175,-1.334520010262045
842.9000000000116,42.41667813987413,-1.2623813918254503,-1.334520008601023
844.3000000000116,42.46414821332765,-1.263370525501495,-1.3345149062941828
845.7000000000116,42.51184328896953,-1.2607521559575507,-1.336726435675248
847.1000000000116,42.55908865014951,-1.260485048400854,-1.3356156565995163
848.5000000000117,42.60648175183373,-1.2575247881142584,-1.3348237901683646
849.9000000000117,42.65363572068321,-1.2574970459670034,-1.3355104356858796
851.3000000000117,42.70142401473579,-1.2570680223242454,-1.3353468319723691
852.7000000000118,42.74897344897342,-1.2582687611033785,-1.3348001967485654
854.1000000000117,42.796473423992225,-1.2574186236366127,-1.3348553044901479
855.5000000000117,42.84414229558777,-1.260727432882553,-1.3344967421776412
856.9000000000118,42.891497148216786,-1.2616639129900804,-1.3341872221464888
858.3000000000118,42.93917634004759,-1.262175621785715,-1.3367885834553506
859.7000000000119,42.98678439581828,-1.264445793468681,-1.3368203930007958
861.1000000000118,43.034287028506355,-1.2675429313955915,-1.3368196409469641
862.5000000000118,43.0819643811149,-1.2686235510346446,-1.3382219531913937
863.9000000000119,43.12932774377463,-1.2697168667374323,-1.3381401085117872
865.3000000000119,43.17686500615609,-1.269044301191761,-1.3381492107282473
866.7000000000119,43.2245762512475,-1.2670662628064753,-1.3381170288680089
868.100000000012,43.27217535318924,-1.2692331557388676,-1.3381499335058136
869.5000000000119,43.31986240328628,-1.269211918517587,-1.3381671390625955
870.900000000012,43.367235819235276,-1.2691365542195867,-1.3381401355835045
872.300000000012,43.41451573051802,-1.2697414176355357,-1.3381400916896293
873.700000000012,43.46212211742629,-1.2713611269410308,-1.3381400920150375
875.1000000000121,43.50983058830335,-1.2693266597136426,-1.3381400926352631
876.500000000012,43.557305520365,-1.268812265735435,-1.3381355803644945
877.900000000012,43.60490036845625,-1.2689313724532054,-1.3394670908619553
879.3000000000121,43.65230289768824,-1.269592508656684,-1.3394563875393257
880.7000000000121,43.699655194420366,-1.2700058283422788,-1.3407787453614852
882.1000000000122,43.74714598145575,-1.2693469747723478,-1.339029237572921
883.5000000000122,43.794286526261324,-1.2671148923141549,-1.338171676157156
884.9000000000121,43.84192591278234,-1.2684707694778246,-1.338194076782163
886.3000000000122,43.88957710604521,-1.2669925794560957,-1.339458623415585
887.7000000000122,43.93693705840247,-1.2656116264860082,-1.3407742179243103
889.1000000000122,43.98403811580948,-1.2657123864973459,-1.3407707469420016
890.5000000000123,44.03176182579037,-1.2646986217215994,-1.3416374844039707
891.9000000000123,44.07917796757843,-1.2635024424231742,-1.3421997784067488
892.0000000000123,44.08258852283529,-1.2633109228505064,-1.3422009523723055