File: 01_Data/Polyisocyanurate_Foam_Board/STA/N2/10K_min/Polyisocyanurate_Foam_Board_STA_N2_10KData_221019_R2.csv
##Temp./Â°C,Time/min,DSC/(mW/mg),Mass loss/mg
51.0,10.720700340566191,-1.6249417832434938,0.030880356159390665
52.000000000000014,11.089103426726199,-1.5097575119320148,0.033641014019727855
53.00000000000003,11.326337514545951,-1.43503666599916,0.03247791314499615
54.00000000000004,11.521930162471143,-1.3780210958173111,0.029629527227880814
55.00000000000006,11.69050082411908,-1.332774456251117,0.030348679263213718
56.00000000000007,11.85967760326753,-1.2926459333615536,0.03365380902161785
57.000000000000085,12.010806171054012,-1.2623315717778736,0.030662115755125008
58.0000000000001,12.156178043907504,-1.2356242947195224,0.029563621724764566
59.000000000000114,12.295810862241698,-1.2133604520207386,0.03077951231181153
60.00000000000013,12.431161631424043,-1.1924818972395845,0.03158507110314801
61.00000000000014,12.563701268772277,-1.1737623572068736,0.029890890366282896
62.000000000000156,12.693903619028944,-1.1568509880231286,0.03156223940310987
63.00000000000017,12.819641695003632,-1.1429932942224459,0.03142743662433922
64.00000000000018,12.945220944288149,-1.1274876357919537,0.034684380368939394
65.0000000000002,13.068359060982079,-1.1156018125174487,0.03349910917408838
66.00000000000021,13.18910316582105,-1.1032946587648154,0.034468579364581586
67.00000000000023,13.30852013882401,-1.0896439621654483,0.034440783973690436
68.00000000000024,13.425752332647734,-1.0802136353553402,0.034364285405929174
69.00000000000026,13.542654117798477,-1.06884952587749,0.03304132599520315
70.00000000000027,13.66010117784312,-1.056918503753411,0.033339591529006896
71.00000000000028,13.774740357195528,-1.0477123295875728,0.03289403483803799
72.0000000000003,13.887175315038569,-1.0390890898733585,0.030123484630225406
73.00000000000031,14.001767605937044,-1.0291666577439156,0.03219798445989319
74.00000000000033,14.112624807137449,-1.0204813929395962,0.033020865956434164
75.00000000000034,14.22670432149549,-1.0112384035207416,0.034418430020961566
76.00000000000036,14.335901955331636,-1.002575093306313,0.03428017842999953
77.00000000000037,14.444474492606208,-0.9958827129198732,0.03317605863764239
78.00000000000038,14.554736561735425,-0.9886798813696008,0.033167319733684586
79.0000000000004,14.663481830447598,-0.9807142372045198,0.03333228201424632
80.00000000000041,14.769496891643133,-0.974042359554187,0.03318952286620647
81.00000000000043,14.878439525970514,-0.9671767700183056,0.03256577620192047
82.00000000000044,14.985340620890453,-0.9604429740663697,0.033054273363898545
83.00000000000045,15.091298599840394,-0.9537893762533569,0.03456084087877809
84.00000000000047,15.196726235852537,-0.9473533297963918,0.03317598869111826
85.00000000000048,15.300827221401311,-0.9418933609935097,0.03254888363492192
86.0000000000005,15.407903613904047,-0.9354126752653513,0.03447968076741681
87.00000000000051,15.511098874886,-0.9279639469374417,0.03447921177990043
88.00000000000053,15.614145162851996,-0.9236961019251584,0.03446865717814518
89.00000000000054,15.71879291351538,-0.9176778707052448,0.03346321576433464
90.00000000000055,15.820255951843052,-0.9110009414404703,0.034480670423836735
91.00000000000057,15.921610129313192,-0.9061289316501828,0.033257224274241715
92.00000000000058,16.024016182240945,-0.8994052564716722,0.035360144179973574
93.0000000000006,16.125672693197522,-0.893661936131701,0.03449185070954375
94.00000000000061,16.22725742701386,-0.8885613154419401,0.03516669125128491
95.00000000000063,16.328033749026417,-0.8832688425269039,0.036372522649052996
96.00000000000064,16.429901382248673,-0.8766987082132318,0.035789923762007625
97.00000000000065,16.530312664477172,-0.8716894245985721,0.03549908035077287
98.00000000000067,16.63028061702003,-0.8654458536486576,0.034474632745356004
99.00000000000068,16.72924491648834,-0.8594148321736373,0.03579687594776537
100.0000000000007,16.829319481527197,-0.854737934464846,0.03711049490441454
101.00000000000071,16.928742322633155,-0.8490205925675692,0.037113729996892
102.00000000000072,17.02719479192812,-0.8437039736009313,0.03541535661333839
103.00000000000074,17.1257073023251,-0.8398575558043211,0.03440109237458078
104.00000000000075,17.22343105202977,-0.8339653512559675,0.03576823102107962
105.00000000000077,17.32322841666054,-0.8287855636855277,0.036946478502221325
106.00000000000078,17.4218620040121,-0.8237194541363997,0.034462940281015264
107.0000000000008,17.51936658558442,-0.8182556549638056,0.035789698524346214
108.00000000000081,17.619118945678352,-0.811998747652714,0.03716313045587061
109.00000000000082,17.716935737021235,-0.8076870614574341,0.03580017347903386
110.00000000000084,17.816205901474497,-0.8016263276645385,0.03573871452865962
111.00000000000085,17.912977530205414,-0.7956500702215853,0.0358003306068273
112.00000000000087,18.011702432776403,-0.7903070616902927,0.0373060938282439
113.00000000000088,18.107007118066406,-0.7861891315508907,0.037219066435514314
114.0000000000009,18.207487343981676,-0.7824775288083186,0.03722081397514998
115.00000000000091,18.30407189558694,-0.7777765483654144,0.037221185542435364
116.00000000000092,18.40092119333493,-0.7731350122656093,0.03590996841198102
117.00000000000094,18.49891032068093,-0.7675881641555415,0.03482821630738986
118.00000000000095,18.597076081304245,-0.7607482557861841,0.03588978601683568
119.00000000000097,18.693974056394403,-0.7593229992596877,0.03466579996477481
120.00000000000098,18.792694933518725,-0.7539134477513527,0.03487702955870642
121.000000000001,18.888924689325627,-0.7481109460772954,0.035580075450735826
122.00000000000101,18.986877690061768,-0.7441197543730789,0.034611036495571845
123.00000000000102,19.082723302391543,-0.7395992013538907,0.03466890812540768
124.00000000000104,19.180773392300186,-0.7361828845058708,0.034589920862022616
125.00000000000105,19.278082102122998,-0.7320284729567338,0.03375619068155178
126.00000000000107,19.373607351968552,-0.7293426631437264,0.03327000198594732
127.00000000000108,19.46989107082358,-0.7241086772704913,0.03462191630733091
128.00000000000108,19.56625008530493,-0.720934252710424,0.03456599027227192
129.0000000000011,19.664963430529596,-0.7154224948593527,0.034589836487349146
130.00000000000114,19.761590218983773,-0.7122049964343637,0.03327190204826724
131.00000000000114,19.857690022392504,-0.7081866271235729,0.03426080340905013
132.00000000000114,19.95371821176797,-0.7032866645858581,0.034552480479022485
133.00000000000117,20.05087477468925,-0.7002031698245389,0.03554638297939494
134.0000000000012,20.147368974172167,-0.6967904803382605,0.03535082742560025
135.0000000000012,20.243506377568046,-0.6914751328282928,0.03518594538440212
136.0000000000012,20.339902495919407,-0.6879069698319765,0.03403461337311864
137.00000000000122,20.43498737294537,-0.6848693391746394,0.03401300061073087
138.00000000000125,20.530675778031558,-0.6791324565627546,0.034037135352178005
139.00000000000125,20.626175271342603,-0.6763490823920701,0.03255920770555054
140.00000000000125,20.723225248672243,-0.6731906067784602,0.031397627557606
141.00000000000128,20.818933924327386,-0.6693839329415555,0.032763200416898286
142.0000000000013,20.91381736348084,-0.6645677471778116,0.03283454512981265
143.0000000000013,21.010129182759144,-0.6606099763240396,0.03141008287156932
144.0000000000013,21.10439171501361,-0.6581131409851763,0.030089000844957248
145.00000000000134,21.200094043294204,-0.6544093194929074,0.030089826283368204
146.00000000000136,21.296215025856867,-0.6522088371322339,0.030090013280609007
147.00000000000136,21.390969933110785,-0.6475308839862635,0.030092677320889827
148.00000000000136,21.48403996527895,-0.6447786795103051,0.030323709110477992
149.0000000000014,21.581364051432132,-0.6414380638398348,0.03008091595530793
150.00000000000142,21.677305462353438,-0.6386505647758068,0.028769768135588514
151.00000000000142,21.77217815896762,-0.635066233404255,0.028770163784676228
152.00000000000142,21.865812724147123,-0.6321120640028249,0.02744857559970093
153.00000000000145,21.96148124069615,-0.6280267410201698,0.02877367224530225
154.00000000000148,22.056814169543863,-0.6250895824012962,0.028769819924279183
155.00000000000148,22.15083038847371,-0.6209929054538575,0.028768199133205385
156.00000000000148,22.24605753157172,-0.6174547981457067,0.026138766127485447
157.0000000000015,22.34176651622056,-0.6136056500516941,0.027449976831494638
158.00000000000153,22.43766955547241,-0.6109942771951175,0.026166752479642064
159.00000000000153,22.531488219568498,-0.6065760960467425,0.024800461339301805
160.00000000000153,22.626837574234504,-0.604008633282553,0.025502557204950982
161.00000000000156,22.721361898422614,-0.5995497234551702,0.024778128381627518
162.0000000000016,22.81721815836496,-0.5962958914324916,0.02300840006781879
163.0000000000016,22.908950712662854,-0.5922190091797815,0.021185587716129106
164.0000000000016,23.0075519270891,-0.5887590547802067,0.021189006370514463
165.00000000000162,23.101906164699646,-0.583213999605538,0.018552537132378255
166.00000000000165,23.1969386321951,-0.5793846232955256,0.018587405667641832
167.00000000000165,23.28834951963989,-0.5769744034669368,0.01987007451010303
168.00000000000165,23.386450863249287,-0.573103690592256,0.01856871989405473
169.00000000000168,23.481088489998974,-0.5670194465749715,0.015962273899919666
170.0000000000017,23.576522091564737,-0.5645111884734727,0.013290126934060176
171.0000000000017,23.672016296987422,-0.5598388683980301,0.013290139999991624
172.0000000000017,23.76631449732748,-0.5552317021762703,0.013290128878596263
173.00000000000173,23.86192649871671,-0.5515933090668083,0.011964104877709936
174.00000000000176,23.9578764169749,-0.5467191183042525,0.01199899371783264
175.00000000000176,24.051757943242485,-0.5427319041616203,0.010645215427071086
176.00000000000176,24.147126119277207,-0.5392005964308542,0.00891564805915479
177.0000000000018,24.24051714292485,-0.5360717564065659,0.0059464137477034384
178.00000000000182,24.336446888757933,-0.5301413648351551,0.005969183883822282
179.00000000000182,24.432163351479353,-0.5271062665660298,0.005270341960744496
180.00000000000182,24.526781512261767,-0.5226443415196648,0.0032820436561751265
181.00000000000185,24.621224887329774,-0.5173296681714364,0.0013385313454978842
182.00000000000188,24.716343364025867,-0.5136543563950478,-0.0011521918985275548
183.00000000000188,24.811231813430048,-0.5104825992920149,-0.003958783703005508
184.00000000000188,24.906005720386478,-0.5047689855327926,-0.003946995568687939
185.0000000000019,25.001476070778228,-0.5012695675730522,-0.0050463565817118194
186.00000000000193,25.095800151416086,-0.4984034585576191,-0.007976573994173286
187.00000000000193,25.19019687719948,-0.4919114379378601,-0.010545389260864013
188.00000000000193,25.28517181245517,-0.4881417425557131,-0.014446488778696143
189.00000000000196,25.380000000000177,-0.48364000000000495,-0.015809889689923473
190.000000000002,25.47468656408076,-0.4796575595100123,-0.017469325738264985
191.000000000002,25.56824370881906,-0.47618416930578444,-0.01974937691116363
192.000000000002,25.662975603533095,-0.47111295183479396,-0.021000985158592833
193.00000000000202,25.757811001928275,-0.467858808759714,-0.023725265838590914
194.00000000000205,25.852432389315176,-0.4635077942463719,-0.024226870983211413
195.00000000000205,25.94719015476411,-0.45915136411510904,-0.027338864274377705
196.00000000000205,26.041929742475872,-0.4564908992075375,-0.030367928005192724
197.00000000000207,26.135874715032486,-0.4520838163790592,-0.03500134829590795
198.0000000000021,26.23186319880714,-0.4469879465592494,-0.03918375426632981
199.0000000000021,26.32599075738133,-0.444611225537666,-0.040735292638278686
200.0000000000021,26.41903673612571,-0.4401268673836703,-0.044557477935183165
201.00000000000213,26.51551589238034,-0.43703566282261,-0.047496126753576284
202.00000000000216,26.609804411184747,-0.4314725142809892,-0.05124556383906853
203.00000000000216,26.705024822990488,-0.4282860825402464,-0.05462834800065597
204.00000000000216,26.79943568848314,-0.4251771553222974,-0.058729855155135624
205.0000000000022,26.89450336355038,-0.42132884132153015,-0.06000079261157776
206.00000000000222,26.989250843581633,-0.4170394010592363,-0.06284176880172687
207.00000000000222,27.084015894655312,-0.4134347826973118,-0.06695561843569475
208.00000000000222,27.178681873729207,-0.4104465214026757,-0.07137413002257098
209.00000000000225,27.273328391543636,-0.4063619001253249,-0.07263932972544485
210.00000000000227,27.368065603084474,-0.4025149963318749,-0.07690868237094328
211.00000000000227,27.462903828122148,-0.39967259655816617,-0.08033702601004311
212.00000000000227,27.558361890585317,-0.3949762097908695,-0.08575437038618716
213.0000000000023,27.652663785297467,-0.3921141305423313,-0.08737829995057034
214.00000000000233,27.747297690559435,-0.39016104145812547,-0.09062490656359135
215.00000000000233,27.842578183442654,-0.38591223951521564,-0.097059586058581
216.00000000000233,27.936260288645144,-0.38202223545608716,-0.10044487641475008
217.00000000000236,28.030949865981913,-0.37805510890791894,-0.10308117630413394
218.0000000000024,28.125949552351692,-0.37439519207991984,-0.1065621516170463
219.0000000000024,28.221602851760867,-0.37167242050049837,-0.111132494847904
220.0000000000024,28.315698095532422,-0.36901650090569127,-0.11513897527490169
221.00000000000242,28.40906897061294,-0.3655568445556509,-0.1180372807466532
222.00000000000244,28.504298114746327,-0.3625407530178268,-0.1236417677349384
223.00000000000244,28.59970925238352,-0.3602807661481325,-0.1290798490729106
224.00000000000244,28.693809302097204,-0.35731595673925337,-0.13173711577760194
225.00000000000247,28.78823624610515,-0.3547589831371147,-0.13442067938983904
226.0000000000025,28.881620596982867,-0.3507452270696258,-0.13879316738150127
227.0000000000025,28.97966422969842,-0.3481384151991104,-0.1414864667845288
228.0000000000025,29.07345338458638,-0.3466279671997951,-0.14491217980657956
229.00000000000253,29.168587440808313,-0.34388058623844076,-0.14993862710033
230.00000000000256,29.264561680473502,-0.34150339519922895,-0.15123113880171246
231.00000000000256,29.357689044726595,-0.3392782504272764,-0.1547850407988305
232.00000000000256,29.45304788541033,-0.33544342640150143,-0.1582400271045139
233.0000000000026,29.547953453458017,-0.33346528464930314,-0.1610406224049039
234.00000000000261,29.642890602133967,-0.33081041578670783,-0.16402829934945995
235.00000000000261,29.738429033667437,-0.32854134212764335,-0.16874954279769216
236.00000000000261,29.829452793665602,-0.32507440707104496,-0.17060468685849406
237.00000000000264,29.928361490431023,-0.32214903483170704,-0.17492641395187114
238.00000000000267,30.023345780538257,-0.3208423205869255,-0.1775139684714362
239.00000000000267,30.118457587989738,-0.31675962705876226,-0.1814349108474098
240.00000000000267,30.211658127997413,-0.3138383472324305,-0.1814266450531683
241.0000000000027,30.307795216448007,-0.3114549345609913,-0.18432682638146725
242.00000000000273,30.403179248721788,-0.3077961792166797,-0.18829566276610388
243.00000000000273,30.495738120265024,-0.3059058645112898,-0.1897445252473826
244.00000000000273,30.594099379121197,-0.3024609781412406,-0.19380370738728026
245.00000000000276,30.686989615041274,-0.3007435226244282,-0.1963947646742148
246.00000000000279,30.784231532383554,-0.29553903925413316,-0.19902609753973222
247.00000000000279,30.87940767859235,-0.293257540453433,-0.2023510742675687
248.00000000000279,30.973701635504103,-0.29058695766839004,-0.20494138701860454
249.0000000000028,31.06943103954408,-0.2850299457194189,-0.20721158464058176
250.00000000000284,31.162856891920637,-0.2826761443081747,-0.20890934269125339
251.00000000000284,31.259349529117458,-0.2773206218798891,-0.2108732695857296
252.00000000000284,31.355976078621488,-0.2738131510511437,-0.21372080565555862
253.00000000000287,31.45077834003499,-0.26987924560325194,-0.21647652188802047
254.0000000000029,31.546157327274607,-0.26495314964149375,-0.22043057521772536
255.0000000000029,31.6418384544365,-0.26127914543736996,-0.22338383444774568
256.0000000000029,31.73682907560749,-0.25632975189970086,-0.22489174673524204
257.00000000000296,31.832639936977127,-0.2504398475458478,-0.22770253242909844
258.00000000000296,31.927932911612668,-0.24690919686365476,-0.23334282594042222
259.00000000000296,32.02130089209139,-0.24191728829106568,-0.2342639791839587
260.00000000000296,32.1185249983132,-0.23681601368176813,-0.23633626526354412
261.00000000000296,32.21387310362353,-0.231087860320439,-0.24056859488900306
262.000000000003,32.30905460389232,-0.22453560803036668,-0.24352423536718115
263.000000000003,32.40413347076068,-0.2185738487699967,-0.24766062919546394
264.000000000003,32.50045964351088,-0.21032904899860763,-0.2501164822016202
265.00000000000307,32.59557340506801,-0.20682996834563933,-0.25203973825693726
266.00000000000307,32.691183585831865,-0.19930554721073102,-0.25580014167725507
267.00000000000307,32.786629718138215,-0.19352221665303823,-0.2589133449883221
268.00000000000307,32.88384800438432,-0.18684297962646532,-0.26264869652397005
269.00000000000307,32.977467714014864,-0.17976752236725382,-0.26707279615858504
270.0000000000031,33.07325508679259,-0.17289821024039528,-0.27189736915314944
271.0000000000031,33.168304917783644,-0.16574508275039748,-0.2756047625164486
272.0000000000031,33.26503851363134,-0.15751536112218983,-0.27818101277593543
273.0000000000032,33.359829748321175,-0.14774028210790205,-0.2841158602026761
274.0000000000032,33.45616663123653,-0.13838483095196966,-0.2873569644175431
275.0000000000032,33.55099544303598,-0.131473259042852,-0.2932194082237918
276.0000000000032,33.64686521226993,-0.12120276039316258,-0.29664501940500276
277.0000000000032,33.74150553597553,-0.11166357019811603,-0.3051207946937584
278.00000000000324,33.83807070654437,-0.10027367610801438,-0.31174542449327536
279.00000000000324,33.93323150221131,-0.08934492365178945,-0.31640559827254044
280.00000000000324,34.02890411260764,-0.07930151101226166,-0.31812746556006744
281.0000000000033,34.125043154888424,-0.06865892860005025,-0.32432249027372384
282.0000000000033,34.21798454332622,-0.054722621394506385,-0.33084339088083103
283.0000000000033,34.31468874556844,-0.043866949145495326,-0.3385290826004459
284.0000000000033,34.40947169201841,-0.030972487318971353,-0.34618516727654836
285.0000000000033,34.50700009844893,-0.01803906574701313,-0.3517389136101672
286.00000000000335,34.59984440131546,-0.005300762884539105,-0.35888359765048916
287.00000000000335,34.69802391714801,0.009378609649978772,-0.36657348829986036
288.00000000000335,34.79359086503971,0.02506849991873383,-0.3776378231374169
289.0000000000034,34.889415671292845,0.03824428104104053,-0.3847346988507798
290.0000000000034,34.98459650928753,0.05488304236490385,-0.3938869955010027
291.0000000000034,35.080873604892275,0.07031591650431737,-0.4015115894403718
292.0000000000034,35.17549992868377,0.08654077770871717,-0.4104872996500015
293.0000000000034,35.27151745552353,0.10143006234490291,-0.4223277243768666
294.00000000000347,35.367390923852575,0.11740962138446843,-0.4333612280549364
295.00000000000347,35.46411437223648,0.13299405371643172,-0.4417240484557543
296.00000000000347,35.55960712849396,0.14878090946826447,-0.4540102679679503
297.0000000000035,35.65561006247282,0.16354231712749737,-0.4665059918015455
298.0000000000035,35.75164315807218,0.1801350580231645,-0.47909397588115743
299.0000000000035,35.84761522715689,0.19293248003817784,-0.49103405951310375
300.0000000000035,35.943504560328115,0.20721600558185918,-0.5052594285789289
301.0000000000035,36.03935459089986,0.22177582005633065,-0.517961723726224
302.0000000000036,36.13568109226237,0.23414992679909843,-0.532090118465903
303.0000000000036,36.2314443153778,0.24511087450317037,-0.5461112273667466
304.0000000000036,36.32740831603228,0.2575005736994093,-0.559499023516604
305.00000000000364,36.422679331680285,0.26787784296557327,-0.5751223004808752
306.00000000000364,36.519167163390875,0.27901919049335516,-0.5915256846478423
307.00000000000364,36.61555021613605,0.2861034470416715,-0.6083569224187029
308.00000000000364,36.711033185053246,0.29273257356817023,-0.6258786464426476
309.00000000000364,36.806871810099686,0.2990189419483908,-0.6418746981777614
310.0000000000037,36.90310879298516,0.30281131408346784,-0.6609003459366134
311.0000000000037,36.99901381806327,0.30641782024849273,-0.6793892394641254
312.0000000000037,37.09495967984889,0.30625012916961925,-0.7004506934644747
313.00000000000375,37.19128330632866,0.3028243040655713,-0.7190227118787624
314.00000000000375,37.287058243614254,0.2950082771282426,-0.740628565728735
315.00000000000375,37.3828848991347,0.2805703271349204,-0.7636452187030653
316.00000000000375,37.47862927554267,0.26210679775386914,-0.7844627265916277
317.00000000000375,37.575437686963646,0.2362161506317123,-0.8077511664874764
318.0000000000038,37.67058048579437,0.2061090429203304,-0.8336319771106737
319.0000000000038,37.767238097596824,0.16439209245379108,-0.8563874957395368
320.0000000000038,37.86257731611989,0.12039378135750854,-0.8807980162456559
321.00000000000387,37.9584358140005,0.06936705653267525,-0.9062794894138979
322.00000000000387,38.05472861970085,0.011996736584911124,-0.929114847287424
323.00000000000387,38.15019395022115,-0.04823676924869374,-0.9549402455958043
324.00000000000387,38.245909714549676,-0.10741583470127035,-0.9760791243835012
325.00000000000387,38.341473110249055,-0.16937740788416605,-0.9998812052696389
326.0000000000039,38.43745379467018,-0.22880062324096745,-1.022786096368058
327.0000000000039,38.53281153917407,-0.2851602382367046,-1.0476781105563115
328.0000000000039,38.628580446043514,-0.3355464916881139,-1.0686966686899444
329.000000000004,38.7235967198946,-0.38188845833777646,-1.0913451152803586
330.000000000004,38.8188983000872,-0.4224860686105255,-1.1093714732346927
331.000000000004,38.91544459103925,-0.45774815839753186,-1.1304036344635877
332.000000000004,39.00844635602785,-0.4861032528519775,-1.1479803562096857
333.000000000004,39.10526663785869,-0.5107150007788586,-1.165256272600113
334.00000000000404,39.20264648511503,-0.5277604721172081,-1.184666987536236
335.00000000000404,39.29845499417579,-0.5423894653556315,-1.2024941300622558
336.00000000000404,39.39379103137465,-0.5517563077053594,-1.2175484038745217
337.0000000000041,39.49010056286927,-0.5590526470348671,-1.2340867654678749
338.0000000000041,39.58539944711785,-0.5641220663661629,-1.2476844251408932
339.0000000000041,39.68175729960989,-0.5654740967481198,-1.2643787088687972
340.0000000000041,39.777412443963,-0.5671926256846358,-1.2772254209909546
341.0000000000041,39.872610161610766,-0.5660020891879916,-1.289608313898265
342.00000000000415,39.9709045578099,-0.5630070392784704,-1.3019026435487668
343.00000000000415,40.066717348492865,-0.5604496092027764,-1.3139578589941774
344.00000000000415,40.16283151128412,-0.557640672754093,-1.3272988961332204
345.0000000000042,40.25848084075387,-0.5527046861512844,-1.3390685511187237
346.0000000000042,40.355420126004205,-0.5465492067292066,-1.350561746055332
347.0000000000042,40.45139664390923,-0.5433067374639775,-1.3604414328740302
348.0000000000042,40.547312555421755,-0.5388776588440529,-1.3700556713167682
349.0000000000042,40.645209185699805,-0.5346865064798366,-1.3794720912114102
350.00000000000426,40.741824900001326,-0.5285045770858052,-1.3880898449022854
351.00000000000426,40.83774187782013,-0.5223117058677456,-1.3992230097099743
352.00000000000426,40.93483659353808,-0.5170748712605303,-1.4078275008215888
353.0000000000043,41.03196730161459,-0.5103441153177584,-1.4178655311159738
354.0000000000043,41.12840160673566,-0.5074055118971971,-1.4249643811561983
355.0000000000043,41.22546395721508,-0.5022098833196093,-1.4360922738180513
356.0000000000043,41.32278731364034,-0.4975118516323537,-1.4437847483953203
357.0000000000043,41.418922909734825,-0.49318794021060197,-1.4518293746440074
358.0000000000044,41.516631163549405,-0.48858196025657347,-1.4609900046445103
359.0000000000044,41.61329571260168,-0.48422539988704955,-1.4697770796697518
360.0000000000044,41.71020753249159,-0.47978896210936905,-1.4778239998364175
361.00000000000443,41.807319163388314,-0.4757998720007607,-1.4812122011543107
362.00000000000443,41.904004083522324,-0.4731147361167894,-1.4909777170682714
363.00000000000443,42.00147055387044,-0.46843657047897985,-1.505716425414394
364.00000000000443,42.098824943591055,-0.46763568818796175,-1.5116511800653623
365.00000000000443,42.19548764054492,-0.4658692173447473,-1.5203465622069157
366.0000000000045,42.29281629580282,-0.46240621165640317,-1.527652225044922
367.0000000000045,42.389709141535114,-0.46146505266896226,-1.5348433220312865
368.0000000000045,42.48692421286604,-0.45960291591589303,-1.5440987328699185
369.00000000000455,42.583748643227175,-0.45854461828985277,-1.5506157748135245
370.00000000000455,42.68038404884726,-0.4562742360668419,-1.5588424402896202
371.00000000000455,42.778305464513274,-0.45406187626765504,-1.5665702092562235
372.00000000000455,42.875366374649964,-0.45296897509575534,-1.576837035457253
373.00000000000455,42.97219753512665,-0.4506659796278169,-1.5821448524700163
374.0000000000046,43.06861384515393,-0.45154234523427317,-1.5913665582010643
375.0000000000046,43.16394952050436,-0.4492595206484881,-1.6017797118034758
376.0000000000046,43.26328532614704,-0.4484418191979121,-1.6122404751260055
377.00000000000466,43.35989840165085,-0.4482770600180082,-1.618406198860892
378.00000000000466,43.45653080815018,-0.44719748387741365,-1.6271058041114266
379.00000000000466,43.5536261595179,-0.4471399351371057,-1.634537137868632
380.00000000000466,43.64907645138568,-0.4470468102510956,-1.6403974069877658
381.00000000000466,43.748487454626556,-0.4461928451417373,-1.6492281686435248
382.0000000000047,43.844350968614705,-0.4461626038202429,-1.6578912591355848
383.0000000000047,43.942363667888195,-0.4443150762117322,-1.666942039914812
384.0000000000047,44.03989749196196,-0.4454282965507347,-1.6754975295769872
385.0000000000048,44.13606408256482,-0.44528490258004233,-1.6826519058924698
386.0000000000048,44.23175509785568,-0.44412282750318266,-1.6897226778986711
387.0000000000048,44.33113599118728,-0.44154428186071476,-1.6976831758174833
388.0000000000048,44.428478545054546,-0.4419315038640652,-1.7068976620053329
389.0000000000048,44.52476820148884,-0.44077154701183285,-1.7133388788423112
390.00000000000483,44.62250913424543,-0.43834295807471746,-1.7213542880126647
391.00000000000483,44.7190970360779,-0.4366399281631943,-1.7304282532217368
392.00000000000483,44.81673261453788,-0.4330537237288992,-1.7382639279750633
393.0000000000049,44.91442288082184,-0.43266304608067996,-1.7451526210315862
394.0000000000049,45.01153426366985,-0.4290376941140448,-1.7534966149152673
395.0000000000049,45.10937586033983,-0.426453752055393,-1.7615116164038889
396.0000000000049,45.207449358784864,-0.424302903352664,-1.7710246568363184
397.0000000000049,45.30347993116747,-0.41965114034598155,-1.7790724881344304
398.00000000000495,45.397765805649456,-0.4179756448360874,-1.7866014829815473
399.00000000000495,45.499204005295326,-0.4148265407610794,-1.7939545930596448
400.00000000000495,45.59591481390092,-0.4120802170399161,-1.8016769403391972
401.000000000005,45.69383284965758,-0.40930744007204095,-1.8090073960169546
402.000000000005,45.79118046030205,-0.4063015447441305,-1.8148364581626844
403.000000000005,45.88932530790277,-0.40236143434419996,-1.8226572479509855
404.000000000005,45.98602388502198,-0.40182189852763234,-1.8323456621402179
405.000000000005,46.082736274169314,-0.39916694355023374,-1.8388402118180132
406.00000000000506,46.181567005073056,-0.39874924147497515,-1.8462848029000751
407.00000000000506,46.27808922985247,-0.39574767274365436,-1.8540104654458824
408.00000000000506,46.375688435312874,-0.3940076371573359,-1.861548586891523
409.0000000000051,46.472568882272,-0.3917089061047773,-1.8691604799342123
410.0000000000051,46.570286446780415,-0.38874323089921575,-1.8749876611520144
411.0000000000051,46.66888398945917,-0.3893235337564613,-1.8809475693691518
412.0000000000051,46.76562251591877,-0.38878492896636213,-1.889682518832482
413.0000000000051,46.86284069867295,-0.3857107620700805,-1.8950303853984116
414.0000000000052,46.96076065720516,-0.385500145776723,-1.9035380991470499
415.0000000000052,47.05769513191832,-0.38349774630347216,-1.9159564768468549
416.0000000000052,47.1555686961617,-0.3827380611791854,-1.921461687339555
417.00000000000523,47.25295645127544,-0.3796678135063437,-1.927546807518374
418.00000000000523,47.34924902134989,-0.3778554364436361,-1.9332443440703364
419.00000000000523,47.44879848321802,-0.3770425341394394,-1.941184196725465
420.00000000000523,47.545491547973356,-0.3742683885313256,-1.9493861176504614
421.00000000000523,47.64404896229733,-0.37599999582868887,-1.9547087364550468
422.0000000000053,47.74084340927934,-0.3722268137981226,-1.9612230701598286
423.0000000000053,47.838102266644306,-0.3717942519378308,-1.9684110558473895
424.0000000000053,47.93642487492222,-0.36935508738899725,-1.9754722649837593
425.00000000000534,48.03471008658433,-0.36843055746354203,-1.9812320605648739
426.00000000000534,48.132902191268364,-0.36738704588974425,-1.986835206513951
427.00000000000534,48.22954137658376,-0.36580359468589274,-1.9935248014615166
428.00000000000534,48.32776420587814,-0.3637253086066724,-2.001357074638628
429.00000000000534,48.42577453605337,-0.36161800898363794,-2.0096088471791957
430.0000000000054,48.52429872894061,-0.35904258005327744,-2.0183326418721426
431.0000000000054,48.62153282215688,-0.35791212233535447,-2.025112475143179
432.0000000000054,48.719162675622236,-0.35633991278266586,-2.030933273151985
433.00000000000546,48.8181962041297,-0.3526908653917884,-2.0353690954143273
434.00000000000546,48.91665738837205,-0.3526569303402987,-2.04179249823929
435.00000000000546,49.01179163093572,-0.35131378278628717,-2.047909646097536
436.00000000000546,49.11246310508246,-0.3481951440258784,-2.052619513054154
437.00000000000546,49.209801734859425,-0.3464904210631308,-2.058534042822675
438.0000000000055,49.30789931067752,-0.34380792781558367,-2.0636607898934516
439.0000000000055,49.4066442877981,-0.3419980398773734,-2.070424211365488
440.0000000000055,49.50389650840772,-0.3411681239070306,-2.076357527485067
441.00000000000557,49.599885115727375,-0.33776458111295515,-2.0824560900459614
442.00000000000557,49.699136433498005,-0.3347267580526466,-2.088386032529623
443.00000000000557,49.795418959067376,-0.33391662270086864,-2.094984930495641
444.00000000000557,49.896410601750176,-0.33022267330899835,-2.101905278928284
445.00000000000557,49.994443525864845,-0.32830876954426297,-2.1100875221233166
446.0000000000056,50.09273004366112,-0.32769779507059854,-2.115061898198017
447.0000000000056,50.18981195564714,-0.32619794695083815,-2.1214395726686774
448.0000000000056,50.287471293917605,-0.32422199273676755,-2.127965749607113
449.0000000000057,50.386015381186134,-0.3218356405126421,-2.1341120250658108
450.0000000000057,50.484662024935794,-0.32004627514197653,-2.1410705454229224
451.0000000000057,50.58182092661626,-0.31717354282649235,-2.1471825727118596
452.0000000000057,50.681314718630006,-0.31660711163577765,-2.15520550562127
453.0000000000057,50.77829222095857,-0.3162638608949859,-2.1611155246154494
454.00000000000574,50.876902242775984,-0.31475719863091384,-2.1652907523593647
455.00000000000574,50.973533033819756,-0.31239464350913493,-2.173385418236582
456.00000000000574,51.07265412367312,-0.3110964693309291,-2.1811665674688654
457.0000000000058,51.17123423251668,-0.3116476642323265,-2.187427285367213
458.0000000000058,51.26914805070264,-0.3098671646153234,-2.195249460109877
459.0000000000058,51.367997137895074,-0.3082677277209261,-2.2038148602706378
460.0000000000058,51.46592183678581,-0.3080857760457002,-2.2106386866873415
461.0000000000058,51.56445655824213,-0.3062170393866643,-2.21554338831327
462.00000000000585,51.662826352279865,-0.3064596288134884,-2.2199863008999063
463.00000000000585,51.76086623293418,-0.3041009238898664,-2.2259465017793163
464.00000000000585,51.85917444483732,-0.3039550384268728,-2.233689378321625
465.0000000000059,51.95745200507088,-0.30405811911257685,-2.240102530188058
466.0000000000059,52.05537381634166,-0.30396586848555973,-2.2479328396661953
467.0000000000059,52.154168648929186,-0.3027486025109391,-2.2544560596404524
468.0000000000059,52.251854665407556,-0.3024225332139887,-2.2614595651831726
469.0000000000059,52.351528995572366,-0.3018341926680875,-2.2698109497957875
470.00000000000597,52.448844378171785,-0.3007380456024143,-2.27679154111271
471.00000000000597,52.54723576470678,-0.30113430735552427,-2.2826590563389857
472.00000000000597,52.64563020240629,-0.3016593810318522,-2.290806380204109
473.000000000006,52.74443037063658,-0.30298280122263305,-2.2963312052150258
474.000000000006,52.84171137737026,-0.3021271553373285,-2.30485024698783
475.000000000006,52.94020554220689,-0.3003820857909663,-2.3091936254401055
476.000000000006,53.03870040605941,-0.30245028988195416,-2.315042473531464
477.000000000006,53.1365211295845,-0.3018193998048998,-2.322056862000279
478.0000000000061,53.23556148933404,-0.3002908308398428,-2.3281518241619796
479.0000000000061,53.333887362449815,-0.30058661371073525,-2.334121098533908
480.0000000000061,53.431886790438305,-0.3010783072807896,-2.342197954322799
481.00000000000614,53.530284715643525,-0.2999050392710278,-2.347731782000446
482.00000000000614,53.6290569121262,-0.3008265337321126,-2.354094473205416
483.00000000000614,53.72712925039261,-0.2995950766455728,-2.3612950676793947
484.00000000000614,53.82547855419449,-0.2988837091577174,-2.3681017628503542
485.00000000000614,53.9237570378386,-0.3005068077821253,-2.373890432262785
486.0000000000062,54.02231574977531,-0.3009731298182332,-2.379375417435383
487.0000000000062,54.12093706739518,-0.3005672817312945,-2.3826307869954118
488.0000000000062,54.22027641366043,-0.3003353083535616,-2.390196219572973
489.00000000000625,54.318530841433244,-0.2975682615634907,-2.395786667399083
490.00000000000625,54.41706545935232,-0.2993749217230592,-2.4013842239704575
491.00000000000625,54.515786571737,-0.29902851210930664,-2.4053442555439934
492.00000000000625,54.61436736164766,-0.29852447517036634,-2.4099639762048506
493.00000000000625,54.71360637370503,-0.29832712300921194,-2.4151044546799407
494.0000000000063,54.81229714944284,-0.298428700376702,-2.4187520281277544
495.0000000000063,54.91129017371189,-0.2988140146482091,-2.4255647566722174
496.0000000000063,55.01107243627292,-0.296443087212737,-2.4323275512810616
497.00000000000637,55.10849851125787,-0.2965850141820377,-2.4356810775919495
498.00000000000637,55.20758328567729,-0.2971953275880708,-2.4384411532372496
499.00000000000637,55.30689517835621,-0.29672664148339273,-2.4452906601533977
500.00000000000637,55.40543025053177,-0.29499016234277936,-2.451069743161538
501.00000000000637,55.50354659875905,-0.29569247598656107,-2.455921152743183
502.0000000000064,55.604251721892915,-0.29326754277560246,-2.4586193714052973
503.0000000000064,55.7021985702817,-0.2930292551386751,-2.4628951712347416
504.0000000000064,55.801474598642315,-0.2919720608787941,-2.4678871825051134
505.0000000000065,55.90081570677545,-0.2900319556008561,-2.470826356831505
506.0000000000065,56.000105241279755,-0.2895946478700155,-2.475609435749336
507.0000000000065,56.098403126288005,-0.28847504676005226,-2.479066321313398
508.0000000000065,56.197047374545726,-0.28832660529894927,-2.4802359521545547
509.0000000000065,56.29609599916196,-0.2879079006353437,-2.483696490209685
510.00000000000654,56.3954228896046,-0.2877184921760208,-2.4855333430972055
511.00000000000654,56.494964122950556,-0.2861684504645731,-2.4892993220060813
512.0000000000066,56.59366474628892,-0.28476751056397426,-2.4967602558737507
513.0000000000066,56.69320582147777,-0.2841646693822361,-2.5026674147642636
514.0000000000066,56.791853347441744,-0.2836535131734864,-2.506408268741505
515.0000000000066,56.89193076557022,-0.2826268221639806,-2.5081671667137453
516.0000000000066,56.99011749729523,-0.28322552000027773,-2.510008835170325
517.0000000000066,57.08937072767076,-0.283907752699291,-2.5089378026134646
518.0000000000066,57.18826863643825,-0.28128675108264767,-2.5138113670999065
519.0000000000066,57.287518246823815,-0.2812844127389986,-2.517987093904352
520.0000000000066,57.38696670228095,-0.28103958168796694,-2.5261659247893045
521.0000000000067,57.486168713170784,-0.28053438082435317,-2.530133247480816
522.0000000000067,57.58595108067903,-0.27885832369262176,-2.5312811159950477
523.0000000000067,57.684269395530656,-0.27935301658172035,-2.536421904314814
524.0000000000067,57.78394026948337,-0.27858115196987115,-2.541796736145528
525.0000000000067,57.883754592926906,-0.27855866262241097,-2.544288314593621
526.0000000000068,57.982136388426945,-0.27867163529634476,-2.5434459854688827
527.0000000000068,58.081532918481564,-0.2779329762081159,-2.544220662898464
528.0000000000068,58.18061115546596,-0.2775475676731758,-2.5486723248013594
529.0000000000068,58.28029034964241,-0.27670549037576225,-2.5527778488505763
530.0000000000068,58.37862663108537,-0.27624516049771014,-2.5542279467415034
531.0000000000068,58.47862902254991,-0.27534268095785736,-2.557471007186618
532.0000000000068,58.576260326190436,-0.2749693034816456,-2.561615442910184
533.0000000000068,58.67612950939567,-0.2759460945646309,-2.5630274970221034
534.0000000000068,58.775248859686286,-0.27401451817377503,-2.5660406808007656
535.0000000000068,58.874702759062366,-0.27520435760428963,-2.569832859605677
536.0000000000068,58.97413402018177,-0.2739776261045682,-2.5717712843374665
537.0000000000069,59.073756060088485,-0.27428672373988383,-2.5763963378546775
538.0000000000069,59.17185363816792,-0.27336388544176665,-2.578909073187556
539.0000000000069,59.27071064429197,-0.273301494527686,-2.5822740494949614
540.0000000000069,59.37050478941419,-0.2724022887771639,-2.585321166838942
541.0000000000069,59.469413557504794,-0.27321273853251293,-2.587534499210247
542.000000000007,59.568045532765304,-0.27338703947667814,-2.5917118442166114
543.000000000007,59.66751894424984,-0.27201686556294336,-2.5953833200335055
544.000000000007,59.7662989249405,-0.2714104174574027,-2.598176147633817
545.000000000007,59.86548712073102,-0.27237964774110335,-2.6009289330988032
546.000000000007,59.96501694472639,-0.27180254108987356,-2.603655368780551
547.000000000007,60.063746661463945,-0.27162399649445224,-2.6063891876955947
548.000000000007,60.16171026936975,-0.27129411488488625,-2.60766089855362
549.000000000007,60.26218454868348,-0.2719480819855677,-2.6111653655040445
550.000000000007,60.362022926513696,-0.2714450927359469,-2.6147707283487827
551.000000000007,60.46042443651293,-0.2709456913608562,-2.617543801485562
552.000000000007,60.560293197003865,-0.27032747932167406,-2.6205193823120627
553.0000000000072,60.659504020221846,-0.2719928659222197,-2.623878020094904
554.0000000000072,60.759012830760966,-0.27114046454259505,-2.628725816286395
555.0000000000072,60.857644493250994,-0.2716083417457063,-2.6299036900430073
556.0000000000072,60.95713318955984,-0.2708727369571909,-2.634180893386902
557.0000000000072,61.056570161351445,-0.27050201172746713,-2.638392995863312
558.0000000000073,61.155188470763164,-0.27046322844714027,-2.640226966325025
559.0000000000073,61.254840691741876,-0.2700262070055112,-2.6429088318907468
560.0000000000073,61.35408576551445,-0.2695595887381841,-2.646687012616531
561.0000000000073,61.45235375185119,-0.26979337481604104,-2.6491469372653715
562.0000000000073,61.55106889445134,-0.2714018783363523,-2.650369015268661
563.0000000000073,61.6508313851338,-0.2708839691932004,-2.653129165886466
564.0000000000073,61.75205082823808,-0.27041988088958113,-2.6559148292930472
565.0000000000073,61.852049699277735,-0.2700117131845801,-2.6587237272312825
566.0000000000073,61.95091745323237,-0.2694566761333809,-2.6602580497593005
567.0000000000073,62.050384475032835,-0.2683272197734471,-2.664418281755123
568.0000000000074,62.14926631851349,-0.2695775104683542,-2.667134650092142
569.0000000000074,62.24972424606992,-0.26891256572092315,-2.672194095224653
570.0000000000074,62.34799692578867,-0.2680629616243397,-2.6743272927372796
571.0000000000074,62.44890367156661,-0.2681481387613761,-2.6764256085082145
572.0000000000074,62.54874810122014,-0.26813290795623157,-2.676522719174681
573.0000000000074,62.64823400916285,-0.2680778088127198,-2.679190157547312
574.0000000000074,62.74813405618495,-0.26653104819186413,-2.683214307648055
575.0000000000075,62.84647375913714,-0.2670235515302912,-2.685716225601136
576.0000000000075,62.94687942924671,-0.26592697603502874,-2.687762794463837
577.0000000000075,63.04630147969967,-0.2648863501019105,-2.69055610829406
578.0000000000075,63.145235029178224,-0.2663025563726331,-2.6958013682255233
579.0000000000075,63.24528714802513,-0.2649079443236031,-2.697556728341328
580.0000000000075,63.342164610769636,-0.2637769324640434,-2.6990942266983224
581.0000000000075,63.44431036550604,-0.2635320871277626,-2.70192971680914
582.0000000000075,63.54389372630253,-0.2622153672433852,-2.7055211435397206
583.0000000000075,63.64258779748196,-0.2611043278062221,-2.7074000220307886
584.0000000000076,63.742049730078286,-0.2600645763095592,-2.708676039792949
585.0000000000076,63.8405130308635,-0.2593794880325051,-2.7113388393300966
586.0000000000076,63.94058644890395,-0.2570854389407669,-2.714260255761093
587.0000000000076,64.03980829218362,-0.2576401048693048,-2.7155860617057055
588.0000000000076,64.13918632497719,-0.254642729722096,-2.7195391731937386
589.0000000000076,64.23816861815922,-0.2541799074498712,-2.7208684357391038
590.0000000000076,64.3360682466636,-0.2540328435492971,-2.7220948654418144
591.0000000000077,64.43729068685158,-0.2514620704597199,-2.7249087777994694
592.0000000000077,64.5368001101106,-0.2509159661340837,-2.728858798150511
593.0000000000077,64.6358527895022,-0.2497015473763894,-2.7302090155302907
594.0000000000077,64.73560697186099,-0.24786141417140756,-2.7329375684891484
595.0000000000077,64.83477645275993,-0.2485181310300216,-2.734277572422321
596.0000000000077,64.9352210657622,-0.2489109003409138,-2.7344894888709392
597.0000000000077,65.03497228942139,-0.24761085453523038,-2.736847017076591
598.0000000000077,65.13449620750684,-0.2475074691953291,-2.7381988923780467
599.0000000000077,65.23468617140784,-0.24510010279888086,-2.739546746546594
600.0000000000078,65.33549500409048,-0.2435576271312573,-2.741817877332164
601.0000000000078,65.43472327408566,-0.2405793091352755,-2.7424567402477735
602.0000000000078,65.53369922095371,-0.2390360349668965,-2.743920285814455
603.0000000000078,65.63430937646521,-0.2375759287698066,-2.7452305761949862
604.0000000000078,65.73332104574474,-0.237053021595739,-2.7479967216782413
605.0000000000078,65.8330139305735,-0.235231414501064,-2.7505018054795025
606.0000000000078,65.93407405881767,-0.23570324674984044,-2.751998398608783
607.000000000008,66.03402831809606,-0.23423415915163617,-2.7532578122251343
608.000000000008,66.13348080581974,-0.23293803535092378,-2.754483464731746
609.000000000008,66.23306842922004,-0.23097512423932157,-2.7543640478034366
610.000000000008,66.33288890039528,-0.22956538432157814,-2.757152149629857
611.000000000008,66.4337615869522,-0.2285235503729642,-2.759709922080189
612.000000000008,66.53299774904072,-0.22715650028138215,-2.761074841390985
613.000000000008,66.63260140885113,-0.2289101087702806,-2.7632417421375477
614.000000000008,66.732201840765,-0.22549841033326104,-2.763700612649642
615.000000000008,66.83233965902976,-0.22275946715060657,-2.7662180214184833
616.0000000000081,66.93087101848278,-0.22331826694625612,-2.76507628518687
617.0000000000081,67.03044921555909,-0.22079035249126402,-2.7698318626426057
618.0000000000081,67.13079417705846,-0.22034221927368625,-2.7698100044727703
619.0000000000081,67.23000000000083,-0.22277999999995263,-2.769383272920303
620.0000000000081,67.3300000000008,-0.22061999999994703,-2.768500477597449
621.0000000000081,67.4289529353964,-0.22015461295941893,-2.7697632374367327
622.0000000000081,67.5280979818888,-0.21968972229945255,-2.7703615161207233
623.0000000000082,67.62733748513003,-0.21853085078464574,-2.7723467939921056
624.0000000000082,67.72766656999343,-0.21700143929102989,-2.7740698489406954
625.0000000000082,67.82781900844947,-0.21448082590373055,-2.775310371076329
626.0000000000082,67.92587880708474,-0.21305410153594495,-2.7740000256767217
627.0000000000082,68.02716244069846,-0.21206020421015714,-2.77666693404698
628.0000000000082,68.12626622590476,-0.20967592625149695,-2.7779904267679227
629.0000000000082,68.22588399333775,-0.2087841231213672,-2.776558271729195
630.0000000000082,68.3252604877169,-0.2081171388538224,-2.777919148506018
631.0000000000082,68.42442906758816,-0.20603534298662649,-2.7793829218959805
632.0000000000083,68.5249922324374,-0.20476438367152736,-2.7767036161165586
633.0000000000083,68.62454954563354,-0.20311087352131715,-2.779372387023657
634.0000000000083,68.7236783955293,-0.20252040578925426,-2.7805816231649856
635.0000000000083,68.82418006795909,-0.20013417075361736,-2.7818987505966
636.0000000000083,68.92355273502483,-0.19994858681710434,-2.7838805527734904
637.0000000000083,69.02254504576261,-0.1990212090496831,-2.784526639735684
638.0000000000083,69.12283374150694,-0.19736993039414064,-2.7866174678707454
639.0000000000084,69.22204527294735,-0.19511899930417018,-2.7865093748746896
640.0000000000084,69.32205885805986,-0.19243354165813828,-2.7865292561831994
641.0000000000084,69.42041532287939,-0.19258926201267837,-2.787724220644857
642.0000000000084,69.52083019335446,-0.19197798325731882,-2.78683966680851
643.0000000000084,69.61960126403254,-0.1908448369212608,-2.7868431531187667
644.0000000000084,69.72000000000085,-0.18760000000007637,-2.790757127098412
645.0000000000084,69.8187013724548,-0.1864015324631802,-2.7921096027883103
646.0000000000084,69.91972314140037,-0.1858354064562499,-2.791100471122988