File: 01_Data/Polyisocyanurate_Foam_Board/STA/N2/10K_min/Polyisocyanurate_Foam_Board_STA_N2_10KData_221018_R1.csv
##Temp./Â°C,Time/min,DSC/(mW/mg),Mass loss/mg
51.0,10.701895228330441,-1.6502264919094167,0.016853836651715248
52.100000000000016,11.1043038275499,-1.524192928365223,0.014793122329376907
53.20000000000003,11.357349497866512,-1.4439191652231855,0.01926397991790285
54.30000000000005,11.568495872453147,-1.3818119108793179,0.015853523142395076
55.40000000000006,11.752640444845136,-1.3361690551442058,0.017598343596744392
56.50000000000008,11.924115198820285,-1.2965681297398877,0.015710635674778928
57.600000000000094,12.089076795610806,-1.263595758634893,0.01533566880677828
58.70000000000011,12.245333735932354,-1.237876884800412,0.016313796555260218
59.800000000000125,12.396042048508617,-1.2166104025385334,0.017368899411213334
60.90000000000014,12.541643033426338,-1.1953355073996743,0.017377909975609285
62.000000000000156,12.684483004112614,-1.177434602238429,0.016540267997168456
63.10000000000017,12.824235555004279,-1.1598846230679316,0.01576692585487649
64.20000000000019,12.960293798055817,-1.1444985596888837,0.017170846703394638
65.30000000000021,13.096150814586291,-1.1313143104777812,0.017326838544051704
66.40000000000022,13.230108665959513,-1.1168079708600513,0.0169108684277548
67.50000000000023,13.360310850361767,-1.1032978544518086,0.01691019899178059
68.60000000000025,13.491409438052191,-1.0910340324660475,0.015393436680998462
69.70000000000027,13.620289560049521,-1.0785214184976204,0.016919245008972794
70.80000000000028,13.745521309958509,-1.0680291931208243,0.017042760141843694
71.90000000000029,13.872436030467105,-1.0564197386260865,0.016878048956033176
73.00000000000031,13.997080754766912,-1.0461355116378541,0.016741713204332598
74.10000000000034,14.120119596828099,-1.0376737029395362,0.016909924504814988
75.20000000000034,14.24378015925864,-1.0266374177853843,0.018116569485568057
76.30000000000035,14.366284453153819,-1.0170890316028338,0.015522294370158285
77.40000000000038,14.485893490310856,-1.0085014872800515,0.018238440744558382
78.5000000000004,14.605478570030945,-0.9998813095133005,0.01791472180949505
79.6000000000004,14.724692183501576,-0.9913834077899348,0.017140454319473974
80.70000000000041,14.842960584732865,-0.9821702665519998,0.01692207942194468
81.80000000000044,14.96102971849502,-0.9754920736777195,0.018237617192468747
82.90000000000046,15.077578714803812,-0.9680397232416206,0.017249145281990508
84.00000000000047,15.194030452267793,-0.9624466983675545,0.018426565773302706
85.10000000000048,15.307496239445813,-0.9554745884836202,0.018198497503345124
86.2000000000005,15.423549532900678,-0.9498050428127446,0.01648423694836687
87.30000000000052,15.539503194544208,-0.942671730309488,0.01823670769989505
88.40000000000053,15.653229345179389,-0.9354171107859257,0.01817901124154009
89.50000000000054,15.767353068154382,-0.9298845077412439,0.017938685447600022
90.60000000000056,15.880000000000049,-0.9232599999999976,0.013183396956387483
91.70000000000059,15.992297529251418,-0.9160743524803883,0.015498776873981157
92.8000000000006,16.104575705083708,-0.9105703568050264,0.018212601910964743
93.9000000000006,16.217221573234095,-0.9043649506171151,0.018119833024795362
95.00000000000063,16.32771241697823,-0.8985625108564456,0.019547615833481302
96.10000000000065,16.43773316252103,-0.8927630856742257,0.021624085369498225
97.20000000000066,16.548079824623823,-0.8859309482864401,0.0225921237832738
98.30000000000067,16.65931180934863,-0.8789490050521597,0.02130293482525847
99.40000000000069,16.767509103833177,-0.8739630367030298,0.020984835974109828
100.50000000000071,16.877474954566072,-0.8660076416067739,0.018767183367358165
101.60000000000072,16.98658854648563,-0.8609480417836475,0.017759458769088354
102.70000000000073,17.09634168889011,-0.8541222535514532,0.020430041251783493
103.80000000000075,17.203986941715584,-0.8490326567820166,0.01857740282211484
104.90000000000077,17.312567441814345,-0.8436336290565051,0.018155865995308496
106.00000000000078,17.42126651138086,-0.8380306229779599,0.01944002121031918
107.10000000000079,17.529829931506676,-0.8316844023371286,0.020617846210827295
108.20000000000081,17.636724469542347,-0.8272001754988294,0.0190873925100572
109.30000000000084,17.74715087449543,-0.8218091245962611,0.01811958895077037
110.40000000000084,17.855738483855454,-0.8163357390523528,0.016226329298739905
111.50000000000085,17.963307688188515,-0.8098195167662517,0.019652446229786236
112.60000000000088,18.07162802267793,-0.8034107818669862,0.021031437671137354
113.7000000000009,18.177461600715628,-0.7984108487455096,0.018839776522736607
114.8000000000009,18.285520083464036,-0.7933678963405315,0.018263386288530192
115.90000000000092,18.392461331099266,-0.7867679702475995,0.019653899462579894
117.00000000000094,18.500709131842616,-0.7815459003709713,0.018339935725989243
118.10000000000096,18.607156554339443,-0.7758658631451655,0.02007777625178786
119.20000000000097,18.715177664702995,-0.7702788438123092,0.019276154155890346
120.30000000000098,18.821228827999896,-0.7647044656869018,0.020310039846384242
121.400000000001,18.92935175043381,-0.7597120488696774,0.02158863717100079
122.50000000000102,19.034894664608707,-0.7551339749754856,0.020321232288764257
123.60000000000103,19.14309791394708,-0.7503872625708021,0.020262761466855572
124.70000000000104,19.249476081029965,-0.7461174296469947,0.01897951306047574
125.80000000000106,19.35574832942915,-0.7414219917177359,0.019944632911599314
126.90000000000109,19.462802618070395,-0.7368826407234382,0.01900000519076528
128.00000000000108,19.568823354004792,-0.7320611717281414,0.018494051455011373
129.1000000000011,19.67620289239503,-0.726196608319631,0.01893749908139064
130.20000000000113,19.782120475240852,-0.7228772811657952,0.01767990339414638
131.30000000000115,19.887493656892353,-0.7190098780156633,0.017679251549257202
132.40000000000117,19.99398645556387,-0.714132165073938,0.017487993274977853
133.50000000000117,20.10090710306397,-0.7099513760453355,0.016370157291396126
134.6000000000012,20.2060658827068,-0.7056760315397963,0.014890721696525944
135.7000000000012,20.31331303692979,-0.7006321533596047,0.017223542721971796
136.8000000000012,20.41843941043662,-0.6964077316099935,0.01724011885888377
137.90000000000123,20.523766429138167,-0.6922166692348517,0.01817030176804213
139.00000000000125,20.629900762704935,-0.6876397877810587,0.01719446311038375
140.10000000000127,20.73424485218017,-0.6830268474302919,0.018180808720165587
141.2000000000013,20.83952000409539,-0.6804367815622996,0.017009754206898542
142.3000000000013,20.944388938884558,-0.6751220025977517,0.015700174004116718
143.4000000000013,21.050791428693163,-0.6717200594201601,0.016687065913534305
144.50000000000134,21.156426046334836,-0.666555984341663,0.01635863621077327
145.60000000000133,21.259743169707185,-0.6618082632492596,0.015709976657140245
146.70000000000135,21.365667487572804,-0.6587940323885728,0.01439034658926186
147.80000000000138,21.470748090054887,-0.655362980689372,0.014721695158499415
148.9000000000014,21.572013588699264,-0.6536091866215111,0.016040433882921867
150.00000000000142,21.680409630333568,-0.6490990525290055,0.014720003642636037
151.10000000000142,21.783332681672782,-0.6445690599568163,0.015582788396461211
152.20000000000144,21.888566213743935,-0.6410576676072824,0.013400008869314028
153.30000000000146,21.99296914746532,-0.6376594703646141,0.013399954999910868
154.40000000000146,22.097666903877375,-0.6333995295158159,0.013399956909765365
155.50000000000148,22.202734001133646,-0.6300779272726835,0.012095596220920157
156.6000000000015,22.307501333559483,-0.6259529393858491,0.012119490374269404
157.70000000000152,22.411734900881985,-0.6227930198681977,0.013391706815370163
158.80000000000155,22.514212411690742,-0.6175774511201099,0.010153769230989873
159.90000000000154,22.621191454750907,-0.6126034242861749,0.013294106280528517
161.00000000000156,22.725080009266428,-0.608501616177057,0.013280449410457251
162.1000000000016,22.8297903676327,-0.603937843706001,0.010659619400541942
163.20000000000158,22.93111407134843,-0.598840171339697,0.009340935009459095
164.3000000000016,23.03818109966253,-0.5952277384585632,0.00803030827990181
165.40000000000163,23.142906712706203,-0.5897803752916657,0.00538808967227844
166.50000000000165,23.2467780895772,-0.5876497044642586,0.005394274321889547
167.60000000000167,23.35177830821248,-0.5801022410973082,0.004423882100894616
168.70000000000167,23.455956569432182,-0.576060214162644,0.0030801692760986654
169.8000000000017,23.561587652160693,-0.5716631323168833,0.003079531997819629
170.9000000000017,23.665603518087025,-0.5675763253968837,-3.109313880766962e-05
172.0000000000017,23.769305960991627,-0.5614361542234454,-0.0012001259909775186
173.10000000000173,23.874673288990607,-0.5581954850526085,-0.0011976027777427234
174.20000000000175,23.977706532949917,-0.552309737766602,-0.0025098635915759004
175.30000000000177,24.082285619801837,-0.5474423057187079,-0.00349871318629269
176.4000000000018,24.187134240026126,-0.5432297122489097,-0.005150920815279569
177.5000000000018,24.29191920186919,-0.5377975639556087,-0.006479477779906873
178.6000000000018,24.396419990318254,-0.5324899640280615,-0.009470639941442371
179.70000000000184,24.500821455684857,-0.5276251820963971,-0.012141713462074932
180.80000000000183,24.605491301114736,-0.5235333658953553,-0.012731167590136039
181.90000000000185,24.71009331931416,-0.5193344955604433,-0.014050293764505284
183.00000000000188,24.813996580769416,-0.5137002605914023,-0.017744949015535916
184.1000000000019,24.917888082537484,-0.5098314530173378,-0.020833573767776947
185.20000000000192,25.02205590317929,-0.5063804610547198,-0.022288718305071953
186.30000000000192,25.127062849305474,-0.5009366836186346,-0.025325447698645753
187.40000000000194,25.230388245835172,-0.4970840369816418,-0.02755005273907507
188.50000000000196,25.335811476458787,-0.49021920021750176,-0.03019006703148097
189.60000000000196,25.437792212019886,-0.4850558515701553,-0.03198926213416975
190.70000000000198,25.543986207539945,-0.4816331238476402,-0.0336406760291581
191.800000000002,25.648352716512772,-0.47719669439804885,-0.03818626198835329
192.90000000000202,25.751650179035888,-0.4731493005734298,-0.038695535203734366
194.00000000000205,25.85624195857391,-0.4679731327555627,-0.04040348390344928
195.10000000000204,25.960191930456656,-0.4636485909610605,-0.04314975466757165
196.20000000000206,26.063686711361086,-0.45989932781713144,-0.04666790752968453
197.3000000000021,26.169153464627886,-0.45455788909019945,-0.04989310354956
198.40000000000208,26.27257307272098,-0.45044307445647097,-0.05185306457774885
199.5000000000021,26.377915445362103,-0.4450267031809567,-0.05522775797923929
200.60000000000213,26.482209930196003,-0.44025446049684225,-0.0595623591262906
201.70000000000215,26.585541910921318,-0.43705961283547073,-0.06526134392267746
202.80000000000217,26.69019426203924,-0.43309692712906434,-0.06761317496036234
203.90000000000217,26.795120675626436,-0.4275520958756842,-0.07164331689486492
205.0000000000022,26.8996095302345,-0.42507525266071317,-0.07672966579401441
206.1000000000022,27.003136211608677,-0.4204461057754117,-0.0756635491510429
207.2000000000022,27.10573877103433,-0.4173940917984146,-0.07811564436611196
208.30000000000223,27.209712287042418,-0.4122463536727624,-0.08209911109903789
209.40000000000225,27.31473181514909,-0.407589573372395,-0.08637492316505035
210.50000000000227,27.4192037498928,-0.4037022929661271,-0.09078100458101401
211.6000000000023,27.52397278421446,-0.40146710974915234,-0.09341320169487988
212.7000000000023,27.62850911770889,-0.39770484229267355,-0.09702881357192705
213.8000000000023,27.731842460089958,-0.3939330897221819,-0.10240375289244419
214.90000000000234,27.836762868495505,-0.38902703756460877,-0.10734748460641752
216.00000000000233,27.941073780057298,-0.3857029146934801,-0.11064536036055861
217.10000000000235,28.045782013923116,-0.3815241597622012,-0.11558225335961314
218.20000000000238,28.150284337577638,-0.37820226615800573,-0.12000139282055367
219.3000000000024,28.25396009510473,-0.37391044372795695,-0.12337461740988775
220.40000000000242,28.35842091106621,-0.37114686041041484,-0.12618452987344186
221.50000000000242,28.462801602034446,-0.36848932114456484,-0.13043934141068414
222.60000000000244,28.56759834856648,-0.36391014043282005,-0.13451154118903075
223.70000000000246,28.670148966442945,-0.36081399216471144,-0.13392566487804913
224.80000000000246,28.77611097207464,-0.35753661196957853,-0.13796902690627988
225.90000000000248,28.880112568631034,-0.35365388248699725,-0.14468509810017238
227.0000000000025,28.98387041542399,-0.34986206442960505,-0.15007003498402893
228.10000000000252,29.08918365880497,-0.344316488495795,-0.15278390470991576
229.20000000000255,29.19403258537705,-0.34208475320321874,-0.15844427217367274
230.30000000000254,29.29875689351573,-0.3384556364225601,-0.16261516899829953
231.40000000000256,29.402785751532456,-0.3370089480789567,-0.16532564750382495
232.5000000000026,29.50729954903637,-0.3331852650994101,-0.1682385670105071
233.60000000000258,29.61097655010753,-0.33159638408923614,-0.171001827390882
234.7000000000026,29.716640940863673,-0.32802648686155267,-0.17489127148553552
235.80000000000263,29.821197465520957,-0.32525145560284097,-0.1790822042444562
236.90000000000265,29.9245581887925,-0.3219253269768642,-0.18222819036429216
238.00000000000267,30.030000000000236,-0.3194200000000295,-0.18442982500000138
239.10000000000267,30.134387418771215,-0.3162509608567215,-0.18726427785205368
240.2000000000027,30.23841615715031,-0.3140691260614876,-0.19138391128778665
241.3000000000027,30.343027320303968,-0.3102699681170988,-0.19572026082694682
242.4000000000027,30.448341711355468,-0.3065827274505385,-0.19706611089646664
243.50000000000273,30.55154929993474,-0.3034877473720674,-0.20017499433898944
244.60000000000275,30.65783753100341,-0.300359151654063,-0.20346789421851508
245.70000000000277,30.761731831416622,-0.2962627425283725,-0.20410691707111406
246.8000000000028,30.86668995810734,-0.29246072276324303,-0.2090206042054925
247.9000000000028,30.97123341124211,-0.2888633240878266,-0.21165136236218407
249.0000000000028,31.07564128980997,-0.28451306874535137,-0.21352762745046228
250.10000000000284,31.180733310670675,-0.2811291367625633,-0.21665972132256117
251.20000000000283,31.286094718910945,-0.27588546076202236,-0.2210069258028513
252.30000000000285,31.39106238066106,-0.2712879188662285,-0.22233644165713118
253.40000000000288,31.49526283255985,-0.2672482218868334,-0.22676453071803682
254.5000000000029,31.600193571723636,-0.26178690062944043,-0.22879633318363446
255.60000000000292,31.70471881090967,-0.2566498660895407,-0.23145129234826234
256.7000000000029,31.80999902098251,-0.2513200043265803,-0.23448990628382216
257.8000000000029,31.914041818404396,-0.24567595547261808,-0.23844281400787892
258.90000000000293,32.019712019160664,-0.2412041109225186,-0.24249046465015756
260.00000000000296,32.12452294474971,-0.2341779250900005,-0.24518381551632773
261.100000000003,32.22850661570175,-0.2299410812184607,-0.248296705784532
262.200000000003,32.33354730215614,-0.2222265843152912,-0.2505639873749983
263.300000000003,32.43884368585967,-0.21664028661899656,-0.25588291882274383
264.40000000000305,32.54392044203653,-0.20925860197089638,-0.2585397357422665
265.50000000000307,32.647967498112656,-0.2029785966857048,-0.2597554595113145
266.6000000000031,32.753715386865295,-0.19576449468865573,-0.2625868498984838
267.7000000000031,32.858538898677736,-0.18821278701650804,-0.26851937663005065
268.8000000000031,32.96415206517906,-0.18243987622587549,-0.27270203101550194
269.9000000000031,33.069018774270155,-0.17320032570204458,-0.2783603056273187
271.0000000000031,33.17345461004743,-0.16406726544478642,-0.2836650885025671
272.10000000000315,33.280101499018336,-0.1554279932542816,-0.28500076064780533
273.2000000000032,33.384441558441985,-0.1468074388473824,-0.2898330981008388
274.30000000000314,33.4893544658393,-0.13843843362490044,-0.3005253563247843
275.40000000000316,33.594393880798044,-0.12670829784694684,-0.3055022641324934
276.5000000000032,33.69854772595755,-0.11534426995839615,-0.30937211186923586
277.6000000000032,33.80433664986587,-0.1030141129574898,-0.3118121323835972
278.70000000000323,33.90908342807748,-0.09180501632368941,-0.31641646461835915
279.80000000000325,34.01469957953809,-0.08196612062468289,-0.32324827156060687
280.9000000000033,34.12066248602265,-0.06781164177792638,-0.3300406244193357
282.0000000000033,34.22451188871643,-0.05395195568008457,-0.33656592442678823
283.1000000000033,34.32865368517337,-0.04151030514395698,-0.34326472786571927
284.20000000000334,34.43512945165947,-0.028365302136803768,-0.35009811013381986
285.30000000000337,34.540777745747576,-0.012188611168756018,-0.3565362161051673
286.40000000000333,34.64606217354513,0.002001137442702554,-0.36509979485574684
287.50000000000335,34.75156755994814,0.0186549671971488,-0.3741096601511762
288.6000000000034,34.856466737517835,0.03557758837575313,-0.38351502478358057
289.7000000000034,34.96322589554081,0.05194139575121179,-0.3928937983081431
290.8000000000034,35.06689000355297,0.07132716074872261,-0.4018953805206009
291.9000000000034,35.17229202980286,0.089644165864484,-0.4116893262410781
293.0000000000034,35.27818031585328,0.10502838500573837,-0.41772495531355025
294.10000000000343,35.38406371259934,0.12325980876017806,-0.43017879421186933
295.20000000000346,35.48949638750301,0.14271921797709378,-0.442819460949587
296.3000000000035,35.59463477561086,0.16003712981253548,-0.4550401510307003
297.4000000000035,35.697756046608234,0.1792226665687321,-0.4693137852990059
298.5000000000035,35.80553206749782,0.1960142083280781,-0.48241477255350995
299.60000000000355,35.91051582194937,0.21472930116149463,-0.49928600335501816
300.70000000000357,36.01655075618171,0.22911309791463025,-0.5145827272388388
301.8000000000036,36.12240002061618,0.24491276428236752,-0.5294177544728793
302.9000000000036,36.22883875660974,0.26016895221329006,-0.5414846878138824
304.0000000000036,36.33367428876683,0.27573222480738024,-0.555036520742243
305.1000000000036,36.43674589180341,0.28700740519392065,-0.5723693851284977
306.2000000000036,36.54561259065932,0.2988389560887717,-0.5898610037522385
307.30000000000365,36.65109318312099,0.3088127377375065,-0.6067199739526181
308.4000000000037,36.7569797482848,0.31749524209727026,-0.6225785748553645
309.5000000000037,36.86281258459525,0.32604222007786726,-0.6430322031624423
310.60000000000366,36.96782129790497,0.3306290149935899,-0.6632240053371965
311.7000000000037,37.07368342841397,0.33373879266503026,-0.6839940304771099
312.8000000000037,37.180000915381655,0.3337399804605101,-0.7055702725110629
313.90000000000373,37.28502994396961,0.3301468533990849,-0.726288808144337
315.00000000000375,37.38883030198588,0.3198641425412294,-0.7491747522909291
316.1000000000038,37.49774194082015,0.3019467348481276,-0.774487131403343
317.2000000000038,37.60280881806641,0.27676509608597455,-0.799789013139371
318.3000000000038,37.70777992609665,0.2443984030024409,-0.8273628308258432
319.40000000000384,37.81324264729345,0.20318192733539656,-0.8514093742247582
320.5000000000038,37.920196879027834,0.15134480993883406,-0.8782902877686287
321.60000000000383,38.025088148210685,0.0944659205099001,-0.9019262043414682
322.70000000000385,38.129999114428834,0.03097721927244609,-0.9300675117232342
323.8000000000039,38.234998019295105,-0.0358299279436959,-0.9551608110713019
324.9000000000039,38.3407043209109,-0.1045698567539342,-0.9834933225968987
326.0000000000039,38.44586548630956,-0.17134302187497155,-1.0087427200446188
327.10000000000394,38.55165798263142,-0.23842973953084093,-1.0354471846287323
328.2000000000039,38.656574403957535,-0.2994992163823592,-1.0580123215076576
329.30000000000393,38.76110091986394,-0.3515947075843361,-1.0811016850177322
330.40000000000396,38.86666965281141,-0.39828643160238464,-1.1030124064229598
331.500000000004,38.97303532745978,-0.43716109600682185,-1.1262808535788897
332.600000000004,39.07760556319652,-0.46963841735726813,-1.145809210435548
333.700000000004,39.183202571227525,-0.49531638246096066,-1.167368302251878
334.80000000000405,39.28929873488984,-0.5161112641601435,-1.1863103743354682
335.90000000000407,39.394878591593915,-0.5291406335001166,-1.2027874007573005
337.0000000000041,39.49855016595753,-0.5388405414185328,-1.2185421978900322
338.10000000000406,39.60527064434407,-0.5434948676669532,-1.2363567088735303
339.2000000000041,39.709770813172014,-0.5474849761681524,-1.2530517964576973
340.3000000000041,39.81638560158543,-0.5501228203857289,-1.269475293670057
341.4000000000041,39.924403057342644,-0.5490272026198844,-1.2847516066460694
342.50000000000415,40.02979851089445,-0.5465452560771394,-1.297488744294108
343.6000000000042,40.134566377556546,-0.5432691766590645,-1.3110125595824136
344.7000000000042,40.2414454183702,-0.538383141466522,-1.3221957607319457
345.80000000000416,40.348768423877864,-0.5341820560047559,-1.3326726371718514
346.9000000000042,40.45445357899842,-0.5265824304118749,-1.3442988636337079
348.0000000000042,40.56047686871522,-0.52248728881623,-1.3521228069818751
349.10000000000423,40.665963140543944,-0.5163750609071152,-1.3663704838710569
350.20000000000425,40.77311374344061,-0.5107059490338236,-1.3761461295200461
351.3000000000043,40.879216857804096,-0.5040372201343315,-1.3882330822341626
352.4000000000043,40.98483954894963,-0.4978900756526984,-1.4000408267196
353.5000000000043,41.091790644257095,-0.49241611008600616,-1.4082528654003408
354.60000000000434,41.1973620093563,-0.48708930726600874,-1.416948854822008
355.7000000000043,41.30454250292417,-0.48154463189854874,-1.4290457340055611
356.80000000000433,41.41090336975162,-0.4755971500995983,-1.4381317933794415
357.90000000000435,41.51764084680917,-0.4707117832942279,-1.446036708581564
359.0000000000044,41.624452798398885,-0.46482595205372784,-1.455720583018337
360.1000000000044,41.730336679256084,-0.46154436753352485,-1.4660714655403577
361.2000000000044,41.836583537633466,-0.45726373208931104,-1.475529596748303
362.30000000000445,41.9439460649163,-0.45271861339479846,-1.4858312987356737
363.4000000000044,42.05019348101802,-0.4512120228861593,-1.500630768423791
364.50000000000443,42.15737150685042,-0.44744583331248355,-1.5023536859119835
365.60000000000446,42.2640697964267,-0.44345739884679697,-1.5116104629056584
366.7000000000045,42.37056143360735,-0.44099426486161813,-1.5229609344880641
367.8000000000045,42.47775889371217,-0.4385497978425531,-1.5379494502703395
368.9000000000045,42.58428796869453,-0.4365030880711964,-1.545090664857811
370.00000000000455,42.687164537791446,-0.4332573630981814,-1.5492743831438371
371.10000000000457,42.79714258795819,-0.431036825359281,-1.558581893338661
372.2000000000046,42.90392219908761,-0.42919146663736346,-1.5667285194930622
373.30000000000456,43.0114152575267,-0.4275303390762544,-1.5769529370810003
374.4000000000046,43.118143416411186,-0.42765315247972735,-1.586539681954282
375.5000000000046,43.2241226105015,-0.42609330153981345,-1.593806309581188
376.6000000000046,43.331498362161014,-0.4248529953837444,-1.6052016372166134
377.70000000000465,43.437888961749636,-0.4246084632904667,-1.6122360965978881
378.8000000000047,43.54500258868194,-0.42379902184899576,-1.621323770449703
379.9000000000047,43.652380784063794,-0.4230527339691456,-1.6306704850792881
381.00000000000466,43.75861818752239,-0.42231483710628953,-1.6391800475068825
382.1000000000047,43.865384665002075,-0.4229008028535092,-1.6455931822769796
383.2000000000047,43.97229683529592,-0.42098338688884146,-1.658574333989029
384.30000000000473,44.08018737498333,-0.42029476997807347,-1.6670701258039657
385.40000000000475,44.186154495267616,-0.4190939194792471,-1.676849211754166
386.5000000000048,44.29145433688829,-0.41761026103888443,-1.683314399397692
387.6000000000048,44.40027195544512,-0.4156236697992688,-1.6911222759626088
388.7000000000048,44.50746985980288,-0.4142945234868468,-1.6988148533464331
389.80000000000484,44.614122121025005,-0.41200616290082875,-1.7109556468820752
390.9000000000048,44.72139110586543,-0.4088577980173129,-1.721889808947612
392.00000000000483,44.82898039890172,-0.4046624217334153,-1.7290622683996864
393.10000000000485,44.93594885513377,-0.4013474167235499,-1.7339298070524394
394.2000000000049,45.04249569321953,-0.40084490062065486,-1.7449966576214502
395.3000000000049,45.150578725139,-0.39739291525551856,-1.7556141615548375
396.4000000000049,45.25751661945918,-0.3927914389634355,-1.7642874572458198
397.50000000000495,45.36482959049419,-0.389572874609204,-1.7700657853464907
398.6000000000049,45.471799635575195,-0.3859564080078172,-1.7790127966444627
399.70000000000493,45.57891240874454,-0.38438574653108,-1.786138821591127
400.80000000000496,45.68707656912256,-0.37982057239287725,-1.7952876939581865
401.900000000005,45.793100266935944,-0.3773357250193003,-1.8020860222158244
403.000000000005,45.90117366691582,-0.37471113991719857,-1.8116187459511228
404.100000000005,46.00819802581873,-0.3709208048223705,-1.8222787997863672
405.20000000000505,46.115310057715455,-0.36833887308103436,-1.8296723996623134
406.30000000000507,46.223243252364924,-0.3660622499976194,-1.8354782595496104
407.4000000000051,46.33058926982418,-0.364483340473345,-1.8436182029713049
408.50000000000506,46.43896404496103,-0.3626392361862939,-1.8525218137273027
409.6000000000051,46.54535072213614,-0.36046736625202813,-1.8602550104465
410.7000000000051,46.65195065324806,-0.35880506766139775,-1.868309975858499
411.8000000000051,46.75979383789287,-0.3563034373140891,-1.8755234180265532
412.90000000000515,46.86725851329556,-0.3550253842264167,-1.8840518533137653
414.0000000000052,46.97314976293624,-0.3547074503348379,-1.893185947427099
415.1000000000052,47.078915323161965,-0.35136516650657695,-1.9012968961018926
416.20000000000516,47.189897865890394,-0.35136074163692965,-1.909767352197402
417.3000000000052,47.29724396906186,-0.34939604249708783,-1.9179269123147713
418.4000000000052,47.40440579893251,-0.34717765777721876,-1.9235748509807205
419.50000000000523,47.51305983558137,-0.34471127021862674,-1.9307187789861655
420.60000000000525,47.61959495589269,-0.3429035904717709,-1.9395990724443122
421.7000000000053,47.72684441132333,-0.3414504112176719,-1.9477617423482387
422.8000000000053,47.835140659503686,-0.33908994610338716,-1.9562365391210843
423.9000000000053,47.942919470235,-0.33752426364733557,-1.9644452555920258
425.00000000000534,48.050499061981334,-0.336024751136246,-1.9715312243640888
426.1000000000053,48.15844578161104,-0.3354867381946183,-1.979262872411879
427.20000000000533,48.26559835199878,-0.33245210882985754,-1.9868988369747376
428.30000000000535,48.37416285896608,-0.32865149930085086,-1.9963205649365432
429.4000000000054,48.48148581961491,-0.3272867896717163,-2.0033634145338186
430.5000000000054,48.58862188655049,-0.3242573525755264,-2.009307602754073
431.6000000000054,48.69399571159559,-0.3230669198142798,-2.019262773472534
432.70000000000545,48.80452962565295,-0.32058553762752273,-2.0248844161837116
433.8000000000054,48.91238476453645,-0.31866974227035655,-2.03253049117184
434.90000000000543,49.01786710559092,-0.3136346817341773,-2.039035057196917
436.00000000000546,49.127351581038006,-0.31175366479312633,-2.0456952825122467
437.1000000000055,49.235351405863454,-0.31032227815453406,-2.054186225357137
438.2000000000055,49.34406977639401,-0.30646345930439645,-2.0600184012221225
439.3000000000055,49.45106911207928,-0.30267269971468225,-2.0667760471092134
440.40000000000555,49.559644362163525,-0.2992237654483015,-2.0738956161725715
441.50000000000557,49.666697434105856,-0.2969354711860211,-2.080674886768197
442.6000000000056,49.773586378726506,-0.2946717796463386,-2.087329694057408
443.70000000000556,49.88250636698229,-0.2910115074825409,-2.09627370854922
444.8000000000056,49.99062821586556,-0.29013977151930576,-2.1032003545538362
445.9000000000056,50.098575328704484,-0.2876928739197636,-2.108504300740313
447.0000000000056,50.2063644107538,-0.28611151589723105,-2.116366086407342
448.10000000000565,50.31430251145606,-0.2842255479732581,-2.1246801128276416
449.2000000000057,50.422153569513945,-0.28292354451202756,-2.1323387991205855
450.3000000000057,50.52961348313153,-0.28055693025189005,-2.139863475874825
451.40000000000566,50.638765549733385,-0.27955144888746364,-2.146972705697666
452.5000000000057,50.74633004646962,-0.2791604279601655,-2.154611162359575
453.6000000000057,50.85486335568723,-0.27948697571341596,-2.162491245959675
454.70000000000573,50.96331566995662,-0.27695035414910923,-2.170825421118299
455.80000000000575,51.070816310141225,-0.2759611712430315,-2.1777982144018777
456.9000000000058,51.17840459583877,-0.2763351242257777,-2.1847284182255646
458.0000000000058,51.286508838258364,-0.27640656503808814,-2.1920022283953533
459.1000000000058,51.394565074804895,-0.2740457197620723,-2.2001776238156956
460.20000000000584,51.50254835833907,-0.2746903561933888,-2.2084605940701567
461.3000000000058,51.610763829198625,-0.27626742130889353,-2.2159018921168765
462.40000000000583,51.718341777400255,-0.2752027456030712,-2.2231656969673548
463.50000000000585,51.82537899471821,-0.2750990051665715,-2.230565801397303
464.6000000000059,51.934515751962984,-0.27608421672246586,-2.2392863364719178
465.7000000000059,52.04192537222894,-0.2746467872190741,-2.246870704308476
466.8000000000059,52.15063231561378,-0.2735786473234138,-2.253435657736956
467.90000000000595,52.25912103115029,-0.2758692328280944,-2.261910404985872
469.0000000000059,52.36606835325094,-0.27583915227237965,-2.2697514746644267
470.10000000000593,52.47385948092893,-0.27594982979227917,-2.2760892770117187
471.20000000000596,52.58170378028094,-0.276008501717896,-2.283206770641371
472.300000000006,52.69009840076841,-0.27581745758468246,-2.2916099105624967
473.400000000006,52.79820166964159,-0.27634554120990457,-2.299117323816613
474.500000000006,52.90657257365149,-0.27739853165143724,-2.306604644433188
475.60000000000605,53.015136693014625,-0.27716885499587485,-2.3147880376389924
476.70000000000607,53.1223211479435,-0.27890487940191017,-2.3218630242946725
477.8000000000061,53.230694084795765,-0.27961526974793954,-2.3281959212280023
478.90000000000606,53.33911434210269,-0.27983463451153234,-2.3347984200630454
480.0000000000061,53.447020805596274,-0.2800062736530788,-2.34198741192876
481.1000000000061,53.555847271189094,-0.2783729114218287,-2.347770470314444
482.2000000000061,53.66470484147731,-0.2794550373619205,-2.3552695396242953
483.30000000000615,53.77296614026348,-0.27771437589285103,-2.363139344034492
484.4000000000062,53.881661045267265,-0.27782035749668144,-2.3694351278553007
485.5000000000062,53.99024397310536,-0.2778493229682672,-2.376916848005887
486.60000000000616,54.09908791690005,-0.27832586050492686,-2.3831950836139013
487.7000000000062,54.20665677011524,-0.2776495585858328,-2.387672805508407
488.8000000000062,54.315350059595836,-0.2763306329601238,-2.394315063297692
489.90000000000623,54.4238882124637,-0.2762985249227409,-2.3992594719641724
491.00000000000625,54.5316639381763,-0.2751769739675839,-2.404404053325697
492.1000000000063,54.64215102401823,-0.27590210272885585,-2.4119361181252374
493.2000000000063,54.74989822727563,-0.27637703922196033,-2.416200876266306
494.3000000000063,54.85783110214727,-0.27505054199444057,-2.4219047389761608
495.40000000000634,54.966737111635574,-0.27410516878313207,-2.424974094429287
496.5000000000063,55.07481989002572,-0.2738141894203365,-2.430642764183503
497.60000000000633,55.184180255272814,-0.2728474762577184,-2.439126914351008
498.70000000000636,55.29220748076786,-0.27126137223267127,-2.4448128593080414
499.8000000000064,55.400942436212155,-0.27089942227889746,-2.447582980631311
500.9000000000064,55.508862070176356,-0.27139529290594555,-2.4524661835018664
502.0000000000064,55.617371317834944,-0.269793081355047,-2.4572250235586024
503.10000000000645,55.725834241625975,-0.2693197369096578,-2.463218804661987
504.2000000000064,55.83554173540146,-0.26788085273680107,-2.465864241449718
505.30000000000643,55.94325055914887,-0.26734310117887977,-2.4703307212123655
506.40000000000646,56.05205710749383,-0.2660654805210466,-2.474839481588609
507.5000000000065,56.16000000000068,-0.26486999999999955,-2.483172347390668
508.6000000000065,56.268950063522865,-0.26316042652497457,-2.4850991322339366
509.7000000000065,56.37669294856534,-0.2622817076919774,-2.4875287443733067
510.80000000000655,56.485116730929576,-0.26333437991963576,-2.493170871497349
511.90000000000657,56.59477155821263,-0.26204255568037815,-2.493744015949571
513.0000000000066,56.70243318506871,-0.26185704108405417,-2.497532819764133
514.1000000000065,56.81089771285038,-0.2614615758489534,-2.5052921675281565
515.2000000000066,56.92105601311018,-0.26007122896028245,-2.504201069957261
516.3000000000065,57.029590908046586,-0.2588156855286688,-2.5075093923641987
517.4000000000067,57.13882467204227,-0.2579242234129431,-2.511291061256289
518.5000000000066,57.245433152857544,-0.2575169803342122,-2.5156499273334103
519.6000000000067,57.35610866085288,-0.2564131046843216,-2.520697109836511
520.7000000000066,57.464795645483925,-0.25612834094330034,-2.5199750716323646
521.8000000000067,57.573509125406126,-0.2574069211300867,-2.5229853520783303
522.9000000000067,57.6824351169598,-0.2561686653433858,-2.5282742554963322
524.0000000000067,57.791438127507874,-0.25617059512589396,-2.532643735206068
525.1000000000067,57.90048297744581,-0.2548321766579901,-2.534931519017411
526.2000000000068,58.00932784584454,-0.2555164188006404,-2.539272689273382
527.3000000000068,58.11883693311761,-0.2538452604843788,-2.542920650144028
528.4000000000068,58.22786632603906,-0.2531879377437316,-2.545379777801655
529.5000000000068,58.3365774630467,-0.2529648391750007,-2.549874696741192
530.6000000000068,58.44594728040278,-0.25193297100745893,-2.5538785271685542
531.7000000000069,58.55377256173546,-0.25305917880939865,-2.557894327470584
532.8000000000068,58.6630048821646,-0.2531995827259734,-2.5610635616975097
533.9000000000069,58.77215143252446,-0.25196509626628105,-2.5635134243577897
535.0000000000068,58.87860990373295,-0.2520414320339542,-2.5655018165075294
536.100000000007,58.989464472340515,-0.25366585191247665,-2.5690854251102917
537.2000000000069,59.09821353909769,-0.2532709126542674,-2.5729147400586356
538.300000000007,59.20812607911169,-0.251830326020351,-2.5765323299533076
539.4000000000069,59.31675990643299,-0.25189313448267825,-2.5783305044359155
540.5000000000069,59.426003744397384,-0.2516310133405983,-2.5823800213854318
541.600000000007,59.53482232862351,-0.2502476887683831,-2.5838490137696692
542.700000000007,59.64400370493655,-0.24889400463788133,-2.587448572294279
543.800000000007,59.75325399437855,-0.24955885737584035,-2.594786007823056
544.900000000007,59.861430800833055,-0.24977244350264796,-2.597865220022746
546.000000000007,59.97110427734424,-0.24998988044117257,-2.600182167460038
547.1000000000071,60.080632191317676,-0.24846219422325924,-2.603713323558067
548.2000000000071,60.18933025386127,-0.25080241149468463,-2.607626232485247
549.300000000007,60.300001038143776,-0.24832995949479308,-2.6105199968659627
550.4000000000071,60.40812346482596,-0.24981881423347702,-2.612392174367627
551.500000000007,60.51758664026442,-0.24895716386083006,-2.6150230635714147
552.6000000000072,60.626747176841405,-0.24898785301690973,-2.6186759864451403
553.7000000000071,60.735737454310154,-0.2480650942316896,-2.620074214932643
554.8000000000072,60.84506427815849,-0.24818600445337116,-2.6231591744711054
555.9000000000071,60.95420425878432,-0.2489713925488571,-2.632234093809862
557.0000000000072,61.063214079320666,-0.24754070213667342,-2.628967413267783
558.1000000000072,61.17212342966116,-0.24761558314942145,-2.632487254899434
559.2000000000072,61.28172418602555,-0.24804738804470225,-2.635521609844263
560.3000000000072,61.389475292950436,-0.24697985393024266,-2.639607750522919
561.4000000000073,61.49694732769883,-0.2469906596168191,-2.6409905995539606
562.5000000000073,61.60978795161763,-0.2479846065898459,-2.6464135592915827
563.6000000000073,61.7186290712487,-0.249190067513382,-2.6490170238294652
564.7000000000073,61.8281371231262,-0.2500660193228819,-2.653320765606664
565.8000000000073,61.9374967226658,-0.24966593785873079,-2.655278217676312
566.9000000000074,62.04658664299029,-0.2515242731504327,-2.657305197177073
568.0000000000074,62.156203193621025,-0.25191168824894866,-2.6599107212042647
569.1000000000074,62.26582467075357,-0.2503071259782326,-2.661478374676247
570.2000000000073,62.375207328723256,-0.2508802505463913,-2.6671216320949647
571.3000000000073,62.484885971443774,-0.2518419763962124,-2.6684697624189084
572.4000000000074,62.59481656405325,-0.25028967382006767,-2.672580020930704
573.5000000000074,62.703935121010126,-0.2500057413547075,-2.6755284820075658
574.6000000000074,62.81279233949987,-0.2500138373268781,-2.6780592800429672
575.7000000000074,62.922097382755446,-0.24994434695116668,-2.6794809346149466
576.8000000000075,63.03189351411886,-0.24867211421248445,-2.68221223569306
577.9000000000075,63.141820950605656,-0.24970022226775168,-2.6863079669268535
579.0000000000075,63.251641297466314,-0.2490408671687743,-2.686613676232394
580.1000000000075,63.361156267012994,-0.24902007481269914,-2.690521315639907
581.2000000000075,63.47067001101346,-0.24764269671538958,-2.69522598335742
582.3000000000076,63.5803169131367,-0.24507222798663186,-2.696005343748223
583.4000000000076,63.69109254063304,-0.24577386649705144,-2.6988211018109727
584.5000000000076,63.798448299794636,-0.2457001501055202,-2.70154010960274
585.6000000000076,63.90843614088352,-0.24515651749672876,-2.7052691382983265
586.7000000000077,64.0189486066059,-0.24266074924549136,-2.7080489517675073
587.8000000000077,64.12789812534959,-0.24328214093357692,-2.7107579619646893
588.9000000000076,64.2377035131451,-0.24211213884274846,-2.712054814537149
590.0000000000076,64.34766117390839,-0.24164913761911888,-2.7135790875259738
591.1000000000076,64.45805068928625,-0.2410606881622172,-2.7148105012205406
592.2000000000077,64.56668324300027,-0.23881299774960368,-2.7174759249481015
593.3000000000077,64.67672850768255,-0.23861536019547125,-2.7200541056229675
594.4000000000077,64.78635090607457,-0.23700599591235022,-2.7221453915563214
595.5000000000077,64.89434968056783,-0.23682885097304499,-2.725648178684108
596.6000000000078,65.00568069482374,-0.23519031549470376,-2.72808828399549
597.7000000000078,65.11596687123082,-0.2347730686214716,-2.7279530317493608
598.8000000000078,65.22499055056483,-0.23519960259397243,-2.7294132337318184
599.9000000000078,65.3348521219825,-0.23339697041647312,-2.732065783649695
601.0000000000078,65.44451675570394,-0.2330484112673239,-2.7334613583706373
602.1000000000079,65.55428908811555,-0.23175129797176752,-2.7371019394030327
603.2000000000079,65.66418462135313,-0.23362497360927045,-2.738329463953511
604.3000000000079,65.77219484366182,-0.23070251006961398,-2.739641297771702
605.4000000000078,65.88245670527776,-0.23060396541181846,-2.7409506164459336
606.5000000000078,65.99316375141197,-0.23066898859544283,-2.7422919083289607
607.6000000000079,66.10199276836272,-0.23033770654742147,-2.744903596495357
608.7000000000079,66.21232694097135,-0.23049339559443685,-2.7463888748448024
609.8000000000079,66.32121888288532,-0.22988741487628783,-2.7489639804014114
610.9000000000079,66.43104299265548,-0.2303233476963103,-2.749056094531255
612.000000000008,66.54132576002239,-0.23088326746398913,-2.748836328598165
613.100000000008,66.65187984969003,-0.22999462499521547,-2.7501381740117843
614.200000000008,66.76128131647458,-0.23232465919277873,-2.752242267715226
615.300000000008,66.86865946302554,-0.2332953096317678,-2.7533436561784215
616.400000000008,66.97916240732866,-0.2333554227346417,-2.7554324943133714
617.5000000000081,67.08944097131834,-0.2330102124731247,-2.7554397167143114
618.6000000000081,67.19989724486355,-0.23476693860206027,-2.757741461730287
619.7000000000081,67.30944001828317,-0.23387095838414962,-2.7580806435293614
620.8000000000081,67.41885355535767,-0.2336921880704873,-2.760633550860726
621.9000000000082,67.52842324653017,-0.23529786816179035,-2.7619748299669524
623.0000000000082,67.63859577120103,-0.23280491259959818,-2.7607110061696662
624.1000000000081,67.74906798285821,-0.23096784900717945,-2.762021610447186
625.2000000000081,67.8585335568921,-0.23164582366868508,-2.7633394705275522
626.3000000000081,67.96808814481992,-0.23198402054304681,-2.7633399070428406
627.4000000000082,68.07786345018965,-0.23066446121216397,-2.7646559580702896
628.5000000000082,68.18809958303396,-0.22792550222337193,-2.7659450582175547
629.6000000000082,68.29827082769583,-0.22647432106158286,-2.767290807562536
630.7000000000082,68.40611280437282,-0.2263519454400297,-2.7672825831555605
631.8000000000083,68.5167238794994,-0.22495890291765203,-2.7686098713720795
632.9000000000083,68.62567647295872,-0.22356375307196016,-2.7699679811305185
634.0000000000083,68.73632482687889,-0.22301169446096408,-2.770419860308216
635.1000000000083,68.8468004246498,-0.2212074838901823,-2.7705898117959045
636.2000000000083,68.95582870972075,-0.21940597362494363,-2.771567970750522
637.3000000000084,69.06646163096597,-0.21780488709531345,-2.7725703298759345
638.4000000000084,69.17673065534815,-0.21907848704776367,-2.7808595558739855
639.5000000000084,69.28606159190821,-0.21763989249295518,-2.7779536664261615
640.6000000000083,69.39612647257057,-0.21667287219799675,-2.7772886478758823
641.7000000000083,69.50610619172656,-0.21712825291505897,-2.773988769055735
642.8000000000084,69.61657559341747,-0.21569253448736447,-2.773991696361035
643.9000000000084,69.72596627509306,-0.2161669036576072,-2.7767243025094297
645.0000000000084,69.83662074104284,-0.2167696062892114,-2.779259830401371
646.1000000000084,69.94652872270188,-0.21715315040788602,-2.7805747507644796
647.2000000000085,70.056448100802,-0.21809394147817865,-2.781899007436058
648.3000000000085,70.16636297366182,-0.2204414120237895,-2.7809099354913256
649.4000000000085,70.2762519059954,-0.22050513281566478,-2.7821993973829313
650.5000000000085,70.38582689053982,-0.22006163040936025,-2.7831969989341516
651.6000000000085,70.49579715257187,-0.22170903884588394,-2.7832031268658306
652.7000000000086,70.60612224800435,-0.22322551592961629,-2.7845337603206373
653.8000000000086,70.71474716075745,-0.2232549511805651,-2.784178450940494
654.9000000000086,70.82683686131975,-0.22203545644429912,-2.7845300574749308
656.0000000000086,70.9366560797652,-0.22240181308645518,-2.787169847364345
657.1000000000087,71.046122904573,-0.22351595106813457,-2.788467396193446
658.2000000000087,71.15644717287705,-0.2234013591875537,-2.7884825196376593
659.3000000000086,71.26706214424713,-0.22572053081331483,-2.7871835171384225
660.4000000000086,71.37640732391891,-0.22510581942291338,-2.7871715170000626
661.5000000000086,71.4866532156169,-0.2282029684352512,-2.788492628193482
662.6000000000087,71.59743902427385,-0.22938173624554264,-2.7884535346023114
663.7000000000087,71.70701108457273,-0.2286271733302206,-2.788474164399407
664.8000000000087,71.81584843329287,-0.2298852454756593,-2.7899124306989798
665.9000000000087,71.92821018201427,-0.22987459707621904,-2.79111992475214
667.0000000000088,72.03827943783004,-0.23029245639286572,-2.79112066460109
668.1000000000088,72.14735593309655,-0.23203967600982633,-2.791123371884173
669.2000000000088,72.25889758605251,-0.23323551251554453,-2.792431029144572
670.3000000000088,72.37000099998254,-0.23501003214511296,-2.792209278833382
671.4000000000088,72.4794209380419,-0.2364164358244379,-2.7924372591692297
672.5000000000089,72.58981034654943,-0.23677995359437864,-2.793101162578381
673.6000000000089,72.70049775876242,-0.23854561114169642,-2.794419686126708
674.7000000000089,72.81063549326251,-0.2404360470083049,-2.795729690686114
675.8000000000088,72.92163031707678,-0.24007648699462342,-2.7957298477822734
676.9000000000088,73.03119515003286,-0.24202276684736407,-2.7970521375722965
678.0000000000089,73.14085576192151,-0.2417953373192384,-2.797095359998133
679.1000000000089,73.2523695010575,-0.24421375736551057,-2.798370105124471
680.2000000000089,73.3616837386669,-0.24244384488585766,-2.7996818322692953
681.3000000000089,73.47296484725975,-0.24438781753626782,-2.798310222442296
682.400000000009,73.58334267832969,-0.24403327741694966,-2.798614639076797
683.500000000009,73.69095720998378,-0.2462193250839723,-2.799019953899122
684.600000000009,73.80292370024532,-0.24689498095822152,-2.799627542446214
685.700000000009,73.91327107273135,-0.24765107945666914,-2.8016398539370284
686.800000000009,74.02359968529593,-0.24875944529284474,-2.8016502292546295
687.9000000000091,74.13204310706386,-0.2489719418108694,-2.80163134025473
689.0000000000091,74.24412407451892,-0.250812833534767,-2.7979220377951535
690.1000000000091,74.35467167889809,-0.25326620166554964,-2.8015741465113786
691.2000000000091,74.46386378994504,-0.25588628155429083,-2.803419799511681
692.3000000000092,74.57430118837406,-0.2566582884175075,-2.8047299600803717
693.4000000000092,74.6840160755407,-0.25842880954292013,-2.804781547628574
694.5000000000091,74.79544993907314,-0.26027863345503927,-2.8060566555950945
695.6000000000091,74.90477328678189,-0.26285607179801745,-2.8063815759478503
696.7000000000091,75.01558400241593,-0.2657245145597518,-2.8082483450701643
697.8000000000092,75.12642413785743,-0.2632719725622289,-2.8095567391351857
698.9000000000092,75.23585306166068,-0.26553905751378554,-2.811309048238713
700.0000000000092,75.34661922149981,-0.26617908167407933,-2.8113514726153204
701.1000000000092,75.45746826744481,-0.2685310607159298,-2.8113733121151645
702.2000000000093,75.56823444283948,-0.26974912739619483,-2.811320049541886
703.3000000000093,75.67784337684417,-0.2713598313637168,-2.8116395291628606
704.4000000000093,75.78886122061611,-0.27451483079135747,-2.8139423931060934
705.5000000000093,75.8986951289656,-0.27462896100001377,-2.8139507507234365
706.6000000000093,76.00820760011966,-0.2755821455983599,-2.8139510949868907
707.7000000000094,76.11940062918659,-0.27761737075355053,-2.8152804137216525
708.8000000000094,76.23009485433512,-0.2811638311420565,-2.814716505127364
709.9000000000094,76.34019496307523,-0.2830499776632659,-2.8162611931778523
711.0000000000093,76.4502863153028,-0.28383079831144553,-2.818254322901912
712.1000000000093,76.56041216967155,-0.28735048512448924,-2.817899868822426
713.2000000000094,76.67020996365665,-0.2884610137943426,-2.81791074489883
714.3000000000094,76.78065881600627,-0.291765917995872,-2.817910130371417
715.4000000000094,76.89162385296466,-0.29359988378502994,-2.822307860454607
716.5000000000094,77.00226349366389,-0.2976744063548227,-2.826822763269405
717.6000000000095,77.11249340288016,-0.2968359110751888,-2.8162154470318406
718.7000000000095,77.22329471455487,-0.29706343737724106,-2.8192930246352796
719.8000000000095,77.33334443731486,-0.29887594902887843,-2.8245496969104034
720.9000000000095,77.44107153720866,-0.30166100906810156,-2.8226586241346063
722.0000000000095,77.55440873631488,-0.3045761570425475,-2.8229501796110124
723.1000000000096,77.66509305743932,-0.30511691950901537,-2.8243290398889207
724.2000000000096,77.77551603168473,-0.30577389355803664,-2.824270006949169
725.3000000000096,77.8856243136776,-0.306521370934507,-2.825588078373327
726.4000000000096,77.99645743067418,-0.3085924260546778,-2.8249797763187847
727.5000000000097,78.10699878689475,-0.3107605747499231,-2.8272288543409294
728.6000000000097,78.21647560971321,-0.313629326861782,-2.8296969734636797
729.7000000000096,78.32768908392778,-0.31378451972585,-2.82855040333276
730.8000000000096,78.43727337475708,-0.3146783820756114,-2.8295483883756316
731.9000000000096,78.54835927753729,-0.3166444527773552,-2.831193549478228
733.0000000000097,78.65834543721813,-0.31856205252895936,-2.833161490987132
734.1000000000097,78.76980237954956,-0.3186886614891728,-2.8331602909155422
735.2000000000097,78.88072455742277,-0.3228309705502619,-2.833160285603762
736.3000000000097,78.99095218771433,-0.3239269513945993,-2.8331764756057827
737.4000000000098,79.1019518164433,-0.32787808461830253,-2.833003427659336
738.5000000000098,79.21328297109785,-0.33255095740105,-2.833510988991459
739.6000000000098,79.32427100411594,-0.3332115249657013,-2.8361301506526626
740.7000000000098,79.43503544574949,-0.33617891811252465,-2.8358758233974313
741.8000000000098,79.54573359120506,-0.3379678291186823,-2.836128134553971
742.9000000000099,79.6562471518193,-0.3382016583089071,-2.8375258529652774
744.0000000000099,79.76827907248662,-0.3417372529426832,-2.8382748027305427
745.1000000000099,79.87882247128938,-0.33848130486316663,-2.838765718523316
746.0000000000099,79.96980140474409,-0.3411479632343405,-2.840080005932927