File: 01_Data/Nylon_Carpet_Low_Pile/STA/N2/3K_min/Nylon_Carpet_Low_Pile_STA_N2_3KData_220106_R1.csv
##Temp./Â°C,Time/min,DSC/(mW/mg),Mass loss/mg
50.0,10.725672894260155,-0.9814507048324065,-0.012483836815369465
51.20000000000002,11.539415630624246,-0.8943867064107717,-0.012065554056052363
52.400000000000034,12.08009518641937,-0.857919099545312,-0.012922742036822754
53.60000000000005,12.557023321238237,-0.840095085279656,-0.011628470444160932
54.80000000000007,13.018025753778593,-0.8290304471366704,-0.01285687615062514
56.000000000000085,13.464561135508621,-0.8201020187148556,-0.013167212585047494
57.2000000000001,13.89892321659394,-0.812352159127008,-0.012180457545754919
58.40000000000012,14.339524174026318,-0.8042999547696527,-0.012699924199330859
59.600000000000136,14.766282169368296,-0.7970204797293318,-0.011851539369157393
60.80000000000015,15.185104917064015,-0.7909802202214415,-0.014149486751085405
62.00000000000017,15.59570861168775,-0.7835462568446953,-0.014463125277610622
63.20000000000019,15.99490046061968,-0.7776709315969624,-0.01314813431727302
64.4000000000002,16.422841134119043,-0.7714673456291532,-0.013482490408088132
65.60000000000022,16.832605689002616,-0.7682859908988483,-0.012499840986094135
66.80000000000024,17.240285090426703,-0.7633452313265937,-0.013165800553641915
68.00000000000026,17.645905602865493,-0.7567136638843642,-0.01341576563013458
69.20000000000027,18.04969720333671,-0.7522264773643932,-0.014150686686958736
70.40000000000029,18.45415707102118,-0.7482199189030267,-0.014152650003222966
71.6000000000003,18.863049277298593,-0.7441320953886758,-0.014149722323167246
72.80000000000032,19.267259882848812,-0.7395886843125162,-0.011772528104169844
74.00000000000034,19.67094087667695,-0.7364430767289376,-0.01488777452903367
75.20000000000036,20.08222608333392,-0.7307034914323267,-0.014049909466375077
76.40000000000038,20.484793062819197,-0.7260089754566789,-0.012746452027439403
77.60000000000039,20.879709267422584,-0.7210032549805294,-0.013716244779014453
78.80000000000041,21.28982363115401,-0.7159731638462826,-0.01502012877620551
80.00000000000043,21.68868381795641,-0.7101069076314944,-0.01478743753918188
81.20000000000044,22.093515101366123,-0.706705323862401,-0.01535761751608522
82.40000000000046,22.490749679974876,-0.7031758667440096,-0.015019763760260929
83.60000000000048,22.89486463718409,-0.7006411527454075,-0.017660070011336515
84.8000000000005,23.297990820382342,-0.6959372253293612,-0.018517055604458932
86.00000000000051,23.698669531153307,-0.6892306066490103,-0.018058242678407055
87.20000000000053,24.10224799742074,-0.6864269318123613,-0.018969862073061172
88.40000000000055,24.511770833114785,-0.6826874638593377,-0.019303493002738925
89.60000000000056,24.914624184034466,-0.6783316374424034,-0.01864999040968751
90.80000000000058,25.29621043875456,-0.6728137755264444,-0.02024334253643989
92.0000000000006,25.71267317132399,-0.6674260634640031,-0.01864224793795799
93.20000000000061,26.104903792701773,-0.6648899675115024,-0.01854852068069146
94.40000000000063,26.502400851990455,-0.659965063928222,-0.01798955206344477
95.60000000000065,26.89963579036407,-0.6570112625352721,-0.01917513110576685
96.80000000000067,27.301610657878584,-0.6543016796529213,-0.018317878967295975
98.00000000000068,27.69843499815624,-0.6496254801561965,-0.017324776690228916
99.2000000000007,28.098979035105252,-0.6452163788338218,-0.018970484959015543
100.40000000000072,28.496653224913505,-0.6421049372141966,-0.01997010453432324
101.60000000000073,28.90154749068627,-0.6377071794378344,-0.019931988664825262
102.80000000000075,29.29604958767719,-0.6332033580818948,-0.01869632403427257
104.00000000000077,29.692658019863615,-0.6288235103989746,-0.019885773852711175
105.20000000000078,30.089986780157453,-0.6236204253433874,-0.02183514368570183
106.4000000000008,30.487363285015267,-0.6197962586662726,-0.020687236255913177
107.60000000000082,30.885962651330647,-0.6175536687844967,-0.02069942918033263
108.80000000000084,31.28442551327727,-0.6137739309831143,-0.021329035464717983
110.00000000000085,31.66913880998141,-0.6072506758340069,-0.02270334506814642
111.20000000000087,32.075574383261184,-0.6030052012467829,-0.021059068446143137
112.40000000000089,32.47171585943553,-0.5982021412059948,-0.021594373538630585
113.6000000000009,32.86555323811214,-0.596175960691667,-0.023483393237056838
114.80000000000092,33.26333961565294,-0.5910427945774603,-0.023595240899212833
116.00000000000094,33.661135132088404,-0.5843214451410448,-0.02259885065799594
117.20000000000095,34.052327872312645,-0.5804660695148803,-0.02348221618445212
118.40000000000097,34.45210277789928,-0.5750915798894035,-0.025595317181940302
119.60000000000099,34.84433075930409,-0.5720096253204214,-0.02816955894186357
120.800000000001,35.24918346115701,-0.5693718345409247,-0.02588326425104892
122.00000000000102,35.64012786926602,-0.5667513534840866,-0.02757269522158534
123.20000000000104,36.04294086635392,-0.5640610196883344,-0.025842977653439902
124.40000000000106,36.43615110200857,-0.5582543244391274,-0.027210149073481738
125.60000000000107,36.82820326881015,-0.5532540434634763,-0.02721159186256461
126.80000000000109,37.22251805768178,-0.5500151040677977,-0.029964398682478688
128.0000000000011,37.61757065042654,-0.5460756184862817,-0.02730499398519637
129.20000000000113,38.0101273927959,-0.5406285524103388,-0.028301370361956124
130.40000000000114,38.40799173068191,-0.5375069534665724,-0.028299880081077866
131.60000000000116,38.79725137724191,-0.5334252116106373,-0.027651391502015343
132.80000000000118,39.191939727130865,-0.5311260178384409,-0.028300108957034276
134.0000000000012,39.590747774956554,-0.5267149117951841,-0.027974916068997935
135.2000000000012,39.98407623638796,-0.5207643689971257,-0.027306985800922057
136.40000000000123,40.37812021563022,-0.5184752738459211,-0.027334790047246926
137.60000000000124,40.77061948649048,-0.5140561678464771,-0.027309418217590142
138.80000000000126,41.164767133047384,-0.5109200477028485,-0.02664246951274407
140.00000000000128,41.56182362951482,-0.5060194310510122,-0.027649891665106452
141.2000000000013,41.95961297357989,-0.5022308122339766,-0.025673167192748814
142.4000000000013,42.35378328167827,-0.49737050977418407,-0.02861975150179763
143.60000000000133,42.74454829308042,-0.491780671837236,-0.02796580679179783
144.80000000000135,43.133628849890094,-0.48773970760863516,-0.025649916456848665
146.00000000000136,43.52946586297883,-0.4829889189880651,-0.028966865496133032
147.20000000000138,43.92061402453337,-0.4788235075680162,-0.030278805796894126
148.4000000000014,44.31570732648371,-0.475723870247023,-0.029897749074939917
149.60000000000142,44.71106092231071,-0.471396928851692,-0.02961863071341231
150.80000000000143,45.104576979436374,-0.4655972060661599,-0.02895223986489448
152.00000000000145,45.50305198902535,-0.4636501393543862,-0.030178152911663148
153.20000000000147,45.89296640046978,-0.45637662066720375,-0.030270106432093158
154.40000000000148,46.28565907105858,-0.4503011208126014,-0.030272050577926812
155.6000000000015,46.6766819565662,-0.4453972932016399,-0.030736180859092244
156.80000000000152,47.066670000000464,-0.4359400000000477,-0.02995002659478896
158.00000000000153,47.4575827532886,-0.4316202404100653,-0.031919285874943526
159.20000000000155,47.84866164073875,-0.4251158366278782,-0.03060997698405643
160.40000000000157,48.24137783369087,-0.42023493586334965,-0.03356969203335414
161.6000000000016,48.63447599062522,-0.4135529662705638,-0.03357000000056498
162.8000000000016,49.02561356376724,-0.40704617115934977,-0.032250237158494954
164.00000000000162,49.420085627873114,-0.40013522141833696,-0.033563851090311125
165.20000000000164,49.81171795589481,-0.393466819860372,-0.03425866760248564
166.40000000000165,50.203314955234354,-0.38723646579519533,-0.034350598500982876
167.60000000000167,50.595064576288095,-0.38353042705373486,-0.03288749343548325
168.8000000000017,50.983235519097704,-0.3822200719355338,-0.03160020901938321
170.0000000000017,51.379590439972105,-0.3851851622963919,-0.032381402936297654
171.20000000000172,51.77493982754628,-0.3872312005300522,-0.03127011466596041
172.40000000000174,52.1618425816234,-0.38706084932100177,-0.03227050666380826
173.60000000000176,52.55341082842073,-0.38801294035872413,-0.031247093548317117
174.80000000000177,52.94905906915776,-0.38523579051748,-0.032250276598214
176.0000000000018,53.33395073575923,-0.38555378202326795,-0.03158985702606376
177.2000000000018,53.72556515064435,-0.38220101497107706,-0.03266067771705394
178.40000000000182,54.11949874832752,-0.37826733210745983,-0.03126571766552999
179.60000000000184,54.510299301300044,-0.37354690872883034,-0.032879762861656836
180.80000000000186,54.89589074544386,-0.37027490268291263,-0.03245143324611277
182.00000000000188,55.28657735433853,-0.3674207101794063,-0.03143280614935495
183.2000000000019,55.67632220423136,-0.36450480778636957,-0.03262974401914409
184.4000000000019,56.069612342257045,-0.3605052809940025,-0.03421981221392745
185.60000000000193,56.458982171200226,-0.35633170359240096,-0.03686668688666028
186.80000000000194,56.848571448937065,-0.35169101377987705,-0.03686011000000455
188.00000000000196,57.2394126479249,-0.3462285253287505,-0.035815111044284365
189.20000000000198,57.62665982466422,-0.3421597010176784,-0.03684126298407708
190.400000000002,58.017002246311385,-0.3375316175546109,-0.03752011982447723
191.600000000002,58.41136840780896,-0.333349383147839,-0.03619948509972737
192.80000000000203,58.79659706111436,-0.3321150340361826,-0.037508419383388336
194.00000000000205,59.192643585311,-0.3285161327664965,-0.03644567300279267
195.20000000000206,59.5823260997511,-0.322645454016678,-0.03619454937648037
196.40000000000208,59.96906271434787,-0.32003016104122456,-0.036200587869105405
197.6000000000021,60.364093501987924,-0.3152500768021114,-0.035869997917576946
198.80000000000211,60.75490060343162,-0.3121852738860723,-0.034570625341411976
200.00000000000213,61.147644949085816,-0.30790570123904076,-0.03310365920967939
201.20000000000215,61.53916622892454,-0.3057313723883647,-0.03521013652422056
202.40000000000217,61.936912625692955,-0.3018558755510541,-0.03631010892113373
203.60000000000218,62.32368702138227,-0.29640061960222425,-0.036094670745285384
204.8000000000022,62.714920992764945,-0.2894737767575748,-0.04527706402050846
206.00000000000222,63.10284451817253,-0.2855360072645033,-0.03586091821927262
207.20000000000223,63.48366381484805,-0.2815685482276824,-0.03825288084638423
208.40000000000225,63.87070535882739,-0.2760874684465242,-0.033335558920613906
209.60000000000227,64.25575661164149,-0.2734129108570956,-0.032426262091004965
210.80000000000229,64.63674880045544,-0.2658279551436424,-0.0400164830484675
212.0000000000023,65.0200251463408,-0.2642082285794866,-0.040479731433205934
213.20000000000232,65.40811999310107,-0.2597870677726935,-0.04255867230343657
214.40000000000234,65.79773252700848,-0.25341984666580336,-0.04342133296931028
215.60000000000235,66.18770735261954,-0.24209501548869466,-0.04235725571106652
216.80000000000237,66.58077891085469,-0.22301066008633708,-0.04587500818571044
218.0000000000024,66.97176409428984,-0.1921215126778168,-0.044386855711960216
219.2000000000024,67.36640062199086,-0.154454739869234,-0.04289247168623511
220.40000000000242,67.75411795492879,-0.13037429346668303,-0.047279580384539166
221.60000000000244,68.15673775785102,-0.12167047011538425,-0.04346219351240155
222.80000000000246,68.54333606064017,-0.12135366225425306,-0.04597011984201327
224.00000000000247,68.93850320933988,-0.1273661242391352,-0.04492742329309429
225.2000000000025,69.32895432682912,-0.14807069995974828,-0.046073399097148915
226.4000000000025,69.72115002116449,-0.17721611648879396,-0.045800316783100925
227.60000000000252,70.11075202336107,-0.197711401346746,-0.04618588016623093
228.80000000000254,70.50139816178458,-0.20701909025752493,-0.04617994977675188
230.00000000000256,70.88956476006818,-0.212621103399806,-0.047159953089455975
231.20000000000258,71.27814417521778,-0.21257908098926448,-0.04717610694958285
232.4000000000026,71.66606467202568,-0.2139958844524384,-0.0474849574818883
233.6000000000026,72.05564386661656,-0.2117423270877147,-0.046567421032945866
234.80000000000263,72.44521800169656,-0.20809473864716385,-0.04824654045065824
236.00000000000264,72.83819825795105,-0.20516626977464153,-0.048567352723997814
237.20000000000266,73.22414210447273,-0.20412961484146652,-0.04947017892119554
238.40000000000268,73.6220196976621,-0.20285637044832414,-0.05209481700995777
239.6000000000027,74.01700298927531,-0.19776087728295622,-0.05244813151120287
240.8000000000027,74.40629019736492,-0.1944435949933686,-0.05309021094470401
242.00000000000273,74.79614074382555,-0.1910473502395344,-0.05243002034618227
243.20000000000275,75.18163930519016,-0.18593844815398441,-0.05244004153190307
244.40000000000276,75.56816824821095,-0.18344278382293114,-0.05242041589790425
245.60000000000278,75.96141125312795,-0.18031644290128676,-0.0528643804360196
246.8000000000028,76.35259607065345,-0.17569377306540157,-0.05281453931572644
248.0000000000028,76.7343342210939,-0.17160148140489054,-0.05242991647834527
249.20000000000283,77.13119384442822,-0.17173962937204665,-0.05243109274484059
250.40000000000285,77.52321811721764,-0.16784448511768316,-0.052799971650472344
251.60000000000286,77.90960269885225,-0.16369353205560974,-0.05308997580932173
252.80000000000288,78.30000000000095,-0.16209000000000634,-0.05340974057881143
254.0000000000029,78.68557156836444,-0.15775888639632074,-0.054409184771790464
255.20000000000292,79.07850349707321,-0.15448109807494065,-0.052763253045982506
256.40000000000293,79.47013062839225,-0.1517565685961976,-0.05341967748086773
257.600000000003,79.85742603341187,-0.14929025010773417,-0.054251531891809535
258.80000000000297,80.24670616801377,-0.14506082042519397,-0.05342019724171099
260.00000000000296,80.63514098875946,-0.1415684979634274,-0.05404209184196285
261.200000000003,81.02331346494596,-0.1369582712477704,-0.05639153122994944
262.40000000000305,81.4113330591018,-0.13575028226660119,-0.056388231326200966
263.60000000000304,81.80509310461711,-0.1314233456402698,-0.05770416967116976
264.800000000003,82.1948410457572,-0.12701314638340513,-0.058689211913317774
266.00000000000307,82.58374035554736,-0.12530039238801804,-0.057699603812394695
267.2000000000031,82.97897526809179,-0.12179415739654072,-0.058661643197896574
268.4000000000031,83.37102354881178,-0.11844951034690984,-0.05835289324029702
269.6000000000031,83.75841504526738,-0.11466350897819622,-0.05900991502419117
270.80000000000314,84.15428773960348,-0.10971830236070809,-0.0590099142201872
272.0000000000032,84.54140135466439,-0.10587570673918575,-0.058022760800245266
273.2000000000032,84.93207974350604,-0.10344303421754598,-0.05938789408161904
274.40000000000316,85.31963684275422,-0.09941121595763401,-0.05704016140682411
275.6000000000032,85.71034736643873,-0.09721271977654632,-0.058359882591670686
276.80000000000325,86.10186773972097,-0.09311082999082307,-0.06098537471127674
278.00000000000324,86.4899365981035,-0.08760464017979545,-0.06229910363748958
279.20000000000323,86.87920481692984,-0.08586842370835208,-0.06230920273789042
280.4000000000033,87.27245722734942,-0.08029319510458159,-0.06296109788001791
281.6000000000033,87.66157529581545,-0.07903781625139585,-0.06494000543345724
282.8000000000033,88.05427270253156,-0.07625232403457766,-0.06693586786067529
284.0000000000033,88.44216535570663,-0.07271118071127287,-0.06887992225955264
285.20000000000334,88.83574398925877,-0.07065145670339294,-0.07052619201361665
286.4000000000034,89.21995830700078,-0.06377734545198112,-0.07183662479919173
287.6000000000034,89.60872923654243,-0.06019558072943864,-0.07346816793905298
288.80000000000337,90.00124634123091,-0.05773790517122853,-0.0738198649484949
290.0000000000034,90.38974035110097,-0.05193787141345801,-0.07382092824363173
291.20000000000346,90.78047780330323,-0.049439465568931265,-0.074479940369927
292.40000000000344,91.17034827682711,-0.045644985162834224,-0.07645983669029954
293.60000000000343,91.55919836460313,-0.03936035684703766,-0.07746810018250594
294.8000000000035,91.95403729013347,-0.03801780935962053,-0.07940068957728119
296.0000000000035,92.34506003430626,-0.03350486386518623,-0.08302371043373657
297.2000000000035,92.73929375746864,-0.02899246687185633,-0.08533753024271995
298.4000000000035,93.13262923224104,-0.026368001209335364,-0.08830030202203076
299.60000000000355,93.52557810658224,-0.021113649167600754,-0.0902791736330748
300.8000000000036,93.91737945032256,-0.01708424183822189,-0.09257978648857845
302.0000000000036,94.31055365133486,-0.016318790046494128,-0.09553014752005007
303.20000000000357,94.70455062914714,-0.013218913726175629,-0.09948674687228642
304.4000000000036,95.10103192207869,-0.009689178035676194,-0.10243978137373544
305.60000000000366,95.4901960953636,-0.0036533778712660755,-0.10642265321051969
306.80000000000365,95.88163294226571,0.003120593993212175,-0.11163302676914144
308.00000000000364,96.27304031602792,0.007436952399840761,-0.11679952012822037
309.2000000000037,96.66742935415128,0.010712771806886503,-0.12251861903067596
310.40000000000373,97.05945973665872,0.015486113203788539,-0.1278065972155833
311.6000000000037,97.45091958551279,0.020432703543431824,-0.13357304120421798
312.8000000000037,97.84429441136304,0.026229263229274057,-0.1395384928482546
314.00000000000375,98.23392890337593,0.03314967133274465,-0.1432800228856963
315.2000000000038,98.62731115243254,0.04098840457888177,-0.1487608411927117
316.4000000000038,99.01447437122235,0.043567907062741065,-0.1567093663504986
317.6000000000038,99.40997811570595,0.0511945853670796,-0.16440880993001228
318.8000000000038,99.80238663297662,0.058867973013275766,-0.17391330604478172
320.00000000000387,100.19868535819063,0.06409834908305899,-0.183262127483522
321.20000000000385,100.59321808601486,0.07249868615231721,-0.19484073983639183
322.40000000000384,100.98293530626216,0.07953252519099997,-0.205671999822171
323.6000000000039,101.36957343477185,0.08771926650843691,-0.21737091882911663
324.80000000000393,101.76115600427438,0.0951380101983529,-0.2291934755328855
326.0000000000039,102.15078515016626,0.10311382190862523,-0.24080399407659359
327.2000000000039,102.54636859172763,0.10915216958711464,-0.2538298187873207
328.40000000000396,102.94067608259589,0.11714882952568952,-0.26778150824278724
329.600000000004,103.33479384274627,0.12588923095303356,-0.282073124329413
330.800000000004,103.72575864011331,0.1322946782291945,-0.2980251037451467
332.000000000004,104.12238990484197,0.1392953916407809,-0.31591402309494665
333.200000000004,104.51308491088798,0.14516002526406674,-0.33290507377508227
334.40000000000407,104.90639727334647,0.15396238870201173,-0.35076588264938824
335.60000000000406,105.29820098613362,0.15940751142472429,-0.36769461914648227
336.80000000000405,105.69274982001431,0.16636842542803282,-0.38693668162435557
338.0000000000041,106.08503820815446,0.17458558328575674,-0.4063227247141121
339.20000000000414,106.48000668608125,0.18052489790992,-0.42733135636742103
340.4000000000041,106.87030158984896,0.19047858332578665,-0.447550498891502
341.6000000000041,107.2643654597638,0.19607716379964957,-0.4700225377490539
342.80000000000416,107.65599695127769,0.20329927162932832,-0.4932371086029015
344.0000000000042,108.0487329918873,0.20748964672320203,-0.5123811946436367
345.2000000000042,108.44501034046105,0.21264570074324102,-0.538409352591267
346.4000000000042,108.84138067920198,0.21995355888943685,-0.562892207172828
347.60000000000423,109.23368711234957,0.22562992680734445,-0.5867783199100649
348.8000000000043,109.62836038970445,0.2331752328034264,-0.61397397015303
350.00000000000426,110.02252057026055,0.23928600902487765,-0.6419006454231595
351.20000000000425,110.41451364931481,0.24653017460481896,-0.6686419749483368
352.4000000000043,110.81222829504937,0.25093419231328656,-0.6983209949304521
353.60000000000434,111.2084712833768,0.2602748542676103,-0.7277793874952789
354.80000000000433,111.60000325001518,0.2653996187640961,-0.7559600733924974
356.0000000000043,111.99227279084441,0.273133327463962,-0.7857730718301252
357.20000000000437,112.38474327806006,0.2768974524330959,-0.8156992497548905
358.4000000000044,112.77756727254052,0.280714627365576,-0.8461863066628763
359.6000000000044,113.16778638797736,0.2835344521190005,-0.8769853175420961
360.8000000000044,113.56300751563198,0.28526768487229753,-0.9105587420019301
362.00000000000443,113.95494320827619,0.28914788757390775,-0.9415729004368405
363.2000000000045,114.34706528261108,0.29135878833620726,-0.975056163016363
364.40000000000447,114.74205211216433,0.29037786300643564,-1.008528704490526
365.60000000000446,115.13756438905975,0.2895173539747076,-1.0409841284509311
366.8000000000045,115.529812549079,0.2910080596536984,-1.075102648471217
368.00000000000455,115.92192928814183,0.2889189807254591,-1.106414554205572
369.20000000000454,116.31435355448455,0.28210973146068063,-1.1356598609840818
370.4000000000045,116.71206708464857,0.27613739660959763,-1.1669963509723362
371.60000000000457,117.10891862631763,0.26978435761149655,-1.1950038427399492
372.8000000000046,117.50322622238198,0.26106339286305064,-1.2227220411141428
374.0000000000046,117.89722220803853,0.25070449925611193,-1.2496815737613458
375.2000000000046,118.29114220702274,0.24180676130943418,-1.2740575569755976
376.40000000000464,118.6887934130162,0.23405418319478538,-1.2945665756130884
377.6000000000047,119.07594136656526,0.22276244825006877,-1.3143163234411444
378.8000000000047,119.47254057158628,0.211857964007898,-1.3333235354853454
380.00000000000466,119.86667000000187,0.20359000000007899,-1.3482707815863417
381.2000000000047,120.25717656678783,0.19524955876543765,-1.3637080021832433
382.40000000000475,120.65282812557885,0.18986614309713945,-1.3753246038093296
383.60000000000474,121.04523877007466,0.18421708455933886,-1.386766192344603
384.80000000000473,121.44027583116245,0.18650568716097088,-1.3972955022919176
386.0000000000048,121.83551584876926,0.18528024636616516,-1.4082311219717862
387.2000000000048,122.22987447951965,0.1860077702884875,-1.417643748988735
388.4000000000048,122.62175824446554,0.18669578223422528,-1.4273863446529904
389.6000000000048,123.01994418610879,0.1922072835990249,-1.4377935951278342
390.80000000000484,123.41007500778446,0.19405330620089403,-1.447121891466384
392.0000000000049,123.8065953563633,0.19621140311760285,-1.4567575338734864
393.2000000000049,124.20030354517706,0.20169705100672408,-1.465531799400844
394.40000000000487,124.5960746275805,0.2006784697452545,-1.4736730863930014
395.6000000000049,124.99510588776789,0.20477298270310182,-1.4828256151100767
396.80000000000496,125.39124128696845,0.20704373627980965,-1.4928168486693476
398.00000000000495,125.78791686395182,0.21128113650871397,-1.500965494370519
399.20000000000493,126.18415720236405,0.21315831273511562,-1.51159028765731
400.400000000005,126.5820693217493,0.21919480692783727,-1.5191886472326082
401.600000000005,126.97859100937751,0.22286367215495662,-1.5265429502189907
402.800000000005,127.3682179489245,0.22761298231237811,-1.5351428730944354
404.000000000005,127.76520743237486,0.2300816147618624,-1.544055626095819
405.20000000000505,128.15937939399038,0.23241430436525637,-1.5542717919960678
406.4000000000051,128.5542605179882,0.23617419184855268,-1.5624961294988893
407.6000000000051,128.95193100971952,0.2379491231654974,-1.5718761572627873
408.80000000000507,129.34793272849694,0.24188157523697762,-1.5810986315464142
410.0000000000051,129.74369044766215,0.24740295593296296,-1.5913453596760125
411.20000000000516,130.14229313087856,0.25197362190451394,-1.6014202578419536
412.40000000000515,130.5366031455188,0.25445877632335046,-1.6091508057125434
413.60000000000514,130.9357807322098,0.26002288782184746,-1.6210973233218153
414.8000000000052,131.33144447526607,0.26372441653950557,-1.6303323849117488
416.00000000000523,131.7308455203199,0.2657500199153409,-1.6396052840663953
417.2000000000052,132.1283658521294,0.2682289725773056,-1.649521975770556
418.4000000000052,132.52763786365753,0.27407473679996386,-1.6600699424722443
419.60000000000525,132.9265977999986,0.2763331619041719,-1.670135100561546
420.8000000000053,133.3242102098187,0.281186134862162,-1.680307395863963
422.0000000000053,133.71825163944158,0.2852491387135259,-1.6913687373917923
423.2000000000053,134.11498960758556,0.2898985454654468,-1.7010613284087137
424.4000000000053,134.50902657942137,0.2939661726296483,-1.712628230187561
425.60000000000537,134.90450129972297,0.29942605327625943,-1.723846877587797
426.80000000000535,135.3000033415736,0.3029000015914684,-1.7358998559780066
428.00000000000534,135.69855646531826,0.30382196214449775,-1.7481858884022636
429.2000000000054,136.09591422236727,0.3101117654290647,-1.761271119201631
430.40000000000543,136.49210968894835,0.3137115874019017,-1.7732334237101508
431.6000000000054,136.89087084404383,0.31773550834436254,-1.7850800154289237
432.8000000000054,137.2924825159512,0.322138583472769,-1.7979949008190257
434.00000000000546,137.6909301374942,0.3276943241673657,-1.8116374688834296
435.2000000000055,138.08255780115746,0.33369443437749696,-1.8242529374950585
436.4000000000055,138.47628788123814,0.33638647272045125,-1.8378421365575885
437.6000000000055,138.87081135973636,0.3375649396485105,-1.8506274963178755
438.8000000000055,139.26865693134164,0.3403525154539896,-1.8654821318687347
440.00000000000557,139.66842755082735,0.3460404285277784,-1.8776920693673094
441.20000000000556,140.06450490536116,0.3504962329752955,-1.8934999808860815
442.40000000000555,140.4651911961441,0.3528518808154921,-1.9094709649726687
443.6000000000056,140.86252652761164,0.3534709231414437,-1.9243124434334353
444.80000000000564,141.25892185607677,0.35814089608064986,-1.9388144273311867
446.0000000000056,141.65676276667585,0.35832988847101227,-1.9530229001412578
447.2000000000056,142.05796981435086,0.35802395958554445,-1.968383693340026
448.40000000000566,142.45852069013088,0.3567413265348666,-1.980017590767444
449.6000000000057,142.8490452284849,0.3557658100726504,-1.9930599764857164
450.8000000000057,143.24693767596617,0.35403758436854615,-2.00236759872879
452.0000000000057,143.6455044440954,0.3502153636403251,-2.011620622447139
453.20000000000573,144.04149454238663,0.34417405328426215,-2.0182241182864007
454.4000000000058,144.44281278155202,0.3433890839672752,-2.0231696762533695
455.60000000000576,144.83756935509146,0.34067817811688433,-2.0250989991306185
456.80000000000575,145.2374666613645,0.34206785814880175,-2.0271037823432145
458.0000000000058,145.6375232617266,0.34574282054468475,-2.0297308631482656
459.20000000000584,146.035059530309,0.3486950788748606,-2.0300702209524473
460.40000000000583,146.43333342090682,0.3596203455400643,-2.031719889569673
461.6000000000058,146.83079610646053,0.37036652459291,-2.0313922384585763
462.80000000000587,147.22678887967695,0.3787961760180364,-2.029773492744347
464.0000000000059,147.62406982938003,0.3827314863789818,-2.0323698548232616
465.2000000000059,148.0239701245243,0.3856332330265437,-2.0330253791435005
466.4000000000059,148.41967095629167,0.3851423234995264,-2.0353493978555277
467.60000000000593,148.82292841873567,0.386522579676869,-2.0357104123995033
468.800000000006,149.22145226821362,0.3853761400033472,-2.036313971706709
470.00000000000597,149.62019924740036,0.3857948181271615,-2.0377436727777254
471.20000000000596,150.02415573163873,0.38352365153137474,-2.0390057757754634
472.400000000006,150.4187588234188,0.3817235079436101,-2.039289880638287
473.60000000000605,150.81357276777203,0.38267938945773006,-2.039289853172852
474.80000000000604,151.20842199653015,0.38057625714071575,-2.0406074496293902
476.000000000006,151.6085671065827,0.3819229632439,-2.041593020364947
477.20000000000607,152.01298940916007,0.38286023411316833,-2.0403487248112055
478.4000000000061,152.41378050207743,0.380499868420713,-2.0405979808621515
479.6000000000061,152.81570647025836,0.3826535396671838,-2.0414480222490825
480.8000000000061,153.21873707260133,0.3812638406353808,-2.042254170291995
482.00000000000614,153.61771183019516,0.38170080777470305,-2.042250154999999
483.2000000000062,154.0170462987885,0.3849192782916119,-2.0425797552306446
484.4000000000062,154.41432044544615,0.38976905647288285,-2.044878587807311
485.60000000000616,154.81475706349218,0.39733967866266523,-2.0442361696725384
486.8000000000062,155.21667356170775,0.3997597606661875,-2.0452098756784123
488.00000000000625,155.61292438510537,0.4049542108592217,-2.0445498949396574
489.20000000000624,156.01597744029186,0.4113053921826787,-2.044879969999079
490.40000000000623,156.4148115331858,0.41798289571429526,-2.0448779874183916
491.6000000000063,156.81129744382767,0.4226123817415325,-2.045941967228017
492.8000000000063,157.21147342589023,0.42846194647459096,-2.0460142539029618
494.0000000000063,157.60927601692185,0.43486489846527704,-2.0465277138531413
495.2000000000063,158.01267404596277,0.44253898547132803,-2.04586740321702
496.40000000000634,158.41044832495234,0.44733100186902586,-2.0470474831918675
497.6000000000064,158.809867080282,0.4523961404471485,-2.0468385762948156
498.8000000000064,159.20833892087504,0.46048759204569706,-2.0464388241012346
500.00000000000637,159.61295894082372,0.46563481861236766,-2.0472001165853375
501.2000000000064,160.01029194031594,0.4708710346416251,-2.047427911673582
502.40000000000646,160.40810873127327,0.47631940008443274,-2.047509515039445
503.60000000000645,160.79843787685334,0.483531118356801,-2.047513664031278
504.80000000000643,161.2103514387654,0.4860373285831457,-2.0478499120149203
506.0000000000065,161.61129029622768,0.49079992213567813,-2.047850875787742
507.2000000000065,162.01339012297115,0.49736029362297457,-2.044151593591606
508.4000000000065,162.41098132320454,0.5033913257914562,-2.050183362707483
509.6000000000065,162.81399241735565,0.5065258921959425,-2.049441633204056
510.80000000000655,163.21240047475519,0.5129469813061461,-2.0474620427630987
512.0000000000066,163.61417773288827,0.5157041305549458,-2.050858987080681
513.2000000000066,164.01851114453893,0.5195207247200213,-2.050755212614437
514.4000000000066,164.4119797047723,0.5275314006799937,-2.0521097492186224
515.6000000000066,164.81088957039614,0.5304886120653879,-2.0491592335063133
516.8000000000067,165.2131874309391,0.5354757469175211,-2.051455204540688
518.0000000000066,165.61130570763842,0.5413514711259322,-2.0517519617240705
519.2000000000066,166.01487428466984,0.5460237592443368,-2.0521198949999993
520.4000000000067,166.41435244203467,0.5508687337809111,-2.050773574997665
521.6000000000067,166.81993563119732,0.5567132505099176,-2.054434492139567
522.8000000000068,167.22587677718573,0.5633574718243022,-2.0531101950000004
524.0000000000067,167.6262912198607,0.5640956307003595,-2.0531101947932826
525.2000000000068,168.0288961602169,0.5711954686502989,-2.053128285095922
526.4000000000068,168.42937766598678,0.5769716538736034,-2.052406750346387
527.6000000000067,168.83242670283153,0.5821258318667771,-2.051789528103459
528.8000000000068,169.22793583842224,0.5891455753024895,-2.052450049668856
530.0000000000068,169.62851635170975,0.5914159107386667,-2.0519404902908245
531.2000000000069,170.0283264713328,0.5959648873166525,-2.0535612072820895
532.4000000000069,170.42993310946648,0.6022168953520102,-2.054750189828484
533.6000000000068,170.83175317249473,0.6086164924659916,-2.0558237826770025
534.8000000000069,171.23485369477817,0.6125400518644575,-2.0564407764102506
536.0000000000069,171.63777814935187,0.6189581254456964,-2.0565101473510143
537.2000000000069,172.0380795822187,0.6249539729518923,-2.057819646279869
538.4000000000069,172.43781245932166,0.6281519437498446,-2.0572220648643147
539.600000000007,172.843946022079,0.634478051190149,-2.055850827299718
540.800000000007,173.2415065719292,0.6400092591136911,-2.0561665944523666
542.000000000007,173.6438476454556,0.6440213579524949,-2.0572305063846006
543.200000000007,174.04664048645068,0.651882798713901,-2.0577593443768425
544.400000000007,174.44860541066475,0.6546871431046072,-2.0592107197609626
545.6000000000071,174.84666969727067,0.6621755058744447,-2.059140155000008
546.800000000007,175.24824652899068,0.6641877104416789,-2.0591400542033815
548.000000000007,175.65100695633575,0.670138489450696,-2.0611200954506823
549.2000000000071,176.05478610234863,0.674843248127169,-2.061120604354064
550.4000000000071,176.45850284370113,0.6819245475669142,-2.061109511201092
551.6000000000072,176.8602249005049,0.6873775813067561,-2.06077956272311
552.8000000000071,177.2613208702231,0.6921186548442946,-2.0621506576206015
554.0000000000072,177.66127769993585,0.6949542068528677,-2.062100057674198
555.2000000000072,178.0663165280412,0.7003215963185366,-2.0621035083240584
556.4000000000071,178.4686888948852,0.7087084250572213,-2.063191964635494
557.6000000000072,178.8686544043843,0.7126857948375304,-2.0634510283903666
558.8000000000072,179.2681153293042,0.7201949475655917,-2.0624301949999886
560.0000000000073,179.6740694270339,0.7242279845999683,-2.062430349591497
561.2000000000073,180.07663406378623,0.7284040936482066,-2.0636573728769196
562.4000000000073,180.47598385066382,0.7339626349327693,-2.064730178977164
563.6000000000073,180.88226899088798,0.7400524135830343,-2.065039102123044
564.8000000000073,181.28511619336004,0.7437684617164482,-2.063348568303379
566.0000000000073,181.6870485482265,0.7523887288163079,-2.0653903669174225
567.2000000000073,182.0853109379499,0.757692543134464,-2.0660625348320867
568.4000000000074,182.48824165924086,0.7662370048952464,-2.066049481768606
569.6000000000074,182.89369580140286,0.7728998304819287,-2.0667914432579653
570.8000000000075,183.29922361853622,0.7791176537199571,-2.0667100049296563
572.0000000000074,183.70182236351755,0.7857385384825237,-2.067697471355272
573.2000000000074,184.105710529441,0.791373204263296,-2.067930207015668
574.4000000000075,184.50136331634508,0.7980304181218887,-2.069020458548901
575.6000000000074,184.9066104806762,0.8041901870595481,-2.0709807956368067
576.8000000000075,185.3044056415125,0.8086459121497382,-2.0703259745872478
578.0000000000075,185.70747307927485,0.8144561577986763,-2.0716501947779973
579.2000000000075,186.11469154673134,0.8201405545024443,-2.072936077369469
580.4000000000076,186.51439720734328,0.8270299320038313,-2.0722624945445416
581.6000000000075,186.9200406513558,0.8325911805785755,-2.0742747046426544
582.8000000000076,187.32210674528412,0.8414079007527528,-2.07600399978572
584.0000000000076,187.7257081735221,0.8456342449334947,-2.0763275163419315
585.2000000000075,188.12765193044405,0.8553553729662666,-2.0772391526732585
586.4000000000076,188.52868092952676,0.8602489941910003,-2.078554483812044
587.6000000000076,188.93229391919328,0.8687847138953276,-2.0812736106870386
588.8000000000077,189.33909981912836,0.8755831648018548,-2.078550503887649
590.0000000000077,189.73945589958535,0.8815637443813464,-2.080221997599949
591.2000000000077,190.1426027031649,0.8876691673146605,-2.081515129679027
592.4000000000077,190.5496339157723,0.8955698854774488,-2.082825594461405
593.6000000000078,190.95160281050443,0.9013510961317357,-2.083822734966245
594.8000000000077,191.35603004353516,0.9097978881763286,-2.086111323118801
596.0000000000077,191.75950408020032,0.9157529484615364,-2.0890876740334816
597.2000000000078,192.16524235840984,0.9243733157183746,-2.0917035260441232
598.4000000000078,192.57356136275388,0.9340443066101191,-2.0930301898378847
599.6000000000079,192.9734367525252,0.9419395471633693,-2.0943110252739903
600.8000000000078,193.37612162072207,0.9488727780557772,-2.097971213908523
602.0000000000078,193.77979498308983,0.9566731106194818,-2.0970208301352256
603.2000000000079,194.18372826824537,0.9614685013231641,-2.0983129708494883
604.4000000000078,194.58899280145675,0.972116356344594,-2.1022645698949534
605.6000000000079,194.99168551898197,0.9811323897156973,-2.103402830598477
606.8000000000079,195.39698647312665,0.9925237029812987,-2.104856465212947
608.000000000008,195.79781036710497,0.9959266341506621,-2.1070868627082757
609.200000000008,196.2034334110753,1.0060233177556825,-2.1088122880282247
610.4000000000079,196.60935505707968,1.0139929625268056,-2.112821659281641
611.600000000008,197.01251270285704,1.0239373707008246,-2.116049445753972
612.800000000008,197.4132558922053,1.036533573459117,-2.1199343900744134
614.000000000008,197.81696604602013,1.0449579345555742,-2.1229705591727557
615.200000000008,198.21630469834062,1.0544400056711312,-2.126930594591161
616.400000000008,198.6230233201667,1.0651015052124,-2.1292023249368928
617.6000000000081,199.02222753458656,1.0713682928382517,-2.132018335507456
618.8000000000081,199.4247725772047,1.0831014255435758,-2.1347799837194676
620.0000000000081,199.8233494114465,1.0949224462304294,-2.1384393864933307
621.2000000000081,200.23257220672815,1.1000231053021907,-2.141059529461869
622.4000000000082,200.63461541511418,1.112400451913124,-2.142696075355552
623.6000000000081,201.03793790044693,1.1229340857796515,-2.147667894085324
624.8000000000081,201.44235219797304,1.13216426117073,-2.1513529390103514
626.0000000000082,201.8491826629761,1.143158024009329,-2.155312390338353
627.2000000000082,202.25833635687235,1.1529330906107045,-2.1598089964458937
628.4000000000083,202.66163727581636,1.1631833658483688,-2.1621570811954083
629.6000000000082,203.06631945169028,1.1748200316590067,-2.167276008338693
630.8000000000083,203.468129376324,1.1871647193207973,-2.17278213159603
632.0000000000083,203.8687545917384,1.1991271160512635,-2.179425585540276
633.2000000000082,204.27193279190982,1.21254193381673,-2.184622062701469
634.4000000000083,204.6772008819754,1.2229888049519961,-2.1908646194237797
635.6000000000083,205.08238958223725,1.2343446422101576,-2.1961337339353766
636.8000000000084,205.48820219326737,1.24976941922432,-2.2020513299849624
638.0000000000084,205.8904708573516,1.2612457674388426,-2.2080087708601086
639.2000000000083,206.29780685397597,1.273896956507263,-2.2144248698967197
640.4000000000084,206.70714261109026,1.2883344871240785,-2.22035285570903
641.6000000000084,207.10813045915157,1.3042597389225679,-2.228964602375579
642.8000000000084,207.5105502273336,1.3172747532789324,-2.2359785281072653
644.0000000000084,207.91085311079328,1.3330965069205585,-2.2432310908344304
645.2000000000085,208.31432661040134,1.3463496067610785,-2.2506775760419804
646.4000000000085,208.71973843128228,1.3647269153220867,-2.2574416617924005
647.6000000000085,209.12151117274036,1.3818319323765549,-2.2668965087480215
648.8000000000085,209.52754313050218,1.398374699227147,-2.2734163496162547
650.0000000000085,209.9357242904615,1.4134694621300794,-2.2828756028712047
651.2000000000086,210.34405668646298,1.430741633692738,-2.2917856392429106
652.4000000000085,210.74867642717155,1.4497669730242206,-2.30208487576672
653.6000000000085,211.15675450826205,1.4663098759453121,-2.3112979813319257
654.8000000000086,211.55946413502028,1.485289885273894,-2.322951491718434
656.0000000000086,211.96609163983146,1.5048746060770422,-2.3338651030278292
657.2000000000087,212.3686221328339,1.5257167011046735,-2.345411791339129
658.4000000000086,212.77066911257918,1.5488142182350098,-2.357431677246006
659.6000000000087,213.1769935644001,1.5679657187720433,-2.3704153587667225
660.8000000000087,213.58155844622638,1.5924569934011825,-2.3817178247175663
662.0000000000086,213.98841629664162,1.6156471799518726,-2.3946072432908814
663.2000000000087,214.39238739287197,1.6374278833155977,-2.4046492442250154
664.4000000000087,214.80074190870388,1.6614162284405096,-2.4186071108533245
665.6000000000088,215.19795757201814,1.6852972535114086,-2.4306149125528
666.8000000000088,215.60837102334943,1.712290203034501,-2.4448719812973287
668.0000000000088,216.01263886353732,1.7326626548262232,-2.4594635208695683
669.2000000000088,216.41584237737814,1.758406604932274,-2.473766141539576
670.4000000000088,216.8271189561707,1.7803261509257062,-2.489206419219796
671.6000000000088,217.22939423348993,1.8014316047168042,-2.5061600843984424
672.8000000000088,217.63800344681428,1.8253696160797026,-2.5220178310992214
674.0000000000089,218.0393891360492,1.8460133602063367,-2.5399771875441353
675.2000000000089,218.44458631389432,1.8654209765371963,-2.55437141226178
676.400000000009,218.85077191902153,1.885530018788114,-2.5724115248680466
677.6000000000089,219.2578916158927,1.9035041717814811,-2.588117063361821
678.8000000000089,219.66028190467466,1.924812906400725,-2.606987966907455
680.000000000009,220.06304467718533,1.9440348723179366,-2.6237912052989483
681.2000000000089,220.46872584722635,1.9576077576053224,-2.6417823323697673
682.400000000009,220.87425890536775,1.9774751592802429,-2.6607783731515733
683.600000000009,221.28171768063783,1.989902900595673,-2.6789690206360355
684.800000000009,221.68514610364062,2.0062222802996694,-2.6979287424329197
686.0000000000091,222.09144730661757,2.020626346950997,-2.7162598195789274
687.200000000009,222.49788919852904,2.0336910284746668,-2.735322633238871
688.4000000000091,222.90262909229793,2.0406473171658015,-2.7538083656389007
689.6000000000091,223.30512780029508,2.0503188714408402,-2.7709182344556513
690.800000000009,223.7093077160626,2.050803471014281,-2.7905229443722033
692.0000000000091,224.1196292114675,2.0480213292105804,-2.8099588500117383
693.2000000000091,224.52655468843903,2.0398000224111943,-2.829819560491326
694.4000000000092,224.92933936277953,2.0188501770529306,-2.849376304185868
695.6000000000092,225.33730417023332,1.9780491984660717,-2.8645473765565836
696.8000000000092,225.73996608656793,1.9037723981989123,-2.882114225411944
698.0000000000092,226.14589971811753,1.7540700962163196,-2.8939428575290664
699.2000000000093,226.55165501678533,1.5134170036739492,-2.9007897778649285
700.4000000000092,226.96385972799635,1.4214809910704758,-2.903009974051507
701.6000000000092,227.36783292094685,1.4176227668837325,-2.9032899250092887
702.8000000000093,227.77598594890986,1.4221530328781848,-2.9036224382613685
704.0000000000093,228.17064682744154,1.4322625828025182,-2.904600666283417
705.2000000000094,228.58584818294833,1.4391825554846391,-2.9046000999999997
706.4000000000093,228.99114052180468,1.4457478640894532,-2.904600099844601
707.6000000000093,229.4036741049096,1.453069481601634,-2.9052598317354237
708.8000000000094,229.8103964637663,1.4626435096834336,-2.9039399503640215
710.0000000000093,230.21303255630153,1.4709443137826008,-2.9035901538308115
711.2000000000094,230.61752561162146,1.4763705989109788,-2.9038927420070055
712.4000000000094,231.01852187760073,1.4874904456311706,-2.902619949975698
713.6000000000095,231.4231366607027,1.495495742712835,-2.901316893277654
714.8000000000095,231.82530180569108,1.5039700024335998,-2.9010004703477925
716.0000000000094,232.23685248388784,1.5110835737350128,-2.9013064601040233
717.2000000000095,232.6478384733073,1.5181590764641577,-2.902882498180226
718.4000000000095,233.05396057537186,1.524504641631135,-2.9029603297634825
719.6000000000095,233.46437977267476,1.5352840378557848,-2.9046018492218195
720.8000000000095,233.86965567477668,1.5429922782728818,-2.902540369526206
722.0000000000095,234.27152476915091,1.5505544352152845,-2.9039489027653063
723.2000000000096,234.67980251350994,1.5595953683528965,-2.9048431535578576
724.4000000000096,235.0836920103117,1.570828204736249,-2.9075721874090976
725.6000000000096,235.48721080095626,1.579625673845876,-2.9064158291690996
726.8000000000096,235.89071442686054,1.5879171253975406,-2.909534431745878
728.0000000000097,236.30465480621268,1.602385081563528,-2.91018649686923
729.2000000000096,236.7084383524019,1.6061670667324972,-2.910348508577057
730.4000000000096,237.11448897537733,1.6176309321039695,-2.910850026340724
731.6000000000097,237.52360442108233,1.6210277766698162,-2.912587762269048
732.8000000000097,237.9271896802723,1.6326264201351928,-2.9112896758924887
734.0000000000098,238.33755506937123,1.6413337889400863,-2.9084098831795453
735.2000000000097,238.7433603817199,1.6494332974699366,-2.9095263991318365
736.4000000000098,239.15366357138245,1.654957091991335,-2.9086004306250706
737.6000000000098,239.5562445568175,1.66549309515367,-2.907556481869368
738.8000000000097,239.9606112051562,1.6770071668950137,-2.9078897258998824
740.0000000000098,240.36404739955128,1.6878926287071463,-2.909200024863643
741.2000000000098,240.76666590679366,1.6978000126649897,-2.9072622092520235
742.4000000000099,241.17427530229907,1.7086972664192415,-2.9085523295385225
743.6000000000099,241.58574661054618,1.7139710865972848,-2.910530232371765
744.8000000000098,241.98990460007425,1.7256857788641768,-2.909963763582371
746.0000000000099,242.39639986859834,1.7346275811547323,-2.9121691190725625
747.2000000000099,242.80273862924528,1.7416443227772116,-2.9111869109051898
748.4000000000099,243.20190730731497,1.7520857792694304,-2.9099589571172695
749.6000000000099,243.6033913971712,1.7588684259004577,-2.9105534600304503
750.80000000001,244.01515358099024,1.7674557108466262,-2.909215284992716
752.00000000001,244.42589381307639,1.7728983737750326,-2.9079192376951393
753.20000000001,244.83258375033873,1.7823529440092571,-2.9091378334749702
754.40000000001,245.2394170741338,1.7927102384181497,-2.908283008878568
755.60000000001,245.64463148252975,1.80318968821959,-2.9085987420679147
756.8000000000101,246.0452635736163,1.8134294072355768,-2.9088799228275
758.00000000001,246.45031921843213,1.8196267808251367,-2.9102110915800847
759.20000000001,246.85606497559243,1.8341142817965028,-2.9111808057291277
760.4000000000101,247.25240349109447,1.843415456250198,-2.911185197167173
761.6000000000101,247.6771556228624,1.8528644516689035,-2.912500128835438
762.8000000000102,248.08175572160852,1.864772268750427,-2.9128196165512645
764.0000000000101,248.49083554438064,1.8762946075724964,-2.913273852952717
765.2000000000102,248.8980677661616,1.8895936868745864,-2.913820249608336
766.4000000000102,249.3032808451263,1.8962272870962675,-2.9150042892454238
767.6000000000101,249.7053692316776,1.906396110528479,-2.9161185445964604
768.8000000000102,250.1079823883755,1.9180766075003457,-2.915868342319106
770.0000000000102,250.51667000000376,1.9274900000000947,-2.916439859303156
771.2000000000103,250.9240696275907,1.9415334859127935,-2.915460743752053
772.4000000000103,251.3348418867393,1.9509101161414002,-2.9158038865577227
773.6000000000103,251.73849152003996,1.9613929016052647,-2.9157738141172684
774.8000000000103,252.14756159609018,1.9713039184813144,-2.9170998051198476
776.0000000000103,252.55470734242724,1.9849205988801444,-2.9184201057823316
777.2000000000103,252.95973257849204,1.9956051034584796,-2.918419922617163
778.4000000000103,253.3677134140595,2.004009066643878,-2.916439823256946
779.6000000000104,253.77061560628684,2.016507904553106,-2.9161108647272203
780.8000000000104,254.1790467596487,2.023097689296006,-2.917153311802603
782.0000000000105,254.59177471404104,2.0283357836899056,-2.9162147118800705
783.2000000000104,254.99236374526285,2.0409472073282573,-2.913810006177938
784.4000000000104,255.39874378165598,2.052963104407418,-2.9138098399980192
785.6000000000105,255.80636600745632,2.0620253504903707,-2.9125024164095783
786.8000000000104,256.21563110419106,2.0680402543094534,-2.9143955272311226
788.0000000000105,256.624793295162,2.0800875676139285,-2.9164494482228003
789.2000000000105,257.02922681542947,2.0933505560544696,-2.9153167847875894
790.4000000000106,257.4388960812956,2.11001074857877,-2.91810146248016
791.6000000000106,257.84362507798187,2.114053485235673,-2.9193749862752387
792.8000000000105,258.24676348173426,2.1280590588403534,-2.9197347833640714
794.0000000000106,258.65426716705383,2.1448103673658836,-2.921677334249287
795.2000000000106,259.0624713522859,2.1551673089103165,-2.9221257977455863
796.4000000000106,259.4642806551257,2.165283842171345,-2.9200610024631546
797.0000000000106,259.66773825760527,2.17218818576708,-2.9210496342023524