File: 01_Data/Rug_Pad/STA/N2/10K_min/Rug_Pad_STA_N2_10KData_221025_R3.csv
##Temp./Â°C,Time/min,DSC/(mW/mg),Mass loss/mg
51.0,10.707199887509569,-1.639104263577482,-0.01602628116119753
52.100000000000016,11.108489617138899,-1.5101671270509507,-0.013201877202257073
53.20000000000003,11.361855437676677,-1.4283173557450264,-0.013556435467716454
54.30000000000005,11.572383215306337,-1.3659370924847447,-0.013311296440353004
55.40000000000006,11.758887290404738,-1.3173220619778072,-0.014428175101047103
56.50000000000008,11.930731882403395,-1.2778776695549667,-0.013340490320887355
57.600000000000094,12.092574939360228,-1.244799973070965,-0.01322518289919472
58.70000000000011,12.249869648899056,-1.2176011476708188,-0.013505379250570826
59.800000000000125,12.40095785763795,-1.195323826119569,-0.013416108884825917
60.90000000000014,12.545695866566026,-1.1747070786932041,-0.01268369733808239
62.000000000000156,12.68815432690021,-1.1581766536710274,-0.013278142999197051
63.10000000000017,12.827242557235566,-1.1401528632496982,-0.014517591224874948
64.20000000000019,12.965620932546175,-1.1239954578227203,-0.01518660173574915
65.30000000000021,13.102860666404649,-1.1079909241884733,-0.01403657358544308
66.40000000000022,13.232444816485865,-1.0962766585674733,-0.01467497517434957
67.50000000000023,13.365398945631012,-1.0812980164615846,-0.01503233530362369
68.60000000000025,13.493914717323243,-1.070600461183547,-0.015378418831331508
69.70000000000027,13.624353322863126,-1.058570108314226,-0.01580814935582442
70.80000000000028,13.752585434444864,-1.045032611327143,-0.015591181452192515
71.90000000000029,13.87701756816816,-1.033926515840487,-0.015544895072681975
73.00000000000031,14.001010659849564,-1.0228204665695628,-0.015601021434203055
74.10000000000034,14.124701376699587,-1.0100950035705676,-0.015591469321656781
75.20000000000034,14.247645015446675,-1.0020587513191295,-0.01589343349680572
76.30000000000035,14.370774565928654,-0.9920035719676594,-0.01650511764703655
77.40000000000038,14.490348481846137,-0.9815430844742749,-0.016935436336540377
78.5000000000004,14.611296108933256,-0.9726534515397274,-0.018151505928344136
79.6000000000004,14.728995078913812,-0.964526840383275,-0.01750668016839274
80.70000000000041,14.848783500075836,-0.9551702654061647,-0.018322648750110915
81.80000000000044,14.96638759461837,-0.9470935726010179,-0.018005965518738343
82.90000000000046,15.082571513645648,-0.9389818014114139,-0.016917099316827944
84.00000000000047,15.200107858772304,-0.9309865642294978,-0.018335649106035135
85.10000000000048,15.315144115325806,-0.9237014097689951,-0.018316959809780542
86.2000000000005,15.43095290549243,-0.9167829919383341,-0.017024158798417233
87.30000000000052,15.544101865634833,-0.9094852259176259,-0.018372354602265162
88.40000000000053,15.658573562038798,-0.9010943755237802,-0.01833306686997993
89.50000000000054,15.769416215772189,-0.8942566866378686,-0.01834090607681471
90.60000000000056,15.884639195727065,-0.8880394456037618,-0.01965155096083393
91.70000000000059,15.9985319622923,-0.8808639405603274,-0.01844979600148733
92.8000000000006,16.10989745096459,-0.8754781992752815,-0.019652902377698567
93.9000000000006,16.21969707902299,-0.8683011298236867,-0.0196520347704352
95.00000000000063,16.3324981954855,-0.8622817950226602,-0.0209797786517516
96.10000000000065,16.44281791681916,-0.8565482158398159,-0.019658709384968276
97.20000000000066,16.552760416128137,-0.8500443921554801,-0.01964537753036666
98.30000000000067,16.663692650963423,-0.8433928566991192,-0.019329814240435006
99.40000000000069,16.77253793846221,-0.8373772095495365,-0.01964472480725732
100.50000000000071,16.878819006625108,-0.8315548741523298,-0.01967991180098405
101.60000000000072,16.99202687938941,-0.8249136695667627,-0.01959940374248248
102.70000000000073,17.100098333412987,-0.8189003074772586,-0.019660853696092495
103.80000000000075,17.20978614227861,-0.8130202078123981,-0.020955413573096493
104.90000000000077,17.31864522840939,-0.8078602173955305,-0.020966544932366382
106.00000000000078,17.42655768865511,-0.8025599971533905,-0.020982590813527047
107.10000000000079,17.533188732897955,-0.7968678186490951,-0.020988179842990284
108.20000000000081,17.64294682460294,-0.7914150900157895,-0.022290070893975056
109.30000000000084,17.75130782645263,-0.7837670556697314,-0.022272314203499732
110.40000000000084,17.85646448761261,-0.7793818215785162,-0.020967667472663543
111.50000000000085,17.967698751582052,-0.7728357698263573,-0.021113641187533005
112.60000000000088,18.07586270862487,-0.7698146722392711,-0.022290570933047427
113.7000000000009,18.183268449769603,-0.7628374494686251,-0.021644704108206625
114.8000000000009,18.2900000000001,-0.757750000000002,-0.023603333339592858
115.90000000000092,18.39807468241024,-0.7522862751849075,-0.022693341420558788
117.00000000000094,18.506373562224148,-0.7483192485818463,-0.02229826489331721
118.10000000000096,18.613454897217633,-0.742433529817511,-0.022290149160380857
119.20000000000097,18.72061101650866,-0.7386279881530268,-0.020976398919061445
120.30000000000098,18.827080362422148,-0.7345579734323981,-0.022288366723979713
121.400000000001,18.93435174171832,-0.7290253084626274,-0.02360989291833704
122.50000000000102,19.040426443625577,-0.725243689805874,-0.022290098478416454
123.60000000000103,19.149097223443018,-0.7190363888919996,-0.02225480989227613
124.70000000000104,19.255753724564034,-0.7150606068924439,-0.02230012224689837
125.80000000000106,19.3609407874796,-0.7111489284933881,-0.023598615503292564
126.90000000000109,19.466761799701874,-0.7056363004164456,-0.02360991587041994
128.00000000000108,19.57273660289004,-0.7011499355182258,-0.02222166690086702
129.1000000000011,19.67685192931757,-0.695414721001733,-0.022218961811885762
130.20000000000113,19.785341362501583,-0.6909696654846575,-0.024526190668469283
131.30000000000115,19.892738851713595,-0.6860056386948745,-0.023609928987451845
132.40000000000117,19.99923750937625,-0.6822722069440582,-0.023372379723128667
133.50000000000117,20.104932455389935,-0.677981202102363,-0.024293667696545285
134.6000000000012,20.209804436063603,-0.6733159367191711,-0.02492865630513208
135.7000000000012,20.31639857118901,-0.6682643450515376,-0.023606761504630036
136.8000000000012,20.42112468579649,-0.6629851762719721,-0.023587527199576463
137.90000000000123,20.527144527026454,-0.6590597492440129,-0.02362878173444294
139.00000000000125,20.632179461636056,-0.654564195349451,-0.02492978071809482
140.10000000000127,20.737132715586448,-0.6516045667764153,-0.024920770321639196
141.2000000000013,20.842847950027064,-0.6470813260475257,-0.02558420167790665
142.3000000000013,20.948416427003835,-0.643345682952774,-0.025584710915257602
143.4000000000013,21.054167583657105,-0.6386674522254726,-0.02626346369200938
144.50000000000134,21.15910234098302,-0.635496634706577,-0.02624976465378559
145.60000000000133,21.263235936213416,-0.6311976955427894,-0.025923701838513225
146.70000000000135,21.368950107302563,-0.6285336486384907,-0.02595268501637893
147.80000000000138,21.473435283003823,-0.62366776338367,-0.0263716590978893
148.9000000000014,21.577648036721964,-0.6215008131850268,-0.02722227199187266
150.00000000000142,21.68351119690845,-0.6178066214919036,-0.02761369162237859
151.10000000000142,21.788582297788277,-0.6126354459619203,-0.027560535215471305
152.20000000000144,21.89258729869243,-0.6100918913859695,-0.027566726939725505
153.30000000000146,21.996568114897954,-0.6062890709539869,-0.02887764397224757
154.40000000000146,22.101240623380207,-0.6035647215323332,-0.02755340947126328
155.50000000000148,22.207498452022058,-0.6001307734490221,-0.027889925285427886
156.6000000000015,22.311641563820597,-0.5953570084556697,-0.028727727079032483
157.70000000000152,22.416274945889274,-0.5924968237346062,-0.029209945688196903
158.80000000000155,22.52056571918245,-0.5879261153515859,-0.029688411269070514
159.90000000000154,22.624744177626923,-0.5854325547917972,-0.029210167845226565
161.00000000000156,22.729739618618655,-0.5808287210116692,-0.029210169388824703
162.1000000000016,22.834110363845273,-0.5771497514093381,-0.029841590598223
163.20000000000158,22.939238142222802,-0.5741065456527307,-0.030505033205680654
164.3000000000016,23.043614195129102,-0.5720187053274529,-0.029199328773828803
165.40000000000163,23.146304520992306,-0.5691777248569986,-0.030520912549950374
166.50000000000165,23.252739494038565,-0.5661885707504324,-0.030530124393150615
167.60000000000167,23.356055888046416,-0.5641068920682305,-0.03053001999980154
168.70000000000167,23.460648020684285,-0.559312331036381,-0.0305300200003229
169.8000000000017,23.565541194787983,-0.5576001308725083,-0.030530468739469185
170.9000000000017,23.670449638113308,-0.5553425658313178,-0.03091041879617773
172.0000000000017,23.77467684490539,-0.5525200370139286,-0.03216987030988783
173.10000000000173,23.878671015647857,-0.5484690198687916,-0.03348747717505507
174.20000000000175,23.98266848242837,-0.5446327083015374,-0.033150352366675406
175.30000000000177,24.086935263635745,-0.5418204192765381,-0.032170076400736214
176.4000000000018,24.192419723183324,-0.5404676420170251,-0.03215702862581438
177.5000000000018,24.29705833186434,-0.5364745272347106,-0.033160338218961805
178.6000000000018,24.4008768679377,-0.5342136366867632,-0.03448043876813589
179.70000000000184,24.50543248130093,-0.5312758382614634,-0.0341500340853349
180.80000000000183,24.609543693055816,-0.5287726161412385,-0.03284381253004742
181.90000000000185,24.71315340760908,-0.5258667822767596,-0.03530745735411589
183.00000000000188,24.815009769928636,-0.5209418058746023,-0.035460065867205515
184.1000000000019,24.92259487167907,-0.5200888003801557,-0.03414071973236865
185.20000000000192,25.026155533329096,-0.5166726490594281,-0.03545981962957612
186.30000000000192,25.131078961293884,-0.5121250231240805,-0.035459655092506814
187.40000000000194,25.235069869580112,-0.5107584344895478,-0.03678011913885104
188.50000000000196,25.339472024499727,-0.5065190681604627,-0.037745582491774954
189.60000000000196,25.44303176967838,-0.5021727491372465,-0.03776039424301825
190.70000000000198,25.547868455641762,-0.5007149800071106,-0.03809989177345319
191.800000000002,25.65219121405214,-0.49681659649553583,-0.03941153014921106
192.90000000000202,25.757648523360764,-0.4952531841771877,-0.03940967076274671
194.00000000000205,25.86046100461342,-0.4900488954361295,-0.04006995364972532
195.10000000000204,25.965702865733782,-0.48744029229263314,-0.0404912951396037
196.20000000000206,26.07026665788189,-0.4839983075560508,-0.040079548740815873
197.3000000000021,26.174330880001797,-0.4819054525720366,-0.04138999451139913
198.40000000000208,26.27891464169199,-0.478343554368863,-0.04202578749918562
199.5000000000021,26.38063283291008,-0.475254503296707,-0.04204982980598526
200.60000000000213,26.486655001732608,-0.4728556920893816,-0.04218289975682055
201.70000000000215,26.59188988486417,-0.4697651565152255,-0.0443490951835015
202.80000000000217,26.695692687516672,-0.4669874365486587,-0.04469003065028865
203.90000000000217,26.79990189765826,-0.4635183959136814,-0.0446839670684307
205.0000000000022,26.903480396074777,-0.46077381841420284,-0.0460000296092149
206.1000000000022,27.008278098771942,-0.4560057705963605,-0.045949778541947595
207.2000000000022,27.112840499512824,-0.45354480852089113,-0.04699018029769064
208.30000000000223,27.216858541892655,-0.4497334868384782,-0.04754752438954135
209.40000000000225,27.320614976933964,-0.4471778409084154,-0.04831018512312557
210.50000000000227,27.425158016342642,-0.4434267037197726,-0.04937285326884666
211.6000000000023,27.530093034994728,-0.44057969071189895,-0.05029377451731687
212.7000000000023,27.633805865629714,-0.43711271848835803,-0.050619683258638304
213.8000000000023,27.735490087589863,-0.43454932572101423,-0.052600204667115236
214.90000000000234,27.842982174602685,-0.4302072648857962,-0.05260002000175934
216.00000000000233,27.94732649310314,-0.42773670342157405,-0.0526017541039554
217.10000000000235,28.051375833533747,-0.42448511097755254,-0.05390995872218696
218.20000000000238,28.15601489571432,-0.42070105452075585,-0.05522377027183456
219.3000000000024,28.259736448045803,-0.4176009528040623,-0.056208731844254345
220.40000000000242,28.364593262805876,-0.4156321394785327,-0.057096314285175254
221.50000000000242,28.46778836038883,-0.4118589777389934,-0.057860081317628875
222.60000000000244,28.57256220947442,-0.4090922543104039,-0.05883200739100225
223.70000000000246,28.677028105476598,-0.4051547258895888,-0.059882718235960475
224.80000000000246,28.782303290984704,-0.4010631912532845,-0.0618201084697283
225.90000000000248,28.886548768721045,-0.39698531532651965,-0.0631292627852682
227.0000000000025,28.99141669299501,-0.3930712820116938,-0.06313010153033538
228.10000000000252,29.095172872564753,-0.3897855876938668,-0.06573968774424177
229.20000000000255,29.199274800547606,-0.3860212560497022,-0.06708009901307221
230.30000000000254,29.30465852550865,-0.38170932071639746,-0.06710006340744634
231.40000000000256,29.409387702417632,-0.3778490054485274,-0.06840554870596538
232.5000000000026,29.513608350750363,-0.373439960449287,-0.07070025286513193
233.60000000000258,29.6180693221764,-0.37037475888343774,-0.07122874005594682
234.7000000000026,29.722882940861357,-0.3663688504102897,-0.07249032930850863
235.80000000000263,29.827394649425948,-0.3627022763424065,-0.074986932740436
236.90000000000265,29.931736210007177,-0.3595514159225397,-0.07629828956363127
238.00000000000267,30.03592333148494,-0.35681492179101104,-0.07890708729547402
239.10000000000267,30.140749171362433,-0.3533693222278636,-0.07894085293154163
240.2000000000027,30.24516672420451,-0.35089181557687454,-0.0793555312685239
241.3000000000027,30.350648814225835,-0.3481318101749343,-0.08191024288523696
242.4000000000027,30.454489311853493,-0.3451129574798518,-0.08553223724031511
243.50000000000273,30.558682703657706,-0.34109662230876325,-0.08584975571139797
244.60000000000275,30.661451352055487,-0.33601731655857553,-0.08718162245646344
245.70000000000277,30.76897602844993,-0.3316376649764985,-0.08848726445869914
246.8000000000028,30.87387440128515,-0.32410791098843006,-0.08979720480659381
247.9000000000028,30.977867401755304,-0.31659122440579407,-0.09381109748625605
249.0000000000028,31.08268742050875,-0.3071414212972059,-0.09370012156549734
250.10000000000284,31.186903999164812,-0.29211826097922,-0.0951081767476305
251.20000000000283,31.292114894361227,-0.2669698798859555,-0.097696183420239
252.30000000000285,31.396589320576965,-0.24156140550058097,-0.10027397054606535
253.40000000000288,31.501221675158554,-0.2217224363060463,-0.10167940685545762
254.5000000000029,31.606730864294146,-0.2125788787465827,-0.10429047661266555
255.60000000000292,31.71138331244343,-0.22579174662858048,-0.10560611673909737
256.7000000000029,31.816820512003858,-0.24335997594355477,-0.10693736273057208
257.8000000000029,31.920875241731093,-0.26316318568866576,-0.10956862540557699
258.90000000000293,32.025085254894165,-0.2772303943292048,-0.11083519996624913
260.00000000000296,32.13017851337712,-0.291231862948888,-0.11291059729763608
261.100000000003,32.23505288607128,-0.298888799605935,-0.11619822092948917
262.200000000003,32.33954263608966,-0.3043918860180095,-0.11890112638873962
263.300000000003,32.4446157897451,-0.3080298218957742,-0.12027492372466408
264.40000000000305,32.5489021500536,-0.3076146005191675,-0.12284289350885391
265.50000000000307,32.65105857268399,-0.3086572717065803,-0.12425546797031783
266.6000000000031,32.75702078073684,-0.3084667466130283,-0.12809796652355931
267.7000000000031,32.86282001270037,-0.3067652440013527,-0.13062037375464008
268.8000000000031,32.96757438412395,-0.30574543824219824,-0.13202594611368657
269.9000000000031,33.072041032304156,-0.3036164831972091,-0.1358782058676553
271.0000000000031,33.177045995039286,-0.3034921112806554,-0.1376633808101495
272.10000000000315,33.28104652473454,-0.3028437574030493,-0.14032060515691303
273.2000000000032,33.38747020169202,-0.3011279409094231,-0.14419127125584286
274.30000000000314,33.491263876895715,-0.30059343981379366,-0.14707613612281234
275.40000000000316,33.59648429388103,-0.29846338727365057,-0.15075553397428498
276.5000000000032,33.701229814030775,-0.29942621264644464,-0.15456535562909357
277.6000000000032,33.80624135265376,-0.29729812615446205,-0.15569929649239134
278.70000000000323,33.91120979258611,-0.2956293470152476,-0.15978452090408712
279.80000000000325,34.01663318165495,-0.29472724269158973,-0.162370497789476
280.9000000000033,34.121247250138204,-0.2941711527629084,-0.16630887694163876
282.0000000000033,34.227098375745555,-0.29313899645000996,-0.16948504451934365
283.1000000000033,34.33218370632519,-0.29411576931281314,-0.17262454175974185
284.20000000000334,34.436272462062384,-0.2921326773203517,-0.1761188475177864
285.30000000000337,34.54293506289056,-0.29062846343023957,-0.17888614925159851
286.40000000000333,34.646985317174654,-0.2901106211867105,-0.18235801512512895
287.50000000000335,34.75329353466735,-0.2889244501487121,-0.18556960364205732
288.6000000000034,34.85812759890801,-0.2895454354662457,-0.18949239848584565
289.7000000000034,34.963059814275255,-0.28927589137278653,-0.19223913349227173
290.8000000000034,35.06849924843678,-0.28813913867435986,-0.19486421858761815
291.9000000000034,35.171261356554396,-0.28861577209946443,-0.19952804840007943
293.0000000000034,35.279814360806995,-0.28913003432012874,-0.2032147150190844
294.10000000000343,35.38477122832543,-0.28784278244389705,-0.20584649197864024
295.20000000000346,35.48960789567511,-0.28825789786567996,-0.20899954232176388
296.3000000000035,35.59492714297344,-0.28813969046184945,-0.2123370013579211
297.4000000000035,35.69969625166094,-0.2877089031209174,-0.21625569922288834
298.5000000000035,35.8059353993375,-0.287184793068028,-0.21850340422226067
299.60000000000355,35.912332978620945,-0.2879585495227762,-0.22202661376603894
300.70000000000357,36.01662941361502,-0.2881359868149093,-0.22464231164432436
301.8000000000036,36.12207210614319,-0.28845203788396134,-0.2264757457920097
302.9000000000036,36.22632530578736,-0.28803986129961195,-0.2299211909130232
304.0000000000036,36.332616218284905,-0.2894382085185644,-0.2329753995157784
305.1000000000036,36.43798983879677,-0.28949422485801796,-0.23608635910551934
306.2000000000036,36.54341381602144,-0.2892697448677092,-0.23934178856875654
307.30000000000365,36.648372693650636,-0.28946269243872325,-0.2413115676951949
308.4000000000037,36.754471049716635,-0.29014089319826725,-0.24489194657954938
309.5000000000037,36.85990482658278,-0.2898018608923396,-0.24767186580943656
310.60000000000366,36.9651418547819,-0.29158090538506115,-0.2503150074999829
311.7000000000037,37.0710983753775,-0.2907554825122246,-0.2529482910416738
312.8000000000037,37.17649378746563,-0.29200536532860244,-0.25560052684116075
313.90000000000373,37.28103188592644,-0.2919492408269503,-0.25854567858277866
315.00000000000375,37.38764505761159,-0.2934773693877083,-0.26184507864332307
316.1000000000038,37.49203174119413,-0.2930796840237572,-0.2646266294359241
317.2000000000038,37.59874706269022,-0.29585005331610886,-0.26734135100421375
318.3000000000038,37.704613817487356,-0.2947725384886139,-0.2699860205067499
319.40000000000384,37.80990916820997,-0.29615426744257317,-0.2726002245840671
320.5000000000038,37.91585340009132,-0.29661716878760575,-0.2755620431584678
321.60000000000383,38.02222464005449,-0.297423046889546,-0.27796897130534814
322.70000000000385,38.1271660212384,-0.2977198774661948,-0.28184460715822457
323.8000000000039,38.234532492781746,-0.29957227988978896,-0.28632683884503374
324.9000000000039,38.340000923560645,-0.3022299703541997,-0.288850195906341
326.0000000000039,38.44540996713115,-0.30214738802426994,-0.2913904543262502
327.10000000000394,38.54991862835863,-0.30270220169442597,-0.2950928352899047
328.2000000000039,38.656900883798976,-0.3042761407556984,-0.2973776957705456
329.30000000000393,38.763475472819906,-0.30413594804024274,-0.30076833853900453
330.40000000000396,38.86908355425437,-0.30463393971916075,-0.3051115723409028
331.500000000004,38.97281209100233,-0.30526446098727383,-0.3095101387700563
332.600000000004,39.081124277502134,-0.3068933497744842,-0.3131186584326122
333.700000000004,39.185000940744,-0.30851767982771505,-0.3162766901797398
334.80000000000405,39.29292125262289,-0.3080812306287255,-0.3205764624941345
335.90000000000407,39.39854729576126,-0.31047743153641594,-0.32550996750096806
337.0000000000041,39.504452190274826,-0.3109863471817998,-0.33025933711725086
338.10000000000406,39.61028987938495,-0.312295543467641,-0.33333800804492153
339.2000000000041,39.71632609061173,-0.3121273375903156,-0.3402200896086742
340.3000000000041,39.82233819950891,-0.3132143717883444,-0.343813341705443
341.4000000000041,39.92623330519144,-0.3142721358273327,-0.3490318767089122
342.50000000000415,40.03387816367933,-0.3163813992696404,-0.3553717397116998
343.6000000000042,40.13839220925474,-0.31666002453485287,-0.3603854160130564
344.7000000000042,40.246249106343,-0.3172432375476318,-0.3664235817726391
345.80000000000416,40.35226917834076,-0.318023054429367,-0.3741486465888646
346.9000000000042,40.45905961350731,-0.3189004687624801,-0.38125064884486015
348.0000000000042,40.56432778941748,-0.3198783198367684,-0.38822650622626
349.10000000000423,40.670812515183485,-0.31913754270537736,-0.3958520621581796
350.20000000000425,40.777245907985844,-0.32028366528401075,-0.40598043012991525
351.3000000000043,40.88285423459733,-0.32028509704322095,-0.4134456974973859
352.4000000000043,40.987971433150555,-0.3191860507068389,-0.4229629284917902
353.5000000000043,41.09563644862727,-0.3199387225833534,-0.43343632049558556
354.60000000000434,41.20187225161419,-0.3179484301166414,-0.44460346591239475
355.7000000000043,41.307610186521806,-0.316525995150922,-0.4554472153737179
356.80000000000433,41.41473370897734,-0.31690174009345123,-0.4665466777121705
357.90000000000435,41.521293382827814,-0.31411902693562044,-0.4790454137494997
359.0000000000044,41.62655312569571,-0.31363822915229883,-0.4932561557427788
360.1000000000044,41.73412893329272,-0.31014530677849755,-0.5057424383651457
361.2000000000044,41.840104830757305,-0.30751677734037475,-0.5200612811710608
362.30000000000445,41.94449005487906,-0.3073457362667984,-0.5338855645834935
363.4000000000044,42.05388455683789,-0.3035889689425937,-0.5506482746802703
364.50000000000443,42.16056320045511,-0.3005504122246151,-0.5679845346214862
365.60000000000446,42.26707873839857,-0.2975116333495279,-0.5850766174947077
366.7000000000045,42.371042243935165,-0.29345646073546044,-0.6023161302984246
367.8000000000045,42.47971424775015,-0.2898894561027661,-0.6202392283847646
368.9000000000045,42.586960724618216,-0.28520951609485373,-0.6404698075948589
370.00000000000455,42.69325239194566,-0.2811230403223697,-0.6603542108570508
371.10000000000457,42.8003959256013,-0.27799497121735417,-0.6806363144477157
372.2000000000046,42.90596401020432,-0.2731337208088774,-0.7013621099448817
373.30000000000456,43.012790259547565,-0.2698012509772491,-0.7224816333532793
374.4000000000046,43.11930359654802,-0.2652311291424753,-0.7440654820935291
375.5000000000046,43.22630874678465,-0.26193802169688957,-0.7667005039757231
376.6000000000046,43.33240584097177,-0.25942275746566096,-0.7886787569040776
377.70000000000465,43.4382479355347,-0.2555511387736544,-0.8104086179997099
378.8000000000047,43.5454322166936,-0.25177900299817746,-0.8314117174173434
379.9000000000047,43.65161726687215,-0.24935110663492552,-0.85443237449027
381.00000000000466,43.75821833381389,-0.247235630147563,-0.8776185782083363
382.1000000000047,43.86523343828582,-0.24566621464285401,-0.8992352807535906
383.2000000000047,43.97184013991718,-0.24323408081525136,-0.9208441837310355
384.30000000000473,44.077990046997634,-0.24234208137782265,-0.9411284730170468
385.40000000000475,44.185068534334505,-0.24066190096322165,-0.9635001050269243
386.5000000000048,44.29289760428886,-0.24002519181008963,-0.9834077424463703
387.6000000000048,44.399065869323344,-0.23971073080218394,-1.0045010754604542
388.7000000000048,44.505653865261806,-0.23932670000582268,-1.0236480647237705
389.80000000000484,44.6124568398281,-0.23915449479399398,-1.0432284545830033
390.9000000000048,44.719915980937266,-0.23839548907886365,-1.061038422194709
392.00000000000483,44.826590324862856,-0.23825759987204284,-1.079302705166254
393.10000000000485,44.93281518043282,-0.23919144821778587,-1.0977376592025228
394.2000000000049,45.039662452871255,-0.23841618815325508,-1.114254043748403
395.3000000000049,45.1483992038366,-0.2390404680890249,-1.1325431647339577
396.4000000000049,45.25519344792984,-0.2390888679418468,-1.1498050890513243
397.50000000000495,45.36217330099054,-0.23999470611633353,-1.1655580930562839
398.6000000000049,45.46892437709339,-0.24007102385658216,-1.1820724397523152
399.70000000000493,45.575999819962774,-0.24032109964716103,-1.1972617639414675
400.80000000000496,45.68357741908125,-0.24100940861980708,-1.2119692041669845
401.900000000005,45.7909663236551,-0.24117738492217675,-1.2284544765886642
403.000000000005,45.89768973633099,-0.24175747596838476,-1.2443362546315644
404.100000000005,46.00508217060436,-0.24141485877296545,-1.2589128060698966
405.20000000000505,46.11270251834081,-0.24181975931778601,-1.272702106709342
406.30000000000507,46.219552503502044,-0.2413776778415028,-1.2884577063002354
407.4000000000051,46.32636543756996,-0.2398009729568377,-1.3018672533832918
408.50000000000506,46.43352332152778,-0.2398770892872189,-1.3173885759161852
409.6000000000051,46.540686031708475,-0.23860945055378535,-1.3320223029243627
410.7000000000051,46.64779540245451,-0.23702384308527996,-1.345998212772182
411.8000000000051,46.7566143741289,-0.23803716275681064,-1.3601594021573225
412.90000000000515,46.86205387600729,-0.2352733973390848,-1.3755099676133433
414.0000000000052,46.97044613780104,-0.23525316976863905,-1.390473648329297
415.1000000000052,47.077659905243856,-0.23488452995898024,-1.4032277862035296
416.20000000000516,47.18591274307288,-0.23645692509689775,-1.4194595501690923
417.3000000000052,47.29220851250082,-0.234239110387012,-1.4316322854450725
418.4000000000052,47.40143818573117,-0.23449559663118702,-1.446564001860903
419.50000000000523,47.508035979532536,-0.23334975273907638,-1.4607608223711352
420.60000000000525,47.61560930250358,-0.2324174357291999,-1.4737382418962492
421.7000000000053,47.72282168350929,-0.23221020425990468,-1.4883722639178227
422.8000000000053,47.83134374309466,-0.23164237580422847,-1.500995144915596
423.9000000000053,47.93777320331496,-0.2322679367709044,-1.513460139503176
425.00000000000534,48.04548608212582,-0.23349868786537878,-1.5264302369764322
426.1000000000053,48.152637408157645,-0.23462796454382306,-1.5381385084832475
427.20000000000533,48.26009654884794,-0.23598611155892896,-1.5492831862794576
428.30000000000535,48.367631289718204,-0.23614079603909996,-1.5610760719983494
429.4000000000054,48.47537839300808,-0.23693607165420197,-1.5703782225495053
430.5000000000054,48.58298977635053,-0.23845605404631212,-1.58130599410923
431.6000000000054,48.69059977846141,-0.23913546385487164,-1.591917492689121
432.70000000000545,48.79748278329425,-0.2404559173250942,-1.601511506315076
433.8000000000054,48.905542101593824,-0.24090079483838128,-1.6113442582762914
434.90000000000543,49.01289261282264,-0.24112782513829176,-1.620185596490174
436.00000000000546,49.12031206967214,-0.240860484429251,-1.6260212473668316
437.1000000000055,49.22828842270668,-0.23991792230105854,-1.6375618870058704
438.2000000000055,49.33556324699536,-0.23856085345193204,-1.6454188049783518
439.3000000000055,49.44249506628985,-0.24083600413941383,-1.6523582026967762
440.40000000000555,49.54980079418873,-0.23973993325559997,-1.6613580601574554
441.50000000000557,49.65800683859828,-0.23827898950437354,-1.6695767863465827
442.6000000000056,49.76559020355514,-0.23737532386794746,-1.6759714354001298
443.70000000000556,49.87329965213367,-0.23728861877985857,-1.6833819417508273
444.8000000000056,49.98009408273429,-0.23674650289100121,-1.6908651768585332
445.9000000000056,50.08880782910414,-0.2377371984073123,-1.6983465448536168
447.0000000000056,50.19626478660363,-0.2375473303528149,-1.7053236033080266
448.10000000000565,50.303799308345866,-0.2358958036050337,-1.711343361030436
449.2000000000057,50.411998899081894,-0.23421828261470012,-1.7180738935493212
450.3000000000057,50.5188587708309,-0.23415637529169941,-1.7232621910349923
451.40000000000566,50.62821842544587,-0.23222034978538447,-1.728112966417894
452.5000000000057,50.734585721000684,-0.2311681926120142,-1.7345386614406069
453.6000000000057,50.8425400056755,-0.23024114476482893,-1.7391636267675836
454.70000000000573,50.95054513035498,-0.22786250019218687,-1.7440275651701223
455.80000000000575,51.05876865781357,-0.22758597065596464,-1.7489631618812287
456.9000000000058,51.16718297359453,-0.22572347545604804,-1.7531055962995516
458.0000000000058,51.274707409418625,-0.22428031031161824,-1.7577924025084086
459.1000000000058,51.38368552340679,-0.2234231388497041,-1.761991636475151
460.20000000000584,51.49084116027414,-0.22273353062954565,-1.7670525147937184
461.3000000000058,51.598720917524155,-0.22229540359136185,-1.7703756948884366
462.40000000000583,51.70728351086666,-0.2220997965088227,-1.7742615198740852
463.50000000000585,51.81278219187858,-0.22353646331864524,-1.7758564241238326
464.6000000000059,51.92246599651131,-0.22376520713893835,-1.7797601178645386
465.7000000000059,52.03092127082731,-0.22531684161141113,-1.7825228426833108
466.8000000000059,52.13963186201221,-0.22510110837313588,-1.7851882756813815
467.90000000000595,52.24616573359215,-0.2271126981246738,-1.7871788742512686
469.0000000000059,52.35494705325957,-0.22743402602205132,-1.7897192144581036
470.10000000000593,52.464260523768694,-0.2290069401373741,-1.7911424329941772
471.20000000000596,52.57124614451712,-0.23048979980678086,-1.7937355752687738
472.300000000006,52.68108537986544,-0.23075528222547,-1.7951840660261924
473.400000000006,52.78804355155751,-0.23319690913853638,-1.7970433459601085
474.500000000006,52.89647777932949,-0.23505632391060993,-1.7987217109726248
475.60000000000605,53.00560368689147,-0.2361028045476664,-1.8009963018536195
476.70000000000607,53.11368153643835,-0.23667085076045613,-1.8022151647032758
477.8000000000061,53.22207881825671,-0.23644140565117722,-1.8049508382465689
478.90000000000606,53.330583299429996,-0.2381939077941752,-1.8056268041893468
480.0000000000061,53.43889109727732,-0.23843462737061744,-1.8069153266233853
481.1000000000061,53.54806663375229,-0.2379918184175886,-1.8090365974904157
482.2000000000061,53.6562184648422,-0.23912952801506698,-1.810850711609619
483.30000000000615,53.76430512012821,-0.24026992488821902,-1.8121901559001765
484.4000000000062,53.8724356237002,-0.24104674711119273,-1.8133349607974085
485.5000000000062,53.9807014269674,-0.24154687487438833,-1.814831164575442
486.60000000000616,54.089278617779094,-0.24499705311937256,-1.8148308178565413
487.7000000000062,54.19707966299672,-0.24441380636654073,-1.8181831128925765
488.8000000000062,54.305665419527145,-0.24562893147526307,-1.8193971301350738
489.90000000000623,54.41257036729361,-0.2461609444922902,-1.8197786728418746
491.00000000000625,54.52258928898627,-0.24589843242551937,-1.821007390711948
492.1000000000063,54.62980426915598,-0.24567151534178672,-1.820739754778002
493.2000000000063,54.7380492030546,-0.246159698999255,-1.8220627539563572
494.3000000000063,54.84649551145505,-0.24344947102226064,-1.824788449386685
495.40000000000634,54.95420373143399,-0.24372256356813762,-1.8260268918582567
496.5000000000063,55.062661507992,-0.2437782111063606,-1.8260375780892413
497.60000000000633,55.17050917926355,-0.2424927676502498,-1.8273406039918099
498.70000000000636,55.27940311771145,-0.24425785597518018,-1.8273471470238585
499.8000000000064,55.38698915652023,-0.24394531409104933,-1.8293296520474382
500.9000000000064,55.49566379707964,-0.24373782721258994,-1.8300114253079514
502.0000000000064,55.60419780834065,-0.2427648391295319,-1.8299744182118793
503.10000000000645,55.71358080878733,-0.24284901761181435,-1.8319600038851673
504.2000000000064,55.821618160796376,-0.2448273056513105,-1.8329534289686764
505.30000000000643,55.92968050161057,-0.24236979148825286,-1.8345990017528049
506.40000000000646,56.038376952068916,-0.24395706959549385,-1.8346008412607038
507.5000000000065,56.1474525741665,-0.24347049768214843,-1.835911927292198
508.6000000000065,56.25649341631882,-0.24187102397072083,-1.8364411328841097
509.7000000000065,56.364829629579845,-0.24173150451942077,-1.8385487137150611
510.80000000000655,56.473762767840064,-0.24161548272849856,-1.837135541415353
511.90000000000657,56.582886947256306,-0.24212700325787737,-1.8396718716789806
513.0000000000066,56.692057606710286,-0.24200490971368946,-1.8421679933490793
514.1000000000065,56.80020792240577,-0.24250363159395744,-1.8421788242757189
515.2000000000066,56.90905831632128,-0.24207535415115522,-1.8421668293320077
516.3000000000065,57.01698633580304,-0.24265882751472942,-1.843481382505073
517.4000000000067,57.126040476771735,-0.24172959004554312,-1.8447993435508727
518.5000000000066,57.23495239693278,-0.24250027149676048,-1.8459554241662173
519.6000000000067,57.34266520870572,-0.24278538451887782,-1.8461212060286782
520.7000000000066,57.45215757415061,-0.24295537412497475,-1.8487835776812984
521.8000000000067,57.56142569914817,-0.24187966092175914,-1.8487500644411101
522.9000000000067,57.669574929559516,-0.24271400212193936,-1.8510253788620923
524.0000000000067,57.779038764172675,-0.24312141928659148,-1.8513868493946273
525.1000000000067,57.88710834607007,-0.24222012269413307,-1.8513902207067598
526.2000000000068,57.996479853815444,-0.24209169691183346,-1.8540469276616989
527.3000000000068,58.10498988202624,-0.24074748280274452,-1.854689097436188
528.4000000000068,58.21319218899803,-0.24019647382532133,-1.8574019932371715
529.5000000000068,58.32313114189521,-0.24096447016059608,-1.8574198971421274
530.6000000000068,58.43174032267858,-0.241623252257551,-1.8587457394912206
531.7000000000069,58.541302014259976,-0.2406986249568859,-1.8601396095056364
532.8000000000068,58.650291624018124,-0.2400659081081457,-1.8626969215296727
533.9000000000069,58.759221748436325,-0.23925141174450854,-1.8626983717878591
535.0000000000068,58.867276704784516,-0.23845707992371937,-1.8639998927241108
536.100000000007,58.97683996397315,-0.2383283354699546,-1.86654522901949
537.2000000000069,59.086091003059416,-0.2386488915592308,-1.8675434629486674
538.300000000007,59.194365859001714,-0.23661528118682998,-1.8697308236782728
539.4000000000069,59.30390481228682,-0.23753274509561495,-1.8696122066000727
540.5000000000069,59.41182295774191,-0.23624946663743096,-1.8722230361223295
541.600000000007,59.521136740193384,-0.2352002369339042,-1.8745504921480571
542.700000000007,59.63136711624551,-0.23451383235607373,-1.8771975599037418
543.800000000007,59.73787117787731,-0.23362153780355072,-1.8778390362277424
544.900000000007,59.84856165227035,-0.2321738498599311,-1.8791556436922416
546.000000000007,59.95815247321635,-0.2313995149305988,-1.8827813701526308
547.1000000000071,60.06699416642013,-0.23209850923854586,-1.884128480893295
548.2000000000071,60.17622855777705,-0.23051148318729267,-1.8853978746071762
549.300000000007,60.28642416035322,-0.23007765816771403,-1.887840012577826
550.4000000000071,60.395179121904675,-0.22826478777538328,-1.8903374467976732
551.500000000007,60.50444267848391,-0.22919809454584472,-1.8930991269858786
552.6000000000072,60.614319560911625,-0.22722253735045272,-1.895747167122619
553.7000000000071,60.72392706543807,-0.22533990480337768,-1.8983791481546604
554.8000000000072,60.83285297036344,-0.22472737819874494,-1.9002576940273732
555.9000000000071,60.94141772281693,-0.2240436385750478,-1.9026620545232298
557.0000000000072,61.051015899043676,-0.22465879064090646,-1.9068511618239046
558.1000000000072,61.158569649115066,-0.22232538461938367,-1.9083102318426226
559.2000000000072,61.2685033271262,-0.22150681368745967,-1.9124173408526084
560.3000000000072,61.379902767033265,-0.2191761627442125,-1.915491879123599
561.4000000000073,61.48870349581671,-0.2187612250515777,-1.9187956153827983
562.5000000000073,61.59891550513408,-0.21708836230074882,-1.9221572985849154
563.6000000000073,61.707451899132565,-0.21536190222917154,-1.9249101364003858
564.7000000000073,61.81633162969413,-0.21284220463871906,-1.9290000148379782
565.8000000000073,61.926318908720084,-0.21274488606183445,-1.9321627283870675
566.9000000000074,62.03461952051258,-0.2112873199563915,-1.9347940027965187
568.0000000000074,62.144273253482964,-0.20955118205307433,-1.939508292777881
569.1000000000074,62.25280659702642,-0.20968543294913172,-1.9436849753860233
570.2000000000073,62.36231878925846,-0.2066136198282351,-1.9478103678875214
571.3000000000073,62.472230657557056,-0.208440401386061,-1.9501426653366196
572.4000000000074,62.58148039150932,-0.20583880959456533,-1.9543628302941385
573.5000000000074,62.690091855856906,-0.20404288956549022,-1.9581074153619666
574.6000000000074,62.79859786626421,-0.2062258327975375,-1.9620464123463952
575.7000000000074,62.90947637194264,-0.20774938469854437,-1.9671782148961836
576.8000000000075,63.0190480874999,-0.2068247915086976,-1.9693060093573407
577.9000000000075,63.12948708550766,-0.20620420961388045,-1.9736497897956622
579.0000000000075,63.237843018793875,-0.20567283077561652,-1.9762467434233866
580.1000000000075,63.348560148736205,-0.2079284885409894,-1.9817565544069407
581.2000000000075,63.45819666342094,-0.20869834419671374,-1.985209606848208
582.3000000000076,63.5680069616912,-0.21098185471339,-1.9878888386786224
583.4000000000076,63.67753174835152,-0.21146978200396827,-1.9911249318256408
584.5000000000076,63.788421690705995,-0.21109363645674986,-1.994951297610815
585.6000000000076,63.8971295057194,-0.21017842095204115,-1.9989918039179186
586.7000000000077,64.00620388744859,-0.21120130027724937,-2.001646145657056
587.8000000000077,64.11692308148531,-0.20946871872343925,-2.0028468088326816
588.9000000000076,64.22566356919303,-0.206995903704365,-2.0057034644691685
590.0000000000076,64.33552941747107,-0.20471081964018908,-2.0074948937528254
591.1000000000076,64.4440683124278,-0.19848833378604286,-2.0095865252567218
592.2000000000077,64.55394240371373,-0.1911616376515309,-2.009598012012859
593.3000000000077,64.66320850542817,-0.18211198087537286,-2.0109040792884585
594.4000000000077,64.77256810102045,-0.17781136319330465,-2.0123479107758304
595.5000000000077,64.88189399650646,-0.18004621553499112,-2.01367881869976
596.6000000000078,64.98907129607224,-0.1790859284280744,-2.0148632161737545
597.7000000000078,65.09989925110182,-0.17812024244954472,-2.0161261485740543
598.8000000000078,65.20980432424486,-0.17385158131421413,-2.0181235418696843
599.9000000000078,65.3195934763012,-0.1723815235823628,-2.017506364429037
601.0000000000078,65.4292502901934,-0.1716640473733118,-2.0190805024481397
602.1000000000079,65.53811930424799,-0.1702669799165347,-2.0201298497702087
603.2000000000079,65.64845573172218,-0.16573801107869945,-2.020131514251063
604.3000000000079,65.75726615889569,-0.16043334173508175,-2.0214327788043285
605.4000000000078,65.86685125785634,-0.15551341036272362,-2.022760007332372
606.5000000000078,65.9750566806334,-0.1527820636598164,-2.0240784026656766
607.6000000000079,66.0869680381246,-0.15116670920145678,-2.025069787420184
608.7000000000079,66.19640132897345,-0.14741619410119772,-2.0253012440661537
609.8000000000079,66.30683987014534,-0.1424140724796787,-2.025390282930842
610.9000000000079,66.41461113644026,-0.13742984531468203,-2.0263807737282478
612.000000000008,66.52528964289628,-0.13140955343083702,-2.027700803960536
613.100000000008,66.63464393966424,-0.12558845035055224,-2.0303389899908275
614.200000000008,66.74447628424424,-0.11931216133772114,-2.0289360197327166
615.300000000008,66.8539673094326,-0.11066784264862994,-2.031706149222218
616.400000000008,66.96378975183788,-0.1026944440885572,-2.032970089027824
617.5000000000081,67.07426188983386,-0.09490434602689814,-2.0335319023474403
618.6000000000081,67.1837581864093,-0.08566415936527084,-2.036309018046767
619.7000000000081,67.29275036314925,-0.07911481927030038,-2.0359071467438814
620.8000000000081,67.40334666336422,-0.06976635806587604,-2.038455436204135
621.9000000000082,67.51334231540244,-0.06089621878431289,-2.0399462945247517
623.0000000000082,67.62326983882161,-0.051232247955055654,-2.0408080308029555
624.1000000000081,67.73259707419466,-0.04045610626148693,-2.043490578881923
625.2000000000081,67.84199083757304,-0.02988239378240585,-2.044766823129904
626.3000000000081,67.95249744823336,-0.020552368681438643,-2.047554079914124
627.4000000000082,68.06274501990237,-0.009589047049576383,-2.0474594358369327
628.5000000000082,68.17210011357324,0.0020029593553947045,-2.050077946291394
629.6000000000082,68.28073884790587,0.014418617568921618,-2.051452119451851
630.7000000000082,68.39176417181115,0.02234281066186667,-2.0541809278101364
631.8000000000083,68.50101095973747,0.034189780050037,-2.0554467496923348
632.9000000000083,68.61080576310358,0.0455762184655613,-2.0593077964299917
634.0000000000083,68.72129146453341,0.05862698490145188,-2.061952872227288
635.1000000000083,68.83065656466447,0.07221997270881828,-2.064257694482362
636.2000000000083,68.94120873631421,0.08386969829130318,-2.0668912082139697
637.3000000000084,69.05021241551356,0.09698229474556026,-2.06864876787885
638.4000000000084,69.15999781469571,0.11128957738885967,-2.072600185684321
639.5000000000084,69.268316959924,0.1250876583080175,-2.075236537032551
640.6000000000083,69.37981017854385,0.13881892832115506,-2.077303640195958
641.7000000000083,69.4903952341978,0.15260009387372978,-2.0822608342280615
642.8000000000084,69.59906878464574,0.16578511899793189,-2.0845856049680815
643.9000000000084,69.70954171571742,0.1811549286243409,-2.0881938628326613
645.0000000000084,69.82010551857024,0.19614649582161023,-2.0923671550035716
646.1000000000084,69.9297984722786,0.21297812197068572,-2.093770970615769
647.2000000000085,70.03970016785885,0.22587284707223565,-2.099157813560445
648.3000000000085,70.15066970281178,0.24030398294079472,-2.1035603278452717
649.4000000000085,70.260679875799,0.255714205496604,-2.10623602443272
650.5000000000085,70.37024818321359,0.27324824547603227,-2.1119207478862503
651.6000000000085,70.48063491536362,0.28974035175876883,-2.115111104755041
652.7000000000086,70.5913268133646,0.3041226798793141,-2.1198413379543073
653.8000000000086,70.70210085979134,0.3208718404739884,-2.124261083842934
654.9000000000086,70.81298742551115,0.3378564445105957,-2.1285307672825486
656.0000000000086,70.92187038710898,0.3528618778115457,-2.133781338563832
657.1000000000087,71.03356716585228,0.36889181631517254,-2.138613078664189
658.2000000000087,71.14385484655126,0.38603994755295507,-2.142925015466786
659.3000000000086,71.25518036620187,0.4009522351155485,-2.1493670482014866
660.4000000000086,71.3648079320363,0.4141674460117283,-2.1551443599002136
661.5000000000086,71.4757592814923,0.43445482336939695,-2.160302295080012
662.6000000000087,71.58577527481201,0.44826122552433806,-2.1650623525289436
663.7000000000087,71.69713956608801,0.46550841858722947,-2.172779871724121
664.8000000000087,71.80788594539273,0.4796192252368179,-2.177282734416391
665.9000000000087,71.91783205981176,0.4948966091217348,-2.183279246429472
667.0000000000088,72.02635392743959,0.5111954663506579,-2.18956300170546
668.1000000000088,72.13782432442963,0.5250440767941414,-2.194810318054463
669.2000000000088,72.24746709358365,0.5402962596593733,-2.2015261109995587
670.3000000000088,72.35663813517348,0.5548549429469306,-2.2080451899930296
671.4000000000088,72.46666030463905,0.5677526523773225,-2.2143795582933237
672.5000000000089,72.57662140164229,0.578252756005971,-2.2214953832127122
673.6000000000089,72.68564684420882,0.5889503942648818,-2.2281174328277604
674.7000000000089,72.79654074893398,0.6009894059039591,-2.234397578657685
675.8000000000088,72.90584335819571,0.6067293766099402,-2.2399953538257296
676.9000000000088,73.01555557298227,0.6117472689600156,-2.247000711987087
678.0000000000089,73.12519605947558,0.6180605478247756,-2.254438737757531
679.1000000000089,73.23629500810277,0.6209504858817511,-2.261568326956767
680.2000000000089,73.3470828495851,0.62060987536932,-2.267644021037457
681.3000000000089,73.4567365368492,0.6185828068047942,-2.2741734282051693
682.400000000009,73.5671438096511,0.6162549194173566,-2.2809009210042435
683.500000000009,73.67764123159692,0.6139729903747607,-2.2869565621960586
684.600000000009,73.78692853702441,0.6144333795060176,-2.293829291655176
685.700000000009,73.89780788087464,0.6177764636642362,-2.3011506815727234
686.800000000009,74.00839819286337,0.6299389083902107,-2.3080571744883525
687.9000000000091,74.11868876846529,0.6512095250917529,-2.3153477078311173
689.0000000000091,74.22903462390886,0.6822162836303591,-2.3220439191024953
690.1000000000091,74.33936572864273,0.7200454309080904,-2.327485885325488
691.2000000000091,74.4499055571548,0.7631496537627496,-2.3343243625070373
692.3000000000092,74.5593289635206,0.8086390946339567,-2.3430711696426547
693.4000000000092,74.670304360905,0.8551038652875593,-2.3503817287416364
694.5000000000091,74.77970325399919,0.9028259635986322,-2.358580893344598
695.6000000000091,74.89010258394269,0.946312515115306,-2.3669404118917967
696.7000000000091,75.0006892249291,0.9910651905893975,-2.3763084534408416
697.8000000000092,75.11018803765968,1.0358470769672012,-2.3853784692242783
698.9000000000092,75.22073507221575,1.079953081018136,-2.3944479251636306
700.0000000000092,75.33109604577287,1.1233813512385744,-2.4048263572224036
701.1000000000092,75.44149187503278,1.1678316151715518,-2.415065414451138
702.2000000000093,75.55215596999241,1.2097811638911729,-2.42584360404373
703.3000000000093,75.66302779810468,1.2543431730423136,-2.4362716296553026
704.4000000000093,75.77283842575737,1.2943031420731128,-2.446392992201997
705.5000000000093,75.88380130421625,1.3374467861444232,-2.458693224163926
706.6000000000093,75.99402253008047,1.3806541621694353,-2.4687542184362337
707.7000000000094,76.10432894000992,1.419293178550774,-2.4824954922731113
708.8000000000094,76.21475729102777,1.4622891505699547,-2.4929572793023542
709.9000000000094,76.32470615251644,1.5027444122888491,-2.5043431037351302
711.0000000000093,76.43550318224133,1.5394051509770876,-2.5177640971504243
712.1000000000093,76.54686826228608,1.5818358762864135,-2.5323522288107165
713.2000000000094,76.65736272572462,1.6170645453296435,-2.5444287310724825
714.3000000000094,76.76782307567403,1.6550394063077536,-2.5580927988739894
715.4000000000094,76.87871072052842,1.6910443768904957,-2.5717935643313687
716.5000000000094,76.98887767303752,1.7238205904291863,-2.5854012174413836
717.6000000000095,77.10011353121885,1.7592964784266107,-2.5985825577200177
718.7000000000095,77.21158075228584,1.7893773691465777,-2.615198914214504
719.8000000000095,77.32188641720818,1.8169632434097518,-2.629019627868859
720.9000000000095,77.43331689760703,1.8407898066607993,-2.643703530370481
722.0000000000095,77.54308975336801,1.8636426642527406,-2.6580498779813695
723.1000000000096,77.65435327746354,1.8817881330570807,-2.6734158621875226
724.2000000000096,77.76291073050598,1.8961733342811948,-2.6879218045601405
725.3000000000096,77.87579673910956,1.9001015918331778,-2.703326362638074
726.4000000000096,77.98600906375215,1.8961571479850188,-2.7170573342639432
727.5000000000097,78.09571281756587,1.8840400996985913,-2.733483284494489
728.6000000000097,78.20724465703864,1.8577740061662305,-2.748567998445632
729.7000000000096,78.31749419471288,1.8124597681610999,-2.762551618411598
730.8000000000096,78.42741293058766,1.746923396111949,-2.776717390135577
731.9000000000096,78.53649337800049,1.6532997311400495,-2.7896238342023487
733.0000000000097,78.64793963802904,1.5150375663907814,-2.8030782040087794
734.1000000000097,78.75824064968799,1.2950975473989532,-2.816080797727724
735.2000000000097,78.8670748315516,0.8694924952830536,-2.8238494022511067
736.3000000000097,78.97646333629413,0.2544454939804304,-2.8307206241821175
737.4000000000098,79.08504087307332,-0.024773070760127188,-2.831021651140192
738.5000000000098,79.19438022825317,-0.14172984894029586,-2.832080042838796
739.6000000000098,79.30568336688519,-0.19438207882853997,-2.8360993052916283
740.7000000000098,79.41559558174669,-0.2171630352920773,-2.8426472277131793
741.8000000000098,79.52586339945005,-0.23357366663396814,-2.841281135273262
742.9000000000099,79.63487381042674,-0.2413752964441627,-2.838560227013638
744.0000000000099,79.74672022012702,-0.2463599204096663,-2.8385638413002496
745.1000000000099,79.85720801658088,-0.2503342946871748,-2.8365444713935046
746.0000000000099,79.94757297503156,-0.24938787778466884,-2.836580100199616