File: 01_Data/Rug_Pad/STA/N2/10K_min/Rug_Pad_STA_N2_10KData_221025_R1.csv
##Temp./Â°C,Time/min,DSC/(mW/mg),Mass loss/mg
51.0,10.719776215482307,-1.7023511971630345,0.026549219314770944
52.100000000000016,11.111122018240595,-1.5845903966621044,0.027601912016010477
53.20000000000003,11.366623498948966,-1.5046345770087115,0.028826404812805517
54.30000000000005,11.57762155049649,-1.44419177840116,0.027846398002620898
55.40000000000006,11.765148465898163,-1.3985061567022805,0.028994457609415214
56.50000000000008,11.937449119567235,-1.361474959773595,0.02791667492274108
57.600000000000094,12.099806958829088,-1.3303355385553715,0.028897259491158955
58.70000000000011,12.256152431770419,-1.3034736800975175,0.02800161534443779
59.800000000000125,12.40473137955111,-1.282913861555309,0.027388214134651978
60.90000000000014,12.550548597713064,-1.2634668423888638,0.029362035603150982
62.000000000000156,12.694048636881718,-1.2444833713892316,0.02818598825508234
63.10000000000017,12.833419057626523,-1.2291412723007455,0.028266721878821954
64.20000000000019,12.968549691548219,-1.2137535734723137,0.028428117829707222
65.30000000000021,13.10732371207628,-1.2001368745713263,0.029716767652496312
66.40000000000022,13.239928432000324,-1.1861580302962527,0.031046061451023288
67.50000000000023,13.369283322177072,-1.1739275961578661,0.0305607844337481
68.60000000000025,13.499560136379209,-1.1623639433319386,0.02974105961547968
69.70000000000027,13.62841666372933,-1.1498653956304619,0.029852699341181843
70.80000000000028,13.753717345309202,-1.1368343661330997,0.029877947761125956
71.90000000000029,13.879783955201606,-1.1263866598077943,0.02985346220916618
73.00000000000031,14.002653734645996,-1.1172697278249917,0.029864343096152268
74.10000000000034,14.12463416949465,-1.1068499092334523,0.03120436122472059
75.20000000000034,14.24635084438956,-1.0948127049358765,0.029791075227468156
76.30000000000035,14.372554482837089,-1.085443669808179,0.02987671804136216
77.40000000000038,14.49146245507038,-1.075582932851461,0.030707594037278962
78.5000000000004,14.611153457282484,-1.0677622328208807,0.03118541071409142
79.6000000000004,14.73023445118721,-1.0586448070448837,0.031253429949409384
80.70000000000041,14.847707873062271,-1.0504606073157676,0.03006032069750786
81.80000000000044,14.966599206647743,-1.0438623844729666,0.029853473611760162
82.90000000000046,15.08322800420909,-1.0350427854266822,0.031535217682757466
84.00000000000047,15.199827896892788,-1.0287094374854393,0.029970725175043622
85.10000000000048,15.315324264632576,-1.0205833835544458,0.0298893909198914
86.2000000000005,15.430690123135975,-1.0138435743930716,0.029855946049254456
87.30000000000052,15.543258658574553,-1.0074845468392122,0.028967573498297927
88.40000000000053,15.65767729902914,-1.0006899297689928,0.02986778190763051
89.50000000000054,15.772474283427112,-0.9941877060593579,0.031056076788105624
90.60000000000056,15.885452324790604,-0.9869551372691462,0.031168654926985173
91.70000000000059,15.998757811999166,-0.9810916616490548,0.03046386611193652
92.8000000000006,16.10999032850057,-0.9748747931811848,0.029846242925974487
93.9000000000006,16.221451545605515,-0.9689938967472126,0.028950729612642778
95.00000000000063,16.33370510099666,-0.9614936525445545,0.030751131914370955
96.10000000000065,16.44258706615459,-0.9552637882849229,0.030530228145329463
97.20000000000066,16.552822424862626,-0.9489883959444191,0.029487651559156003
98.30000000000067,16.664204455079684,-0.9442151478522818,0.030196094264156148
99.40000000000069,16.773195601878243,-0.9365487421534303,0.029452424967399526
100.50000000000071,16.881815149299,-0.9319434289251228,0.030386496029028986
101.60000000000072,16.99277691457245,-0.9258326868056196,0.030462663042189586
102.70000000000073,17.099170000000075,-0.920229999999993,0.030408864412204917
103.80000000000075,17.209170000000086,-0.914519999999988,0.030410130063963425
104.90000000000077,17.317669520561893,-0.9083192158054385,0.030413150932850908
106.00000000000078,17.42685502004921,-0.9031923621928436,0.029108445735968047
107.10000000000079,17.53530762655144,-0.8986021168399037,0.02908979174751236
108.20000000000081,17.643571684838548,-0.8923042035646382,0.02908958918784288
109.30000000000084,17.752552721237805,-0.8867457632509836,0.03040716981254432
110.40000000000084,17.860383279415228,-0.8815509150403525,0.03041031750889056
111.50000000000085,17.96860312823784,-0.8769719079986416,0.03040888735899161
112.60000000000088,18.075791843368535,-0.8714948920784473,0.03012314064429278
113.7000000000009,18.183196294054532,-0.8673747449693248,0.029277258174996046
114.8000000000009,18.291062108713064,-0.8629403827729122,0.030439438710884392
115.90000000000092,18.39884149429461,-0.8562085731888684,0.030342725655916336
117.00000000000094,18.505480734330806,-0.8522450447522874,0.02911153970866609
118.10000000000096,18.6131141558918,-0.8482015542856839,0.030443504923725495
119.20000000000097,18.71868482770687,-0.8443280532225907,0.030403382904633514
120.30000000000098,18.826289398092438,-0.8380028564546497,0.030395136658335264
121.400000000001,18.93314678286492,-0.8344837140349278,0.029086093643958755
122.50000000000102,19.040181881730838,-0.8312564312737503,0.02909066146485939
123.60000000000103,19.146819637606416,-0.8264449192424147,0.029101441224301805
124.70000000000104,19.252496960416664,-0.8224276621272009,0.0290898265062296
125.80000000000106,19.36083375534563,-0.8172164641475113,0.03043720834387953
126.90000000000109,19.4673393213152,-0.8138801261792035,0.02942098862279563
128.00000000000108,19.573583251796897,-0.8101650536329715,0.029313637568977757
129.1000000000011,19.679477289161273,-0.8056186831882165,0.029089936340745304
130.20000000000113,19.785824274367716,-0.8019802465740377,0.029734355142442048
131.30000000000115,19.89114272410013,-0.7969961267638229,0.028740653832682206
132.40000000000117,19.997871468303124,-0.793565508291062,0.02777655730929718
133.50000000000117,20.102534552316797,-0.7896169249304404,0.029100386628593267
134.6000000000012,20.209465304105183,-0.785108920818428,0.029423163861935997
135.7000000000012,20.312181649441932,-0.7809121307754399,0.030409440229469897
136.8000000000012,20.420892401714458,-0.7769869606982616,0.029401323781996336
137.90000000000123,20.526193428748407,-0.7730715298610094,0.02975448855315843
139.00000000000125,20.632315679368393,-0.7672209210508413,0.029072561097992722
140.10000000000127,20.73643803781728,-0.7636777758073097,0.029304541605634338
141.2000000000013,20.841882576038184,-0.7599276816828412,0.0287599362857347
142.3000000000013,20.946245391645903,-0.7575591495760826,0.028758059209978537
143.4000000000013,21.051304764933516,-0.7517780775955496,0.029070041172314376
144.50000000000134,21.157235587259418,-0.7505221839293346,0.02908746838630627
145.60000000000133,21.261079904409296,-0.7467313106438062,0.029087770649597555
146.70000000000135,21.366975489185307,-0.7434161025405965,0.028119599263080275
147.80000000000138,21.4704720835534,-0.7404016751069105,0.029099262319479013
148.9000000000014,21.5761243580407,-0.7368320578168991,0.027901945517831983
150.00000000000142,21.68152231300696,-0.7323663330416129,0.027779909303311978
151.10000000000142,21.78643712270998,-0.7314724641919541,0.026894748658852663
152.20000000000144,21.891221185234716,-0.7255259191576143,0.02706706429366834
153.30000000000146,21.995439549659537,-0.7236159253974093,0.02644992631041365
154.40000000000146,22.10052338420742,-0.7202490539303175,0.02777013208161483
155.50000000000148,22.20312334973057,-0.7175834180823818,0.026460118228012863
156.6000000000015,22.307447312255498,-0.7146446485360792,0.027708604662221692
157.70000000000152,22.412082631585644,-0.710407294564233,0.026461998653939833
158.80000000000155,22.518688373235666,-0.7083358736662406,0.027780093493030567
159.90000000000154,22.62348312807096,-0.7052706391762684,0.027116098607782302
161.00000000000156,22.727817735881963,-0.7023198844364549,0.026459449662732837
162.1000000000016,22.83200323446495,-0.6988318653379924,0.02644932436512626
163.20000000000158,22.93671509877761,-0.6952728555400451,0.02643562115692122
164.3000000000016,23.041546235781816,-0.692920782576237,0.026459830510716653
165.40000000000163,23.145218751884848,-0.6898483964675426,0.02675337501608821
166.50000000000165,23.25050533565911,-0.6868687592309057,0.02693688673977368
167.60000000000167,23.35470554654642,-0.6849791507393368,0.0257996825732536
168.70000000000167,23.460131092921678,-0.6815968531468846,0.026459801483149192
169.8000000000017,23.562587305108842,-0.6788243469180092,0.025147805607884433
170.9000000000017,23.669073297719613,-0.6762034277865777,0.025139892768964334
172.0000000000017,23.772852637106908,-0.6727733681891909,0.02482038553762811
173.10000000000173,23.878022465014762,-0.6702854838680736,0.024819963997869898
174.20000000000175,23.98304783093579,-0.6674683250175184,0.024819525720417346
175.30000000000177,24.087390426870016,-0.6647133444573361,0.023499988794265292
176.4000000000018,24.190819971357396,-0.6621516399087589,0.02382946666898933
177.5000000000018,24.29574992335072,-0.6588860454003884,0.022501679936387298
178.6000000000018,24.400740058063725,-0.656422762326401,0.023819116281400987
179.70000000000184,24.505537848740904,-0.6541186324744266,0.021095279486666563
180.80000000000183,24.60999986403332,-0.6521004373516393,0.021842131136398546
181.90000000000185,24.713693824516614,-0.6497340859514352,0.02149999674926928
183.00000000000188,24.818877668977127,-0.6465266486395007,0.02052930884005333
184.1000000000019,24.92355966913248,-0.6429996180405257,0.019909621593217075
185.20000000000192,25.027805845158984,-0.6407877793995841,0.01986997083811559
186.30000000000192,25.131925526642295,-0.6374018872958491,0.019869974370549937
187.40000000000194,25.235788049271797,-0.6342065173319671,0.020246636911316784
188.50000000000196,25.340457867303453,-0.6319719911612351,0.01887763075030824
189.60000000000196,25.444839057700378,-0.6291463569314616,0.01888826655513398
190.70000000000198,25.547692455300073,-0.6266353347250715,0.018542422134185443
191.800000000002,25.652847494082923,-0.6232240497616046,0.018015977605121414
192.90000000000202,25.756155774556625,-0.6207109825891803,0.016249969434029232
194.00000000000205,25.861185015195705,-0.61765822175895,0.01755853991483658
195.10000000000204,25.964487607017652,-0.6143039823672416,0.01756999597754172
196.20000000000206,26.06926061956958,-0.6108686400813541,0.017569996787963227
197.3000000000021,26.17255172347314,-0.607830107610812,0.017230119204229677
198.40000000000208,26.276915584686673,-0.6054049935214669,0.015921001568327764
199.5000000000021,26.38215650586236,-0.6024233828477475,0.014325369993510417
200.60000000000213,26.48553015745551,-0.5990596813146034,0.014271142985348817
201.70000000000215,26.589715628065935,-0.5966402726958571,0.013609865455793457
202.80000000000217,26.694097553847463,-0.5925323948386649,0.013609851423758812
203.90000000000217,26.798609992321687,-0.5883976013817364,0.01228944816519828
205.0000000000022,26.90202691469618,-0.5861262074513728,0.012289878100969265
206.1000000000022,27.00633749889164,-0.5836941410052104,0.012201484063710577
207.2000000000022,27.110442897912208,-0.5799553291621972,0.00934058245769398
208.30000000000223,27.21492354133515,-0.5756711275858151,0.008019826518338213
209.40000000000225,27.31822120247817,-0.5749994604846962,0.009326480891257205
210.50000000000227,27.420880998395198,-0.5718311970178269,0.008019862721322824
211.6000000000023,27.526869003091367,-0.5677817672492488,0.008010322984647988
212.7000000000023,27.630665207144453,-0.5661831330894542,0.005379902109318824
213.8000000000023,27.73527359780535,-0.5621246852677554,0.005379846000136634
214.90000000000234,27.840329409706577,-0.5586713942493664,0.005379846072059102
216.00000000000233,27.943583725628795,-0.5578723951343454,0.00533600492086217
217.10000000000235,28.049267741144448,-0.552953092070589,0.0027398195555572435
218.20000000000238,28.153026603346152,-0.5497376478376159,0.0027311713289663864
219.3000000000024,28.256455569233363,-0.5472625456693578,0.0004350548921663311
220.40000000000242,28.361301078584358,-0.54396056900963,-4.983725058993471e-05
221.50000000000242,28.464975490147566,-0.5419263484830894,-0.0012122401636092128
222.60000000000244,28.570576829479563,-0.5394553563071376,-0.0025030464523587703
223.70000000000246,28.674866662818044,-0.5344184633804774,-0.0028333589430586947
224.80000000000246,28.778305083721122,-0.5325201194258382,-0.0028501056738630126
225.90000000000248,28.88332244723417,-0.5298369902390666,-0.0035084084544863003
227.0000000000025,28.98765573295736,-0.525458974939191,-0.0061818547513703415
228.10000000000252,29.09177408899315,-0.5207177118758689,-0.006149960429850498
229.20000000000255,29.19714850417678,-0.516734882345288,-0.007472761397452121
230.30000000000254,29.300591118894108,-0.514737559064904,-0.008771782146491436
231.40000000000256,29.404862036360043,-0.5113983985068766,-0.010162913537650642
232.5000000000026,29.509689474088976,-0.5067724685396509,-0.010801208573786525
233.60000000000258,29.611533453660456,-0.5033072696677605,-0.012751456263156324
234.7000000000026,29.718410482830027,-0.5015365439204776,-0.014050152938035687
235.80000000000263,29.823619809705882,-0.49902019219367705,-0.015369112514761252
236.90000000000265,29.928439984130456,-0.4947040426689668,-0.017118009093297637
238.00000000000267,30.033280194324554,-0.4947074891746853,-0.019009346484630818
239.10000000000267,30.137246942828803,-0.49206860750328496,-0.019059500039200206
240.2000000000027,30.242041811315747,-0.48958276195702455,-0.020639872892512567
241.3000000000027,30.347503123139855,-0.4881335591477774,-0.02328017797961035
242.4000000000027,30.450801973726115,-0.48550723433023724,-0.024590144216456444
243.50000000000273,30.556043807031035,-0.48279780623721746,-0.025909363564533994
244.60000000000275,30.65967826004981,-0.48113918299187924,-0.02722364343917194
245.70000000000277,30.764639811160507,-0.4775845473397604,-0.029924811058031686
246.8000000000028,30.86985567592691,-0.47334128341685755,-0.032481706105659924
247.9000000000028,30.974145585810962,-0.4685912103263326,-0.0338770993715829
249.0000000000028,31.079260553862678,-0.4627982818623681,-0.033825949435099645
250.10000000000284,31.18433892090345,-0.4545678629210049,-0.036514049689126526
251.20000000000283,31.287601609385646,-0.4410830718358212,-0.03911092084480883
252.30000000000285,31.39256098781703,-0.42670965242478076,-0.03976639705797824
253.40000000000288,31.497086222647425,-0.4180185986348854,-0.04174814198655197
254.5000000000029,31.60272140543412,-0.4122132204927682,-0.04304579081104665
255.60000000000292,31.707196087588592,-0.4165153719349505,-0.04648286653239664
256.7000000000029,31.81247661638144,-0.42351608642506017,-0.04829671214285902
257.8000000000029,31.916635536583954,-0.4328397694095951,-0.051139647498561036
258.90000000000293,32.02229596750017,-0.43947385800962907,-0.05200519708512186
260.00000000000296,32.12662325860457,-0.44529567831582895,-0.053820816613171285
261.100000000003,32.232153128186575,-0.44787696279913547,-0.05764995678428164
262.200000000003,32.33593538328818,-0.4504989035135112,-0.05895863584655192
263.300000000003,32.44130028070949,-0.4506185831422746,-0.0627069099610158
264.40000000000305,32.54658880184806,-0.4509326867121529,-0.06421833913813124
265.50000000000307,32.65124987990181,-0.4502437299754018,-0.06505497729122967
266.6000000000031,32.75551057138118,-0.45002061336172017,-0.06886863405224686
267.7000000000031,32.86090161395156,-0.44920474532930127,-0.07146890445422294
268.8000000000031,32.96426218259933,-0.447137772798849,-0.07416728019690666
269.9000000000031,33.06977681252222,-0.44648782392133957,-0.0762014608685111
271.0000000000031,33.17421261190561,-0.4444482009848844,-0.07877459694083555
272.10000000000315,33.27916901555224,-0.44310995855385066,-0.08277007343463794
273.2000000000032,33.38420121884432,-0.4423359712205712,-0.08408279530606455
274.30000000000314,33.49037866807544,-0.44090708873093903,-0.08832397455654428
275.40000000000316,33.59445882167466,-0.43951460681227544,-0.09081656465798948
276.5000000000032,33.69897216171587,-0.4382891742492938,-0.09495074683496307
277.6000000000032,33.80400120103151,-0.4378139004455978,-0.09872558473733273
278.70000000000323,33.90896658168716,-0.43686058960952506,-0.101537619870264
279.80000000000325,34.01491104265963,-0.43657396345406824,-0.1041947906999603
280.9000000000033,34.11917094673072,-0.43542998465331334,-0.1054284538690724
282.0000000000033,34.22445619433089,-0.43524905135006203,-0.1098837955606986
283.1000000000033,34.329803636584536,-0.4345537010525423,-0.11362943116247148
284.20000000000334,34.434094437426516,-0.4325186887344178,-0.11646511953838612
285.30000000000337,34.53779688875467,-0.4334383303254296,-0.12088691098897231
286.40000000000333,34.64548333144159,-0.43367466986256736,-0.12358514298865275
287.50000000000335,34.74897465606794,-0.43289834693909063,-0.12732927749519263
288.6000000000034,34.85473396417219,-0.432638400575157,-0.12968234468317608
289.7000000000034,34.96082653953492,-0.43186630479779453,-0.13500649219255756
290.8000000000034,35.06599983438143,-0.4323975286825225,-0.13820690203979202
291.9000000000034,35.171183511128774,-0.43252124506591366,-0.14092006994868367
293.0000000000034,35.2771349400224,-0.43301250109619016,-0.14496365332804295
294.10000000000343,35.379374779028964,-0.43335666069692635,-0.14854673179293387
295.20000000000346,35.48700896612254,-0.4322305412608842,-0.15233600243566636
296.3000000000035,35.59216503378515,-0.4324215958459413,-0.15524450610214968
297.4000000000035,35.69652944661527,-0.4325738315126829,-0.15844204807036366
298.5000000000035,35.80372625636294,-0.4334670445952667,-0.16332186025466067
299.60000000000355,35.908611167977384,-0.4346539954423743,-0.1636668072878158
300.70000000000357,36.01261512824749,-0.43424674132421703,-0.16785433745721523
301.8000000000036,36.11946753049068,-0.4353958423409425,-0.1714838451966112
302.9000000000036,36.22509117914055,-0.4364120149303307,-0.17578406654143697
304.0000000000036,36.32961086532363,-0.436509952353864,-0.17853631328885333
305.1000000000036,36.435261191034805,-0.43705102331871715,-0.17951382437111407
306.2000000000036,36.54059969567339,-0.4375874655462172,-0.1822685303662599
307.30000000000365,36.64553202451736,-0.4365718863891694,-0.18665252634753093
308.4000000000037,36.75062488687275,-0.43722850139454233,-0.18959939118124103
309.5000000000037,36.85589143247616,-0.43808675330262214,-0.19093554441898686
310.60000000000366,36.960391329559336,-0.43854213345173965,-0.19552443014449095
311.7000000000037,37.06660256255724,-0.4400072374169142,-0.19751792827693748
312.8000000000037,37.17241249641358,-0.4399533892809605,-0.20027082831053278
313.90000000000373,37.27728516022767,-0.44094570325909205,-0.20410072946014335
315.00000000000375,37.38229220979851,-0.44190591709469873,-0.20565088804389386
316.1000000000038,37.48724930363171,-0.4427592186624605,-0.2082699810466755
317.2000000000038,37.593166292433786,-0.4437733613664371,-0.2108205248487014
318.3000000000038,37.69840240478449,-0.4451917906239141,-0.21443976030178558
319.40000000000384,37.80372659751899,-0.44449410603622985,-0.21768338147372157
320.5000000000038,37.908907540478026,-0.44679413206214913,-0.22033050395270992
321.60000000000383,38.014616166030635,-0.44981755786053085,-0.22205202372848554
322.70000000000385,38.12037215487211,-0.45022386593731484,-0.22706752508996253
323.8000000000039,38.22616125782872,-0.45159712556724935,-0.23128447334545577
324.9000000000039,38.331511839198974,-0.4530923011571364,-0.23412936609034718
326.0000000000039,38.43737685142119,-0.4554245624421906,-0.23667380429683904
327.10000000000394,38.54305378787377,-0.45630202453733004,-0.239686819088599
328.2000000000039,38.64877391673849,-0.4596053683959016,-0.24237996701159625
329.30000000000393,38.754827397351356,-0.4611756191173198,-0.2468331855887178
330.40000000000396,38.8604566282772,-0.462958307981924,-0.25096170543917085
331.500000000004,38.965926824384155,-0.46544387450056124,-0.2549696119010112
332.600000000004,39.07257192789472,-0.4658501800353462,-0.25890608633167167
333.700000000004,39.17764784725173,-0.46907758282352174,-0.26351654688925885
334.80000000000405,39.28478839693648,-0.46996494951278794,-0.2679770039602096
335.90000000000407,39.391007295890155,-0.47308748588135313,-0.2723134911057272
337.0000000000041,39.496647677416874,-0.47450078378965516,-0.2766213777762325
338.10000000000406,39.60176636227043,-0.4763673772513424,-0.279822185868817
339.2000000000041,39.70823375559952,-0.47666732109564636,-0.28551644802372644
340.3000000000041,39.81462032201632,-0.47796852182251176,-0.29044932074790974
341.4000000000041,39.920005156880094,-0.48073004926054064,-0.297417101715983
342.50000000000415,40.02665086280856,-0.4826299465395721,-0.300848221169828
343.6000000000042,40.13170609383541,-0.48430360100601516,-0.3086436192265256
344.7000000000042,40.237784309686944,-0.48505076120332036,-0.31439711534941983
345.80000000000416,40.344553382378244,-0.48703016827338247,-0.3210786465752471
346.9000000000042,40.451336879357,-0.48726625409601426,-0.3284070220537356
348.0000000000042,40.55550290813158,-0.4888182281370058,-0.33666287683887
349.10000000000423,40.663525759451694,-0.4874054388743247,-0.3455282064933396
350.20000000000425,40.770941563039216,-0.4888020495402848,-0.3543389540245343
351.3000000000043,40.87615344074897,-0.49005390179517844,-0.3635396095826944
352.4000000000043,40.98160486679214,-0.48910937866495374,-0.3718749810203432
353.5000000000043,41.089555090774,-0.4901047620147765,-0.38285623113366585
354.60000000000434,41.1957711862569,-0.4889567648139362,-0.393841714814009
355.7000000000043,41.30153966928148,-0.487515998699006,-0.40547817431285704
356.80000000000433,41.40869860935,-0.4863171867142754,-0.4177747471595765
357.90000000000435,41.51526961759176,-0.4864148374884502,-0.4321377597428695
359.0000000000044,41.62148428545555,-0.4834495806921275,-0.443999773151718
360.1000000000044,41.72715196063969,-0.48068901667283576,-0.4575155447313879
361.2000000000044,41.83465744397394,-0.47941684084415154,-0.47369113336568214
362.30000000000445,41.9418659103525,-0.4751495578304968,-0.49055045926885255
363.4000000000044,42.048080528827754,-0.4732817601939544,-0.5052235387445934
364.50000000000443,42.1543708033849,-0.4699200907924208,-0.5223476067696646
365.60000000000446,42.26195471363277,-0.4669512262665212,-0.5409356500395264
366.7000000000045,42.36822080194142,-0.4641979488758853,-0.5608487521200058
367.8000000000045,42.475157018431894,-0.4600450748248538,-0.5801551876275406
368.9000000000045,42.581080687420226,-0.4571464949355095,-0.5988581041412537
370.00000000000455,42.68845674572102,-0.45417654850233946,-0.6207877337902823
371.10000000000457,42.79513850716206,-0.44890373553584795,-0.6414661656526492
372.2000000000046,42.901283121315096,-0.44545542379262293,-0.6626334239987743
373.30000000000456,43.00851795545565,-0.44025471599520144,-0.6864585721808663
374.4000000000046,43.11557025859208,-0.435999027207489,-0.7088425342058433
375.5000000000046,43.22210930393174,-0.4338605419823724,-0.7308855376580148
376.6000000000046,43.32837951054948,-0.42968239871572234,-0.7542469234481985
377.70000000000465,43.435953755792276,-0.42535286585482496,-0.7778639799424298
378.8000000000047,43.540375501537575,-0.4218265468921675,-0.8006424291990379
379.9000000000047,43.649891610650876,-0.4203716374254935,-0.8243644936638153
381.00000000000466,43.75680212852211,-0.4195467171437644,-0.8481413398725164
382.1000000000047,43.86208977455719,-0.41542423361669123,-0.8699739990140518
383.2000000000047,43.97076063931923,-0.415745438465668,-0.8914975173115782
384.30000000000473,44.07678667134716,-0.4125472391989225,-0.9134659194921513
385.40000000000475,44.184195106008715,-0.4112627258452037,-0.9353473116573161
386.5000000000048,44.29062221066162,-0.410878726743745,-0.955763221629979
387.6000000000048,44.39558246894556,-0.41027407729583876,-0.9754686893768785
388.7000000000048,44.504871224873305,-0.4113605349029447,-0.9965965532294483
389.80000000000484,44.6106202053387,-0.41120559953530483,-1.015011789138541
390.9000000000048,44.7171390537395,-0.4105340711548785,-1.0313753730092516
392.00000000000483,44.82488352707823,-0.41132101831732193,-1.050813458080944
393.10000000000485,44.93202790588859,-0.4114507319300841,-1.06964580477998
394.2000000000049,45.03622139559209,-0.4115485062678114,-1.084695976917521
395.3000000000049,45.14559269568729,-0.41254422879280445,-1.1022342915130938
396.4000000000049,45.25317400063889,-0.4134067660135085,-1.1179247965945915
397.50000000000495,45.359263883284235,-0.41484822461625315,-1.132318316972309
398.6000000000049,45.46676065644121,-0.4141224789641463,-1.1470908491607763
399.70000000000493,45.57425401873633,-0.4147443159416719,-1.163217393302841
400.80000000000496,45.68169816690825,-0.4158342015699207,-1.176692911888412
401.900000000005,45.78780281945233,-0.41729577749412583,-1.1862260228706947
403.000000000005,45.89532190850598,-0.41611981549521065,-1.2045838120578591
404.100000000005,46.00258958442409,-0.4153413251523403,-1.2160167621943012
405.20000000000505,46.10935002772265,-0.41672661864650884,-1.2304714410839401
406.30000000000507,46.21661685424715,-0.41710512602819416,-1.2414435097216217
407.4000000000051,46.324434801119786,-0.416367448665941,-1.253709138992181
408.50000000000506,46.43161579301204,-0.41563770030613023,-1.2658093306723943
409.6000000000051,46.53764549324837,-0.41493089183472764,-1.2782124019381387
410.7000000000051,46.645874147670916,-0.41386822162187736,-1.2901040126339547
411.8000000000051,46.75348227787051,-0.41429596753840886,-1.3002426275739674
412.90000000000515,46.86134404399334,-0.41435073239595965,-1.3104130675708605
414.0000000000052,46.967930194205614,-0.4136875361369097,-1.323764652325223
415.1000000000052,47.07505201826654,-0.41239550457512714,-1.3348921438549595
416.20000000000516,47.18263390738551,-0.41237664741634855,-1.3454338222767372
417.3000000000052,47.28906952649255,-0.4133710016392367,-1.3572397053941918
418.4000000000052,47.397097586771245,-0.41335388959869307,-1.3663500936582818
419.50000000000523,47.50448397863377,-0.41298460144703397,-1.3775320252025587
420.60000000000525,47.61137056694786,-0.41272089587861643,-1.3879548772001336
421.7000000000053,47.71896647879814,-0.41093494082665244,-1.3981762687112318
422.8000000000053,47.82672824570937,-0.40953590556943015,-1.4075868901495627
423.9000000000053,47.93399401119706,-0.4087486893677579,-1.4182628393129808
425.00000000000534,48.041714759753525,-0.4077208250897647,-1.4255500701573247
426.1000000000053,48.14967793070293,-0.40837712229643347,-1.4362967344744622
427.20000000000533,48.25699079190597,-0.40934234670790853,-1.443935166866448
428.30000000000535,48.364821310450026,-0.40695520971427973,-1.4535434528565667
429.4000000000054,48.47166997083607,-0.4061373086874635,-1.4632506863459658
430.5000000000054,48.57917000000049,-0.40638000000002394,-1.4721899740000195
431.6000000000054,48.68655264952248,-0.4052906097037336,-1.4808729473958562
432.70000000000545,48.792947764685444,-0.40500604638006726,-1.4886443271194647
433.8000000000054,48.902152954546764,-0.40502231605898065,-1.4961158495049034
434.90000000000543,49.00944135013034,-0.403767617793732,-1.5064558744360155
436.00000000000546,49.11705329647319,-0.40568624874294196,-1.5134852406146941
437.1000000000055,49.224766988876674,-0.4047395639830918,-1.5206262386281115
438.2000000000055,49.33168306288524,-0.40396601018833606,-1.5304114913061437
439.3000000000055,49.437464185531496,-0.4055131748293753,-1.5364247660124581
440.40000000000555,49.54736826018477,-0.40605696459187923,-1.5443545505491763
441.50000000000557,49.655675804099495,-0.40724623473665456,-1.5520809603560868
442.6000000000056,49.76320334570059,-0.407947675014579,-1.5594754278653946
443.70000000000556,49.87085052295753,-0.4093869727580216,-1.5668578065655976
444.8000000000056,49.97883818823671,-0.4111748131784764,-1.5757849368228136
445.9000000000056,50.08660332819872,-0.41053613290291935,-1.580645430671444
447.0000000000056,50.19507354292542,-0.41083052463914316,-1.5882609826134932
448.10000000000565,50.3019721418706,-0.4117342835500389,-1.59466376956961
449.2000000000057,50.40956475392031,-0.4118420962474885,-1.600613612933198
450.3000000000057,50.517127979666554,-0.4127912928650922,-1.6067361457399745
451.40000000000566,50.62585223346571,-0.41214863201344326,-1.613055726510114
452.5000000000057,50.733347181223515,-0.41234791504272944,-1.6165237629226938
453.6000000000057,50.84015408113067,-0.41190927586703413,-1.6241044216142386
454.70000000000573,50.949445879067135,-0.41282129761275815,-1.627184224390788
455.80000000000575,51.058504557152204,-0.4118692087924633,-1.633953599691102
456.9000000000058,51.16536520761758,-0.41244184659523797,-1.6375227056223474
458.0000000000058,51.2727130707397,-0.41093175922159275,-1.6415037243712347
459.1000000000058,51.38189216060042,-0.4097802042378318,-1.6453046817941681
460.20000000000584,51.49026046982488,-0.4103675934832378,-1.649371904770073
461.3000000000058,51.59742649435426,-0.4105846904517051,-1.654977962458748
462.40000000000583,51.70614257043098,-0.4094703496343289,-1.657831421296469
463.50000000000585,51.814402338435876,-0.40996333762333276,-1.6600014817684996
464.6000000000059,51.92248195159916,-0.4117173053548153,-1.6636516299856767
465.7000000000059,52.02975599673083,-0.4118934317389147,-1.6662788374731945
466.8000000000059,52.135815364811315,-0.41216724155454604,-1.6689183369384315
467.90000000000595,52.24534827112101,-0.41283545528248944,-1.6716996516305178
469.0000000000059,52.3542873314422,-0.4154022034980092,-1.6752196057943562
470.10000000000593,52.46232214835281,-0.4171076470763566,-1.6772577734925833
471.20000000000596,52.569073680363644,-0.41771055396894746,-1.6779197363836413
472.300000000006,52.677787813471596,-0.42100324536174305,-1.6814221238629425
473.400000000006,52.786210296090054,-0.42358457492812507,-1.6818688293407953
474.500000000006,52.89268656169267,-0.42630654395790285,-1.683100856674685
475.60000000000605,53.001564970042615,-0.4273788781335443,-1.6858226119229482
476.70000000000607,53.109672383139646,-0.42909102543273203,-1.6861533254052765
477.8000000000061,53.21742257969276,-0.4295118801172606,-1.6887737249731205
478.90000000000606,53.32622041387707,-0.4330067272951789,-1.688774643364872
480.0000000000061,53.43408975060187,-0.4353136279623447,-1.690194270528568
481.1000000000061,53.54318764462853,-0.4365661043558805,-1.6924899640531716
482.2000000000061,53.65068749694727,-0.437233703545942,-1.692753788784275
483.30000000000615,53.75981449717273,-0.43810736438053516,-1.6940643858157314
484.4000000000062,53.868324790089964,-0.4393267159090268,-1.6966899086238483
485.5000000000062,53.97704889438625,-0.4413409523826911,-1.6978453375826321
486.60000000000616,54.08524684908339,-0.4427216627213011,-1.6981805672130594
487.7000000000062,54.19437757389136,-0.44201824528033057,-1.6983432794363176
488.8000000000062,54.30311491347911,-0.4431687489192079,-1.6996698610728398
489.90000000000623,54.41167656080283,-0.44350266650775716,-1.7009807012542213
491.00000000000625,54.518638812493165,-0.4430814509361423,-1.7009789417536507
492.1000000000063,54.628549394247756,-0.44366785549558285,-1.7022982245527145
493.2000000000063,54.736812756823596,-0.44411595962216116,-1.7036199812940973
494.3000000000063,54.846090590232095,-0.4451900298424144,-1.7039669828230304
495.40000000000634,54.95493566255273,-0.4449676834222516,-1.7046950448568663
496.5000000000063,55.06330289661425,-0.44453739668820647,-1.7059201563402158
497.60000000000633,55.17170535878932,-0.44380182799287116,-1.7082278676605025
498.70000000000636,55.279272626077926,-0.44349311089215365,-1.7069810998066153
499.8000000000064,55.38879321472707,-0.4445738410109532,-1.7082269246248836
500.9000000000064,55.4976599467635,-0.4461218979700162,-1.7105355247887633
502.0000000000064,55.605861288078735,-0.44669438410144113,-1.709436870546826
503.10000000000645,55.71520387705862,-0.4462350406911419,-1.7108865316343067
504.2000000000064,55.82367795705945,-0.44651277996011685,-1.712179960152426
505.30000000000643,55.93215516993053,-0.44651634342089036,-1.7121333808424959
506.40000000000646,56.03827107247841,-0.4455017516140851,-1.7131740109465867
507.5000000000065,56.15043600144073,-0.44592781534382264,-1.714810111952978
508.6000000000065,56.25855043757107,-0.44568585317331716,-1.71480994860531
509.7000000000065,56.366538310923694,-0.4466055890883549,-1.7161301408115008
510.80000000000655,56.475989382127594,-0.4479524338436726,-1.7161228500881252
511.90000000000657,56.585229482948456,-0.4467711886604728,-1.7187706118415922
513.0000000000066,56.69486202042044,-0.4474667856930666,-1.7187701707886833
514.1000000000065,56.8039027207624,-0.4457252425151512,-1.7192693504786458
515.2000000000066,56.91148362089421,-0.44634930324919303,-1.718957407412852
516.3000000000065,57.0214154920643,-0.4476172284042974,-1.722044874656064
517.4000000000067,57.13162915575174,-0.44789240330769514,-1.7227245047782707
518.5000000000066,57.2394562472281,-0.4480688635890569,-1.7240224951640486
519.6000000000067,57.34832875271488,-0.44694328837662844,-1.7239799510400884
520.7000000000066,57.45690497787052,-0.44764554837618975,-1.724030048892577
521.8000000000067,57.56643948976964,-0.44767268901841795,-1.7253494974430237
522.9000000000067,57.67516493630104,-0.44854053715685915,-1.726670526058807
524.0000000000067,57.78372317906325,-0.44913976491833707,-1.7266574312851222
525.1000000000067,57.89258683200983,-0.44827364965814537,-1.7279936113644898
526.2000000000068,58.0013915744177,-0.4479178958112586,-1.7306204211030742
527.3000000000068,58.11016998555261,-0.4482675562773195,-1.7306285392004015
528.4000000000068,58.21907382950035,-0.449225076818607,-1.7319337411419684
529.5000000000068,58.3289767816569,-0.4467150834045216,-1.7319402178401506
530.6000000000068,58.437605510340596,-0.44843559110937564,-1.7332085532562775
531.7000000000069,58.54646438545316,-0.44848603363564854,-1.7345700175058818
532.8000000000068,58.655430269435115,-0.44714737304470603,-1.735582155368295
533.9000000000069,58.764231607174445,-0.4464316822276737,-1.7372102601858184
535.0000000000068,58.87322403133061,-0.4467324637288445,-1.73851908349029
536.100000000007,58.982130270350076,-0.4482957727781482,-1.7388412229595853
537.2000000000069,59.09097808222646,-0.44726889137273357,-1.741331901492833
538.300000000007,59.1997528745078,-0.44542305460894466,-1.742140056472694
539.4000000000069,59.30854155755853,-0.4461035114978721,-1.7434663860510424
540.5000000000069,59.41794353606185,-0.4473830789040665,-1.7460194319116469
541.600000000007,59.52677798105245,-0.44509975606766117,-1.7463583052825213
542.700000000007,59.63538841351495,-0.4448579237791596,-1.7474127413976794
543.800000000007,59.74492932353965,-0.444049643324284,-1.7501482027818227
544.900000000007,59.85389243243451,-0.4428918142376334,-1.7523752666227432
546.000000000007,59.96372764011192,-0.4438352739489356,-1.7540773283147786
547.1000000000071,60.07298454355724,-0.4440931310755319,-1.7550254725428789
548.2000000000071,60.182046551441,-0.4424706779886535,-1.7576352388991765
549.300000000007,60.29189172300784,-0.44220614973840106,-1.7603899807514711
550.4000000000071,60.40056730934025,-0.4424982406352143,-1.7615698186161581
551.500000000007,60.51000186954198,-0.4396297024391684,-1.7629555789229054
552.6000000000072,60.61711154951097,-0.4386847623798258,-1.7668602579029882
553.7000000000071,60.72861849482906,-0.44059962379468154,-1.767284041772172
554.8000000000072,60.83764494650974,-0.43873960692464353,-1.7694502015297564
555.9000000000071,60.94742156848775,-0.4398293114866198,-1.773981521471101
557.0000000000072,61.05614511983988,-0.438768166566126,-1.775235953281606
558.1000000000072,61.16598885503538,-0.43811244726018517,-1.7783400612218623
559.2000000000072,61.275540414176156,-0.43713497646546606,-1.7811643582230436
560.3000000000072,61.38518903589891,-0.4358388708661542,-1.7835468532075782
561.4000000000073,61.49519868410962,-0.4366065143252097,-1.786175721246773
562.5000000000073,61.60452177027919,-0.4367711056847934,-1.788921164011441
563.6000000000073,61.71271119188963,-0.43599089330463264,-1.7919493017895292
564.7000000000073,61.82269181405589,-0.43593607389267575,-1.793235768570423
565.8000000000073,61.93190910692767,-0.43460172310497325,-1.79700708259266
566.9000000000074,62.04070526827075,-0.43687662229127694,-1.7996836790470891
568.0000000000074,62.150880549112756,-0.4357710928530035,-1.8022977715912463
569.1000000000074,62.257863410671305,-0.43489530872494253,-1.8051288747555403
570.2000000000073,62.36890562418048,-0.4370378856569446,-1.8064799119301482
571.3000000000073,62.47842042885537,-0.4366583810370926,-1.8091084272584723
572.4000000000074,62.58566371468454,-0.4362825865190306,-1.8116411956983716
573.5000000000074,62.696641234591404,-0.43354743762635745,-1.8153960190814011
574.6000000000074,62.80657634268563,-0.4361115754300601,-1.816588632506579
575.7000000000074,62.91641596543136,-0.4366183767103676,-1.8194304160676729
576.8000000000075,63.024902677076575,-0.43568658985742437,-1.8213166604760325
577.9000000000075,63.1349600884061,-0.43435926442079786,-1.8233916823698522
579.0000000000075,63.244419867851214,-0.4301272534041021,-1.825598999972375
580.1000000000075,63.3543125377053,-0.4280640726322652,-1.827381852693117
581.2000000000075,63.46403847115559,-0.4212817186197128,-1.8285601596631467
582.3000000000076,63.57232758017712,-0.4100658231542339,-1.8286499750609275
583.4000000000076,63.68187471869753,-0.4031481972399642,-1.8312903329076802
584.5000000000076,63.791892814379416,-0.39746360819474524,-1.8313917468489902
585.6000000000076,63.90048628924803,-0.3954210101473888,-1.8339295896741903
586.7000000000077,64.01011607594427,-0.39025232581440833,-1.8343371967112967
587.8000000000077,64.1195435355375,-0.38725250183681076,-1.835240075036828
588.9000000000076,64.2287769366054,-0.38769545623473073,-1.8352400750272788
590.0000000000076,64.3386268072675,-0.3920723914287543,-1.836634929075915
591.1000000000076,64.4488114071656,-0.3932747257332067,-1.8358999935250337
592.2000000000077,64.55748259737948,-0.3963168658933123,-1.8372096428031304
593.3000000000077,64.66747126669978,-0.3988284218555765,-1.8385299382415612
594.4000000000077,64.77433594794219,-0.40088669865454335,-1.8385312027702718
595.5000000000077,64.88606339981354,-0.40371671776742496,-1.8412407142126788
596.6000000000078,64.9955283153924,-0.4047506219064796,-1.841792217329132
597.7000000000078,65.10519817358383,-0.4052043336553238,-1.8425092548790163
598.8000000000078,65.21415957573181,-0.4021421651217464,-1.8438001198137495
599.9000000000078,65.32494167300203,-0.4012132369146327,-1.8452616314060175
601.0000000000078,65.43369245916891,-0.3981835409663355,-1.8458537109223472
602.1000000000079,65.54345376905646,-0.3944120753565681,-1.8457847589503507
603.2000000000079,65.65242665087527,-0.3903659116602482,-1.8471015696600808
604.3000000000079,65.76132017056415,-0.3851963026275222,-1.8476346070666332
605.4000000000078,65.87130102362357,-0.3794505963337747,-1.848418408929263
606.5000000000078,65.98058669487965,-0.3740323700375665,-1.851048890420265
607.6000000000079,66.09133642511057,-0.3668953692688594,-1.8510504839933426
608.7000000000079,66.20056578228662,-0.3627154073053826,-1.8531262886305888
609.8000000000079,66.31046721148817,-0.3556749203714229,-1.8556754209643502
610.9000000000079,66.42157471067611,-0.3487425220946522,-1.854349266106769
612.000000000008,66.53037959494813,-0.34226322183470254,-1.855646659402232
613.100000000008,66.63974678111263,-0.335969712345126,-1.8582960111726794
614.200000000008,66.74977026771121,-0.32771952976900237,-1.8592806192087346
615.300000000008,66.86025315575053,-0.3199231226061516,-1.8619716716618786
616.400000000008,66.97030266613663,-0.31203784060794426,-1.863289211467039
617.5000000000081,67.07947067050664,-0.30451574652736163,-1.8635555288309886
618.6000000000081,67.18986945099402,-0.2968596976570181,-1.864869963350006
619.7000000000081,67.29916898557082,-0.2860301956851501,-1.8662000185175498
620.8000000000081,67.40657528554578,-0.2779069380126069,-1.8702004667001457
621.9000000000082,67.51741541708726,-0.2692925928663701,-1.871462243591218
623.0000000000082,67.62753462943999,-0.25888982744284833,-1.874099654220299
624.1000000000081,67.73709448375196,-0.24859044225482932,-1.8740963805126651
625.2000000000081,67.84771037750137,-0.23837778985919916,-1.8767397389014517
626.3000000000081,67.95651207430237,-0.22751073917211798,-1.8793471187393802
627.4000000000082,68.06556247889374,-0.2164318042565553,-1.8817236499842553
628.5000000000082,68.17646183398591,-0.20560964975165155,-1.8819457874150736
629.6000000000082,68.28497538173544,-0.19400103424508658,-1.8875154963494478
630.7000000000082,68.39475270876477,-0.18121908463964265,-1.8880080727900488
631.8000000000083,68.50469134619222,-0.1681188804023778,-1.8921981106011185
632.9000000000083,68.61363683880708,-0.1570129910586911,-1.8948538465262073
634.0000000000083,68.72304450985963,-0.14304104367478238,-1.8969950854303588
635.1000000000083,68.83219722323419,-0.13101583678458512,-1.8996979973917667
636.2000000000083,68.94215770350444,-0.11787009497631251,-1.9029370556650647
637.3000000000084,69.05186107901723,-0.10352261531677405,-1.9052011091244987
638.4000000000084,69.16148980393056,-0.08698204059579699,-1.9087423290477799
639.5000000000084,69.27063291523645,-0.07302868892875312,-1.9119604858352308
640.6000000000083,69.38064831882129,-0.05667819909319918,-1.91540088854098
641.7000000000083,69.48839980123375,-0.04241706673949429,-1.9191221521194977
642.8000000000084,69.59977214505717,-0.027304537449243778,-1.922574881767534
643.9000000000084,69.70951826056773,-0.010820583968121841,-1.9264673510674104
645.0000000000084,69.82023729495937,0.006124493974164824,-1.9291078590653479
646.1000000000084,69.92917202746305,0.023895385068826474,-1.9333901908252185
647.2000000000085,70.04002523274197,0.0417763361647664,-1.9379087572319178
648.3000000000085,70.15024430322944,0.058218745058599454,-1.940555546882837
649.4000000000085,70.26042745332775,0.07447398111938157,-1.9455591082563117
650.5000000000085,70.37142765903461,0.0907134764349566,-1.9509825777344592
651.6000000000085,70.48061998399555,0.10717313496557447,-1.9565296960999623
652.7000000000086,70.59063402529024,0.1250875718147184,-1.956736278190435
653.8000000000086,70.7015018632623,0.1389803790924067,-1.9654488787287998
654.9000000000086,70.81152976677294,0.1580845104336533,-1.9717010524924743
656.0000000000086,70.92183634333021,0.17699816307918026,-1.975475973371545
657.1000000000087,71.03235956853116,0.19370156802405789,-1.980755095701198
658.2000000000087,71.1429653323642,0.20901078052902552,-1.9852945628743517
659.3000000000086,71.25320001079376,0.22920679893813875,-1.9910878058227288
660.4000000000086,71.36300849935394,0.24925772240567998,-1.9973692948570814
661.5000000000086,71.47341477148228,0.2659469222038661,-2.0031687803797915
662.6000000000087,71.58378681028385,0.2815432263828416,-2.008711619148265
663.7000000000087,71.6928156545559,0.29590297299021884,-2.014107033360398
664.8000000000087,71.80272816686956,0.3162123384494632,-2.02088565986206
665.9000000000087,71.91234650982841,0.33314497633211737,-2.027102073042263
667.0000000000088,72.02258199681465,0.349369357051627,-2.033379077538956
668.1000000000088,72.13194100427413,0.36908962080631236,-2.0394162138872733
669.2000000000088,72.24254138744091,0.38378450584033763,-2.0455600385304527
670.3000000000088,72.35155270969193,0.3951824875236412,-2.05326349138014
671.4000000000088,72.46236496049072,0.41176457515551784,-2.0606454421137337
672.5000000000089,72.57235336479702,0.4255848620670442,-2.0673239457058674
673.6000000000089,72.68300597742169,0.4321931749503032,-2.0749610554579716
674.7000000000089,72.7930535550332,0.4426439251258903,-2.0802235363570736
675.8000000000088,72.90324140486693,0.446997225334525,-2.0885372817157943
676.9000000000088,73.01240589435871,0.4453401171119075,-2.095730694404814
678.0000000000089,73.12413249215278,0.44043787377590865,-2.1033078063025235
679.1000000000089,73.23360833835012,0.42957306140707857,-2.109970102018126
680.2000000000089,73.34402594564446,0.4182803416574629,-2.116971056973849
681.3000000000089,73.45471739576645,0.40528407102117786,-2.1234123698522946
682.400000000009,73.564939160106,0.39839261187316355,-2.12837127522901
683.500000000009,73.6757787245775,0.41033776427781876,-2.135948616255334
684.600000000009,73.78653299185086,0.4423924984877063,-2.1428623929925736
685.700000000009,73.89704806991354,0.49297437061402466,-2.148625148385743
686.800000000009,74.0071360762002,0.5498713444068668,-2.156786416992463
687.9000000000091,74.11746312793717,0.6012364903822118,-2.1643258798499705
689.0000000000091,74.22877889633804,0.6560954457600301,-2.1722928850926166
690.1000000000091,74.33885245104335,0.7054894998481394,-2.1803690788842682
691.2000000000091,74.45025610052807,0.7542807775633478,-2.189161264598057
692.3000000000092,74.56049955033109,0.8016887532114845,-2.198826779140529
693.4000000000092,74.67079645056462,0.8475947927099058,-2.208429422634301
694.5000000000091,74.78230413698087,0.8906301450612144,-2.218532364481592
695.6000000000091,74.89366934207789,0.9306250398532481,-2.2270103536520987
696.7000000000091,75.00457488358876,0.9726263135543338,-2.238321255521128
697.8000000000092,75.11518334372315,1.0139300283680142,-2.247838817137667
698.9000000000092,75.22520590125954,1.0532591135722758,-2.2604399176856833
700.0000000000092,75.33619332310417,1.0875843304333888,-2.2699412904454697
701.1000000000092,75.4466413389162,1.1290888131924839,-2.2825487993566695
702.2000000000093,75.55767477204128,1.1647772699267702,-2.2947847846273377
703.3000000000093,75.66806318407014,1.1983749314385594,-2.306219761443092
704.4000000000093,75.77906483318648,1.2338139162295636,-2.3183887523791293
705.5000000000093,75.88925405756757,1.2648011172822207,-2.3307087628172583
706.6000000000093,75.99971855419511,1.2904307311457686,-2.342967831813739
707.7000000000094,76.11000849017158,1.3200746959002618,-2.356858200223809
708.8000000000094,76.22083579512028,1.3458661425648943,-2.369902662235129
709.9000000000094,76.32974206911652,1.3726189194049814,-2.381794974080273
711.0000000000093,76.44177064349125,1.3958488267119942,-2.395285860040378
712.1000000000093,76.55059532624729,1.4211020704557915,-2.408843900486799
713.2000000000094,76.65817999013954,1.4386097463164935,-2.4216052619186326
714.3000000000094,76.77125497637152,1.4573230918814182,-2.436452406752773
715.4000000000094,76.88236371897939,1.4712739565074502,-2.449491729468366
716.5000000000094,76.9919628509591,1.4872520680374526,-2.462721518157983
717.6000000000095,77.10215954230499,1.4986075192132597,-2.4777054379844197
718.7000000000095,77.21399088018886,1.5092307247886125,-2.4920003750809716
719.8000000000095,77.32187593487072,1.5176045804488223,-2.5044824201363127
720.9000000000095,77.43580856104711,1.5205816679072053,-2.519904130557393
722.0000000000095,77.54590825357478,1.5239800456334927,-2.534872639830046
723.1000000000096,77.65668249047638,1.5221781967470613,-2.550170872091318
724.2000000000096,77.76708203670879,1.5089443450352489,-2.5628149342345843
725.3000000000096,77.87805416393932,1.4773276053575881,-2.5768315252143688
726.4000000000096,77.9883384403806,1.434645615070634,-2.590557319566943
727.5000000000097,78.09917000000098,1.3701899999992737,-2.6043900696101376
728.6000000000097,78.2094717397687,1.2678750499572446,-2.61726044963395
729.7000000000096,78.31916908491837,1.1229216246005946,-2.629750118489001
730.8000000000096,78.42858692861621,0.8398499538096641,-2.6404496265077766
731.9000000000096,78.53779057174225,0.1497153606581782,-2.6471417453467745
733.0000000000097,78.64660724619854,-0.28280293938346196,-2.6498306871684805
734.1000000000097,78.7567458516124,-0.42723431452696536,-2.6509796224967284
735.2000000000097,78.86697111463442,-0.47878391940942516,-2.6525219131781617
736.3000000000097,78.97761233371057,-0.498210614122554,-2.6524681929124503
737.4000000000098,79.08791826468817,-0.5074025219230563,-2.6511501555514916
738.5000000000098,79.1982176164235,-0.5138284358659023,-2.6511520988098027
739.6000000000098,79.30862989402391,-0.5160834314231706,-2.6534545943557144
740.7000000000098,79.41864694887833,-0.5176194218043075,-2.653737715192494
741.8000000000098,79.52896737220074,-0.515623076085995,-2.6537871569413336
742.9000000000099,79.64005657741646,-0.5195481877630009,-2.655100120078618
744.0000000000099,79.75035077577867,-0.5211705323370766,-2.6557459676867263
745.1000000000099,79.8583870235441,-0.5233061816850836,-2.6544210279865164
746.0000000000099,79.9519944886036,-0.5229129874490941,-2.6544518511023654