File: 01_Data/Plastic_Laminate_Countertop_Laminate/STA/N2/10K_min/Plastic_Laminate_Countertop_Laminate_STA_N2_10KData_220930_R1.csv
##Temp./Â°C,Time/min,DSC/(mW/mg),Mass loss/mg
51.0,10.739496911467656,-1.6517151769652572,-0.0020140361511886695
52.100000000000016,11.119897698882426,-1.5281862691392814,-0.001988670969861328
53.20000000000003,11.373381879706894,-1.4496479368551622,-0.0020044086744297474
54.30000000000005,11.584906922139103,-1.3882030280609627,-0.0033468763508093247
55.40000000000006,11.770811715005854,-1.341599672938124,-0.0016454569996215973
56.50000000000008,11.942626248028803,-1.3039829048640295,-0.000734867906404979
57.600000000000094,12.1044389124607,-1.27104417838729,-0.0011951072927263162
58.70000000000011,12.25878495424662,-1.2430971600656047,-0.001689138273042179
59.800000000000125,12.410208517193686,-1.218354257735631,-0.002495019027654699
60.90000000000014,12.556739487317905,-1.197657883642239,-0.0018338081498843195
62.000000000000156,12.698235259053428,-1.178875634259228,-0.002235391013917898
63.10000000000017,12.836959802045138,-1.1596828605332188,-0.0022602067132715398
64.20000000000019,12.974808448748547,-1.1416247785827247,-0.0019589102100465716
65.30000000000021,13.108808884395291,-1.1241898338955862,-0.002446014674446939
66.40000000000022,13.242635904426049,-1.1087516181629007,-0.0023821655079330206
67.50000000000023,13.373081573522867,-1.0944552411186081,-0.0023290353119578278
68.60000000000025,13.50291722329954,-1.0788341130755958,-0.0035853911658225712
69.70000000000027,13.629970143412761,-1.0651945799160984,-0.0033238158337343116
70.80000000000028,13.755154496371027,-1.0522439848530192,-0.003406582115647261
71.90000000000029,13.881172201170108,-1.038194903442145,-0.004967669700512989
73.00000000000031,14.006023218787092,-1.0262277040846222,-0.00491539923248796
74.10000000000034,14.130433659973455,-1.013117587888083,-0.006336315015907701
75.20000000000034,14.252704719970739,-1.0004413757197699,-0.006372578214098201
76.30000000000035,14.375747107080457,-0.9899507357575272,-0.005061760174445151
77.40000000000038,14.496391233797723,-0.9787773836748719,-0.006406813358017516
78.5000000000004,14.615304672985017,-0.9664352869263273,-0.006418970306440563
79.6000000000004,14.735413136912179,-0.955338118813927,-0.0076912660578329906
80.70000000000041,14.853562713136546,-0.9449720116396404,-0.007962221154482751
81.80000000000044,14.971667616650114,-0.9354768244395474,-0.009642656398061167
82.90000000000046,15.087968808689121,-0.9254221535762482,-0.009007818013457847
84.00000000000047,15.202727114280266,-0.9180796682194498,-0.010901768726112149
85.10000000000048,15.32124141190811,-0.9074636887531287,-0.011678294331247674
86.2000000000005,15.434430450590284,-0.8993843575446211,-0.011647166580297963
87.30000000000052,15.550098757924523,-0.8902410805933594,-0.011651577926975243
88.40000000000053,15.663743715924923,-0.8838430375953642,-0.011647881679150096
89.50000000000054,15.776812356186475,-0.8759071648219287,-0.012961484559578906
90.60000000000056,15.889682018539188,-0.8682897038955776,-0.012960047766320315
91.70000000000059,16.000578739376174,-0.8621216558534249,-0.0129615540888679
92.8000000000006,16.114534607747792,-0.8560586498847499,-0.01427975445176033
93.9000000000006,16.224764078065846,-0.8495386236983664,-0.0156221603310005
95.00000000000063,16.336219991845034,-0.8443850404132086,-0.016266975766754843
96.10000000000065,16.445780344004234,-0.8381918845195703,-0.016916997488815255
97.20000000000066,16.55623860765165,-0.8315602831697434,-0.017071889319330236
98.30000000000067,16.665907356058298,-0.826784748787905,-0.016938209178683383
99.40000000000069,16.775234927578968,-0.821320780838158,-0.018229804743687072
100.50000000000071,16.884876610820427,-0.8162074009127562,-0.01859508915565522
101.60000000000072,16.994616445060654,-0.8103967578515199,-0.01820733726817192
102.70000000000073,17.10275131734231,-0.8054442184838199,-0.01822821708660749
103.80000000000075,17.21146432704696,-0.8010505718283504,-0.01922906323793816
104.90000000000077,17.321211282737288,-0.7973377567747667,-0.019551822984320122
106.00000000000078,17.428176940656776,-0.7925399537560264,-0.019567063363433057
107.10000000000079,17.53580191814055,-0.7889616286123107,-0.019474317803811925
108.20000000000081,17.644258559675283,-0.7832563414521623,-0.02053987944751201
109.30000000000084,17.750866933813032,-0.778416734488533,-0.020849749249562954
110.40000000000084,17.85957500205418,-0.7748703651915051,-0.02087190072704015
111.50000000000085,17.968617894708398,-0.7694511268228185,-0.021858474541178285
112.60000000000088,18.074844889856887,-0.7652664451359712,-0.019500630870467273
113.7000000000009,18.18293514399893,-0.7616067746079958,-0.02217975616092227
114.8000000000009,18.290038537811817,-0.7578511194280694,-0.02151613187944834
115.90000000000092,18.397888330808314,-0.7514594936390226,-0.022192471574881356
117.00000000000094,18.504465680927332,-0.7486238896278113,-0.022161386157453666
118.10000000000096,18.612744348695717,-0.7452738485961076,-0.02352976710770438
119.20000000000097,18.719268774462606,-0.7406408688485671,-0.023499976990765337
120.30000000000098,18.825272761161465,-0.7366846572339137,-0.023500047917442313
121.400000000001,18.932276612726906,-0.7323070487760894,-0.02339922816611706
122.50000000000102,19.039353096441587,-0.7281276339048028,-0.02487263390243344
123.60000000000103,19.145631334289046,-0.7247591389772683,-0.02480997221173542
124.70000000000104,19.252899622924417,-0.7196382423808849,-0.024495369878325235
125.80000000000106,19.359835004501438,-0.7154091104264415,-0.024789794664224374
126.90000000000109,19.464538687245337,-0.7105269294490241,-0.024819708628954995
128.00000000000108,19.570629588516088,-0.7068570143787007,-0.02250578965218475
129.1000000000011,19.676995782969925,-0.7027222990764682,-0.02400272037181761
130.20000000000113,19.782166639285588,-0.69931801674193,-0.02526028402088354
131.30000000000115,19.89001566440784,-0.6939087722213233,-0.026570029757726044
132.40000000000117,19.995510538014102,-0.6896339313317024,-0.026553478326750035
133.50000000000117,20.100995232247357,-0.6838433706484375,-0.026900157193751273
134.6000000000012,20.20693862108729,-0.6797476015212482,-0.02657008979973563
135.7000000000012,20.312311246399112,-0.674737330407602,-0.026570289206305997
136.8000000000012,20.41891290415192,-0.6717009876527876,-0.026574341618855968
137.90000000000123,20.524664661268496,-0.6650907899292188,-0.027897018929329498
139.00000000000125,20.630246242586555,-0.6599014749363801,-0.027912512866553385
140.10000000000127,20.731596506725406,-0.657328353257149,-0.02758431988619936
141.2000000000013,20.840560851457266,-0.6520096438429412,-0.028850191045571183
142.3000000000013,20.94671818238707,-0.6463729229520142,-0.029216929742867048
143.4000000000013,21.051702404701754,-0.6424620780532787,-0.02821999422131727
144.50000000000134,21.156582729615746,-0.6373916492081069,-0.0295397851956003
145.60000000000133,21.26139676769095,-0.631104830039904,-0.02952819893155878
146.70000000000135,21.36733473455539,-0.6264560084491579,-0.03052991143458783
147.80000000000138,21.473019343154096,-0.621782656196352,-0.02924428800651402
148.9000000000014,21.575169875750518,-0.6170711169357967,-0.030520166355706646
150.00000000000142,21.680145019442005,-0.6103701014404829,-0.030542260477936622
151.10000000000142,21.78400057683448,-0.605949276330926,-0.03184017042920395
152.20000000000144,21.889670592589255,-0.5995952667638993,-0.030529182461316307
153.30000000000146,21.99514247094549,-0.5946042853149994,-0.03186505518113014
154.40000000000146,22.09959575664024,-0.589072916882817,-0.03435238609340274
155.50000000000148,22.203734543727318,-0.5831904920317003,-0.033160277889092704
156.6000000000015,22.308133798746958,-0.5790452673376769,-0.03480148884892298
157.70000000000152,22.41250845122517,-0.5728108024144468,-0.035462610058064836
158.80000000000155,22.516927959910632,-0.5682592617097595,-0.03545968979053438
159.90000000000154,22.6215528380234,-0.564513545583903,-0.036571467988742334
161.00000000000156,22.726298232736074,-0.5593504072828474,-0.035469711001117954
162.1000000000016,22.831523416663675,-0.5542479212934618,-0.036788542752423936
163.20000000000158,22.93492736214186,-0.5497235540421632,-0.03678995089024051
164.3000000000016,23.040469751814886,-0.5461479912126909,-0.038084640428476035
165.40000000000163,23.144410895870877,-0.5421480601436651,-0.038436190033393824
166.50000000000165,23.249603171009383,-0.5380916931326777,-0.03975014203651428
167.60000000000167,23.353066175534373,-0.5340117075857582,-0.03974782311326219
168.70000000000167,23.45811066640995,-0.5292914290690125,-0.0423792088527839
169.8000000000017,23.563265236003588,-0.5256224768046468,-0.041385425113849905
170.9000000000017,23.66832021475123,-0.5198806925561094,-0.04163889217911354
172.0000000000017,23.76889947725012,-0.5189252758121604,-0.042710150109865896
173.10000000000173,23.876266014086593,-0.5146825353182535,-0.04271015244601006
174.20000000000175,23.981154771523226,-0.510408956739249,-0.04367734444449045
175.30000000000177,24.086009520601618,-0.5071752736014414,-0.045003801421080514
176.4000000000018,24.190527734603283,-0.5033234520137404,-0.04402745270804287
177.5000000000018,24.29400091725663,-0.5006865423143045,-0.04669638225281636
178.6000000000018,24.399481745992805,-0.4965084541366558,-0.04773706359734797
179.70000000000184,24.50374327061625,-0.49388859534361046,-0.047979910022723615
180.80000000000183,24.608984571657768,-0.4901488255279815,-0.04797990997961721
181.90000000000185,24.712543150663738,-0.48761835104312523,-0.04827552404195812
183.00000000000188,24.818405926923823,-0.48338641217216843,-0.050517077103143126
184.1000000000019,24.920605056872454,-0.4814426014550466,-0.05062006096691496
185.20000000000192,25.02657131836838,-0.47985332671432374,-0.05186353624624607
186.30000000000192,25.130807636853334,-0.4759960820458774,-0.05325954901626728
187.40000000000194,25.23459936364823,-0.47395481037902987,-0.05455802614419136
188.50000000000196,25.339263140580123,-0.4705127423533684,-0.05587983144479036
189.60000000000196,25.442398473199745,-0.46845729532594227,-0.05588923755058195
190.70000000000198,25.547469985631245,-0.4653930413627496,-0.05719998625639189
191.800000000002,25.65084859635776,-0.4620672760886853,-0.057118068637770136
192.90000000000202,25.756197994900813,-0.4590813223969025,-0.05851997979567036
194.00000000000205,25.86084171271832,-0.4576415618429664,-0.05893942796471485
195.10000000000204,25.964070340120948,-0.4555309259607776,-0.06116014131210701
196.20000000000206,26.068206246997953,-0.45380593134786545,-0.06248212201860959
197.3000000000021,26.173453379775005,-0.45152039957199985,-0.06376245385513313
198.40000000000208,26.2767083365918,-0.4495384076626663,-0.06414455744515202
199.5000000000021,26.380657649826514,-0.44816517532718053,-0.06520934128997835
200.60000000000213,26.485181721801663,-0.4446021276696758,-0.06533338589960946
201.70000000000215,26.58888301285884,-0.44399233752317935,-0.0667599909957759
202.80000000000217,26.69298003077854,-0.4421596304103001,-0.06809160249916335
203.90000000000217,26.79844023706793,-0.43894081860099043,-0.0693900853575431
205.0000000000022,26.901936563225853,-0.4369409404475756,-0.07168549796121226
206.1000000000022,27.005601584293025,-0.43649593662234565,-0.07298054636454276
207.2000000000022,27.109359320600383,-0.43442563346891216,-0.07323269465682936
208.30000000000223,27.213724261906748,-0.4338610458960467,-0.07598733194660046
209.40000000000225,27.318342061710844,-0.4321807752919235,-0.07729678239889148
210.50000000000227,27.422460774579214,-0.4321136012621289,-0.07731830955957442
211.6000000000023,27.526481133566165,-0.4300338189078558,-0.07906013316186433
212.7000000000023,27.63001925637484,-0.42744308214394633,-0.08123998027703516
213.8000000000023,27.734612094989274,-0.42821074413781796,-0.08253146525155053
214.90000000000234,27.837296931710444,-0.42857926695267357,-0.0838798497533797
216.00000000000233,27.94346306668107,-0.42822515120224186,-0.08640289176162375
217.10000000000235,28.048147250225128,-0.42852672110568224,-0.08782974223492879
218.20000000000238,28.1526364722248,-0.42798202081970754,-0.08916597703906382
219.3000000000024,28.256636105121636,-0.4280999036483844,-0.09046978230298075
220.40000000000242,28.35794156706216,-0.42758559635442583,-0.09178945971371277
221.50000000000242,28.46494754058319,-0.427374590991574,-0.09310020165324628
222.60000000000244,28.570162855701618,-0.4274517840517281,-0.09574786426584847
223.70000000000246,28.673241171645007,-0.42875835636384124,-0.09716512653982123
224.80000000000246,28.778985779857923,-0.4290337692821713,-0.09848023246656412
225.90000000000248,28.883318972852845,-0.4286105521790943,-0.09975672113133127
227.0000000000025,28.987896028928798,-0.4286649328646136,-0.1024396403159411
228.10000000000252,29.091934734070435,-0.42873342953191695,-0.10411263441605945
229.20000000000255,29.19625795244634,-0.4284427186472801,-0.10739753175071609
230.30000000000254,29.300910683215918,-0.4293308845697783,-0.10735793015012352
231.40000000000256,29.406206838480927,-0.43019836658675426,-0.11168494361266124
232.5000000000026,29.508883846929642,-0.4299233101004065,-0.11427693432794728
233.60000000000258,29.61471281645821,-0.43032497006919385,-0.11627137033712875
234.7000000000026,29.718566663242267,-0.4301792780381914,-0.11758383924667859
235.80000000000263,29.823378049606568,-0.43127914943600476,-0.12021866086922994
236.90000000000265,29.924182734871383,-0.4315081111992051,-0.1232604671144597
238.00000000000267,30.032150713243045,-0.4306518168897625,-0.12480148885420084
239.10000000000267,30.13711944217437,-0.43174774594247606,-0.12737881195571044
240.2000000000027,30.240779459613282,-0.43225233465592183,-0.12876049643391596
241.3000000000027,30.34523811290823,-0.4306856539092676,-0.13290534278342703
242.4000000000027,30.450998725985972,-0.4325496051289936,-0.13615092210480162
243.50000000000273,30.555412812434668,-0.43268787214130944,-0.13894511519482577
244.60000000000275,30.65907502817128,-0.4335100265871859,-0.14293942353037803
245.70000000000277,30.76359553145056,-0.43380915446857504,-0.1442626815730801
246.8000000000028,30.868318528513655,-0.43469922607941464,-0.14820695747754087
247.9000000000028,30.972606910866073,-0.4349885553261487,-0.15111144371014396
249.0000000000028,31.07633978934849,-0.43522639250006334,-0.15530723224677212
250.10000000000284,31.182572783031066,-0.4359301798053374,-0.15829036107446193
251.20000000000283,31.28691068372161,-0.43440418669599384,-0.16203027459130404
252.30000000000285,31.390620392506616,-0.43409335382232017,-0.16596724643084837
253.40000000000288,31.493480913527634,-0.4338105629683216,-0.16995797344008468
254.5000000000029,31.600284197491746,-0.4343700659914332,-0.17345469505918887
255.60000000000292,31.705217849117155,-0.43528258512511914,-0.17611979817027068
256.7000000000029,31.809877476433066,-0.43450894519023864,-0.18134617702520117
257.8000000000029,31.913092714050094,-0.43514195583680493,-0.18600478095662876
258.90000000000293,32.01734793672959,-0.43456463055365807,-0.19057677501156833
260.00000000000296,32.12129754129146,-0.434305577103029,-0.1936160968535101
261.100000000003,32.226634298048374,-0.433161470894791,-0.19911284290232834
262.200000000003,32.33158220972863,-0.4329446350249108,-0.20233263025285764
263.300000000003,32.43617480113467,-0.4328872464790384,-0.20856537923442753
264.40000000000305,32.5405318127144,-0.43212755939939507,-0.21273183688363329
265.50000000000307,32.64531526528847,-0.4313840309501842,-0.2175585961303761
266.6000000000031,32.750367313986494,-0.43059788518421566,-0.22452457022632277
267.7000000000031,32.855245942212164,-0.4303325741533654,-0.23069375442699247
268.8000000000031,32.95897866708671,-0.4297524333031457,-0.233820748907847
269.9000000000031,33.063166567858836,-0.42816684434029634,-0.24144399292547192
271.0000000000031,33.16767505244137,-0.4280746145909667,-0.24794161132217019
272.10000000000315,33.2727838291344,-0.42696010925194894,-0.25366145296645426
273.2000000000032,33.37626184481912,-0.4259298935407009,-0.26191710614097863
274.30000000000314,33.4825240477102,-0.4261466754171108,-0.2669122328178992
275.40000000000316,33.58740156522346,-0.42463623765278585,-0.27407996847895966
276.5000000000032,33.69181998180494,-0.42239755044840593,-0.2808658383807523
277.6000000000032,33.79734830190496,-0.4219938468960753,-0.28742854062682843
278.70000000000323,33.90196780307632,-0.42107228231240884,-0.2948659655380488
279.80000000000325,34.006309055473984,-0.42084077618393034,-0.3028828722244503
280.9000000000033,34.11152687059121,-0.4182494455376598,-0.3091771708805471
282.0000000000033,34.216702613201605,-0.41712691767765997,-0.3172661443630709
283.1000000000033,34.32181969359144,-0.41712648329965263,-0.3273558867615618
284.20000000000334,34.42652102217582,-0.41593565726625026,-0.3344499313072409
285.30000000000337,34.53135842133104,-0.4144938099745193,-0.3443909384835093
286.40000000000333,34.63604210188012,-0.4133487036508855,-0.3515041173352147
287.50000000000335,34.74188571110748,-0.4127356067850155,-0.36205437472043744
288.6000000000034,34.84645958108345,-0.4109482702926959,-0.37134660556268306
289.7000000000034,34.95207059356562,-0.4105934908037679,-0.38133357466624096
290.8000000000034,35.05762624153692,-0.40961455077268244,-0.3924271971516693
291.9000000000034,35.16244707154107,-0.4071821194690656,-0.40319600544837186
293.0000000000034,35.26743236015904,-0.4067266696155802,-0.4135274961763806
294.10000000000343,35.37260862713365,-0.40594790122318414,-0.4240528019688794
295.20000000000346,35.47768840484696,-0.40451829956233665,-0.43596229008888665
296.3000000000035,35.58154347564367,-0.4033439150785943,-0.44717141618718026
297.4000000000035,35.688147352945236,-0.4022476195502946,-0.46128047326980814
298.5000000000035,35.79338958891513,-0.4015628790323006,-0.47302103732356926
299.60000000000355,35.898520070927134,-0.4021440605504153,-0.4848582381411295
300.70000000000357,36.00269222371484,-0.40035693692727115,-0.49876654707440915
301.8000000000036,36.10857479508432,-0.40057570003297616,-0.5119961556264063
302.9000000000036,36.213897508174234,-0.40003356097970866,-0.5279704453783949
304.0000000000036,36.3195202238056,-0.40218173507298616,-0.542045469309532
305.1000000000036,36.423516028916715,-0.4008594086433801,-0.5571140279028208
306.2000000000036,36.52968924130271,-0.40034358139095333,-0.5732704638341404
307.30000000000365,36.63360225236649,-0.4004521306563496,-0.5878951287670473
308.4000000000037,36.739491114380314,-0.39866660859867387,-0.6032048833700769
309.5000000000037,36.845976318281174,-0.40034357207212934,-0.6205750567643742
310.60000000000366,36.95128085802613,-0.40028830370986496,-0.6364465294594437
311.7000000000037,37.05633767337989,-0.40023666602655394,-0.6560590037366261
312.8000000000037,37.16119041800875,-0.4014882783244765,-0.6747418117721384
313.90000000000373,37.26705141988029,-0.40166817405447175,-0.6933349021184649
315.00000000000375,37.372117970406535,-0.4018832627897011,-0.7137623167926099
316.1000000000038,37.47753520512619,-0.4014509657842294,-0.7334809257976485
317.2000000000038,37.5828374466131,-0.4022684945820282,-0.7534026201023734
318.3000000000038,37.68873200681546,-0.4031064659446322,-0.7731598189282214
319.40000000000384,37.79356569126912,-0.4047054859878035,-0.7959259884739973
320.5000000000038,37.89935814268562,-0.40425286234058155,-0.8193696724221686
321.60000000000383,38.003962273018374,-0.4048707499340119,-0.840822778590661
322.70000000000385,38.1093482741312,-0.40523640083156615,-0.8657959713295074
323.8000000000039,38.21506434315743,-0.4054284801215403,-0.8915633796583089
324.9000000000039,38.32028026514681,-0.40706668284396497,-0.9149749799238935
326.0000000000039,38.4261949736564,-0.4057840021647134,-0.94130163890576
327.10000000000394,38.53191004796893,-0.40769290467519365,-0.9661240302309286
328.2000000000039,38.637916981237545,-0.40716476503760834,-0.994492408978211
329.30000000000393,38.74276280309754,-0.4084016147065727,-1.0225143057831447
330.40000000000396,38.846038273188285,-0.410418432586318,-1.047711170195734
331.500000000004,38.95367088281803,-0.41087531148978,-1.0766673346458489
332.600000000004,39.059371568171784,-0.41081627671075666,-1.1089910153075238
333.700000000004,39.165521875685016,-0.4115175627421314,-1.1383616411650008
334.80000000000405,39.27126178583197,-0.41370052037408617,-1.1694557507181487
335.90000000000407,39.37615727057754,-0.4156534485543127,-1.2006677595662323
337.0000000000041,39.48195145935223,-0.41774394258943076,-1.232301474157726
338.10000000000406,39.58759766075566,-0.4215480726232449,-1.2643414786469074
339.2000000000041,39.6936104060383,-0.42615854050715163,-1.2975545578528949
340.3000000000041,39.79907400341949,-0.4303832821532864,-1.3303366985034581
341.4000000000041,39.9053725493556,-0.43426298704986194,-1.3642721595339409
342.50000000000415,40.01008103270207,-0.43935120269702366,-1.3947022000649616
343.6000000000042,40.11596068263045,-0.4442627057586135,-1.4289585101754092
344.7000000000042,40.222659728635136,-0.4502586979424529,-1.4615567604197022
345.80000000000416,40.327307391220295,-0.4555380055938225,-1.4931938445370592
346.9000000000042,40.434636110167446,-0.4604500289060344,-1.5250463551136337
348.0000000000042,40.54076317773154,-0.4661819703026811,-1.5547720072848072
349.10000000000423,40.64710649916893,-0.46993931614000034,-1.5816902638676678
350.20000000000425,40.753029745578374,-0.47109966800928266,-1.6103662134919507
351.3000000000043,40.85829631081028,-0.4731341176429041,-1.635867949325187
352.4000000000043,40.96505663597442,-0.47257338578129393,-1.6601058764585703
353.5000000000043,41.070437088374675,-0.4732669028757957,-1.6806844261412084
354.60000000000434,41.17716790438264,-0.4718124670504221,-1.7010409298652505
355.7000000000043,41.28307461658799,-0.46846604102725947,-1.71920877432476
356.80000000000433,41.38906749133517,-0.467250674859524,-1.7355363466874172
357.90000000000435,41.495802918437946,-0.46493857625874413,-1.750253068452829
359.0000000000044,41.601886921580565,-0.46404955520191243,-1.765021482270662
360.1000000000044,41.708336395717005,-0.46181184296038796,-1.777085631137933
361.2000000000044,41.814895017081774,-0.45783948167435917,-1.788095691665117
362.30000000000445,41.92075237119861,-0.45726486968286695,-1.7981924786523273
363.4000000000044,42.026677844097776,-0.4532000107440764,-1.8074980561858927
364.50000000000443,42.13521837899795,-0.44966180045232745,-1.815362253779345
365.60000000000446,42.24154753247611,-0.4443327903988807,-1.8246373051316582
366.7000000000045,42.34754641988326,-0.4386825358071934,-1.8311786870493334
367.8000000000045,42.45366549761212,-0.43720658320033,-1.8389916044230143
368.9000000000045,42.560664652634784,-0.4328304485880331,-1.844558305600441
370.00000000000455,42.66737320405273,-0.43168965137373033,-1.8527510127037465
371.10000000000457,42.773151556079235,-0.4306770048171934,-1.8598531291257525
372.2000000000046,42.8795684564316,-0.43007186008676485,-1.865121008395343
373.30000000000456,42.98695588817377,-0.4288442432455815,-1.8694075950003652
374.4000000000046,43.09349204902024,-0.42913079291147666,-1.8754686427125828
375.5000000000046,43.2000594920431,-0.4291888439865062,-1.8827334254636656
376.6000000000046,43.3062251042447,-0.4284823917580619,-1.8862236970015256
377.70000000000465,43.41364354961749,-0.42453866989063616,-1.8913154441464575
378.8000000000047,43.52052250664091,-0.42456359500301083,-1.8968459171318885
379.9000000000047,43.62707889125023,-0.42393000387831176,-1.900682264977815
381.00000000000466,43.73300621392489,-0.4210683447892678,-1.9054084419312824
382.1000000000047,43.84026548460669,-0.42008664127977474,-1.9088558343642132
383.2000000000047,43.9464358155103,-0.41892111231228,-1.9142249411351693
384.30000000000473,44.05332428742314,-0.41666692279089185,-1.9172386774056496
385.40000000000475,44.160491107180185,-0.4131679097540426,-1.919905055541411
386.5000000000048,44.266536733314545,-0.4120652711083235,-1.9258923358727107
387.6000000000048,44.37386864121601,-0.4108452043856699,-1.93059295600968
388.7000000000048,44.4807965221447,-0.4094750759165873,-1.9347099274671682
389.80000000000484,44.587839951867046,-0.40676806794544706,-1.9389117677542882
390.9000000000048,44.69327376165107,-0.4053087594980608,-1.9420438022688156
392.00000000000483,44.80153552021771,-0.404644938736643,-1.946645380057597
393.10000000000485,44.90827971879429,-0.4032992675821038,-1.9493994854154633
394.2000000000049,45.01455554527621,-0.3997460850410087,-1.952616774689762
395.3000000000049,45.121359297943556,-0.39812325150835254,-1.9583083548461402
396.4000000000049,45.228662818487535,-0.3966309115171054,-1.9626812209158468
397.50000000000495,45.33543998353278,-0.3930725110247779,-1.966562158945965
398.6000000000049,45.44267348019173,-0.39358591790958886,-1.9709412545375824
399.70000000000493,45.54826704874017,-0.39171668579209634,-1.9751411106756556
400.80000000000496,45.656179371982,-0.3896479735465108,-1.9786172104150113
401.900000000005,45.76479169482027,-0.3879318015279578,-1.9818926144371622
403.000000000005,45.87141684126083,-0.38536127424820926,-1.9855593013990454
404.100000000005,45.97804406371082,-0.3841127664192612,-1.9901694049378895
405.20000000000505,46.08539629218246,-0.38172834363196567,-1.9940136425938895
406.30000000000507,46.192280463350116,-0.3814861351533999,-1.9998000604424244
407.4000000000051,46.29927126213344,-0.3785194715607814,-2.0021292970686235
408.50000000000506,46.40578082092683,-0.37553305898663014,-2.0073303844822097
409.6000000000051,46.512672140014814,-0.3752860594415369,-2.012150169286488
410.7000000000051,46.619372573495085,-0.3718782105197133,-2.01617659627256
411.8000000000051,46.72667763338195,-0.36950882703233406,-2.021721757749399
412.90000000000515,46.833442581521794,-0.3681265585110497,-2.0262594131677814
414.0000000000052,46.939863068604026,-0.36482655311805773,-2.03045449188843
415.1000000000052,47.04851043483224,-0.36290323461267954,-2.034364217214155
416.20000000000516,47.1549574093563,-0.3619585804279273,-2.039082046515895
417.3000000000052,47.261496767683084,-0.3576803567420663,-2.04238960088081
418.4000000000052,47.36819538105808,-0.3570961715069373,-2.046996881832969
419.50000000000523,47.47397521808184,-0.3546106525215381,-2.052630382487515
420.60000000000525,47.584254261645576,-0.35306916504222446,-2.0571163247081232
421.7000000000053,47.69096966710646,-0.35029298782349405,-2.061515193908506
422.8000000000053,47.798195373061276,-0.34903570766456643,-2.0649491969456664
423.9000000000053,47.90532702909261,-0.3463550891685059,-2.0696038958942307
425.00000000000534,48.01302642390512,-0.34621856852274235,-2.074318338594815
426.1000000000053,48.11966727576067,-0.3455792750636228,-2.0793509709698093
427.20000000000533,48.22678187833345,-0.34299946067651954,-2.0855647811246265
428.30000000000535,48.333706530076846,-0.3439888283446592,-2.0892950264826258
429.4000000000054,48.44076677648636,-0.3423057229098868,-2.0937160933080587
430.5000000000054,48.54852471041372,-0.34165759269663387,-2.099776311936347
431.6000000000054,48.65566417202676,-0.3410220167318995,-2.1037370404302362
432.70000000000545,48.76321359225311,-0.3402257720089827,-2.107069333784776
433.8000000000054,48.87166616404207,-0.3391571503626628,-2.1134762497235338
434.90000000000543,48.978897669893904,-0.33921762990999227,-2.1178297078084563
436.00000000000546,49.08520720203704,-0.3388455247524073,-2.1220721455013614
437.1000000000055,49.19341047904731,-0.33565359583319115,-2.1257224689037333
438.2000000000055,49.30081907480198,-0.3351886037863243,-2.1306792648679305
439.3000000000055,49.40775230880581,-0.33481082952082025,-2.1348832654558607
440.40000000000555,49.51585676305772,-0.3333145324272118,-2.1388596484560765
441.50000000000557,49.62304616624749,-0.3321639045022943,-2.145635217200737
442.6000000000056,49.730364880032774,-0.33297353844734046,-2.148794528685572
443.70000000000556,49.83843820891123,-0.331951386577687,-2.1528300912861464
444.8000000000056,49.94583758595718,-0.33191288031951677,-2.1572014304280387
445.9000000000056,50.054022397285564,-0.32989190437275323,-2.161647726798126
447.0000000000056,50.16104936608935,-0.3295695665522256,-2.1658071692220906
448.10000000000565,50.26860678761034,-0.32820313296401327,-2.170685236651884
449.2000000000057,50.37709876125467,-0.32732514335966423,-2.175815336550833
450.3000000000057,50.48420653271695,-0.3281788477766374,-2.178820427436836
451.40000000000566,50.5922464055609,-0.32855028665589425,-2.1840611469512567
452.5000000000057,50.700762963657525,-0.3268694584365536,-2.186779632007297
453.6000000000057,50.80849585087192,-0.32558765205142126,-2.1916583609980345
454.70000000000573,50.9164478988422,-0.3255129891443171,-2.195275519415702
455.80000000000575,51.02144785768664,-0.32557639989992665,-2.1994643957199456
456.9000000000058,51.132481683020984,-0.32390340159633696,-2.2040871719594755
458.0000000000058,51.24050241918435,-0.3231804854970994,-2.2088139240925826
459.1000000000058,51.348729922880096,-0.32187825037019013,-2.2115897369758706
460.20000000000584,51.456079495513876,-0.3227847427285422,-2.214576462160541
461.3000000000058,51.56390006382185,-0.32015214011279847,-2.2192450901799163
462.40000000000583,51.6696130329492,-0.31958191388931045,-2.2223971703576453
463.50000000000585,51.77851359171071,-0.3174921234227063,-2.2277439710632536
464.6000000000059,51.886445326737245,-0.3173831064920526,-2.230911576529578
465.7000000000059,51.99410754271354,-0.31518559495931775,-2.2345223624906088
466.8000000000059,52.102369915518544,-0.3129836561200582,-2.2368620536346184
467.90000000000595,52.208417705793394,-0.31429014377522485,-2.2414365890871544
469.0000000000059,52.3175198111552,-0.3129673845325836,-2.245544349071414
470.10000000000593,52.426314712088434,-0.31235256545274437,-2.248945948703658
471.20000000000596,52.533362248493454,-0.3109095258050181,-2.2524707094343825
472.300000000006,52.63896614674201,-0.31051682108970063,-2.255158338176244
473.400000000006,52.74862215815294,-0.31058837954788887,-2.259452404263513
474.500000000006,52.85679299765986,-0.3076537008805154,-2.2626353482866204
475.60000000000605,52.965023609410586,-0.3074330406719685,-2.26682999487858
476.70000000000607,53.07332809398507,-0.30910615119453555,-2.2704623312371033
477.8000000000061,53.180399018090775,-0.30950909828428547,-2.273942244472087
478.90000000000606,53.289170973091245,-0.30966993153975503,-2.276250123299356
480.0000000000061,53.397393898816155,-0.3089833252003883,-2.281665868081288
481.1000000000061,53.50554724863489,-0.3078474839281662,-2.28477248998192
482.2000000000061,53.61338574799359,-0.3075186448708671,-2.286652556026096
483.30000000000615,53.72201776121642,-0.30595563705871187,-2.2894245899108636
484.4000000000062,53.830245716354156,-0.3059482584296953,-2.292049975127734
485.5000000000062,53.9386618490308,-0.3055314463924802,-2.2961841850630575
486.60000000000616,54.04761843065819,-0.3055921431924282,-2.29944372799169
487.7000000000062,54.15468446745771,-0.30685528169871634,-2.303898280358376
488.8000000000062,54.26294487114187,-0.30592471861639836,-2.306895603241049
489.90000000000623,54.372083122750034,-0.30529777189810947,-2.310332945640699
491.00000000000625,54.480093818932886,-0.3061633245886971,-2.3128240778061837
492.1000000000063,54.58647674077197,-0.3049312306912961,-2.3154514633089245
493.2000000000063,54.69566974708935,-0.304336292564115,-2.318072419140437
494.3000000000063,54.80450200758224,-0.3038532387650944,-2.3219667306625054
495.40000000000634,54.91314138394126,-0.30524994187336163,-2.3237812563270657
496.5000000000063,55.021507511967386,-0.30445512741169983,-2.3273435426976197
497.60000000000633,55.12842386102581,-0.3042971185054869,-2.327773816565041
498.70000000000636,55.23767030763016,-0.3036688560459707,-2.3315812619151255
499.8000000000064,55.34645313935598,-0.3035528403450191,-2.333335120550978
500.9000000000064,55.45380901614531,-0.3032024709751226,-2.3372184602449853
502.0000000000064,55.56283666078833,-0.3028697707234428,-2.3391469656201105
503.10000000000645,55.67110752465557,-0.3032029576925277,-2.3427856121704584
504.2000000000064,55.77784240617989,-0.30311847403358666,-2.3468815323923073
505.30000000000643,55.88723108523649,-0.3025582416059975,-2.346950629012815
506.40000000000646,55.9953112320501,-0.3024389777838198,-2.3498322584608493
507.5000000000065,56.10437064979738,-0.30275767673997,-2.35396049299897
508.6000000000065,56.212390300996,-0.30187768744433896,-2.3549291206699015
509.7000000000065,56.320867997257785,-0.3020271678549173,-2.3580425080093144
510.80000000000655,56.42865942316185,-0.3013582543475731,-2.3606842389420772
511.90000000000657,56.536180821217876,-0.301731378238479,-2.364707947613347
513.0000000000066,56.64513361083113,-0.30158305778861166,-2.366474476182411
514.1000000000065,56.753398272290156,-0.3007585699639977,-2.367818803158973
515.2000000000066,56.86327766611786,-0.30163547791419254,-2.3716288873219153
516.3000000000065,56.970801898115774,-0.3001743697272153,-2.3754242237047096
517.4000000000067,57.07991964874466,-0.3006998058541859,-2.376103457571726
518.5000000000066,57.18907022301072,-0.30025231340211184,-2.377705720228608
519.6000000000067,57.296903040581675,-0.3009026805390222,-2.3804146490391935
520.7000000000066,57.40531750908704,-0.29915301091162927,-2.3829647505508444
521.8000000000067,57.51439145031702,-0.2996799495254313,-2.385918030707699
522.9000000000067,57.62249878905853,-0.3007741068623731,-2.3885597284355056
524.0000000000067,57.73205291076871,-0.2995680451220163,-2.391177713300745
525.1000000000067,57.841061309069865,-0.29712903602847013,-2.392015341130469
526.2000000000068,57.950184147917916,-0.2980935456153445,-2.3938238160125453
527.3000000000068,58.05879336654895,-0.2966669452500198,-2.3967939326860703
528.4000000000068,58.16713684229863,-0.29945208908045523,-2.399381057003372
529.5000000000068,58.27616279796826,-0.2981543651946188,-2.4030479098719244
530.6000000000068,58.38540057263203,-0.2975795886137831,-2.4047135093644507
531.7000000000069,58.493956637321475,-0.2977587932752429,-2.4069992344668516
532.8000000000068,58.60273955101715,-0.29702121341527243,-2.4079485862790544
533.9000000000069,58.710982947595916,-0.2945571189699727,-2.4109780383641546
535.0000000000068,58.82087779039786,-0.29280867937996935,-2.413395589740472
536.100000000007,58.92917198113408,-0.2923802134445175,-2.4132502945575602
537.2000000000069,59.035724238988216,-0.2942526402402875,-2.4162256507705164
538.300000000007,59.14669766700219,-0.2910755827527307,-2.4176688217442353
539.4000000000069,59.2550901869673,-0.29018498012982447,-2.420483047512327
540.5000000000069,59.363994109009326,-0.2887601713628085,-2.4217111009344157
541.600000000007,59.4731104313987,-0.28763809186086625,-2.424949153946613
542.700000000007,59.58244207948324,-0.2870995377328798,-2.428437907526815
543.800000000007,59.69085984558231,-0.28611872008444117,-2.4285209401099737
544.900000000007,59.80013568567594,-0.2861694068651032,-2.4311449119281416
546.000000000007,59.90917000000065,-0.286729999999941,-2.4337770242442787
547.1000000000071,60.01637553239577,-0.2880623502480949,-2.437615441490315
548.2000000000071,60.12568766534856,-0.286965362022926,-2.43776810347119
549.300000000007,60.234479598832436,-0.28445271068930955,-2.439053845293871
550.4000000000071,60.34444954148461,-0.286579342595686,-2.4404425642735172
551.500000000007,60.4532717724187,-0.28714151660042214,-2.4421067449808365
552.6000000000072,60.5625216119338,-0.2875980103251569,-2.443340296357696
553.7000000000071,60.671994758488445,-0.28987533551052047,-2.4459949680649227
554.8000000000072,60.78155628501394,-0.28917115042926295,-2.4500281034012987
555.9000000000071,60.8880403975726,-0.2901091801051966,-2.450040253120738
557.0000000000072,60.99961508689906,-0.29160330704497556,-2.452692887105012
558.1000000000072,61.10897424480844,-0.2907168170961228,-2.453000361148189
559.2000000000072,61.21817323076384,-0.2912647598764125,-2.455599579875161
560.3000000000072,61.32711559126763,-0.2918484392287129,-2.4569687422820268
561.4000000000073,61.43637563013344,-0.2919238025219712,-2.458270697913153
562.5000000000073,61.545169392533424,-0.2924174289092798,-2.4608644877796735
563.6000000000073,61.65454558356474,-0.2918573078985329,-2.4627162027672362
564.7000000000073,61.76425026686104,-0.29185615818085736,-2.463313846416966
565.8000000000073,61.87375009807894,-0.28982278794100363,-2.464928148278414
566.9000000000074,61.982182301367736,-0.29256021819305106,-2.4665416474718462
568.0000000000074,62.09232633993109,-0.29243553669003364,-2.4656187243791923
569.1000000000074,62.20083690311882,-0.2918618718798365,-2.4682599598209634
570.2000000000073,62.309891437731594,-0.2926824031814362,-2.46957962141836
571.3000000000073,62.41838930168942,-0.29219901483108174,-2.472228854109444
572.4000000000074,62.52808874050816,-0.2908910311649758,-2.4748452386433666
573.5000000000074,62.637120201439025,-0.29297875225977366,-2.474840103309064
574.6000000000074,62.74666122787322,-0.2929138908794896,-2.4774796189797863
575.7000000000074,62.855823896325845,-0.29408804115452764,-2.477619551708268
576.8000000000075,62.965154831337834,-0.291536310337051,-2.478782779706406
577.9000000000075,63.07374117641026,-0.291850858038215,-2.4801101915506414
579.0000000000075,63.18198880084747,-0.29140616240433304,-2.4816625163570967
580.1000000000075,63.28927110896917,-0.29001098911311907,-2.485489846884919
581.2000000000075,63.39797597295623,-0.28853486960826513,-2.485489901707095
582.3000000000076,63.510394177001714,-0.28728125896415807,-2.488415441681532
583.4000000000076,63.61907192247492,-0.28838004987847204,-2.4897998140212505
584.5000000000076,63.72766113224378,-0.2883218671935869,-2.489964799562227
585.6000000000076,63.837232772791054,-0.28780716539940365,-2.4910992968985997
586.7000000000077,63.94664265492667,-0.2883229217914191,-2.493730043122178
587.8000000000077,64.0572164757968,-0.28781995124643067,-2.4943316337899217
588.9000000000076,64.16567970536391,-0.2863333923545781,-2.495050068042311
590.0000000000076,64.27440819567379,-0.2870063913355626,-2.495041932839545
591.1000000000076,64.38387401463866,-0.2868699600042189,-2.4976950637414466
592.2000000000077,64.49315372552569,-0.2843683841278331,-2.4990018244791017
593.3000000000077,64.60333300174564,-0.2846047841647362,-2.500238288463759
594.4000000000077,64.71232048686547,-0.2846730310936782,-2.501628180103721
595.5000000000077,64.82273639198452,-0.2843917913769796,-2.5029495294677
596.6000000000078,64.93161903636769,-0.27961502891871154,-2.5042763580995198
597.7000000000078,65.04073484864357,-0.28193884062574154,-2.5055900407220846
598.8000000000078,65.15104947355594,-0.2801678648062128,-2.505587897478763
599.9000000000078,65.26055164941361,-0.2779884054753299,-2.5086906032113028
601.0000000000078,65.36980760931549,-0.2784297446094674,-2.5098687440005536
602.1000000000079,65.47960091984268,-0.2767877399604216,-2.510849903491366
603.2000000000079,65.5884493410187,-0.2756470047450919,-2.51216936681317
604.3000000000079,65.69936275136237,-0.2747790003715185,-2.5121704305079087
605.4000000000078,65.80808685565049,-0.2736669714609655,-2.5146202282861494
606.5000000000078,65.91762861424333,-0.2732477492711742,-2.5149100493139467
607.6000000000079,66.02723347000996,-0.2725999905643095,-2.514888010676504
608.7000000000079,66.13757076253779,-0.2730937262411515,-2.517219068187106
609.8000000000079,66.2459852154129,-0.2729591625413747,-2.5187842841088863
610.9000000000079,66.35568292622598,-0.2733374826636667,-2.5201989770825564
612.000000000008,66.46464129470623,-0.27154372346024025,-2.521450242229986
613.100000000008,66.57452428960836,-0.27088158009493624,-2.522901690313902
614.200000000008,66.68434609564447,-0.27023889568824633,-2.5241403987795
615.300000000008,66.79350172350011,-0.2693844976366888,-2.525459375380706
616.400000000008,66.9030883590298,-0.270092378104115,-2.5267798089722175
617.5000000000081,67.01204854071929,-0.270122532648673,-2.5266884045117384
618.6000000000081,67.12193518157468,-0.2707805373197153,-2.529194158974164
619.7000000000081,67.23264189625246,-0.2677575733302177,-2.5303654056224953
620.8000000000081,67.34045441169823,-0.26952148215623284,-2.5317228703001597
621.9000000000082,67.45048575496448,-0.2690696013393402,-2.532039461158429
623.0000000000082,67.56049253493836,-0.26793598511452754,-2.5331041958665983
624.1000000000081,67.66988673054999,-0.2663033733103782,-2.5344537528239783
625.2000000000081,67.78022537516391,-0.26639137497772636,-2.5357801207426407
626.3000000000081,67.8898090938862,-0.26625627050598916,-2.536483482312544
627.4000000000082,67.99916796397136,-0.26583003856807624,-2.539070034041483
628.5000000000082,68.10844236131301,-0.2654690762358958,-2.5405926778891557
629.6000000000082,68.2179327809809,-0.26582804977123603,-2.540390208930932
630.7000000000082,68.32574756568742,-0.2639386674275946,-2.5417082272726326
631.8000000000083,68.4372985950398,-0.26417124672053316,-2.542849140356681
632.9000000000083,68.54733559480914,-0.2641638241882838,-2.5443445000925364
634.0000000000083,68.65748616499552,-0.26667266923323263,-2.546968003602954
635.1000000000083,68.76639481393407,-0.2666128740299303,-2.5460710091548413
636.2000000000083,68.87669012585674,-0.26696048572244374,-2.548397456883403
637.3000000000084,68.98572201019235,-0.26823577461468284,-2.549710186794809
638.4000000000084,69.09543478709475,-0.2713819852752381,-2.5510198646525297
639.5000000000084,69.20633857312616,-0.2725898468965661,-2.551256391626385
640.6000000000083,69.3148836654729,-0.2768955811958074,-2.552359875121424
641.7000000000083,69.42480262673352,-0.2785155754163003,-2.551040901055508
642.8000000000084,69.53494548569284,-0.2818040688534561,-2.5523497517334173
643.9000000000084,69.64388714566265,-0.2839632342679152,-2.5550122841617737
645.0000000000084,69.75420473941067,-0.2883267459113226,-2.556257450126231
646.1000000000084,69.86318466930435,-0.29062652683062723,-2.558922534161052
647.2000000000085,69.97273975608795,-0.2945912611418899,-2.5589317515635934
648.3000000000085,70.08245335322965,-0.2936266265896713,-2.5589401353810883
649.4000000000085,70.1916348469796,-0.2963101622779765,-2.5602436976311473
650.5000000000085,70.30152455837174,-0.2975283178155153,-2.5602582132810325
651.6000000000085,70.41114962261634,-0.2988004075167145,-2.5628899444792386
652.7000000000086,70.52094117336651,-0.30229484383618516,-2.563369818113618
653.8000000000086,70.62991741486739,-0.30368812354324526,-2.562890319008965
654.9000000000086,70.74078862529984,-0.3031695350723159,-2.5655356536623692
656.0000000000086,70.85085225355373,-0.304626607758203,-2.565005644149772
657.1000000000087,70.96106817111391,-0.30665809947065886,-2.564207664167433
658.2000000000087,71.07138623094258,-0.3068010471279223,-2.5656782288727995
659.3000000000086,71.17917103490204,-0.30628008071388046,-2.567830028914878
660.4000000000086,71.29114877089287,-0.30876560901428596,-2.5681241889652036
661.5000000000086,71.40136279285811,-0.3064329133557728,-2.5694801201828756
662.6000000000087,71.51076585866397,-0.3084239239919401,-2.5694801188755125
663.7000000000087,71.62141052625951,-0.30951757727375045,-2.5707871323200897
664.8000000000087,71.73154114085841,-0.30836134228335066,-2.5722171985694517
665.9000000000087,71.8418523027459,-0.31202953137541123,-2.572118240067809
667.0000000000088,71.95274567902035,-0.31382280919317374,-2.5731086453787193
668.1000000000088,72.06306592450068,-0.31089513109061506,-2.5732236431942113
669.2000000000088,72.17291772743405,-0.31601973160970304,-2.574749660727902
670.3000000000088,72.2835777528777,-0.3160848041699322,-2.5760702391710932
671.4000000000088,72.39299785933376,-0.31675581136975633,-2.5747528300634803
672.5000000000089,72.50329131467556,-0.3180457952966483,-2.576072483064319
673.6000000000089,72.61354596774977,-0.3199609327281893,-2.577380111367958
674.7000000000089,72.72322282485065,-0.3198799574040125,-2.5773930348819394
675.8000000000088,72.8339742382437,-0.32050688515541087,-2.578699648037902
676.9000000000088,72.94366395437747,-0.321108757182901,-2.5804309689866263
678.0000000000089,73.05438066932517,-0.320752988249488,-2.5827399406754945
679.1000000000089,73.1646169922459,-0.32397178474996596,-2.5826501720161352
680.2000000000089,73.27403007435845,-0.32593158001462513,-2.5839738831075163
681.3000000000089,73.3838432336928,-0.32494869388432307,-2.5849598134333656
682.400000000009,73.49497429404876,-0.32846194783960814,-2.5835536097740572
683.500000000009,73.60453925947564,-0.3268148813934961,-2.5849605701650615
684.600000000009,73.71429249651527,-0.3278009998526602,-2.584962886798911
685.700000000009,73.82547904238695,-0.32853978881165896,-2.586269868571616
686.800000000009,73.93515612559317,-0.3320694963075222,-2.587580115274766
687.9000000000091,74.04553781018139,-0.3295053617481607,-2.5866015007564087
689.0000000000091,74.15614372228089,-0.3307853913508668,-2.586741306217661
690.1000000000091,74.26552969631803,-0.33118297074849606,-2.58792016782032
691.2000000000091,74.3762899534909,-0.33138423532128874,-2.5892454769306505
692.3000000000092,74.48619456068056,-0.33301806089334895,-2.5915263123093526
693.4000000000092,74.59676600145664,-0.33632559614198265,-2.5928588855087265
694.5000000000091,74.70653005008305,-0.3402292342969985,-2.59286174909259
695.6000000000091,74.81607557651994,-0.3389770215365875,-2.591549685713116
696.7000000000091,74.92631629300848,-0.33952157466438176,-2.591886747718536
697.8000000000092,75.03648312767206,-0.33899555908264617,-2.591880059997594
698.9000000000092,75.14676203210038,-0.3407752622134902,-2.5918800482547213
700.0000000000092,75.2568717828692,-0.3416245175725309,-2.5937059061504644
701.1000000000092,75.36655901920355,-0.34279892148154434,-2.595079521256377
702.2000000000093,75.47784272019004,-0.34528228281087214,-2.593189414263439
703.3000000000093,75.58763799937651,-0.3470619723769571,-2.596228265519133
704.4000000000093,75.6978000486302,-0.3480192970411497,-2.5979098510155856
705.5000000000093,75.80763220222032,-0.34867648764759,-2.5978359685911796
706.6000000000093,75.91758793488353,-0.34999684161598793,-2.5979098770759457
707.7000000000094,76.0281611066703,-0.35106040571777314,-2.596589903556402
708.8000000000094,76.13844210002169,-0.35286657105441954,-2.600743644298006
709.9000000000094,76.24936932621178,-0.35363968777041854,-2.602090010585971
711.0000000000093,76.35960726860223,-0.3527866013394854,-2.600766469115592
712.1000000000093,76.46989192753938,-0.3545396647846045,-2.599444336031251
713.2000000000094,76.58081881706069,-0.35677812806617,-2.601419874013196
714.3000000000094,76.69058776122256,-0.3575758595982758,-2.602450882905722
715.4000000000094,76.80091068400803,-0.3589093824367657,-2.601434747638115
716.5000000000094,76.9121621633934,-0.35835655056482835,-2.6041713447893367
717.6000000000095,77.02164383904338,-0.35780732647864044,-2.605384118193829
718.7000000000095,77.13183888045926,-0.35822993619817706,-2.6040923303191748
719.8000000000095,77.24298739015491,-0.35815663060587427,-2.60533361856268
720.9000000000095,77.352985370347,-0.36261537799092536,-2.60540233663403
722.0000000000095,77.46433943248796,-0.3641796893016779,-2.605359837221729
723.1000000000096,77.57471073006018,-0.36555705422958434,-2.6066858491185485
724.2000000000096,77.68515559285662,-0.36515179981452794,-2.607275250153058
725.3000000000096,77.79486564728715,-0.3659504266538809,-2.6079591982423773
726.4000000000096,77.90531868332958,-0.3673162257147757,-2.609345264053238
727.5000000000097,78.01580610527631,-0.3673212724229876,-2.6080101680319867
728.6000000000097,78.12735894357644,-0.3705931954537111,-2.608011817424524
729.7000000000096,78.23676286677258,-0.37565418576803145,-2.6115701909738043
730.8000000000096,78.34833263308138,-0.3785728408907946,-2.609225412990301
731.9000000000096,78.45799650856524,-0.3801780288242154,-2.609193170241699
733.0000000000097,78.5676263673351,-0.37762483810221303,-2.611682963583399
734.1000000000097,78.67926824995148,-0.3794900377664277,-2.610541805964243
735.2000000000097,78.78888268916282,-0.38197881951649615,-2.611850111319087
736.3000000000097,78.89917103357185,-0.38178998265835423,-2.6118598321510946
737.4000000000098,79.00916777258237,-0.38218986094954754,-2.6118598500000307
738.5000000000098,79.12003791952847,-0.37927145738147816,-2.6132221426840276
739.6000000000098,79.23021013276764,-0.3774748986176782,-2.6118687592064944
740.7000000000098,79.34105602266263,-0.38181636907123284,-2.614489924392516
741.8000000000098,79.45027431708255,-0.38258295724920743,-2.6144894896626623
742.9000000000099,79.56178621969526,-0.37995657103508,-2.6144887597442272
744.0000000000099,79.67227091559215,-0.38047086384322226,-2.617139689532901
745.1000000000099,79.78274225821268,-0.381029172242177,-2.6171300256363326
746.2000000000098,79.89343137331028,-0.38221359027363055,-2.6157618803447003
747.0000000000099,79.97351518111853,-0.38137538867900744,-2.61680010418553