File: 01_Data/Plastic_Laminate_Countertop_Laminate/STA/N2/10K_min/Plastic_Laminate_Countertop_Laminate_STA_N2_10KData_221005_R2.csv
##Temp./Â°C,Time/min,DSC/(mW/mg),Mass loss/mg
51.0,10.66,-1.62757,-0.006599361707461782
52.000000000000014,11.057233630182575,-1.5017630788932148,-0.006732534052554584
53.00000000000003,11.30355941569471,-1.4203364150585343,-0.004742289161113966
54.00000000000004,11.506398673725233,-1.356703902359864,-0.0049377890871316055
55.00000000000006,11.68439185980315,-1.3066274454513203,-0.0044730226360742975
56.00000000000007,11.847117671205066,-1.2677457461225934,-0.005034357909119436
57.000000000000085,11.99812095111433,-1.234434524279453,-0.0038188379103596404
58.0000000000001,12.143875689782377,-1.2047364046110736,-0.00379777967630357
59.000000000000114,12.283852048035515,-1.1796715050785984,-0.005343805282498337
60.00000000000013,12.420847233978836,-1.1552358654842447,-0.0049048915395095705
61.00000000000014,12.552175950553721,-1.1357810296706319,-0.005625531540758288
62.000000000000156,12.680402857188213,-1.1178102304796704,-0.005728991176297882
63.00000000000017,12.808751166460647,-1.1000495823421148,-0.006139074174285497
64.00000000000018,12.934229274866311,-1.0841384178620825,-0.006156241098818072
65.0000000000002,13.057048020137707,-1.069167485089331,-0.004897840312608537
66.00000000000021,13.179473262581089,-1.0545429020944996,-0.005601241113471822
67.00000000000023,13.299647545968721,-1.0411009382677792,-0.0057206097276152335
68.00000000000024,13.418682160379253,-1.0265645833660417,-0.004885880359502437
69.00000000000026,13.535698021008335,-1.0135657202854642,-0.006264867149282871
70.00000000000027,13.65320505728622,-0.9989702717622129,-0.007475339752748056
71.00000000000028,13.770339812892598,-0.9855870441059827,-0.007440124584486618
72.0000000000003,13.884634995785417,-0.9741085870892766,-0.009537447508148666
73.00000000000031,13.998490858278641,-0.9614749871801871,-0.00874033617009129
74.00000000000033,14.109568167081338,-0.9507659499216643,-0.008781544744781655
75.00000000000034,14.222744088237896,-0.9389092844228147,-0.008805489563204816
76.00000000000036,14.334281172459345,-0.9266670961924603,-0.00871965108398065
77.00000000000037,14.443114527246657,-0.9155020369700626,-0.008797916201537248
78.00000000000038,14.552890689140543,-0.9061398891228701,-0.010063267821410093
79.0000000000004,14.661388252924159,-0.8956141023316454,-0.010107120011735304
80.00000000000041,14.769351147912603,-0.8860586318087831,-0.01138411209360779
81.00000000000043,14.877411069117347,-0.876831146798094,-0.01278591906714066
82.00000000000044,14.985345222769437,-0.8670539588424679,-0.011667466019058104
83.00000000000045,15.09184535086919,-0.8567030225099126,-0.012739463356960634
84.00000000000047,15.198040700763638,-0.8483924598923027,-0.013912354379952419
85.00000000000048,15.302506162949719,-0.8406988206560255,-0.01658900203590452
86.0000000000005,15.407001047182746,-0.8323219595077721,-0.014857317290006833
87.00000000000051,15.51199754754342,-0.8241340608375594,-0.011879328097973207
88.00000000000053,15.615639500512492,-0.8168848186933751,-0.014734731141859747
89.00000000000054,15.71819367436646,-0.8098246405357635,-0.01468805051245159
90.00000000000055,15.821218597418206,-0.8030933699979863,-0.013268395962133361
91.00000000000057,15.924508143759786,-0.7962002277865948,-0.014600410250285911
92.00000000000058,16.025027002099392,-0.7902591345988441,-0.016807059019997794
93.0000000000006,16.128381175963934,-0.7846399062501312,-0.01724082286048212
94.00000000000061,16.23064369315345,-0.7788537369885677,-0.0168756645704633
95.00000000000063,16.330568448435493,-0.7729044118083067,-0.01743951530460297
96.00000000000064,16.431162844380125,-0.7684680902985814,-0.01724062002855664
97.00000000000065,16.532241219839523,-0.7621650504239773,-0.01854924980533923
98.00000000000067,16.63234701787776,-0.7560626187651056,-0.01854961151752299
99.00000000000068,16.732633126401126,-0.7529755732218096,-0.019869755105858644
100.0000000000007,16.832345699060568,-0.7471530666096377,-0.01862264360242971
101.00000000000071,16.932147430644253,-0.7432126013785044,-0.017239879041498263
102.00000000000072,17.03150514027867,-0.7385915385248927,-0.018458903706705776
103.00000000000074,17.130814965789863,-0.7330282114893814,-0.019833753833485623
104.00000000000075,17.226272501905594,-0.7306956654832388,-0.0211900885041425
105.00000000000077,17.327656963464516,-0.7258650343270507,-0.022499488416461766
106.00000000000078,17.425469546090486,-0.7195583196682196,-0.022151089686494707
107.0000000000008,17.52507314383716,-0.7166832099798234,-0.02086563770490013
108.00000000000081,17.623454076740753,-0.7124026761224282,-0.01811009080184789
109.00000000000082,17.721553016435244,-0.7091895580397783,-0.01943012179860304
110.00000000000084,17.820483216194027,-0.7048467846230503,-0.020750134521198227
111.00000000000085,17.91659823569149,-0.7008526816312827,-0.02075023987467528
112.00000000000087,18.017921926802806,-0.6970818406277282,-0.022324928257792642
113.00000000000088,18.11533235050389,-0.6908789669518466,-0.02371061516534745
114.0000000000009,18.211735882802817,-0.6866416985776411,-0.0250318990092131
115.00000000000091,18.309902471705467,-0.6815738229134936,-0.023719903349631366
116.00000000000092,18.40854167415518,-0.6796266260804803,-0.02372297782899846
117.00000000000094,18.50497267110356,-0.6748796981229471,-0.025040215516638042
118.00000000000095,18.601999034887946,-0.671002655842322,-0.025029945661363406
119.00000000000097,18.699254455256813,-0.6679513660894235,-0.024038453551752603
120.00000000000098,18.796895344310318,-0.6642329522603475,-0.025224125658011687
121.000000000001,18.894221456566587,-0.6598597973532352,-0.0253601814970148
122.00000000000101,18.991462825110894,-0.6571829679056284,-0.02634608515786674
123.00000000000102,19.089203462873098,-0.6538804008601763,-0.02634843452282709
124.00000000000104,19.186696892892527,-0.6487325132810211,-0.025294345100738802
125.00000000000105,19.28244687330195,-0.6451211850664248,-0.025192566714232534
126.00000000000107,19.379801660204,-0.6407328905392465,-0.02503112495905757
127.00000000000108,19.47650705627374,-0.6382673898555978,-0.02534891599905187
128.00000000000108,19.57407206122002,-0.632658748478968,-0.026680188321465792
129.0000000000011,19.67214134968362,-0.6285104315502236,-0.026725314570557934
130.00000000000114,19.767671694970982,-0.623603451889373,-0.02635804927356844
131.00000000000114,19.864019798146302,-0.6183833754566851,-0.026680091749706314
132.00000000000114,19.959617442430677,-0.615235663885433,-0.027999069926386788
133.00000000000117,20.057047591394543,-0.609297071341501,-0.028650175773609732
134.0000000000012,20.15304581393316,-0.6065409262745215,-0.028706857350670134
135.0000000000012,20.249906633321864,-0.6021963452272346,-0.0293180790669183
136.0000000000012,20.345846250024785,-0.598241177467252,-0.028659859177977864
137.00000000000122,20.443096665739205,-0.5927614345338665,-0.028659648945482452
138.00000000000125,20.53822880480077,-0.5890642219302552,-0.0289897641223833
139.00000000000125,20.63574627512279,-0.5831592702470302,-0.029057816972418493
140.00000000000125,20.730103339097205,-0.5791549053261006,-0.027937711374325325
141.00000000000128,20.82580428371913,-0.5747179785090869,-0.0293704801799608
142.0000000000013,20.922081909998845,-0.5695424424142638,-0.030629908500058534
143.0000000000013,21.016108362721425,-0.5657213965419304,-0.032094759281234175
144.0000000000013,21.113811562336345,-0.5623725590308528,-0.03063008234736664
145.00000000000134,21.207785930511065,-0.5550545454842166,-0.030630003999782218
146.00000000000136,21.304004522713445,-0.551128624102881,-0.030630006872031323
147.00000000000136,21.400745345750664,-0.5452523180457791,-0.03193948582787698
148.00000000000136,21.495469720009307,-0.5405730690115124,-0.03193660682213739
149.0000000000014,21.59202744128925,-0.5352663037020501,-0.031940097996531414
150.00000000000142,21.687295829772566,-0.5300137112988872,-0.03193910563182456
151.00000000000142,21.78327754442756,-0.525607215787255,-0.030625253547634124
152.00000000000142,21.87893092596202,-0.5215517119511232,-0.03293247812350142
153.00000000000145,21.973689919874865,-0.5162389793151363,-0.03424858750773119
154.00000000000148,22.06839745863899,-0.5109876875983761,-0.034256206336488404
155.00000000000148,22.163494066570358,-0.5058298986955628,-0.034910031114486095
156.00000000000148,22.260092526430565,-0.5024267559696427,-0.03559808544678411
157.0000000000015,22.356386665730405,-0.4960831760803234,-0.035570047207844624
158.00000000000153,22.451252907511655,-0.49217895324185595,-0.036879280120957425
159.00000000000153,22.545600742472956,-0.48739569569061647,-0.036196917577099086
160.00000000000153,22.642712153904924,-0.4813384273937322,-0.03686601343277385
161.00000000000156,22.737453165736163,-0.4776572457743333,-0.036827800261065136
162.0000000000016,22.832238573616202,-0.47300861860807714,-0.0387437923006404
163.0000000000016,22.928117384951015,-0.4673833699459949,-0.03853001372989873
164.0000000000016,23.022634952362385,-0.464485433887342,-0.0385380061357079
165.00000000000162,23.117918335615546,-0.45848343046254403,-0.03935426965480637
166.00000000000165,23.210944294114103,-0.454581847988104,-0.04019016071398607
167.00000000000165,23.307992249941666,-0.4489341399505623,-0.0415000290335632
168.00000000000165,23.40389328892107,-0.4446507235656638,-0.041477222252249035
169.00000000000168,23.498926897117627,-0.4416255688998803,-0.04149995611578472
170.0000000000017,23.59464989078707,-0.43708428476714717,-0.04149903093547014
171.0000000000017,23.688986224739093,-0.43304153134359713,-0.0441297123644917
172.0000000000017,23.78338718965336,-0.42913067788372017,-0.044140016885654276
173.00000000000173,23.878796279748364,-0.4256222640900149,-0.04413999556256698
174.00000000000176,23.975148027028137,-0.42029963800719095,-0.045451604274048485
175.00000000000176,24.070089715414326,-0.4178262592808563,-0.04676998179618863
176.00000000000176,24.165970401322227,-0.4144438132285462,-0.04677009799999521
177.0000000000018,24.260092554065203,-0.41073803996053787,-0.04677010014025029
178.00000000000182,24.356847910405868,-0.40679294999629484,-0.04808897107897181
179.00000000000182,24.450296713876117,-0.40342616780509605,-0.050718067182776494
180.00000000000182,24.545644548232115,-0.40125151294583417,-0.04940144061056184
181.00000000000185,24.64123132560513,-0.3980343355684407,-0.04940000426039326
182.00000000000188,24.735930161681075,-0.39546005952193986,-0.05082971826794758
183.00000000000188,24.831247703630044,-0.39124681467047795,-0.05203983605647444
184.00000000000188,24.926737539206776,-0.3885911664677596,-0.05342226008861317
185.0000000000019,25.018964563437134,-0.3853198576602382,-0.053371478422199914
186.00000000000193,25.116670868514873,-0.38359795153326504,-0.05467984002858994
187.00000000000193,25.211228769718417,-0.379813897111782,-0.05470166275568111
188.00000000000193,25.30616664678445,-0.37745906749038277,-0.05730006350933525
189.00000000000196,25.401444155126878,-0.3746458324706284,-0.05730014436994946
190.000000000002,25.49539905114458,-0.36993756502196207,-0.05861938444956838
191.000000000002,25.58925807443703,-0.3689944913668464,-0.05993986667818341
192.000000000002,25.686007115158745,-0.36619710205198136,-0.05994177891512731
193.00000000000202,25.780929174227268,-0.3651804523707152,-0.06126020234959251
194.00000000000205,25.875885879467702,-0.3617019048990769,-0.06126024199686064
195.00000000000205,25.969904133271385,-0.3601257812843536,-0.06257375944427412
196.00000000000205,26.065143075315785,-0.3575904798945955,-0.06290013336192679
197.00000000000207,26.159792624746988,-0.35654758371666984,-0.06289944852529272
198.0000000000021,26.255354634348603,-0.3543857853236121,-0.06448848231891136
199.0000000000021,26.350515023057856,-0.3520315850151206,-0.06685987129655091
200.0000000000021,26.446214481624526,-0.3495062225851453,-0.06687141172516897
201.00000000000213,26.540616363426786,-0.34693132801941184,-0.07082612743117744
202.00000000000216,26.63479676678844,-0.3457580976611793,-0.07075091159098257
203.00000000000216,26.730000000000203,-0.3437400000000077,-0.07211983197035199
204.00000000000216,26.82601031225884,-0.3413524695299275,-0.07278267286359519
205.0000000000022,26.920960075809177,-0.33999045266996414,-0.0748041631541847
206.00000000000222,27.016386629853876,-0.33912900424312226,-0.07608024683618808
207.00000000000222,27.109129040947828,-0.33667742698004566,-0.07742084177567676
208.00000000000222,27.204155797314908,-0.33554722514877766,-0.07839010129415191
209.00000000000225,27.29899210501217,-0.3335853813410876,-0.07969977833527819
210.00000000000227,27.39532297039098,-0.33345748576148965,-0.08002547377275038
211.00000000000227,27.488776487643484,-0.332625330239339,-0.08268501047422427
212.00000000000227,27.581388011351574,-0.332017853919532,-0.08399020292539428
213.0000000000023,27.67869351383027,-0.3303306994207169,-0.08266127379768484
214.00000000000233,27.77387474720699,-0.3308248233917237,-0.08530410823966905
215.00000000000233,27.868595210105937,-0.32965748653103666,-0.08662106350779863
216.00000000000233,27.96302408082563,-0.3299339758305414,-0.08909187138837682
217.00000000000236,28.05840940061504,-0.3293288248941146,-0.0879049933096292
218.0000000000024,28.15393266803941,-0.32810449082497684,-0.09054585248797675
219.0000000000024,28.24745853977714,-0.32843255230936663,-0.09189003834568021
220.0000000000024,28.342177076522557,-0.32723207679057237,-0.09371658645712388
221.00000000000242,28.436627426551723,-0.32703306049485686,-0.0972151530009504
222.00000000000244,28.53260649087385,-0.32768525051878045,-0.09774562674307452
223.00000000000244,28.626824759918428,-0.32851822573165335,-0.10084168892146206
224.00000000000244,28.7224152897883,-0.32695588360938216,-0.1023964381682716
225.00000000000247,28.81710781659436,-0.3280814373095562,-0.10375195074427923
226.0000000000025,28.910104461585757,-0.3281509236069012,-0.10506040074749734
227.0000000000025,29.00686758464681,-0.3292328529986207,-0.10627611239687651
228.0000000000025,29.101915737641665,-0.3284876333620453,-0.10913748332815487
229.00000000000253,29.196802132536305,-0.32814853389811793,-0.11176293344941612
230.00000000000256,29.2921322746151,-0.32927750842497405,-0.1143874188009244
231.00000000000256,29.386951736062038,-0.3289514894759897,-0.11449330114603784
232.00000000000256,29.482972092135174,-0.3302644416493488,-0.11794813784049074
233.0000000000026,29.577478969297047,-0.32997985910538363,-0.12086068583127618
234.00000000000261,29.671864514848586,-0.33013956299431735,-0.12213507105760257
235.00000000000261,29.767788011460688,-0.3306796520163804,-0.12494823748436312
236.00000000000261,29.86325679026211,-0.33030468863107154,-0.12641230693025785
237.00000000000264,29.957865980522936,-0.331292471036452,-0.12947119707122123
238.00000000000267,30.053972240256112,-0.33034308595340345,-0.1315283333500319
239.00000000000267,30.14778318816212,-0.3300562175880802,-0.1339730802916148
240.00000000000267,30.245270228083644,-0.33039957133086556,-0.13692725834634567
241.0000000000027,30.339382469140663,-0.3302231222407887,-0.1396580661368083
242.00000000000273,30.435297938411612,-0.3296843164691463,-0.142178290652768
243.00000000000273,30.5300983429362,-0.3292785678370768,-0.14491926197938998
244.00000000000273,30.625482014503095,-0.33012868721011607,-0.14748188324617928
245.00000000000276,30.719313356839166,-0.3300244619595239,-0.1488797920771252
246.00000000000279,30.81588407327,-0.33134455258443996,-0.15406196308326914
247.00000000000279,30.910862867977777,-0.33044726503733535,-0.15732265299646198
248.00000000000279,31.006791355287643,-0.32999145524224993,-0.1592884880543628
249.0000000000028,31.101781922660766,-0.32873652144858706,-0.16250984279276093
250.00000000000284,31.197394808445004,-0.32793546822656866,-0.16524527728256722
251.00000000000284,31.293169630379804,-0.3284501948867696,-0.16994610467017468
252.00000000000284,31.387622278983105,-0.32808210800381976,-0.17272913704275528
253.00000000000287,31.483328590106183,-0.3273142454121474,-0.17572584096216692
254.0000000000029,31.578284625963416,-0.32583188369279814,-0.18148203449061473
255.0000000000029,31.672534311779916,-0.32625318066333725,-0.18621070263786965
256.0000000000029,31.76878595026099,-0.3248534050013944,-0.18847163731114547
257.00000000000296,31.863977785404792,-0.3252648839693928,-0.19171990804217298
258.00000000000296,31.960186164814765,-0.3241047596826191,-0.19694970886490148
259.00000000000296,32.054280499204054,-0.3235589233671139,-0.20298419475944218
260.00000000000296,32.15020346250555,-0.3222026861116799,-0.2060603003217074
261.00000000000296,32.245379797338536,-0.3217943586254654,-0.20997448908493865
262.000000000003,32.34136683152594,-0.32018161716136684,-0.2157354048004998
263.000000000003,32.43297380161614,-0.32105838183742985,-0.21848936355737258
264.000000000003,32.53040093465362,-0.31972146024618786,-0.22257295947754052
265.00000000000307,32.62611265934987,-0.31769982468371794,-0.22796554888006604
266.00000000000307,32.72075925110378,-0.31766462691860786,-0.23254664721325735
267.00000000000307,32.8179954708266,-0.3175456798822422,-0.2390326598506345
268.00000000000307,32.91221207594309,-0.3166243578866413,-0.24608808378284852
269.00000000000307,33.00716915227285,-0.3136148341042658,-0.2525581295252386
270.0000000000031,33.103563465631154,-0.31250408665693347,-0.256322229796083
271.0000000000031,33.19798609915329,-0.31052631280415427,-0.2629720220389844
272.0000000000031,33.293321005118095,-0.30989616029152545,-0.2676588191624858
273.0000000000032,33.388270998394404,-0.30770215722302086,-0.2739686624719404
274.0000000000032,33.48486701927381,-0.3058693036534456,-0.28082309937986105
275.0000000000032,33.580387578069356,-0.30275766141153715,-0.28777744589768206
276.0000000000032,33.67607348389842,-0.30092147893415533,-0.29322098606032787
277.0000000000032,33.77094680395515,-0.29869022288516395,-0.29942942181021914
278.00000000000324,33.86663787938466,-0.2985091875683768,-0.3066138593720056
279.00000000000324,33.96280841700706,-0.2969318132813833,-0.31350598752985226
280.00000000000324,34.05806451207256,-0.29421433153910564,-0.3235370854919406
281.0000000000033,34.15307898183118,-0.29477831820820277,-0.3318916218091825
282.0000000000033,34.24907087060921,-0.2931448020533934,-0.33790407758076757
283.0000000000033,34.34522951815842,-0.28971183081731733,-0.34616659715859477
284.0000000000033,34.44062308625997,-0.28741283028332615,-0.35418606620453374
285.0000000000033,34.535606409856406,-0.28718318627308115,-0.3620838380348017
286.00000000000335,34.632780513423256,-0.28560614292078723,-0.37228944272612496
287.00000000000335,34.72705578026382,-0.2833793537830802,-0.38169763569343607
288.00000000000335,34.82327209012996,-0.2825811193183001,-0.3922745531383103
289.0000000000034,34.916320548651235,-0.279606718617065,-0.40282248176343316
290.0000000000034,35.01328743472544,-0.2757556067577507,-0.41239857836437954
291.0000000000034,35.10851253329049,-0.2758140406972756,-0.4209424114979563
292.0000000000034,35.204978626463195,-0.2744170581676806,-0.4305328283821419
293.0000000000034,35.300647392797316,-0.2717776770858003,-0.4387766875183443
294.00000000000347,35.395347672085514,-0.2702767565229238,-0.45013638939190326
295.00000000000347,35.49278187258666,-0.2688763990655244,-0.46105795574392827
296.00000000000347,35.58801444041024,-0.26744289685959033,-0.47329439079918245
297.0000000000035,35.684334401019306,-0.26577717904281956,-0.4862443028649466
298.0000000000035,35.7805968271807,-0.2624767535928673,-0.4973607028185585
299.0000000000035,35.87570509923224,-0.2632106674845958,-0.5081837214053233
300.0000000000035,35.97000000000029,-0.2611599999999852,-0.5209190000106663
301.0000000000035,36.068036265627974,-0.26025012677887077,-0.5355869549662096
302.0000000000036,36.16371314991856,-0.26049627866877717,-0.548723670004982
303.0000000000036,36.25947397985895,-0.258372714754668,-0.5625313737039574
304.0000000000036,36.355200322550935,-0.2579054734968128,-0.5774387556513103
305.00000000000364,36.451433069747964,-0.2566746993211677,-0.5924471338936792
306.00000000000364,36.5475956270101,-0.2543741289913554,-0.6069732037040225
307.00000000000364,36.6430783455567,-0.2554283863606694,-0.6228530635798171
308.00000000000364,36.740000000000364,-0.2544300000000179,-0.6391582634895854
309.00000000000364,36.83542870969181,-0.253962259239959,-0.6520943353265989
310.0000000000037,36.93168336759838,-0.2534462603767344,-0.6676183490780319
311.0000000000037,37.02788042673503,-0.2543516662268294,-0.685338791438368
312.0000000000037,37.12481271843642,-0.2553879936960028,-0.7041356722913314
313.00000000000375,37.21972740933379,-0.2545303507018215,-0.7220045816706775
314.00000000000375,37.31730037192814,-0.25377938211627676,-0.7403910290533133
315.00000000000375,37.41326798523094,-0.2535323257414741,-0.7587717646655667
316.00000000000375,37.51011102175729,-0.2532974704712498,-0.7776185362739714
317.00000000000375,37.60608105361662,-0.25224541794894695,-0.7984099839804966
318.0000000000038,37.7021263056605,-0.25345355115545676,-0.8191016918234473
319.0000000000038,37.79892193315802,-0.2518709774816559,-0.840240469319613
320.0000000000038,37.89117524368816,-0.25129149123138533,-0.8610387041384344
321.00000000000387,37.98951769312285,-0.2511124179102727,-0.8831598270795284
322.00000000000387,38.08615419260702,-0.2514629569165389,-0.9057734091068066
323.00000000000387,38.183540898554696,-0.2509325821868811,-0.9274860302795345
324.00000000000387,38.279361952925115,-0.2512319612727828,-0.9523043824393258
325.00000000000387,38.376077965116245,-0.25045968901855786,-0.9753272593331572
326.0000000000039,38.4694441069616,-0.25089284853925004,-0.9992947083557078
327.0000000000039,38.56804480993534,-0.2497024757534588,-1.0261413515005167
328.0000000000039,38.66458767959996,-0.2506068641435134,-1.0514408121419354
329.000000000004,38.76165426147299,-0.24955926653077262,-1.079572254835766
330.000000000004,38.856889062509204,-0.2509353043442518,-1.1039689538280237
331.000000000004,38.95522420889721,-0.25105658286080546,-1.133313473363844
332.000000000004,39.051760587245035,-0.25122853036859405,-1.1611353261404393
333.000000000004,39.14812300703194,-0.25334504761859894,-1.188810793087396
334.00000000000404,39.24515775422154,-0.254084033062164,-1.2206136934548129
335.00000000000404,39.34191119225366,-0.255747723217985,-1.247601960208283
336.00000000000404,39.439068699347004,-0.2562227290133769,-1.2757816775078106
337.0000000000041,39.53411925536272,-0.2581696483916513,-1.3073547444401763
338.0000000000041,39.631995840942366,-0.2617811167390774,-1.3381381096947997
339.0000000000041,39.72731826680935,-0.2653121490301713,-1.3710713150769815
340.0000000000041,39.825332679496206,-0.26858059176081234,-1.4022671806096438
341.0000000000041,39.920000000000435,-0.27231000000001054,-1.4357416268268324
342.00000000000415,40.01740135101023,-0.2777755913398633,-1.464774492360068
343.00000000000415,40.11402677163791,-0.27901984201223956,-1.4975206942722181
344.00000000000415,40.21083257520667,-0.28413791461595705,-1.5294996403484142
345.0000000000042,40.307093013713164,-0.2902027757879451,-1.5590002868461412
346.0000000000042,40.40360466699835,-0.2953430802785226,-1.5890251960267463
347.0000000000042,40.50000000000039,-0.29899999999998816,-1.6173405780625831
348.0000000000042,40.5969105044087,-0.30481441086899125,-1.645646437738427
349.0000000000042,40.69345854109411,-0.3080822013040281,-1.6712041479605806
350.00000000000426,40.790671110172006,-0.3116429807516723,-1.6991018457604774
351.00000000000426,40.88529101022905,-0.31313941598095374,-1.7231030184955607
352.00000000000426,40.9834081594744,-0.31461347047727684,-1.7457583288620468
353.0000000000043,41.08020774940185,-0.31542639664519967,-1.7682092522160513
354.0000000000043,41.17804703389324,-0.31512498158500285,-1.7881163856941753
355.0000000000043,41.275336485084615,-0.31561177437205823,-1.805836817511735
356.0000000000043,41.37248921106893,-0.31494195663008073,-1.821178565530667
357.0000000000043,41.46937395874655,-0.31283813152126766,-1.8355740959212583
358.0000000000044,41.56637008713967,-0.3131231471935189,-1.8506949588398696
359.0000000000044,41.66310516825708,-0.3105748497539628,-1.862662746352223
360.0000000000044,41.75978159179177,-0.3099712178424602,-1.8754016242250002
361.00000000000443,41.8579810632594,-0.3069514836577046,-1.8874504720427456
362.00000000000443,41.95514005937026,-0.3063977283210766,-1.8971200536005846
363.00000000000443,42.051321573927474,-0.3043818374249347,-1.9056171761556175
364.00000000000443,42.148247212783566,-0.301896518642549,-1.9125690001072542
365.00000000000443,42.246697188831305,-0.2994751093090955,-1.9207167681723765
366.0000000000045,42.343266566675176,-0.2952366670035598,-1.9279714654905655
367.0000000000045,42.441049371245235,-0.2916287218548048,-1.9350782625676186
368.0000000000045,42.536417842656576,-0.2886036810543013,-1.942203017716876
369.00000000000455,42.636119286258584,-0.2851261700589344,-1.948036389184447
370.00000000000455,42.73318893410926,-0.2842174404173008,-1.954163341664545
371.00000000000455,42.83000000000043,-0.2816899999999799,-1.96050977987182
372.00000000000455,42.92752011068047,-0.2809462632017934,-1.9659357622210072
373.00000000000455,43.02433274671879,-0.2795175410704735,-1.9712709632271856
374.0000000000046,43.118887361202425,-0.27858718142185984,-1.9779520731033755
375.0000000000046,43.219093568171466,-0.2762453345185535,-1.9833421355574976
376.0000000000046,43.31658973164085,-0.27446195837587295,-1.987921538269061
377.00000000000466,43.41353503146541,-0.27306323021574275,-1.993500777272165
378.00000000000466,43.51132662049531,-0.27033462065109726,-1.9978484465580633
379.00000000000466,43.60808517219938,-0.27022767102816864,-2.001472342572195
380.00000000000466,43.70462929304101,-0.2670496365589129,-2.00534628156805
381.00000000000466,43.80299252337947,-0.2654507507951527,-2.0100555465700185
382.0000000000047,43.8998031598976,-0.2639502056371147,-2.012761577274655
383.0000000000047,43.99722499766063,-0.26191839565460273,-2.018018993649521
384.0000000000047,44.094614478730726,-0.26091694000093674,-2.0219405291179804
385.0000000000048,44.191282375976705,-0.25897635387638535,-2.027029590300056
386.0000000000048,44.289048538198266,-0.25630922993940175,-2.032035536383607
387.0000000000048,44.38645169077217,-0.25580284481559007,-2.0361076525626984
388.0000000000048,44.48104812457973,-0.2531375961465504,-2.039619101176655
389.0000000000048,44.580702082026676,-0.25168032598665663,-2.0446167050927504
390.00000000000483,44.67802176693661,-0.2498658897608177,-2.0478347551613387
391.00000000000483,44.77618534233012,-0.24912154514356522,-2.0508266348077715
392.00000000000483,44.872304053936915,-0.24758124768455705,-2.0516442906567374
393.0000000000049,44.96956534470502,-0.24464047612789278,-2.0553644937229505
394.0000000000049,45.06788204656736,-0.24354631044034367,-2.059783013874208
395.0000000000049,45.16571557261688,-0.24199430345911865,-2.0645825024567253
396.0000000000049,45.262908711630516,-0.23888215874236643,-2.068719779012413
397.0000000000049,45.36078803011043,-0.2376679991386666,-2.0746915446458027
398.00000000000495,45.45473019090717,-0.23683977251314584,-2.0751514887807034
399.00000000000495,45.55575119175933,-0.23336321733268545,-2.0784136296543805
400.00000000000495,45.654574541937386,-0.23275768405670524,-2.0820548520974462
401.000000000005,45.75155390558879,-0.23078766490346442,-2.0876144109402097
402.000000000005,45.849049002262504,-0.22797166233859728,-2.092197971379135
403.000000000005,45.94712445137986,-0.22678657653392506,-2.0974124459909653
404.000000000005,46.04553213474742,-0.22265818240248475,-2.10118348778456
405.000000000005,46.14228279685853,-0.22073916369229274,-2.1027273455298303
406.00000000000506,46.24126763115998,-0.2188676178146435,-2.1066197302419623
407.00000000000506,46.3384410350525,-0.21681836326723355,-2.111326623039055
408.00000000000506,46.435931370471046,-0.21465793335762332,-2.1152177353029034
409.0000000000051,46.53375187945039,-0.21203309010449398,-2.1172275858970497
410.0000000000051,46.63168025110072,-0.21012636890395847,-2.12401692016364
411.0000000000051,46.72990717200276,-0.20579469211501294,-2.1275921084615947
412.0000000000051,46.826059284418484,-0.20387812092696747,-2.1305971556424237
413.0000000000051,46.92422813860308,-0.20216245692729037,-2.13399832659987
414.0000000000052,47.023204318163856,-0.1996807599713482,-2.1398679851080247
415.0000000000052,47.120714348895326,-0.19733204885026961,-2.1445378066275915
416.0000000000052,47.219206804392456,-0.19566620988378874,-2.148944558837983
417.00000000000523,47.31687476623563,-0.19237228800835848,-2.1518666580813197
418.00000000000523,47.413141610035105,-0.19151137229291895,-2.1577876822818043
419.00000000000523,47.5125171104345,-0.1891275747782403,-2.1609932498558573
420.00000000000523,47.60915889760007,-0.18796143871284454,-2.164553276676566
421.00000000000523,47.7061468005393,-0.1859231749045418,-2.1704044696545752
422.0000000000053,47.8047195241954,-0.18234107091186463,-2.1732328276723747
423.0000000000053,47.90335296857698,-0.1791642428796598,-2.177749423432071
424.0000000000053,48.00098954473613,-0.17858114692941351,-2.1817241181906586
425.00000000000534,48.09864286239286,-0.17705490634884158,-2.1858395296601576
426.00000000000534,48.197050675817586,-0.17440217917859546,-2.1901819949477455
427.00000000000534,48.29459790886365,-0.17415574703496167,-2.192961215268022
428.00000000000534,48.39220331666804,-0.17335237098825115,-2.1991471072135402
429.00000000000534,48.49035820034448,-0.17094300997005785,-2.203480834699948
430.0000000000054,48.58783369163592,-0.16938337664443465,-2.2091039589457866
431.0000000000054,48.68666606374528,-0.16791448155996452,-2.2133832026406015
432.0000000000054,48.78420951765458,-0.16640852909125756,-2.216539255060317
433.00000000000546,48.882416306014434,-0.16565932966585958,-2.2222931949758906
434.00000000000546,48.980634108247266,-0.1638619559088322,-2.2254424812483147
435.00000000000546,49.07882037324652,-0.16408780610872634,-2.2285689743856296
436.00000000000546,49.176263013398575,-0.16339621812553665,-2.2345657368681646
437.00000000000546,49.27382156351005,-0.1617688274973306,-2.239145300801268
438.0000000000055,49.37275762633445,-0.16150057944391588,-2.242147184962062
439.0000000000055,49.47090361408964,-0.1599202093757155,-2.247585892205877
440.0000000000055,49.56814791775222,-0.1580343434522869,-2.251725349033649
441.00000000000557,49.66671659685721,-0.15836238231009545,-2.2553650085666836
442.00000000000557,49.76569567350476,-0.15763484259650123,-2.258856849529234
443.00000000000557,49.863380074988065,-0.15677320690773014,-2.2642191489426935
444.00000000000557,49.961338202769895,-0.15603836851010663,-2.2683340259911473
445.00000000000557,50.05960110778027,-0.155331669275111,-2.2719560473852405
446.0000000000056,50.157378104190435,-0.15539796867853323,-2.2755460074579843
447.0000000000056,50.25592434315517,-0.1526142847436424,-2.280675694073518
448.0000000000056,50.35482947635416,-0.15293202025656957,-2.2847998668812455
449.0000000000057,50.4525425095362,-0.15226594368463442,-2.289073370654066
450.0000000000057,50.55164777199605,-0.1522249142408953,-2.2932128361973314
451.0000000000057,50.649530475315416,-0.15138411565008572,-2.296012427537325
452.0000000000057,50.748473477733825,-0.15091946532075287,-2.2978488746632664
453.0000000000057,50.84684786252235,-0.14784963018787872,-2.3040578484893026
454.00000000000574,50.9459461090491,-0.14691805499722893,-2.3079686468912977
455.00000000000574,51.04426723409216,-0.14559130589777913,-2.3141528032647094
456.00000000000574,51.14257420921557,-0.14523485105245532,-2.3156231822594875
457.0000000000058,51.240977784048894,-0.1439297096798282,-2.3199210868256603
458.0000000000058,51.339094604330064,-0.1434244391636575,-2.323477215872387
459.0000000000058,51.437738769554684,-0.14150054139297688,-2.326003033999556
460.0000000000058,51.53620030333561,-0.14173788585208086,-2.329845674314913
461.0000000000058,51.633606795015666,-0.14078464735481755,-2.3342797018532915
462.00000000000585,51.7332046930452,-0.13957300047676788,-2.3384304891978775
463.00000000000585,51.83231547538801,-0.13951579279218831,-2.34152923240499
464.00000000000585,51.930101976829036,-0.1389163374015558,-2.3448084458647642
465.0000000000059,52.02884389965313,-0.13819969740370963,-2.3471619232208396
466.0000000000059,52.12685510762105,-0.13744164235144132,-2.3503759867787277
467.0000000000059,52.226334304203604,-0.13606787928757966,-2.354521932054958
468.0000000000059,52.32474795962299,-0.13480799479501193,-2.358305054657794
469.0000000000059,52.423561448781555,-0.13137115824924486,-2.360894317963661
470.00000000000597,52.521931557331804,-0.13168788658837902,-2.365034002931345
471.00000000000597,52.61950775373636,-0.13124643866325517,-2.367676482216698
472.00000000000597,52.71847823900506,-0.12948053035650423,-2.3714349622452633
473.000000000006,52.8163361242742,-0.12895559522040415,-2.3754463161602635
474.000000000006,52.91509857054481,-0.127787619713104,-2.3782749420002745
475.000000000006,53.01383503401793,-0.12535200464005267,-2.380886312625322
476.000000000006,53.11254792607046,-0.1251826817333266,-2.384858458509776
477.000000000006,53.21100517023646,-0.12432807037604651,-2.3862548016381435
478.0000000000061,53.309702486398365,-0.12358379205589148,-2.390228327824522
479.0000000000061,53.40833575012973,-0.12333206410337585,-2.394054500246411
480.0000000000061,53.506846906951665,-0.12394245824525532,-2.3982230651871133
481.00000000000614,53.60621016261924,-0.12191943113537661,-2.400066548736614
482.00000000000614,53.70412567393084,-0.1201312236440264,-2.4019409108716685
483.00000000000614,53.80306968823835,-0.11977280262948783,-2.4055182709936447
484.00000000000614,53.899221744963526,-0.11921982442351885,-2.4099139474705384
485.00000000000614,54.00009442479124,-0.11978015589889317,-2.4142547563603616
486.0000000000062,54.09961422999945,-0.11882968848653784,-2.4162172196758283
487.0000000000062,54.19807604419702,-0.11796495659681067,-2.417602564851948
488.0000000000062,54.294943671455954,-0.11818589765940002,-2.4201342784878297
489.00000000000625,54.39522337633243,-0.11714163988309607,-2.423320487306891
490.00000000000625,54.49391876555632,-0.11614005852624092,-2.4260567236191926
491.00000000000625,54.59269070910781,-0.11546189639952673,-2.428752702689344
492.00000000000625,54.69067240025974,-0.11548559426000925,-2.433602272457948
493.00000000000625,54.78989154823071,-0.11452928937150036,-2.4371809060678937
494.0000000000063,54.887321415289605,-0.11364867063044504,-2.440210492147531
495.0000000000063,54.98687345455494,-0.11241186077575388,-2.441581202835157
496.0000000000063,55.08606011627431,-0.11386842168134458,-2.442912141887626
497.00000000000637,55.185574238134954,-0.11113159746497167,-2.4468946573762302
498.00000000000637,55.284243962559415,-0.11007968535512092,-2.451007235092761
499.00000000000637,55.3833433274147,-0.11038573638402115,-2.453806490144172
500.00000000000637,55.48200448704347,-0.11056665516943041,-2.4563986794833506
501.00000000000637,55.580855579167654,-0.11057702995542104,-2.4579087806976267
502.0000000000064,55.680000000000646,-0.11062000000004873,-2.460570341718653
503.0000000000064,55.7792820982302,-0.11092708577664881,-2.4620198454106834
504.0000000000064,55.87818211409343,-0.11131514711098262,-2.4680207080202075
505.0000000000065,55.97737926587973,-0.11299100864825372,-2.468059531003621
506.0000000000065,56.07617724838838,-0.11065309801471025,-2.471404413527922
507.0000000000065,56.17523151730693,-0.10799543862011773,-2.4736660337287804
508.0000000000065,56.2739258101589,-0.10708060496375212,-2.475134089711173
509.0000000000065,56.37298771488513,-0.10952340831619904,-2.4792706881093234
510.00000000000654,56.472079321672105,-0.10746363480909657,-2.48139752683791
511.00000000000654,56.57123927940206,-0.1081360480851843,-2.483951762591471
512.0000000000066,56.66843608901667,-0.10609346964539086,-2.486802391367173
513.0000000000066,56.769494550274004,-0.10637837860748767,-2.4894485129261676
514.0000000000066,56.86849002086632,-0.10542995851808373,-2.4914571440135402
515.0000000000066,56.96764992366112,-0.10374412010516768,-2.4935641820743255
516.0000000000066,57.066514556913916,-0.10203464836162031,-2.4943659555430138
517.0000000000066,57.16580607052017,-0.10093550834320421,-2.498001270893165
518.0000000000066,57.26482152748394,-0.10058617696313732,-2.500249878881223
519.0000000000066,57.36404893850916,-0.10127605141333461,-2.502577699283111
520.0000000000066,57.463636134874974,-0.1018263692598358,-2.5040344448192697
521.0000000000067,57.56262355658344,-0.10128396398910479,-2.5044999182475944
522.0000000000067,57.661686501132166,-0.10002191829359894,-2.5085024218619507
523.0000000000067,57.75949055490062,-0.09962841340587399,-2.5110775647204973
524.0000000000067,57.86063324606545,-0.09834987108687637,-2.5130962162446107
525.0000000000067,57.959603098259095,-0.09848925924693346,-2.5150172755922284
526.0000000000068,58.056542111273004,-0.0980877883499643,-2.517651953928011
527.0000000000068,58.15832548910768,-0.09652941688003816,-2.5188460529038466
528.0000000000068,58.256688434252894,-0.09776893289317014,-2.519740736589045
529.0000000000068,58.35671463775654,-0.09453918353145158,-2.521658778850801
530.0000000000068,58.4563553602362,-0.09381282171579113,-2.5255083042327113
531.0000000000068,58.5553465031351,-0.09194662370508798,-2.5271154106508247
532.0000000000068,58.65470154261485,-0.09204141897803508,-2.529728555947778
533.0000000000068,58.7536967018193,-0.0910674945877236,-2.53123126057865
534.0000000000068,58.85361338223548,-0.08999576564058775,-2.5340785591953767
535.0000000000068,58.95260777148607,-0.08853495837578175,-2.536426597485728
536.0000000000068,59.051980357560765,-0.08720857873254521,-2.5385838406923193
537.0000000000069,59.152117452943905,-0.08670463603530852,-2.540573171711727
538.0000000000069,59.250000000000675,-0.08510709999999817,-2.5425762176553186
539.0000000000069,59.35093209892127,-0.08406790123059757,-2.543576170664968
540.0000000000069,59.450408973180565,-0.0841316795413825,-2.545896483650459
541.0000000000069,59.548969690350695,-0.08363861953194977,-2.547190611600823
542.000000000007,59.64865653308738,-0.08277586348662647,-2.5498576091046754
543.000000000007,59.74722445384351,-0.08404371725936384,-2.552962392576002
544.000000000007,59.84741732595088,-0.08161647043741982,-2.555115588376087
545.000000000007,59.94715071220159,-0.08157178299087775,-2.5562492760800835
546.000000000007,60.04471823911136,-0.08022718394778805,-2.5563717392908645
547.000000000007,60.14629638756867,-0.08124456972281469,-2.5577449331405484
548.000000000007,60.244887825008846,-0.07928270486013134,-2.5603476423574625
549.000000000007,60.345754236473,-0.07777684719601827,-2.56308516278222
550.000000000007,60.444397895149685,-0.07643439443525694,-2.5654090188500405
551.000000000007,60.54404317201335,-0.07709775570091966,-2.566772860466076
552.000000000007,60.644175754905596,-0.07647527471736985,-2.566729387580418
553.0000000000072,60.74374749563943,-0.0767968977636519,-2.5679774873636223
554.0000000000072,60.843365978063034,-0.0769442220153896,-2.5720952687365832
555.0000000000072,60.94383554591946,-0.07631632371112036,-2.5733739211119637
556.0000000000072,61.04332782929671,-0.07342758880686977,-2.5746696146658437
557.0000000000072,61.14228235742075,-0.07508816374230996,-2.577276107242283
558.0000000000073,61.2413900976477,-0.07242809282968621,-2.5785671405148927
559.0000000000073,61.34072245442879,-0.07170637967518735,-2.5799001162111566
560.0000000000073,61.44109994909374,-0.07192301309267161,-2.5804334298169866
561.0000000000073,61.54061244049507,-0.0696240068152215,-2.5815400712193997
562.0000000000073,61.63938161588446,-0.07176694179641152,-2.5841779559819607
563.0000000000073,61.738794071081564,-0.07025281663721027,-2.5868315328110274
564.0000000000073,61.83479000008364,-0.06892480880114003,-2.5880944602386178
565.0000000000073,61.93647406732604,-0.06994373006388926,-2.5907640795657505
566.0000000000073,62.03375905436542,-0.06764659457976566,-2.5930498487013063
567.0000000000073,62.13593496569373,-0.06634472769247339,-2.593347598297597
568.0000000000074,62.23455114836096,-0.06681922370150266,-2.59232751348592
569.0000000000074,62.334170800126806,-0.06445453371170418,-2.595701624088467
570.0000000000074,62.43288648267715,-0.06440011535753142,-2.596234571037762
571.0000000000074,62.532638414108135,-0.06527264901756233,-2.597350372911485
572.0000000000074,62.632001414076385,-0.06367915436291269,-2.5986589959013315
573.0000000000074,62.732366524469946,-0.06304257261467229,-2.601311462958967
574.0000000000074,62.83126750579532,-0.06360673734624753,-2.6025872614931833
575.0000000000075,62.93128748056173,-0.062044663018043344,-2.6040180021237527
576.0000000000075,63.03009478006453,-0.062332171708316154,-2.6052812532695495
577.0000000000075,63.130000000000756,-0.0623999400000244,-2.60623321656433
578.0000000000075,63.230103306953154,-0.06153222135143492,-2.6052611350360375
579.0000000000075,63.328684252242965,-0.06009934459086096,-2.6092311280809866
580.0000000000075,63.42882716838368,-0.06001982563259695,-2.6105538400932895
581.0000000000075,63.52819860124077,-0.05790454466225934,-2.612666260181765
582.0000000000075,63.627641090492695,-0.05723039112611403,-2.6144123414558798
583.0000000000075,63.72610757539109,-0.056006929773229755,-2.6167167299895047
584.0000000000076,63.82666438293844,-0.05479854735787231,-2.6178187237205464
585.0000000000076,63.92635058884392,-0.051442425625538246,-2.6180753919497652
586.0000000000076,64.02647039079677,-0.04985268337783544,-2.6197626936937732
587.0000000000076,64.12567170045047,-0.049658972225667064,-2.6210110637016983
588.0000000000076,64.22487857256472,-0.04871883307707697,-2.6210787575188177
589.0000000000076,64.32483490285348,-0.047944062159260455,-2.621066490316601
590.0000000000076,64.42474446043262,-0.04732224785387304,-2.6223727634193432
591.0000000000077,64.52502029355362,-0.045961967433405956,-2.6250943273141134
592.0000000000077,64.62415323959675,-0.044752296809680424,-2.626551270547962
593.0000000000077,64.72362379729894,-0.04127647970727599,-2.629038905124358
594.0000000000077,64.82374324073278,-0.0413407496056136,-2.631617941088365
595.0000000000077,64.92338049798346,-0.041277860901525944,-2.6317324732231167
596.0000000000077,65.02312615151827,-0.03683183207645495,-2.632930298024127
597.0000000000077,65.12298089951159,-0.037088351747916734,-2.632941492297775
598.0000000000077,65.22302846345505,-0.03474728373730659,-2.63292598449465
599.0000000000077,65.32132177366763,-0.03266786609413914,-2.634243289255789
600.0000000000078,65.42152625263887,-0.03177735822857694,-2.635669558013843
601.0000000000078,65.52179190115416,-0.03060366024852317,-2.6376951359659175
602.0000000000078,65.62165810670336,-0.029343196722835925,-2.638260328238226
603.0000000000078,65.7206799147505,-0.028410464173893042,-2.64082943926275
604.0000000000078,65.82051860421304,-0.029393373959898404,-2.6408446870662408
605.0000000000078,65.91951248019696,-0.028006410255436917,-2.6434587771307223
606.0000000000078,66.01990829618012,-0.026094803409765117,-2.6447376662556805
607.000000000008,66.11990302388776,-0.022983050304658654,-2.6441196919023047
608.000000000008,66.21919775665053,-0.023323335589000765,-2.644788149701914
609.000000000008,66.31989045777945,-0.022790345774458334,-2.6461094157877687
610.000000000008,66.41970973970528,-0.022341728550331945,-2.646746323034362
611.000000000008,66.51952076040959,-0.020608974230867945,-2.648740071140824
612.000000000008,66.61775670565108,-0.020514013680896077,-2.6513528300342695
613.000000000008,66.71860254371134,-0.018211564206955223,-2.65271379021522
614.000000000008,66.81794702280072,-0.017084902235611512,-2.6532790560486266
615.000000000008,66.91796288427966,-0.01617752004251736,-2.6559719650680336
616.0000000000081,67.01796530744714,-0.014490524669332774,-2.6546831648820364
617.0000000000081,67.11901043384125,-0.01224442466343075,-2.6559883032572977
618.0000000000081,67.21900738953839,-0.012150087942709414,-2.657312440940159
619.0000000000081,67.3191896985064,-0.012633842061380691,-2.657295394305171
620.0000000000081,67.41906800811549,-0.008583632097308636,-2.65885901788808
621.0000000000081,67.51850698521243,-0.006278308452836771,-2.660590742526499
622.0000000000081,67.61789064335295,-0.005992131721396456,-2.66169528548007
623.0000000000082,67.71802173142852,-0.002995352103775607,-2.66325193008924
624.0000000000082,67.81794828944055,-0.0018384618654487405,-2.6658694076012197
625.0000000000082,67.91770585175885,-0.0024233729565390485,-2.6646736063964815
626.0000000000082,68.01818419668092,-0.0008688398374449282,-2.66586014273506
627.0000000000082,68.11825302336183,0.0014401245690995323,-2.6671809401419617
628.0000000000082,68.21812005434862,0.0019135592120622256,-2.6684620919222217
629.0000000000082,68.31630128187435,0.003833998392824542,-2.6710172989637915
630.0000000000082,68.41779099335258,0.0067014184103410855,-2.6738108793489737
631.0000000000082,68.51749415150897,0.006979073605634941,-2.672452089409263
632.0000000000083,68.61779702772098,0.01009581398697304,-2.675096302788096
633.0000000000083,68.71694411079137,0.01240855331717582,-2.676295505052025
634.0000000000083,68.81709860464579,0.012454465202067408,-2.676400038789076
635.0000000000083,68.91812280407669,0.013577298602860985,-2.6777193180826195
636.0000000000083,69.01779877434917,0.014729683718207758,-2.677716957381456
637.0000000000083,69.11902420742284,0.013743667429843748,-2.6803685482111423
638.0000000000083,69.2187150184053,0.013307276480376684,-2.6819974248870757
639.0000000000084,69.31789456088474,0.0100270444468872,-2.6831159163780685
640.0000000000084,69.41902133806653,0.007593925261791935,-2.6833707721370232
641.0000000000084,69.5185287991849,0.005804816483278704,-2.684739736543664
642.0000000000084,69.61825737088425,0.0025967821571101744,-2.686055050936666
643.0000000000084,69.71839403557323,0.0001946770292067293,-2.687389369050928
644.0000000000084,69.8184696651587,-0.0018357367744334856,-2.6887034961247
645.0000000000084,69.91836647758461,-0.006677990492734013,-2.6884464204993446