File: 01_Data/Plastic_Laminate_Countertop_Laminate/STA/N2/10K_min/Plastic_Laminate_Countertop_Laminate_STA_N2_10KData_221005_R3.csv
##Temp./Â°C,Time/min,DSC/(mW/mg),Mass loss/mg
51.0,10.763201368621532,-1.573936694825167,-0.0035547049354320848
52.000000000000014,11.110158718998568,-1.4642528653927598,-0.003390646530336383
53.00000000000003,11.342202643633147,-1.3907046640429837,-0.006164300224598129
54.00000000000004,11.541861059556485,-1.3306941101364917,-0.004542278725084614
55.00000000000006,11.714261728910001,-1.286716214323944,-0.005275487910345156
56.00000000000007,11.872852103813747,-1.248887802086245,-0.004407480662998786
57.000000000000085,12.025873576224127,-1.2175873449906884,-0.005408945809576515
58.0000000000001,12.172484689982308,-1.190031107818176,-0.004549922435558074
59.000000000000114,12.307560176030805,-1.1651518589242464,-0.005289470024921528
60.00000000000013,12.448727871006634,-1.1434512578084757,-0.006016316894982943
61.00000000000014,12.57861254396336,-1.1247013952052594,-0.0064838030124194646
62.000000000000156,12.709886683391696,-1.106501164157608,-0.007128332515124569
63.00000000000017,12.836985368681917,-1.0901949423771624,-0.007041301894388674
64.00000000000018,12.958193025052752,-1.0748173410233004,-0.008390586590901528
65.0000000000002,13.083853768751913,-1.0600793609748176,-0.008319402344953097
66.00000000000021,13.202994894081822,-1.0463680292603488,-0.008035322487452312
67.00000000000023,13.326930304985309,-1.0326773018414463,-0.009602864911737008
68.00000000000024,13.44512582626243,-1.0191126007476996,-0.00844101573226208
69.00000000000026,13.561418597347291,-1.0070454749644668,-0.009636317193854715
70.00000000000027,13.679785543473429,-0.9946124441980015,-0.008940154511902776
71.00000000000028,13.794721136783773,-0.9803848286407808,-0.009270921585597947
72.0000000000003,13.909170000000035,-0.9697999999999977,-0.00851902667238047
73.00000000000031,14.022256760918262,-0.9580671214905212,-0.009773829452635496
74.00000000000033,14.13468657602014,-0.9466926422692339,-0.011028797157285553
75.00000000000034,14.245363044997301,-0.9347342247341863,-0.012289404280075189
76.00000000000036,14.356371937241589,-0.9233486780221297,-0.012297432214009696
77.00000000000037,14.465381001718036,-0.9128806273855798,-0.012289532975990447
78.00000000000038,14.575175063252896,-0.9014469988253282,-0.012292139090697596
79.0000000000004,14.685247811554367,-0.8918256611039587,-0.013601551905416898
80.00000000000041,14.793654115286003,-0.8821073540048325,-0.01361687702953951
81.00000000000043,14.89998353216239,-0.8734292066402342,-0.01391330730813145
82.00000000000044,15.006263870102352,-0.8626739563277771,-0.013905227657414976
83.00000000000045,15.113535480971109,-0.8545534206887653,-0.01617966556727435
84.00000000000047,15.219077734062733,-0.8464519494592918,-0.016257730621883404
85.00000000000048,15.323575578691397,-0.8377311802581096,-0.01579180138843661
86.0000000000005,15.428212117489384,-0.8283971673370665,-0.016231520911606623
87.00000000000051,15.532514102239091,-0.821666628422471,-0.016805502370567105
88.00000000000053,15.636006634574958,-0.8137574949917878,-0.017780032314496097
89.00000000000054,15.740594106635939,-0.8075139955848428,-0.016845967660352734
90.00000000000055,15.841924018734872,-0.8013781534733381,-0.017577082196273963
91.00000000000057,15.945960551478855,-0.7931218877926655,-0.019947170914089263
92.00000000000058,16.046422873509684,-0.7874668246268284,-0.018837689404557878
93.0000000000006,16.1468744271001,-0.7820854581745011,-0.019048211113675606
94.00000000000061,16.249980113635935,-0.7758444121557896,-0.019460125265498007
95.00000000000063,16.35104070890232,-0.7714970035372567,-0.02018984294586268
96.00000000000064,16.452345065779177,-0.7660588186377058,-0.02150969088523258
97.00000000000065,16.55071524765362,-0.7617808052553179,-0.020216012717137133
98.00000000000067,16.651306043447867,-0.7573886241749683,-0.021509917643636633
99.00000000000068,16.751631414842482,-0.7532521718612802,-0.022836637449168862
100.0000000000007,16.85044944770226,-0.7490552400915703,-0.023029643675659628
101.00000000000071,16.94917000000008,-0.7442499999999933,-0.0228403447416774
102.00000000000072,17.049067565166748,-0.7397783564633585,-0.024149969543716843
103.00000000000074,17.148382814536948,-0.7353867466061985,-0.0240968354873079
104.00000000000075,17.24713153334621,-0.7326542764768499,-0.02513264771442536
105.00000000000077,17.345677540554778,-0.7279377048016824,-0.024122924820131786
106.00000000000078,17.443529271469586,-0.7248454263198576,-0.02554511624084288
107.0000000000008,17.54213693209175,-0.7203326109979469,-0.025468394385512738
108.00000000000081,17.640454832895443,-0.7162081728933779,-0.02679058203563045
109.00000000000082,17.738733092751975,-0.7123839006446663,-0.02810042387907874
110.00000000000084,17.834960886033176,-0.7096488348919314,-0.027067816239359388
111.00000000000085,17.934207620917494,-0.7041249636907502,-0.02814557479351798
112.00000000000087,18.032792577230317,-0.7004638154828127,-0.02808606891481613
113.00000000000088,18.130436058460337,-0.697540041563896,-0.029409955768786133
114.0000000000009,18.2274494003294,-0.6936883588215538,-0.02940998740573697
115.00000000000091,18.32646032171534,-0.6903943843306695,-0.028099627487427448
116.00000000000092,18.424707665818747,-0.686337809909964,-0.029420239370352874
117.00000000000094,18.521948406178748,-0.6817294282481154,-0.029445756671654166
118.00000000000095,18.619070162910884,-0.676474018920426,-0.030823706764796732
119.00000000000097,18.71747516018999,-0.6744609998795683,-0.030186617598280563
120.00000000000098,18.814448632480243,-0.6708603978854842,-0.030853192832015708
121.000000000001,18.91216523517714,-0.6671925023662812,-0.03127426431402025
122.00000000000101,19.008747861699693,-0.6628192906037375,-0.030740154439095946
123.00000000000102,19.105665857590118,-0.6593628025277739,-0.032062784927208376
124.00000000000104,19.20346608286992,-0.6543535609672722,-0.031949844624484136
125.00000000000105,19.300665911669476,-0.652606992564048,-0.03203421917065885
126.00000000000107,19.397120320143966,-0.6485597625585844,-0.030730167469495306
127.00000000000108,19.49492309362908,-0.6456028970426235,-0.032052688551884145
128.00000000000108,19.592120164168527,-0.6415712474499207,-0.03203974606107263
129.0000000000011,19.687941029878445,-0.6386518457858759,-0.03205000936230906
130.00000000000114,19.785560537852305,-0.6331958073715931,-0.031935536081284965
131.00000000000114,19.881476013321308,-0.6294486583542945,-0.030753266122659717
132.00000000000114,19.977325544562625,-0.6257460487864668,-0.03209248475823667
133.00000000000117,20.075012017986733,-0.6227593334523555,-0.032683223007857976
134.0000000000012,20.17028112034887,-0.6177451406597954,-0.03204985994869958
135.0000000000012,20.26674784595741,-0.6144931961785426,-0.032059632978599595
136.0000000000012,20.363515911311232,-0.6101552339340224,-0.03373616267578594
137.00000000000122,20.458652196294782,-0.6058308362399731,-0.03339784215133346
138.00000000000125,20.555763332136802,-0.6011238238583494,-0.0333080376685162
139.00000000000125,20.651975448536216,-0.5962136990173055,-0.03467806669700568
140.00000000000125,20.74701275635345,-0.593090034718415,-0.03468991242363906
141.00000000000128,20.84343049896397,-0.5880763869334418,-0.03599003158696412
142.0000000000013,20.940367935506863,-0.5853554232863695,-0.03467835900687888
143.0000000000013,21.035198100195633,-0.5808820480881932,-0.033304313996709745
144.0000000000013,21.130284079516013,-0.5762072055633244,-0.03467981804157194
145.00000000000134,21.226576899738436,-0.571644827250979,-0.033462657307023136
146.00000000000136,21.3221559540294,-0.5670304154366563,-0.03468988068652212
147.00000000000136,21.416956381052813,-0.5609999589169323,-0.034689872413173894
148.00000000000136,21.513892209944874,-0.5571535936223747,-0.03599731617255841
149.0000000000014,21.608905652549417,-0.5530918336936413,-0.036078386948585006
150.00000000000142,21.704583080060935,-0.5476765029963889,-0.03600980033731105
151.00000000000142,21.800346152269228,-0.5420026269496583,-0.03731868217944534
152.00000000000142,21.895655539624336,-0.5379951648406258,-0.03863947428403325
153.00000000000145,21.990355014004773,-0.5329768148725527,-0.03864005368527046
154.00000000000148,22.08443608565577,-0.5288894697313175,-0.0373218210174846
155.00000000000148,22.180927835522432,-0.5240039466005412,-0.037319552635556974
156.00000000000148,22.276469678759245,-0.5188886438944497,-0.03863970464963096
157.0000000000015,22.37222868936356,-0.5146452448086505,-0.036981908026265664
158.00000000000153,22.46687741231003,-0.5100810950220528,-0.036990123822111975
159.00000000000153,22.562372229383087,-0.5064566080642812,-0.03830662288698594
160.00000000000153,22.65775408400891,-0.5004582748209915,-0.03962117466434911
161.00000000000156,22.752254190223578,-0.4970253235426248,-0.04194513058168159
162.0000000000016,22.847528112805854,-0.49173630769762694,-0.041053106344878465
163.0000000000016,22.942714221856715,-0.4890360301270135,-0.04220340900482089
164.0000000000016,23.037600559719834,-0.48442973417359225,-0.042919830021216576
165.00000000000162,23.131103701711805,-0.4803725763382433,-0.04411034255207191
166.00000000000165,23.226933373929157,-0.47601674106018116,-0.04423982969120388
167.00000000000165,23.321485524152067,-0.4724716876353167,-0.044239829921079554
168.00000000000165,23.416477781331707,-0.46892009171549365,-0.04477914565702967
169.00000000000168,23.511703084496663,-0.4648326441875647,-0.04554989619138361
170.0000000000017,23.60546675405191,-0.46173303787276015,-0.0468711143031415
171.0000000000017,23.70378260961637,-0.4568979376113202,-0.04686980159249199
172.0000000000017,23.79861734037508,-0.45325312119865957,-0.047858103443225275
173.00000000000173,23.892534420219306,-0.4484700772490981,-0.04882194747049784
174.00000000000176,23.98898515992644,-0.44702178939111736,-0.050147348858639695
175.00000000000176,24.0854315781478,-0.44444925501941,-0.05016993009405457
176.00000000000176,24.180073110647736,-0.44163104206013326,-0.050169729586651
177.0000000000018,24.274825688954373,-0.43764417143217726,-0.05147335140412235
178.00000000000182,24.370681360273558,-0.43595070651954015,-0.05259293414905297
179.00000000000182,24.464586436174407,-0.4322172163557267,-0.05280013009251405
180.00000000000182,24.560575179219658,-0.42825214019230196,-0.05280013019701091
181.00000000000185,24.65446494530125,-0.4270189150918826,-0.053715163202505245
182.00000000000188,24.75012565868494,-0.42353609988584123,-0.05411991975230279
183.00000000000188,24.845224563845925,-0.420677929517304,-0.054112904640510884
184.00000000000188,24.940199527691973,-0.41809115213725323,-0.055542275731709445
185.0000000000019,25.034810411571662,-0.4160794320450713,-0.0580485804978359
186.00000000000193,25.13032232571756,-0.41468954601421026,-0.05806986929160729
187.00000000000193,25.225001659067228,-0.411239489364662,-0.058607479095048376
188.00000000000193,25.32009307868786,-0.40686751293341283,-0.05939006158751692
189.00000000000196,25.415345400999097,-0.4059065850416697,-0.06064428033968383
190.000000000002,25.509671452317605,-0.40348954199989573,-0.0607100721786864
191.000000000002,25.60440196428343,-0.39970162424764233,-0.06186262167778178
192.000000000002,25.700322956554707,-0.3979973224967748,-0.06307249189313602
193.00000000000202,25.795061055148004,-0.3958998260729292,-0.06466184696258193
194.00000000000205,25.889075111293344,-0.3929831384710223,-0.06596980822970355
195.00000000000205,25.985375205056666,-0.3916165145545298,-0.06596643619509912
196.00000000000205,26.0803435947411,-0.3889359141380483,-0.06730164279445905
197.00000000000207,26.174703561341975,-0.38712348488367637,-0.06762115207940145
198.0000000000021,26.270220895872317,-0.3855311469243883,-0.06780295477695741
199.0000000000021,26.364964472432234,-0.38287290641374616,-0.07043622263058946
200.0000000000021,26.45975825933916,-0.380689523109198,-0.06936820958654888
201.00000000000213,26.555148480126633,-0.3800736623678273,-0.07202897776614758
202.00000000000216,26.64823047254644,-0.37754054566349066,-0.07234998197157338
203.00000000000216,26.742712279595032,-0.37464151143839036,-0.07463827513601373
204.00000000000216,26.83885269982333,-0.373646581658467,-0.07596206706161457
205.0000000000022,26.933426541832713,-0.37272662295150577,-0.077280234962263
206.00000000000222,27.02917000000021,-0.3706599999999962,-0.07859987000156998
207.00000000000222,27.123368880924584,-0.36945399244021854,-0.07860138006888029
208.00000000000222,27.218149894884576,-0.36758197973576096,-0.08124158565016959
209.00000000000225,27.31363742396001,-0.3676267346538969,-0.0812343457752025
210.00000000000227,27.40643865945209,-0.3659963994006587,-0.08386992496492773
211.00000000000227,27.50348632339907,-0.3662883330096735,-0.08324935342417117
212.00000000000227,27.597137732869182,-0.36487525794656317,-0.08551052562390193
213.0000000000023,27.69214859196409,-0.36370721309095133,-0.08551616208218071
214.00000000000233,27.787524096582803,-0.3640781335247884,-0.08815324164576754
215.00000000000233,27.882516036592747,-0.36370359074037395,-0.08821331815104827
216.00000000000233,27.9773483564794,-0.362522074588505,-0.09072989365619488
217.00000000000236,28.0711513522978,-0.36286617674026433,-0.09340226474075042
218.0000000000024,28.16684271382709,-0.3621013665506959,-0.094741545355153
219.0000000000024,28.261810861466735,-0.36239701542416436,-0.09538983265201217
220.0000000000024,28.357981215570494,-0.3615273682986875,-0.09670983219182006
221.00000000000242,28.451286086753566,-0.3613836327607211,-0.09824513056026518
222.00000000000244,28.547584111023166,-0.362058406407887,-0.1006798539535132
223.00000000000244,28.64218548291457,-0.3620307595159424,-0.10198072282878012
224.00000000000244,28.736539760635274,-0.36173394993746966,-0.1040874791528772
225.00000000000247,28.832164233547164,-0.36260514511777403,-0.10560809531140736
226.0000000000025,28.92692320053538,-0.3624304931652638,-0.1048258333872436
227.0000000000025,29.02198068080136,-0.3619232116234847,-0.10691573672389598
228.0000000000025,29.1164723516197,-0.3620916616146871,-0.10955999375896441
229.00000000000253,29.211720237148146,-0.36156467470536885,-0.11087731689076241
230.00000000000256,29.306647635626856,-0.36374708678616285,-0.1135898406670579
231.00000000000256,29.40174638417757,-0.36264980774242456,-0.11413935371471773
232.00000000000256,29.496313659556115,-0.36141073746216834,-0.11416756354515067
233.0000000000026,29.5915165127919,-0.3636053171119068,-0.11736644344341629
234.00000000000261,29.687519521547227,-0.36286365417164806,-0.12075228596844756
235.00000000000261,29.7834549380877,-0.3634631210432455,-0.12208039927909153
236.00000000000261,29.877960498104358,-0.363003275252101,-0.12347670690874768
237.00000000000264,29.973398917220877,-0.3636102594869406,-0.126837471986188
238.00000000000267,30.06814929642455,-0.3629970147284172,-0.12811054990731785
239.00000000000267,30.16428857855806,-0.3647984466698241,-0.13076457560259236
240.00000000000267,30.259068504884805,-0.3645103528601952,-0.13403671797058614
241.0000000000027,30.353281049553452,-0.3639236260335209,-0.13635835195361778
242.00000000000273,30.449263145665228,-0.36508665858727946,-0.13907193925532813
243.00000000000273,30.54246804489838,-0.364308392816459,-0.14192494623244833
244.00000000000273,30.640076744735275,-0.3635749756614706,-0.14460123560484917
245.00000000000276,30.734966974134025,-0.3626739464886171,-0.14729232212850984
246.00000000000279,30.829820615442713,-0.3631156166803735,-0.1499826590654374
247.00000000000279,30.925349826377076,-0.3625260810867473,-0.15427530990399685
248.00000000000279,31.02068615946863,-0.3621225046310459,-0.15710348865424706
249.0000000000028,31.11470621320609,-0.3621031383166108,-0.15971677932347816
250.00000000000284,31.210424758389305,-0.3632264613132139,-0.16237009143298398
251.00000000000284,31.305933282176504,-0.3611088128767429,-0.16515287917934085
252.00000000000284,31.400910302220176,-0.3624758386818121,-0.16944301979322596
253.00000000000287,31.49557642679243,-0.3622864928646875,-0.17254120818407515
254.0000000000029,31.590785776880107,-0.3615521701743654,-0.17620731955172353
255.0000000000029,31.687226815749657,-0.36061313857863053,-0.1791788731666797
256.0000000000029,31.781486423587353,-0.36226989289244277,-0.18337161330356677
257.00000000000296,31.876964288203418,-0.3611336208366828,-0.18771462930094351
258.00000000000296,31.971846313125713,-0.361867394574782,-0.1909193986428095
259.00000000000296,32.0667073142153,-0.36017204759011406,-0.19410508462035647
260.00000000000296,32.162006713151555,-0.36032828083331714,-0.19719828579937637
261.00000000000296,32.25642351551677,-0.35992626210014633,-0.20251114260693193
262.000000000003,32.351791099290594,-0.3588307473123371,-0.20699948310592697
263.000000000003,32.447254075188376,-0.35908642842925403,-0.21258989634135972
264.000000000003,32.54093361984306,-0.35742975491013484,-0.217343034267361
265.00000000000307,32.63957798785333,-0.35912446605188136,-0.22227649582148734
266.00000000000307,32.73364172144694,-0.35738019756853473,-0.22586396072524062
267.00000000000307,32.828554103824374,-0.35649623860677115,-0.23180497949983003
268.00000000000307,32.92382981156692,-0.35544561539640485,-0.23721109541509833
269.00000000000307,33.0195448772011,-0.3537507046078256,-0.24237852735811405
270.0000000000031,33.11507414561359,-0.3518531037471119,-0.2479237117737747
271.0000000000031,33.20952736960867,-0.3522477765297292,-0.25406654409905993
272.0000000000031,33.304578045275754,-0.35037559177603445,-0.25913597339000116
273.0000000000032,33.400411375100106,-0.34871771866351803,-0.26606274386001916
274.0000000000032,33.49585342484641,-0.34800209659093945,-0.27096951719757856
275.0000000000032,33.59148355223457,-0.3475601955398303,-0.277497044626533
276.0000000000032,33.685568802478386,-0.3462584508407412,-0.284338503663887
277.0000000000032,33.78260634759357,-0.34596304490744734,-0.29150009268945665
278.00000000000324,33.878248717618455,-0.3440432642764624,-0.29830824512588094
279.00000000000324,33.973875683488394,-0.3426833388968092,-0.30454537311668917
280.00000000000324,34.06818399632435,-0.3410418131293045,-0.31155983465080483
281.0000000000033,34.1637012577255,-0.339762467304646,-0.3185608956657284
282.0000000000033,34.25858261005556,-0.33839128242057526,-0.32580487679263603
283.0000000000033,34.35506191495082,-0.33652702285811154,-0.3348229261172584
284.0000000000033,34.44974064962037,-0.3359524977424438,-0.3434153707569605
285.0000000000033,34.54477449962999,-0.33436842283752854,-0.35142924048161905
286.00000000000335,34.64093591629087,-0.33406630661355624,-0.3604775275377743
287.00000000000335,34.73724263527018,-0.33190648410507956,-0.36858122392835035
288.00000000000335,34.83084955477628,-0.3297427090383745,-0.37722262192091893
289.0000000000034,34.92695730584663,-0.3285815435245154,-0.38695511014127915
290.0000000000034,35.02221282890636,-0.32678355374424045,-0.39710413811019185
291.0000000000034,35.11959872272669,-0.32620406294278165,-0.4064657247331951
292.0000000000034,35.21297973126658,-0.32499420062406276,-0.4164853746451067
293.0000000000034,35.31121228113597,-0.3231691871287378,-0.4265057605586371
294.00000000000347,35.40545372126587,-0.32269046027760007,-0.43609391291346356
295.00000000000347,35.50124583017687,-0.32161919064001754,-0.4483493332281512
296.00000000000347,35.59731668096698,-0.3210435283854961,-0.45855528972000315
297.0000000000035,35.69355034442455,-0.32079034877919615,-0.47036131351764077
298.0000000000035,35.789464513006116,-0.32052329229801174,-0.4829596172725017
299.0000000000035,35.882609315754266,-0.3191809671420432,-0.49509524178702913
300.0000000000035,35.98048578247338,-0.3192920317991729,-0.5076458117848466
301.0000000000035,36.07642559151783,-0.31836290160984165,-0.5201604286371508
302.0000000000036,36.17221543960418,-0.31775041352726785,-0.5337212706507954
303.0000000000036,36.268351228248,-0.316271841111122,-0.547777250115574
304.0000000000036,36.36446938795077,-0.3167599137631339,-0.5618462805056832
305.00000000000364,36.45974038201227,-0.31646119672691086,-0.5762453817739361
306.00000000000364,36.555833678832165,-0.3158296257964423,-0.5901731836729867
307.00000000000364,36.652475906175546,-0.3166644254415873,-0.6044856415005277
308.00000000000364,36.74851410694637,-0.3156800931017043,-0.6191738201126245
309.00000000000364,36.84418997000171,-0.3153171552082231,-0.6365907874111207
310.0000000000037,36.940808161491795,-0.31550242735361017,-0.6519187699918123
311.0000000000037,37.036179485086684,-0.3177362189626347,-0.6680103197727711
312.0000000000037,37.13291258505775,-0.31659363956100617,-0.6843060056761003
313.00000000000375,37.22846911216665,-0.3162497380911996,-0.7022922375000893
314.00000000000375,37.32474045101397,-0.31538276338023147,-0.7213018235707436
315.00000000000375,37.42023719891865,-0.31567299784054464,-0.7399332808757522
316.00000000000375,37.51446376386532,-0.316889023488484,-0.7579931180866866
317.00000000000375,37.6133970703089,-0.3171728640833932,-0.7781520676026732
318.0000000000038,37.70955698271285,-0.31845491979847595,-0.7982162130641459
319.0000000000038,37.80635738077907,-0.31890840032661844,-0.818471025685394
320.0000000000038,37.90257752282638,-0.3194359874675926,-0.8394774839254628
321.00000000000387,37.998492547674076,-0.32073515815623216,-0.8614398749318424
322.00000000000387,38.09485318605308,-0.3228231017815102,-0.8818859708074238
323.00000000000387,38.19260569854986,-0.32236364057775524,-0.9062041563415137
324.00000000000387,38.2877893150574,-0.32245990747629294,-0.9296290190440946
325.00000000000387,38.384953596428616,-0.32220337337874505,-0.9532934457771329
326.0000000000039,38.478871515215,-0.3235756899662117,-0.9766669243403165
327.0000000000039,38.57700378743558,-0.3237940875427831,-1.0009327912131232
328.0000000000039,38.67502084665968,-0.3247667331854615,-1.0265151204557084
329.000000000004,38.7701701112166,-0.3268587393202896,-1.0544007040772185
330.000000000004,38.86792168791312,-0.32703104403269884,-1.0806971251525077
331.000000000004,38.96370052943061,-0.3282345933656313,-1.107318652089214
332.000000000004,39.06044865538292,-0.32971907339052126,-1.1343661913372962
333.000000000004,39.157036997162514,-0.33084451919983165,-1.163016892772685
334.00000000000404,39.25353565876252,-0.33196289773588467,-1.1896266666071411
335.00000000000404,39.3508395986191,-0.3341529002577456,-1.220020426521733
336.00000000000404,39.44644780880448,-0.33773188568610646,-1.248703184283892
337.0000000000041,39.544501134494844,-0.3408039906957845,-1.28092927572966
338.0000000000041,39.64133803560962,-0.34541062700790515,-1.3123691529188815
339.0000000000041,39.73778859914444,-0.346747677039387,-1.3430097975731266
340.0000000000041,39.83460743547472,-0.35111959616403515,-1.3728474286179173
341.0000000000041,39.932186072018034,-0.35789022789876207,-1.403400511248201
342.00000000000415,40.02837333290115,-0.36152088728834897,-1.4362559394273022
343.00000000000415,40.12518260526698,-0.3653575503321329,-1.4639694010037858
344.00000000000415,40.22288403201639,-0.37008355714133273,-1.4953367169857121
345.0000000000042,40.31887635428647,-0.3736970457329472,-1.526787711254582
346.0000000000042,40.41521974693823,-0.3772003005820335,-1.5553933551262755
347.0000000000042,40.51261399032574,-0.3801636317789706,-1.5846524420692112
348.0000000000042,40.60935575674807,-0.38498029849167975,-1.6108886581260924
349.0000000000042,40.70618692679448,-0.38704302115090183,-1.6376486138305006
350.00000000000426,40.803155612368066,-0.38812076757953234,-1.6650606837265487
351.00000000000426,40.90083102531952,-0.38885366463550786,-1.6894863061393446
352.00000000000426,40.9978742030145,-0.3889618937879349,-1.7121846394873805
353.0000000000043,41.094425259343375,-0.38720241295180857,-1.7320460933278268
354.0000000000043,41.19261445778243,-0.38528800592521006,-1.7533526599725846
355.0000000000043,41.28593509690621,-0.3827648824412756,-1.7687547903924683
356.0000000000043,41.384807512913085,-0.37747144441130576,-1.7871456228260425
357.0000000000043,41.481228574378065,-0.3744930277228867,-1.8011904712886242
358.0000000000044,41.57863268580621,-0.37161269148271664,-1.8155049805347239
359.0000000000044,41.67617070199971,-0.3686341872115497,-1.825294086522414
360.0000000000044,41.77289829306668,-0.3658523329198983,-1.8386374267122845
361.00000000000443,41.87029628099563,-0.36156629211184654,-1.8502166846704453
362.00000000000443,41.96764246296769,-0.3593635138874062,-1.8598059236215048
363.00000000000443,42.06419742891591,-0.35746184695364414,-1.8690886214218536
364.00000000000443,42.16171469075178,-0.3511975935879908,-1.8783604870592887
365.00000000000443,42.2588792159716,-0.34855807811690886,-1.886376442576943
366.0000000000045,42.35586553969197,-0.3438114559627166,-1.8944481064563745
367.0000000000045,42.45293172709309,-0.3400956008229203,-1.9016287033990142
368.0000000000045,42.55019281423475,-0.3352704534138496,-1.9073122695060944
369.00000000000455,42.64714631793478,-0.3319366560860023,-1.912650623675864
370.00000000000455,42.74398001393053,-0.32911520858780546,-1.919758129447085
371.00000000000455,42.84095967389424,-0.32892199734418953,-1.9265471070122144
372.00000000000455,42.93863549897361,-0.32698754846223166,-1.9326899950898966
373.00000000000455,43.035973446024904,-0.3260994756497426,-1.9397303505584786
374.0000000000046,43.131980840698404,-0.3262088387770795,-1.9433555072326403
375.0000000000046,43.22937686270987,-0.32372816155376755,-1.948810863398188
376.0000000000046,43.32657750360299,-0.3230028417275661,-1.9537292120200043
377.00000000000466,43.42454919912104,-0.3204718792866931,-1.9584576058856729
378.00000000000466,43.520286382987564,-0.3208400156579739,-1.9621336739107287
379.00000000000466,43.619066813338904,-0.31926202524667224,-1.9665382455000935
380.00000000000466,43.713690961026494,-0.31963457475196533,-1.9704416850092596
381.00000000000466,43.81274558729832,-0.3165866709201983,-1.975163962640671
382.0000000000047,43.910177359309905,-0.31596503082334526,-1.9786084390510288
383.0000000000047,44.00760864115885,-0.3142562998374016,-1.9830917759222468
384.0000000000047,44.1045354348247,-0.31296713992579417,-1.987443224242607
385.0000000000048,44.20135159823925,-0.31235398288415617,-1.9906618197126131
386.0000000000048,44.29989663921535,-0.3115859226717418,-1.994271075841858
387.0000000000048,44.39538464143206,-0.31011856204340676,-1.9992929533236912
388.0000000000048,44.49335004445005,-0.30805334540097684,-2.0036471403415304
389.0000000000048,44.59063618693233,-0.30684374484070626,-2.0076131249446014
390.00000000000483,44.68860263157104,-0.30651174993678404,-2.0094833063591397
391.00000000000483,44.78620162758697,-0.3043436022469777,-2.0146432527379052
392.00000000000483,44.88354040419314,-0.3046279637507654,-2.019538542305337
393.0000000000049,44.981633408660414,-0.30181058572172803,-2.022738656801112
394.0000000000049,45.07936873801574,-0.30100031287365187,-2.0255080822052838
395.0000000000049,45.17786188323133,-0.30069912562951284,-2.0310823604649437
396.0000000000049,45.275460404716334,-0.298181453371734,-2.0345699642567108
397.0000000000049,45.37284082954502,-0.29748178781586865,-2.039305465947136
398.00000000000495,45.470093125604976,-0.29631369762300847,-2.0422768367249193
399.00000000000495,45.56788250231496,-0.293082019116816,-2.045612539613284
400.00000000000495,45.66568364666922,-0.292328268567906,-2.0488878798850485
401.000000000005,45.76447114226927,-0.2905726627714043,-2.0541148991095266
402.000000000005,45.861385747885784,-0.2876402844990423,-2.0574785958230803
403.000000000005,45.960197641606875,-0.2859957579974331,-2.060814991877089
404.000000000005,46.056692100479474,-0.2839661503576267,-2.06439467804936
405.000000000005,46.15454368704179,-0.2827390841664143,-2.0675978918030897
406.00000000000506,46.25226081735062,-0.2806850784574352,-2.0704643411497146
407.00000000000506,46.34998074248589,-0.27839503770513796,-2.076784807410115
408.00000000000506,46.44692827534453,-0.2748088224505209,-2.081151040489418
409.0000000000051,46.545334754943134,-0.27381554879337056,-2.0840727366078413
410.0000000000051,46.642474972981695,-0.2714053182187191,-2.0866986544333805
411.0000000000051,46.739622255661025,-0.2692277294712233,-2.0898109115634194
412.0000000000051,46.837466070783734,-0.26639280980134383,-2.096238110672977
413.0000000000051,46.934471546263275,-0.2643674502117233,-2.101689813790373
414.0000000000052,47.032870242667904,-0.262638419497677,-2.1047624885475713
415.0000000000052,47.13087995612958,-0.26070758150101014,-2.1075231193248136
416.0000000000052,47.226233697716566,-0.2584779632918197,-2.11390753480347
417.00000000000523,47.326574592023746,-0.2551533231148734,-2.118727858496829
418.00000000000523,47.42400734740079,-0.2547170727753882,-2.1227297629166006
419.00000000000523,47.5196401775944,-0.2507316086135138,-2.1257495768970585
420.00000000000523,47.61887146218497,-0.24888368149418827,-2.1317362012281347
421.00000000000523,47.7165959744667,-0.2464050141791066,-2.1347672219814093
422.0000000000053,47.814855236302115,-0.24566911830749574,-2.138673299197739
423.0000000000053,47.91025187019809,-0.24395487348975847,-2.143533201101855
424.0000000000053,48.01076042744234,-0.2436486953411825,-2.147959186720667
425.00000000000534,48.108256183954204,-0.2418761382549922,-2.1500158604809734
426.00000000000534,48.205838908980716,-0.2404105752994728,-2.1565298300682865
427.00000000000534,48.30441916653724,-0.2392871429768242,-2.1606593855512104
428.00000000000534,48.400994926093475,-0.23678702774908533,-2.1647005781521527
429.00000000000534,48.49857763465689,-0.23671763997660436,-2.169052964759834
430.0000000000054,48.59665140366228,-0.2349507515112122,-2.1715608476665538
431.0000000000054,48.69487661685879,-0.23313852040600377,-2.1768285994729277
432.0000000000054,48.79270634013198,-0.233010729733031,-2.1804048164854994
433.00000000000546,48.89059646114885,-0.23237380672878438,-2.1862250514302373
434.00000000000546,48.98851002348494,-0.2297418539109818,-2.1906359260722614
435.00000000000546,49.086131055944584,-0.22955528605691838,-2.1953438494023874
436.00000000000546,49.18412297893039,-0.2284927035210637,-2.197478855787384
437.00000000000546,49.28218905325851,-0.22535530610968654,-2.2002726759076587
438.0000000000055,49.3800222769147,-0.22482922426567648,-2.2061268376797756
439.0000000000055,49.47743504233381,-0.22491128255890988,-2.210501154190451
440.0000000000055,49.576128452324795,-0.2250845017703953,-2.2136369168054717
441.00000000000557,49.67492524317378,-0.22431977099519435,-2.2193538337929333
442.00000000000557,49.771947281778985,-0.22363352908107123,-2.2229942333312516
443.00000000000557,49.87005890643171,-0.22344112338968156,-2.227417443741182
444.00000000000557,49.968761042808495,-0.22181047602918869,-2.2314128428085955
445.00000000000557,50.06541055793639,-0.21966553912237413,-2.2357347577653295
446.0000000000056,50.16420712683041,-0.21991075322044554,-2.239812444655586
447.0000000000056,50.26174458118627,-0.2188036869469842,-2.242922365772415
448.0000000000056,50.36041117053319,-0.21878291262721597,-2.2444383544651805
449.0000000000057,50.458873528458234,-0.21848905570543536,-2.25021917644579
450.0000000000057,50.55801665331348,-0.21617030983825547,-2.254741532882083
451.0000000000057,50.65581658266607,-0.2162413064359143,-2.2575896637121486
452.0000000000057,50.75363202357213,-0.21486985257319205,-2.261617041048559
453.0000000000057,50.85230142317377,-0.21461513881764832,-2.2657920695963205
454.00000000000574,50.949851041182896,-0.21259017796033683,-2.269728407068281
455.00000000000574,51.049075060072205,-0.2133898448403957,-2.2736122308343765
456.00000000000574,51.14680594569349,-0.2115812533087689,-2.278014222353214
457.0000000000058,51.24552638523602,-0.21256091709322789,-2.2828829396782613
458.0000000000058,51.34367908704479,-0.21102266964636274,-2.285054213003094
459.0000000000058,51.4421145263965,-0.21066241917358644,-2.2893587670816067
460.0000000000058,51.540661525692336,-0.20983394252516896,-2.2931753990304156
461.0000000000058,51.63867203596446,-0.20959869144175075,-2.296514575033501
462.00000000000585,51.73761303337234,-0.20865560330726968,-2.2981938229445626
463.00000000000585,51.83607948339949,-0.2085828765477028,-2.3009100835609493
464.00000000000585,51.93355720060895,-0.20499982446333487,-2.3047977778487687
465.0000000000059,52.03166091870053,-0.20479484120738717,-2.3093361683430196
466.0000000000059,52.13105772684905,-0.20531471304616714,-2.3121287240620925
467.0000000000059,52.22985989121517,-0.20527369237372717,-2.314790871847735
468.0000000000059,52.32885757084218,-0.2039445954404791,-2.319146406530318
469.0000000000059,52.426950948982096,-0.20269721109260003,-2.32333127111
470.00000000000597,52.525379345082776,-0.20043421543603596,-2.3260420793268612
471.00000000000597,52.62398185251371,-0.20120117328677045,-2.3293903206675415
472.00000000000597,52.72167410831752,-0.20105782262945585,-2.3337141720970562
473.000000000006,52.82110187460919,-0.20005595962060801,-2.335687672797614
474.000000000006,52.91728891762941,-0.20060150515905237,-2.3382060131414937
475.000000000006,53.01652276391318,-0.19821186421327508,-2.342321906342235
476.000000000006,53.116486197002516,-0.19719218785638423,-2.3452808041339006
477.000000000006,53.21573788984836,-0.19738184984378573,-2.347874704062461
478.0000000000061,53.314947535640634,-0.19607648687184212,-2.3520880372176864
479.0000000000061,53.41127708570193,-0.19520168110643915,-2.354815710747519
480.0000000000061,53.51163710486452,-0.19407804849618465,-2.357563900145178
481.00000000000614,53.609884838029465,-0.1939509136492192,-2.360338907935208
482.00000000000614,53.708136685229626,-0.19491325517797423,-2.364222498054193
483.00000000000614,53.80749434221443,-0.1921727418547397,-2.367016410131297
484.00000000000614,53.904666111865666,-0.19173971522007519,-2.3695242799549927
485.00000000000614,54.00498741336027,-0.19322802447004114,-2.373875994311481
486.0000000000062,54.10353956129463,-0.19246012517534986,-2.3759376577675173
487.0000000000062,54.202228912345774,-0.19195320054985562,-2.3772788940018934
488.0000000000062,54.301092916848106,-0.19129256055946317,-2.381368185604095
489.00000000000625,54.399170000000616,-0.19073999999997,-2.384140590605045
490.00000000000625,54.49794040344051,-0.18957784407624373,-2.386056259429254
491.00000000000625,54.59723129076333,-0.19023220133050514,-2.387923477027753
492.00000000000625,54.69704121143574,-0.18907595186319134,-2.391863780049635
493.00000000000625,54.79460400772243,-0.18908069586098933,-2.3943848235966296
494.0000000000063,54.89328910652934,-0.18781870086266253,-2.397272075421757
495.0000000000063,54.99086184594157,-0.18797682320288328,-2.3998171045838435
496.0000000000063,55.09088724399583,-0.18801277317128515,-2.4025063574251955
497.00000000000637,55.190771560077025,-0.18644892143456882,-2.4064461457602775
498.00000000000637,55.28977452830013,-0.1857261151481347,-2.410098319591386
499.00000000000637,55.389776632731305,-0.1850479618565477,-2.4101205075427696
500.00000000000637,55.488154183075864,-0.18619428782193995,-2.4129729466812186
501.00000000000637,55.58632520357966,-0.1857487943494225,-2.414776474973324
502.0000000000064,55.68550078781606,-0.18466699759461272,-2.4189359344772026
503.0000000000064,55.78468687895774,-0.1857571013439753,-2.4231969196268293
504.0000000000064,55.88403076196337,-0.18516910036851258,-2.4239842802127516
505.0000000000065,55.98023153779412,-0.18639021352350435,-2.4266467384769257
506.0000000000065,56.08181309719463,-0.18436016571218358,-2.4293697704706827
507.0000000000065,56.18089875306452,-0.18482766875860654,-2.430637893916852
508.0000000000065,56.27947722599393,-0.1838677607733223,-2.433339444706358
509.0000000000065,56.37955485670661,-0.18402809423536434,-2.4360749622956845
510.00000000000654,56.478181846653314,-0.18347033955129366,-2.4380593092808804
511.00000000000654,56.57707659816886,-0.18402710950054263,-2.440611049369578
512.0000000000066,56.67487738163294,-0.18175153559432083,-2.443927290797322
513.0000000000066,56.77490817775674,-0.18288233829930156,-2.4453141475785762
514.0000000000066,56.87389835029553,-0.18328983365328738,-2.4480976490488837
515.0000000000066,56.97315070362589,-0.18334064834237485,-2.45061028089877
516.0000000000066,57.07148428991701,-0.1847436240113625,-2.453510766115377
517.0000000000066,57.17083607674457,-0.18354742603957327,-2.455991549045094
518.0000000000066,57.27038806398241,-0.1833100190644409,-2.4559253020196086
519.0000000000066,57.36938131901092,-0.18393599392391446,-2.4585909181332575
520.0000000000066,57.46766919263713,-0.1832973943860138,-2.461332246162433
521.0000000000067,57.567364615065046,-0.18391650223932826,-2.4638357071212393
522.0000000000067,57.66755218060794,-0.1838075894035896,-2.4674717726042035
523.0000000000067,57.76653011704647,-0.1835807113694975,-2.468910561866857
524.0000000000067,57.865744188138656,-0.18224655135849105,-2.4715154992530253
525.0000000000067,57.964813138354614,-0.18118760462304423,-2.4702149883497135
526.0000000000068,58.06552858218787,-0.18197664204561814,-2.474239561358441
527.0000000000068,58.16324885771863,-0.18016799579421794,-2.4768553359743173
528.0000000000068,58.26346567689669,-0.18168649889025332,-2.4785668499606848
529.0000000000068,58.36227000163947,-0.17958824509427085,-2.4804273102557826
530.0000000000068,58.4612101662468,-0.180733072596319,-2.484485656617882
531.0000000000068,58.56210453773327,-0.1787253453148931,-2.4863289039330274
532.0000000000068,58.66125959370835,-0.17898593525838494,-2.4870319557847624
533.0000000000068,58.760532733363455,-0.17914689751892746,-2.4896510490677093
534.0000000000068,58.860246572768965,-0.1794181700862274,-2.4909692905888
535.0000000000068,58.958961635645856,-0.17825595340144648,-2.4922847056292072
536.0000000000068,59.05936726681656,-0.17888783756518556,-2.493609821084849
537.0000000000069,59.1586473690789,-0.17839248482803988,-2.4962084599420358
538.0000000000069,59.25775649466842,-0.17662478150330796,-2.4975021082944284
539.0000000000069,59.35703559977657,-0.176054236299113,-2.5001841384106065
540.0000000000069,59.45625071868945,-0.1753376036529856,-2.5015058472611864
541.0000000000069,59.5558597059297,-0.17359608935054188,-2.504182789034741
542.000000000007,59.6550903700104,-0.1729210063032551,-2.506420744246384
543.000000000007,59.753746422040074,-0.1726099518138008,-2.508085135508101
544.000000000007,59.85333909281874,-0.17297687589957356,-2.5096295977338023
545.000000000007,59.953116911176735,-0.17006462669286979,-2.5119434468752675
546.000000000007,60.052226683951844,-0.17002952849525763,-2.512051301593578
547.000000000007,60.150542253363746,-0.1692498031029984,-2.514689640689615
548.000000000007,60.250508805500935,-0.16835808126123483,-2.5173177393317316
549.000000000007,60.350811765268425,-0.16817723342338575,-2.5194391986703195
550.000000000007,60.44936725926004,-0.1676156654102711,-2.5212698889393446
551.000000000007,60.547947851552365,-0.16603156973259567,-2.5212724237470936
552.000000000007,60.64896429836099,-0.16457719954504632,-2.523222837720396
553.0000000000072,60.747786140263194,-0.16419555401810715,-2.525215393885679
554.0000000000072,60.84476758970154,-0.16416563502829867,-2.526517386235426
555.0000000000072,60.945372794039784,-0.16450440058696708,-2.5278636603588556
556.0000000000072,61.044497572040164,-0.1627335480142746,-2.529179793004382
557.0000000000072,61.144033664690696,-0.16208023043944983,-2.531346482077866
558.0000000000073,61.2440402336777,-0.16121256512872856,-2.5331094981147233
559.0000000000073,61.34331036908824,-0.160101465628925,-2.5343449204334827
560.0000000000073,61.44320614371027,-0.15997923588895857,-2.5358042644133363
561.0000000000073,61.541024590012356,-0.16101553826826026,-2.5383784050932157
562.0000000000073,61.64069264384792,-0.15984833540177318,-2.5397276928250556
563.0000000000073,61.7405140841243,-0.1584922657001844,-2.5410364379068535
564.0000000000073,61.84050332178092,-0.15780734510793576,-2.542428302727674
565.0000000000073,61.93952942599596,-0.15696592957994876,-2.5437840244799785
566.0000000000073,62.03896672597021,-0.15689689991166628,-2.5449904024031227
567.0000000000073,62.138087551455975,-0.15707347005444153,-2.5462978934502285
568.0000000000074,62.23722718370191,-0.15512333126937256,-2.5476194134590817
569.0000000000074,62.337379934371285,-0.15406132242037143,-2.5494716744588026
570.0000000000074,62.43682169786476,-0.15222745746678518,-2.5507998859241123
571.0000000000074,62.535619528348334,-0.1512572967809743,-2.552125713249757
572.0000000000074,62.63436108140032,-0.15051104432290296,-2.553465225962304
573.0000000000074,62.73355103081476,-0.1502957214801402,-2.5543862679654743
574.0000000000074,62.83296117392055,-0.14997036556399576,-2.5571232844066727
575.0000000000075,62.93269406835336,-0.14836535214833713,-2.558354034918181
576.0000000000075,63.03261938825843,-0.14745118009565783,-2.558653921493584
577.0000000000075,63.13099602807348,-0.14678220588828753,-2.559649900580945
578.0000000000075,63.2318277058272,-0.14726478595005868,-2.5623262170720817
579.0000000000075,63.33048747021946,-0.14575130813314982,-2.5636561164474676
580.0000000000075,63.430868196274965,-0.145401522570749,-2.566321890117673
581.0000000000075,63.529780486473356,-0.14481671104751406,-2.567604553886323
582.0000000000075,63.62762208829787,-0.14399673602945648,-2.567632131066083
583.0000000000075,63.72936828451817,-0.14303749147596329,-2.5689098963951267
584.0000000000076,63.82856130509887,-0.14229794771211748,-2.570230880675967
585.0000000000076,63.92817963303999,-0.14125202553603267,-2.5708599119959743
586.0000000000076,64.02708259234161,-0.14043648671516581,-2.5715021734662535
587.0000000000076,64.12656535030071,-0.13993064912529432,-2.5750410289884234
588.0000000000076,64.22668634928779,-0.13833766502260642,-2.5764780053819787
589.0000000000076,64.3265118857204,-0.13996067105146318,-2.5765013903106735
590.0000000000076,64.42533028543367,-0.1356789719004561,-2.5765294764156086
591.0000000000077,64.52553400387997,-0.1363849337922394,-2.579135574001336
592.0000000000077,64.62494627175934,-0.13354785977413874,-2.579466250276372
593.0000000000077,64.72525722299372,-0.13253248543241694,-2.581687847020574
594.0000000000077,64.82390633805578,-0.1310505366488214,-2.581769736189205
595.0000000000077,64.92364796031535,-0.13092436564453322,-2.5840089709461465
596.0000000000077,65.02382283438655,-0.1286319889845703,-2.5845131366181047
597.0000000000077,65.122037365437,-0.1300538590020699,-2.5845163518656067
598.0000000000077,65.22320351316282,-0.12707184343960712,-2.585753938291319
599.0000000000077,65.32318785253663,-0.1267364145359576,-2.587465283723165
600.0000000000078,65.42302668747037,-0.12319692194054188,-2.589989932088966
601.0000000000078,65.52188639326327,-0.12484236291933859,-2.5914612711647083
602.0000000000078,65.6226017724244,-0.12398660639373447,-2.591498608601663
603.0000000000078,65.72251659933433,-0.12349233542920782,-2.5927684352500195
604.0000000000078,65.82131657386658,-0.12357051173879467,-2.594059285944155
605.0000000000078,65.9208266964,-0.12225122174060604,-2.596688758185141
606.0000000000078,66.02074040340842,-0.12056080526455472,-2.597993971804761
607.000000000008,66.12016040759806,-0.1202874168903217,-2.598026888543645
608.000000000008,66.22007478974338,-0.120751578325822,-2.597995240603962
609.000000000008,66.32049534551706,-0.11900302187742437,-2.6007046203929143
610.000000000008,66.41937609200731,-0.11821250337605425,-2.6019600406673655
611.000000000008,66.52021665989443,-0.11903333377351001,-2.603282869115657
612.000000000008,66.61847103647237,-0.11616337911245506,-2.6046061778481073
613.000000000008,66.7177690321194,-0.1149123770994949,-2.604547735505105
614.000000000008,66.81783073148777,-0.11467345258432897,-2.6072527022439558
615.000000000008,66.91826579588586,-0.11173169685069025,-2.6078142222009886
616.0000000000081,67.0167899584044,-0.11026330296840595,-2.6079313625935012
617.0000000000081,67.11690414047949,-0.11033552211251835,-2.608736364302441
618.0000000000081,67.21831931598821,-0.10844314804990209,-2.6101326463501007
619.0000000000081,67.31861984907833,-0.1050179448144283,-2.612473177169733
620.0000000000081,67.41776184876225,-0.10337132971590356,-2.61304978557566
621.0000000000081,67.51683336115542,-0.10123066950270834,-2.6138208799690785
622.0000000000081,67.61760498052456,-0.0997701212716708,-2.6164523165448523
623.0000000000082,67.71725445690909,-0.09717391151110241,-2.6178249476010875
624.0000000000082,67.81725925702344,-0.09556686507315013,-2.6166620776341154
625.0000000000082,67.91737969139787,-0.0916994891445063,-2.618751003453143
626.0000000000082,68.0169557513557,-0.09036220391070027,-2.6190915776049097
627.0000000000082,68.11681945786427,-0.0880016241549677,-2.6204018631829706
628.0000000000082,68.2168242647295,-0.0845728497670643,-2.6230467688434604
629.0000000000082,68.31526491236421,-0.08376133997948794,-2.6230392377052363
630.0000000000082,68.41653206208358,-0.08052742716015594,-2.623291750903295
631.0000000000082,68.51591336067807,-0.07975931223988636,-2.6243601060658
632.0000000000083,68.61505274079825,-0.07585866538931163,-2.6256788344693716
633.0000000000083,68.71560561887827,-0.07141769990383427,-2.626975491233507
634.0000000000083,68.81593222009731,-0.06766238363602126,-2.6286109371641806
635.0000000000083,68.91452294847338,-0.06585082522178938,-2.629911945904031
636.0000000000083,69.01573249382118,-0.06452027155834054,-2.6299813038901383
637.0000000000083,69.11524569335023,-0.0634812805174466,-2.6325944561772676
638.0000000000083,69.2142563174842,-0.06427280265762228,-2.6322588429402565
639.0000000000084,69.31454563746165,-0.06633718613181262,-2.633249831204576
640.0000000000084,69.41423515517852,-0.0694241173380178,-2.6335737422774654
641.0000000000084,69.51411733509205,-0.07407964647805403,-2.6375463107746233
642.0000000000084,69.6142075586001,-0.07780541954978755,-2.637564437887339
643.0000000000084,69.71365574855423,-0.08395879809891235,-2.638859669853085
644.0000000000084,69.81277144501615,-0.0897195309928394,-2.640195683676901
645.0000000000084,69.91376376589423,-0.0937262006732936,-2.640826672435544