File: 01_Data/PU_Aerogel/STA/N2/30K_min/PU_Aerogel_STA_N2_30KData_231214_R2.csv
##Temp./Â°C,Time/min,DSC/(mW/mg),Mass loss/mg
51.0,10.433179422145813,-2.5149925305950043,0.011188908886780702
52.100000000000016,10.689150010662019,-2.4671891920617104,0.009695794646726874
53.20000000000003,10.826827986296802,-2.4355461996946914,0.008111106402079571
54.30000000000005,10.934460314397853,-2.4089287470161533,0.00931072894461682
55.40000000000006,11.022464975749514,-2.3889134602394355,0.009394863249439389
56.50000000000008,11.099531566582456,-2.367339791101041,0.007320395714526029
57.600000000000094,11.169080020609663,-2.3494186016537193,0.007679258699807789
58.70000000000011,11.234367772302074,-2.3312560982763326,0.007493245448346286
59.800000000000125,11.294286649474396,-2.3163301080686596,0.008817717408257764
60.90000000000014,11.352279397515838,-2.299391202668507,0.007824852966803242
62.000000000000156,11.406642534337207,-2.2849012744086354,0.008523230147208238
63.10000000000017,11.459202765550586,-2.268562546649986,0.00792776461887712
64.20000000000019,11.510334967058093,-2.253498504768516,0.006908996885782948
65.30000000000021,11.559211185344083,-2.2387185158306537,0.006588519121464742
66.40000000000022,11.607191946519723,-2.2255009300111124,0.007027920178487079
67.50000000000023,11.653403118208491,-2.2131239921012638,0.010485741406935922
68.60000000000025,11.699282226473468,-2.2022343645380538,0.00911929129128719
69.70000000000027,11.744167577111714,-2.1895301813229002,0.007981549358340168
70.80000000000028,11.788668646941062,-2.1763170597007937,0.008444147248717115
71.90000000000029,11.83222821937411,-2.1662559346044072,0.008908651932104661
73.00000000000031,11.8751341973927,-2.1571470128390358,0.00863185530251176
74.10000000000034,11.917333541341296,-2.144221206225337,0.007941104506813623
75.20000000000034,11.959192640668041,-2.1345074717680306,0.007576670817943665
76.30000000000035,12.000971144123517,-2.1232737860978634,0.007749759080462937
77.40000000000038,12.041730127746552,-2.1150312711300705,0.007364663422221973
78.5000000000004,12.081645921449248,-2.1044982402281227,0.007225441242363573
79.6000000000004,12.12155409964704,-2.094626352555155,0.007364700567022986
80.70000000000041,12.162222124689952,-2.0852630495630926,0.007243315255815119
81.80000000000044,12.201753512123602,-2.0779301851113536,0.008250413356161168
82.90000000000046,12.241323664115459,-2.066503217245454,0.008650478167733233
84.00000000000047,12.280392894151335,-2.058031269664747,0.006425757731634896
85.10000000000048,12.319478750896254,-2.0491066298557445,0.006169834106766636
86.2000000000005,12.35811493267026,-2.039483069924213,0.007291419697765811
87.30000000000052,12.396772425299673,-2.030821700551949,0.00728531376926167
88.40000000000053,12.434961889875872,-2.0220535230739913,0.008636448415233033
89.50000000000054,12.473675600321718,-2.0146072557887993,0.007374551220470593
90.60000000000056,12.511479435670706,-2.0040963080544083,0.006688112089587861
91.70000000000059,12.548051649216626,-1.9949234835385776,0.005987100740339812
92.8000000000006,12.585726599080052,-1.9850826326580804,0.005961247757442223
93.9000000000006,12.624197388690611,-1.9762000112094817,0.006785445653183508
95.00000000000063,12.661444436876966,-1.966885076104233,0.006138520380076784
96.10000000000065,12.69872116306769,-1.9579543410422937,0.006393524382488636
97.20000000000066,12.736487414715633,-1.948866292234044,0.007347755775862552
98.30000000000067,12.773463130544261,-1.9391226949241105,0.006136419020042361
99.40000000000069,12.81034281714219,-1.9306426797157652,0.006999123386166595
100.50000000000071,12.847388999041694,-1.9211105809093025,0.006483442405059492
101.60000000000072,12.884239232142487,-1.913858079143162,0.007380820807846078
102.70000000000073,12.92155262813011,-1.9046331570853667,0.007372528592370031
103.80000000000075,12.957843991030819,-1.8962355504374269,0.007348689837338718
104.90000000000077,12.994719926273802,-1.8882728573381402,0.007050656875440708
106.00000000000078,13.031748987344915,-1.881092835819232,0.007354037788182666
107.10000000000079,13.06848333715038,-1.870922977557918,0.006138313379001836
108.20000000000081,13.104811896789274,-1.8633373340978987,0.006044133576416755
109.30000000000084,13.141546388451005,-1.8559807535703179,0.005328667531241393
110.40000000000084,13.178304496456409,-1.8494995464915902,0.006024985932895355
111.50000000000085,13.215402523981494,-1.84099347610467,0.005845172159428813
112.60000000000088,13.252020491682126,-1.8359289093209825,0.004732215051446609
113.7000000000009,13.28869544586871,-1.8256050372275905,0.006023482144389192
114.8000000000009,13.324948275076128,-1.8201659781022306,0.006031665334097269
115.90000000000092,13.36179825473923,-1.8131653260559202,0.006159731431588433
117.00000000000094,13.398538612416978,-1.806866531147805,0.006001983775090203
118.10000000000096,13.435033083579551,-1.8004253231111318,0.006041624812942459
119.20000000000097,13.471315314212427,-1.792690985691937,0.006133512442784372
120.30000000000098,13.507652072265246,-1.786850500907733,0.007368340407901464
121.400000000001,13.543422698114423,-1.779752784782446,0.006054587895340191
122.50000000000102,13.579868276000786,-1.7722782762071554,0.006039835327100285
123.60000000000103,13.616415352447392,-1.766886050943573,0.006039990536637063
124.70000000000104,13.652331316928962,-1.7584710682691753,0.006039992995181542
125.80000000000106,13.688076293546006,-1.7540793900635105,0.006039993000169552
126.90000000000109,13.723636970738625,-1.7465662020431056,0.006039993010130473
128.00000000000108,13.76072651916956,-1.7395366195314281,0.006039994868750398
129.1000000000011,13.797168624592619,-1.735048070177104,0.0060399329638824995
130.20000000000113,13.832748313006672,-1.7292360115665493,0.006202325923011287
131.30000000000115,13.868679031662172,-1.7210485757608442,0.006038599737672179
132.40000000000117,13.904310544993576,-1.7178018478401829,0.006044915619697555
133.50000000000117,13.940226536018097,-1.711198328935411,0.005090210224286018
134.6000000000012,13.976086919102972,-1.7049267656122609,0.0047295120913801725
135.7000000000012,14.012088272246874,-1.6998505085505324,0.0047297015721792235
136.8000000000012,14.047373653396882,-1.6954282195255876,0.004742764393210308
137.90000000000123,14.082638354645743,-1.6896790411470368,0.006082152658214213
139.00000000000125,14.118568420483601,-1.682825767187182,0.006039718603327415
140.10000000000127,14.153768086423986,-1.6783308735090683,0.006039966243453598
141.2000000000013,14.189396824203858,-1.671906100065481,0.006039970749752932
142.3000000000013,14.22475276407129,-1.6684404849027117,0.0060399109467477174
143.4000000000013,14.260031257806741,-1.6626359472024694,0.006040107357597968
144.50000000000134,14.295137110119539,-1.6569232124187896,0.004952086141192247
145.60000000000133,14.330096550956014,-1.6509937211979764,0.0047203666468504935
146.70000000000135,14.365189886119733,-1.6458743084763086,0.004712741728663872
147.80000000000138,14.401099433074938,-1.6402514447821155,0.005795996257957903
148.9000000000014,14.43603165175745,-1.633389929174556,0.006040275929819039
150.00000000000142,14.47086195348883,-1.628843277676961,0.006035862224218036
151.10000000000142,14.505651014928532,-1.6227146480633066,0.004741523849936868
152.20000000000144,14.540420211003694,-1.6179910013470884,0.0047338989993557234
153.30000000000146,14.575699706120776,-1.6115675773140192,0.003905162307431098
154.40000000000146,14.610504778008432,-1.6075478581522076,0.004720131821658313
155.50000000000148,14.645666557805615,-1.6015424489346686,0.004720290123164439
156.6000000000015,14.680412951270638,-1.5965285506386127,0.004726027432581326
157.70000000000152,14.715201936567192,-1.5913536833191286,0.005433637585882778
158.80000000000155,14.750096395190727,-1.5857471282781954,0.005380423038842785
159.90000000000154,14.784430640728363,-1.5798325112343392,0.005380196015971173
161.00000000000156,14.81834846990375,-1.5739108174265592,0.00538027217478021
162.1000000000016,14.853608513863573,-1.5666484740810582,0.005292801381897583
163.20000000000158,14.88840124294444,-1.5643025933525692,0.0040582543405651705
164.3000000000016,14.923141018905943,-1.5580704474491953,0.004089956072265366
165.40000000000163,14.95796918098639,-1.5512423384156524,0.002717262978307211
166.50000000000165,14.993065484278427,-1.5484678101695577,0.002739671637845831
167.60000000000167,15.027512671775035,-1.5408019351411197,0.0027399738360411874
168.70000000000167,15.061943881085272,-1.5360769872834263,0.0027399710235638253
169.8000000000017,15.096359836631715,-1.5300663937373926,0.0027399710004321065
170.9000000000017,15.13114039271312,-1.525403229139987,0.0027399711326747678
172.0000000000017,15.165175911160835,-1.5208203134689047,0.0027399599019775067
173.10000000000173,15.199752385257247,-1.5127108183646998,0.002739112276249678
174.20000000000175,15.23439070375507,-1.5095290621886592,0.0017435684865940715
175.30000000000177,15.268589089324196,-1.5043687870064062,0.001423035625332858
176.4000000000018,15.302907733698742,-1.5008077288050707,0.0005082944608147955
177.5000000000018,15.337490564321255,-1.495679975428823,0.0011007358065695527
178.6000000000018,15.371473048133195,-1.4908245585396183,0.001113698894577908
179.70000000000184,15.405824752342744,-1.4849316659762208,-0.0002632624068228395
180.80000000000183,15.439937858964683,-1.4808621950613416,-0.0002199971919552013
181.90000000000185,15.47422781017787,-1.475927204205295,-0.00022000168637426043
183.00000000000188,15.508255155619532,-1.4726067909101745,-0.00022000703505131725
184.1000000000019,15.542312263082538,-1.468755523472605,-0.00022000682433898078
185.20000000000192,15.57631456495273,-1.4645219275571741,-0.00022001257337134206
186.30000000000192,15.610581578954038,-1.4616181815504596,-0.0002209301672042585
187.40000000000194,15.643563127359688,-1.458806123188691,-0.0001191457308573618
188.50000000000196,15.677886654516074,-1.4540720736010133,-0.0026877989234828092
189.60000000000196,15.711634594812951,-1.4504187485736357,-0.0028485797405153335
190.70000000000198,15.746206141812205,-1.4477438504972873,-0.002849415735927785
191.800000000002,15.780063034972024,-1.4442588072296276,-0.003185172149240856
192.90000000000202,15.814002612504318,-1.441973029304477,-0.004177344217607626
194.00000000000205,15.847727679954357,-1.437944636766974,-0.004169996440559487
195.10000000000204,15.881730552237943,-1.436393442180292,-0.004170063528553314
196.20000000000206,15.915543842369242,-1.4322860884193438,-0.004169457928258069
197.3000000000021,15.949596262551314,-1.4308394359539158,-0.004468481472907904
198.40000000000208,15.982999921463367,-1.4282622268662888,-0.005486414558283137
199.5000000000021,16.016936885280106,-1.4265815414844605,-0.005480692203583715
200.60000000000213,16.050700054502833,-1.426106045662538,-0.005504039681442308
201.70000000000215,16.084491293605502,-1.4235604554658292,-0.006785883937437731
202.80000000000217,16.118442700922976,-1.4228503760511453,-0.00680011935652125
203.90000000000217,16.15185391183194,-1.4207068587229486,-0.0068000892342006125
205.0000000000022,16.18554995517273,-1.4206728902864796,-0.0067929830717075035
206.1000000000022,16.219528877098853,-1.4211075561029634,-0.007747885646475439
207.2000000000022,16.253142244560628,-1.42151643935064,-0.00814681820270824
208.30000000000223,16.286640139067302,-1.4232024628640658,-0.009422251125869252
209.40000000000225,16.320641950762862,-1.4243005956102233,-0.009439969502634149
210.50000000000227,16.3544388255086,-1.427353136781205,-0.009495264437723527
211.6000000000023,16.388233787010126,-1.4303666023873014,-0.01075236136779445
212.7000000000023,16.421694379097286,-1.4338370011178605,-0.012107385530216064
213.8000000000023,16.455518124560182,-1.4416066705158284,-0.012069355619701128
214.90000000000234,16.48940670117576,-1.4483361811682323,-0.012067858242115648
216.00000000000233,16.523142291427355,-1.4552852908290783,-0.013261953424623663
217.10000000000235,16.556610854149184,-1.4666300251768518,-0.01329799372051177
218.20000000000238,16.58971082991611,-1.4778378318614218,-0.014823167361260658
219.3000000000024,16.624523146325977,-1.48956186652015,-0.01617696710172911
220.40000000000242,16.658008560243506,-1.5068230610045465,-0.016920533340102573
221.50000000000242,16.692350276744314,-1.5263199513659034,-0.017741178256884815
222.60000000000244,16.725268783666998,-1.546228398102087,-0.018871365302527643
223.70000000000246,16.759306364528314,-1.5708479179802386,-0.019810329529013515
224.80000000000246,16.793918176416,-1.599898380454027,-0.020961877933777018
225.90000000000248,16.827952255748578,-1.6306473495982412,-0.02240709123454021
227.0000000000025,16.861792834001747,-1.6668628121768947,-0.0235511495939571
228.10000000000252,16.896206723133545,-1.7072013037604206,-0.02470529024308732
229.20000000000255,16.930454281064534,-1.7519913171961576,-0.026607702149596513
230.30000000000254,16.964477413473507,-1.7996818169498154,-0.02871061071964842
231.40000000000256,16.998970935829348,-1.8509448198838547,-0.030610148473542154
232.5000000000026,17.0331261275286,-1.9036603967252366,-0.032135674715540574
233.60000000000258,17.06732478242266,-1.959824807076226,-0.03421109457561755
234.7000000000026,17.10125568705149,-2.019239100209839,-0.03729679925956075
235.80000000000263,17.136205183928247,-2.0779535340105064,-0.04005607633671637
236.90000000000265,17.170333454901545,-2.13344831969468,-0.04251181780364233
238.00000000000267,17.204885825356946,-2.189678585020175,-0.046149622975883986
239.10000000000267,17.239245726106223,-2.244009695129949,-0.04998258018010526
240.2000000000027,17.273311533769952,-2.2919191277317883,-0.05365088766108972
241.3000000000027,17.307344770429562,-2.3382998990861092,-0.057340913912396374
242.4000000000027,17.341449017352843,-2.378099678576313,-0.06072246540947113
243.50000000000273,17.375123124244954,-2.414983681194567,-0.06449230127598415
244.60000000000275,17.409199156903185,-2.4443927800281844,-0.06950376111231593
245.70000000000277,17.443406802224423,-2.469203130950269,-0.07429433685251796
246.8000000000028,17.477295690873458,-2.489965639411068,-0.07933709705483061
247.9000000000028,17.511192024082504,-2.5005757137428857,-0.08391683297049646
249.0000000000028,17.544682792115804,-2.511840276204743,-0.08935447175314737
250.10000000000284,17.57813433211448,-2.5205311060318336,-0.09628129100001948
251.20000000000283,17.611760209731326,-2.5234865438573677,-0.10247477830780793
252.30000000000285,17.64502226257431,-2.5257587341952057,-0.10851908506154517
253.40000000000288,17.678466982208803,-2.526272121468107,-0.11548610784535951
254.5000000000029,17.712120387717864,-2.5269551536285175,-0.121196056141613
255.60000000000292,17.745427939960408,-2.5248727378377396,-0.1282510823272207
256.7000000000029,17.778917989564384,-2.523425849820795,-0.13682208259042783
257.8000000000029,17.81207522956219,-2.523952455838578,-0.1461493723636651
258.90000000000293,17.845476854623996,-2.5242613762813657,-0.15487282152785253
260.00000000000296,17.87888682547399,-2.525885064326588,-0.16369147507377546
261.100000000003,17.912336512645766,-2.528703642245366,-0.17342541912526732
262.200000000003,17.94593493616295,-2.5326281436663645,-0.1829807021730936
263.300000000003,17.979163927773335,-2.536957549149229,-0.19339490924787972
264.40000000000305,18.01263756026819,-2.541845043593581,-0.20424528884908932
265.50000000000307,18.045979640273455,-2.548427303580248,-0.2153693943765509
266.6000000000031,18.07870347908094,-2.555100406071527,-0.2262451054131902
267.7000000000031,18.112655030235757,-2.5616948638778476,-0.2382597292133175
268.8000000000031,18.146185488325283,-2.566953129101517,-0.2510399673171757
269.9000000000031,18.179488189534325,-2.5732777096547217,-0.263721666912033
271.0000000000031,18.213063610212924,-2.5774450778327878,-0.2769096823259307
272.10000000000315,18.246478394865598,-2.581170291989751,-0.2909543586927037
273.2000000000032,18.27975304993955,-2.584556261149654,-0.3058373829290679
274.30000000000314,18.313068767235766,-2.5862916688174287,-0.3200673923139634
275.40000000000316,18.345777104253784,-2.586171778547183,-0.3357199984704846
276.5000000000032,18.379585466633692,-2.5837441993513712,-0.35309007241541446
277.6000000000032,18.41306975391357,-2.5784251436380172,-0.36844767869905404
278.70000000000323,18.445703630287962,-2.5718955883346575,-0.38440896137308656
279.80000000000325,18.479530301622614,-2.561851029208018,-0.4011171461292671
280.9000000000033,18.51258236582352,-2.549772411715429,-0.4191421131334452
282.0000000000033,18.54573908298315,-2.5367027578801182,-0.43803569953792953
283.1000000000033,18.579089269399677,-2.516374665102769,-0.45795927054865837
284.20000000000334,18.611761310582256,-2.498628643159231,-0.47655971898552973
285.30000000000337,18.645059925789283,-2.474588519270582,-0.4965068257870793
286.40000000000333,18.677790681144902,-2.447274810992162,-0.5161573050357329
287.50000000000335,18.71054351166326,-2.4190551898546375,-0.5357211010644405
288.6000000000034,18.74358135429752,-2.384428417787293,-0.5559904208917104
289.7000000000034,18.776457557370787,-2.3484709324078494,-0.5757009230476751
290.8000000000034,18.8093370943782,-2.3080365117206205,-0.5955715232388972
291.9000000000034,18.84212973019676,-2.2671927011701003,-0.6169316467021142
293.0000000000034,18.875022391555706,-2.2238894075528,-0.6369735914726773
294.10000000000343,18.907847204466613,-2.1783703333042794,-0.6575347321808764
295.20000000000346,18.94041343343269,-2.1296328551900023,-0.6779494057540263
296.3000000000035,18.97300901820663,-2.0813409346340106,-0.6982903602033854
297.4000000000035,19.005202566184877,-2.032689923723564,-0.7185314214574241
298.5000000000035,19.038465703209962,-1.9841620810839498,-0.7387819649121905
299.60000000000355,19.071204804527266,-1.9360654571554226,-0.7576866791871262
300.70000000000357,19.104148397358262,-1.88901120584192,-0.7755636936802213
301.8000000000036,19.136338137968536,-1.844667609858096,-0.7931286099575261
302.9000000000036,19.169489051223213,-1.8041557574061424,-0.8107569443581006
304.0000000000036,19.202131593584866,-1.7639746564570904,-0.8283837031814625
305.1000000000036,19.23525913540738,-1.7308516481192173,-0.8454745987896723
306.2000000000036,19.268040740361478,-1.7032568323808364,-0.8603272542394187
307.30000000000365,19.301070861609986,-1.6753991742183953,-0.8761466192914327
308.4000000000037,19.33414613275184,-1.6538250131796983,-0.8911873794869356
309.5000000000037,19.367197479547208,-1.6329283839469926,-0.9049757779115155
310.60000000000366,19.400602198583435,-1.6216225328802079,-0.9198080663544737
311.7000000000037,19.433433031014214,-1.6100001219618876,-0.9328300115164034
312.8000000000037,19.467243634300488,-1.6074283797104971,-0.9451277004790732
313.90000000000373,19.50005907687603,-1.6038773514007252,-0.9564499939084592
315.00000000000375,19.5334816186609,-1.605941287988494,-0.9680265699171233
316.1000000000038,19.566225465212497,-1.6097122429525634,-0.9792728273219873
317.2000000000038,19.60090229032415,-1.6166151861238072,-0.991223117720661
318.3000000000038,19.63416813111793,-1.6247662839951929,-1.001948458394247
319.40000000000384,19.66757159729905,-1.6333206357511658,-1.0114627820465665
320.5000000000038,19.701342828308647,-1.6450573679961968,-1.0210579537937048
321.60000000000383,19.734962560922323,-1.6567473979403136,-1.0320461948280402
322.70000000000385,19.768259575579833,-1.6681774201887443,-1.0426399546921625
323.8000000000039,19.80207696730982,-1.6804726697506902,-1.0520387167251783
324.9000000000039,19.835042834405172,-1.6920818944814522,-1.0606804001697379
326.0000000000039,19.869339488807412,-1.7048061813330697,-1.0691864816548606
327.10000000000394,19.902599223214022,-1.7161167278676472,-1.0785740451523544
328.2000000000039,19.936746804599547,-1.7245274600416545,-1.0884380313112971
329.30000000000393,19.969849388595016,-1.7373156628322275,-1.0980157957872372
330.40000000000396,20.004142418773217,-1.7437012195182098,-1.1078192158021332
331.500000000004,20.037659956061663,-1.7534211759983749,-1.1174607510174188
332.600000000004,20.07155136273614,-1.7606598308766566,-1.1267186867153671
333.700000000004,20.10526685782246,-1.7655792527287972,-1.1364270742887825
334.80000000000405,20.138902462917766,-1.7680187982316637,-1.1459402233789162
335.90000000000407,20.17230152946191,-1.7695710621702734,-1.156302072315055
337.0000000000041,20.20626148824905,-1.7699332905096823,-1.1668721888344757
338.10000000000406,20.239579497458834,-1.7677151176888792,-1.1765318618368994
339.2000000000041,20.273324945378594,-1.761331564624297,-1.1864537769951085
340.3000000000041,20.30706642199984,-1.7530866792753756,-1.1955205341471027
341.4000000000041,20.340541853461648,-1.745209286795544,-1.2056933958149116
342.50000000000415,20.37414793415097,-1.7338336485104726,-1.2156691684604746
343.6000000000042,20.40790800511312,-1.7196616149331763,-1.2256984627275567
344.7000000000042,20.44117404346782,-1.7049828804104743,-1.2356127112709783
345.80000000000416,20.474869649975787,-1.6877569985436387,-1.245587449616306
346.9000000000042,20.508508230194675,-1.669938195008084,-1.2562970727294664
348.0000000000042,20.54163683358822,-1.6480732865856036,-1.26654543740817
349.10000000000423,20.575061967645055,-1.620661756695236,-1.2763362160336231
350.20000000000425,20.60854623662177,-1.5914460869639415,-1.2861675453845116
351.3000000000043,20.64172867646401,-1.55966443724656,-1.2953492963038538
352.4000000000043,20.67541728251456,-1.5275195173359501,-1.304245403660984
353.5000000000043,20.708851194670693,-1.4952729329210368,-1.3134996228171416
354.60000000000434,20.742153468684883,-1.4599017523439581,-1.3231667302319865
355.7000000000043,20.77573079187576,-1.429705567290002,-1.3324535792968333
356.80000000000433,20.8091096594544,-1.397885695391342,-1.3417887238090498
357.90000000000435,20.842548732946195,-1.3706659807509687,-1.3513810018252888
359.0000000000044,20.87616758271991,-1.3415169249556809,-1.3610587096976672
360.1000000000044,20.909415690976473,-1.315836322168954,-1.3700338024092305
361.2000000000044,20.94337949553391,-1.291555088831715,-1.37876361364027
362.30000000000445,20.976706246999534,-1.2651150990089455,-1.3879446803427173
363.4000000000044,21.010855774018488,-1.240296405097996,-1.3976236772609671
364.50000000000443,21.044222143828552,-1.2186487410596802,-1.4074703524147627
365.60000000000446,21.07804947969465,-1.196343916436973,-1.4169752182262227
366.7000000000045,21.111815190395095,-1.1731581098133004,-1.4253624794384363
367.8000000000045,21.144854114927668,-1.1521827723438531,-1.4346222439268477
368.9000000000045,21.178968968723133,-1.1292891729609749,-1.4452089693075743
370.00000000000455,21.21194557694275,-1.1063489377051081,-1.4548515055204572
371.10000000000457,21.245959004332807,-1.0827940428676648,-1.4640042816861785
372.2000000000046,21.279968396346256,-1.05805285152182,-1.4738472466516788
373.30000000000456,21.313510250564043,-1.034622154048541,-1.4829685057677104
374.4000000000046,21.347256742623188,-1.0092632153878593,-1.4912377074339518
375.5000000000046,21.38111503642942,-0.9844193788772516,-1.5003822540072713
376.6000000000046,21.41491180642799,-0.9586252758081187,-1.5098388044173987
377.70000000000465,21.448775414732694,-0.9342700870628757,-1.518285998577226
378.8000000000047,21.482558391646403,-0.9085782731478337,-1.5274749480306977
379.9000000000047,21.515782529427533,-0.8829734446114119,-1.5348085729701775
381.00000000000466,21.549937264903544,-0.8574401790757076,-1.5428792908774884
382.1000000000047,21.58375912101637,-0.8329886250798714,-1.5512794504930048
383.2000000000047,21.61748197286623,-0.8088839114681841,-1.5576027989927028
384.30000000000473,21.651537416053152,-0.7828762103937468,-1.5656065364837075
385.40000000000475,21.685427886899074,-0.7593640579982849,-1.5740011519586083
386.5000000000048,21.71916785772612,-0.7377442244916952,-1.5810206000134563
387.6000000000048,21.753209039049736,-0.7120749829590862,-1.588635589657382
388.7000000000048,21.787067279209275,-0.6907649555630029,-1.5963061891138124
389.80000000000484,21.820690207279227,-0.6697232448768663,-1.6041317455689184
390.9000000000048,21.85503759820759,-0.6489587154984088,-1.611512684036478
392.00000000000483,21.888820593761253,-0.6287117627816696,-1.6181441694481764
393.10000000000485,21.922858220387326,-0.6099576558263933,-1.6251477230937201
394.2000000000049,21.95702838817335,-0.5913504257468153,-1.6323197190404768
395.3000000000049,21.990853200726043,-0.5734354952766625,-1.6367601103496936
396.4000000000049,22.025028512283736,-0.5550984609927228,-1.6442096148709369
397.50000000000495,22.0589860346229,-0.5389259739672041,-1.6509297813675015
398.6000000000049,22.093418489632416,-0.5211687374460054,-1.6580550261089648
399.70000000000493,22.12741209990651,-0.5044526413973484,-1.6657640336675197
400.80000000000496,22.161659961402655,-0.4907167957265301,-1.6720414650190034
401.900000000005,22.195669691380616,-0.47571703453213254,-1.6783771256488884
403.000000000005,22.22972452858335,-0.4658269106829925,-1.6845704153543704
404.100000000005,22.264141718038328,-0.4500820186362956,-1.69099745365749
405.20000000000505,22.29843561162421,-0.43679886841499505,-1.6985325811205598
406.30000000000507,22.33271560452354,-0.42501622696268654,-1.7057452886927558
407.4000000000051,22.36684973943758,-0.4145026528184849,-1.7123779403717325
408.50000000000506,22.401287239158243,-0.4052381743202548,-1.7191674228467884
409.6000000000051,22.435164638964174,-0.39896427471326934,-1.7261890493009333
410.7000000000051,22.46987931955465,-0.3918120225936593,-1.7325740665345264
411.8000000000051,22.50420803392908,-0.38910200772099923,-1.7391476791251121
412.90000000000515,22.538822178300908,-0.3824036542294016,-1.7458329013958318
414.0000000000052,22.573295902185833,-0.3815797487665872,-1.7536014033230924
415.1000000000052,22.607970188561758,-0.3808620403789902,-1.7604633082349563
416.20000000000516,22.642180619349407,-0.3814084234774045,-1.7677520246831113
417.3000000000052,22.676916223423312,-0.38392581742122067,-1.7755019212659224
418.4000000000052,22.71161086562153,-0.38797805964428067,-1.7825798845640617
419.50000000000523,22.746013714700748,-0.3927686236558575,-1.7905755138367323
420.60000000000525,22.780160316627935,-0.400025678166498,-1.7987256717588855
421.7000000000053,22.815370412239318,-0.4116418696596051,-1.8059952097277483
422.8000000000053,22.85009669924659,-0.4220536827354116,-1.8125438773057025
423.9000000000053,22.884680048356763,-0.43195668990717495,-1.8204323643528069
425.00000000000534,22.919967421993675,-0.4458175929254065,-1.8282147474035155
426.1000000000053,22.954458508034566,-0.4593970057026972,-1.8360223459884035
427.20000000000533,22.989362914067748,-0.47503720004249483,-1.8440955451230514
428.30000000000535,23.024284831488234,-0.4884190652427229,-1.8520688919166264
429.4000000000054,23.059191279249667,-0.5039592900058211,-1.8592544358397123
430.5000000000054,23.094055478943833,-0.5166414912337831,-1.866321285781345
431.6000000000054,23.12871428472334,-0.534923784578629,-1.8749784265470462
432.70000000000545,23.163786666634653,-0.5488264216776008,-1.882206562859634
433.8000000000054,23.19851526333269,-0.5653912743493766,-1.8893176206302358
434.90000000000543,23.233695981457835,-0.5778889633931265,-1.8976011078917536
436.00000000000546,23.268671192140975,-0.5920171941763962,-1.9039917269058022
437.1000000000055,23.302976699927964,-0.6057800266801456,-1.912087433611509
438.2000000000055,23.337900512638438,-0.6197105744219777,-1.9185481979783483
439.3000000000055,23.373444099931135,-0.6317528194866463,-1.9273977199706311
440.40000000000555,23.40849928758011,-0.6438929578245981,-1.9349183154310374
441.50000000000557,23.442866678703393,-0.6562654438600948,-1.9425333921915522
442.6000000000056,23.47819343853666,-0.6646766887091382,-1.9500697038138477
443.70000000000556,23.513344621866896,-0.6752164564685513,-1.9572592454238316
444.8000000000056,23.548390101509227,-0.6866530105534068,-1.9651221916019068
445.9000000000056,23.583349368966903,-0.6924701056626771,-1.9714940311748834
447.0000000000056,23.618143140359436,-0.7022311359170412,-1.9794125696757634
448.10000000000565,23.653428415861754,-0.7080350882645924,-1.9886032114312813
449.2000000000057,23.688621160313744,-0.7155311616247124,-1.9958934910911972
450.3000000000057,23.723535538401237,-0.7230514881671343,-2.0036629520769007
451.40000000000566,23.75845063354855,-0.7271392648142617,-2.0109433387049807
452.5000000000057,23.79331287398657,-0.7334956019680707,-2.0179331354785943
453.6000000000057,23.82833738197759,-0.7375787255986874,-2.0262892259902903
454.70000000000573,23.863432616144692,-0.7430974631561421,-2.033901642010375
455.80000000000575,23.898386243863712,-0.7468620848635319,-2.04159903412568
456.9000000000058,23.933359793375434,-0.7513214317047101,-2.048942323688517
458.0000000000058,23.967598193873986,-0.7557810591766576,-2.0560505260194137
459.1000000000058,24.003314299874855,-0.7601109152326166,-2.0642003491419194
460.20000000000584,24.038249049897882,-0.7617090666291872,-2.0727314371719388
461.3000000000058,24.073233774697428,-0.7654645264298293,-2.078873406401031
462.40000000000583,24.10862066305414,-0.7679964729121833,-2.086751126243792
463.50000000000585,24.14355142194796,-0.7708706957846396,-2.0933492393764226
464.6000000000059,24.178586562599783,-0.7740484980901722,-2.1008844604922947
465.7000000000059,24.213482490785523,-0.7754112735216243,-2.108289049058374
466.8000000000059,24.248540022882256,-0.7770038966797724,-2.115207230983568
467.90000000000595,24.283410790314928,-0.7798181568469141,-2.1226369144476473
469.0000000000059,24.31871523720244,-0.7810897658762492,-2.1306581533151236
470.10000000000593,24.353506270717464,-0.7822649475445084,-2.1373594287182995
471.20000000000596,24.38860000889415,-0.7844574879851172,-2.144582117435573
472.300000000006,24.423869356677315,-0.7849673736963302,-2.1514273982986176
473.400000000006,24.458880930773354,-0.7858567209562017,-2.1579593606955174
474.500000000006,24.494080139276633,-0.7852313364868908,-2.165854141499122
475.60000000000605,24.529099798141328,-0.7866706631434226,-2.172787413558545
476.70000000000607,24.563946476397465,-0.7857895292408917,-2.182161508863001
477.8000000000061,24.59911441232699,-0.7854863509794211,-2.1889543737182855
478.90000000000606,24.634580839540405,-0.7868310074494057,-2.19603096631693
480.0000000000061,24.669493076393408,-0.786927454032472,-2.203263477038478
481.1000000000061,24.70494995524992,-0.7859613843440907,-2.209983302390482
482.2000000000061,24.739968983750064,-0.7857507265366963,-2.216304465449703
483.30000000000615,24.7751705088134,-0.7857096762236757,-2.2223494742917205
484.4000000000062,24.810031877659945,-0.7850209954047283,-2.229598410476246
485.5000000000062,24.845270548108644,-0.78398777535981,-2.2376414803515257
486.60000000000616,24.880347401803036,-0.7824779750083999,-2.2443981663978443
487.7000000000062,24.915554781676143,-0.7810557570814269,-2.2507584149772146
488.8000000000062,24.950642000266896,-0.7801937085742887,-2.2566931129999706
489.90000000000623,24.98593961942855,-0.7788489873567565,-2.2645727246779828
491.00000000000625,25.021166280867387,-0.7801723691074343,-2.271132491623944
492.1000000000063,25.056339668145217,-0.7779005752589887,-2.2774076675291983
493.2000000000063,25.091660561465048,-0.778695675047583,-2.2854718837426815
494.3000000000063,25.126805691353873,-0.775703145062903,-2.2925541883965117
495.40000000000634,25.161580919451588,-0.7756008531339756,-2.2975376451234104
496.5000000000063,25.197352445130193,-0.7731816223455965,-2.3050557288420412
497.60000000000633,25.232652919106187,-0.7728289031530423,-2.3126458168527053
498.70000000000636,25.26767558790193,-0.7726498914054731,-2.319651434080825
499.8000000000064,25.30307438377643,-0.77219101276803,-2.325401912646432
500.9000000000064,25.338414353210254,-0.771212713461255,-2.3313205710802047
502.0000000000064,25.373777064226154,-0.7688157937757278,-2.3395102243799615
503.10000000000645,25.408912609981428,-0.7672917968070078,-2.3463619514320335
504.2000000000064,25.444355652854064,-0.7652706539524428,-2.353081103845124
505.30000000000643,25.479867620882295,-0.7642410124403635,-2.359879441302666
506.40000000000646,25.51492686926303,-0.7630812689793112,-2.3680909232245586
507.5000000000065,25.550321677728938,-0.7605433013425409,-2.3755441479179558
508.6000000000065,25.585284568443917,-0.759386800678229,-2.3819585168102924
509.7000000000065,25.620496922925945,-0.7568510569596998,-2.3895426748397206
510.80000000000655,25.65537515838013,-0.7553306375622802,-2.395894945389073
511.90000000000657,25.691379747267675,-0.7541153277876703,-2.4026135408082068
513.0000000000066,25.726898160920136,-0.7527830252786337,-2.4099819093976746
514.1000000000065,25.762052858710433,-0.7509236307282728,-2.4176621919359684
515.2000000000066,25.79771264298825,-0.7494784941552325,-2.4245924261115643
516.3000000000065,25.83311192522893,-0.7485459680198364,-2.4319774192906918
517.4000000000067,25.868114509750445,-0.7468240471336776,-2.4393147139539675
518.5000000000066,25.903481041741355,-0.746451642006118,-2.4465089563570004
519.6000000000067,25.939610699212235,-0.7449791342383536,-2.454159490189413
520.7000000000066,25.97530096154831,-0.7430701872778388,-2.4624152150183582
521.8000000000067,26.010959626410674,-0.7392556893296078,-2.469165339067299
522.9000000000067,26.046437748530924,-0.7394072669648069,-2.4750520972440007
524.0000000000067,26.082019153871375,-0.7368894837725009,-2.483136406053184
525.1000000000067,26.117433939591837,-0.7353996071156693,-2.489689382285672
526.2000000000068,26.152876938688156,-0.7340531930977492,-2.4973310975382796
527.3000000000068,26.188531314519324,-0.7322437061362358,-2.504941616433131
528.4000000000068,26.22395702097028,-0.7300344551562657,-2.5120817986110175
529.5000000000068,26.259647780698185,-0.7308410351804508,-2.518695900312436
530.6000000000068,26.29533679682127,-0.7290404828238819,-2.525374565223319
531.7000000000069,26.3307001506005,-0.7283482647041843,-2.5326039439393404
532.8000000000068,26.366479277168402,-0.7260919295250292,-2.5389312785908333
533.9000000000069,26.40124491863604,-0.7251507159995536,-2.5460377118695767
535.0000000000068,26.43743580901668,-0.7243930213453901,-2.5523802944165523
536.100000000007,26.47336969560967,-0.723871302222376,-2.560913166576318
537.2000000000069,26.508914131973107,-0.7229552194241334,-2.5678848181294582
538.300000000007,26.54459971542039,-0.7221742471966692,-2.574171596490979
539.4000000000069,26.580128353566973,-0.7226181077403878,-2.5811470695512466
540.5000000000069,26.61598945640698,-0.7225625761546012,-2.5850003008307825
541.600000000007,26.65168723874506,-0.72168171975887,-2.590804091030966
542.700000000007,26.68736209317214,-0.7219013182409078,-2.5974381076496655
543.800000000007,26.72303444860073,-0.72086083324363,-2.6037071891611117
544.900000000007,26.75875033806091,-0.7208360601291041,-2.6102314445216157
546.000000000007,26.79469333670771,-0.7198718934824977,-2.615907947262106
547.1000000000071,26.830223806605048,-0.7205389387361673,-2.622759563966021
548.2000000000071,26.866139480003838,-0.7206239685909623,-2.628556939316134
549.300000000007,26.9020709506466,-0.7204014596496121,-2.634736176013387
550.4000000000071,26.937795516611448,-0.7217592106708302,-2.6396619029253405
551.500000000007,26.97342064520316,-0.7218114845720078,-2.6452070859735106
552.6000000000072,27.009349504041516,-0.7226165277387928,-2.651514676060995
553.7000000000071,27.045215844366947,-0.7223483347220108,-2.656326527060739
554.8000000000072,27.080294488621284,-0.7213471556305159,-2.661413554032011
555.9000000000071,27.117145362821198,-0.7227376897204489,-2.665932848213017
557.0000000000072,27.152650654133954,-0.72163789708431,-2.6715145350555334
558.1000000000072,27.18846810066541,-0.719836802724223,-2.675529313543442
559.2000000000072,27.22455405783964,-0.7208554490530986,-2.6802600841282085
560.3000000000072,27.260126557140943,-0.7191737394020997,-2.6855289049447677
561.4000000000073,27.295985512635045,-0.7192373772018896,-2.6908454598822162
562.5000000000073,27.331385699285935,-0.7180662925446576,-2.6950596992676266
563.6000000000073,27.367685533455646,-0.7181418136707081,-2.6989308846716042
564.7000000000073,27.40371437278141,-0.717770285018075,-2.7026469763017382
565.8000000000073,27.439706382883543,-0.7155428759701477,-2.7074588645205155
566.9000000000074,27.47535989992783,-0.7146610114610844,-2.7115856035358394
568.0000000000074,27.511493197525606,-0.7150816191702191,-2.7141976048552143
569.1000000000074,27.54707334580897,-0.7138541684037246,-2.7177560702773174
570.2000000000073,27.583191682511746,-0.7128434260443149,-2.7225435536476716
571.3000000000073,27.619047914829913,-0.7126119802291186,-2.7265825840530775
572.4000000000074,27.654991698432536,-0.7123369763900821,-2.7303643664906456
573.5000000000074,27.691094283526812,-0.7118719390738683,-2.733021046098064
574.6000000000074,27.72690311880337,-0.7115286591764773,-2.7367530996505085
575.7000000000074,27.762732862703004,-0.7114604318014275,-2.7412552215438515
576.8000000000075,27.798688569565137,-0.7106598008889813,-2.7454703648037144
577.9000000000075,27.83486716776927,-0.7098718004417501,-2.749014058758399
579.0000000000075,27.87087206835303,-0.7102294748165238,-2.7513409179959956
580.1000000000075,27.906954495921063,-0.7083254557103198,-2.755057920785232
581.2000000000075,27.942786068573586,-0.707357808428931,-2.7572571282779075
582.3000000000076,27.97870322666991,-0.7064782608376515,-2.760385503104702
583.4000000000076,28.01479325807259,-0.7058490341597741,-2.764479482866473
584.5000000000076,28.05076818740861,-0.706746719930125,-2.7685491212994484
585.6000000000076,28.087164998870264,-0.7043047629130138,-2.771140452281368
586.7000000000077,28.123092741085497,-0.706191577146525,-2.773510656493717
587.8000000000077,28.158977421051578,-0.7040699661392533,-2.777077072406526
588.9000000000076,28.194842046633863,-0.7049579091247076,-2.780256649981723
590.0000000000076,28.2305343056131,-0.7057902773646473,-2.782893880619638
591.1000000000076,28.267047103220857,-0.7038170623709069,-2.7845432943230572
592.2000000000077,28.303218377347548,-0.7052922774611075,-2.7875969262628795
593.3000000000077,28.339253477245702,-0.7057970851647616,-2.7899574338066957
594.4000000000077,28.375360663305322,-0.7060030701347065,-2.793332027085447
595.5000000000077,28.411336156919955,-0.7064919473412578,-2.7958738899738296
596.6000000000078,28.44742542849871,-0.7061386278338476,-2.7983526318130343
597.7000000000078,28.48370818796956,-0.7079215612551797,-2.8002364507668642
598.8000000000078,28.519735189876943,-0.7081206205150817,-2.8036191701450885
599.9000000000078,28.555692059162343,-0.708709715934753,-2.807297746128243
601.0000000000078,28.59187565999665,-0.7102504096146777,-2.808960181729095
602.1000000000079,28.628066128224354,-0.7120896071745245,-2.81060257288797
603.2000000000079,28.664149983140327,-0.7125679790214837,-2.812438854693438
604.3000000000079,28.700332620579537,-0.712811103614317,-2.815204812461644
605.4000000000078,28.7364725697824,-0.7177728157586246,-2.817233193062317
606.5000000000078,28.772424200742055,-0.7176635381301739,-2.818321534242405
607.6000000000079,28.808905010759865,-0.7196900866675877,-2.8207451459169546
608.7000000000079,28.8449120715681,-0.721917099520043,-2.8232697668620483
609.8000000000079,28.881154498961195,-0.7231785271303856,-2.8256540160981416
610.9000000000079,28.91744408789791,-0.7250859897108111,-2.8276403438107804
612.000000000008,28.953665478270654,-0.7287449523619992,-2.830303449051396
613.100000000008,28.98966787943578,-0.7309602820797932,-2.8319820863897016
614.200000000008,29.026060954587027,-0.7335400956383933,-2.8334276094540654
615.300000000008,29.06201001181756,-0.7358760723446679,-2.8356470267390987
616.400000000008,29.09853337471973,-0.7404353290136574,-2.838018991948805
617.5000000000081,29.13492310938541,-0.7422083798195663,-2.838138714654976
618.6000000000081,29.17094876505868,-0.7448968394043712,-2.8405297258933873
619.7000000000081,29.20710487570105,-0.7490642279772544,-2.842671632516022
620.8000000000081,29.24347128474492,-0.7540699889551682,-2.844497344755263
621.9000000000082,29.27983306431753,-0.7559465087553612,-2.84591872617003
623.0000000000082,29.315969478935447,-0.7603448008272553,-2.8472419277672127
624.1000000000081,29.352345397971874,-0.7641714569885452,-2.8486700728445786
625.2000000000081,29.388601982241706,-0.7670246118021107,-2.8500795478942655
626.3000000000081,29.42482400565788,-0.7708078820091783,-2.851444075412715
627.4000000000082,29.461198056466863,-0.7737185751609558,-2.8518492472692
628.5000000000082,29.497500696453752,-0.7775234033250092,-2.8528376391780412
629.6000000000082,29.533679067096624,-0.7826853247393759,-2.853604986901589
630.7000000000082,29.57020105790719,-0.7860644780698791,-2.8541500286506776
631.8000000000083,29.60637437598495,-0.7896556833552283,-2.8554765223794707
632.9000000000083,29.642804172493094,-0.7948888027837244,-2.856796652085066
634.0000000000083,29.678966224999527,-0.8007292715440736,-2.857343894495215
635.1000000000083,29.715370036513832,-0.8035708179704666,-2.8599636683102334
636.2000000000083,29.751720756146938,-0.8095248625203173,-2.8605002743729826
637.3000000000084,29.788080200702712,-0.8135043538317197,-2.861867725030958
638.4000000000084,29.82451576829376,-0.8172024807209296,-2.863465577891513
639.5000000000084,29.860905474518216,-0.8207115100476322,-2.864714500401092
640.6000000000083,29.897330586886255,-0.8268795175023935,-2.8646453928091935
641.7000000000083,29.933519539657382,-0.8311782768275839,-2.865997845911744
642.8000000000084,29.970196627233303,-0.8347610036564242,-2.8673409135478822
643.9000000000084,30.00674230335105,-0.8413395614002512,-2.867234394224484
645.0000000000084,30.0427913266845,-0.8442458053459307,-2.8673462539589845
646.1000000000084,30.079330428806514,-0.8489441398841565,-2.8686170606125705
647.2000000000085,30.115708379342625,-0.8534269403669198,-2.8687203168400233
648.3000000000085,30.152168001455127,-0.8575405938407488,-2.8699632119254996
649.4000000000085,30.188827843677807,-0.8627255715466372,-2.871298016136085
650.5000000000085,30.224995226212666,-0.8666258450452944,-2.872168083259387
651.6000000000085,30.26133753258661,-0.8724903453366172,-2.87394198485522
652.7000000000086,30.297654179246663,-0.8787989217838724,-2.873920495720917
653.8000000000086,30.333493895249248,-0.8851895262733861,-2.8752606199853723
654.9000000000086,30.370064475191594,-0.8908372561075244,-2.874270462666103
656.0000000000086,30.406378515522224,-0.8958275851981735,-2.8755431099936786
657.1000000000087,30.44273337902246,-0.9005718300058404,-2.876461792559492
658.2000000000087,30.4798366026547,-0.9080614206283858,-2.8765500692532653
659.3000000000086,30.51584506579035,-0.9125255093607512,-2.877838160656732
660.4000000000086,30.55261605696478,-0.9168414109742751,-2.877833500171881
661.5000000000086,30.589092399646493,-0.9215938478640434,-2.8791890803678117
662.6000000000087,30.62540253402598,-0.926758651886274,-2.8791737263645114
663.7000000000087,30.661642411024012,-0.9325211549144207,-2.8803016663548586
664.8000000000087,30.698546197339564,-0.9374569902880434,-2.8805156490871617
665.9000000000087,30.73466539295699,-0.942017431615105,-2.881817179480644
667.0000000000088,30.771337125783003,-0.9461765834857924,-2.8818134482759463
668.1000000000088,30.807765605890243,-0.9526103998454828,-2.883040623914665
669.2000000000088,30.84397291531716,-0.958537056837358,-2.88348272979041
670.3000000000088,30.88017431206368,-0.965433849993136,-2.884125870299597
671.4000000000088,30.916775701652284,-0.9717019878893027,-2.884243731588512
672.5000000000089,30.953544460457092,-0.9759260004146898,-2.8854578184637187
673.6000000000089,30.98993369827735,-0.9809385373414596,-2.8867480445541487
674.7000000000089,31.026582856696475,-0.988316865462801,-2.887128702976076
675.8000000000088,31.063113032653174,-0.994081117057666,-2.8880436352593644
676.9000000000088,31.099436547109597,-1.0009920120041294,-2.8893938325771433
678.0000000000089,31.136053065853613,-1.0054015009066464,-2.8892212316508044
679.1000000000089,31.172351122484653,-1.009121282027755,-2.888411616349666
680.2000000000089,31.208820772517342,-1.014298472595146,-2.889714155392936
681.3000000000089,31.245241470329248,-1.019449672632443,-2.890207481947858
682.400000000009,31.281812371689565,-1.022304302976598,-2.89102811339615
683.500000000009,31.318184450342756,-1.0297039362332872,-2.891852189140321
684.600000000009,31.354879961993955,-1.034135944447573,-2.8923518117491267
685.700000000009,31.391205626635262,-1.0386649279855162,-2.893723102555939
686.800000000009,31.42772252950331,-1.0447668093253302,-2.8936686831181087
687.9000000000091,31.464438236478127,-1.050074641017996,-2.894464499844658
689.0000000000091,31.500965782604787,-1.0557238505652407,-2.895022656116674
690.1000000000091,31.53758923895083,-1.0620665207243078,-2.8962930383415744
691.2000000000091,31.57397914747458,-1.0651331286803336,-2.8975859423019754
692.3000000000092,31.610795350531145,-1.071893201155716,-2.8983462031967417
693.4000000000092,31.647457058345438,-1.0779739189202175,-2.898941543415118
694.5000000000091,31.683962077126687,-1.0829165372154226,-2.8988602544423743
695.6000000000091,31.720573493284487,-1.0872087117707168,-2.9002595210536324
696.7000000000091,31.756958110800827,-1.0949116716462777,-2.900259944346945
697.8000000000092,31.79375644424395,-1.099278325167429,-2.900254298614459
698.9000000000092,31.830402089057714,-1.1038993050301906,-2.9015646677770244
700.0000000000092,31.86686332760472,-1.1095491806703033,-2.9013699922703515
701.1000000000092,31.9035251401546,-1.1143578819832147,-2.9004075476506874
702.2000000000093,31.940169059147497,-1.116829960898343,-2.9015703276318114
703.3000000000093,31.976744485481955,-1.1201580313115767,-2.9014678767766586
704.4000000000093,32.01351778536586,-1.1272512916339634,-2.9028896290819186
705.5000000000093,32.05013366780477,-1.1293218432657732,-2.904217098050653
706.6000000000093,32.08694295437163,-1.1331439573440425,-2.904235054626958
707.7000000000094,32.12363354055767,-1.1369304976955612,-2.904436612579654
708.8000000000094,32.16020211175046,-1.1399568332668168,-2.9055369053152824
709.9000000000094,32.19680755201366,-1.1443384315485443,-2.9055567224975736
711.0000000000093,32.233713206628416,-1.1495386714875833,-2.906855100078727
712.1000000000093,32.27033485731941,-1.1542133972147146,-2.906850205679531
713.2000000000094,32.307267771148005,-1.1573777527755573,-2.906850199465962
714.3000000000094,32.343551484252025,-1.1592372477247115,-2.9068500045027004
715.4000000000094,32.38042710912097,-1.1603795665238978,-2.9068462302032505
716.5000000000094,32.417202479712635,-1.1630192600958063,-2.9081843622480603
717.6000000000095,32.454023489617434,-1.1665094947923151,-2.9091475996205034
718.7000000000095,32.49035638499256,-1.1684319500628089,-2.90949927673453
719.8000000000095,32.52668568285281,-1.171730859036443,-2.9108135852674413
720.9000000000095,32.563814667625806,-1.1738832917674509,-2.9121665120791853
722.0000000000095,32.600746478907126,-1.1744935899629194,-2.9128474245674987
723.1000000000096,32.63770410464993,-1.177141860451049,-2.9137176613155757
724.2000000000096,32.674564065096575,-1.1790617900555842,-2.914896407239867
725.3000000000096,32.71135681674964,-1.1820806511441264,-2.9135539905878827
726.4000000000096,32.748006399726805,-1.1821563660899417,-2.9135488745601865
727.5000000000097,32.7851291326154,-1.183256008426052,-2.9158309226303585
728.6000000000097,32.82228095951808,-1.1851798755932632,-2.916136625155332
729.7000000000096,32.85917779279353,-1.1865451331964876,-2.917500835038801
730.8000000000096,32.896024562436295,-1.1864131043813542,-2.9182056705050172
731.9000000000096,32.932494036296184,-1.1860700021766906,-2.9177944132959106
733.0000000000097,32.969766100198626,-1.1843131082181628,-2.9189188621792965
734.1000000000097,33.00645464325929,-1.185738566016906,-2.920205234529949
735.2000000000097,33.04382722913925,-1.1830521067967923,-2.9202399569956006
736.3000000000097,33.07990418003687,-1.1809369923363686,-2.920240077208415
737.4000000000098,33.11683720953447,-1.1794243123772612,-2.9213019392808928
738.5000000000098,33.15474455236813,-1.1782041915752004,-2.9216203083980155
739.6000000000098,33.19162550407449,-1.1766872490589815,-2.9228748048399793
740.7000000000098,33.22856168270152,-1.1729722096486115,-2.9228876053743176
741.8000000000098,33.265537100145814,-1.1717144788038005,-2.9242104232698276
742.9000000000099,33.302559630195866,-1.1709056345705775,-2.9255548181675364
743.0000000000098,33.306099667271155,-1.1709986255974003,-2.9255489122050506