File: 01_Data/PU_Aerogel/STA/N2/30K_min/PU_Aerogel_STA_N2_30KData_240108_R3.csv
##Temp./Â°C,Time/min,DSC/(mW/mg),Mass loss/mg
52.0,10.641409194251342,-2.5734473437053573,-0.004417700474713904
53.100000000000016,10.80112876968275,-2.542822248364199,-0.004839604742937098
54.20000000000003,10.914248482772603,-2.520268657783174,-0.0059168741972071
55.30000000000005,11.007970511217929,-2.5000178317424115,-0.006534496650699495
56.40000000000006,11.088525070618829,-2.4835533999205848,-0.005073687806135929
57.50000000000008,11.1606918809707,-2.4686008836684814,-0.00475410512065455
58.600000000000094,11.226346553369156,-2.4546001263745008,-0.0070015318605278765
59.70000000000011,11.28985328131605,-2.439862200888719,-0.004946744785928381
60.800000000000125,11.348547052247124,-2.4295917925587562,-0.007658520363825083
61.90000000000014,11.404711186996645,-2.4161558760291992,-0.007917085327552975
63.000000000000156,11.458243632361356,-2.4072183369011917,-0.008000147151498105
64.10000000000016,11.508974668400002,-2.395677919469175,-0.008095271218363287
65.20000000000019,11.559875235355545,-2.3868396475161124,-0.007435328585282619
66.30000000000021,11.607846853650912,-2.3789055090236553,-0.007267995968227581
67.40000000000022,11.656039168690887,-2.3699188967460767,-0.007764649255254774
68.50000000000023,11.702477914686396,-2.3610646847226944,-0.00816429304972921
69.60000000000025,11.74746341371063,-2.3549449176990054,-0.006895102480826587
70.70000000000027,11.79189242452981,-2.3456821847553018,-0.007210991076637363
71.80000000000028,11.836484366179363,-2.3398877701023086,-0.006784311434974377
72.90000000000029,11.879507032977509,-2.3332528563999686,-0.0074969551742416485
74.00000000000031,11.922116557713379,-2.3276923813207673,-0.009394543936825706
75.10000000000034,11.964572370313208,-2.3199842209903068,-0.008046336355785222
76.20000000000034,12.006363771015383,-2.3150936649435616,-0.008183311722342879
77.30000000000035,12.04807820891711,-2.3080083993927203,-0.007512926370929485
78.40000000000038,12.08823978459515,-2.3034331996146475,-0.008476458619139038
79.5000000000004,12.130107830932728,-2.2999956086499997,-0.0076293997537870695
80.6000000000004,12.17051861253815,-2.294435680482734,-0.008614580801244998
81.70000000000041,12.210162336802291,-2.2888701245894887,-0.007898766510497701
82.80000000000044,12.250300352126894,-2.2833386603172916,-0.008460779925832718
83.90000000000046,12.289346255155076,-2.2793183344117787,-0.009067713137152822
85.00000000000047,12.328994322374287,-2.2745617632628763,-0.010059620740386688
86.10000000000048,12.368103836724455,-2.269539028011752,-0.01033038609697412
87.2000000000005,12.406711064624933,-2.2634590903714242,-0.010270678987298165
88.30000000000052,12.445035655374816,-2.2583284376410746,-0.008831637535915426
89.40000000000053,12.48364771125666,-2.254718207265587,-0.009219617568616556
90.50000000000054,12.521200942132158,-2.24792877379369,-0.00919850241671849
91.60000000000056,12.559417820385757,-2.241329147837713,-0.01052669808401241
92.70000000000059,12.597394776221734,-2.2358790249746563,-0.010571712200849959
93.8000000000006,12.635288690741541,-2.2287501689773475,-0.009453189146663377
94.9000000000006,12.67292441237323,-2.2237987937739097,-0.01053461098163977
96.00000000000063,12.710641307397385,-2.2170966744517235,-0.009171052508323285
97.10000000000065,12.747806942406665,-2.2107694447144706,-0.010555921094474563
98.20000000000066,12.78501023947395,-2.2036122256644832,-0.010647806484636924
99.30000000000067,12.822310580212172,-2.1991474881077586,-0.009868723549658398
100.40000000000069,12.859463159249316,-2.1900439987897204,-0.010541361431191998
101.50000000000071,12.89643561165266,-2.187448569525743,-0.010470484482312248
102.60000000000072,12.933499489672013,-2.1793111575808153,-0.010650083728767079
103.70000000000073,12.970726854452177,-2.172230807891086,-0.010958905857374468
104.80000000000075,13.007090809681372,-2.167345098432752,-0.01062333284040129
105.90000000000077,13.04418492154998,-2.161252831051318,-0.010617657553293025
107.00000000000078,13.081022092370265,-2.155297632306413,-0.010972755403214407
108.10000000000079,13.117317745780692,-2.149769908878951,-0.01098579291325441
109.20000000000081,13.154542092681012,-2.1446990771557943,-0.011979596867687459
110.30000000000084,13.191142608470015,-2.1381834306557947,-0.011814857943175383
111.40000000000084,13.228008129297573,-2.1327148971057226,-0.010660275781221529
112.50000000000085,13.26472428728211,-2.129476937551205,-0.010620227581836339
113.60000000000088,13.301379884862362,-2.124537303953651,-0.010649410099952572
114.7000000000009,13.337919404749183,-2.1192031014839565,-0.010804536375037088
115.8000000000009,13.374463675817063,-2.114069826631162,-0.01196591825002935
116.90000000000092,13.411071344088109,-2.10976905633987,-0.011950453781829573
118.00000000000094,13.447637700051212,-2.103954284329086,-0.011729072308947597
119.10000000000096,13.483911276389764,-2.1013332132983042,-0.011957704803805314
120.20000000000097,13.520320494744833,-2.0972916918966793,-0.011975434847071309
121.30000000000098,13.556781763582862,-2.0925064569642546,-0.01065009533735184
122.400000000001,13.593378113462908,-2.088600453782919,-0.01064063614285704
123.50000000000102,13.6296136279827,-2.0849936065933314,-0.010644200337637688
124.60000000000103,13.666146418809236,-2.0817894515942417,-0.010341152347461247
125.70000000000104,13.70212102815629,-2.07776388016706,-0.010639601063475279
126.80000000000106,13.738185906365395,-2.072776648809195,-0.01200073688433223
127.90000000000109,13.774493040394455,-2.069380386108941,-0.01197033728353114
129.00000000000108,13.810715363667496,-2.0660849613586207,-0.011969966599251869
130.1000000000011,13.845493995762872,-2.0617693192592705,-0.011911801330557914
131.20000000000113,13.882127228782121,-2.0600630477041824,-0.013274419722695718
132.30000000000115,13.918335234132616,-2.0557927239352414,-0.013272965492404865
133.40000000000117,13.953829887352931,-2.051931913533353,-0.01191463716175889
134.50000000000117,13.989460376220736,-2.0476308831884316,-0.012209628869758404
135.6000000000012,14.02549048227729,-2.0445737703237175,-0.013282662268837342
136.7000000000012,14.060893960883863,-2.039686716258835,-0.014037534047809608
137.8000000000012,14.096837620430712,-2.037662473009915,-0.014270429914375882
138.90000000000123,14.131981035849925,-2.034558819764793,-0.014263968159027307
140.00000000000125,14.167887600575579,-2.0306054511414224,-0.012791884312692403
141.10000000000127,14.203273159064965,-2.027784744737444,-0.011344373534463603
142.2000000000013,14.238544280693544,-2.0229078143133425,-0.010103394380969188
143.3000000000013,14.273592713904964,-2.019533189618391,-0.010100066206379044
144.4000000000013,14.309362678780143,-2.0167496841343753,-0.0100999824564032
145.50000000000134,14.344289496395248,-2.0131007087310793,-0.010116164870890731
146.60000000000133,14.379331218015858,-2.0110914418551418,-0.011529526698915049
147.70000000000135,14.41458347096639,-2.0087177058526113,-0.012847775975838971
148.80000000000138,14.44994130632865,-2.0053286471477203,-0.01403604846785722
149.9000000000014,14.48514106423694,-2.0018106293849747,-0.01415267750922089
151.00000000000142,14.51980357722788,-1.9987642844897333,-0.015509290176730861
152.10000000000142,14.554908534233439,-1.9965526102329239,-0.015490131450910827
153.20000000000144,14.589609686526732,-1.992415418824471,-0.01580762314999573
154.30000000000146,14.624783052156351,-1.990065559398291,-0.015810119839351433
155.40000000000146,14.659686155923925,-1.9873401295229656,-0.01580996320775263
156.50000000000148,14.694544855381206,-1.9851303835423724,-0.01581017539334706
157.6000000000015,14.729263242714781,-1.980828065776703,-0.015798165151564625
158.70000000000152,14.763996414282493,-1.9773137780078094,-0.014959839742659131
159.80000000000155,14.798819532904698,-1.9737773258933071,-0.015150675376701894
160.90000000000154,14.833503293384641,-1.9710466966991935,-0.015150022187531142
162.00000000000156,14.867308652183175,-1.969759746272847,-0.015150008068054444
163.1000000000016,14.902520954604723,-1.9655658727105736,-0.01515003984421659
164.20000000000158,14.937496796049613,-1.9640367334798394,-0.015148114732999485
165.3000000000016,14.972310132627406,-1.9593474759180405,-0.015514582085397688
166.40000000000163,15.007006582188897,-1.9565377847488212,-0.015479901599521284
167.50000000000165,15.040673900692115,-1.9545773825044255,-0.01570664143350209
168.60000000000167,15.0759167899705,-1.9516770714285923,-0.017195083317200766
169.70000000000167,15.110766556726679,-1.9481773666869713,-0.018112796680388676
170.8000000000017,15.145288479731535,-1.9436972357854778,-0.018110017145292368
171.9000000000017,15.179703832897522,-1.9435699219397775,-0.018111652079955576
173.0000000000017,15.214143315355733,-1.941531928231916,-0.01829060304325747
174.10000000000173,15.248433173313272,-1.9369845669853425,-0.019418927434332378
175.20000000000175,15.283018502610705,-1.934076259619545,-0.019430795552766167
176.30000000000177,15.317405730814075,-1.9310140920035563,-0.02066959695143078
177.4000000000018,15.351871683896789,-1.9275247959083155,-0.02073454532489638
178.5000000000018,15.386165626733401,-1.9265685532394017,-0.01944435134213851
179.6000000000018,15.420475481386937,-1.9245158814241565,-0.0194301371074177
180.70000000000184,15.454794273142827,-1.9213132160233757,-0.019432327127778315
181.80000000000183,15.488699909236539,-1.9186148775323164,-0.01904344365753108
182.90000000000185,15.522959174453582,-1.9159823577617743,-0.018289157071900597
184.00000000000188,15.556842460892339,-1.914618061466588,-0.019418117507980615
185.1000000000019,15.591077374205563,-1.9125584113706153,-0.020785402959376587
186.20000000000192,15.625166646795597,-1.9096458544713821,-0.022156012368795608
187.30000000000192,15.658981820027824,-1.9089433154656374,-0.02265951017638379
188.40000000000194,15.693228522336586,-1.9059558694057452,-0.02272974624871882
189.50000000000196,15.72710062485352,-1.9041918011778072,-0.0227299810122501
190.60000000000196,15.761179534400156,-1.9037040704743016,-0.02273002442929517
191.70000000000198,15.794911176006977,-1.9009454674103787,-0.022739100136605295
192.800000000002,15.82904814725021,-1.899870424226545,-0.023432128085972614
193.90000000000202,15.86255901661831,-1.8990832975986705,-0.02338912290601769
195.00000000000205,15.896728248146033,-1.897573326430959,-0.0245837149590713
196.10000000000204,15.930452560155496,-1.897575007352853,-0.02469289354048554
197.20000000000206,15.96408194643688,-1.897048090778214,-0.025747259861499394
198.3000000000021,15.997905123183427,-1.8963175887038206,-0.026010979083655794
199.40000000000208,16.031841677759598,-1.895757653650534,-0.02601000791838981
200.5000000000021,16.06556718105373,-1.8959678695253215,-0.026023994135452977
201.60000000000213,16.0994438884939,-1.8958484690308484,-0.027337581439581093
202.70000000000215,16.13285022388026,-1.8963784097610192,-0.02750117302326549
203.80000000000217,16.166109598334376,-1.897576373148803,-0.028628792900031286
204.90000000000217,16.200561822285568,-1.8995757324491063,-0.029062911270806957
206.0000000000022,16.23454323902223,-1.899709848610563,-0.030856162917727303
207.1000000000022,16.268130773988,-1.90368544368465,-0.03128121924506244
208.2000000000022,16.301189408334018,-1.90452673652457,-0.031286027862701626
209.30000000000223,16.335628948327475,-1.9095883676257557,-0.03243405828454238
210.40000000000225,16.36935848132681,-1.911486894562731,-0.03119875635116598
211.50000000000227,16.40239823309727,-1.9166729633411546,-0.03177208665815412
212.6000000000023,16.43694542682429,-1.922277457876064,-0.031152853608372943
213.7000000000023,16.470589556835126,-1.9286437181550435,-0.03128201232986072
214.8000000000023,16.504428767905807,-1.9366259749526362,-0.031356658700623985
215.90000000000234,16.538382578938993,-1.9453192056450375,-0.03262371506946593
217.00000000000233,16.57193322358182,-1.9584975975567662,-0.03521860324524928
218.10000000000235,16.60580246380327,-1.97140547625757,-0.035142780048583955
219.20000000000238,16.639835974726754,-1.9870948822816676,-0.03655981276728859
220.3000000000024,16.673189735744366,-2.002654486436106,-0.037311717982949855
221.40000000000242,16.707347762462827,-2.0211000695242354,-0.037880770089973925
222.50000000000242,16.741144622405837,-2.045520031800267,-0.03935015894313931
223.60000000000244,16.77503831797931,-2.0700815446929073,-0.040709957580638
224.70000000000246,16.809291681674438,-2.099445643860169,-0.042272162013858416
225.80000000000246,16.843120573301327,-2.1318428329926435,-0.04369722773687812
226.90000000000248,16.877171653616486,-2.1660171926158953,-0.04598464164132654
228.0000000000025,16.911486866219896,-2.2066750479925106,-0.047659849396199494
229.10000000000252,16.945419924871214,-2.251621078056953,-0.048251205789264784
230.20000000000255,16.979941851621547,-2.2990080378926945,-0.05076365195384369
231.30000000000254,17.0141481305041,-2.3511663248968557,-0.05272053649351127
232.40000000000256,17.048305899822843,-2.4057515408433234,-0.05522334071480817
233.5000000000026,17.082618301345732,-2.463288066031914,-0.057688847504319796
234.60000000000258,17.116929820509387,-2.5218110650441377,-0.06055907966338836
235.7000000000026,17.151445235937043,-2.581873043511874,-0.06358798719522119
236.80000000000263,17.185545993864967,-2.639409615220614,-0.06646928277277242
237.90000000000265,17.22009922615887,-2.699185165617472,-0.06901835385827271
239.00000000000267,17.254216684920024,-2.7542827434727903,-0.073984242193192
240.10000000000267,17.28870348677545,-2.805989969054424,-0.07797223788212948
241.2000000000027,17.322789081633438,-2.8526213033081738,-0.08197481367700288
242.3000000000027,17.35696087732778,-2.894419340306457,-0.08534513827624313
243.4000000000027,17.39027425372586,-2.932935775887591,-0.09006063100083717
244.50000000000273,17.4240316068663,-2.965379200903427,-0.09472568688879024
245.60000000000275,17.458734800580444,-2.9944041746899956,-0.09713727845674525
246.70000000000277,17.492795422135607,-3.015777485261534,-0.10283259850882409
247.8000000000028,17.52639315827389,-3.0303726917905003,-0.10780579414185354
248.9000000000028,17.55957601706542,-3.0437698345228377,-0.11317915799501543
250.0000000000028,17.593528913383018,-3.054357897894575,-0.11981642494193512
251.10000000000284,17.627039283125836,-3.0589958146213867,-0.12547346283047967
252.20000000000283,17.660695837938896,-3.0642527484139426,-0.13145500405276467
253.30000000000285,17.694248153846356,-3.065710942070515,-0.13810182467219434
254.40000000000288,17.727826642319048,-3.065646517167793,-0.14417055807457357
255.5000000000029,17.761249187232927,-3.066088676935432,-0.15124071959824503
256.6000000000029,17.794639839442798,-3.065458357792164,-0.15957641967183633
257.7000000000029,17.827840750325933,-3.0673292268435617,-0.1674634640295074
258.8000000000029,17.86159357413694,-3.0686117814612492,-0.17626327142690945
259.90000000000293,17.894881656536334,-3.0715856175752143,-0.1859978948847445
261.00000000000296,17.928197323339333,-3.074611430489356,-0.195496204744265
262.100000000003,17.961692408765074,-3.0795958561456414,-0.20638248124925296
263.200000000003,17.995008272249184,-3.0851705221150882,-0.21682436337552158
264.300000000003,18.028712545846467,-3.09154254446451,-0.22653900482010414
265.40000000000305,18.061247693942168,-3.0996835046324933,-0.2369644600551637
266.50000000000307,18.095321969963717,-3.107824480965772,-0.24952060428939316
267.6000000000031,18.128787477179632,-3.1146996806413725,-0.2613905225024564
268.7000000000031,18.16237145856678,-3.1209036012406655,-0.27491057627834836
269.8000000000031,18.195928853010578,-3.1286034133354192,-0.28871099257465227
270.9000000000031,18.229352990353348,-3.1350982520781163,-0.3004494540682652
272.0000000000031,18.262447843569777,-3.140129781372489,-0.3140565683180334
273.10000000000315,18.2962021009347,-3.1461531282181463,-0.32820829199708346
274.2000000000032,18.329476442349613,-3.148392038985837,-0.34436991003269046
275.30000000000314,18.363192082663815,-3.149533875311527,-0.3604469680821327
276.40000000000316,18.396357197084722,-3.1493443667319347,-0.37513779177210216
277.5000000000032,18.429538723713463,-3.1454179540343965,-0.3914943024591597
278.6000000000032,18.462886958303592,-3.140244173770756,-0.4073385447258038
279.70000000000323,18.496223235329786,-3.1327901862404315,-0.42607455889091783
280.80000000000325,18.52938452587178,-3.1217387242800854,-0.4443847249719073
281.9000000000033,18.56250977149699,-3.1083518563745356,-0.4635368154343693
283.0000000000033,18.59575813195369,-3.09257920269832,-0.4815239803222435
284.1000000000033,18.628205278319033,-3.0755378202282633,-0.4993925918004014
285.20000000000334,18.662035541295793,-3.052222429263493,-0.5194387579213213
286.30000000000337,18.695083492600308,-3.0271897449554457,-0.5386420129602545
287.40000000000333,18.728010595723237,-3.0007978571774823,-0.5581272583746935
288.50000000000335,18.760762040325755,-2.9684189816881257,-0.5789856176168815
289.6000000000034,18.793879807220364,-2.9335883128280056,-0.600352446816387
290.7000000000034,18.826602867177744,-2.896345719598419,-0.6201092054938502
291.8000000000034,18.859584269209837,-2.857090756806117,-0.640528115975501
292.9000000000034,18.89211843828651,-2.813202538526555,-0.6617336502769433
294.0000000000034,18.92470146655793,-2.7692576373009112,-0.6826655548305629
295.10000000000343,18.95714685302601,-2.7240763732393503,-0.7025267587661559
296.20000000000346,18.990493897195638,-2.6754731796293076,-0.7224067435030608
297.3000000000035,19.023320413565166,-2.6272034719115345,-0.7424398060697417
298.4000000000035,19.055707314400042,-2.580279926583354,-0.7625078040486928
299.5000000000035,19.088608224785798,-2.5303562886473077,-0.7822353453642221
300.60000000000355,19.12111055697254,-2.4845369795692074,-0.8014322292762635
301.70000000000357,19.15380441324813,-2.4427083781440393,-0.8196364777403442
302.8000000000036,19.18684385257162,-2.4006374458234045,-0.8358292796456674
303.9000000000036,19.219770245042103,-2.3612459097021516,-0.8535399654583813
305.0000000000036,19.25286787020773,-2.327216292574425,-0.8690460147379295
306.1000000000036,19.28553789929167,-2.2956320478083754,-0.8850452128404291
307.2000000000036,19.318611449985053,-2.268663764164359,-0.900684185054637
308.30000000000365,19.35134940066722,-2.2475852364270636,-0.9152259065512101
309.4000000000037,19.384775084208542,-2.2276661933902697,-0.9284066919209919
310.5000000000037,19.418077262171092,-2.2142563578296715,-0.9420461899374786
311.60000000000366,19.451288172356787,-2.204660003247057,-0.9553735129103105
312.7000000000037,19.484531087882267,-2.1984434132770625,-0.9686493450518019
313.8000000000037,19.51780967251853,-2.1967874695263574,-0.980751018410599
314.90000000000373,19.551175533450486,-2.1965005248146334,-0.9906157076459277
316.00000000000375,19.58480250720379,-2.199466983469946,-1.0022209702488887
317.1000000000038,19.61841577350516,-2.2044324672171927,-1.0130187602538663
318.2000000000038,19.651741272749415,-2.212469851303244,-1.0231720007859395
319.3000000000038,19.685303577045346,-2.2232660545935534,-1.0338965244481697
320.40000000000384,19.71843742893859,-2.23253974063091,-1.04322271833655
321.5000000000038,19.752908932391026,-2.244628425233644,-1.0542263953799824
322.60000000000383,19.786250851653136,-2.2567211488720673,-1.0647081457669785
323.70000000000385,19.81962954305817,-2.269925843687441,-1.0729431361085382
324.8000000000039,19.853753742209186,-2.283208049491005,-1.081564692015717
325.9000000000039,19.88725523461589,-2.291965265423134,-1.0910070878713465
327.0000000000039,19.920988592976805,-2.3057353415926123,-1.1025165527531788
328.10000000000394,19.954666070777737,-2.317633235053972,-1.11181551782273
329.2000000000039,19.988449077688692,-2.3266574175749826,-1.1218540802382981
330.30000000000393,20.02219689846628,-2.3381322557604776,-1.1321325832986684
331.40000000000396,20.055938028523343,-2.3486621943402746,-1.1416852677252964
332.500000000004,20.08968812947999,-2.354135166332286,-1.150885981836554
333.600000000004,20.123510900260257,-2.361258712271515,-1.1600704332494698
334.700000000004,20.157044315917297,-2.3661661649264154,-1.1715654829194055
335.80000000000405,20.190760814430696,-2.3677117676870365,-1.1816801284732024
336.90000000000407,20.224353737273123,-2.3692908613593824,-1.1903174482899868
338.0000000000041,20.258137012101002,-2.3691103123835378,-1.1998615730308786
339.10000000000406,20.2910621907032,-2.3658657899334616,-1.2096240324171186
340.2000000000041,20.325620139378454,-2.359805562201345,-1.2192122908752907
341.3000000000041,20.359107857294024,-2.3514356482274326,-1.2295543120756545
342.4000000000041,20.391926255240953,-2.341505979210519,-1.2402203488949195
343.50000000000415,20.425613699309686,-2.331444610066707,-1.2501729992902884
344.6000000000042,20.45935189411204,-2.3178998210798984,-1.2596017941335371
345.7000000000042,20.493288617572308,-2.3020795863279,-1.2693119350646564
346.80000000000416,20.526515833901747,-2.2888283659936692,-1.2794297106343624
347.9000000000042,20.560325938607015,-2.266000857887914,-1.2901439969799458
349.0000000000042,20.594180293740077,-2.2409618638468554,-1.2993415237745913
350.10000000000423,20.627603996022366,-2.212762508844556,-1.3096140455790484
351.20000000000425,20.661214276340477,-2.1817052617599604,-1.3195841870299372
352.3000000000043,20.694242279640598,-2.151210290942152,-1.3293716764293957
353.4000000000043,20.727791553402113,-2.1195456094618077,-1.3390835100776428
354.5000000000043,20.761314691855997,-2.0870205624768055,-1.3489914837340962
355.60000000000434,20.79472156937856,-2.056736360641655,-1.3588833627971235
356.7000000000043,20.827864508773626,-2.0260449389725297,-1.36818062031197
357.80000000000433,20.86141083674395,-1.9989226062316388,-1.3771533268057539
358.90000000000435,20.894920594424104,-1.9703650308798426,-1.3867882965586769
360.0000000000044,20.928376539072097,-1.945553526522469,-1.3965409203870536
361.1000000000044,20.962044882574453,-1.9206160763483962,-1.405397065600329
362.2000000000044,20.995591675962817,-1.8952110667052628,-1.4151017025564432
363.30000000000445,21.029485661462843,-1.872820273549939,-1.4253947160974287
364.4000000000044,21.06306768586809,-1.849725143174508,-1.4337907763222222
365.50000000000443,21.096459947936655,-1.82598339400286,-1.442839457366028
366.60000000000446,21.129859051948987,-1.8047027806609894,-1.452738149629679
367.7000000000045,21.163425467735046,-1.781556376653168,-1.462357945523424
368.8000000000045,21.19764399187173,-1.7599700624502408,-1.4716484450012697
369.9000000000045,21.231062251613963,-1.7380819158668643,-1.4808085565050377
371.00000000000455,21.264646213415435,-1.7118708837952659,-1.4898189102430979
372.10000000000457,21.298119277974653,-1.6892764808972003,-1.498956274387944
373.2000000000046,21.33175204228944,-1.664617833717048,-1.5077049892121162
374.30000000000456,21.365613415806397,-1.6399965472140443,-1.5169476640818882
375.4000000000046,21.399262735859107,-1.615234226904072,-1.5272119043369283
376.5000000000046,21.433064150704205,-1.5913232365302221,-1.5365536441506817
377.6000000000046,21.46656780567514,-1.566145298082397,-1.5448845671500213
378.70000000000465,21.500379458953784,-1.540890769795184,-1.5530196667862373
379.8000000000047,21.534179857324528,-1.5144745253275673,-1.560861059753464
380.9000000000047,21.56785672273135,-1.4906473933090443,-1.5695759911777332
382.00000000000466,21.60141964779454,-1.4636656149812877,-1.577696633243311
383.1000000000047,21.634932052971664,-1.4396750609151185,-1.586151153424869
384.2000000000047,21.668225527721617,-1.4168570926117845,-1.5919828321353529
385.30000000000473,21.702954425165583,-1.3929437399452982,-1.5997852533574486
386.40000000000475,21.73678699320925,-1.368609715799496,-1.6078232059413518
387.5000000000048,21.77054581944385,-1.3478446986508585,-1.6164158963864756
388.6000000000048,21.80440857162361,-1.3248675265940792,-1.623510206633922
389.7000000000048,21.838112427485626,-1.3045755165772828,-1.6306633810028943
390.80000000000484,21.872163210407674,-1.2838081825395655,-1.6379213307132794
391.9000000000048,21.906034723447743,-1.2653099865289748,-1.6454037500090588
393.00000000000483,21.9397284513335,-1.2434491324198316,-1.6529992641218576
394.10000000000485,21.973482073530068,-1.225292985640345,-1.6608241038562133
395.2000000000049,22.007558618086673,-1.2066952741193613,-1.6669023704897015
396.3000000000049,22.041676350098747,-1.1882559604053708,-1.6743987009095829
397.4000000000049,22.07570046373172,-1.1724388573380213,-1.6801619928439568
398.50000000000495,22.109902459078754,-1.156481423397181,-1.6868716930823413
399.6000000000049,22.143434723842628,-1.1402943248387445,-1.6936601387466945
400.70000000000493,22.17748415873399,-1.1247220894934933,-1.7004856158350576
401.80000000000496,22.21176141270847,-1.1106394345719435,-1.7073301140071417
402.900000000005,22.245844259830374,-1.0973565884390413,-1.714287822700677
404.000000000005,22.279870654586112,-1.0840298075360846,-1.7188254752518666
405.100000000005,22.31405246674546,-1.072800912121508,-1.725471717501108
406.20000000000505,22.34827496263416,-1.0614730332015614,-1.731820724101861
407.30000000000507,22.382302326678055,-1.052558297338354,-1.7389995994207763
408.4000000000051,22.416315539462534,-1.043901499565942,-1.7466946656243634
409.50000000000506,22.450367368887537,-1.0326342090072524,-1.7535963816057554
410.6000000000051,22.484917067910107,-1.0261651965235132,-1.760868645748086
411.7000000000051,22.518821248456284,-1.022234170341585,-1.7683116122622335
412.8000000000051,22.5533456969926,-1.0193788267581436,-1.775698277688949
413.90000000000515,22.587745947746665,-1.0168418885161958,-1.7834096827920827
415.0000000000052,22.62195117890206,-1.01536116982933,-1.7900516173537238
416.1000000000052,22.65665741355646,-1.0159441942645369,-1.7978277489962045
417.20000000000516,22.690854035937473,-1.0188122005330646,-1.8047958201313201
418.3000000000052,22.72522927344134,-1.0250671524468753,-1.8108706713859721
419.4000000000052,22.75981088205808,-1.030208536860608,-1.8189064813756213
420.50000000000523,22.794383865546664,-1.038200411637588,-1.8257433861175905
421.60000000000525,22.829104669637623,-1.0476804529194819,-1.8331433545371167
422.7000000000053,22.863704382807594,-1.0583373797630184,-1.841233179994184
423.8000000000053,22.89830206119153,-1.0699651413584217,-1.8492931930968637
424.9000000000053,22.932785750913812,-1.0841735119638254,-1.8569489278032094
426.00000000000534,22.9676263383317,-1.0978526996423537,-1.8649089893349284
427.1000000000053,23.002309534282723,-1.1134103321136002,-1.8715027989109978
428.20000000000533,23.03696708666617,-1.1272707792452032,-1.8787776335825432
429.30000000000535,23.071795344363927,-1.1428184712666145,-1.887366735789167
430.4000000000054,23.10598729215882,-1.1610318695112374,-1.8938655548591465
431.5000000000054,23.140558988983294,-1.1759876346252345,-1.9017079462766309
432.6000000000054,23.17615407016215,-1.1908526627583151,-1.9095688087521512
433.70000000000545,23.211055295990768,-1.2091758742274699,-1.9167924579599434
434.8000000000054,23.24578600352749,-1.2247446887331073,-1.9246748700847038
435.90000000000543,23.280512942645533,-1.2412812250682213,-1.9324822842469658
437.00000000000546,23.315398888848872,-1.2553010658438024,-1.9386665278297173
438.1000000000055,23.350220671408607,-1.2697957936793578,-1.9461830385308279
439.2000000000055,23.385148832089914,-1.2809458113059646,-1.9537402843596747
440.3000000000055,23.41982978830628,-1.2962666863625174,-1.9606217189272344
441.40000000000555,23.454749205702377,-1.3081281479263316,-1.9679848979784058
442.50000000000557,23.489537748013188,-1.3200703094489203,-1.975960095773146
443.6000000000056,23.524498869136398,-1.3294743109419362,-1.9827461010036087
444.70000000000556,23.55945470448651,-1.3432788049811477,-1.9907825494856723
445.8000000000056,23.594213969419073,-1.3504717757899418,-1.9985052807444608
446.9000000000056,23.629331358995007,-1.3602782277190197,-2.0064370539978515
448.0000000000056,23.66388994033509,-1.3676835665070841,-2.0147238544332255
449.10000000000565,23.699073346096373,-1.374692771982719,-2.0221862959238344
450.2000000000057,23.734240761745333,-1.3835182879079186,-2.0295542225788914
451.3000000000057,23.768862061620553,-1.3902579078442225,-2.037343587918675
452.40000000000566,23.80362225908209,-1.3944050237465941,-2.045577342271835
453.5000000000057,23.838661916137337,-1.4033016638742726,-2.053596637522057
454.6000000000057,23.873593240127217,-1.4073937490016852,-2.060877890230321
455.70000000000573,23.90859806924134,-1.413626424287104,-2.0690572409743284
456.80000000000575,23.943408997836826,-1.4196507414165105,-2.07585816631324
457.9000000000058,23.97867878016459,-1.4233404501805293,-2.081695297286645
459.0000000000058,24.01355486100606,-1.427436022057628,-2.089431320299422
460.1000000000058,24.048186572660605,-1.431855183067696,-2.096427647642501
461.20000000000584,24.083336420853776,-1.4357622940656365,-2.104970070245512
462.3000000000058,24.118155442814352,-1.4391521859210998,-2.1126746525851146
463.40000000000583,24.152969378072324,-1.4425965683345219,-2.1208942208226373
464.50000000000585,24.188242933656554,-1.4450509503633895,-2.12888954853881
465.6000000000059,24.22327917445071,-1.4488528696937506,-2.135966337479844
466.7000000000059,24.257623350854573,-1.4522062434472207,-2.1426527298343796
467.8000000000059,24.29332023046377,-1.4539424710581117,-2.150290824914253
468.90000000000595,24.32854966630181,-1.455790129275559,-2.157788696810208
470.0000000000059,24.36330809419488,-1.4573465632847091,-2.165023581010956
471.10000000000593,24.398193195809842,-1.4601206207666058,-2.172718536112235
472.20000000000596,24.433363679948638,-1.4623446776259446,-2.179153194513022
473.300000000006,24.46851152994272,-1.4629093614964361,-2.186601344083206
474.400000000006,24.503402801742887,-1.4636749400573477,-2.1943397099084008
475.500000000006,24.538670595385653,-1.4640947077472988,-2.2015738983219597
476.60000000000605,24.573109409734396,-1.4661485213506273,-2.2084839071331652
477.70000000000607,24.60842755262416,-1.4660432295653438,-2.2148625504325437
478.8000000000061,24.64352872192408,-1.4676184025455965,-2.2221677299110594
479.90000000000606,24.678643123639784,-1.467288892242975,-2.228396027411755
481.0000000000061,24.713693338456032,-1.4684293047622972,-2.235543011962991
482.1000000000061,24.74865497521868,-1.4682744550530187,-2.242224032587801
483.2000000000061,24.783399272962036,-1.4689925944272688,-2.2485641958343097
484.30000000000615,24.819072639725277,-1.46903620259845,-2.2557039828520478
485.4000000000062,24.854027692513185,-1.4693259764221607,-2.2638520093330152
486.5000000000062,24.889265367092275,-1.4689302772263118,-2.270773368441203
487.60000000000616,24.924266005988212,-1.47012128043924,-2.2779393161059382
488.7000000000062,24.95963699381255,-1.4690747904467647,-2.284876971817006
489.8000000000062,24.99456183360181,-1.4702227416764324,-2.291577560606815
490.90000000000623,25.029706857330957,-1.469678126047974,-2.297607138687725
492.00000000000625,25.064765758861665,-1.469461180711632,-2.3033577669169523
493.1000000000063,25.099938423542287,-1.4690383636882716,-2.311412112271549
494.2000000000063,25.135148958895815,-1.4703110665647225,-2.317186796845748
495.3000000000063,25.17041625749609,-1.4697988816811243,-2.323757555427768
496.40000000000634,25.205255343587982,-1.4689178849839657,-2.332498973026626
497.5000000000063,25.240614597343523,-1.468333545698915,-2.3381796889948228
498.60000000000633,25.27568360828348,-1.4696755390096328,-2.345820339029701
499.70000000000636,25.310592841974298,-1.4689189586267677,-2.3517598817215557
500.8000000000064,25.346202323850545,-1.4680234493595576,-2.3587783769542994
501.9000000000064,25.381394838803196,-1.4683130192321139,-2.3650945229178
503.0000000000064,25.41661253120197,-1.4675763543217142,-2.372355284820461
504.10000000000645,25.451947412011933,-1.4679893512026339,-2.3794521028286937
505.2000000000064,25.487389815392785,-1.466668431884531,-2.385816600817514
506.30000000000643,25.522487219475092,-1.465449461115318,-2.3933487173697685
507.40000000000646,25.55687337786364,-1.464910159170207,-2.3994279257414846
508.5000000000065,25.593006012180275,-1.464614382581586,-2.407937213675592
509.6000000000065,25.628315163110752,-1.4631535424200965,-2.4154174443320136
510.7000000000065,25.663573615947474,-1.4624685148341934,-2.42188249894456
511.80000000000655,25.699070066055302,-1.4598740677769138,-2.4298071854313905
512.9000000000066,25.7340655937788,-1.4600759918009067,-2.4356074464055464
514.0000000000066,25.769555113118415,-1.4584978526124908,-2.441331820135942
515.1000000000065,25.804666959520347,-1.4588471886097705,-2.4485860686116476
516.2000000000066,25.840065175467885,-1.4565043437084335,-2.456058370385851
517.3000000000065,25.87565415998417,-1.456438642191627,-2.464856815226467
518.4000000000067,25.911007680541818,-1.4550692703998043,-2.471729270504016
519.5000000000066,25.945979209734727,-1.4544269338839302,-2.479132855497361
520.6000000000067,25.981517717535155,-1.453745264512826,-2.4864289352813467
521.7000000000066,26.01677687815216,-1.4534334346901252,-2.493788435767221
522.8000000000067,26.052488463921932,-1.4514857018371896,-2.5017666560015286
523.9000000000067,26.08771839724375,-1.45197425083546,-2.5085381712133286
525.0000000000067,26.123012474555996,-1.4516432759349531,-2.5162081185815017
526.1000000000067,26.158609786364373,-1.4499119542653212,-2.5231969017692943
527.2000000000068,26.193794188280318,-1.4519214089389234,-2.530808878564729
528.3000000000068,26.229298147683373,-1.451542044543273,-2.5375507855947506
529.4000000000068,26.26524964353107,-1.4498028321452687,-2.5441583573162188
530.5000000000068,26.300060950976388,-1.4497632932025255,-2.5522074291897585
531.6000000000068,26.335916733768993,-1.4494977574613148,-2.558960682789306
532.7000000000069,26.37153222121561,-1.449705254228746,-2.5657828441467245
533.8000000000068,26.406958273165767,-1.4508081613526749,-2.572386869623209
534.9000000000069,26.442278325708354,-1.448828537436922,-2.578465830339053
536.0000000000068,26.4780140233182,-1.4492803285183502,-2.584878977212158
537.100000000007,26.51343504097944,-1.450759410273735,-2.5911280906294394
538.2000000000069,26.549301801897602,-1.4513890883054488,-2.5982656429803166
539.300000000007,26.58451457226716,-1.451328970302446,-2.6040555384694106
540.4000000000069,26.619965075330324,-1.4506474825062885,-2.6109241762231887
541.5000000000069,26.6555277138722,-1.4518128869848055,-2.6172083013399097
542.600000000007,26.691421202361365,-1.4520341001363535,-2.6236688267372705
543.700000000007,26.72710654071423,-1.450908361229006,-2.629526437220199
544.800000000007,26.76275008168889,-1.4542801159495409,-2.6353720611254063
545.900000000007,26.79804891532658,-1.4544486855773386,-2.6415010176207563
547.000000000007,26.833848138976887,-1.4551092614893626,-2.6471227738337118
548.1000000000071,26.869201610940866,-1.4586008078952677,-2.652805027072229
549.2000000000071,26.904964239186274,-1.4598472174589177,-2.658199428299006
550.300000000007,26.940898469441255,-1.4612640995661366,-2.664512714915007
551.4000000000071,26.976335425997007,-1.4620337880973606,-2.6697415516971965
552.500000000007,27.012260206232508,-1.4637911859333068,-2.673782649898091
553.6000000000072,27.047223452600402,-1.4645681739049146,-2.679875060997663
554.7000000000071,27.083740708354682,-1.4653179674400008,-2.6847488081240325
555.8000000000072,27.11950279026455,-1.4661391685815452,-2.689412327550358
556.9000000000071,27.154919449756658,-1.4686166317510516,-2.6948752375900287
558.0000000000072,27.19094825025779,-1.4697570528251658,-2.699570987720739
559.1000000000072,27.226813808294917,-1.4707864042215653,-2.7046141277094815
560.2000000000072,27.262232236845936,-1.4720642524239202,-2.7082521725609245
561.3000000000072,27.29821567715038,-1.4733212665168631,-2.7133270541888868
562.4000000000073,27.33362894781498,-1.4731248408972422,-2.717538253288432
563.5000000000073,27.369359283163732,-1.4744665387391296,-2.722105675868421
564.6000000000073,27.405654691698714,-1.4758355301098436,-2.7261784103785285
565.7000000000073,27.44164459803446,-1.4767741533229444,-2.730282795502068
566.8000000000073,27.476980797026727,-1.4766288501605533,-2.7344122737231595
567.9000000000074,27.51259126751176,-1.4756999171112253,-2.73875997280587
569.0000000000074,27.54871045485747,-1.4775468324436447,-2.7426694800781846
570.1000000000074,27.584455739616892,-1.4778855566658884,-2.7466184202403765
571.2000000000073,27.620350206541033,-1.4787132330233128,-2.7519688473911312
572.3000000000073,27.65591852385299,-1.4785146645040481,-2.7545073331214165
573.4000000000074,27.691990844007734,-1.480149090517716,-2.7590843130092164
574.5000000000074,27.7279981729158,-1.4810214266601283,-2.763364388159452
575.6000000000074,27.76312817628748,-1.480235659578372,-2.7669166872088065
576.7000000000074,27.79963265236379,-1.4801333399824808,-2.770742824012086
577.8000000000075,27.835321696316385,-1.4821376703668683,-2.774457113752863
578.9000000000075,27.871292442229777,-1.4828786977828743,-2.7772851938620304
580.0000000000075,27.906732629529138,-1.4833142012482334,-2.779436344011602
581.1000000000075,27.942990022561066,-1.4839093632256024,-2.78308783161046
582.2000000000075,27.97884289579204,-1.484221842543659,-2.7859381485028045
583.3000000000076,28.014891777605634,-1.4862022937332482,-2.7891060181184866
584.4000000000076,28.050999993266842,-1.4884312401683215,-2.792291876975315
585.5000000000076,28.08677086513068,-1.4884056039062417,-2.796039100279245
586.6000000000076,28.12304607040495,-1.4908157086889393,-2.798905645420417
587.7000000000077,28.158706365968907,-1.492844427561874,-2.801958511671521
588.8000000000077,28.19500128749635,-1.4945477949167865,-2.805267478924973
589.9000000000076,28.23107859866817,-1.4944980332828168,-2.807734503450738
591.0000000000076,28.266905307639597,-1.4968081759737655,-2.8109632724037388
592.1000000000076,28.302761897492605,-1.5001905070027137,-2.8137657631423036
593.2000000000077,28.338908688358785,-1.5001886947900953,-2.8164883685813784
594.3000000000077,28.374805250157433,-1.5027847949552058,-2.8189426461749294
595.4000000000077,28.41081423113335,-1.5066542896040525,-2.822041449639038
596.5000000000077,28.447126916446027,-1.5107560949151815,-2.8251502232309766
597.6000000000078,28.48285223206432,-1.5132497844066253,-2.827274960399269
598.7000000000078,28.51904020013479,-1.5182261612636394,-2.8304258955593005
599.8000000000078,28.555118062580704,-1.5190015346947383,-2.832266331908521
600.9000000000078,28.591640899813534,-1.5231849813773248,-2.835158207500431
602.0000000000078,28.627847461903446,-1.525979484587595,-2.837194174716035
603.1000000000079,28.663667916319977,-1.5303646454434137,-2.838921889268414
604.2000000000079,28.7000542753869,-1.5346326695808077,-2.8410617601096546
605.3000000000079,28.73602637714082,-1.537492413879147,-2.8436503446900625
606.4000000000078,28.77239763367149,-1.5422304232449429,-2.844786171086599
607.5000000000078,28.808128495243153,-1.5462145147360395,-2.847446581381246
608.6000000000079,28.844576230282186,-1.5504407529595987,-2.849595262064917
609.7000000000079,28.880681336780704,-1.5525766642975996,-2.851395180100897
610.8000000000079,28.91692438952565,-1.5563470785560454,-2.8524217472931217
611.9000000000079,28.95328275288792,-1.5605203504499916,-2.8541447474560426
613.000000000008,28.98966398473796,-1.5649416639735672,-2.8571461329752337
614.100000000008,29.025714326017496,-1.5721673112816468,-2.858482193556542
615.200000000008,29.06216872489856,-1.573734741602886,-2.8597565944643195
616.300000000008,29.098230634356824,-1.577187931125624,-2.8613028386143196
617.400000000008,29.134303051912706,-1.582579455453626,-2.8620044189981977
618.5000000000081,29.17086328329001,-1.5889569504337753,-2.8641985655987705
619.6000000000081,29.206626612751528,-1.5936622486391934,-2.8662863219420354
620.7000000000081,29.243334680022638,-1.5956300471386575,-2.8680039361508687
621.8000000000081,29.27959658217095,-1.601520053329508,-2.869403808034262
622.9000000000082,29.31593840309828,-1.6061728636898684,-2.8708340007721773
624.0000000000082,29.352147933444268,-1.6127477691603365,-2.872258137643483
625.1000000000081,29.38805413884833,-1.6168874167598974,-2.8733281856314803
626.2000000000081,29.42437049718379,-1.6222056954823008,-2.87564783353917
627.3000000000081,29.46129974353725,-1.6267279295495654,-2.8775236045970773
628.4000000000082,29.49739792362523,-1.632871523790736,-2.87901628015168
629.5000000000082,29.533813016514507,-1.6377579426036835,-2.8802975333397702
630.6000000000082,29.57057585237374,-1.645909481705688,-2.8821010018136795
631.7000000000082,29.606664943839807,-1.6496827425699612,-2.8825601316775114
632.8000000000083,29.643302842890535,-1.657669405079411,-2.882780033304297
633.9000000000083,29.679373158337558,-1.666863358075432,-2.883891323909682
635.0000000000083,29.715811206242464,-1.6734347828959752,-2.8851921356561347
636.1000000000083,29.751943742244332,-1.678845910932222,-2.8867199176237945
637.2000000000083,29.788529280992904,-1.687658614612012,-2.8880950375997703
638.3000000000084,29.82499905453355,-1.6915860039678245,-2.8877091799110683
639.4000000000084,29.86136584210846,-1.6989126281696334,-2.8888123687176077
640.5000000000084,29.89774876118627,-1.7037269925825023,-2.8901641050956286
641.6000000000083,29.934206610398494,-1.709702663013358,-2.8901430327966224
642.7000000000083,29.970516324307418,-1.7183564535313607,-2.8913702020692504
643.8000000000084,30.006930198356958,-1.7269059602486592,-2.892922755918552
644.9000000000084,30.043315199027457,-1.7319996499273538,-2.893475527594825
646.0000000000084,30.079878703346473,-1.737797020023674,-2.8944317562919135
647.1000000000084,30.116114505735037,-1.7452893717222682,-2.895613448461648
648.2000000000085,30.15249269301883,-1.7500353083977331,-2.8957447852761393
649.3000000000085,30.189170337055316,-1.7604500674858974,-2.8970700476577034
650.4000000000085,30.22534777889769,-1.7635871468446997,-2.8976633842957225
651.5000000000085,30.2616980026931,-1.7698357642794964,-2.898393852339294
652.6000000000085,30.298503558170786,-1.77785082243914,-2.8996963413165826
653.7000000000086,30.33475164339127,-1.7846738459878297,-2.899700719227372
654.8000000000086,30.371155869506172,-1.7905248367167792,-2.8997820608869564
655.9000000000086,30.407621653236113,-1.7970407402543673,-2.9010135728975897
657.0000000000086,30.444202768151733,-1.804745301038484,-2.9021349632507567
658.1000000000087,30.480675467108174,-1.8113750494421121,-2.9029102261307207
659.2000000000087,30.51704185832101,-1.8215323451668546,-2.9037853882700553
660.3000000000086,30.55359298014097,-1.827879999302937,-2.9050820444826986
661.4000000000086,30.589954399298897,-1.8360494842029074,-2.9043977091668456
662.5000000000086,30.62678165161321,-1.842861421143058,-2.904890077678057
663.6000000000087,30.663004742912804,-1.8550507573455846,-2.905712065160319
664.7000000000087,30.699337633521733,-1.8632590711262498,-2.9070689238855367
665.8000000000087,30.736082556291798,-1.8708444213478053,-2.9082363083579246
666.9000000000087,30.772748700489625,-1.8799889227560784,-2.9083794916260333
668.0000000000088,30.809036173929012,-1.890456580369149,-2.908376196306973
669.1000000000088,30.84531054596766,-1.8988293623818788,-2.9097166240314793
670.2000000000088,30.882064590278024,-1.90563017516551,-2.9095611323076516
671.3000000000088,30.91850692217261,-1.917098938348061,-2.909704734148591
672.4000000000088,30.9550363937955,-1.9266054362873983,-2.9110531464648757
673.5000000000089,30.99153617462153,-1.9365096099506236,-2.9110085060470148
674.6000000000089,31.028157630548712,-1.9421508387159294,-2.911586532427857
675.7000000000089,31.064700117031542,-1.9504048805041005,-2.912282394159896
676.8000000000088,31.100930899690926,-1.9576359859227346,-2.9133427822512417
677.9000000000088,31.13750364800062,-1.967174268720251,-2.9129855095105963
679.0000000000089,31.17338103255524,-1.972496803249224,-2.914283304155115
680.1000000000089,31.21055339075687,-1.979425827499932,-2.9147654195801445
681.2000000000089,31.24689097881993,-1.9857405547061076,-2.9155749691575306
682.3000000000089,31.28349564285499,-1.9922860549861627,-2.916927883374074
683.400000000009,31.319601937306274,-1.9989862939077567,-2.918281657651571
684.500000000009,31.356450910446082,-2.003888645322181,-2.918210405684343
685.600000000009,31.392851207777525,-2.0123699165983453,-2.919565613380274
686.700000000009,31.429376188422097,-2.018167777622258,-2.919576920853009
687.800000000009,31.46592899308791,-2.0231301755662,-2.9208950338769766
688.9000000000091,31.502240546228595,-2.0278244314178653,-2.920884977875162
690.0000000000091,31.538742768878414,-2.0338241816396847,-2.922217113461108
691.1000000000091,31.57457884158244,-2.038268788703113,-2.9222243339857394
692.2000000000091,31.61176002613029,-2.0447477094346316,-2.923578235032248
693.3000000000092,31.648011150991984,-2.049524938611124,-2.923530861542366
694.4000000000092,31.684677548427278,-2.0547419423082403,-2.9249373212686836
695.5000000000091,31.721392633446264,-2.0619833155939675,-2.924856282383608
696.6000000000091,31.757720381387117,-2.066338709922264,-2.9261052283612417
697.7000000000091,31.794253768099896,-2.070857114030556,-2.9264244896669074
698.8000000000092,31.831093912295835,-2.0766741549608163,-2.9274841925904616
699.9000000000092,31.867401081159397,-2.0810631188834248,-2.926763974134893
701.0000000000092,31.903810554485005,-2.088283213280703,-2.927850699848034
702.1000000000092,31.9401753577997,-2.091876855103652,-2.928139555540497
703.2000000000093,31.976844775444356,-2.0963029717960255,-2.928316192922359
704.3000000000093,32.01321123866438,-2.1020737189877674,-2.9294850458103596
705.4000000000093,32.05029959173863,-2.107583620249702,-2.9308964718423076
706.5000000000093,32.086937481050306,-2.1130594364664055,-2.932183899774345
707.6000000000093,32.12321301530266,-2.119016605206353,-2.93224478200508
708.7000000000094,32.15978852484768,-2.1216797480387366,-2.933479284293117
709.8000000000094,32.19638069011408,-2.1268717875024405,-2.936141760626887
710.9000000000094,32.23305551077873,-2.1313426856969175,-2.9349798769730437
712.0000000000093,32.26954628546311,-2.135640421925966,-2.9347293233730056
713.1000000000093,32.30604109570357,-2.1384206819697176,-2.934952641640467
714.2000000000094,32.34249712505412,-2.1444985687411946,-2.934742837869463
715.3000000000094,32.37920249196673,-2.148024985955846,-2.9361500833075604
716.4000000000094,32.41602881521902,-2.150062152773709,-2.9368214590988257
717.5000000000094,32.45235928103206,-2.153656378851014,-2.9374993375575205
718.6000000000095,32.48913613307254,-2.158174043033971,-2.9400950654868
719.7000000000095,32.525786215508845,-2.1598890619384714,-2.9400976441045827
720.8000000000095,32.562222169516104,-2.16190950481804,-2.9399540689641386
721.9000000000095,32.59890370466738,-2.1657697564169025,-2.940432846022511
723.0000000000095,32.635479622935115,-2.166904598032667,-2.940572236021948
724.1000000000096,32.67216595851992,-2.166664354666896,-2.9414248668150336
725.2000000000096,32.70897096347846,-2.1698958204803884,-2.94141940314407
726.3000000000096,32.745687003094204,-2.1718390447492255,-2.9427485581822426
727.4000000000096,32.78234998926383,-2.1744150976229446,-2.943673831742431
728.5000000000097,32.81870901545047,-2.175261504832566,-2.9450449216297643
729.6000000000097,32.855462140996565,-2.177742705993797,-2.9456310484678982
730.7000000000096,32.89209213647632,-2.178717089629481,-2.944984773888827
731.8000000000096,32.928625141865524,-2.1801374818079444,-2.9459837403296207
732.9000000000096,32.965495703649374,-2.1814305503796767,-2.9449552044516323
734.0000000000097,33.002152221347636,-2.183762957159132,-2.9463537401253626
735.1000000000097,33.0387758337328,-2.185020992637882,-2.946997175494805
736.2000000000097,33.075823366843586,-2.1853587292335126,-2.9476838717991125
737.3000000000097,33.112355670538236,-2.1869601957571994,-2.947824438628609
738.4000000000098,33.14916933586543,-2.1863000413465024,-2.948934187431905
739.5000000000098,33.18609786344731,-2.182512337970158,-2.948861156527892
740.6000000000098,33.22241869007006,-2.1861253675168726,-2.9490287417729126
741.7000000000098,33.25913682957288,-2.186719342579815,-2.950320434455775
742.8000000000098,33.295952180968314,-2.1881054390030386,-2.950833740397245
743.0000000000098,33.302667390215,-2.188215890889479,-2.9506520945354158