File: 01_Data/PU_Aerogel/STA/N2/30K_min/PU_Aerogel_STA_N2_30KData_231213_R1.csv
##Temp./Â°C,Time/min,DSC/(mW/mg),Mass loss/mg
51.0,10.438664234080697,-2.526511911406326,0.003181148244862264
52.100000000000016,10.697449064797103,-2.4670541728584277,0.0016733012965968186
53.20000000000003,10.834362388728492,-2.428879149896118,0.0022899646715064392
54.30000000000005,10.937492250914074,-2.39781828182416,0.001404016478371517
55.40000000000006,11.02491995733034,-2.368532065975874,0.0016061699550000696
56.50000000000008,11.102004565229556,-2.343454835910511,0.0010027683974369594
57.600000000000094,11.170467663248102,-2.320042153570553,0.001593308611743005
58.70000000000011,11.235631111882194,-2.296709712823536,0.0024529926376484212
59.800000000000125,11.294553109460029,-2.275735052544946,0.001742178169650721
60.90000000000014,11.353066325950493,-2.2534152638371903,0.0013813255326642349
62.000000000000156,11.407126450075685,-2.2339460412677474,0.0015952688996385689
63.10000000000017,11.459928395486076,-2.2145207446796054,0.0006242573553514319
64.20000000000019,11.511101111351566,-2.194437649620931,0.0008676458414980104
65.30000000000021,11.559421720546963,-2.177847653137697,-3.4530452552417046e-05
66.40000000000022,11.6071861546802,-2.160263387926374,0.0005026874518208047
67.50000000000023,11.654323148792688,-2.143221042697759,0.0012164634685234432
68.60000000000025,11.699045785992237,-2.1287434901553404,0.0007891161050643802
69.70000000000027,11.744055216683922,-2.111115694532939,5.5200662949950186e-05
70.80000000000028,11.788075199363032,-2.0948932992435063,0.00042647037623755324
71.90000000000029,11.831931731284405,-2.0799721632195847,-0.000332915199145134
73.00000000000031,11.87468363143379,-2.0662698329691507,0.0005227713916253762
74.10000000000034,11.916704414792783,-2.051105726269271,0.0007371273952605506
75.20000000000034,11.958700381290214,-2.037773947847335,-0.0010079736072050594
76.30000000000035,12.000187918688281,-2.026234647628001,0.0006062611557853259
77.40000000000038,12.040996847490467,-2.012446167336335,0.00021568273840255614
78.5000000000004,12.081355715387884,-1.9987689906721502,-0.000720183590023904
79.6000000000004,12.121596366546493,-1.9877525431180887,0.0005456289053586971
80.70000000000041,12.161733898450189,-1.9756379659037528,0.0005050929814265359
81.80000000000044,12.201877387458445,-1.9623099967257085,-0.00012167225009607208
82.90000000000046,12.24107008431112,-1.9511639727251362,-0.0015846326969208846
84.00000000000047,12.2801373233489,-1.9385212784470687,-0.0010109338371151466
85.10000000000048,12.319239711246832,-1.9254477785149449,0.0003326362839617403
86.2000000000005,12.35753080213554,-1.913758095651777,-0.0004189156892837609
87.30000000000052,12.396173545311012,-1.9021442296683622,-0.00027426298173383046
88.40000000000053,12.434600152489509,-1.890979099947166,0.0001764607834964238
89.50000000000054,12.472712687578749,-1.8797282706622782,0.0004750603394292341
90.60000000000056,12.510446355585714,-1.8678772359622569,0.00024708967534525783
91.70000000000059,12.548482327409737,-1.8549059957731828,-0.0011620658420334884
92.8000000000006,12.585720582386323,-1.8430837962280482,-0.0012113312566897072
93.9000000000006,12.623774640891334,-1.8332840271353867,-0.001298784274678333
95.00000000000063,12.66057289326352,-1.822865919380644,-0.0007456490164501339
96.10000000000065,12.698314863976648,-1.8095619118658446,-0.001180060595524779
97.20000000000066,12.735256616659122,-1.798948219056642,6.598618251008048e-05
98.30000000000067,12.772635715666752,-1.7881767812926443,-0.0012146453831158865
99.40000000000069,12.809786559173915,-1.777180543095303,-0.0011325218775954937
100.50000000000071,12.846487895546053,-1.7664377140820795,-0.0012429929961732533
101.60000000000072,12.883426405109251,-1.7552049594027777,-0.0013481261981045378
102.70000000000073,12.91987028350932,-1.7461319544156022,-0.0012243904048743204
103.80000000000075,12.957099974812689,-1.7351719750116728,-0.0012259027419094792
104.90000000000077,12.993273572485782,-1.7235690407833977,-0.0012817543902046147
106.00000000000078,13.030312676591816,-1.714186356431639,-0.001221744846567674
107.10000000000079,13.067032505704118,-1.7055590787281565,-0.0012900439963012822
108.20000000000081,13.103728550069562,-1.6933052234544408,-0.00252592652944017
109.30000000000084,13.139440259625161,-1.686116455818077,-0.002509894742166896
110.40000000000084,13.176531713591771,-1.6751231110249927,-0.00121718192318232
111.50000000000085,13.213617208044228,-1.6661119321595064,-0.001210055667502985
112.60000000000088,13.249798153783386,-1.6568406963802864,-0.001211547815640479
113.7000000000009,13.286405144292198,-1.645753759774256,-0.0026148291517769096
114.8000000000009,13.323010155322626,-1.6401233615024704,-0.0017659937072607157
115.90000000000092,13.359270241864497,-1.6296063976392348,-0.0007255756223818466
117.00000000000094,13.396123451318237,-1.621296668772965,-0.0010819266728270271
118.10000000000096,13.432052462833086,-1.6137051888013194,-0.0010999471830688279
119.20000000000097,13.468525887091232,-1.6064158824425472,-0.0010999770493502758
120.30000000000098,13.504800588441315,-1.5994937319452154,-0.0020070707681627553
121.400000000001,13.541281375179851,-1.590502460850883,-0.0010992287502658016
122.50000000000102,13.577820116010445,-1.5838756075536788,-0.0010999949541190546
123.60000000000103,13.613870197639674,-1.5762155250579495,-0.001099915065942536
124.70000000000104,13.650044984654963,-1.5693359575516772,-0.0010970641971623785
125.80000000000106,13.685602129009037,-1.5609469393737325,-0.00040180857204985543
126.90000000000109,13.721718612950315,-1.5538968747731938,-1.3804295666108857e-05
128.00000000000108,13.757999528653873,-1.5459808371954669,-0.0009263386160824894
129.1000000000011,13.793610903258639,-1.5400323644411393,-0.0010990797213303871
130.20000000000113,13.829829538780537,-1.5306407175988073,-0.0011000080932888068
131.30000000000115,13.86549765316842,-1.5239603997974,-0.0011001028393549106
132.40000000000117,13.901262384837494,-1.5172456669527876,-0.0010989125298768165
133.50000000000117,13.936893043204371,-1.5098172843614306,-0.0023611744179663496
134.6000000000012,13.972655730756411,-1.5023144189893645,-0.0021304785406308646
135.7000000000012,14.00831275961454,-1.4957540511542127,-0.00110041035648889
136.8000000000012,14.04365225758102,-1.4887413605179853,-0.0011000133235441467
137.90000000000123,14.079404962305542,-1.4816879061680719,-0.0011000001710992358
139.00000000000125,14.114993257039222,-1.4758956102096037,-0.0010978578493627822
140.10000000000127,14.149871616702743,-1.4675006343882229,-0.0012639975652546376
141.2000000000013,14.185715954182033,-1.4604044109300667,-0.0011083520913266476
142.3000000000013,14.221120679686726,-1.453782624127756,-0.0011077305149638228
143.4000000000013,14.256313927976596,-1.4476034134995903,-0.0024251797002676767
144.50000000000134,14.291475211078145,-1.4397164149788257,-0.0024199994464364494
145.60000000000133,14.326539872724881,-1.4340773871047467,-0.0024199992374693835
146.70000000000135,14.36211490545716,-1.4274933879686071,-0.002419970007780936
147.80000000000138,14.397041359088947,-1.4211861779900783,-0.002422174686803835
148.9000000000014,14.432102420210095,-1.4136433426448685,-0.0038387383144584675
150.00000000000142,14.467485828476727,-1.4056629909603409,-0.0037379975870663884
151.10000000000142,14.501759525375496,-1.4004726188137513,-0.00352429037675428
152.20000000000144,14.53687478942203,-1.3927572233151044,-0.0024206224575542556
153.30000000000146,14.571952559902043,-1.3878853355398015,-0.002420006848565137
154.40000000000146,14.60666235979189,-1.380916690079412,-0.002420006249498563
155.50000000000148,14.641450084431987,-1.3744185439206085,-0.0024199871167844833
156.6000000000015,14.6762110125646,-1.367308171790515,-0.002358308821852173
157.70000000000152,14.71094038923166,-1.3621421446564768,-0.003048240588302331
158.80000000000155,14.746200066573751,-1.3547626990430381,-0.0037351070886146864
159.90000000000154,14.780627165255455,-1.3470385794356634,-0.003728678420986231
161.00000000000156,14.815265765203357,-1.3424561420637797,-0.004079992045404879
162.1000000000016,14.849982337534268,-1.3347608991133608,-0.0050514612086098865
163.20000000000158,14.884755731043095,-1.329467904794237,-0.005049946290179186
164.3000000000016,14.91929594513668,-1.3241452356850574,-0.005049999974999775
165.40000000000163,14.954012107993716,-1.31653673534332,-0.0050500000270883305
166.50000000000165,14.988496895111552,-1.310436964329532,-0.0050499974279447635
167.60000000000167,15.022980721298307,-1.3048759399950456,-0.005049851136100347
168.70000000000167,15.057494324195908,-1.2981619478460353,-0.005075253372736288
169.8000000000017,15.09198537736886,-1.2933782951109,-0.006374004412297296
170.9000000000017,15.126595130951246,-1.286772935173029,-0.006369800697880734
172.0000000000017,15.161166145352915,-1.2813783058600041,-0.006369992457195384
173.10000000000173,15.195517707197496,-1.2784911032777637,-0.006371003287531263
174.20000000000175,15.229858016051752,-1.2717888739719287,-0.006394389773408005
175.30000000000177,15.263924000271086,-1.2648751728563024,-0.007677537608174134
176.4000000000018,15.298437447026517,-1.2590394308303914,-0.007690053696366217
177.5000000000018,15.332769249050918,-1.2539621653448185,-0.007691004309587246
178.6000000000018,15.366960771380516,-1.2504981334715584,-0.007351687708030408
179.70000000000184,15.40133237874976,-1.2454996980026865,-0.006700266235211583
180.80000000000183,15.435471185154459,-1.2392549897906453,-0.006714034760161969
181.90000000000185,15.469855105716144,-1.2351917472223202,-0.00802918623886617
183.00000000000188,15.503745410471748,-1.2312631905507398,-0.008024809481086415
184.1000000000019,15.538061334867603,-1.2274337835569902,-0.00930827826283842
185.20000000000192,15.571992241251708,-1.2225420748155502,-0.009326190623474506
186.30000000000192,15.605159602396672,-1.2184830952881438,-0.010722342780594474
187.40000000000194,15.639138613870982,-1.2147524073576141,-0.010649991166858719
188.50000000000196,15.67373985175135,-1.2103980772751743,-0.01064999134756306
189.60000000000196,15.707787396128424,-1.2072064350345066,-0.010650000039299723
190.70000000000198,15.741811533938195,-1.2025819761495684,-0.010649998816048445
191.800000000002,15.775551013901582,-1.2000757348821285,-0.010650124566267571
192.90000000000202,15.809292879934299,-1.1962713520508073,-0.010650476090250827
194.00000000000205,15.84267311070552,-1.194707007270273,-0.011840913972636535
195.10000000000204,15.87721197462402,-1.1907503011058367,-0.01197138023104527
196.20000000000206,15.910657083597151,-1.1884277168628383,-0.012048475721142538
197.3000000000021,15.944509777858508,-1.1849495358893722,-0.012653086740011421
198.40000000000208,15.978427004440551,-1.1820213166893765,-0.013299016483588666
199.5000000000021,16.01238696108934,-1.1806720389030305,-0.013290251001609743
200.60000000000213,16.046020835058474,-1.1793567247203962,-0.0133104680846019
201.70000000000215,16.079464538103647,-1.1786141994304742,-0.015272055098027426
202.80000000000217,16.113339562657103,-1.1762812293389209,-0.015590686348723182
203.90000000000217,16.146935980944157,-1.175177021296999,-0.01560210709286558
205.0000000000022,16.180761859900695,-1.1744606863025264,-0.016948650946899235
206.1000000000022,16.214310595069538,-1.1738593175567227,-0.016909045343637796
207.2000000000022,16.248084170046077,-1.1758849418476534,-0.016910076820731312
208.30000000000223,16.281884760470795,-1.1764167863159336,-0.016924128316626597
209.40000000000225,16.315434790394086,-1.178353120792747,-0.018192841545954686
210.50000000000227,16.349230235190525,-1.182244293543677,-0.018228029196610596
211.6000000000023,16.382628265809103,-1.1843602319640747,-0.01951819977873015
212.7000000000023,16.416772079674708,-1.1882737057181927,-0.019799372377228508
213.8000000000023,16.45035356481573,-1.1952991219308737,-0.021303077272709636
214.90000000000234,16.484104455907165,-1.2026296627536415,-0.022009954708645196
216.00000000000233,16.517208897526714,-1.2095804749480237,-0.021295347933310005
217.10000000000235,16.551703734126516,-1.219073148198068,-0.021491823676185184
218.20000000000238,16.585373639043816,-1.2314406582359247,-0.02260827025708867
219.3000000000024,16.618874415972265,-1.2452096923312148,-0.02394379315423789
220.40000000000242,16.652850988569234,-1.2613178317160847,-0.02390344843197001
221.50000000000242,16.686490190381022,-1.2791769713440944,-0.02528080553301404
222.60000000000244,16.72009420346171,-1.300528089700314,-0.025315111609723218
223.70000000000246,16.754165479214873,-1.324778000647795,-0.026625356019405633
224.80000000000246,16.78750198307496,-1.3517475965578272,-0.029116919666803298
225.90000000000248,16.822277994452257,-1.3832465402015588,-0.030888887560694744
227.0000000000025,16.85628424876117,-1.4187442796981429,-0.033150169986819744
228.10000000000252,16.890381754509814,-1.4572206966605246,-0.03554380079500685
229.20000000000255,16.923734618174752,-1.4994008407774662,-0.0368978068951753
230.30000000000254,16.958616552042663,-1.548188316001473,-0.03853499214711409
231.40000000000256,16.99196892139519,-1.596971855062581,-0.04017040879638101
232.5000000000026,17.02642831943736,-1.651910186701735,-0.04244967330908844
233.60000000000258,17.06128815937202,-1.709809325306509,-0.04542265464332429
234.7000000000026,17.095564042992734,-1.7647097045668019,-0.048030535464061774
235.80000000000263,17.130293796500002,-1.8251291817723265,-0.051169771424661725
236.90000000000265,17.164153861360216,-1.8810133816450525,-0.054282099563136565
238.00000000000267,17.19837432312091,-1.936685873304556,-0.057550422756277975
239.10000000000267,17.232831755918035,-1.9887579352837503,-0.0600539167743559
240.2000000000027,17.266753598733757,-2.0384667811731645,-0.0629659813107386
241.3000000000027,17.30077986063584,-2.082330872758494,-0.06642377545233602
242.4000000000027,17.33514154624407,-2.124774058133293,-0.07118606383052484
243.50000000000273,17.369137963447606,-2.158819603654291,-0.0742165918849409
244.60000000000275,17.40287405549992,-2.18944175512643,-0.07890598704479723
245.70000000000277,17.436628719142572,-2.2117682028102994,-0.08342269093293053
246.8000000000028,17.470550370448844,-2.231686604291408,-0.09048467812137684
247.9000000000028,17.504060136471242,-2.246585825102575,-0.09495239196817984
249.0000000000028,17.53772510875451,-2.2572199621924174,-0.09983983568785515
250.10000000000284,17.571580193141973,-2.265324854087308,-0.1068491333773105
251.20000000000283,17.604949162907765,-2.2684960607180056,-0.11329481187672297
252.30000000000285,17.63806071666068,-2.2711758678749976,-0.11933301379980055
253.40000000000288,17.671335456064135,-2.2724772940910145,-0.1258100542720877
254.5000000000029,17.705211108242693,-2.270364022555509,-0.13397265145667925
255.60000000000292,17.738502348048137,-2.2716480098266523,-0.14241231268084853
256.7000000000029,17.771784965175605,-2.272596004351103,-0.15027377257163232
257.8000000000029,17.805332704590043,-2.2735400760909137,-0.158338823374657
258.90000000000293,17.838209444662787,-2.275201867552973,-0.16718900770567702
260.00000000000296,17.871764419725604,-2.278061360612693,-0.17591083132083174
261.100000000003,17.9044224262236,-2.280800076624389,-0.18499109291970095
262.200000000003,17.93848118361175,-2.2849205782912687,-0.1953976409340754
263.300000000003,17.971844639486825,-2.2910500199230253,-0.2062498303701905
264.40000000000305,18.00570894573791,-2.298548244861428,-0.21677517738536478
265.50000000000307,18.039349591430252,-2.306490312608801,-0.22831219329175445
266.6000000000031,18.072711256173516,-2.312433094631751,-0.24031277022958442
267.7000000000031,18.10563417383745,-2.319452883524125,-0.2529872480491422
268.8000000000031,18.13942044618179,-2.3264604867366563,-0.2661099800051936
269.9000000000031,18.1730313851304,-2.3330872950527013,-0.2798994148849032
271.0000000000031,18.20634403441247,-2.337964589177992,-0.2929617666645692
272.10000000000315,18.23976541399963,-2.3451406723229375,-0.3066627260669943
273.2000000000032,18.273193736237857,-2.3469272977993363,-0.3199760552597417
274.30000000000314,18.30647675813109,-2.34925461210451,-0.33573196185871534
275.40000000000316,18.33979531106909,-2.350329664719483,-0.3514494525440024
276.5000000000032,18.372957872337587,-2.347585963551892,-0.36911861512169875
277.6000000000032,18.406922768044886,-2.343502701124404,-0.3860083696277328
278.70000000000323,18.439998471018335,-2.3368685583317195,-0.4034537811013883
279.80000000000325,18.47316286790003,-2.3279501186551705,-0.4209186158866163
280.9000000000033,18.50657887849391,-2.316373896772353,-0.43935715912066886
282.0000000000033,18.539408210365675,-2.3029363636716305,-0.4579330471683756
283.1000000000033,18.57268159477871,-2.285442505821068,-0.47639686389168157
284.20000000000334,18.605576787480405,-2.2657667240816264,-0.49487163065346307
285.30000000000337,18.638528484830957,-2.2434940883406265,-0.5134040479420983
286.40000000000333,18.671687598571854,-2.2144943361633613,-0.5336493040889825
287.50000000000335,18.70498683619717,-2.184257459189579,-0.5553383682301356
288.6000000000034,18.73792059204229,-2.1520039360430014,-0.5764231437446456
289.7000000000034,18.77089807889385,-2.1168429901096117,-0.5958720159483879
290.8000000000034,18.803589940407914,-2.0782494603577777,-0.6161889156683387
291.9000000000034,18.836268773962274,-2.039449147751015,-0.637511726880958
293.0000000000034,18.869375210688553,-1.9944080851982322,-0.6586653531094817
294.10000000000343,18.901657391368044,-1.9510735003579782,-0.6784413372424094
295.20000000000346,18.934052196324835,-1.9038616686526237,-0.698632222149469
296.3000000000035,18.967192274108168,-1.8560440129904205,-0.7191480003260087
297.4000000000035,18.999765266934823,-1.80864120671795,-0.7393249903136581
298.5000000000035,19.031887856155016,-1.76351854474418,-0.7585149630222179
299.60000000000355,19.065585009969837,-1.7151017024647948,-0.7785532329329543
300.70000000000357,19.09793236608562,-1.672433196038281,-0.7978173513322444
301.8000000000036,19.130213761152465,-1.6297110809425344,-0.8147240287196662
302.9000000000036,19.163216456261747,-1.5893562200176816,-0.831713191801962
304.0000000000036,19.195967736812126,-1.55449729045896,-0.848375656581783
305.1000000000036,19.229503582944865,-1.5224124804927366,-0.8650112447456815
306.2000000000036,19.262285905309785,-1.4946403306858316,-0.8809537494609652
307.30000000000365,19.29550176094989,-1.4723053518329907,-0.8954261253223423
308.4000000000037,19.3288622421589,-1.4528008066353761,-0.9096187936313842
309.5000000000037,19.36178564117208,-1.4401757773332966,-0.923800060111374
310.60000000000366,19.395092713719116,-1.4295874530608739,-0.9371404306593338
311.7000000000037,19.42824702168701,-1.422229506761151,-0.9495366735126156
312.8000000000037,19.461628074129063,-1.420435918059698,-0.9612884950149199
313.90000000000373,19.495225068702595,-1.4190357146187502,-0.9729931206865614
315.00000000000375,19.528404332365255,-1.4241695630286078,-0.9839105283489196
316.1000000000038,19.562275905160188,-1.431202272450253,-0.9950371239950195
317.2000000000038,19.595636043881306,-1.439784764938122,-1.0068308269681792
318.3000000000038,19.629109904292388,-1.4523560255638701,-1.0166998565142342
319.40000000000384,19.662834977453727,-1.4640457288564421,-1.027542540367854
320.5000000000038,19.696370563181944,-1.477277846683695,-1.0374036171152046
321.60000000000383,19.729965402517177,-1.491133493050457,-1.0462049909672202
322.70000000000385,19.763576255183015,-1.5050229392121708,-1.056183294736468
323.8000000000039,19.79685884508764,-1.5208357911907315,-1.0651506190152613
324.9000000000039,19.830834723411826,-1.53509968410707,-1.0748442694555362
326.0000000000039,19.864893770037632,-1.5485112426439906,-1.0843356673189537
327.10000000000394,19.89828365026513,-1.56458154867536,-1.0936200363044324
328.2000000000039,19.932220766989083,-1.5781907237262334,-1.1035098036252875
329.30000000000393,19.965727324215468,-1.5904968336984786,-1.1122727655527918
330.40000000000396,19.99958831640235,-1.6019243890267612,-1.1212031506117666
331.500000000004,20.033351343844245,-1.6121955341758514,-1.1289478173969334
332.600000000004,20.067193506854576,-1.6198650038323985,-1.1394275643689626
333.700000000004,20.10091661382669,-1.6286603966361706,-1.1494932130247144
334.80000000000405,20.13455933978464,-1.6350084570164949,-1.1593358020338314
335.90000000000407,20.16811391592843,-1.6383442337138934,-1.1684346416251032
337.0000000000041,20.202181625101737,-1.6433796434866705,-1.1782159703503106
338.10000000000406,20.235822972438843,-1.6415527398848044,-1.1885093015318318
339.2000000000041,20.269468742021925,-1.637790352180533,-1.1984743848138062
340.3000000000041,20.303414160795025,-1.6336809442435902,-1.2090765481806156
341.4000000000041,20.3367203077949,-1.6290490768121737,-1.2195018451511541
342.50000000000415,20.370504034183814,-1.6186519434477686,-1.2291846539434372
343.6000000000042,20.404025159028784,-1.6086104605656517,-1.2392431467997032
344.7000000000042,20.437643913286696,-1.597558532406682,-1.2490297726800534
345.80000000000416,20.4713805427106,-1.5856420561060336,-1.2586159124885046
346.9000000000042,20.504739690912658,-1.5698322776735605,-1.2692939585003566
348.0000000000042,20.538288161496645,-1.5473073375454824,-1.2785134738505701
349.10000000000423,20.571624619483604,-1.525026237249496,-1.2875705534518063
350.20000000000425,20.605467329533525,-1.4969976883743072,-1.2976211429730315
351.3000000000043,20.63832149627165,-1.4690157883660764,-1.3070618430487952
352.4000000000043,20.672070786317146,-1.4393671919625022,-1.3163728674923019
353.5000000000043,20.70563619905825,-1.4102213989847012,-1.3263689557480154
354.60000000000434,20.73901966244113,-1.3800618709702843,-1.3362428267975233
355.7000000000043,20.772497781383787,-1.3513581614089967,-1.3467706204103718
356.80000000000433,20.806233701110674,-1.324406977868643,-1.3556268990516687
357.90000000000435,20.83947567151328,-1.2978074278946876,-1.3647001425159058
359.0000000000044,20.873144707109322,-1.273858415114108,-1.3746737710187338
360.1000000000044,20.90676609534556,-1.2479488648600674,-1.3845297332557154
361.2000000000044,20.94010145277495,-1.227522253157819,-1.395526105151824
362.30000000000445,20.974030506835035,-1.2042951931509083,-1.404964753696417
363.4000000000044,21.007431505586922,-1.185354549708348,-1.4132917503309863
364.50000000000443,21.041340070098205,-1.1638771757270767,-1.4217892878676714
365.60000000000446,21.07508126654426,-1.144303797999406,-1.430698496901695
366.7000000000045,21.108643092139456,-1.123919664796941,-1.4409921465483175
367.8000000000045,21.142434311191945,-1.1058757130040808,-1.451883700256599
368.9000000000045,21.176267173682312,-1.0850118953195051,-1.4612177854006063
370.00000000000455,21.209848031400664,-1.063750614220938,-1.4697883956243172
371.10000000000457,21.243340206024588,-1.0442722528511146,-1.4784655477955333
372.2000000000046,21.27730555742422,-1.0218258198782872,-1.4884330896733364
373.30000000000456,21.311106855321622,-1.0016475944263694,-1.4978434044088198
374.4000000000046,21.344778195636717,-0.9783078470227081,-1.5064048415875324
375.5000000000046,21.378860192633805,-0.9555078781097822,-1.5155995897608703
376.6000000000046,21.412121566138836,-0.9345800243983008,-1.5235808639722
377.70000000000465,21.446254781834728,-0.9131630173016272,-1.5325830686585142
378.8000000000047,21.479754019867276,-0.8901355460240019,-1.541150892740926
379.9000000000047,21.51388023629924,-0.8685306467203794,-1.5498007468766333
381.00000000000466,21.547440044587603,-0.8457090120897552,-1.5582628336365203
382.1000000000047,21.581522189193926,-0.8242336875025789,-1.5672293211397288
383.2000000000047,21.615475097747105,-0.8017191955183817,-1.574692865281512
384.30000000000473,21.648863196182496,-0.7818047196311912,-1.5820120539514173
385.40000000000475,21.68294017809074,-0.7616954441916137,-1.5899690750718505
386.5000000000048,21.717091631220796,-0.7422638134511905,-1.5967818445101685
387.6000000000048,21.750952106238234,-0.7235071136642939,-1.6046601216838612
388.7000000000048,21.784796930763147,-0.7048355719542422,-1.6124702235697526
389.80000000000484,21.81877057233085,-0.6876810096122555,-1.618655385546003
390.9000000000048,21.85283473127064,-0.6692025985732974,-1.6264646990132823
392.00000000000483,21.8869088244714,-0.6537747945642425,-1.633570539594456
393.10000000000485,21.921016705239655,-0.6370060530232808,-1.6395008848991988
394.2000000000049,21.954938061830475,-0.6229033127900346,-1.6461040782998952
395.3000000000049,21.988982366869294,-0.6075189675287817,-1.6528860789640731
396.4000000000049,22.023150768423783,-0.595316392616341,-1.6591788516587456
397.50000000000495,22.057253023864217,-0.5810526414170015,-1.6655080895240109
398.6000000000049,22.091544545424657,-0.5666408533734387,-1.6713426102971671
399.70000000000493,22.125026339170507,-0.5536970705480686,-1.6785699692473464
400.80000000000496,22.159486054390975,-0.5457635143138329,-1.6855514530378648
401.900000000005,22.193434848159885,-0.534071896411142,-1.6911059789369745
403.000000000005,22.227754766708266,-0.5209365843566482,-1.6988699791092303
404.100000000005,22.261921197816267,-0.5133311968951556,-1.7055584780198365
405.20000000000505,22.2963664916621,-0.503487564247506,-1.7115911766287
406.30000000000507,22.330311936856145,-0.4979062412075619,-1.7185595100962523
407.4000000000051,22.364751195375323,-0.49223114313720256,-1.7251765758608895
408.50000000000506,22.3993934078967,-0.4851197206919683,-1.732226136278289
409.6000000000051,22.43350412414134,-0.4783320719740885,-1.7394474860592193
410.7000000000051,22.467273961736115,-0.47734933296902926,-1.7463983291498826
411.8000000000051,22.50237653531827,-0.47592846425649976,-1.75338418088679
412.90000000000515,22.537002904882012,-0.47450674819948935,-1.7608558230586087
414.0000000000052,22.57183066640363,-0.4758776360993122,-1.768647656424625
415.1000000000052,22.606459819911446,-0.4790478156032837,-1.7763732957638156
416.20000000000516,22.640871528714516,-0.48443179210440207,-1.782939034846557
417.3000000000052,22.675412066349942,-0.4907188976579076,-1.79031898387088
418.4000000000052,22.7100810498131,-0.4986258466199608,-1.7967328170258794
419.50000000000523,22.74489300498394,-0.5063507415363356,-1.8040719586242675
420.60000000000525,22.779426635230582,-0.5174145474160106,-1.8121341133440638
421.7000000000053,22.81423559906644,-0.530664238443531,-1.8199964937530129
422.8000000000053,22.848888737635676,-0.5442827076069616,-1.8275035901909091
423.9000000000053,22.884256211882704,-0.5598078557664183,-1.8345271071451
425.00000000000534,22.919014395752235,-0.5734183987581798,-1.8422451834334832
426.1000000000053,22.95341314754221,-0.5932236489200137,-1.8496007012944085
427.20000000000533,22.988756343199704,-0.6119230825851082,-1.8575746497294205
428.30000000000535,23.02351769110528,-0.6276248873776183,-1.865339394747905
429.4000000000054,23.058275836766665,-0.6457652198759379,-1.8721383638569153
430.5000000000054,23.09312780097762,-0.6663461252142125,-1.8801092108174728
431.6000000000054,23.12837544436973,-0.6838327595026613,-1.8881203317915172
432.70000000000545,23.163282709205703,-0.7032359866518146,-1.8955144774740762
433.8000000000054,23.197940573858684,-0.7251091443365834,-1.903884091339528
434.90000000000543,23.23322375908046,-0.7412958246077759,-1.9105236782912653
436.00000000000546,23.268253926965475,-0.7582440564101293,-1.9178910121738775
437.1000000000055,23.303211723777338,-0.7759099011893354,-1.9259200440982487
438.2000000000055,23.33828846504686,-0.792137533423136,-1.9332118158951648
439.3000000000055,23.373012610955488,-0.8073467654635158,-1.9406666031778665
440.40000000000555,23.40818768165237,-0.8225142694612254,-1.9480445115726548
441.50000000000557,23.443212107994352,-0.837168818722604,-1.9561928508757385
442.6000000000056,23.478369561799987,-0.8518646953899311,-1.9651075217673588
443.70000000000556,23.51343352538013,-0.8636058117628101,-1.9727776156237185
444.8000000000056,23.548439701885634,-0.878748779936463,-1.9784759626589543
445.9000000000056,23.5833500937387,-0.8908435802832098,-1.9859352472234044
447.0000000000056,23.618336030757334,-0.9007763245223049,-1.9931047583906105
448.10000000000565,23.653437818381825,-0.9127362974794491,-2.000982431366932
449.2000000000057,23.68869150982817,-0.9212030468286069,-2.0084040258002913
450.3000000000057,23.723790211466007,-0.9320110120208228,-2.0160867524016775
451.40000000000566,23.758849143483694,-0.9433696518879191,-2.0241299105736332
452.5000000000057,23.793602581647818,-0.9515347313284661,-2.0314473859608784
453.6000000000057,23.82889309426253,-0.9609861086390186,-2.0390747411813583
454.70000000000573,23.863935297242758,-0.968410801375687,-2.044920774681647
455.80000000000575,23.898911225314905,-0.9757693894392461,-2.0524507974657276
456.9000000000058,23.933883300389063,-0.9818352667155487,-2.059916849562037
458.0000000000058,23.96891441102281,-0.9904247830280694,-2.0677492696721176
459.1000000000058,24.004425225187735,-0.9978680631489505,-2.0760908669654645
460.20000000000584,24.039611260629474,-1.0028619668868708,-2.0832263533415354
461.3000000000058,24.07439196800973,-1.008766021879464,-2.0906209200239303
462.40000000000583,24.10958275793294,-1.0156585726411032,-2.100026001079078
463.50000000000585,24.144741923640613,-1.0196840129614695,-2.1063362576545064
464.6000000000059,24.179547881049956,-1.0267185407118793,-2.114570373228805
465.7000000000059,24.214884962233658,-1.032247990621133,-2.1222587696132624
466.8000000000059,24.25024160537042,-1.0383840797217663,-2.1285588111624945
467.90000000000595,24.28534323085031,-1.0426915073432192,-2.1366195673183688
469.0000000000059,24.320525508526504,-1.0484713738162212,-2.143496097003492
470.10000000000593,24.355480638507256,-1.0528364469434626,-2.1514057983053947
471.20000000000596,24.390817312389977,-1.0570749414409413,-2.1592455650945204
472.300000000006,24.4261064003738,-1.063318171808061,-2.165451908056025
473.400000000006,24.461173335291456,-1.0676422999917574,-2.1732041122749797
474.500000000006,24.496418936041547,-1.071288731262237,-2.1796358267797813
475.60000000000605,24.530667277466677,-1.0760929669959765,-2.186794907965565
476.70000000000607,24.56659792773481,-1.0825393563929893,-2.193694672720083
477.8000000000061,24.601842029715637,-1.0856980927703377,-2.2003323547324563
478.90000000000606,24.636706578304867,-1.0901083082249898,-2.206973536445831
480.0000000000061,24.672168688357043,-1.094131647067372,-2.2138297163252862
481.1000000000061,24.707329350133254,-1.0996466809922243,-2.2214075280531476
482.2000000000061,24.742644191433257,-1.1037938199471216,-2.227614183595823
483.30000000000615,24.777563300665733,-1.107710436176124,-2.2341727257417316
484.4000000000062,24.812873463522603,-1.1112062307876447,-2.240798633219975
485.5000000000062,24.848600864795756,-1.1155187175577712,-2.247505969412907
486.60000000000616,24.883790286031726,-1.1184006993862656,-2.2534893474188076
487.7000000000062,24.918758719915623,-1.1212897729870699,-2.260480280433184
488.8000000000062,24.954167476182793,-1.1265010709117391,-2.266308488560484
489.90000000000623,24.989137334308197,-1.127737964510709,-2.273171856083037
491.00000000000625,25.024230976447647,-1.1299297509900923,-2.280229190093837
492.1000000000063,25.059745909597314,-1.1326736823938617,-2.2865618492098747
493.2000000000063,25.09511173929897,-1.1368374370319014,-2.295488514055058
494.3000000000063,25.13015547736717,-1.139060852296118,-2.301410223967525
495.40000000000634,25.165660170671845,-1.141016236013001,-2.3088650860148205
496.5000000000063,25.200790979832902,-1.1435344020860945,-2.3151353081218424
497.60000000000633,25.236335006209487,-1.1458998606922,-2.3212069121537984
498.70000000000636,25.270952133142984,-1.148835008510119,-2.3273179810956934
499.8000000000064,25.306395989777048,-1.1511801928842675,-2.333812887058003
500.9000000000064,25.341905063545404,-1.154568877234719,-2.340597392446744
502.0000000000064,25.376877813205745,-1.1565236520568503,-2.3487251601892334
503.10000000000645,25.412039119642216,-1.161085442456482,-2.3557020511275977
504.2000000000064,25.44761808695941,-1.162232183286095,-2.3631778832485355
505.30000000000643,25.48299635597338,-1.1661129816455955,-2.36966009046363
506.40000000000646,25.518155185939097,-1.1686118483946437,-2.3759813168588684
507.5000000000065,25.553884593496097,-1.1694423212931924,-2.384081909537917
508.6000000000065,25.589106417262006,-1.1717391090890235,-2.39062564681562
509.7000000000065,25.624314308390147,-1.1746606628847829,-2.3979663938269704
510.80000000000655,25.659878848145052,-1.1778892101672631,-2.404553042185482
511.90000000000657,25.695071785892836,-1.1820457453881077,-2.411283033008324
513.0000000000066,25.730247242636228,-1.1830507060194446,-2.4178327089833793
514.1000000000065,25.766094958358774,-1.1854123339065574,-2.4245664485112446
515.2000000000066,25.801520704464487,-1.1887321937211892,-2.4330375912146116
516.3000000000065,25.83630166703248,-1.1921578363407617,-2.4386811794898247
517.4000000000067,25.87177476813793,-1.1950667251392662,-2.445875607997972
518.5000000000066,25.9078819899597,-1.1972610611959864,-2.452857507169771
519.6000000000067,25.943327499090195,-1.2007316948846865,-2.4600537658819235
520.7000000000066,25.97863268142577,-1.203541905103657,-2.4677385592806953
521.8000000000067,26.01478151301281,-1.2076193802322293,-2.474815974957542
522.9000000000067,26.05013688886596,-1.2101074374388605,-2.4822786855912327
524.0000000000067,26.085790480042828,-1.2117058068476685,-2.488412774444385
525.1000000000067,26.12125818017088,-1.2172793933916122,-2.4956839056156213
526.2000000000068,26.156802849973577,-1.220877323514101,-2.5034652653586384
527.3000000000068,26.1923661025549,-1.224624130603109,-2.5097758392724905
528.4000000000068,26.22788088454621,-1.2276746516212338,-2.5169950578832765
529.5000000000068,26.263224943120054,-1.2311603487285017,-2.5240885289083543
530.6000000000068,26.299010228099277,-1.2339973715088965,-2.531579181264795
531.7000000000069,26.334519795806134,-1.2365748742137705,-2.537682867108362
532.8000000000068,26.370126731003126,-1.240492436395047,-2.5445888488831283
533.9000000000069,26.405801857818606,-1.243002568794511,-2.551875724881855
535.0000000000068,26.441227611565754,-1.2487864542410674,-2.557817869958247
536.100000000007,26.477037989073928,-1.2499039700205608,-2.564858260162913
537.2000000000069,26.5125607904028,-1.2545212550134552,-2.570366110450947
538.300000000007,26.548258112787583,-1.2574610557436692,-2.5778419973063484
539.4000000000069,26.583792210524948,-1.2633270152669467,-2.5836940533497925
540.5000000000069,26.619740019952395,-1.2679627082776423,-2.5897960934723465
541.600000000007,26.655213863711175,-1.2712470925083412,-2.59584779302375
542.700000000007,26.6905246592634,-1.276533787148847,-2.6010880359655157
543.800000000007,26.72695227947631,-1.281607725852438,-2.607845054998471
544.900000000007,26.762352761411403,-1.2853902771751327,-2.6132791297523306
546.000000000007,26.798165965636574,-1.290072947018691,-2.6193641783997945
547.1000000000071,26.83418299251725,-1.2973684324136625,-2.624741424920108
548.2000000000071,26.86983354639826,-1.3026037034755982,-2.6308875350713863
549.300000000007,26.9056191939977,-1.3078904274939043,-2.636721415214553
550.4000000000071,26.94133664738637,-1.3121319536013718,-2.6411239431884175
551.500000000007,26.97725351149672,-1.3179872700445814,-2.6462957931230227
552.6000000000072,27.012787744652538,-1.3231241417176038,-2.6518038587191826
553.7000000000071,27.048635272633568,-1.3272367032749472,-2.6573374072977547
554.8000000000072,27.084464705041825,-1.3309995471919966,-2.6627301244039754
555.9000000000071,27.120544913305928,-1.3364534472708487,-2.6680695280407845
557.0000000000072,27.156235193163866,-1.3405638436453111,-2.6733719184554166
558.1000000000072,27.192177515855004,-1.3456400464792035,-2.6777576921545245
559.2000000000072,27.228036267746823,-1.3487532284701829,-2.6819113189730652
560.3000000000072,27.263513596038415,-1.3540838539143785,-2.686013610003343
561.4000000000073,27.299642892199113,-1.3583560980520133,-2.6900012833285545
562.5000000000073,27.335658279837485,-1.3635055793185344,-2.69297936205244
563.6000000000073,27.371455450190993,-1.367080599221855,-2.6974694021454413
564.7000000000073,27.407332233965,-1.3726157747545444,-2.702723082517195
565.8000000000073,27.443190437085715,-1.3757363091223678,-2.7074714302456653
566.9000000000074,27.479267018713724,-1.3805529491757114,-2.7106021110125273
568.0000000000074,27.515162778153552,-1.38459726478846,-2.713518531368023
569.1000000000074,27.550969088518258,-1.3874000253497125,-2.7171527662967607
570.2000000000073,27.586813052319027,-1.390500864445241,-2.7216331604473964
571.3000000000073,27.622817948509624,-1.395243374318123,-2.726378312545732
572.4000000000074,27.658866191118047,-1.399435562317616,-2.730824120936373
573.5000000000074,27.69446877520376,-1.404108799054771,-2.734805087400349
574.6000000000074,27.73073570512995,-1.4082253688612163,-2.7381946411200535
575.7000000000074,27.766527533653207,-1.412378281453467,-2.7403773535294347
576.8000000000075,27.801840411454283,-1.415787207760687,-2.743930173165407
577.9000000000075,27.838470094702704,-1.4225356595303882,-2.747562053372837
579.0000000000075,27.874543049039367,-1.428233929496271,-2.751338259782952
580.1000000000075,27.91079574603771,-1.430796013521502,-2.7548744787602963
581.2000000000075,27.946842201513576,-1.4349215692328392,-2.7580365543566723
582.3000000000076,27.982553475807048,-1.4406958180080867,-2.761318773552908
583.4000000000076,28.018844991977986,-1.4446495446362342,-2.7653751550801933
584.5000000000076,28.05473898836255,-1.4494986433854862,-2.767632574803691
585.6000000000076,28.090717026738805,-1.4527266567280497,-2.7713762837363483
586.7000000000077,28.126893278856063,-1.4568520815226944,-2.7749250300146215
587.8000000000077,28.163002773784584,-1.46200911132123,-2.7775835246266167
588.9000000000076,28.19849650742747,-1.4656774659372198,-2.77925337945678
590.0000000000076,28.235045871340354,-1.4701387724456592,-2.7815201365043665
591.1000000000076,28.2710895604656,-1.4757443820503457,-2.783186240249183
592.2000000000077,28.307199679516554,-1.47938305677485,-2.786539620587198
593.3000000000077,28.343583719233813,-1.4857190779489775,-2.7897990270229767
594.4000000000077,28.37982708827423,-1.4909116537709028,-2.7930606908532662
595.5000000000077,28.41573188756773,-1.4961002817239237,-2.7957356942803044
596.6000000000078,28.45182997398676,-1.5016670441113384,-2.798444858476543
597.7000000000078,28.487338088250908,-1.5077043356536184,-2.8006766130710545
598.8000000000078,28.524061947963062,-1.5146216992385706,-2.802345298057964
599.9000000000078,28.560167185176443,-1.5204877725816066,-2.804350629622922
601.0000000000078,28.596870638993977,-1.527909139986565,-2.806341379246199
602.1000000000079,28.63278117868334,-1.5355657431745866,-2.8089378309871114
603.2000000000079,28.668870872866833,-1.5418037780475873,-2.811197069094057
604.3000000000079,28.705100861934625,-1.548906628620746,-2.8145545687969573
605.4000000000078,28.741361719124235,-1.5560466956726762,-2.8161361215952696
606.5000000000078,28.77744905858359,-1.5620294733787132,-2.8178990167025053
607.6000000000079,28.81386640803764,-1.570342951608826,-2.8193823745310613
608.7000000000079,28.850131147635555,-1.57491629719169,-2.8208761981223276
609.8000000000079,28.88625590855253,-1.5834655023333548,-2.823234284842737
610.9000000000079,28.922365405259168,-1.5899152855580114,-2.8254589869588633
612.000000000008,28.9584949381128,-1.59488970945368,-2.828753037677103
613.100000000008,28.99472988283001,-1.6041348905974757,-2.8302809657877024
614.200000000008,29.03060261602682,-1.6116083989161403,-2.831764627470517
615.300000000008,29.06727356313389,-1.6207580234339263,-2.8334433022573693
616.400000000008,29.103743372863256,-1.6290927977508647,-2.834786199361976
617.5000000000081,29.140104633262037,-1.6355668134673185,-2.8361438723982406
618.6000000000081,29.17590307076273,-1.643782043256976,-2.8380280175346337
619.7000000000081,29.212152917455303,-1.6524952691835961,-2.8389256929271394
620.8000000000081,29.24873920487483,-1.6612537138018861,-2.8400646889321344
621.9000000000082,29.285093308656275,-1.6691188927978862,-2.841769419379153
623.0000000000082,29.32131319714448,-1.6771183843149593,-2.8433116591678855
624.1000000000081,29.357753902967247,-1.684784699387127,-2.8444358446508735
625.2000000000081,29.39390027862253,-1.6940236524870174,-2.8466190582586606
626.3000000000081,29.430034526761865,-1.7021938735546975,-2.8480925766371263
627.4000000000082,29.46654284427885,-1.7111851060729175,-2.849657063855328
628.5000000000082,29.50239837760181,-1.7198074501108969,-2.849848814045024
629.6000000000082,29.539036698078327,-1.727468084958252,-2.8505197065496595
630.7000000000082,29.57562563974971,-1.738117317561736,-2.8521603690776907
631.8000000000083,29.611611396493842,-1.747285073756594,-2.85355737208056
632.9000000000083,29.648012674153176,-1.7583107369415474,-2.855016724698355
634.0000000000083,29.684388145511186,-1.7660165682938818,-2.8564319520532004
635.1000000000083,29.720774145187878,-1.7748047835358396,-2.85683374065773
636.2000000000083,29.75710410503453,-1.783917917095776,-2.8576952135935265
637.3000000000084,29.79354232234847,-1.7928686546806707,-2.859100711395857
638.4000000000084,29.829702536775095,-1.8026838913510563,-2.8604243402345726
639.5000000000084,29.866293357349846,-1.8124978080516292,-2.8605733295286875
640.6000000000083,29.902701857140652,-1.8196627115208215,-2.860412045135306
641.7000000000083,29.93896723270208,-1.8303149515088797,-2.861053372292802
642.8000000000084,29.975167720910434,-1.8420685665519416,-2.8623129721027474
643.9000000000084,30.011688850663656,-1.8517448716570861,-2.863159427105831
645.0000000000084,30.048329789797425,-1.8611544238401228,-2.864364831843954
646.1000000000084,30.084725891885043,-1.8709740394288847,-2.865622843464099
647.2000000000085,30.120995290686324,-1.8810897345896145,-2.8665036946501155
648.3000000000085,30.15728971560502,-1.8927896384019733,-2.8679239343423535
649.4000000000085,30.19386598092955,-1.9019751950711616,-2.868345506040707
650.5000000000085,30.23019019336799,-1.913064755404978,-2.869738933718506
651.6000000000085,30.266803556291215,-1.9248245243141398,-2.869737047119812
652.7000000000086,30.30329427505131,-1.9327074175989973,-2.87077359046899
653.8000000000086,30.339664658498958,-1.9398402804366421,-2.872516076653354
654.9000000000086,30.375873969662354,-1.951343649719631,-2.8724391666163873
656.0000000000086,30.412433217906344,-1.9632430604940097,-2.8738134618483
657.1000000000087,30.44884394827284,-1.9730245064140237,-2.875118769295079
658.2000000000087,30.485530005642463,-1.9832105558360702,-2.8751480417843798
659.3000000000086,30.52167091425677,-1.9921132424722745,-2.876089089417389
660.4000000000086,30.55812298211421,-2.003288253757677,-2.8765021219198963
661.5000000000086,30.594907012182425,-2.011959020418645,-2.8754470978379065
662.6000000000087,30.631389760430263,-2.019626320248404,-2.876421176198452
663.7000000000087,30.667490322953224,-2.0312885438737,-2.8777726348018273
664.8000000000087,30.70411494347473,-2.0408007387569453,-2.879003129371608
665.9000000000087,30.740643143462115,-2.05204794326922,-2.8790772776484848
667.0000000000088,30.77720237294038,-2.0616507119312093,-2.8803789021479145
668.1000000000088,30.813571781370847,-2.071768681494487,-2.8804403234732945
669.2000000000088,30.850214257887473,-2.0813865360584773,-2.881713407594468
670.3000000000088,30.886455616822232,-2.093408337746841,-2.881723405855682
671.4000000000088,30.92314779919219,-2.105473240866454,-2.883081262275477
672.5000000000089,30.95977498555321,-2.11184881114889,-2.8830502739961403
673.6000000000089,30.996065863377392,-2.1231204065341203,-2.884331265243722
674.7000000000089,31.032372083652678,-2.135116728438906,-2.8849898033462855
675.8000000000088,31.069135214182786,-2.146660646807507,-2.884356239299361
676.9000000000088,31.105564171823804,-2.1553091486624747,-2.884962356454144
678.0000000000089,31.142364436332304,-2.1641293052384847,-2.885666484008343
679.1000000000089,31.17883624325038,-2.1734365639089064,-2.8869654476811304
680.2000000000089,31.214931520813625,-2.182029419039851,-2.8875265533325027
681.3000000000089,31.250958110518336,-2.194337056582012,-2.8882991164910923
682.400000000009,31.288095500281948,-2.204856321694214,-2.888860592871196
683.500000000009,31.324699909616356,-2.2139664817125735,-2.8896095334070253
684.600000000009,31.361120594628073,-2.222312377925551,-2.890434309952269
685.700000000009,31.39746360522045,-2.2359061443469197,-2.8909318730804827
686.800000000009,31.43418481321135,-2.2455327886036818,-2.891194145575977
687.9000000000091,31.470751788445668,-2.2562639309316244,-2.8922527997138716
689.0000000000091,31.50724314126262,-2.264837655773522,-2.8922427460243103
690.1000000000091,31.543843746150625,-2.2755750673124195,-2.893561410830376
691.2000000000091,31.580343554447374,-2.282996556495943,-2.895118467268629
692.3000000000092,31.616169129439744,-2.292422799839286,-2.8944527519098524
693.4000000000092,31.652835005969752,-2.3021707753305782,-2.8940803448937267
694.5000000000091,31.689103575283657,-2.311108446067051,-2.893780450502458
695.6000000000091,31.726406960625834,-2.3211364244329857,-2.8949803297030625
696.7000000000091,31.762890345347824,-2.3307467129695327,-2.8952829544768433
697.8000000000092,31.799735834605944,-2.3400668681068657,-2.896411088996289
698.9000000000092,31.836186098352965,-2.347214780930445,-2.896411727105643
700.0000000000092,31.872620385217537,-2.358403061247075,-2.8966991984039936
701.1000000000092,31.909170655896997,-2.367830185719918,-2.8977297694521846
702.2000000000093,31.946082126563482,-2.3771644262278815,-2.8979048587954095
703.3000000000093,31.98281781227513,-2.3866293683083724,-2.8977590860564013
704.4000000000093,32.019472506341366,-2.397109013707602,-2.897737763748249
705.5000000000093,32.056050697750706,-2.405119910505775,-2.899100993984238
706.6000000000093,32.09262987854343,-2.4129462021566597,-2.9004821494267503
707.7000000000094,32.12916965960668,-2.426069888067019,-2.9017299423353293
708.8000000000094,32.165375422357656,-2.4324806621261863,-2.9016703617188058
709.9000000000094,32.20261616149054,-2.441049078968951,-2.9029816551743894
711.0000000000093,32.23952910720936,-2.4530519204522503,-2.9041207735541192
712.1000000000093,32.275860771176426,-2.459177864550548,-2.9030092412172848
713.2000000000094,32.312759649336975,-2.470520790126501,-2.9029743227898557
714.3000000000094,32.34936335844059,-2.4773175800393084,-2.904328425876218
715.4000000000094,32.38582672260586,-2.48230771837241,-2.9049796607593033
716.5000000000094,32.42275757259496,-2.4905930960470943,-2.9043347501151917
717.6000000000095,32.45967211847735,-2.4971778310589454,-2.9056419257565205
718.7000000000095,32.496297376880364,-2.504753787651452,-2.905635203631892
719.8000000000095,32.532951523213086,-2.5113808356433167,-2.9073657829810076
720.9000000000095,32.56937094986524,-2.517520969231592,-2.9074118304085363
722.0000000000095,32.60686448573026,-2.5253746328181426,-2.9087192076730926
723.1000000000096,32.64334890088114,-2.5307906956040775,-2.9087196173272205
724.2000000000096,32.68001275356842,-2.5386848004415197,-2.9091178769787955
725.3000000000096,32.71692994297317,-2.5441886631918944,-2.908749215384171
726.4000000000096,32.753517342140796,-2.5535956187426705,-2.91005524542832
727.5000000000097,32.79014746151549,-2.5592993459642424,-2.911530601125144
728.6000000000097,32.827213748045345,-2.5636879887255124,-2.9121793587929043
729.7000000000096,32.86365024070291,-2.570398838771004,-2.913004235679516
730.8000000000096,32.900838905943964,-2.5773699245867645,-2.9142877234510847
731.9000000000096,32.93738541857814,-2.5818179705908797,-2.915296826177123
733.0000000000097,32.97441333712247,-2.5877429544600954,-2.915788720264333
734.1000000000097,33.01099919649983,-2.5935537834319455,-2.9166202090315525
735.2000000000097,33.047652578029414,-2.599474180931585,-2.916562199262734
736.3000000000097,33.08444360846832,-2.6037164148021614,-2.9169504539239943
737.4000000000098,33.121434040648126,-2.610613905988535,-2.9177945315625413
738.5000000000098,33.157940653345584,-2.6140717572782792,-2.9182282948935656
739.6000000000098,33.19522807652589,-2.6163422588361183,-2.9195694893578854
740.7000000000098,33.23191200362155,-2.6235021002005516,-2.9195759671663772
741.8000000000098,33.26876930492556,-2.628776374936124,-2.9209070164533237
742.9000000000099,33.30545566260236,-2.630099025379625,-2.9222921910078417
743.0000000000098,33.30882840020372,-2.630544541200974,-2.922225431735852