File: 01_Data/PU_Aerogel/STA/N2/3K_min/PU_Aerogel_STA_N2_3KData_231215_R1.csv
##Temp./Â°C,Time/min,DSC/(mW/mg),Mass loss/mg
50.0,10.01917,-2.52115,-0.0037280869518179216
51.100000000000016,11.420248580363598,-2.461721562021307,-0.0030552429012882243
52.20000000000003,11.917557152796121,-2.4380492423606452,-0.00462080806084586
53.30000000000005,12.378231037317171,-2.422591529703375,-0.0029672314192961124
54.40000000000006,12.791286689536864,-2.412851159149041,-0.0051977862109913175
55.50000000000008,13.195515280142592,-2.405612575571394,-0.0035865583716230276
56.600000000000094,13.597966496052784,-2.40189501418858,-0.004949243571333639
57.70000000000011,13.982229658159511,-2.393847205406625,-0.004924175429964706
58.800000000000125,14.370631023618131,-2.3874288464920035,-0.0035439979795963694
59.90000000000014,14.754023083183965,-2.381968709907883,-0.0030801747347304342
61.000000000000156,15.127362215892738,-2.377399894673364,-0.004828949746729094
62.10000000000017,15.50085508771271,-2.373777153046206,-0.004060424528625539
63.20000000000019,15.871897014353545,-2.3701838552214167,-0.005720334476611022
64.30000000000021,16.243541777891362,-2.3640340326435663,-0.006679979647274514
65.40000000000022,16.61844179716392,-2.360373539486328,-0.008327296744253587
66.50000000000023,16.987317299608936,-2.355303000384894,-0.005819372437640524
67.60000000000025,17.353553006542803,-2.3515939840870628,-0.005058877250191607
68.70000000000027,17.7169226548563,-2.3457249935768782,-0.005049287673755565
69.80000000000028,18.076227414124105,-2.341815714284907,-0.007302002714506983
70.90000000000029,18.45422410438349,-2.336513128338155,-0.006043164631239328
72.00000000000031,18.81836815781918,-2.33230920101522,-0.007634995063741101
73.10000000000034,19.164694639628042,-2.3286651414557062,-0.006478845197809946
74.20000000000034,19.55425825707598,-2.3243554860109943,-0.0087798860107835
75.30000000000035,19.913462442673517,-2.320577654748381,-0.00812310167235708
76.40000000000038,20.27874828210962,-2.3150661350284114,-0.008345872143238786
77.5000000000004,20.636828926057593,-2.3111478296669423,-0.009669952850301478
78.6000000000004,21.002820621316452,-2.3063082628086002,-0.009332362940674521
79.70000000000041,21.36834621382746,-2.3031022764602955,-0.008350060158401895
80.80000000000044,21.70037194272706,-2.2973847762137987,-0.007376886985468012
81.90000000000046,22.090167211420518,-2.293617112493559,-0.009339988023360668
83.00000000000047,22.453373432495663,-2.2916286742719,-0.010249837510508009
84.10000000000048,22.8161763995728,-2.2860212638038178,-0.008993133431300038
85.2000000000005,23.179170000000333,-2.281280000000012,-0.011559871241540343
86.30000000000052,23.54782619539408,-2.278074767693451,-0.010319883285332843
87.40000000000053,23.912896561524256,-2.273037865203416,-0.011639453076227824
88.50000000000054,24.26961011953288,-2.2695710866435204,-0.010330158530204692
89.60000000000056,24.631947284106065,-2.265578447593725,-0.009999911835167019
90.70000000000059,24.993166785097376,-2.2610883943804185,-0.011312708493104395
91.8000000000006,25.34589443402194,-2.256767523046997,-0.013242561903422434
92.9000000000006,25.714295037928817,-2.2537109687750534,-0.012375255005895092
94.00000000000063,26.075069532412712,-2.250587873329289,-0.010666879238093507
95.10000000000065,26.434976746032138,-2.245955900045432,-0.01116644826870683
96.20000000000066,26.791297864776258,-2.242189774942712,-0.011508352948445655
97.30000000000067,27.15618027069145,-2.23727966342429,-0.011247313346328447
98.40000000000069,27.512579507769008,-2.233555227332156,-0.011310099014473884
99.50000000000071,27.878342886947305,-2.2310503380085662,-0.012644878435334128
100.60000000000072,28.233905438333014,-2.2261196305307425,-0.011304759222349858
101.70000000000073,28.607388378620094,-2.222810100741552,-0.011079327543899176
102.80000000000075,28.958039248744484,-2.2186254983258924,-0.011443650094301816
103.90000000000077,29.31841750789869,-2.21301006955816,-0.013070062337211752
105.00000000000078,29.674213603972728,-2.210650137448924,-0.012379637174981362
106.10000000000079,30.038146591289262,-2.205432919482813,-0.015071044752027696
107.20000000000081,30.397906922792828,-2.2009301667379426,-0.012715714173268111
108.30000000000084,30.759914087051474,-2.1969057483222603,-0.012419138377709693
109.40000000000084,31.117536690790004,-2.1929200364133283,-0.012480204213770385
110.50000000000085,31.47727760855887,-2.188126096760965,-0.013730100065239448
111.60000000000088,31.835208770950345,-2.184679618816632,-0.01373433851446837
112.7000000000009,32.19238686554105,-2.1810312069489233,-0.013364198138665628
113.8000000000009,32.5605062770374,-2.176092491377489,-0.014719755422039071
114.90000000000092,32.918006734410454,-2.1727260436223195,-0.013554749686007561
116.00000000000094,33.27382902258585,-2.168676422298499,-0.014716090678700056
117.10000000000096,33.634927436580256,-2.1648702483969173,-0.01406441347671361
118.20000000000097,34.0017575901541,-2.1603480456938384,-0.015704455420097574
119.30000000000098,34.34845691217805,-2.1573553092779965,-0.015710048279021116
120.400000000001,34.7064795688495,-2.153320190628669,-0.016477884801758158
121.50000000000102,35.068337645946194,-2.150647657972706,-0.016470198006171444
122.60000000000103,35.42449153751461,-2.14646107435322,-0.015206724189277487
123.70000000000104,35.786152153724586,-2.142303948906139,-0.01581235399305747
124.80000000000106,36.14212858765356,-2.140779099419541,-0.01703408828675279
125.90000000000109,36.50505033881392,-2.1365140634095336,-0.0164049567181328
127.0000000000011,36.84606202175697,-2.1322060759010584,-0.01679569496307831
128.1000000000011,37.21774905966388,-2.1299811181605537,-0.016733594096793425
129.20000000000113,37.575274895509665,-2.1269870553008627,-0.017016556599205757
130.30000000000115,37.93393153298133,-2.1227661780458487,-0.016960148439752132
131.40000000000117,38.28946749527165,-2.1172617178260453,-0.01728651318892105
132.50000000000117,38.64985851150184,-2.1134599765389233,-0.019406666615363832
133.6000000000012,39.005297682862334,-2.1098838564556126,-0.018549283540932215
134.7000000000012,39.360403874875466,-2.105800706560824,-0.020546886503215234
135.8000000000012,39.71917000000037,-2.102379999999988,-0.019219990166310374
136.90000000000123,40.077682412920325,-2.099578555527621,-0.020539457880374368
138.00000000000125,40.43821857181586,-2.09775964619177,-0.021405886716168165
139.10000000000127,40.79680404361109,-2.0945274204728297,-0.02008974881134895
140.2000000000013,41.154790552347826,-2.091008536463015,-0.020089869521221715
141.3000000000013,41.513615964893994,-2.087967887637828,-0.021595929101711597
142.4000000000013,41.875129508105296,-2.0826226733073265,-0.02450514446014962
143.50000000000134,42.23127376381422,-2.079260777265513,-0.022729937660128652
144.60000000000133,42.58541903721591,-2.0750449442691026,-0.02305980972364763
145.70000000000135,42.94027799079937,-2.0704159238476993,-0.02571480415385663
146.80000000000138,43.3013212870156,-2.068689128872708,-0.024692864733531827
147.9000000000014,43.659395999792515,-2.0651126963889475,-0.025371604987341367
149.00000000000142,44.01312597094499,-2.061977534951322,-0.025359811319140668
150.10000000000142,44.36987319492638,-2.0578433540262555,-0.024370082885638578
151.20000000000144,44.72470174385998,-2.0543570956619557,-0.02668071794275484
152.30000000000146,45.08285683478678,-2.0517225892672415,-0.026350086000380024
153.40000000000146,45.43704848182872,-2.0482362524128366,-0.026350084926017203
154.50000000000148,45.793898706741714,-2.045852365497465,-0.026390828397346855
155.6000000000015,46.13842927798062,-2.0414458837951197,-0.029716862878359063
156.70000000000152,46.49854047615781,-2.0379404826503764,-0.027941315563341007
157.80000000000155,46.857928482923995,-2.0332086187856397,-0.029545231979071662
158.90000000000154,47.215378764949264,-2.03118393083068,-0.02865008572260752
160.00000000000156,47.56801957922248,-2.0278419770784253,-0.03131259286426902
161.1000000000016,47.92150368362977,-2.02522560520802,-0.03205494181637292
162.20000000000158,48.284551788106334,-2.022086781464547,-0.03161985191831507
163.3000000000016,48.63578484535509,-2.0191274072626455,-0.030991888616205276
164.40000000000163,48.989172151486194,-2.016329917976529,-0.03162003212824871
165.50000000000165,49.34658355479866,-2.0118970427916296,-0.032940069334436384
166.60000000000167,49.70435667540163,-2.00671546445576,-0.034259768744213215
167.70000000000167,50.060431323282955,-2.0056535220442417,-0.03501853303137192
168.8000000000017,50.41917000000057,-2.0034600000000107,-0.035349851328836834
169.9000000000017,50.7698772294563,-1.9988546553224276,-0.0350765208990893
171.0000000000017,51.12695351717462,-1.9967120005358425,-0.035350093066314425
172.10000000000173,51.4830496432195,-1.9937818953819368,-0.035019992956838664
173.20000000000175,51.82938344966513,-1.9880329592502617,-0.03633980999999942
174.30000000000177,52.1934340809919,-1.9866156479592127,-0.037937880494862686
175.4000000000018,52.550936011504795,-1.9836246467375358,-0.03831990606700586
176.5000000000018,52.90276772114095,-1.9827955941247506,-0.0383198569197849
177.6000000000018,53.25986599741648,-1.9798189550605196,-0.03963989401924284
178.70000000000184,53.62253662745194,-1.9765262638239953,-0.04029997853258305
179.80000000000183,53.970185494509614,-1.9717622436941251,-0.041290062000014505
180.90000000000185,54.3138361400822,-1.9693681491792092,-0.04128967933351513
182.00000000000188,54.6772525434282,-1.9671970218629753,-0.042521723506442566
183.1000000000019,55.032938434818405,-1.965699505341363,-0.0431568318162463
184.20000000000192,55.38532742719741,-1.9630441116263888,-0.042820256403513834
185.30000000000192,55.742688661328444,-1.9601367451632488,-0.044138507043529174
186.40000000000194,56.101037579374236,-1.9583894907073751,-0.04676942625205571
187.50000000000196,56.45556914539496,-1.9573211893651183,-0.04544990426713014
188.60000000000196,56.808101988630916,-1.9563105097709363,-0.046769903987765815
189.70000000000198,57.16330154049716,-1.9530589995454197,-0.04809008573216644
190.800000000002,57.51721464680484,-1.9521375716105105,-0.049762620375259026
191.90000000000202,57.873270849747776,-1.952303628357281,-0.05105987187142258
193.00000000000205,58.23061720819127,-1.9487612900230846,-0.05205003896100413
194.10000000000204,58.585401452597964,-1.9483439441777797,-0.05270003939399537
195.20000000000206,58.937784446059865,-1.946578980969225,-0.05665005648446364
196.3000000000021,59.294988519541825,-1.945369988124463,-0.05533956467751766
197.40000000000208,59.64980285748803,-1.9466778131530211,-0.05731009208038218
198.5000000000021,60.00803819516132,-1.945194924315079,-0.05895970567689224
199.60000000000213,60.364069924044344,-1.9452984040263053,-0.059286018476284674
200.70000000000215,60.71171684397454,-1.9462124808223742,-0.06324015129520033
201.80000000000217,61.07442574695143,-1.945426464016822,-0.0655400354618525
202.90000000000217,61.42845691447162,-1.9459723821003179,-0.06685717274736014
204.0000000000022,61.78140378547764,-1.9468314528428492,-0.07115004127730673
205.1000000000022,62.128077462849994,-1.9487279041257177,-0.07245982824383868
206.2000000000022,62.48952218176646,-1.9527159505787726,-0.07443554416072917
207.30000000000223,62.84371309753929,-1.9527404540635802,-0.07837544384883488
208.40000000000225,63.196499232175505,-1.9563403306708667,-0.08216305496226006
209.50000000000227,63.5541818773007,-1.9607331469389735,-0.08495396007682654
210.6000000000023,63.91211061665547,-1.9647216930142906,-0.08903409027824516
211.7000000000023,64.26892190846391,-1.9695247456642397,-0.09219565172601119
212.8000000000023,64.62687086746368,-1.9748225130120165,-0.09781184741101612
213.90000000000234,64.98418586689908,-1.9810936392962364,-0.10438900606597024
215.00000000000233,65.33833879452793,-1.9874419041253366,-0.10704528861278018
216.10000000000235,65.69764818044615,-1.994070248389753,-0.11429988420628989
217.20000000000238,66.05454830410167,-2.000850634235795,-0.12230679537060851
218.3000000000024,66.41115609203632,-2.0047614511210847,-0.1288955188137031
219.40000000000242,66.76428933711772,-2.00956973746098,-0.13677123819519688
220.50000000000242,67.12518512169673,-2.0154515152647554,-0.146108914175894
221.60000000000244,67.4803609382258,-2.019184590289964,-0.15538398545867205
222.70000000000246,67.83748684040032,-2.0216572446365553,-0.16753330208367379
223.80000000000246,68.19696600230498,-2.0238369525311826,-0.17438368306009977
224.90000000000248,68.55203009100505,-2.023514726977021,-0.189175271608637
226.0000000000025,68.91117691063283,-2.0235039870020475,-0.19929415560697672
227.10000000000252,69.25734426283864,-2.022564145450395,-0.21265847054630704
228.20000000000255,69.61609102045371,-2.022348095268688,-0.22593543897277124
229.30000000000254,69.96781620726057,-2.018739366455552,-0.24223182992162196
230.40000000000256,70.32215064018449,-2.0168086267538325,-0.25522047109544044
231.5000000000026,70.67622790436818,-2.0172520848268047,-0.27274673357271384
232.60000000000258,71.030817593929,-2.0148834424039674,-0.2905589218771407
233.7000000000026,71.38464752991602,-2.0139777803646868,-0.30855560621418165
234.80000000000263,71.74000780465292,-2.013891892218434,-0.32591659941443396
235.90000000000265,72.10167978118876,-2.01164182556577,-0.3444415683815434
237.00000000000267,72.45830581293279,-2.008279688343632,-0.3681392557347083
238.10000000000267,72.81423744659611,-2.005582429327723,-0.39030704418929174
239.2000000000027,73.16622488201408,-2.00400127129863,-0.41159476223976466
240.3000000000027,73.51829109871979,-1.9989691700206942,-0.4355313091902895
241.4000000000027,73.87379573504974,-1.9963554861715267,-0.45907978152684814
242.50000000000273,74.23083432693709,-1.991128532039575,-0.4825842289873945
243.60000000000275,74.5871001562949,-1.9844053651248492,-0.5084840791307332
244.70000000000277,74.94078442263104,-1.978436044962969,-0.5323213650384884
245.8000000000028,75.29259685919581,-1.9734901500092956,-0.555075111977561
246.9000000000028,75.64728546384835,-1.9662906403801972,-0.5782432205203727
248.0000000000028,76.00377363407726,-1.9588340614009379,-0.5996173735433925
249.10000000000284,76.35947334743987,-1.948423795849902,-0.6231454827024461
250.20000000000283,76.71249022901712,-1.9385989207197596,-0.6433496464595034
251.30000000000285,77.06632999437193,-1.928909020054053,-0.6635861483341845
252.40000000000288,77.42356316411671,-1.9188341361277013,-0.6834239163084721
253.5000000000029,77.77171004033751,-1.9079641615126415,-0.6996968074030518
254.60000000000292,78.12841944425433,-1.8963041029043994,-0.7162485272647388
255.70000000000292,78.4837685403074,-1.8885174465063241,-0.7320429833396309
256.8000000000029,78.84047070841277,-1.8789129438252097,-0.7452745315554044
257.90000000000293,79.19289771617677,-1.8719134821811367,-0.7591001177856564
259.00000000000296,79.54688255964547,-1.862540156308844,-0.7682189366278043
260.100000000003,79.90279411921392,-1.8532442298931948,-0.7810150673862304
261.200000000003,80.25691873176675,-1.8472230667622156,-0.7931166797362774
262.300000000003,80.60688786327039,-1.8414649483783785,-0.802051897060716
263.40000000000305,80.95917375920813,-1.8324495948631576,-0.8141747079261736
264.50000000000307,81.31488654445815,-1.828840838093486,-0.8210844889754139
265.6000000000031,81.6675234290255,-1.8234690400841136,-0.8307403701618479
266.7000000000031,82.02451536100203,-1.815838156311622,-0.8412730043918888
267.8000000000031,82.38147567098295,-1.8127452169140943,-0.8501928933923235
268.9000000000031,82.73807143147464,-1.8087255081331504,-0.8568705401424364
270.0000000000031,83.09077529616191,-1.805309134484958,-0.8653586771605677
271.10000000000315,83.45178766786302,-1.8021496506868904,-0.8756356484076604
272.2000000000032,83.80571637952643,-1.8013947248293505,-0.8791562323472433
273.30000000000314,84.1618322127846,-1.7998206479110461,-0.890850060632177
274.40000000000316,84.51853417258553,-1.7980110673387102,-0.8962605787942461
275.5000000000032,84.87410018841955,-1.7955340589887296,-0.9014172935651965
276.6000000000032,85.23022454014641,-1.7931454633269337,-0.9103930991875715
277.70000000000323,85.58734599286566,-1.7926868054660863,-0.9181275862767255
278.80000000000325,85.94089579435366,-1.791194749356606,-0.9242440167891024
279.9000000000033,86.30433163624673,-1.7902410011064491,-0.9326756624593235
281.0000000000033,86.64746875023049,-1.7895714511724718,-0.9382113541289967
282.1000000000033,87.00632708152686,-1.78857953036414,-0.9452348690816939
283.20000000000334,87.36101484862189,-1.786823913154419,-0.9523710643787848
284.30000000000337,87.72033685753709,-1.7868858114710071,-0.9576507785429174
285.40000000000333,88.07268190889222,-1.7873573910996252,-0.9630325931085189
286.50000000000335,88.42620114298249,-1.786199065776332,-0.9709189277215127
287.6000000000034,88.78273893010132,-1.7856505903408204,-0.9775701252045783
288.7000000000034,89.13312590094355,-1.7850675730302403,-0.9862989257967536
289.8000000000034,89.48119941018274,-1.7866485325208772,-0.9917271473146632
290.9000000000034,89.84572567612219,-1.7863898789664865,-0.9983837360143593
292.0000000000034,90.2062119574589,-1.7863560833735714,-1.0046005761332801
293.10000000000343,90.56366604905963,-1.7842647370723022,-1.0114369848483622
294.20000000000346,90.92944381958391,-1.7868473812528871,-1.0181498509479034
295.3000000000035,91.27423233465696,-1.7862795587904874,-1.0240746449267495
296.4000000000035,91.63527200169526,-1.7869716271079226,-1.0343872490081063
297.5000000000035,91.99137191944966,-1.7862058288136227,-1.0407655212143632
298.60000000000355,92.34355522556268,-1.786487997393365,-1.0465535849895176
299.70000000000357,92.70445441327985,-1.7874393546072185,-1.0574423972757567
300.8000000000036,93.05917242595909,-1.7879398641427877,-1.0653501062281516
301.9000000000036,93.41382922924363,-1.78893665002369,-1.0720428097089036
303.0000000000036,93.77607647097362,-1.788035694686423,-1.0797826564434176
304.1000000000036,94.13650586304325,-1.7906360969430715,-1.0893530523780615
305.2000000000036,94.49290387523224,-1.7920265851642496,-1.0999712935432875
306.30000000000365,94.85208662039355,-1.790452130721377,-1.1095573854887055
307.4000000000037,95.20676444388832,-1.7910641692262095,-1.116824629227764
308.5000000000037,95.57032666660804,-1.7926219655759676,-1.129128826244742
309.60000000000366,95.92871914643982,-1.7913676260465659,-1.139395364218728
310.7000000000037,96.28562211581159,-1.7948092945052923,-1.1516639548365224
311.8000000000037,96.6428849134018,-1.7948762062217327,-1.1618538662435656
312.90000000000373,96.99693107973377,-1.7954100716428518,-1.1745355464362608
314.00000000000375,97.35371900578468,-1.7954567908531767,-1.1866352031719467
315.1000000000038,97.71193989046424,-1.797078121460743,-1.2005231649094155
316.2000000000038,98.06680182663486,-1.7997977911360612,-1.2137338449763178
317.3000000000038,98.42703417675581,-1.7996340660517727,-1.2298048167170705
318.40000000000384,98.77913773834793,-1.7977642018335627,-1.2431689220053688
319.5000000000038,99.13911734018112,-1.7976653272865313,-1.2605637832774121
320.60000000000383,99.49997843133028,-1.7949496711659976,-1.277254922413864
321.70000000000385,99.85916658375663,-1.7920599404769193,-1.2921599328919173
322.8000000000039,100.22022247644963,-1.7892823763573649,-1.309151362718321
323.9000000000039,100.5782352788717,-1.78669351098681,-1.326656154648381
325.0000000000039,100.92917000000156,-1.7817300000000809,-1.3446299681265241
326.10000000000394,101.28635975631286,-1.7777162309821044,-1.3631763463600879
327.2000000000039,101.64916513050633,-1.7731998368447401,-1.3800899741025416
328.30000000000393,102.00657065050692,-1.7699567173792965,-1.3971418619041254
329.40000000000396,102.36218939633628,-1.763758980476951,-1.4122389131348485
330.500000000004,102.71977862772206,-1.7567299572874822,-1.4308293664606255
331.600000000004,103.07758393043456,-1.7500879441992,-1.4474398732924936
332.700000000004,103.43557489095811,-1.7419203377904697,-1.4621520949056315
333.80000000000405,103.79226458530984,-1.731111299465176,-1.4772645805584168
334.90000000000407,104.15249067704771,-1.7253805902859949,-1.4907347163388827
336.0000000000041,104.50774262703456,-1.7173865034582139,-1.5049996547991191
337.10000000000406,104.86651245696603,-1.7107492830951485,-1.5188388180413614
338.2000000000041,105.22530543194453,-1.7015209428871503,-1.5290435309508865
339.3000000000041,105.58496892521708,-1.6947705674384441,-1.54021644137143
340.4000000000041,105.93949237528895,-1.6894205419233808,-1.5519094329287948
341.50000000000415,106.29602482031126,-1.6833039784469614,-1.5613544348273485
342.6000000000042,106.66114668122032,-1.6774999814281824,-1.5702882234568398
343.7000000000042,107.01665597443706,-1.670603132329662,-1.5799207650501437
344.80000000000416,107.3747434528206,-1.664340373210946,-1.5897032162196498
345.9000000000042,107.732380453541,-1.6587849087273687,-1.597462031025311
347.0000000000042,108.09087703464368,-1.6542290162349262,-1.6050634122610443
348.10000000000423,108.4505253447687,-1.6497284988586969,-1.61359005768281
349.20000000000425,108.80916711079468,-1.645409955394338,-1.6188699981492412
350.3000000000043,109.16758355454505,-1.6409400249915822,-1.6268166073719281
351.4000000000043,109.52526327886991,-1.6363239164033145,-1.633368766977843
352.5000000000043,109.88431074289035,-1.633658054709603,-1.6399533852997896
353.60000000000434,110.24836711958001,-1.6285248567429653,-1.6480761768128027
354.7000000000043,110.60776239158571,-1.6256767039576405,-1.6547650536513427
355.80000000000433,110.96667329338071,-1.6222615931121362,-1.6610362074716156
356.90000000000435,111.32326984555407,-1.6182712572575932,-1.6689514759391102
358.0000000000044,111.6825466278645,-1.6148182090923175,-1.675859803573804
359.1000000000044,112.04042714328193,-1.611215160789133,-1.6836118635218922
360.2000000000044,112.40086354803708,-1.6070480516947767,-1.68947023354351
361.30000000000445,112.75672909961015,-1.605788723629447,-1.697349313288833
362.4000000000044,113.11776207002106,-1.6027363340503984,-1.7066193209350162
363.50000000000443,113.47234120964862,-1.599337335199664,-1.7135335808510344
364.60000000000446,113.83812811322369,-1.5970000104301434,-1.7187685934122623
365.7000000000045,114.1987637218336,-1.5934342790430471,-1.7287088141766627
366.8000000000045,114.55102742016395,-1.5927416557628613,-1.7372755592297904
367.9000000000045,114.91807930752793,-1.5887550428313375,-1.7439292986334243
369.00000000000455,115.27946197103748,-1.586543673885489,-1.75360822103569
370.10000000000457,115.64483400483407,-1.5860886609037146,-1.7638795700438656
371.2000000000046,116.00605314884861,-1.5843692673842458,-1.772827575987904
372.30000000000456,116.36722288602496,-1.5820360428766662,-1.779586153266207
373.4000000000046,116.72714987142562,-1.5807658714327275,-1.790059182495153
374.5000000000046,117.09221688302077,-1.580235221642722,-1.7972997940639979
375.6000000000046,117.45076400302592,-1.5772525215821498,-1.8057562244069372
376.70000000000465,117.81571833432577,-1.5768866578678062,-1.8155063607186839
377.8000000000047,118.17364389597977,-1.575445167349959,-1.8252569444685216
378.9000000000047,118.5375099588,-1.5729529911963571,-1.8334752039988405
380.00000000000466,118.8904360451785,-1.5723514561298217,-1.8428414196796137
381.1000000000047,119.24990044828337,-1.5716635485431687,-1.852382037881012
382.2000000000047,119.61344503856587,-1.5728238202906675,-1.8621997717348733
383.30000000000473,119.97204484144977,-1.5729775703455193,-1.8712869359327469
384.40000000000475,120.33696211967637,-1.572835182052619,-1.8812064981217698
385.5000000000048,120.7002596266151,-1.5729194668730047,-1.8904774365701646
386.6000000000048,121.06199511155646,-1.5738783189750583,-1.9000735569440246
387.7000000000048,121.4225492133444,-1.5747922944165025,-1.9103792831664896
388.80000000000484,121.79632751776488,-1.5760347798963998,-1.9187024510450978
389.9000000000048,122.1537681070721,-1.577840753958074,-1.9277544752831206
391.00000000000483,122.5162872763278,-1.5752173121224635,-1.93673988413701
392.10000000000485,122.87374065147311,-1.5765586952792525,-1.94544738209586
393.2000000000049,123.24099963554005,-1.577342153034971,-1.9551734844016666
394.3000000000049,123.60646661606069,-1.576615003825485,-1.964485949861746
395.4000000000049,123.96952193027316,-1.5776463414336406,-1.9722906210087254
396.50000000000495,124.34003993307681,-1.5793198492732252,-1.9826013019762945
397.6000000000049,124.70493585372078,-1.579620711942242,-1.9921568441701605
398.70000000000493,125.07409104532871,-1.5780687416830212,-1.9992660576857109
399.80000000000496,125.43517869877512,-1.5779014961167397,-2.0068027618612203
400.900000000005,125.79755344407577,-1.5796783176334572,-2.015623601368051
402.000000000005,126.1588288806162,-1.5784929211004413,-2.0236235712201807
403.100000000005,126.50916870125643,-1.5794999125305065,-2.03109159060971
404.20000000000505,126.87980129449376,-1.5797560767314953,-2.0404686070374884
405.30000000000507,127.24744617306746,-1.5790098940230028,-2.0496486407987584
406.4000000000051,127.61145496197261,-1.580276542932508,-2.0563550785449634
407.50000000000506,127.97718923621579,-1.5809047642523564,-2.06425692017307
408.6000000000051,128.3413548821361,-1.5806239366410524,-2.0708058592500196
409.7000000000051,128.70916664837435,-1.5827801466749831,-2.079849938608916
410.8000000000051,129.07291061341644,-1.580132707578526,-2.0874357426343426
411.90000000000515,129.43292026316033,-1.5805793815235296,-2.0928168918510117
413.0000000000052,129.79139731774669,-1.5789844748130755,-2.102253176061735
414.1000000000052,130.15922301260002,-1.5795074025237508,-2.1100253621618914
415.20000000000516,130.51794693643512,-1.5791251840534826,-2.118523763872603
416.3000000000052,130.8818566578849,-1.577130977338234,-2.1284732061149723
417.4000000000052,131.2437364625082,-1.5785908560127682,-2.1322609134964767
418.50000000000523,131.60590972943388,-1.5792150657985133,-2.137544001729024
419.60000000000525,131.96682053612378,-1.5784905091639327,-2.145604602597646
420.7000000000053,132.33256233393783,-1.5776654290521026,-2.1524429415668456
421.8000000000053,132.6960331488522,-1.5790581125244383,-2.1602421663849705
422.9000000000053,133.06264460448426,-1.5796192336158859,-2.1668167379746253
424.00000000000534,133.42926191341738,-1.5812066975784502,-2.1756065851017583
425.1000000000053,133.79456766463417,-1.58187478417582,-2.1805065601014126
426.20000000000533,134.16010574032862,-1.5813167383550457,-2.1884302258620214
427.30000000000535,134.52223545801195,-1.579124466266461,-2.1934291403448674
428.4000000000054,134.885287333924,-1.577959988477777,-2.2000713888093326
429.5000000000054,135.24848957331875,-1.5773327431728974,-2.2082980826380463
430.6000000000054,135.61144085736512,-1.5761418941136254,-2.213585961748584
431.70000000000545,135.9758393528716,-1.5759545592796504,-2.2201518086279615
432.8000000000054,136.3338310302872,-1.575225980689156,-2.2267366819610253
433.90000000000543,136.70531925538094,-1.5757412080591882,-2.2346497581166327
435.00000000000546,137.07031992402077,-1.5757564899671006,-2.2399123250154527
436.1000000000055,137.43356671458034,-1.5771249423210905,-2.246093694737988
437.2000000000055,137.80243217205435,-1.5755143815871224,-2.254187297867172
438.3000000000055,138.1659385041126,-1.5734262081731516,-2.258317651312271
439.40000000000555,138.53217541367465,-1.5739767092780264,-2.2682710482438733
440.50000000000557,138.9004360683288,-1.574529782315255,-2.2739418587038878
441.6000000000056,139.26581106596484,-1.5736686673289826,-2.277850650037758
442.70000000000556,139.63241024235367,-1.5731540349760111,-2.2857948631203877
443.8000000000056,139.99547731081998,-1.5725213083572083,-2.2896573165492797
444.9000000000056,140.36641667565965,-1.5720557679991192,-2.297155483394646
446.0000000000056,140.73119445019879,-1.5725062147802322,-2.3058217477097185
447.10000000000565,141.09604233617418,-1.5730447530019227,-2.310232838926094
448.2000000000057,141.4631057803739,-1.5712598245760365,-2.31491326019267
449.3000000000057,141.83445760526607,-1.5723368566950795,-2.3194186838259494
450.40000000000566,142.20136238773102,-1.5701538284290253,-2.331113307032475
451.5000000000057,142.56801629946398,-1.5703993608098592,-2.3377229472077
452.6000000000057,142.92391494605818,-1.5696176346365938,-2.341569137365673
453.70000000000573,143.30028813361307,-1.5678871077224268,-2.3485815474055602
454.80000000000575,143.6663713052003,-1.5665961523707979,-2.355747999155253
455.9000000000058,144.03216751020761,-1.5644254214760602,-2.360885995647199
457.0000000000058,144.39516539600473,-1.5657723223835058,-2.3660165866847964
458.1000000000058,144.76212701726382,-1.565122440043959,-2.3724910105863457
459.20000000000584,145.12916758049846,-1.5623001549521716,-2.379120051125917
460.3000000000058,145.4544767722027,-1.5643394386549048,-2.38070183979441
461.40000000000583,145.8641738941906,-1.5631777355498038,-2.393280531048563
462.50000000000585,146.22510750405377,-1.5620948377181358,-2.39923852747312
463.6000000000059,146.59099553854827,-1.5622724835430277,-2.405800093227736
464.7000000000059,146.95683179489424,-1.5617137332989144,-2.411059206402147
465.8000000000059,147.32383949848477,-1.561523974240236,-2.4179661878695846
466.90000000000595,147.69407954502776,-1.5621911460754172,-2.423082607308117
468.0000000000059,148.05963998309352,-1.561689059009126,-2.4308280426996838
469.10000000000593,148.42674792528973,-1.558937966269525,-2.4363938826262164
470.20000000000596,148.7928335559201,-1.5577513667107528,-2.441366058584351
471.300000000006,149.15301053814045,-1.556555176011145,-2.4451710489383096
472.400000000006,149.5238366235789,-1.5562482065889518,-2.4532300879858893
473.500000000006,149.88876489460637,-1.5570128938566357,-2.4598031396824225
474.60000000000605,150.2576670886883,-1.5599422500376332,-2.4649646731420294
475.70000000000607,150.62583343759522,-1.559514036368319,-2.4719143383141424
476.8000000000061,150.99214907767018,-1.5602567109907093,-2.4747511599672984
477.90000000000606,151.35845227391462,-1.5594486856890677,-2.4837731169361827
479.0000000000061,151.72356588798326,-1.559271142157312,-2.490320097737827
480.1000000000061,152.08415938029273,-1.5588852159567046,-2.4929540215468626
481.2000000000061,152.45247131900433,-1.5564964430486168,-2.50086710175224
482.30000000000615,152.82381992722853,-1.557457403356162,-2.506137492791967
483.4000000000062,153.18585625576546,-1.5581002103437145,-2.5107467634145255
484.5000000000062,153.558576470945,-1.558157470647264,-2.517457284886105
485.60000000000616,153.92288545655765,-1.5579903833091613,-2.5240798427088453
486.7000000000062,154.29090073575802,-1.5587211658819158,-2.528970635514333
487.8000000000062,154.66078895374525,-1.5587601596305423,-2.53423363546085
488.90000000000623,155.02421131277433,-1.557768747976618,-2.5403872022544336
490.00000000000625,155.38873475147042,-1.5565615771600112,-2.546063360540776
491.1000000000063,155.7599304835246,-1.557271382074388,-2.5487661154828256
492.2000000000063,156.1267866962664,-1.5564504794949239,-2.5563294212898673
493.3000000000063,156.49375164446903,-1.556722500658621,-2.5616893950914474
494.40000000000634,156.86064243724365,-1.5572399344313905,-2.5669597834919005
495.5000000000063,157.2256164590103,-1.5568153217716674,-2.570872624367201
496.60000000000633,157.59377009254948,-1.5583125404606726,-2.5775054519252603
497.70000000000636,157.96110614798263,-1.5573741034355097,-2.581446034745361
498.8000000000064,158.32951221002125,-1.5594071146237791,-2.5867300728748157
499.9000000000064,158.700223463095,-1.5580566610912248,-2.5919906718410104
501.0000000000064,159.06402176633335,-1.5573165135915195,-2.5959499909848622
502.10000000000645,159.43330917704031,-1.5542454980360287,-2.6015623246994624
503.2000000000064,159.8003266918389,-1.555253931857826,-2.6054987518936366
504.30000000000643,160.16982169078796,-1.5565081641998924,-2.6125146696162287
505.40000000000646,160.54078312479595,-1.55385775988561,-2.6135509057450594
506.5000000000065,160.9053615708268,-1.5547524472654275,-2.6217287513298135
507.6000000000065,161.27184389787084,-1.555101874072299,-2.626751132516277
508.7000000000065,161.64003408414234,-1.5543129585741975,-2.628335041047916
509.80000000000655,162.00674336303584,-1.5531720289073605,-2.633438757077859
510.90000000000657,162.37684879178914,-1.5550134766484596,-2.638887688405039
512.0000000000066,162.7467781702047,-1.5568626260896634,-2.642814049550894
513.1000000000065,163.1180251519514,-1.5553166635397575,-2.6467455334644194
514.2000000000066,163.48058723248715,-1.5549598931812953,-2.6507335410276234
515.3000000000065,163.8513052874187,-1.553911054913149,-2.6559901136036115
516.4000000000067,164.22172437087215,-1.5555860073204157,-2.6626154706385607
517.5000000000066,164.5885873018526,-1.556438033573507,-2.66540313234972
518.6000000000067,164.95719435881273,-1.5560303582526087,-2.6693901944951968
519.7000000000066,165.32468652174072,-1.55596524946509,-2.674767985879953
520.8000000000067,165.69086129835364,-1.5534692078951546,-2.67872014167473
521.9000000000067,166.05882222432354,-1.5542120375440363,-2.682668211212323
523.0000000000067,166.42308934932274,-1.555785742924385,-2.686621066921353
524.1000000000067,166.75046425049413,-1.552396477715037,-2.690579858918975
525.2000000000068,167.15658246488422,-1.557412342891596,-2.694853340167385
526.3000000000068,167.52765071111668,-1.5545476197094363,-2.698160872288979
527.4000000000068,167.89886982571795,-1.5547143011802724,-2.7027318609290374
528.5000000000068,168.26993401176733,-1.5540163929053368,-2.708688832381069
529.6000000000068,168.63818851378025,-1.5546248036739787,-2.711320677282156
530.7000000000069,169.00212646092425,-1.5551095658501766,-2.716829600326772
531.8000000000068,169.3740451321591,-1.554021799982683,-2.7167104819409706
532.9000000000069,169.74486163803417,-1.5544430016674906,-2.7244300764084026
534.0000000000068,170.11271651582825,-1.552444979206485,-2.7272400070591916
535.100000000007,170.47531638855648,-1.5536579196450941,-2.7288227115429255
536.2000000000069,170.84816318168555,-1.553051854296711,-2.7302623030743893
537.300000000007,171.2171989691817,-1.5521770051510402,-2.7382201258517433
538.4000000000069,171.58782816347932,-1.5535189730469836,-2.7421698973287025
539.5000000000069,171.9604196480156,-1.5541055454152288,-2.7438305982244544
540.600000000007,172.33372124791552,-1.5540847004026128,-2.7476169392742724
541.700000000007,172.70654443429316,-1.5546062272560777,-2.753157412676564
542.800000000007,173.0721851267298,-1.5532358636588062,-2.7553450992096504
543.900000000007,173.4425875958639,-1.5521670425403071,-2.7571547535676966
545.000000000007,173.81319196871516,-1.5510318475363298,-2.762487760398427
546.1000000000071,174.1758968927593,-1.5517408166547704,-2.7657694365229193
547.2000000000071,174.5484848602189,-1.5516594380594744,-2.768408322278937
548.300000000007,174.9159316833301,-1.5513447112221277,-2.7724697981407975
549.4000000000071,175.29048417061048,-1.5545239354860396,-2.775769780917737
550.500000000007,175.65579918022434,-1.5507543939930402,-2.778414732139363
551.6000000000072,176.02060484406329,-1.5527647241114035,-2.7810399463367057
552.7000000000071,176.39542892102253,-1.5547191175307746,-2.783205678963114
553.8000000000072,176.76682279879742,-1.5564122431704914,-2.7860236631619646
554.9000000000071,177.1385002964898,-1.5573040077600313,-2.7907085772912894
556.0000000000072,177.5100828190576,-1.55729668027292,-2.792197181842816
557.1000000000072,177.88858960605677,-1.5577628132665289,-2.795313127362893
558.2000000000072,178.24954208070483,-1.5596520657317345,-2.796658732513989
559.3000000000072,178.6166667005059,-1.5607844177889292,-2.798171645700328
560.4000000000073,178.98916311011087,-1.5609701771786817,-2.8037598990807338
561.5000000000073,179.35277575678333,-1.5603108058777848,-2.804430087149878
562.6000000000073,179.72253862009305,-1.5615136232288898,-2.805735614186097
563.7000000000073,180.09516310695244,-1.5625330025089503,-2.8083799161958396
564.8000000000073,180.46511540398296,-1.564695012625691,-2.811010195978082
565.9000000000074,180.8384899833803,-1.5644568663640608,-2.813271329651611
567.0000000000074,181.20774341792497,-1.565005629918368,-2.8149598459999945
568.1000000000074,181.57907862584779,-1.5671724304841483,-2.8186579764653876
569.2000000000073,181.9520379255099,-1.5660387645949283,-2.819392996088522
570.3000000000073,182.3211595482185,-1.5673863884846708,-2.8215498259612763
571.4000000000074,182.69097010251645,-1.567932072306055,-2.8217084355144104
572.5000000000074,183.0604923527314,-1.5676481721325872,-2.8242550781739757
573.6000000000074,183.42788368783883,-1.567095847605541,-2.825830050299389
574.7000000000074,183.79397436156898,-1.5680124276988623,-2.826681573562925
575.8000000000075,184.16456411811512,-1.5685350535983773,-2.830445029016777
576.9000000000075,184.53812877808906,-1.5679600423973805,-2.8308798699937583
578.0000000000075,184.90979692749232,-1.5711843824518434,-2.832200177937482
579.1000000000075,185.27593557756273,-1.5723647232739684,-2.8327852847281365
580.2000000000075,185.65139121717706,-1.5743740110924036,-2.8330418528566215
581.3000000000076,186.02334140181517,-1.5768445391557864,-2.8361500957053996
582.4000000000076,186.3963931395423,-1.5813850767930315,-2.837232706188294
583.5000000000076,186.770976941713,-1.5817829121819857,-2.837349882003185
584.6000000000076,187.13559210526023,-1.5847762529157516,-2.8386725853114525
585.7000000000077,187.50941545189883,-1.5872050122578805,-2.8399910709519554
586.8000000000077,187.879735203056,-1.5895647883419313,-2.8419699587655485
587.9000000000076,188.24916494132592,-1.5924400755515977,-2.841630244233447
589.0000000000076,188.61628531487764,-1.5924037547637584,-2.844599960000006
590.1000000000076,188.98649928288432,-1.594485343015918,-2.8452601616009163
591.2000000000077,189.35759217759966,-1.5967857064515687,-2.8462142595155036
592.3000000000077,189.72209862557443,-1.5990739234583833,-2.8467077631400928
593.4000000000077,190.1041695139306,-1.6034777434265521,-2.8482330689758677
594.5000000000077,190.4738572015058,-1.6051628491669692,-2.848229980591479
595.6000000000078,190.84353599039486,-1.605263226068509,-2.849548946851578
596.7000000000078,191.21539456360213,-1.6097549837480574,-2.85251038311959
597.8000000000078,191.5820832744963,-1.613777726033654,-2.852526187569433
598.9000000000078,191.95152739495703,-1.617101809766002,-2.8518803812397895
600.0000000000078,192.32659471750466,-1.6205429576180037,-2.8548100820025946
601.1000000000079,192.69801531693744,-1.6228379921605207,-2.8561298575628067
602.2000000000079,193.06756820648104,-1.6271468069249155,-2.8548198480292397
603.3000000000079,193.4303099308337,-1.6348596696772877,-2.857439969774509
604.4000000000078,193.80447556084016,-1.6408670176304825,-2.8564601077421314
605.5000000000078,194.17589394942678,-1.6446365258732303,-2.854480520574242
606.6000000000079,194.54848576876213,-1.6499771950523008,-2.858439379612497
607.7000000000079,194.91058185452889,-1.654547946167736,-2.8597558041933517
608.8000000000079,195.29344544607181,-1.6604867779212655,-2.8610701805005165
609.9000000000079,195.6645347311434,-1.6643573777191452,-2.861069954573475
611.000000000008,196.03588968145664,-1.666367505580601,-2.8628253553658136
612.100000000008,196.4058142701829,-1.6709564756535145,-2.862390092587276
613.200000000008,196.77445911827348,-1.6755079184572301,-2.8630497850431937
614.300000000008,197.14754407240372,-1.6802307939617156,-2.8660099112818553
615.400000000008,197.51590749563064,-1.6825351048075357,-2.8650211811826085
616.5000000000081,197.8887353432976,-1.686977764732496,-2.867330181065462
617.6000000000081,198.26383027915733,-1.6929535373824078,-2.8669998698707273
618.7000000000081,198.63596295561766,-1.694004537908568,-2.866999699534416
619.8000000000081,199.0071397584399,-1.6979261247385957,-2.866669879462031
620.9000000000082,199.3765028989542,-1.7031909464288166,-2.8701821239637964
622.0000000000082,199.74645972474133,-1.705456382195674,-2.872802043396055
623.1000000000081,200.11772691395427,-1.7072807516401673,-2.870179989870251
624.2000000000081,200.4862665056141,-1.710926855519844,-2.8705096488236643
625.3000000000081,200.8559992623643,-1.7142840593679023,-2.874139982589707
626.4000000000082,201.2291594395378,-1.718139391069176,-2.871500199441246
627.5000000000082,201.60250292700624,-1.7192358685587121,-2.8714999160010812
628.6000000000082,201.97306409986317,-1.7257342484949854,-2.8734701047510596
629.7000000000082,202.346186335607,-1.7284353287725085,-2.8724467231054773
630.8000000000083,202.71412201154834,-1.732703777704623,-2.8761072652898254
631.9000000000083,203.09327852924682,-1.7358364405508175,-2.8770452569930876
633.0000000000083,203.46166574479145,-1.7362141075466178,-2.8771856532338758
634.1000000000083,203.8359575141608,-1.7407089864512064,-2.8793998853996494
635.2000000000083,204.20875937772382,-1.7426103666796917,-2.878089667717859
636.3000000000084,204.57949315272975,-1.7431673421764309,-2.8794100279994725
637.4000000000084,204.95201611578395,-1.74487611566025,-2.8817098339885208
638.5000000000084,205.3266071415228,-1.7505333278213326,-2.882355383404719
639.6000000000083,205.70250094165243,-1.7529749016544771,-2.8813799193238583
640.7000000000083,206.08110708353803,-1.7568192478601727,-2.883647112549234
641.8000000000084,206.4546567210354,-1.7592214567509614,-2.884349803994921
642.9000000000084,206.8291627456352,-1.7600293914122402,-2.8856294367170525
644.0000000000084,207.1985514381237,-1.7605904538407333,-2.8861060102348866
645.1000000000084,207.5788560674132,-1.761792471762611,-2.8857701381576097
646.2000000000085,207.94984279331254,-1.7624540408650125,-2.8870902474967854
647.3000000000085,208.32087570726318,-1.765304459109647,-2.8870898979999895
648.4000000000085,208.6960643486732,-1.7698056432534077,-2.8870847164818016
649.5000000000085,209.0734703250245,-1.7718475130543019,-2.887711292596169
650.6000000000085,209.4474419932277,-1.7730393068567312,-2.887089385572464
651.7000000000086,209.82121299718844,-1.7771813437387411,-2.888069862615593
652.8000000000086,210.19917421668583,-1.782949873939925,-2.8897199079859512
653.9000000000086,210.57160702394245,-1.7827631654159208,-2.893306470059444
655.0000000000086,210.94435950057695,-1.7856042282793105,-2.8926798649340917
656.1000000000087,211.31483383287585,-1.7928283802805904,-2.8930203252438105
657.2000000000087,211.69358266141887,-1.79401911583236,-2.8936799374197855
658.3000000000086,212.0643262707266,-1.7962714919565457,-2.8958999119998343
659.4000000000086,212.44338699827085,-1.7996599626225442,-2.894554091580476
660.5000000000086,212.81835778718235,-1.8022921590585108,-2.898484573130678
661.6000000000087,213.19544945565914,-1.8017298729164084,-2.8968598966629795
662.7000000000087,213.57077118987553,-1.8035315117210533,-2.8974193614758033
663.8000000000087,213.94122280111563,-1.8052460411232045,-2.8977374810624568
664.9000000000087,214.3125027619935,-1.8082172707451187,-2.8991598679297583
666.0000000000088,214.6875172888585,-1.8098502680221826,-2.8993558892997306
667.1000000000088,215.06435790284613,-1.8123309370638268,-2.899170185162964
668.2000000000088,215.44131457351946,-1.8133605690894004,-2.901532851258434
669.3000000000088,215.81882612711902,-1.8164622865987303,-2.903117234068481
670.4000000000088,216.19012469972648,-1.8162171447201265,-2.904429847918282
671.5000000000089,216.56366556311642,-1.820329457030557,-2.902022084687524
672.6000000000089,216.940624710034,-1.8212293856984045,-2.9046600182062674
673.7000000000089,217.3126100628333,-1.8225696394288275,-2.9059801839999997
674.8000000000088,217.69207850763584,-1.825915067275105,-2.9072900784202815
675.9000000000088,218.0727063997044,-1.828579432471495,-2.907812091559351
677.0000000000089,218.44836959041612,-1.8280835999764198,-2.906630026073209
678.1000000000089,218.82053589890268,-1.830461610383133,-2.9089393133850168
679.2000000000089,219.1938125925088,-1.8278842678376612,-2.9102498826910397
680.3000000000089,219.56666215075217,-1.8335183989744024,-2.9109100354081803
681.400000000009,219.94417500881008,-1.8344046883455767,-2.910921054739914
682.500000000009,220.32127510361815,-1.8361936834353523,-2.9109098480488043
683.600000000009,220.69617216580187,-1.8354522767113501,-2.9119302425354583
684.700000000009,221.0732334120625,-1.8341782766701786,-2.9143204827609726
685.800000000009,221.45477931112634,-1.8364330725464317,-2.9133224779050506
686.9000000000091,221.83237728799665,-1.8384310374267059,-2.9143081180199215
688.0000000000091,222.21032782896128,-1.8383786294993,-2.9169510438047856
689.1000000000091,222.58833648864157,-1.838792497891152,-2.9169503671893438
690.2000000000091,222.96711536682116,-1.840743834727227,-2.9182814891057056
691.3000000000092,223.34423041103662,-1.8450272862077923,-2.9195755064771536
692.4000000000092,223.71617258952838,-1.8416143160237815,-2.92045984000005
693.5000000000091,224.0964865439691,-1.8457949050994138,-2.920787901804575
694.6000000000091,224.47037580961452,-1.8493662187080266,-2.9204703591255563
695.7000000000091,224.85077171545265,-1.848346926775278,-2.9231000733193997
696.8000000000092,225.22674736641548,-1.84884426766984,-2.925386146815698
697.9000000000092,225.60044437166684,-1.851204290631363,-2.9250489269894793
699.0000000000092,225.9716652849516,-1.85338699937906,-2.923760059997579
700.1000000000092,226.3606813407461,-1.8551730630604608,-2.9263949273699295
701.2000000000093,226.73203759651025,-1.856749614715106,-2.928346112078935
702.3000000000093,227.11210152256572,-1.8583225776629968,-2.9281542201428827
703.4000000000093,227.49135352430937,-1.8602768317539922,-2.926847691364708
704.5000000000093,227.8695099855762,-1.861052633037847,-2.9284799543505393
705.6000000000093,228.24957971492884,-1.8636880030433434,-2.9289430344583645
706.7000000000094,228.6283169286064,-1.863619924685081,-2.9295798362443017
707.8000000000094,228.99885179908935,-1.8648941858404802,-2.932209802163678
708.9000000000094,229.377560788383,-1.8629852566182636,-2.93220890518924
710.0000000000093,229.75311675109194,-1.8622207452834474,-2.9330762198384166
711.1000000000093,230.12714889668644,-1.8637764513639492,-2.9344098407290486
712.2000000000094,230.51062048394692,-1.8650187553114328,-2.9350632773173264
713.3000000000094,230.89045061634175,-1.8679441014571947,-2.935060108000214
714.4000000000094,231.27504721407715,-1.8689716853247773,-2.9376979722933863
715.5000000000094,231.65729597183378,-1.8703599891006755,-2.937815278925156
716.6000000000095,232.0352815955308,-1.8693980167919506,-2.9391300840001326
717.7000000000095,232.41477978222989,-1.8688492871127347,-2.9404185559666263
718.8000000000095,232.7925683384208,-1.8685639374978893,-2.9394619936819413
719.9000000000095,233.16798232100348,-1.8720241306771923,-2.9420900097735716
721.0000000000095,233.54347968326007,-1.8754177171799118,-2.9395216603144414
722.1000000000096,233.9158519552302,-1.8778067134469094,-2.941755181986407
723.2000000000096,234.2947635268883,-1.8758609836918119,-2.9430698940000077
724.3000000000096,234.6755506036378,-1.8786768073313318,-2.9458275989226634
725.4000000000096,235.05361573288118,-1.8825874447940498,-2.944251444137842
726.5000000000097,235.43505575687885,-1.8841706321352418,-2.9453563074538023
727.6000000000097,235.8130429156957,-1.8816367170366908,-2.946702785875898
728.7000000000096,236.1898840354038,-1.8830171612314388,-2.9470295506074526
729.8000000000096,236.56457939929004,-1.883248067006401,-2.9483432286394784
730.9000000000096,236.94644968872996,-1.8829390017219914,-2.947917775180258
732.0000000000097,237.32406244116868,-1.8849431647682948,-2.9482823437857197
733.1000000000097,237.70257449031126,-1.8877264040668988,-2.9513207010153963
734.2000000000097,238.0753166944732,-1.8842931844289765,-2.9506737947584494
735.3000000000097,238.45087621126518,-1.8863648594262006,-2.952629971672718
736.4000000000098,238.82318343236423,-1.885120518695511,-2.953978768085779
737.5000000000098,239.20653546141565,-1.883541876224928,-2.9505408367354553
738.6000000000098,239.58499480444192,-1.8863286678387805,-2.953297375693382
739.7000000000098,239.96190613927936,-1.8874721666725882,-2.95577653447512
740.8000000000098,240.34050475644614,-1.8834988178808978,-2.957196602710455
741.9000000000099,240.71479677872543,-1.8810508278997464,-2.955810152057181
743.0000000000099,241.09109433695446,-1.883503314288274,-2.9584756074573093
744.1000000000099,241.4670635274682,-1.8828825367799447,-2.9591058419180127
745.2000000000098,241.8488293225697,-1.8819947661059153,-2.958396954778072
746.3000000000098,242.22551642461397,-1.884011867533055,-2.9590090227209567
747.4000000000099,242.60115526912276,-1.8855182676010007,-2.958450368076621
748.5000000000099,242.97917000000325,-1.8862299999999284,-2.9584498940002684
749.0000000000099,243.1469610518043,-1.8863304526201459,-2.9610774794656223