File: 01_Data/Basswood_Panel/STA/N2/30K_min/Basswood_Panel_STA_N2_30KData_220315_R3.csv
##Temp./Â°C,Time/min,DSC/(mW/mg),Mass loss/mg
49.0,10.416614480911603,-1.057600305578494,-0.06527111472616287
50.20000000000002,10.68380419334778,-0.8757801426934783,-0.06330509034974696
51.400000000000034,10.823794444634594,-0.7423350746826326,-0.06308360258088808
52.60000000000005,10.929698231149594,-0.6337940358161991,-0.06307950335821211
53.80000000000007,11.018256486972525,-0.5404080859876803,-0.06368568804339425
55.000000000000085,11.09762251079284,-0.4553850808876378,-0.06129858464510907
56.2000000000001,11.16934919938623,-0.37879492798178743,-0.06281489915664995
57.40000000000012,11.236013055581019,-0.3074294672920453,-0.0633284318778431
58.600000000000136,11.29832581528552,-0.24347826405079784,-0.062307071029888306
59.80000000000015,11.357465646010123,-0.18189721454850305,-0.06317396772812511
61.00000000000017,11.414157771209918,-0.1263158888933018,-0.06342205552965208
62.20000000000019,11.469213995354238,-0.07161905600727343,-0.062345532441599794
63.400000000000205,11.522661250840452,-0.020784212813419183,-0.06397733582302667
64.60000000000022,11.574204616699351,0.02838610666585066,-0.0638029852132771
65.80000000000024,11.62431947336071,0.0744373488789867,-0.06370335019334128
67.00000000000026,11.673549841013827,0.11802760657476963,-0.06377688471351028
68.20000000000027,11.722169891028043,0.1631438283629243,-0.06464942734679546
69.40000000000029,11.770358295083724,0.20214148377604696,-0.06478096744172746
70.6000000000003,11.816783951344373,0.24054945020895807,-0.06548517907286033
71.80000000000032,11.863728758991959,0.27712016980270476,-0.06659120078214453
73.00000000000034,11.909323502751427,0.3159693015658225,-0.06547127903225558
74.20000000000036,11.954389260231553,0.3518291954754201,-0.0656874038234001
75.40000000000038,11.999618625443125,0.3856562021286097,-0.06572788506129523
76.60000000000039,12.043850506096378,0.41730171937148824,-0.06621789198398886
77.80000000000041,12.087983648882762,0.4500606224964514,-0.06719226359817476
79.00000000000043,12.131652473682673,0.4806817075668497,-0.06831502375314535
80.20000000000044,12.175207381465773,0.5105916819035036,-0.06897408947668726
81.40000000000046,12.218613548111136,0.5391567023033169,-0.06843583443909385
82.60000000000048,12.261933172711688,0.5687100179973839,-0.0675239656189115
83.8000000000005,12.304776956452951,0.594593723026172,-0.06754896788101927
85.00000000000051,12.346470688340153,0.6224028193768678,-0.07005915258429596
86.20000000000053,12.389064390753209,0.6479165793168045,-0.07006873081270326
87.40000000000055,12.431572092327178,0.6756467275351201,-0.07099135268346979
88.60000000000056,12.47321189878193,0.6997263049621413,-0.0713709774406932
89.80000000000058,12.514565514741163,0.7221927482901692,-0.07244409157888354
91.0000000000006,12.556161058666966,0.7464997818805063,-0.07141597283318157
92.20000000000061,12.597825047766092,0.7688325224161449,-0.07270619793054811
93.40000000000063,12.639031072815836,0.7909179039705596,-0.07289044862558214
94.60000000000065,12.6802517550653,0.8110405715117976,-0.07409474023334672
95.80000000000067,12.721204022149221,0.8308807673946016,-0.07410160811118516
97.00000000000068,12.76213717475358,0.8526981371466767,-0.07432140101260742
98.2000000000007,12.803173170046227,0.8693630961179027,-0.0755746408913387
99.40000000000072,12.844016486523698,0.8876352047148135,-0.07691178001504184
100.60000000000073,12.884155535901325,0.904212091455219,-0.07682537546731849
101.80000000000075,12.924856847343436,0.9201451480243402,-0.07689476896294645
103.00000000000077,12.96540262601834,0.9345886707673029,-0.0771458519207795
104.20000000000078,13.006529332130583,0.948614196932355,-0.07819994951647047
105.4000000000008,13.046182678417436,0.9619047053019361,-0.07855295403861629
106.60000000000082,13.086905536572793,0.9767720859392713,-0.07951968232818007
107.80000000000084,13.127170984772032,0.9872455280071096,-0.08080255078371179
109.00000000000085,13.167403515640629,1.0017462300913238,-0.08018654168905925
110.20000000000087,13.207635506534745,1.0115921798143332,-0.08018026959227553
111.40000000000089,13.247966904468694,1.0241065095686592,-0.08023707604642416
112.6000000000009,13.288132286863805,1.0299226871957874,-0.08150450724054759
113.80000000000092,13.328014438153726,1.0414753332328104,-0.08131691719670897
115.00000000000094,13.368375148250733,1.0512418379582544,-0.0821419453343406
116.20000000000095,13.408696883409185,1.0594174604647306,-0.08345902797291549
117.40000000000097,13.448382624223335,1.069334048231125,-0.08346826214091285
118.60000000000099,13.488413701849801,1.0773096434883305,-0.08367251122580965
119.800000000001,13.528361860601537,1.0874541015305579,-0.08346889319967721
121.00000000000102,13.567912788582232,1.0972273649930802,-0.08346998714381515
122.20000000000104,13.607718036373182,1.1067957110140942,-0.08346914403485695
123.40000000000106,13.647603525587643,1.115430732777901,-0.08478525291011385
124.60000000000107,13.687678262289309,1.126529790094424,-0.08479000000000259
125.80000000000109,13.726851625228862,1.1360065114797906,-0.08609853210373775
127.00000000000111,13.766173211930461,1.147361355121165,-0.08610005483351024
128.20000000000113,13.805912093435506,1.1566531185124114,-0.08612107486147025
129.40000000000114,13.844992821738083,1.1677610448722167,-0.08707616517382455
130.60000000000116,13.884095112714169,1.1796193222533633,-0.0870874148451839
131.80000000000118,13.923246967522038,1.1898878425072286,-0.08568983627285265
133.0000000000012,13.962841652579517,1.2023360937906682,-0.08577807506323465
134.2000000000012,14.001736448455253,1.2148691665399651,-0.08627012889395091
135.40000000000123,14.040749318212441,1.2285362145343492,-0.08709092701970444
136.60000000000124,14.079570564075846,1.241486809193858,-0.08709056143264116
137.80000000000126,14.118470396529153,1.2554050120873606,-0.08715047727958547
139.00000000000128,14.157691663643853,1.2672882480622918,-0.08839977781661901
140.2000000000013,14.195662257383695,1.2821943247438672,-0.08840000684837346
141.4000000000013,14.233657962254291,1.2959963296581845,-0.08852549120097031
142.60000000000133,14.273278191061639,1.310013564400518,-0.0897264571937395
143.80000000000135,14.311812621598158,1.324007653916552,-0.08971995830459356
145.00000000000136,14.35037017192444,1.337874054809646,-0.08971992316680799
146.20000000000138,14.388460326707818,1.3530475516714304,-0.08971992299952314
147.4000000000014,14.426685957628663,1.365680289259918,-0.08971992343459068
148.60000000000142,14.465096618441086,1.3809827497575353,-0.08972003737429723
149.80000000000143,14.5030436483658,1.3976579538646396,-0.08974264932216247
151.00000000000145,14.541828483175138,1.4126122669073038,-0.09104779567652788
152.20000000000147,14.580136155831703,1.4274917846022759,-0.09103995271119736
153.40000000000148,14.618051139192485,1.442787409977441,-0.09103992392867255
154.6000000000015,14.656259365125168,1.4573827231831735,-0.09104110714989044
155.80000000000152,14.694043155747034,1.4721521470228898,-0.0914073288190087
157.00000000000153,14.732128256767647,1.4864926758029826,-0.09241845980164376
158.20000000000155,14.769795269827206,1.5017799937027103,-0.09235013998481323
159.40000000000157,14.807627019387027,1.5173335536194659,-0.09235033838041673
160.6000000000016,14.845632904189602,1.5315067667952815,-0.09254589372310296
161.8000000000016,14.883710998225819,1.5460275337109344,-0.09333320833584269
163.00000000000162,14.921349574779072,1.5596481863759701,-0.09334178275938054
164.20000000000164,14.95932443998594,1.5765505528818902,-0.09467772351714077
165.40000000000165,14.997129151110899,1.5897721844803736,-0.09532117119370076
166.60000000000167,15.03510980553306,1.6027614217940447,-0.09531991447244303
167.8000000000017,15.072387402677832,1.6166934875697325,-0.09531990346622798
169.0000000000017,15.109795710691193,1.631823922843054,-0.09531998192138236
170.20000000000172,15.147603820851911,1.648599815694361,-0.0952947556765702
171.40000000000174,15.185103349077496,1.6610822947404693,-0.09567647127334711
172.60000000000176,15.222950742154582,1.676478148457844,-0.09660342390308507
173.80000000000177,15.2602947482222,1.6897108422256493,-0.096639981191188
175.0000000000018,15.297679445324908,1.7026239929078273,-0.09794556822269573
176.2000000000018,15.335412911541452,1.7173130152683995,-0.09795000084702288
177.40000000000182,15.37295237974035,1.7310475787698723,-0.09797636014790179
178.60000000000184,15.410096729276585,1.7451561667746602,-0.09927332081929263
179.80000000000186,15.447166844702172,1.757749423837097,-0.09926987732224646
181.00000000000188,15.484381090256832,1.7706501714890108,-0.09927002826609899
182.2000000000019,15.521808622404704,1.7834256780365725,-0.09928191875332981
183.4000000000019,15.55902055077333,1.7965244231917596,-0.10190940365131906
184.60000000000193,15.59577043794526,1.8097622879801607,-0.10190025107353806
185.80000000000194,15.632909351285976,1.8220270277450663,-0.10192100244225788
187.00000000000196,15.669683460812616,1.8351527231369407,-0.10124193860170072
188.20000000000198,15.70707323904773,1.8472629179771225,-0.10124005053387064
189.400000000002,15.744151626011217,1.8584086517263432,-0.10124177584148386
190.600000000002,15.781048855643222,1.8722393230983903,-0.10099452499243222
191.80000000000203,15.818072507739306,1.8845164232812195,-0.10120452235627697
193.00000000000205,15.854920216650397,1.8959982637363215,-0.1039618134781981
194.20000000000206,15.891927945545032,1.9098511050115827,-0.103884723940606
195.40000000000208,15.928619784853204,1.9208232472435334,-0.10518727448448484
196.6000000000021,15.965252354593826,1.9319904405274848,-0.10519040792109946
197.80000000000211,16.001860770861374,1.943987070129049,-0.10586696057882339
199.00000000000213,16.03886699977214,1.9563627814825675,-0.10781663299831923
200.20000000000215,16.075859408355413,1.9691061961185525,-0.1092391116343272
201.40000000000217,16.112246479935536,1.9799073224796206,-0.10925114085983267
202.60000000000218,16.149289738700826,1.9926215206369335,-0.1105768579985873
203.8000000000022,16.185837706196008,2.0033486812243626,-0.11095305845290593
205.00000000000222,16.22273782553244,2.0166461266242584,-0.11204795779426746
206.20000000000223,16.259231175539647,2.0265874055395323,-0.11320010705627626
207.40000000000225,16.295928868304586,2.040304433690626,-0.1132271297184575
208.60000000000227,16.33287627302336,2.053287837285439,-0.11468643564216707
209.80000000000229,16.36917000000007,2.0654900000000307,-0.11581999705621193
211.0000000000023,16.40580749749931,2.078479732732858,-0.11698785523268729
212.20000000000232,16.44254439980884,2.0902924459984757,-0.11715803429269789
213.40000000000234,16.47888092281224,2.102690146686947,-0.11845958401943735
214.60000000000235,16.51582855000952,2.1165415523211393,-0.11909422597253316
215.80000000000237,16.552145062923408,2.129204883530098,-0.1200169113475078
217.0000000000024,16.58874090294661,2.1426593952814934,-0.12119868231873321
218.2000000000024,16.625331374196083,2.1548109074080726,-0.12255473429910912
219.40000000000242,16.661711963939034,2.1664965055504517,-0.1239438219798834
220.60000000000244,16.698548369184504,2.179261562949539,-0.1253519499768072
221.80000000000246,16.73505146810465,2.192990498054779,-0.12688128430710366
223.00000000000247,16.771481025109026,2.204344604624511,-0.1283006279657326
224.2000000000025,16.807957493361034,2.2164810364198178,-0.12920911124094792
225.4000000000025,16.844538499163406,2.229553540584538,-0.12989880865659575
226.60000000000252,16.88097440438479,2.2402005595626817,-0.1320285313517675
227.80000000000254,16.91694196996312,2.252323038538932,-0.1341107140430089
229.00000000000256,16.9538877213259,2.263310162620892,-0.13556755281096144
230.20000000000258,16.989742815009105,2.275428139199307,-0.1382449502400247
231.4000000000026,17.026196114061925,2.28357764964896,-0.13958697543406995
232.6000000000026,17.06210178249389,2.295672470519218,-0.14107221344092435
233.80000000000263,17.09943877555539,2.3055212686093967,-0.1429472253133035
235.00000000000264,17.13567276156648,2.3154383542978567,-0.14550490548817363
236.20000000000266,17.17108999337551,2.3256030188085233,-0.14743106274336704
237.40000000000268,17.208191007427068,2.3350836046375743,-0.1492944178540525
238.6000000000027,17.244387632616103,2.3427244075761955,-0.1518057102810637
239.8000000000027,17.28095829793771,2.352222424244229,-0.15394292201164772
241.00000000000273,17.317165314991406,2.3594364895093554,-0.15729601483256594
242.20000000000275,17.353734830888655,2.3675540026198747,-0.15901688376108636
243.40000000000276,17.38950602479515,2.3752959046082176,-0.16057718916364472
244.60000000000278,17.426168119138836,2.384591074373834,-0.16271894353370397
245.8000000000028,17.462535073846247,2.388940471695819,-0.16614247148847516
247.0000000000028,17.49877413480867,2.3972851854841997,-0.16821884064967918
248.20000000000283,17.53529840095058,2.4027910231004785,-0.17125385565844553
249.40000000000285,17.57156706979248,2.4103462857598585,-0.17342663937371228
250.60000000000286,17.607851674111213,2.413741605668431,-0.17671250983420128
251.80000000000288,17.644165948405735,2.4185413935165583,-0.18050626501476152
253.0000000000029,17.6792620495539,2.4240586523190277,-0.18515505789011133
254.20000000000292,17.716367276229985,2.4287209117237674,-0.18902527553713622
255.40000000000293,17.752564212253773,2.4322784531807518,-0.19150070820610843
256.600000000003,17.788869555502725,2.435929521279247,-0.1948813025457281
257.80000000000297,17.825456353344357,2.439970572770269,-0.19854110386558332
259.00000000000296,17.861662367886282,2.443665058997746,-0.20188906652411598
260.200000000003,17.897450340111728,2.448146502841697,-0.20539383021945934
261.40000000000305,17.933979645880402,2.451264585822272,-0.20869006971903037
262.60000000000304,17.970227878347288,2.456241022274484,-0.2123321811571266
263.800000000003,18.00636557090053,2.462608134022469,-0.215702567677015
265.00000000000307,18.042728713621607,2.466168524860943,-0.21892799106527905
266.2000000000031,18.07883832533052,2.469990583061209,-0.2223082248311159
267.4000000000031,18.11515008697921,2.473953039144647,-0.2265162165334833
268.6000000000031,18.1514789863648,2.480022612470483,-0.23130768506498667
269.80000000000314,18.187427263265125,2.4851622833880676,-0.23551392882724453
271.0000000000032,18.223771995661313,2.4906800409772716,-0.2400690671475436
272.2000000000032,18.259882047422085,2.4940172565334016,-0.244825476962808
273.40000000000316,18.295927832916448,2.499172810792588,-0.2494251723982508
274.6000000000032,18.332427681352595,2.5062466322332666,-0.25408170339458946
275.80000000000325,18.368606047658265,2.510885214569438,-0.2601042665410169
277.00000000000324,18.404891291083107,2.5158196097312646,-0.26429090704195835
278.20000000000323,18.441151388197632,2.5204288710293365,-0.27012298124986156
279.4000000000033,18.477132067767954,2.5241669720047852,-0.2758625105881123
280.6000000000033,18.513455976102314,2.52833513675341,-0.2835352810373446
281.8000000000033,18.549895845708477,2.5334915726841207,-0.28933024145467856
283.0000000000033,18.585500042920483,2.5371681912027113,-0.2950706829288934
284.20000000000334,18.62247074780674,2.5385297459973604,-0.30190573695065037
285.4000000000034,18.65871177851593,2.543258159363031,-0.3099681673817507
286.6000000000034,18.694880915293204,2.5470247748713883,-0.3195587774275319
287.80000000000337,18.731168502326067,2.547429714089842,-0.32655156033633315
289.0000000000034,18.767510367931994,2.551520662739496,-0.33399440046838347
290.20000000000346,18.803994666012127,2.551485320624374,-0.3420670325505335
291.40000000000344,18.84029874039335,2.5502628134682133,-0.3515438122002661
292.60000000000343,18.876598660994773,2.5513945194293317,-0.3628953179686438
293.8000000000035,18.912615210986143,2.5497009760877987,-0.37304344424305924
295.0000000000035,18.94905209448083,2.548185669082891,-0.38474602489304255
296.2000000000035,18.985377171480394,2.5469835901847557,-0.39703890563180044
297.4000000000035,19.021775220989454,2.5425733826260584,-0.4089000224465411
298.60000000000355,19.05784769068176,2.5377150964417234,-0.42180126394247086
299.8000000000036,19.09419416981067,2.533515296938491,-0.43335149050524535
301.0000000000036,19.130949345962044,2.5274631061275876,-0.44670135535185906
302.20000000000357,19.16664381838767,2.520860014553856,-0.46070967781351646
303.4000000000036,19.203106083182643,2.514945014134348,-0.47586332637619533
304.60000000000366,19.239505429921834,2.5063445919677045,-0.4909893202413502
305.80000000000365,19.275792572986795,2.4998762053224555,-0.5070996140237987
307.00000000000364,19.312017205714348,2.490330630694384,-0.5249095442777776
308.2000000000037,19.34844056304978,2.481593516412423,-0.5436349808911638
309.40000000000373,19.384638796687568,2.475002440471506,-0.5618805500065465
310.6000000000037,19.421062697003286,2.465052341747653,-0.5804884235647467
311.8000000000037,19.45739427182537,2.45453368094833,-0.5991072310610313
313.00000000000375,19.4937151803873,2.4466458216383966,-0.6187081935977843
314.2000000000038,19.53033278621692,2.4393991317814,-0.6389128879664074
315.4000000000038,19.566614928634262,2.430156753760755,-0.6593903957877547
316.6000000000038,19.60298473422732,2.4263587124697867,-0.6806978473993084
317.8000000000038,19.638935924954424,2.419755668507749,-0.701960384551461
319.00000000000387,19.675502214246073,2.413802749189024,-0.7241981535739828
320.20000000000385,19.711965510621457,2.4120882531262637,-0.7468680193258246
321.40000000000384,19.748668168729058,2.4087093050262522,-0.7695301534091183
322.6000000000039,19.78479020259874,2.406869573942269,-0.7926913529602939
323.80000000000393,19.821569460766685,2.4072231211748965,-0.8160873596773426
325.0000000000039,19.857774431964877,2.4078802728122746,-0.8386192469232538
326.2000000000039,19.894313244534562,2.408725873052208,-0.8608253626669922
327.40000000000396,19.930752185460815,2.412531095946063,-0.8828318914653157
328.600000000004,19.966890422908683,2.418856014344058,-0.9049232895717925
329.800000000004,20.0036325390283,2.423782451943419,-0.9277974628230643
331.000000000004,20.040030929124306,2.430784933935914,-0.9523662230461918
332.200000000004,20.07633812403745,2.441092757189518,-0.9751270214375709
333.40000000000407,20.113093569699284,2.4504852038163563,-0.9980962981308541
334.60000000000406,20.149715869406403,2.4606012531948456,-1.0215774712340018
335.80000000000405,20.186514480325997,2.4723106336135463,-1.0455537339197454
337.0000000000041,20.222919514458987,2.4837379585581782,-1.0689298232999631
338.20000000000414,20.259416678190405,2.497289758183613,-1.0921946447925595
339.4000000000041,20.29627389474982,2.510774413341545,-1.1164869012015255
340.6000000000041,20.332814151119116,2.5265884617429526,-1.1405982128869372
341.80000000000416,20.369385117307484,2.5430493938368177,-1.163823079439405
343.0000000000042,20.40621919728666,2.558707695578912,-1.1873867572657009
344.2000000000042,20.442950658059004,2.575040799905847,-1.2116342269413098
345.4000000000042,20.479700624305373,2.594654565638094,-1.2366349926638067
346.60000000000423,20.516255710222428,2.6109220071062405,-1.261372278055953
347.8000000000043,20.553200356918286,2.632609428305393,-1.2856265748737092
349.00000000000426,20.58958578455418,2.651268762198712,-1.3115535723613365
350.20000000000425,20.62657019383492,2.6743099269100625,-1.339135688438632
351.4000000000043,20.663558418156658,2.6936155129093686,-1.365087081416433
352.60000000000434,20.700345751941228,2.715301899247594,-1.3920054775761335
353.80000000000433,20.737226451097758,2.7385034370145926,-1.4205788944583002
355.0000000000043,20.774162122413617,2.760986033296126,-1.4492732754486037
356.20000000000437,20.81080625363943,2.7845425083008974,-1.4772231299973275
357.4000000000044,20.847635756953032,2.8104142702547152,-1.5065545037988834
358.6000000000044,20.884625099726964,2.8374260218748155,-1.5366949476263896
359.8000000000044,20.921506986760036,2.86149865926033,-1.5681581557718989
361.00000000000443,20.95879920067451,2.88847811962665,-1.5997806302545245
362.2000000000045,20.995617397756423,2.915508877322592,-1.6326581325952096
363.40000000000447,21.032557364899223,2.9417106522445233,-1.6666647626044289
364.60000000000446,21.069107051976786,2.971008762235203,-1.7017316147343409
365.8000000000045,21.106568132478305,3.0004532314110217,-1.7380523106218333
367.00000000000455,21.143498163264695,3.0296368040106385,-1.7760830209456442
368.20000000000454,21.180645234213227,3.0576684838125696,-1.8158051202643195
369.4000000000045,21.21768949305552,3.08665817690638,-1.8555791103987054
370.60000000000457,21.25495634708616,3.1153095816827547,-1.8960730261590442
371.8000000000046,21.291984975712076,3.1407658622939305,-1.9369122231872367
373.0000000000046,21.32917000000015,3.165010000000094,-1.979280048401932
374.2000000000046,21.366338359652318,3.185957742288817,-2.02342501663483
375.40000000000464,21.403371298033196,3.20591528491372,-2.070462074354011
376.6000000000047,21.440393230719568,3.2244135995240986,-2.1161251658997795
377.8000000000047,21.477534614865426,3.234788559583308,-2.1626654269453605
379.00000000000466,21.514715954730242,3.240352122792928,-2.209662192923923
380.2000000000047,21.551875072912697,3.2413945817586316,-2.257350488215631
381.40000000000475,21.589231306518673,3.2369555996129766,-2.306433097803924
382.60000000000474,21.62640404837602,3.2256399279432437,-2.357622889192344
383.80000000000473,21.663705376659617,3.203510476158401,-2.4091344283076657
385.0000000000048,21.700620842957438,3.1758542806211194,-2.4587560179396366
386.2000000000048,21.73814513406498,3.13525895913526,-2.507953459468346
387.4000000000048,21.774636805312543,3.087557003191199,-2.5549682357311587
388.6000000000048,21.812202516889418,3.031358779005504,-2.5997420264399542
389.80000000000484,21.848578642332935,2.964004678184701,-2.643364419484149
391.0000000000049,21.88662121731295,2.882620402234407,-2.6875556068012667
392.2000000000049,21.92369102158219,2.7951724047345747,-2.7287322138293906
393.40000000000487,21.960554120596136,2.6986649892160655,-2.7674308045190097
394.6000000000049,21.997914530372846,2.5959725844158354,-2.8043564844781677
395.80000000000496,22.03519332662683,2.486983066014309,-2.838542478401079
397.00000000000495,22.072003584123927,2.3795851322748582,-2.867727275700509
398.20000000000493,22.10907621530436,2.2709955329910505,-2.895479581152852
399.400000000005,22.14648028748163,2.166112365086982,-2.918621586113048
400.600000000005,22.183365029316047,2.0705187698951266,-2.9389531980388
401.800000000005,22.220583638180855,1.9844115099738393,-2.955950270135877
403.000000000005,22.257766772087443,1.9054899897900637,-2.97040596300741
404.20000000000505,22.29485257800866,1.8434965884636676,-2.9822437675494538
405.4000000000051,22.331889573669507,1.7907408396303206,-2.991774675593716
406.6000000000051,22.36916969860551,1.7457303300956994,-3.001009753607439
407.80000000000507,22.406303744877984,1.7110511029533861,-3.0083538527984874
409.0000000000051,22.443659400659616,1.6806382325021456,-3.012987768741837
410.20000000000516,22.480945609329467,1.6578213205846544,-3.020393331609502
411.40000000000515,22.518004295457533,1.635684092013195,-3.0250707922176954
412.60000000000514,22.555327227228872,1.6187242733295168,-3.0308909744366073
413.8000000000052,22.592565961915255,1.604909044571263,-3.0352762331177843
415.00000000000523,22.63010867891385,1.591348972788951,-3.0388708039915935
416.2000000000052,22.667144145813975,1.5794837824053007,-3.0433210635260703
417.4000000000052,22.70462297524081,1.5672311338065683,-3.0494117150729907
418.60000000000525,22.742124619912683,1.5559533509085457,-3.0527077106276397
419.8000000000053,22.77913821131361,1.5481570012444492,-3.0561527007064884
421.0000000000053,22.816770156552835,1.5397377746408982,-3.059371896654988
422.2000000000053,22.854268974303658,1.5312417548591586,-3.063286332249324
423.4000000000053,22.89160395682493,1.5245982297106055,-3.067746348992606
424.60000000000537,22.92895342424718,1.5192532423578053,-3.0712490273841326
425.80000000000535,22.96636189090172,1.5127949593852543,-3.076964065137311
427.00000000000534,23.003800567259617,1.5061748863482216,-3.0814775688247495
428.2000000000054,23.04120252203745,1.501746808606288,-3.084595660059403
429.40000000000543,23.079074956861273,1.4964509080504946,-3.088200837481643
430.6000000000054,23.11639533445911,1.4916285101510482,-3.0914101639931717
431.8000000000054,23.154050862800645,1.4892765746850958,-3.0947085744585205
433.00000000000546,23.191655359400194,1.4839149499130924,-3.0988247729372067
434.2000000000055,23.22913965393902,1.4820630060966589,-3.1022484961572028
435.4000000000055,23.266738768897767,1.4803881671201473,-3.1058761859465305
436.6000000000055,23.30408682392226,1.4762126670900835,-3.109017780434116
437.8000000000055,23.3421142714634,1.4778641203200529,-3.1126317846986424
439.00000000000557,23.37979907217795,1.4748308591052126,-3.1159653132685103
440.20000000000556,23.417618806392262,1.4741818952511156,-3.120961227698501
441.40000000000555,23.45504489322123,1.474242190224481,-3.125055096182937
442.6000000000056,23.492903838374968,1.4755475849499604,-3.12860584708762
443.80000000000564,23.530553726842165,1.477341917094593,-3.1313806108993347
445.0000000000056,23.568582526745086,1.4763895331598378,-3.134996620314413
446.2000000000056,23.60616802398529,1.4794933940539097,-3.1377007666929106
447.40000000000566,23.6438575915015,1.4801829789238659,-3.1405778946415164
448.6000000000057,23.681697546882017,1.4822668653527629,-3.1426770078675355
449.8000000000057,23.719360937300102,1.4867518332446406,-3.1467105137818407
451.0000000000057,23.75774293891835,1.490135362637294,-3.1507930645608595
452.20000000000573,23.795432102777504,1.4932150515916467,-3.1532200207786696
453.4000000000058,23.833352130351322,1.4974336995831892,-3.1565011922318673
454.60000000000576,23.871172493841996,1.5020275106948222,-3.1598362035096086
455.80000000000575,23.909042237537594,1.5074227331573997,-3.161251210495663
457.0000000000058,23.94696095835883,1.5117728654672682,-3.1647198541755355
458.20000000000584,23.984937129766376,1.5162754969611518,-3.168439252499922
459.40000000000583,24.022954939078414,1.5226086849634204,-3.1710536116377543
460.6000000000058,24.06086509947755,1.527554047655964,-3.174908687051203
461.80000000000587,24.098848342659437,1.5346170229680143,-3.176605152131595
463.0000000000059,24.136825611427934,1.5397563615466405,-3.179369727006526
464.2000000000059,24.174922519153885,1.5465812339453748,-3.1821648709272994
465.4000000000059,24.21293145518564,1.5539854108392726,-3.1835046144351855
466.60000000000593,24.250959558968617,1.560109929962317,-3.18553539375167
467.800000000006,24.289264366939914,1.5658162341887358,-3.187156089211994
469.00000000000597,24.326969938085117,1.5724493590427167,-3.1913256287115757
470.20000000000596,24.365428254937836,1.5788207678508213,-3.195227233556552
471.400000000006,24.403128595752378,1.585085906423256,-3.196533189416377
472.60000000000605,24.44145371134961,1.590615410306453,-3.1984576656114663
473.80000000000604,24.479556831333397,1.5992174239768469,-3.2005791110261628
475.000000000006,24.51758493484611,1.6037096541925038,-3.2034860796807747
476.20000000000607,24.555965357205736,1.6102883802634465,-3.2050315979922024
477.4000000000061,24.59415330520231,1.6150923442312757,-3.206802854192347
478.6000000000061,24.632092709787155,1.6224067888125262,-3.2092266857906
479.8000000000061,24.670645444287764,1.626067858609693,-3.2113930802500126
481.00000000000614,24.70825858021119,1.630067522549659,-3.2138155895624445
482.2000000000062,24.747074706394876,1.6374619512925923,-3.2163047300909158
483.4000000000062,24.78516202498131,1.6427327947309784,-3.2177293598337693
484.60000000000616,24.823303332524187,1.6460097892234729,-3.2191807210098435
485.8000000000062,24.861755220468797,1.6507464651323664,-3.220805362764956
487.00000000000625,24.89992791992656,1.6544246066585162,-3.222253419221772
488.20000000000624,24.93817060037717,1.658594065729336,-3.2240111608122777
489.40000000000623,24.976766864503418,1.6640922841890442,-3.2269449779878663
490.6000000000063,25.015273003858347,1.6678614867615453,-3.228983390555081
491.8000000000063,25.053478754305985,1.6715442845266941,-3.2303461602845016
493.0000000000063,25.091725902204068,1.6757109632258678,-3.232598367364916
494.2000000000063,25.130317757359627,1.6796866048737382,-3.233926564808394
495.40000000000634,25.168633979338782,1.6826461640610997,-3.23540465618876
496.6000000000064,25.206687777051563,1.6859304963446289,-3.237073151403669
497.8000000000064,25.245435394795916,1.6879748046317407,-3.239447233289543
499.00000000000637,25.284068548473854,1.691767462312027,-3.240828588791048
500.2000000000064,25.322398306948692,1.6951230619047637,-3.24234207214141
501.40000000000646,25.360869056097822,1.6992105507198778,-3.2441261832752244
502.60000000000645,25.39926643728791,1.699823935575861,-3.2447221667114894
503.80000000000643,25.437668652090856,1.7050730191401708,-3.245720481731564
505.0000000000065,25.476260002282554,1.706617096451674,-3.247207113382001
506.2000000000065,25.51477656115076,1.7084260023231204,-3.2486576776320573
507.4000000000065,25.553309938341197,1.7112206349623014,-3.2499714675750537
508.6000000000065,25.591884524029602,1.7161224275427263,-3.2515120517070084
509.80000000000655,25.63039628375326,1.7144947981072733,-3.2529199962670083
511.0000000000066,25.668943031566506,1.7169924292461962,-3.2547961657959807
512.2000000000066,25.70796581525786,1.72110148723606,-3.2553861579304035
513.4000000000066,25.74646495527683,1.7218977575771213,-3.257010429172178
514.6000000000066,25.784781408124942,1.7244919149077553,-3.2579079806340414
515.8000000000067,25.82335960724472,1.7276001169182231,-3.2593859348695093
517.0000000000066,25.861689888483856,1.7300298138636148,-3.2607156661942804
518.2000000000066,25.9005736633555,1.732176124399911,-3.2621352695836974
519.4000000000067,25.939358087940676,1.7328914943211826,-3.2639474459444546
520.6000000000067,25.977796173725554,1.736794641180132,-3.2652324973583946
521.8000000000068,26.016427115953064,1.7377760152046429,-3.2665460372266235
523.0000000000067,26.054713319031855,1.7386506008954001,-3.266857890163176
524.2000000000068,26.093775824495474,1.741829088434501,-3.2688893193969375
525.4000000000068,26.132533642952623,1.7427012459662836,-3.270756520799409
526.6000000000067,26.171195640756444,1.7431441677328117,-3.270950150298963
527.8000000000068,26.209678171357805,1.7461323000174427,-3.272402653734978
529.0000000000068,26.24849587936563,1.747501731727513,-3.273902847475231
530.2000000000069,26.287029379247276,1.747645979402625,-3.2743919030459194
531.4000000000069,26.325586342848407,1.75051811949642,-3.2752526174051493
532.6000000000068,26.364315942232015,1.7513721361014378,-3.2769047945722267
533.8000000000069,26.402871295636942,1.7535764460950052,-3.2768764615420247
535.0000000000069,26.44186899870698,1.7545476552213546,-3.279086901524955
536.2000000000069,26.4807004273257,1.758688001613169,-3.2802712447130498
537.4000000000069,26.51942077798861,1.7576364270372604,-3.280497048832973
538.600000000007,26.558212593345125,1.7604034580270298,-3.280487450444416
539.800000000007,26.597223679038734,1.7640534515727548,-3.281821770877094
541.000000000007,26.635629686653502,1.7698755051684627,-3.2833500143523104
542.200000000007,26.674618231070706,1.7777536790609392,-3.284746286525672
543.400000000007,26.713129206139126,1.7848806857426769,-3.2863132846851304
544.6000000000071,26.752128459780764,1.791529163192441,-3.2868124631872364
545.800000000007,26.79079111610326,1.7969831173854038,-3.2874923855645264
547.000000000007,26.829465848773523,1.8043065009072259,-3.2888289224297207
548.2000000000071,26.868301088362017,1.8105154586326861,-3.2901325864315414
549.4000000000071,26.907340188119083,1.814975770283811,-3.291447362973787
550.6000000000072,26.94612801390101,1.8186579728642773,-3.2925262625884972
551.8000000000071,26.98494542110538,1.8227227538312305,-3.2927577079013735
553.0000000000072,27.02374018096709,1.8264592836132438,-3.2948730139120057
554.2000000000072,27.062622123718533,1.8316049717740361,-3.295043678217385
555.4000000000071,27.10160136910423,1.8363572686980318,-3.2963869855917194
556.6000000000072,27.140808812591487,1.8405181921100329,-3.2968784594522775
557.8000000000072,27.17968643058059,1.8436641054801846,-3.2977010333159322
559.0000000000073,27.21825682777343,1.8464872763194728,-3.2990308539226643
560.2000000000073,27.25729124994747,1.8519088712953167,-3.300214338257415
561.4000000000073,27.296316331977312,1.8552738651189307,-3.3003734095161996
562.6000000000073,27.335212294279486,1.8638629668529108,-3.301665730766506
563.8000000000073,27.374304920001563,1.8664172755218902,-3.301654663119699
565.0000000000073,27.413354638795482,1.8696616682740197,-3.3029644582220916
566.2000000000073,27.45250395156912,1.8741359774361988,-3.304468162109223
567.4000000000074,27.490986845833167,1.8776031966351738,-3.304390328393877
568.6000000000074,27.5305360796501,1.8818131772573496,-3.304493015841728
569.8000000000075,27.56923293409332,1.885893708875309,-3.3057199948317777
571.0000000000074,27.608648261148847,1.8864638028744594,-3.3063368881269533
572.2000000000074,27.647538756405382,1.8894978683910986,-3.307050274415616
573.4000000000075,27.686589228502854,1.8895839932806222,-3.3083548622121874
574.6000000000074,27.725748154068356,1.8942818244655302,-3.3089945158150402
575.8000000000075,27.765018195362668,1.8953117965499773,-3.309666953293707
577.0000000000075,27.804131159919475,1.8962391000166672,-3.310710525447173
578.2000000000075,27.843195713269985,1.8957391994195858,-3.3113379181040585
579.4000000000076,27.88234517488679,1.8953311368183672,-3.312232763713066
580.6000000000075,27.92187674480243,1.891143638701386,-3.3135355746609534
581.8000000000076,27.960879102819423,1.8906629240463797,-3.3157273975383723
583.0000000000076,28.00003630702238,1.8870370480354166,-3.316259080762089
584.2000000000075,28.03923419579355,1.8883586972145616,-3.315275556011167
585.4000000000076,28.0784943829629,1.8823647981234175,-3.316579736868213
586.6000000000076,28.117813210594715,1.8821196087967866,-3.316804335628043
587.8000000000077,28.15701356152589,1.8806516173887853,-3.3180040927284917
589.0000000000077,28.196467919161563,1.8825245087541518,-3.318437314334435
590.2000000000077,28.23580729373515,1.8801117040613595,-3.3193492971713656
591.4000000000077,28.275125662932304,1.8799000048763064,-3.3206442891857426
592.6000000000078,28.314372031103083,1.8799112493104913,-3.320707536006254
593.8000000000077,28.353912968847332,1.8820837235417125,-3.3219500882283763
595.0000000000077,28.393282141691394,1.8816932654824217,-3.3231848277350036
596.2000000000078,28.43247801769037,1.879036733497733,-3.3232707394305505
597.4000000000078,28.47196485679846,1.8813281624888298,-3.3233899944253116
598.6000000000079,28.51131655118903,1.8835660723789411,-3.3246519512549026
599.8000000000078,28.550674059719544,1.8832619277746134,-3.3268973239913975
601.0000000000078,28.59001419411376,1.8841972412441128,-3.326874824519466
602.2000000000079,28.62943241640305,1.8837984945639223,-3.3282098289225632
603.4000000000078,28.668881428266126,1.8864723228330504,-3.328212509239988
604.6000000000079,28.7081420771964,1.886459131736172,-3.329529005572631
605.8000000000079,28.747967812740296,1.886244671732529,-3.329534384545325
607.000000000008,28.787628676430863,1.8861361026085373,-3.3308422598546628
608.200000000008,28.82676735925623,1.8883149596298638,-3.3309958683850605
609.4000000000079,28.86626045298711,1.8879473814962497,-3.3322656202381307
610.600000000008,28.905984321175385,1.8910260429232943,-3.3326586834190493
611.800000000008,28.94546743024135,1.8897800293715568,-3.3335874172377653
613.000000000008,28.98505820474797,1.8911397509591399,-3.332973832834157
614.200000000008,29.02424443317455,1.8922321542806093,-3.3342460070765187
615.400000000008,29.064490521180794,1.893937558335667,-3.334325222840072
616.6000000000081,29.103694799524426,1.896386772276363,-3.3355562707747453
617.8000000000081,29.143122785098022,1.896921322980202,-3.335569749676969
619.0000000000081,29.182762527593564,1.8954667628309052,-3.3368783501001724
620.2000000000081,29.22227826120941,1.8978387801995629,-3.3368923513698405
621.4000000000082,29.262069082128303,1.898585509807387,-3.338193825420343
622.6000000000081,29.301871432132923,1.8985498782377779,-3.3389936124688466
623.8000000000081,29.341077133382598,1.9038122515190778,-3.3388180165439416
625.0000000000082,29.38046117437452,1.9036579150110753,-3.3401517354956423
626.2000000000082,29.420571348904733,1.9049375232681782,-3.3401598346272157
627.4000000000083,29.460055445058302,1.9085768274801613,-3.34015153120533
628.6000000000082,29.499305656066458,1.90884890055964,-3.341469107606351
629.8000000000083,29.538969890596334,1.9112164789631192,-3.3414692973635662
631.0000000000083,29.578649534849376,1.9154126534729452,-3.342787958510667
632.2000000000082,29.618218475560035,1.9180861555840443,-3.342802077559722
633.4000000000083,29.658080166816326,1.921462252079962,-3.3441116431534503
634.6000000000083,29.697384902641026,1.9227873860556084,-3.3441087527012305
635.8000000000084,29.737019284879025,1.9242403391468985,-3.344709143574108
637.0000000000084,29.776735808303464,1.9271667301240603,-3.344753674787634
638.2000000000083,29.816269069162633,1.9289515048117565,-3.3460586644958377
639.4000000000084,29.855433653429643,1.9306035700400852,-3.34607166615954
640.6000000000084,29.89580164911631,1.9341509145617617,-3.34737152638935
641.8000000000084,29.93546417932261,1.9364969345293535,-3.3473925975555456
643.0000000000084,29.97518744074683,1.939753526527115,-3.3486728595572486
644.2000000000085,30.01458826624029,1.943122510216055,-3.34871160443873
645.4000000000085,30.05440008587576,1.9468587803965478,-3.3501203304452805
646.6000000000085,30.094189738215206,1.9478961259190068,-3.350026995117016
647.8000000000085,30.133614287040345,1.9528842179579038,-3.3510379582437024
649.0000000000085,30.17330837216727,1.954857105714219,-3.3513386251502526
650.2000000000086,30.212602621235302,1.9603667972169025,-3.3512980057262016
651.4000000000085,30.25258559479217,1.9638494081717524,-3.3524312529420723
652.6000000000085,30.29252707728559,1.9663072987671384,-3.352668393031293
653.8000000000086,30.332024380537288,1.968707707741221,-3.3540282720956744
655.0000000000086,30.3715187067429,1.9721339578910864,-3.3539802843166897
656.2000000000087,30.41145454739032,1.9777684834424318,-3.353959602948648
657.4000000000086,30.450938241000372,1.978973285475264,-3.3552954772869503
658.6000000000087,30.491067622962248,1.9863447283074758,-3.3566512312812464
659.8000000000087,30.53035159313685,1.98520027219554,-3.355261626422979
661.0000000000086,30.570277761127645,1.9923785143566453,-3.3552882434905915
662.2000000000087,30.610157206014634,1.993499674314922,-3.356358662543677
663.4000000000087,30.649532346439543,1.9976187801924439,-3.3566098046273187
664.6000000000088,30.689270188164798,2.0015836039154586,-3.3566097396635155
665.8000000000088,30.729007594479157,2.004282095383238,-3.356297538488577
667.0000000000088,30.768808246345106,2.009916319304206,-3.3576341776777054
668.2000000000088,30.80856953292267,2.0122789589425265,-3.356628904252549
669.4000000000088,30.84866190461442,2.0160715955985076,-3.3579303875833304
670.6000000000088,30.88780775356574,2.0197302700934796,-3.3579304732995823
671.8000000000088,30.927956204941648,2.0254802625651847,-3.358484622640039
673.0000000000089,30.967461101778184,2.029139018620552,-3.359938046198675
674.2000000000089,31.007126323494326,2.0315293488255173,-3.359921182169746
675.400000000009,31.04701995284377,2.0349082270889767,-3.3612433555274857
676.6000000000089,31.08664697512691,2.0407534109807854,-3.361219546764312
677.8000000000089,31.126556441012962,2.0424659586348546,-3.361129806075098
679.000000000009,31.16615352063107,2.0452531462738444,-3.363236633269689
680.2000000000089,31.20573738246866,2.0502636310282023,-3.3630845077026477
681.400000000009,31.24556861067396,2.055717083249857,-3.363908351766364
682.600000000009,31.285761398692678,2.0573275867267014,-3.363200568383174
683.800000000009,31.325386609319203,2.066141337756756,-3.363545397274847
685.0000000000091,31.365302069917348,2.068830612953303,-3.364513788584169
686.200000000009,31.405114881892075,2.0724797388449128,-3.3648395935168027
687.4000000000091,31.444783225708555,2.07921519582093,-3.3658316665589005
688.6000000000091,31.48443560023944,2.081855950298076,-3.36532339228612
689.800000000009,31.524377463046964,2.085266356680586,-3.3644629202806744
691.0000000000091,31.564287406258483,2.090236328910653,-3.365817230496086
692.2000000000091,31.60393844919627,2.0925307142674994,-3.365831201989348
693.4000000000092,31.64380534921418,2.099043342039221,-3.367040434257273
694.6000000000092,31.68352703584637,2.1020813005718844,-3.368458778000548
695.8000000000092,31.723497677418607,2.1076692683762577,-3.368457232439834
697.0000000000092,31.76328113831096,2.110218553614612,-3.3694555628957366
698.2000000000093,31.803174999157655,2.1144855574941523,-3.3688062575106184
699.4000000000092,31.84331369614693,2.117265070887142,-3.368461126974381
700.6000000000092,31.882916256604325,2.1212609644984988,-3.3684815054475017
701.8000000000093,31.923006434785687,2.1265975503982517,-3.3708424907683168
703.0000000000093,31.962662051612632,2.130038228488684,-3.370746147953128
704.2000000000094,32.00240917540162,2.1329335115081967,-3.369753623201679
705.4000000000093,32.04261480050606,2.1396245958538835,-3.369770117110889
706.6000000000093,32.08263149885235,2.1408605964423795,-3.369771284125274
707.8000000000094,32.122482308208824,2.1443031577822693,-3.371180893553386
709.0000000000093,32.162265766490464,2.14794958002561,-3.3710905764657184
710.2000000000094,32.202234991391784,2.1525417036350087,-3.371089915742089
711.4000000000094,32.24199237384841,2.1577701509454523,-3.371056803884037
712.6000000000095,32.28209652019265,2.1600944860188274,-3.3723982442515603
713.8000000000095,32.321824574601806,2.1619420391863744,-3.3724098121218615
715.0000000000094,32.36232029152865,2.1692598826619136,-3.37237667072025
716.2000000000095,32.402393326886546,2.1736533820930966,-3.3737065984242998
717.4000000000095,32.44249044708942,2.1754043893413355,-3.3737200581861333
718.6000000000095,32.482544243710514,2.1773371402105006,-3.3737197435399953
719.8000000000095,32.522463530124995,2.1831334242296574,-3.373650855544839
721.0000000000095,32.5625611851616,2.187749062368103,-3.3743892370253668
722.2000000000096,32.60290586639337,2.190133773341013,-3.3737094210482432
723.4000000000096,32.64317772675651,2.1972086091777925,-3.373724157808847
724.6000000000096,32.683263012766005,2.199753426697758,-3.374968073110429
725.8000000000096,32.72335183259789,2.2031745906229268,-3.3751235658170327
727.0000000000097,32.76331255411269,2.2062161165846295,-3.376359475025421
728.2000000000096,32.803757649343495,2.2094030946111043,-3.377397046632202
729.4000000000096,32.84370340488149,2.2150518178391154,-3.376369252271975
730.6000000000097,32.883904491968856,2.2205682348887743,-3.3763601081112644
731.8000000000097,32.924154915918606,2.225077178866742,-3.3763600661274245
733.0000000000098,32.964463850924304,2.227470329065243,-3.3763600332125767
734.2000000000097,33.00438831684107,2.231347072028752,-3.376353606558804
735.4000000000098,33.04437578271164,2.236428316534298,-3.3776162945806925
736.6000000000098,33.08446308622715,2.2422740921291773,-3.3776716059253826
737.8000000000097,33.12482535492823,2.2449559093676714,-3.3772042969064926
739.0000000000098,33.16507501850597,2.2499563482749476,-3.378000485369827
740.2000000000098,33.2052000734897,2.2569575977067724,-3.3779997395239443
741.4000000000099,33.245570216472345,2.2602366765387334,-3.3779055019936117
742.6000000000099,33.28546843862628,2.262768791820788,-3.3790253473965586
743.8000000000098,33.325971806286056,2.269523523298165,-3.378990314589919
745.0000000000099,33.36607641208376,2.270150137121995,-3.379126165993453
746.2000000000099,33.406234561834374,2.276251367116092,-3.3803134678851836
747.4000000000099,33.446342632411785,2.280502578065695,-3.3802197164045173
748.6000000000099,33.486047687021156,2.2864207595311226,-3.381620515984416
749.80000000001,33.527085840957234,2.290533633717299,-3.380936881039487
751.00000000001,33.567172412164325,2.295750383474558,-3.3806319073919604
752.20000000001,33.60766114935231,2.2997670422106693,-3.3811626260638556
753.40000000001,33.6478289165477,2.3046069000128986,-3.3819508269436773
754.60000000001,33.68806509737016,2.3086331357189773,-3.3819499395693704
755.8000000000101,33.72810331419974,2.3104287580715104,-3.3819499112212026
757.00000000001,33.76838674462092,2.315481176047775,-3.3819460862992825
758.20000000001,33.80910131268621,2.3209574671940034,-3.383269552569187
759.4000000000101,33.84934081531486,2.3257812774118074,-3.383269171657625
760.6000000000101,33.889439696721105,2.331546325009582,-3.384368989566159
761.8000000000102,33.929993491184284,2.3355356982758533,-3.384249718897731
763.0000000000101,33.9701061643216,2.340587129413306,-3.3838471036796927
764.2000000000102,34.0104881230897,2.346000563486657,-3.384025662637992
765.4000000000102,34.05091839704269,2.3500754541180218,-3.384259754075646
766.6000000000101,34.09116660685705,2.357599760077028,-3.3842598740210645
767.8000000000102,34.13190120837308,2.3622557940001503,-3.384260853151761
769.0000000000102,34.171966787842806,2.3664645035628182,-3.384475352045412
770.2000000000103,34.212265522668446,2.3738627425471264,-3.38557023586153
771.4000000000103,34.25255143159396,2.377496968133768,-3.3855066891034378
772.6000000000103,34.29311335643254,2.3794456912907678,-3.3868877587532618
773.8000000000103,34.33299490772119,2.3868174245129974,-3.3863057937420185
775.0000000000103,34.37347373862263,2.3927947345324285,-3.3855696689742456
776.2000000000103,34.413821905090025,2.3976659220583176,-3.3855929732714585
777.4000000000103,34.45448536001164,2.4034158577610416,-3.386896864895231
778.6000000000104,34.49478252626897,2.411431591833758,-3.3868899733370634
779.8000000000104,34.535395529107205,2.4157682038487107,-3.386915724159024
781.0000000000105,34.575649565550634,2.4231230865850604,-3.3882057377802806
782.2000000000104,34.61588203079323,2.427048579409395,-3.388199964896484
783.4000000000104,34.65618851068939,2.4342376164810875,-3.388197004617179
784.6000000000105,34.696417234541634,2.440762080059942,-3.387877268165213
785.8000000000104,34.736899502400775,2.4460133779532978,-3.387870090147965
787.0000000000105,34.7770694882913,2.4525848109475765,-3.3878901066471183
788.2000000000105,34.81781010904075,2.4607371163404457,-3.38919213447062
789.4000000000106,34.858244339497496,2.467575710144718,-3.3891663449109686
790.6000000000106,34.89856857434602,2.4721626977767217,-3.390489213150409
791.8000000000105,34.93893822892174,2.479782450902948,-3.3895486991229147
793.0000000000106,34.979406991786696,2.487839115328566,-3.3895202901455153