File: 01_Data/Basswood_Panel/STA/N2/30K_min/Basswood_Panel_STA_N2_30KData_220315_R2.csv
##Temp./Â°C,Time/min,DSC/(mW/mg),Mass loss/mg
49.0,10.466931008958634,-1.0585137525668786,-0.02209743532010755
50.20000000000002,10.70530766623087,-0.8843190903663595,-0.021537765002089593
51.400000000000034,10.838606014621803,-0.7570955078289779,-0.0217457912179273
52.60000000000005,10.943693660364824,-0.653676979707789,-0.0221147442350218
53.80000000000007,11.031510099980752,-0.5650591050761359,-0.021652946390948724
55.000000000000085,11.109265265487934,-0.48673243099261265,-0.020887952039083668
56.2000000000001,11.180340726931844,-0.41483960141481974,-0.023646550435763913
57.40000000000012,11.246498206772845,-0.34780043504482394,-0.022905586571384084
58.600000000000136,11.308886387653121,-0.28663561583799524,-0.02124725637186753
59.80000000000015,11.367939334659868,-0.230357090087535,-0.023445901653644796
61.00000000000017,11.423780423212884,-0.17559898604947546,-0.022163348751770062
62.20000000000019,11.478377378255123,-0.12419617837331183,-0.02328206079820294
63.400000000000205,11.531327645615036,-0.07690926936048743,-0.02385485422303457
64.60000000000022,11.582967253568041,-0.02930709117800455,-0.02299518361019537
65.80000000000024,11.633360730983352,0.014128728395854601,-0.022950480225781167
67.00000000000026,11.682290437459491,0.056491439597775805,-0.023498041131143843
68.20000000000027,11.730276726554875,0.09527254899709363,-0.023687706767836936
69.40000000000029,11.777940833085637,0.13352418782810077,-0.023651170439296543
70.6000000000003,11.825414792569665,0.17132025378558316,-0.02388471239203316
71.80000000000032,11.871591863620758,0.20425637662764712,-0.0248134396877151
73.00000000000034,11.916947411736686,0.23966440056473706,-0.024861005675900216
74.20000000000036,11.962323709639149,0.27206054877191715,-0.025676212723984015
75.40000000000038,12.006595844312287,0.30381548361589866,-0.024797901142113776
76.60000000000039,12.05131001293027,0.3343616884293422,-0.024095467645779856
77.80000000000041,12.095638385116864,0.3647256853909919,-0.02474716070441474
79.00000000000043,12.139507830869826,0.3934385234864058,-0.024713764304943098
80.20000000000044,12.183205111439982,0.4237045406037847,-0.025929364502745855
81.40000000000046,12.226194726348378,0.4481925136118718,-0.026052911119684996
82.60000000000048,12.268790511711387,0.47515717731592816,-0.026081877596136227
83.8000000000005,12.31137512178151,0.5011293929152917,-0.026645998190945708
85.00000000000051,12.354240665785065,0.5263448813191041,-0.02701450782261894
86.20000000000053,12.395918685372056,0.550934773018726,-0.02787100591819458
87.40000000000055,12.438874865543486,0.5738858590630942,-0.02785948143925454
88.60000000000056,12.480415896585333,0.5967632518911965,-0.0291910410284002
89.80000000000058,12.52061000555477,0.6189269312973492,-0.029153790990092077
91.0000000000006,12.562901799009593,0.6417026506628367,-0.029362834715977115
92.20000000000061,12.604170856594463,0.6603407077258855,-0.030447475527073387
93.40000000000063,12.645602377124723,0.6801332154041121,-0.03218578650189219
94.60000000000065,12.6868717661846,0.7016773479695276,-0.031363644851122974
95.80000000000067,12.727564968985963,0.7202163328609926,-0.03239157797772085
97.00000000000068,12.769082411027789,0.7369102470255102,-0.033451661537376776
98.2000000000007,12.808334169679126,0.7516761788688182,-0.032193420793109606
99.40000000000072,12.8500331513888,0.7689619210164668,-0.033489732983211784
100.60000000000073,12.890727773254998,0.7837554382246076,-0.03256010343482929
101.80000000000075,12.931464824828808,0.7981843775334015,-0.03344940523573614
103.00000000000077,12.972371755872649,0.8100822460492074,-0.033683391042321986
104.20000000000078,13.01190482179678,0.8243169594837931,-0.034769993551644784
105.4000000000008,13.052564771171012,0.8369743268474672,-0.03547805861839315
106.60000000000082,13.093158531491964,0.8484491104800808,-0.03607982127661957
107.80000000000084,13.133511937697016,0.8589863460567069,-0.03647749142851264
109.00000000000085,13.173634206187241,0.8688580900484711,-0.03608587620621595
110.20000000000087,13.214631231513222,0.8789606486757935,-0.03737472628184069
111.40000000000089,13.254481703272612,0.8868021164248062,-0.037425197473865524
112.6000000000009,13.294631655563554,0.8966330585419506,-0.03872536019746242
113.80000000000092,13.334711055314854,0.9058845973523212,-0.038199222652717246
115.00000000000094,13.37477893782355,0.9148762660817202,-0.03812820616685286
116.20000000000095,13.41496928579528,0.9235170596440735,-0.03938650304530178
117.40000000000097,13.454951503816474,0.9305434720067098,-0.039376438352085597
118.60000000000099,13.494988532070428,0.9397145699304676,-0.040428890213277224
119.800000000001,13.534916802324009,0.950315568243528,-0.040003615773897216
121.00000000000102,13.574771685627958,0.9589174947150922,-0.0400290150249103
122.20000000000104,13.614372403592093,0.9682574126169377,-0.039799577465124525
123.40000000000106,13.654666059839998,0.9780611714718467,-0.03870647975271213
124.60000000000107,13.69385168051236,0.9879855281522804,-0.03870725669498487
125.80000000000109,13.733500698628925,0.998644322519393,-0.03955678827367226
127.00000000000111,13.77253964505174,1.0100984223386362,-0.040030370659122294
128.20000000000113,13.812395701533903,1.0199910076425192,-0.041426190643579996
129.40000000000114,13.852169039825334,1.0321918167251851,-0.040875462498127124
130.60000000000116,13.891226758041599,1.0434774095794346,-0.040370671292987215
131.80000000000118,13.930524333451435,1.0555589019503941,-0.04036997480693039
133.0000000000012,13.969428804037458,1.0665311476935238,-0.04062245392170638
134.2000000000012,14.008365212319491,1.0788618262142107,-0.041351692594198575
135.40000000000123,14.047154908960447,1.0918731827981702,-0.04135002155921308
136.60000000000124,14.08619392743921,1.1048699265783177,-0.041350018103411657
137.80000000000126,14.124883062274476,1.1178422875679934,-0.041351703710627685
139.00000000000128,14.163778688150519,1.1318143868305708,-0.04276173816941098
140.2000000000013,14.202527723688235,1.143783239018062,-0.042670297430605686
141.4000000000013,14.241045692304455,1.1581756871983042,-0.0426647840903831
142.60000000000133,14.279598093180743,1.171580032876242,-0.04167631713623221
143.80000000000135,14.318184632794662,1.1853157835948616,-0.04300657108203554
145.00000000000136,14.356618304931345,1.2001148462890328,-0.04299007434333735
146.20000000000138,14.394878439862907,1.2142192156119374,-0.04298861689511302
147.4000000000014,14.433077458024224,1.2279235958566552,-0.04277928702196121
148.60000000000142,14.47175973865026,1.2420346570554033,-0.04234081616840735
149.80000000000143,14.509362214071814,1.2560754441692747,-0.042339939185013
151.00000000000145,14.547692310786323,1.2709325577538302,-0.042341409037060185
152.20000000000147,14.586303530411614,1.2852568164180074,-0.04372496897630329
153.40000000000148,14.62407296600142,1.2976896749843043,-0.04365040567263634
154.6000000000015,14.662224187236834,1.3145186933190813,-0.043649941328670394
155.80000000000152,14.700634068654695,1.3291695977210467,-0.04364993900572811
157.00000000000153,14.738307956798128,1.3399320140124986,-0.04364993656726934
158.20000000000155,14.776098470608833,1.3562707473393831,-0.043649269739270746
159.40000000000157,14.81411614388146,1.368675579979307,-0.044422947172411575
160.6000000000016,14.8521234570211,1.3817831365490532,-0.044947045530655316
161.8000000000016,14.890348066080621,1.3971924161769935,-0.04627936054458415
163.00000000000162,14.92812925282302,1.4122672102187013,-0.046280144389903466
164.20000000000164,14.965713330758337,1.4240283790942891,-0.04629823062749949
165.40000000000165,15.00356107105909,1.4395270185506719,-0.04683241118529535
166.60000000000167,15.041449799672096,1.4528652773360697,-0.046620362416284866
167.8000000000017,15.078820783995909,1.4674656978877498,-0.04661807356311298
169.0000000000017,15.116309639876006,1.4791303065569843,-0.04771246496807802
170.20000000000172,15.154382307017219,1.4948895474735693,-0.047928893546844265
171.40000000000174,15.191558420870482,1.5072823755267775,-0.04792995040108394
172.60000000000176,15.228986746423429,1.5203692557442499,-0.04793682895597762
173.80000000000177,15.266846453894678,1.5352956274079945,-0.04927193984389966
175.0000000000018,15.303980274319686,1.5496534837805116,-0.049581879289327446
176.2000000000018,15.341625532824056,1.5602144288273516,-0.05056049032938059
177.40000000000182,15.378966605952646,1.5740678402504114,-0.05056079172318517
178.60000000000184,15.416468292279252,1.5881727709678297,-0.05100669529137836
179.80000000000186,15.45335184310339,1.6007779312127648,-0.05191035164802926
181.00000000000188,15.490687658411778,1.6124601497691238,-0.05322121680887504
182.2000000000019,15.527901686169248,1.6265584823135961,-0.0532031318451911
183.4000000000019,15.565279466117211,1.6405185957842305,-0.052147759414973294
184.60000000000193,15.602384244470082,1.6524837444462246,-0.05188099964829407
185.80000000000194,15.639601040414071,1.6655855311983545,-0.05188018269946415
187.00000000000196,15.676384363743212,1.676852698982558,-0.05187646138475355
188.20000000000198,15.713091506389064,1.6897178683289464,-0.05279320427907397
189.400000000002,15.750376335461137,1.6998745211063124,-0.05350942755350818
190.600000000002,15.787023320699793,1.7156738252572843,-0.0546469957408644
191.80000000000203,15.824036706732686,1.7261015685908943,-0.05582324356689261
193.00000000000205,15.861280238191437,1.7396612522676556,-0.055173967043827155
194.20000000000206,15.897663899209133,1.749673699989555,-0.05517156379766286
195.40000000000208,15.934691553848463,1.7632317175954837,-0.05658803920518496
196.6000000000021,15.971496095932057,1.7744853109508734,-0.056489369512645826
197.80000000000211,16.008198227550956,1.7858986044189107,-0.05701974047625713
199.00000000000213,16.04496075983746,1.7970350700913917,-0.0587982061296044
200.20000000000215,16.081635521837956,1.8090403450433075,-0.058790178124308756
201.40000000000217,16.11833839579205,1.8210728318354183,-0.05878533351894877
202.60000000000218,16.15482232636344,1.8336986038064325,-0.060036293286873654
203.8000000000022,16.191605402412105,1.84674150632005,-0.06017168667698147
205.00000000000222,16.228330969386313,1.8571866063041411,-0.06142525203640403
206.20000000000223,16.265312629502553,1.8687320600278858,-0.0614293234169363
207.40000000000225,16.301827225476142,1.8823681169711861,-0.06193435696307015
208.60000000000227,16.338325421097483,1.8931412109705232,-0.0626753433915006
209.80000000000229,16.374694998771325,1.9075290377457268,-0.0640653128266031
211.0000000000023,16.411414266016315,1.9197043876206838,-0.06437498862715874
212.20000000000232,16.44826799278812,1.932623988877356,-0.06489637749296717
213.40000000000234,16.484942081134314,1.944219104799817,-0.06593487368501316
214.60000000000235,16.521297249392628,1.95735899505796,-0.06723631172430222
215.80000000000237,16.557886337519953,1.968616554821603,-0.06845965079209382
217.0000000000024,16.594097883505476,1.9823465738254284,-0.06857089935924199
218.2000000000024,16.630982077974085,1.9941755444920668,-0.07008652557382833
219.40000000000242,16.66735071701045,2.006786546053926,-0.07149142390356378
220.60000000000244,16.703669748602586,2.019044844877052,-0.07289398726336227
221.80000000000246,16.740120524205196,2.029847217100523,-0.0735996056909256
223.00000000000247,16.77657646335708,2.043811316309446,-0.07514724074639378
224.2000000000025,16.813400504877663,2.0552679035934656,-0.07658621611151739
225.4000000000025,16.849875666350506,2.067677233390296,-0.07797641116112164
226.60000000000252,16.886084656385016,2.0780580764559655,-0.07982643815135138
227.80000000000254,16.922597419439025,2.08821335675995,-0.08125993057614256
229.00000000000256,16.95891953916627,2.100388741470212,-0.08238182024324647
230.20000000000258,16.995594919886273,2.1101301956761778,-0.08372034421944585
231.4000000000026,17.03184668481768,2.1209862570295357,-0.08482744275337017
232.6000000000026,17.068440176087126,2.13129469114392,-0.08745148216878817
233.80000000000263,17.10452672332693,2.1420502647024566,-0.08889668528076689
235.00000000000264,17.140937333104876,2.150269229511172,-0.09028650868229882
236.20000000000266,17.17752299158683,2.1608323087660524,-0.09194744191753301
237.40000000000268,17.213735462580026,2.169462048771594,-0.09423527535546228
238.6000000000027,17.25009069667631,2.1771500049213257,-0.09790441482309076
239.8000000000027,17.286423402755922,2.187226723043862,-0.10035969629129271
241.00000000000273,17.322723555711644,2.192317337522884,-0.10250509229763827
242.20000000000275,17.35916804161185,2.2002872114651577,-0.10472854853614688
243.40000000000276,17.39547187773256,2.2078973894484673,-0.10730780566993792
244.60000000000278,17.431900689314084,2.2168061135930475,-0.10974981301095754
245.8000000000028,17.468194528603334,2.2218818756507406,-0.11235041533907664
247.0000000000028,17.504356237072777,2.228620202840399,-0.11441828911743102
248.20000000000283,17.540803818131867,2.2341750230768818,-0.11698787195454985
249.40000000000285,17.577090169176213,2.240246844851719,-0.12043751849240358
250.60000000000286,17.613589626187117,2.2444213935177233,-0.12327680617777181
251.80000000000288,17.64984816331456,2.2501723057669487,-0.12741307029765814
253.0000000000029,17.68590768722652,2.252785247907099,-0.1308984894161469
254.20000000000292,17.721815090060254,2.2563519188675887,-0.13465367268193607
255.40000000000293,17.758550262366445,2.2609788067699803,-0.13706535575618073
256.600000000003,17.794554998518443,2.2651814372109973,-0.1383843698964915
257.80000000000297,17.831047189228546,2.2697353032490972,-0.14185940807602382
259.00000000000296,17.86694587212181,2.271788169415413,-0.14588265645447107
260.200000000003,17.903683748072847,2.2758482886160443,-0.14892473525447425
261.40000000000305,17.939674828977825,2.2811078275577357,-0.15292170295732532
262.60000000000304,17.9758686163264,2.285703501444415,-0.15696522615033848
263.800000000003,18.01176669353351,2.2904675718619902,-0.16130176571471644
265.00000000000307,18.048125401683418,2.295563668019473,-0.16518165478985347
266.2000000000031,18.08438005582606,2.2993280262886833,-0.16848977806036913
267.4000000000031,18.120763738892226,2.305739832133018,-0.17087025914271514
268.6000000000031,18.156784830209816,2.309841300944689,-0.17523955350777998
269.80000000000314,18.193213400481486,2.317347961938981,-0.17911681803649948
271.0000000000032,18.22973584745169,2.3235425365336235,-0.1834683221902531
272.2000000000032,18.265526915096036,2.3268178124362633,-0.18756930717990894
273.40000000000316,18.301549222871742,2.331262353947702,-0.1921124173547013
274.6000000000032,18.337924963313537,2.33529418723227,-0.1972942571890539
275.80000000000325,18.374041975034636,2.342501469289027,-0.202123119555758
277.00000000000324,18.41030709230653,2.3489123402902665,-0.2076861869796076
278.20000000000323,18.44651294846222,2.353649938575152,-0.21319180468382726
279.4000000000033,18.482581523134105,2.3574496993819793,-0.2192861670850763
280.6000000000033,18.519176630594195,2.3618923062630466,-0.22583464812212073
281.8000000000033,18.555016492712817,2.3668623072291566,-0.23275434625853064
283.0000000000033,18.591362534791166,2.3720844575362943,-0.24010534020513585
284.20000000000334,18.6276465962131,2.374801957717979,-0.2466655353171503
285.4000000000034,18.664006531681064,2.3779104917181955,-0.25406015630344614
286.6000000000034,18.699999695061617,2.381229957800278,-0.2612699959195779
287.80000000000337,18.73654794688387,2.3840334864152473,-0.2693267862668298
289.0000000000034,18.772844983151252,2.383727171824717,-0.2777555992862428
290.20000000000346,18.80877054402339,2.3859090057431267,-0.28669831156609593
291.40000000000344,18.845343920169853,2.387844070359576,-0.2963727344092115
292.60000000000343,18.88128922089763,2.3855016839545486,-0.3058995672057052
293.8000000000035,18.91786741028426,2.3844268132212028,-0.3158513318594447
295.0000000000035,18.95400220921915,2.383558329346811,-0.32678532555238693
296.2000000000035,18.99025172944439,2.38146362840505,-0.3380121897961099
297.4000000000035,19.026487363801458,2.377661837684909,-0.3492883795043147
298.60000000000355,19.062829804819593,2.374491618835609,-0.3621946012816424
299.8000000000036,19.099079892314332,2.369962596863317,-0.3754045198151119
301.0000000000036,19.135244900539906,2.365318573701398,-0.38930278314079914
302.20000000000357,19.17164642421036,2.3583408040033795,-0.4048698531029218
303.4000000000036,19.20796651743024,2.352247806714862,-0.41994100047354443
304.60000000000366,19.244345200098127,2.346194967408414,-0.43546586170147084
305.80000000000365,19.28079592340485,2.3390547580476624,-0.4516383032863862
307.00000000000364,19.316873318709174,2.3305298419196987,-0.4671388750761216
308.2000000000037,19.353308572805833,2.3246854402885666,-0.48525496182971706
309.40000000000373,19.389723166775713,2.317262972349318,-0.5030971866785867
310.6000000000037,19.426010859990953,2.30633017169489,-0.5214020819749869
311.8000000000037,19.462398079644835,2.2977585778423553,-0.540871022695419
313.00000000000375,19.498309947953118,2.29088812694554,-0.5610435553288999
314.2000000000038,19.535072144709062,2.2806218513611216,-0.5807942511078052
315.4000000000038,19.571435286368718,2.2738570647683995,-0.6016569919630141
316.6000000000038,19.607767370566716,2.2695660485364413,-0.622876482205529
317.8000000000038,19.644213295151587,2.264134114942467,-0.6436096961802176
319.00000000000387,19.680187224047852,2.261467972881035,-0.6645038705336743
320.20000000000385,19.71681809974634,2.256103037041579,-0.6856807938962977
321.40000000000384,19.75287796218533,2.254380149060222,-0.7068195110082054
322.6000000000039,19.789543368031264,2.2509734835035355,-0.730627120552203
323.80000000000393,19.826137429879353,2.2516237316152585,-0.7544906949246499
325.0000000000039,19.862491031777243,2.2539925350039005,-0.7766388826406767
326.2000000000039,19.898725744393563,2.2581550303131017,-0.7989797874775402
327.40000000000396,19.93527260685972,2.259568244598405,-0.8220082345075403
328.600000000004,19.972049873145526,2.2648425459138934,-0.8453292580512692
329.800000000004,20.008205303739413,2.2728404765499137,-0.8673052761649913
331.000000000004,20.04505711150649,2.2769931890939894,-0.8897692360999816
332.200000000004,20.08124698159419,2.2867280937199523,-0.9116264505137455
333.40000000000407,20.118045544649878,2.2958514559948937,-0.933605420284235
334.60000000000406,20.15451791416823,2.3080229356428967,-0.9566924180468996
335.80000000000405,20.19094301867065,2.318935650962076,-0.9800615520805387
337.0000000000041,20.227502933471477,2.330882132433559,-1.0025974654583747
338.20000000000414,20.26415697238914,2.3447498736162853,-1.025048075858615
339.4000000000041,20.300656628073142,2.359039153987828,-1.0488373013673193
340.6000000000041,20.337552127342185,2.3741608022588863,-1.0730278535210473
341.80000000000416,20.37426796541574,2.3908095186281613,-1.0981896748606985
343.0000000000042,20.41021223038248,2.4077762871669246,-1.1215690875644877
344.2000000000042,20.447512620095903,2.426126448336354,-1.1465848036831883
345.4000000000042,20.484141162404192,2.4434775944546305,-1.1702913598092417
346.60000000000423,20.521005971756356,2.464967074598313,-1.1939634926302167
347.8000000000043,20.55748632401433,2.483554088683098,-1.2178425115816869
349.00000000000426,20.59441539895839,2.502935553534619,-1.2428585124990885
350.20000000000425,20.631108438148125,2.5251782497288215,-1.269851568821446
351.4000000000043,20.66767957124272,2.5486646011946674,-1.2954156577418336
352.60000000000434,20.704658535533124,2.5702154637276524,-1.322547114938538
353.80000000000433,20.74150724385221,2.5925215909925723,-1.3497552212291293
355.0000000000043,20.778143378382374,2.614903383020889,-1.3778439579953483
356.20000000000437,20.81516763801789,2.6415913472757437,-1.407241325047889
357.4000000000044,20.85182957895042,2.6655096957017124,-1.437388089788998
358.6000000000044,20.88878793035732,2.691955455155376,-1.4672915230991896
359.8000000000044,20.92611636219907,2.718955362139514,-1.498585907690126
361.00000000000443,20.96245199057775,2.745475397530518,-1.5280467756947291
362.2000000000045,20.99984622169257,2.7742911697396506,-1.560335684454273
363.40000000000447,21.036738248438972,2.801883551293411,-1.5944890259197386
364.60000000000446,21.072779076058296,2.8316258539373242,-1.628357112163819
365.8000000000045,21.110615472719918,2.861873182264463,-1.664750563759024
367.00000000000455,21.14770487141725,2.8917328285000687,-1.7017554747629977
368.20000000000454,21.184325042517802,2.920490285217281,-1.739808560513222
369.4000000000045,21.22135399279245,2.949872187422888,-1.7786887822358612
370.60000000000457,21.258775685391797,2.9782834895446344,-1.819909491377623
371.8000000000046,21.295617642215262,3.005727859530432,-1.8638025174911483
373.0000000000046,21.332540949946612,3.031388989471784,-1.9063284534709108
374.2000000000046,21.369936622595063,3.053957138458155,-1.9505820970843852
375.40000000000464,21.40689290803417,3.0717392082634185,-1.9944417744632559
376.6000000000047,21.44395011682448,3.0896649911067384,-2.039034504276803
377.8000000000047,21.481052869116652,3.0998240598478763,-2.0854000958162002
379.00000000000466,21.51811338710627,3.1069542484496897,-2.1319243028176604
380.2000000000047,21.55503910515903,3.1086321470656277,-2.1793668155227723
381.40000000000475,21.592263944735375,3.101793986472315,-2.2275908312317307
382.60000000000474,21.62927082707549,3.0891516873760345,-2.27678424688158
383.80000000000473,21.666428786882793,3.0681558868498335,-2.3266716063258723
385.0000000000048,21.70379779514815,3.038010041890113,-2.3757489051162017
386.2000000000048,21.740824261671772,3.001399678308067,-2.423747972544796
387.4000000000048,21.77782408597426,2.9523696147604794,-2.470104269123984
388.6000000000048,21.81492860546553,2.8920858273088053,-2.516453514035932
389.80000000000484,21.85242255540866,2.820804378285484,-2.561161397324411
391.0000000000049,21.88938537705946,2.743003229995839,-2.6039889728932657
392.2000000000049,21.92651604570595,2.65303372079347,-2.6443673179406098
393.40000000000487,21.963460363120994,2.554453104848869,-2.6828956801001858
394.6000000000049,22.00013439437398,2.4505135254685495,-2.7167419576680865
395.80000000000496,22.037618475390065,2.3403062543145463,-2.74889479852736
397.00000000000495,22.075076367749272,2.2294060619582368,-2.7787660519197566
398.20000000000493,22.112027559976628,2.118927657399849,-2.804803900547717
399.400000000005,22.14933447341565,2.0117155729456266,-2.827021683508537
400.600000000005,22.18617009811159,1.9158907001784853,-2.8462023120648325
401.800000000005,22.223655722816027,1.8271326710828284,-2.862403488401912
403.000000000005,22.260783105523686,1.750032098863289,-2.876087204887431
404.20000000000505,22.29771516311738,1.6850814883979164,-2.887891539943511
405.4000000000051,22.334880533932026,1.6322513436327415,-2.8977627891268005
406.6000000000051,22.371730970464423,1.5903471397967799,-2.9064819505704778
407.80000000000507,22.409370750299757,1.5561787620781025,-2.911944634279751
409.0000000000051,22.446340032050408,1.5259663778168082,-2.9184872051514934
410.20000000000516,22.483451567827338,1.5023641849023668,-2.924652774578233
411.40000000000515,22.520724344145652,1.4811827600641512,-2.9289104593623576
412.60000000000514,22.558022953903738,1.4636044096729481,-2.9345036851928654
413.8000000000052,22.59550555405861,1.44941247003537,-2.938232652493946
415.00000000000523,22.63264521087155,1.4359388663079664,-2.9430256567152298
416.2000000000052,22.67003128713849,1.4243444013105666,-2.947814887044692
417.4000000000052,22.707477629243296,1.4127169838659912,-2.951367136300358
418.60000000000525,22.744854580884898,1.4046120660644559,-2.955358247290385
419.8000000000053,22.78243702333648,1.3949645843303584,-2.960415383964909
421.0000000000053,22.819664596754173,1.3880905196668536,-2.9644436559658582
422.2000000000053,22.857303815802968,1.3804076140876318,-2.968350263469749
423.4000000000053,22.89493421153396,1.3748419862159136,-2.9714635069658315
424.60000000000537,22.93209221455832,1.366271015079354,-2.9750107537408446
425.80000000000535,22.969655696128346,1.360785427554367,-2.9788136192850105
427.00000000000534,23.00733546433213,1.3562614147031922,-2.982307432686631
428.2000000000054,23.044658819112534,1.3498846754779323,-2.9857122069100255
429.40000000000543,23.08248113669379,1.3476553197591405,-2.9900009318666365
430.6000000000054,23.11975575815606,1.3449009416571942,-2.9937512048396275
431.8000000000054,23.15770464390276,1.340812272054518,-2.9972534421161248
433.00000000000546,23.195084155647443,1.338648939791048,-3.0009495085020603
434.2000000000055,23.232914862235504,1.3369340722424294,-3.003382903371521
435.4000000000055,23.270647956034157,1.33355971258814,-3.006556157213981
436.6000000000055,23.308102603209313,1.333504673275921,-3.0108968751857184
437.8000000000055,23.345822639836694,1.3318748003978278,-3.014557696924194
439.00000000000557,23.38356992271262,1.332637006308964,-3.0175399750614513
440.20000000000556,23.421217080422494,1.3330321541994066,-3.020980145000765
441.40000000000555,23.45909661748331,1.332652151906068,-3.0245034473195633
442.6000000000056,23.49687973020538,1.3335733440663353,-3.027498432057513
443.80000000000564,23.5347844503774,1.3333882035237001,-3.030242625440838
445.0000000000056,23.57240277269862,1.3364261689610004,-3.0349196071155653
446.2000000000056,23.609937153261143,1.3389914838940553,-3.038186554079954
447.40000000000566,23.647323862874792,1.3414843240624161,-3.0410315472625475
448.6000000000057,23.685603300842793,1.347703070059776,-3.0432914904496378
449.8000000000057,23.723915172452884,1.3508225119853898,-3.045371641428548
451.0000000000057,23.761431731042162,1.3536502623963118,-3.0489284301276784
452.20000000000573,23.799056630107444,1.3575531276766755,-3.052763183492024
453.4000000000058,23.83709140107046,1.3624048459499187,-3.0553789800352775
454.60000000000576,23.874805901834364,1.3665860991402696,-3.0577862081346554
455.80000000000575,23.912183002249275,1.3729169492984734,-3.059753784451842
457.0000000000058,23.95039703524873,1.37634313271281,-3.0632206490000544
458.20000000000584,23.98882018027109,1.3825316408437915,-3.0657057830560634
459.40000000000583,24.026958122484167,1.3892961909405814,-3.0677304394782814
460.6000000000058,24.065007332816123,1.3943308802892636,-3.070776351738539
461.80000000000587,24.102816025810476,1.4010757920849468,-3.073118730811213
463.0000000000059,24.141024542430827,1.4078899516559464,-3.0747479720718998
464.2000000000059,24.178677114722223,1.414569971255195,-3.078358074797914
465.4000000000059,24.217099459714397,1.4218347289973354,-3.0811791729448625
466.60000000000593,24.254842274472935,1.4262595400551106,-3.084574842855216
467.800000000006,24.2930309351083,1.4340040714533826,-3.0863165497605385
469.00000000000597,24.331434945456138,1.4399313450419964,-3.0885673631301893
470.20000000000596,24.369421871523233,1.4444734566364315,-3.090820977387274
471.400000000006,24.407601085601012,1.4532817189377047,-3.092819221267733
472.60000000000605,24.44580103359954,1.4582447800308762,-3.095173876141879
473.80000000000604,24.48378380805115,1.4663387444578413,-3.0969840384100618
475.000000000006,24.522475245027206,1.4746910852004276,-3.0984980470851604
476.20000000000607,24.560376050352726,1.4774999679473269,-3.1014191593098417
477.4000000000061,24.598886361335477,1.484747450191219,-3.1033727473778647
478.6000000000061,24.636907559819946,1.488706047871749,-3.1047673456555254
479.8000000000061,24.675262612724996,1.4964370016003374,-3.1068964013890197
481.00000000000614,24.713523707830877,1.5028590266545017,-3.108603884440679
482.2000000000062,24.75178494900271,1.5100092742761817,-3.1105034454552563
483.4000000000062,24.790197881837347,1.5112613585669097,-3.1122471099391857
484.60000000000616,24.82805251748718,1.519911424060054,-3.1147440830724147
485.8000000000062,24.866567365756666,1.5232469619506828,-3.1168733506665327
487.00000000000625,24.905214075416957,1.5297473197416493,-3.119039508473671
488.20000000000624,24.943307654446624,1.5338450391347669,-3.1214814327159592
489.40000000000623,24.981450845692724,1.537808871600327,-3.122760007478969
490.6000000000063,25.019999675044062,1.543479965833229,-3.1242997564600623
491.8000000000063,25.058176464379255,1.5468414747086723,-3.12565061481014
493.0000000000063,25.096321051085827,1.5521004583820186,-3.1267157582062532
494.2000000000063,25.134817724142177,1.5558169684664938,-3.128206886811347
495.40000000000634,25.173314546534154,1.5597130225490385,-3.129566295371281
496.6000000000064,25.211609878086943,1.5644750675011234,-3.132261654488448
497.8000000000064,25.25006527779396,1.5666491384803651,-3.1338397819499093
499.00000000000637,25.288571928029512,1.5707478928349694,-3.1346835682878944
500.2000000000064,25.32663337635691,1.5743394820514292,-3.1353606368281493
501.40000000000646,25.365182764641613,1.5769775485026851,-3.1367135747792227
502.60000000000645,25.403627921316545,1.5804913811179262,-3.139157315553122
503.80000000000643,25.441731378203635,1.5822920487841747,-3.1407772325380363
505.0000000000065,25.4808581725708,1.58612034893431,-3.141814617985383
506.2000000000065,25.519427910800097,1.5889054882152414,-3.143449625825475
507.4000000000065,25.55780583779343,1.5905278591273366,-3.1446403868643014
508.6000000000065,25.596049004647874,1.5946971497600586,-3.1447095377858214
509.80000000000655,25.63457402934448,1.5983040268921966,-3.1460710672018397
511.0000000000066,25.672890708858144,1.5985386723945652,-3.1466201677698145
512.2000000000066,25.711410025521786,1.601562997353539,-3.1475150747501495
513.4000000000066,25.749839350065642,1.60543095593787,-3.1490923451252706
514.6000000000066,25.788527953747703,1.6082512792963282,-3.1519237867463206
515.8000000000067,25.827182227878318,1.610331915049338,-3.153235102319049
517.0000000000066,25.865564239055637,1.6123976935632593,-3.15471083879301
518.2000000000066,25.904433977258208,1.616129224678408,-3.1561181535724936
519.4000000000067,25.9426395516726,1.6179859148709563,-3.1574339011646595
520.6000000000067,25.98139663202012,1.6186444882807918,-3.1587715678951334
521.8000000000068,26.0200646911114,1.6243900050171645,-3.1587388543916597
523.0000000000067,26.058569424561107,1.6248802547421166,-3.1600466033895698
524.2000000000068,26.097311428774603,1.6275430475074995,-3.161341619356599
525.4000000000068,26.13580874232583,1.6308361790375148,-3.1628368873315784
526.6000000000067,26.174578417130135,1.6347099591938403,-3.164314076443074
527.8000000000068,26.213142646388683,1.635268672031685,-3.1642288941541588
529.0000000000068,26.25204062158013,1.639175582485127,-3.1655234074086778
530.2000000000069,26.29052337400432,1.6401544237729313,-3.16723864912045
531.4000000000069,26.329577554890495,1.6450417247146687,-3.1685729929762303
532.6000000000068,26.36803182754667,1.6441443537892004,-3.168896866246917
533.8000000000069,26.406696208154607,1.6482148854479568,-3.170243914440587
535.0000000000069,26.445500257257624,1.64956812172078,-3.1715615211458603
536.2000000000069,26.484205898604824,1.651034300657937,-3.1729368491353758
537.4000000000069,26.52323567032124,1.6535002463453552,-3.173158129799274
538.600000000007,26.56160946783678,1.654909864058708,-3.174264582758518
539.800000000007,26.6008249974167,1.6589232317080813,-3.175659697656945
541.000000000007,26.63984089375824,1.6695013577491773,-3.176949875845424
542.200000000007,26.67803577776909,1.6795270597102363,-3.178295556459005
543.400000000007,26.717187028915223,1.688176912729213,-3.1782536517511577
544.6000000000071,26.755950960069942,1.6964681616823225,-3.1795611171373523
545.800000000007,26.79457890331944,1.703101045002911,-3.181007619418657
547.000000000007,26.833283125708526,1.7097500126262666,-3.181169491847946
548.2000000000071,26.872232763321847,1.7147337907638078,-3.1822078477576987
549.4000000000071,26.910945470502064,1.7215284232446635,-3.18351769483703
550.6000000000072,26.949583932722103,1.7264167457646975,-3.1835284504925574
551.8000000000071,26.988693500767663,1.7299462762439606,-3.1848443046827395
553.0000000000072,27.02750606112125,1.7364070757608616,-3.1855893245585074
554.2000000000072,27.06583004003552,1.7411992428784273,-3.1861614242201655
555.4000000000071,27.105363581116883,1.745737515592354,-3.1864516356264776
556.6000000000072,27.144277255369712,1.7488766050936992,-3.187441859710895
557.8000000000072,27.183325137598413,1.7527799248256275,-3.1887843117648837
559.0000000000073,27.22254306553017,1.7600940672825465,-3.1902981517534266
560.2000000000073,27.261375979751243,1.7657189881902033,-3.192248851307016
561.4000000000073,27.30013314205724,1.7726093927258393,-3.192204129285553
562.6000000000073,27.33922756958613,1.7767876224895607,-3.193505359044256
563.8000000000073,27.377916421048997,1.7832278264496142,-3.194817080066528
565.0000000000073,27.417019674994588,1.7875379427860234,-3.1948320304160616
566.2000000000073,27.45608574459606,1.7924097097375649,-3.196217933251706
567.4000000000074,27.49527577285162,1.7979680871770767,-3.1961078590335
568.6000000000074,27.53414559998817,1.8004426276335581,-3.1974568704271933
569.8000000000075,27.573178247539225,1.804397606365416,-3.198827735377156
571.0000000000074,27.61229615353931,1.8090014643734853,-3.1987956458704145
572.2000000000074,27.651539014167547,1.809418267619804,-3.200093109377865
573.4000000000075,27.69034978866533,1.8135746526068761,-3.201021006242977
574.6000000000074,27.729590903639963,1.8165519020500716,-3.2000895975180987
575.8000000000075,27.76867924300464,1.817808495131906,-3.201431360328959
577.0000000000075,27.807810144816024,1.8216933304092175,-3.2013101799118164
578.2000000000075,27.84697941041275,1.8221921180854297,-3.203699297183423
579.4000000000076,27.88611793744011,1.822605352568908,-3.2043012222827763
580.6000000000075,27.925388121463502,1.8229369175403582,-3.205030345394779
581.8000000000076,27.964351538566305,1.8197173592342146,-3.2049818074365692
583.0000000000076,28.003603158614524,1.8199291751606446,-3.2063247697923156
584.2000000000075,28.043234465108796,1.8180576881280928,-3.2072596256263752
585.4000000000076,28.08230646012472,1.8203327607135102,-3.2076350141518426
586.6000000000076,28.12128148271205,1.8158170565928424,-3.208972378500377
587.8000000000077,28.160568808496947,1.8158779158655198,-3.208996813388244
589.0000000000077,28.199771174039938,1.8163939309309023,-3.208972482297648
590.2000000000077,28.238996641082714,1.8161475968337233,-3.2105215767366317
591.4000000000077,28.278652573555945,1.8185542612059395,-3.212478405461478
592.6000000000078,28.31793252765931,1.8200354438370403,-3.212931171662581
593.8000000000077,28.35714784963914,1.8206104562738399,-3.213347985878655
595.0000000000077,28.3963690402986,1.8219588435839655,-3.21424435834123
596.2000000000078,28.435740982738455,1.8244269879191146,-3.2156468915775713
597.4000000000078,28.475011402668727,1.8266546173697242,-3.215531022777593
598.6000000000079,28.514276564344325,1.828905955703512,-3.215517251457116
599.8000000000078,28.55406323947779,1.8293846219837286,-3.2155561801083703
601.0000000000078,28.593197867045284,1.832948275434223,-3.217489509679935
602.2000000000079,28.632803731764998,1.8334755057865266,-3.217530877247116
603.4000000000078,28.67203804269884,1.8344776658539645,-3.217680752904932
604.6000000000079,28.711190533070592,1.8371752562532928,-3.2188505550882947
605.8000000000079,28.751006217063022,1.8376669246800321,-3.2188540317356633
607.000000000008,28.790269080969495,1.8422606164885196,-3.2201605957642228
608.200000000008,28.829319384524474,1.8448464452195852,-3.2210907554444406
609.4000000000079,28.8689474668288,1.8442154006500777,-3.2214811707636084
610.600000000008,28.908499666556764,1.8484294696184984,-3.2228256576525984
611.800000000008,28.947951787084353,1.8514621618235447,-3.222801804246397
613.000000000008,28.987136426050427,1.8523462896173755,-3.224165961065064
614.200000000008,29.026609548604167,1.854108077642558,-3.2241253132455245
615.400000000008,29.066030093437643,1.8560548649481312,-3.2254656622781446
616.6000000000081,29.105557820348167,1.858404663062448,-3.225444719016732
617.8000000000081,29.144948255349803,1.8585440293825406,-3.226785703795785
619.0000000000081,29.18445691096623,1.8625071775969668,-3.226740061162918
620.2000000000081,29.223978401725898,1.8627037104978108,-3.2267353286568836
621.4000000000082,29.263248198410395,1.8667598522035682,-3.228143623440217
622.6000000000081,29.302853420211964,1.872174439559524,-3.23032688595612
623.8000000000081,29.34263673938053,1.8747253317372596,-3.230344074731642
625.0000000000082,29.3821191976573,1.8769632147738105,-3.228634751060806
626.2000000000082,29.42102662159164,1.8785257815746692,-3.229907755095003
627.4000000000083,29.460525762792034,1.880868411281668,-3.2299196424888197
628.6000000000082,29.500710968901377,1.8858714786424788,-3.2305163581001426
629.8000000000083,29.54026496314702,1.8887178917583265,-3.2299265932166628
631.0000000000083,29.57946274923658,1.8910344865023654,-3.231524764512322
632.2000000000082,29.619203171118162,1.894713592947302,-3.2325608749304444
633.4000000000083,29.65909833003486,1.8986866676247312,-3.2325599088963903
634.6000000000083,29.6983118554168,1.9008179181444562,-3.232756674930952
635.8000000000084,29.73803141115956,1.9049726805507516,-3.2338738186406433
637.0000000000084,29.777397321111106,1.906042379677526,-3.2346581845801516
638.2000000000083,29.817060867974934,1.9115366550971498,-3.234428301376486
639.4000000000084,29.856472928378178,1.9124551782683505,-3.2358393170673727
640.6000000000084,29.896209418330226,1.9178754044842925,-3.2358400899167834
641.8000000000084,29.93589139359322,1.9208273464371703,-3.235839828294644
643.0000000000084,29.97562922129412,1.924675540742371,-3.2357879057521064
644.2000000000085,30.01497848867503,1.928384052722095,-3.2371472082155623
645.4000000000085,30.05483813920204,1.930842189996867,-3.2371731567156927
646.6000000000085,30.09454283581067,1.934434981866678,-3.238543703005416
647.8000000000085,30.13418172542956,1.9384610770437376,-3.239851351336174
649.0000000000085,30.173947195999908,1.9435096406752355,-3.2398486086935856
650.2000000000086,30.21356456831738,1.9469154614282118,-3.239900371636014
651.4000000000085,30.253158890614284,1.9500285748807378,-3.239786288314894
652.6000000000085,30.292673539277203,1.9564798883994654,-3.2412323420808677
653.8000000000086,30.33228204107904,1.9580194669343853,-3.2424342213763695
655.0000000000086,30.372446752657435,1.9625538744795092,-3.243839398137002
656.2000000000087,30.41211875309996,1.9676693263298874,-3.242682763295537
657.4000000000086,30.45180425460186,1.9738446445039055,-3.2440590648425323
658.6000000000087,30.49143594731738,1.9768939348482686,-3.244078989852186
659.8000000000087,30.531141946093467,1.9803489474097582,-3.243728202271255
661.0000000000086,30.571228373403365,1.9860158667474572,-3.2450517794027767
662.2000000000087,30.610780835371774,1.9897500889399689,-3.2450598685620764
663.4000000000087,30.65039639590806,1.9950438867666231,-3.245060833832732
664.6000000000088,30.690032757174407,2.0006085130559326,-3.2463708963844353
665.8000000000088,30.73003329314627,2.0064908011296754,-3.246639985895114
667.0000000000088,30.769676210382237,2.0097565433558957,-3.2478008031984635
668.2000000000088,30.809601614093776,2.015692981635068,-3.2477933144090523
669.4000000000088,30.84915772284556,2.0189661570656474,-3.246465504630579
670.6000000000088,30.889151510436594,2.0258504168019313,-3.2478376269468603
671.8000000000088,30.928777187671702,2.027575968834766,-3.2464962612794146
673.0000000000089,30.96866087874157,2.0344601445980244,-3.247835150053218
674.2000000000089,31.008129730481528,2.0382250736227747,-3.2478103060510044
675.400000000009,31.048016280368817,2.0428244278331307,-3.247807342362109
676.6000000000089,31.087893675812985,2.0455694644186364,-3.2490316827305032
677.8000000000089,31.127675231172542,2.052643481077379,-3.249119313373895
679.000000000009,31.167524878821485,2.0586396069010693,-3.249119137714618
680.2000000000089,31.206867643875093,2.063628107402977,-3.250178794321285
681.400000000009,31.24654560282325,2.068137632521849,-3.2515081302713464
682.600000000009,31.286395529763034,2.0727846195428854,-3.251420338125947
683.800000000009,31.32637961578848,2.0759099301590505,-3.2514235390116024
685.0000000000091,31.36608713347167,2.082712810654261,-3.2524592396692853
686.200000000009,31.405889377159365,2.086290209481478,-3.252458084470728
687.4000000000091,31.445417482068375,2.091336603307052,-3.25111072907186
688.6000000000091,31.485378969211858,2.096061436518181,-3.251460492683159
689.800000000009,31.525435272941788,2.103526963543338,-3.251714917647199
691.0000000000091,31.565075695233354,2.105378165648798,-3.25274366205904
692.2000000000091,31.60487796684557,2.113290318156932,-3.2527395969017077
693.4000000000092,31.644675957658183,2.1153160314822643,-3.252654045150641
694.6000000000092,31.684351759041522,2.122773681405154,-3.2540548283837527
695.8000000000092,31.724331059806374,2.12711086143844,-3.255064963412457
697.0000000000092,31.764358493258083,2.132077358776881,-3.2553743373686697
698.2000000000093,31.804340309623267,2.135795560715139,-3.2540764282304666
699.4000000000092,31.843989653283007,2.144192526837222,-3.2540507969442376
700.6000000000092,31.883937649177675,2.1484645149129036,-3.2542447410876267
701.8000000000093,31.92379797908628,2.1540009173166084,-3.255060146816027
703.0000000000093,31.964026966289236,2.1591315668577216,-3.256369765065953
704.2000000000094,32.0038114996115,2.1643263993546626,-3.256359957180095
705.4000000000093,32.043814536922504,2.169788236682586,-3.2563600071993895
706.6000000000093,32.08350165955341,2.1752723650989028,-3.256378692437754
707.8000000000094,32.123650327283535,2.1789925150655405,-3.257686362557931
709.0000000000093,32.1635945531362,2.1858116714935654,-3.2576809924166423
710.2000000000094,32.203531619003606,2.1901227945919834,-3.2590878352129633
711.4000000000094,32.24369779098066,2.1960972183646312,-3.258990583925021
712.6000000000095,32.28378856399646,2.203734412755143,-3.2589917320720443
713.8000000000095,32.3234985389096,2.2076376416979695,-3.2604045656397007
715.0000000000094,32.363752241422475,2.21362207862303,-3.260328194059425
716.2000000000095,32.403615379884755,2.217366114503584,-3.2590013216615437
717.4000000000095,32.44363950728619,2.2257288248019775,-3.258990214919485
718.6000000000095,32.483838139550244,2.228895675814725,-3.258989817310817
719.8000000000095,32.5237005052648,2.2369030720526846,-3.2597073387668543
721.0000000000095,32.563740760297904,2.2428957100781663,-3.260308117074678
722.2000000000096,32.60400020471998,2.249974018074145,-3.2603308723015925
723.4000000000096,32.643243486090995,2.2522424672065897,-3.2616234757948486
724.6000000000096,32.684212861240795,2.2577854668173476,-3.26161993365424
725.8000000000096,32.72389754421758,2.262914532593767,-3.261619900594712
727.0000000000097,32.76407625364227,2.2687366977935755,-3.261616871016313
728.2000000000096,32.804084387880536,2.2751205840831163,-3.261297453513038
729.4000000000096,32.843954457527666,2.279604068838069,-3.261289713068529
730.6000000000097,32.884218694152196,2.2877517915880183,-3.261240056318034
731.8000000000097,32.92425468878866,2.2954963236086234,-3.2622755611001333
733.0000000000098,32.964071535610636,2.30118579890418,-3.2622800928654954
734.2000000000097,33.004387106208405,2.306283410256412,-3.262302294892646
735.4000000000098,33.044917838868805,2.312130470566167,-3.2635948201053413
736.6000000000098,33.08487048946633,2.319080988318419,-3.2635901055704237
737.8000000000097,33.12479317990076,2.3245774923370255,-3.2635911552847743
739.0000000000098,33.16539985168935,2.3285491353805625,-3.2650024955608394
740.2000000000098,33.20530629362624,2.335785322755366,-3.2649106282493565
741.4000000000099,33.24551565298968,2.3432953684277704,-3.2649097385043007
742.6000000000099,33.285893180328,2.349205798003556,-3.2648276649993977
743.8000000000098,33.32591464242286,2.353581849457642,-3.266170265548258
745.0000000000099,33.36582883222144,2.3617648040811083,-3.2654779917826278
746.2000000000099,33.406114920734446,2.3679474488765133,-3.2668883099082784
747.4000000000099,33.44622809804079,2.3729517322081235,-3.2668899067053334
748.6000000000099,33.48634856333825,2.3789796768692133,-3.2668880635702315
749.80000000001,33.526625251908804,2.3847048062428766,-3.2674736243261613
751.00000000001,33.56703835030653,2.3907677093968847,-3.2680299256930896
752.20000000001,33.6070862933572,2.397622612312998,-3.268209161200807
753.40000000001,33.64719176425099,2.4023810192134616,-3.2681998636760543
754.60000000001,33.68720952934221,2.406544668102135,-3.266841664578412
755.8000000000101,33.727548926761266,2.4135535197840556,-3.2668895287498048
757.00000000001,33.76774990278118,2.4182809938297076,-3.266845697001665
758.20000000001,33.80758633598293,2.4259455766118387,-3.2682033336809075
759.4000000000101,33.848224998648746,2.430841223997208,-3.268210090595109
760.6000000000101,33.88823951444133,2.4397942207684764,-3.2682112207526783
761.8000000000102,33.92859761651345,2.4466412778730766,-3.269544738066774
763.0000000000101,33.968699604244016,2.4529850151382995,-3.2695203299333695
764.2000000000102,34.00890343163631,2.460436797546157,-3.269526586869472
765.4000000000102,34.049058933730805,2.471027075734753,-3.2707628934706943
766.6000000000101,34.08858067953062,2.4764827807724057,-3.269514594254539
767.8000000000102,34.129625791104566,2.4807016357679275,-3.269613193030098
769.0000000000102,34.16947099617964,2.489129038783821,-3.272153355660807
770.2000000000103,34.209830791432445,2.4961984404534285,-3.272149981928785
771.4000000000103,34.25013270004581,2.5024398750348635,-3.2721548403827767
772.6000000000103,34.29034328572053,2.5113506678559467,-3.2714490623385326
773.8000000000103,34.33056672689778,2.5160693179607647,-3.272197228166492
775.0000000000103,34.37110354152056,2.5234727161695356,-3.272809491220372
776.2000000000103,34.411315022773465,2.5297905314271225,-3.272810024162095
777.4000000000103,34.45162358257415,2.5396834648445177,-3.27281059606989
778.6000000000104,34.491734260380355,2.541887631939274,-3.2729392989765485
779.8000000000104,34.53201682648522,2.553422299482403,-3.27348648394743
781.0000000000105,34.57255986975877,2.5599613070864415,-3.2734698250913694
782.2000000000104,34.61303654000438,2.566897349945218,-3.2721473019360108
783.4000000000104,34.65301388789975,2.5753633477569986,-3.2734462971296727
784.6000000000105,34.69357942130089,2.5818445099604133,-3.2734654224129525
785.8000000000104,34.73390680195604,2.589205238505846,-3.2747632399523097
787.0000000000105,34.77410019548576,2.5977927317757143,-3.2747897419433407
788.2000000000105,34.81468109349263,2.606797161818863,-3.274789874164795
789.4000000000106,34.854776515515276,2.6111181449860124,-3.2747898425224835
790.6000000000106,34.89545797892786,2.6193899201054203,-3.2747831839855945
791.8000000000105,34.93552146401179,2.6264596846914703,-3.2760628810430306
793.0000000000106,34.975902551225765,2.6343235875523887,-3.2762122057477283