File: 01_Data/Basswood_Panel/STA/N2/30K_min/Basswood_Panel_STA_N2_30KData_220315_R1.csv
##Temp./Â°C,Time/min,DSC/(mW/mg),Mass loss/mg
49.0,10.404067774085359,-1.0880933177757748,-0.0044182783333655
50.20000000000002,10.677318121046298,-0.9033924197470735,-0.006111290213445031
51.400000000000034,10.819078644287263,-0.7735903854234023,-0.007011134978434974
52.60000000000005,10.925745371409583,-0.6661449935648065,-0.007869229698385105
53.80000000000007,11.016087127087474,-0.5738716460751202,-0.007141263890015459
55.000000000000085,11.095579506386647,-0.49135205204483295,-0.006316501242482175
56.2000000000001,11.167076759293137,-0.4172577133232095,-0.0075817807272802185
57.40000000000012,11.234388367068778,-0.3499829784530971,-0.006385515182980583
58.600000000000136,11.296999067819746,-0.28599800224009575,-0.005988021277702593
59.80000000000015,11.356834129121202,-0.2260627477557576,-0.006459233316503443
61.00000000000017,11.413616199596085,-0.1705547918402076,-0.0067425141018890855
62.20000000000019,11.46963797239229,-0.11687596359061855,-0.009164780331800237
63.400000000000205,11.522000740093633,-0.0680194364537816,-0.007067173494321288
64.60000000000022,11.573686111473023,-0.019219928257466715,-0.006375056036517002
65.80000000000024,11.62425550345403,0.02488892742398335,-0.006708660498610186
67.00000000000026,11.674059093299045,0.06803006503285161,-0.008035005814739371
68.20000000000027,11.721955726256178,0.10968152696612204,-0.007852058341846657
69.40000000000029,11.769831552288016,0.1506521330039514,-0.008161722338577704
70.6000000000003,11.816981452924491,0.1872966165962135,-0.008021552102300156
71.80000000000032,11.863032494574421,0.2223698984507978,-0.009031638570127676
73.00000000000034,11.908880128369205,0.25850829913141626,-0.008384222306553113
74.20000000000036,11.954448600654807,0.29373320529430313,-0.008099918574445475
75.40000000000038,11.999320798473954,0.3276343359826485,-0.008791603614313637
76.60000000000039,12.043487390249023,0.35744081498615987,-0.00960582865102566
77.80000000000041,12.087843766684205,0.3888347133516478,-0.008136504824371116
79.00000000000043,12.131788130975606,0.41833208656506105,-0.0071942509290297
80.20000000000044,12.174916642940044,0.4485109021123245,-0.010602729564383573
81.40000000000046,12.218211259726488,0.4757129941089327,-0.011261914539568707
82.60000000000048,12.261707708759197,0.5046691333747662,-0.011911135261008177
83.8000000000005,12.30393826634047,0.5305943264759855,-0.01016532837159545
85.00000000000051,12.346681117133905,0.5565018825077132,-0.011199688557717913
86.20000000000053,12.388599233462282,0.5828430822217108,-0.011156005970160088
87.40000000000055,12.431036811068573,0.608526204056797,-0.010345923211252384
88.60000000000056,12.472413848897455,0.6313796176322606,-0.011543865440749812
89.80000000000058,12.514076777680218,0.653956430076369,-0.01208279744118368
91.0000000000006,12.554786921825903,0.6762130930770568,-0.012586890321983901
92.20000000000061,12.596989987175032,0.6981402364512852,-0.013275875358987221
93.40000000000063,12.637303452225474,0.7183328468023826,-0.013403118182349516
94.60000000000065,12.678862108031348,0.7390979046961252,-0.014485019006711397
95.80000000000067,12.719948926323031,0.7586788896525418,-0.01461164809834603
97.00000000000068,12.761104807708143,0.7761590925395384,-0.015086902313671047
98.2000000000007,12.802086721498986,0.7940236589225373,-0.0145705408611283
99.40000000000072,12.842359595318408,0.8118249125367172,-0.01592234125570169
100.60000000000073,12.882969554262514,0.8272604532291418,-0.01483447339187105
101.80000000000075,12.923554859658092,0.8436860050076749,-0.016237229209731474
103.00000000000077,12.963595212578253,0.8581986752194181,-0.017070437378859715
104.20000000000078,13.004114258404298,0.8724733819989352,-0.01721638565332473
105.4000000000008,13.044908838078676,0.8840229557950332,-0.018464308170344168
106.60000000000082,13.085118301799023,0.8977716967340835,-0.01797384313234751
107.80000000000084,13.125201990295468,0.9087712617541466,-0.01721484322494682
109.00000000000085,13.165239911017252,0.9197850882795987,-0.018523727708999793
110.20000000000087,13.205523014749888,0.9324201688237204,-0.018530645692426795
111.40000000000089,13.245773191219897,0.9431055996116837,-0.019433809190440243
112.6000000000009,13.285937399352846,0.9532288725808291,-0.0198499208215015
113.80000000000092,13.326236548482969,0.9620213155880508,-0.019849626912329832
115.00000000000094,13.365955880047256,0.9718814250237139,-0.021127202950798285
116.20000000000095,13.406039937044806,0.9807818704707991,-0.02115327968878411
117.40000000000097,13.445845222677812,0.9906813964996112,-0.021473513508832198
118.60000000000099,13.485882468213493,0.9982967917553408,-0.02148992411202677
119.800000000001,13.525684509594774,1.0107219793793454,-0.021490095628338146
121.00000000000102,13.565447860067431,1.0199260735771554,-0.0214900981762991
122.20000000000104,13.605029567581033,1.0303889893201765,-0.02149015043589042
123.40000000000106,13.6447459442339,1.0405333374660715,-0.02150576513562541
124.60000000000107,13.684414927845435,1.051549591905056,-0.02263557299304164
125.80000000000109,13.723477869427294,1.0613116198158052,-0.022480785989489327
127.00000000000111,13.763274417723112,1.0724740627337888,-0.022479720052231755
128.20000000000113,13.802491104254768,1.084341168163371,-0.02241157562444851
129.40000000000114,13.841329639153573,1.0972081647195409,-0.02378897880794817
130.60000000000116,13.880716019667403,1.1076870351241888,-0.023799948543977045
131.80000000000118,13.919685283363059,1.1192874317710009,-0.023795969584676335
133.0000000000012,13.959234238269154,1.1322392502540346,-0.024766730844437923
134.2000000000012,13.99767085012699,1.144797475386658,-0.023797854414609354
135.40000000000123,14.037191547803639,1.1583032714955168,-0.023793475578728795
136.60000000000124,14.075786805891081,1.1710103337218483,-0.02501856584888973
137.80000000000126,14.114815657495472,1.1860013236338665,-0.025121048735123885
139.00000000000128,14.153554901088661,1.1982209084235411,-0.02476711378922758
140.2000000000013,14.191618877487391,1.2118883763499126,-0.02478985431010905
141.4000000000013,14.230451116594262,1.2267326524067774,-0.024789888558023776
142.60000000000133,14.269264686870953,1.2413240074839629,-0.024789888003033944
143.80000000000135,14.307733685105159,1.2551687390860025,-0.024789886703698194
145.00000000000136,14.345816375744029,1.27035407287581,-0.024789664917642895
146.20000000000138,14.384271310168112,1.284352982356703,-0.024756226220145727
147.4000000000014,14.421905372952045,1.298056311595239,-0.026103355362142366
148.60000000000142,14.461138652913796,1.314443712303013,-0.026109888008327253
149.80000000000143,14.498848747961292,1.3279692238921688,-0.026106041545897796
151.00000000000145,14.537112157890975,1.3440398155498074,-0.027400264073725644
152.20000000000147,14.575095403018896,1.3582895826122046,-0.027420614026984147
153.40000000000148,14.613173115649065,1.3725173362996224,-0.027594287660633654
154.6000000000015,14.651225230376792,1.3876909074931487,-0.02741914677530577
155.80000000000152,14.689201785673731,1.4030962403666474,-0.027419121164379945
157.00000000000153,14.727302951187028,1.4174580697522663,-0.026115074032516006
158.20000000000155,14.765068882274374,1.4320040543018069,-0.026109953687009302
159.40000000000157,14.802868000983377,1.4471071518544418,-0.02611075774156113
160.6000000000016,14.840608576109705,1.4629987235645312,-0.02745171712085348
161.8000000000016,14.87844246501691,1.4774680158520193,-0.0274193404655243
163.00000000000162,14.916259939667956,1.4923336584363913,-0.02742000489410401
164.20000000000164,14.95406847585527,1.5061405287901153,-0.027482997271517817
165.40000000000165,14.991998602690964,1.521744847235756,-0.028736923055978636
166.60000000000167,15.02958618628504,1.5355691980117636,-0.028730051823257163
167.8000000000017,15.067339614445432,1.5498184239450772,-0.028751814656410524
169.0000000000017,15.10514985847511,1.563168494607553,-0.030049656743409425
170.20000000000172,15.142862707136352,1.5773456058439308,-0.031015214639331212
171.40000000000174,15.180354695791216,1.591404505305292,-0.03133450719254194
172.60000000000176,15.217723226310182,1.6060917232908902,-0.03070841239667077
173.80000000000177,15.255262152484132,1.6212780602628314,-0.03070958808128399
175.0000000000018,15.292884707138146,1.6359759030697623,-0.03067317665151137
176.2000000000018,15.330290243221766,1.6501872781699087,-0.03202293419252289
177.40000000000182,15.367320773102215,1.661291238139579,-0.032030186739090194
178.60000000000184,15.404652503606288,1.6745706133483407,-0.03203009518565825
179.80000000000186,15.44210589245926,1.6878724914617182,-0.03203009423298209
181.00000000000188,15.479326262345683,1.6994420105100603,-0.03203009536465107
182.2000000000019,15.516611272566358,1.7131275394712853,-0.032026565281893404
183.4000000000019,15.554003288397887,1.7268296902400642,-0.033055596043008784
184.60000000000193,15.5910219627591,1.7381502037479428,-0.034665208712872264
185.80000000000194,15.627987062987676,1.7509350788902855,-0.03466773056553407
187.00000000000196,15.664761013772818,1.7620310738524878,-0.036024022350383156
188.20000000000198,15.701828037551696,1.7741875309909527,-0.03598035569700109
189.400000000002,15.738927345243328,1.789946748560065,-0.035979538670396494
190.600000000002,15.776113484981899,1.8002756889269163,-0.037160145506660136
191.80000000000203,15.812464968638814,1.812878108179657,-0.03729894491472496
193.00000000000205,15.849627748919296,1.8251223520198085,-0.03730006910529848
194.20000000000206,15.886732651820319,1.8363621994062376,-0.038418345946973353
195.40000000000208,15.92350167388919,1.850908812146614,-0.03860818656203069
196.6000000000021,15.96060539576446,1.8613822166858243,-0.038608556599404764
197.80000000000211,15.997133947484848,1.8735669397586951,-0.039970465389741694
199.00000000000213,16.033971193068073,1.8857789161865353,-0.03988538354789428
200.20000000000215,16.070474337733813,1.8979822597333371,-0.04123235404489067
201.40000000000217,16.10743969538846,1.9088909697622143,-0.04124012681866107
202.60000000000218,16.14404034738718,1.9214627544294114,-0.041243264710963956
203.8000000000022,16.18043163878369,1.9339523674993413,-0.042699447321083106
205.00000000000222,16.217430144423474,1.9465553806512452,-0.04386825380194059
206.20000000000223,16.253945668021277,1.958340293527767,-0.04541520575971614
207.40000000000225,16.290509089333455,1.9681509697069821,-0.046061836204571716
208.60000000000227,16.327507924910954,1.9820931361196994,-0.04661330765720528
209.80000000000229,16.36385588464118,1.9930738589449999,-0.04628877602561943
211.0000000000023,16.400376536684036,2.005692299946126,-0.04758171588739746
212.20000000000232,16.43728377649332,2.018152474633385,-0.048933065035968504
213.40000000000234,16.473660832841137,2.0332866379701957,-0.05041326957569581
214.60000000000235,16.510261866192984,2.0444628063724184,-0.051685604898346504
215.80000000000237,16.546728505623143,2.05824856450351,-0.05240711788607655
217.0000000000024,16.583587831057937,2.0719320714985603,-0.052981611971174125
218.2000000000024,16.619961291353768,2.084603878505214,-0.054313590109810406
219.40000000000242,16.656603410140434,2.0980637966342197,-0.0555832253579327
220.60000000000244,16.69339165634154,2.1117506687103984,-0.05723868051916181
221.80000000000246,16.72979529280626,2.1217692159070394,-0.05818066919139575
223.00000000000247,16.766226891614195,2.1347041179770256,-0.05886938126748209
224.2000000000025,16.80265483940789,2.148474499806022,-0.06060058458838746
225.4000000000025,16.838925615520793,2.1596006798801244,-0.06194991746161538
226.60000000000252,16.875604015597414,2.171210964885925,-0.06299563105737072
227.80000000000254,16.912244655632552,2.1835911017124285,-0.06420765810767914
229.00000000000256,16.948364789163058,2.1947362549128924,-0.0663893060233951
230.20000000000258,16.984795845297864,2.2066192605678827,-0.06837443278721089
231.4000000000026,17.021308154363904,2.216228451299549,-0.069954877339232
232.6000000000026,17.056879817629543,2.228914777082748,-0.07146794155817648
233.80000000000263,17.094189538403256,2.23762636421233,-0.07288405217812688
235.00000000000264,17.130582414527677,2.250517024171869,-0.07440478085881486
236.20000000000266,17.16682083446252,2.2587666339696946,-0.07742771749115906
237.40000000000268,17.203047613332696,2.26723810246668,-0.0796829249634694
238.6000000000027,17.23949740704918,2.2771051282610015,-0.08239200239613353
239.8000000000027,17.27550137108574,2.285941472704053,-0.08470987721514245
241.00000000000273,17.31227858145844,2.295278039122782,-0.087412790423397
242.20000000000275,17.34874743819137,2.302186729695418,-0.09049168577324096
243.40000000000276,17.384525441617807,2.310116115242843,-0.09266664827393845
244.60000000000278,17.421007196372514,2.316460863150268,-0.0948726572875418
245.8000000000028,17.457201604624927,2.324518822382361,-0.09610065272313939
247.0000000000028,17.4935131646699,2.3310278337215866,-0.09891566447369415
248.20000000000283,17.530067932294113,2.3378893864803847,-0.10163583558623124
249.40000000000285,17.565192528155865,2.3426216890473777,-0.10614608959776639
250.60000000000286,17.601808831409684,2.348469174509572,-0.10867547607161354
251.80000000000288,17.63882762869934,2.3537789727894634,-0.11133231339105043
253.0000000000029,17.674775304300972,2.3572568596488086,-0.11385656153915935
254.20000000000292,17.711134320112922,2.3611281874607504,-0.11767238885328624
255.40000000000293,17.74722857215425,2.3665963063058153,-0.120420098782414
256.600000000003,17.783391333514146,2.37061798869299,-0.12396293916313583
257.80000000000297,17.8193820342204,2.3738911030207874,-0.12813193833617742
259.00000000000296,17.854794066158526,2.3783152694577296,-0.13033810589130423
260.200000000003,17.891822885902606,2.3827524486593474,-0.13310798992629547
261.40000000000305,17.928317636977436,2.388785170822867,-0.13612335881287185
262.60000000000304,17.964348321497873,2.3930268884958714,-0.14061930949373735
263.800000000003,18.00063145481184,2.3983619626030896,-0.14486245942651355
265.00000000000307,18.03682728111569,2.4008311325818306,-0.14841371617686416
266.2000000000031,18.07292223457171,2.4059097774446916,-0.15290389471012533
267.4000000000031,18.109140842756876,2.4110799683413005,-0.1560774829942866
268.6000000000031,18.14535460466557,2.4156177387333444,-0.159972500962402
269.80000000000314,18.18139187947482,2.4210584848389423,-0.16575638006346427
271.0000000000032,18.217769791609808,2.426540436397447,-0.1693335016619617
272.2000000000032,18.254024688849963,2.43176689148602,-0.17404909727129558
273.40000000000316,18.290100607452562,2.4379084438471,-0.17830123297673728
274.6000000000032,18.3261701043796,2.442635782106707,-0.18237413539119407
275.80000000000325,18.362413128765148,2.4496297146365396,-0.18748699760771093
277.00000000000324,18.398708868123858,2.455273051454957,-0.19307783160551706
278.20000000000323,18.43481201455335,2.458422665758416,-0.197523729425654
279.4000000000033,18.471126476276133,2.463187367969146,-0.2032760305672916
280.6000000000033,18.507206375110343,2.4677489219223014,-0.20928231557171095
281.8000000000033,18.543377799514708,2.4724184105452705,-0.21594145029046308
283.0000000000033,18.579675393571772,2.476549103507041,-0.2224135926360713
284.20000000000334,18.61585710185344,2.479948519930951,-0.23031671537828569
285.4000000000034,18.652076833309934,2.4828657999486285,-0.2380859425726567
286.6000000000034,18.688536415641963,2.486236231462863,-0.24509666066098346
287.80000000000337,18.724818704524388,2.4898412567711135,-0.2535839848933512
289.0000000000034,18.760925385228393,2.4913014056667233,-0.2615921829875605
290.20000000000346,18.797284491034247,2.4925207141591312,-0.2716076154334024
291.40000000000344,18.833223167542368,2.492234789545606,-0.2813186377475043
292.60000000000343,18.869474924706086,2.4932851366859667,-0.2904075003677238
293.8000000000035,18.905764835656175,2.4916649803495785,-0.29964190328314855
295.0000000000035,18.942065421165168,2.4912582242697887,-0.311558257712945
296.2000000000035,18.978306117846877,2.4870149413779297,-0.3230241868688144
297.4000000000035,19.014524626014573,2.483748914539252,-0.33476268041252855
298.60000000000355,19.050943029253876,2.479823905521577,-0.3460598352271802
299.8000000000036,19.087193318507673,2.4766544889673505,-0.35912923965248655
301.0000000000036,19.123387982286655,2.4709352968851728,-0.37328733077507437
302.20000000000357,19.15975627621123,2.465538810434305,-0.3873788042199364
303.4000000000036,19.196094312221806,2.459743918418748,-0.40234497713436124
304.60000000000366,19.23237878060023,2.453261548064938,-0.41906247819382925
305.80000000000365,19.268573460275388,2.446240800461781,-0.43496336235858024
307.00000000000364,19.304687479352232,2.4409297852120573,-0.45126074044194775
308.2000000000037,19.341144250210593,2.431057612646148,-0.4685120582736628
309.40000000000373,19.377365022410267,2.4225584271888603,-0.486156779157739
310.6000000000037,19.413617184310787,2.4140178332252695,-0.5047090320228058
311.8000000000037,19.449817320005504,2.4054655585120317,-0.5232053314118632
313.00000000000375,19.48609141234271,2.39823980762299,-0.5424886920494152
314.2000000000038,19.522219620063687,2.391612053805501,-0.5620666667925276
315.4000000000038,19.558595925386253,2.382559194027287,-0.582838812511473
316.6000000000038,19.594995421365674,2.378678553842123,-0.604274072273288
317.8000000000038,19.6315274063877,2.374253254245853,-0.6269962846361485
319.00000000000387,19.66745614515286,2.370496227452072,-0.6483629397915553
320.20000000000385,19.70423232946398,2.3651575103310845,-0.6692332512839378
321.40000000000384,19.740359125667858,2.362822363701034,-0.690747191694975
322.6000000000039,19.776821067812843,2.3612103674561173,-0.7131665833447105
323.80000000000393,19.813460466970895,2.3596774445536037,-0.735801618584325
325.0000000000039,19.849697477442234,2.36065372303503,-0.7585819905086426
326.2000000000039,19.886077485671105,2.3626547832304707,-0.7802665369151391
327.40000000000396,19.922863009086402,2.366771619279502,-0.8031002545469934
328.600000000004,19.95889422618726,2.370048665160702,-0.8261208278137944
329.800000000004,19.995732022381954,2.375373993471543,-0.8500416173486784
331.000000000004,20.032219154547988,2.3804957729319294,-0.8747879204701103
332.200000000004,20.068571984863322,2.389270543929137,-0.8971763645969961
333.40000000000407,20.105219510021243,2.3991537444254396,-0.9196452389557312
334.60000000000406,20.1419362899123,2.409307795561475,-0.9412308076307538
335.80000000000405,20.17833993942319,2.4190955008770256,-0.9637562865452298
337.0000000000041,20.214654819554752,2.4315906810268313,-0.9874717679516061
338.20000000000414,20.251575763229283,2.445326476819622,-1.0104292877547514
339.4000000000041,20.288246011903777,2.459654654317266,-1.0336714239151288
340.6000000000041,20.32502246935067,2.473353750104982,-1.0574595519741607
341.80000000000416,20.36182044423721,2.489145032959723,-1.081512238897231
343.0000000000042,20.398359134750184,2.5074014412105714,-1.1036538023826679
344.2000000000042,20.434929272346256,2.5254715695225523,-1.1283634684668455
345.4000000000042,20.471580698406523,2.54257688777986,-1.1532942908890789
346.60000000000423,20.508569968419827,2.5604312227369266,-1.1780348134227787
347.8000000000043,20.545272981423008,2.579528717341083,-1.2023882977248217
349.00000000000426,20.58200658793432,2.601904991831167,-1.2271510347245371
350.20000000000425,20.618826489176257,2.62308037837134,-1.2535695971562393
351.4000000000043,20.655578678546384,2.642618037746923,-1.280182264341581
352.60000000000434,20.692413696477967,2.6652416054172443,-1.306045283395704
353.80000000000433,20.729327509739704,2.6891845459570707,-1.3330264073515972
355.0000000000043,20.766136510349057,2.7128871156874865,-1.3615306435232357
356.20000000000437,20.80290001677014,2.737406571148438,-1.3904104906427786
357.4000000000044,20.83988544917775,2.763354940367433,-1.4198115721785247
358.6000000000044,20.876767590713946,2.787810488423617,-1.4503405685860349
359.8000000000044,20.91389842855661,2.8153217168538545,-1.4821468614775593
361.00000000000443,20.95050808651213,2.842979183870483,-1.5145765921027472
362.2000000000045,20.987798408800643,2.8722077061259426,-1.5473793133856701
363.40000000000447,21.024492589670764,2.9007368576771713,-1.5807055582122058
364.60000000000446,21.061494887221897,2.9274208191054445,-1.6147678953432512
365.8000000000045,21.09853443533577,2.9587509420655245,-1.6496131700889922
367.00000000000455,21.13553872031676,2.9888214592262794,-1.6860230875649722
368.20000000000454,21.172743316940736,3.0169170422066713,-1.723799251874171
369.4000000000045,21.209654206352564,3.045633440976682,-1.762728945230831
370.60000000000457,21.246441967366298,3.0750256628686508,-1.803248466084053
371.8000000000046,21.283799180310993,3.1016633492253707,-1.8456953018365159
373.0000000000046,21.320676545602968,3.126774536563767,-1.8886345619927742
374.2000000000046,21.357819727822893,3.1502012755356534,-1.9336401579980356
375.40000000000464,21.394922005827755,3.1708475851320235,-1.9791367787172356
376.6000000000047,21.4313787863786,3.1877949491563538,-2.024456025884845
377.8000000000047,21.468706848835264,3.199270352321052,-2.071686769958603
379.00000000000466,21.50555811749221,3.2081069114181133,-2.118474193629776
380.2000000000047,21.54314467320076,3.2104283548081973,-2.1667723705848747
381.40000000000475,21.58040969162401,3.2041573817405524,-2.2150984383160335
382.60000000000474,21.617349414426048,3.1937457795529833,-2.262710401668805
383.80000000000473,21.65458566622767,3.174873035103973,-2.3113814147874123
385.0000000000048,21.69168857031013,3.144731506709174,-2.3598587563772186
386.2000000000048,21.728801228393305,3.108018021034721,-2.4081260996996727
387.4000000000048,21.76615544625468,3.0590897334464433,-2.4558454552370623
388.6000000000048,21.803065929944857,3.001192172393122,-2.502388666135823
389.80000000000484,21.8404142331743,2.9313286880695575,-2.5474012096332785
391.0000000000049,21.87749549345108,2.8526839879224437,-2.592847841014859
392.2000000000049,21.914231715297586,2.763506035722001,-2.63393621985744
393.40000000000487,21.951679736913146,2.6634062207113303,-2.6719314059086434
394.6000000000049,21.988771818343913,2.560201059167538,-2.7072175306636126
395.80000000000496,22.02596193977326,2.450293154512064,-2.740842582622812
397.00000000000495,22.06314337420174,2.3390319072669166,-2.769991773530406
398.20000000000493,22.100094448675183,2.2277481358348012,-2.7949746653283087
399.400000000005,22.137465031511475,2.12058270449693,-2.818128411282751
400.600000000005,22.17426055092374,2.0217470735446446,-2.837536949274555
401.800000000005,22.21135372610656,1.9306216174779551,-2.8540621325340734
403.000000000005,22.248352873819965,1.854857572729666,-2.8687343502956333
404.20000000000505,22.285690030294376,1.7836397573887586,-2.8788820442646914
405.4000000000051,22.322842989280588,1.7311043802435817,-2.888599819686017
406.6000000000051,22.35970713681198,1.6842763919382608,-2.8978123568276333
407.80000000000507,22.397302123764398,1.6456418178977896,-2.9066385623962505
409.0000000000051,22.43423226971701,1.6166468024335003,-2.913011818037537
410.20000000000516,22.47188043363878,1.5928571718953883,-2.9180872332702235
411.40000000000515,22.50858172447738,1.5712624361190108,-2.922964527658098
412.60000000000514,22.546377502326667,1.553230906273832,-2.9284463265785803
413.8000000000052,22.583605801927295,1.5385034196257148,-2.933046722703213
415.00000000000523,22.62107213235366,1.5243113520939637,-2.9379433520236145
416.2000000000052,22.658355909179335,1.5127133133018402,-2.9419158404298433
417.4000000000052,22.695801398533995,1.5029406767298474,-2.9460770777265717
418.60000000000525,22.73326903549155,1.4931533077492884,-2.950058094383597
419.8000000000053,22.770553338805836,1.4829624321346115,-2.953466921772158
421.0000000000053,22.808157216108853,1.475422783399045,-2.9570181875659394
422.2000000000053,22.84548917702656,1.4690804143868017,-2.961084526265095
423.4000000000053,22.883091393931878,1.4612509444769535,-2.965734364124459
424.60000000000537,22.920695305380175,1.4552317495253413,-2.968285350083232
425.80000000000535,22.958316178439908,1.4497158009390487,-2.971467268957641
427.00000000000534,22.995446788200773,1.4456108204701392,-2.976589599248788
428.2000000000054,23.03296211886561,1.4405834882454744,-2.9802771872833707
429.40000000000543,23.070632672955334,1.4358890279411958,-2.983110378469298
430.6000000000054,23.108329514025726,1.4314144750175655,-2.988218688887925
431.8000000000054,23.146188567296623,1.4282702950353074,-2.992220549430087
433.00000000000546,23.183653876935413,1.4267334513845675,-2.9939755902359586
434.2000000000055,23.22112845978788,1.4241093771085815,-2.9958781144862505
435.4000000000055,23.25917032126923,1.4218799910915845,-2.9992960603070933
436.6000000000055,23.296503785649065,1.4207988603737574,-3.0043636507879006
437.8000000000055,23.334268590177896,1.4217318708735482,-3.0087758242507334
439.00000000000557,23.371629858398713,1.4193072534361568,-3.012117553451717
440.20000000000556,23.409603376298456,1.4211961979243979,-3.0147679905992297
441.40000000000555,23.447318607083076,1.4208865550783096,-3.0179491905884492
442.6000000000056,23.484898176704768,1.423588350879554,-3.02193223647707
443.80000000000564,23.522768160249026,1.4231688841527976,-3.025042544581111
445.0000000000056,23.560387299862704,1.4258832835972073,-3.027775442616363
446.2000000000056,23.598055870246565,1.4263357320461167,-3.03090698495739
447.40000000000566,23.63612744212477,1.4313799662463305,-3.0335205018341607
448.6000000000057,23.67395995775096,1.4343158998148726,-3.036831912338625
449.8000000000057,23.71179680426749,1.4382081328280345,-3.0400433450910542
451.0000000000057,23.749546161142973,1.4412930344799582,-3.044221238611601
452.20000000000573,23.78765639532823,1.4494270135293479,-3.0479077318374195
453.4000000000058,23.82536986635221,1.452323270657157,-3.0494865917245426
454.60000000000576,23.863319891175383,1.4574953580793553,-3.051756570425094
455.80000000000575,23.901466602689055,1.4625230583501898,-3.0553117935341882
457.0000000000058,23.939296185484345,1.4676130401773693,-3.058821157735807
458.20000000000584,23.977118962402336,1.4726987358906518,-3.060502747848388
459.40000000000583,24.01507818033839,1.4807330627920199,-3.0639892661873724
460.6000000000058,24.05333137275203,1.4846736733370793,-3.065133461264579
461.80000000000587,24.091402907551352,1.4912540766647016,-3.0675999618743166
463.0000000000059,24.129297174859552,1.4972347532743686,-3.070341343606873
464.2000000000059,24.167152556783407,1.5042263474283832,-3.073434526636548
465.4000000000059,24.205218118055697,1.5131455589373557,-3.07580902183219
466.60000000000593,24.243261846132906,1.5188477148891042,-3.07818927834704
467.800000000006,24.281504011629078,1.526591467010092,-3.080381003442901
469.00000000000597,24.319805984339354,1.5318758714811422,-3.0823460025256537
470.20000000000596,24.357894299552797,1.5380982697703798,-3.085184282116542
471.400000000006,24.395995632887136,1.5460623764859198,-3.0870381476905155
472.60000000000605,24.434256789429273,1.5509399328308822,-3.089811858929759
473.80000000000604,24.47233862704732,1.558578525906413,-3.091763916887042
475.000000000006,24.51042251070957,1.564833900768953,-3.0931195211717166
476.20000000000607,24.54876752583791,1.573474340834514,-3.094319361189184
477.4000000000061,24.587174861630913,1.5794147789706021,-3.096842798923265
478.6000000000061,24.625387395616823,1.5862601175787758,-3.0987991288456573
479.8000000000061,24.663500366853384,1.5915351828923927,-3.1010689127201347
481.00000000000614,24.701807723858206,1.5963472878119878,-3.1041593879434117
482.2000000000062,24.740273320565045,1.602398458983036,-3.10590261936931
483.4000000000062,24.7784909587289,1.6088296773542936,-3.107392272861917
484.60000000000616,24.817015505970144,1.612947436221284,-3.109103358963332
485.8000000000062,24.855158811429256,1.6192394659778335,-3.1115894180025534
487.00000000000625,24.893650780037706,1.6228596021211281,-3.113497042491222
488.20000000000624,24.931867403992396,1.6281951285553542,-3.1143464609641
489.40000000000623,24.970207578733763,1.6313631578425365,-3.1164372929130333
490.6000000000063,25.008813576080662,1.6364769560095682,-3.1176972924528066
491.8000000000063,25.047074897051548,1.64247897431149,-3.119368668205924
493.0000000000063,25.08568314683461,1.6462328913894646,-3.121452578667757
494.2000000000063,25.123916160639578,1.6491146565617085,-3.123576540802172
495.40000000000634,25.162515397968573,1.6546213464642476,-3.125376357805048
496.6000000000064,25.20121768777516,1.6585834344739412,-3.126354603132684
497.8000000000064,25.239742502771495,1.6605014645808236,-3.128485648227657
499.00000000000637,25.277869446302237,1.6651872077562277,-3.1297264342351547
500.2000000000064,25.316754009029914,1.66882882516126,-3.132064384280814
501.40000000000646,25.35502579167029,1.6717458516543127,-3.1335185344303538
502.60000000000645,25.393277676096172,1.6752220827344972,-3.1347274261356306
503.80000000000643,25.431717853409125,1.6799269700792498,-3.1361346474288414
505.0000000000065,25.470452285149143,1.6823719354522286,-3.137800103262606
506.2000000000065,25.508636679393984,1.6872757817587214,-3.139224482318049
507.4000000000065,25.547520522815223,1.6875292647352793,-3.1406560009000177
508.6000000000065,25.58601725725912,1.6903423765055414,-3.142000592013444
509.80000000000655,25.624669159090633,1.69183376955648,-3.1434901469985013
511.0000000000066,25.66313666707688,1.697805689269988,-3.1448577995114446
512.2000000000066,25.701866079834243,1.7011719665426275,-3.1447823414611835
513.4000000000066,25.740312505889246,1.7036569338877876,-3.1461033820269177
514.6000000000066,25.778882006849877,1.708145900602439,-3.1475529877341755
515.8000000000067,25.81744762534108,1.7110117277990358,-3.149076625955152
517.0000000000066,25.856198359999706,1.7133518549176905,-3.150385571841868
518.2000000000066,25.89473105495083,1.7145771694971266,-3.1509259152042493
519.4000000000067,25.93340849066143,1.7201260721484348,-3.151678278789678
520.6000000000067,25.97211975975084,1.720163442774367,-3.1530150856288213
521.8000000000068,26.010855035454792,1.7222007017402319,-3.1545447810556624
523.0000000000067,26.049300111621008,1.7283239022824708,-3.155888012478677
524.2000000000068,26.087962447087126,1.7289700712564067,-3.15744662865545
525.4000000000068,26.126915595949214,1.7313212613763298,-3.1581881197336408
526.6000000000067,26.165383899483516,1.7351286132681,-3.1587298964882367
527.8000000000068,26.204258534280466,1.7374843045754256,-3.1607325514725666
529.0000000000068,26.242798529561757,1.7390132503029934,-3.1620836128692686
530.2000000000069,26.28164563144029,1.7442993168719418,-3.163562086850094
531.4000000000069,26.319971772519487,1.74522059124163,-3.1648074849386276
532.6000000000068,26.358792827439324,1.7461562235129562,-3.164748762679741
533.8000000000069,26.397570483680564,1.7495815658192926,-3.1660511202895187
535.0000000000069,26.43671663193872,1.753893227227831,-3.167392565078087
536.2000000000069,26.47530194775163,1.7553874729014998,-3.1683780004192705
537.4000000000069,26.51404259826302,1.7580835212153003,-3.1687697352127424
538.600000000007,26.552862485705706,1.7625218130636413,-3.170176175917647
539.800000000007,26.5913885865145,1.7640564139810528,-3.1714643939695026
541.000000000007,26.630488950171678,1.7674546258295258,-3.172231955293264
542.200000000007,26.669370074163783,1.7687199577516193,-3.172776901489846
543.400000000007,26.707957496942875,1.775275828204147,-3.1741159526453946
544.6000000000071,26.746992326610695,1.7751769805932411,-3.1755312862726064
545.800000000007,26.785576711006907,1.7781322953277787,-3.176907085390977
547.000000000007,26.824547570596998,1.7837761762432385,-3.1771311841618197
548.2000000000071,26.863152159568706,1.7925525725700782,-3.178153469192849
549.4000000000071,26.90193965214896,1.802449601665562,-3.1781467635548575
550.6000000000072,26.94049017788065,1.811416532309872,-3.1794538436746955
551.8000000000071,26.979787971826113,1.8176544307800986,-3.180181396380856
553.0000000000072,27.018500619703904,1.824710439211388,-3.180791793878944
554.2000000000072,27.057166288621048,1.8277363545815386,-3.182863698841409
555.4000000000071,27.09630731486676,1.8327130943984113,-3.1840771857231287
556.6000000000072,27.13514047817749,1.8380145545292383,-3.185351870698489
557.8000000000072,27.1738402741792,1.842752765511747,-3.1854133754592198
559.0000000000073,27.212902032229824,1.8497267197526934,-3.1867128892806433
560.2000000000073,27.251884124993904,1.8563826236998842,-3.1878774792721627
561.4000000000073,27.290682587317935,1.8608051466496955,-3.1881380450916907
562.6000000000073,27.3301394218716,1.8656255224004672,-3.1893425380092424
563.8000000000073,27.369104404035667,1.8714481362470459,-3.190658081397729
565.0000000000073,27.40857294239641,1.8734006143040263,-3.19065861863109
566.2000000000073,27.44703509441862,1.8792188166138628,-3.1919587672876455
567.4000000000074,27.486058361976916,1.8842578431215777,-3.192663123510754
568.6000000000074,27.52504684268373,1.8899559591332733,-3.1939482621662805
569.8000000000075,27.564162707339715,1.8952051828672791,-3.1942060404244836
571.0000000000074,27.603077529251166,1.899383220319938,-3.1946254427458403
572.2000000000074,27.642486141196976,1.905398008947294,-3.195599884790936
573.4000000000075,27.6812653383129,1.9102687343956424,-3.1969526929500436
574.6000000000074,27.720724912688475,1.9150967032672768,-3.196968607853081
575.8000000000075,27.759302322779984,1.9168583173251637,-3.1982293840444616
577.0000000000075,27.798493438911184,1.9215850458667216,-3.1995466949635363
578.2000000000075,27.837670876023232,1.9229727075309213,-3.2003912537521044
579.4000000000076,27.87688954204827,1.9243811911119124,-3.2008605113404642
580.6000000000075,27.916163408871697,1.928465895467631,-3.2009941139419458
581.8000000000076,27.955177097400966,1.9328974541212705,-3.202187412310376
583.0000000000076,27.994637248965688,1.9341013506568119,-3.2035764451359903
584.2000000000075,28.033611443812458,1.9371656643592903,-3.203493378650037
585.4000000000076,28.072886825229332,1.939183298639089,-3.204273522151875
586.6000000000076,28.11195937523935,1.9405527444800272,-3.2055897289470687
587.8000000000077,28.151310715199514,1.941140505252707,-3.2068540660655005
589.0000000000077,28.190594901312345,1.9399806266057393,-3.208208978707436
590.2000000000077,28.22998842154525,1.9401916743531327,-3.208259940311673
591.4000000000077,28.26936876000962,1.941511618010381,-3.2085510404521074
592.6000000000078,28.308402062686895,1.9393519176044578,-3.2088676548878485
593.8000000000077,28.34788773313163,1.939057553895168,-3.2101734957858157
595.0000000000077,28.38717278136004,1.939612678475385,-3.2101038255994547
596.2000000000078,28.426533824101522,1.9386339283148604,-3.2114990676828064
597.4000000000078,28.46588060199982,1.9417399186319424,-3.211524540507339
598.6000000000079,28.505354658279085,1.9415925673214045,-3.2129607190695513
599.8000000000078,28.54461626021211,1.9430093751740631,-3.2142869955630484
601.0000000000078,28.58385509813342,1.9440411916725338,-3.214240155809396
602.2000000000079,28.623229702543675,1.9451188533092048,-3.214192773466026
603.4000000000078,28.66240808591294,1.9460736437642754,-3.2155573830513093
604.6000000000079,28.701761056773755,1.9497831007312294,-3.216912063340937
605.8000000000079,28.74144013850189,1.9506828840128887,-3.216964619520039
607.000000000008,28.780640497888417,1.9506669120036833,-3.2181923361478626
608.200000000008,28.820259890636034,1.9532606271156205,-3.218195223625749
609.4000000000079,28.85982123625891,1.9565687093880917,-3.21951313612737
610.600000000008,28.898898958716735,1.961398170554761,-3.2195139719554864
611.800000000008,28.938177538248326,1.963747139526799,-3.2208210993067947
613.000000000008,28.977965127705836,1.962890988745762,-3.220834883881545
614.200000000008,29.01717034704021,1.9676868767914744,-3.2221426889889724
615.400000000008,29.056485953385135,1.9710701950497638,-3.2221420984890625
616.6000000000081,29.096117628363693,1.9712194490071016,-3.2235176210401053
617.8000000000081,29.13555791928589,1.975166919453894,-3.2234603383909195
619.0000000000081,29.175117994802854,1.9784733863063213,-3.223455177425284
620.2000000000081,29.21439543951576,1.9794802460371765,-3.2247599776911224
621.4000000000082,29.253698076104268,1.9841835233956122,-3.2261422779130955
622.6000000000081,29.293288645030916,1.9873683010450705,-3.225400241628635
623.8000000000081,29.333014833822546,1.9910789296488105,-3.2254259170504334
625.0000000000082,29.372229024452892,1.9929305311144911,-3.226712469360773
626.2000000000082,29.411609263475444,1.9979854660256813,-3.228140193938007
627.4000000000083,29.45095718607991,1.99888431858335,-3.227984493275726
628.6000000000082,29.490609897835345,2.0032057844119744,-3.228722471595147
629.8000000000083,29.530324269154825,2.0055572060415723,-3.2298007480238384
631.0000000000083,29.56952237747936,2.0089384154072607,-3.230040167141762
632.2000000000082,29.60913800140266,2.0142613065688906,-3.230040052173144
633.4000000000083,29.648259794715795,2.015692375949841,-3.2313456990255265
634.6000000000083,29.68770738962362,2.019248504044136,-3.2313126192129076
635.8000000000084,29.727506216673483,2.024682895168768,-3.2326701527163775
637.0000000000084,29.76702160017206,2.025970865848276,-3.2313747381498663
638.2000000000083,29.806533101540712,2.0277751466578224,-3.2327107946301084
639.4000000000084,29.845993628396652,2.032675739387226,-3.233493189959485
640.6000000000084,29.8858275097823,2.038870605155214,-3.235361918271907
641.8000000000084,29.925289195715425,2.0407168277149905,-3.2353014386822796
643.0000000000084,29.964855864211607,2.0439156783334465,-3.235609751904292
644.2000000000085,30.004457523398234,2.0488134920584926,-3.2366249317411504
645.4000000000085,30.04428107662638,2.0528293466380756,-3.2356666787271706
646.6000000000085,30.083965541645153,2.0562391677615968,-3.2370082935350553
647.8000000000085,30.123608049954466,2.06115761322295,-3.237936059168164
649.0000000000085,30.163301125963763,2.065038829507565,-3.237852564115423
650.2000000000086,30.202982715931547,2.068416942597098,-3.2392479780033305
651.4000000000085,30.24266614070617,2.072827276959493,-3.2392502402675474
652.6000000000085,30.282208180991695,2.0758259672491333,-3.2392645885963427
653.8000000000086,30.32183401633525,2.0794285481557266,-3.240568422194933
655.0000000000086,30.361926110292348,2.0849112252425583,-3.2405596547244233
656.2000000000087,30.40147185525092,2.0880850887001645,-3.2411135435328697
657.4000000000086,30.441071588981277,2.092286861650734,-3.2418787204598134
658.6000000000087,30.480930751305443,2.098753597583823,-3.24188083071133
659.8000000000087,30.520464250871534,2.1016127056632743,-3.24324610432239
661.0000000000086,30.55990461434245,2.1059737154216056,-3.2431900728379226
662.2000000000087,30.600021051712382,2.1110372706532323,-3.2431898930521386
663.4000000000087,30.63933106817029,2.115113071291721,-3.2431896382278227
664.6000000000088,30.67889897777726,2.1200453593448447,-3.2430437037022366
665.8000000000088,30.719334554589384,2.1261187307461076,-3.243516275693365
667.0000000000088,30.75876961354485,2.130055117859137,-3.2435201148173527
668.2000000000088,30.798346128390918,2.133166644397818,-3.24352569629798
669.4000000000088,30.837816680347274,2.1424427265462813,-3.2448527626419454
670.6000000000088,30.87799860429049,2.144456043543608,-3.2448409491556793
671.8000000000088,30.917364217693283,2.1478501776037504,-3.2456505204766675
673.0000000000089,30.957525407205377,2.1547225636020246,-3.24615035616679
674.2000000000089,30.997003275504657,2.1588234612407904,-3.2461578052081363
675.400000000009,31.037002062797253,2.1634197428869055,-3.2464268225385116
676.6000000000089,31.076690427404127,2.16891325598585,-3.2474674289196175
677.8000000000089,31.11651622166298,2.171876446745434,-3.247463001328744
679.000000000009,31.156183417038278,2.176833271130703,-3.2487744960513543
680.2000000000089,31.196021249790867,2.1833744050890194,-3.2487898079910504
681.400000000009,31.23543815801271,2.186523411782198,-3.2487321311363724
682.600000000009,31.27544717415541,2.189718211711525,-3.25009009064821
683.800000000009,31.315084852624924,2.19597484063296,-3.2500998466869837
685.0000000000091,31.355046991697435,2.2022602484355667,-3.2500999005130145
686.200000000009,31.394681822947163,2.206806598004529,-3.250099864075257
687.4000000000091,31.434255779634793,2.2106018319386402,-3.250092875911715
688.6000000000091,31.474098845918185,2.217197992614484,-3.251394943802327
689.800000000009,31.513895223014664,2.221886786977602,-3.251373059382411
691.0000000000091,31.55361696960183,2.2277719781589385,-3.2527179428670943
692.2000000000091,31.593268820441494,2.2319757235869915,-3.2523945342658185
693.4000000000092,31.633386172047558,2.2357005558105887,-3.252421583678972
694.6000000000092,31.673346590250997,2.2417442678335524,-3.2537902287700513
695.8000000000092,31.7132335025255,2.2464577039695923,-3.2527166658187707
697.0000000000092,31.752928130048986,2.2511248177322596,-3.2524115696251914
698.2000000000093,31.792819942576287,2.2543745120673626,-3.252726387948016
699.4000000000092,31.83263611733086,2.2612956333257506,-3.255054494157781
700.6000000000092,31.872575049642318,2.267800214673879,-3.2550479418042007
701.8000000000093,31.912428051934725,2.2735582827443985,-3.2537296528147444
703.0000000000093,31.95206598091704,2.2796175512906225,-3.2537271355676225
704.2000000000094,31.991702780383378,2.2853580682777648,-3.2531351625057336
705.4000000000093,32.031950280476686,2.290206389325556,-3.2537143400572273
706.6000000000093,32.071569388841596,2.2957564197210125,-3.2537402399012247
707.8000000000094,32.11171745452821,2.300093763280796,-3.2550439453766593
709.0000000000093,32.15131124144418,2.3053655866847977,-3.255799277625492
710.2000000000094,32.191339625999575,2.3096359935817943,-3.257349169115578
711.4000000000094,32.231121995126195,2.316327814153628,-3.257375354499681
712.6000000000095,32.2709300320881,2.321568944138505,-3.2563605408510767
713.8000000000095,32.310780689739346,2.3261148239863862,-3.256402162257406
715.0000000000094,32.3505849452562,2.3337670284583547,-3.2566898988127164
716.2000000000095,32.39015317013003,2.336296388104336,-3.2572959259811745
717.4000000000095,32.43055732619472,2.342182334296301,-3.2590920234663017
718.6000000000095,32.47026688595975,2.347838882210546,-3.2593198039164686
719.8000000000095,32.510349983505925,2.354380335882916,-3.2593177272760707
721.0000000000095,32.55012595802187,2.358594397354002,-3.2606533290016593
722.2000000000096,32.590005155251475,2.3634406293400345,-3.25997348911252
723.4000000000096,32.63019941062578,2.369670094379423,-3.259305431415908
724.6000000000096,32.670218506004396,2.3764281913216276,-3.2606287114391863
725.8000000000096,32.709843759171534,2.3813076813680754,-3.260629869152412
727.0000000000097,32.750293009772285,2.386664369669769,-3.2606326395824836
728.2000000000096,32.78991725068042,2.392494976744858,-3.2613560882710866
729.4000000000096,32.83007167311204,2.3946684054288356,-3.2606399122750975
730.6000000000097,32.869942621611465,2.4021684316697054,-3.2606436183219554
731.8000000000097,32.910181558678474,2.406654311987141,-3.2619554357628164
733.0000000000098,32.95015756630312,2.4127996159909992,-3.262290183363364
734.2000000000097,32.99016819610679,2.415603434782452,-3.262590967001999
735.4000000000098,33.03015046184331,2.425787439953853,-3.262196365884151
736.6000000000098,33.07003360159598,2.431669150636737,-3.262276160528393
737.8000000000097,33.11011639382136,2.4381932444626453,-3.263346814901014
739.0000000000098,33.15015692699933,2.443525137614029,-3.2649670458183113
740.2000000000098,33.19014836111432,2.4497022610951285,-3.2649201935203305
741.4000000000099,33.230371087817005,2.455799509718524,-3.2649199825861324
742.6000000000099,33.27039288632084,2.4607881993842287,-3.264925997788399
743.8000000000098,33.310593004476985,2.465896980160026,-3.266234575894978
745.0000000000099,33.34981647363145,2.4705333893903614,-3.2662301179638358
746.2000000000099,33.39081256786815,2.4798037933310018,-3.2662301200233754
747.4000000000099,33.43070361903125,2.484039874209778,-3.266228546899417
748.6000000000099,33.470546714790316,2.490220654940181,-3.2655672340873143
749.80000000001,33.51100672797354,2.4979151733471587,-3.26524028629312
751.00000000001,33.55104573932579,2.50427966205884,-3.265251825324884
752.20000000001,33.5912586688021,2.510525607659879,-3.266565628347254
753.40000000001,33.63158842945654,2.5191368500527282,-3.26656085072329
754.60000000001,33.67154907119,2.525224145072335,-3.267959222109099
755.8000000000101,33.71111912056522,2.5298472610813763,-3.26788048235663
757.00000000001,33.75183800192097,2.5370294975185286,-3.267876699388756
758.20000000001,33.792107515215505,2.5427756793453735,-3.2691668812617607
759.4000000000101,33.83255285944425,2.5496715422206724,-3.2691903329210974
760.6000000000101,33.87276072019572,2.554100589248551,-3.268833951955501
761.8000000000102,33.912803145892674,2.5647764294528046,-3.269567127240504
763.0000000000101,33.95335865816772,2.5689519673716523,-3.2701782427938273
764.2000000000102,33.99354292645587,2.5749803408543026,-3.2701780013276798
765.4000000000102,34.03372678839819,2.5819005280985956,-3.27022616567869
766.6000000000101,34.07422913111098,2.5908065577305157,-3.270179833082385
767.8000000000102,34.1144987687734,2.596548800304822,-3.2700759157074692
769.0000000000102,34.1546762933654,2.6056054160616755,-3.268818843126758
770.2000000000103,34.19506631597901,2.611296728519521,-3.2710479883274486
771.4000000000103,34.23528214794236,2.617183991156905,-3.2714889870774417
772.6000000000103,34.27573573971569,2.623012331734534,-3.2714653265292757
773.8000000000103,34.31601537654805,2.6317080229651926,-3.271232053721309
775.0000000000103,34.35647955365689,2.6396128586222614,-3.2723383476935477
776.2000000000103,34.39670156564181,2.643073061244978,-3.2724796494544544
777.4000000000103,34.43701578406401,2.6536833091568,-3.272480988313372
778.6000000000104,34.47739309343256,2.6581449002339315,-3.27382393030002
779.8000000000104,34.517704914624254,2.665401950355812,-3.2720238097381693
781.0000000000105,34.558341375051135,2.675166437732148,-3.269584667620693
782.2000000000104,34.59874162149538,2.6820188984464095,-3.2726658241433237
783.4000000000104,34.63896192631556,2.6913141919611836,-3.27401893015733
784.6000000000105,34.6795486670475,2.6983340825919995,-3.274019965806831
785.8000000000104,34.719999790497944,2.701606090766351,-3.2740199571103155
787.0000000000105,34.76014335789989,2.714050047809773,-3.27401995985284
788.2000000000105,34.80071401899424,2.7211702243511997,-3.2740204825715375
789.4000000000106,34.84109516379122,2.729361679150944,-3.274117478060761
790.6000000000106,34.88153372435789,2.7381041831796065,-3.273586787502121
791.8000000000105,34.92226857586182,2.744886942483239,-3.2743482456416024
793.0000000000106,34.962678694646755,2.753202826520334,-3.2743501748150345
793.8000000000106,34.989779195321546,2.7629629840169283,-3.2743501851469765