File: 01_Data/Cardboard/STA/N2/3K_min/Cardboard_STA_N2_3KData_230921_R1.csv
##Temp./Â°C,Time/min,DSC/(mW/mg),Mass loss/mg
28.0,15.704136158263083,-2.4695620662159983,-0.036230119699045105
29.100000000000016,16.567471894854236,-2.444596834641545,-0.039616388365843136
30.20000000000003,17.072230768265406,-2.4336170916656683,-0.04095056216243931
31.300000000000047,17.540379294325845,-2.4286318665557998,-0.04361849443696908
32.40000000000006,17.996512359002324,-2.427914235568846,-0.04163415129199777
33.50000000000008,18.419925670219495,-2.4264041258622826,-0.044903260003018364
34.600000000000094,18.81860137375973,-2.426247508344937,-0.04394890965617737
35.70000000000011,19.238840951129223,-2.4260013644828584,-0.043919938389742175
36.800000000000125,19.62530728496289,-2.4271453752621888,-0.046715967945500037
37.90000000000014,20.036718770512657,-2.4274507870127993,-0.04791581586668503
39.000000000000156,20.419626369908798,-2.4274612765624797,-0.0491866830353751
40.10000000000017,20.808809871130993,-2.425334569156789,-0.05035223024264335
41.20000000000019,21.194894379139733,-2.4259159173042946,-0.05119701946891775
42.3000000000002,21.575507253676072,-2.4282847190640156,-0.0531242149741491
43.40000000000022,21.949153172047374,-2.42495273043122,-0.05446272303100086
44.500000000000234,22.31691476528637,-2.4275405093061106,-0.05707208907315575
45.60000000000025,22.690762932052557,-2.430771165851465,-0.05808015899994423
46.700000000000266,23.067967800262807,-2.426819220840335,-0.061026211653506746
47.80000000000028,23.45120328323704,-2.4267186314479128,-0.061410753823499586
48.9000000000003,23.824048311759178,-2.4277487327713523,-0.06367716418139224
50.00000000000031,24.19294970751988,-2.427011096146584,-0.06533002602227356
51.10000000000033,24.564819134056723,-2.4266492568997733,-0.0664310372029151
52.200000000000344,24.938868058155386,-2.4252157547424202,-0.07025985050784112
53.30000000000036,25.306439256834622,-2.422837090680341,-0.07157985999189309
54.400000000000375,25.68348676662501,-2.421746390384284,-0.07288536690906877
55.50000000000039,26.038221911353542,-2.417466222821163,-0.07520042994439757
56.600000000000406,26.424608718221553,-2.4174761701931855,-0.07741351785211004
57.70000000000042,26.790741817653604,-2.412629530471479,-0.07850723269066995
58.80000000000044,27.16296990215178,-2.412228689120109,-0.08244007881691484
59.90000000000045,27.527949108091505,-2.40652060628617,-0.08269907702894086
61.00000000000047,27.90041145880464,-2.4057760430342663,-0.0850798282478138
62.100000000000485,28.260687770282313,-2.4020295099319635,-0.08640028026303348
63.2000000000005,28.634526586078945,-2.398333497709111,-0.09003230648635352
64.30000000000052,28.996896565691678,-2.396016929734282,-0.0916707732878792
65.40000000000053,29.362980120926814,-2.3915517556581656,-0.09297887414046935
66.50000000000054,29.72832304272742,-2.386146910032492,-0.09562267145921322
67.60000000000056,30.099938064109406,-2.3824617872870473,-0.09731879697030177
68.70000000000059,30.469170000000215,-2.3764700000000025,-0.09859012030056169
69.8000000000006,30.834213340124833,-2.372932755124962,-0.10023019383820442
70.9000000000006,31.198671803437506,-2.365900652668312,-0.10188993040105032
72.00000000000063,31.562695251438836,-2.3615398697132526,-0.10320005439738456
73.10000000000065,31.925063538468645,-2.357276392320244,-0.10418501116461476
74.20000000000066,32.29134527222763,-2.35115836722654,-0.107159946000003
75.30000000000067,32.65027528699947,-2.3462167129662115,-0.10780656452716997
76.40000000000069,33.01716090210019,-2.3430225647328045,-0.1101103885256336
77.50000000000071,33.37617216904096,-2.33812401657552,-0.10832387175128
78.60000000000072,33.74283221523741,-2.332480661547733,-0.11208994401207972
79.70000000000073,34.10840459361954,-2.330146833464902,-0.11241991699999909
80.80000000000075,34.47426427805301,-2.324736904503291,-0.11372991695613566
81.90000000000077,34.847417195977656,-2.3187891971367507,-0.1141410760874555
83.00000000000078,35.20218125738344,-2.3139298029380364,-0.11746983603040073
84.10000000000079,35.57505957038709,-2.3104116753716664,-0.11717778670252521
85.20000000000081,35.94212047793839,-2.3039816108183313,-0.11764879005336182
86.30000000000084,36.30214642701131,-2.3006364347803134,-0.11954998972316444
87.40000000000084,36.66704770858066,-2.2972791856003654,-0.11922006799685914
88.50000000000085,37.030976534900645,-2.2941500706530316,-0.12071706097148471
89.60000000000088,37.39115928070826,-2.290394317786361,-0.12121748002505717
90.7000000000009,37.7494924536608,-2.2852602567389333,-0.12123546834534826
91.8000000000009,38.112565068525186,-2.2815095986084217,-0.12053943676024037
92.90000000000092,38.47481925829968,-2.278533010600327,-0.12218982442707205
94.00000000000094,38.84127224495133,-2.274398941996676,-0.12218983299994113
95.10000000000096,39.20596375594677,-2.2713856479169476,-0.12153083372364026
96.20000000000097,39.56611643033266,-2.2678368275777157,-0.1215652974553727
97.30000000000098,39.928084685419044,-2.263798071517915,-0.12284996800000947
98.400000000001,40.28607614107463,-2.260718403362753,-0.12285007599436781
99.50000000000102,40.65028213497161,-2.2593353809262187,-0.12367670616178117
100.60000000000103,41.01264952608463,-2.254632304144623,-0.12515001982416418
101.70000000000104,41.37257611283135,-2.25181596258619,-0.12508013250187222
102.80000000000106,41.73819005158023,-2.25218558922335,-0.12516011387132986
103.90000000000109,42.10043756409721,-2.247069821564131,-0.12682907433220691
105.0000000000011,42.46505789508067,-2.245476138314636,-0.12614192087057186
106.1000000000011,42.82598252834353,-2.2429341831181393,-0.12382901558072046
107.20000000000113,43.18476426729163,-2.240909852639848,-0.12646992200882545
108.30000000000115,43.546116108102325,-2.236296916815743,-0.12547992000684705
109.40000000000116,43.906966535442955,-2.236438562770035,-0.1267994506184813
110.50000000000117,44.27059644049887,-2.2341897351638806,-0.12613453798876995
111.60000000000119,44.628826675719104,-2.2315158141685765,-0.12746011005182423
112.70000000000121,44.98534683208627,-2.2278413332089557,-0.1291000349492557
113.80000000000122,45.3459296784327,-2.2271021189201505,-0.1264063725332516
114.90000000000123,45.70767661660414,-2.226591206655651,-0.12712981516113286
116.00000000000125,46.06741214971403,-2.2217777885088084,-0.12779221885223313
117.10000000000127,46.43104802114661,-2.2191250317226676,-0.12822987600931235
118.20000000000128,46.79021555009255,-2.2179173258486093,-0.12790002713042226
119.30000000000129,47.15224247870863,-2.2150808793951136,-0.1282299636310933
120.40000000000131,47.50999836490644,-2.2135869193326685,-0.12692019169131497
121.50000000000134,47.8763407993266,-2.2125477810042273,-0.128900405259615
122.60000000000134,48.236031245545206,-2.210895840846111,-0.12756889943950167
123.70000000000135,48.58917000001338,-2.209949999999999,-0.1288901209454263
124.80000000000138,48.960056302788914,-2.2088938455627494,-0.12889012663646504
125.9000000000014,49.321223100542376,-2.2062985718384738,-0.12921985699818617
127.0000000000014,49.670928055546156,-2.2047852812399773,-0.12888987745304226
128.10000000000142,50.034530880931555,-2.2040707103309813,-0.12986868255976258
129.20000000000144,50.39278133071788,-2.2016976681263327,-0.12986157575695856
130.30000000000146,50.752284436328225,-2.2013044539946396,-0.13052905758923528
131.40000000000146,51.110215738763976,-2.198873136274621,-0.12854998609605106
132.50000000000148,51.476237020058846,-2.198859529980486,-0.12821990987005094
133.6000000000015,51.83654680190495,-2.196497405537542,-0.12789959343552848
134.70000000000152,52.19146881663528,-2.1957753149934165,-0.1302132407943466
135.80000000000155,52.55265451271287,-2.1936031232500763,-0.1305313018161911
136.90000000000154,52.9102399540834,-2.1927985343774834,-0.1308642594223839
138.00000000000156,53.268077706728825,-2.190243413016572,-0.12988012899986856
139.1000000000016,53.62757763336404,-2.1904808727788017,-0.12950427861848457
140.20000000000158,53.979695128221735,-2.188773181367897,-0.1295498110000004
141.3000000000016,54.33800458446329,-2.1874250673346283,-0.12952195734849736
142.40000000000163,54.70585389763137,-2.186778809428243,-0.12822986267809666
143.50000000000165,55.05807325745782,-2.1842491605064613,-0.13019986214723334
144.60000000000167,55.41836052751862,-2.1832221696657834,-0.13087693390039812
145.70000000000167,55.77998723392618,-2.1813480500076063,-0.13137253054057485
146.8000000000017,56.13975685551349,-2.1820815657043036,-0.13152034310807492
147.9000000000017,56.499603127592316,-2.1792725597034583,-0.13150724462611096
149.0000000000017,56.85887677512462,-2.176026323254047,-0.13218786341580913
150.10000000000173,57.215080924620956,-2.177513778879567,-0.130869741040184
151.20000000000175,57.57285967651039,-2.1772461852380687,-0.1309599939105568
152.30000000000177,57.930707180416626,-2.1732827636374275,-0.13089653140814184
153.4000000000018,58.2847383875614,-2.1745161937492052,-0.13151976745959892
154.5000000000018,58.6493926105056,-2.171819970966703,-0.13251016400331084
155.6000000000018,59.00693958761596,-2.1716934085419357,-0.13251016399999882
156.70000000000184,59.36448265030194,-2.1707461746892487,-0.13185016400079785
157.80000000000183,59.71583997315107,-2.1676469437073975,-0.13317014613829237
158.90000000000185,60.075014666901424,-2.1689106746867126,-0.13328031637112225
160.00000000000188,60.432469205035,-2.167081039598142,-0.13295155540432813
161.1000000000019,60.78857938442259,-2.167616412190856,-0.13360981899949342
162.20000000000192,61.1513959049559,-2.165312015141987,-0.1326199061662523
163.30000000000192,61.499170000000724,-2.1644099999999655,-0.13349350370637358
164.40000000000194,61.847234273984284,-2.163616879546397,-0.13207263833123495
165.50000000000196,62.20463292761193,-2.161078407582826,-0.13327992700000024
166.60000000000196,62.57032125386526,-2.1619765226554866,-0.1335734584568815
167.70000000000198,62.924608840711876,-2.1607094131075857,-0.13261989551634645
168.800000000002,63.28319167220665,-2.1600771216802404,-0.13360995307640255
169.90000000000202,63.63765983531734,-2.1591276151242145,-0.1336099539999549
171.00000000000205,63.99146999879502,-2.158842482580972,-0.13401382824067465
172.10000000000204,64.35008539195486,-2.158559715040757,-0.13426007394000772
173.20000000000206,64.70873838416829,-2.1573097593567643,-0.13458576602134764
174.3000000000021,65.06169679630092,-2.1568620769001594,-0.13491995042134874
175.40000000000208,65.42480631781565,-2.155981855749484,-0.13491995600736972
176.5000000000021,65.78227781025387,-2.1556997239153364,-0.1344367938869242
177.60000000000213,66.1440423200274,-2.1531258515450578,-0.13590995400278683
178.70000000000215,66.49779937727199,-2.1538947580543106,-0.13456111288460493
179.80000000000217,66.85875144501584,-2.1531391643240303,-0.13557995400559708
180.90000000000217,67.21283579639856,-2.1526674938524804,-0.13558007438089703
182.0000000000022,67.57375707436383,-2.151483674624384,-0.13788787740135966
183.1000000000022,67.93447719103928,-2.1495076177555523,-0.13715448410623887
184.2000000000022,68.28705323856185,-2.1493651146716872,-0.13637266798136594
185.30000000000223,68.64216706410394,-2.1471444928725996,-0.1362399518564743
186.40000000000225,68.99712069754658,-2.148050176755543,-0.13821990616482793
187.50000000000227,69.3485089244167,-2.1466225889287065,-0.13821992475886757
188.6000000000023,69.70017486205099,-2.1482777494529754,-0.1368999227836385
189.7000000000023,70.0649044495111,-2.146779006766844,-0.13689581423702268
190.8000000000023,70.41952985090603,-2.1441798050799603,-0.13953525151858504
191.90000000000234,70.77363258183328,-2.1453753305543892,-0.1388810258762394
193.00000000000233,71.1314332802393,-2.1439542769537616,-0.13887996137139025
194.10000000000235,71.48731281074816,-2.14531860668413,-0.13956515299850913
195.20000000000238,71.84306124649383,-2.141692563601166,-0.13953966384387861
196.3000000000024,72.19586185710833,-2.1443984897757327,-0.13953981899999945
197.40000000000242,72.55637080350054,-2.142672806449783,-0.14088228191401964
198.50000000000242,72.91196307339375,-2.1407323574237087,-0.1385610546029996
199.60000000000244,73.26680087478184,-2.1399406342415994,-0.1408617742381124
200.70000000000246,73.62131181683056,-2.1404441155715297,-0.1408601384865933
201.80000000000246,73.98409139476101,-2.1391208109346245,-0.1405227263395057
202.90000000000248,74.33190462811685,-2.139960101220887,-0.14185005627792746
204.0000000000025,74.68777124982249,-2.139163196749816,-0.1434899460000003
205.10000000000252,75.03876884114553,-2.136760118084913,-0.1428334007124734
206.20000000000255,75.40868979846547,-2.137830936334171,-0.1434898164485885
207.30000000000254,75.75763807441433,-2.138070934507833,-0.14478318624524888
208.40000000000256,76.12070050018072,-2.1356470808546737,-0.14643556912140232
209.5000000000026,76.47850492173905,-2.1358444541173385,-0.14679007495533059
210.60000000000258,76.83315363022295,-2.135324074346835,-0.1458013199736179
211.7000000000026,77.19046399924349,-2.135943203153065,-0.14678570103739697
212.80000000000263,77.54640508328515,-2.1359498266219474,-0.14745868354061908
213.90000000000265,77.89619911221865,-2.1336998477589426,-0.14677999511548112
215.00000000000267,78.25417679260526,-2.133029156166344,-0.15007966376331616
216.10000000000267,78.61078021564562,-2.133046563262603,-0.1500798029996253
217.2000000000027,78.96386685845769,-2.1325190308780866,-0.14895197691097994
218.3000000000027,79.32151780020281,-2.13508508471057,-0.1530414306368555
219.4000000000027,79.67784642241855,-2.1330106418765293,-0.1536995074326688
220.50000000000273,80.04052246881955,-2.1318009116378924,-0.152277108478454
221.60000000000275,80.39454403507794,-2.133986284961177,-0.15435940952784
222.70000000000277,80.75094556404697,-2.132935916438874,-0.15502011300075758
223.8000000000028,81.10615495958079,-2.1327262797545012,-0.15647357667033734
224.9000000000028,81.46220190088626,-2.1322458603076835,-0.15894851553441347
226.0000000000028,81.81711887727849,-2.1299954715961427,-0.16095010735560988
227.10000000000284,82.17186676823593,-2.129303712501238,-0.16359885331033563
228.20000000000283,82.52847190974627,-2.13047645935754,-0.1649034875405948
229.30000000000285,82.87917000000114,-2.129200000000095,-0.1658901239999211
230.40000000000288,83.23475137098714,-2.1283695685381985,-0.16785964841261292
231.5000000000029,83.58886392548392,-2.1299396843282783,-0.17049982958376075
232.60000000000292,83.94204536342055,-2.130222024255842,-0.17197159482344837
233.70000000000292,84.30080164879766,-2.1265850505284076,-0.17444992316261843
234.80000000000294,84.6598908069344,-2.128270910486877,-0.17708972070404982
235.90000000000296,85.01031612744573,-2.1273109125680736,-0.1797197711542724
237.00000000000296,85.36898004766931,-2.1267357750038816,-0.18187073986980096
238.10000000000298,85.72632293058491,-2.1264727211338332,-0.18397015816646967
239.200000000003,86.08343924488568,-2.1261107587575347,-0.18663011694086862
240.30000000000302,86.43917000000093,-2.126009999999937,-0.19025990199167309
241.40000000000305,86.80146454819096,-2.1236348729165684,-0.19454017141992308
242.50000000000304,87.15306569976185,-2.124766465984083,-0.19706018073973341
243.60000000000306,87.51164308929036,-2.124322631078072,-0.20069672531611005
244.7000000000031,87.86497954447586,-2.123400501453355,-0.20529996201448375
245.80000000000308,88.21011330046085,-2.124317369568473,-0.2079281620744946
246.9000000000031,88.57461507327652,-2.1228912821156345,-0.21362785631884496
248.00000000000313,88.92949764543235,-2.1227697521302185,-0.21978056366249366
249.10000000000315,89.28646158045454,-2.123034854928587,-0.2223637690134983
250.20000000000317,89.64100210264128,-2.121847368080178,-0.22536156262913032
251.30000000000317,89.99146262982345,-2.12138473747392,-0.23121640514998232
252.4000000000032,90.35734335362761,-2.1218091331162223,-0.23614997502360247
253.5000000000032,90.7137246346876,-2.121310586679055,-0.2421889462626119
254.6000000000032,91.06647332784392,-2.122615352276965,-0.24811122804593522
255.70000000000323,91.43107871419764,-2.1215172259149027,-0.25475387419743
256.80000000000325,91.78166332397076,-2.121766193903909,-0.2608083314666625
257.9000000000033,92.14135756901719,-2.1223504728914135,-0.26620778148556834
259.0000000000033,92.49648781671615,-2.1227219379140956,-0.2754521588741312
260.1000000000033,92.8562177409372,-2.1224117578467343,-0.2811236777255446
261.20000000000334,93.20628571435743,-2.1240989012972356,-0.2893172333830307
262.30000000000337,93.56110784409425,-2.1221505405744012,-0.2978517870453907
263.40000000000333,93.91275113413067,-2.122678329033812,-0.3060239601359829
264.50000000000335,94.27118698587604,-2.123269600432241,-0.31389402813711564
265.6000000000034,94.62129264148263,-2.1234157511314393,-0.3209309705872738
266.7000000000034,94.99502126374756,-2.1252604362541825,-0.3325774279969793
267.8000000000034,95.34585819280487,-2.124725542749551,-0.34315051450799183
268.9000000000034,95.6980199012706,-2.12668560755379,-0.3525528248357772
270.0000000000034,96.05861374494765,-2.1249135619672828,-0.3626705745211196
271.10000000000343,96.4158255360288,-2.126219274366798,-0.37460558885828776
272.20000000000346,96.77363784850401,-2.127205940797886,-0.3833878292656254
273.3000000000035,97.1284960069623,-2.1280512465453105,-0.3984034917596784
274.4000000000035,97.485471764175,-2.1304197274354646,-0.40850466300107957
275.5000000000035,97.842338615533,-2.1293480119106953,-0.42181928860803186
276.60000000000355,98.1991676794932,-2.1325206637665897,-0.4341993966297979
277.70000000000357,98.55778899915653,-2.131781521585212,-0.448412534872038
278.8000000000036,98.91773859512072,-2.1333765033796266,-0.46368884526022347
279.9000000000036,99.27429216063128,-2.135923922600432,-0.478816488301427
281.0000000000036,99.6267409598862,-2.136514622089744,-0.4929239318308629
282.1000000000036,99.9875067591008,-2.1374467922995306,-0.5094189461347813
283.2000000000036,100.34184417304134,-2.13961159757957,-0.5260651962079552
284.30000000000365,100.70188302874105,-2.1415488184918723,-0.540826759195093
285.4000000000037,101.0584277251542,-2.143884914197094,-0.559596065585211
286.5000000000037,101.419170000001,-2.144590000000047,-0.5767999149866072
287.60000000000366,101.77951667004842,-2.1445159305061243,-0.5957481869696295
288.7000000000037,102.13986370444184,-2.146761419604244,-0.6142223057175169
289.8000000000037,102.49475192997627,-2.1498741586695798,-0.633842342334193
290.90000000000373,102.85194495234585,-2.15337415211418,-0.6550148804609979
292.00000000000375,103.20770261229188,-2.1527689835645965,-0.6748017461189915
293.1000000000038,103.56481869324121,-2.1550858960137975,-0.6954548844023973
294.2000000000038,103.93307697546943,-2.1597202066845664,-0.7186624060283622
295.3000000000038,104.28707989092642,-2.161070911462168,-0.7412494859381038
296.40000000000384,104.64409844954804,-2.162292249910551,-0.7647610619366034
297.5000000000038,105.0029251728146,-2.1646428898416348,-0.7882964488567827
298.60000000000383,105.3646340564538,-2.1664108668249296,-0.8143229698744752
299.70000000000385,105.72094171001417,-2.1702596318425966,-0.8387862078547825
300.8000000000039,106.08394090233013,-2.1722480309826233,-0.8656463537947041
301.9000000000039,106.43832265206576,-2.1730752275847345,-0.8921259776219777
303.0000000000039,106.79917000000145,-2.175210000000001,-0.9190425624111209
304.10000000000394,107.15582236059484,-2.178585131597548,-0.9498380340230037
305.2000000000039,107.51582981447879,-2.180681944078346,-0.9789500394683048
306.30000000000393,107.87389472641559,-2.1841264122029216,-1.01020966717304
307.40000000000396,108.22886077512227,-2.1850625940310193,-1.0444684332319052
308.500000000004,108.58785066503614,-2.1885648587352486,-1.0711174419248146
309.600000000004,108.95006306593874,-2.1914678688614364,-1.1016644761771426
310.700000000004,109.30604619123315,-2.1958622530061023,-1.1402291099622626
311.80000000000405,109.66322753333755,-2.197593161871344,-1.1757606826697367
312.90000000000407,110.01533309906091,-2.2015430960653144,-1.211745823837148
314.0000000000041,110.38443791649787,-2.2044352014536535,-1.2505795586650792
315.10000000000406,110.74308804416123,-2.208066674986552,-1.2875765943472164
316.2000000000041,111.09539081364946,-2.2133413450212376,-1.3275810913510009
317.3000000000041,111.45372276694351,-2.217966112718117,-1.3676733368064915
318.4000000000041,111.80962913693416,-2.2202972624808925,-1.408771746926286
319.50000000000415,112.16707409255773,-2.223914157885346,-1.4509805247445895
320.6000000000042,112.53384641177534,-2.227872819819576,-1.4958870713399617
321.7000000000042,112.88996988419828,-2.233666524967235,-1.5411222697742204
322.80000000000416,113.25438614789797,-2.233744350004313,-1.586829913738255
323.9000000000042,113.61246167892507,-2.238294557094454,-1.6339211133979434
325.0000000000042,113.9694466477497,-2.241540643784921,-1.6823518173001437
326.10000000000423,114.3307469213745,-2.242855027204191,-1.7309309875566412
327.20000000000425,114.68879559571693,-2.2462998428619345,-1.7820643347245895
328.3000000000043,115.0494954115351,-2.246679684084225,-1.8336303477938398
329.4000000000043,115.40420036739879,-2.25007456265365,-1.884312581706721
330.5000000000043,115.76728973767123,-2.251840553063858,-1.9362321538014702
331.60000000000434,116.12238498816498,-2.249165078798874,-1.9877611343889319
332.7000000000043,116.48152197360609,-2.248451314054731,-2.0402402069339853
333.80000000000433,116.8341996966011,-2.2440817374159705,-2.0901438481267025
334.90000000000435,117.19598504220211,-2.2418499447861757,-2.141986745553742
336.0000000000044,117.5510733506984,-2.235940426368955,-2.1912866207177863
337.1000000000044,117.90694826388517,-2.2302431445345277,-2.2404754965105242
338.2000000000044,118.27277399755472,-2.2223462482094747,-2.2866322958375576
339.30000000000445,118.6282867644085,-2.212604593226346,-2.3331384201433525
340.4000000000044,118.9900014403493,-2.2043670901122105,-2.3744638287779
341.50000000000443,119.34573792980275,-2.1931900755996403,-2.4130406332215357
342.60000000000446,119.70403408536035,-2.184189923145457,-2.4502421302971618
343.7000000000045,120.05999151038421,-2.173619023200181,-2.48284110023139
344.8000000000045,120.41575570282026,-2.1633643971912333,-2.513024288011683
345.9000000000045,120.7761230511633,-2.1538583978072365,-2.5404339661928486
347.00000000000455,121.1410097209805,-2.1486442840904654,-2.566041351448291
348.10000000000457,121.49881850554642,-2.1396420165672465,-2.588901356367633
349.2000000000046,121.86012535346023,-2.133009899607878,-2.6094829312906893
350.30000000000456,122.2234182060879,-2.1232764083746383,-2.62885251369838
351.4000000000046,122.57801003374325,-2.1174548955260124,-2.6431167932095487
352.5000000000046,122.93950685089483,-2.1101781292976862,-2.6574116079922687
353.6000000000046,123.29593276893277,-2.104498853060259,-2.669353817076596
354.70000000000465,123.65151187158662,-2.1004418179377353,-2.6814686140009023
355.8000000000047,124.020343779737,-2.0940982897485143,-2.6918919058901305
356.9000000000047,124.37584740955012,-2.090468676920032,-2.700083309422495
358.00000000000466,124.7291700000012,-2.0873299999999726,-2.709344833368914
359.1000000000047,125.08808386042588,-2.085428961605482,-2.714638667431112
360.2000000000047,125.45042857568183,-2.082364600059421,-2.7204912366385057
361.30000000000473,125.80489088772998,-2.0799474079875337,-2.7266610604971353
362.40000000000475,126.17188827860129,-2.081109672308191,-2.7318559229225703
363.5000000000048,126.53190871549583,-2.081735114913969,-2.737202873537547
364.6000000000048,126.89510176176104,-2.0788605914777647,-2.741886649638065
365.7000000000048,127.25978953280979,-2.080303220500077,-2.7478188639049583
366.80000000000484,127.61997959219318,-2.080871464891279,-2.750409447187973
367.9000000000048,127.97424269940709,-2.079580399112682,-2.7553497299961562
369.00000000000483,128.3363516419949,-2.0788291226882687,-2.757985722390827
370.10000000000485,128.69616399127833,-2.0795687360868893,-2.7617784318097183
371.2000000000049,129.05851066249136,-2.0816482394267526,-2.7665500572593595
372.3000000000049,129.41743034475527,-2.0799121297841667,-2.7705007377407966
373.4000000000049,129.77250448874,-2.079907479787404,-2.775439887690535
374.50000000000495,130.1346096376548,-2.0827676608929995,-2.779392333456439
375.6000000000049,130.49441749121573,-2.081999502902237,-2.7833501207907743
376.70000000000493,130.85614724346362,-2.0840403323023953,-2.787300175410185
377.80000000000496,131.22052508906842,-2.0831132162171757,-2.7899119527532763
378.900000000005,131.58436787103497,-2.084704484382874,-2.7948395971109257
380.000000000005,131.946165781027,-2.085103079015919,-2.8004432712460767
381.100000000005,132.30461478333856,-2.085265651824527,-2.801789968581086
382.20000000000505,132.6650388845438,-2.0877090187814313,-2.8070565937477836
383.30000000000507,133.02489676049183,-2.0869240371019435,-2.810997748165783
384.4000000000051,133.3833770744336,-2.0877282238313746,-2.8148158788006654
385.50000000000506,133.7500931281613,-2.0894988690586445,-2.817589960227315
386.6000000000051,134.11388440623014,-2.0909730674470843,-2.8234943947182845
387.7000000000051,134.4760032446334,-2.091776778260674,-2.8241834688364413
388.8000000000051,134.8346666922717,-2.0928061958484703,-2.8280294440836897
389.90000000000515,135.19457197423236,-2.0953416298344045,-2.8314400708685072
391.0000000000052,135.5544080388877,-2.0949086846459304,-2.8341551054200664
392.1000000000052,135.9176643520105,-2.0956961355348596,-2.8380101132646836
393.20000000000516,136.2775290373583,-2.0980389670916777,-2.840640113239354
394.3000000000052,136.6423236872864,-2.1019856116112052,-2.844600194647381
395.4000000000052,137.0070659318131,-2.1007932317572404,-2.848220015821176
396.50000000000523,137.36981454243121,-2.1014958469150677,-2.852170062049753
397.60000000000525,137.7333245052341,-2.1025695072299806,-2.855769273947118
398.7000000000053,138.09740603516298,-2.105980761215725,-2.857783202507507
399.8000000000053,138.45814891280054,-2.106957362751226,-2.8627180532067964
400.9000000000053,138.8203412720821,-2.108305090230273,-2.8640328159072026
402.00000000000534,139.18347544300082,-2.1106828764880783,-2.8666602796527627
403.1000000000053,139.53613158166544,-2.1116267729983322,-2.8693005900598827
404.20000000000533,139.8958056416962,-2.1128628388225796,-2.8717951032576083
405.30000000000535,140.26850708232362,-2.1154148759362803,-2.876162430043782
406.4000000000054,140.62728262763721,-2.1169501136809705,-2.878214125825025
407.5000000000054,140.9894920191219,-2.1190696811988685,-2.882803360821047
408.6000000000054,141.3480708837347,-2.1212733239279995,-2.8846521909631333
409.70000000000545,141.71450315704757,-2.124286331248824,-2.887077971862299
410.8000000000054,142.07525667746,-2.126286726824589,-2.888813434977525
411.90000000000543,142.437261980949,-2.1293575364953226,-2.8936602392121147
413.00000000000546,142.80227111905728,-2.1297723433282623,-2.8959753638018553
414.1000000000055,143.16715261273697,-2.1331669782526106,-2.8986106184837857
415.2000000000055,143.52874916438435,-2.1352909244148828,-2.9025614587652138
416.3000000000055,143.89457040299877,-2.1369326004607685,-2.9038759474305356
417.40000000000555,144.2589557258011,-2.138006379374516,-2.907866043847105
418.50000000000557,144.62106675236768,-2.143934520372572,-2.9104852198901416
419.6000000000056,144.98854488899693,-2.147500834691999,-2.912901898415633
420.70000000000556,145.33861109519526,-2.1492003867764398,-2.915740007584742
421.8000000000056,145.70707235500643,-2.1511709457578383,-2.915740433988951
422.9000000000056,146.06984497720936,-2.1553485581986354,-2.9196916362906764
424.0000000000056,146.43917000000164,-2.1578000000002504,-2.922230592145563
425.10000000000565,146.80083867210743,-2.159494843508389,-2.9249599910031163
426.2000000000057,147.16386392107285,-2.1598376656696834,-2.9273212856686395
427.3000000000057,147.52399438608103,-2.1634628164573,-2.9302657646186194
428.40000000000566,147.8895995185392,-2.1671338613779554,-2.931225191385013
429.5000000000057,148.2474110618015,-2.1705343768547256,-2.9343082771531406
430.6000000000057,148.60814968577594,-2.1739950803233743,-2.935169953704434
431.70000000000573,148.97491297540418,-2.1820079615141115,-2.936490182421505
432.80000000000575,149.33198111051345,-2.1840780780522753,-2.9388005367847736
433.9000000000058,149.70440198490252,-2.189986438297636,-2.940410323907564
435.0000000000058,150.0638456157006,-2.194899005341232,-2.94209081977063
436.1000000000058,150.4366251436182,-2.1997591607528064,-2.944731854432169
437.20000000000584,150.801335061383,-2.2027109797011475,-2.9464399295727217
438.3000000000058,151.16707219900672,-2.2042234534963483,-2.9480197216937096
439.40000000000583,151.52629431310012,-2.208857629004712,-2.9506708309573995
440.50000000000585,151.87908554009354,-2.2108231476756224,-2.9507205373470247
441.6000000000059,152.25172204237745,-2.2177836642272384,-2.9532900000827116
442.7000000000059,152.61731517095902,-2.220701264070193,-2.955920361360059
443.8000000000059,152.98125591768405,-2.2229160594332096,-2.9598800436333947
444.90000000000595,153.34717987286731,-2.2242249816737347,-2.958921967224224
446.0000000000059,153.71017107948015,-2.228570793115106,-2.9615026566359086
447.10000000000593,154.0766913980476,-2.2296651569698573,-2.9638293640656244
448.20000000000596,154.4458933474064,-2.234223922576586,-2.9638161259569475
449.300000000006,154.8142425434654,-2.23450564997999,-2.9646130782448767
450.400000000006,155.17804876083335,-2.2388283577153514,-2.9671200810082095
451.500000000006,155.54449852207497,-2.2409607611627833,-2.96972115261178
452.60000000000605,155.90832536941338,-2.2436590644512635,-2.970736831274027
453.70000000000607,156.2713743938761,-2.2456552074052554,-2.972621660853111
454.8000000000061,156.64100370405745,-2.247559531042471,-2.9763474146360056
455.90000000000606,157.00542326764668,-2.2499587675707637,-2.976999833059768
457.0000000000061,157.37231354248004,-2.2522995313431653,-2.9770328756748867
458.1000000000061,157.73487563524358,-2.2515282433957275,-2.979299955001958
459.2000000000061,158.09916656186178,-2.256050301040067,-2.9796298610572096
460.30000000000615,158.46541458855117,-2.2580885852722234,-2.9812801109639873
461.4000000000062,158.8244771387449,-2.2581635935614655,-2.9826000030102433
462.5000000000062,159.1892330576981,-2.259265089135634,-2.9842409776753955
463.60000000000616,159.55567385011346,-2.2569304024988237,-2.9861102552694594
464.7000000000062,159.92053701222372,-2.259926119665208,-2.987539450716444
465.8000000000062,160.28019625753257,-2.2576030793427098,-2.9908300074334293
466.90000000000623,160.65563057419828,-2.252960847800359,-2.9919574790878136
468.00000000000625,161.01398164805724,-2.253056453157163,-2.9918200950032974
469.1000000000063,161.38830549812187,-2.2536122897232103,-2.993788111677448
470.2000000000063,161.75385389844195,-2.254439570881685,-2.99182116882363
471.3000000000063,162.12500578636696,-2.2541983621395834,-2.9957843374920534
472.40000000000634,162.485827737886,-2.254241125730182,-2.996905820708423
473.5000000000063,162.85733324601637,-2.256773259488058,-2.998400764481238
474.60000000000633,163.22037283116072,-2.256567095912532,-2.9993898150011553
475.70000000000636,163.59004696968393,-2.2567158503110303,-3.0004418168401488
476.8000000000064,163.9529892808608,-2.25652663189597,-3.0010491329458064
477.9000000000064,164.32264907220414,-2.257860645036183,-3.0023630106987835
479.0000000000064,164.68603677383786,-2.2587896824586613,-3.0030250415510604
480.10000000000645,165.04869563682487,-2.2593206672894617,-3.005004515106786
481.2000000000064,165.4131658190575,-2.262247472494485,-3.0056599563370723
482.30000000000643,165.78544910378315,-2.262611982478402,-3.0066836870303524
483.40000000000646,166.14504087527652,-2.2607977267886317,-3.0076310888842683
484.5000000000065,166.51955943550195,-2.2630965179124654,-3.010047933289212
485.6000000000065,166.88515006144274,-2.2616899099880117,-3.009390037032001
486.7000000000065,167.25111746141062,-2.2640349371592206,-3.0106627139457256
487.80000000000655,167.60818741296117,-2.263348138199581,-3.0109422808805126
488.90000000000657,167.9835273859891,-2.264355942421843,-3.014330038403658
490.0000000000066,168.352651969671,-2.2644160021738786,-3.014978521638801
491.10000000000656,168.72543007202742,-2.2650527819125026,-3.0169598915620606
492.2000000000066,169.09589783605065,-2.2613565708020853,-3.01729071301044
493.3000000000066,169.46053742127475,-2.2613000042664475,-3.016981978063083
494.4000000000066,169.82395823708498,-2.26092414744185,-3.018940151832454
495.50000000000665,170.19188567291408,-2.263306377578781,-3.0189300552062566
496.6000000000067,170.5597787064635,-2.2631445493892945,-3.0190564885650186
497.7000000000067,170.9282967599752,-2.262739070328915,-3.0220097916280517
498.80000000000666,171.29574902401845,-2.2651564608182775,-3.0223515707129236
499.9000000000067,171.66606231346398,-2.266290276105635,-3.023991455619309
501.0000000000067,172.0344787580121,-2.268312853256825,-3.0240068534696185
502.10000000000673,172.40059199249632,-2.2694855522725343,-3.0266308653463936
503.20000000000675,172.77309201795478,-2.2709508165246897,-3.0266198749999997
504.3000000000068,173.13788351563505,-2.2725023845937296,-3.0269501660082443
505.4000000000068,173.50245128358424,-2.2749506602247966,-3.0276040194082356
506.5000000000068,173.86678889392334,-2.276839136120403,-3.0304593050293134
507.60000000000684,174.23741225443842,-2.277401980972299,-3.0319300462594905
508.7000000000068,174.6017760106885,-2.2825260253011748,-3.0307985756334386
509.80000000000683,174.96886614421595,-2.285946491368316,-3.0334301545257225
510.90000000000686,175.33734326069688,-2.288117832324893,-3.0344100879523275
512.0000000000068,175.70817876941595,-2.289068250876278,-3.033743205293536
513.100000000007,176.06840921280522,-2.291303489446169,-3.035399901996694
514.2000000000069,176.4396887329649,-2.294037661626125,-3.038039805011285
515.300000000007,176.81045697719193,-2.29658769538381,-3.0393161495491023
516.4000000000069,177.17674946941813,-2.2985840703719536,-3.0390301234072075
517.5000000000069,177.54269130861022,-2.302385540300017,-3.0399297515359818
518.600000000007,177.91551621032136,-2.304794550718343,-3.0409053073312338
519.700000000007,178.2852576460498,-2.306571653914059,-3.0421859520342824
520.800000000007,178.65371143190177,-2.3123001400036363,-3.040898719297074
521.900000000007,179.024701544772,-2.3149666443794916,-3.042210077619198
523.000000000007,179.39458378391873,-2.317109460112524,-3.0450454448898183
524.1000000000071,179.76348364342138,-2.3194627569525545,-3.0453904516935233
525.2000000000071,180.12513945061886,-2.321020233280619,-3.0449286025242674
526.300000000007,180.49317905534204,-2.3261078381330975,-3.046624353358357
527.4000000000071,180.86283930134886,-2.327562099202448,-3.0491122916637465
528.500000000007,181.22917000000328,-2.3318399999997323,-3.0491206196071245
529.6000000000072,181.60099678753852,-2.3346259836255627,-3.047479955393573
530.7000000000071,181.97044445910987,-2.338296829483062,-3.048803501715337
531.8000000000072,182.3422653698656,-2.3430304932214345,-3.0501195357945563
532.9000000000071,182.709815397775,-2.3454207364360817,-3.051430146928304
534.0000000000072,183.07422563491124,-2.3459913958379057,-3.0509811344947977
535.1000000000072,183.44118274977717,-2.3520647114773903,-3.05229380758251
536.2000000000072,183.80973536590395,-2.3545036828215364,-3.0543438386674913
537.3000000000072,184.17495393283335,-2.3583854996340663,-3.053634280548723
538.4000000000073,184.54093254861692,-2.3612160286618296,-3.056248361456846
539.5000000000073,184.9159311856122,-2.3627404627605437,-3.057910062696546
540.6000000000073,185.28271900137366,-2.367674924252872,-3.056590123038544
541.7000000000073,185.6537268916058,-2.370440840069925,-3.05658995772186
542.8000000000073,186.02393733061965,-2.373984748316234,-3.059021926520865
543.9000000000074,186.39424260470048,-2.3776569829682335,-3.0602007248858425
545.0000000000074,186.76146017214526,-2.379983099483873,-3.0592317969235343
546.1000000000074,187.13031948179162,-2.3840212577822784,-3.0592667820407264
547.2000000000073,187.4955126308903,-2.386907891460809,-3.0635099472019935
548.3000000000073,187.86489873654955,-2.389578293327983,-3.0607570471884245
549.4000000000074,188.2300538556513,-2.3930521449056457,-3.061077561408346
550.5000000000074,188.60155199152706,-2.397278257716473,-3.063619838190869
551.6000000000074,188.97105462209763,-2.4026394679969916,-3.0631459789163475
552.7000000000074,189.34239058368576,-2.4055942182517334,-3.0636545489544833
553.8000000000075,189.70883364686713,-2.4082586252132177,-3.066360405290377
554.9000000000075,190.07514599501928,-2.4116120999662054,-3.0666584062969617
556.0000000000075,190.44659662543734,-2.412932317661602,-3.06405992349446
557.1000000000075,190.8198272649591,-2.4139402027036923,-3.06769487331303
558.2000000000075,191.19088275564053,-2.4201734389718954,-3.0675684164247627
559.3000000000076,191.5641895141836,-2.4245514663133063,-3.0715572969726557
560.4000000000076,191.9360891095412,-2.4275424586106826,-3.0689996195157088
561.5000000000076,192.3004613159576,-2.431463881922504,-3.0699800649999984
562.6000000000076,192.66733063725016,-2.4341002637355147,-3.071299949090438
563.7000000000077,193.03982470708522,-2.439123669351419,-3.0713012024741504
564.8000000000077,193.41213146843052,-2.4421422935408343,-3.0713029477135017
565.9000000000076,193.78248352204534,-2.446397573875957,-3.0730049896134157
567.0000000000076,194.1518066670138,-2.450408175424116,-3.0713016684084327
568.1000000000076,194.5213863176312,-2.4561866504677417,-3.0731707829779116
569.2000000000077,194.8929120121837,-2.4601592833680854,-3.0728400589798004
570.3000000000077,195.26448983097745,-2.463631136154238,-3.075469960448041
571.4000000000077,195.63134735911026,-2.4662047428945657,-3.0744903187806214
572.5000000000077,195.9977000773694,-2.4690082431334943,-3.077117028534315
573.6000000000078,196.3688496230573,-2.472017756082404,-3.073818697726839
574.7000000000078,196.73769812638892,-2.476496959189925,-3.076460184020826
575.8000000000078,197.11407509750546,-2.480266138485564,-3.0754694410864953
576.9000000000078,197.48635213368294,-2.4854940423201977,-3.078110049
578.0000000000078,197.85579844153165,-2.488607184916892,-3.0767900212477537
579.1000000000079,198.22599247771922,-2.4918968378155446,-3.078109798361959
580.2000000000079,198.59308950281707,-2.492248390143778,-3.0807154175753966
581.3000000000079,198.960618398168,-2.4971537175848604,-3.078109451622598
582.4000000000078,199.32873109911102,-2.5007915867198,-3.078758819713136
583.5000000000078,199.70069407360666,-2.5028829525064467,-3.081384558068992
584.6000000000079,200.0698917226721,-2.5076960426660007,-3.083050008116076
585.7000000000079,200.44352238068387,-2.5130966664397305,-3.0830499050746694
586.8000000000079,200.8138870124934,-2.5147793143949815,-3.0817299362586503
587.9000000000079,201.17865407756705,-2.518174273290214,-3.083715969076076
589.000000000008,201.55579712865293,-2.523132785661526,-3.08431795519472
590.100000000008,201.92305246143655,-2.5279381797783387,-3.0850200623925432
591.200000000008,202.2965697781802,-2.5316696372718965,-3.085470389518532
592.300000000008,202.66841356679637,-2.534963867945322,-3.0860096600549403
593.400000000008,203.03316062300385,-2.539415801122738,-3.087440248524413
594.5000000000081,203.40413832665482,-2.5447795497823242,-3.0871250562996075
595.6000000000081,203.7821208356121,-2.5473290713406778,-3.089075814637621
596.7000000000081,204.1603526197485,-2.552117918618971,-3.0920493799894504
597.8000000000081,204.53366842789453,-2.555787703851773,-3.0933737859774184
598.9000000000082,204.9067701811246,-2.5594860186363135,-3.094909868222521
600.0000000000082,205.25925028436296,-2.5655709302888856,-3.0944569687935615
601.1000000000081,205.64762275687232,-2.5637950916090553,-3.095174121939065
602.2000000000081,206.02398737789326,-2.57086975297591,-3.09611053500474
603.3000000000081,206.3906334357124,-2.5726673772916153,-3.0961099619613157
604.4000000000082,206.76552705622814,-2.5740675456731568,-3.097120496390093
605.5000000000082,207.131765341832,-2.57705070010267,-3.0987414711325023
606.6000000000082,207.5022227802262,-2.5800173887896256,-3.098187758383953
607.7000000000082,207.87438139059083,-2.5846391888812703,-3.099198024033786
608.8000000000083,208.24342438426336,-2.5877118959967267,-3.1019414549774056
609.9000000000083,208.6137213916226,-2.5899285824506344,-3.1026420872144085
611.0000000000083,208.98291457527517,-2.5941899827962853,-3.102589961890123
612.1000000000083,209.35846701640008,-2.5982501605999175,-3.1029201934309385
613.2000000000083,209.7313112794108,-2.5979814859059007,-3.104240082
614.3000000000084,210.09977442908115,-2.604831933339557,-3.105530215807652
615.4000000000084,210.4808655675635,-2.6077716265856603,-3.1068809827619663
616.5000000000084,210.85236005524985,-2.6091052620089825,-3.1068765772718008
617.6000000000083,211.2175413990746,-2.6108373570366146,-3.1078622235748163
618.7000000000083,211.59067776481737,-2.6167975756553545,-3.1076613127903427
619.8000000000084,211.95976107445483,-2.62012765909805,-3.1108175192984913
620.9000000000084,212.33071097962727,-2.621485466594,-3.1097816326809147
622.0000000000084,212.70168493743992,-2.625892946315354,-3.1102898137637647
623.1000000000084,213.07212954539787,-2.626261964338422,-3.1123119668210757
624.2000000000085,213.44444761084497,-2.630292509493775,-3.111772649642419
625.3000000000085,213.81443846785513,-2.6324565384929293,-3.1104795732534183
626.4000000000085,214.1847263509596,-2.637843026624015,-3.1128004643741383
627.5000000000085,214.55734552509617,-2.6423842369921635,-3.112911321518214
628.6000000000085,214.92763123947114,-2.6459743908092714,-3.1147899286690137
629.7000000000086,215.29529930756829,-2.6490848138681033,-3.1153379912729555
630.8000000000086,215.66454616716553,-2.6520284745913147,-3.1156844979654084
631.9000000000086,216.03206540734038,-2.657636219130522,-3.1171520544871036
633.0000000000086,216.40829272804748,-2.664209433489821,-3.117739648067608
634.1000000000087,216.77652505951667,-2.666452853677681,-3.1164255004221584
635.2000000000087,217.15969359008434,-2.6758911146994944,-3.116749977001248
636.3000000000086,217.5306721546995,-2.675339046152453,-3.11674740417432
637.4000000000086,217.89800195768777,-2.6810417073118638,-3.1169765908245926
638.5000000000086,218.27366451314225,-2.6846221352179507,-3.1173206847803323
639.6000000000087,218.64335313000612,-2.6892387603351118,-3.119159885316102
640.7000000000087,219.017167575259,-2.6967380686354554,-3.119820158004532
641.8000000000087,219.38782870085242,-2.701225354366308,-3.1187032607732084
642.9000000000087,219.76190287144092,-2.708388156431144,-3.119492230308364
644.0000000000088,220.12857241196835,-2.7126359530910054,-3.1201601997423145
645.1000000000088,220.50041751179538,-2.7180396993683615,-3.1193600739858187
646.2000000000088,220.87503704840844,-2.723662998220627,-3.1227897146727885
647.3000000000088,221.24952288466503,-2.7260141679626684,-3.1219199690000585
648.4000000000088,221.62072214651965,-2.7338870237750648,-3.1219223268824114
649.5000000000089,221.99297324267027,-2.737326700251172,-3.1235599104609517
650.6000000000089,222.36893780420337,-2.739614946466922,-3.1227117578024535
651.7000000000089,222.73916552603131,-2.74954969007911,-3.1225366447426306
652.8000000000088,223.11389236993574,-2.757430894255705,-3.1230120787897824
653.9000000000088,223.48306726779407,-2.7581281423107544,-3.1243300961576947
655.0000000000089,223.84626157980273,-2.7485714580641307,-3.1233411237952717
656.1000000000089,224.21839596145503,-2.7335103219845736,-3.1253388869188945
657.2000000000089,224.5891658272948,-2.7295001628161306,-3.123886297016468
658.3000000000089,224.96076620314545,-2.7313168352065613,-3.124332180099988
659.400000000009,225.33255453320743,-2.7366240410691294,-3.125320641900239
660.500000000009,225.70454419545,-2.740429277635645,-3.1272768598801575
661.600000000009,226.08000205772,-2.7493121598608417,-3.1259546757881536
662.700000000009,226.45375956084337,-2.753766952204345,-3.1249870515308094
663.800000000009,226.82830341036228,-2.7607472975306413,-3.12758813949074
664.9000000000091,227.19983949417522,-2.768000336385437,-3.1262823135497664
666.0000000000091,227.57311199181467,-2.772753846581116,-3.1263064782288597
667.1000000000091,227.94238930030588,-2.7806721964015324,-3.128288721191802
668.2000000000091,228.31455949905398,-2.7877015279374,-3.128665631681745
669.3000000000092,228.6903471613455,-2.79503840116013,-3.1280168951681824
670.4000000000092,229.06730174665293,-2.7995662551749594,-3.1279499529999963
671.5000000000091,229.43638087878452,-2.808110969788441,-3.1286257397855035
672.6000000000091,229.80528782164,-2.817790138751402,-3.1288087182464777
673.7000000000091,230.18397012756503,-2.8297258408956183,-3.128074298313226
674.8000000000092,230.55405230685977,-2.8354237360775327,-3.129600110173265
675.9000000000092,230.927614340649,-2.8463752367634,-3.12836716536056
677.0000000000092,231.30048255199102,-2.855417732355158,-3.130260363746549
678.1000000000092,231.67432947707238,-2.864235628037229,-3.129270024234951
679.2000000000093,232.05127931403626,-2.8735286955224795,-3.1310206737582984
680.3000000000093,232.42949236640396,-2.8812799749209255,-3.13099732393799
681.4000000000093,232.79614590592297,-2.887865440694395,-3.1315114383234706
682.5000000000093,233.17381131459555,-2.8975215662446807,-3.1301436977975756
683.6000000000093,233.53859020165902,-2.90400478449035,-3.1304698911806463
684.7000000000094,233.91507944438345,-2.913273652425077,-3.1317901806630934
685.8000000000094,234.2862031080445,-2.9171180378697725,-3.133122188983702
686.9000000000094,234.65726884705487,-2.9311743794695944,-3.1334856031789564
688.0000000000093,235.0330175871586,-2.941679414562275,-3.1333300720000006
689.1000000000093,235.40976221535672,-2.9529379556770157,-3.133330072001323
690.2000000000094,235.7871048879606,-2.955878143732438,-3.1326698829290174
691.3000000000094,236.15672777718368,-2.960432583889612,-3.1353208668975716
692.4000000000094,236.5324643023322,-2.9700718918328337,-3.1345091297574754
693.5000000000094,236.90469456030672,-2.974080416272,-3.1339438957347148
694.6000000000095,237.2784806969049,-2.9787033223534523,-3.1352988011041747
695.7000000000095,237.65275050305604,-2.9798333819244074,-3.1372802706264524
696.8000000000095,238.02233930389102,-2.9875918720384655,-3.1370948133297127
697.9000000000095,238.39454034730295,-2.9900838844036395,-3.139242102540675
699.0000000000095,238.76534215276564,-2.9989315735811113,-3.1389299262513535
700.1000000000096,239.14835232113296,-3.003906860302865,-3.139591511756363
701.2000000000096,239.52425357914916,-3.007705763954559,-3.13826981479826
702.3000000000096,239.898803933996,-3.012400953277451,-3.139259834382948
703.4000000000096,240.26959317014536,-3.0162171494688645,-3.1402406201368986
704.5000000000097,240.63827075696207,-3.0243931455119313,-3.140370480567394
705.6000000000097,241.0123944309297,-3.025340473756182,-3.1428759177859296
706.7000000000096,241.38345664065207,-3.0282797445495744,-3.1402486143866684
707.8000000000096,241.7530668435062,-3.0348146434791263,-3.1409097947759097
708.9000000000096,242.1333324060789,-3.0390379651862434,-3.1405742636161085
710.0000000000097,242.50807757080324,-3.042505629443572,-3.142870103868491
711.1000000000097,242.88415741219737,-3.043879788442294,-3.1409118279917227
712.2000000000097,243.2570531665068,-3.0498041498366195,-3.1415577841433056
713.3000000000097,243.62446392895413,-3.048613653355675,-3.141570319380919
714.4000000000098,244.00308345533628,-3.052285320351315,-3.1429925454344616
715.5000000000098,244.3773027463828,-3.0589707888522666,-3.1423951707260223
716.6000000000098,244.74893786539462,-3.061526525809716,-3.1458653447943004
717.7000000000098,245.12386029372618,-3.06605433612724,-3.144530212929165
718.8000000000098,245.49499401693356,-3.0691776931305617,-3.145509938000005
719.9000000000099,245.86948961546582,-3.0706947912280267,-3.145510036477071
721.0000000000099,246.24352710272777,-3.0749588461691513,-3.1468263801868814
722.1000000000099,246.61493113564944,-3.0786627956704513,-3.1468298134232153
723.2000000000098,246.99029238491485,-3.0839690425015087,-3.145839530431016
724.3000000000098,247.36584801231885,-3.0851715701297167,-3.147433640966092
725.4000000000099,247.73400117736517,-3.090628721470962,-3.1459663083636675
726.5000000000099,248.11408931563724,-3.098357353694386,-3.1485933424689483
727.6000000000099,248.49157070471244,-3.1032912209271712,-3.1479217534332813
728.7000000000099,248.86563204096257,-3.108776800091601,-3.1479298996058365
729.80000000001,249.243808552057,-3.111233315558713,-3.1496017264286458
730.90000000001,249.61661160954947,-3.1136402213194163,-3.1492399197569245
732.00000000001,249.99220412530724,-3.1182063283569947,-3.150547893483326
733.10000000001,250.37067500587585,-3.122256747245469,-3.150559822943006
734.20000000001,250.74217477902943,-3.1274465155903153,-3.151220167
735.3000000000101,251.11255580314273,-3.131419295533888,-3.1512201663398307
736.4000000000101,251.48132633246382,-3.1335210557909057,-3.1522240703196918
737.5000000000101,251.8481928030087,-3.1389408240527423,-3.153865853286882
738.6000000000101,252.23157432215197,-3.1450167689342785,-3.1525499780000006
739.7000000000102,252.59767839402394,-3.1517530158593936,-3.1541890415309077
740.8000000000102,252.97454514108114,-3.1504100089874028,-3.154190162522333
741.9000000000101,253.35178992058025,-3.1571172295358116,-3.15518015626048
743.0000000000101,253.72885252907818,-3.1613162256259066,-3.1555101353160566
744.1000000000101,254.1003556148652,-3.16738202699566,-3.155840023581265
745.2000000000102,254.47489748565965,-3.172171892207847,-3.155840442811473
746.3000000000102,254.85277814211736,-3.173281086976817,-3.1571599717926855
747.4000000000102,255.22855362256203,-3.1816383569567046,-3.159130915715876
748.5000000000102,255.6037660403359,-3.1888346728370185,-3.158139910253146
749.0000000000102,255.77131165268528,-3.191010005836648,-3.1574796930094227