File: 01_Data/Cotton_Rug/STA/N2/3K_min/Cotton_Rug_STA_N2_3KData_220114_R1.csv
##Temp./Â°C,Time/min,DSC/(mW/mg),Mass loss/mg
50.0,10.6,-1.00635,-0.03433421982781848
51.20000000000002,11.503289484643622,-0.9221347043613122,-0.03414551428892665
52.400000000000034,12.041977166946786,-0.8914960077128218,-0.03563183548649018
53.60000000000005,12.525537862141203,-0.8752794465272287,-0.03682606777243436
54.80000000000007,12.980842720616849,-0.8649816361474013,-0.03698317739170598
56.000000000000085,13.4234672645776,-0.856432811009993,-0.034506896783362606
57.2000000000001,13.859606308600476,-0.8487965352414946,-0.03718480413838687
58.40000000000012,14.292891414167448,-0.8414086308635716,-0.03572571724841467
59.600000000000136,14.71143514409139,-0.8360944216734116,-0.03854822626323262
60.80000000000015,15.136603352100064,-0.8287680388403996,-0.03594979658411823
62.00000000000017,15.54547376928869,-0.8248246259074477,-0.03912709799475067
63.20000000000019,15.964479219089966,-0.8183980166023521,-0.04195031026890117
64.4000000000002,16.378368144414676,-0.8139751984211039,-0.04247827615179922
65.60000000000022,16.785107655788288,-0.8082923723927752,-0.043155568297426505
66.80000000000024,17.193462996848886,-0.8037414402045977,-0.0440027867767796
68.00000000000026,17.59452370765546,-0.7999035114827255,-0.048338240131769794
69.20000000000027,18.001616310740438,-0.7966416725426201,-0.04728313762391245
70.40000000000029,18.42706587430635,-0.794376016738636,-0.04365726372305723
71.6000000000003,18.80414324983839,-0.7898757594176841,-0.05002239101037631
72.80000000000032,19.207550580528025,-0.7857888832105882,-0.04946822424375341
74.00000000000034,19.610109705797928,-0.7832709076986093,-0.04538863498309631
75.20000000000036,20.013003864315642,-0.7787255004131702,-0.04739092924971189
76.40000000000038,20.41903886538157,-0.7743812432518377,-0.050783583114410114
77.60000000000039,20.817937567639568,-0.7718475384153904,-0.052435673628807855
78.80000000000041,21.211332078364727,-0.7668697552949748,-0.053456570250862256
80.00000000000043,21.618908957678066,-0.7630579622296305,-0.05036114765451494
81.20000000000044,22.022233926267198,-0.7599475133930569,-0.049492029751682765
82.40000000000046,22.423098258461653,-0.7559941128821402,-0.05229891625063399
83.60000000000048,22.827043684509658,-0.7543392116544485,-0.05150207356875569
84.8000000000005,23.22622521105233,-0.751265727687693,-0.05371996717116634
86.00000000000051,23.62513263607294,-0.7461042205494768,-0.053119751318766006
87.20000000000053,24.023413338882,-0.7436469937201025,-0.05434370322653326
88.40000000000055,24.42473562894014,-0.7394578552492966,-0.05464264878955749
89.60000000000056,24.827002697772,-0.7366268549218817,-0.054007186417284636
90.80000000000058,25.226255172314,-0.7337270773946495,-0.0598933386940006
92.0000000000006,25.627240689818308,-0.7301862526201507,-0.05669744490131645
93.20000000000061,26.028124139246376,-0.7251203575027908,-0.05611761300539264
94.40000000000063,26.408863167004363,-0.7219209977426079,-0.05737367496552892
95.60000000000065,26.821669625574607,-0.7179442541918085,-0.05901385138118975
96.80000000000067,27.21910643639547,-0.7128128000470364,-0.05879591371200199
98.00000000000068,27.615311652990773,-0.7094040370950758,-0.05472319766814415
99.2000000000007,28.01055162267198,-0.7060810395162072,-0.06085661089169392
100.40000000000072,28.412210723808045,-0.7018806743452161,-0.05818083917191075
101.60000000000073,28.80556374597917,-0.6980191489919467,-0.059584600151572076
102.80000000000075,29.204547618264463,-0.6932627509381157,-0.060942792791737865
104.00000000000077,29.602572593991866,-0.6894036487263951,-0.061214654987605144
105.20000000000078,29.99972144598934,-0.6860857688651583,-0.061853025161940245
106.4000000000008,30.392799327289648,-0.6809990276721765,-0.06416482960805858
107.60000000000082,30.797694915811313,-0.6780606147695031,-0.059429790081439116
108.80000000000084,31.19307850385099,-0.6752847775781439,-0.06352072387828134
110.00000000000085,31.587656914124825,-0.6683712465345255,-0.06346062275557518
111.20000000000087,31.98483237444838,-0.6644698760493797,-0.06327851787033456
112.40000000000089,32.38398704268336,-0.6605625675261964,-0.06329031716811695
113.6000000000009,32.77913315561093,-0.6550611604801081,-0.06732388300711278
114.80000000000092,33.17715570211687,-0.6524723536130255,-0.06703986460125666
116.00000000000094,33.57387504491353,-0.6496317092160021,-0.06280892790249215
117.20000000000095,33.97104893940597,-0.6443891868796511,-0.0664810473111439
118.40000000000097,34.36868603558079,-0.6389014674289452,-0.06411185200451719
119.60000000000099,34.76351801051053,-0.6328248834486137,-0.06560093223145635
120.800000000001,35.159659559438616,-0.6282665470796291,-0.06828200961218656
122.00000000000102,35.55355567317948,-0.6248295475917595,-0.06490865607397822
123.20000000000104,35.94744182794453,-0.6220818064829635,-0.06908296353111698
124.40000000000106,36.34159412449925,-0.6170222801313571,-0.06770420587466042
125.60000000000107,36.73528746007448,-0.6143986547633229,-0.06767987498331784
126.80000000000109,37.1315260117545,-0.6102206884956096,-0.06909815539831232
128.0000000000011,37.52578882162338,-0.6047892557784108,-0.06756983033149488
129.20000000000113,37.92159125489845,-0.6013601842085957,-0.07031354607907847
130.40000000000114,38.314007913999326,-0.597567861682679,-0.06820767706250042
131.60000000000116,38.70883042565702,-0.594092259012941,-0.06752721648536841
132.80000000000118,39.10553193301981,-0.5916482878164052,-0.07021000621519757
134.0000000000012,39.50086492812997,-0.5869077793095789,-0.0713930647822627
135.2000000000012,39.89933142832661,-0.5802244932996946,-0.0692206907754187
136.40000000000123,40.29152345572159,-0.5777685333901494,-0.07215889628375027
137.60000000000124,40.68484889583423,-0.5743750660471496,-0.0708011548387093
138.80000000000126,41.07889683202035,-0.5708563843322816,-0.07178007941498432
140.00000000000128,41.4745812014261,-0.566945598134197,-0.06921098154517402
141.2000000000013,41.86698379711552,-0.5631976163739155,-0.07312283486998705
142.4000000000013,42.26292874614621,-0.5586318000671614,-0.07322874632142806
143.60000000000133,42.65793242104384,-0.5551847933417784,-0.0689899099379847
144.80000000000135,43.05085352327808,-0.5519060732475782,-0.07203778079205758
146.00000000000136,43.44692172781648,-0.5478365199651778,-0.07494596732558811
147.20000000000138,43.844333909584655,-0.5447133054105778,-0.07267869065011201
148.4000000000014,44.23333350967056,-0.5390298790266533,-0.07407091505387609
149.60000000000142,44.62503769954819,-0.5341109570366056,-0.07142546845060949
150.80000000000143,45.0155383997087,-0.5304306621288429,-0.0731251530445336
152.00000000000145,45.402174847530915,-0.5267888610472399,-0.0740499471000895
153.20000000000147,45.80300242147432,-0.5224225802258627,-0.07057260752583971
154.40000000000148,46.184215446143,-0.5198727169057923,-0.07697190710316093
155.6000000000015,46.58896391121329,-0.5146229501743369,-0.07993934483504894
156.80000000000152,46.979902802212166,-0.5103433225072616,-0.07638532181205271
158.00000000000153,47.37034195805345,-0.5069933858440749,-0.07572402631964348
159.20000000000155,47.76230616965519,-0.503570544509605,-0.07657007452893971
160.40000000000157,48.154764601389445,-0.4986531269847602,-0.07623199073855957
161.6000000000016,48.54805447100562,-0.49583834544792665,-0.07383570706252307
162.8000000000016,48.9403250562906,-0.49153618324744214,-0.07700700738788147
164.00000000000162,49.33723260451024,-0.48616776869172446,-0.07559926820456297
165.20000000000164,49.72903723593728,-0.4826802756994939,-0.07589587680643906
166.40000000000165,50.1137335166587,-0.47872137161293693,-0.07736226709255156
167.60000000000167,50.50278626711392,-0.4750221190080985,-0.07886945267757195
168.8000000000017,50.89640845522378,-0.47085000004200755,-0.08066810064086916
170.0000000000017,51.286333086588,-0.4680465853905281,-0.07630287786142453
171.20000000000172,51.67505838757138,-0.46340739213551363,-0.08056352243106879
172.40000000000174,52.070177855965305,-0.4612101633687882,-0.08040991928009689
173.60000000000176,52.46708943714839,-0.45763545991786253,-0.07826782139562294
174.80000000000177,52.84801292995594,-0.45119025656909856,-0.08106144418626382
176.0000000000018,53.24408906268551,-0.44703817186341915,-0.08203115826899054
177.2000000000018,53.63994704642856,-0.44214645191985935,-0.08243007423584459
178.40000000000182,54.02743435188238,-0.4403717946821934,-0.08106992680366787
179.60000000000184,54.41927211312791,-0.43775165019284334,-0.08104955143123949
180.80000000000186,54.809250423102114,-0.43402012892974273,-0.08172128038708237
182.00000000000188,55.20168454820767,-0.43024631481100184,-0.0842502760864905
183.2000000000019,55.59522936365893,-0.42750362030713474,-0.08508812232823804
184.4000000000019,55.98427552765841,-0.4240508307835481,-0.08403074847926639
185.60000000000193,56.37497162985712,-0.41927143905633085,-0.0833686357045682
186.80000000000194,56.76799328965648,-0.4162549403252708,-0.08436025582224893
188.00000000000196,57.158197062719665,-0.4125815335680306,-0.08369742283058113
189.20000000000198,57.55182070586,-0.40779770890726935,-0.08625715851632165
190.400000000002,57.940125907930565,-0.403436143240326,-0.0851003786500204
191.600000000002,58.332098956057315,-0.39964339312805713,-0.08614510323814528
192.80000000000203,58.723753458459164,-0.39551720147821834,-0.08797036888616372
194.00000000000205,59.10802550938229,-0.3929477174269083,-0.08677642193891888
195.20000000000206,59.500849941497655,-0.38946536781896196,-0.090440418718845
196.40000000000208,59.89157796166792,-0.3872645973633373,-0.08519071525472466
197.6000000000021,60.2840860031123,-0.38437296291320455,-0.08800798190387837
198.80000000000211,60.67346488069542,-0.380905051553997,-0.09094717727253121
200.00000000000213,61.06327344357915,-0.37516014235691275,-0.09007562111832002
201.20000000000215,61.45678641605292,-0.3724238739284882,-0.09138149014426089
202.40000000000217,61.844834743538776,-0.3677806153617291,-0.09123727312859442
203.60000000000218,62.23437822245798,-0.3639454093656775,-0.08994554703593227
204.8000000000022,62.61961215710431,-0.3588954751667764,-0.08975976028162425
206.00000000000222,63.01299540063656,-0.3558897524432822,-0.0915265769147493
207.20000000000223,63.40254043653163,-0.35194163422286134,-0.0945733438737939
208.40000000000225,63.79124085727942,-0.348430898431096,-0.09323987881264628
209.60000000000227,64.18083382442985,-0.34387906387626754,-0.09579116149726152
210.80000000000229,64.57413798742307,-0.3412276327922202,-0.09306106431311578
212.0000000000023,64.96861780126932,-0.33727237704580304,-0.09817505214727795
213.20000000000232,65.3542939088373,-0.3328518847861878,-0.09815897859497102
214.40000000000234,65.74501997000554,-0.3313836530449344,-0.09687492347386861
215.60000000000235,66.13864680432113,-0.3265648228825534,-0.10081006762573441
216.80000000000237,66.52613734103369,-0.32056831274313813,-0.09724456653261582
218.0000000000024,66.91591751827552,-0.3168396467688269,-0.09719018919432942
219.2000000000024,67.30432470105532,-0.3134183333501701,-0.1024599120207208
220.40000000000242,67.69362874329134,-0.31053404495252523,-0.09926111076571464
221.60000000000244,68.08696879650631,-0.308449773925656,-0.09948630017130844
222.80000000000246,68.47686629488194,-0.3059251482261405,-0.10267563442002592
224.00000000000247,68.8642257483024,-0.29972060225408587,-0.10078829117197818
225.2000000000025,69.2550005256954,-0.29433954269564594,-0.10717799676643747
226.4000000000025,69.64586447226591,-0.29219623255366545,-0.10673101383657269
227.60000000000252,70.0314871804506,-0.28947425688170164,-0.10574203704739693
228.80000000000254,70.42518965557713,-0.28408713166641814,-0.11075562849052911
230.00000000000256,70.81633564707313,-0.2806096763797623,-0.10707829670554636
231.20000000000258,71.20268513162091,-0.27754190105586035,-0.11302542037220498
232.4000000000026,71.5906157792975,-0.2730755060016021,-0.10989509525921637
233.6000000000026,71.98134581639087,-0.2696272192983844,-0.11643961709822204
234.80000000000263,72.37674762383578,-0.266793729699483,-0.11443234605862873
236.00000000000264,72.76635977363682,-0.26144262784967326,-0.11952153842216884
237.20000000000266,73.15178895819754,-0.2566739866208975,-0.1190195625366064
238.40000000000268,73.5439532864576,-0.2526402363978062,-0.1215743239418372
239.6000000000027,73.93332663102612,-0.24827982154617595,-0.12428019968530668
240.8000000000027,74.32267279193194,-0.24340536218300693,-0.1242679696981912
242.00000000000273,74.71443985446217,-0.2405741100645778,-0.12655762884144117
243.20000000000275,75.10561224751439,-0.2325725783073123,-0.129884063867431
244.40000000000276,75.49638336521492,-0.2269598204630331,-0.12906728183471428
245.60000000000278,75.88861164583189,-0.21816275452914116,-0.1332222684213722
246.8000000000028,76.28057342229643,-0.21011884933389102,-0.1350429320172828
248.0000000000028,76.67088950154641,-0.19970572720816845,-0.1370002349276085
249.20000000000283,77.057292377726,-0.193425588517617,-0.14049021868605616
250.40000000000285,77.44913238776452,-0.18974348389613796,-0.14124509149948983
251.60000000000286,77.8430901822596,-0.18256254257399152,-0.14778892374632235
252.80000000000288,78.23036088210233,-0.17087742804225775,-0.14846925002652478
254.0000000000029,78.61771001161068,-0.14333975114464828,-0.14875984072095472
255.20000000000292,79.01527322137389,-0.08964500068999048,-0.1548953625719358
256.40000000000293,79.39849866387262,-0.05922412031672938,-0.15849477866254835
257.600000000003,79.7861148371874,-0.07374393286189594,-0.160251650861293
258.80000000000297,80.18008144641601,-0.13251820671069134,-0.162795509868225
260.00000000000296,80.57047019323707,-0.16263379919980023,-0.16933206115652544
261.200000000003,80.96420109540696,-0.17201222610187475,-0.17199756258430643
262.40000000000305,81.35594525263906,-0.17424510535533957,-0.17644139911024403
263.60000000000304,81.74525704332437,-0.17465005326636054,-0.17990290763830874
264.800000000003,82.13541553363046,-0.17105994102130798,-0.1838010674597501
266.00000000000307,82.52297815355091,-0.1679408728687848,-0.18758993533845914
267.2000000000031,82.9108592156044,-0.1632667688215314,-0.19474789290807104
268.4000000000031,83.30230903974639,-0.16197828397628655,-0.20062110402983757
269.6000000000031,83.69547575542802,-0.1593087733223334,-0.20427787279563736
270.80000000000314,84.08584254709503,-0.15531107556667845,-0.20905728093994647
272.0000000000032,84.47472601964188,-0.15470983437571653,-0.21710986127672127
273.2000000000032,84.86737544669784,-0.15136202317015438,-0.2143318233208933
274.40000000000316,85.2543684102333,-0.14992303851960792,-0.2300011437578875
275.6000000000032,85.6477765889911,-0.14761100346794043,-0.23235286937512312
276.80000000000325,86.0360148889438,-0.14347274881445812,-0.24023136951342794
278.00000000000324,86.42516974997089,-0.14119485786847588,-0.24807159590589656
279.20000000000323,86.81539489778831,-0.13932006201016947,-0.25536909362439486
280.4000000000033,87.20715143542105,-0.13650550779888426,-0.26543731925668457
281.6000000000033,87.58956814967132,-0.13649720153983969,-0.26973007129024484
282.8000000000033,87.98665536471162,-0.13247142969193662,-0.28211487179246264
284.0000000000033,88.37796055396818,-0.128978684854274,-0.28817504970565855
285.20000000000334,88.76982390633712,-0.12669309667103162,-0.2975514763403386
286.4000000000034,89.15713477111854,-0.12475665559948203,-0.3143099626875987
287.6000000000034,89.54999667746861,-0.12020030774405924,-0.32093629052515205
288.80000000000337,89.9438407397079,-0.1172262697024723,-0.33333309526677724
290.0000000000034,90.33262830899733,-0.11330917290282702,-0.3437696497891398
291.20000000000346,90.72251148622317,-0.11197279736305947,-0.3515134906712767
292.40000000000344,91.11601833628045,-0.10859714640423324,-0.3651711235720545
293.60000000000343,91.50973424816952,-0.1067646501438868,-0.3785785840439089
294.8000000000035,91.90000371824449,-0.10199012932958054,-0.39239452686809084
296.0000000000035,92.29182359624005,-0.09866873153877245,-0.40402279871500113
297.2000000000035,92.68154314602386,-0.09113798890676114,-0.42176494591536073
298.4000000000035,93.07191890140594,-0.0863167951362863,-0.4370975754877091
299.60000000000355,93.46387924998373,-0.07716979511915179,-0.4563300896318374
300.8000000000036,93.85733527056068,-0.06993508155372606,-0.475614242844006
302.0000000000036,94.252107103222,-0.05716107527830805,-0.48638315531905496
303.20000000000357,94.64118676195402,-0.044246260169587055,-0.5121590856862186
304.4000000000036,95.03361922709682,-0.030181814910457568,-0.5371583787685168
305.60000000000366,95.42372506233517,-0.01735944975639822,-0.5539774138943403
306.80000000000365,95.81389965174832,-0.006181779753894899,-0.5763071736593104
308.00000000000364,96.20408697907779,0.004354176673922491,-0.6009690348830579
309.2000000000037,96.59999683219286,0.016450027410528333,-0.6283125984686722
310.40000000000373,96.98981811321345,0.027274156526719474,-0.654023731028949
311.6000000000037,97.38332655144012,0.03677083020005263,-0.6867496367248687
312.8000000000037,97.77847727970432,0.045594895044252265,-0.715998186688239
314.00000000000375,98.17345330960815,0.05718261521132642,-0.7509079071971563
315.2000000000038,98.56434964182668,0.07161686765252061,-0.7853119310465533
316.4000000000038,98.94787661335131,0.08346169588534999,-0.8196826366115042
317.6000000000038,99.344149751597,0.09397122234515919,-0.8593495637734767
318.8000000000038,99.73937172206632,0.1105007717179489,-0.9038591679573456
320.00000000000387,100.12995222157055,0.1233123629500173,-0.9459686207426152
321.20000000000385,100.52258550863188,0.13727290516528604,-0.9906031847732235
322.40000000000384,100.9124087152281,0.15392097615802083,-1.0472951098338892
323.6000000000039,101.30841552388083,0.1690718839477206,-1.1009319488535518
324.80000000000393,101.69810402551911,0.1853750374311796,-1.1544796623726041
326.0000000000039,102.09210676565135,0.20237707151068265,-1.2151514439110125
327.2000000000039,102.4871144615858,0.21604648525986067,-1.2842250691756307
328.40000000000396,102.88176156311881,0.22928215737152444,-1.355914227504969
329.600000000004,103.27858420166102,0.23858109510610437,-1.4277143176834932
330.800000000004,103.66836960207749,0.24418981696613734,-1.504332674952182
332.000000000004,104.05926935127765,0.24498325250583342,-1.5813429549117615
333.200000000004,104.45382454991436,0.2416943407980572,-1.6575295500438139
334.40000000000407,104.84723809113585,0.2367141086400616,-1.7350960130942354
335.60000000000406,105.23534543231692,0.22545208090041302,-1.8080473042437326
336.80000000000405,105.62349222351537,0.21472968336631273,-1.8811328846090603
338.0000000000041,106.01312192327434,0.19804503570932228,-1.9507596055684893
339.20000000000414,106.39964788262617,0.17861128743569887,-2.0178451846813195
340.4000000000041,106.79618832721056,0.1552351522350288,-2.077927814941702
341.6000000000041,107.18993655537093,0.12989079416388688,-2.1326485022028567
342.80000000000416,107.58161420043348,0.10624372540692639,-2.1860917270130074
344.0000000000042,107.97341918963332,0.0814561463082606,-2.228805976702773
345.2000000000042,108.36931502090624,0.06007346740202946,-2.2672388059678523
346.4000000000042,108.75550532885823,0.04373568342263482,-2.299249846798463
347.60000000000423,109.14344105329354,0.0284283878919251,-2.3265805263396757
348.8000000000043,109.53880520447268,0.015023783778457887,-2.350955043828594
350.00000000000426,109.92886703356807,0.004612247499966894,-2.371730271376321
351.20000000000425,110.32633118092107,0.0010256625404470516,-2.390137241592476
352.4000000000043,110.71345278256274,-0.003089867547526984,-2.405384689124026
353.60000000000434,111.11303392775301,-0.004099903914319001,-2.4197073534292275
354.80000000000433,111.50238721012356,-0.00440306200826698,-2.4369137152578024
356.0000000000043,111.89682051913762,-0.005196824589423303,-2.44421964283801
357.20000000000437,112.29014265104657,-0.0003791438007887513,-2.4610007250992547
358.4000000000044,112.6822230917391,0.0004721410448076893,-2.471179680535971
359.6000000000044,113.07843685901437,0.0020680477128721007,-2.4812979028670448
360.8000000000044,113.47102872069172,0.005653474716201262,-2.4945399068321956
362.00000000000443,113.86384831619671,0.005503670314642057,-2.505871310754438
363.2000000000045,114.25953222698486,0.010247004134961074,-2.5163536554089614
364.40000000000447,114.65181876769714,0.013070695336327532,-2.5294526154176045
365.60000000000446,115.03523483474665,0.017309571512085956,-2.539809811454009
366.8000000000045,115.43497598011398,0.021227548056289722,-2.5520885923225634
368.00000000000455,115.83239416991917,0.02279507197854428,-2.5626418105910185
369.20000000000454,116.22705543195649,0.027138575083290175,-2.574773688133556
370.4000000000045,116.61738324205636,0.03151140286386758,-2.5853591986025455
371.60000000000457,117.01470865730164,0.03247201399508081,-2.600183864380496
372.8000000000046,117.4101144989957,0.03642818675314011,-2.6110676606310337
374.0000000000046,117.80308423310758,0.0414601715607865,-2.622568786425199
375.2000000000046,118.19816393736961,0.04448226658092431,-2.6374944033029397
376.40000000000464,118.59157232493337,0.04802014582475165,-2.650371949809342
377.6000000000047,118.98918710810207,0.05025540721418728,-2.6607339370605496
378.8000000000047,119.38222055145765,0.055538901247483494,-2.6755464591054126
380.00000000000466,119.78001366651634,0.05737809211287856,-2.6898237000377243
381.2000000000047,120.17397328271095,0.061935247860957415,-2.706004763546134
382.40000000000475,120.5657439590563,0.06364849173882396,-2.721228724966603
383.60000000000474,120.96178542197381,0.06951657459016575,-2.7364294180544824
384.80000000000473,121.3531088391963,0.07341259782755076,-2.7532943755494337
386.0000000000048,121.745679966254,0.07642390915740023,-2.7626206570250034
387.2000000000048,122.14002297529365,0.07932276518360659,-2.7821156428840887
388.4000000000048,122.53433890848018,0.08333658574692364,-2.8023947527179924
389.6000000000048,122.92720164871895,0.08798392614240781,-2.8209103065871313
390.80000000000484,123.32667707684136,0.08983764682133982,-2.8391382788308075
392.0000000000049,123.72384126066721,0.09659876859884717,-2.858131594090404
393.2000000000049,124.12496135748201,0.10105522087834365,-2.8766631080357445
394.40000000000487,124.51636562470098,0.10378080341768667,-2.8993110791634473
395.6000000000049,124.91382943700137,0.11104733594963746,-2.9218102909359542
396.80000000000496,125.3082350062622,0.1131872120777212,-2.940494385488808
398.00000000000495,125.700000000002,0.11775000000013461,-2.9614038683081274
399.20000000000493,126.09790504432863,0.12066237365424098,-2.9864888169876864
400.400000000005,126.4915473383394,0.12423503717316352,-3.006855756134647
401.600000000005,126.89049359218147,0.12791242648127688,-3.0285042463395597
402.800000000005,127.2908212889902,0.13377167565630724,-3.0540350426286693
404.000000000005,127.68446803241922,0.13560946699147328,-3.075933286941293
405.20000000000505,128.08042507405565,0.1423871286127012,-3.1008433032268017
406.4000000000051,128.4755215505912,0.14622737545011838,-3.1132230624527706
407.6000000000051,128.86958704190423,0.15101096572419714,-3.138370167380483
408.80000000000507,129.26266592305055,0.15246290054661843,-3.1595266864641673
410.0000000000051,129.65380803546904,0.15615891817602295,-3.173989465093178
411.20000000000516,130.05190369790097,0.15650703464163912,-3.1937911606558265
412.40000000000515,130.4463302641282,0.16096117766723672,-3.2115493129114507
413.60000000000514,130.84672498237316,0.16461282010259265,-3.2323926542459205
414.8000000000052,131.24065725820043,0.16525813795422142,-3.2431323402598498
416.00000000000523,131.63747950288456,0.1661028229740237,-3.258491647421386
417.2000000000052,132.03079276131328,0.16892877432664316,-3.2711244654736786
418.4000000000052,132.42571099248806,0.1708983919959125,-3.2864406241399955
419.60000000000525,132.82160278220456,0.17218979294589104,-3.296897153681308
420.8000000000053,133.21667287305834,0.1746001672938371,-3.3067010715451137
422.0000000000053,133.60951131124784,0.1752846610304656,-3.3188772527243517
423.2000000000053,134.00815350444992,0.17684510381209817,-3.334990885337574
424.4000000000053,134.40505881088478,0.17634579965162875,-3.3394848396500625
425.60000000000537,134.80368585205247,0.1782589582295455,-3.3511523772099174
426.80000000000535,135.19967002447504,0.17517364810907238,-3.3593079199263194
428.00000000000534,135.59835468361536,0.17794800438419756,-3.3641273488057397
429.2000000000054,136.00024831144685,0.17918831776137586,-3.377472017268397
430.40000000000543,136.39376006885075,0.18027613911639315,-3.3790021593051884
431.6000000000054,136.78543435403157,0.18319443865051793,-3.3888914847941765
432.8000000000054,137.1794008487448,0.18132366945764436,-3.394470452073468
434.00000000000546,137.57752321595237,0.18610485256704912,-3.4017856195458025
435.2000000000055,137.96805511960713,0.18536747985436136,-3.4070169887484694
436.4000000000055,138.36509468444757,0.18882724221150538,-3.4138531266131533
437.6000000000055,138.76268067056395,0.18757514582632462,-3.4175819530321223
438.8000000000055,139.16084991527802,0.18885933783682698,-3.4225864096694134
440.00000000000557,139.55822127622548,0.19053502107796422,-3.4254610782697954
441.20000000000556,139.95277167395878,0.19497231839219598,-3.4307907321227136
442.40000000000555,140.35611220435973,0.19511941668876173,-3.4347263302280577
443.6000000000056,140.75386147087076,0.1962247621219294,-3.434060262096246
444.80000000000564,141.15273906605177,0.20142939029120865,-3.444376367542916
446.0000000000056,141.54860134478295,0.20341176714558132,-3.4430469631175384
447.2000000000056,141.94596018183964,0.20907977551577356,-3.4480031160209874
448.40000000000566,142.34268979159992,0.21775996828395844,-3.4507303538670135
449.6000000000057,142.73957587867233,0.22567013735681607,-3.4519297735851273
450.8000000000057,143.1355340252845,0.23272405005245927,-3.456868865392969
452.0000000000057,143.5354328085753,0.23730888730816824,-3.460370479979579
453.20000000000573,143.93261864679533,0.24800728728891402,-3.459070017336788
454.4000000000058,144.32913528525395,0.2551543315676889,-3.464229013286408
455.60000000000576,144.7243398820433,0.26309311936499097,-3.4646343147799197
456.80000000000575,145.12229783886065,0.2671281104372947,-3.4694624516149766
458.0000000000058,145.51954110980728,0.27041161404164454,-3.469251637590641
459.20000000000584,145.91776605402032,0.27319425503535805,-3.471131641919082
460.40000000000583,146.31416869361428,0.2746615279830712,-3.4756743680267403
461.6000000000058,146.7150782835921,0.2789561232746833,-3.4746020869378773
462.80000000000587,147.11300631854996,0.2799862204892544,-3.4746426889795394
464.0000000000059,147.50966430510132,0.27383184874474364,-3.480005203432614
465.2000000000059,147.9067245714327,0.27455373412734346,-3.4762841148580375
466.4000000000059,148.29962629720083,0.2748079433702061,-3.4850598649984494
467.60000000000593,148.7088713674383,0.2776374354004847,-3.4845195638082664
468.800000000006,149.09856789627187,0.27870257853178365,-3.480665383512727
470.00000000000597,149.50693112527406,0.2833260969991188,-3.4871509829760887
471.20000000000596,149.90276603997074,0.2862466748681381,-3.486819843002957
472.400000000006,150.29562792534534,0.28742372108711106,-3.487479646392889
473.60000000000605,150.69396021813532,0.2896968188330636,-3.487129610407183
474.80000000000604,151.09251887636614,0.29247278654782444,-3.4890092999480613
476.000000000006,151.49199760463446,0.2953041710496117,-3.488013530472431
477.20000000000607,151.88629165491494,0.2970415173760063,-3.494694242380249
478.4000000000061,152.2881797502003,0.3007669885631528,-3.4927178217038146
479.6000000000061,152.69104196179657,0.3028652313509518,-3.494073343376175
480.8000000000061,153.09051179666832,0.30598308362437415,-3.4955290284369527
482.00000000000614,153.49276052135434,0.3081741583001082,-3.499458146521456
483.2000000000062,153.89250405284696,0.3115022232669027,-3.500927021687177
484.4000000000062,154.28960001726244,0.31644644226959184,-3.5029769124494528
485.60000000000616,154.69023767814053,0.3200065534301875,-3.5011885914941616
486.8000000000062,155.08905908812972,0.3243308309565168,-3.5049758838215785
488.00000000000625,155.48623789908305,0.3298943412540995,-3.504695488368741
489.20000000000624,155.8846475829967,0.3309921990358874,-3.503244844359906
490.40000000000623,156.28688648969816,0.33553975610247533,-3.5039379709818697
491.6000000000063,156.6895145647355,0.33487905825534436,-3.508860050733607
492.8000000000063,157.08648563348032,0.3402514881613075,-3.508414977460864
494.0000000000063,157.48513364390695,0.34261631343211046,-3.5088681223003073
495.2000000000063,157.88589827295195,0.34611679096391595,-3.5098493800139616
496.40000000000634,158.2877417928358,0.3483805546338905,-3.512154653879379
497.6000000000064,158.68912498240553,0.3530395259023599,-3.5148304229058542
498.8000000000064,159.08826321606773,0.35485912967589023,-3.5144593763226286
500.00000000000637,159.48776960846672,0.35953861124297154,-3.5160930558133505
501.2000000000064,159.88476726445077,0.3609553404428607,-3.51566900737591
502.40000000000646,160.2844476733597,0.3625843050645886,-3.517806081083779
503.60000000000645,160.68687965114654,0.3650442067630077,-3.520594317707181
504.80000000000643,161.08814067749356,0.3676670118179492,-3.519097978559454
506.0000000000065,161.48772241990872,0.3719480913704967,-3.5213758915775317
507.2000000000065,161.8866447355017,0.3751653004313856,-3.52399966330935
508.4000000000065,162.28571799951544,0.3762318334969477,-3.5210041543584927
509.6000000000065,162.68124243866498,0.38048842049457104,-3.525310133426772
510.80000000000655,163.08433375963796,0.38460774091784833,-3.5262521287431374
512.0000000000066,163.48507251202776,0.3882841810196719,-3.5224645520528384
513.2000000000066,163.88701297290808,0.38843697452929166,-3.529474777499984
514.4000000000066,164.28891487455647,0.39457484552306116,-3.530261540635954
515.6000000000066,164.68415524042274,0.39678699198559675,-3.530295419197797
516.8000000000067,165.087600929492,0.3969905394503466,-3.5316872758641793
518.0000000000066,165.48681947113653,0.39984795976119936,-3.532782486647524
519.2000000000066,165.88864919344465,0.401399583851707,-3.530859762581897
520.4000000000067,166.2938243618752,0.4076726060283126,-3.5312833124602827
521.6000000000067,166.68997993663254,0.40983969618028354,-3.530633234941872
522.8000000000068,167.094579472894,0.4130859803563544,-3.533825592572823
524.0000000000067,167.4941479782875,0.4195537159688635,-3.5368273297487964
525.2000000000068,167.89564741822923,0.4232671265815345,-3.535526862172362
526.4000000000068,168.29626814039418,0.42813189891820996,-3.5395361553155658
527.6000000000067,168.6960129350267,0.43397267280790486,-3.5382683246178814
528.8000000000068,169.0909871828204,0.4386130656121942,-3.538258859587853
530.0000000000068,169.4925656839392,0.4430224030660227,-3.5382626761495004
531.2000000000069,169.8951704893092,0.44481804508535716,-3.5431884300331653
532.4000000000069,170.2975906004016,0.4496097317815811,-3.540960923950265
533.6000000000068,170.69831272648497,0.45293489335777704,-3.539425249427075
534.8000000000069,171.1024001709174,0.4571766953385426,-3.5427760229378844
536.0000000000069,171.50359642247975,0.4622026735714021,-3.5447170769652536
537.2000000000069,171.90175375629195,0.4646355295675745,-3.542133273583416
538.4000000000069,172.303440614754,0.4688278920543984,-3.545170015807917
539.600000000007,172.70587128134997,0.4741410817681699,-3.5478167391066244
540.800000000007,173.09960907198064,0.47728816674924607,-3.5451698410667856
542.000000000007,173.49927981541393,0.4854134369266191,-3.54649289560685
543.200000000007,173.9019956500957,0.48940883136611246,-3.5491388897582956
544.400000000007,174.29354946837782,0.49435254863035893,-3.5467845353270064
545.6000000000071,174.70164301481276,0.5031818464924865,-3.5514075099111313
546.800000000007,175.10836097146273,0.5120359269288103,-3.551078519073347
548.000000000007,175.5045086095012,0.521562300119773,-3.5509699520865787
549.2000000000071,175.9041846685952,0.533299700915792,-3.5520538365186973
550.4000000000071,176.3061853125919,0.5439581382045905,-3.551969957798975
551.6000000000072,176.7098620527873,0.559960980571701,-3.556263744943273
552.8000000000071,177.10563327396295,0.5811982846053705,-3.5549884919677175
554.0000000000072,177.50694022804623,0.5985550299733842,-3.55882721988098
555.2000000000072,177.90778405616913,0.6062661153594462,-3.559531386863819
556.4000000000071,178.31005745712494,0.6103164836547456,-3.560424063801392
557.6000000000072,178.7133380628512,0.6141494324509498,-3.5621895449607317
558.8000000000072,179.116997425204,0.6133745801401518,-3.564480232058395
560.0000000000073,179.517020193146,0.6132679054784712,-3.5670062617105147
561.2000000000073,179.91586250143655,0.6144314963899,-3.567384688352726
562.4000000000073,180.3199528873734,0.6123211620939344,-3.56809976457496
563.6000000000073,180.71908785218994,0.6108964053195646,-3.5688528469385354
564.8000000000073,181.1210821167429,0.6102950797053648,-3.5688081991024285
566.0000000000073,181.53096146302133,0.6079635317639016,-3.5737694943294516
567.2000000000073,181.93502118039453,0.5983624920691031,-3.568564181947211
568.4000000000074,182.33638013356708,0.598305491319653,-3.5704008391115467
569.6000000000074,182.74002656335816,0.5971222927419747,-3.572345198560992
570.8000000000075,183.14515574617582,0.597866656944854,-3.5750315628669123
572.0000000000074,183.54731571888962,0.6056361303119913,-3.5788400167290835
573.2000000000074,183.9429770685516,0.6085422215156591,-3.5711782635272273
574.4000000000075,184.34359415079524,0.615621062240701,-3.5785099885901483
575.6000000000074,184.75000699778158,0.6230504753042704,-3.577554696306369
576.8000000000075,185.1554450820378,0.6302795298525474,-3.5766624797743125
578.0000000000075,185.5573308338856,0.6352914338002361,-3.5773014258740212
579.2000000000075,185.95879342173086,0.6420163897369435,-3.580389913601225
580.4000000000076,186.36095783399222,0.6481529363448784,-3.58034489040224
581.6000000000075,186.76391673826888,0.6553776062409279,-3.5803800926044773
582.8000000000076,187.16442682958714,0.6606832835334413,-3.580334188316806
584.0000000000076,187.56167755987036,0.6655796124695623,-3.5830221348895304
585.2000000000075,187.96666668962166,0.673529945722778,-3.5834298967076363
586.4000000000076,188.37102214896865,0.6802465684749596,-3.5849887484634095
587.6000000000076,188.77298752117184,0.6860488907866947,-3.5825116880056047
588.8000000000077,189.172935717815,0.6922443789967541,-3.585427319234254
590.0000000000077,189.5764090084561,0.6982192061433521,-3.5838782680029193
591.2000000000077,189.97812714871185,0.7084626061562549,-3.5881271477259093
592.4000000000077,190.37684055732115,0.7133869262289301,-3.584668265666811
593.6000000000078,190.7790229140388,0.7204515772861733,-3.584649483314254
594.8000000000077,191.18592730414505,0.7238146142955865,-3.5873995684648943
596.0000000000077,191.59623203538428,0.7284091948643722,-3.588428189208634
597.2000000000078,192.00280303207953,0.7347753582976707,-3.5907043948084567
598.4000000000078,192.4038680150261,0.7403369717906817,-3.5867639264266353
599.6000000000079,192.8093822887195,0.7489846957526513,-3.589296825258144
600.8000000000078,193.21308100082442,0.7550071019119123,-3.5878891194158635
602.0000000000078,193.61198448162355,0.7632666852505481,-3.591915408887636
603.2000000000079,194.01603395437334,0.7665193406436823,-3.592526884995735
604.4000000000078,194.41284818538062,0.7747473019356949,-3.5932475929264385
605.6000000000079,194.81629877889722,0.7814003881915835,-3.59199981176355
606.8000000000079,195.22174937685676,0.7867680731643161,-3.5921900214590123
608.000000000008,195.62288388530354,0.7945629845262492,-3.591296517351884
609.200000000008,196.02694134696299,0.7991150261619825,-3.593751081106662
610.4000000000079,196.43608352024057,0.8073790567459034,-3.5952848587497312
611.600000000008,196.8365355148704,0.810316353657238,-3.5923523948827305
612.800000000008,197.2375370700851,0.8189526117560423,-3.5970583544625545
614.000000000008,197.6409591262575,0.8240488332910919,-3.593014256000505
615.200000000008,198.04544469051675,0.8294371130657604,-3.5927905612295876
616.400000000008,198.44999314867025,0.8342797413712852,-3.5973782528467346
617.6000000000081,198.85757672149856,0.8393169104052846,-3.5970980675020905
618.8000000000081,199.26263150137535,0.8458090663042674,-3.59573598428388
620.0000000000081,199.66518075630987,0.8504476075140294,-3.5996822526663417
621.2000000000081,200.0680619745835,0.8592064740915135,-3.59803988060075
622.4000000000082,200.47332380305747,0.8644240132469277,-3.5995600177724913
623.6000000000081,200.86438566428723,0.8751067445195455,-3.60101006019719
624.8000000000081,201.27912486515967,0.8793376456347647,-3.597416830195376
626.0000000000082,201.68553567329516,0.8844537835911666,-3.602818213204334
627.2000000000082,202.09223010391096,0.8902326172605156,-3.600129925001425
628.4000000000083,202.493210142162,0.8971123083439148,-3.600259458456183
629.6000000000082,202.90035325189413,0.9031625893290341,-3.601550215917624
630.8000000000083,203.30354254943353,0.9068502805686208,-3.6015538859766867
632.0000000000083,203.7063557036428,0.9135922760091316,-3.6021945957189194
633.2000000000082,204.10957549760144,0.9193905507269265,-3.600238692450084
634.4000000000083,204.50924822665692,0.9228742880019751,-3.6028572659973954
635.6000000000083,204.91559006718563,0.9333885071761613,-3.6011890153091457
636.8000000000084,205.3217833404691,0.9394249203684476,-3.603102900225951
638.0000000000084,205.72146935215298,0.9471584938699057,-3.602758178967532
639.2000000000083,206.1265995507663,0.9512922902116627,-3.605060199605008
640.4000000000084,206.5297177108985,0.9567176950045931,-3.6037502020118275
641.6000000000084,206.93719701850026,0.9609683821780873,-3.607682253275099
642.8000000000084,207.34012198429105,0.9668183378670172,-3.6029522236480624
644.0000000000084,207.7427392831728,0.9735428824910489,-3.607085757827499
645.2000000000085,208.1418083871152,0.9815625748122138,-3.6045814538513667
646.4000000000085,208.5482834289984,0.9830672664344389,-3.6036268189424043
647.6000000000085,208.95316039294897,0.9906904205068389,-3.6106619972461296
648.8000000000085,209.36043411614344,1.0003639859688263,-3.607041238777613
650.0000000000085,209.7669978892749,1.004139132522011,-3.608789982281041
651.2000000000086,210.1694894674945,1.0103940027533722,-3.6060710678074894
652.4000000000085,210.56868237614358,1.014566344785836,-3.608066008783402
653.6000000000085,210.97393435978282,1.0213190042881888,-3.6092109962471755
654.8000000000086,211.38020199628613,1.0268449518089393,-3.610539971593326
656.0000000000086,211.7851881452564,1.0332429119008817,-3.6089055893123163
657.2000000000087,212.19012707757255,1.0405515980650146,-3.6132884160414585
658.4000000000086,212.5920127243337,1.0458966265587846,-3.6129857452949503
659.6000000000087,213.00033682167276,1.0528414660954961,-3.613793341734019
660.8000000000087,213.40065614050437,1.0618712203762968,-3.6102124277766188
662.0000000000086,213.8050000981245,1.0660236969711363,-3.6128151849842
663.2000000000087,214.2076409424028,1.0720214363216287,-3.612157495847609
664.4000000000087,214.60662902375867,1.0808982993380145,-3.6140825447912013
665.6000000000088,215.01318434311312,1.0871605509846414,-3.614997861562075
666.8000000000088,215.4225738652709,1.0941138939488089,-3.6138933332454615
668.0000000000088,215.82881490619064,1.1010249841430275,-3.615511211059201
669.2000000000088,216.23262540848026,1.1071907200849278,-3.6137701194986844
670.4000000000088,216.63332268485524,1.1164997541962267,-3.6197544247726716
671.6000000000088,217.04278001156285,1.1179555524902622,-3.613424689009257
672.8000000000088,217.44735780590707,1.1247427109430066,-3.6170028155358978
674.0000000000089,217.8524836176938,1.1325249125322292,-3.6172797756663075
675.2000000000089,218.2565752936636,1.141882809888734,-3.61563957411751
676.400000000009,218.65453234997355,1.1459784994901272,-3.621619279990649
677.6000000000089,219.06156147534566,1.155743797471327,-3.6200642324296695
678.8000000000089,219.4655280338182,1.1613155130714576,-3.6153749631572842
680.000000000009,219.8718784987428,1.16698827862603,-3.6191230808505215
681.2000000000089,220.27977424856746,1.1719209845676974,-3.6189322304124496
682.400000000009,220.68518566764416,1.1784451646543905,-3.6162168016534375
683.600000000009,221.0822578009482,1.187661564518133,-3.621239971722912
684.800000000009,221.49082881732815,1.1965156478991177,-3.6192491989518065
686.0000000000091,221.8960605470364,1.203805784475873,-3.6212984261347634
687.200000000009,222.2987786889861,1.2125681683017706,-3.6240039810437077
688.4000000000091,222.69852571549166,1.2182410817682288,-3.6201419455641144
689.6000000000091,223.10698624075974,1.2263012449573625,-3.6214253265482683
690.800000000009,223.51152871124384,1.2358144239799609,-3.6227948021960032
692.0000000000091,223.91453472115558,1.2433788420700547,-3.6221433281983364
693.2000000000091,224.31984721929368,1.2515096850754293,-3.621309276656186
694.4000000000092,224.7257238586068,1.2555717855922401,-3.624051043338834
695.6000000000092,225.1333372549807,1.2637288386343153,-3.6239619417011175
696.8000000000092,225.53735471763554,1.271491342361748,-3.6214161300676677
698.0000000000092,225.94004306252637,1.2805901272965587,-3.6228305824015745
699.2000000000093,226.3435346162899,1.2870813987546872,-3.624140300655859
700.4000000000092,226.75107086267008,1.2972731439155805,-3.626449960907119
701.6000000000092,227.15372047997846,1.303619317236869,-3.625128684792135
702.8000000000093,227.55670455625574,1.3128829740788737,-3.6277777693723636
704.0000000000093,227.96558528065242,1.3191050500217198,-3.6255694471042315
705.2000000000094,228.37430057097004,1.3246009167968427,-3.625240157221502
706.4000000000093,228.7793760451823,1.3312549212637326,-3.628263347508005
707.6000000000093,229.18294965732656,1.3421403372743468,-3.62458114135228
708.8000000000094,229.5862069154623,1.3439151632035615,-3.627581542605034
710.0000000000093,229.99410242419543,1.3533585295054142,-3.6255438135187275
711.2000000000094,230.39910312180507,1.3606965101702164,-3.6254696175280063
712.4000000000094,230.80184954949962,1.368966836317694,-3.6288400997868386
713.6000000000095,231.20984062614485,1.3763534442531573,-3.6305396299803943
714.8000000000095,231.61498861028775,1.38342270746651,-3.6273054064267485
716.0000000000094,232.01571598077635,1.3930533402680005,-3.632534286074919
717.2000000000095,232.41924895040648,1.3985389579077963,-3.631494715857996
718.4000000000095,232.82613099886447,1.4064134748477852,-3.630497345427906
719.6000000000095,233.23631867772414,1.4163427538436717,-3.6301789638211233
720.8000000000095,233.64279069194984,1.4247438149242544,-3.630171719889704
722.0000000000095,234.0435586657159,1.4316900901435623,-3.631496904308685
723.2000000000096,234.45221534263118,1.4434759194663556,-3.6328098369119926
724.4000000000096,234.85779039490114,1.448937175916825,-3.6298716252996694
725.6000000000096,235.26238354152528,1.4550126905986067,-3.6328803163503336
726.8000000000096,235.66888217973488,1.4637288208767816,-3.632407890042329
728.0000000000097,236.0750170818094,1.4722088275046699,-3.6308331683371415
729.2000000000096,236.48231442356405,1.4839699688358616,-3.633459915430517
730.4000000000096,236.8927063597225,1.4893087967455785,-3.6318261297965515
731.6000000000097,237.29709006572264,1.4997339386124247,-3.633003366135857
732.8000000000097,237.70511217082625,1.506916712824276,-3.633982721225215
734.0000000000098,238.10685253079197,1.5202458993359882,-3.6346836450356017
735.2000000000097,238.515344656033,1.5286019643158322,-3.635660618033027
736.4000000000098,238.9211260575598,1.5340640165793598,-3.631281533043542
737.6000000000098,239.3235278371749,1.5425841329833083,-3.6375872883862783
738.8000000000097,239.73076031174202,1.548415518584698,-3.629326164919152
740.0000000000098,240.1366986109008,1.5586895425752345,-3.635205867130968
741.2000000000098,240.53871558291223,1.5684873505966774,-3.632658293388795
742.4000000000099,240.9459225597688,1.5822868150761318,-3.6367260190551036
743.6000000000099,241.35154360200167,1.5865840847139667,-3.6355531689735043
744.8000000000098,241.75688018794054,1.5984633150979808,-3.6381760951423057
746.0000000000099,242.16483921436995,1.6073653783702972,-3.635426472587799
747.2000000000099,242.5683391163291,1.618524361573628,-3.6370829277307157
748.4000000000099,242.97474497352562,1.6273031803636466,-3.6377423835060663
749.6000000000099,243.3806138594928,1.634281573637198,-3.6396993422106494
750.80000000001,243.7930482379466,1.644282881173482,-3.634389763139156
752.00000000001,244.20354802664465,1.6517534229354687,-3.6367086747625503
753.20000000001,244.60475235941576,1.6599119298741867,-3.6392778964172354
754.40000000001,245.00432127450367,1.6733479490678551,-3.6414895649014576
755.60000000001,245.4118236154141,1.6851903222063527,-3.6362811025036517
756.8000000000101,245.81596453833484,1.6943992374347427,-3.6374237408277184
758.00000000001,246.21952050120063,1.7056762672025068,-3.640432094667154
759.20000000001,246.62931664010543,1.7150343729585813,-3.640665900181536
760.4000000000101,247.03385799602785,1.7262426226693703,-3.6405614472719687
761.6000000000101,247.43939220239156,1.7374482846575352,-3.638289875532633
762.8000000000102,247.84784946879066,1.7473140612306832,-3.6422597885196804
764.0000000000101,248.2541083275965,1.7564219987420673,-3.639538348018395
765.2000000000102,248.66018870662313,1.7664611612573253,-3.6371036683194338
766.4000000000102,249.06822203585992,1.7759671329554991,-3.6447205629300545
767.6000000000101,249.47593998226117,1.785469360455688,-3.6392179309675527
768.8000000000102,249.8802402582363,1.8005177424194712,-3.6433399767295174
770.0000000000102,250.28563686893892,1.8117044118124404,-3.6431990036121036
771.2000000000103,250.69151105884185,1.8195597589136623,-3.6414329652065414
772.4000000000103,251.09891320307906,1.8331350687480608,-3.6403139741200827
773.6000000000103,251.50546451177712,1.8414610091386239,-3.6416991444380202
774.8000000000103,251.91110815275098,1.8526722316314699,-3.6420259092752207
776.0000000000103,252.32403767958016,1.8624236307995201,-3.641091046258935
777.2000000000103,252.725265153452,1.8757555656114542,-3.6426186003476424
778.4000000000103,253.13047461724358,1.88926184002524,-3.6412319786646257
779.6000000000104,253.54171775975772,1.8995779120212606,-3.642391992064161
780.8000000000104,253.94372580507587,1.910179911931935,-3.6419166651227695
782.0000000000105,254.35372859553593,1.921934658030819,-3.6437935439603018
783.2000000000104,254.76257030032355,1.929073728431938,-3.646615460789845
784.4000000000104,255.17196800336458,1.943035437111926,-3.6463456567777293
785.6000000000105,255.5789504627504,1.9515038629035124,-3.6426737696498543
786.8000000000104,255.98597644054072,1.9629143822018262,-3.6427027246778287
788.0000000000105,256.39095119173913,1.9721980629669766,-3.6453197007248286
789.2000000000105,256.797464470358,1.987579921304823,-3.6453148192513765
790.4000000000106,257.20479547135864,2.0027002211987024,-3.64510137317605
791.6000000000106,257.60857648660993,2.011731543422518,-3.6451345173094207
792.8000000000105,258.0175420539388,2.023998193443147,-3.6437683881411864
794.0000000000106,258.4240244933133,2.037001030374058,-3.6466858223970027
795.2000000000106,258.8305717691282,2.046201779203697,-3.6449080488630585
796.4000000000106,259.23768617608937,2.060164607192427,-3.6474840476046926
797.6000000000106,259.6500065369426,2.0739112036654523,-3.647849923987039
798.0000000000107,259.7861131827485,2.0751699553567624,-3.648949829228452