File: 01_Data/Polyester_Carpet_High_Pile/STA/N2/30K_min/Polyester_Carpet_High_Pile_STA_N2_30KData_230926_R3.csv
##Temp./Â°C,Time/min,DSC/(mW/mg),Mass loss/mg
51.0,10.599310281080315,-2.268017566148243,0.024694438389337492
52.20000000000002,10.783038639549883,-2.242067693159596,0.025426126797025717
53.400000000000034,10.907901636693213,-2.220063326346147,0.026477599827350318
54.60000000000005,11.006643203638074,-2.2016271998872186,0.027347253239518032
55.80000000000007,11.090581055094322,-2.1858252074706357,0.02534265585190898
57.000000000000085,11.169115149111803,-2.1719319462042663,0.024959721807357838
58.2000000000001,11.240549355715912,-2.156466181574024,0.02600522979407316
59.40000000000012,11.305666271120492,-2.144399508559291,0.025475684886053784
60.600000000000136,11.367265604058797,-2.132044096527963,0.027621328903745024
61.80000000000015,11.426322742602448,-2.1186198057884638,0.02588929108054039
63.00000000000017,11.482249127288476,-2.106322771394696,0.027666659298392737
64.20000000000019,11.537766259981268,-2.0946623337755508,0.026459492249764516
65.4000000000002,11.58973562880785,-2.0838016325375426,0.025269075143650177
66.60000000000022,11.641459761409857,-2.072836695367423,0.024322943674751407
67.80000000000024,11.692055124092937,-2.0625406858217357,0.025611617151350075
69.00000000000026,11.740517029886364,-2.0509933980810953,0.026495949844052014
70.20000000000027,11.788993758308322,-2.042945034949601,0.026261974011724476
71.40000000000029,11.83673781470256,-2.0342419390671456,0.026164777547855067
72.6000000000003,11.883771013148317,-2.0265319866474942,0.025917626341205313
73.80000000000032,11.929961081136172,-2.0183737485988944,0.026642366962351005
75.00000000000034,11.97512137104243,-2.012493359822201,0.026056378410411973
76.20000000000036,12.02014625714434,-2.0049323596670554,0.026166321399942127
77.40000000000038,12.064810824186653,-1.9972364972437229,0.026316089826221578
78.60000000000039,12.108981368294103,-1.9911354326912052,0.02627015880448713
79.80000000000041,12.15243366994881,-1.982768384837446,0.028110570939199775
81.00000000000043,12.196350762173633,-1.972635390838823,0.028600054622072157
82.20000000000044,12.238965584492776,-1.9587898458819208,0.026724467425552234
83.40000000000046,12.281306416389457,-1.947015737761545,0.02651529898850402
84.60000000000048,12.323537461297299,-1.9305645534540408,0.02650619019573952
85.8000000000005,12.365788840077512,-1.9168278509835217,0.026436283960291185
87.00000000000051,12.407835874058284,-1.9049157949161781,0.02646907387771691
88.20000000000053,12.449231587736296,-1.8936498476456172,0.026043177488662472
89.40000000000055,12.490517210769113,-1.8815608997614268,0.026388652670582324
90.60000000000056,12.532047523973105,-1.8689676933061723,0.026322534871160208
91.80000000000058,12.572980163395437,-1.8595826706686016,0.026420050098979964
93.0000000000006,12.614409202448355,-1.850125721511842,0.02733668156479041
94.20000000000061,12.654522482707327,-1.8412338116594107,0.026346633522589258
95.40000000000063,12.695237404784626,-1.8310221660153854,0.026367267146850004
96.60000000000065,12.735876404470336,-1.8232249180760378,0.026408603034499656
97.80000000000067,12.776219661568147,-1.8152424271999883,0.02671449272420645
99.00000000000068,12.816535294976724,-1.8075411609999945,0.026352723255929078
100.2000000000007,12.856825015222956,-1.8013347742870152,0.02603104906794229
101.40000000000072,12.897098870431304,-1.793172971641975,0.026345954868666865
102.60000000000073,12.937234487597614,-1.7882175064979113,0.02633461395440495
103.80000000000075,12.977618639970098,-1.7824166844119158,0.026228289381950987
105.00000000000077,13.017163488165082,-1.7758538011857892,0.026341226622680125
106.20000000000078,13.057431806994336,-1.7715022660863664,0.026003693730249466
107.4000000000008,13.09758852819849,-1.7656277059225813,0.026342769518350906
108.60000000000082,13.137406456625804,-1.7608554553110838,0.025023369376643068
109.80000000000084,13.17737391825745,-1.7545967379691594,0.026235851350901562
111.00000000000085,13.21687650576164,-1.7506799617077866,0.026349604308119723
112.20000000000087,13.256983103579795,-1.7473581404422105,0.026350286931446476
113.40000000000089,13.296933965205595,-1.7424340231759197,0.025948984002713615
114.6000000000009,13.336685997274207,-1.738858502866165,0.025024299571775543
115.80000000000092,13.376599571367347,-1.7351661311990656,0.026302153971097475
117.00000000000094,13.416036067568719,-1.7298824465420646,0.025717052735050316
118.20000000000095,13.45587933194269,-1.7290362469501959,0.025576543206671687
119.40000000000097,13.495230984632377,-1.7242801346080454,0.026344417037978296
120.60000000000099,13.535288063909135,-1.720675620413766,0.025039733049896817
121.800000000001,13.5742839286889,-1.7166306919861518,0.025030236735923417
123.00000000000102,13.613661849558932,-1.7114616810305847,0.025030762362951542
124.20000000000104,13.65269880285446,-1.7083873846770832,0.025139142662437663
125.40000000000106,13.691908562887981,-1.7048982879483894,0.02539239819677075
126.60000000000107,13.731740717692526,-1.7020601337805952,0.02536025691619237
127.80000000000109,13.770384717538672,-1.699406433694747,0.025360091719739408
129.0000000000011,13.810188006987996,-1.6963297462095714,0.02536014991809754
130.20000000000113,13.849074064695635,-1.692797368161448,0.025314271565430424
131.40000000000114,13.888365214388248,-1.689690125799495,0.026679233205905817
132.60000000000116,13.926180401230484,-1.6863548204789933,0.0266748306798279
133.80000000000118,13.965766870063419,-1.6836455847941423,0.02634942877018087
135.0000000000012,14.003741216986173,-1.6803914066470091,0.026363609516534936
136.2000000000012,14.043183676842398,-1.6785577548048676,0.02537343748938614
137.40000000000123,14.081909505143539,-1.6760765612468114,0.026748058247694217
138.60000000000124,14.12016365805231,-1.6748249026239703,0.026670169511240793
139.80000000000126,14.1593208168193,-1.673332339443944,0.02667012387737344
141.00000000000128,14.197848838655176,-1.6707624592643877,0.026670125069057526
142.2000000000013,14.235985532896448,-1.6701968040650041,0.026670100362852445
143.4000000000013,14.274541287492358,-1.6684098390439306,0.02666094311880407
144.60000000000133,14.31268806475698,-1.6680589110739674,0.026348912682344405
145.80000000000135,14.350523157104007,-1.6692031438012118,0.026340075508271887
147.00000000000136,14.389262410584715,-1.6698651743010908,0.026330509874872732
148.20000000000138,14.427230191216086,-1.668840117167356,0.0250205636913714
149.4000000000014,14.465373193868981,-1.6731392822471705,0.02502016399264395
150.60000000000142,14.503703677995885,-1.67698088236492,0.025020143296754505
151.80000000000143,14.541598599659244,-1.6826029284142945,0.025022856552721073
153.00000000000145,14.579967062689697,-1.6894243190105103,0.024218227495316214
154.20000000000147,14.61823894117144,-1.6989934619813112,0.023709905827285382
155.40000000000148,14.656564501082311,-1.7092802574374337,0.02371011327735406
156.6000000000015,14.69426736015307,-1.721044400288497,0.023709700798064226
157.80000000000152,14.732432201571488,-1.7337506809527623,0.023663581644827403
159.00000000000153,14.77070070837771,-1.7472075301120475,0.025029288737596467
160.20000000000155,14.808616335423935,-1.76446156444781,0.02498786260821273
161.40000000000157,14.846838432159322,-1.778224809837975,0.026338479400060066
162.6000000000016,14.884776640601034,-1.7907352137501427,0.026339926484232556
163.8000000000016,14.922613191665638,-1.7977805385287826,0.02633130790881566
165.00000000000162,14.960128589279345,-1.7932500836864915,0.025033381404849564
166.20000000000164,14.997443347140408,-1.781132281482098,0.026351750151230924
167.40000000000165,15.03488098389737,-1.7628784192116682,0.02634921529214651
168.60000000000167,15.071317614924915,-1.7397808213130188,0.026320237381672662
169.8000000000017,15.109572739753864,-1.7153662652681183,0.02406770471782327
171.0000000000017,15.146706087691294,-1.693543173219706,0.02370239129741858
172.20000000000172,15.183936456404886,-1.6742432177846496,0.024935621936114316
173.40000000000174,15.221508185769785,-1.6557478960572527,0.025029860657816982
174.60000000000176,15.258448773978255,-1.6429341612699688,0.025029927574444777
175.80000000000177,15.29500298398338,-1.6312270877248225,0.025029927010094433
177.0000000000018,15.332022125014813,-1.6225159910928701,0.0250299269918397
178.2000000000018,15.369476604302514,-1.611966854047575,0.02502992659500336
179.40000000000182,15.406942298160228,-1.6031330136865942,0.02503003654901459
180.60000000000184,15.444335259808968,-1.59638092382842,0.025057437663366322
181.80000000000186,15.480742602446336,-1.5919084189988313,0.02599302805805781
183.00000000000188,15.518301674856788,-1.5875450912939182,0.026020003854365648
184.2000000000019,15.554995729007173,-1.5844599718960828,0.026019801575307255
185.4000000000019,15.592208942736445,-1.5803773685148816,0.026008949312221752
186.60000000000193,15.62914199183127,-1.5778433976444697,0.024704398699741503
187.80000000000194,15.665958408927091,-1.5743776610663833,0.02470013697302509
189.00000000000196,15.702450629453025,-1.571588663917077,0.024700026618040383
190.20000000000198,15.739554705611255,-1.5696364708732975,0.024700025999000452
191.400000000002,15.776546762325674,-1.568886193459412,0.024700025882447463
192.600000000002,15.813154163750626,-1.566148354108753,0.024700009854549343
193.80000000000203,15.849819683319854,-1.5633649483865528,0.02469985683924758
195.00000000000205,15.887045915560629,-1.5631176829808022,0.025154340505540773
196.20000000000206,15.923385608959759,-1.5607369812303653,0.024721653087460993
197.40000000000208,15.959719345713637,-1.5596394554731325,0.023375754608435884
198.6000000000021,15.996943826126401,-1.5591058603241517,0.023379725115040273
199.80000000000211,16.033174403227648,-1.5578315936273306,0.023380023423844598
201.00000000000213,16.06975629735914,-1.5568991548309392,0.023380026001926346
202.20000000000215,16.106628161869892,-1.5557076224527058,0.023380026000186405
203.40000000000217,16.14314642517503,-1.5538835728862714,0.023380026003198218
204.60000000000218,16.179814070356965,-1.5535621500574341,0.023380026187179936
205.8000000000022,16.216536394691463,-1.5539410817374992,0.02337999931111856
207.00000000000222,16.252970454849105,-1.553562701597813,0.02337381436635777
208.20000000000223,16.289550185989754,-1.5534976781710232,0.024475268664197358
209.40000000000225,16.32596987142239,-1.552657412844112,0.02470025985240376
210.60000000000227,16.362903179081375,-1.5512762502285706,0.024700246672511028
211.80000000000229,16.399097485851268,-1.5522376183813504,0.024708065964642145
213.0000000000023,16.435730096546756,-1.5532593478062304,0.023352525962287984
214.20000000000232,16.47227971620476,-1.5543095997227008,0.023379740804453597
215.40000000000234,16.509144385282234,-1.5543098039598868,0.02338002582984977
216.60000000000235,16.545156601507518,-1.5559246320060274,0.02338002601914191
217.80000000000237,16.581403762382102,-1.5559933323967083,0.023380026000137555
219.0000000000024,16.61806909262848,-1.5583511776689507,0.023380025999999
220.2000000000024,16.654637238761417,-1.5593075624503592,0.023380025999999887
221.40000000000242,16.690914529260453,-1.5615360671674066,0.023380025999999887
222.60000000000244,16.727668804115837,-1.5647015507192965,0.023380025999999
223.80000000000246,16.763864262838254,-1.5676426122398643,0.023380025999917287
225.00000000000247,16.800246656234318,-1.5726075197488916,0.023380025999177434
226.2000000000025,16.83667049524876,-1.5748614703908395,0.023380027054524355
227.4000000000025,16.87334894517071,-1.5813302107108713,0.023380162576954966
228.60000000000252,16.909544445005906,-1.5864643224045545,0.023377370106704376
229.80000000000254,16.945946640985394,-1.590427205297359,0.022852959624611202
231.00000000000256,16.98253851830673,-1.598812267367878,0.02272072682541726
232.20000000000258,17.01885339098023,-1.6071813898157963,0.02271004806634469
233.4000000000026,17.055563638683147,-1.6151259652851657,0.022068961325077296
234.6000000000026,17.09199312897961,-1.6263339798968688,0.02335483275533523
235.80000000000263,17.12825031381863,-1.637389297613387,0.023380106850304117
237.00000000000264,17.16492021789118,-1.6519701042872477,0.022358163894066863
238.20000000000266,17.201443470027787,-1.6699881140278114,0.021399910164758396
239.40000000000268,17.238070960894444,-1.6919394990824481,0.02140135058512005
240.6000000000027,17.274704575753756,-1.7196091913805058,0.020888049554223187
241.8000000000027,17.31140217614015,-1.7538172183852063,0.02075030741381223
243.00000000000273,17.3484365429661,-1.79960579290914,0.02074335202673705
244.20000000000275,17.385507459048334,-1.85771096679166,0.02191980123469328
245.40000000000276,17.42283637552176,-1.9277497042000638,0.022070091964386584
246.60000000000278,17.46018964202959,-2.0065164133141025,0.02207001446191814
247.8000000000028,17.497379543970652,-2.081902489178529,0.02207110754015762
249.0000000000028,17.534157686761894,-2.140498876716252,0.021565543852034352
250.20000000000283,17.571487853255054,-2.1679171115303895,0.020274318245292022
251.40000000000285,17.607604265981,-2.162178185880482,0.0194270395439764
252.60000000000286,17.643554818794925,-2.124145254172219,0.019429538986488026
253.80000000000288,17.67889812903845,-2.0695180005606613,0.019365556261262462
255.0000000000029,17.714515105908163,-2.0034839387979777,0.020726580576991616
256.2000000000029,17.749359375432885,-1.9387179894513134,0.021379905557546763
257.40000000000293,17.78529858785281,-1.8762412094448406,0.021408583567851913
258.600000000003,17.820312266353397,-1.820688126210276,0.021409836428442297
259.80000000000297,17.856014879587384,-1.7715848147420556,0.021410106864972356
261.00000000000296,17.89157616502268,-1.728687349336868,0.021425074620295526
262.200000000003,17.927352143868056,-1.6933999040214063,0.02006344438088359
263.40000000000305,17.963162226508523,-1.6654680955798902,0.020086659947903485
264.60000000000304,17.998953386957137,-1.6418762890852452,0.020711481955599353
265.800000000003,18.034637182425463,-1.6231296064166971,0.01951067359270109
267.00000000000307,18.070631322475787,-1.608830158735421,0.0194300891082424
268.2000000000031,18.105984332233938,-1.5948029286443846,0.019430031858981067
269.4000000000031,18.142532004045655,-1.587883758655522,0.019429883228825773
270.6000000000031,18.178560094400904,-1.5810190042753556,0.01944047293943818
271.80000000000314,18.214628245861487,-1.5762863689300903,0.018456505879594687
273.0000000000032,18.25056608384312,-1.5719701202782037,0.018439831547128804
274.2000000000032,18.28661890323599,-1.5695027383942828,0.01843980356846142
275.40000000000316,18.322988264195146,-1.5671289834543234,0.018439765388228224
276.6000000000032,18.35889767726603,-1.5649610281828146,0.018440612090450337
277.80000000000325,18.395024746200207,-1.5663491101989504,0.01830730535541214
279.00000000000324,18.43141586246447,-1.5628760406586155,0.018755120020607308
280.20000000000323,18.466838346712134,-1.5641771865291725,0.017467636959792365
281.4000000000033,18.50384293905786,-1.5638928816439481,0.017448345660297626
282.6000000000033,18.539969680571676,-1.5645956728485495,0.01722220817745601
283.8000000000033,18.576120725727286,-1.5657435638163442,0.016140346513880743
285.0000000000033,18.61273167596122,-1.5682206392467244,0.01613281472436867
286.20000000000334,18.648286399272653,-1.5671142618799312,0.015350774176293491
287.4000000000034,18.68504757894573,-1.5704155528180677,0.016134200268626664
288.6000000000034,18.721268646300107,-1.5728427156153835,0.01612863607326176
289.80000000000337,18.757611173542294,-1.5740341779040363,0.016095216230848308
291.0000000000034,18.793742154700297,-1.5754240737212795,0.01482134333757923
292.20000000000346,18.82997006465539,-1.576469420159295,0.014820117774029917
293.40000000000344,18.86620442388802,-1.5757623311287312,0.01382841908271093
294.60000000000343,18.902648273785427,-1.5791440287964509,0.013501808960731942
295.8000000000035,18.939095743914393,-1.5840212562963505,0.013503752378210443
297.0000000000035,18.97531725447785,-1.5860642143556087,0.012202265002157375
298.2000000000035,19.011695349658062,-1.5880242463770846,0.012179750714510718
299.4000000000035,19.04801061525238,-1.5923693098881933,0.012169200667495161
300.60000000000355,19.084444597697708,-1.5956123067386607,0.013519987642415465
301.8000000000036,19.12067887653763,-1.5989598383425265,0.012782947403850109
303.0000000000036,19.157056285066048,-1.6006453689049494,0.012178002187204662
304.20000000000357,19.19334680903048,-1.6015520535129264,0.012180147017717857
305.4000000000036,19.22990974176041,-1.6066247447969033,0.0121801683441225
306.60000000000366,19.265922235479888,-1.6073924198739529,0.012189122521565565
307.80000000000365,19.30250324901269,-1.6105196331648122,0.01088158023444219
309.00000000000364,19.338768602703457,-1.6135148203978318,0.010850827729753654
310.2000000000037,19.37503450875255,-1.6139216236145053,0.009552401443869485
311.40000000000373,19.411676039944844,-1.6198496980502617,0.008231624850950858
312.6000000000037,19.447583753525688,-1.6234732012863213,0.0082298901021991
313.8000000000037,19.484199283872364,-1.6268799224680328,0.008395968777966445
315.00000000000375,19.520671397027126,-1.6309492172235234,0.009545276874050046
316.2000000000038,19.55730532751886,-1.636804057163991,0.008345992631714871
317.4000000000038,19.593814123320808,-1.640302578483361,0.008230873620830081
318.6000000000038,19.63051219100694,-1.6471087663027295,0.008230137826207518
319.8000000000038,19.66667092527606,-1.6466253284159826,0.007847969746369365
321.00000000000387,19.703086421182597,-1.6541410143777933,0.006908555009872863
322.20000000000385,19.73975018089609,-1.6628988311205997,0.006270843602191434
323.40000000000384,19.77598886535591,-1.6685811256187157,0.0055942524806251726
324.6000000000039,19.812838037373957,-1.6763681367897572,0.004406669909689853
325.80000000000393,19.84957622226488,-1.682371180177939,0.005383515452175303
327.0000000000039,19.8861649543069,-1.688965282758703,0.004208788100619643
328.2000000000039,19.922470456304264,-1.6938770664369476,0.004276672165426376
329.40000000000396,19.95918993444384,-1.700161858887871,0.0029490135307206344
330.600000000004,19.99554924343814,-1.7058435101173637,0.0016465323067906823
331.800000000004,20.03240218525749,-1.7112622175554855,0.0007808692833934927
333.000000000004,20.06936936569107,-1.7184502674107938,-0.00028552385330282704
334.200000000004,20.10586963060352,-1.7250711790959767,-0.0017189813674800547
335.40000000000407,20.14246272569528,-1.731415853995473,-0.003214115816927432
336.60000000000406,20.179059918237858,-1.7374035900514646,-0.003935632619115559
337.80000000000405,20.215870564609805,-1.7423786231943466,-0.005322300767867105
339.0000000000041,20.25257328596548,-1.747024444359294,-0.008016122819252125
340.20000000000414,20.289421262842847,-1.7507437191070032,-0.010368009508309406
341.4000000000041,20.326358312378513,-1.756196071390691,-0.012382152215411502
342.6000000000041,20.363021825861967,-1.7606772154172061,-0.013966132688318034
343.80000000000416,20.400060019445366,-1.762789871875787,-0.016156687501427847
345.0000000000042,20.43651651386318,-1.764192470080327,-0.01712459225664542
346.2000000000042,20.473316149902608,-1.7671799640657329,-0.019232480715634992
347.4000000000042,20.51009234224563,-1.7673773953240206,-0.020323742662815114
348.60000000000423,20.547156078336165,-1.771162260353587,-0.023399768790405062
349.8000000000043,20.583766797562404,-1.772663289773173,-0.02751754335592871
351.00000000000426,20.620610743832515,-1.7712914726899858,-0.030179078674430926
352.20000000000425,20.6574006445908,-1.771297636865632,-0.03411375388566462
353.4000000000043,20.69405190817463,-1.7713097514485179,-0.03782031328537805
354.60000000000434,20.731028539694968,-1.7704380885055155,-0.041257098545135484
355.80000000000433,20.76798179177783,-1.7671900241140275,-0.04464984184105525
357.0000000000043,20.804410088783644,-1.7654777750998532,-0.047919747414700176
358.20000000000437,20.84138645067422,-1.759530332704333,-0.05190966946995257
359.4000000000044,20.878350937324978,-1.758105093288338,-0.05709953161412695
360.6000000000044,20.914938351657707,-1.753769153376581,-0.06230165220657291
361.8000000000044,20.951996489384392,-1.7490258224130122,-0.06744907985257154
363.00000000000443,20.98892758750568,-1.7471037280072106,-0.07216697041022657
364.2000000000045,21.025787155281826,-1.742011834736968,-0.07808616692387016
365.40000000000447,21.06185491072614,-1.738243047261566,-0.08360649805265963
366.60000000000446,21.098802126237935,-1.7383000700048354,-0.08955982846846977
367.8000000000045,21.136543080013748,-1.7361416920813564,-0.09426776289457361
369.00000000000455,21.173532019528054,-1.7399525238862699,-0.10086032776051779
370.20000000000454,21.210546863002048,-1.7373406482546336,-0.10649863263438242
371.4000000000045,21.247559040369055,-1.7402308316539905,-0.11245753068477748
372.60000000000457,21.2846499285998,-1.7417716712560138,-0.11731524338592347
373.8000000000046,21.321811480072537,-1.7474036526344785,-0.12457773704112851
375.0000000000046,21.35875636808484,-1.7488545790098904,-0.13040684309396067
376.2000000000046,21.39575226139031,-1.7538847664804385,-0.13736878259862717
377.40000000000464,21.432916375902657,-1.7593374172830047,-0.14371873862910478
378.6000000000047,21.470212144957046,-1.7639553656254712,-0.15100101150893064
379.8000000000047,21.5071578936722,-1.768304226827007,-0.15662144547097911
381.00000000000466,21.54413115411378,-1.7721718811165768,-0.16338285120651896
382.2000000000047,21.581505551945938,-1.7794177839215095,-0.17006647382253215
383.40000000000475,21.61875274511778,-1.7846871672695115,-0.17686276322029792
384.60000000000474,21.65600069684522,-1.7889998421289868,-0.18190342446679608
385.80000000000473,21.693044092511656,-1.7950744378708299,-0.1886807312481884
387.0000000000048,21.730221683248327,-1.7989653314209537,-0.19611290157352546
388.2000000000048,21.76758642601372,-1.804475253643609,-0.20327378737790402
389.4000000000048,21.805079883022078,-1.8113997866674927,-0.2093304647183234
390.6000000000048,21.84208822466919,-1.815168179013506,-0.21619606378639267
391.80000000000484,21.87966243857441,-1.8206402254527254,-0.22272061613633953
393.0000000000049,21.916999756780637,-1.8245760892928848,-0.2306334960906642
394.2000000000049,21.954057329611743,-1.8291255411243474,-0.2373283509481965
395.40000000000487,21.99136774625456,-1.8312769222093521,-0.24348463926996455
396.6000000000049,22.02833942121002,-1.8379377445938287,-0.2510915786426775
397.80000000000496,22.066001547599253,-1.8402413885173905,-0.25916643823461083
399.00000000000495,22.103206145584824,-1.841038947591997,-0.2666296687670542
400.20000000000493,22.14084210153695,-1.8429080533807154,-0.27410159607383733
401.400000000005,22.178050725435853,-1.8452150904655182,-0.28071408068990156
402.600000000005,22.21552748341255,-1.8469109545050604,-0.2868920355057316
403.800000000005,22.252782845067063,-1.849252322179501,-0.29377969203436427
405.000000000005,22.29021797236852,-1.850179783688451,-0.30251896325925465
406.20000000000505,22.327056618939732,-1.8506365497553314,-0.31120904022050944
407.4000000000051,22.365086756037872,-1.8529482789105505,-0.31978488166546803
408.6000000000051,22.402398261886304,-1.855073329287195,-0.3289238319805756
409.80000000000507,22.439843240713913,-1.8550382608594078,-0.337758245197024
411.0000000000051,22.477126149555527,-1.8548041799382915,-0.34684288478812775
412.20000000000516,22.514597302697563,-1.8550461831031504,-0.3559060471227138
413.40000000000515,22.552097648042274,-1.8538690665050361,-0.3648657681860845
414.60000000000514,22.58971354101719,-1.8553305819951695,-0.37406633300772096
415.8000000000052,22.62737701026208,-1.8552866373243952,-0.3839442849340937
417.00000000000523,22.66479822518877,-1.8549825275362193,-0.39338687286002116
418.2000000000052,22.702385985670965,-1.855980238151764,-0.40385452822367274
419.4000000000052,22.739670702646233,-1.8573204793166114,-0.4126666424484453
420.60000000000525,22.777465591406088,-1.8541209703562103,-0.4223567251338043
421.8000000000053,22.814948915775574,-1.8577449243935387,-0.43359476523786844
423.0000000000053,22.852736783504078,-1.856588607919875,-0.4448305728390394
424.2000000000053,22.89003100746372,-1.8580406942821839,-0.45670922122001656
425.4000000000053,22.927496051330095,-1.8621001285055123,-0.4682607080000758
426.60000000000537,22.965402043742174,-1.8640813780080152,-0.4800306755695476
427.80000000000535,23.002388907797425,-1.8672030628982583,-0.49075096657221007
429.00000000000534,23.040805971345094,-1.871990423377975,-0.5036985668507086
430.2000000000054,23.078358038565874,-1.8772586287847028,-0.5168659622298142
431.40000000000543,23.115968833356117,-1.8848249442372396,-0.5307606495800936
432.6000000000054,23.15371155647497,-1.8926561604153425,-0.5451067839003843
433.8000000000054,23.19105744226947,-1.9038287995184144,-0.560964453497161
435.00000000000546,23.229586402372895,-1.9152169368918872,-0.5764212601025873
436.2000000000055,23.26729640177238,-1.9301910355675442,-0.5918860298209658
437.4000000000055,23.30498047653758,-1.9470476054634585,-0.6079498568618122
438.6000000000055,23.3430022691308,-1.9636567766316249,-0.6257655203679517
439.8000000000055,23.38094202466871,-1.9825377354303066,-0.6433925357504306
441.00000000000557,23.41863022988489,-2.002088625624105,-0.663000485375894
442.20000000000556,23.456643819826738,-2.0219797570209432,-0.6825099583877159
443.40000000000555,23.494627915753398,-2.0391353737978455,-0.7033839198667686
444.6000000000056,23.532720726235823,-2.0577358410632764,-0.7231775545338124
445.80000000000564,23.570714290628104,-2.0741164274478887,-0.7445318569400108
447.0000000000056,23.608697813229945,-2.091049214736982,-0.7667899262710494
448.2000000000056,23.646365101954174,-2.1060386013321444,-0.79023357642901
449.40000000000566,23.684817416476836,-2.118692148060635,-0.8131592149577589
450.6000000000057,23.722883348177657,-2.1339297767640777,-0.8376508237760296
451.8000000000057,23.760665002391427,-2.147447917225856,-0.8626751440000691
453.0000000000057,23.7988395748082,-2.1609873077918484,-0.889072692785327
454.20000000000573,23.83672994265532,-2.1723279967342086,-0.914929592615374
455.4000000000058,23.874547233626604,-2.184220666841169,-0.942170142877516
456.60000000000576,23.912602545673344,-2.1956601899418025,-0.970645512968515
457.80000000000575,23.9509181115218,-2.2061049107908057,-0.9998252064679232
459.0000000000058,23.989073373205862,-2.2156042599399814,-1.0288479133835575
460.20000000000584,24.026676099179063,-2.2208183665597625,-1.0565902779806788
461.40000000000583,24.06474930675133,-2.22475053706786,-1.0864453883452905
462.6000000000058,24.10261390029585,-2.225808229972974,-1.115698968046709
463.80000000000587,24.140681735498667,-2.2253466185173827,-1.1444729211670839
465.0000000000059,24.177793605427343,-2.218179784081633,-1.1725735784379405
466.2000000000059,24.21647120710076,-2.20835507244027,-1.2016638401288438
467.4000000000059,24.254230407556946,-2.193249033368212,-1.2284807894243994
468.60000000000593,24.291776235953556,-2.1749184449520493,-1.253364454311519
469.800000000006,24.329899159849692,-2.152997359220005,-1.2764984466063671
471.00000000000597,24.367247715241465,-2.124715675265772,-1.2967105145161542
472.20000000000596,24.404862426872356,-2.0951674787799637,-1.316194607390916
473.400000000006,24.442449211598998,-2.060387149000566,-1.3322778674050326
474.60000000000605,24.480188276442025,-2.0241148731580845,-1.3468012289232898
475.80000000000604,24.517461912069137,-1.9889414547349045,-1.3613557611380385
477.000000000006,24.55495298967909,-1.9551267536502734,-1.373792148528762
478.20000000000607,24.59281163011165,-1.9225840431840382,-1.3862297297819692
479.4000000000061,24.63059643888208,-1.8950798433840932,-1.3973758970849257
480.6000000000061,24.667662054223815,-1.8718895518788898,-1.407779722514352
481.8000000000061,24.706456464970604,-1.8536042635690366,-1.4181952939639517
483.00000000000614,24.744228403246353,-1.8394051008043393,-1.4280342466307863
484.2000000000062,24.782293199096838,-1.8285483423771574,-1.4387311930731643
485.4000000000062,24.820329109390563,-1.8208644511225067,-1.4491000954629207
486.60000000000616,24.858544207357745,-1.8190447121435513,-1.458979486297519
487.8000000000062,24.896667666778722,-1.8162597423970068,-1.4678375513153443
489.00000000000625,24.934645508482475,-1.8171819702758336,-1.479242583093693
490.20000000000624,24.97305434507768,-1.8203444451133786,-1.4896119551633653
491.40000000000623,25.011060191895506,-1.8226073086177244,-1.5013181559660564
492.6000000000063,25.049331054771088,-1.8272482089353588,-1.513274326172731
493.8000000000063,25.08751544161462,-1.8272235768530882,-1.5254878417649342
495.0000000000063,25.125772168895498,-1.829614191532829,-1.537997069421913
496.2000000000063,25.16383257778068,-1.8276889152913034,-1.55039669382148
497.40000000000634,25.202286624859592,-1.8205021160640118,-1.5625681603070198
498.6000000000064,25.24029363341036,-1.808701727789092,-1.575177627849278
499.8000000000064,25.278333852007105,-1.788621867211689,-1.5877115920680938
501.00000000000637,25.31650698335873,-1.7597068535808544,-1.5998526006107974
502.2000000000064,25.354089628015338,-1.7257964483568957,-1.6098945915790996
503.40000000000646,25.392203661617327,-1.6921248719452244,-1.6198798120721465
504.60000000000645,25.430096152912622,-1.651027133410147,-1.629428978958309
505.80000000000643,25.46791020121943,-1.6047451708000269,-1.6370024669569645
507.0000000000065,25.505585475420503,-1.560562087990267,-1.6415505326789432
508.2000000000065,25.543081773788707,-1.5175167073176827,-1.645568161852672
509.4000000000065,25.581115179908753,-1.4779838658496498,-1.6487395107730034
510.6000000000065,25.619076469424378,-1.4477521357514385,-1.6519649439940167
511.80000000000655,25.65752471087459,-1.426138714024939,-1.6534892044960303
513.0000000000066,25.695660293158276,-1.4091336437397683,-1.6573622703553514
514.2000000000066,25.733530149940385,-1.398776615603089,-1.657833967603013
515.4000000000066,25.77221024326424,-1.3909501843418839,-1.659009139547654
516.6000000000066,25.81061564089182,-1.3918520793144524,-1.6608084210646732
517.8000000000067,25.848835739793778,-1.389266075135672,-1.6611567977725055
519.0000000000066,25.887332517788323,-1.392516187337154,-1.6625372566337502
520.2000000000066,25.92583129863201,-1.3931275765721722,-1.6640449475498964
521.4000000000067,25.963999094396875,-1.3947286877396072,-1.6654056091044698
522.6000000000067,26.002829121411768,-1.397854212543193,-1.6660314284237185
523.8000000000068,26.041624950294484,-1.4004145721914056,-1.6667218105736223
525.0000000000067,26.080128867785017,-1.4080624470427374,-1.6680577495985252
526.2000000000068,26.118866690490535,-1.4120704804885067,-1.669402817504554
527.4000000000068,26.157510561600095,-1.4169075094683066,-1.6707678300808206
528.6000000000067,26.195875024847762,-1.4214247668639797,-1.67221924733145
529.8000000000068,26.234745516745015,-1.4287438537947725,-1.6736408915514267
531.0000000000068,26.273718449318324,-1.4314516553482757,-1.6735615370071546
532.2000000000069,26.312180015011347,-1.4374626469847673,-1.6749160520285784
533.4000000000069,26.350760783570088,-1.4416394572192701,-1.6763001940770526
534.6000000000068,26.38970827120211,-1.4467127455234468,-1.677608928209382
535.8000000000069,26.427690077163756,-1.4534358512736636,-1.677517343754083
537.0000000000069,26.46756489076421,-1.4569498249152164,-1.6788436261317936
538.2000000000069,26.506173362165637,-1.4650449974148385,-1.6802310992934468
539.4000000000069,26.54494601062589,-1.468835200474328,-1.6815382448155036
540.600000000007,26.58408109447085,-1.4726687307018458,-1.6819087083730961
541.800000000007,26.62299882299596,-1.479111269702825,-1.6849426110897623
543.000000000007,26.662120742182317,-1.4854741780600087,-1.6857012280130124
544.200000000007,26.70060088177724,-1.4906522275905922,-1.6869206671611963
545.400000000007,26.739310588486045,-1.4952364980455042,-1.6873177680494886
546.6000000000071,26.778457726977685,-1.502034528285134,-1.6882782092541775
547.800000000007,26.817733213589584,-1.5064136756681052,-1.6897243111792242
549.000000000007,26.856793165402614,-1.5125610428210838,-1.690852631387668
550.2000000000071,26.89596202611003,-1.5152934448089599,-1.6915642688271246
551.4000000000071,26.934829392864792,-1.5213845239244208,-1.692357704383761
552.6000000000072,26.974076523128392,-1.524509014384197,-1.6949652490358957
553.8000000000071,27.01334605029056,-1.5297704184654421,-1.6969555996916852
555.0000000000072,27.052097497818067,-1.5319997902887326,-1.698419619849905
556.2000000000072,27.090984027392118,-1.5348725708088815,-1.6998173753975028
557.4000000000071,27.13038689284417,-1.5397997088384892,-1.700805024637281
558.6000000000072,27.16953781547915,-1.5415088722431103,-1.702439121182366
559.8000000000072,27.208147191103947,-1.5457157304019662,-1.7027200525615838
561.0000000000073,27.247779754698612,-1.549554938499938,-1.7028695886385545
562.2000000000073,27.286987931272375,-1.5542097399186026,-1.7042251519701215
563.4000000000073,27.325995771208923,-1.5576387572899557,-1.705344116242034
564.6000000000073,27.36524397816114,-1.5620315928113544,-1.706743580788813
565.8000000000073,27.403987714952223,-1.565812487098671,-1.7081293640728266
567.0000000000073,27.443866565970897,-1.5672002159098184,-1.7099406109120787
568.2000000000073,27.482866073927998,-1.5725818607187734,-1.7114372105252578
569.4000000000074,27.52201571356078,-1.5777526409376472,-1.7124815185066633
570.6000000000074,27.5613533752371,-1.5816765874567662,-1.7138354104067628
571.8000000000075,27.600262461046096,-1.5874920932298302,-1.7151515158721349
573.0000000000074,27.639836130831004,-1.5946395014538612,-1.7164660730418007
574.2000000000074,27.679560897986747,-1.600025676673602,-1.7180034057874223
575.4000000000075,27.71868242498081,-1.6066316011774116,-1.719317633630408
576.6000000000074,27.758270570311716,-1.6114215427862641,-1.720673051520865
577.8000000000075,27.797505037302113,-1.6175165634714999,-1.7224079039515883
579.0000000000075,27.836669006957393,-1.6235495265288415,-1.7251786708876593
580.2000000000075,27.876166822622068,-1.631794132738379,-1.7270938645874838
581.4000000000076,27.91566990399713,-1.6390470790414844,-1.7299100380447219
582.6000000000075,27.955348283361683,-1.6461653881164238,-1.7317556614605198
583.8000000000076,27.994548166464597,-1.6504594729748812,-1.7334558790297994
585.0000000000076,28.033717672607466,-1.6609714810656053,-1.7364500739623496
586.2000000000075,28.073577374174697,-1.6689018653240053,-1.7363365204816237
587.4000000000076,28.113086586707503,-1.6744873853934767,-1.735462297821615
588.6000000000076,28.152337661422507,-1.6827518528628918,-1.7408002534666966
589.8000000000077,28.191974790760753,-1.6915349629455834,-1.7443467871980314
591.0000000000077,28.231346755077297,-1.700392304457365,-1.7474621633720302
592.2000000000077,28.27093634416457,-1.7099651163523832,-1.7508989999528617
593.4000000000077,28.310795470696046,-1.7196440890209732,-1.7525983173901518
594.6000000000078,28.349967447248876,-1.73137897865975,-1.7546659925596417
595.8000000000077,28.389738396723175,-1.7409337703093781,-1.757845881808322
597.0000000000077,28.428716194701366,-1.7574749677992123,-1.7606695972875865
598.2000000000078,28.469267503348206,-1.7728987870623951,-1.762876840117864
599.4000000000078,28.508798937531267,-1.7911852666600456,-1.7664141837044869
600.6000000000079,28.548250886236048,-1.8109079329538869,-1.7696163769565443
601.8000000000078,28.58823773931489,-1.832187945646156,-1.7721484124009264
603.0000000000078,28.627782418010483,-1.8533980571220332,-1.7767287850193285
604.2000000000079,28.66786852021824,-1.877120657435002,-1.7801715107822353
605.4000000000078,28.707409690569673,-1.8981664581733437,-1.7850063636542464
606.6000000000079,28.7470834083014,-1.9176907812580144,-1.7899432212374107
607.8000000000079,28.786591977983484,-1.9329774528873194,-1.7966645097264902
609.000000000008,28.82658987759377,-1.9468190104384355,-1.8021441951960289
610.200000000008,28.866255725240528,-1.956979746058501,-1.8077726623813537
611.4000000000079,28.906144454867317,-1.9661654004633313,-1.8138234809693885
612.600000000008,28.94539989995169,-1.9784494330123636,-1.8210353748696688
613.800000000008,28.985384466374967,-1.9877044928360896,-1.8241059998332978
615.000000000008,29.02498914006818,-1.9939112962213614,-1.8297374665164736
616.200000000008,29.06470953421255,-2.00288663448455,-1.844416869093434
617.400000000008,29.104578336677548,-2.0109402355023205,-1.8545761286700024
618.6000000000081,29.14407132305757,-2.0176285828835434,-1.8624966795474966
619.8000000000081,29.183700338146334,-2.0250777974107885,-1.8695381850677055
621.0000000000081,29.22329216486657,-2.0283973247402955,-1.8774956490370394
622.2000000000081,29.263134605835727,-2.034288124341188,-1.886003682208779
623.4000000000082,29.30252387737579,-2.042031657046752,-1.894647455302172
624.6000000000081,29.34239975959744,-2.04623577101069,-1.9037785284683948
625.8000000000081,29.382111367429257,-2.050146049641342,-1.9130210001599037
627.0000000000082,29.42181251609261,-2.054789721115108,-1.9221697755714873
628.2000000000082,29.461290340624256,-2.0601131397839874,-1.9322807143601217
629.4000000000083,29.50105843290303,-2.0679059652778156,-1.9422481829916984
630.6000000000082,29.540454657253008,-2.0718854057749976,-1.9541813870088602
631.8000000000083,29.580234658756886,-2.078334214976766,-1.9637515701567563
633.0000000000083,29.61989919560284,-2.0824603717085792,-1.972455849146996
634.2000000000082,29.659601428711753,-2.086644243847728,-1.9819327159016638
635.4000000000083,29.699331261138493,-2.0941259735534605,-1.9915301562983831
636.6000000000083,29.73879796213739,-2.095816842008891,-1.9993583988575687
637.8000000000084,29.778538143183358,-2.0996556625810485,-2.0062091410309097
639.0000000000084,29.81815609907277,-2.110020135661339,-2.012414216880156
640.2000000000083,29.857903971048394,-2.1242386651618554,-2.014895742119965
641.4000000000084,29.897666567184913,-2.1280148883276357,-2.01822811949506
642.6000000000084,29.937201000825603,-2.12917248395421,-2.0199343020793954
643.8000000000084,29.977125048805142,-2.126984740960801,-2.0230235288646057
645.0000000000084,30.016874030657235,-2.121420369938888,-2.024800710939327
646.2000000000085,30.05614372929039,-2.1149283571687194,-2.027018420071838
647.4000000000085,30.096072516684192,-2.1124700105814944,-2.0285440342764005
648.6000000000085,30.13579083036735,-2.1165562530542115,-2.030493147008485
649.8000000000085,30.175470293279318,-2.1237858242816814,-2.0315294737352216
651.0000000000085,30.215418625999824,-2.1353662990434064,-2.0327234075802187
652.2000000000086,30.255079766311326,-2.156238856054099,-2.033661675140687
653.4000000000085,30.295049354570594,-2.1800714957572724,-2.03445265466687
654.6000000000085,30.33481032052545,-2.2036016051483025,-2.0359508774432244
655.8000000000086,30.374740235263726,-2.2268593025211447,-2.0374609452078176
657.0000000000086,30.41469756282134,-2.253304966945174,-2.0344440529613608
658.2000000000087,30.454873399836057,-2.279263226390566,-2.0388010834127197
659.4000000000086,30.49480505814641,-2.307791809670781,-2.047379735286941
660.6000000000087,30.534655380976023,-2.336874421676711,-2.0604686654650215
661.8000000000087,30.574561105084655,-2.3640388505810344,-2.0369300624762565
663.0000000000086,30.614632373211847,-2.390313819119021,-2.0424919754776223
664.2000000000087,30.65488315894352,-2.4206311356603747,-2.051984599446902
665.4000000000087,30.695110050480633,-2.4506591742737527,-2.054244547702321
666.6000000000088,30.735046848099667,-2.478491841743652,-2.0554180291383752
667.8000000000088,30.774959700935586,-2.513728442134743,-2.05728605725512
669.0000000000088,30.814955981815913,-2.5450865928618223,-2.0597703375542586
670.2000000000088,30.85430905255309,-2.5786562702792324,-2.0613745430821973
671.4000000000088,30.89542107366293,-2.6147112098340837,-2.064204733451456
672.6000000000088,30.9354111461728,-2.651287852984948,-2.0666310209851635
673.8000000000088,30.975568262772086,-2.693084717046901,-2.069528081967561
675.0000000000089,31.01586244704848,-2.7355814268486,-2.0724503552619824
676.2000000000089,31.055992827462106,-2.7802414509545694,-2.0743656998414193
677.400000000009,31.096436390629815,-2.827649965393484,-2.0764004931441464
678.6000000000089,31.13631299912372,-2.875380957627236,-2.079417106116024
679.8000000000089,31.176991725627616,-2.9262423163069102,-2.0823279587100454
681.000000000009,31.217243443116008,-2.9778622766912237,-2.0840272742585
682.2000000000089,31.257691081803127,-3.035274982142825,-2.0873373655797662
683.400000000009,31.298051777084858,-3.092138233917237,-2.091230565223086
684.600000000009,31.33823308485757,-3.14946503459188,-2.0943719042541957
685.800000000009,31.378940858557893,-3.2074419580754308,-2.098752739309191
687.0000000000091,31.41902443170826,-3.2693803410731137,-2.1031243142456884
688.200000000009,31.459897730662558,-3.331108626764681,-2.1075954977541103
689.4000000000091,31.5002365322525,-3.3965398276789847,-2.110066769956557
690.6000000000091,31.54063154595015,-3.4604458271543175,-2.115881431812417
691.800000000009,31.58097575317425,-3.5265095741540904,-2.1198217991649626
693.0000000000091,31.621948941958053,-3.5909560538408307,-2.1251499718972147
694.2000000000091,31.66246135223492,-3.6601120334165174,-2.1302061381564323
695.4000000000092,31.702980173321134,-3.7285669700832615,-2.1367875123180795
696.6000000000092,31.74340909452682,-3.798641708410857,-2.1421487662823604
697.8000000000092,31.784238574940566,-3.86775672312356,-2.1463063409206597
699.0000000000092,31.824632928263735,-3.940735994464973,-2.1517489377074672
700.2000000000093,31.865321750198863,-4.008449738065166,-2.1573446139543115
701.4000000000092,31.905813793932808,-4.079393869116735,-2.163798295316511
702.6000000000092,31.94681380167134,-4.1548107436179045,-2.170788869089907
703.8000000000093,31.98758139662916,-4.22915307751501,-2.1761363916106493
705.0000000000093,32.028122039056136,-4.300649240814406,-2.1828445477251766
706.2000000000094,32.068890681705305,-4.37633606025705,-2.1898427565180905
707.4000000000093,32.10933325178392,-4.454460700503105,-2.196305740104858
708.6000000000093,32.150396627594105,-4.528786550778538,-2.203078447011234
709.8000000000094,32.19087743798717,-4.603256912536616,-2.2095930805639465
711.0000000000093,32.232061612599125,-4.684593747564101,-2.216944377902231
712.2000000000094,32.27271145175461,-4.760160499313835,-2.2247115352605067
713.4000000000094,32.313250218607116,-4.837515578475271,-2.2320160315038513
714.6000000000095,32.35420233582712,-4.916753071496699,-2.2392289172150885
715.8000000000095,32.39505627294864,-4.995460763507837,-2.248272644401906
717.0000000000094,32.43575231460136,-5.076669182029027,-2.256287065096261
718.2000000000095,32.47653615302417,-5.151820932438916,-2.2652058090804066
719.4000000000095,32.51728560226645,-5.233285806583502,-2.273576286173754
720.6000000000095,32.55804177719955,-5.312097004750721,-2.284188664308374
721.8000000000095,32.598890603185865,-5.391800948328179,-2.293670881297475
723.0000000000095,32.63989837896723,-5.473307614707556,-2.3008888083084
724.2000000000096,32.68086739749651,-5.554472306438854,-2.3117214419606738
725.4000000000096,32.721469709765294,-5.637818080292314,-2.3225185792963456
726.6000000000096,32.762049377878206,-5.723177700821681,-2.3332027800670168
727.8000000000096,32.80343053635096,-5.81564974716538,-2.3426851373084956
729.0000000000097,32.84446866143812,-5.906287305115842,-2.3501859301981547
730.2000000000096,32.885317048693516,-6.000508001956008,-2.3613992361864744
731.4000000000096,32.92657729839803,-6.099246163470636,-2.3715810063966902
732.6000000000097,32.9676780321602,-6.202948851422491,-2.3818162282786153
733.8000000000097,33.00863223883458,-6.311457168841742,-2.3927875459022925
735.0000000000098,33.049519283161445,-6.425011943707862,-2.40413012035263
736.2000000000097,33.0911246393778,-6.539136603208873,-2.4155756366627705
737.4000000000098,33.13242117162909,-6.657586603065512,-2.428117801195569
738.6000000000098,33.17323764999388,-6.774777483801055,-2.4386690597677907
739.8000000000097,33.21483317454506,-6.895817071423305,-2.4500104526017115
741.0000000000098,33.255868583415044,-7.0140379864852145,-2.463264472146058
742.2000000000098,33.29700543886064,-7.124097338995546,-2.476170369638668
743.4000000000099,33.33844301805241,-7.228264036928455,-2.489473866385336
744.6000000000099,33.379304780332006,-7.32166063849398,-2.5033077755269453
745.8000000000098,33.41972225840684,-7.406781630406622,-2.5144879915947618
747.0000000000099,33.4611757675586,-7.477963013367542,-2.52792620914579
748.2000000000099,33.501975435000716,-7.532927077178108,-2.5419639874437
749.4000000000099,33.54275034679854,-7.573349342134838,-2.5569651201080528
750.6000000000099,33.58311875967679,-7.589472159253442,-2.570407055947518
751.80000000001,33.623334781685784,-7.589180421370012,-2.5840744193982297
753.00000000001,33.66337893606527,-7.561024830149553,-2.597609874363325
754.20000000001,33.703359626916146,-7.500670948031537,-2.610737310386491
755.40000000001,33.742750777280435,-7.409317607715973,-2.623627452525267
756.60000000001,33.78153750761308,-7.265128104606466,-2.6358915078019542
757.8000000000101,33.82066059727702,-7.064208695015728,-2.649565589796892
759.00000000001,33.85819409831169,-6.794605554719406,-2.6613226765888705
760.20000000001,33.89566033258347,-6.432149792073655,-2.6709735973933744
761.4000000000101,33.93160107082506,-5.938037842843322,-2.680131038043889
762.6000000000101,33.965987275644046,-5.196656990222293,-2.689395478839746
763.8000000000102,33.99921601821944,-4.310663541828149,-2.6968187334242013
765.0000000000101,34.03316428768193,-3.5432588484813485,-2.7026314838639447
766.2000000000102,34.06894416962749,-2.973872297894938,-2.705736930218171
767.4000000000102,34.10547322960183,-2.586296280311895,-2.705954302091894
768.6000000000101,34.14354891930806,-2.3215259832614747,-2.705747476335728
769.8000000000102,34.182189068426666,-2.148873073760454,-2.707248020187729
771.0000000000102,34.221378552405405,-2.0354158990586484,-2.708472519472443
772.2000000000103,34.260809438610735,-1.9588937666246002,-2.7084700032972027
773.4000000000103,34.3004475315187,-1.9070181447974208,-2.708463240888176
774.6000000000103,34.34036326877051,-1.873535282940613,-2.709771485604173
775.8000000000103,34.37952293231862,-1.8483983560160397,-2.7084628795609236
777.0000000000103,34.42046360529445,-1.8342622626566554,-2.7084482286503837
778.2000000000103,34.46057323731769,-1.8237864443269454,-2.7071552781957404
779.4000000000103,34.500903904137985,-1.8158436333105825,-2.70847272432998
780.6000000000104,34.54115918555127,-1.8120791121127227,-2.7084756244072263
781.8000000000104,34.581600839663615,-1.807240587887081,-2.7097950961975634
783.0000000000105,34.621980430954245,-1.8101323098573305,-2.709789665683774
784.2000000000104,34.66176832328457,-1.8064044937496624,-2.709716622322608
785.4000000000104,34.701918229193105,-1.8036277645950722,-2.707919514832485
786.6000000000105,34.74234134589585,-1.8058172068779497,-2.7105046338634313
787.8000000000104,34.78327910554894,-1.8084445659669606,-2.7133368279015553
789.0000000000105,34.823766898894796,-1.8077656447227037,-2.714741390408717
790.2000000000105,34.863929474358024,-1.8071160723335875,-2.713459490715014
791.4000000000106,34.904243472089945,-1.8106666131999811,-2.714737023685993
792.6000000000106,34.944787933283486,-1.812325633625804,-2.7147301008177234
793.8000000000105,34.985223019147035,-1.8159918610618484,-2.714730068212651
794.0000000000106,34.9919590525213,-1.8166866570558144,-2.714730067888284