File: 01_Data/Polyester_Carpet_High_Pile/STA/N2/30K_min/Polyester_Carpet_High_Pile_STA_N2_30KData_230925_R2.csv
##Temp./Â°C,Time/min,DSC/(mW/mg),Mass loss/mg
51.0,10.613178851674089,-2.3072644536930174,-0.001846379719048219
52.20000000000002,10.791010303000855,-2.280577442814347,-0.000793569445536324
53.400000000000034,10.913146113167883,-2.2569010661698856,-8.328606451790677e-05
54.60000000000005,11.012422581064335,-2.2366935348122308,-8.56234168624681e-05
55.80000000000007,11.096874188598623,-2.2201883186452607,-0.0005239843837552272
57.000000000000085,11.172691079564176,-2.2015048740509964,-0.00024211441203814132
58.2000000000001,11.243371447059017,-2.186471723441276,0.004416802548452559
59.40000000000012,11.30885388680791,-2.1712998357598994,0.0003336327074241474
60.600000000000136,11.370685156749541,-2.157893624040093,-0.003133931363948239
61.80000000000015,11.429487371725022,-2.1423574464606414,-0.002429586465367173
63.00000000000017,11.485516069597901,-2.1290180178345075,-0.0015528444721533141
64.20000000000019,11.539713100214497,-2.1170380753531104,-0.0008646846445219403
65.4000000000002,11.5924334101423,-2.104635618546599,-0.0019958088513063466
66.60000000000022,11.643374543709458,-2.09319553876109,0.003507856756868044
67.80000000000024,11.694426076133443,-2.081998970339668,-0.0010883198106359515
69.00000000000026,11.743034353078407,-2.0713233966777107,-0.0035544264190252584
70.20000000000027,11.790980122639217,-2.060252643925549,-0.0020221290266353442
71.40000000000029,11.83836989641709,-2.051224160856366,-0.0011735913243486884
72.6000000000003,11.884992749499315,-2.0424492186321745,-0.0025583125289121433
73.80000000000032,11.93142340617993,-2.0337555790402364,-0.003285545713730631
75.00000000000034,11.97638108470474,-2.027132737769943,-0.003927510390556055
76.20000000000036,12.022004994807265,-2.018609652769593,-0.0032133935141738235
77.40000000000038,12.06659050788827,-2.0115914180813084,-0.003427149755287573
78.60000000000039,12.111063256949969,-2.0054655724666044,-0.002920515223456377
79.80000000000041,12.154437137757574,-1.995954659317562,-0.0037725212212187387
81.00000000000043,12.196909313727911,-1.9846322451972347,-0.006130676468388163
82.20000000000044,12.239856175616694,-1.9724046893606277,-0.004292526209309866
83.40000000000046,12.282538111105161,-1.9578102545750504,-0.0017359974671009581
84.60000000000048,12.325895231332495,-1.9430865635305266,-0.001333373402485627
85.8000000000005,12.367186190228907,-1.9301229911784792,-0.0019218499631374897
87.00000000000051,12.410034585594419,-1.91622119863491,-0.004296184934995839
88.20000000000053,12.45098035182227,-1.9046509137382557,-0.004637606026243635
89.40000000000055,12.492211351076842,-1.8940404888518783,-0.0027763474520901
90.60000000000056,12.53399942947679,-1.8835046905414108,-0.0011170799144393229
91.80000000000058,12.575089503149336,-1.8736118698432214,-0.002657769994809378
93.0000000000006,12.615856491236858,-1.8661572150862997,-0.002697749638758573
94.20000000000061,12.656379346352715,-1.856388979923161,-0.0027622960882505154
95.40000000000063,12.696849806051471,-1.8475706921785229,-0.00282360825990402
96.60000000000065,12.737629316183682,-1.8397699294935237,-0.003909069997652281
97.80000000000067,12.777812823787634,-1.830958407069728,-0.0027551812121604513
99.00000000000068,12.818305905457194,-1.825640440499677,-0.004119149297373781
100.2000000000007,12.858259363203484,-1.820013356921144,-0.0027512069675625916
101.40000000000072,12.898650242382699,-1.8122275384409223,-0.0017965745850871961
102.60000000000073,12.938715145066443,-1.8075882037532898,-0.0027258301613111158
103.80000000000075,12.978345965728824,-1.8029442385153387,-0.0013767126998311952
105.00000000000077,13.018904054764967,-1.7970905768460128,-0.0024223530581415353
106.20000000000078,13.058628476496523,-1.7934020620421125,-0.0013724692421717144
107.4000000000008,13.098704814601577,-1.7878313771080554,-0.0027387345068690117
108.60000000000082,13.138075146028685,-1.7851679990884533,-0.0027510096373362103
109.80000000000084,13.178345542723076,-1.779700483925455,-0.004154107973994847
111.00000000000085,13.21825337311967,-1.7751392204621688,-0.003489350443026673
112.20000000000087,13.257831481426319,-1.77177278725169,-0.0030223052256661553
113.40000000000089,13.297839287294446,-1.7664233957168742,-0.004075536290145898
114.6000000000009,13.336987959126201,-1.7640600834051916,-0.0028351353367677135
115.80000000000092,13.37722797635637,-1.761350261120906,-0.002750820275347454
117.00000000000094,13.416787237621222,-1.757853275775759,-0.003984767581461934
118.20000000000095,13.45619763434731,-1.7546716690502588,-0.00273627087934436
119.40000000000097,13.496236408986789,-1.7527934585240783,-0.00274054729075468
120.60000000000099,13.535187303930467,-1.7466936952852707,-0.002956618444643677
121.800000000001,13.574932666579002,-1.74373619287938,-0.004696408387634854
123.00000000000102,13.61435947101318,-1.7432897582960558,-0.00471981280273015
124.20000000000104,13.653515920155195,-1.738230960519677,-0.004722579694702134
125.40000000000106,13.693116399179956,-1.73567114092461,-0.0050334068954951405
126.60000000000107,13.732188387194435,-1.7315512290123247,-0.005380821994294127
127.80000000000109,13.771539296335268,-1.73141726413674,-0.0053801783517637425
129.0000000000011,13.810533454889475,-1.727105735263247,-0.004441006015165172
130.20000000000113,13.849266300805024,-1.7253248336508722,-0.004718516472779211
131.40000000000114,13.888411147369956,-1.7216808758261746,-0.003413253796348492
132.60000000000116,13.927583895227583,-1.7209931839482764,-0.003409892997149111
133.80000000000118,13.966172359636337,-1.7192124415926542,-0.003409827274718058
135.0000000000012,14.005206784683605,-1.716080678725799,-0.0034092314775882038
136.2000000000012,14.043721887945585,-1.7143863482673316,-0.0044166741385889274
137.40000000000123,14.082471536365011,-1.711258526300334,-0.004400035902139887
138.60000000000124,14.120508607961352,-1.7101309119780717,-0.004399855452266621
139.80000000000126,14.159006534054667,-1.7085754644929978,-0.004399854004614401
141.00000000000128,14.198052187971522,-1.7094419878188818,-0.004399853514534868
142.2000000000013,14.236918539397339,-1.7073389941300596,-0.004399828157195973
143.4000000000013,14.275219480752845,-1.7066409192293648,-0.004402418330304858
144.60000000000133,14.31390729377327,-1.7071356859798283,-0.004300819291994884
145.80000000000135,14.351688391197975,-1.7079675701722927,-0.0034099748222566895
147.00000000000136,14.390468887911897,-1.707857395323323,-0.0034575361018660544
148.20000000000138,14.428144613727737,-1.7107778098528625,-0.004725207557367828
149.4000000000014,14.466324181811625,-1.7143284412422408,-0.004720080703912721
150.60000000000142,14.504812812599578,-1.719278633585949,-0.004720083419802901
151.80000000000143,14.542640423505702,-1.7248348285598643,-0.004719636675138528
153.00000000000145,14.58124096143274,-1.7309551389053282,-0.005420814559446097
154.20000000000147,14.619138792985009,-1.7427025225879667,-0.006039020523124883
155.40000000000148,14.657396339300236,-1.7528341105815373,-0.006040099539321719
156.6000000000015,14.695246258196404,-1.7654305795202456,-0.006043227738342871
157.80000000000152,14.733560080288632,-1.7792706323044656,-0.005764135586510566
159.00000000000153,14.771413390866732,-1.7939265286331245,-0.004713288076963806
160.20000000000155,14.809721278004963,-1.8077163890760535,-0.0047198510414614425
161.40000000000157,14.84776591002838,-1.8212913333642302,-0.004719862221822968
162.6000000000016,14.88527934985982,-1.8300083481536595,-0.004719862003055297
163.8000000000016,14.923310870229196,-1.8324710249458178,-0.004719862000025721
165.00000000000162,14.960582561385701,-1.8249762173135118,-0.0047198620001140945
166.20000000000164,14.998184238078013,-1.8087927654985263,-0.004719861901022249
167.40000000000165,15.035218324095224,-1.7858164612633003,-0.004719843638538723
168.60000000000167,15.07268545434261,-1.761690945175092,-0.004718306896162705
169.8000000000017,15.10990434135209,-1.7384285713619478,-0.005379861999918578
171.0000000000017,15.14702442335674,-1.716559989747524,-0.00604207085772579
172.20000000000172,15.184512940166236,-1.696893955336509,-0.006039887433331614
173.40000000000174,15.221665090797405,-1.6798990213839369,-0.006040500164861573
174.60000000000176,15.258764665114384,-1.6672772629357469,-0.006024180332373064
175.80000000000177,15.295874783010076,-1.6547661368064017,-0.0067033850029787345
177.0000000000018,15.333064837549422,-1.6460544856435213,-0.006700170061201494
178.2000000000018,15.370423148608134,-1.6383181451432969,-0.006700107093095209
179.40000000000182,15.407232326356112,-1.6311818189939746,-0.006706129034957264
180.60000000000184,15.444676919778015,-1.6253469776006355,-0.005403001205911195
181.80000000000186,15.481175130687552,-1.6213879829042142,-0.005380260959501282
183.00000000000188,15.517824034888998,-1.6176621861242428,-0.005380143621518396
184.2000000000019,15.555200221687102,-1.6124063142818397,-0.005380142136869992
185.4000000000019,15.591947549752811,-1.6113259159454845,-0.0053799259603684035
186.60000000000193,15.629139699526723,-1.6068919831163697,-0.005380469614533645
187.80000000000194,15.66595310518132,-1.6048521813428671,-0.006029482890486548
189.00000000000196,15.702737522250382,-1.601892132013058,-0.0060400512670772954
190.20000000000198,15.739711820762464,-1.6001666642807664,-0.006040143842368728
191.400000000002,15.776481300712016,-1.5971408803649874,-0.006040144005302839
192.600000000002,15.81323888785968,-1.5963293373004368,-0.006040144000045267
193.80000000000203,15.849757345055451,-1.5933899180943838,-0.006040144000001302
195.00000000000205,15.886730866473034,-1.5905822451539477,-0.006040144000000414
196.20000000000206,15.923241471444944,-1.5900108230826373,-0.006040143999929359
197.40000000000208,15.959911756845234,-1.5899040567578873,-0.006040143997760428
198.6000000000021,15.996789678292332,-1.5885130616706693,-0.006040144800554703
199.80000000000211,16.033293910909624,-1.587360900001861,-0.006040287877801642
201.00000000000213,16.06976436147075,-1.5865623262337334,-0.006043576682754459
202.20000000000215,16.10665473687606,-1.585827776834153,-0.005714527516465839
203.40000000000217,16.143101751002817,-1.5844496172333633,-0.005709851162958746
204.60000000000218,16.1797971432624,-1.5846895051310088,-0.005709804077641767
205.8000000000022,16.216060758790473,-1.5856496952112997,-0.00570980399865606
207.00000000000222,16.25288312008827,-1.5841969914258551,-0.005709804254768525
208.20000000000223,16.28926149310187,-1.5856062047608506,-0.005709804991380185
209.40000000000225,16.326112032127725,-1.5851385014830834,-0.005706343211832721
210.60000000000227,16.362451346505466,-1.5864716301110837,-0.006639407674288389
211.80000000000229,16.399075820744066,-1.5873336693770832,-0.007030025802726048
213.0000000000023,16.435663432673586,-1.5872933571895607,-0.007029984127261191
214.20000000000232,16.472560569511046,-1.5884324076700491,-0.007029970103244576
215.40000000000234,16.50904564936922,-1.5896889404474037,-0.00702996998646066
216.60000000000235,16.54548368137592,-1.5910722738579621,-0.007029933895613016
217.80000000000237,16.58183224839151,-1.592200634319775,-0.007026049796447165
219.0000000000024,16.618326949608115,-1.5953606131874587,-0.008365136841959941
220.2000000000024,16.654673204386185,-1.5971216620312283,-0.008433572747417184
221.40000000000242,16.69088361787512,-1.6006768414984458,-0.00703240938830918
222.60000000000244,16.72782413018618,-1.6043979292502266,-0.007029647794571492
223.80000000000246,16.764159321382227,-1.6059541755710418,-0.006939419162419913
225.00000000000247,16.800000059547546,-1.610919510687782,-0.008349679677530641
226.2000000000025,16.8368582850674,-1.6159280689483824,-0.008350144942469662
227.4000000000025,16.873864440715092,-1.622078508604173,-0.008350136117933893
228.60000000000252,16.910054697785927,-1.6268557133693597,-0.00835013479785962
229.80000000000254,16.946562605281038,-1.6339908486495038,-0.008349830901529298
231.00000000000256,16.983065243387937,-1.6411319704287066,-0.008336681935322332
232.20000000000258,17.019840102723816,-1.6508573348303588,-0.00737102549856905
233.4000000000026,17.05592000665047,-1.6597165103181037,-0.007360220805845419
234.6000000000026,17.092895471641633,-1.6716807517446468,-0.007360136474371171
235.80000000000263,17.129293336114316,-1.6871814650878367,-0.007360138510624115
237.00000000000264,17.165693424953083,-1.7021909956231138,-0.007352862688383421
238.20000000000266,17.20235646860816,-1.722484780065179,-0.008643902265098813
239.40000000000268,17.239107066674876,-1.7484242477844132,-0.008669958928518184
240.6000000000027,17.27575916923533,-1.7812121609096163,-0.008669670827440079
241.8000000000027,17.312782456522665,-1.8212494872193619,-0.008629037996880307
243.00000000000273,17.35002513958932,-1.8761746220452786,-0.009984571598388836
244.20000000000275,17.387305816998527,-1.942286526803236,-0.009990209199450373
245.40000000000276,17.424648885055504,-2.022655704422593,-0.009990121132691154
246.60000000000278,17.462387966912207,-2.110128360074301,-0.00999011842354891
247.8000000000028,17.499535709322423,-2.1883136904839646,-0.00999024357846423
249.0000000000028,17.536456757950006,-2.2394969456702674,-0.01002129490586734
250.20000000000283,17.573154954049507,-2.2517655011653215,-0.00965897775118929
251.40000000000285,17.609139804072946,-2.226207639302254,-0.009660181955190694
252.60000000000286,17.644797292670855,-2.1720401435174503,-0.0096650959027893
253.80000000000288,17.680107845342594,-2.1041904542920533,-0.008344790516571887
255.0000000000029,17.715331011573554,-2.0353259816453138,-0.009629978015655016
256.2000000000029,17.750762355427334,-1.9640482219010238,-0.00966978423036835
257.40000000000293,17.786203928317253,-1.9024213148356162,-0.009669968160843201
258.600000000003,17.82145038697701,-1.8455131405055687,-0.009710994030384779
259.80000000000297,17.857467165262324,-1.7988289335811083,-0.011092073713488748
261.00000000000296,17.8926333468579,-1.7576656770958476,-0.01108887096676403
262.200000000003,17.92881049933728,-1.7226017590800138,-0.010946303382988631
263.40000000000305,17.964404532313935,-1.6938237451574367,-0.009781538665925904
264.60000000000304,18.000129161465228,-1.6721724482719478,-0.009779953398170615
265.800000000003,18.036197574196414,-1.6550536631206318,-0.009779396759099779
267.00000000000307,18.072157859991254,-1.6393315042066885,-0.009718050028305836
268.2000000000031,18.108134646299924,-1.6278153795223,-0.011100967074522572
269.4000000000031,18.14404173399651,-1.6201473129283197,-0.011074118275097078
270.6000000000031,18.180165947399317,-1.6138095766241844,-0.00955262572568838
271.80000000000314,18.21629965391804,-1.6063740482008801,-0.009559317270495526
273.0000000000032,18.252379083048663,-1.6027471727467857,-0.011078200733623866
274.2000000000032,18.28823976894648,-1.6006372398146071,-0.012620011683665666
275.40000000000316,18.32479664760169,-1.5981255808713362,-0.013930502544012846
276.6000000000032,18.360822650563215,-1.5982045004105883,-0.013950040450557921
277.80000000000325,18.39692672466094,-1.5971087358023586,-0.013950099959878948
279.00000000000324,18.433114869166424,-1.5966387737038685,-0.013944458002042914
280.20000000000323,18.469294210336976,-1.5949557204848754,-0.015268180122582464
281.4000000000033,18.505618322306034,-1.5967519249091326,-0.015270231672956491
282.6000000000033,18.54149254546904,-1.595461074175772,-0.015269901847746237
283.8000000000033,18.57808773777275,-1.5958420483426992,-0.015269759180243092
285.0000000000033,18.614052786519323,-1.5971666005460556,-0.015258200378994502
286.20000000000334,18.650416854773,-1.5954896189991368,-0.01424759595603664
287.4000000000034,18.68679523776498,-1.5976296919273913,-0.014269654086269679
288.6000000000034,18.72288721478301,-1.5980077326816249,-0.013955688955630485
289.80000000000337,18.758302751053634,-1.5980784088843176,-0.01394977956582899
291.0000000000034,18.79484073294187,-1.599937567832496,-0.013943601676618123
292.20000000000346,18.831008712886742,-1.600330529605797,-0.015065206645222595
293.40000000000344,18.86716145898165,-1.6018770323494387,-0.015260335039089412
294.60000000000343,18.903830148950004,-1.60143047763993,-0.015262518670060565
295.8000000000035,18.94055101088455,-1.6021684319967446,-0.01664810238731862
297.0000000000035,18.976363532518356,-1.6032608166843367,-0.016578909258745167
298.2000000000035,19.012961549226517,-1.6056860201628038,-0.016579852226387803
299.4000000000035,19.04941966563154,-1.6063438646044994,-0.016579660956188125
300.60000000000355,19.085360922691272,-1.6077119453450694,-0.017976497949832027
301.8000000000036,19.12205250846828,-1.6091062377101575,-0.01790052061032421
303.0000000000036,19.158395955736584,-1.6092497554005294,-0.017900037352271525
304.20000000000357,19.19470580129863,-1.6102752644951732,-0.01789460083327299
305.4000000000036,19.230995833348036,-1.6104685849637783,-0.01920006753049508
306.60000000000366,19.26652713836471,-1.613334215198662,-0.019220080376844084
307.80000000000365,19.303454492917144,-1.6157842478528128,-0.019219589856406483
309.00000000000364,19.33904502267801,-1.6164965171540102,-0.01922081218279237
310.2000000000037,19.375783534033562,-1.619018712433608,-0.02056389350124954
311.40000000000373,19.412865951074792,-1.6222585329939643,-0.020529923507927705
312.6000000000037,19.4489903932199,-1.6243052589457843,-0.020533002806728984
313.8000000000037,19.485364999560215,-1.6260337304130497,-0.02097254803064752
315.00000000000375,19.521613321330296,-1.6288112431858837,-0.02053122335362101
316.2000000000038,19.557426836244336,-1.6323237368005907,-0.020525288132904773
317.4000000000038,19.594129277054968,-1.6351050968356686,-0.021824402642494523
318.6000000000038,19.630705084118194,-1.636970006488835,-0.02366891684800221
319.8000000000038,19.667435909828967,-1.6392112409075508,-0.02416090707975327
321.00000000000387,19.703802042872628,-1.642150445127169,-0.024156812283322004
322.20000000000385,19.740254151222814,-1.6474554700917976,-0.024900109653353653
323.40000000000384,19.776482891509787,-1.6494501222415086,-0.0254718149262807
324.6000000000039,19.813541742160666,-1.65301344231693,-0.02546506747857835
325.80000000000393,19.849739221010452,-1.6542818506549088,-0.026785565672510003
327.0000000000039,19.88647561686419,-1.656626928179831,-0.025450165826357285
328.2000000000039,19.922788885307295,-1.6610696708476218,-0.026841207941797673
329.40000000000396,19.959201198553984,-1.66173508701954,-0.026789957450714663
330.600000000004,19.9957803441674,-1.6641897069520963,-0.027949657936565675
331.800000000004,20.03254342115308,-1.665621368933932,-0.029329153963161048
333.000000000004,20.069200614522057,-1.6700819404764433,-0.0308515572336594
334.200000000004,20.10600723091891,-1.6724921644723987,-0.031153165153285922
335.40000000000407,20.142787444674234,-1.6758231984154057,-0.03376467446545517
336.60000000000406,20.17950421050284,-1.677747804904619,-0.035041482682224956
337.80000000000405,20.216133926189105,-1.6803800913874247,-0.03700569698070133
339.0000000000041,20.25281808787285,-1.6858325598243933,-0.03757855784179975
340.20000000000414,20.289532803647926,-1.687297873463385,-0.03976157300915828
341.4000000000041,20.326372644659145,-1.6914467441109489,-0.04091104473171736
342.6000000000041,20.362808142550236,-1.69504534128001,-0.04255135554367451
343.80000000000416,20.399562765928923,-1.6954329220819184,-0.04424268686057431
345.0000000000042,20.436736330889588,-1.6992414034307133,-0.04659187196879744
346.2000000000042,20.473273283428533,-1.7017681925038495,-0.04924225006057359
347.4000000000042,20.510128798598238,-1.7040876532399265,-0.050281944260079925
348.60000000000423,20.547086327866182,-1.7043025284866944,-0.053218453306661306
349.8000000000043,20.58377427120037,-1.7025980558525258,-0.056572884576960636
351.00000000000426,20.620385291891758,-1.7029377984348986,-0.05889935291509296
352.20000000000425,20.65744887168947,-1.7028305186927368,-0.06222461767094112
353.4000000000043,20.694005693637113,-1.7036810228827717,-0.06503248553818208
354.60000000000434,20.731157903236305,-1.7010597351364025,-0.06893166534419226
355.80000000000433,20.767713893047052,-1.6995573884582438,-0.07323559931945534
357.0000000000043,20.80473472474814,-1.6965346360858418,-0.07830333400729605
358.20000000000437,20.84140546200807,-1.6936182257087347,-0.08281737769449915
359.4000000000044,20.878409537840174,-1.6887457427661032,-0.08786578576491788
360.6000000000044,20.91510208640111,-1.685995069079481,-0.09219951104560842
361.8000000000044,20.95206875357415,-1.6839806063042526,-0.09692014735074705
363.00000000000443,20.989234432201926,-1.6805432720941529,-0.10166746120493686
364.2000000000045,21.025855245997228,-1.6767057507728236,-0.10638778931086756
365.40000000000447,21.062616333811988,-1.6740406454836636,-0.11205253501002543
366.60000000000446,21.098816469650615,-1.6724149555363503,-0.11718585971145501
367.8000000000045,21.13693653606247,-1.6720879491611038,-0.1237953601777062
369.00000000000455,21.173701394539847,-1.6714935675796465,-0.12963567168307133
370.20000000000454,21.21064848247001,-1.673130261912503,-0.13557074575965267
371.4000000000045,21.247438726693712,-1.6751196691427546,-0.14045806188913978
372.60000000000457,21.28485523952819,-1.677549175507093,-0.14597701901016302
373.8000000000046,21.321607610177004,-1.68068808532815,-0.15210262066037084
375.0000000000046,21.358803726481185,-1.6840538523293183,-0.15829834670066179
376.2000000000046,21.395694744389168,-1.6885994201560237,-0.162745972919494
377.40000000000464,21.433023389910964,-1.693284295623938,-0.16924209913632682
378.6000000000047,21.46988766656944,-1.6992861715369578,-0.17609624441078475
379.8000000000047,21.50739746328756,-1.7052113266036464,-0.1842701384787495
381.00000000000466,21.544208056835256,-1.7093719117549822,-0.1894131132596253
382.2000000000047,21.581379299131427,-1.7130716117692293,-0.19666599725040168
383.40000000000475,21.61877186184676,-1.718676900786474,-0.20251732876917394
384.60000000000474,21.655909610007676,-1.7268476492690714,-0.20947542786948148
385.80000000000473,21.693151162817614,-1.731819987361114,-0.2150086826430666
387.0000000000048,21.730594514032408,-1.7392100406454865,-0.22162141610339203
388.2000000000048,21.76770702415442,-1.7432523091098524,-0.22786270565110156
389.4000000000048,21.804587764812414,-1.7483929170582553,-0.2353108210837278
390.6000000000048,21.84150707383738,-1.752445867517579,-0.24122502217757136
391.80000000000484,21.87923479478551,-1.7580763172054803,-0.24790462055815876
393.0000000000049,21.91651425943325,-1.7618774766105734,-0.25471991315249953
394.2000000000049,21.95400815040261,-1.7649772313815606,-0.2623499233991886
395.40000000000487,21.991143608281465,-1.7683015809479747,-0.2696991462170786
396.6000000000049,22.028365658544526,-1.773390943195006,-0.2783457604528512
397.80000000000496,22.065648360698745,-1.7754252130655443,-0.28542917767719134
399.00000000000495,22.103067196149077,-1.77854796921428,-0.29219566794882024
400.20000000000493,22.14062643496058,-1.779972979789003,-0.2989719769307837
401.400000000005,22.17779043620383,-1.7822102487672251,-0.3058389345113439
402.600000000005,22.21536340061087,-1.785492613539736,-0.313769421959861
403.800000000005,22.252386161639997,-1.784934435594925,-0.32070058235124765
405.000000000005,22.289822628990844,-1.785138889096153,-0.32857740254599
406.20000000000505,22.327248445266186,-1.788301698054654,-0.33684296418430604
407.4000000000051,22.36475814269514,-1.7895769552839424,-0.34652885516664345
408.6000000000051,22.402009634960304,-1.7905792434685759,-0.35464665792338934
409.80000000000507,22.439353800285332,-1.7892334769034435,-0.3632315536164543
411.0000000000051,22.477155876358186,-1.790346740280812,-0.37029280232552386
412.20000000000516,22.514306570735382,-1.7893580096143848,-0.3787778328098743
413.40000000000515,22.552059444286655,-1.7911387852966272,-0.38839252110648825
414.60000000000514,22.589232699298407,-1.789283901788322,-0.39732208007140546
415.8000000000052,22.626969910968874,-1.7914773212581523,-0.40641848208679576
417.00000000000523,22.664343226957925,-1.7900504960209298,-0.41635267838114
418.2000000000052,22.702082352522396,-1.790358248114199,-0.42685809732775226
419.4000000000052,22.739617181281993,-1.789313658401598,-0.43550652895389375
420.60000000000525,22.776356729254317,-1.788971594001383,-0.44578475923364014
421.8000000000053,22.814646771279804,-1.789902548941915,-0.4586102470760496
423.0000000000053,22.851520753287733,-1.790813931166007,-0.46907020787906717
424.2000000000053,22.889813537976394,-1.7900243796058404,-0.4805334356778408
425.4000000000053,22.92732482181716,-1.7923773625201873,-0.4917647668128997
426.60000000000537,22.965012075912703,-1.7939249858588016,-0.5033760850104874
427.80000000000535,23.00251258928236,-1.7980619474582802,-0.515137062337689
429.00000000000534,23.04035454601433,-1.8017201685016302,-0.5268373055444155
430.2000000000054,23.07788895675032,-1.8083754322657977,-0.5406728051885614
431.40000000000543,23.115821928807236,-1.81426907091409,-0.554011815277867
432.6000000000054,23.153415066891856,-1.8244957496384933,-0.5680653902512729
433.8000000000054,23.191299048697843,-1.8350331754194698,-0.5849711136570024
435.00000000000546,23.229394527309648,-1.8485083578085326,-0.5999350995075501
436.2000000000055,23.267110862438795,-1.8623189478600854,-0.6160693789614178
437.4000000000055,23.30476756011479,-1.879715782372317,-0.6313949426212653
438.6000000000055,23.34304195459967,-1.8972585534467112,-0.6484519718574822
439.8000000000055,23.38114912390605,-1.9170599258577938,-0.6668681828277987
441.00000000000557,23.41913792811515,-1.9382702419478242,-0.6849242284824806
442.20000000000556,23.457153909862036,-1.9590602422453043,-0.70430339131565
443.40000000000555,23.49445510877197,-1.978095433184451,-0.7238244427717784
444.6000000000056,23.53293089458073,-1.9963254456572694,-0.7448859312161238
445.80000000000564,23.570981264936993,-2.0124732702254033,-0.7654395469709536
447.0000000000056,23.609106201595885,-2.029703132860673,-0.788608803626857
448.2000000000056,23.64736987973428,-2.0466202358749594,-0.8113351057789155
449.40000000000566,23.68534206348331,-2.059681664937198,-0.8333600263048462
450.6000000000057,23.723367917388366,-2.0768915731525217,-0.8575510939479942
451.8000000000057,23.761105768079435,-2.089718859005873,-0.8821599013385284
453.0000000000057,23.799135871397244,-2.1013244797364146,-0.9077768242994102
454.20000000000573,23.83752900521248,-2.1149621565339456,-0.9347906155771075
455.4000000000058,23.87585193789802,-2.1274250887323123,-0.9620830094486377
456.60000000000576,23.913803352214845,-2.137586852093806,-0.9904056094370088
457.80000000000575,23.95226059549409,-2.1478722540750863,-1.0202352112210114
459.0000000000058,23.99003298266144,-2.1569168060015462,-1.0501873288912709
460.20000000000584,24.028624942175774,-2.1626238712528187,-1.0794754687427406
461.40000000000583,24.066433973627472,-2.1658446642723614,-1.1080452553921085
462.6000000000058,24.104517719615114,-2.166666058209722,-1.1361238042742436
463.80000000000587,24.142668085778723,-2.164416056376313,-1.1653273975811222
465.0000000000059,24.179910691514443,-2.1563058257020953,-1.1924184698909701
466.2000000000059,24.217597713867708,-2.145184589746144,-1.218862582948797
467.4000000000059,24.25570749912558,-2.12922253418065,-1.2453266511284005
468.60000000000593,24.294218414503888,-2.109761575491539,-1.2699721994562485
469.800000000006,24.331994526180562,-2.0858354914875266,-1.2906823033656787
471.00000000000597,24.369818549678943,-2.0561257128988237,-1.3093477594394622
472.20000000000596,24.407497265550088,-2.0240780372438225,-1.3276880825641912
473.400000000006,24.44562475877036,-1.9900760943392057,-1.3440698387210608
474.60000000000605,24.483149891194053,-1.9522494877783176,-1.3586224797617268
475.80000000000604,24.520902712899186,-1.9166536991991925,-1.3726803375489842
477.000000000006,24.558594205388275,-1.8808653731129137,-1.3850394184703112
478.20000000000607,24.596362615300325,-1.8510137472228765,-1.3974499586165043
479.4000000000061,24.634351596368116,-1.8262798117306307,-1.4093576839594886
480.6000000000061,24.672143736977578,-1.8029198202398677,-1.4199391734532112
481.8000000000061,24.709886506920874,-1.7859884317483137,-1.4297394740341418
483.00000000000614,24.74802456028993,-1.7712274670522028,-1.4391398427017226
484.2000000000062,24.785598343800693,-1.76346505708901,-1.4484680522226316
485.4000000000062,24.824344769142506,-1.7586437961619477,-1.4578755290671217
486.60000000000616,24.862520189425634,-1.75669843695804,-1.4690038835972206
487.8000000000062,24.900635359155398,-1.755379224125151,-1.4795988613007207
489.00000000000625,24.93892069985077,-1.7560751117569253,-1.4894798161174307
490.20000000000624,24.97719968454534,-1.7566475993034356,-1.4988188966018852
491.40000000000623,25.015488421835926,-1.7631724737862666,-1.5109739398556843
492.6000000000063,25.053689129298824,-1.7649637290719165,-1.522188592180549
493.8000000000063,25.09171165815829,-1.76646290118699,-1.533128678301729
495.0000000000063,25.130124296252667,-1.7657844246658019,-1.5448100758076757
496.2000000000063,25.168426085469605,-1.7618013790034586,-1.5566931139066802
497.40000000000634,25.206896276654845,-1.7529169101906574,-1.5675382672343758
498.6000000000064,25.24474799865658,-1.7393358594043764,-1.5801574344089802
499.8000000000064,25.28267679902352,-1.7161936356797252,-1.5920080148007192
501.00000000000637,25.32112422579961,-1.6887799150917724,-1.6017791410052986
502.2000000000064,25.35901196734919,-1.6607617212033194,-1.6116889361957227
503.40000000000646,25.39703654541197,-1.62270121570038,-1.6210142634184153
504.60000000000645,25.43500832709363,-1.5822506484946295,-1.6286638970673843
505.80000000000643,25.4726899442233,-1.5383920388474985,-1.6354402015780245
507.0000000000065,25.51051768186463,-1.4945022584017875,-1.640606694368012
508.2000000000065,25.54859189005017,-1.4564864975282537,-1.6442942430358496
509.4000000000065,25.5862876861084,-1.4234727288478852,-1.647691162390811
510.6000000000065,25.62473742365684,-1.400499581009324,-1.6512116654118651
511.80000000000655,25.66262509740916,-1.381199347344618,-1.6520174765777145
513.0000000000066,25.701206223116937,-1.3673904663946101,-1.6539406291992877
514.2000000000066,25.739201702239097,-1.365546688611729,-1.655309706961885
515.4000000000066,25.777974690919503,-1.3604250681102255,-1.6566515600971345
516.6000000000066,25.81650297475903,-1.3605548910515106,-1.6582333852777458
517.8000000000067,25.85488790068809,-1.36243831798526,-1.6584883270385031
519.0000000000066,25.893348413534483,-1.365475006432935,-1.6595144933624035
520.2000000000066,25.93217824714136,-1.3697404141775538,-1.660808616204136
521.4000000000067,25.970454255914483,-1.3727094056070264,-1.6607747480117605
522.6000000000067,26.00929657121462,-1.3785145033473294,-1.6621177637927582
523.8000000000068,26.04791261460791,-1.3832701324302712,-1.6635695498786838
525.0000000000067,26.08638564226978,-1.3877650746659136,-1.6650800646429342
526.2000000000068,26.125001686109,-1.3931030582989807,-1.6663712913629842
527.4000000000068,26.163784314628984,-1.4000272983872557,-1.6676938594720063
528.6000000000067,26.202467541271837,-1.4066794758454995,-1.667714218610318
529.8000000000068,26.240696579501464,-1.411526938316486,-1.6685860924291678
531.0000000000068,26.279938361171457,-1.4204827513167038,-1.6696819057032228
532.2000000000069,26.31878131417541,-1.4271034429615006,-1.6711021422922467
533.4000000000069,26.357278642619562,-1.4338282646869356,-1.6726366742790684
534.6000000000068,26.3963819780194,-1.440540602700342,-1.673852480037353
535.8000000000069,26.434980186208666,-1.4482573060043094,-1.675080885836374
537.0000000000069,26.47392573630017,-1.4556756817673595,-1.676349011603941
538.2000000000069,26.51286132198622,-1.4609612078841452,-1.6786335724257797
539.4000000000069,26.551574504804428,-1.4705426231174674,-1.6785019999400355
540.600000000007,26.590648271722905,-1.4776847532070574,-1.6792326818285819
541.800000000007,26.62936493565294,-1.4845844777338444,-1.6802456504247596
543.000000000007,26.66777673086629,-1.4900069823551516,-1.6815126169224888
544.200000000007,26.70716271928581,-1.4964214750181035,-1.6833646074414776
545.400000000007,26.74626361189787,-1.5038580197446567,-1.6848758276467728
546.6000000000071,26.785301212013234,-1.5110706896969297,-1.6864482380905224
547.800000000007,26.824069627907015,-1.5179875482328866,-1.687687623263511
549.000000000007,26.86321480832307,-1.5241539714244023,-1.6881367901442874
550.2000000000071,26.90239323491141,-1.5288489329662769,-1.6929914353297986
551.4000000000071,26.94126946010496,-1.5327732422738165,-1.6957515560514023
552.6000000000072,26.98031789188098,-1.5401616667214062,-1.692842482771284
553.8000000000071,27.019201195691718,-1.5462392196563501,-1.6908170182520155
555.0000000000072,27.058159405880538,-1.5496664669324747,-1.6918343194825973
556.2000000000072,27.097487603003703,-1.5565086787500853,-1.6931931035751662
557.4000000000071,27.136762331494534,-1.5595273936386833,-1.6958229218448064
558.6000000000072,27.175955686499503,-1.5637924215524952,-1.6973511515699888
559.8000000000072,27.215013577471318,-1.5691482128906884,-1.6986033761869725
561.0000000000073,27.25442702361579,-1.5730321787436012,-1.699991780100203
562.2000000000073,27.29342146867912,-1.5799539706221297,-1.701292758362896
563.4000000000073,27.33204421363339,-1.583924526054216,-1.7022146919894108
564.6000000000073,27.371650943512467,-1.5866681829576632,-1.7044075966320018
565.8000000000073,27.410758002093235,-1.5957407623423303,-1.705812438507175
567.0000000000073,27.450090040203772,-1.5996444535790557,-1.7084567840805986
568.2000000000073,27.489558351225725,-1.6044583408365936,-1.7097588111204036
569.4000000000074,27.52845438865119,-1.6114340206186062,-1.7110774965444477
570.6000000000074,27.568005757514403,-1.6150425061142066,-1.7126452054017571
571.8000000000075,27.60712314148324,-1.6196045198744766,-1.7138579050362024
573.0000000000074,27.646362583693513,-1.624653462996583,-1.7146279747108575
574.2000000000074,27.685574841459736,-1.6352892828345598,-1.7165203393190462
575.4000000000075,27.72487839414099,-1.640408120103155,-1.7185604444314118
576.6000000000074,27.76450511449931,-1.6460344695557505,-1.7199493552836627
577.8000000000075,27.803513001323783,-1.6558500967126266,-1.7212502160936793
579.0000000000075,27.842601749370836,-1.6618898095305197,-1.721530960819457
580.2000000000075,27.88197952235573,-1.6690222861196187,-1.7240094622210433
581.4000000000076,27.92162797355266,-1.678756341767405,-1.726177807185167
582.6000000000075,27.960751306523424,-1.6887802768145863,-1.7276587257422213
583.8000000000076,27.99976122977794,-1.6967797346247966,-1.7295972528274786
585.0000000000076,28.039365941154205,-1.7052660180528352,-1.7325055874154263
586.2000000000075,28.079072081377895,-1.7143968370409426,-1.7340249531215153
587.4000000000076,28.118240344405642,-1.7206313308992691,-1.7365657482577261
588.6000000000076,28.157581339279112,-1.7317639548385382,-1.7388690724863216
589.8000000000077,28.197212923424818,-1.739678221731574,-1.7403939480856279
591.0000000000077,28.23677506076122,-1.749405268866421,-1.741747934484514
592.2000000000077,28.27629599152532,-1.7599973188559668,-1.7450014443343718
593.4000000000077,28.31558794549243,-1.770838931719266,-1.7478583458120758
594.6000000000078,28.355150442521936,-1.7832014646847036,-1.750577210464379
595.8000000000077,28.394477633402648,-1.7980537466417321,-1.7538902990392113
597.0000000000077,28.43414260436111,-1.812584355259141,-1.7569473160346951
598.2000000000078,28.474036898578486,-1.827956688255166,-1.7597393915450792
599.4000000000078,28.513013515546323,-1.847271012608597,-1.7629584600860846
600.6000000000079,28.55295386319823,-1.8676524014927796,-1.7667984082293726
601.8000000000078,28.59279033482599,-1.8886799501238443,-1.7712318945880816
603.0000000000078,28.632271520012445,-1.9122964145244452,-1.7752115350354072
604.2000000000079,28.67187575902743,-1.937231292683821,-1.7803942608424737
605.4000000000078,28.711673852866227,-1.9582420689103666,-1.7849819123561943
606.6000000000079,28.751495921810996,-1.9792364699718838,-1.7890989596864926
607.8000000000079,28.791310301143152,-1.9960007942911766,-1.794631888038822
609.000000000008,28.831034043180043,-2.0123338015972645,-1.7998368142524481
610.200000000008,28.870700906612157,-2.0244223400488313,-1.80420006269163
611.4000000000079,28.91022453574318,-2.0355955267516026,-1.811467192009903
612.600000000008,28.949945914690066,-2.0426358334496175,-1.8186003176071113
613.800000000008,28.989563866790803,-2.053218481821342,-1.8248732677811033
615.000000000008,29.029069918582206,-2.0615275457812188,-1.833485739535429
616.200000000008,29.06860389557972,-2.070741691324484,-1.8394147280888893
617.400000000008,29.10830713169756,-2.078159194709654,-1.8468667905308407
618.6000000000081,29.148170218212414,-2.08693647864051,-1.8541245401986886
619.8000000000081,29.187597861528957,-2.0927446785493418,-1.862247270597872
621.0000000000081,29.227277110075587,-2.1017876155942874,-1.8716535511335173
622.2000000000081,29.26682311204833,-2.1072353849439605,-1.8802973427625482
623.4000000000082,29.30662380087894,-2.112468100636199,-1.8895330965156618
624.6000000000081,29.346155022936294,-2.117633318114311,-1.898926099704982
625.8000000000081,29.385811809222265,-2.1221339964393233,-1.9076577374194934
627.0000000000082,29.42541628699107,-2.1279605074002474,-1.9171088044293456
628.2000000000082,29.46511270019901,-2.134769411740232,-1.9266584620562206
629.4000000000083,29.50477308593589,-2.142714691766881,-1.936112624279184
630.6000000000082,29.544902119455763,-2.1506950290733524,-1.9462099474308032
631.8000000000083,29.584280543557966,-2.15600467119748,-1.9554249133591242
633.0000000000083,29.623973424695016,-2.161645115354482,-1.965306567071344
634.2000000000082,29.663663489693587,-2.1707041158262426,-1.9747150015588764
635.4000000000083,29.703232922585478,-2.174575977918841,-1.9848075156998575
636.6000000000083,29.743275606572485,-2.180782278888961,-1.9934646094927415
637.8000000000084,29.7824117932958,-2.1859808257318343,-2.0009316442198175
639.0000000000084,29.822611163619776,-2.198720114768414,-2.0070296439755135
640.2000000000083,29.862718681317865,-2.21063482786336,-2.0113865491489515
641.4000000000084,29.902403814547366,-2.2187523785469176,-2.0151919197496446
642.6000000000084,29.94247773687696,-2.222106089872536,-2.0174243078174854
643.8000000000084,29.98173087341241,-2.2229264937769093,-2.018953443982171
645.0000000000084,30.021628819159428,-2.2214485805029454,-2.021176703186291
646.2000000000085,30.061465118274075,-2.2178535079947306,-2.023235560518164
647.4000000000085,30.101124117436484,-2.213482836183135,-2.024554806929584
648.6000000000085,30.141210685687174,-2.2183860362876975,-2.026270371691212
649.8000000000085,30.18084745540881,-2.225452921904731,-2.0263822036517913
651.0000000000085,30.22076370971738,-2.237633735466622,-2.0277286138530295
652.2000000000086,30.26043557243968,-2.2518766052414017,-2.029048463548997
653.4000000000085,30.300524870311346,-2.2733311513293493,-2.02979290009314
654.6000000000085,30.339863437686382,-2.2947995146182234,-2.0315026342664972
655.8000000000086,30.380603057248678,-2.318890791867421,-2.0334455902053294
657.0000000000086,30.420632631883745,-2.3466759074160075,-2.034881860982031
658.2000000000087,30.46034982336489,-2.372997217030771,-2.0367278566212415
659.4000000000086,30.50055728720351,-2.4078388152159733,-2.0385748803013533
660.6000000000087,30.54040568047285,-2.434786543905785,-2.0406115496030433
661.8000000000087,30.58074802813864,-2.467777900172736,-2.0421281082676046
663.0000000000086,30.621006196030812,-2.4981787257840913,-2.043609160342723
664.2000000000087,30.66122821327269,-2.533086760329033,-2.0439120291465893
665.4000000000087,30.701237072936596,-2.567454173629128,-2.047339007707572
666.6000000000088,30.74122319396329,-2.6012747440035073,-2.048877501909976
667.8000000000088,30.78164229687408,-2.6347958428288623,-2.0510700211474564
669.0000000000088,30.821359089627528,-2.670099277767326,-2.0538315274409498
670.2000000000088,30.86178507861935,-2.7053166808136813,-2.055277582138697
671.4000000000088,30.902153797216528,-2.7429159249968365,-2.0581620320142346
672.6000000000088,30.942327104897302,-2.781756513601911,-2.060071952955898
673.8000000000088,30.9826484598964,-2.824930318805444,-2.0631183882608135
675.0000000000089,31.02296985943926,-2.86611199924105,-2.065607881710151
676.2000000000089,31.063057245598156,-2.910688419558838,-2.0686159994376636
677.400000000009,31.103345309199852,-2.9599633411922244,-2.0706443659449922
678.6000000000089,31.143697187579836,-3.0087286902215267,-2.0734905215495063
679.8000000000089,31.183868879623226,-3.060972118889601,-2.077058202258071
681.000000000009,31.22441694917575,-3.1142869148746355,-2.0792429641061947
682.2000000000089,31.264742113275066,-3.1691093602076736,-2.082487048094938
683.400000000009,31.305223258017183,-3.228644066080873,-2.0853107301271177
684.600000000009,31.34584867597273,-3.285686394905883,-2.089794364765345
685.800000000009,31.386387583962183,-3.3453882213035246,-2.0937751863993666
687.0000000000091,31.42668592151928,-3.407822629503983,-2.097520962729313
688.200000000009,31.466990507689278,-3.4679673091089587,-2.1025494456391165
689.4000000000091,31.50767978334272,-3.533088857178751,-2.1066467457172124
690.6000000000091,31.548204026696354,-3.6005276279527427,-2.1101748103373295
691.800000000009,31.58836780018673,-3.667362817707168,-2.11518400306134
693.0000000000091,31.629137228067304,-3.7357958502688056,-2.120355801345159
694.2000000000091,31.670056167355195,-3.804461162944705,-2.12431663761702
695.4000000000092,31.710592901090486,-3.8762606190015205,-2.129913942464053
696.6000000000092,31.7511124684541,-3.9460074995667718,-2.134600575949827
697.8000000000092,31.791683600575404,-4.020314071470718,-2.139106571038927
699.0000000000092,31.832463339883336,-4.095743434609164,-2.144600988060925
700.2000000000093,31.873176133409572,-4.1688975398890955,-2.1505649200590264
701.4000000000092,31.913527040158414,-4.244850079655418,-2.1561061776502313
702.6000000000092,31.9543075836868,-4.319751286478505,-2.162126791604406
703.8000000000093,31.994918720731025,-4.398679047058868,-2.1668764493629213
705.0000000000093,32.03580236222887,-4.4753255875225175,-2.17174886621663
706.2000000000094,32.07587912688791,-4.553297614087611,-2.1795571228989687
707.4000000000093,32.11704494395545,-4.632475573901834,-2.1867602498241565
708.6000000000093,32.15776945135545,-4.710495534089804,-2.193914109880395
709.8000000000094,32.19855782099347,-4.7899081796860274,-2.201143373888118
711.0000000000093,32.23972103277103,-4.871139683508779,-2.2081987506191885
712.2000000000094,32.27954220290876,-4.9505970294973265,-2.2162648815217962
713.4000000000094,32.321158415604245,-5.029716950037096,-2.2244495443004473
714.6000000000095,32.362001085340296,-5.109926086576645,-2.231277390008369
715.8000000000095,32.40265797745726,-5.190410209960009,-2.2383961321979378
717.0000000000094,32.44333902149834,-5.2723974838566185,-2.246838849604401
718.2000000000095,32.48409811629956,-5.352378870152643,-2.253136086380735
719.4000000000095,32.52487714749085,-5.435889813875881,-2.262864415319127
720.6000000000095,32.565831537571846,-5.517160162954116,-2.2727480410399448
721.8000000000095,32.60654952304253,-5.6010553756663395,-2.2821479003135776
723.0000000000095,32.647272227331854,-5.676024529066846,-2.2858423702449504
724.2000000000096,32.68833593613675,-5.759139290160641,-2.2942426619926763
725.4000000000096,32.729067852686526,-5.844269060100535,-2.312551118938612
726.6000000000096,32.76975603779799,-5.9262531110927466,-2.3228281752531257
727.8000000000096,32.810915752001506,-6.01378059111886,-2.3317375468396326
729.0000000000097,32.85174756557383,-6.105933375421348,-2.3409181922333695
730.2000000000096,32.89251130252394,-6.199820311224491,-2.3509255470057973
731.4000000000096,32.93376430478499,-6.299639715011436,-2.36198944024735
732.6000000000097,32.97478687163683,-6.403825069949389,-2.3721562279461033
733.8000000000097,33.015234016374045,-6.513111946633737,-2.3812246062754596
735.0000000000098,33.05697514819736,-6.628770334174011,-2.392009768764137
736.2000000000097,33.09837834910203,-6.747005623026004,-2.401798608034556
737.4000000000098,33.13943997733212,-6.8702093781329046,-2.4129983017283605
738.6000000000098,33.180525561029604,-6.994524880394025,-2.4252065409268413
739.8000000000097,33.22201465945181,-7.125041756732016,-2.437233291821747
741.0000000000098,33.26344923519676,-7.243549832034477,-2.450696386930211
742.2000000000098,33.304287417725526,-7.364160881569935,-2.462022595647222
743.4000000000099,33.345609436320444,-7.4766652298195035,-2.473780686606102
744.6000000000099,33.386637333816076,-7.582734196106929,-2.487999182327867
745.8000000000098,33.42713891448587,-7.675905746131712,-2.501016425360072
747.0000000000099,33.46824866772093,-7.759717313786629,-2.5133155963476455
748.2000000000099,33.5094133428999,-7.826949798611935,-2.526742393769646
749.4000000000099,33.549845874901465,-7.875437812569501,-2.5406233482597247
750.6000000000099,33.5906303583146,-7.905852312183,-2.554490765840791
751.80000000001,33.630639271741735,-7.907524382675526,-2.5683322037533496
753.00000000001,33.67089091734291,-7.889170834395457,-2.58169834211749
754.20000000001,33.710652637124326,-7.84291603422425,-2.595205057215364
755.40000000001,33.75029571758891,-7.762224560398211,-2.6081520212064677
756.60000000001,33.78948555370468,-7.638281270522825,-2.619414113396725
757.8000000000101,33.82829183772416,-7.461786731481739,-2.6322135648398346
759.00000000001,33.86668920483551,-7.208532565376715,-2.6440889786503083
760.20000000001,33.9041873131045,-6.876039874409683,-2.655082204025621
761.4000000000101,33.94079066826805,-6.432150148094221,-2.665457968468931
762.6000000000101,33.97532654133505,-5.737488143239389,-2.674920997468149
763.8000000000102,34.00880928826636,-4.874100975647025,-2.682050453308344
765.0000000000101,34.042771387303,-4.035758495147704,-2.687104750931922
766.2000000000102,34.07798719772942,-3.4166376666201366,-2.6884952638137083
767.4000000000102,34.114651793764665,-2.9856902528097695,-2.6908098292679714
768.6000000000101,34.152207209784365,-2.7028959925492004,-2.6917506927713135
769.8000000000102,34.19012567881403,-2.518697188480657,-2.69287111147524
771.0000000000102,34.2298538216688,-2.3982779588489356,-2.693213548855367
772.2000000000103,34.26926955967729,-2.3241239098446695,-2.6945330848181586
773.4000000000103,34.309105388893954,-2.273961063155115,-2.6945298412774488
774.6000000000103,34.348470430212245,-2.241648436643964,-2.6958374909166265
775.8000000000103,34.38900301861298,-2.221429043882222,-2.695839934007502
777.0000000000103,34.4292384714398,-2.2039588856636643,-2.6958398934476726
778.2000000000103,34.469374107731184,-2.1945509978838946,-2.696516795641231
779.4000000000103,34.50877534200325,-2.191449871198106,-2.6971603346667945
780.6000000000104,34.54972201151571,-2.189494608679521,-2.6971602818703646
781.8000000000104,34.589789793903925,-2.190734517525746,-2.6985097116953187
783.0000000000105,34.63023144280853,-2.193586152912946,-2.697913660343348
784.2000000000104,34.67021442778916,-2.197931341091084,-2.6985035995283426
785.4000000000104,34.710881573860014,-2.2002895906914692,-2.698480214125672
786.6000000000105,34.75164191481299,-2.2031957344154485,-2.698479906740119
787.8000000000104,34.79189549790194,-2.211216178267509,-2.6984525726375694
789.0000000000105,34.832342478126115,-2.218062796420362,-2.6997782610035097
790.2000000000105,34.87300545744522,-2.2238160325564795,-2.7001164483708386
791.4000000000106,34.91363876376643,-2.2285000273720934,-2.701109926265432
792.6000000000106,34.95405820579804,-2.2353296950772283,-2.7009764747126237
793.0000000000106,34.96737855373908,-2.2390517330818667,-2.699946164205361