File: 01_Data/Polyester_Carpet_High_Pile/STA/N2/30K_min/Polyester_Carpet_High_Pile_STA_N2_30KData_230925_R1.csv
##Temp./Â°C,Time/min,DSC/(mW/mg),Mass loss/mg
51.0,10.613816451936428,-2.247307997844839,0.0037199416570192767
52.20000000000002,10.790138814732119,-2.2036923296670383,0.0006487147842006991
53.400000000000034,10.91258418289322,-2.1672248473411955,0.0006114997679809164
54.60000000000005,11.011098907473704,-2.133995452133198,0.001222510425997747
55.80000000000007,11.096708192689082,-2.1061148560618568,0.0023581461145978366
57.000000000000085,11.172514186618766,-2.07971718328352,0.0010809801066118396
58.2000000000001,11.242626889364843,-2.0535783289201803,-1.1756402935603205e-06
59.40000000000012,11.308082173324046,-2.028680536741519,0.001409722454881468
60.600000000000136,11.369283483684056,-2.005578260331964,0.0005839357841503912
61.80000000000015,11.427895403992247,-1.9828273259197418,0.0014496790255549286
63.00000000000017,11.484219162422656,-1.9618357110575162,0.002789447728395622
64.20000000000019,11.538445558118056,-1.9425165599200678,0.0021115535915114947
65.4000000000002,11.589419785382635,-1.9240308599902889,0.0003810414188274436
66.60000000000022,11.64129321729092,-1.9059378554280104,0.0002492077596469855
67.80000000000024,11.692012665524834,-1.8877640095322052,0.0007331705977042802
69.00000000000026,11.740963388149602,-1.8712434492560364,-0.0005779004030985746
70.20000000000027,11.78951904110253,-1.8540318759455199,-0.0010533853898593293
71.40000000000029,11.836401290780664,-1.8391129958245656,7.670933389292145e-05
72.6000000000003,11.882813115997454,-1.8234370661891919,0.0004440750848528907
73.80000000000032,11.92919570373001,-1.809756664479616,0.0016507534431111637
75.00000000000034,11.974479570349393,-1.796783642769995,0.0007390265692990283
76.20000000000036,12.019574041115728,-1.7838695522804886,0.00042709267315732546
77.40000000000038,12.063551913851851,-1.7706633452815117,-0.0008824668976483707
78.60000000000039,12.107722763248262,-1.7585398818068168,-0.0009227445557460356
79.80000000000041,12.1515872173379,-1.7430805481287424,0.000406194895189671
81.00000000000043,12.194184416700077,-1.7292134065571074,0.00041735595284553284
82.20000000000044,12.237477100706856,-1.7117308885962466,0.0006123043141599283
83.40000000000046,12.279778894773639,-1.690886603771411,0.000675372470725577
84.60000000000048,12.322173852977052,-1.6766147445738053,0.00010334276965640043
85.8000000000005,12.364429018775136,-1.6597059644228496,0.0005660544594503492
87.00000000000051,12.406132983176171,-1.6430768157398636,0.0004517419463825334
88.20000000000053,12.448077371702986,-1.6294365657968544,0.0007381398897461366
89.40000000000055,12.489194862673633,-1.6172128268779282,-0.00018772745937489788
90.60000000000056,12.530367593948265,-1.6026901529500073,-0.0007785034022029791
91.80000000000058,12.571263625496146,-1.5893692367018533,-0.0007066931187145187
93.0000000000006,12.612157548375235,-1.5783167270700504,0.0002597378351651969
94.20000000000061,12.653047263830961,-1.5644851480350541,0.00039836687720296027
95.40000000000063,12.694007147418347,-1.5549485901324684,-0.0007048423942057624
96.60000000000065,12.733999210802889,-1.543051616207335,-0.0006390001522662558
97.80000000000067,12.773725973011192,-1.5332310199240264,-0.002005231317355083
99.00000000000068,12.815179492261809,-1.5237022399629339,-0.0016660439006406236
100.2000000000007,12.854898089156398,-1.5158515012909008,-0.0010457002610086974
101.40000000000072,12.89500340122381,-1.5065002832146925,-0.0013152708220607323
102.60000000000073,12.935646608053487,-1.4989086958073095,-0.0011677499514926026
103.80000000000075,12.97556235774868,-1.4914471919137864,-0.0007813283718425268
105.00000000000077,13.015192130942708,-1.4845186307375144,-0.002106221477497172
106.20000000000078,13.055607120714665,-1.4770319905455902,-0.002270192486542477
107.4000000000008,13.095417039215702,-1.4690658715170275,-0.003400564998350397
108.60000000000082,13.135224246317561,-1.4653436092760275,-0.0020439136660348467
109.80000000000084,13.17502210285155,-1.4577938837677769,-0.0020583392561981384
111.00000000000085,13.214974791275319,-1.4520476917158716,-0.00207048642309271
112.20000000000087,13.25492005741383,-1.4484960587266968,-0.0020898780503841863
113.40000000000089,13.294720324713232,-1.4407734530897975,-0.00207729200105522
114.6000000000009,13.334340208840091,-1.4362473842495214,-0.0007155987423033139
115.80000000000092,13.374286705682497,-1.4301843518363517,-0.0007832412608763661
117.00000000000094,13.413788846951649,-1.4256363157338994,-0.0021370512790577223
118.20000000000095,13.453208506974153,-1.419689388070394,-0.002091544377635479
119.40000000000097,13.493061141769966,-1.4163318115969152,-0.0023585701700543638
120.60000000000099,13.532863294419254,-1.4115254781206048,-0.0033531036303706685
121.800000000001,13.572074022372032,-1.4054222938166747,-0.0027485699422697962
123.00000000000102,13.611687014234953,-1.4018980061927353,-0.0027513195804305113
124.20000000000104,13.650863448768636,-1.3951122092166732,-0.0026033774296880807
125.40000000000106,13.690331494902187,-1.3901105138637635,-0.003408960856924992
126.60000000000107,13.729297984820523,-1.3877048845869777,-0.003410893272112858
127.80000000000109,13.76890223342565,-1.3826031238961831,-0.002782608584135815
129.0000000000011,13.807947378733074,-1.3789045846507788,-0.0030908703430734263
130.20000000000113,13.84687594679208,-1.373976818560389,-0.0030907695544133418
131.40000000000114,13.886234696817812,-1.3703283475537178,-0.00329545850990165
132.60000000000116,13.924770143001009,-1.3658604851284906,-0.003409563146210992
133.80000000000118,13.963812043755874,-1.36271056417067,-0.0034101380558206884
135.0000000000012,14.002823393305261,-1.3575870018802945,-0.003410345012584415
136.2000000000012,14.041328616739769,-1.356130377608379,-0.0034277946476848342
137.40000000000123,14.080195601450491,-1.3520100464937552,-0.0030662615386409797
138.60000000000124,14.119034426881388,-1.348536472705044,-0.004072320295295917
139.80000000000126,14.157409151284375,-1.345002400270468,-0.0040725221281947555
141.00000000000128,14.195811861376288,-1.3435635710626237,-0.0037128197014206776
142.2000000000013,14.234567580111701,-1.3415411638657322,-0.0037397451668796933
143.4000000000013,14.27299319131619,-1.3397349453862084,-0.003739935038158393
144.60000000000133,14.310856611684903,-1.3385274659727582,-0.0037399359798415688
145.80000000000135,14.348648483019833,-1.337869271387292,-0.0037399395845314487
147.00000000000136,14.388040466835125,-1.3384902014291367,-0.003740819095710002
148.20000000000138,14.425981834380552,-1.3393669578265428,-0.0041123171920052215
149.4000000000014,14.4634975399452,-1.3411377936062792,-0.004731329891167313
150.60000000000142,14.50255858106135,-1.3431261356013933,-0.004729374390074703
151.80000000000143,14.540801050888948,-1.348563102656427,-0.005507411966817699
153.00000000000145,14.57881692624934,-1.3534402915525017,-0.004733012958384464
154.20000000000147,14.61695611180213,-1.361116379045096,-0.004729915988538558
155.40000000000148,14.655448895538413,-1.372910080042846,-0.004729868331040166
156.6000000000015,14.693478703640741,-1.381909925456897,-0.00472986800175601
157.80000000000152,14.731612428338677,-1.3967584906263946,-0.0047298680000054105
159.00000000000153,14.770031849321043,-1.4078929721767743,-0.004729867999992088
160.20000000000155,14.80764926459727,-1.4223547585899379,-0.004729868028976014
161.40000000000157,14.8457946576819,-1.4350030405543777,-0.004729874327832562
162.6000000000016,14.88390018429111,-1.4408461317223835,-0.0047308034578659175
163.8000000000016,14.921768600707141,-1.438092285392447,-0.004281126063667706
165.00000000000162,14.95917351796615,-1.4301081319239197,-0.004031505231422372
166.20000000000164,14.99639803238295,-1.4120817329779483,-0.005060314014010636
167.40000000000165,15.033598929487717,-1.3883840346107106,-0.005060065276210501
168.60000000000167,15.071066974838237,-1.3594474830626788,-0.00505993523886783
169.8000000000017,15.108499032495509,-1.3332707027524895,-0.005041927183769168
171.0000000000017,15.145534849890659,-1.3102443624881912,-0.003703327880480778
172.20000000000172,15.182437149718908,-1.2903154196394513,-0.004072461398915372
173.40000000000174,15.2195283278349,-1.2719114182133933,-0.004087751189874034
174.60000000000176,15.256819324661745,-1.2578770037512457,-0.0050734699495533775
175.80000000000177,15.294066139254262,-1.2460948543749997,-0.005060176590916399
177.0000000000018,15.331444738011845,-1.2341022439499783,-0.00506133293709965
178.2000000000018,15.368595790746042,-1.2252046611734555,-0.005986118195610679
179.40000000000182,15.405258601954843,-1.2178319062937153,-0.005788546830293839
180.60000000000184,15.442536470891,-1.211838460741735,-0.0045047729263894
181.80000000000186,15.479543147378674,-1.204345093014568,-0.004510358458842845
183.00000000000188,15.516638616403457,-1.1985270164581894,-0.005154722545501755
184.2000000000019,15.553647926170836,-1.1935281494791308,-0.00583068093567185
185.4000000000019,15.590093925396399,-1.189617112647047,-0.005830160134118856
186.60000000000193,15.627429763858702,-1.184336592920321,-0.005830160101357507
187.80000000000194,15.6642631307327,-1.1806673008924669,-0.005830182516618265
189.00000000000196,15.701237576259343,-1.1761816671244827,-0.0058312932440323095
190.20000000000198,15.73840825284107,-1.1725365562958006,-0.005255758051298187
191.400000000002,15.774203306473265,-1.1696964801479404,-0.005171355891885554
192.600000000002,15.81151197742321,-1.165182471324771,-0.005170028106229907
193.80000000000203,15.848157885888817,-1.163678171722452,-0.005170102169325119
195.00000000000205,15.884789647676246,-1.1603382627816718,-0.00518692843593449
196.20000000000206,15.921652641780913,-1.1574850950956779,-0.005816674745961592
197.40000000000208,15.958429375154147,-1.1542591922374295,-0.005830268256145743
198.6000000000021,15.995117888261545,-1.1530130185736058,-0.005830161560848701
199.80000000000211,16.03178382955946,-1.150520773814325,-0.005830182506801229
201.00000000000213,16.06856292965597,-1.1482560124130046,-0.005836822233955097
202.20000000000215,16.104975333758492,-1.1472333355649171,-0.0046988955682953915
203.40000000000217,16.141404566342498,-1.1455108456846703,-0.004508514023403798
204.60000000000218,16.17810583533204,-1.1422205167083377,-0.005015143337469219
205.8000000000022,16.21465797867127,-1.1410987320311172,-0.006462692805510706
207.00000000000222,16.25147959551387,-1.140645349061001,-0.007459121727199758
208.20000000000223,16.287650910313758,-1.1380967445213601,-0.0074701384410529315
209.40000000000225,16.32437410464539,-1.136839193822936,-0.0074692751524843
210.60000000000227,16.36077298031676,-1.1380981432459736,-0.0077458999070865175
211.80000000000229,16.39742353802026,-1.135358433187583,-0.0077993402110836385
213.0000000000023,16.434146086995035,-1.1338178547234674,-0.007799994127033472
214.20000000000232,16.47030826680555,-1.1371999841273113,-0.007799996034306922
215.40000000000234,16.506896731664913,-1.135136929680463,-0.00779999600039627
216.60000000000235,16.54346117699498,-1.1331102425676725,-0.0077999960000010304
217.80000000000237,16.580119601877925,-1.1344955358486541,-0.007799996007201493
219.0000000000024,16.616342964324513,-1.1363259429418522,-0.00779999696946021
220.2000000000024,16.653133599002505,-1.1367198830582756,-0.00779997030782642
221.40000000000242,16.689485831819802,-1.1388405719976986,-0.007783841984558393
222.60000000000244,16.72601126216161,-1.1384469663548538,-0.0067888938955071865
223.80000000000246,16.762036562565257,-1.143361749246386,-0.00717039982342893
225.00000000000247,16.798622037446048,-1.145186183975303,-0.0071398923323853225
226.2000000000025,16.835380443449356,-1.1473256917970125,-0.007141293000876736
227.4000000000025,16.871651870625346,-1.152623606172198,-0.007228499420834034
228.60000000000252,16.90819457153051,-1.1570263814897266,-0.008048055325007297
229.80000000000254,16.944545468207178,-1.1605400515463853,-0.009762045785026707
231.00000000000256,16.981327617599035,-1.168772419437791,-0.00977970687928309
232.20000000000258,17.017476119522623,-1.1776136177458971,-0.009763825482163924
233.4000000000026,17.05426762364764,-1.1857456468393452,-0.008464198904635012
234.6000000000026,17.090603142610366,-1.196150146922153,-0.00845447250653919
235.80000000000263,17.1271975702577,-1.2094630519969165,-0.009805912464657673
237.00000000000264,17.16353781369812,-1.224702053244461,-0.010327121991708488
238.20000000000266,17.200212847319914,-1.2436777523085984,-0.011103288478638618
239.40000000000268,17.236989271516798,-1.2673165825955053,-0.01109981201102439
240.6000000000027,17.273666300962937,-1.2974288436407042,-0.011099799779888286
241.8000000000027,17.310624519875198,-1.3397469327677958,-0.011099799892878792
243.00000000000273,17.34756356877682,-1.3947147672711018,-0.011099843536934273
244.20000000000275,17.385099673442816,-1.461667038662803,-0.011108901541423855
245.40000000000276,17.421831209532144,-1.5393197811176305,-0.011426729375263456
246.60000000000278,17.460187680235773,-1.6295131353266052,-0.010495047000189217
247.8000000000028,17.497260911005675,-1.6991573758239111,-0.010957908186517429
249.0000000000028,17.534314009608554,-1.7434475599353767,-0.011098847066802087
250.20000000000283,17.570902530453754,-1.7444711624301674,-0.011100069170671745
251.40000000000285,17.606675900533105,-1.7147756820693991,-0.011100072082611767
252.60000000000286,17.641724197356332,-1.6575916578803787,-0.011100071942470535
253.80000000000288,17.67736173776931,-1.5895598816819587,-0.01110008063755874
255.0000000000029,17.712703155867455,-1.51706037087899,-0.011101044084658618
256.2000000000029,17.74805604112369,-1.4496209137104719,-0.0122661409574647
257.40000000000293,17.783470460504674,-1.3838917942392903,-0.012408032575133454
258.600000000003,17.81888744379675,-1.3315090108096788,-0.012409847314607703
259.80000000000297,17.85420394082857,-1.2842208131695263,-0.01240984021599889
261.00000000000296,17.889853985417556,-1.2429724999462182,-0.01240983977464083
262.200000000003,17.92550623989474,-1.2085944364215222,-0.012409356810779926
263.40000000000305,17.96145133876197,-1.1787877259837602,-0.01238265589812837
264.60000000000304,17.997356009893018,-1.156526327911239,-0.013733778618671089
265.800000000003,18.033253617978943,-1.1386379609527435,-0.013730134077897027
267.00000000000307,18.069145020593467,-1.1240276710051265,-0.013730532691681674
268.2000000000031,18.105029514536547,-1.1131764633996217,-0.013994559887976266
269.4000000000031,18.140791598617863,-1.1041441462117683,-0.01505160974697084
270.6000000000031,18.17681062160456,-1.095455469742689,-0.015049931960713359
271.80000000000314,18.213107200034454,-1.0901775254269412,-0.015049979629320198
273.0000000000032,18.249198076519022,-1.0858116327810903,-0.015049979998252638
274.2000000000032,18.285339872885334,-1.0816320570410694,-0.015049978786905172
275.40000000000316,18.321048306097367,-1.0796539367512845,-0.015049930425929503
276.6000000000032,18.357175025168665,-1.0789440081560544,-0.01506292849700408
277.80000000000325,18.393787951840007,-1.0759768680047637,-0.016430077765404505
279.00000000000324,18.42943090395879,-1.0751142044639865,-0.016366191455840173
280.20000000000323,18.46585969123817,-1.0730147837298483,-0.017529327900737357
281.4000000000033,18.501907529674778,-1.0705848894089385,-0.01867287942130158
282.6000000000033,18.537981822123225,-1.0705624564340732,-0.0186714645814261
283.8000000000033,18.57431048144128,-1.0702567786517287,-0.020083296634504144
285.0000000000033,18.61054147995386,-1.071341025660215,-0.019989549697305264
286.20000000000334,18.646821221742638,-1.0701705773767491,-0.020458930789674312
287.4000000000034,18.683071659570547,-1.069280602156029,-0.020648744834685928
288.6000000000034,18.71895049070835,-1.0701918827952566,-0.020647300170520744
289.80000000000337,18.75523009289168,-1.0692683327559531,-0.021373110108675597
291.0000000000034,18.79143139766215,-1.06837258989592,-0.02131017371839139
292.20000000000346,18.827620022461822,-1.0687328252503074,-0.021537901938423865
293.40000000000344,18.86384942684386,-1.069186896645123,-0.02164030536852568
294.60000000000343,18.900061273643498,-1.0700901916522534,-0.021641965168246458
295.8000000000035,18.936468140049442,-1.0703810573610497,-0.02287618428788374
297.0000000000035,18.972487710371663,-1.0696131156646536,-0.023615108278172592
298.2000000000035,19.00894542358905,-1.0713741479880499,-0.024849154025929465
299.4000000000035,19.045249247572293,-1.0709481299456514,-0.024918362924231552
300.60000000000355,19.081374395200534,-1.0703720815007634,-0.024914261015502426
301.8000000000036,19.11749326686352,-1.0705550352996367,-0.024446813240172283
303.0000000000036,19.153798834247834,-1.0710218929476647,-0.024931705150546435
304.20000000000357,19.190281155611626,-1.0717773813330829,-0.02493006737009651
305.4000000000036,19.226464120173922,-1.070929790202871,-0.02493277413978312
306.60000000000366,19.26214815767745,-1.0734570274907145,-0.02631654983660514
307.80000000000365,19.299312797499933,-1.0737375441875823,-0.026249755486947635
309.00000000000364,19.335885329061227,-1.0757947880808523,-0.02603342061811098
310.2000000000037,19.371790532802862,-1.078473461171858,-0.0264215400992871
311.40000000000373,19.40808937893831,-1.081249003024908,-0.027232757761813886
312.6000000000037,19.444676118588568,-1.0812937370020377,-0.02723027290539548
313.8000000000037,19.480988389441016,-1.0844268685554133,-0.02723746847906927
315.00000000000375,19.517359717596758,-1.0889179729469096,-0.02918487820908844
316.2000000000038,19.55370009016718,-1.0906749470006765,-0.029650998426939523
317.4000000000038,19.589877032928264,-1.0939409916124887,-0.028769680701942413
318.6000000000038,19.626477712276028,-1.098202794301656,-0.029790487332869375
319.8000000000038,19.662925948800332,-1.1016160161920785,-0.03022032070789127
321.00000000000387,19.699788433679938,-1.106670009979521,-0.031408829583669196
322.20000000000385,19.73591772410103,-1.1085796108150432,-0.03267401293104211
323.40000000000384,19.772462538934146,-1.1140463446875826,-0.032720137869097776
324.6000000000039,19.80892280335775,-1.1172270790721983,-0.0327283066180426
325.80000000000393,19.8453795183643,-1.123627764243563,-0.03279495322570991
327.0000000000039,19.881945039111766,-1.1284438648638355,-0.032729527870285935
328.2000000000039,19.918722688299486,-1.1303310902625832,-0.03405042057800678
329.40000000000396,19.95530388912075,-1.132459958592423,-0.035605576023122865
330.600000000004,19.991723767253077,-1.1376628431617248,-0.036910209082045675
331.800000000004,20.028222520589313,-1.142658728400387,-0.0380611865339775
333.000000000004,20.06471089054116,-1.1444305721429822,-0.03930964281711358
334.200000000004,20.101887554331004,-1.1509999211961266,-0.04019531626211936
335.40000000000407,20.1382385042553,-1.154140207850593,-0.04144102491824553
336.60000000000406,20.174965502388712,-1.1573722069079977,-0.04194970964652622
337.80000000000405,20.21121333379587,-1.1631432024903006,-0.04371270182917897
339.0000000000041,20.247875097001135,-1.1653675740624152,-0.04572331264101015
340.20000000000414,20.284572367615223,-1.169357323628524,-0.04750180718084218
341.4000000000041,20.321959788278452,-1.1742213540475293,-0.0490891611193649
342.6000000000041,20.35821720324117,-1.178304624050573,-0.05139356638528847
343.80000000000416,20.39472729415546,-1.18092263548381,-0.05360523683721796
345.0000000000042,20.43199036377045,-1.1845198005137307,-0.05541917398657992
346.2000000000042,20.468791504315323,-1.1854780677523282,-0.058710753458514287
347.4000000000042,20.50594056894186,-1.1908555644819347,-0.06173372398705235
348.60000000000423,20.54265932222979,-1.1919415297450309,-0.06457185484793504
349.8000000000043,20.579081621098524,-1.1921904663649645,-0.06748448377818894
351.00000000000426,20.61595868883258,-1.1939350684954666,-0.07064148848896101
352.20000000000425,20.65310286410716,-1.1950580931071915,-0.07390665897729543
353.4000000000043,20.689875454926568,-1.1919023666413646,-0.0773880804870104
354.60000000000434,20.72667564668384,-1.1888216114575518,-0.08144395272654359
355.80000000000433,20.763430080562756,-1.1878904140601516,-0.0853518363584187
357.0000000000043,20.80006144791032,-1.18395267612731,-0.08981696898758385
358.20000000000437,20.83699708576016,-1.1790377681915039,-0.0938217715254317
359.4000000000044,20.873837355122557,-1.1761068458953585,-0.09761296487801951
360.6000000000044,20.91067744263066,-1.1715443336183626,-0.1028495541775647
361.8000000000044,20.94739504275747,-1.1679772571552267,-0.10842081056529418
363.00000000000443,20.984033187670075,-1.162990454295929,-0.11370179924123258
364.2000000000045,21.02120076402511,-1.1608683064550438,-0.11880439670777188
365.40000000000447,21.05782677996318,-1.156039833688276,-0.1243391033955441
366.60000000000446,21.09497295699839,-1.1559680810654744,-0.12976886304193913
367.8000000000045,21.131871484528695,-1.1545127651858007,-0.13630348951895277
369.00000000000455,21.169099447390952,-1.1544744760845953,-0.1416850518052053
370.20000000000454,21.205896275607376,-1.1528102866137042,-0.1482535533854783
371.4000000000045,21.242999038645337,-1.1550074282053535,-0.15402973419643162
372.60000000000457,21.27985039094152,-1.1564917005308986,-0.15971454751219794
373.8000000000046,21.31697906783182,-1.1599645394921647,-0.1654696883939022
375.0000000000046,21.354244087698433,-1.1636238530613048,-0.17308827447699437
376.2000000000046,21.391385909455046,-1.1654401476895526,-0.17957039901844363
377.40000000000464,21.428577606584227,-1.1695537754138552,-0.18688612098397428
378.6000000000047,21.465347899068597,-1.175092182366984,-0.19270497207028203
379.8000000000047,21.502667346302765,-1.1806728121096548,-0.1992380177795905
381.00000000000466,21.539782672176713,-1.1841763317022174,-0.20505880860929127
382.2000000000047,21.577073275875087,-1.187569203862184,-0.21160978508323103
383.40000000000475,21.614515420748962,-1.1959700744109931,-0.21916452705475953
384.60000000000474,21.651753845707333,-1.2003121223160413,-0.22642497140586615
385.80000000000473,21.68878594914455,-1.203267202137549,-0.23313505887411834
387.0000000000048,21.725893445655256,-1.2061926284076667,-0.24015546011527045
388.2000000000048,21.762669396634074,-1.211962021503318,-0.2458363575051492
389.4000000000048,21.800778288318064,-1.2157973619357543,-0.253130389674197
390.6000000000048,21.837896820537704,-1.2181577222697642,-0.259869232779828
391.80000000000484,21.874954724322286,-1.2211392105049639,-0.26730531582958106
393.0000000000049,21.911979424321686,-1.2245311871144744,-0.27361170706048155
394.2000000000049,21.94937651652587,-1.226414202856627,-0.28045415160978493
395.40000000000487,21.98683839507773,-1.229522490107088,-0.2880173377195554
396.6000000000049,22.024310156651882,-1.2309825622725337,-0.2951117337992364
397.80000000000496,22.061361964153967,-1.2341940204612039,-0.301668234291129
399.00000000000495,22.09888140717578,-1.2349134367579375,-0.30930996503924524
400.20000000000493,22.13639379136958,-1.2371805070585544,-0.31683302520911605
401.400000000005,22.17282440232054,-1.2360073453456997,-0.3233883220749205
402.600000000005,22.210980220209,-1.2364957723044332,-0.33117808083309086
403.800000000005,22.248190026051894,-1.2371109961533457,-0.3392604065961953
405.000000000005,22.28580087737928,-1.237929660482693,-0.34839326159127815
406.20000000000505,22.323092566192347,-1.2366171452931627,-0.35663014620575906
407.4000000000051,22.36028310362236,-1.236922504773016,-0.36504208925185866
408.6000000000051,22.39767603310346,-1.2345531536438092,-0.37302635915956683
409.80000000000507,22.435217662772896,-1.2358199358598245,-0.3825026947016492
411.0000000000051,22.472523083395473,-1.2341539498167728,-0.39117846299316117
412.20000000000516,22.510031130749823,-1.2345566969993684,-0.39973898168379396
413.40000000000515,22.54749806801825,-1.233025866807452,-0.4089852586656053
414.60000000000514,22.584885533410215,-1.2337683360875893,-0.41981799777584783
415.8000000000052,22.62194159421523,-1.2337772485061218,-0.4288721337315571
417.00000000000523,22.65975412970889,-1.2337311298179032,-0.4388554696954472
418.2000000000052,22.697280863738104,-1.231346216186989,-0.4497386149220475
419.4000000000052,22.734846704158354,-1.2313025154536148,-0.4592403869810955
420.60000000000525,22.77231793147874,-1.2318683628197173,-0.4695775479823898
421.8000000000053,22.809783435498165,-1.2306560755043545,-0.47976864808461883
423.0000000000053,22.84756970321181,-1.2317638323465192,-0.49040935806664754
424.2000000000053,22.88506130296948,-1.2314343270297776,-0.5018979525290002
425.4000000000053,22.922797585535573,-1.2308628264444803,-0.5143232674010534
426.60000000000537,22.960376386020112,-1.2346841365695118,-0.5273268161104481
427.80000000000535,22.998141166053315,-1.2387500383060397,-0.5414156585820593
429.00000000000534,23.03524199638911,-1.2410121382181343,-0.5533165735148096
430.2000000000054,23.073374936698542,-1.2475953601070886,-0.5665669592258462
431.40000000000543,23.11110269384233,-1.2532218897665293,-0.5804945833393838
432.6000000000054,23.149017139475518,-1.2645391186231887,-0.5952354770939543
433.8000000000054,23.186870601298253,-1.2740269151397419,-0.6104431948454501
435.00000000000546,23.224504073432836,-1.2873460408599136,-0.6254948870348112
436.2000000000055,23.2625122656633,-1.3011555362178577,-0.6428765731176829
437.4000000000055,23.300466762259113,-1.3161726472134898,-0.6609022756012686
438.6000000000055,23.33817036641707,-1.332555607244051,-0.6783109448709457
439.8000000000055,23.376556057956034,-1.3524811773302725,-0.6962658320205097
441.00000000000557,23.414598866026285,-1.3709410748194624,-0.716277374228663
442.20000000000556,23.45237676637091,-1.3887358493392314,-0.73587192809658
443.40000000000555,23.49060888991448,-1.4108313455951087,-0.7563621370201781
444.6000000000056,23.528687674729905,-1.4252693654135262,-0.7772156498516383
445.80000000000564,23.566642750829498,-1.4418432964330752,-0.799061974615376
447.0000000000056,23.604465065872134,-1.457255236186436,-0.8217461125726215
448.2000000000056,23.642866686021495,-1.4720991363937914,-0.8446969207179995
449.40000000000566,23.6810526450321,-1.4853710841698966,-0.8708364524317505
450.6000000000057,23.719381071153393,-1.4992691842067898,-0.8960774836044809
451.8000000000057,23.75715967184616,-1.5122891858801726,-0.920462992725569
453.0000000000057,23.795308501454674,-1.5250097002663066,-0.9468688320478611
454.20000000000573,23.83351280883825,-1.5354124448950048,-0.9732246633576622
455.4000000000058,23.871582472712827,-1.5468170098614562,-0.9998644111665236
456.60000000000576,23.909317392433387,-1.5579442625433706,-1.027408851589866
457.80000000000575,23.947851765543373,-1.5667996651283718,-1.0566267532350686
459.0000000000058,23.986107725652513,-1.5745776963665754,-1.0863744202398697
460.20000000000584,24.023972539843022,-1.5782717082184987,-1.115770354311088
461.40000000000583,24.062412056638884,-1.5801181992897182,-1.1458945917679637
462.6000000000058,24.10031504522508,-1.5798360171944736,-1.1744809455686234
463.80000000000587,24.138618296243486,-1.5757454168002598,-1.203551646116841
465.0000000000059,24.176482114247257,-1.5665755124767438,-1.2309282986615253
466.2000000000059,24.21430075724294,-1.5507745357055296,-1.2579172594368728
467.4000000000059,24.252183994427234,-1.5357401407362195,-1.2843965974999074
468.60000000000593,24.290157496461703,-1.5111585730447301,-1.3091421745082483
469.800000000006,24.328135494383037,-1.4859581459578783,-1.3308612053161797
471.00000000000597,24.365825869689445,-1.4557230914830044,-1.3511721070093063
472.20000000000596,24.40378506566661,-1.4234748794449352,-1.369053646473065
473.400000000006,24.44136275835925,-1.3855777707290224,-1.385058178515742
474.60000000000605,24.479254014504285,-1.3483465066460283,-1.4003439169331169
475.80000000000604,24.51673994600828,-1.3157112666899808,-1.4134412970270072
477.000000000006,24.555005123740308,-1.281221984952332,-1.4264392711367204
478.20000000000607,24.592969464741476,-1.2516922485803355,-1.4372988974310195
479.4000000000061,24.630736280661786,-1.226382540222047,-1.4492023010536856
480.6000000000061,24.66879724949552,-1.2070057989756084,-1.4600902570374608
481.8000000000061,24.706922928868483,-1.1899661806002273,-1.469476618323835
483.00000000000614,24.74521584828159,-1.17924386488648,-1.4791542618257183
484.2000000000062,24.782933486625094,-1.170343672419474,-1.4900702665923138
485.4000000000062,24.821375098580894,-1.1643808303464958,-1.5002727419150972
486.60000000000616,24.85968277034248,-1.163132116700226,-1.5097703729640628
487.8000000000062,24.897915178646468,-1.16078003930582,-1.5204745432067241
489.00000000000625,24.936600104306773,-1.1631481104301982,-1.53185677094155
490.20000000000624,24.97444681038206,-1.1670273631558938,-1.542422507396823
491.40000000000623,25.013003402289673,-1.1678507203302158,-1.5533562247232946
492.6000000000063,25.051697962456807,-1.1722640813573284,-1.56537585958666
493.8000000000063,25.08984565585081,-1.1728299866070089,-1.5763425643007682
495.0000000000063,25.128070667238234,-1.1701553478569109,-1.5883720151524918
496.2000000000063,25.166431406424735,-1.1631921923459019,-1.6006070430909132
497.40000000000634,25.205134783353735,-1.1487011622623218,-1.6127340035278124
498.6000000000064,25.243319573408947,-1.130630657782515,-1.6252182179435506
499.8000000000064,25.281573436535815,-1.1070546405408597,-1.6371302221294668
501.00000000000637,25.318835378789473,-1.0805026039542898,-1.6475433077520982
502.2000000000064,25.357310061712262,-1.0470184305648895,-1.6567146016414616
503.40000000000646,25.39513325978068,-1.0087791908985253,-1.666845088858333
504.60000000000645,25.43356846488792,-0.965515104227661,-1.6749172630962743
505.80000000000643,25.471401490985592,-0.9211099217341079,-1.6805384272972974
507.0000000000065,25.509451858403207,-0.8789518142124615,-1.6865535714442164
508.2000000000065,25.54754690575539,-0.8431418434088284,-1.6885439170646763
509.4000000000065,25.585341315452837,-0.8125348815767345,-1.691484680959297
510.6000000000065,25.62396203583542,-0.7873911323145476,-1.6929636774108028
511.80000000000655,25.66217175802713,-0.7714953748144466,-1.6944912789627669
513.0000000000066,25.7005965518524,-0.7593416580613996,-1.6959707832005884
514.2000000000066,25.73935947503012,-0.7523728955578037,-1.697477236574421
515.4000000000066,25.777586028966805,-0.7501202070495264,-1.6987153767459802
516.6000000000066,25.81609235083331,-0.7510966492838794,-1.700146197443242
517.8000000000067,25.854678325464562,-0.749608359034674,-1.6997822314240785
519.0000000000066,25.893574229475632,-0.7512172353791704,-1.7018620285758743
520.2000000000066,25.93234296596835,-0.7537290725753376,-1.7048559008205721
521.4000000000067,25.970791523206202,-0.7546619827757597,-1.7050670562711092
522.6000000000067,26.009611481862827,-0.7614080684914979,-1.7063732214075724
523.8000000000068,26.048446027592796,-0.7634433917032865,-1.7079294905089446
525.0000000000067,26.087046865403394,-0.7692479019592434,-1.7091007317584985
526.2000000000068,26.126013832613232,-0.7737634526628878,-1.7092255281512982
527.4000000000068,26.16466825432185,-0.7781200581919614,-1.7102582627469256
528.6000000000067,26.203237129271248,-0.7866497560192081,-1.710824071002909
529.8000000000068,26.24247865546687,-0.7937141768244018,-1.713159033386824
531.0000000000068,26.281292097245746,-0.797281495674083,-1.7144826659638208
532.2000000000069,26.319871240396782,-0.8027535961589796,-1.71580136727024
533.4000000000069,26.358688530259784,-0.8070055812604272,-1.716698111889571
534.6000000000068,26.397636225040237,-0.8134874676569821,-1.7164303547167274
535.8000000000069,26.4366515869529,-0.8186829877033567,-1.7171867934040113
537.0000000000069,26.475434933751284,-0.824539144608969,-1.7187682090974512
538.2000000000069,26.51450402428824,-0.8291047708981093,-1.7200223671535566
539.4000000000069,26.553344903239815,-0.8362675097278086,-1.7207979121015229
540.600000000007,26.592452606542103,-0.8412675157758523,-1.7223976141358532
541.800000000007,26.631466387463995,-0.8462862797907358,-1.7241786035638338
543.000000000007,26.670463288306014,-0.851102168503425,-1.7259379393382317
544.200000000007,26.70918902594876,-0.8563659849772456,-1.7273581521729038
545.400000000007,26.74823125856413,-0.8621174125268753,-1.7286894472182222
546.6000000000071,26.78703740784173,-0.8677665573611322,-1.72867369511511
547.800000000007,26.826148426769457,-0.8711179919675099,-1.730039840506227
549.000000000007,26.865230238632027,-0.878523616756699,-1.7314513422251823
550.2000000000071,26.904073789752378,-0.8824546161748813,-1.7327255177985674
551.4000000000071,26.94306797257401,-0.8873647306628918,-1.7327701016914285
552.6000000000072,26.982290355767002,-0.8904748696813676,-1.7332397796616101
553.8000000000071,27.02124366380554,-0.893395787969731,-1.7366628397124866
555.0000000000072,27.060299413512066,-0.8976856546137154,-1.7384414760973237
556.2000000000072,27.099247326876196,-0.8996121394634651,-1.7397428563911235
557.4000000000071,27.138436237364814,-0.9025184867448286,-1.7412494270584085
558.6000000000072,27.17768765424499,-0.9050483841785179,-1.7412248680653715
559.8000000000072,27.21683045311436,-0.9103624562820647,-1.742889829782618
561.0000000000073,27.255604449693262,-0.9118896835343883,-1.7437051969016952
562.2000000000073,27.294519933574826,-0.9155783442935685,-1.7453549860322664
563.4000000000073,27.33348896645238,-0.92116281058334,-1.7468833984553234
564.6000000000073,27.372789810790408,-0.9236519093730126,-1.7483995045244547
565.8000000000073,27.41203525654587,-0.9263935228721027,-1.7499481676312238
567.0000000000073,27.450967323656467,-0.9286852315390006,-1.7519862983308792
568.2000000000073,27.49029443375492,-0.934975217931202,-1.753472549445842
569.4000000000074,27.52936991166371,-0.9406905319345906,-1.7547991956027138
570.6000000000074,27.568405445671615,-0.9453025127826122,-1.7561869149938558
571.8000000000075,27.607325329617804,-0.9519624740402781,-1.757579163252891
573.0000000000074,27.646771644035546,-0.9588615443666646,-1.7585768346761643
574.2000000000074,27.686074531027057,-0.9622535434742203,-1.7591792842636127
575.4000000000075,27.72509889866062,-0.96621394759033,-1.7614633832135347
576.6000000000074,27.764396357321058,-0.9747993969023171,-1.7633276193478324
577.8000000000075,27.803680713907887,-0.983336091791643,-1.7644649880225116
579.0000000000075,27.84282955796613,-0.9860197499099518,-1.7658596653406167
580.2000000000075,27.882015503785468,-0.9949338019992778,-1.7674225476285543
581.4000000000076,27.92162254475989,-1.000631072177861,-1.7699213835147507
582.6000000000075,27.960785022705377,-1.0096556273013702,-1.7725784422847517
583.8000000000076,28.00009898914732,-1.0158663905307008,-1.774116264102633
585.0000000000076,28.039174926438722,-1.0239532367846929,-1.775995089771219
586.2000000000075,28.078914171214592,-1.0325306222051698,-1.7786791564744537
587.4000000000076,28.118339467305102,-1.039558741731592,-1.7808375686910112
588.6000000000076,28.15743748374105,-1.0460218886611194,-1.7836192191946547
589.8000000000077,28.196327197088845,-1.0544268968777328,-1.784743627478698
591.0000000000077,28.236329485977198,-1.0639656915416396,-1.788329230389297
592.2000000000077,28.27571412529674,-1.0728083528913797,-1.7909631003409214
593.4000000000077,28.315177622565447,-1.0838931603160333,-1.793558315743386
594.6000000000078,28.35448952280262,-1.097116113817066,-1.7956948229190686
595.8000000000077,28.393843654244975,-1.1103218349466726,-1.7990068168775757
597.0000000000077,28.433464290058545,-1.1258783594496153,-1.802111179827814
598.2000000000078,28.473183262807648,-1.1439837187963062,-1.8057519056130378
599.4000000000078,28.512476082247577,-1.161881882243424,-1.8089979094953534
600.6000000000079,28.55198341765717,-1.1850082291148374,-1.8115825734413664
601.8000000000078,28.591621777488218,-1.2057749121751604,-1.8153122146770575
603.0000000000078,28.63105741998047,-1.2261311319354218,-1.8199674407187776
604.2000000000079,28.670779909611436,-1.2480285073543331,-1.8254553799338633
605.4000000000078,28.710609426023304,-1.2710255023137613,-1.8305349551718648
606.6000000000079,28.749933123231923,-1.2879332641659689,-1.8362340756987838
607.8000000000079,28.78905397394913,-1.3037980042534643,-1.8420077082348723
609.000000000008,28.829154927130677,-1.3143048726247686,-1.8474030266633696
610.200000000008,28.86880082492371,-1.3262580018966852,-1.8546094647736315
611.4000000000079,28.908236309038447,-1.3372649149768037,-1.860842335785275
612.600000000008,28.947468655269123,-1.344795130933465,-1.8676633963249412
613.800000000008,28.987582510926842,-1.3520352639659143,-1.875082925680983
615.000000000008,29.027087487816285,-1.3609637854518226,-1.8821222130788668
616.200000000008,29.066613719516674,-1.3683887124462109,-1.8895364691477963
617.400000000008,29.105886889237304,-1.3743222465871223,-1.8971757547761552
618.6000000000081,29.145590856323004,-1.3807257238626627,-1.9063744559083982
619.8000000000081,29.185270485870813,-1.386094445595218,-1.9144164866158313
621.0000000000081,29.224416961933464,-1.3922141804723482,-1.9240795119970238
622.2000000000081,29.264104989163084,-1.396464238985919,-1.9337530231052038
623.4000000000082,29.304180203415875,-1.3994296528963344,-1.9431971678310704
624.6000000000081,29.343851916010266,-1.4069373802467229,-1.9526774862547365
625.8000000000081,29.383343385521776,-1.4087162339562793,-1.962754044644234
627.0000000000082,29.422783854758084,-1.4130218373824361,-1.9733429108520788
628.2000000000082,29.462592890091802,-1.4175785507753818,-1.9830152145457807
629.4000000000083,29.50202813926105,-1.4226773852637693,-1.9946271508310516
630.6000000000082,29.541879519961242,-1.4271158358279263,-2.004713942476246
631.8000000000083,29.58148398948832,-1.4332914387655933,-2.013130289785238
633.0000000000083,29.621152046482447,-1.4383342385432385,-2.0227228531030144
634.2000000000082,29.660926490200065,-1.4415094460496183,-2.032494756985269
635.4000000000083,29.700604263823493,-1.4426710719533629,-2.040381685840259
636.6000000000083,29.740201693402575,-1.449764389453777,-2.049032419685032
637.8000000000084,29.779933493492635,-1.4578842206179594,-2.055157982694724
639.0000000000084,29.819796122299877,-1.4671220906520264,-2.058978337406702
640.2000000000083,29.85925723694908,-1.4753297516274015,-2.0627742324814915
641.4000000000084,29.89889630951225,-1.4760424527777645,-2.0662955020514
642.6000000000084,29.938754367918754,-1.473308505481358,-2.0679135249921194
643.8000000000084,29.978391177523264,-1.4655850150300958,-2.0692102925154643
645.0000000000084,30.01783406044704,-1.4612291211281838,-2.0707396652294596
646.2000000000085,30.05771836639729,-1.460158651723904,-2.072428022743485
647.4000000000085,30.09735875826101,-1.4608576140358716,-2.0733235566085257
648.6000000000085,30.13720056500928,-1.472924425780622,-2.0746122687385173
649.8000000000085,30.176998306571416,-1.4856704086976413,-2.075926895662982
651.0000000000085,30.21710659880953,-1.5049410155268146,-2.076287591273589
652.2000000000086,30.256718001694164,-1.528976100505782,-2.0773881618150254
653.4000000000085,30.29666868123935,-1.5467122292702322,-2.0792281103872563
654.6000000000085,30.336616660472316,-1.5713684337237768,-2.0809270111667475
655.8000000000086,30.37621203334627,-1.5992304231200436,-2.082916288144243
657.0000000000086,30.41637344676044,-1.6229821316233866,-2.0844154335555944
658.2000000000087,30.456308920109855,-1.6538696818464913,-2.08582337773815
659.4000000000086,30.496470143862997,-1.686625404883883,-2.0873115007383225
660.6000000000087,30.536287613827056,-1.7165674113746854,-2.089687226396313
661.8000000000087,30.5764605831249,-1.7454796589566044,-2.0918913910828176
663.0000000000086,30.61645156929358,-1.7773958902655784,-2.0934137163490436
664.2000000000087,30.656657545656575,-1.8100334994566032,-2.095619832567659
665.4000000000087,30.696467393398393,-1.8399755310603885,-2.098345416551139
666.6000000000088,30.736365850134195,-1.8750332367328113,-2.099993179641086
667.8000000000088,30.776717495855433,-1.9119553279841954,-2.1027623676236633
669.0000000000088,30.81673802549499,-1.9472239675842489,-2.1048016236770466
670.2000000000088,30.856956197121516,-1.9854852788149777,-2.1075619976559263
671.4000000000088,30.897477883578233,-2.0265076035564586,-2.110007334793438
672.6000000000088,30.937647532883346,-2.066511196722559,-2.112878197589304
673.8000000000088,30.977657503189057,-2.110095760789876,-2.1150610819074798
675.0000000000089,31.01810511166873,-2.155359830732514,-2.117029435684087
676.2000000000089,31.058335690837367,-2.202177952259733,-2.120354387644622
677.400000000009,31.098559221551888,-2.2538115412739814,-2.1234111257067605
678.6000000000089,31.138961648187294,-2.3028944730347254,-2.1269657106394053
679.8000000000089,31.179043952289224,-2.360026602795921,-2.130478634457084
681.000000000009,31.21980461193951,-2.412402208681388,-2.134507130699119
682.2000000000089,31.25996575299026,-2.471975715703632,-2.1370464269013927
683.400000000009,31.30038303645285,-2.5299497306887604,-2.140044600695795
684.600000000009,31.340831335647266,-2.589419918227981,-2.1443022988393987
685.800000000009,31.381046704467707,-2.6522535214393588,-2.1491331667350675
687.0000000000091,31.421516501804692,-2.7173621136896595,-2.1531884324518265
688.200000000009,31.46206908839568,-2.781086455680474,-2.1590335488625145
689.4000000000091,31.502114456631823,-2.848154229095658,-2.1636103845171872
690.6000000000091,31.54329336588481,-2.914311157620712,-2.1667738610177834
691.800000000009,31.58374815010257,-2.9818053936338873,-2.1705745813376938
693.0000000000091,31.624260100811004,-3.0518836718972673,-2.1761004096407195
694.2000000000091,31.664811771466905,-3.1220622954375172,-2.181104006484162
695.4000000000092,31.705488364016187,-3.1947534237835025,-2.1866602134243154
696.6000000000092,31.746094234530215,-3.26673096246962,-2.1912743246486968
697.8000000000092,31.78651833718194,-3.3385097841339264,-2.196963041440943
699.0000000000092,31.827534992032234,-3.4147127818607848,-2.2027592076280835
700.2000000000093,31.868124226573197,-3.489197877776783,-2.2088206186689225
701.4000000000092,31.908725671451197,-3.5646108965103487,-2.2148690001646383
702.6000000000092,31.94942871717635,-3.6386203360051597,-2.223108281604567
703.8000000000093,31.99027364472296,-3.719863543098649,-2.229761434718114
705.0000000000093,32.03073866599879,-3.7951908471070963,-2.2362681949792282
706.2000000000094,32.07141778282243,-3.8737063476840534,-2.24403814847529
707.4000000000093,32.11214169678285,-3.949451761763497,-2.249443850839258
708.6000000000093,32.153206693610244,-4.0271004394994625,-2.2568011936439665
709.8000000000094,32.193831735380826,-4.108554538961888,-2.2645915448277094
711.0000000000093,32.2347753885667,-4.18689724492807,-2.272809636448141
712.2000000000094,32.275207235677065,-4.265456359059026,-2.2804139744853327
713.4000000000094,32.31535794938079,-4.343421682014445,-2.288437252385276
714.6000000000095,32.356712776465315,-4.424983786877631,-2.297143505664293
715.8000000000095,32.39733805510997,-4.504219403643466,-2.306537846424491
717.0000000000094,32.43832874474138,-4.5853785725851335,-2.314992769195971
718.2000000000095,32.47911123992874,-4.663708795383924,-2.323890902760784
719.4000000000095,32.51976497991126,-4.742706603319401,-2.333540778221356
720.6000000000095,32.56072190872241,-4.825089191056818,-2.3425298624260167
721.8000000000095,32.60141778064261,-4.906260069587697,-2.350474146023224
723.0000000000095,32.64255679325694,-4.989492549274488,-2.360857028472682
724.2000000000096,32.68345888362571,-5.076161572501276,-2.3711354504987243
725.4000000000096,32.72408323030231,-5.1632941897632625,-2.3810345549960688
726.6000000000096,32.765100473538695,-5.254599537336416,-2.391841112050612
727.8000000000096,32.80571868075163,-5.345159635317084,-2.402087210794533
729.0000000000097,32.84737927486161,-5.449735821053146,-2.4122242081447904
730.2000000000096,32.88853390162596,-5.553898537520392,-2.4236948853827847
731.4000000000096,32.92996616830591,-5.663479503590886,-2.4342211001200793
732.6000000000097,32.971077074684125,-5.777684615079234,-2.4457340862139105
733.8000000000097,33.012115743404806,-5.892697413303551,-2.4560707028552025
735.0000000000098,33.05355585275007,-6.013075647771877,-2.4679099976646253
736.2000000000097,33.094759189511656,-6.1331150704064346,-2.4804183082873257
737.4000000000098,33.13599830023795,-6.253826434477353,-2.4927389097059525
738.6000000000098,33.17717094471218,-6.370867229427209,-2.505962865146421
739.8000000000097,33.21815167029592,-6.482219267968394,-2.5186418079510577
741.0000000000098,33.259262754944835,-6.5844136526811905,-2.5314028020131296
742.2000000000098,33.30044175119973,-6.685207988440059,-2.5442341392979837
743.4000000000099,33.34133179320558,-6.76930891183739,-2.557228391222269
744.6000000000099,33.3823943206379,-6.843281173892278,-2.571006969953826
745.8000000000098,33.42325211034488,-6.899487293039316,-2.5849664195535755
747.0000000000099,33.46407233724523,-6.933088299661985,-2.598285287295501
748.2000000000099,33.50349420380373,-6.948604359760408,-2.611736739043967
749.4000000000099,33.544258603353086,-6.939608206660233,-2.6254530393611804
750.6000000000099,33.58371147565691,-6.908138953198636,-2.63872335221017
751.80000000001,33.62443083085426,-6.845796320785715,-2.6524178212211087
753.00000000001,33.663832670055896,-6.7408988064153395,-2.6652991551506715
754.20000000001,33.702709137575724,-6.596239994390043,-2.676885265451876
755.40000000001,33.74149567051965,-6.39223427492674,-2.6894216714057873
756.60000000001,33.779689533999715,-6.117368234594845,-2.701343041632324
757.8000000000101,33.81694024400946,-5.762170175959568,-2.7124331092820393
759.00000000001,33.85285467869382,-5.272194787517552,-2.7221916309762264
760.20000000001,33.88761475134934,-4.533943960017293,-2.7303845967247273
761.4000000000101,33.920722581686576,-3.674133422590209,-2.73673600436351
762.6000000000101,33.95462038012714,-2.9106029978146144,-2.741994935186398
763.8000000000102,33.990392590021166,-2.3524381418659384,-2.74276993660747
765.0000000000101,34.02756542769301,-1.9689846852690218,-2.745232332347713
766.2000000000102,34.06527213669512,-1.7193873346499446,-2.7467303362166215
767.4000000000102,34.104173899853684,-1.549366148621597,-2.746789237854059
768.6000000000101,34.143313803210305,-1.4397999993963264,-2.7474510308094766
769.8000000000102,34.182699833887014,-1.3682557020901538,-2.7482199976869057
771.0000000000102,34.22241173478467,-1.322387695771278,-2.749419632901148
772.2000000000103,34.26253087846579,-1.2879406674722431,-2.74979641721718
773.4000000000103,34.302341631868025,-1.2680532366484354,-2.7491569927193487
774.6000000000103,34.34250858591446,-1.2497012703138186,-2.749420442812586
775.8000000000103,34.38258216254683,-1.2392458414525442,-2.74961694367751
777.0000000000103,34.42249965410882,-1.2321743373666005,-2.750692257055329
778.2000000000103,34.46280043039634,-1.2293621477596484,-2.752048206796916
779.4000000000103,34.50319631750227,-1.223788398444467,-2.7520502782711818
780.6000000000104,34.54336062073483,-1.2235691266941917,-2.7520685690165596
781.8000000000104,34.583438373266496,-1.2237295405184458,-2.7533744342608744
783.0000000000105,34.624117528031185,-1.2243098251905515,-2.753364034985898
784.2000000000104,34.664065699921665,-1.2268157679239267,-2.754303884001148
785.4000000000104,34.70446247821131,-1.2318943691164577,-2.754059916442897
786.6000000000105,34.74415719018153,-1.232665523167637,-2.7540270987407136
787.8000000000104,34.78483414168,-1.2338251566068796,-2.7550801259030164
789.0000000000105,34.82560749483357,-1.2413191375291575,-2.7553489265365716
790.2000000000105,34.86584339086942,-1.24651647903307,-2.755349986487105
791.4000000000106,34.906599001348646,-1.250699331957052,-2.7553904726620146
792.6000000000106,34.94739752543614,-1.2567356572420376,-2.756001810771279
793.8000000000105,34.98770402270436,-1.2612777515425613,-2.755999942065927
794.0000000000106,34.9942305079034,-1.2625098471542269,-2.755999872843199