File: 01_Data/Cardboard/STA/N2/10K_min/Cardboard_STA_N2_10KData_230814_R2.csv
##Temp./Â°C,Time/min,DSC/(mW/mg),Mass loss/mg
27.0,15.8660245388807,-2.361450426133762,-0.1506340711873646
28.100000000000016,16.157020258194866,-2.3193038751116606,-0.14812915477157818
29.20000000000003,16.372761597368875,-2.2953620959519094,-0.14951006034555325
30.300000000000047,16.54787748955357,-2.27860978246245,-0.1485869286839443
31.400000000000063,16.716969068159642,-2.266459643391514,-0.14873130324512784
32.50000000000008,16.867759334750716,-2.2577064064039605,-0.1499734364869525
33.600000000000094,17.013310082033236,-2.2515368858936444,-0.1531025409885589
34.70000000000011,17.152760539528472,-2.2478069398130907,-0.15149735829721367
35.800000000000125,17.288502039819278,-2.2450248067938694,-0.15325327876843664
36.90000000000014,17.418325234248044,-2.242349254865532,-0.15341331596699614
38.000000000000156,17.549889745030065,-2.242514139410028,-0.15468213872077596
39.10000000000017,17.678856802955867,-2.2444048123021556,-0.15602318101925317
40.20000000000019,17.806728413176053,-2.2461049308888645,-0.1577443777813805
41.3000000000002,17.93212529945823,-2.2486610889769465,-0.16029465360726158
42.40000000000022,18.055658634894122,-2.2512820459483383,-0.15995204624040493
43.500000000000234,18.18020549601317,-2.256709674802398,-0.16127807217092682
44.60000000000025,18.302253298364167,-2.25883216410726,-0.16461281189389432
45.700000000000266,18.423153164401796,-2.2633222404423705,-0.165410054025235
46.80000000000028,18.544727908803377,-2.2673910612883783,-0.16687978787717572
47.9000000000003,18.66498296657633,-2.2701109909544677,-0.16818981392364662
49.00000000000031,18.78352491450853,-2.2737910705872864,-0.1721330665182803
50.10000000000033,18.90248969587952,-2.278299561450815,-0.1734639094148709
51.200000000000344,19.0207734717157,-2.281278301458833,-0.17608955685813665
52.30000000000036,19.137879919855692,-2.2843065501625905,-0.1800982816441321
53.400000000000375,19.257240935867884,-2.2880054535242644,-0.18092916601212927
54.50000000000039,19.373116139031378,-2.290441116521569,-0.18404369394931397
55.600000000000406,19.4883867360074,-2.2915932976427067,-0.18521577526796218
56.70000000000042,19.602845936818415,-2.2948484109933913,-0.187383402320902
57.80000000000044,19.7183269464046,-2.295967062012873,-0.19190781466652096
58.90000000000045,19.831943222960597,-2.2960486781811924,-0.194546425451247
60.00000000000047,19.943830445579525,-2.294344236651672,-0.19716112997813928
61.100000000000485,20.05988331252811,-2.2931565862159173,-0.19848889088428567
62.2000000000005,20.171239895533933,-2.292378035802689,-0.2024430079819055
63.300000000000516,20.283636034449472,-2.28931833160193,-0.20507954777019544
64.40000000000053,20.395190672932944,-2.286552140473735,-0.2063913550410148
65.50000000000054,20.505103053068577,-2.2824958112613962,-0.20902362931582186
66.60000000000056,20.61674894025953,-2.2763227029887063,-0.21165620111483996
67.70000000000059,20.727825136407557,-2.2716588764399512,-0.21560025899471702
68.8000000000006,20.838299666537722,-2.2657819360515083,-0.21825260186589235
69.9000000000006,20.94782346954386,-2.2583193751363377,-0.22088301311691172
71.00000000000063,21.059046863963268,-2.2493209924904405,-0.22483911900287712
72.10000000000065,21.1675507400941,-2.243122424535317,-0.22882802359077958
73.20000000000066,21.2771787221898,-2.234584142819048,-0.23140061197578277
74.30000000000067,21.388810439396515,-2.2251749094192723,-0.2327400075255146
75.40000000000069,21.49631586134313,-2.2139404286451687,-0.23537935358199702
76.50000000000071,21.606162504590753,-2.2041804166605345,-0.23907160647900705
77.60000000000072,21.71517782812324,-2.1937140652019633,-0.2406395125295533
78.70000000000073,21.823426275425113,-2.1824483825579795,-0.2419658909791056
79.80000000000075,21.931848304666982,-2.1697389205158606,-0.24459564020190738
80.90000000000077,22.040398266454027,-2.1597120200317996,-0.24722688605932097
82.00000000000078,22.14956832946869,-2.146382277943855,-0.2497219107983626
83.10000000000079,22.258433627761423,-2.1340518311203005,-0.252027966271708
84.20000000000081,22.36742880748917,-2.1206590935496883,-0.25362357899404886
85.30000000000084,22.47544951910883,-2.1072710816435016,-0.2551624650485027
86.40000000000084,22.58408647466419,-2.093929513603096,-0.2577630705421634
87.50000000000085,22.689728028481035,-2.080452048943028,-0.25908988610713957
88.60000000000088,22.799605445160743,-2.066841765330569,-0.26040993425009873
89.7000000000009,22.906975422169744,-2.0539540000366854,-0.2617333479868904
90.8000000000009,23.013239471353902,-2.040975824444615,-0.26434997981147257
91.90000000000092,23.120799567225895,-2.027467946823912,-0.2659104671928785
93.00000000000094,23.225522019819685,-2.0149749657080265,-0.2669900000899137
94.10000000000096,23.333887499244298,-2.000458002056623,-0.26688017756698645
95.20000000000097,23.440695918640344,-1.9893196229480037,-0.26963001783841634
96.30000000000098,23.54726422859105,-1.9743842053112381,-0.27094309295997876
97.400000000001,23.65367027281052,-1.9628595887223346,-0.27227457091263974
98.50000000000102,23.762226319899046,-1.9513788561166614,-0.2722737806992295
99.60000000000103,23.86730666491941,-1.9380038487919322,-0.27358000507435554
100.70000000000104,23.97312688584122,-1.9277636771334221,-0.2748999999999997
101.80000000000106,24.078792950392838,-1.915603893855793,-0.27490000351925703
102.90000000000109,24.18629835511716,-1.9041870184283312,-0.27538070978816753
104.0000000000011,24.292360325226458,-1.8944128765467703,-0.2762203164195136
105.1000000000011,24.395511924770005,-1.8839894299258952,-0.2775412009520686
106.20000000000113,24.50587218386955,-1.8723097579324353,-0.27884999503918584
107.30000000000115,24.61088085832271,-1.8622948567931967,-0.27884999999767723
108.40000000000116,24.716147934360926,-1.853369435063241,-0.2788483510764501
109.50000000000117,24.82210973886584,-1.8428624926766484,-0.28017049364961366
110.60000000000119,24.928936166718742,-1.8347537175694366,-0.28149555929222103
111.70000000000121,25.035193180247436,-1.8264928167694332,-0.2814899999870373
112.80000000000122,25.14045010138235,-1.8175476514755937,-0.2828100060226797
113.90000000000123,25.244982179539623,-1.8096584764386725,-0.2814815072611099
115.00000000000125,25.35229798847396,-1.8020040461615843,-0.28267485021659855
116.10000000000127,25.458109278099215,-1.7952090635980889,-0.28214011069541023
117.20000000000128,25.563696620732696,-1.788035054885473,-0.28345979928615694
118.30000000000129,25.669023782222908,-1.7837367046181565,-0.28279993099931255
119.40000000000131,25.776112874942985,-1.7758314430190734,-0.28411999628324525
120.50000000000134,25.881257626599282,-1.769622141696079,-0.2841200653393443
121.60000000000134,25.986802450685694,-1.7647717488551427,-0.2854402052702576
122.70000000000135,26.09287713106977,-1.7582359937004632,-0.2851925559072077
123.80000000000138,26.199901647833155,-1.7535898984339633,-0.2841264734123161
124.9000000000014,26.3057443992792,-1.7480396578243655,-0.2847815373895397
126.0000000000014,26.41103858878976,-1.7428565417340414,-0.2841213165332541
127.10000000000142,26.516926725921234,-1.73847557149598,-0.2854402825471505
128.20000000000144,26.623797946396735,-1.7351457553323393,-0.28411976552961793
129.30000000000146,26.72918004330893,-1.7315934791403806,-0.2841204752743338
130.40000000000146,26.835247467530657,-1.7269739261872699,-0.28544001288560716
131.50000000000148,26.938279518968862,-1.7226408320828883,-0.28543999999174474
132.6000000000015,27.045042085713295,-1.7190314915681821,-0.285439159867785
133.70000000000152,27.15111639170794,-1.7155762149235563,-0.2867543119386493
134.80000000000155,27.256361198551016,-1.711223589340253,-0.2854399982133855
135.90000000000154,27.363586883629097,-1.7069716162664954,-0.28543958055817464
137.00000000000156,27.46902541064104,-1.7039585191963234,-0.2867928549741552
138.1000000000016,27.57444006127691,-1.700681309254706,-0.285437441575902
139.20000000000158,27.679691276427636,-1.6981635932730992,-0.2860999529651447
140.3000000000016,27.784916779428734,-1.69560459115514,-0.2851076106981276
141.40000000000163,27.889907590196167,-1.692698541863674,-0.28576999088084465
142.50000000000165,27.996534591551743,-1.690769264877637,-0.28547770457140986
143.60000000000167,28.101204573923415,-1.687373673764645,-0.28643021589808004
144.70000000000167,28.207271518324372,-1.6850153061279007,-0.2854678927291845
145.8000000000017,28.31295423328418,-1.6816781001970613,-0.2867277864962756
146.9000000000017,28.41790323403266,-1.679775455001362,-0.28535069115314515
148.0000000000017,28.524485545468238,-1.6766691123051383,-0.28675123253393453
149.10000000000173,28.62990039791758,-1.6751699585480926,-0.28757310313568674
150.20000000000175,28.734142197127493,-1.672360428646789,-0.28674297272624694
151.30000000000177,28.83911225753005,-1.6693387722851387,-0.2875924021441021
152.4000000000018,28.944989063631603,-1.666279475668798,-0.2867600770318073
153.5000000000018,29.05009843405282,-1.6640154106662386,-0.28675999999999746
154.6000000000018,29.156082728621527,-1.6603814410351134,-0.28675999985960887
155.70000000000184,29.259613151998092,-1.6591730353126515,-0.2870843425013945
156.80000000000183,29.365988991252703,-1.6556362732016143,-0.28676010555935383
157.90000000000185,29.471078448519226,-1.653874872317626,-0.2867701466734198
159.00000000000188,29.576047193657633,-1.650676555089956,-0.288069989752588
160.1000000000019,29.680369847841913,-1.648682924826202,-0.2880755061623952
161.20000000000192,29.786984271959504,-1.6476051127885802,-0.28807000016733486
162.30000000000192,29.89087260892675,-1.645368964494459,-0.2880135391178902
163.40000000000194,29.996385885718745,-1.643807653867777,-0.2867499847423751
164.50000000000196,30.10127789405127,-1.6416337476740919,-0.2870892140665129
165.60000000000196,30.20654656367676,-1.6394676991658386,-0.2884000088269243
166.70000000000198,30.310387858935254,-1.6373198522012826,-0.2883998952827378
167.800000000002,30.416945283793773,-1.6358994641899538,-0.287410481998577
168.90000000000202,30.51980183297225,-1.6333885379462152,-0.28733458782324117
170.00000000000205,30.626980505592073,-1.6315869424075717,-0.2884068410437406
171.10000000000204,30.732363399015817,-1.6297507150483819,-0.2884112625932551
172.20000000000206,30.835653215381733,-1.6267469470810745,-0.28840199248837317
173.3000000000021,30.940667206039283,-1.6247530880320091,-0.2886307795568537
174.40000000000208,31.04619838663025,-1.6219097401055573,-0.28840133714772787
175.5000000000021,31.15148294104155,-1.621493758582004,-0.29082770864306706
176.60000000000213,31.25558987603125,-1.6193450274119756,-0.2897436812153611
177.70000000000215,31.36060844354911,-1.617537191181732,-0.2897200482901554
178.80000000000217,31.46523760652644,-1.6157192487427565,-0.28971999999962117
179.90000000000217,31.57059625796156,-1.6140537722857684,-0.2897202364372098
181.0000000000022,31.674987657890206,-1.6130176209109301,-0.28997515050539624
182.1000000000022,31.779894870810804,-1.612299288502885,-0.28927127120328233
183.2000000000022,31.88391114793469,-1.6107453667360978,-0.29094998642776826
184.30000000000223,31.987426705208705,-1.6099165819888281,-0.2896099984136744
185.40000000000225,32.093958497935105,-1.6083839619506026,-0.2896099973415245
186.50000000000227,32.199229492012726,-1.6082092012198526,-0.2909327841198399
187.6000000000023,32.304177610370225,-1.6061422116154818,-0.29093000014706316
188.7000000000023,32.40763631637336,-1.6045194927803998,-0.2910119092201717
189.8000000000023,32.51359085796592,-1.603906289645251,-0.2912969385524917
190.90000000000234,32.6187063636709,-1.602435646977028,-0.2912497315330662
192.00000000000233,32.72306824612666,-1.600294870010984,-0.2916000402552923
193.10000000000235,32.827245808863125,-1.5990751749947039,-0.2909200371256029
194.20000000000238,32.93257448164296,-1.5985368591919455,-0.2922391767854231
195.3000000000024,33.03672931043575,-1.5961141654694715,-0.2910749002794297
196.40000000000242,33.14203382039548,-1.5961391870203467,-0.2937799499854057
197.50000000000242,33.24628153415251,-1.5938376789078275,-0.2937800208678407
198.60000000000244,33.35069700919232,-1.5920324335160427,-0.29389098704083194
199.70000000000246,33.45711950560729,-1.5906099928060793,-0.2950817103578327
200.80000000000246,33.560000000000244,-1.5905199999999806,-0.2938024426110366
201.90000000000248,33.66574219353691,-1.5889438419737072,-0.2937713967622013
203.0000000000025,33.770192247364825,-1.5876810096330216,-0.2937800000033044
204.10000000000252,33.87547049391232,-1.5865705253769966,-0.29378000006319516
205.20000000000255,33.97991010802037,-1.5852179911680948,-0.2937800822568848
206.30000000000254,34.08409726782171,-1.585143317259979,-0.2947699804130166
207.40000000000256,34.18971054164591,-1.5842817678330183,-0.2947702952540783
208.5000000000026,34.294335732303686,-1.5819369722612877,-0.2960899931114511
209.60000000000258,34.39812077238799,-1.5810914163770482,-0.2960899999999853
210.7000000000026,34.5030834785455,-1.5795793861889253,-0.29609001442137073
211.80000000000263,34.607887422450666,-1.5795571266091901,-0.29504828677493977
212.90000000000265,34.71064611723219,-1.5790807092926185,-0.29802694171748856
214.00000000000267,34.8157650626626,-1.5776161070291996,-0.2987199998028469
215.10000000000267,34.920507278802376,-1.5765580726248576,-0.2987200000000141
216.2000000000027,35.025874330180315,-1.5753613826823687,-0.2987200007838915
217.3000000000027,35.13074837204316,-1.5738389839520572,-0.3002564919665951
218.4000000000027,35.23405683299248,-1.5737708348212829,-0.29894192945272646
219.50000000000273,35.33692153955086,-1.5728569616941424,-0.298939984609385
220.60000000000275,35.443469020476016,-1.5713019971926974,-0.3002615076961286
221.70000000000277,35.5478447129307,-1.5694927645688628,-0.30157325162568904
222.8000000000028,35.65186304511791,-1.5696991404582672,-0.3001757350759746
223.9000000000028,35.757547138527954,-1.5692248791864287,-0.30575379931405333
225.0000000000028,35.861776502209814,-1.567761077708927,-0.3029632333667962
226.10000000000284,35.96611647961724,-1.5680556119627977,-0.3048469659050741
227.20000000000283,36.070194099259716,-1.5662966906154687,-0.30586969398996944
228.30000000000285,36.175269311544305,-1.5667430515599539,-0.3045464742073283
229.40000000000288,36.27928417525508,-1.566943484825368,-0.30543447151965086
230.5000000000029,36.3820853003635,-1.5657465025613555,-0.3069697523239796
231.60000000000292,36.4889049112493,-1.565847360703366,-0.308071160716052
232.70000000000292,36.593285049242034,-1.563659122192513,-0.3113115388196772
233.80000000000294,36.69846791175377,-1.5647413967449701,-0.3113410415739093
234.90000000000296,36.80307545488428,-1.5651915838106614,-0.311349556706777
236.00000000000296,36.90745930332602,-1.5649812459138337,-0.31343061447098197
237.10000000000298,37.012565762451516,-1.565285593063473,-0.313980000087855
238.200000000003,37.11656182127666,-1.5645186416567665,-0.3152694011838735
239.30000000000302,37.22088943072216,-1.5643023955154833,-0.31660433827063583
240.40000000000305,37.32527468705201,-1.563594195524128,-0.3178544044223637
241.50000000000304,37.428466997505176,-1.5645108363552505,-0.3189178345211814
242.60000000000306,37.53425461519115,-1.5639776122116884,-0.32079804856228833
243.7000000000031,37.63882159264494,-1.5651538241662641,-0.3231353188237098
244.80000000000308,37.74386514638889,-1.5650577143504019,-0.32451215347630535
245.9000000000031,37.84917578954693,-1.5675279709909617,-0.32584982142982977
247.00000000000313,37.95305408143746,-1.5673073397134574,-0.33002371163909316
248.10000000000315,38.05743902742049,-1.566393985760062,-0.3300004807278385
249.20000000000317,38.16296527812455,-1.564762893155064,-0.33194677683076934
250.30000000000317,38.26730106868117,-1.5656379765428698,-0.3344328912327783
251.4000000000032,38.373250420927015,-1.5650920414071516,-0.33689593907005433
252.5000000000032,38.477862301693214,-1.565300748721417,-0.3394082370962317
253.6000000000032,38.583120874523246,-1.5654770834090832,-0.3405504180468153
254.70000000000323,38.68654048015459,-1.5639811574670193,-0.3457899899827166
255.80000000000325,38.79282872453151,-1.56318139702374,-0.3484508670221853
256.9000000000033,38.897584247242435,-1.56169504328506,-0.35114144930867175
258.0000000000033,39.000880865044174,-1.5579150829101256,-0.35410785666191114
259.1000000000033,39.10496749464337,-1.5532860211404975,-0.35747738976338717
260.20000000000334,39.21183165782583,-1.549337659692555,-0.36069692496157524
261.30000000000337,39.316881096512425,-1.5443870465812346,-0.36337278317728616
262.40000000000333,39.421753607349004,-1.5374738462189625,-0.3675008169326799
263.50000000000335,39.52683886053894,-1.532754001491234,-0.3712190491118603
264.6000000000034,39.631326233438116,-1.5301410270246245,-0.37604334506410364
265.7000000000034,39.73659926318019,-1.5287762145141788,-0.38021193609078985
266.8000000000034,39.84086228862299,-1.5275429917948324,-0.3850291274275168
267.9000000000034,39.94681741605739,-1.5269746802487074,-0.38943285077897194
269.0000000000034,40.050521730101416,-1.5258388638409852,-0.39474281330709937
270.10000000000343,40.15661944531081,-1.526179430846793,-0.4001379011348969
271.20000000000346,40.26130977591687,-1.5254447685300836,-0.40557937185163784
272.3000000000035,40.36473797916995,-1.5248320027291338,-0.4102879780272781
273.4000000000035,40.470820420566625,-1.5236336549748057,-0.41616113724252557
274.5000000000035,40.57663749090535,-1.523526912476287,-0.4216729662204708
275.60000000000355,40.680684555737976,-1.522015782204897,-0.4282784725798452
276.70000000000357,40.785908776504506,-1.5227029258225246,-0.43494655776370994
277.8000000000036,40.89186592664544,-1.5211868553697638,-0.44308215887958013
278.9000000000036,40.99709913189322,-1.521326243867908,-0.4499993231515824
280.0000000000036,41.100197987161636,-1.5221086048269563,-0.4581242719610068
281.1000000000036,41.207405146655354,-1.5223887494528745,-0.4646119359078442
282.2000000000036,41.31220820217111,-1.5221981397650588,-0.47295667493956817
283.30000000000365,41.418611629163095,-1.5224099156549322,-0.48232745596131554
284.4000000000037,41.52371654756606,-1.521894803626473,-0.4912730809767938
285.5000000000037,41.62810867842432,-1.5234362553215965,-0.4996828509730902
286.60000000000366,41.73503892378724,-1.523962620407508,-0.5095941666749697
287.7000000000037,41.84020150223997,-1.5260725826768764,-0.5196170077292575
288.8000000000037,41.9455360087806,-1.526383959505234,-0.5311229107436923
289.90000000000373,42.05136189890365,-1.527803673611078,-0.5425154625580855
291.00000000000375,42.157003020200236,-1.5303650914517988,-0.5524963180888984
292.1000000000038,42.26115071941203,-1.5331318363744675,-0.5646146239996575
293.2000000000038,42.36833267708933,-1.533737627868675,-0.576429900047374
294.3000000000038,42.473145500695956,-1.5356057190381356,-0.5886191629436444
295.40000000000384,42.57892141293555,-1.5378533070231035,-0.6016949800157851
296.5000000000038,42.68410850343211,-1.539778194800546,-0.6155929939557883
297.60000000000383,42.79089440319294,-1.5425191082240555,-0.6286430127676819
298.70000000000385,42.89460588476037,-1.5441089056841182,-0.6415520490301563
299.8000000000039,43.00139541248758,-1.5472102824956666,-0.6557600905397303
300.9000000000039,43.107012629516746,-1.5503034105124376,-0.6705045740376709
302.0000000000039,43.21290529173317,-1.5509370221528387,-0.6869236319453451
303.10000000000394,43.3190062503937,-1.554264865298756,-0.7032866274616225
304.2000000000039,43.4246956962899,-1.556396271630843,-0.719003952412347
305.30000000000393,43.5303972460537,-1.559763476845938,-0.7353860814381394
306.40000000000396,43.635703325652656,-1.562530744084859,-0.7504893584514027
307.500000000004,43.74184934897065,-1.564340120792755,-0.7720916307447254
308.600000000004,43.84718679364315,-1.5680521976114457,-0.7908389689425084
309.700000000004,43.95295360835846,-1.5706835335208942,-0.8105419753583032
310.80000000000405,44.058494443901274,-1.5727549648528516,-0.829787589443681
311.90000000000407,44.16519564652712,-1.5777788925221194,-0.8496547857438377
313.0000000000041,44.27050416714807,-1.5814273366061327,-0.8690050362267527
314.10000000000406,44.37678363288619,-1.5849921264830198,-0.8907368696339968
315.2000000000041,44.4827962090094,-1.5896779904941438,-0.9123715395489032
316.3000000000041,44.58814457832236,-1.5923755043391463,-0.9345240387639944
317.4000000000041,44.69341482959637,-1.5970462686957132,-0.9568867749419177
318.50000000000415,44.79939464386392,-1.600344649789487,-0.9808104122134131
319.6000000000042,44.905951423714974,-1.6034697146506498,-1.0067425892388484
320.7000000000042,45.01277434130908,-1.6079569743752553,-1.029588185491113
321.80000000000416,45.11735109473946,-1.6129715806792695,-1.0556913349074462
322.9000000000042,45.22293041366837,-1.6178145745542092,-1.0804970727315806
324.0000000000042,45.32924404109774,-1.6224542432953415,-1.1081900600075851
325.10000000000423,45.43536857657829,-1.6268351946051252,-1.1365733058279028
326.20000000000425,45.54103374787773,-1.6329053956573765,-1.1637283675949588
327.3000000000043,45.647793418096526,-1.6381057360197806,-1.193235518854285
328.4000000000043,45.753387118172945,-1.6448224741349131,-1.2243839831028773
329.5000000000043,45.86058901959276,-1.6507485835101314,-1.2557505446317556
330.60000000000434,45.966687418378854,-1.6585346328406982,-1.2865598075383216
331.7000000000043,46.07332175906706,-1.6644699832829484,-1.3184354362158133
332.80000000000433,46.17971097603635,-1.6717073223328218,-1.3519888570619978
333.90000000000435,46.28719860123994,-1.6798752449834249,-1.3847685163334318
335.0000000000044,46.3925534185339,-1.6870862160878786,-1.4213684960113948
336.1000000000044,46.49989052964777,-1.6952910959888507,-1.4576653067658008
337.2000000000044,46.60594277035482,-1.704552708753825,-1.4941723115642613
338.30000000000445,46.71323192830477,-1.7114731356629516,-1.5320776441784565
339.4000000000044,46.818085081664336,-1.7220335956697277,-1.5715953886818093
340.50000000000443,46.92599224412,-1.7308179358743676,-1.6110098795379493
341.60000000000446,47.033659032175706,-1.7414211448147392,-1.6532053276195855
342.7000000000045,47.14050730442314,-1.7505281423818004,-1.696679838178924
343.8000000000045,47.248129233029765,-1.7582029910650818,-1.7379927146645104
344.9000000000045,47.35432167950385,-1.7670651697157989,-1.7816417488843768
346.00000000000455,47.46167925097647,-1.7734188564623639,-1.828489245286156
347.10000000000457,47.56810432581241,-1.7808080417851804,-1.874394805538195
348.2000000000046,47.67458937062543,-1.7876317932564332,-1.9185487986230507
349.30000000000456,47.77979661791322,-1.7924607395587295,-1.9667068231849787
350.4000000000046,47.889117193016695,-1.7949161958439244,-2.014810992470312
351.5000000000046,47.99616262988807,-1.7965523398581469,-2.063058709525629
352.6000000000046,48.10291550983282,-1.7945443772791825,-2.1122647071797407
353.70000000000465,48.20848656535525,-1.7923539638505184,-2.1594799376010605
354.8000000000047,48.31469717287635,-1.785334830346904,-2.208072672595926
355.9000000000047,48.42098594630103,-1.7749410441584854,-2.25633941682265
357.00000000000466,48.52542290362195,-1.7625791639293293,-2.3013236093981897
358.1000000000047,48.633522224440824,-1.7478740250483378,-2.3477682282274808
359.2000000000047,48.73907554945945,-1.7286389223234866,-2.3915630021041396
360.30000000000473,48.842468929262665,-1.7077884296439811,-2.432830088158953
361.40000000000475,48.95081081064805,-1.6812451301439222,-2.475983661138484
362.5000000000048,49.055749042592375,-1.6537912984748195,-2.5146224258914165
363.6000000000048,49.16091408465028,-1.625884210484814,-2.5486580777156425
364.7000000000048,49.26651946897275,-1.5961199706568059,-2.5817204739632644
365.80000000000484,49.37215532281097,-1.5673494063810307,-2.612746228903459
366.9000000000048,49.47623051820444,-1.537054272414088,-2.639700587950216
368.00000000000483,49.58251859151055,-1.5101797171225588,-2.6660257056437424
369.10000000000485,49.68724074447918,-1.4826562331754178,-2.6881079028807027
370.2000000000049,49.793359089935976,-1.4587193793555457,-2.7083503102768938
371.3000000000049,49.899581221324446,-1.4329028748064285,-2.728362541470431
372.4000000000049,50.00413297724101,-1.409548937441829,-2.744112718197634
373.50000000000495,50.11039610345557,-1.3862643712603493,-2.758907473893643
374.6000000000049,50.216548519594475,-1.367288602332371,-2.772655025424914
375.70000000000493,50.323269309674224,-1.3452273672904391,-2.7840294821801743
376.80000000000496,50.42923910580245,-1.3243357511137974,-2.794107056920857
377.900000000005,50.535011880095446,-1.3074840005535289,-2.8037970655514846
379.000000000005,50.64054400835924,-1.2919866879402953,-2.8114737526861524
380.100000000005,50.74529402190496,-1.28104586835622,-2.8192416249571313
381.20000000000505,50.85384352933637,-1.2700544510512504,-2.824058000241112
382.30000000000507,50.9603017210192,-1.2616967998644586,-2.82926054209121
383.4000000000051,51.066800652910125,-1.2559918095574887,-2.8346265035773985
384.50000000000506,51.17396282412753,-1.2516067359690037,-2.8390728205142715
385.6000000000051,51.279894582768144,-1.2508388125282912,-2.843495972039996
386.7000000000051,51.38720237699668,-1.249546240781596,-2.847845785353559
387.8000000000051,51.49476262451039,-1.2454960401446378,-2.850608113068638
388.90000000000515,51.60145080088083,-1.2424935591945845,-2.8546181661155727
390.0000000000052,51.70968672594235,-1.242241598533005,-2.8573319953232996
391.1000000000052,51.81646009030173,-1.2404029542187198,-2.8606748959176
392.20000000000516,51.92286808052946,-1.2393162594980807,-2.864444086652651
393.3000000000052,52.03055718761297,-1.238253750572277,-2.868245158155368
394.4000000000052,52.13811161006169,-1.2350251147223943,-2.871120588221758
395.50000000000523,52.245059203300755,-1.2343378277914756,-2.874150543252161
396.60000000000525,52.3527164399236,-1.23216647852897,-2.8777014320556287
397.7000000000053,52.460178077386715,-1.229817652049623,-2.8811611340319256
398.8000000000053,52.56771638878013,-1.2276140286957973,-2.8855530481970626
399.9000000000053,52.674887911208906,-1.2270570479858502,-2.8878468064228455
401.00000000000534,52.78264663805177,-1.2256020042841504,-2.8907132460991507
402.1000000000053,52.8896050018986,-1.2228528245713006,-2.8946615583313675
403.20000000000533,52.99853052042176,-1.221270729239152,-2.897432907030095
404.30000000000535,53.10543751061574,-1.219795084679092,-2.900220016559736
405.4000000000054,53.21099022103733,-1.2181598643507316,-2.9035736946008592
406.5000000000054,53.32032601118926,-1.2181442909350182,-2.906176790985339
407.6000000000054,53.427856985267184,-1.218651039941815,-2.9107303616525133
408.70000000000545,53.53584374028751,-1.2176337199048508,-2.9118940018751456
409.8000000000054,53.642832883714256,-1.2150317247598454,-2.915799976254987
410.90000000000543,53.74932911553878,-1.2159275055559378,-2.918373429721671
412.00000000000546,53.857430960788975,-1.2145658747920856,-2.922267332758654
413.1000000000055,53.96651996375368,-1.2129128488009608,-2.925060534452167
414.2000000000055,54.07438557854266,-1.212186696157703,-2.9280273341458694
415.3000000000055,54.183632175346574,-1.214970335510165,-2.9304389027469915
416.40000000000555,54.29072024613953,-1.2149017452136883,-2.932429290676354
417.50000000000557,54.397617999007984,-1.2139259868553465,-2.935040877032328
418.6000000000056,54.50659776702348,-1.2172228449672993,-2.9387126941821715
419.70000000000556,54.61372661542093,-1.2213403803915244,-2.9417867916115625
420.8000000000056,54.72240530850544,-1.2278561669738197,-2.9444911148982937
421.9000000000056,54.83066112950765,-1.2404703905408458,-2.94609886010385
423.0000000000056,54.93756440749443,-1.247906595926743,-2.949689534091215
424.10000000000565,55.04616668914581,-1.2569407590908594,-2.952401813422996
425.2000000000057,55.15462552898002,-1.2652376578248457,-2.955029177481788
426.3000000000057,55.261887058787146,-1.272418062866327,-2.957688449428894
427.40000000000566,55.371988768249054,-1.2769785894128929,-2.9604133974854907
428.5000000000057,55.47951946639567,-1.2831401044098045,-2.9639070360928184
429.6000000000057,55.587531799477794,-1.2894315079853085,-2.966565719992108
430.70000000000573,55.69527298512055,-1.292639551648749,-2.9678896919999227
431.80000000000575,55.803818575506305,-1.2961158046576757,-2.9704911504475224
432.9000000000058,55.91138679915806,-1.3002702237183297,-2.9733254089477645
434.0000000000058,56.01980046547694,-1.3045313812726707,-2.9759030884398032
435.1000000000058,56.127854721074236,-1.3087746646967422,-2.9790230527736856
436.20000000000584,56.2340976765689,-1.3113951164044733,-2.9810987332740124
437.3000000000058,56.344240232383825,-1.3190668036820614,-2.983864457800932
438.40000000000583,56.45246305876689,-1.326985315290589,-2.985300192378852
439.50000000000585,56.56040557372786,-1.3326331681824313,-2.987792125202504
440.6000000000059,56.668822043901436,-1.3384657130073658,-2.9897519468567912
441.7000000000059,56.77488956596352,-1.3402303147999188,-2.992136470512266
442.8000000000059,56.88525020246125,-1.341947280476727,-2.994769179927582
443.90000000000595,56.99132816096505,-1.344531675309914,-2.996206464705784
445.0000000000059,57.10187304106554,-1.3481227177473936,-3.0001679260386838
446.10000000000593,57.21010322118064,-1.3513096319979452,-3.0003832191753763
447.20000000000596,57.319896867578834,-1.3528177281131486,-3.004218956249458
448.300000000006,57.42764274894178,-1.356749683893569,-3.0048083489309003
449.400000000006,57.53561965545024,-1.3588417789380598,-3.0075219922278165
450.500000000006,57.6448799974555,-1.364246101303297,-3.0101492260528175
451.60000000000605,57.753212752879456,-1.3663411298380899,-3.009081993892476
452.70000000000607,57.8621189747259,-1.370347114701332,-3.015574144124969
453.8000000000061,57.9676711849655,-1.373329617549344,-3.016703670497076
454.90000000000606,58.07928767128071,-1.3765379764813555,-3.018169841211353
456.0000000000061,58.18766548295647,-1.3774616672489894,-3.0209375690594014
457.1000000000061,58.29589111073606,-1.3807549148507803,-3.023540916583682
458.2000000000061,58.40549992266379,-1.383833346792096,-3.0236562197097774
459.30000000000615,58.514880447006924,-1.3882644238956021,-3.025704264031826
460.4000000000062,58.62319971422487,-1.3904716347548196,-3.028019090266388
461.5000000000062,58.73129123019332,-1.3915692392885086,-3.0291400505854114
462.60000000000616,58.83813171001894,-1.392036804488369,-3.0309593389368814
463.7000000000062,58.949150775896,-1.3933641971888848,-3.0333529498987195
464.8000000000062,59.05765672862114,-1.3939240728844022,-3.035710699689137
465.90000000000623,59.16594219919768,-1.3929865327756097,-3.0370462878538564
467.00000000000625,59.27540550783627,-1.3938620585963468,-3.039242311722661
468.1000000000063,59.38383401799679,-1.3928309494996183,-3.04099843233799
469.2000000000063,59.49275842362669,-1.3937460342524193,-3.042295878204868
470.3000000000063,59.601356440172275,-1.393899888468947,-3.043191123129311
471.40000000000634,59.71115641203831,-1.394291339073052,-3.0462760271355727
472.5000000000063,59.817433604520716,-1.3933975274378747,-3.0463025332928098
473.60000000000633,59.92970911909604,-1.3920546612097244,-3.0485492970768684
474.70000000000636,60.03894247844888,-1.3936496737806068,-3.0508681908117996
475.8000000000064,60.14899164072823,-1.3926038044940618,-3.052200223337382
476.9000000000064,60.25666282707251,-1.3935304770725139,-3.0539038321424226
478.0000000000064,60.36679777760249,-1.393314134882108,-3.056123869530631
479.10000000000645,60.475683079371265,-1.3929184895135656,-3.0574600597795865
480.2000000000064,60.58440181460564,-1.3918469515793463,-3.0581017823640555
481.30000000000643,60.693907374339005,-1.3935959977625565,-3.059440653435435
482.40000000000646,60.80378081215271,-1.3924939207567644,-3.0606021190641686
483.5000000000065,60.91331728027147,-1.3929864886495293,-3.062343392782186
484.6000000000065,61.02225059989341,-1.3912240597400536,-3.062922415982049
485.7000000000065,61.132096687724896,-1.3876272130031122,-3.064058192994983
486.80000000000655,61.24118103171383,-1.3827754393103255,-3.066679272819783
487.90000000000657,61.34927026373099,-1.377669577209829,-3.0680088373124543
489.0000000000066,61.45899553157599,-1.3705917236777356,-3.069575976074719
490.10000000000656,61.56776738169441,-1.3605485474983006,-3.0719333558610837
491.2000000000066,61.678154404605024,-1.3471488046518283,-3.071969853372753
492.3000000000066,61.78682681008836,-1.3408271375585386,-3.073928693032501
493.4000000000066,61.89585966563613,-1.3345808106289647,-3.0759103795701
494.50000000000665,62.002590901052926,-1.3303088639943468,-3.076899236417579
495.6000000000067,62.113844715241946,-1.3271809967864991,-3.075952845197731
496.7000000000067,62.223690665900726,-1.3221841152705214,-3.0786549879310945
497.80000000000666,62.33283487960031,-1.317637248742002,-3.0807700101460886
498.9000000000067,62.44135441262152,-1.3135371627601404,-3.081575152389549
500.0000000000067,62.55071068397292,-1.3082047350640331,-3.0820271935081514
501.10000000000673,62.660285689543315,-1.3035994587598367,-3.0840405426089132
502.20000000000675,62.76921992010686,-1.3005836429141404,-3.085359728029352
503.3000000000068,62.8788352856049,-1.2972337924262107,-3.0840535209773727
504.4000000000068,62.9879492990707,-1.2941435615835366,-3.0865166772355646
505.5000000000068,63.09680742876107,-1.2921284812702796,-3.0892827613983567
506.60000000000684,63.20675803313229,-1.289068816360295,-3.0904702529238044
507.7000000000068,63.315625419886366,-1.2852073553302445,-3.0906200889169946
508.80000000000683,63.42617553762182,-1.2821804688570946,-3.09081902615582
509.90000000000686,63.53595532626764,-1.2797812094867083,-3.0937038660204896
511.0000000000069,63.64548959503706,-1.2784238177376148,-3.095081735764967
512.100000000007,63.75550742320886,-1.2766851405600739,-3.096329298899405
513.2000000000069,63.86554503014485,-1.2748543945284143,-3.0963300660705553
514.300000000007,63.97474642156879,-1.2752146691803623,-3.0976490056702835
515.4000000000069,64.08479361271353,-1.2731873287712092,-3.098496022285551
516.5000000000069,64.19547501581134,-1.2702086705530917,-3.098959366835324
517.600000000007,64.30570916651016,-1.2702253976904494,-3.1002854301320775
518.700000000007,64.41464421585104,-1.2699659738715408,-3.101927876456561
519.800000000007,64.52641344834844,-1.2691663208375898,-3.103563566721098
520.900000000007,64.63570526000764,-1.2691050870163472,-3.104105238828038
522.000000000007,64.74553617254676,-1.2696010244570282,-3.1048870763959298
523.1000000000071,64.85538805055936,-1.2730667208590873,-3.1076061777495765
524.2000000000071,64.96474346762133,-1.2750478621555672,-3.1062138051794177
525.300000000007,65.07479710000672,-1.2763615898474046,-3.1075301225062635
526.4000000000071,65.18505335703533,-1.277500758009331,-3.108849886033155
527.500000000007,65.29497548586414,-1.2813715031413533,-3.1088445517214307
528.6000000000072,65.40407378967033,-1.2845824576310547,-3.1101699993482175
529.7000000000071,65.51401897481011,-1.2864937891172517,-3.111422203773561
530.8000000000072,65.62465108591823,-1.2895659340790613,-3.1127985823746576
531.9000000000071,65.73554230108786,-1.2903845419487872,-3.1138741983348077
533.0000000000072,65.84570657841617,-1.2915193756205359,-3.1150937540102044
534.1000000000072,65.9552875252998,-1.2945096786283008,-3.115110259756662
535.2000000000072,66.06594980177226,-1.2967952752980085,-3.1177399421621876
536.3000000000072,66.17491182739515,-1.2996401681185126,-3.1164197185793516
537.4000000000073,66.28688970189127,-1.3033182909576113,-3.1163420247543447
538.5000000000073,66.3960045755525,-1.3058233058826303,-3.1177400009264993
539.6000000000073,66.50438916236638,-1.3089444260382592,-3.118978304365104
540.7000000000073,66.61614822767719,-1.3117040221270138,-3.121369271623813
541.8000000000073,66.72726551372509,-1.3148571177456485,-3.1200448014116287
542.9000000000074,66.83654049492169,-1.3183420923367326,-3.122647253634939
544.0000000000074,66.94701435622049,-1.3214181039747195,-3.123340344275438
545.1000000000074,67.05688534303457,-1.3249225033112944,-3.1234923457485655
546.2000000000073,67.16683215582405,-1.3274862754639238,-3.1258389222551743
547.3000000000073,67.27812796893066,-1.3294543842839743,-3.1259699984552345
548.4000000000074,67.38723382202028,-1.3328585556925903,-3.1272958660575148
549.5000000000074,67.49593539497647,-1.3345833980475497,-3.128610320418187
550.6000000000074,67.60643217795003,-1.3372284284638705,-3.129969899313612
551.7000000000074,67.71848024132281,-1.340981520744342,-3.12927008733234
552.8000000000075,67.82862654858053,-1.3443372145505474,-3.1305799633835236
553.9000000000075,67.9407176502538,-1.3463923698745268,-3.1305800006335645
555.0000000000075,68.0504119540927,-1.3496715211521002,-3.1318967923486856
556.1000000000075,68.1609294421452,-1.3527919565074231,-3.1328678759850477
557.2000000000075,68.271407116039,-1.3557388876373493,-3.134530572670643
558.3000000000076,68.3810640400324,-1.3604285367842877,-3.13321142749614
559.4000000000076,68.49275892564025,-1.3625802350341087,-3.135740674239956
560.5000000000076,68.60390416546721,-1.3639002471438237,-3.1364063184119075
561.6000000000076,68.71316159889282,-1.3663804325066038,-3.1358500791882014
562.7000000000077,68.8228795761576,-1.369316235450408,-3.1371697627645814
563.8000000000077,68.93526457348108,-1.3706831629808536,-3.1384782667103037
564.9000000000076,69.04522645566172,-1.3751344560219216,-3.138479424122086
566.0000000000076,69.15656559123778,-1.377157432581721,-3.139799983039585
567.1000000000076,69.26615630788135,-1.379394220662703,-3.141130398060493
568.2000000000077,69.37586958527612,-1.3838882253590867,-3.1398091913011745
569.3000000000077,69.48910490709163,-1.3838904636627332,-3.1414590017202597
570.4000000000077,69.5976093741479,-1.387306189099991,-3.1421096656102367
571.5000000000077,69.71020959046972,-1.3885855202005146,-3.1421094407367542
572.6000000000078,69.82182726958625,-1.3914232847212495,-3.143429942074441
573.7000000000078,69.9318363156352,-1.392986591888821,-3.143429999833299
574.8000000000078,70.04246115800383,-1.3962673130694465,-3.1448382672245385
575.9000000000078,70.15314701520519,-1.398516523769552,-3.1447499982422435
577.0000000000078,70.26400494287154,-1.400110457811507,-3.146069598191366
578.1000000000079,70.37517176120615,-1.402965654644264,-3.1463209531293512
579.2000000000079,70.48595431866092,-1.4059261693528993,-3.146408413887043
580.3000000000079,70.59766418770636,-1.4102364487493162,-3.1478714736004973
581.4000000000078,70.70788509808494,-1.4111452482649103,-3.1491601906339395
582.5000000000078,70.81896284144776,-1.4158832112354307,-3.15149015363824
583.6000000000079,70.93010326156357,-1.4179505056047486,-3.1513299999953563
584.7000000000079,71.04167279745116,-1.423114797350919,-3.1513300272596796
585.8000000000079,71.14978422678583,-1.4250941919943751,-3.152650013925483
586.9000000000079,71.26317727103712,-1.4300636289620143,-3.1525944785578344
588.000000000008,71.3736917368006,-1.4321174661536171,-3.153996515980375
589.100000000008,71.48426366341967,-1.4337739816008253,-3.1526067465251693
590.200000000008,71.59455352346312,-1.437443951376398,-3.1553257009130733
591.300000000008,71.70637169356391,-1.4382509029698707,-3.155280000209472
592.400000000008,71.81716087457929,-1.4412785299700432,-3.1544590224152356
593.5000000000081,71.9274819011905,-1.4453443566302402,-3.155444369739218
594.6000000000081,72.03901834698812,-1.448714217701302,-3.1565999998832557
595.7000000000081,72.14930683897065,-1.4492786758031775,-3.1565998201375054
596.8000000000081,72.2608604734079,-1.453612616258988,-3.1566109201244474
597.9000000000082,72.37257288097608,-1.4559206087332197,-3.156747434031044
599.0000000000082,72.48351806533023,-1.461654133642406,-3.157945687452286
600.1000000000081,72.59335267238305,-1.4635966749645357,-3.159402756449042
601.2000000000081,72.70493002061555,-1.466029069892704,-3.161530245812378
602.3000000000081,72.81578275324742,-1.4717613315779454,-3.1615500123913876
603.4000000000082,72.92668851407636,-1.4778892753722987,-3.160867553743596
604.5000000000082,73.03869259185983,-1.4795132566707658,-3.1611891769011145
605.6000000000082,73.15010865101891,-1.4814623341484165,-3.16386626458723
606.7000000000082,73.26020938373432,-1.4848629562004,-3.1635055589737373
607.8000000000083,73.37319721786496,-1.491078065419392,-3.164717566013888
608.9000000000083,73.4837999709782,-1.4937945389557443,-3.164927693092149
610.0000000000083,73.59402006508259,-1.4965215799333804,-3.166012328934054
611.1000000000083,73.70580999695828,-1.5013476009659417,-3.1673600011039142
612.2000000000083,73.81793747155015,-1.5062571665989088,-3.1673600000127546
613.3000000000084,73.92989788857506,-1.509126094261586,-3.1673580175989517
614.4000000000084,74.04105739189525,-1.5125174389740004,-3.1686790669772797
615.5000000000084,74.15173313486375,-1.5163817599914824,-3.1673534019971745
616.6000000000083,74.26320145659918,-1.5203950142087412,-3.1702472141045526
617.7000000000083,74.37475543996167,-1.5237485946899816,-3.170110000258618
618.8000000000084,74.48619547764721,-1.5272761394838374,-3.170109762519586
619.9000000000084,74.59634415494152,-1.5271589213113461,-3.1714484839251496
621.0000000000084,74.70663514720376,-1.527700141478596,-3.1727372358701227
622.1000000000084,74.81713636287576,-1.5272487936320707,-3.174504828294964
623.2000000000085,74.9284273078086,-1.5296484931589174,-3.1753798993010998
624.3000000000085,75.03874424759361,-1.5305136742889274,-3.174719821441908
625.4000000000085,75.15094527129197,-1.5330865407696719,-3.17602995449204
626.5000000000085,75.26154009170315,-1.5348893205945615,-3.1760300000388613
627.6000000000085,75.37295171103449,-1.537071951631344,-3.1765663560392996
628.7000000000086,75.48338238901428,-1.5410834426955484,-3.1776493932339944
629.8000000000086,75.59628117865165,-1.5452179221265483,-3.1785372241920613
630.9000000000086,75.70732414788687,-1.551098294917831,-3.179344399255453
632.0000000000086,75.81732725774947,-1.556319009080691,-3.1806394540914136
633.1000000000087,75.92929171619353,-1.5609703494553848,-3.181959885604646
634.2000000000087,76.04115085429673,-1.5668500902267588,-3.18327986363001
635.3000000000086,76.15312434915963,-1.5711538967777527,-3.1845922890374343
636.4000000000086,76.26518654168787,-1.5771677759534417,-3.184595527770743
637.5000000000086,76.37466433372903,-1.5811633256215238,-3.185454817884055
638.6000000000087,76.48743844888823,-1.5876593408583954,-3.186652579707383
639.7000000000087,76.59876705858196,-1.5934109127400988,-3.1885496797460475
640.8000000000087,76.70958794305312,-1.6008899090832676,-3.189867667749052
641.9000000000087,76.82252928226026,-1.6060421733186867,-3.1900609451493542
643.0000000000088,76.93346387710066,-1.6094933505304323,-3.191189999943818
644.1000000000088,77.04507235434441,-1.6170869541739608,-3.1912168590595194
645.2000000000088,77.15554037965607,-1.620889677033244,-3.192513058692445
646.3000000000088,77.2682664175369,-1.6218185695014724,-3.193159965771121
647.4000000000088,77.37888327915195,-1.6249420536246966,-3.1944637935585236
648.5000000000089,77.49128835017662,-1.6275720618523464,-3.193822482420357
649.6000000000089,77.60297595686595,-1.6295257446141198,-3.1978905836787
650.7000000000089,77.71414138794225,-1.6317508059196741,-3.1965560725427324
651.8000000000088,77.82622558144364,-1.6321043280898342,-3.1966744081585854
652.9000000000088,77.93731297204675,-1.634810348102239,-3.1992050142927018
654.0000000000089,78.04866828179685,-1.6340680503556992,-3.2005203594440257
655.1000000000089,78.16033327523951,-1.631563811077437,-3.2018405789536626
656.2000000000089,78.27154605395803,-1.6334572120189659,-3.203150000097591
657.3000000000089,78.38262614498211,-1.6342483475767517,-3.2023715409243136
658.400000000009,78.49457956075632,-1.6352945482271264,-3.20348000495468
659.500000000009,78.60665786669998,-1.6342506443266995,-3.2044412457370464
660.600000000009,78.71656903012845,-1.6328743376971793,-3.204799999939871
661.700000000009,78.82939948400339,-1.6299791447587508,-3.2045750917573237
662.800000000009,78.94192890996943,-1.6292786361840867,-3.2057811569202714
663.9000000000091,79.05319360578204,-1.6271493033555793,-3.20711612395705
665.0000000000091,79.16463578721547,-1.6249373639562337,-3.208030567136727
666.1000000000091,79.27615593167732,-1.6196956084604013,-3.207762180749789
667.2000000000091,79.3880001997763,-1.6165019997062333,-3.2084296767228393
668.3000000000092,79.5003321889242,-1.6140515452276236,-3.20842337189756
669.4000000000092,79.6120392044371,-1.6115099972938556,-3.210813396917428
670.5000000000091,79.72366837601284,-1.6103436007319258,-3.2096217640792553
671.6000000000091,79.83650654272566,-1.6116410166381165,-3.2107299746736637
672.7000000000091,79.9481385887597,-1.6125491255287927,-3.212051444442799
673.8000000000092,80.05979526134325,-1.6153502030958449,-3.2120565145682685
674.9000000000092,80.17208423828345,-1.6168421690245158,-3.2133225268910275
676.0000000000092,80.28437400712141,-1.6200221853426637,-3.212040707001574
677.1000000000092,80.39585119164084,-1.6210002371617869,-3.2120400001348215
678.2000000000093,80.50770067584017,-1.620474250701047,-3.212398760544027
679.3000000000093,80.61719866230354,-1.6219077823357053,-3.2136900224201135
680.4000000000093,80.73107716282708,-1.6263644171512848,-3.2136901820132797
681.5000000000093,80.8419580655984,-1.6273644865048777,-3.2150099265898024
682.6000000000093,80.95430751754323,-1.6257407113280027,-3.2154147964278654
683.7000000000094,81.06321544085553,-1.625459436020663,-3.2150267618594626
684.8000000000094,81.17737156206748,-1.6264040910880706,-3.216326159565675
685.9000000000094,81.28889365674948,-1.6281134461868612,-3.217006397432579
687.0000000000093,81.4007921565618,-1.631018387967208,-3.2182995802643948
688.1000000000093,81.51251297112023,-1.6301832023057723,-3.216982038144984
689.2000000000094,81.6242354527112,-1.6319511172105448,-3.2169800000420135
690.3000000000094,81.73724074731358,-1.632396877963162,-3.2168985640900276
691.4000000000094,81.84671042624969,-1.6351834231361253,-3.2183000001190516
692.5000000000094,81.96010256429507,-1.6368734288272597,-3.2183004340076264
693.6000000000095,82.07058596548804,-1.6356621520665355,-3.2196200079517228
694.7000000000095,82.18367697267246,-1.6337811918223728,-3.220980628158223
695.8000000000095,82.29690249631871,-1.6329479374500417,-3.2199397650985895
696.9000000000095,82.40820361457602,-1.6343306986438642,-3.2212600996716256
698.0000000000095,82.52088255975616,-1.6361888145247976,-3.221260000000343
699.1000000000096,82.63211847240116,-1.6369811549555893,-3.221258233541588
700.2000000000096,82.7435459558867,-1.6382619135371934,-3.222584190368159
701.3000000000096,82.8559753863601,-1.637655706022542,-3.223901311803556
702.4000000000096,82.96815033968885,-1.6385597196707669,-3.223577541753121
703.5000000000097,83.07798849193851,-1.639114248971853,-3.223564256469456
704.6000000000097,83.19021776440756,-1.6400357229553297,-3.223569888215442
705.7000000000096,83.30211237976974,-1.6373012378613425,-3.2248900040224515
706.8000000000096,83.41391944080608,-1.6402039619282274,-3.2262109533035335
707.9000000000096,83.5254562545123,-1.6390679833928266,-3.225868910950294
709.0000000000097,83.63805040761498,-1.6409915958051222,-3.2238969493498013
710.1000000000097,83.7496923942609,-1.6428296244013239,-3.226539899621421
711.2000000000097,83.86137948562852,-1.6454662933910496,-3.2265300173934515
712.3000000000097,83.97355492624801,-1.6506087639479543,-3.22794752573271
713.4000000000098,84.08530703588367,-1.6522201085226436,-3.229170152353365
714.5000000000098,84.19804845670205,-1.6560837832766473,-3.2281806360668996
715.6000000000098,84.309681228888,-1.655783151848221,-3.2294994950807405
716.7000000000098,84.42245876859783,-1.6603959222817095,-3.230489931253298
717.8000000000098,84.53613851888962,-1.6625496428709996,-3.2291508176697405
718.9000000000099,84.64721575882433,-1.6674355226050914,-3.2291700570265234
720.0000000000099,84.75807443344925,-1.673814912276065,-3.231480861633302
721.1000000000099,84.87239814211858,-1.67966997957736,-3.231463814308489
722.2000000000098,84.983616407554,-1.685266927947588,-3.230487405582426
723.3000000000098,85.09659448696397,-1.690625377762014,-3.232811650433804
724.4000000000099,85.20871073765748,-1.6959863112472369,-3.23411084160523
725.5000000000099,85.32107711752506,-1.7026885874287634,-3.2327893241575043
726.6000000000099,85.43411050040964,-1.7109481605324657,-3.234110328093571
727.7000000000099,85.5464554675851,-1.7164672650723969,-3.2350999513474794
728.80000000001,85.65758750726516,-1.7259770185428502,-3.2337990548514535
729.90000000001,85.77121501933523,-1.7338593508953988,-3.235090349279849
731.00000000001,85.88359221682099,-1.7408823437216951,-3.23641592349125
732.10000000001,85.99574262971014,-1.7502585010161464,-3.2377350751441387
733.20000000001,86.10876561686207,-1.758959031889906,-3.2376798411573207
734.3000000000101,86.22074040207588,-1.767227922154222,-3.237730004908049
735.4000000000101,86.33319072977106,-1.7792391131148335,-3.2364093172597164
736.5000000000101,86.44555879847579,-1.7849011291086636,-3.238697310136947
737.6000000000101,86.55717795096406,-1.7898726162047531,-3.240119282662919
738.7000000000102,86.6704084106574,-1.8001674194964008,-3.240039898987498
739.8000000000102,86.78251671683631,-1.810382946423104,-3.237402053917348
740.9000000000101,86.8956038102049,-1.8166070011654614,-3.238720033814691
742.0000000000101,87.00781797293507,-1.8264999362736967,-3.238720323539855
743.1000000000101,87.12142119682976,-1.833634987929692,-3.2400381966736043
744.2000000000102,87.23320344205814,-1.8427165865404145,-3.2426373168315203
745.3000000000102,87.34583221005423,-1.8522840317481049,-3.241359718151107
746.0000000000102,87.41683711897207,-1.857579968409161,-3.2426942397932645