File: 01_Data/Cardboard/STA/N2/10K_min/Cardboard_STA_N2_10KData_230818_R4.csv
##Temp./Â°C,Time/min,DSC/(mW/mg),Mass loss/mg
28.0,15.656334533153142,-2.3550246398373185,-0.08497170239173801
29.100000000000016,16.034156979346175,-2.3090533334625247,-0.09020157517477223
30.20000000000003,16.265928665028888,-2.284982122726816,-0.09309573701034202
31.300000000000047,16.449588934663566,-2.2669106570550053,-0.09250378883465604
32.40000000000006,16.622045444015555,-2.254494764770057,-0.09452628894313353
33.50000000000008,16.775434890151097,-2.244166882373039,-0.09497650268078894
34.600000000000094,16.919593264711818,-2.2378819638750325,-0.09692593825631901
35.70000000000011,17.05892615450151,-2.232616351653139,-0.09985714581212912
36.800000000000125,17.193936363120272,-2.230235442686083,-0.0990729096297609
37.90000000000014,17.32642468983044,-2.2279253868723403,-0.10032679934814093
39.000000000000156,17.455089018695435,-2.2261949717256053,-0.10108606175292012
40.10000000000017,17.58243953868896,-2.227579163151594,-0.10070088685524148
41.20000000000019,17.70451924988688,-2.2266415283486927,-0.10061737319987252
42.3000000000002,17.8329889853669,-2.2275650397421316,-0.10189873336526167
43.40000000000022,17.95250490344868,-2.2307212767379436,-0.10327236664716688
44.500000000000234,18.079790045153906,-2.23238996985341,-0.10461995007897817
45.60000000000025,18.20110138063518,-2.2344917921369465,-0.10586442540197138
46.700000000000266,18.321837639657574,-2.237937950091419,-0.10586625256815152
47.80000000000028,18.44300107648844,-2.240757279116537,-0.1084756779455267
48.9000000000003,18.564140032751038,-2.2443596817061033,-0.11109411797650415
50.00000000000031,18.68159838686323,-2.248224909876276,-0.11374059301270956
51.10000000000033,18.801134296071687,-2.2519970443186783,-0.11447978864307284
52.200000000000344,18.918919099585835,-2.2546100736437493,-0.11638027000937745
53.30000000000036,19.036714004664873,-2.2588917308290015,-0.11771455944378495
54.400000000000375,19.152279727759264,-2.262333233566255,-0.11833818370516447
55.50000000000039,19.2679484434172,-2.2650766814170833,-0.1209661543840066
56.600000000000406,19.384992224803856,-2.2667118434566054,-0.1222711071459619
57.70000000000042,19.50026864193775,-2.2697481277525147,-0.12284762669206639
58.80000000000044,19.614260648601515,-2.271615813641989,-0.1262259743996319
59.90000000000045,19.728111437176693,-2.2741927403795366,-0.12758449742403588
61.00000000000047,19.841677810510664,-2.2729758864998315,-0.13138448109012169
62.100000000000485,19.95370984551149,-2.274300058620106,-0.13251043257128536
63.2000000000005,20.06659099728884,-2.2741448329200633,-0.13382803005417943
64.30000000000052,20.179434637575937,-2.2722733187677675,-0.13677768090571485
65.40000000000053,20.29225538413191,-2.2725090244427815,-0.13812433917940847
66.50000000000054,20.40353766684582,-2.2700797523699836,-0.14350353349969414
67.60000000000056,20.515217215391058,-2.266273196163787,-0.14350279744254246
68.70000000000059,20.625342630855016,-2.263829863539901,-0.14480937950297745
69.8000000000006,20.735933790959493,-2.2595589206772253,-0.14743796434510115
70.9000000000006,20.845797195416033,-2.255854228270312,-0.15011279895082996
72.00000000000063,20.957381843013117,-2.249614714451554,-0.15271975619367018
73.10000000000065,21.06725313824371,-2.2432243379284644,-0.15657964775194033
74.20000000000066,21.175799259663187,-2.23622571910707,-0.15666026765731855
75.30000000000067,21.28583906432569,-2.229162607536818,-0.15929993158501832
76.40000000000069,21.395992009408197,-2.2202989194919587,-0.1619442869690868
77.50000000000071,21.503357139651886,-2.212545036081583,-0.1645801661834252
78.60000000000072,21.61244019254068,-2.203471370612657,-0.1657753444584995
79.70000000000073,21.722231224802666,-2.1944504523467647,-0.16986990119056067
80.80000000000075,21.830433782639485,-2.1852175876037276,-0.16983441101187635
81.90000000000077,21.938894856654624,-2.1743714932688114,-0.1724921963737116
83.00000000000078,22.048428799941366,-2.163168252054587,-0.17510886274355286
84.10000000000079,22.15608846070334,-2.152783906569637,-0.1764442508141788
85.20000000000081,22.264132989977366,-2.1428795616095773,-0.17901123170594024
86.30000000000084,22.372469450969668,-2.1312334045468346,-0.1803838294739708
87.40000000000084,22.47959169538269,-2.1185032552120213,-0.1803801268723908
88.50000000000085,22.586990802297837,-2.1067633786141884,-0.18300988890871128
89.60000000000088,22.693677025105817,-2.095683635503781,-0.18532001393910935
90.7000000000009,22.802379683831766,-2.0827863273500995,-0.1863105154932283
91.8000000000009,22.909816823631107,-2.072042780627316,-0.18667316342898488
92.90000000000092,23.016266103606018,-2.061893703452406,-0.1879479838758682
94.00000000000094,23.12348398643499,-2.049857752686082,-0.18959897066310338
95.10000000000096,23.230132816295185,-2.037224146258848,-0.1909198699547643
96.20000000000097,23.33694814354579,-2.025577190066692,-0.1927923251268071
97.30000000000098,23.443488387696807,-2.0151253496798827,-0.19487049750545138
98.400000000001,23.54782158541234,-2.0027310964266465,-0.19585869747897888
99.50000000000102,23.656995075133043,-1.991180676668074,-0.19460523498906301
100.60000000000103,23.763400071838795,-1.979758775702962,-0.19585017209232758
101.70000000000104,23.868746901949134,-1.9705282616146198,-0.19716992525965793
102.80000000000106,23.972797292370483,-1.96087050453517,-0.1957826682599184
103.90000000000109,24.08132007603636,-1.949532645427493,-0.19904326913000103
105.0000000000011,24.188755772132247,-1.9407049626567017,-0.1987101509872118
106.1000000000011,24.29475761207403,-1.9295993444659114,-0.20036800733143023
107.20000000000113,24.4008824816844,-1.919653449579751,-0.20281935021386133
108.30000000000115,24.507862023209032,-1.9116220574530316,-0.20239133392573194
109.40000000000116,24.613382333949474,-1.9030165717646992,-0.20199032803128336
110.50000000000117,24.720023272445623,-1.8941137058542397,-0.20285518197979346
111.60000000000119,24.824861163360467,-1.8867876989371835,-0.202769620221114
112.70000000000121,24.931531485017167,-1.8788911751705446,-0.20283228000818543
113.80000000000122,25.036844322301434,-1.872063786885021,-0.20277996000153964
114.90000000000123,25.14337357517522,-1.8630775051679662,-0.20277710664387438
116.00000000000125,25.249622418308658,-1.8578658766356893,-0.20486108553663884
117.10000000000127,25.354728725999358,-1.8515746727058902,-0.20222797112176938
118.20000000000128,25.46128705859889,-1.8456839851706939,-0.20279759679509235
119.30000000000129,25.56674360827159,-1.8403207074202435,-0.20354027958424492
120.40000000000131,25.672085087713175,-1.8335165989533289,-0.20221954520335306
121.50000000000134,25.77868577705406,-1.8282367609855255,-0.2022207685317059
122.60000000000134,25.885131338421054,-1.8223072406205931,-0.20490623597419555
123.70000000000135,25.990283426963593,-1.8163284445963668,-0.20486183142256253
124.80000000000138,26.09656122253295,-1.8125841448544076,-0.2048566805692369
125.9000000000014,26.19950001073384,-1.8087843955925575,-0.2048601671656085
127.0000000000014,26.3081648816474,-1.8048914738090704,-0.2035731702834318
128.10000000000142,26.41502373487549,-1.8007543672649324,-0.20617010843003847
129.20000000000144,26.520439740407564,-1.7954360001981224,-0.20616920764357838
130.30000000000146,26.6258709317695,-1.7919216684226016,-0.2074697226228941
131.40000000000146,26.731119288589287,-1.7888893204033671,-0.20486137441942853
132.50000000000148,26.837242525983577,-1.7863063698840669,-0.20481445203454696
133.6000000000015,26.943262392751006,-1.7837333271709592,-0.20484519258202338
134.70000000000152,27.047928086969918,-1.7790175937029784,-0.20387012162003115
135.80000000000155,27.153755470378094,-1.775367536991961,-0.20519375936022177
136.90000000000154,27.25987913610858,-1.7718653719779942,-0.20519011199983161
138.00000000000156,27.36586058024949,-1.771050442580356,-0.20519179870018434
139.1000000000016,27.470802814339116,-1.7678428731147469,-0.20350848446478098
140.20000000000158,27.576351243986522,-1.765911656049411,-0.2048563406210544
141.3000000000016,27.681813360179063,-1.762212426083255,-0.20573356805704535
142.40000000000163,27.78630038416685,-1.7600549764047555,-0.20715997841928013
143.50000000000165,27.892691300691897,-1.7573135294393742,-0.20715962683276246
144.60000000000167,27.995420293930163,-1.755651003159685,-0.20716179077272834
145.70000000000167,28.102331508292274,-1.7527254463446034,-0.2082694084140888
146.8000000000017,28.207338607500066,-1.7511999640548135,-0.20716994807172728
147.9000000000017,28.312620650022648,-1.7478741493043066,-0.20847849930614926
149.0000000000017,28.418052655357744,-1.745711755730788,-0.2084881555232374
150.10000000000173,28.523078338701634,-1.744052376168172,-0.2084899366173225
151.20000000000175,28.62693022329341,-1.7416423760063828,-0.2078491743294406
152.30000000000177,28.733243063822925,-1.7405500033671701,-0.20717004044525789
153.4000000000018,28.83843098623719,-1.7383929412582058,-0.2071604721092002
154.5000000000018,28.943403057172834,-1.7344087217274018,-0.20683019258797186
155.6000000000018,29.047159290102925,-1.7332420220674902,-0.20582739538557515
156.70000000000184,29.152609802188675,-1.7314762382645872,-0.20715989826605963
157.80000000000183,29.257954889551407,-1.7301374657769677,-0.20716055585987236
158.90000000000185,29.362584804745456,-1.7274884952617506,-0.20847997137803764
160.00000000000188,29.46753790428112,-1.7241010503520402,-0.20715691242367074
161.1000000000019,29.57208495363885,-1.7229466853651914,-0.2068221757501414
162.20000000000192,29.677771609281393,-1.71857078264276,-0.20944165762929812
163.30000000000192,29.78237303009326,-1.7198746244824532,-0.2084962759337463
164.40000000000194,29.887699182738693,-1.7187263614800534,-0.2095518976773736
165.50000000000196,29.993180044888174,-1.7169475926902398,-0.20686824068810905
166.60000000000196,30.09823629239652,-1.7151968698634006,-0.2068400691909793
167.70000000000198,30.20235032602463,-1.7137466997469188,-0.20815963858673525
168.800000000002,30.30773144198918,-1.7116618146933409,-0.20814624976606266
169.90000000000202,30.4129212284449,-1.7108411080241714,-0.20946898812491455
171.00000000000205,30.518524245902377,-1.708343514842068,-0.20814993946668015
172.10000000000204,30.623785677658592,-1.706243766092687,-0.20946981743567106
173.20000000000206,30.728520956840597,-1.7058242104412074,-0.21152592059849162
174.3000000000021,30.83183825273524,-1.703769613816443,-0.21298412970964398
175.40000000000208,30.93944564531327,-1.7039850448996763,-0.21278547726557484
176.5000000000021,31.043503278058605,-1.7024218411361338,-0.2120658859345248
177.60000000000213,31.14875339409455,-1.7004087957476204,-0.21009144356304432
178.70000000000215,31.2531986412653,-1.7001001838485281,-0.21078408604547327
179.80000000000217,31.359027700380643,-1.697797972994957,-0.21176261526213347
180.90000000000217,31.46314046512878,-1.6949609164204638,-0.2117700146263024
182.0000000000022,31.569322440118288,-1.6946117336395838,-0.21046557048620107
183.1000000000022,31.67430744598783,-1.6925472845460652,-0.2117709724715584
184.2000000000022,31.77758058561456,-1.6922341072876113,-0.2117798480093933
185.30000000000223,31.88259634150109,-1.6914426004826586,-0.21177984799556748
186.40000000000225,31.987099718863327,-1.6900485049742635,-0.21228537207888465
187.50000000000227,32.091669105238395,-1.6878970539169773,-0.2117748271099642
188.6000000000023,32.19699347976798,-1.6877671884029222,-0.211782635331502
189.7000000000023,32.300245250056484,-1.6853534270478931,-0.21112011997472901
190.8000000000023,32.40585732849909,-1.6849840207987077,-0.21044907528519508
191.90000000000234,32.510744476844586,-1.6849966794109692,-0.21045996133350275
193.00000000000233,32.61437676773499,-1.6832020537850043,-0.21178273395862357
194.10000000000235,32.718957989123545,-1.68092441045212,-0.2124310836379273
195.20000000000238,32.82335161369556,-1.6809200546745084,-0.21376011428655683
196.3000000000024,32.92852333479773,-1.678455310198123,-0.21375912752281812
197.40000000000242,33.03258392719308,-1.679232093523649,-0.21273968557999723
198.50000000000242,33.13833000000025,-1.6782599999999834,-0.21445678966694448
199.60000000000244,33.242558337231266,-1.6770146393587972,-0.21316916037959732
200.70000000000246,33.347178068860956,-1.6753346966847091,-0.21308914298255566
201.80000000000246,33.451479622180436,-1.6734209417839698,-0.21341966442754945
202.90000000000248,33.55635238986684,-1.673631865393237,-0.21575029438131388
204.0000000000025,33.66033338146248,-1.6729788023052186,-0.21572984796469274
205.10000000000252,33.76522764629791,-1.6700952916487646,-0.21573073324005554
206.20000000000255,33.86841104789164,-1.6701897546145297,-0.2160629416009323
207.30000000000254,33.9737100705564,-1.6687317811291589,-0.21598114233907806
208.40000000000256,34.079968379869946,-1.6684299739171558,-0.21705018427798484
209.5000000000026,34.18365170290711,-1.6680663853257969,-0.21705018873022341
210.60000000000258,34.28944110201264,-1.6664706862833039,-0.21779222482402671
211.7000000000026,34.394138807102486,-1.6656007536966522,-0.21899992598243623
212.80000000000263,34.49910623941569,-1.665381224469261,-0.22110368182665052
213.90000000000265,34.60360437964546,-1.6642595751354374,-0.22103421030291237
215.00000000000267,34.708134709545504,-1.6642870454924346,-0.21996213603821957
216.10000000000267,34.8133078702931,-1.6634202137905854,-0.2204190432427926
217.2000000000027,34.91814226239852,-1.6626531972065743,-0.2223756272374735
218.3000000000027,35.022432316378286,-1.6610503783427726,-0.2236264350004462
219.4000000000027,35.12715244445897,-1.6593053197063663,-0.2223308548842695
220.50000000000273,35.23209264163039,-1.6585130668824293,-0.22374528778696057
221.60000000000275,35.336631204633214,-1.6566534730526539,-0.22408467162515233
222.70000000000277,35.44185115505307,-1.6569784079157597,-0.22297006922058982
223.8000000000028,35.54523048437981,-1.6540296615930692,-0.2255137811395298
224.9000000000028,35.65069799455365,-1.6545561488316356,-0.22822359431863015
226.0000000000028,35.75577849651016,-1.6528228928137192,-0.227462351236146
227.10000000000284,35.85900789085868,-1.6514810850605934,-0.22824006784891004
228.20000000000283,35.96544631885018,-1.6516190398266963,-0.22824008124234263
229.30000000000285,36.07008753558011,-1.6509048332738354,-0.22955930100466748
230.40000000000288,36.17519388643656,-1.6499671103942817,-0.22956067609649056
231.5000000000029,36.28075783438234,-1.648604034451874,-0.23122280338878642
232.60000000000292,36.38507764707429,-1.6479146982759647,-0.23250594350244747
233.70000000000292,36.49093270265899,-1.6459230512086211,-0.23383997454716487
234.80000000000294,36.594888934437954,-1.6465508815978531,-0.23385364502028416
235.90000000000296,36.700182105519865,-1.6453753172833945,-0.2359726689165238
237.00000000000296,36.80582562044833,-1.64473601742974,-0.2378647600082484
238.10000000000298,36.910628608122074,-1.6442488291264512,-0.23910864290873812
239.200000000003,37.01338018113226,-1.643260229332569,-0.2391099519973956
240.30000000000302,37.11724043664894,-1.642355792550766,-0.23910996299183562
241.40000000000305,37.22434557674273,-1.6418481613673939,-0.24220444059227786
242.50000000000304,37.32968037922856,-1.640358051632882,-0.2463606570994239
243.60000000000306,37.433232148411335,-1.639895712143751,-0.24741756307578333
244.7000000000031,37.537782775489504,-1.638848981419286,-0.24900772403189064
245.80000000000308,37.64396439136812,-1.6384252950946636,-0.2516782578780532
246.9000000000031,37.74787779296436,-1.637908690447614,-0.25294412070879524
248.00000000000313,37.853040366361164,-1.6372596328684779,-0.2542869406551378
249.10000000000315,37.957262297619465,-1.6362095055090886,-0.2552503902240524
250.20000000000317,38.0636972785298,-1.6352294063276096,-0.25712574520495135
251.30000000000317,38.1680418239165,-1.6342677124991836,-0.2606028380298735
252.4000000000032,38.272123933666876,-1.6329826308785382,-0.2626458382250889
253.5000000000032,38.37800171006935,-1.632601225901485,-0.2662629486885426
254.6000000000032,38.48260471813112,-1.6316258933281966,-0.26954027383455603
255.70000000000323,38.58625163309377,-1.631401551017591,-0.27042775848518064
256.80000000000325,38.6921026802484,-1.6302692047009646,-0.272799632720381
257.9000000000033,38.795620198232356,-1.6286351183521,-0.2764455497990035
259.0000000000033,38.90051816863773,-1.628127599886795,-0.2801408324403529
260.1000000000033,39.003668422826046,-1.6283526338461822,-0.280878541958435
261.20000000000334,39.10990492271159,-1.6279385918811589,-0.28610483273993736
262.30000000000337,39.2155594324626,-1.6276185800463012,-0.28998395362870033
263.40000000000333,39.32045571869864,-1.6276249594365406,-0.294122285029907
264.50000000000335,39.42475119868981,-1.6262088594432145,-0.2991368482920178
265.6000000000034,39.52932542074089,-1.6262252318733712,-0.3050837081941782
266.7000000000034,39.634989252202416,-1.624716786818281,-0.30978123391712753
267.8000000000034,39.74050232090009,-1.6264318823405766,-0.31574828501265495
268.9000000000034,39.84476069499978,-1.6267833799225073,-0.320896403654515
270.0000000000034,39.95074481196788,-1.6254122967617464,-0.32524773124397655
271.10000000000343,40.0555753429727,-1.6266269865489031,-0.3317404521915064
272.20000000000346,40.160513155243,-1.6251570818404146,-0.3365773915487873
273.3000000000035,40.26638771588774,-1.6250475038382792,-0.34298153834374423
274.4000000000035,40.37124142603664,-1.627006207272051,-0.34990018583205806
275.5000000000035,40.47582606748973,-1.6273858923682585,-0.356206430777366
276.60000000000355,40.58147849026438,-1.6271686493240318,-0.36299544752965085
277.70000000000357,40.686908745436504,-1.626273489289731,-0.37050545962603776
278.8000000000036,40.79285603967141,-1.6286197978690196,-0.3780572611277786
279.9000000000036,40.8968671307702,-1.6287495143836173,-0.3842830214529269
281.0000000000036,41.00253176469488,-1.628459979813247,-0.39384231761587296
282.1000000000036,41.1091986573506,-1.6295331910721014,-0.40309714417150877
283.2000000000036,41.21342722676799,-1.6310684666346371,-0.4121868534634938
284.30000000000365,41.31992906298656,-1.63161099360833,-0.42092795383363013
285.4000000000037,41.424226957536895,-1.63120700805389,-0.42938530405333575
286.5000000000037,41.5290385897395,-1.6336118335405088,-0.4376640870978359
287.60000000000366,41.63570437859541,-1.6357195732911995,-0.44771062240706394
288.7000000000037,41.74197884626824,-1.6368093741784455,-0.4585716000862914
289.8000000000037,41.84646683337987,-1.6381429701380172,-0.47122031615502813
290.90000000000373,41.95246103834606,-1.6390426370446778,-0.48186174436103
292.00000000000375,42.055952998903635,-1.6411556514054162,-0.49442007767309715
293.1000000000038,42.162179968481354,-1.6450511976431583,-0.5062838225683679
294.2000000000038,42.26862761246036,-1.6465273680648946,-0.5192051200993091
295.3000000000038,42.373089552592184,-1.6495212337171674,-0.5322979107086612
296.40000000000384,42.478673824754715,-1.652273258710622,-0.547319016764205
297.5000000000038,42.58453156723382,-1.653448919435068,-0.5603357130567592
298.60000000000383,42.689385211968634,-1.657736174347572,-0.573058562920929
299.70000000000385,42.79476482132926,-1.6617171597862823,-0.5894844301092239
300.8000000000039,42.90103017438094,-1.6647313345789945,-0.6059999054619718
301.9000000000039,43.007343970906405,-1.6686945006563005,-0.6206171815231345
303.0000000000039,43.11281700674153,-1.6718898079479223,-0.6356970292384196
304.10000000000394,43.21851263378833,-1.6761759651900563,-0.652374590439754
305.2000000000039,43.32346871296062,-1.6810244995866301,-0.6701016424518502
306.30000000000393,43.43080028929846,-1.6834112491202755,-0.6888563964453542
307.40000000000396,43.537054289173874,-1.6874763623773288,-0.7084669715584315
308.500000000004,43.64247447536549,-1.690452656287242,-0.7272978723981645
309.600000000004,43.7484276967685,-1.6951144139268435,-0.746549887127832
310.700000000004,43.85453068313089,-1.7001385912174432,-0.7657238997795659
311.80000000000405,43.960893511087505,-1.7048919670470155,-0.7860213854131599
312.90000000000407,44.06722635379174,-1.708940275821266,-0.8078817828160347
314.0000000000041,44.1734206306034,-1.7138061575115093,-0.8294156072340217
315.10000000000406,44.28023448921263,-1.716432368921445,-0.8529680303462661
316.2000000000041,44.38632140430644,-1.722413298918317,-0.8720944971613815
317.3000000000041,44.491865080545146,-1.727121055570253,-0.8987720361609446
318.4000000000041,44.59860256565797,-1.732163783613178,-0.92234660127628
319.50000000000415,44.70506893605489,-1.73516675329556,-0.9478949922025661
320.6000000000042,44.81138351315433,-1.7402273898844258,-0.9739540915804366
321.7000000000042,44.91655729634348,-1.7438784591485865,-1.0005951438258935
322.80000000000416,45.023925847562424,-1.7503407574999772,-1.025379595520898
323.9000000000042,45.12919310155769,-1.7558251918580372,-1.0540762132534152
325.0000000000042,45.23531133495548,-1.762533108500277,-1.081872961727433
326.10000000000423,45.342252732667426,-1.7686828641645604,-1.1118675895265517
327.20000000000425,45.447379808135835,-1.7752893891281112,-1.138565746894531
328.3000000000043,45.554338683261435,-1.7812216951824713,-1.1702944766720091
329.4000000000043,45.66065720357954,-1.7874157728284377,-1.2022471943375685
330.5000000000043,45.76704481969222,-1.7967857843681632,-1.2336111314274412
331.60000000000434,45.873127318707425,-1.8045035778140752,-1.2658051100234187
332.7000000000043,45.978429444469164,-1.8113485786699735,-1.301767930719254
333.80000000000433,46.08662876327002,-1.8207502097304764,-1.3361060086429255
334.90000000000435,46.1938816645383,-1.8292063760419275,-1.3728376450120399
336.0000000000044,46.30174522331164,-1.8378555264625034,-1.4120063630304722
337.1000000000044,46.4067612805085,-1.8491569375770016,-1.4493878040838042
338.2000000000044,46.51277033121037,-1.859608630552126,-1.4882625281801238
339.30000000000445,46.62090838274681,-1.868183083431771,-1.528874312595946
340.4000000000044,46.72654032557667,-1.8774034710948275,-1.5699592538273515
341.50000000000443,46.834267118059934,-1.8891241278065847,-1.6107254498780619
342.60000000000446,46.94089304993151,-1.8992039862824304,-1.6536135463614867
343.7000000000045,47.04744350908702,-1.9096994399030893,-1.696903871287939
344.8000000000045,47.154331467181144,-1.9185190563838452,-1.741251449889584
345.9000000000045,47.26155249235851,-1.9274939238507622,-1.7881790211977995
347.00000000000455,47.36795407010429,-1.9350040405645452,-1.835057740090308
348.10000000000457,47.475099104938536,-1.941848786724038,-1.8829736036088094
349.2000000000046,47.58218583520499,-1.9468942978922172,-1.9309639971439525
350.30000000000456,47.68867294958727,-1.9497515694565086,-1.9802199301154109
351.4000000000046,47.795034500483105,-1.9519587366362052,-2.0311633236549906
352.5000000000046,47.90228200968138,-1.952535244181574,-2.079829863802844
353.6000000000046,48.00641392331606,-1.9488336333696572,-2.1284065730381307
354.70000000000465,48.11487079589608,-1.9416143043844203,-2.17742469905742
355.8000000000047,48.219597261046054,-1.9317164018936015,-2.2255656894443017
356.9000000000047,48.32609211036316,-1.919154640419506,-2.275247792016416
358.00000000000466,48.432530110247804,-1.904508082486256,-2.31995077199714
359.1000000000047,48.53901356286627,-1.8839514661461372,-2.367786727439741
360.2000000000047,48.64588988742398,-1.860321387617118,-2.409811219363505
361.30000000000473,48.74943434902193,-1.8325346950066033,-2.451145633759115
362.40000000000475,48.855645975166084,-1.8055293630152895,-2.4903327589704256
363.5000000000048,48.96103447301244,-1.7738446419808247,-2.527142221683853
364.6000000000048,49.06596390407566,-1.744592889316607,-2.5612642420112275
365.7000000000048,49.171342208416334,-1.7113380804242713,-2.591767160025884
366.80000000000484,49.27591633920194,-1.6820310349020517,-2.6186666128716074
367.9000000000048,49.38078478530788,-1.6511774122906193,-2.6466517959465974
369.00000000000483,49.48728984355368,-1.624007217450163,-2.6694480693849796
370.10000000000485,49.5924649189183,-1.594957722239104,-2.6902246093521525
371.2000000000049,49.6968244858244,-1.56884928958425,-2.707543045473084
372.3000000000049,49.80317752576553,-1.5457887356466904,-2.7231143643793008
373.4000000000049,49.909110462648236,-1.5242300110908484,-2.738788567652081
374.50000000000495,50.01510669712286,-1.5027903251658632,-2.7515322223115257
375.6000000000049,50.121797387707964,-1.4832455065506815,-2.7621975744048477
376.70000000000493,50.22705160993321,-1.4663873723814247,-2.7748407083568942
377.80000000000496,50.33367364824548,-1.4478209276295522,-2.7819085105267694
378.900000000005,50.44021727618731,-1.4325862153524755,-2.7895555292588186
380.000000000005,50.54543516185886,-1.41974134470972,-2.7965465620183085
381.100000000005,50.65281712309547,-1.4067226015492482,-2.8037997236363275
382.20000000000505,50.758715209510406,-1.395888160522476,-2.809182118197894
383.30000000000507,50.8658568046675,-1.3883438500380538,-2.8135288691476914
384.4000000000051,50.972692781769446,-1.3822630128829352,-2.819357541634922
385.50000000000506,51.080058601622994,-1.3778967999389353,-2.8222001295155463
386.6000000000051,51.18547044013299,-1.3744155907608584,-2.8251089289573956
387.7000000000051,51.29417659506777,-1.370990336976722,-2.8299591279211667
388.8000000000051,51.401799458295436,-1.368268138683846,-2.833368526201893
389.90000000000515,51.5074494304536,-1.3644870197254582,-2.8376779953329843
391.0000000000052,51.6148317842993,-1.3643297878449123,-2.8391192304686275
392.1000000000052,51.72312942291893,-1.3626855541645773,-2.843292604439267
393.20000000000516,51.829083684870895,-1.3613353506163388,-2.847178261963346
394.3000000000052,51.93427657912731,-1.3610320062131473,-2.8501466934146777
395.4000000000052,52.04321368508652,-1.3585866331569554,-2.8546269291302524
396.50000000000523,52.15096925953648,-1.3579272334530978,-2.8560098826247176
397.60000000000525,52.2591868126482,-1.3577650275591693,-2.858492788501324
398.7000000000053,52.365866216037446,-1.3559849143603149,-2.8637410916724892
399.8000000000053,52.47327685061109,-1.355545062018076,-2.86808999291162
400.9000000000053,52.580795889311034,-1.3546436564975763,-2.873750322864945
402.00000000000534,52.68747420217487,-1.3535126541396434,-2.876305103568955
403.1000000000053,52.79640795267584,-1.3529757562496483,-2.8776285267044948
404.20000000000533,52.90422468879119,-1.352850176478451,-2.8820290289770405
405.30000000000535,53.011604545225644,-1.352341539649232,-2.8848032142409203
406.4000000000054,53.11906950742728,-1.3511825585289787,-2.8872653667793866
407.5000000000054,53.22692324700824,-1.3499968227925203,-2.890820306207733
408.6000000000054,53.3352239059924,-1.3516732366563964,-2.8931689758335404
409.70000000000545,53.443045438769516,-1.3521211712993402,-2.895007333547593
410.8000000000054,53.55062100803209,-1.3510983258389373,-2.9005978786740716
411.90000000000543,53.658782755556885,-1.351161601037709,-2.903218369318435
413.00000000000546,53.76698727472243,-1.351467980792649,-2.905862281717967
414.1000000000055,53.873662762233565,-1.352592616733266,-2.908489256082767
415.2000000000055,53.98244131479622,-1.3543580684828633,-2.9113177995018846
416.3000000000055,54.0907416515651,-1.3566829568471892,-2.9156152190651636
417.40000000000555,54.19879815762324,-1.3567323532527191,-2.9194004150663684
418.50000000000557,54.30664857842962,-1.3581479216562387,-2.9216625030980206
419.6000000000056,54.414753689107364,-1.3594332508887497,-2.9229784051456797
420.70000000000556,54.52266730987573,-1.360639548830547,-2.927410062557322
421.8000000000056,54.62856484467836,-1.3614598402272988,-2.932978775907852
422.9000000000056,54.73852197094232,-1.3635827578521393,-2.9343011917321484
424.0000000000056,54.8467438581326,-1.3649024979211388,-2.9356371289120555
425.10000000000565,54.955418242187704,-1.36488025689715,-2.938046374909961
426.2000000000057,55.06277438160145,-1.3683553558693318,-2.941022656540054
427.3000000000057,55.16972854512428,-1.3704846762501581,-2.945494836279681
428.40000000000566,55.2790730473177,-1.3724109907709787,-2.946906819296155
429.5000000000057,55.38742240705652,-1.3759395815759374,-2.949659675884276
430.6000000000057,55.4942869399813,-1.3775531047664882,-2.951553035836513
431.70000000000573,55.60346474361531,-1.3810604706042269,-2.954725618710278
432.80000000000575,55.71206024548118,-1.38258106632118,-2.9575665107496745
433.9000000000058,55.82117041658922,-1.3859039483280104,-2.961344738076894
435.0000000000058,55.92822915713677,-1.3872955268567435,-2.9616724123863234
436.1000000000058,56.03519857272832,-1.39016205813972,-2.9632103994009125
437.20000000000584,56.144184575919276,-1.3921847557338158,-2.9672088520323463
438.3000000000058,56.253311377303994,-1.395276404520566,-2.9732900652427805
439.40000000000583,56.36086172597339,-1.399017085028887,-2.974848867924749
440.50000000000585,56.469413009947154,-1.4010845629898625,-2.977551541952345
441.6000000000059,56.57860009241324,-1.4052708881038032,-2.9788698816287096
442.7000000000059,56.68587658525747,-1.4079855427599226,-2.9801749499242316
443.8000000000059,56.794939667772326,-1.4119669151090202,-2.982540133961197
444.90000000000595,56.90409328619938,-1.4143498481293588,-2.9841476025226727
446.0000000000059,57.01281556390406,-1.4161005008692578,-2.9854499735229107
447.10000000000593,57.12178130843422,-1.4210061643082932,-2.986701003074244
448.20000000000596,57.229035342159946,-1.4239238508954923,-2.9908886508755543
449.300000000006,57.33898694846448,-1.426260394383587,-2.992522210316248
450.400000000006,57.44793365945259,-1.4285245845355827,-2.9936836261358213
451.500000000006,57.55613158248431,-1.4312569736054697,-2.9978368407843283
452.60000000000605,57.66568433676912,-1.434717383769586,-3.000491644967596
453.70000000000607,57.773975762277395,-1.4371875403094654,-3.002467842488531
454.8000000000061,57.882708203772495,-1.4397806648711406,-3.003113257196102
455.90000000000606,57.99217003652298,-1.4425313524490504,-3.0074369677341295
457.0000000000061,58.1015052698612,-1.4459538779793406,-3.007405616635667
458.1000000000061,58.20993702417465,-1.4460498038453096,-3.0092125050376852
459.2000000000061,58.319184695704145,-1.4492452782529432,-3.011359836132423
460.30000000000615,58.42721672760009,-1.4505989546670457,-3.013571989096725
461.4000000000062,58.5358535310454,-1.45567258242334,-3.0139564012579565
462.5000000000062,58.64508159013251,-1.4578459754218027,-3.0159453463552097
463.60000000000616,58.751803961529006,-1.4595517535432578,-3.0173172596103983
464.7000000000062,58.86214629977893,-1.462862352430918,-3.021992529808143
465.8000000000062,58.971073079355776,-1.4649987043707433,-3.0239802900856017
466.90000000000623,59.08008941019899,-1.4702159421530174,-3.0239904182397215
468.00000000000625,59.18616547439797,-1.472564228812353,-3.0239142312567298
469.1000000000063,59.297185631616784,-1.4770963041295577,-3.02761233145146
470.2000000000063,59.40646095857979,-1.4803964716249616,-3.030201184545559
471.3000000000063,59.515313675443686,-1.4836521979037718,-3.0302845871170883
472.40000000000634,59.6240836010089,-1.4872797151284496,-3.032882344038276
473.5000000000063,59.73287665973502,-1.4926229832041178,-3.032978171269745
474.60000000000633,59.84072935280579,-1.4996401612856867,-3.0363976332596314
475.70000000000636,59.95055669972197,-1.507497336308983,-3.0396465545643725
476.8000000000064,60.05954422885161,-1.5144834679783805,-3.0402384003643808
477.9000000000064,60.167369461387096,-1.5210063397832903,-3.0420238566166313
479.0000000000064,60.27691684653088,-1.52658271114273,-3.0424325681966637
480.10000000000645,60.38643771419033,-1.5301285323085048,-3.0437533835299475
481.2000000000064,60.49527749159941,-1.5358633010205598,-3.04506874409245
482.30000000000643,60.60444507592388,-1.5400991433521862,-3.0477567276993422
483.40000000000646,60.712748267676325,-1.5426778142414765,-3.0490138020597457
484.5000000000065,60.822622502872875,-1.5476429417736801,-3.049350121935913
485.6000000000065,60.931551787043155,-1.5509558666715968,-3.049011698936944
486.7000000000065,61.03936239578684,-1.5543544519492047,-3.0516627541917156
487.80000000000655,61.14979764488059,-1.5561748618727909,-3.055628068581339
488.90000000000657,61.258427087921156,-1.560089357046346,-3.055600493215183
490.0000000000066,61.36767843754568,-1.5653658035842164,-3.0556963658339185
491.10000000000656,61.47777768750158,-1.5679357360365402,-3.0571964366511257
492.2000000000066,61.58355304667519,-1.5737631423761476,-3.0574362265408697
493.3000000000066,61.696350906002905,-1.5775494443209466,-3.0611654764065706
494.4000000000066,61.80481826041766,-1.5816920768507208,-3.0613071797470726
495.50000000000665,61.91529887084143,-1.583791494281126,-3.0626833329767025
496.6000000000067,62.0245490460128,-1.5875176718667265,-3.065385007490224
497.7000000000067,62.133263352242835,-1.5915637370465796,-3.065369152056859
498.80000000000666,62.24326486004558,-1.5943883664109324,-3.0666897885735693
499.9000000000067,62.351732492848676,-1.5975475747378654,-3.066695943856682
501.0000000000067,62.46231861776751,-1.6011258564744817,-3.0693801385502164
502.10000000000673,62.570717930920644,-1.604098285999371,-3.070718716311159
503.20000000000675,62.6808472400686,-1.6064319874362718,-3.070495925411977
504.3000000000068,62.79031935588475,-1.6079514998235263,-3.072491132615519
505.4000000000068,62.89982352378223,-1.609327612619331,-3.0758338742286253
506.5000000000068,63.0093057182858,-1.6133930072415583,-3.074255269157795
507.60000000000684,63.11877246205021,-1.6153171050098567,-3.0760118946563093
508.7000000000068,63.22862258087713,-1.6172542303092692,-3.0773399240487946
509.80000000000683,63.33863611550079,-1.6182563155201923,-3.077677084367393
510.90000000000686,63.44713286356391,-1.6173494232854644,-3.081193256779573
512.0000000000068,63.55658824504247,-1.6184829899814266,-3.080968608122777
513.100000000007,63.6660231431132,-1.6195340829639684,-3.0836217846419935
514.2000000000069,63.77553836347896,-1.6191214177856774,-3.087144029689857
515.300000000007,63.88403313655697,-1.6191084065450436,-3.0863832062612784
516.4000000000069,63.994239865295924,-1.6222175770607954,-3.0864598075103915
517.5000000000069,64.10348556433357,-1.6215975555707667,-3.088075284445032
518.600000000007,64.21146660792868,-1.6226403869814148,-3.089301975948258
519.700000000007,64.32285177492308,-1.6172442911674554,-3.0894200640054104
520.800000000007,64.43162138224201,-1.6119947697963795,-3.0894206344124293
521.900000000007,64.54066737732572,-1.6061103043706357,-3.0920698539256337
523.000000000007,64.65025748854575,-1.604808842788177,-3.0933738386685063
524.1000000000071,64.76057405211701,-1.5993278147891417,-3.0933704285891803
525.2000000000071,64.86892265332442,-1.5936153754635756,-3.0946765987105684
526.300000000007,64.9787862469951,-1.5917025024075406,-3.096011570614635
527.4000000000071,65.0887567977979,-1.5881024360482248,-3.0960124668685207
528.500000000007,65.19701628764916,-1.5839795783250827,-3.0986398714578605
529.6000000000072,65.30814134104095,-1.5796023783106097,-3.099299463723418
530.7000000000071,65.41843683777857,-1.574928589912001,-3.099300077585049
531.8000000000072,65.52793189603594,-1.5741969053685338,-3.0986022188208486
532.9000000000071,65.63760568478507,-1.573693158911626,-3.098640539691052
534.0000000000072,65.74742872198337,-1.5738961973526995,-3.09994991492279
535.1000000000072,65.85510534388459,-1.5727633072991654,-3.101269432476841
536.2000000000072,65.96724198545849,-1.571874933597988,-3.10417041507998
537.3000000000072,66.07671415283974,-1.5689976560789907,-3.1052315842249563
538.4000000000073,66.18670443777884,-1.5668733094965066,-3.105231094444485
539.5000000000073,66.29685963225748,-1.564715332684127,-3.1065401034860476
540.6000000000073,66.40660759824911,-1.56291280030128,-3.106541084299629
541.7000000000073,66.51665525543424,-1.563732065363296,-3.1078565760034724
542.8000000000073,66.6259989926928,-1.5627986630067496,-3.1091675618278583
543.9000000000074,66.73566651261869,-1.562922537522038,-3.1104900705134586
545.0000000000074,66.84631319075945,-1.5621604035289118,-3.1131341231580256
546.1000000000074,66.95664463072772,-1.5619874055878642,-3.1131300597099476
547.2000000000073,67.0667493365332,-1.5635584410153127,-3.1144513643417295
548.3000000000073,67.17676594104489,-1.5622512161717297,-3.115046522505601
549.4000000000074,67.28484292554405,-1.5611922367195996,-3.1158718849925533
550.5000000000074,67.39727246868942,-1.5603359687252036,-3.115879498121652
551.6000000000074,67.50656118484733,-1.5616643589977246,-3.117191426387265
552.7000000000074,67.6176399217326,-1.5619820158631201,-3.115879881860085
553.8000000000075,67.72763194897061,-1.5622026583010102,-3.1165381138009467
554.9000000000075,67.83771029150425,-1.5630700702673908,-3.117868254657661
556.0000000000075,67.94616336214284,-1.564757357914468,-3.1178467784097625
557.1000000000075,68.05864250426393,-1.564671317435709,-3.1191708164736673
558.2000000000075,68.16980034416906,-1.5654913992504853,-3.12180894220975
559.3000000000076,68.27928949694102,-1.565212724580883,-3.120424636529739
560.4000000000076,68.39054657148839,-1.5677485547013499,-3.119178086486535
561.5000000000076,68.50089987835733,-1.5686429651641098,-3.1218064333596347
562.6000000000076,68.61123991990861,-1.5674115269711282,-3.123486361160685
563.7000000000077,68.72249161447732,-1.5699311497891908,-3.1271985087715244
564.8000000000077,68.83168146880016,-1.570361597452187,-3.126953456094781
565.9000000000076,68.94371798546547,-1.5730962227384777,-3.125545687463228
567.0000000000076,69.0544731895324,-1.5729239471639602,-3.125542033675734
568.1000000000076,69.16463892708279,-1.5728282523218122,-3.125538367114891
569.2000000000077,69.27538944338163,-1.574260041707777,-3.126860687101186
570.3000000000077,69.38600777515111,-1.5770162381871746,-3.12918419465277
571.4000000000077,69.49729888107161,-1.5768575207961864,-3.1307228999582595
572.5000000000077,69.60814150631124,-1.5788252096942983,-3.1291228097000157
573.6000000000078,69.71884770814333,-1.581510132623578,-3.129130348172694
574.7000000000078,69.8297572918379,-1.5822688224435588,-3.1316904964810925
575.8000000000078,69.94153288064095,-1.5840404261833336,-3.132598972564061
576.9000000000078,70.0517438183741,-1.5885529950136825,-3.1343263815620848
578.0000000000078,70.16250133752061,-1.5902259776794476,-3.1343435754508264
579.1000000000079,70.2733011010062,-1.5912043784528425,-3.1338597306963303
580.2000000000079,70.384051489181,-1.5920304729228396,-3.135127002399342
581.3000000000079,70.49474938485558,-1.594411092887152,-3.1382707903998432
582.4000000000078,70.60680927047228,-1.5970133084902824,-3.138492640338046
583.5000000000078,70.71793520443144,-1.599157029366172,-3.138929829178058
584.6000000000079,70.82741231964762,-1.603244126220024,-3.1382297945101594
585.7000000000079,70.93920131516494,-1.6070994449364793,-3.1389191245436763
586.8000000000079,71.04977365344264,-1.6045747452702819,-3.1386477764984457
587.9000000000079,71.16111099810813,-1.6011836809360205,-3.138270547913821
589.000000000008,71.27075120141613,-1.5913182938136994,-3.1401208837686134
590.100000000008,71.3821496625592,-1.5767742869122316,-3.14085765343533
591.200000000008,71.49253979859456,-1.5694975451184492,-3.1390913571556855
592.300000000008,71.60232241861746,-1.5713138975332488,-3.1415678250663412
593.400000000008,71.71294100800188,-1.5743902087820685,-3.1435501973436106
594.5000000000081,71.82335086397106,-1.579564401228673,-3.142490822132548
595.6000000000081,71.93457533577535,-1.5842640243911212,-3.142323899803374
596.7000000000081,72.04426278769688,-1.590526367627082,-3.144856306943482
597.8000000000081,72.15574671706196,-1.5959335584771417,-3.1458244545477507
598.9000000000082,72.2668302934675,-1.6012998405910186,-3.147241826169231
600.0000000000082,72.37723095675183,-1.6072849681884809,-3.148498473771998
601.1000000000081,72.48863418048605,-1.615619861332387,-3.1461719537055615
602.2000000000081,72.59948563510875,-1.620087863659687,-3.1475353501719168
603.3000000000081,72.70951653596356,-1.626306229163732,-3.1481806111631916
604.4000000000082,72.82125171895453,-1.632932780943484,-3.1474993454464197
605.5000000000082,72.93280880818477,-1.639809095327543,-3.1487946479152074
606.6000000000082,73.04450292265307,-1.6483949223730718,-3.148764567514261
607.7000000000082,73.155931422293,-1.657382099644826,-3.151462565928434
608.8000000000083,73.26738049356244,-1.6638443092417865,-3.154074820354015
609.9000000000083,73.37852763064927,-1.6707266460617758,-3.15507018160147
611.0000000000083,73.48968753570833,-1.679545352387404,-3.1554000470591785
612.1000000000083,73.60145869795723,-1.6908196402426687,-3.1540132205268234
613.2000000000083,73.7118906674486,-1.6944125851426548,-3.1535173588192036
614.3000000000084,73.82298752789816,-1.7034660424229178,-3.1521463058972725
615.4000000000084,73.93480509840617,-1.7111578099345603,-3.151317657676219
616.5000000000084,74.04614883922127,-1.7189672944323706,-3.1567437579442936
617.6000000000083,74.15641909781951,-1.7279145419433413,-3.1580398901890536
618.7000000000083,74.26811103921483,-1.7360645329462758,-3.156853784241911
619.8000000000084,74.37930551676853,-1.747681092219135,-3.1581074839156336
620.9000000000084,74.4907919336801,-1.753931499552927,-3.1603157150553214
622.0000000000084,74.60194291541775,-1.7611828977661563,-3.161647409270736
623.1000000000084,74.71436765285014,-1.771121349568319,-3.1629465294313235
624.2000000000085,74.82512183806057,-1.7788722439117108,-3.1619150183527083
625.3000000000085,74.93436572090926,-1.7886887323809562,-3.16329580132136
626.4000000000085,75.04823723285129,-1.7960453593758903,-3.160450056535037
627.5000000000085,75.15881347506892,-1.8044601844766321,-3.163810472303852
628.6000000000085,75.27063690364336,-1.810454747109119,-3.165584795128704
629.7000000000086,75.3816635921777,-1.8148009470347295,-3.1634530101679545
630.8000000000086,75.4940669901693,-1.8215654219397048,-3.165500913040556
631.9000000000086,75.60488233976692,-1.8249804871639483,-3.169673843174937
633.0000000000086,75.71632094648562,-1.8278023105395058,-3.1709886348504224
634.1000000000087,75.82723690606743,-1.8334383491259894,-3.171622849884227
635.2000000000087,75.93812072595821,-1.8376518011508398,-3.1709898400510306
636.3000000000086,76.05030301929587,-1.840203958460465,-3.173145021299045
637.4000000000086,76.16053469500503,-1.8431514597547134,-3.17329012571216
638.5000000000086,76.27216500014954,-1.8467041182679755,-3.1732900679982956
639.6000000000087,76.38158089828815,-1.8498614188221931,-3.1732935680741337
640.7000000000087,76.49544481703127,-1.853862035649116,-3.1736314441553963
641.8000000000087,76.60651680363803,-1.8571089735272461,-3.1749332065369726
642.9000000000087,76.71861247410553,-1.8580189201941915,-3.175601323583804
644.0000000000088,76.83029994060396,-1.8618899223271341,-3.179552289768215
645.1000000000088,76.94104788780072,-1.8637594461252027,-3.1814802160005335
646.2000000000088,77.05226693651876,-1.8663020743080032,-3.1821799515951863
647.3000000000088,77.16410326929905,-1.87056476779133,-3.1816184298786094
648.4000000000088,77.27557422916163,-1.8722218095969252,-3.1780053718296277
649.5000000000089,77.38665005544398,-1.8729588746298238,-3.178040919855391
650.6000000000089,77.4991270446833,-1.873534979365754,-3.1829691062291285
651.7000000000089,77.60918943577535,-1.8724331941431875,-3.1821595150775703
652.8000000000088,77.7237753697134,-1.8757498395200614,-3.1861940677412477
653.9000000000088,77.83539673214202,-1.8743621218963333,-3.1874626900555976
655.0000000000089,77.94744022769802,-1.8754872595842074,-3.1868916897670756
656.1000000000089,78.05854592687953,-1.8756347045793005,-3.1861577517035964
657.2000000000089,78.17035385044645,-1.876035865305241,-3.1854770018359546
658.3000000000089,78.28177388070468,-1.8777627923979343,-3.185584522539078
659.400000000009,78.39335004038934,-1.8750660555505336,-3.185408030789108
660.500000000009,78.50585821915578,-1.8739490745738379,-3.1898652643683496
661.600000000009,78.61744113577026,-1.870945825445668,-3.1902238635840594
662.700000000009,78.72906357663466,-1.868466892280505,-3.1901995817640403
663.800000000009,78.84156874072131,-1.8661250920320935,-3.1901884196679657
664.9000000000091,78.95280052318404,-1.8657835040821107,-3.1905357850634273
666.0000000000091,79.06553188790805,-1.8664626318851751,-3.1918499039376336
667.1000000000091,79.17740624099216,-1.8651464680357583,-3.191849888025126
668.2000000000091,79.28746381328759,-1.8697040335038353,-3.1918046137489737
669.3000000000092,79.40091099859958,-1.8695566094383484,-3.1941501037497377
670.4000000000092,79.5122992066473,-1.8721896973913643,-3.1928405175487815
671.5000000000091,79.6241922599713,-1.8758325866813828,-3.1930223054190146
672.6000000000091,79.73610340915302,-1.8787153940582917,-3.1918638906177015
673.7000000000091,79.84720282960616,-1.8803294057687232,-3.1945138160239415
674.8000000000092,79.95949382150295,-1.8829296143156906,-3.1957910641141347
675.9000000000092,80.07181093740444,-1.8863523925382975,-3.196121942069116
677.0000000000092,80.18391782552567,-1.892046512940827,-3.194506397729943
678.1000000000092,80.29535959104479,-1.8938564493300662,-3.1944761742951044
679.2000000000093,80.40728089100318,-1.8987946436634344,-3.1961298698235905
680.3000000000093,80.51977147393599,-1.9011096728121002,-3.1948143640985447
681.4000000000093,80.632065303093,-1.9045100820057048,-3.1977773876291105
682.5000000000093,80.74333069796636,-1.9083520974770687,-3.1996840740530783
683.6000000000093,80.85643088913211,-1.9113798537573226,-3.1974868954265063
684.7000000000094,80.9680277870287,-1.9135929156878635,-3.1980018605828766
685.8000000000094,81.07955204429177,-1.9173147135884618,-3.196306594374299
686.9000000000094,81.1926991462602,-1.919498700869521,-3.1980790966045465
688.0000000000093,81.30460834707766,-1.9235967664069755,-3.199271089200174
689.1000000000093,81.41790080969675,-1.929018143762249,-3.2026396276133853
690.2000000000094,81.52778056730544,-1.932279886137949,-3.2053262092077084
691.3000000000094,81.64052546021657,-1.9359183589026796,-3.2013939573188375
692.4000000000094,81.75190642849437,-1.9404571335645164,-3.20133998079062
693.5000000000094,81.86388468953042,-1.9440663807162504,-3.2020627073096
694.6000000000095,81.97697759930844,-1.9482861563248042,-3.200516995097292
695.7000000000095,82.089177402728,-1.9509660228381338,-3.2005200311865614
696.8000000000095,82.20165446133245,-1.9554256795476663,-3.203253861425184
697.9000000000095,82.31421904287926,-1.9617026474627488,-3.204470043525819
699.0000000000095,82.42371181726955,-1.9635190985685873,-3.2035394014681646
700.1000000000096,82.5386390046183,-1.966673276916624,-3.204478485935006
701.2000000000096,82.65137012647826,-1.974791678392034,-3.2031598737365066
702.3000000000096,82.76324347769443,-1.9774143052773703,-3.2018373426311695
703.4000000000096,82.8745201668053,-1.9808085526119303,-3.203341052626696
704.5000000000097,82.98701364631175,-1.9859300286380073,-3.2077753967748883
705.6000000000097,83.09960583719905,-1.9917226539250183,-3.2067498213397108
706.7000000000096,83.21168074539783,-1.9985923780628192,-3.2035894305934662
707.8000000000096,83.32340990270251,-2.002512125060917,-3.204227251032863
708.9000000000096,83.43631253802609,-2.00920594079712,-3.2019501477922505
710.0000000000097,83.54746874807716,-2.012794492621266,-3.205887990161044
711.1000000000097,83.66139579930524,-2.015381358666715,-3.210028338512224
712.2000000000097,83.7734510402441,-2.0211916266805123,-3.2130146239014272
713.3000000000097,83.88592867693598,-2.027562516144347,-3.2117589218356093
714.4000000000098,83.99822409833811,-2.0317618569622073,-3.207534310663715
715.5000000000098,84.1095736332312,-2.0386816204193225,-3.2074262682179095
716.6000000000098,84.22245923836893,-2.0440714870869376,-3.2084547267486947
717.7000000000098,84.33467114417093,-2.0508406288864185,-3.20864855018371
718.8000000000098,84.44833101240972,-2.0550299517607797,-3.209030116565254
719.9000000000099,84.56071278608755,-2.060997606440024,-3.2114321831095376
721.0000000000099,84.67303140197524,-2.069621388886127,-3.2109765085298365
722.1000000000099,84.78616483875084,-2.0720981428603924,-3.2122657475856826
723.2000000000098,84.89865776517739,-2.078820313071264,-3.2140237831492993
724.3000000000098,85.01078269134192,-2.0851997023521536,-3.212761979287694
725.4000000000099,85.12376565830695,-2.0919969252800374,-3.211594258609887
726.5000000000099,85.2357107145021,-2.098896919018472,-3.2142390334143762
727.6000000000099,85.34874205375357,-2.102631703880204,-3.214062346379108
728.7000000000099,85.46217723783086,-2.108405220307876,-3.2142421037619235
729.80000000001,85.57384263155345,-2.114932827137322,-3.214129611993961
730.90000000001,85.68645572832786,-2.1221838371034596,-3.2154498183669427
732.00000000001,85.79962815548375,-2.1273225904057793,-3.2147818588913317
733.10000000001,85.91153057776987,-2.1315393374615677,-3.2141401620083276
734.20000000001,86.02468158325127,-2.1391021549762965,-3.214084962045053
735.3000000000101,86.13722602440727,-2.143949715386074,-3.2157799410391164
736.4000000000101,86.24944159114365,-2.148410295786602,-3.2144600281311906
737.5000000000101,86.36097885585585,-2.1543362522496667,-3.2157798110201656
738.6000000000101,86.47363623831234,-2.160053093272012,-3.2167776466724423
739.7000000000102,86.58733732237096,-2.1670995247298936,-3.2193999972870926
740.8000000000102,86.69924653361436,-2.1742597178082996,-3.2187400505063355
741.9000000000101,86.81127697476559,-2.1807045344237896,-3.217372557951985
743.0000000000101,86.92366328170047,-2.187852651464745,-3.216828454206068
744.1000000000101,87.03665898018178,-2.190290326502324,-3.218576048093155
745.2000000000102,87.14823247576436,-2.194162432343754,-3.2181998237718914
746.0000000000102,87.23132528988462,-2.199522888229681,-3.218427784536575