File: 01_Data/Cardboard/STA/N2/10K_min/Cardboard_STA_N2_10KData_230818_R5.csv
##Temp./Â°C,Time/min,DSC/(mW/mg),Mass loss/mg
28.0,15.61017126031175,-2.3518869731754304,-0.08429454888180521
29.100000000000016,16.021329737843274,-2.3093065106439186,-0.08611138489142123
30.20000000000003,16.257816403331805,-2.2865321629487263,-0.08758944184515816
31.300000000000047,16.450195020274442,-2.272937223710431,-0.0889715665579689
32.40000000000006,16.61578790957695,-2.262208983867413,-0.0900907348908353
33.50000000000008,16.76798461573695,-2.253945438274735,-0.08932320680494854
34.600000000000094,16.913577670351742,-2.245811956198599,-0.09154426739250443
35.70000000000011,17.053982701125886,-2.2416309559426497,-0.09215224088386131
36.800000000000125,17.188427516838825,-2.239803554734076,-0.09164041799187883
37.90000000000014,17.319692870499008,-2.237225016807331,-0.09262390051731595
39.000000000000156,17.450243550383636,-2.2377015758362875,-0.09523899649790568
40.10000000000017,17.57587861995468,-2.2386151762240045,-0.09562933376113136
41.20000000000019,17.70473959595659,-2.237939755968041,-0.09643390169301025
42.3000000000002,17.828804954407047,-2.241273033139586,-0.09857600891743123
43.40000000000022,17.95269988000519,-2.2429604146371873,-0.10114455943869638
44.500000000000234,18.077293979569173,-2.2445948862645753,-0.10001536609894801
45.60000000000025,18.19862825219638,-2.2465949102466345,-0.10221255443775723
46.700000000000266,18.31804038462943,-2.2502252703916175,-0.1029747982500604
47.80000000000028,18.439286726715057,-2.2547802002235415,-0.10495144201565587
48.9000000000003,18.559833196458186,-2.25734488521332,-0.10529082839431725
50.00000000000031,18.67767638709546,-2.2617190539718255,-0.10666144963357427
51.10000000000033,18.795559436745837,-2.264457708246451,-0.10923952464622433
52.200000000000344,18.911782781195225,-2.26840563252612,-0.11055981522897351
53.30000000000036,19.03069491306149,-2.2732268299036646,-0.11198568461220981
54.400000000000375,19.147789465013975,-2.2764861076728096,-0.11443852475987581
55.50000000000039,19.26352847608584,-2.2798028558856,-0.11576813401748831
56.600000000000406,19.38023826610893,-2.282507808495219,-0.1184638026257967
57.70000000000042,19.493856225817606,-2.284523216392195,-0.12110707000190413
58.80000000000044,19.60983649981701,-2.287619055278588,-0.12241026720233972
59.90000000000045,19.72215890420883,-2.2900755495174403,-0.12504996467480423
61.00000000000047,19.837273414653676,-2.290801010985974,-0.1275267114163099
62.100000000000485,19.95122908938082,-2.292076263353032,-0.12904297465534453
63.2000000000005,20.06327155327074,-2.2925779388414647,-0.1303472436737656
64.30000000000052,20.17378282307419,-2.2932875587884696,-0.1329501279543197
65.40000000000053,20.285318758019937,-2.292077411356579,-0.13426217913238014
66.50000000000054,20.393576637141617,-2.2900119543143407,-0.13689635795878496
67.60000000000056,20.50724284926337,-2.288840025266658,-0.13953223248238356
68.70000000000059,20.619802445458056,-2.286627624370582,-0.1421719239265311
69.8000000000006,20.730527958904933,-2.2827848559650845,-0.14480630253496463
70.9000000000006,20.841108207777193,-2.2772328946989258,-0.14743366682403902
72.00000000000063,20.951749725710187,-2.274362863780851,-0.15006474568077977
73.10000000000065,21.061815804109486,-2.269191971442434,-0.15268990609384048
74.20000000000066,21.171252989375677,-2.2624158149654954,-0.15531139142566275
75.30000000000067,21.28191562435863,-2.256680021540405,-0.1566838055970523
76.40000000000069,21.390673555040028,-2.250532343382342,-0.15929372310527645
77.50000000000071,21.500058578861942,-2.2401822098051114,-0.16194917406435616
78.60000000000072,21.607655898141513,-2.23285967112246,-0.16456162551074938
79.70000000000073,21.71802820282243,-2.2242258184383146,-0.16588027296572116
80.80000000000075,21.82732660959872,-2.2132421180224195,-0.1685256627957692
81.90000000000077,21.937362912098777,-2.2034255876766533,-0.16983812520236974
83.00000000000078,22.04495148240678,-2.1950609766174876,-0.17116008822556017
84.10000000000079,22.153695664122843,-2.183886681577446,-0.1737810635916417
85.20000000000081,22.25886737922266,-2.173131893451565,-0.1764201623666013
86.30000000000084,22.369484194035515,-2.162459930736765,-0.1790502212816305
87.40000000000084,22.477348166192265,-2.1515794245399853,-0.17908152179748082
88.50000000000085,22.58287323212497,-2.140383429787723,-0.18039034353386052
89.60000000000088,22.69248366265371,-2.1282559227720297,-0.18301586790389113
90.7000000000009,22.800352894482813,-2.11762653030741,-0.18431993657379353
91.8000000000009,22.906688550544352,-2.104615263029212,-0.18563925458752806
92.90000000000092,23.014772622768668,-2.0937228963614856,-0.18827986183600887
94.00000000000094,23.122352113345137,-2.0820626686110364,-0.1882749449103125
95.10000000000096,23.227142853877233,-2.070928994385232,-0.19091988980553465
96.20000000000097,23.334440688448687,-2.0580485786770204,-0.19083558541544487
97.30000000000098,23.442003986324472,-2.0464635769546975,-0.19223911944754724
98.400000000001,23.54749377646107,-2.0357224062771877,-0.19354952338689557
99.50000000000102,23.652745680260658,-2.0251261656254465,-0.1926004472368521
100.60000000000103,23.76048322605792,-2.01423017937997,-0.19388014269514287
101.70000000000104,23.866546739586802,-2.0030080622023756,-0.19651827208711659
102.80000000000106,23.972510429937536,-1.9927444128824539,-0.1975035484139438
103.90000000000109,24.077763569060465,-1.9850637215789486,-0.19782997628596988
105.0000000000011,24.184217316379847,-1.9730660271567453,-0.19783015660963255
106.1000000000011,24.290840444198214,-1.9642088886433096,-0.19915010884448447
107.20000000000113,24.39521744918038,-1.953901025166954,-0.1978404815916086
108.30000000000115,24.502182145429344,-1.9462811964842754,-0.19928634718353688
109.40000000000116,24.60898883104231,-1.9371771916286973,-0.1998088015849886
110.50000000000117,24.71463771738667,-1.9293416854125194,-0.20012691905611524
111.60000000000119,24.821843596754405,-1.9200975562207983,-0.2012230713336547
112.70000000000121,24.927946426408177,-1.9128191170837894,-0.20276992310994446
113.80000000000122,25.033142203209252,-1.905312277235174,-0.20277549889970237
114.90000000000123,25.139389001316285,-1.8988657025040065,-0.20275154628627368
116.00000000000125,25.24475903968769,-1.8919518129376751,-0.2027698504721469
117.10000000000127,25.351388389764,-1.8847133520580563,-0.2041038624525271
118.20000000000128,25.457978378188006,-1.8784486261762885,-0.20310000923921923
119.30000000000129,25.562708971015844,-1.8720342990833878,-0.20310008877045105
120.40000000000131,25.66997176027464,-1.8673617084410568,-0.2044198250387428
121.50000000000134,25.77438530133714,-1.861707582653574,-0.20445458487978208
122.60000000000134,25.879079388463108,-1.8581447724018265,-0.20441727795124276
123.70000000000135,25.985722149653352,-1.852121435301274,-0.20540680170443393
124.80000000000138,26.093146167154945,-1.8473721009122768,-0.2054000560069209
125.9000000000014,26.197379727684748,-1.8428523358794489,-0.20541372266298152
127.0000000000014,26.304275993046396,-1.8392514273142164,-0.20540017376942954
128.10000000000142,26.40907519588576,-1.835251578746047,-0.2058038100420223
129.20000000000144,26.515720060398017,-1.8318998723648305,-0.20672017563397604
130.30000000000146,26.616660803518855,-1.8275535420315445,-0.20668984946624036
131.40000000000146,26.725244514094495,-1.8248849361091102,-0.20541008895592272
132.50000000000148,26.832365436730484,-1.8225041215857734,-0.20541008800648086
133.6000000000015,26.9378927914169,-1.8185203224319744,-0.20541438147459523
134.70000000000152,27.043389249437517,-1.8172804526199107,-0.20540971804949582
135.80000000000155,27.14965191695854,-1.8147391527014254,-0.2054097995660813
136.90000000000154,27.254552954866185,-1.810152871270307,-0.20681466693263628
138.00000000000156,27.358534664479873,-1.8085578403989475,-0.20671977887284987
139.1000000000016,27.466072758637523,-1.8058859556667148,-0.20671887984690684
140.20000000000158,27.57070012377144,-1.804120790075505,-0.2067199200001717
141.3000000000016,27.676221412605955,-1.8032444974520452,-0.2067203254040444
142.40000000000163,27.78125675255229,-1.8001459187808866,-0.20540010513978935
143.50000000000165,27.886752869336725,-1.7982470975607714,-0.20672047943599559
144.60000000000167,27.992984760732718,-1.7956957091228272,-0.20672073938343338
145.70000000000167,28.096958598877745,-1.793022405358756,-0.20705009003331387
146.8000000000017,28.202374852750953,-1.7918155327930285,-0.2070472391950804
147.9000000000017,28.308821324633875,-1.7892109055589764,-0.2070601175260749
149.0000000000017,28.414389460750858,-1.786751887275026,-0.20836907386641412
150.10000000000173,28.51840852796522,-1.7854735165136257,-0.2083700240022126
151.20000000000175,28.624544109740118,-1.7833538087935297,-0.20835797130344202
152.30000000000177,28.728623964600253,-1.7814219734735839,-0.20704405610754595
153.4000000000018,28.832629681258204,-1.7809142956345105,-0.2083701437490415
154.5000000000018,28.94023465644846,-1.777848313406326,-0.20762075260150548
155.6000000000018,29.044843675049272,-1.7767458824478832,-0.20704985633525208
156.70000000000184,29.1492593474715,-1.7746931698583726,-0.2073425571107692
157.80000000000183,29.25473214226698,-1.7728893530473357,-0.2083698552814961
158.90000000000185,29.35881301479825,-1.77072840975699,-0.20837134547562375
160.00000000000188,29.46458097402741,-1.7693695174221056,-0.20830102115738924
161.1000000000019,29.569613670006664,-1.767868730930361,-0.20836997786016287
162.20000000000192,29.67459065252347,-1.7656957265110693,-0.20967824849934447
163.30000000000192,29.779170000000192,-1.7654700000000045,-0.20967997600078858
164.40000000000194,29.885124845524714,-1.7634451529497606,-0.20999592166457637
165.50000000000196,29.98985796825737,-1.7614794966982348,-0.21163337614377076
166.60000000000196,30.09368549839498,-1.7596020723815542,-0.21098367565138876
167.70000000000198,30.1991700000002,-1.7579499999999881,-0.20968988797310795
168.800000000002,30.30408487038312,-1.7561064401129358,-0.2095871576641466
169.90000000000202,30.40945162121598,-1.7565136583407923,-0.21100988907171692
171.00000000000205,30.514736761558236,-1.7549697113948837,-0.2096909761332557
172.10000000000204,30.618142710813707,-1.7534624179670797,-0.20969105925487463
173.20000000000206,30.724353122487614,-1.7525271668730071,-0.20969000800851845
174.3000000000021,30.82961739600319,-1.7507879765907643,-0.20969006244880628
175.40000000000208,30.934354601626595,-1.7498003643913558,-0.2110088074202192
176.5000000000021,31.038758472055704,-1.7498074795763046,-0.21167014923545624
177.60000000000213,31.144828490638865,-1.7476085028182313,-0.2107506647073154
178.70000000000215,31.24966393827317,-1.7462987825356762,-0.21162097214253173
179.80000000000217,31.354723398111517,-1.7449634017957927,-0.21162781892274074
180.90000000000217,31.459613175014212,-1.7437430877160305,-0.21066972782318372
182.0000000000022,31.564412437947333,-1.743461861395703,-0.21329432138188276
183.1000000000022,31.669553854272735,-1.741768056891347,-0.21232108989329923
184.2000000000022,31.77457811513589,-1.7423992273549804,-0.2124929708526504
185.30000000000223,31.87836472741712,-1.7405426411914733,-0.2136409134816346
186.40000000000225,31.98449059232222,-1.7399776385181212,-0.2133098665406683
187.50000000000227,32.088383017326265,-1.7388791044197018,-0.21330986400000196
188.6000000000023,32.19395126698574,-1.7383541144074142,-0.2133098646825502
189.7000000000023,32.29838535628291,-1.7370608838850805,-0.21463825555073734
190.8000000000023,32.40357978524427,-1.7362393068195603,-0.2146302631385515
191.90000000000234,32.508867634635344,-1.7357605450421059,-0.2133099920647492
193.00000000000233,32.613045806692114,-1.7338223727157487,-0.21344199219776083
194.10000000000235,32.718129532023596,-1.7338655273762762,-0.21364005594728264
195.20000000000238,32.82340840441255,-1.7325900010514526,-0.21364005779349649
196.3000000000024,32.92778587804355,-1.7322968850540725,-0.21464425365412065
197.40000000000242,33.0327626258951,-1.7327748978211543,-0.21463005599569085
198.50000000000242,33.137312974658194,-1.7320559092648748,-0.2146300560155887
199.60000000000244,33.241693756046104,-1.7303494940947273,-0.2146312601853091
200.70000000000246,33.34663324524445,-1.7306293051616575,-0.21562002459220864
201.80000000000246,33.45168483114724,-1.7296313978721818,-0.21660004846448322
202.90000000000248,33.55614117275993,-1.7286191781032914,-0.21659946772116268
204.0000000000025,33.66114637209034,-1.7273440906734168,-0.21792017807673592
205.10000000000252,33.764699948908856,-1.7282724114236607,-0.2165937899837158
206.20000000000255,33.86983701614077,-1.7265466054017042,-0.21858190827078472
207.30000000000254,33.97435505757842,-1.7250809905203883,-0.21727134060865838
208.40000000000256,34.07803993058775,-1.7251156887327193,-0.21725986400490704
209.5000000000026,34.18270916650625,-1.724688566294444,-0.217259439421138
210.60000000000258,34.287457350634014,-1.7234905175291673,-0.21859289509013458
211.7000000000026,34.391371014564825,-1.7229134367157115,-0.219900128825532
212.80000000000263,34.49646485208756,-1.7215098425553181,-0.2212191336945062
213.90000000000265,34.60099046768323,-1.7212171220763959,-0.22122010146004278
215.00000000000267,34.70530121560574,-1.7207244189464632,-0.22088982250278155
216.10000000000267,34.80801223232297,-1.719953692133578,-0.2208895542078153
217.2000000000027,34.915651978802245,-1.718827982775466,-0.2215530562589283
218.3000000000027,35.019260064012315,-1.7174364248082208,-0.22352147565794134
219.4000000000027,35.12386529539841,-1.7172207252193255,-0.22351981893371775
220.50000000000273,35.22869155372352,-1.717751037657652,-0.22483985807087503
221.60000000000275,35.33352459365085,-1.716208158145135,-0.22351346871830602
222.70000000000277,35.437957238970675,-1.7165215838668222,-0.22483982284366233
223.8000000000028,35.54230335498024,-1.7149375388146666,-0.22743731241356446
224.9000000000028,35.647152326559365,-1.7143936256281724,-0.22878348739525523
226.0000000000028,35.751718791484976,-1.7139871217217877,-0.22781009775071048
227.10000000000284,35.855932585791194,-1.713607841752771,-0.22773523811238494
228.20000000000283,35.96160981863305,-1.7131879434088146,-0.2297701083416066
229.30000000000285,36.06679923689557,-1.7130405913163211,-0.22977011110351242
230.40000000000288,36.170891013897574,-1.7108493929031712,-0.2300930650527655
231.5000000000029,36.275794079229875,-1.7105439787440655,-0.2314202704714492
232.60000000000292,36.38025235954668,-1.7102778759446435,-0.23273181077169802
233.70000000000292,36.48558786998265,-1.7108704529745462,-0.23405509733922703
234.80000000000294,36.590181130063456,-1.7084566716734144,-0.23441576085633553
235.90000000000296,36.695254638308874,-1.7089824900658768,-0.23570160162990073
237.00000000000296,36.79934733419529,-1.7079538993026098,-0.23702816927060955
238.10000000000298,36.90444196653433,-1.70594964225759,-0.23958619283710858
239.200000000003,37.00859181434323,-1.7048301095475376,-0.24066698905370654
240.30000000000302,37.113345353497,-1.704930787839077,-0.24195673934792783
241.40000000000305,37.21917123651319,-1.703089962650421,-0.24459980873645026
242.50000000000304,37.32304729128429,-1.7018922135037475,-0.24603926130719778
243.60000000000306,37.427532580564886,-1.7016518480206282,-0.24848382312690553
244.7000000000031,37.53229530238574,-1.7015136930643018,-0.24855239818324204
245.80000000000308,37.63734790057678,-1.7004401462413883,-0.24983412080118272
246.9000000000031,37.74167537060314,-1.7001313411738341,-0.2538531363451466
248.00000000000313,37.845438490951445,-1.701218420988104,-0.25513070272209015
249.10000000000315,37.95081758412814,-1.697898613974374,-0.2564452457016948
250.20000000000317,38.05560850639709,-1.6960988193960282,-0.25909083085045337
251.30000000000317,38.16036173973664,-1.696080307068631,-0.2617255300178063
252.4000000000032,38.26442828993714,-1.695865449997517,-0.2643676657328604
253.5000000000032,38.366826405372876,-1.69524512350568,-0.26561577572719486
254.6000000000032,38.47374833876251,-1.695459045199294,-0.26826784206456855
255.70000000000323,38.57817546042094,-1.6937422827438695,-0.27101994610083535
256.80000000000325,38.683075784606224,-1.6929984810895162,-0.27553772338432836
257.9000000000033,38.78782329798365,-1.6921717583292355,-0.2794401876233388
259.0000000000033,38.89280761772208,-1.6927926697758375,-0.2831592074829521
260.1000000000033,38.9970432245686,-1.692376261669547,-0.2864343384211274
261.20000000000334,39.102284933908294,-1.6916694299330213,-0.2896069941486701
262.30000000000337,39.206132266669286,-1.690362047779088,-0.2938073527452518
263.40000000000333,39.3113492661032,-1.6899142948759502,-0.2980974148065636
264.50000000000335,39.41442474165436,-1.6899623774921397,-0.3026590803043048
265.6000000000034,39.521859401833254,-1.6906498751879684,-0.30745543554225563
266.7000000000034,39.626489008885784,-1.6896984507993855,-0.3125416536970085
267.8000000000034,39.73245669002897,-1.689476351851044,-0.3170640497171253
268.9000000000034,39.83769339139551,-1.690036174458752,-0.32216156883962865
270.0000000000034,39.942490254098715,-1.6904845672363227,-0.32784892149488476
271.10000000000343,40.04737110684568,-1.690553829618858,-0.3333321426348905
272.20000000000346,40.15308257451995,-1.6913449018548408,-0.33895591597672503
273.3000000000035,40.25888871457951,-1.690400056926533,-0.34570392737432254
274.4000000000035,40.364325281804724,-1.6918627736854506,-0.3519778767943178
275.5000000000035,40.467524813447326,-1.6912246006942908,-0.35695170253250064
276.60000000000355,40.57283558174022,-1.6919512317009548,-0.36565022262988967
277.70000000000357,40.67954048553313,-1.6934870048411692,-0.37318544420090216
278.8000000000036,40.78475761813901,-1.6934228625702985,-0.3797835222537729
279.9000000000036,40.88956791060856,-1.6935037315532526,-0.3888850006184641
281.0000000000036,40.99475220368067,-1.6946334059396089,-0.3961419099921293
282.1000000000036,41.10047254708406,-1.6956207026349408,-0.40390544087529134
283.2000000000036,41.205304857315426,-1.695464311091727,-0.4120187580435539
284.30000000000365,41.311207965557976,-1.6960749994363264,-0.4239425041978637
285.4000000000037,41.416111918977435,-1.6991465290097765,-0.4324460325363444
286.5000000000037,41.52084603075991,-1.7008249010657739,-0.4421881953318505
287.60000000000366,41.6260381652859,-1.703502630734392,-0.45331768362831504
288.7000000000037,41.731998947734816,-1.7037983807716037,-0.46316538288124054
289.8000000000037,41.83771041699829,-1.7056424184663577,-0.4745450607455637
290.90000000000373,41.94244233081167,-1.7069816778176143,-0.4869685973577469
292.00000000000375,42.04890077749762,-1.7085354914343212,-0.49804937916124636
293.1000000000038,42.15386806318386,-1.7115014894263478,-0.5104405665747409
294.2000000000038,42.25927257898553,-1.7137495516742622,-0.523898468050819
295.3000000000038,42.36484682252547,-1.7173172648413622,-0.5372836749380197
296.40000000000384,42.47157575070544,-1.7191084745265555,-0.5505164326472078
297.5000000000038,42.576978647805156,-1.721958398360784,-0.5651173214537697
298.60000000000383,42.682780939465246,-1.7255083217857319,-0.5789391011736869
299.70000000000385,42.788948755452395,-1.7284739524394142,-0.5954232169268638
300.8000000000039,42.89474805886347,-1.7318318124858618,-0.6109540901050847
301.9000000000039,43.00026955711504,-1.734627718444493,-0.6266709388182496
303.0000000000039,43.10645057300664,-1.73817584839017,-0.643358768439199
304.10000000000394,43.21183215096568,-1.7413787397533567,-0.6603300066986137
305.2000000000039,43.31785455194149,-1.7450214539477882,-0.6786720515119873
306.30000000000393,43.423807326476584,-1.7481268970149195,-0.6965870805755938
307.40000000000396,43.53023381502424,-1.7522663800591631,-0.714748082283752
308.500000000004,43.63652144151703,-1.7554660855631283,-0.7339709738388551
309.600000000004,43.74217152301084,-1.7602402385263296,-0.7537370413678346
310.700000000004,43.84788505148613,-1.7627894005550755,-0.7740938625086535
311.80000000000405,43.953398372367985,-1.7672764206030693,-0.7947437912865034
312.90000000000407,44.059776521619554,-1.7718405398667358,-0.816165785360718
314.0000000000041,44.16633226641696,-1.7761095884443616,-0.8395983918709153
315.10000000000406,44.27210117168877,-1.7813824807574445,-0.8616573515017838
316.2000000000041,44.378196544189244,-1.7849353991538885,-0.8851735620630174
317.3000000000041,44.48461656480376,-1.7898415140239963,-0.908860795663192
318.4000000000041,44.58945669074931,-1.7938908582970778,-0.9316978748080378
319.50000000000415,44.696188471977585,-1.7989313969438043,-0.9581409815834379
320.6000000000042,44.80197688064082,-1.8048857107720828,-0.9831820721597389
321.7000000000042,44.90802141258106,-1.8069275757080299,-1.0092730533547423
322.80000000000416,45.015385186675076,-1.8140374860743376,-1.0389577282694162
323.9000000000042,45.12105161921723,-1.8199332726789612,-1.0660750443073534
325.0000000000042,45.227398018618565,-1.8263110103375695,-1.094751513716092
326.10000000000423,45.333644366910036,-1.8311266292265902,-1.1252233691335438
327.20000000000425,45.43858386813224,-1.8380801260264454,-1.1544888274785037
328.3000000000043,45.54555956621574,-1.843386179805397,-1.1854427639848701
329.4000000000043,45.65130252662382,-1.8518490424136458,-1.2184550441090387
330.5000000000043,45.75715819877264,-1.8594822436492637,-1.2513589232737368
331.60000000000434,45.86230226652311,-1.865773625929091,-1.2848072970901483
332.7000000000043,45.969784960291,-1.8758133480464028,-1.3201279157851218
333.80000000000433,46.0760521948572,-1.8859184578512744,-1.3541882541753725
334.90000000000435,46.182181479598476,-1.8930906846551712,-1.3927810263575395
336.0000000000044,46.28888243187812,-1.902023757185753,-1.4305870324146555
337.1000000000044,46.3958050251769,-1.9118468164807059,-1.4682225129312618
338.2000000000044,46.50165529177122,-1.921432963767981,-1.507389923046155
339.30000000000445,46.60768810131729,-1.930926163925789,-1.5499663353232256
340.4000000000044,46.71539389146259,-1.942417619873952,-1.5904254546356116
341.50000000000443,46.820469643561424,-1.9513806284881885,-1.635210389353388
342.60000000000446,46.92826635801561,-1.9615159421274526,-1.680402937255828
343.7000000000045,47.03568539886505,-1.9691347637055379,-1.7240924425244861
344.8000000000045,47.14213226028299,-1.9806031236138553,-1.7703258887937436
345.9000000000045,47.24877776324047,-1.9901060035800027,-1.8174973974571897
347.00000000000455,47.353628171088076,-1.9964639085034228,-1.8654083089852467
348.10000000000457,47.463216046392056,-2.0044866987220797,-1.9148983555505787
349.2000000000046,47.57025831434187,-2.009968308236339,-1.965943817605639
350.30000000000456,47.677370107295836,-2.014422133369237,-2.0149524641572247
351.4000000000046,47.78340711340074,-2.014722999994037,-2.0653748909779033
352.5000000000046,47.89053513319675,-2.015485668348234,-2.117820083372032
353.6000000000046,47.9971790507598,-2.011046399280394,-2.168569075278519
354.70000000000465,48.10356362635705,-2.0055581053243543,-2.218738701343325
355.8000000000047,48.20979228736491,-1.9945050015949986,-2.270496930538936
356.9000000000047,48.315652555860765,-1.9809908145184076,-2.3190996085267996
358.00000000000466,48.421022676759996,-1.9629404918065732,-2.366743180830322
359.1000000000047,48.52784548007899,-1.9455123251011714,-2.414298882057892
360.2000000000047,48.63331200594099,-1.9202119064353556,-2.4589393863505284
361.30000000000473,48.73888239618014,-1.8958909403605864,-2.5010995812863097
362.40000000000475,48.843964901508784,-1.8664483719578948,-2.5422345138914375
363.5000000000048,48.94881022686433,-1.8375256111041598,-2.579891743958557
364.6000000000048,49.053542720740545,-1.807507876099037,-2.614626209143087
365.7000000000048,49.16055795317187,-1.7745798951272809,-2.646397934511226
366.80000000000484,49.26506129047691,-1.7451218457069761,-2.676586799226914
367.9000000000048,49.37138098659701,-1.7136075462091935,-2.702719968370356
369.00000000000483,49.4770417109724,-1.6840694930655782,-2.7260605483160574
370.10000000000485,49.58179139244514,-1.6566760982067537,-2.748697295378223
371.2000000000049,49.68695207752332,-1.630119820570282,-2.767463021833479
372.3000000000049,49.79239650919395,-1.6065845420880438,-2.7848817460770836
373.4000000000049,49.89758231365556,-1.5851110460147602,-2.801057507813046
374.50000000000495,50.00394525455067,-1.5613722675666835,-2.814034591297757
375.6000000000049,50.11047495394387,-1.5408118290011,-2.825852369756392
376.70000000000493,50.215011812426106,-1.523500425215586,-2.8370815766222455
377.80000000000496,50.32109766160052,-1.5066640763952415,-2.846339656061681
378.900000000005,50.42746524049965,-1.4889111347163524,-2.855231925072113
380.000000000005,50.53299109255671,-1.4778157315058411,-2.8616193351612074
381.100000000005,50.640236273829444,-1.466529288978588,-2.868438938653929
382.20000000000505,50.745832883005846,-1.4574210616482475,-2.873312760620635
383.30000000000507,50.851954278254134,-1.4529315787489023,-2.8792132900451133
384.4000000000051,50.95876624147021,-1.4484502158488681,-2.884630929698708
385.50000000000506,51.065762967430956,-1.443588374327979,-2.888463676269656
386.6000000000051,51.172742548894234,-1.4416533984904094,-2.8931400448127973
387.7000000000051,51.28026050745358,-1.4393539187521196,-2.897612103786858
388.8000000000051,51.38593713993175,-1.4374979094670473,-2.901046281712394
389.90000000000515,51.49259492237996,-1.4364958340910523,-2.904754748109478
391.0000000000052,51.599802558161926,-1.4347469234062158,-2.9096338907024872
392.1000000000052,51.70651767153831,-1.4329343678255055,-2.911964818908614
393.20000000000516,51.81512730972892,-1.4306838615954012,-2.9158458369612203
394.3000000000052,51.92043619507592,-1.4292139730088087,-2.918172744734121
395.4000000000052,52.029065055855284,-1.4273553247469462,-2.9214510020350604
396.50000000000523,52.136462066413124,-1.425502999386953,-2.9261351801381847
397.60000000000525,52.243720857758184,-1.4251279395369014,-2.931556985029655
398.7000000000053,52.349514133674155,-1.4228253938060822,-2.9334382020233587
399.8000000000053,52.45648378511349,-1.4218176886847569,-2.935851088728218
400.9000000000053,52.564235214335795,-1.4183072120599156,-2.9399317912875
402.00000000000534,52.67283296106376,-1.4174497053125488,-2.942857858799094
403.1000000000053,52.779796579767314,-1.4167285809280066,-2.9467043170846092
404.20000000000533,52.88697886257307,-1.416265368165279,-2.9508756925298645
405.30000000000535,52.99567586282074,-1.4160774651612598,-2.9523344418387873
406.4000000000054,53.10298093898541,-1.4144191556604515,-2.9548633125247514
407.5000000000054,53.21078766410569,-1.4133904557791968,-2.959037024515985
408.6000000000054,53.318684484890234,-1.4125851345422225,-2.9627283177036596
409.70000000000545,53.42672589111935,-1.4114294599323487,-2.9653066062548743
410.8000000000054,53.53477070924311,-1.4128993721760694,-2.969085835894469
411.90000000000543,53.642231741802334,-1.4115992025688857,-2.9726979207909023
413.00000000000546,53.750404973100444,-1.411242120527147,-2.974676310111673
414.1000000000055,53.85857761526219,-1.4118944932166702,-2.9778294827117726
415.2000000000055,53.96616210391421,-1.4138360956794784,-2.980289320992747
416.3000000000055,54.07388428644696,-1.4147289026263696,-2.9846822613667356
417.40000000000555,54.18216820920987,-1.4139187255633925,-2.987342017814771
418.50000000000557,54.290449696144904,-1.4164057384504403,-2.9905006202960416
419.6000000000056,54.398131520029224,-1.4166220164601753,-2.992937095612418
420.70000000000556,54.50665684333774,-1.4180476547766188,-2.9944511286474116
421.8000000000056,54.61414976182255,-1.4178606561592944,-2.998291846210237
422.9000000000056,54.723312369910374,-1.420060301696566,-3.0008172162306064
424.0000000000056,54.831708883813754,-1.4208574989905798,-3.0045482354425666
425.10000000000565,54.93729122752356,-1.4241564952804386,-3.0063149337961184
426.2000000000057,55.04730470980734,-1.426198166871068,-3.009910677347051
427.3000000000057,55.15620520045565,-1.4297550988191536,-3.0128874592049018
428.40000000000566,55.2645032780751,-1.43146669005713,-3.014482648802515
429.5000000000057,55.37189413679962,-1.434926479323455,-3.016983092940646
430.6000000000057,55.47774926866913,-1.4375667362826188,-3.0213775514221473
431.70000000000573,55.58812043702474,-1.442846618506748,-3.024436468371978
432.80000000000575,55.695895066616636,-1.444544730853802,-3.0261846949580815
433.9000000000058,55.80510802899064,-1.4598586355592476,-3.0288368428666717
435.0000000000058,55.912969881720265,-1.4777482275773144,-3.032286726325747
436.1000000000058,56.02112666433905,-1.4909131400316495,-3.0347102121618725
437.20000000000584,56.129462384303935,-1.5052659596588163,-3.0373810233484306
438.3000000000058,56.23745642446964,-1.522814001237589,-3.03999962333702
439.40000000000583,56.346020785090495,-1.5344596701299584,-3.043393534835121
440.50000000000585,56.454152070381724,-1.5440642944990672,-3.0451159612807865
441.6000000000059,56.56259841337295,-1.5547093822778637,-3.0477052460745293
442.7000000000059,56.671332162483516,-1.5604282923085762,-3.049991464668536
443.8000000000059,56.780244568420684,-1.5656775212911702,-3.05262676267943
444.90000000000595,56.8878667186205,-1.5699681440455107,-3.053177649151432
446.0000000000059,56.9975493580488,-1.5746135861071522,-3.0553901187456107
447.10000000000593,57.10534833217283,-1.5805746254159043,-3.0579456328838286
448.20000000000596,57.2141405854631,-1.5841912884243126,-3.061105634014404
449.300000000006,57.32376502811698,-1.5894305077088204,-3.064608769280725
450.400000000006,57.43237873693339,-1.5924272741212788,-3.0645741023759703
451.500000000006,57.54054948148678,-1.5956370727072562,-3.0675656756873444
452.60000000000605,57.648817142750076,-1.5981557020338455,-3.0708323533014497
453.70000000000607,57.75859792792956,-1.6010399491633913,-3.0724654301588603
454.8000000000061,57.86486263012739,-1.6051700858327793,-3.073426778438883
455.90000000000606,57.97616605053185,-1.6071894496198111,-3.0754911782806795
457.0000000000061,58.08481426888533,-1.608397899757043,-3.077432724369433
458.1000000000061,58.19317808871614,-1.6098210954732206,-3.080136584650319
459.2000000000061,58.30193299571297,-1.613632021324122,-3.082809404040004
460.30000000000615,58.41064671705002,-1.6159441564777266,-3.0845060920478953
461.4000000000062,58.51999700078801,-1.6194270824548262,-3.0856790218119112
462.5000000000062,58.62880222394914,-1.6242930001977824,-3.086998455196709
463.60000000000616,58.73852669327178,-1.6288067478740271,-3.090127115938227
464.7000000000062,58.84693663137343,-1.631891529915008,-3.091171929803268
465.8000000000062,58.95553717724163,-1.6343657370543738,-3.0925791178784388
466.90000000000623,59.06487060635333,-1.6365582825589033,-3.095850886334645
468.00000000000625,59.173706273261786,-1.6388190419855562,-3.097114571922789
469.1000000000063,59.28355234983856,-1.6411781593937191,-3.098736094566381
470.2000000000063,59.392641479220465,-1.6426406077858853,-3.099831720567277
471.3000000000063,59.501819472616546,-1.6449023091902677,-3.102569248122961
472.40000000000634,59.61101931314548,-1.6440936477273895,-3.1038056161369623
473.5000000000063,59.72073510759324,-1.6440334194754382,-3.1065293662249087
474.60000000000633,59.83061640635974,-1.6434646177396706,-3.108945496875685
475.70000000000636,59.93974988511736,-1.643373260831207,-3.1088652084263457
476.8000000000064,60.04802864315946,-1.6415756653850666,-3.111481052496689
477.9000000000064,60.1563238998486,-1.643254263299867,-3.112802392633606
479.0000000000064,60.26633931858099,-1.6432229243239762,-3.1154821487170214
480.10000000000645,60.37621645179923,-1.6453396289658508,-3.115479600659524
481.2000000000064,60.48443729266151,-1.6473034390502188,-3.117186911782383
482.30000000000643,60.594254101058155,-1.646631950826863,-3.1187352320145796
483.40000000000646,60.703402995770915,-1.6467663998651536,-3.120069384499932
484.5000000000065,60.81254353514976,-1.6497229736081327,-3.122779672622264
485.6000000000065,60.92142793513175,-1.6500351789724246,-3.1236441362744807
486.7000000000065,61.031331675731614,-1.649859971233413,-3.124648757403291
487.80000000000655,61.14017629708616,-1.6476071499044038,-3.127288832021656
488.90000000000657,61.24960305761068,-1.6445095232918572,-3.1272900014369904
490.0000000000066,61.35861569508657,-1.6366827085644724,-3.1286089741389413
491.10000000000656,61.467560913991825,-1.622536471715928,-3.1312372627424434
492.2000000000066,61.57740984540644,-1.6111392054940292,-3.132609244117879
493.3000000000066,61.686277694395535,-1.5965365016764774,-3.132882836163735
494.4000000000066,61.796486120052755,-1.5804069340016553,-3.135563907648068
495.50000000000665,61.905306013799155,-1.5691690098009288,-3.1342221887372608
496.6000000000067,62.01450857604469,-1.5591708095213788,-3.1355092856821476
497.7000000000067,62.12409361204456,-1.5478888221494451,-3.1375112063553456
498.80000000000666,62.2335506425044,-1.5410504495240853,-3.1401449974832802
499.9000000000067,62.34288571018575,-1.5341900580496186,-3.14013068362598
501.0000000000067,62.45322818854694,-1.5323087561309658,-3.1427374885607096
502.10000000000673,62.56246664921452,-1.53094490828647,-3.144088557838317
503.20000000000675,62.67242341446172,-1.530957317336261,-3.1441761246375357
504.3000000000068,62.78117836417456,-1.529007981482488,-3.145412187332221
505.4000000000068,62.89079729346907,-1.5294541805215414,-3.1470036366095826
506.5000000000068,62.99954859750427,-1.5285002675983208,-3.1467193390048136
507.60000000000684,63.109694446571055,-1.5272420975979468,-3.149350320417577
508.7000000000068,63.21908004738415,-1.5284183321059028,-3.1493470130911634
509.80000000000683,63.327064433847326,-1.5296027077640855,-3.1519903385907817
510.90000000000686,63.43850539237068,-1.5325397812655623,-3.1533699169192158
512.0000000000068,63.54848471289094,-1.5332145287015797,-3.1546760708262678
513.100000000007,63.657123091317494,-1.53548375806691,-3.1553981653494128
514.2000000000069,63.76682862496436,-1.5374823495335217,-3.155937087723194
515.300000000007,63.87698209718358,-1.5392463456847914,-3.1562651737584035
516.4000000000069,63.98626225862837,-1.5409979244524543,-3.1575806578432832
517.5000000000069,64.095908023167,-1.5427407621923892,-3.160224746789344
518.600000000007,64.2055060487973,-1.5450684204639296,-3.1602302451017965
519.700000000007,64.31504818691859,-1.5458474670045605,-3.162878347093968
520.800000000007,64.4250563830813,-1.546337607172175,-3.162856209947335
521.900000000007,64.53268437964682,-1.5474362078640092,-3.1641709541654155
523.000000000007,64.64542801322489,-1.5491624554432684,-3.1641738674064284
524.1000000000071,64.75453685751236,-1.5487630029704624,-3.166830153967044
525.2000000000071,64.8650750377847,-1.5508665890769218,-3.1684166631472412
526.300000000007,64.97521372846168,-1.551685930640957,-3.167463648624251
527.4000000000071,65.08459761950817,-1.5538901873824766,-3.16986901320913
528.500000000007,65.19533810241683,-1.5564862929535475,-3.171409033937935
529.6000000000072,65.30497419755795,-1.5592260648741625,-3.1724595638725215
530.7000000000071,65.41462576003926,-1.5620476657256253,-3.1737067852496317
531.8000000000072,65.52457158170971,-1.5642540083715295,-3.1732474037453673
532.9000000000071,65.63483186869715,-1.5652777699610936,-3.17405379081981
534.0000000000072,65.74447785017117,-1.5690235873243645,-3.1760216199517823
535.1000000000072,65.85544494042641,-1.571796283295999,-3.176029717129977
536.2000000000072,65.9655832085899,-1.5750996626098663,-3.1772706454415074
537.3000000000072,66.07545667121981,-1.577409996287795,-3.178686375069984
538.4000000000073,66.18582058660458,-1.5796299640932412,-3.179320970646973
539.5000000000073,66.29637158074662,-1.5845415940389778,-3.1797749480948667
540.6000000000073,66.40607182618558,-1.5863666920186414,-3.181629133031384
541.7000000000073,66.51664269105272,-1.5885950084721936,-3.1829498251375132
542.8000000000073,66.62768663054428,-1.5922218551872067,-3.1842559761246236
543.9000000000074,66.73747361657333,-1.596316639914766,-3.18558241583471
545.0000000000074,66.84777963505485,-1.5994322800972811,-3.1868571936488825
546.1000000000074,66.9577775001386,-1.6021534640340616,-3.1859202168121947
547.2000000000073,67.06916900008017,-1.6048199531335616,-3.1869097946879306
548.3000000000073,67.17936726279413,-1.6082538871529444,-3.1882256283836936
549.4000000000074,67.28907218605029,-1.6109522632600393,-3.1888715115604427
550.5000000000074,67.39917000000086,-1.613660000000037,-3.1895399589226225
551.6000000000074,67.51033024497826,-1.618314678401512,-3.189769524466007
552.7000000000074,67.61814251579838,-1.6188694174302884,-3.191190097856602
553.8000000000075,67.72871539345641,-1.6223264014820722,-3.1921377890761002
554.9000000000075,67.8407425365816,-1.6267746386935864,-3.1925076887454775
556.0000000000075,67.95101662685765,-1.6299067014652546,-3.195138330622265
557.1000000000075,68.06094260686258,-1.632781344086557,-3.194809985789554
558.2000000000075,68.1722048538213,-1.6364580455273743,-3.196141975511538
559.3000000000076,68.28220229022044,-1.6389013380891215,-3.1978752892728792
560.4000000000076,68.39161601718567,-1.6415236750024274,-3.198730018269057
561.5000000000076,68.50243225826046,-1.642828275127062,-3.198766213613216
562.6000000000076,68.61340828577747,-1.645341472487406,-3.1987571994209008
563.7000000000077,68.72400515513002,-1.647968092863902,-3.2000799949045344
564.8000000000077,68.8333448690575,-1.6494013078463998,-3.199355382854773
565.9000000000076,68.94478014050817,-1.6522798021617604,-3.2004000534590293
567.0000000000076,69.0547183598478,-1.6550110966591314,-3.2013925807720782
568.1000000000076,69.16626317881665,-1.6571059687436769,-3.2023809282866242
569.2000000000077,69.27621868904055,-1.6604440074633149,-3.202053943906256
570.3000000000077,69.38664543590878,-1.6631244112685615,-3.203370040251478
571.4000000000077,69.4979650135548,-1.663989685724728,-3.204689775366442
572.5000000000077,69.6083210635006,-1.6675008832558749,-3.2060103820997266
573.6000000000078,69.71927197910674,-1.6734323148984205,-3.2060100324850067
574.7000000000078,69.83028120035858,-1.6739595690715283,-3.2073299813153953
575.8000000000078,69.9412948630326,-1.676783737236565,-3.208321175836263
576.9000000000078,70.05235012415787,-1.6785941816452006,-3.208705823014337
578.0000000000078,70.16255433636377,-1.68127383510988,-3.209294428973442
579.1000000000079,70.27196196736895,-1.6844019486904525,-3.210622945930812
580.2000000000079,70.38383404304047,-1.6862942196028197,-3.2106798078600995
581.3000000000079,70.49378406465176,-1.6873086887912043,-3.2122601969132987
582.4000000000078,70.60418275276086,-1.690752665643371,-3.212260138357181
583.5000000000078,70.71538006700501,-1.692547402684097,-3.2135801846254926
584.6000000000079,70.82647864830483,-1.697443826564728,-3.213894106612316
585.7000000000079,70.93725949999283,-1.6978263481628857,-3.214094465677006
586.8000000000079,71.04927442780713,-1.7019592414283022,-3.215229842235254
587.9000000000079,71.15978108794751,-1.7046165459190539,-3.216539990293638
589.000000000008,71.27089439617501,-1.7063172097615147,-3.217534368746769
590.100000000008,71.3815144303657,-1.7078213769426343,-3.217058749332078
591.200000000008,71.49231725201824,-1.7094699874779096,-3.217859532177757
592.300000000008,71.60264462931681,-1.7127317394464354,-3.2191847835405123
593.400000000008,71.71432876668209,-1.7167064649310673,-3.220820168286956
594.5000000000081,71.82462191966601,-1.7176854660208676,-3.2195245255172384
595.6000000000081,71.93529469429514,-1.7210386570742797,-3.220825076239025
596.7000000000081,72.0465017928663,-1.7226041377798458,-3.2223240309719765
597.8000000000081,72.15716260520293,-1.7247952677090668,-3.2231270357423574
598.9000000000082,72.2687749102485,-1.7283804126039657,-3.2244501413271687
600.0000000000082,72.38006043654421,-1.732321220434931,-3.223789858644836
601.1000000000081,72.49100960348864,-1.736650342582227,-3.223788651189476
602.2000000000081,72.60098141799453,-1.73799161076784,-3.2251099716694616
603.3000000000081,72.7120357277655,-1.7423490751228214,-3.2251237213450703
604.4000000000082,72.8222553402692,-1.742871221354607,-3.226823479318047
605.5000000000082,72.9337644128666,-1.7461640949067088,-3.2267598399766353
606.6000000000082,73.04418595324042,-1.7472506207667324,-3.226760767051382
607.7000000000082,73.15511257617007,-1.7521919086644846,-3.2283927802632615
608.8000000000083,73.26557811021219,-1.754585215398928,-3.229381383974798
609.9000000000083,73.37702734969695,-1.759621386663011,-3.2307101029910577
611.0000000000083,73.48714666737513,-1.7616431107798616,-3.2320186268449773
612.1000000000083,73.5986856234818,-1.7624193977503957,-3.2316897459910976
613.2000000000083,73.70888318898407,-1.7653831542510545,-3.232998424980683
614.3000000000084,73.81886220683313,-1.7676000751619114,-3.233330369512409
615.4000000000084,73.92994854220686,-1.771096080755411,-3.234661025330712
616.5000000000084,74.0412124655725,-1.7746926444064197,-3.2346598098190458
617.6000000000083,74.15208081651681,-1.7796228920610402,-3.2359703931060944
618.7000000000083,74.26280663889173,-1.7833383778777547,-3.2356107322003913
619.8000000000084,74.3731473833201,-1.7871073438735243,-3.2370088552656635
620.9000000000084,74.48442327122234,-1.791456433223875,-3.2372206336056184
622.0000000000084,74.59777448486726,-1.7949894950778427,-3.2372900583227446
623.1000000000084,74.70723208240808,-1.8013337042618478,-3.23861015537755
624.2000000000085,74.82060109221794,-1.8059741652819163,-3.2399137983793547
625.3000000000085,74.93245644723777,-1.8103664012049092,-3.2412632238758206
626.4000000000085,75.04325797933468,-1.8110442128826643,-3.240915417131407
627.5000000000085,75.15580829704896,-1.8147039608252284,-3.2408829506803114
628.6000000000085,75.26588065347046,-1.8190687329504103,-3.2432427084794426
629.7000000000086,75.37975831045273,-1.8231274165401068,-3.243550198654616
630.8000000000086,75.49012304979323,-1.8258977639604732,-3.2448700048083463
631.9000000000086,75.60163596670542,-1.8313937033345011,-3.244882153364651
633.0000000000086,75.71325679956024,-1.8372768412832334,-3.2475668312418526
634.1000000000087,75.82436865032145,-1.841352650403615,-3.2475803798846874
635.2000000000087,75.93661271260801,-1.8452405369787357,-3.2479073567580654
636.3000000000086,76.0481287374946,-1.8482855317162983,-3.248821664815029
637.4000000000086,76.15968199865259,-1.853137108323582,-3.250155833686809
638.5000000000086,76.27221788071147,-1.8577550915212244,-3.250825690284822
639.6000000000087,76.383468966849,-1.861421889968003,-3.2501448617626094
640.7000000000087,76.49456651610872,-1.8636208363125208,-3.251450084460797
641.8000000000087,76.60572064104332,-1.8657649473125122,-3.252769169040452
642.9000000000087,76.71646725188752,-1.869258314740542,-3.254075429106605
644.0000000000088,76.82759783390186,-1.8729964351921355,-3.255399703631998
645.1000000000088,76.93997339406431,-1.87573062247935,-3.2564981633768157
646.2000000000088,77.04998102844928,-1.8783513096054876,-3.256800452461624
647.3000000000088,77.16265372853425,-1.8827121433683305,-3.2588056823520795
648.4000000000088,77.27464434142188,-1.8848670112678734,-3.2589652285043047
649.5000000000089,77.38519308895408,-1.888241096548009,-3.260682702607918
650.6000000000089,77.49798183246298,-1.8902237665698156,-3.2619767327068447
651.7000000000089,77.6111139118885,-1.8908188557916594,-3.262008536483595
652.8000000000088,77.7211913424056,-1.894008241090116,-3.2646036414699386
653.9000000000088,77.8336657187204,-1.8945653443389818,-3.2649604022195815
655.0000000000089,77.94491360232753,-1.8926460031232082,-3.2649601214959634
656.1000000000089,78.05623471611474,-1.8934871754440312,-3.2658777288931677
657.2000000000089,78.16749191681176,-1.8928745515603767,-3.2682425236894126
658.3000000000089,78.27586435802718,-1.8920901575301714,-3.2695695366539663
659.400000000009,78.39045664789136,-1.8913680218910693,-3.269334511145652
660.500000000009,78.5011505964578,-1.8903895281005996,-3.2695338485033
661.600000000009,78.61367154004182,-1.8913801605529599,-3.271705437180991
662.700000000009,78.72499576946178,-1.8886597070929663,-3.2721453129274045
663.800000000009,78.836130406994,-1.8879407950693075,-3.272908675759907
664.9000000000091,78.94780489719258,-1.8857016525966794,-3.2741796644450285
666.0000000000091,79.05957921215376,-1.8846203927247738,-3.274195220245622
667.1000000000091,79.17049866737312,-1.8831446065209905,-3.274510031593641
668.2000000000091,79.28046138474693,-1.883246003257973,-3.27451020008054
669.3000000000092,79.39342508529352,-1.8821152888914112,-3.275506404867425
670.4000000000092,79.50578482448027,-1.880660264506501,-3.2758316886205145
671.5000000000091,79.61697561419749,-1.8819273492229744,-3.2765607160954557
672.6000000000091,79.72867758466651,-1.8819956871301293,-3.2754992069542026
673.7000000000091,79.84065589593057,-1.8870787641863938,-3.2774616580884985
674.8000000000092,79.95189581246684,-1.8903357675703394,-3.2774733003817036
675.9000000000092,80.0634463778522,-1.8941907968778875,-3.2771191988375725
677.0000000000092,80.1758885299093,-1.8955865970299481,-3.278643945773812
678.1000000000092,80.28742846979269,-1.899377965111958,-3.277476653327551
679.2000000000093,80.39885089428397,-1.9045999533127198,-3.2794499010979203
680.3000000000093,80.51092060244851,-1.9073971982599063,-3.278203045448761
681.4000000000093,80.62217847574148,-1.9089754899553986,-3.2789322711136495
682.5000000000093,80.73471698547705,-1.9145105046302249,-3.280110183637474
683.6000000000093,80.84573916614504,-1.9202843712173459,-3.2801340786261104
684.7000000000094,80.95714994514148,-1.924253547570401,-3.2807531126553986
685.8000000000094,81.06958966422884,-1.9286033964786957,-3.282080201484246
686.9000000000094,81.18081845809508,-1.934901834753815,-3.28213339181849
688.0000000000093,81.29182675997666,-1.9383876542645866,-3.282080045929767
689.1000000000093,81.40389813799813,-1.9416042499171522,-3.282034276906903
690.2000000000094,81.5159143288358,-1.9448873661210362,-3.2833993413157496
691.3000000000094,81.62797236350626,-1.9499183661833042,-3.282647569442021
692.4000000000094,81.74095250194803,-1.9550848939278749,-3.284390150211146
693.5000000000094,81.85275991013407,-1.9643468528740233,-3.2843913228446637
694.6000000000095,81.96481461839727,-1.966782889511549,-3.2837399386603496
695.7000000000095,82.07709446539289,-1.9719627289626025,-3.2845907283010036
696.8000000000095,82.19052167003187,-1.9755025588690056,-3.285123281574909
697.9000000000095,82.30160724463697,-1.98060356294346,-3.2840831006981457
699.0000000000095,82.41347289930683,-1.9853571158500505,-3.285380235082903
700.1000000000096,82.52551145879475,-1.9911310314989223,-3.288007729767857
701.2000000000096,82.63690927146129,-1.9978765498275015,-3.2866989189208082
702.3000000000096,82.74873455518937,-2.002517956097698,-3.286701343343312
703.4000000000096,82.86124675233368,-2.00907378689574,-3.286033005153418
704.5000000000097,82.97409839812154,-2.013400758401012,-3.287378058566609
705.6000000000097,83.08419973064926,-2.0172041171381023,-3.288009395306811
706.7000000000096,83.19737365027501,-2.0213353481624785,-3.289391655617778
707.8000000000096,83.30960271715469,-2.0254778918496985,-3.2880098958439605
708.9000000000096,83.41927708312407,-2.0332126964246426,-3.2880099333239965
710.0000000000097,83.53386390623703,-2.0375618932250195,-3.2895632394014656
711.1000000000097,83.64527924808914,-2.04431049240274,-3.290650063764228
712.2000000000097,83.75717223729204,-2.048630643072372,-3.290649685202743
713.3000000000097,83.86896784847558,-2.054510713880104,-3.2919601436807557
714.4000000000098,83.98186786213617,-2.059225729228148,-3.290640369690612
715.5000000000098,84.09358063126247,-2.0636556150089187,-3.291629814602618
716.6000000000098,84.20581757077895,-2.0702707827545197,-3.2919894871040016
717.7000000000098,84.3154510327604,-2.076197497164862,-3.2932798272933144
718.8000000000098,84.4300830741626,-2.0805582729747054,-3.291980861575545
719.9000000000099,84.54150940719214,-2.086582771273589,-3.293965751743134
721.0000000000099,84.65391805445654,-2.0955834091947834,-3.293958219430492
722.1000000000099,84.76559977052297,-2.098653988816382,-3.2939399943792895
723.2000000000098,84.8786182630114,-2.106040955111452,-3.294599313401833
724.3000000000098,84.99088903310653,-2.112773323724553,-3.295915910667534
725.4000000000099,85.10343473767156,-2.1169851148348084,-3.2958780790881272
726.5000000000099,85.2150796245518,-2.123621288661894,-3.2972208677072428
727.6000000000099,85.3270051707774,-2.1299140120881823,-3.2972396662080317
728.7000000000099,85.43886864721131,-2.1359987419487734,-3.296579806729625
729.80000000001,85.55178396587537,-2.1410904929559718,-3.297068100278353
730.90000000001,85.66378906263654,-2.148174971388866,-3.297229599593816
732.00000000001,85.77621031768587,-2.1540400988263118,-3.298549918729986
733.10000000001,85.88826478795293,-2.1630575138275625,-3.2983199029701242
734.20000000001,86.0004971676206,-2.1696298115825257,-3.297889881865993
735.3000000000101,86.1106680743165,-2.1768346433644767,-3.299210474042024
736.4000000000101,86.22518732710274,-2.1850009323663873,-3.3005262601991228
737.5000000000101,86.33668278263502,-2.1920563328976552,-3.300519851160411
738.6000000000101,86.44927705582467,-2.2014921181402647,-3.3008496291564575
739.7000000000102,86.56163418890304,-2.2099175760414065,-3.3018405151550567
740.8000000000102,86.67363639445297,-2.2174227102752075,-3.3018687695473163
741.9000000000101,86.78566626717263,-2.2248950123126665,-3.301520841500415
743.0000000000101,86.89804112738098,-2.2339139234939402,-3.3028398946245425
744.1000000000101,87.01011157004584,-2.243099075255621,-3.30283933230076
745.2000000000102,87.12315347939241,-2.251103337701944,-3.302463422015196
746.0000000000102,87.20486231670898,-2.2553395926880775,-3.303819426556742