File: 01_Data/Cardboard/STA/N2/10K_min/Cardboard_STA_N2_10KData_230628_R1.csv
##Temp./Â°C,Time/min,DSC/(mW/mg),Mass loss/mg
26.0,15.47122069948266,-1.8528065300504115,-0.07426009613491136
27.100000000000016,15.98169591355141,-1.7828825066106633,-0.07303708496644745
28.20000000000003,16.226938896193865,-1.7490239086974047,-0.07299092932323337
29.300000000000047,16.41752468043272,-1.7281667037150439,-0.07177569815959117
30.400000000000063,16.587861451019833,-1.7120231664807264,-0.0729172875680506
31.500000000000078,16.742733369892427,-1.701011054139698,-0.07389179416336766
32.600000000000094,16.888841991272507,-1.6903174806995387,-0.07465574941501085
33.70000000000011,17.02203562841816,-1.6832316312526887,-0.07414326729134846
34.800000000000125,17.162230552418947,-1.67919713608485,-0.07626673899393577
35.90000000000014,17.290104871520075,-1.6739174152390115,-0.07829129876355267
37.000000000000156,17.421426475455494,-1.6689989977928525,-0.07774357750360927
38.10000000000017,17.55018208352221,-1.6669401631976768,-0.0776757761839395
39.20000000000019,17.67624284471981,-1.6651538330920734,-0.08139546835933142
40.3000000000002,17.79937785532008,-1.6627044088948348,-0.0812957937134593
41.40000000000022,17.923422677403266,-1.6630913733263182,-0.08284663711064955
42.500000000000234,18.045227227692713,-1.6625886691429432,-0.08249880930103526
43.60000000000025,18.167394318866517,-1.662744106986111,-0.08540235234014482
44.700000000000266,18.288007186774365,-1.6639486542168824,-0.0866115913534573
45.80000000000028,18.408834948642742,-1.6648224470486233,-0.08695247526198013
46.9000000000003,18.528230811516895,-1.6663752592235606,-0.08825988208485391
48.00000000000031,18.648014151356744,-1.667942504658658,-0.08823584595191836
49.10000000000033,18.764921672252417,-1.6689333139847635,-0.09221204424601037
50.200000000000344,18.884917037055782,-1.6691892384385552,-0.09353229046292899
51.30000000000036,19.002425474863255,-1.6721069509999809,-0.09616535682952154
52.400000000000375,19.119683326628163,-1.6736454017974205,-0.09748012680830609
53.50000000000039,19.23437520017078,-1.6743952494697545,-0.09747989858576478
54.600000000000406,19.34986950932616,-1.6764397514549243,-0.10032005480251716
55.70000000000042,19.46580515164162,-1.6767817386164106,-0.10430176372331434
56.80000000000044,19.5799040783434,-1.6786354538091666,-0.10428999804049166
57.90000000000045,19.69545697052528,-1.67860658254055,-0.10692188900828992
59.00000000000047,19.804371721526117,-1.6786989869436506,-0.10824009257167244
60.100000000000485,19.922248308182713,-1.6771278021087224,-0.11094564542296492
61.2000000000005,20.034903336465753,-1.678883058336555,-0.1136963840990779
62.300000000000516,20.145564450424644,-1.6778910361000485,-0.11482043918480755
63.40000000000053,20.254933037748735,-1.676896118339055,-0.11745888101819268
64.50000000000054,20.36990628115115,-1.67518878445079,-0.11878096017290307
65.60000000000056,20.48102737490058,-1.6718094206407046,-0.12009941492954823
66.70000000000059,20.592266903599253,-1.6692894678530914,-0.12311374148884902
67.8000000000006,20.703825414906497,-1.666169474864984,-0.12538220143155687
68.9000000000006,20.813108613779235,-1.6614445519292276,-0.12942053279858534
70.00000000000063,20.92365876505695,-1.6566171832207137,-0.13064015421040676
71.10000000000065,21.033971505749577,-1.6522697949493634,-0.13393690341715558
72.20000000000066,21.14402383031547,-1.646324703231702,-0.135953847310895
73.30000000000067,21.25000000000006,-1.6418999999999988,-0.13854088291728228
74.40000000000069,21.36292465125218,-1.6349217574864614,-0.14137682163606424
75.50000000000071,21.473263900763484,-1.6273523281724345,-0.14359296102960606
76.60000000000072,21.580932384623647,-1.6202591861957907,-0.14523532980726817
77.70000000000073,21.692602470628824,-1.6125293689567282,-0.14919102099964388
78.80000000000075,21.800714342631053,-1.6033882137067519,-0.15182203437446073
79.90000000000077,21.906719000082997,-1.5954401069066275,-0.15352592792069863
81.00000000000078,22.019321045358147,-1.5876675904714161,-0.15445996204430923
82.10000000000079,22.126364105131646,-1.5779107413902371,-0.1570744649280753
83.20000000000081,22.23583834348939,-1.5673409643876404,-0.1597263752121263
84.30000000000084,22.343310139712827,-1.557113847930393,-0.16105011194058516
85.40000000000084,22.45210683675583,-1.5481374568947366,-0.16105002088961395
86.50000000000085,22.55917593762859,-1.538479360041823,-0.16310138015042597
87.60000000000088,22.666820522435117,-1.5280668782758222,-0.16456474594451986
88.7000000000009,22.77521950738594,-1.5164037921255853,-0.16762878433480832
89.8000000000009,22.881422184378415,-1.5057664746710022,-0.17048992172598698
90.90000000000092,22.989661258580004,-1.49701415177807,-0.17170009742239944
92.00000000000094,23.097580554731238,-1.4857404628793944,-0.1730172227478759
93.10000000000096,23.203908787535777,-1.4743808128948803,-0.17432995198529078
94.20000000000097,23.311490886805306,-1.4646276031803196,-0.17563136482931085
95.30000000000098,23.41676443512421,-1.4538475593328137,-0.17561001793500708
96.400000000001,23.524977964054937,-1.4431766721941583,-0.1769598884313437
97.50000000000102,23.630723281536977,-1.431935614175034,-0.17795612187317023
98.60000000000103,23.736580498507273,-1.4232859953745165,-0.17960770297500694
99.70000000000104,23.840302071821387,-1.4124323831913426,-0.18093095229583245
100.80000000000106,23.94866655032548,-1.4034586164620357,-0.18215209896399998
101.90000000000109,24.05603230310148,-1.3924564979713026,-0.1822280184040519
103.0000000000011,24.159902921907154,-1.381500380240281,-0.18354966679838558
104.1000000000011,24.267498398807138,-1.3743068287267592,-0.18487003398984125
105.20000000000113,24.373235539313768,-1.3663536139479089,-0.1843992582068168
106.30000000000115,24.478239266128554,-1.354526650427643,-0.1848969603562427
107.40000000000116,24.58529355389893,-1.3478657727372392,-0.1873160905985971
108.50000000000117,24.69121759535802,-1.3382055949712528,-0.18619035644005688
109.60000000000119,24.797194804755126,-1.330960196548171,-0.18717026575351525
110.70000000000121,24.904098520355518,-1.3230965039993925,-0.18749953020044252
111.80000000000122,25.00960743809271,-1.3157426635240654,-0.18750024237682617
112.90000000000123,25.115985021209184,-1.309250549390313,-0.18882384735550506
114.00000000000125,25.222177575583082,-1.3018088721071037,-0.18882023983519947
115.10000000000127,25.325640051706866,-1.2951651280447094,-0.18891962474711832
116.20000000000128,25.4349270695455,-1.287834839820371,-0.18884036983800723
117.30000000000129,25.541654460559062,-1.2828234014339026,-0.1901192155271092
118.40000000000131,25.647715966583213,-1.2761613348111234,-0.19112990859715673
119.50000000000134,25.754326507259012,-1.2703527528771998,-0.19246602148789194
120.60000000000134,25.856870186457336,-1.2651462850747566,-0.19112005106713248
121.70000000000135,25.96546414724132,-1.2606836521252398,-0.1911200480007471
122.80000000000138,26.07202790659779,-1.2540058313879139,-0.19111918510688586
123.9000000000014,26.178641802435873,-1.2487884191558594,-0.1911302209789234
125.0000000000014,26.284798622161027,-1.2446237064552048,-0.1911301207286753
126.10000000000142,26.390930697921153,-1.2410406782019203,-0.19239752128865817
127.20000000000144,26.496027325292864,-1.23486334358555,-0.19146009634878602
128.30000000000146,26.601604215600823,-1.2312372368201443,-0.19149268316019175
129.40000000000146,26.70741433155398,-1.2267160423545056,-0.192770158493059
130.50000000000148,26.813363319126058,-1.2234087055851015,-0.19409067213318654
131.6000000000015,26.91978957995427,-1.2186768185757173,-0.1940901094609515
132.70000000000152,27.026112004106004,-1.2142725219279322,-0.19451093309837741
133.80000000000155,27.131741475197188,-1.2119727108944236,-0.19375990405846277
134.90000000000154,27.236679238263665,-1.2092349031229808,-0.19376345421646146
136.00000000000156,27.342144592561855,-1.205203311531568,-0.19396211007618192
137.1000000000016,27.44739593352683,-1.201186153774567,-0.19277647041486734
138.20000000000158,27.553149518145656,-1.1984678128240533,-0.1927793002142657
139.3000000000016,27.658728440329067,-1.1962314941194763,-0.1940896824633942
140.40000000000163,27.76510585106979,-1.1920981394205976,-0.195410193370952
141.50000000000165,27.869014361964677,-1.1895830539582615,-0.19409099331986113
142.60000000000167,27.975590887170522,-1.186373557268933,-0.19475597852196014
143.70000000000167,28.081860567309107,-1.1852772164470098,-0.19474803530264495
144.8000000000017,28.18816330329595,-1.1813494469611487,-0.19482065018365535
145.9000000000017,28.29233148408002,-1.1789789962512718,-0.1950797073690822
147.0000000000017,28.398355386746864,-1.1759332538408251,-0.19639970732193834
148.10000000000173,28.504145293898077,-1.173809024517804,-0.195071803317993
149.20000000000175,28.608321058327494,-1.1698637899645459,-0.19474959584767948
150.30000000000177,28.714892868432642,-1.1663347664967485,-0.1970521094539368
151.4000000000018,28.81897133999417,-1.1652532608157438,-0.19703142699716025
152.5000000000018,28.92403945687633,-1.1631790103797823,-0.1970500641151549
153.6000000000018,29.030831982289467,-1.159217815539078,-0.1970249443414609
154.70000000000184,29.134819390676558,-1.156940367931839,-0.19606996762215978
155.80000000000183,29.238059730279673,-1.1541026328285173,-0.19606995924902737
156.90000000000185,29.343550404744317,-1.1525796468072929,-0.19475170472281622
158.00000000000188,29.4497342766901,-1.1505654486887706,-0.1957910377835983
159.1000000000019,29.556320428282415,-1.1471631788633057,-0.195395496103413
160.20000000000192,29.662324228590485,-1.1457961192246915,-0.19574176882125993
161.30000000000192,29.765021829145628,-1.1432244290362916,-0.1957399303684939
162.40000000000194,29.869469495849053,-1.1408351384659663,-0.19705800411154506
163.50000000000196,29.97641551375998,-1.1383778645383775,-0.1973797585263828
164.60000000000196,30.081209529643534,-1.134279900075257,-0.19607002524183592
165.70000000000198,30.185760386638826,-1.1341084770149725,-0.19705175527113106
166.800000000002,30.29155606599697,-1.131663759513532,-0.1973977841056298
167.90000000000202,30.3964617451715,-1.1304922301719165,-0.19868765338001193
169.00000000000205,30.50056222687005,-1.1283592029801617,-0.19836991974470042
170.10000000000204,30.607529453817584,-1.1231502872333712,-0.19836985978937793
171.20000000000206,30.711220469642306,-1.1222230096446095,-0.19738000962509794
172.3000000000021,30.81657100597524,-1.1212651827740427,-0.1973804788257052
173.40000000000208,30.9176014268991,-1.1187103631611965,-0.19869993581556322
174.5000000000021,31.02551132285658,-1.11651441294937,-0.198661224704602
175.60000000000213,31.130381327262047,-1.1142166882589852,-0.20001990518414825
176.70000000000215,31.235866396486884,-1.1123564376156574,-0.1996881323551163
177.80000000000217,31.339206068478788,-1.1098707833625219,-0.1996901430858502
178.90000000000217,31.44486892115934,-1.106254488623162,-0.20001939186294493
180.0000000000022,31.54990568029974,-1.1064920184318634,-0.20100952559514518
181.1000000000022,31.654148519431256,-1.1036904368263436,-0.19969011111070412
182.2000000000022,31.759266832982014,-1.1029409837182726,-0.20098758961313212
183.30000000000223,31.864199202381858,-1.099371040167659,-0.20001731600683748
184.40000000000225,31.96929377507918,-1.0984261310151084,-0.20199886204698014
185.50000000000227,32.073588909704476,-1.0964835637272996,-0.20123664803204733
186.6000000000023,32.178527010192816,-1.0960644678044487,-0.2019997606997581
187.7000000000023,32.28234088005459,-1.094288981981479,-0.20167019358338312
188.8000000000023,32.387671845150855,-1.093411810359763,-0.20035812451620316
189.90000000000234,32.491969030308056,-1.0923335177171054,-0.20298979946454399
191.00000000000233,32.59662823137248,-1.088919051255028,-0.20429979408254084
192.10000000000235,32.70172757179414,-1.087864638278763,-0.20298944570614896
193.20000000000238,32.80568118065675,-1.086267643469228,-0.20298979199872313
194.3000000000024,32.91089202495796,-1.083188659071052,-0.20299063174587317
195.40000000000242,33.01636116695902,-1.082389423510923,-0.20429842074652438
196.50000000000242,33.1214041547448,-1.0812128517107127,-0.20305953484416062
197.60000000000244,33.22537617035801,-1.0785329733562459,-0.20429979339785476
198.70000000000246,33.330378813815585,-1.0772994226691526,-0.2042997919999996
199.80000000000246,33.43488770313229,-1.0769382479343292,-0.20429979199952175
200.90000000000248,33.53940335106666,-1.0758589408922865,-0.20429987630570778
202.0000000000025,33.643786774387216,-1.0721046017330231,-0.20555827443968866
203.10000000000252,33.74856162582935,-1.0703408863353963,-0.2069397911687627
204.20000000000255,33.85276515119939,-1.0686508057814472,-0.2056308575755903
205.30000000000254,33.95717627389528,-1.0667287196396376,-0.20561795707445718
206.40000000000256,34.06028261726902,-1.0638299588480278,-0.20694076033894948
207.5000000000026,34.166875750611126,-1.0622303204002423,-0.20825022891381284
208.60000000000258,34.27104016886355,-1.060325646951431,-0.20825028738036355
209.7000000000026,34.37575954727818,-1.058450160737117,-0.20745064161903937
210.80000000000263,34.48128211474896,-1.057344489471822,-0.20859012736465665
211.90000000000265,34.58442231840261,-1.0566750526745945,-0.20859012798952392
213.00000000000267,34.68925982070328,-1.0548995403233465,-0.2085865743288533
214.10000000000267,34.794025752803606,-1.0523891350646697,-0.21121006363429995
215.2000000000027,34.8991149026057,-1.0518560211729977,-0.21121006400000564
216.3000000000027,35.00043813125451,-1.0497113324765832,-0.21121006399398734
217.4000000000027,35.1074208066426,-1.0467978485044387,-0.2112134517440465
218.50000000000273,35.211348790747124,-1.0461511648865243,-0.21252885693158596
219.60000000000275,35.315245027127084,-1.0440207729705442,-0.2138463133105013
220.70000000000277,35.419388761813885,-1.042833549690502,-0.2125299200738633
221.8000000000028,35.52497235023004,-1.0415759947983603,-0.21282409581277228
222.9000000000028,35.62896041300897,-1.040333586186171,-0.21429186651474907
224.0000000000028,35.73339352510941,-1.0369168691404456,-0.21246629903525083
225.10000000000284,35.837619402601845,-1.0359693688358231,-0.21659580837118586
226.20000000000283,35.94213758429241,-1.0350792208418267,-0.21736082616605046
227.30000000000285,36.04663497275813,-1.03356346384932,-0.21790148130309728
228.40000000000288,36.15175054777952,-1.0313102270950518,-0.2189018975276893
229.5000000000029,36.256636188442286,-1.03058547469463,-0.22025844417819407
230.60000000000292,36.36051186206047,-1.026981169956289,-0.22054958948866688
231.70000000000292,36.465487490330254,-1.0264191605909554,-0.22121003049935606
232.80000000000294,36.56954819370073,-1.024786003085821,-0.22120988352166293
233.90000000000296,36.67393360149603,-1.022860204216591,-0.22252990326083033
235.00000000000296,36.777157581871144,-1.02146010540474,-0.22383949313996876
236.10000000000298,36.88383471664008,-1.020671167660358,-0.22607870797591278
237.200000000003,36.987856791368806,-1.019862351833489,-0.22615008172338502
238.30000000000302,37.092459865263066,-1.017548718092338,-0.22779797159918758
239.40000000000305,37.19611065363688,-1.0170871825854768,-0.22910776923779252
240.50000000000304,37.30199863155457,-1.0146885981599636,-0.23180892561161848
241.60000000000306,37.40638474679969,-1.013914565616106,-0.2330606026354527
242.7000000000031,37.51188231309682,-1.011195065699921,-0.23372776551036623
243.80000000000308,37.61646587459675,-1.0112314037715566,-0.23696628229698558
244.9000000000031,37.72000088048218,-1.010179913807645,-0.23900255657782488
246.00000000000313,37.82458476157249,-1.0075313187209272,-0.24030987975685036
247.10000000000315,37.92717690172137,-1.0073682981772119,-0.2415248566561088
248.20000000000317,38.03415117539248,-1.0040910225459292,-0.24288300039653876
249.30000000000317,38.138823693353515,-1.0037707887346488,-0.2442627342645478
250.4000000000032,38.24370297437592,-1.0016689419405065,-0.248220983006612
251.5000000000032,38.34734647960061,-1.0000236995170477,-0.24952356717233748
252.6000000000032,38.4517684579733,-1.0001498264054525,-0.25223259675796506
253.70000000000323,38.55732334194869,-0.9983310606862644,-0.256343772100184
254.80000000000325,38.66144144135622,-0.9967069912062742,-0.2589690551589854
255.90000000000327,38.76622851540908,-0.9951257930229145,-0.2608914577482766
257.0000000000033,38.87198276533833,-0.9940482681275743,-0.2650817694245795
258.1000000000033,38.97654051448502,-0.9921696124266207,-0.26682481355133447
259.20000000000334,39.08084618739998,-0.9905330922314686,-0.27056966715373143
260.30000000000337,39.186614463345485,-0.98941287268105,-0.2737894575860427
261.40000000000333,39.290837825094975,-0.9886501936598422,-0.278027234155406
262.50000000000335,39.39669117816205,-0.9876274366306513,-0.2820354640941174
263.6000000000034,39.50094747347055,-0.9854929751146086,-0.2851104631050898
264.7000000000034,39.60502480597753,-0.985240254911292,-0.29028824596138936
265.8000000000034,39.71099976102726,-0.983663693010923,-0.29353740303617126
266.9000000000034,39.81629991702773,-0.9815051899536679,-0.29902915812681385
268.0000000000034,39.920192278375175,-0.9807279123845583,-0.30467654630206376
269.10000000000343,40.025587442300896,-0.9807361690604031,-0.30790547433721915
270.20000000000346,40.13210953255566,-0.9786020214765725,-0.31394632159119595
271.3000000000035,40.236495184597246,-0.9788285971733519,-0.3193626926156661
272.4000000000035,40.34156166287679,-0.976511454684511,-0.3262334736533381
273.5000000000035,40.44661785447635,-0.9760626036054969,-0.33219556858783506
274.60000000000355,40.552177448433156,-0.9745084875599652,-0.33793735314163964
275.70000000000357,40.657195483822086,-0.973337597303158,-0.3434543707710125
276.8000000000036,40.76281698405227,-0.9738450362887878,-0.3512729229365892
277.9000000000036,40.86798914502569,-0.9711044455131155,-0.35673752934618275
279.0000000000036,40.97329262171422,-0.9714434367489173,-0.36347280615690813
280.1000000000036,41.07920309601445,-0.9701272717009476,-0.3715298857951259
281.2000000000036,41.18293243834561,-0.9688815343917853,-0.3809258781023015
282.30000000000365,41.28834511600312,-0.9695616846864025,-0.3884273918790839
283.4000000000037,41.393261406939764,-0.9686836873719793,-0.39706356446953706
284.5000000000037,41.49889530929839,-0.9680700192019194,-0.4054859096923069
285.60000000000366,41.60428557615137,-0.968507013433088,-0.4168535309926291
286.7000000000037,41.70868550181155,-0.9689525983491096,-0.42431082635445705
287.8000000000037,41.81380636791787,-0.9672330849715053,-0.43523336324620043
288.90000000000373,41.92075011718112,-0.9686252191057966,-0.4454712671005474
290.00000000000375,42.02459658721439,-0.9686701082441634,-0.45653061800070116
291.1000000000038,42.13020090440314,-0.9701951958460625,-0.4689016645584241
292.2000000000038,42.23606969923989,-0.9708235802128312,-0.4829647908039867
293.3000000000038,42.34144106443663,-0.9720457522913135,-0.4941181650900228
294.40000000000384,42.44687577444979,-0.9733542212578722,-0.5050381508399173
295.5000000000038,42.5525641597907,-0.9753751183689867,-0.5175001059273798
296.60000000000383,42.65852550959164,-0.9767930898729441,-0.5309230024706135
297.70000000000385,42.76415041131974,-0.9784539065006903,-0.544484192878401
298.8000000000039,42.87034225357065,-0.9803026945550102,-0.5587308241008335
299.9000000000039,42.976294082604895,-0.9811233517698185,-0.5718120300000233
301.0000000000039,43.0821980006607,-0.9840658146301365,-0.5869067575414899
302.10000000000394,43.18709853738383,-0.9829242417787056,-0.6035582521158176
303.2000000000039,43.293934408116016,-0.985442264499721,-0.6198661497951861
304.30000000000393,43.399080401258814,-0.9875944028428019,-0.6374719620819249
305.40000000000396,43.502139538996886,-0.9892970332829436,-0.6529807663474081
306.500000000004,43.61043164397174,-0.992154957039902,-0.6711737954082668
307.600000000004,43.71645725025847,-0.9936873513830902,-0.6900361140035365
308.700000000004,43.82184343554179,-0.9952073908171727,-0.710120186019279
309.80000000000405,43.92747924402257,-0.9983984409159525,-0.7268288227186819
310.90000000000407,44.034650513333204,-0.9996987855068576,-0.7464071476518335
312.0000000000041,44.139248620469125,-1.0026774311963924,-0.7659896748259944
313.10000000000406,44.24539499282418,-1.0052362863433861,-0.786047103499131
314.2000000000041,44.350833478729214,-1.0068798113131454,-0.8077935313239593
315.3000000000041,44.45760992255254,-1.0107924504225343,-0.8312370521709544
316.4000000000041,44.56417092262687,-1.0127799485753868,-0.8532788120604913
317.50000000000415,44.67000000000043,-1.013919999999993,-0.875401189660737
318.6000000000042,44.77684940394485,-1.0176430503324214,-0.9004539859306071
319.7000000000042,44.882829000381264,-1.0213395760467414,-0.923594183055263
320.80000000000416,44.98911958711075,-1.0245692796973296,-0.950811683239773
321.9000000000042,45.09472742984991,-1.027112198562766,-0.9760132651754656
323.0000000000042,45.20075178046031,-1.0311607492539414,-1.001931096083596
324.10000000000423,45.30558091595871,-1.034043547640503,-1.029089188122533
325.20000000000425,45.41367664764509,-1.036204396927503,-1.0594725188579055
326.3000000000043,45.51971264375023,-1.0397829967947956,-1.0860172242486588
327.4000000000043,45.627106138102945,-1.0441150286803242,-1.116318276825345
328.5000000000043,45.733127439350575,-1.0484520027272304,-1.1460308594489357
329.60000000000434,45.83929222886218,-1.0525581474294528,-1.177467427299979
330.7000000000043,45.94644093316061,-1.0577658923308237,-1.2098280386960405
331.80000000000433,46.05269497567615,-1.0642153932839844,-1.2437864834521775
332.90000000000435,46.15950538038937,-1.0685734423281843,-1.2775870967730256
334.0000000000044,46.26551238213971,-1.074382523374849,-1.3132095593172455
335.1000000000044,46.372961336164046,-1.0815879999127025,-1.3488262412819
336.2000000000044,46.47908798179569,-1.087465767888071,-1.3847481072242305
337.30000000000445,46.58586782116117,-1.092903710730945,-1.4240089592708451
338.4000000000044,46.69240769423498,-1.0999285444547722,-1.462110317524032
339.50000000000443,46.799612163436,-1.1095434634037138,-1.5025907741823827
340.60000000000446,46.90634966818297,-1.1154087907582653,-1.5438419453957017
341.7000000000045,47.01375492073288,-1.1229749243832434,-1.5847500644337882
342.8000000000045,47.12017118972835,-1.1291020600481276,-1.628244818383103
343.9000000000045,47.22669947823296,-1.1362162960419855,-1.672373577712678
345.00000000000455,47.33485344029499,-1.1412468564388853,-1.7174411212445428
346.10000000000457,47.44092287996279,-1.1485683761832153,-1.7616673610517553
347.2000000000046,47.54810772402982,-1.1532428453149748,-1.811268654342534
348.30000000000456,47.655389261055234,-1.1581182914875032,-1.8556227286687994
349.4000000000046,47.76228202098351,-1.160683223744293,-1.9044618438071832
350.5000000000046,47.870203711920446,-1.1625007617258178,-1.955555967878615
351.6000000000046,47.97624487968362,-1.1626162948454297,-2.001617639078025
352.70000000000465,48.08275509221573,-1.1614943238184654,-2.052662071501849
353.8000000000047,48.1893370664151,-1.1573935090771148,-2.102807124441303
354.9000000000047,48.296603713014115,-1.1510574731878422,-2.15240788388678
356.00000000000466,48.4028390879348,-1.1408830053252401,-2.199544913741726
357.1000000000047,48.50970976196418,-1.1322912161331122,-2.249424200179179
358.2000000000047,48.614404676538754,-1.1154046187241735,-2.293989182017223
359.30000000000473,48.72091780361171,-1.0998808514274026,-2.3391312663402544
360.40000000000475,48.8270042700279,-1.080373600214897,-2.383643850632401
361.5000000000048,48.933154167806265,-1.0575759163934966,-2.426487265495928
362.6000000000048,49.03801210229976,-1.0356864545939568,-2.463796005199502
363.7000000000048,49.14392555739958,-1.0104630667048629,-2.498003577002753
364.80000000000484,49.24972381906201,-0.9877350285607849,-2.5329368160946366
365.9000000000048,49.35457170834489,-0.9606384983378039,-2.562568189179955
367.00000000000483,49.460282263075925,-0.9346013128733552,-2.5912928746150743
368.10000000000485,49.56612887547495,-0.9107621567968025,-2.616877294565476
369.2000000000049,49.67179335902614,-0.8881431768731736,-2.6403462081946336
370.3000000000049,49.77725979379199,-0.8655993543734033,-2.6594330528717562
371.4000000000049,49.88399683564411,-0.8452767798426984,-2.6773548350204166
372.50000000000495,49.988947869838334,-0.8255475827802541,-2.6941211439961275
373.6000000000049,50.09396682298315,-0.8063216833739475,-2.7106068413752267
374.70000000000493,50.200962447636435,-0.7873838944934237,-2.723479149364633
375.80000000000496,50.306838454220404,-0.7697097069528533,-2.736274136777633
376.900000000005,50.41313623588953,-0.7530545496635177,-2.7467285949817746
378.000000000005,50.51990442778846,-0.739377798847716,-2.75531862429131
379.100000000005,50.62502575024667,-0.7237572543298366,-2.761799760745867
380.20000000000505,50.73173234892185,-0.7114943141303396,-2.768369225390217
381.30000000000507,50.838360970176254,-0.7011876124712729,-2.7748811920376824
382.4000000000051,50.943446975015924,-0.6920238366722886,-2.7819884926716214
383.50000000000506,51.05178831153846,-0.6839135989694503,-2.786822118893275
384.6000000000051,51.15824965314208,-0.6780316006500057,-2.790390962067022
385.7000000000051,51.26548265125813,-0.6733241085881702,-2.79444497074298
386.8000000000051,51.37247006224333,-0.667913495697215,-2.798684694106586
387.90000000000515,51.47945875637767,-0.6646638083041994,-2.8032055710322274
389.0000000000052,51.58610384383423,-0.661790122707045,-2.8060062066208387
390.1000000000052,51.693689010254246,-0.6587839514294559,-2.8092667085228915
391.20000000000516,51.801231598145506,-0.6569251291397957,-2.813204918570483
392.3000000000052,51.90813500118031,-0.6537205172766737,-2.8170623021158754
393.4000000000052,52.016050418217596,-0.6524164568735378,-2.821233370160323
394.50000000000523,52.12343103326845,-0.6480804140253253,-2.82485764324558
395.60000000000525,52.229998967281354,-0.6477001451993322,-2.829110005825877
396.7000000000053,52.33772735442045,-0.6439434384282012,-2.833273386865859
397.8000000000053,52.44573022633299,-0.6409833922404984,-2.8347728022085703
398.9000000000053,52.55325697197051,-0.6391560622994504,-2.840468122754199
400.00000000000534,52.66129650996963,-0.6378673344414558,-2.8426601892536643
401.1000000000053,52.767426465581984,-0.634054609894828,-2.8472445307506966
402.20000000000533,52.874701010444674,-0.6338260740496933,-2.847483779726467
403.30000000000535,52.98244612695815,-0.6306820100498011,-2.850423449097533
404.4000000000054,53.087458373220784,-0.6276296513901772,-2.854492852111573
405.5000000000054,53.19672733700712,-0.626463325783968,-2.8582102972960284
406.6000000000054,53.30502670413436,-0.6257108520363748,-2.8611718107361432
407.70000000000545,53.41270965044645,-0.6244301681271375,-2.8652272899467164
408.8000000000054,53.52000102423037,-0.6236300031500995,-2.868190097613188
409.90000000000543,53.6272534867934,-0.6217373159432749,-2.870860746278286
411.00000000000546,53.735095025433864,-0.6197188380523028,-2.8761984525228756
412.1000000000055,53.842204754105516,-0.6183132192527142,-2.8782776397952436
413.2000000000055,53.951382919577426,-0.6179668501257598,-2.8807575467757576
414.3000000000055,54.05849400100108,-0.614655059226803,-2.8830497219147393
415.40000000000555,54.16696307789954,-0.617172743727751,-2.8869965754963065
416.50000000000557,54.27368263898789,-0.6160692801619134,-2.8896269914292887
417.6000000000056,54.38232013680725,-0.6145052183448441,-2.8919103670660062
418.70000000000556,54.48999904297786,-0.6142399986772591,-2.8959764151425245
419.8000000000056,54.59841185627149,-0.6122778817704698,-2.8993697120781317
420.9000000000056,54.7072477717315,-0.6117467852229627,-2.90140738251716
422.0000000000056,54.81562243176157,-0.6107618293629908,-2.9030927369524844
423.10000000000565,54.92362697896123,-0.610813785216361,-2.9070077632358253
424.2000000000057,55.031540119577116,-0.6098134332482109,-2.910950291597874
425.3000000000057,55.139492329779,-0.6103809853551466,-2.9143234109002814
426.40000000000566,55.24765994102458,-0.6114568396002444,-2.9175945827333805
427.5000000000057,55.35640567675156,-0.6093264328768355,-2.920364893013836
428.6000000000057,55.46384112843999,-0.6086311336396035,-2.9217083269674773
429.70000000000573,55.572350122079655,-0.6091980608625868,-2.924472613972994
430.80000000000575,55.680195529065,-0.6094361345626682,-2.926930094553146
431.9000000000058,55.78890539323261,-0.6092672370461629,-2.92956528095929
433.0000000000058,55.89680773132234,-0.6106692530375065,-2.932182325507496
434.1000000000058,56.00478037485205,-0.6104688520494362,-2.934680519072878
435.20000000000584,56.113327407827015,-0.6104814091077677,-2.937711782875426
436.3000000000058,56.22165484316247,-0.6111690805017911,-2.9412057814182413
437.40000000000583,56.32949777011721,-0.6139053281341914,-2.9438281556211163
438.50000000000585,56.43872723904309,-0.6148142691044501,-2.945153279575169
439.6000000000059,56.54639600693914,-0.6138211579711017,-2.9478183053035076
440.7000000000059,56.65538356507737,-0.6136408122497062,-2.9505207911288487
441.8000000000059,56.764976096597444,-0.6162721824708027,-2.954712295760245
442.90000000000595,56.87237758290629,-0.6151227789802438,-2.9560321569500334
444.0000000000059,56.982226619021034,-0.6151267898949392,-2.958756017649729
445.10000000000593,57.09029975196339,-0.6168691891371428,-2.961066934242333
446.20000000000596,57.19941677976581,-0.6160937454720387,-2.963692330844399
447.300000000006,57.30837849246918,-0.6166269940543572,-2.964953130178391
448.400000000006,57.415963899812354,-0.6172588852485213,-2.9676590160393372
449.500000000006,57.52560489403644,-0.6168338002159383,-2.9688689054061754
450.60000000000605,57.63495194232482,-0.6179966518901456,-2.970204633983072
451.70000000000607,57.74309733700183,-0.6180882676372612,-2.973066506036959
452.8000000000061,57.851428862668925,-0.6197894879626982,-2.975554778363324
453.90000000000606,57.96085910030057,-0.6198110205914289,-2.9780931256041243
455.0000000000061,58.069425958857806,-0.620975089442314,-2.9808376462736286
456.1000000000061,58.178438101103,-0.6222986269496151,-2.9835116452977064
457.2000000000061,58.28641396847847,-0.6221938878900903,-2.9847794702198716
458.30000000000615,58.3958480284304,-0.6254071902355283,-2.9861445740377315
459.4000000000062,58.50547267185138,-0.6260291069312309,-2.987747169507542
460.5000000000062,58.61351793362259,-0.6242750396311297,-2.990252102114484
461.60000000000616,58.72208740716721,-0.6274630426732757,-2.9923584135741055
462.7000000000062,58.83198514418754,-0.6277767029512966,-2.9949714425292826
463.8000000000062,58.93933729395688,-0.6282931215829192,-2.9959254338533654
464.90000000000623,59.04892068431608,-0.62892298105942,-2.997627843697977
466.00000000000625,59.15839787572075,-0.6282902278881741,-2.9989483240542265
467.1000000000063,59.26740844080199,-0.6299608037094484,-3.0028983829562743
468.2000000000063,59.37453398239045,-0.6279660083236617,-3.003723292580778
469.3000000000063,59.48549883314019,-0.6288751041580782,-3.006841756052295
470.40000000000634,59.59531256197911,-0.6280234505979879,-3.0081559423894992
471.5000000000063,59.70300838725264,-0.6309763655324077,-3.0094816338615136
472.60000000000633,59.81229043952092,-0.6313267297561537,-3.0118083781426463
473.70000000000636,59.921989039572814,-0.630563603549184,-3.013090051496283
474.8000000000064,60.030000964857756,-0.6327900039799919,-3.015739867253772
475.9000000000064,60.13945019293325,-0.6326022088509,-3.0168382590522542
477.0000000000064,60.24877518544371,-0.6319350029612616,-3.018035396050732
478.10000000000645,60.35841744447002,-0.6324114969590648,-3.018041484632844
479.2000000000064,60.46709341533227,-0.6322196267494804,-3.020662890440141
480.30000000000643,60.57637788598496,-0.6348056248287672,-3.022029905162716
481.40000000000646,60.68507051659039,-0.6403631507845039,-3.023540026817869
482.5000000000065,60.79670358814867,-0.644124195748355,-3.0259548464133434
483.6000000000065,60.905351649099835,-0.645314456780175,-3.0272687872449024
484.7000000000065,61.01388477910601,-0.6488190910409991,-3.0276226232558803
485.80000000000655,61.12348372565726,-0.6492170108896944,-3.030237988477983
486.90000000000657,61.23357665340427,-0.651866743556555,-3.032498126322639
488.0000000000066,61.34242193433761,-0.6539124600591102,-3.0331886718641963
489.10000000000656,61.451313256430964,-0.6552581948677136,-3.034190069214602
490.2000000000066,61.560849267368866,-0.6582921250256025,-3.0365421870188243
491.3000000000066,61.669461019334676,-0.6595079498457628,-3.035846719162217
492.4000000000066,61.777496057140596,-0.6601596414961666,-3.038920998826762
493.50000000000665,61.8889950677843,-0.6635100520268321,-3.0411106170256215
494.6000000000067,61.99816992148347,-0.6651879129504984,-3.041110233367763
495.7000000000067,62.10697488329416,-0.6654259083453579,-3.042427889552819
496.80000000000666,62.216574585896055,-0.6674932606665269,-3.0450597052791464
497.9000000000067,62.32633233805463,-0.6701733244597761,-3.0463799981272506
499.0000000000067,62.435665638143156,-0.6708119618370914,-3.048816019706873
500.10000000000673,62.545015465839306,-0.6732226038686663,-3.0498513052667224
501.20000000000675,62.65391023927126,-0.6713663606397307,-3.048964322375423
502.3000000000068,62.76366697199138,-0.672645310077737,-3.0511243051096724
503.4000000000068,62.87357062298063,-0.6749211632189718,-3.0516453138929345
504.5000000000068,62.9838604026076,-0.67396059777108,-3.0518525617920425
505.60000000000684,63.092271538344484,-0.6731508755112988,-3.0558982446491245
506.7000000000068,63.20133516423252,-0.6729153711514395,-3.055607851407589
507.80000000000683,63.312156557223545,-0.6749477824701027,-3.05659262434353
508.90000000000686,63.42127859379996,-0.6756588741962167,-3.058348244568549
510.0000000000069,63.53082047132865,-0.6738449228472202,-3.059218195300142
511.1000000000069,63.639999048507775,-0.6749697650592721,-3.059549804612307
512.2000000000069,63.749998959385394,-0.6744201622736015,-3.0608597695795625
513.300000000007,63.859280492801965,-0.6750079584191628,-3.0621799315382807
514.4000000000069,63.96908589713929,-0.6741022510809965,-3.0644119723137857
515.5000000000069,64.07917053538611,-0.6765701255473977,-3.064827013672726
516.600000000007,64.18874138267297,-0.6771679663546195,-3.066098229931192
517.700000000007,64.29869074142137,-0.6771257906049009,-3.0661304971089716
518.800000000007,64.40822986497434,-0.6792653375772484,-3.0674805532888128
519.900000000007,64.51843853276111,-0.6780003610284642,-3.0700864272206356
521.000000000007,64.62915476867889,-0.6786064991968694,-3.070228022527134
522.1000000000071,64.73793937458395,-0.6767202862118209,-3.071399739362527
523.2000000000071,64.8487720302301,-0.6763650372291555,-3.0737103671287853
524.300000000007,64.95869796502117,-0.6777918687003013,-3.073097270343873
525.4000000000071,65.06762980142548,-0.6751516699041896,-3.073711489879578
526.500000000007,65.17822689088224,-0.6744531073525248,-3.0759318661293777
527.6000000000072,65.2886526138344,-0.6708510511384401,-3.0773308103745247
528.7000000000071,65.39946061443469,-0.6708827340804042,-3.0770095683853986
529.8000000000072,65.50892955046383,-0.6684188534264394,-3.077329398982693
530.9000000000071,65.61843228607871,-0.6666220832498383,-3.0799609821340708
532.0000000000072,65.72811042034083,-0.6669116947997724,-3.0799668959901645
533.1000000000072,65.83825338332625,-0.667875588311968,-3.0812843221772743
534.2000000000072,65.9476500060571,-0.6655394448396232,-3.0839661036643595
535.3000000000072,66.05702301130037,-0.6624449757327299,-3.0841350222298907
536.4000000000073,66.1677930421303,-0.6610643100265404,-3.085532855684141
537.5000000000073,66.277119321647,-0.6600177724594759,-3.0842774594881215
538.6000000000073,66.38765251280448,-0.6588170635030218,-3.085519736909448
539.7000000000073,66.4970189402837,-0.6560704734511446,-3.0868799223723133
540.8000000000073,66.60706912549573,-0.6557556454165123,-3.0872091561903705
541.9000000000074,66.71554962205309,-0.6539388086633234,-3.0884590570256365
543.0000000000074,66.82648205370525,-0.6535547970730363,-3.0885301328092947
544.1000000000074,66.93660380398023,-0.6520294768507222,-3.0900487988124503
545.2000000000073,67.04596671682215,-0.6487456070760849,-3.090831244746246
546.3000000000073,67.15683336233538,-0.6460480934876995,-3.0920452908245206
547.4000000000074,67.2676158706129,-0.6444556140360719,-3.0923210365994103
548.5000000000074,67.3769904535717,-0.6423382141177258,-3.0934328684343795
549.6000000000074,67.48664764918051,-0.6408622087209404,-3.096109968286007
550.7000000000074,67.59759635342444,-0.640299592293202,-3.0974218321401232
551.8000000000075,67.70663323567715,-0.636794533863545,-3.097417280041476
552.9000000000075,67.81737445338243,-0.6341117274399927,-3.098743201666385
554.0000000000075,67.92831731909853,-0.6334288852603756,-3.100720719814851
555.1000000000075,68.03759135048246,-0.6319033267251786,-3.1007219120039835
556.2000000000075,68.1483948448545,-0.6306491533048161,-3.10203910700489
557.3000000000076,68.25890482222121,-0.6295557552651802,-3.103349527746528
558.4000000000076,68.36966746214809,-0.6270232232196363,-3.104658470189575
559.5000000000076,68.4800000000008,-0.6253400000000626,-3.104670127999641
560.6000000000076,68.5907171349738,-0.6246009968934885,-3.1059899847551278
561.7000000000077,68.70125833911158,-0.6242739931466108,-3.105036048571017
562.8000000000077,68.81210851997388,-0.6189742031972383,-3.105959844857164
563.9000000000076,68.92192790111127,-0.6201409892647938,-3.1059976911326386
565.0000000000076,69.03249610414382,-0.6189421257144948,-3.1073101381577715
566.1000000000076,69.14246651889793,-0.6183346083032334,-3.109936221432372
567.2000000000077,69.25265594307486,-0.6189034759790205,-3.109286001961532
568.3000000000077,69.36391163151865,-0.6197338850702069,-3.1092885360903404
569.4000000000077,69.47391892562837,-0.617253661445237,-3.1119090977340447
570.5000000000077,69.58500917695149,-0.6149147693411451,-3.1118179838760573
571.6000000000078,69.69512023046937,-0.6149133550404163,-3.1118817896480655
572.7000000000078,69.80612417036772,-0.6143345911071696,-3.113208021561066
573.8000000000078,69.9163720657626,-0.6126310958937069,-3.113560292217617
574.9000000000078,70.02698661432976,-0.6109152831209086,-3.1158704191743993
576.0000000000078,70.13838213179164,-0.6112443841568884,-3.1168674647418038
577.1000000000079,70.24861103090757,-0.6099085363331933,-3.116203356233421
578.2000000000079,70.35832049860997,-0.6111859054207732,-3.1177724293494022
579.3000000000079,70.46972224819987,-0.6103280438949852,-3.1188302160864256
580.4000000000078,70.58048512858356,-0.6088910594267076,-3.118830139731054
581.5000000000078,70.69124605010747,-0.6101932177026437,-3.1198034092441698
582.6000000000079,70.8017334657442,-0.6072988375604274,-3.119820084958171
583.7000000000079,70.91192785983617,-0.6121758994919971,-3.121141313956416
584.8000000000079,71.02338943350927,-0.6096420873670383,-3.12178991454296
585.9000000000079,71.13382219995853,-0.6122436682964059,-3.123118699456445
587.000000000008,71.24527068073195,-0.6124199191879107,-3.1231032597401125
588.100000000008,71.35605112753095,-0.612479646721735,-3.1244351468912694
589.200000000008,71.46750672941823,-0.6160986919270788,-3.1250928343961033
590.300000000008,71.57788712501561,-0.6184230211248849,-3.124458140671162
591.400000000008,71.68868595680131,-0.6175384267286008,-3.1246802581267614
592.5000000000081,71.8000000000008,-0.6198699999998576,-3.127720240036073
593.6000000000081,71.90887686931956,-0.6186177958839907,-3.127732308850444
594.7000000000081,72.0222047646234,-0.6178625522727436,-3.127453241160839
595.8000000000081,72.13329171191475,-0.6214918301713439,-3.1279916196612634
596.9000000000082,72.24558420167406,-0.6223338623602473,-3.1290399504146786
598.0000000000082,72.3538313437364,-0.6233074486745027,-3.130380170317548
599.1000000000081,72.46811980787659,-0.6240203100959367,-3.1304250933927866
600.2000000000081,72.57813823798509,-0.6261009341745802,-3.131004555998186
601.3000000000081,72.69021885282177,-0.6271044196057937,-3.132352801509894
602.4000000000082,72.80010090214833,-0.6276638479295331,-3.1323384371385803
603.5000000000082,72.91173830290589,-0.6295260787990264,-3.1336626075712806
604.6000000000082,73.02287201673703,-0.6304924488218825,-3.133650047468712
605.7000000000082,73.13399087550546,-0.6296466165818178,-3.133650089626662
606.8000000000083,73.24498913345397,-0.6323233538223506,-3.135245936377002
607.9000000000083,73.3561922035914,-0.6336434184409874,-3.1358794847131617
609.0000000000083,73.4670784993506,-0.6346422366479975,-3.1366401011880596
610.1000000000083,73.57732424306057,-0.6356601262364799,-3.1373495280410983
611.2000000000083,73.68838811372609,-0.6390436219579421,-3.1371275160541288
612.3000000000084,73.80146955814399,-0.6400446053170191,-3.137599888268469
613.4000000000084,73.9123351845095,-0.6413819301976753,-3.138858448068385
614.5000000000084,74.02293857308081,-0.6447098969025937,-3.140059472449013
615.6000000000083,74.13219141255989,-0.6442773587053555,-3.140240122725337
616.7000000000083,74.24512186141921,-0.6473662328483765,-3.1402519030449807
617.8000000000084,74.35664707795532,-0.6483667527881845,-3.1425572055276136
618.9000000000084,74.46738843509861,-0.6492754899746741,-3.1437706606899964
620.0000000000084,74.57910817690471,-0.6511617930351367,-3.143860797074999
621.1000000000084,74.69070352231141,-0.6530660910442417,-3.1438859934539902
622.2000000000085,74.8021519022121,-0.6576937813214152,-3.1438694489709307
623.3000000000085,74.91303713143817,-0.6614105317467516,-3.145170011800997
624.4000000000085,75.02408695612554,-0.6613993648187557,-3.1464907274780725
625.5000000000085,75.13637526143476,-0.6638713955222395,-3.147490313759029
626.6000000000085,75.24766401799612,-0.6664218887205978,-3.148951608628435
627.7000000000086,75.3586832827593,-0.6689007113224047,-3.1484684004002323
628.8000000000086,75.47010182621716,-0.6733173614260052,-3.1478148572514417
629.9000000000086,75.58115949644487,-0.6728400149162976,-3.151226211944647
631.0000000000086,75.69252119336981,-0.6750879222786801,-3.150449576132079
632.1000000000087,75.8038789675712,-0.6785835976945296,-3.151769482405132
633.2000000000087,75.91549114244384,-0.6808987057670604,-3.1530886843640973
634.3000000000086,76.02611252288771,-0.6824301026119449,-3.155710453824672
635.4000000000086,76.13677403664222,-0.6863532141459963,-3.1557110456980118
636.5000000000086,76.24892175830293,-0.6886096405623758,-3.1570956779523534
637.6000000000087,76.3600022438499,-0.6924698857140984,-3.15572024270431
638.7000000000087,76.47174926153535,-0.6926631153818498,-3.1577696158628754
639.8000000000087,76.58412362067571,-0.6966080188269085,-3.1590402262382575
640.9000000000087,76.69462142030596,-0.6971814682260343,-3.1609880237301446
642.0000000000088,76.80617968199918,-0.6986970904272207,-3.159613340892043
643.1000000000088,76.91854492839683,-0.6982169113910791,-3.1630686763125286
644.2000000000088,77.02960391582977,-0.6990411550163482,-3.163303380604753
645.3000000000088,77.14145977038065,-0.6986108330319867,-3.1643839108242013
646.4000000000088,77.25363266969795,-0.7008669454381168,-3.165605632972621
647.5000000000089,77.3649654423252,-0.7005964698495248,-3.1663726205018476
648.6000000000089,77.47693088830374,-0.7005854158739123,-3.1672485218751554
649.7000000000089,77.58828456555648,-0.7016261882486894,-3.1685600315876092
650.8000000000088,77.69968650858348,-0.6993552544513815,-3.169879789968085
651.9000000000088,77.81115567530864,-0.6990853910156689,-3.1703159825696616
653.0000000000089,77.92329330603901,-0.6968735722571321,-3.1725206550649414
654.1000000000089,78.0353727160136,-0.6930118061818579,-3.1713367022703336
655.2000000000089,78.1470399905533,-0.6927467309451324,-3.172512863117861
656.3000000000089,78.2569528668582,-0.6913066132097356,-3.172509685328011
657.400000000009,78.36955605839393,-0.6880136631992555,-3.1738328538059832
658.500000000009,78.48197824068885,-0.6866796600609049,-3.1751502733769796
659.600000000009,78.59276912227318,-0.6850112221522513,-3.1757567456715607
660.700000000009,78.70410932220493,-0.683380901817556,-3.1777950352790993
661.800000000009,78.81565332845976,-0.6795888334704386,-3.176459494741759
662.9000000000091,78.92636274657717,-0.6769666626048186,-3.177779917464081
664.0000000000091,79.03918753545959,-0.6732714006140225,-3.1780432536260657
665.1000000000091,79.15146462929494,-0.6722627869747995,-3.178962855242088
666.2000000000091,79.26282454950224,-0.6692269803826476,-3.180093737107525
667.3000000000092,79.37487585815558,-0.6705984174602057,-3.1814087666229156
668.4000000000092,79.48723651485707,-0.6691346975756359,-3.180423050667894
669.5000000000091,79.59935827259402,-0.6690713671026037,-3.181712242303405
670.6000000000091,79.71068628798206,-0.6684482676932988,-3.180419016941307
671.7000000000091,79.82390998445246,-0.6706591034399793,-3.181721924229473
672.8000000000092,79.93558929946042,-0.6719375168148835,-3.1824002397483997
673.9000000000092,80.048035237702,-0.675259905856933,-3.1843800330023915
675.0000000000092,80.15979835829951,-0.6735156062345916,-3.184370012570764
676.1000000000092,80.27217641971235,-0.6726369858496152,-3.184370529422583
677.2000000000093,80.38409143943387,-0.6761577947218701,-3.184037273886161
678.3000000000093,80.49618375348919,-0.6781335757692645,-3.1840405431777046
679.4000000000093,80.60834836290563,-0.6794766563776781,-3.1856852547292167
680.5000000000093,80.72153517328978,-0.6814608608853088,-3.187009369732725
681.6000000000093,80.83283095414825,-0.6807883460513615,-3.186016528743912
682.7000000000094,80.94474062352889,-0.682047200615662,-3.1873400830512644
683.8000000000094,81.05600622326752,-0.6835912000185476,-3.187339811585913
684.9000000000094,81.16944617875282,-0.6839392144373341,-3.188645373578966
686.0000000000093,81.28095330872759,-0.6875393220408941,-3.188325107220897
687.1000000000093,81.3940617279414,-0.6903825722775058,-3.1883087102181253
688.2000000000094,81.50583697565835,-0.6900892066643852,-3.189651654213581
689.3000000000094,81.61602110648712,-0.6942803740151046,-3.188330199346911
690.4000000000094,81.72979564193511,-0.6950651975256178,-3.1883302240000093
691.5000000000094,81.84221593829392,-0.6951838949767056,-3.188330631724156
692.6000000000095,81.95446808489265,-0.6982731930761845,-3.190660286485639
693.7000000000095,82.06595464936413,-0.6990241038679792,-3.190623365061343
694.8000000000095,82.17851555853969,-0.6998524967507144,-3.191940016252733
695.9000000000095,82.29120888502814,-0.7023025442281251,-3.192555303841901
697.0000000000095,82.40329083902105,-0.7034894971067704,-3.1919498722080784
698.1000000000096,82.51505014012572,-0.7065264659443401,-3.1930150080253084
699.2000000000096,82.62747462039779,-0.707628183989029,-3.1932702224484872
700.3000000000096,82.74037282189403,-0.7086210833937325,-3.19396623277101
701.4000000000096,82.85260601455617,-0.7100469778268141,-3.1932587564713693
702.5000000000097,82.96438235756716,-0.7125079268275624,-3.193646696991309
703.6000000000097,83.07657482739361,-0.7134399961404018,-3.194531209708853
704.7000000000096,83.18812893398848,-0.7149565036239488,-3.1968898967774066
705.8000000000096,83.30057019825384,-0.7153921505065837,-3.1975990553844857
706.9000000000096,83.41349790167685,-0.7159941933846633,-3.1968902592009516
708.0000000000097,83.52564497179279,-0.7135933905586513,-3.1955697475305573
709.1000000000097,83.6361040559804,-0.7177179160692606,-3.1968803667904897
710.2000000000097,83.75007656889976,-0.7178430557848946,-3.1981694318332714
711.3000000000097,83.8625372518388,-0.7184433109882673,-3.198784128743007
712.4000000000098,83.97513820301819,-0.7189456252359483,-3.1985109138638625
713.5000000000098,84.08706791014494,-0.721509430908171,-3.198483340381255
714.6000000000098,84.19871929903718,-0.7221199730217698,-3.1998451793738862
715.7000000000098,84.31182229731202,-0.7252364711398465,-3.201170235108999
716.8000000000098,84.42167863117349,-0.7258519496686686,-3.1998475889861737
717.9000000000099,84.53617135603609,-0.7308962117872898,-3.201201751700104
719.0000000000099,84.64882935767727,-0.7294803398072449,-3.2021501676992576
720.1000000000099,84.76103159221866,-0.7313424079788924,-3.200811573164522
721.2000000000098,84.87210598183671,-0.735702074311203,-3.202146383511497
722.3000000000098,84.9856655056183,-0.7386746290144819,-3.203469874104802
723.4000000000099,85.09866622761515,-0.7416024490177192,-3.2034698713875454
724.5000000000099,85.21054878519934,-0.743317526033756,-3.202153123970362
725.6000000000099,85.32415793823144,-0.7435601089649492,-3.2021598725526212
726.7000000000099,85.43681988159643,-0.7468330399959505,-3.203444045802253
727.80000000001,85.55000096906723,-0.7504699548700208,-3.2034802778818374
728.90000000001,85.66228646924658,-0.7505697231456597,-3.2047901599282613
730.00000000001,85.77563187760921,-0.7472002034048809,-3.204790170731477
731.10000000001,85.88837607036112,-0.7507722716993004,-3.206109575254045
732.20000000001,86.00144931903762,-0.7527030770554733,-3.2061100168127914
733.3000000000101,86.11119565086818,-0.7538262404683549,-3.2064673663769443
734.4000000000101,86.22607181310455,-0.756862371481762,-3.2074288240454734
735.5000000000101,86.33856118605347,-0.7572691281810848,-3.207100031375992
736.6000000000101,86.45114444283017,-0.7592666208342138,-3.2074234031454174
737.7000000000102,86.56438412552885,-0.7625080809503938,-3.208788876119903
738.8000000000102,86.6773081730379,-0.7682341836940104,-3.207422574662575
739.9000000000101,86.78980190029849,-0.7710766709307386,-3.208742411930322
741.0000000000101,86.90187632725025,-0.7733280068069336,-3.2093984617921683
742.1000000000101,87.01466653951962,-0.7741735826665865,-3.2086264776839606
743.2000000000102,87.1276274629997,-0.7756752828976401,-3.2099001090517185
744.3000000000102,87.24126969518575,-0.7780815232225075,-3.209289876112483
745.4000000000102,87.35291015927518,-0.7810504643969951,-3.2106115710980196
746.0000000000102,87.41560515302051,-0.7833177791440792,-3.211926828023273