File: 01_Data/Cardboard/STA/N2/10K_min/Cardboard_STA_N2_10KData_230816_R3.csv
##Temp./Â°C,Time/min,DSC/(mW/mg),Mass loss/mg
28.0,15.654548080202533,-2.4314099487030543,-0.10203085272489476
29.100000000000016,16.036652133263384,-2.3659562898497657,-0.10400299240115318
30.20000000000003,16.266945306656943,-2.330760131392605,-0.1055325324456553
31.300000000000047,16.457948231115342,-2.3078840334194215,-0.10970893998183673
32.40000000000006,16.62160062742058,-2.2903618176877547,-0.10827853845274227
33.50000000000008,16.778084094328193,-2.276129019649337,-0.10976518192680862
34.600000000000094,16.922838927580916,-2.267837437724773,-0.11000389902958752
35.70000000000011,17.062176944688467,-2.259831462822807,-0.11260874796194864
36.800000000000125,17.198805012971995,-2.255148685688213,-0.11341596183213776
37.90000000000014,17.329663157346882,-2.2518386069707885,-0.11373984526973846
39.000000000000156,17.45811092530568,-2.248249210828999,-0.11411359668502952
40.10000000000017,17.58659102008742,-2.2473540436020616,-0.11528511822016574
41.20000000000019,17.71213044199038,-2.24764523156591,-0.11647402912276039
42.3000000000002,17.836580867340526,-2.2482031873920665,-0.11779352578534397
43.40000000000022,17.96021229623333,-2.2483613290643896,-0.12040801854548944
44.500000000000234,18.082723698006024,-2.2504185867226276,-0.12196164410642352
45.60000000000025,18.205703304271587,-2.2524186003553246,-0.12255691614016007
46.700000000000266,18.32558442333915,-2.2543500462996158,-0.1231737215319213
47.80000000000028,18.447650782961237,-2.258539642985877,-0.1252906558957383
48.9000000000003,18.568201479744474,-2.2601684339400077,-0.1277230306512207
50.00000000000031,18.68754978804026,-2.2611371014957418,-0.1306783457511913
51.10000000000033,18.8058814721138,-2.2651405547121857,-0.13239915713486683
52.200000000000344,18.922168975910985,-2.266650676373306,-0.13372004344652444
53.30000000000036,19.039812678519198,-2.2695821010776713,-0.13504157411657536
54.400000000000375,19.157781830319777,-2.2711474435541055,-0.13765988849908695
55.50000000000039,19.274980676237213,-2.2724276401887424,-0.1389801998187532
56.600000000000406,19.38917000000005,-2.272720000000001,-0.14161220967050658
57.70000000000042,19.505716928006134,-2.2736516480076387,-0.14426117852041953
58.80000000000044,19.619634699611662,-2.273376657767348,-0.1468875320245182
59.90000000000045,19.733108498486956,-2.272002759357639,-0.14949016863849307
61.00000000000047,19.845628203282164,-2.2699545658285123,-0.15183030889514448
62.100000000000485,19.95791196943396,-2.2684275596913253,-0.15479426327883639
63.2000000000005,20.06870534869007,-2.2650037380784425,-0.15742962103919433
64.30000000000052,20.183505937848967,-2.2623491085121943,-0.16008465000000704
65.40000000000053,20.29585086932917,-2.2583845178471478,-0.16147110751710558
66.50000000000054,20.406597224166823,-2.253916489141996,-0.16508582748006662
67.60000000000056,20.516976428857387,-2.247386152865179,-0.16796326452443022
68.70000000000059,20.627882301137756,-2.241240765857438,-0.16928025476939412
69.8000000000006,20.73829933403867,-2.234352607368458,-0.17084402445012126
70.9000000000006,20.848785828487475,-2.226626270992563,-0.1726233854243282
72.00000000000063,20.95873538396978,-2.219598560624968,-0.17583541792188262
73.10000000000065,21.067531222917065,-2.209345679137424,-0.178495618970262
74.20000000000066,21.17849923414017,-2.199879284145895,-0.1814696628557977
75.30000000000067,21.28775722153209,-2.1920051784684933,-0.18377998727161593
76.40000000000069,21.39753139397138,-2.1793047307556144,-0.18641967393462
77.50000000000071,21.504116418507525,-2.1695280084056443,-0.18773199201456547
78.60000000000072,21.61360534048759,-2.158055467873909,-0.1891530106975483
79.70000000000073,21.722426583501296,-2.146256478664384,-0.19167821079740577
80.80000000000075,21.83108862070865,-2.1323292413904276,-0.19431090686645236
81.90000000000077,21.940989887468675,-2.1212939971137033,-0.19696039496880724
83.00000000000078,22.047615556023576,-2.106857066506632,-0.19881322718723693
84.10000000000079,22.156634685098574,-2.095857458857946,-0.20094766273718134
85.20000000000081,22.264630617015186,-2.080584559430945,-0.20222007390397945
86.30000000000084,22.37197025391288,-2.067708015905299,-0.2035242390231402
87.40000000000084,22.4796930484925,-2.053551459494516,-0.20623813655932066
88.50000000000085,22.58704668813174,-2.041129295329273,-0.20616993630045322
89.60000000000088,22.69485821798751,-2.0270474959035756,-0.2088129651275481
90.7000000000009,22.803069996847693,-2.0130999607640505,-0.20878469961802493
91.8000000000009,22.910396699553868,-1.9991746664789005,-0.21112677755510978
92.90000000000092,23.016510315763224,-1.9864194985723838,-0.21254909263434563
94.00000000000094,23.123114635361105,-1.971685553556049,-0.21406973997240764
95.10000000000096,23.23004327418686,-1.9605991294341125,-0.21476164538715237
96.20000000000097,23.337090149228345,-1.9468036399931954,-0.21604983099626907
97.30000000000098,23.442602969536246,-1.9338067668197318,-0.21671505435054117
98.400000000001,23.549261900770503,-1.9217305441021257,-0.2180297659721897
99.50000000000102,23.655195120607075,-1.908907877876288,-0.21802931714681728
100.60000000000103,23.763274474264318,-1.8962585665000127,-0.22066051736995274
101.70000000000104,23.869073765544552,-1.8829448288983823,-0.2219797487883155
102.80000000000106,23.97568364019416,-1.8710261133060129,-0.22197985173782975
103.90000000000109,24.08161674172265,-1.8604730821059838,-0.2210128363454893
105.0000000000011,24.188197563220367,-1.848479800507072,-0.2223098466018616
106.1000000000011,24.293163023783055,-1.8367217792257073,-0.22362975472141944
107.20000000000113,24.400137827498853,-1.8278402200992716,-0.2236298369986902
108.30000000000115,24.504834322083255,-1.8170779769175147,-0.2236298105403023
109.40000000000116,24.612762693814847,-1.8080897218327374,-0.22494087048286593
110.50000000000117,24.719374716862404,-1.7972859970994213,-0.22559984113031817
111.60000000000119,24.82511288190901,-1.7874375537092058,-0.22692368352400516
112.70000000000121,24.92964269984521,-1.777406215271245,-0.22667810208291872
113.80000000000122,25.036922323388254,-1.769634453753332,-0.22691940506012198
114.90000000000123,25.143832821296424,-1.7627376273158717,-0.22823982410929045
116.00000000000125,25.24870803508093,-1.753478009284992,-0.22823982900063733
117.10000000000127,25.352958715947565,-1.74691519777533,-0.22747500841042134
118.20000000000128,25.46013768680225,-1.7391526259807029,-0.22823689429057126
119.30000000000129,25.566461792124702,-1.7324574543268627,-0.2282298129116791
120.40000000000131,25.672765303773385,-1.7257488628310995,-0.2276414105412119
121.50000000000134,25.77807997024173,-1.7190982884224408,-0.228563620843782
122.60000000000134,25.884652676797316,-1.7137581288433594,-0.22971413593595624
123.70000000000135,25.990181647108546,-1.7065563389277887,-0.2295599630409968
124.80000000000138,26.096555509738153,-1.7008281024284688,-0.22952465151476842
125.9000000000014,26.20246272993014,-1.6948845399478696,-0.22955994569601046
127.0000000000014,26.30946651581843,-1.688991111928825,-0.2295599467874112
128.10000000000142,26.41452939227868,-1.6856504595126143,-0.22966075730821878
129.20000000000144,26.52189817571814,-1.6813136107660829,-0.22954992883684433
130.30000000000146,26.627208888401235,-1.6754050976352686,-0.2308744856333309
131.40000000000146,26.732767008285627,-1.670473360118555,-0.2308699439543953
132.50000000000148,26.833745209840664,-1.6671873770055434,-0.22955780817863403
133.6000000000015,26.944315270915677,-1.6604620147721523,-0.2308744193041936
134.70000000000152,27.047662577567895,-1.6566597835203498,-0.2304925095645105
135.80000000000155,27.154916166731436,-1.6532798213007278,-0.23090977698488313
136.90000000000154,27.260287414911996,-1.6509693766755973,-0.22949657639578103
138.00000000000156,27.365065525811325,-1.6455674976216401,-0.2308800663836812
139.1000000000016,27.47154890885699,-1.6420728855391256,-0.23088006499985747
140.20000000000158,27.576999814316785,-1.6385720012904632,-0.2308799407204054
141.3000000000016,27.681375077585717,-1.6343509769145435,-0.23088046651943683
142.40000000000163,27.786680760916447,-1.6313192960879925,-0.23087004898331376
143.50000000000165,27.892951176116938,-1.6286357092152388,-0.23086982201672468
144.60000000000167,27.997719210852804,-1.6256734557741248,-0.23218998183944617
145.70000000000167,28.10386372233772,-1.6234256090755987,-0.23219343868593434
146.8000000000017,28.209346286009705,-1.619116696062421,-0.2308700309934424
147.9000000000017,28.312075782225758,-1.616286253402481,-0.23088818572538194
149.0000000000017,28.418666906112122,-1.6119572050123223,-0.23120008428731698
150.10000000000173,28.523829430727893,-1.6095770816299453,-0.2312000179111524
151.20000000000175,28.629344241234293,-1.605880172878029,-0.2314342031901182
152.30000000000177,28.735182079168418,-1.6023031811555462,-0.2322001764307693
153.4000000000018,28.839675963558363,-1.6002137262323086,-0.23350764729776863
154.5000000000018,28.944939710316646,-1.5982470087323342,-0.2315715971223078
155.6000000000018,29.049539070578742,-1.5935061054960133,-0.23120013977588094
156.70000000000184,29.153625769538714,-1.590782882000629,-0.23249117361158733
157.80000000000183,29.25942007270821,-1.5879115868307052,-0.23120014523872268
158.90000000000185,29.364443966500048,-1.584285813420532,-0.23218877905456514
160.00000000000188,29.468897372453576,-1.5838962001291188,-0.23218936283721892
161.1000000000019,29.575024439548578,-1.5796215495562604,-0.23252014885616967
162.20000000000192,29.6792515991065,-1.5770154145746225,-0.23252157492379144
163.30000000000192,29.78388020993077,-1.5747034748416677,-0.23245887975630053
164.40000000000194,29.889662955488717,-1.5717061788782762,-0.2325387336649385
165.50000000000196,29.990347249090842,-1.5693002384008086,-0.2335101471809069
166.60000000000196,30.096951302368566,-1.5661448170641543,-0.2335144275788985
167.70000000000198,30.20293311180857,-1.5624109038066134,-0.23350001001081688
168.800000000002,30.307072702442333,-1.5611798764773923,-0.23350013097404299
169.90000000000202,30.41257082179288,-1.5588434033839111,-0.23432930151872755
171.00000000000205,30.51917000000021,-1.556479999999995,-0.23416989801931187
172.10000000000204,30.624590515461197,-1.5540705895465847,-0.23350953559302834
173.20000000000206,30.729068206740838,-1.5518282996172115,-0.233509889999989
174.3000000000021,30.834772831390783,-1.5495633753440465,-0.2335098834138276
175.40000000000208,30.93841482257423,-1.546250911749719,-0.23449743608505713
176.5000000000021,31.04271150122732,-1.5458102432463927,-0.23449989000644322
177.60000000000213,31.14836669563408,-1.5412990299763445,-0.23450013063081876
178.70000000000215,31.254069903529484,-1.5403936570258554,-0.23317967516626048
179.80000000000217,31.359576356631674,-1.53743873019316,-0.23350890708370908
180.90000000000217,31.463972587565138,-1.5349069833285307,-0.2361474894933293
182.0000000000022,31.56927034400121,-1.5336655400486823,-0.23514959501203014
183.1000000000022,31.673640099320394,-1.5308111521013896,-0.23514137562253667
184.2000000000022,31.778959579228896,-1.5295275066818168,-0.23383952979997336
185.30000000000223,31.881948656966536,-1.5276678267966803,-0.23514980515965656
186.40000000000225,31.987670339855327,-1.5248749036551978,-0.23384001643167363
187.50000000000227,32.09226783244412,-1.5238527847721839,-0.23514801413109288
188.6000000000023,32.196978115316234,-1.5212888588739801,-0.23647113918424667
189.7000000000023,32.30180174012037,-1.5202261964702914,-0.23580510540386568
190.8000000000023,32.406331768012016,-1.5171782322269112,-0.23622642092441204
191.90000000000234,32.51065588424891,-1.51629997954458,-0.237129861788274
193.00000000000233,32.61545370601408,-1.5149144348466816,-0.23712986199913688
194.10000000000235,32.72048240569279,-1.5130750610477381,-0.23713004237694513
195.20000000000238,32.82517352687252,-1.511258668579113,-0.23780228679082072
196.3000000000024,32.92934761761093,-1.5088739848345047,-0.23712680822992427
197.40000000000242,33.03365335333249,-1.5066767945695358,-0.2384498610464858
198.50000000000242,33.138121943733985,-1.505512762687714,-0.23844986200000173
199.60000000000244,33.2430134003827,-1.503389160188446,-0.23844986199999685
200.70000000000246,33.34830986004042,-1.501694620626219,-0.2384498610598298
201.80000000000246,33.45286972380457,-1.4987128506743348,-0.23980264232853976
202.90000000000248,33.55682895721543,-1.4975282731289388,-0.23844870125200268
204.0000000000025,33.66197245058922,-1.497060855093502,-0.23844983817662335
205.10000000000252,33.767711363555776,-1.494841850031227,-0.23976085692675086
206.20000000000255,33.87250093142478,-1.4940653093937082,-0.2411863924267421
207.30000000000254,33.97765007247581,-1.491692379989103,-0.24108031825152754
208.40000000000256,34.081662356812785,-1.4888256108303788,-0.24107958993416734
209.5000000000026,34.187331644938375,-1.4875978549841797,-0.24207007824360316
210.60000000000258,34.29207349959757,-1.486734313413583,-0.24240279962008282
211.7000000000026,34.39665618076128,-1.4846396923495777,-0.2437199803964294
212.80000000000263,34.500102189271225,-1.483281794156057,-0.24371987799994876
213.90000000000265,34.605159517440946,-1.4802425250205058,-0.24371987800000117
215.00000000000267,34.70986841337049,-1.4783825744814307,-0.24371987808047457
216.10000000000267,34.81415858644849,-1.476521475250621,-0.24542983592995515
217.2000000000027,34.92009358752227,-1.4755532109484317,-0.24597250730251785
218.3000000000027,35.02333549246582,-1.4738442583888265,-0.24640069461722192
219.4000000000027,35.12827246913541,-1.4726322903944002,-0.24636163108097486
220.50000000000273,35.2328361847337,-1.4696387030852311,-0.2450399312058802
221.60000000000275,35.336984006300554,-1.4698547517756335,-0.24733901365261257
222.70000000000277,35.44244054188012,-1.4670614027697588,-0.24769540682473057
223.8000000000028,35.546193563656225,-1.465232157437776,-0.24833014588089952
224.9000000000028,35.652306868307605,-1.4638581039031233,-0.2488137950160514
226.0000000000028,35.75603052187925,-1.4619557358309065,-0.2503101115994606
227.10000000000284,35.860430778566055,-1.4604817839263053,-0.2507931649102617
228.20000000000283,35.966484354179414,-1.4601869966239804,-0.2516393626439788
229.30000000000285,36.07044304161084,-1.4583411672979831,-0.25294617088645976
230.40000000000288,36.17525102465325,-1.4569122505766006,-0.25432973036766526
231.5000000000029,36.28100100844186,-1.4551592345878925,-0.25424127196467783
232.60000000000292,36.3859650306905,-1.4533924811978514,-0.25553387234260105
233.70000000000292,36.49028236936213,-1.4513324363699203,-0.2569106882997514
234.80000000000294,36.59620344888986,-1.4499645363102942,-0.25689001239729103
235.90000000000296,36.70007958912674,-1.446341418072527,-0.25951582593395095
237.00000000000296,36.804474781586634,-1.4458502031771259,-0.2582241467436379
238.10000000000298,36.909696380211685,-1.4444506351404118,-0.2595361456705181
239.200000000003,37.011668141309414,-1.442186188562729,-0.26228103421638904
240.30000000000302,37.118060420855905,-1.4418696465307521,-0.26348847935873065
241.40000000000305,37.22198608306335,-1.4415076515596417,-0.2647908826615244
242.50000000000304,37.32711520175442,-1.4385198205742737,-0.2661098412247709
243.60000000000306,37.43132222625345,-1.4357313346404914,-0.26742781906539603
244.7000000000031,37.536411084151965,-1.4344106070072886,-0.2687836960743204
245.80000000000308,37.640920963114866,-1.430923246354956,-0.27084615606949436
246.9000000000031,37.74562125233646,-1.4312618917578774,-0.27400868422684876
248.00000000000313,37.8489686966893,-1.4312211232181922,-0.27435236091065196
249.10000000000315,37.954886477507905,-1.429010582898814,-0.276781909277803
250.20000000000317,38.05981890339483,-1.4275956142206891,-0.2797213169997401
251.30000000000317,38.16306472076882,-1.4261899643262608,-0.28139978158035905
252.4000000000032,38.268001099794624,-1.4258078392953033,-0.2836712355462021
253.5000000000032,38.37324402768166,-1.42355000561504,-0.28630155238978006
254.6000000000032,38.4785806349887,-1.4223455436557872,-0.2896141832614676
255.70000000000323,38.581512051153666,-1.4212555806188734,-0.2921905596826635
256.80000000000325,38.68840351647839,-1.4201844522835083,-0.29488693201210125
257.9000000000033,38.79254529075327,-1.4204663770963204,-0.297478938120443
259.0000000000033,38.897160646647905,-1.4176025581356462,-0.30173065192894777
260.1000000000033,39.00330255865811,-1.4177016097888129,-0.3043620154503568
261.20000000000334,39.10672491092871,-1.4160698938094736,-0.3079358138491157
262.30000000000337,39.21270297326216,-1.4161389333601355,-0.31213449169036434
263.40000000000333,39.315307758044426,-1.414368618290619,-0.31591397715516223
264.50000000000335,39.421307859141365,-1.4118892922783681,-0.3192220800766403
265.6000000000034,39.52714303724583,-1.4118807274738288,-0.3235827238258313
266.7000000000034,39.63203629650977,-1.4102017429075382,-0.32839887770956766
267.8000000000034,39.737722079180855,-1.4094086793041292,-0.3323466137563589
268.9000000000034,39.8432445989915,-1.408625823244566,-0.33710067736901417
270.0000000000034,39.94706694693892,-1.4073202376065477,-0.34353176844598066
271.10000000000343,40.050721775818865,-1.4059374009059837,-0.3477458713204493
272.20000000000346,40.159473032357965,-1.4052853080501084,-0.3538447805680751
273.3000000000035,40.26443969980543,-1.4033118016488197,-0.35831209403090103
274.4000000000035,40.369345947278724,-1.4030257154365873,-0.36601002390957804
275.5000000000035,40.47459381680878,-1.4030469456818289,-0.37227446638978856
276.60000000000355,40.579560426442406,-1.402890058759601,-0.3787807555382381
277.70000000000357,40.68522686495113,-1.400907443882088,-0.38682485671864564
278.8000000000036,40.79174147549289,-1.4015136028647235,-0.3934341971620108
279.9000000000036,40.89633643791482,-1.400543875628689,-0.4019261271290131
281.0000000000036,41.00103202023393,-1.4000934459739969,-0.40923436090758925
282.1000000000036,41.1078930742888,-1.3996571991194242,-0.41511384621055836
283.2000000000036,41.212106045398606,-1.4010594167644554,-0.42576431959338334
284.30000000000365,41.31804934893856,-1.4004945774744462,-0.4341665384621791
285.4000000000037,41.422155163081555,-1.4005086484451241,-0.4435473122192497
286.5000000000037,41.528759995879504,-1.4013161025867547,-0.4521624475225625
287.60000000000366,41.633628290134624,-1.4041678704673737,-0.46169725396482786
288.7000000000037,41.73981606421821,-1.403732420448312,-0.47279606542180463
289.8000000000037,41.84513296627017,-1.4051435814844446,-0.483926662521986
290.90000000000373,41.9512444348853,-1.4046221872879527,-0.49382530677977776
292.00000000000375,42.05673869162829,-1.4065284284740212,-0.5054641176998143
293.1000000000038,42.160544280331415,-1.407582506724964,-0.5171324404748243
294.2000000000038,42.26747233350922,-1.4076305721903768,-0.5296104001131048
295.3000000000038,42.37250583745483,-1.4115538800522773,-0.5422953430315833
296.40000000000384,42.479913670399526,-1.413579772623194,-0.5556699785986785
297.5000000000038,42.58507667872937,-1.415793076834857,-0.5695424142163534
298.60000000000383,42.690035968667516,-1.4170140875232904,-0.5822168312579263
299.70000000000385,42.79594324036566,-1.4195911601704343,-0.5965436429440198
300.8000000000039,42.90200202332821,-1.4214069770494266,-0.6108769524098343
301.9000000000039,43.00883373662321,-1.423780309401273,-0.6260424098553576
303.0000000000039,43.11323342518309,-1.4245350441078295,-0.64235954973041
304.10000000000394,43.21997881497799,-1.42616399910627,-0.6590088857495342
305.2000000000039,43.324855940757324,-1.4288580916293097,-0.6740577092307021
306.30000000000393,43.43090567191153,-1.4303366020053434,-0.6913207605685754
307.40000000000396,43.53641907903397,-1.4338347068974613,-0.709675668921518
308.500000000004,43.641456744757456,-1.4366298363116956,-0.7273377333852538
309.600000000004,43.747521543579694,-1.4391241257966687,-0.7465660680383603
310.700000000004,43.85397328333345,-1.441950150433451,-0.7656575553446059
311.80000000000405,43.95755140989202,-1.4449035937778234,-0.7839041201094608
312.90000000000407,44.06534259207667,-1.4487368268794794,-0.8060953716983983
314.0000000000041,44.17088806987414,-1.4530129630724833,-0.8261268212984247
315.10000000000406,44.2747819130048,-1.4549877137437612,-0.8473851385810365
316.2000000000041,44.380128134529606,-1.4600019909323985,-0.8679965444564512
317.3000000000041,44.486336507865246,-1.4625349502489282,-0.891204807519189
318.4000000000041,44.592340608957635,-1.4669464197682482,-0.9153306434193662
319.50000000000415,44.698617817780494,-1.471360662643737,-0.9406257065632788
320.6000000000042,44.804166888335644,-1.4764129283612277,-0.9654106331076915
321.7000000000042,44.90848299257069,-1.4799177578666094,-0.9891633853522612
322.80000000000416,45.015570296303856,-1.4828429237221443,-1.0159612965149174
323.9000000000042,45.12432869044737,-1.4875387416676749,-1.0431402165322456
325.0000000000042,45.230416596827425,-1.49327995550302,-1.0699521679687902
326.10000000000423,45.33613111924186,-1.498076438963746,-1.0990999914602244
327.20000000000425,45.442349755746214,-1.505948384398378,-1.1283077749211206
328.3000000000043,45.548881721831464,-1.5116887388187799,-1.1565854825620892
329.4000000000043,45.654259358117756,-1.517777718876668,-1.188331803936082
330.5000000000043,45.760573229014945,-1.5241051100384262,-1.2184747396573967
331.60000000000434,45.86715600967799,-1.5317633720769828,-1.2520416429602066
332.7000000000043,45.97466425533199,-1.5391627620743167,-1.2873740973068628
333.80000000000433,46.08125995901335,-1.5465534199556215,-1.3223441746897984
334.90000000000435,46.187442299830934,-1.5575879279335016,-1.3544438125803357
336.0000000000044,46.29300045748825,-1.5623243882651288,-1.3927012455774048
337.1000000000044,46.401550519100475,-1.5733147597361055,-1.4291717810840225
338.2000000000044,46.506997842099544,-1.5808387450540167,-1.4662510268846347
339.30000000000445,46.61391615689443,-1.5916988864218031,-1.505685125296679
340.4000000000044,46.72038899475094,-1.5994774148607562,-1.5464191202112207
341.50000000000443,46.827387006399306,-1.6088619707747724,-1.5865438861633465
342.60000000000446,46.9334516885791,-1.6160777230748136,-1.6300462276929704
343.7000000000045,47.0408619403551,-1.6259238950699944,-1.673995921247112
344.8000000000045,47.14863452955798,-1.635551159139786,-1.716526117200059
345.9000000000045,47.25452684325608,-1.642397944417263,-1.7607304676546396
347.00000000000455,47.362126027212724,-1.6502147567439527,-1.8091504234598528
348.10000000000457,47.46864598576134,-1.6564916575898438,-1.8536633056258638
349.2000000000046,47.574961160319475,-1.6602381475916737,-1.9020394372029625
350.30000000000456,47.68166221768558,-1.663137063820753,-1.9510795363094835
351.4000000000046,47.78848701540625,-1.6631304117407322,-1.9986618202975268
352.5000000000046,47.89521240871676,-1.6629597049173812,-2.0489251786788714
353.6000000000046,48.000110322294915,-1.6594628725962675,-2.0986873531953076
354.70000000000465,48.10749412007949,-1.6518154989675808,-2.146367168506746
355.8000000000047,48.21331150571943,-1.6415748669210481,-2.193544262847119
356.9000000000047,48.31906925476285,-1.6271861969908783,-2.2426078329850556
358.00000000000466,48.42497665774338,-1.6090075304574467,-2.2873610849606214
359.1000000000047,48.531833510867784,-1.5888488533029614,-2.330940564376313
360.2000000000047,48.6377020238386,-1.5643068805882612,-2.37720398877059
361.30000000000473,48.742666969717156,-1.5350442722863729,-2.415274933865387
362.40000000000475,48.84834364778737,-1.5073439568679108,-2.4558727161069607
363.5000000000048,48.95373732510389,-1.475714742790566,-2.49225287046134
364.6000000000048,49.05953488901308,-1.4434267670298733,-2.5246869973508828
365.7000000000048,49.16398776718664,-1.4120484923590328,-2.5562540797941686
366.80000000000484,49.26917091330082,-1.3787597257919708,-2.583970140109937
367.9000000000048,49.37464113592138,-1.346433373839256,-2.608340814842793
369.00000000000483,49.48007053745407,-1.3180755368195403,-2.6314368622569484
370.10000000000485,49.58529077158065,-1.2909534365943798,-2.6518347540412903
371.2000000000049,49.690680630183806,-1.2647979485390428,-2.6698715084628017
372.3000000000049,49.7956397429903,-1.24054836642028,-2.687248406850051
373.4000000000049,49.9021788031532,-1.2159184381392,-2.700822531387135
374.50000000000495,50.00789055648176,-1.1939498165984699,-2.7140597969942912
375.6000000000049,50.114098857047736,-1.1738910125358133,-2.7276420538235406
376.70000000000493,50.2186732693353,-1.1521145577708565,-2.7350021635055892
377.80000000000496,50.32602629930335,-1.1344889731168148,-2.7419136890328684
378.900000000005,50.43159120784394,-1.1185636141540676,-2.7520761814838632
380.000000000005,50.538887941123704,-1.1031236025614537,-2.7603658332439123
381.100000000005,50.64440242750353,-1.0904069888323593,-2.76513634474938
382.20000000000505,50.750326273972355,-1.0819175599930388,-2.7710941704233
383.30000000000507,50.856337460587156,-1.0741449509769707,-2.7768236303612666
384.4000000000051,50.96138729722012,-1.0669516948110274,-2.780088754689113
385.50000000000506,51.07068823574221,-1.060808176998224,-2.7846886978523173
386.6000000000051,51.176884485295986,-1.0573640722659474,-2.788859077355829
387.7000000000051,51.28459163172252,-1.054095042119435,-2.7916485243481626
388.8000000000051,51.390497047688825,-1.0516133833299868,-2.795608163951863
389.90000000000515,51.49790908004802,-1.0488706544595932,-2.79860720899056
391.0000000000052,51.603239127035515,-1.0463361030463805,-2.8030745009669404
392.1000000000052,51.71220551452257,-1.0440022570102292,-2.805633081461732
393.20000000000516,51.81974124156223,-1.0419449107139784,-2.8084671775581693
394.3000000000052,51.92717710497075,-1.0394062935145374,-2.811112328452782
395.4000000000052,52.033240787580155,-1.0379539266514977,-2.816138077369616
396.50000000000523,52.14153747319666,-1.0375318436244707,-2.819775165296857
397.60000000000525,52.247670096028855,-1.035562403437288,-2.8239511180605446
398.7000000000053,52.35596605969627,-1.0336249128731314,-2.8273391301416178
399.8000000000053,52.46107071928447,-1.0310317028575318,-2.8299946601139334
400.9000000000053,52.57085231407276,-1.029149391995726,-2.832615109494543
402.00000000000534,52.67779532146021,-1.0294112598513532,-2.836123931225565
403.1000000000053,52.78592813740919,-1.0280569929699732,-2.838052495478701
404.20000000000533,52.89304809151228,-1.0259222576229814,-2.840797959298581
405.30000000000535,53.00178374624098,-1.0243014327384439,-2.8449282646054037
406.4000000000054,53.10927306479285,-1.0238842874308416,-2.8474532841171447
407.5000000000054,53.21737425089792,-1.0213594098368648,-2.850189890591058
408.6000000000054,53.32502207234995,-1.0200550684575214,-2.8548210170744426
409.70000000000545,53.43155500079337,-1.0195305011547104,-2.8573949252450612
410.8000000000054,53.53926541163108,-1.0172856048792633,-2.860448547628485
411.90000000000543,53.64695832729508,-1.0170142816270882,-2.8631565187291237
413.00000000000546,53.753332398738756,-1.0158137859567473,-2.8664436934288062
414.1000000000055,53.863751600797364,-1.014878535532956,-2.8694012882133624
415.2000000000055,53.97099891560167,-1.0142978112741134,-2.87185951909817
416.3000000000055,54.07944999435733,-1.0137071363703878,-2.8746682599315836
417.40000000000555,54.18774424576449,-1.0129315597649173,-2.8773919864103283
418.50000000000557,54.29537926270739,-1.013765053988081,-2.8806380796933526
419.6000000000056,54.402524320981236,-1.0127929446012565,-2.88361794635414
420.70000000000556,54.51074088711535,-1.0135100770044754,-2.8866420095953496
421.8000000000056,54.61847760257322,-1.0137620091502353,-2.8892461788561277
422.9000000000056,54.72593489277004,-1.012252918193817,-2.8913138648359995
424.0000000000056,54.83515762758544,-1.0116210016303036,-2.8951837628474095
425.10000000000565,54.941835097353014,-1.0112036037656211,-2.897832965107784
426.2000000000057,55.049655692958595,-1.0115854601244896,-2.901678650696465
427.3000000000057,55.15849812423952,-1.0119738371823825,-2.904323720795656
428.40000000000566,55.26551999432942,-1.0144078251781619,-2.9053420817680076
429.5000000000057,55.37335868654479,-1.0164000749477216,-2.9082429681855806
430.6000000000057,55.4818702866919,-1.0189843482090026,-2.9121692090889333
431.70000000000573,55.590850250530416,-1.0201458105983152,-2.9135498348563393
432.80000000000575,55.699864485456594,-1.0217617012359186,-2.9161813009632525
433.9000000000058,55.80822842531059,-1.0212692742718492,-2.918816100512202
435.0000000000058,55.917049865313324,-1.0248833228757201,-2.9214757394985784
436.1000000000058,56.02523620841207,-1.0271197545256197,-2.9238276548477993
437.20000000000584,56.13466372786065,-1.028769415654312,-2.9265918813621834
438.3000000000058,56.24328589861519,-1.038338816687686,-2.928900863836133
439.40000000000583,56.3510885835218,-1.0493354737836542,-2.931683083155364
440.50000000000585,56.45990987743796,-1.0606259720100024,-2.932866401644776
441.6000000000059,56.56906905931292,-1.0759131042677523,-2.9351645336940613
442.7000000000059,56.676868221001456,-1.087960229022003,-2.9364005852745345
443.8000000000059,56.785519394578266,-1.0972811451741324,-2.9404488197414684
444.90000000000595,56.892863822951604,-1.1071116454658567,-2.943067418771135
446.0000000000059,57.00222100044361,-1.1120719750480226,-2.9443937451233158
447.10000000000593,57.109360776503586,-1.1190876817391475,-2.9467007610604816
448.20000000000596,57.217755932400806,-1.1222179820214107,-2.948876727018166
449.300000000006,57.3263880867273,-1.125470620345754,-2.950431480466727
450.400000000006,57.43399579994846,-1.1305303350207718,-2.9527047651270815
451.500000000006,57.54277528270511,-1.1339668321187328,-2.9553490218976957
452.60000000000605,57.65080098380062,-1.1379905279212272,-2.9569724642915203
453.70000000000607,57.75847520706054,-1.14036649449038,-2.9595822947610246
454.8000000000061,57.86751368136645,-1.1444249947868426,-2.9619656849857576
455.90000000000606,57.976107662755396,-1.1466580250514609,-2.9623491231085692
457.0000000000061,58.08404791221166,-1.149492759858274,-2.9646622541700465
458.1000000000061,58.191866811666046,-1.151841484420304,-2.966796733523702
459.2000000000061,58.30102896587842,-1.1543885856006926,-2.968539749567376
460.30000000000615,58.40854711763031,-1.1551407533183708,-2.96973243322537
461.4000000000062,58.51743237390765,-1.1551087332400702,-2.9740829822611468
462.5000000000062,58.62598531401533,-1.159752393542753,-2.975457680858648
463.60000000000616,58.73359031450888,-1.1617196983222182,-2.9754575838591597
464.7000000000062,58.84279647728152,-1.1627198824643015,-2.978270939247275
465.8000000000062,58.9516098710914,-1.1633761894501602,-2.9794129504124145
466.90000000000623,59.0605724528131,-1.1659857078233615,-2.9811779309831294
468.00000000000625,59.16917000000063,-1.1683699999999928,-2.984019917419398
469.1000000000063,59.2775863861159,-1.1721632193916318,-2.985348104065714
470.2000000000063,59.386059321826565,-1.1731676101424446,-2.9854912096795014
471.3000000000063,59.49475510296269,-1.1725568634859105,-2.9879722792250343
472.40000000000634,59.60383337654058,-1.174059777653289,-2.9906253814697914
473.5000000000063,59.712664511104705,-1.174177148148279,-2.991795483818052
474.60000000000633,59.821357227486224,-1.1734207751894319,-2.9932472146938967
475.70000000000636,59.92926856287924,-1.1737571736799561,-2.9945586488075175
476.8000000000064,60.03855498240261,-1.1741837282295398,-2.997186195527848
477.9000000000064,60.14649362450035,-1.1727005567080866,-2.998509238868314
479.0000000000064,60.25523022055941,-1.1729173905960792,-2.999987267133312
480.10000000000645,60.36471505414869,-1.1719600415267382,-3.0011301445325165
481.2000000000064,60.47278098858265,-1.1696782867759163,-3.003414463014538
482.30000000000643,60.582708124258495,-1.1698128902917801,-3.0051000122281506
483.40000000000646,60.691418689586,-1.1681489116284254,-3.0051270670146133
484.5000000000065,60.79934679755412,-1.1672486467058343,-3.0064201753637327
485.6000000000065,60.90987215604395,-1.1659607604114282,-3.007733181381551
486.7000000000065,61.01811888588257,-1.1672552468642576,-3.0103316138997567
487.80000000000655,61.12698941987388,-1.1666033508155003,-3.010380605146464
488.90000000000657,61.23577252333149,-1.1655604866754619,-3.0130606269655242
490.0000000000066,61.34564497753064,-1.1626546421230752,-3.014393716382525
491.10000000000656,61.45453099571114,-1.1615521705012626,-3.0156145809178696
492.2000000000066,61.56358016861123,-1.1569875311605915,-3.016960261332362
493.3000000000066,61.67439359082066,-1.1557641580815374,-3.0182751718519905
494.4000000000066,61.782921522824765,-1.152458855146087,-3.0196289952231847
495.50000000000665,61.89179799259755,-1.1498600512628543,-3.0207638851789698
496.6000000000067,62.00053339962565,-1.1468339531688236,-3.022229835528641
497.7000000000067,62.1095438510438,-1.1396758189310312,-3.022228680140198
498.80000000000666,62.2184411843734,-1.136319577217241,-3.0248704991431867
499.9000000000067,62.32773463569842,-1.1301067696332618,-3.027518341861393
501.0000000000067,62.43590232213894,-1.122762791017713,-3.0273752205923774
502.10000000000673,62.54655946253212,-1.1152308797641937,-3.0288073342311783
503.20000000000675,62.656296353656,-1.1098963852372996,-3.0306499070273487
504.3000000000068,62.76508363499579,-1.1061943416109243,-3.03104790554715
505.4000000000068,62.87373876785688,-1.1029457919631738,-3.0327906068860213
506.5000000000068,62.983611831085334,-1.0968658301606617,-3.0327510125510373
507.60000000000684,63.09278706299888,-1.0941262340759055,-3.035399971518672
508.7000000000068,63.20246190897485,-1.0880029256508945,-3.034345959344389
509.80000000000683,63.31123058827641,-1.0854688424646883,-3.0371863554470107
510.90000000000686,63.42094056468376,-1.0824427139478279,-3.0373750865701643
512.0000000000068,63.529437929257675,-1.079009965896995,-3.040670379783707
513.100000000007,63.63728258075401,-1.0768870424291583,-3.040679802428238
514.2000000000069,63.74927201110057,-1.0741927771843098,-3.0419897948460757
515.300000000007,63.85692530724611,-1.0727974469657042,-3.041989902497432
516.4000000000069,63.96728385557734,-1.0726668355406275,-3.043300572731278
517.5000000000069,64.07864658691088,-1.0684424853078127,-3.044620328247528
518.600000000007,64.18883359710533,-1.0689717605312605,-3.0446196302502972
519.700000000007,64.29752646731468,-1.0686691573116605,-3.0472603826172806
520.800000000007,64.40755783708862,-1.0661006411244502,-3.0472488991514695
521.900000000007,64.51822068112908,-1.0659240946207198,-3.049891459401584
523.000000000007,64.62734510252538,-1.0645484415930733,-3.0503857050143095
524.1000000000071,64.73753329112284,-1.063707436757841,-3.0498913378650143
525.2000000000071,64.84762111545925,-1.0642494662718978,-3.0524094992952877
526.300000000007,64.95780689805707,-1.064045389791599,-3.0525191153367746
527.4000000000071,65.06579592863565,-1.0646093643396597,-3.053834174800987
528.500000000007,65.17566112756332,-1.0671760383530406,-3.0548343709600405
529.6000000000072,65.28578610010986,-1.0692445082560893,-3.0547643895626675
530.7000000000071,65.39715541411091,-1.069166146587212,-3.0571814777853623
531.8000000000072,65.5060352116902,-1.0705287773393917,-3.0584459459590856
532.9000000000071,65.61635414358572,-1.0699482203490722,-3.0594441870682463
534.0000000000072,65.72577519872614,-1.0720797356225338,-3.0606167714706354
535.1000000000072,65.83574540089008,-1.0724705056898352,-3.0610800500547564
536.2000000000072,65.9447292542643,-1.0733555872192124,-3.0624358955150726
537.3000000000072,66.05579102172173,-1.0757977325907786,-3.062635746931831
538.4000000000073,66.16520365183663,-1.0772866290132987,-3.0650178745027263
539.5000000000073,66.27303750139129,-1.0778253802934028,-3.0650354530006068
540.6000000000073,66.38516678849379,-1.0790026493578126,-3.0650529926964607
541.7000000000073,66.49496363559174,-1.0803205653068166,-3.0664444195771607
542.8000000000073,66.60443224188035,-1.0812647335501984,-3.0689345597341493
543.9000000000074,66.71481535917904,-1.0823507143415396,-3.06804605861975
545.0000000000074,66.82501566605427,-1.0842815180079464,-3.0690009001506353
546.1000000000074,66.93378416102709,-1.0861648586894197,-3.0702252877403997
547.2000000000073,67.04357275625863,-1.0877333148397994,-3.070305313144179
548.3000000000073,67.15525940333742,-1.0881343661389695,-3.0730222760550285
549.4000000000074,67.26547177932702,-1.0897382415354804,-3.0729493241540298
550.5000000000074,67.37500634300787,-1.091491562275215,-3.0742712192351154
551.6000000000074,67.48572429346008,-1.0920029475554733,-3.07491802966629
552.7000000000074,67.59602874458135,-1.092966517961469,-3.0755423163469464
553.8000000000075,67.70633396474966,-1.0938529044124476,-3.0755801023290026
554.9000000000075,67.8164852756282,-1.0955733567948631,-3.076895655550142
556.0000000000075,67.92765720392553,-1.0967395495851986,-3.0782209878158366
557.1000000000075,68.0375466159415,-1.0962398067432069,-3.0769054249636802
558.2000000000075,68.14864028802401,-1.0995863281162728,-3.0795300246947503
559.3000000000076,68.26009731224786,-1.100982140491539,-3.0808499875632767
560.4000000000076,68.37104522588065,-1.1035989042876044,-3.0821750870853855
561.5000000000076,68.48223919639231,-1.1040333975425454,-3.081970221404128
562.6000000000076,68.59266838898952,-1.1039075483273753,-3.083160098717485
563.7000000000077,68.7035085956606,-1.104684156164193,-3.084478064795317
564.8000000000077,68.81373272536925,-1.1068621250430122,-3.0857899387967183
565.9000000000076,68.92449478834293,-1.1103764180377587,-3.0857627502695566
567.0000000000076,69.03423676304668,-1.1122246082248586,-3.085790071720373
568.1000000000076,69.14599462432027,-1.1144197192871461,-3.0881021844775556
569.2000000000077,69.25690783883962,-1.1161226235728006,-3.0880995659498796
570.3000000000077,69.36707272066319,-1.1218396910643944,-3.0884090002297597
571.4000000000077,69.47764631842496,-1.1222421584695417,-3.088646565327155
572.5000000000077,69.58824511317046,-1.1249381541326036,-3.089408380481829
573.6000000000078,69.69926746408653,-1.1265939372368485,-3.0907299053449475
574.7000000000078,69.80926618002624,-1.127186218283904,-3.0917087899453866
575.8000000000078,69.91998914218348,-1.1277628095188623,-3.091710277095012
576.9000000000078,70.03055578288225,-1.1304535770010673,-3.0930299843189473
578.0000000000078,70.14093037386912,-1.130098491591547,-3.095239043630087
579.1000000000079,70.25118523648088,-1.1334162219408344,-3.094637509497245
580.2000000000079,70.36202901329737,-1.1360877317794036,-3.0945743301268154
581.3000000000079,70.4730352064297,-1.1364269627880879,-3.096563800576308
582.4000000000078,70.58295190693642,-1.1392766543020703,-3.097856339346668
583.5000000000078,70.69378221172417,-1.140508890079186,-3.0965500209703443
584.6000000000079,70.80409760430139,-1.1420072583157455,-3.096546929635606
585.7000000000079,70.91663286378984,-1.1443736087606011,-3.098842635597377
586.8000000000079,71.02713436636286,-1.147031501429439,-3.1007100684529982
587.9000000000079,71.13647831604217,-1.1495087660017496,-3.101407636204253
589.000000000008,71.2482166834304,-1.1513673218761766,-3.100719697240351
590.100000000008,71.35868467642356,-1.1514031353525267,-3.1033561777837497
591.200000000008,71.47009937758969,-1.1543564654315812,-3.1033599056473227
592.300000000008,71.58097036693454,-1.1560705049178643,-3.1046782571425178
593.400000000008,71.69207525620672,-1.1595437638262076,-3.106191780346233
594.5000000000081,71.8021093792894,-1.1641862654326836,-3.104614499786661
595.6000000000081,71.91458757278014,-1.16310713182591,-3.1037901400692673
596.7000000000081,72.0257564292246,-1.1685613432679132,-3.1051972242078563
597.8000000000081,72.13551865628659,-1.1724967631111232,-3.1077539100117844
598.9000000000082,72.24568121589206,-1.175152243798009,-3.1077505674518155
600.0000000000082,72.3590641097155,-1.177823448362099,-3.1078828716684543
601.1000000000081,72.4696839027378,-1.1784701910294868,-3.1087395840379135
602.2000000000081,72.58161864299001,-1.1815368608012486,-3.110050106989204
603.3000000000081,72.69295992440966,-1.18501710688024,-3.1110257068956897
604.4000000000082,72.80383237350435,-1.1901853107670415,-3.110353736915567
605.5000000000082,72.91546877144715,-1.19190569894005,-3.1111500150574467
606.6000000000082,73.02706372037683,-1.1951504194488138,-3.1122267674896453
607.7000000000082,73.13760176140647,-1.1962707465711773,-3.1140179496409592
608.8000000000083,73.24685452198476,-1.200518328484118,-3.113999977428712
609.9000000000083,73.35967608602729,-1.2014496901501486,-3.114659455969461
611.0000000000083,73.47211817161477,-1.2039830162119005,-3.115913563239023
612.1000000000083,73.5828789778161,-1.208380771744406,-3.1153200169121185
613.2000000000083,73.69165636372936,-1.210063117141033,-3.11667429527985
614.3000000000084,73.80494101582619,-1.2152974451685592,-3.117175702243731
615.4000000000084,73.91543230460222,-1.2186260672954479,-3.116693805922372
616.5000000000084,74.02656560766785,-1.2224260101933464,-3.1189012525723117
617.6000000000083,74.13834707911828,-1.2237992040295387,-3.1174232090227
618.7000000000083,74.24721697885855,-1.2283516366862355,-3.12007114232042
619.8000000000084,74.35716800217509,-1.2330472895025755,-3.118730221347963
620.9000000000084,74.46957936210914,-1.2380854641407597,-3.120367699309836
622.0000000000084,74.58276384761533,-1.242704648818613,-3.12168925039082
623.1000000000084,74.69474205547712,-1.2468338216983719,-3.123013777943761
624.2000000000085,74.80472751267868,-1.2515496269886182,-3.122746031698613
625.3000000000085,74.91634571075988,-1.2594495429808439,-3.123009812978169
626.4000000000085,75.02856627281199,-1.2629816948180037,-3.123619587287589
627.5000000000085,75.13803282090205,-1.2675751350782496,-3.1243182059265053
628.6000000000085,75.25093381335927,-1.2719285148473851,-3.126965311560776
629.7000000000086,75.36281390780307,-1.2773478634601334,-3.1281720961020363
630.8000000000086,75.47416739011774,-1.2832957690896174,-3.126960088891501
631.9000000000086,75.586428727332,-1.2882782763008378,-3.128276918439533
633.0000000000086,75.69690425661446,-1.2923112291702756,-3.129589917108099
634.1000000000087,75.80906055069724,-1.2945812714910407,-3.129589743902633
635.2000000000087,75.92039880123598,-1.3004720589742542,-3.1313914599102284
636.3000000000086,76.03108565424928,-1.3046332122750335,-3.133559930909796
637.4000000000086,76.14285785010529,-1.3060282986758303,-3.132229259867239
638.5000000000086,76.25419808337712,-1.3127134672966754,-3.13354180317079
639.6000000000087,76.36610181688553,-1.3169872609467763,-3.1348607859790043
640.7000000000087,76.4774243847956,-1.3202120536975759,-3.1361798497511315
641.8000000000087,76.58844307010159,-1.323184407309415,-3.13618595000903
642.9000000000087,76.70075280481869,-1.328126284156708,-3.1375147308609175
644.0000000000088,76.81200833370805,-1.32928677860384,-3.138114333099954
645.1000000000088,76.92279699523985,-1.3328547974616123,-3.1402236631968936
646.2000000000088,77.03562749130471,-1.3356312034567512,-3.1401403045065472
647.3000000000088,77.1460795122435,-1.3378158112257768,-3.1414518779979836
648.4000000000088,77.25853092923906,-1.337581348126456,-3.1427700311449693
649.5000000000089,77.36994468012986,-1.3376164955350198,-3.1440872884960305
650.6000000000089,77.48305904300439,-1.3359771723879441,-3.144363145665449
651.7000000000089,77.5931592255791,-1.3349123144636097,-3.145399789614377
652.8000000000088,77.70480832023547,-1.334249520953495,-3.145983361476108
653.9000000000088,77.81639535924256,-1.3309168389219461,-3.146772989695307
655.0000000000089,77.92665101077226,-1.3281923310399262,-3.1467200761188674
656.1000000000089,78.03926334664854,-1.3298250207478355,-3.1480399710982296
657.2000000000089,78.15015356942426,-1.327340533333148,-3.149349750578957
658.3000000000089,78.25926528347875,-1.3255800073391661,-3.1500177980319157
659.400000000009,78.37173919731389,-1.3229136313778191,-3.150669828676918
660.500000000009,78.48262568211773,-1.3197948447459333,-3.149382464002124
661.600000000009,78.59459843128808,-1.3179238415119474,-3.152270753573528
662.700000000009,78.70556449825659,-1.3128256458539913,-3.153309864746057
663.800000000009,78.81684821035579,-1.3074607400018765,-3.1544438316998766
664.9000000000091,78.92889887984762,-1.3018675189179554,-3.153630401069741
666.0000000000091,79.04082566639408,-1.2948610402744467,-3.154950124046333
667.1000000000091,79.14982094656142,-1.287832313695013,-3.1562629906784307
668.2000000000091,79.26094066095396,-1.2857584956644699,-3.1562701380245266
669.3000000000092,79.37368283470433,-1.280679188693596,-3.156166384459258
670.4000000000092,79.4869366804485,-1.2798836226167325,-3.1569097640968224
671.5000000000091,79.59845561100104,-1.2792353945326513,-3.155401118060138
672.6000000000091,79.7104068827894,-1.2768314846164057,-3.1567100034736044
673.7000000000091,79.82174230806528,-1.274992255430999,-3.1567100041545255
674.8000000000092,79.9330809378036,-1.2725145652505576,-3.157670534066639
675.9000000000092,80.04320249776461,-1.270085331959001,-3.158030020134144
677.0000000000092,80.15680679332844,-1.2700630956629104,-3.1580300199904285
678.1000000000092,80.26785374028387,-1.2670925431867293,-3.1582605315591694
679.2000000000093,80.37975935924763,-1.270936935336693,-3.159354444543561
680.3000000000093,80.49060186073305,-1.2708442269077096,-3.1603429695374583
681.4000000000093,80.60342469948473,-1.2697842161241018,-3.160670917676409
682.5000000000093,80.71336748886888,-1.2707835609628373,-3.1606598894989855
683.6000000000093,80.82741009337043,-1.2734716675593811,-3.160659897255659
684.7000000000094,80.93836612746955,-1.2748196514635306,-3.161650462973604
685.8000000000094,81.05070684771319,-1.2763464717619972,-3.1619793231811117
686.9000000000094,81.16333498581211,-1.278719978767323,-3.163300217536595
688.0000000000093,81.27416680287571,-1.2802561014224505,-3.163299933999903
689.1000000000093,81.38600901813344,-1.281293907550943,-3.163299930249958
690.2000000000094,81.49855550978893,-1.2849486508429777,-3.161992224071184
691.3000000000094,81.60977490924938,-1.2851097957678996,-3.16329994371919
692.4000000000094,81.72193447724932,-1.2881707132990619,-3.164264593950553
693.5000000000094,81.83352369550222,-1.292286211536528,-3.16461018668911
694.6000000000095,81.94589917812418,-1.2944635647465563,-3.1646169767998664
695.7000000000095,82.05781313133109,-1.295558099148981,-3.1668396148713933
696.8000000000095,82.16866398799367,-1.301367500887523,-3.1672498315806177
697.9000000000095,82.27990124223257,-1.3038352381731686,-3.1659733793296585
699.0000000000095,82.39202497705242,-1.3080516239166298,-3.1673456960350572
700.1000000000096,82.5040402141707,-1.3102081796882123,-3.1672598478823533
701.2000000000096,82.61749140690497,-1.3141005695715875,-3.1675517588218014
702.3000000000096,82.72906219189761,-1.3171672063607585,-3.168243688217219
703.4000000000096,82.84048745001316,-1.3215012276265532,-3.1672506461853813
704.5000000000097,82.95297400645686,-1.3250024427781304,-3.1685700982012888
705.6000000000097,83.06649189434688,-1.3298020885765547,-3.169129646979761
706.7000000000096,83.17847519657742,-1.332173096487368,-3.1698904737548728
707.8000000000096,83.28959600788866,-1.335555723113081,-3.1708801342312896
708.9000000000096,83.40270301949533,-1.3410424499542182,-3.1708801331806673
710.0000000000097,83.51440338293838,-1.3447274967320193,-3.171232057787183
711.1000000000097,83.62653165797997,-1.3512116045425513,-3.1725200232526385
712.2000000000097,83.73864021011832,-1.358333200773264,-3.1721435341379203
713.3000000000097,83.85130273790104,-1.367221387772744,-3.1715300037648673
714.4000000000098,83.96365906417437,-1.3728506662538844,-3.172518226876429
715.5000000000098,84.07489248802665,-1.3817079497538391,-3.1725219988873716
716.6000000000098,84.18788397206505,-1.3906253854768789,-3.1725194750536025
717.7000000000098,84.30089966503947,-1.3984982228821812,-3.1725202534216086
718.8000000000098,84.41315246147475,-1.4060215998601087,-3.1749502784649626
719.9000000000099,84.52645941386032,-1.417126130490662,-3.176469829052938
721.0000000000099,84.63742413588619,-1.4235826037720782,-3.175143986276418
722.1000000000099,84.74983409895684,-1.4351836829102043,-3.175149885001685
723.2000000000098,84.86209448554975,-1.4420051632373265,-3.1751502555772015
724.3000000000098,84.97378777377801,-1.4519463566336541,-3.175860300092537
725.4000000000099,85.08482874335908,-1.4609362298559674,-3.1764381820343797
726.5000000000099,85.19843578234516,-1.4706994087336003,-3.176579683007094
727.6000000000099,85.31029316390803,-1.4806551351980455,-3.1777941562812604
728.7000000000099,85.42205687977324,-1.487278072278734,-3.1777908104488732
729.80000000001,85.53411506120788,-1.4957459224540188,-3.179110110238029
730.90000000001,85.64667588049265,-1.5020561490862503,-3.1804168402452957
732.00000000001,85.75906638647875,-1.5090658180938392,-3.1804301899980656
733.10000000001,85.87121871854542,-1.5167008644512883,-3.1804290287497214
734.20000000001,85.98258888970226,-1.523475550387974,-3.1790886017325324
735.3000000000101,86.0958217334509,-1.532251717437485,-3.180337212358766
736.4000000000101,86.20849842928247,-1.5420541898271578,-3.1804262383243844
737.5000000000101,86.32124245846516,-1.5514064321322272,-3.1817399204617014
738.6000000000101,86.43370816501898,-1.5561743958642613,-3.181740131343551
739.7000000000102,86.54567277815781,-1.5657198571563866,-3.1830659005918034
740.8000000000102,86.65927558930748,-1.5738704215931463,-3.1817481330203363
741.9000000000101,86.77189050152933,-1.5798392796134622,-3.1843801179783973
743.0000000000101,86.88420173637785,-1.5898050985232581,-3.184969076901836
744.1000000000101,86.99717900965675,-1.5964234230365582,-3.1858072221286955
745.2000000000102,87.10897755483643,-1.6042811067236413,-3.185702489153008
746.3000000000102,87.22289105531057,-1.6089020474040912,-3.1856881749149824
747.0000000000102,87.29492787505987,-1.6134269521854838,-3.1856899550037148