File: 01_Data/Cotton_Rug/STA/N2/30K_min/Cotton_Rug_STA_N2_30KData_220113_R3.csv
##Temp./Â°C,Time/min,DSC/(mW/mg),Mass loss/mg
49.0,10.513482720554606,-0.9272300329158706,0.003306774077223018
50.20000000000002,10.725460257784048,-0.7961095655267841,0.0021023746660571163
51.400000000000034,10.854087825847364,-0.7014021654296414,0.0006783702830119864
52.60000000000005,10.956251437328117,-0.6243581753770375,0.00237986287904679
53.80000000000007,11.043527244127224,-0.5591430290063018,0.0009483794116995625
55.000000000000085,11.121191489817116,-0.5010573191258805,0.0019767738512799227
56.2000000000001,11.191086722119321,-0.45009726273577727,0.0018615431521000758
57.40000000000012,11.257144874477763,-0.4034251613093043,0.0011179517837875963
58.600000000000136,11.319787259142858,-0.35834322110621075,0.0016586835220762097
59.80000000000015,11.378217879862099,-0.3171820253097654,0.0015044201325133955
61.00000000000017,11.435150241133837,-0.27787296198157996,0.001615840871846963
62.20000000000019,11.490276355307921,-0.24143853026525308,0.000853973587144452
63.400000000000205,11.543179356880898,-0.20840044934006152,0.0018405777544874269
64.60000000000022,11.594679139856105,-0.17500465173370094,0.0024687623137875647
65.80000000000024,11.644703176184851,-0.14478175456897194,0.0024660254422546046
67.00000000000026,11.694467548075377,-0.11280966399570422,0.002611808231752555
68.20000000000027,11.743060859041247,-0.08448958000725448,0.0010922146602254657
69.40000000000029,11.790689945709218,-0.05811168139473289,0.000690738392275847
70.6000000000003,11.837861846916933,-0.03261299889329101,0.0007532671982746209
71.80000000000032,11.88417331736728,-0.012536059341564376,0.0019018668897796687
73.00000000000034,11.930398730415195,0.006821068220613347,0.0020270787369431886
74.20000000000036,11.975754139051425,0.027513146428500165,0.002717822241457668
75.40000000000038,12.020790293794231,0.04322885270549601,0.0018374034999437683
76.60000000000039,12.065378881310973,0.06042503671783546,0.00030278181268084126
77.80000000000041,12.109448223928132,0.07609222368301924,-0.00014410919985863302
79.00000000000043,12.153576195574097,0.09183187975903341,0.0006735277492806446
80.20000000000044,12.196897415311598,0.10704193129034081,-0.0008480975919145095
81.40000000000046,12.240249444671582,0.12427461759511758,-0.0008750375236896701
82.60000000000048,12.283456881491139,0.13905533168554124,-0.000891485652798174
83.8000000000005,12.326452221472245,0.15400389649044607,-0.0009018500245687733
85.00000000000051,12.368943415777098,0.16856054963610936,-0.0006310057299403482
86.20000000000053,12.410939274322219,0.18444551529457467,-0.0006636021175179252
87.40000000000055,12.452854492569962,0.19830569003547246,0.0006687612373195151
88.60000000000056,12.495018764849021,0.21136555461646234,0.0005983074150375245
89.80000000000058,12.536779704953954,0.22617922391016035,0.00014385737250854902
91.0000000000006,12.578331955993473,0.23943702421977264,-9.400396880998585e-05
92.20000000000061,12.619897200500823,0.2534125612115948,0.0003467106202084125
93.40000000000063,12.661018325201049,0.26793900394162934,-0.0009910835876993929
94.60000000000065,12.702385632172337,0.2791596261272739,-0.0018270698468567659
95.80000000000067,12.74326624884791,0.29318373689639354,-0.0018784536573939192
97.00000000000068,12.78414165895883,0.3056947019542017,-0.0022808231850488525
98.2000000000007,12.825231102697442,0.3178684412579996,-0.0022985946922604583
99.40000000000072,12.866006015060027,0.32946855833978556,-0.002300433630974652
100.60000000000073,12.907248521092669,0.342258658348202,-0.0031777121937448527
101.80000000000075,12.947781460035953,0.35506402065900267,-0.0022985739941345784
103.00000000000077,12.988252100398045,0.3653952088258457,-0.003454180028173326
104.20000000000078,13.028923201877939,0.3775778387587803,-0.003610708283371622
105.4000000000008,13.069473234046555,0.38799957151840997,-0.002935414969229555
106.60000000000082,13.109600955173521,0.4008624842255459,-0.003620156881471104
107.80000000000084,13.150493498245902,0.41085378249312,-0.003788009400173209
109.00000000000085,13.19089370234152,0.42126722105260334,-0.0035852684230750498
110.20000000000087,13.231641022334957,0.43320047418289087,-0.003805461732431681
111.40000000000089,13.271710579065406,0.4424842755267314,-0.004929734293825483
112.6000000000009,13.311857331600265,0.4537489257708289,-0.004929507065367211
113.80000000000092,13.351974454160182,0.46430979716577797,-0.004846531993580427
115.00000000000094,13.392550801203228,0.4743806986098228,-0.0036200993134185566
116.20000000000095,13.432562770553861,0.4843812214257654,-0.004938173925806311
117.40000000000097,13.472548963190809,0.4951355110185165,-0.004939939403428184
118.60000000000099,13.513066611976738,0.5051104858467228,-0.004940189841157405
119.800000000001,13.552642553043206,0.5147125965541257,-0.006222150781989733
121.00000000000102,13.592913838615429,0.524897610030758,-0.006249788533335909
122.20000000000104,13.63301048869253,0.5365956513276591,-0.006211872388442785
123.40000000000106,13.672401343294894,0.5448626103872086,-0.005256168192123489
124.60000000000107,13.711822614469428,0.5545397273074198,-0.005256752095256445
125.80000000000109,13.752072945998725,0.5648630564865315,-0.005253740902986692
127.00000000000111,13.791701820165608,0.5762880204733987,-0.004867204835102612
128.20000000000113,13.830941482653053,0.586129918578165,-0.005956423178899328
129.40000000000114,13.87043241060681,0.5935745672649602,-0.00625013534246488
130.60000000000116,13.909766170754903,0.6054706145641446,-0.006250199979907833
131.80000000000118,13.948596135211387,0.6155904144041089,-0.00625020173823021
133.0000000000012,13.988058524341453,0.6255250678489053,-0.006250597040271089
134.2000000000012,14.026800408492747,0.6348347707501784,-0.005191070133103715
135.40000000000123,14.066044032113767,0.6459370189279843,-0.004931452123687841
136.60000000000124,14.10540428565555,0.6587388497191895,-0.005037366768902096
137.80000000000126,14.14399666622098,0.6685423426662317,-0.0059201749839585815
139.00000000000128,14.182617450536478,0.6810964846455296,-0.005904174626283343
140.2000000000013,14.221684218097126,0.6908490108145774,-0.006575632913238927
141.4000000000013,14.260132050184152,0.7018716527113343,-0.006904507335574017
142.60000000000133,14.298764537898492,0.7139414749723227,-0.0069110322985119765
143.80000000000135,14.337210035521608,0.72508806579373,-0.00813100096566366
145.00000000000136,14.37576641199895,0.735418158019293,-0.006903867144917086
146.20000000000138,14.414122325570647,0.748052233117255,-0.006898538160639234
147.4000000000014,14.45150061935367,0.7585201032195014,-0.005572291063367096
148.60000000000142,14.490346161457065,0.7724271008183117,-0.005599958617206191
149.80000000000143,14.529055934472787,0.7835270341802504,-0.005604118963317362
151.00000000000145,14.567246471537151,0.7941263713795532,-0.008204465580728737
152.20000000000147,14.605310706707613,0.8064296614737956,-0.008219775847065236
153.40000000000148,14.642864792460367,0.8169400147299235,-0.00821991902843866
154.6000000000015,14.681355740160503,0.8290867058444878,-0.008221521581857516
155.80000000000152,14.719349677254456,0.8408283231502602,-0.006881255166944378
157.00000000000153,14.757295549883189,0.852821458848363,-0.008231539753508876
158.20000000000155,14.795196613296978,0.8631651377533794,-0.008315723993982616
159.40000000000157,14.833405200456223,0.8744613222231097,-0.006912278309588515
160.6000000000016,14.871363753199843,0.8863013974261189,-0.0069101667120108345
161.8000000000016,14.908983802148772,0.8969297643563933,-0.00691016020179358
163.00000000000162,14.946505110727786,0.9081839268674663,-0.006910253982140624
164.20000000000164,14.984684764766179,0.9211920397307344,-0.006926403075921073
165.40000000000165,15.02238047650429,0.9312605531917586,-0.007553722591906009
166.60000000000167,15.060097245530192,0.9439481199781596,-0.0075698448536760665
167.8000000000017,15.097658658452577,0.9537524562824816,-0.007569850851746551
169.0000000000017,15.135503765916974,0.9649835289069482,-0.007569850010427537
170.20000000000172,15.172818872263429,0.9757372698661354,-0.007569753506152743
171.40000000000174,15.210307616425302,0.9885543140073104,-0.008096079032288372
172.60000000000176,15.247032706050863,0.99930313906996,-0.008889780834340222
173.80000000000177,15.285487588082477,1.0105888281063167,-0.008889883232843232
175.0000000000018,15.32294213819023,1.020944986262479,-0.008893907882799645
176.2000000000018,15.359968063522357,1.0319288814551397,-0.009549493483280713
177.40000000000182,15.397416515621778,1.0435716664153045,-0.009549692501066076
178.60000000000184,15.43474629040332,1.053222997672763,-0.009549947568462613
179.80000000000186,15.472581807094352,1.0630745292983108,-0.009549951162707515
181.00000000000188,15.509539372519136,1.0751601958348596,-0.009549919579991517
182.2000000000019,15.546583144533667,1.084182534302798,-0.009525968747880142
183.4000000000019,15.583920971460909,1.0932344176265976,-0.008220734567922605
184.60000000000193,15.62003139921217,1.1026408894516575,-0.00823015831423568
185.80000000000194,15.657773683703079,1.1150431877120643,-0.008227420710046118
187.00000000000196,15.694665603488106,1.1237778854826854,-0.009549098446881565
188.20000000000198,15.731847733990127,1.1351243769185313,-0.010206858014732312
189.400000000002,15.769010446103536,1.1436739746301878,-0.010528213371615358
190.600000000002,15.805636838530372,1.1534488199994668,-0.010402528950781864
191.80000000000203,15.842534008527926,1.1646368430413665,-0.009539740887585246
193.00000000000205,15.879495440718594,1.1736454601919275,-0.009539905127936343
194.20000000000206,15.91638627520767,1.1839156123829655,-0.009545284649746577
195.40000000000208,15.953212273608495,1.193939763112342,-0.010851062316074689
196.6000000000021,15.989817170397693,1.2040225343451099,-0.010859876421369208
197.80000000000211,16.02665245339472,1.2148679142712155,-0.010825741691835589
199.00000000000213,16.063713653594995,1.2249139571473309,-0.011191840023846211
200.20000000000215,16.100356545817608,1.2331443011520586,-0.009954023046384819
201.40000000000217,16.136752874571062,1.2426129228195448,-0.009870015781003438
202.60000000000218,16.17357611731478,1.2530524366857354,-0.00986993209688869
203.8000000000022,16.210365408342298,1.2625756161339219,-0.00986964805528956
205.00000000000222,16.247043185326902,1.2728972602019528,-0.011236435703287917
206.20000000000223,16.283841085755064,1.2844591549997433,-0.011178146880583384
207.40000000000225,16.32044509248436,1.2925860773386633,-0.012521568327598764
208.60000000000227,16.35703201411257,1.3045085987702885,-0.012499919204991272
209.80000000000229,16.393306810861038,1.316154451156288,-0.012499899987625795
211.0000000000023,16.42996891164751,1.328659606832924,-0.012499900862050772
212.20000000000232,16.466506810587152,1.3374192098417559,-0.012499029683911367
213.40000000000234,16.5033421838524,1.3484616197220056,-0.011136184633509849
214.60000000000235,16.539692868795445,1.359540317407769,-0.011179938667916112
215.80000000000237,16.576458809377055,1.36910607916931,-0.01117985049484993
217.0000000000024,16.613110301283438,1.3792928376783813,-0.013006579227874404
218.2000000000024,16.649582511456508,1.3893292720222115,-0.013820531482643617
219.40000000000242,16.686213149318274,1.3977035269580478,-0.013812112356799133
220.60000000000244,16.72294367334985,1.4058336684346948,-0.014909593663261944
221.80000000000246,16.75950165920906,1.4136359714051563,-0.014809652866479617
223.00000000000247,16.795735556240974,1.4221133731817432,-0.01480982979399137
224.2000000000025,16.83245457778666,1.4299969413922258,-0.014809748296063852
225.4000000000025,16.869066496954424,1.440852168293443,-0.014814231017532542
226.60000000000252,16.905409434669433,1.4480338069875676,-0.015122059000660215
227.80000000000254,16.941819985810813,1.458934542094124,-0.0151388462389912
229.00000000000256,16.977967707873276,1.4700059852447318,-0.01643842813705554
230.20000000000258,17.01484626417625,1.4807588010265595,-0.01645102469224291
231.4000000000026,17.05123848603272,1.4937425840240885,-0.01782747032407972
232.6000000000026,17.087391929187344,1.5046806231318268,-0.019105234239522595
233.80000000000263,17.12399789595353,1.5186907291103373,-0.018965042502641083
235.00000000000264,17.16043016437983,1.5331839266411476,-0.018760145617504165
236.20000000000266,17.196683938648626,1.5488961489203232,-0.018759980191458858
237.40000000000268,17.233151873842868,1.568443816769072,-0.01875984348352766
238.6000000000027,17.269596274383236,1.5904188163031787,-0.018762598569035838
239.8000000000027,17.306052583996493,1.620287324973754,-0.020220999931888528
241.00000000000273,17.342620179176844,1.652280905452231,-0.021346154845995002
242.20000000000275,17.379071714861105,1.6850256405266306,-0.021501279692443198
243.40000000000276,17.415150474860692,1.7217952780746264,-0.02290521102773635
244.60000000000278,17.451593930635266,1.7571749347355694,-0.022806241360138202
245.8000000000028,17.487888230170274,1.7947665243669095,-0.02262573877881202
247.0000000000028,17.524478627860248,1.8521388308859144,-0.023584630497348158
248.20000000000283,17.5608924569898,1.9430670177786504,-0.023579095863591526
249.40000000000285,17.597286637828617,2.0501326545034284,-0.024952005131331667
250.60000000000286,17.633534552396895,2.148175295688303,-0.0249001560341906
251.80000000000288,17.670062696057883,2.2230027517585436,-0.02489933520919596
253.0000000000029,17.706578266135786,2.2598776832841647,-0.026243001525957155
254.20000000000292,17.74311630770449,2.260989500469423,-0.026206974859964483
255.40000000000293,17.77926598365915,2.2066681263698418,-0.027542008813560948
256.600000000003,17.815719211601113,2.1235134110152964,-0.027422703895148892
257.80000000000297,17.85176191083198,2.043078641151596,-0.028854489622417212
259.00000000000296,17.88852232491752,1.970446101005128,-0.030115121316864446
260.200000000003,17.924577100996764,1.9166840481847687,-0.030438313716638632
261.40000000000305,17.96080215486665,1.871343413267829,-0.03180469162377353
262.60000000000304,17.99745325740031,1.8373587669425802,-0.03300653459249592
263.800000000003,18.033679299546083,1.8113549478933149,-0.034182935838144246
265.00000000000307,18.06883435795529,1.794197314038068,-0.0351005263988835
266.2000000000031,18.10580583270738,1.7807285358475335,-0.03663657035060819
267.4000000000031,18.141991725769163,1.7717797131145046,-0.03741341866886483
268.6000000000031,18.17814739113419,1.7654724393863577,-0.038630128614794756
269.80000000000314,18.21432094926055,1.7625366036465615,-0.040628366386537884
271.0000000000032,18.250511391602597,1.7597188363540721,-0.041710585817685164
272.2000000000032,18.28657411622009,1.7619003848673966,-0.04380445182117576
273.40000000000316,18.322845742780604,1.7660765344233071,-0.045598402706538366
274.6000000000032,18.35914067056315,1.7683245243590988,-0.04757849699676431
275.80000000000325,18.395304902171244,1.7720649884509172,-0.04939935308517551
277.00000000000324,18.431377781944164,1.777181923242789,-0.052175265458632936
278.20000000000323,18.467661197730617,1.7839205267991594,-0.054820214957659985
279.4000000000033,18.504015728532497,1.7897208876127735,-0.05639991926521848
280.6000000000033,18.540510835336104,1.7960676211489084,-0.059170492368308736
281.8000000000033,18.576474158839392,1.8047341497399239,-0.061185133833213
283.0000000000033,18.612626585802275,1.81256550523714,-0.06282570044421387
284.20000000000334,18.64900203267796,1.8198421853754279,-0.06617965345046439
285.4000000000034,18.685481807499087,1.8275472053989534,-0.06725098166198151
286.6000000000034,18.721504987192564,1.836067436383295,-0.07060295997692467
287.80000000000337,18.757974064631018,1.8440807779630857,-0.07283578614286235
289.0000000000034,18.794368506836022,1.854563052973146,-0.07645465439468957
290.20000000000346,18.830683536766593,1.8649961336064171,-0.07990830710037233
291.40000000000344,18.866736082801918,1.8733199160949694,-0.08323631524895525
292.60000000000343,18.903191987041563,1.8833702416748848,-0.08911159807738489
293.8000000000035,18.939583132117495,1.8954443813297073,-0.09231231221042169
295.0000000000035,18.976171708737606,1.9061983146659203,-0.0952243884988846
296.2000000000035,19.012108629529035,1.91781378224003,-0.09890524351868368
297.4000000000035,19.048698182400017,1.9279518171304546,-0.10282750827888787
298.60000000000355,19.08521386680301,1.9382794701231163,-0.10734649942810082
299.8000000000036,19.121276222328742,1.950368035732384,-0.11233846305996709
301.0000000000036,19.157685107451027,1.9637054191228358,-0.11770914502281116
302.20000000000357,19.194008577906974,1.9745163537447703,-0.12329176318025059
303.4000000000036,19.230666124282735,1.9881889474336332,-0.129491959246272
304.60000000000366,19.266723355695238,2.0006908220594233,-0.1352597938575144
305.80000000000365,19.302938192305174,2.0125536870625913,-0.14110515481721952
307.00000000000364,19.339215015230113,2.0266606777984624,-0.1472205658364114
308.2000000000037,19.376076701882404,2.0391550571265156,-0.15397989683948765
309.40000000000373,19.41240528062921,2.050464108919015,-0.15869596921907103
310.6000000000037,19.449018607303618,2.0649416351931946,-0.16564385080022648
311.8000000000037,19.485508475477545,2.0774135772314852,-0.17229260349983377
313.00000000000375,19.521675855402723,2.0904111283322044,-0.18064560009874997
314.2000000000038,19.55805032870781,2.1019125627684385,-0.1891148934005491
315.4000000000038,19.594809461181047,2.1133610698180196,-0.1968039935320336
316.6000000000038,19.631068291445644,2.1274238516102146,-0.20522583002033024
317.8000000000038,19.66748472182233,2.140058399256974,-0.21417390098975098
319.00000000000387,19.70396102262002,2.1497503005990253,-0.22279437132863444
320.20000000000385,19.740188492148306,2.1608046161893415,-0.23214353227793705
321.40000000000384,19.77682687790068,2.1709452019783706,-0.24036358780956402
322.6000000000039,19.812501927466293,2.182460870654986,-0.2500034508980913
323.80000000000393,19.849817013603378,2.191145953849806,-0.2611064677199608
325.0000000000039,19.88655002949395,2.2026413578975896,-0.2722398977189804
326.2000000000039,19.92291782177797,2.215570935228279,-0.2834221670376844
327.40000000000396,19.9593685508404,2.2263185263145138,-0.2970044240803751
328.600000000004,19.995841437662833,2.237173598293918,-0.3106005219744197
329.800000000004,20.031957664173678,2.251363510269145,-0.32231308507433853
331.000000000004,20.069146465900943,2.2668466803177933,-0.3347502083774683
332.200000000004,20.105466054364374,2.2812507465143654,-0.34827443705195016
333.40000000000407,20.142111498073632,2.301576593624809,-0.36218325066500956
334.60000000000406,20.177877630557063,2.321975903336122,-0.3753949590340313
335.80000000000405,20.21575257291026,2.34786482761596,-0.39101446272612383
337.0000000000041,20.25238767134156,2.3718123531057165,-0.40950999784903974
338.20000000000414,20.28865939990124,2.4010504921076783,-0.4272660310244327
339.4000000000041,20.32559734820083,2.4325598606846195,-0.4455654240885276
340.6000000000041,20.36212012091293,2.465429105208926,-0.46494454785402795
341.80000000000416,20.39890071041128,2.501326421780103,-0.4847721152195592
343.0000000000042,20.435506302188664,2.5370873676688297,-0.5051463826524913
344.2000000000042,20.4721900082926,2.575330659318801,-0.52528629540264
345.4000000000042,20.50882983406649,2.614705146864238,-0.5479397055273516
346.60000000000423,20.545251551754852,2.656664831337161,-0.5731410756845468
347.8000000000043,20.58239724955874,2.698527905851542,-0.5992900955536333
349.00000000000426,20.619483102994817,2.743420896119163,-0.6265194701137053
350.20000000000425,20.65616810678397,2.791225018454052,-0.653606543531486
351.4000000000043,20.692993733501428,2.8394976706742883,-0.6834534252957827
352.60000000000434,20.730061237026547,2.8931352192126485,-0.7142107010118153
353.80000000000433,20.766812712737575,2.9490432389644514,-0.7477862764063077
355.0000000000043,20.803667432212837,3.0073280674696536,-0.7838511223590912
356.20000000000437,20.840861946737583,3.0740882000526604,-0.8208453314790045
357.4000000000044,20.877745491228087,3.140675395377992,-0.8598446870738004
358.6000000000044,20.91466388276335,3.212797808107179,-0.9020704385287064
359.8000000000044,20.950695878328077,3.2863011253343353,-0.9441153710812973
361.00000000000443,20.988524467712327,3.3628779562233353,-0.9910055174245866
362.2000000000045,21.025697283994553,3.4394106925366708,-1.038271389533417
363.40000000000447,21.06327460449306,3.516372593335914,-1.0882902807732124
364.60000000000446,21.100031848950344,3.58555319556078,-1.1400264347427873
365.8000000000045,21.136859680128783,3.6460944682936955,-1.193146012748271
367.00000000000455,21.173853079773757,3.699702602370612,-1.2482141743606152
368.20000000000454,21.211650203996005,3.742921767433619,-1.307849288158263
369.4000000000045,21.248592780127716,3.76924761907451,-1.3676122143950287
370.60000000000457,21.285650411280322,3.7893486955730795,-1.4282433526300706
371.8000000000046,21.322994775657342,3.7941180061576905,-1.4896751121607243
373.0000000000046,21.360276569644917,3.7884739994068988,-1.5523262279946772
374.2000000000046,21.397327240102506,3.767472321944185,-1.6149848248546683
375.40000000000464,21.43437080918771,3.7275786363188126,-1.6768107977510018
376.6000000000047,21.471528519843226,3.6691088640002523,-1.7379471703586842
377.8000000000047,21.50876994219929,3.5888866969766067,-1.7977527724294329
379.00000000000466,21.545872327091473,3.483156520831822,-1.8560240544887905
380.2000000000047,21.583095521265125,3.358046627514315,-1.91301827042258
381.40000000000475,21.620000306353113,3.2151887497569693,-1.9639305997737986
382.60000000000474,21.656773343304398,3.056449290424334,-2.0127025211510094
383.80000000000473,21.694415940956915,2.885491617818815,-2.05900193560987
385.0000000000048,21.731151281377045,2.7128191938645236,-2.10038852697807
386.2000000000048,21.767995537746067,2.5428221933697754,-2.138051831150751
387.4000000000048,21.804092398722137,2.383791757078862,-2.1705632590371913
388.6000000000048,21.84176021991511,2.227642958750711,-2.1998876182418226
389.80000000000484,21.878699941037382,2.0952633201543245,-2.225760437238642
391.0000000000049,21.915656066074234,1.9774293747855518,-2.247272293293184
392.2000000000049,21.95293842115397,1.8777779522798026,-2.266743229259964
393.40000000000487,21.98948319516129,1.7997999891022372,-2.284836716407194
394.6000000000049,22.026622099890773,1.7365173010272328,-2.3008061866982477
395.80000000000496,22.06336130308093,1.6895664697916548,-2.3144175433147662
397.00000000000495,22.100362025713576,1.6529454325635924,-2.3269126831858005
398.20000000000493,22.137499183038578,1.6248719140843113,-2.339274774915709
399.400000000005,22.174563401830788,1.6051876200331279,-2.35132820589625
400.600000000005,22.211737381639303,1.5922943007414112,-2.363338437645527
401.800000000005,22.248701197045335,1.5836883210403327,-2.3754979341436675
403.000000000005,22.28581652562605,1.5757657432489705,-2.3872759506787773
404.20000000000505,22.322877904900196,1.573895705574133,-2.4000644455849995
405.4000000000051,22.36028136622295,1.571217547080679,-2.4132885372513426
406.6000000000051,22.397373404903206,1.571671241433455,-2.4242818046336705
407.80000000000507,22.433861507320955,1.5727757007934504,-2.4353563501790423
409.0000000000051,22.472077741190382,1.5746177539453472,-2.4479711297447015
410.20000000000516,22.509245807124863,1.5788724935390241,-2.4583527193166432
411.40000000000515,22.54672742868776,1.5794789280730357,-2.469985801798976
412.60000000000514,22.58402654285528,1.5863474608286006,-2.4813055381853273
413.8000000000052,22.62145014494255,1.592978967937433,-2.492468383933711
415.00000000000523,22.65872147351365,1.5961763199067323,-2.5064743963949185
416.2000000000052,22.69636407191277,1.5989786214050172,-2.519175957684967
417.4000000000052,22.73347222618376,1.603163327684135,-2.5307888004284234
418.60000000000525,22.77059141996895,1.610003273803184,-2.543495579369713
419.8000000000053,22.808692397594694,1.6139807194743325,-2.557398322995251
421.0000000000053,22.845939559236484,1.619576461729279,-2.57138074825723
422.2000000000053,22.88355119712002,1.6249389039131268,-2.584044461158796
423.4000000000053,22.921211292923385,1.6317020341987183,-2.5979564652998395
424.60000000000537,22.958357177008665,1.6350816834025317,-2.611994919069803
425.80000000000535,22.995904418393835,1.6412812855238508,-2.625365783063984
427.00000000000534,23.033708434675646,1.6489111997513488,-2.6394840444236385
428.2000000000054,23.0713363100167,1.6539071628012199,-2.657951275615845
429.40000000000543,23.108005725711603,1.6580171928405196,-2.672658982322386
430.6000000000054,23.14649175357031,1.6661838143025633,-2.688678314029656
431.8000000000054,23.18429580171128,1.672874525024986,-2.705072521590476
433.00000000000546,23.221769061568853,1.6821970830746296,-2.722352569198292
434.2000000000055,23.25933350451533,1.688902557576343,-2.7389474964275946
435.4000000000055,23.297221914589127,1.696970267789595,-2.7561531762844425
436.6000000000055,23.334576613565073,1.7043053450205636,-2.7734502006456876
437.8000000000055,23.37254851042248,1.7129599238270388,-2.7930617111212
439.00000000000557,23.409936526314894,1.7176104115662931,-2.8120958684130777
440.20000000000556,23.447829887094677,1.7272888465110299,-2.8317707588565377
441.40000000000555,23.485495983927816,1.7336007962720696,-2.852349534761305
442.6000000000056,23.523353619423066,1.7392687373346267,-2.873145148562151
443.80000000000564,23.560917454225695,1.7458293776232907,-2.8927921098679166
445.0000000000056,23.598632849499833,1.751178450298709,-2.9096691808711768
446.2000000000056,23.636474889229394,1.7548876179214252,-2.930847827889782
447.40000000000566,23.674176577634547,1.7595277365095665,-2.9540280897106372
448.6000000000057,23.712068805517752,1.763879493402059,-2.974137337526541
449.8000000000057,23.749936726013317,1.766695569379024,-2.9929766206651296
451.0000000000057,23.788146671310265,1.7668590738820824,-3.012606825859061
452.20000000000573,23.825324161530773,1.767715074234584,-3.030502446604723
453.4000000000058,23.863538562313686,1.7674106684549968,-3.050068337165695
454.60000000000576,23.901709166434813,1.7671201752499035,-3.067078305954028
455.80000000000575,23.93915816684966,1.7657096052963912,-3.0828765038942776
457.0000000000058,23.977174075021487,1.7617206675438868,-3.0964589236047138
458.20000000000584,24.015058464498246,1.7575462678824059,-3.1113652699881955
459.40000000000583,24.052573593608646,1.7497457589218735,-3.127444166972455
460.6000000000058,24.090954809019635,1.7419486660650128,-3.1402628709120877
461.80000000000587,24.12868670766757,1.7329930618592302,-3.151282709002311
463.0000000000059,24.16663845589823,1.722171213978913,-3.1636081830699165
464.2000000000059,24.204852278810936,1.7090641741553152,-3.1738665385324527
465.4000000000059,24.242457909859553,1.6956218217619328,-3.1843286497406513
466.60000000000593,24.280557570695958,1.6815268978888194,-3.1949364244547387
467.800000000006,24.318679281496756,1.6660326688972609,-3.2038952066322404
469.00000000000597,24.35699616525744,1.6466890344811373,-3.2130564995359454
470.20000000000596,24.394592570573558,1.6266230259247323,-3.2204751100532683
471.400000000006,24.432522701440053,1.6103228744198712,-3.227777259032293
472.60000000000605,24.470448144250966,1.5924543557703055,-3.2340315109660045
473.80000000000604,24.50862395674444,1.5738198415482534,-3.2424757653817617
475.000000000006,24.54664026398179,1.5570473510189458,-3.248210165517519
476.20000000000607,24.584533211934723,1.5379459494338859,-3.254499774881262
477.4000000000061,24.6229246538096,1.5193334222139452,-3.259543095753597
478.6000000000061,24.660944944931003,1.5011306960785957,-3.2650408500912405
479.8000000000061,24.699228207518296,1.4845491049890573,-3.269631712742163
481.00000000000614,24.737073726072197,1.47156488063501,-3.273955230116494
482.2000000000062,24.775401227005126,1.4557770031482145,-3.278920922009407
483.4000000000062,24.81361192913583,1.4438619741221508,-3.2828819416456696
484.60000000000616,24.85184193203404,1.4310328542182742,-3.285487536235955
485.8000000000062,24.889836829891216,1.422330577244485,-3.287934342563356
487.00000000000625,24.92789047645877,1.411592950908354,-3.2918033313465296
488.20000000000624,24.966241656666483,1.4058601264873178,-3.2947143701538817
489.40000000000623,25.004663154786645,1.3960131914826968,-3.297128292989507
490.6000000000063,25.042655024692994,1.3910550288302714,-3.300363423832702
491.8000000000063,25.081011668915643,1.3848598206689835,-3.3028590980488435
493.0000000000063,25.11944832997205,1.3808013925349165,-3.3054986249871776
494.2000000000063,25.157512600392952,1.3763906482378632,-3.3072678009706165
495.40000000000634,25.1957919534926,1.3714298504612559,-3.309953449002805
496.6000000000064,25.23404732774941,1.370791129176688,-3.3117953488767586
497.8000000000064,25.272446052304606,1.3708150643782417,-3.313978263937571
499.00000000000637,25.311180911958594,1.3675796581001503,-3.3170584483165744
500.2000000000064,25.349212134778373,1.3658816511803555,-3.3184482212299495
501.40000000000646,25.387714500284908,1.3665457501428504,-3.319777521953536
502.60000000000645,25.425893198885973,1.3677816868974384,-3.3212064017611436
503.80000000000643,25.464428876596994,1.367102316276834,-3.3227141837370384
505.0000000000065,25.50270247240565,1.3682615448360518,-3.324593009144083
506.2000000000065,25.541090481613875,1.3696759678314943,-3.32709746512423
507.4000000000065,25.57961542669115,1.3709287769286318,-3.327440698504346
508.6000000000065,25.618119187088837,1.3714250351372685,-3.328816262326205
509.80000000000655,25.656772364728095,1.3725606304766071,-3.3310935298356843
511.0000000000066,25.69507095355126,1.3759410498441829,-3.332386052178963
512.2000000000066,25.73336738680597,1.3765054654016904,-3.333817205105435
513.4000000000066,25.772110251271215,1.3773186333714336,-3.335131015324386
514.6000000000066,25.810474597461038,1.3789854105348414,-3.3361133015300926
515.8000000000067,25.849125162246345,1.382294446547315,-3.336099754665859
517.0000000000066,25.887797651255962,1.3864232395749096,-3.3372529484375177
518.2000000000066,25.926085911226934,1.3869762750481565,-3.3375124312313336
519.4000000000067,25.964742523401856,1.389897102673351,-3.338663601559813
520.6000000000067,26.003344315220637,1.3906624353618655,-3.3400482214771374
521.8000000000068,26.041755668440608,1.3925848895153146,-3.340060144101062
523.0000000000067,26.080354770691425,1.3960602537860434,-3.3413728732777916
524.2000000000068,26.119045332913235,1.3983726007500983,-3.3426880444891687
525.4000000000068,26.157771388295085,1.3998031720389787,-3.344002531915854
526.6000000000067,26.196621570856653,1.4016837949017946,-3.3450289612679427
527.8000000000068,26.235099163075336,1.4050444916657003,-3.3452739595176073
529.0000000000068,26.273783473369207,1.4054160435546044,-3.3466176543830377
530.2000000000069,26.312229190577444,1.4101752853527296,-3.346804569448904
531.4000000000069,26.351189993237703,1.4098934911610563,-3.3480262996833567
532.6000000000068,26.389678050431094,1.4142648526210613,-3.349368762061374
533.8000000000069,26.428586221267352,1.416891506155641,-3.3506826434286436
535.0000000000069,26.466821141416386,1.4183606580326924,-3.3521078644950206
536.2000000000069,26.505857422081686,1.419789417831164,-3.3535311077230174
537.4000000000069,26.544676247771307,1.421117342961684,-3.354632071323966
538.600000000007,26.583447301100815,1.423910622339582,-3.355838574593397
539.800000000007,26.622072070873696,1.4263315714642975,-3.355895177421019
541.000000000007,26.66109202971872,1.4278860036358938,-3.3563259475722576
542.200000000007,26.699835582902587,1.4302644199059351,-3.3564867581864286
543.400000000007,26.738757690766956,1.4329430415570945,-3.3574912269112027
544.6000000000071,26.777504052669823,1.4361921664138715,-3.3574430373148423
545.800000000007,26.81618213769999,1.4369084018977074,-3.3599913348152564
547.000000000007,26.8549131915935,1.4407331997174095,-3.360119675211177
548.2000000000071,26.89399076750665,1.4413642661065709,-3.3600811158772377
549.4000000000071,26.9328335581383,1.443387449564706,-3.3614145081838656
550.6000000000072,26.971679046151714,1.4467197362203634,-3.362228462833417
551.8000000000071,27.01068740586424,1.4505424130140598,-3.362755602544434
553.0000000000072,27.049115505692708,1.4498642286049792,-3.362761575338157
554.2000000000072,27.088336016942478,1.4534209193140293,-3.364057829507381
555.4000000000071,27.127221379880528,1.4563128407288302,-3.3640693002314674
556.6000000000072,27.165911885352642,1.4570821918785113,-3.3650272171508373
557.8000000000072,27.20489318729903,1.4583220940431518,-3.36545233593163
559.0000000000073,27.243887089718303,1.4608107390753766,-3.3667202544371384
560.2000000000073,27.282655610512492,1.4635736092698683,-3.367321730405507
561.4000000000073,27.321491766856546,1.4643429276302011,-3.3686760153400956
562.6000000000073,27.360357413573364,1.4672259920368265,-3.3699893463425914
563.8000000000073,27.399271050230002,1.4705775771161362,-3.371311020280879
565.0000000000073,27.438238884987452,1.471292023104183,-3.3713099889796747
566.2000000000073,27.477354868574768,1.4761660476370129,-3.371304099326631
567.4000000000074,27.516258192655762,1.475162419419552,-3.372610430793684
568.6000000000074,27.555192514814443,1.4794492788705813,-3.3725306530014203
569.8000000000075,27.59421431822498,1.4816341558096215,-3.3739485140453302
571.0000000000074,27.633314669664344,1.4835934510201696,-3.3739513157431382
572.2000000000074,27.67251555660666,1.4850676954391315,-3.374145054363775
573.4000000000075,27.711514845392138,1.4902890294112845,-3.3752604881790864
574.6000000000074,27.75028974521648,1.4895259499559783,-3.3752699451044004
575.8000000000075,27.78979732737247,1.4941591744496963,-3.376579856829996
577.0000000000075,27.82856691886225,1.497578068948923,-3.377918651802929
578.2000000000075,27.867436712596245,1.5003058168455436,-3.3778903975869747
579.4000000000076,27.906746348431646,1.5028442376988445,-3.3780021088223835
580.6000000000075,27.945778188015183,1.5064912369814436,-3.379340059571534
581.8000000000076,27.985127112141043,1.5060241992307795,-3.3806893752518103
583.0000000000076,28.023085691891637,1.5103233734265051,-3.3809699265769804
584.2000000000075,28.063358729299313,1.5123775644279749,-3.3819600135722534
585.4000000000076,28.102530204702077,1.5163864266688338,-3.382598130102788
586.6000000000076,28.141497097824487,1.5185717650291566,-3.3825851609962614
587.8000000000077,28.180561665520568,1.5226009445272606,-3.3839173873002126
589.0000000000077,28.21986811320683,1.5247497265325787,-3.385235833364798
590.2000000000077,28.259061612195406,1.5283493312272507,-3.3852404825400666
591.4000000000077,28.29827079117862,1.533171266406637,-3.3865642632588204
592.6000000000078,28.337355457949574,1.5369872529453878,-3.387865829309174
593.8000000000077,28.376323503392182,1.5400634196650076,-3.389014632198099
595.0000000000077,28.415600077393194,1.5426896264636791,-3.3891958841598555
596.2000000000078,28.454810925432366,1.548305072781818,-3.3891123130989125
597.4000000000078,28.49400600903457,1.5519016553030918,-3.3892018172635323
598.6000000000079,28.53345765132765,1.5527413067737879,-3.390507108163491
599.8000000000078,28.57243477113197,1.5594384174079414,-3.39050021335611
601.0000000000078,28.611548866136246,1.5625437340642976,-3.390498151671453
602.2000000000079,28.651086921639077,1.5691075805857202,-3.39180692548213
603.4000000000078,28.690392634742807,1.5737705197289358,-3.3918428879640135
604.6000000000079,28.729534574493506,1.5796525606697769,-3.3931297559054334
605.8000000000079,28.768821841315287,1.584966564000726,-3.393130012322608
607.000000000008,28.808018850849464,1.5893902266267195,-3.393151935441797
608.200000000008,28.847607241361654,1.5920979015815142,-3.3931716681976583
609.4000000000079,28.886876370010565,1.5969032545977935,-3.3938033230599416
610.600000000008,28.92633759509448,1.6004409179525472,-3.396982048802837
611.800000000008,28.96574658679026,1.6018547365932339,-3.3984042629743865
613.000000000008,29.005219684284782,1.6060952804855053,-3.3991005509775554
614.200000000008,29.044581162132516,1.608191504411762,-3.4008251309732733
615.400000000008,29.08382713779383,1.6110769785221186,-3.401947284187271
616.6000000000081,29.12322726445047,1.6155917820229349,-3.4033670464816415
617.8000000000081,29.16239923129224,1.6190942536123247,-3.4053380912304756
619.0000000000081,29.202205762202578,1.623048113503351,-3.4052135228133995
620.2000000000081,29.241467179245053,1.6284863288163418,-3.406090074499612
621.4000000000082,29.28083199030922,1.6352375786356927,-3.4074020120510182
622.6000000000081,29.320164042101812,1.6390976189188802,-3.4087174576179335
623.8000000000081,29.35969802613374,1.6413425888621869,-3.4093450966027006
625.0000000000082,29.399131718881026,1.6449919037640592,-3.409987992019032
626.2000000000082,29.43847453256536,1.6474009048571332,-3.4113605181432654
627.4000000000083,29.478155984212442,1.6519705137769205,-3.412687748730353
628.6000000000082,29.51766535009748,1.655575518452128,-3.4131296245546796
629.8000000000083,29.556974808890345,1.6569605193696681,-3.4139820800094154
631.0000000000083,29.59676203676402,1.6604820083910674,-3.4139940499588364
632.2000000000082,29.635782059170516,1.6624077590501891,-3.4153469636140885
633.4000000000083,29.675538226802388,1.6660787961489214,-3.4156023652100984
634.6000000000083,29.71506917682826,1.6711258373340847,-3.416613758638986
635.8000000000084,29.75480534329946,1.6718918202434563,-3.417501840585317
637.0000000000084,29.794196798893164,1.675717072886418,-3.4179201327678346
638.2000000000083,29.83358874406546,1.6801848274621045,-3.417945821331002
639.4000000000084,29.873242544950596,1.6820373751262223,-3.4166091612897467
640.6000000000084,29.912722502967135,1.6843355516352456,-3.4166100663158936
641.8000000000084,29.95161566355255,1.6907071165750371,-3.416608601653633
643.0000000000084,29.99124641836987,1.6918878827403305,-3.417915310303873
644.2000000000085,30.031389665049073,1.6971308529566864,-3.4179303648103483
645.4000000000085,30.070766341029866,1.6978582378903229,-3.419285210565275
646.6000000000085,30.110657197848866,1.7019985247601312,-3.419244180044651
647.8000000000085,30.15013192351978,1.7050382497737706,-3.420558979752748
649.0000000000085,30.189504933720468,1.7085583365253938,-3.420566984387562
650.2000000000086,30.229269607841417,1.7127069732921705,-3.4218807850562127
651.4000000000085,30.26901375613268,1.7182806773712493,-3.421879815837903
652.6000000000085,30.30878978551013,1.7240560737072737,-3.4218795159490014
653.8000000000086,30.34821975975243,1.725365193516418,-3.423074888802156
655.0000000000086,30.38767912100844,1.7268358952255598,-3.423199178404097
656.2000000000087,30.42762031927461,1.731678951467391,-3.4232000236270475
657.4000000000086,30.46750082103092,1.7391403997843344,-3.4232515409591713
658.6000000000087,30.507105666718715,1.7414755223349803,-3.421791921694399
659.8000000000087,30.54654807777084,1.7450822386959224,-3.4231822844357964
661.0000000000086,30.586303603461158,1.749629670872931,-3.424471488899277
662.2000000000087,30.62542169975404,1.7546302461162162,-3.4245100997435878
663.4000000000087,30.66566056862927,1.7603965900728198,-3.42452461190564
664.6000000000088,30.705073393084746,1.7649205294819679,-3.4258643780440856
665.8000000000088,30.745155256314565,1.7704990849652988,-3.4258203279193835
667.0000000000088,30.784470083888014,1.7753500896291998,-3.425820119804032
668.2000000000088,30.824025359931245,1.7802968432618265,-3.4258217127149324
669.4000000000088,30.86397049241563,1.7858169877941292,-3.426166476613665
670.6000000000088,30.90383078663695,1.7888064034298792,-3.428461296351305
671.8000000000088,30.94276879238377,1.796106901475341,-3.4284600754631454
673.0000000000089,30.98304551117095,1.8010117195939173,-3.427279598420776
674.2000000000089,31.02274144060761,1.806594770076479,-3.4284636402870636
675.400000000009,31.06238619432156,1.8104762148955171,-3.428460116516335
676.6000000000089,31.102129723326026,1.8187564503971891,-3.4284601000810406
677.8000000000089,31.14178858990068,1.8214571902705488,-3.428460099317118
679.000000000009,31.181865297523153,1.826590910346118,-3.4284599666309457
680.2000000000089,31.2212106981817,1.8293972844951187,-3.4289026208827167
681.400000000009,31.2608947087187,1.8365700726490863,-3.4297691791530913
682.600000000009,31.300822025284745,1.841736406557288,-3.4297643934234876
683.800000000009,31.340165374725682,1.84538267205175,-3.4284543191900774
685.0000000000091,31.380191680817898,1.8534228806119146,-3.429456171370839
686.200000000009,31.42016170188073,1.8572542045381708,-3.4297704727909277
687.4000000000091,31.45959783368537,1.8631886867615304,-3.4310882957302593
688.6000000000091,31.49910311771975,1.8684879376314076,-3.431102946124601
689.800000000009,31.53962992009024,1.875071606081268,-3.433392931775889
691.0000000000091,31.579153790613134,1.879231097935274,-3.433719975684375
692.2000000000091,31.619176244923658,1.8861739169583414,-3.433731145186444
693.4000000000092,31.65912200702581,1.8888858289995925,-3.4350410700661858
694.6000000000092,31.698672709599663,1.895910729518644,-3.4350398906602866
695.8000000000092,31.738420552294354,1.901692938634081,-3.434969434848762
697.0000000000092,31.778277840753987,1.9078000915987343,-3.435026433587938
698.2000000000093,31.818164714618035,1.9112964859740413,-3.435030135776231
699.4000000000092,31.857685328250152,1.9180226973512036,-3.4350301399159493
700.6000000000092,31.89780481293949,1.9228415804057122,-3.4350301291218734
701.8000000000093,31.937710566811358,1.9290956076817658,-3.4350279003315514
703.0000000000093,31.97758546696486,1.9343449302093672,-3.4353772653127663
704.2000000000094,32.01757777768364,1.9382957356974817,-3.4353602603286535
705.4000000000093,32.057253226611174,1.9436938751367325,-3.435355900277431
706.6000000000093,32.09710571414971,1.9486312603004587,-3.4363052789622763
707.8000000000094,32.137116738030166,1.9543766731514796,-3.4357010542493
709.0000000000093,32.176732250473634,1.9593582841309445,-3.4357148628369467
710.2000000000094,32.216780164409364,1.9654782521460321,-3.4370547314487947
711.4000000000094,32.256398776311194,1.9705677836372113,-3.437020324993023
712.6000000000095,32.2964193080218,1.9751775585217657,-3.437020130993603
713.8000000000095,32.33626697505414,1.9811341114680643,-3.4370201300079564
715.0000000000094,32.376325266021595,1.9847347656634053,-3.437020131328647
716.2000000000095,32.41610955553426,1.990554208658614,-3.437022465214241
717.4000000000095,32.45624970254427,1.9970674103147483,-3.4363727921929925
718.6000000000095,32.49589751751486,2.0017519687368415,-3.4374614057958053
719.8000000000095,32.53585207818443,2.006331542211879,-3.43667908775095
721.0000000000095,32.575728666640686,2.012423771089859,-3.437429093886167
722.2000000000096,32.615659046805064,2.016224927907136,-3.4376782665293897
723.4000000000096,32.655819154375116,2.0240627007287952,-3.4380069440600876
724.6000000000096,32.69548467419501,2.028723326212615,-3.4393535392076955
725.8000000000096,32.73536881202278,2.036146768602238,-3.43931003337979
727.0000000000097,32.775653627143804,2.04041506802768,-3.439309821002453
728.2000000000096,32.81545056669148,2.0452282197170377,-3.4393098004587044
729.4000000000096,32.85553901154201,2.0521811212964156,-3.4393061868103842
730.6000000000097,32.895455356045936,2.058095763317863,-3.4403976942949805
731.8000000000097,32.935531187030435,2.060771318155238,-3.440625368531787
733.0000000000098,32.97525721695024,2.0673699998480313,-3.441703950959501
734.2000000000097,33.01544339218141,2.0731294543750867,-3.4419488730509515
735.4000000000098,33.055246669318535,2.0792574757745124,-3.4419497844010505
736.6000000000098,33.095477154542415,2.086984560922887,-3.4419457237715796
737.8000000000097,33.134955899111155,2.0909536179546624,-3.443234135155574
739.0000000000098,33.17537644169613,2.097893065106325,-3.4432600128726896
740.2000000000098,33.21539781141816,2.1038413983878423,-3.4429533877407037
741.4000000000099,33.25516662212188,2.1060881529242224,-3.442930145449543
742.6000000000099,33.29528874571471,2.112985427256145,-3.44233164904558
743.8000000000098,33.33525426923482,2.1189829333444297,-3.4425063598369734
745.0000000000099,33.37553432636917,2.12629395351858,-3.442939251732584
746.2000000000099,33.41547765709338,2.1323541980109293,-3.4432354122853077
747.4000000000099,33.455305709582596,2.136347447281507,-3.4442635243314235
748.6000000000099,33.49535886149926,2.1426229197320437,-3.444260177495663
749.80000000001,33.53537614065363,2.1487071965643625,-3.4442601600872464
751.00000000001,33.5758781675289,2.1524731069757177,-3.4442601585362276
752.20000000001,33.615757194564516,2.1598806320467747,-3.4442598567998752
753.40000000001,33.6556258793787,2.16410604476117,-3.444916201574146
754.60000000001,33.69578697171732,2.172267199110343,-3.4468696444624087
755.8000000000101,33.73559579353323,2.178311115989609,-3.4455751770405025
757.00000000001,33.77566557451117,2.18485721390748,-3.445570112376292
758.20000000001,33.815831032567814,2.192084582665773,-3.4455701098221505
759.4000000000101,33.85601461041135,2.1966361582527245,-3.4455700725589176
760.6000000000101,33.89612668121579,2.2033212464290295,-3.4455630523889513
761.8000000000102,33.936169130336154,2.208975464866408,-3.44685448449539
763.0000000000101,33.97635914148718,2.216814920609422,-3.4468898249437223
764.2000000000102,34.01597920035658,2.2224141927869767,-3.446891923322136
765.4000000000102,34.05668966659849,2.228500683901825,-3.447547473591986
766.6000000000101,34.09637529137796,2.233841028957567,-3.448200445379588
767.8000000000102,34.136946384827894,2.242057851768411,-3.4472790464498355
769.0000000000102,34.177008407163,2.2485509787236215,-3.448230821038967
770.2000000000103,34.21720812927644,2.253089049786596,-3.4482001930544444
771.4000000000103,34.25744720736835,2.261860985060732,-3.4481989051147903
772.6000000000103,34.29769164928797,2.268415823167375,-3.449075192424309
773.8000000000103,34.33791589135723,2.277047358870759,-3.4500669442006724
775.0000000000103,34.377825889891646,2.2818647869247473,-3.45018017365144
776.2000000000103,34.41824843073263,2.2892818818990754,-3.4501800705429324
777.4000000000103,34.45818007173205,2.29739733971089,-3.4501698284354934
778.6000000000104,34.49855606575243,2.3052788451050388,-3.449189326086285
779.8000000000104,34.538496326424315,2.3105654145881145,-3.4491976120738164
781.0000000000105,34.57886928034964,2.3176666926546394,-3.4504114420174785
782.2000000000104,34.61919878322932,2.323901575316258,-3.452188261352218
783.4000000000104,34.659455044278346,2.332950045544761,-3.4525939769217002
784.6000000000105,34.69966102305673,2.340148680615873,-3.453103645912935
785.8000000000104,34.739839497432044,2.346163756932034,-3.452590026624346
787.0000000000105,34.78006798691119,2.3553574637912718,-3.452590069966316
788.2000000000105,34.82065475827491,2.360961073597589,-3.452590069999342
789.4000000000106,34.86069885339791,2.3696750079991316,-3.4525900700039482
790.6000000000106,34.901076007286754,2.3768570159764484,-3.4525900712135695
791.8000000000105,34.94121974752805,2.3831065108684846,-3.4525903407460383
793.0000000000106,34.98155518222172,2.3914749266292143,-3.4526596311921534