File: 01_Data/Cotton_Rug/STA/N2/30K_min/Cotton_Rug_STA_N2_30KData_220113_R2.csv
##Temp./Â°C,Time/min,DSC/(mW/mg),Mass loss/mg
49.0,10.534877564194161,-0.920077317829342,-0.0012894947365253984
50.20000000000002,10.73200838854089,-0.7723459277531491,-0.002360235093696872
51.400000000000034,10.861172274696223,-0.6612760146881747,-0.002998676980784154
52.60000000000005,10.961829995837558,-0.5673478145449865,-0.0025910941843179103
53.80000000000007,11.047122645220565,-0.48946372994075943,-0.004500085340939819
55.000000000000085,11.122822544116588,-0.417584947938687,-0.0032621223399003085
56.2000000000001,11.193941976155525,-0.3515410375563371,-0.0025307917968921956
57.40000000000012,11.259709383739859,-0.2929013748936769,-0.0032963040604867544
58.600000000000136,11.321410271069444,-0.2371361287200343,-0.005370397094775825
59.80000000000015,11.381005827808735,-0.1847682698366176,-0.0039722032461035894
61.00000000000017,11.43714162546556,-0.13455717420238753,-0.004215613637404303
62.20000000000019,11.49231574710121,-0.08866237381528158,-0.0034313368767264762
63.400000000000205,11.544930532032161,-0.04401278530296118,-0.0030546767586914214
64.60000000000022,11.596130528008093,-0.004484004262866436,-0.004053768091299759
65.80000000000024,11.646201905781496,0.03351034600123252,-0.004288206596112509
67.00000000000026,11.696041206474412,0.07305268824624539,-0.0041461334617682866
68.20000000000027,11.744355248486096,0.10879117759825087,-0.004084594647036255
69.40000000000029,11.79239710351309,0.14291753183251857,-0.004288465100330541
70.6000000000003,11.839049294958762,0.17430499952945902,-0.004476166547862981
71.80000000000032,11.885362242372585,0.20299648779985413,-0.0032557919265920887
73.00000000000034,11.931625653860157,0.2289937457330378,-0.0030959752293870935
74.20000000000036,11.976613010165211,0.252112297440832,-0.002799985836229979
75.40000000000038,12.022089410811546,0.2766118896997749,-0.0044296951832674125
76.60000000000039,12.06568245338127,0.2959205161340721,-0.0037261284851135557
77.80000000000041,12.11071708098405,0.3186186593700342,-0.004030608163414051
79.00000000000043,12.154656857175071,0.3379330325775456,-0.004534457531656599
80.20000000000044,12.197944624349967,0.35795716702743063,-0.004274179354479379
81.40000000000046,12.241349915226808,0.3779132767153873,-0.004442761738816081
82.60000000000048,12.284659804586381,0.39658885062884397,-0.004428251116163295
83.8000000000005,12.3271874234999,0.41482022116827444,-0.004639530754487531
85.00000000000051,12.369550965665619,0.4338757156384506,-0.006072925754855518
86.20000000000053,12.41088177134809,0.45239306624205,-0.005208888364378161
87.40000000000055,12.454257185033434,0.4709377048019147,-0.004819590420456876
88.60000000000056,12.496264808329453,0.4899854552891117,-0.006054580822594247
89.80000000000058,12.538231266284201,0.5072662560806908,-0.006268717200997642
91.0000000000006,12.579484156340625,0.5235670723275889,-0.00586990378978669
92.20000000000061,12.621000979121185,0.5425178644581918,-0.005484695736346801
93.40000000000063,12.661889562891552,0.5600352112758316,-0.006479923769275864
94.60000000000065,12.703236765379751,0.5766384375288854,-0.0063575598518346155
95.80000000000067,12.744318883389079,0.591677348443121,-0.007513518079932169
97.00000000000068,12.78538700735126,0.6092550566086743,-0.006424410770424771
98.2000000000007,12.826268982302487,0.6246502697684037,-0.006359777677569234
99.40000000000072,12.867293726940304,0.6405468146539768,-0.0077912060097817815
100.60000000000073,12.907734540136444,0.6575796847818035,-0.008315978935898194
101.80000000000075,12.948299860447719,0.673568233700368,-0.007779216022520963
103.00000000000077,12.988969648772635,0.6882900401559127,-0.007778862086346372
104.20000000000078,13.029907357436207,0.7019964782236713,-0.007827551472006533
105.4000000000008,13.070417986239242,0.7168465963767036,-0.007752633860642177
106.60000000000082,13.110635298714257,0.7316349070657504,-0.00913302083172507
107.80000000000084,13.150878412771805,0.746130983779878,-0.009110183061396881
109.00000000000085,13.191901175952841,0.7588191204197143,-0.009713237157229493
110.20000000000087,13.23212895134429,0.7737098187685404,-0.010420153014893963
111.40000000000089,13.272207359584261,0.7863663118809341,-0.010420153105667573
112.6000000000009,13.31221201407682,0.8000623281994802,-0.010420174324846432
113.80000000000092,13.352550712092446,0.813259993698615,-0.010419270838788464
115.00000000000094,13.392841970597642,0.8254832064061911,-0.010522370072784781
116.20000000000095,13.432833102738265,0.8386199452034745,-0.010410189223331479
117.40000000000097,13.473097709334393,0.8511477261429208,-0.010405582918585399
118.60000000000099,13.512748550736104,0.8639995660528079,-0.011730888157727826
119.800000000001,13.552235297001868,0.8755939890509244,-0.011730063075954256
121.00000000000102,13.592574876249055,0.8876935368770398,-0.011731467522479111
122.20000000000104,13.63248627354537,0.8996244150506068,-0.013082098423208066
123.40000000000106,13.671604416714576,0.9111057065132969,-0.011753794251029959
124.60000000000107,13.71182163012287,0.9225687246457392,-0.011740071044183509
125.80000000000109,13.751049817503764,0.934113984686862,-0.011739994337841786
127.00000000000111,13.790250778043928,0.9455422047869431,-0.011739993996767062
128.20000000000113,13.829992645330767,0.956036500144963,-0.011739978646346572
129.40000000000114,13.869170333244183,0.9661300728284437,-0.011690775425134081
130.60000000000116,13.908595567253709,0.9791470050179153,-0.013049666474294508
131.80000000000118,13.94745131768314,0.9903062811241188,-0.0133725025321767
133.0000000000012,13.986792311769959,1.0005423954480694,-0.01337652325323857
134.2000000000012,14.025804062239544,1.0117457934681853,-0.01436958982195291
135.40000000000123,14.064851599374784,1.024308587444898,-0.013459226927186485
136.60000000000124,14.10355464367385,1.0354415678022202,-0.013380701542171636
137.80000000000126,14.142500246682296,1.0483575148908373,-0.014694865784185662
139.00000000000128,14.180905479124686,1.0588468828716155,-0.014696559129105058
140.2000000000013,14.219741755306924,1.0721740315893509,-0.014373012783016392
141.4000000000013,14.258299363535565,1.0823202131642087,-0.014396041420662975
142.60000000000133,14.29733294921195,1.0965383814368,-0.01534988452196151
143.80000000000135,14.335785142165681,1.1096614442102697,-0.015350451508840735
145.00000000000136,14.37401354168507,1.119722914740843,-0.014513744674763185
146.20000000000138,14.41201974175649,1.1337984310858507,-0.012892740799729907
147.4000000000014,14.450386023154383,1.1448367954373002,-0.012729850933315134
148.60000000000142,14.488692125961727,1.157880493196683,-0.01272983497791591
149.80000000000143,14.52716143089971,1.1704380140943735,-0.012729834999627876
151.00000000000145,14.565432197922123,1.1841793599672257,-0.012729834997647682
152.20000000000147,14.603343147635451,1.196154970775602,-0.012729834768658854
153.40000000000148,14.641577645029185,1.208806417139923,-0.012737196039638743
154.6000000000015,14.679463294980106,1.222890960839177,-0.013713683578385094
155.80000000000152,14.717561542162786,1.2345625612216578,-0.014042964702333904
157.00000000000153,14.755974140355613,1.2486888623239831,-0.014039822501713317
158.20000000000155,14.793618026259756,1.2607018959838325,-0.014039688078927082
159.40000000000157,14.831652227828394,1.2747901102693895,-0.014004878535417653
160.6000000000016,14.869714312743737,1.2881673572631598,-0.014038705245353889
161.8000000000016,14.90725840311556,1.2966822278835848,-0.014040194951717488
163.00000000000162,14.945097213438803,1.309284594397654,-0.014040144528901788
164.20000000000164,14.98255999827461,1.3214574342895822,-0.014040144003514055
165.40000000000165,15.020548760831298,1.3342834875654879,-0.01404014400001019
166.60000000000167,15.058101703676527,1.3458009156093287,-0.014040144000001309
167.8000000000017,15.096233947253337,1.3589922379522175,-0.014040143999999533
169.0000000000017,15.133629186415302,1.3716843536427628,-0.014040143999998644
170.20000000000172,15.171307351154404,1.3848756773221496,-0.014040143999989763
171.40000000000174,15.20904441884743,1.3966079116227665,-0.01404014400007414
172.60000000000176,15.246247695569393,1.4096574401283806,-0.014040144190601733
173.80000000000177,15.283866749210446,1.4221002657949147,-0.014040178980516682
175.0000000000018,15.32153119699609,1.4330957145174676,-0.014043693464819373
176.2000000000018,15.358923288170477,1.4449182587433467,-0.01306617182541503
177.40000000000182,15.396438148348107,1.457467712464771,-0.013051208304934558
178.60000000000184,15.433561637706328,1.4695001391985698,-0.013050086246355175
179.80000000000186,15.470857342327681,1.4817041563717763,-0.013050182972833557
181.00000000000188,15.508252244386435,1.4912681486794939,-0.01438560970802838
182.2000000000019,15.545193552363166,1.5024516915579795,-0.014314469722358059
183.4000000000019,15.582457132003809,1.5155695710311117,-0.015676391306778115
184.60000000000193,15.619620731992162,1.5258361042226551,-0.015690401465005444
185.80000000000194,15.656724454476159,1.5386442224261674,-0.015234021415098553
187.00000000000196,15.693872676106581,1.5491260907868005,-0.012998549805918636
188.20000000000198,15.730408386720198,1.5595281445562066,-0.013050602669700151
189.400000000002,15.767675821917749,1.5700871602623945,-0.014261950617489472
190.600000000002,15.804337173800736,1.581607929140017,-0.015361368000898601
191.80000000000203,15.841429845735455,1.5939034173559223,-0.015360159206197377
193.00000000000205,15.878443932803979,1.6033325280372241,-0.015361085988216061
194.20000000000206,15.915092929182435,1.6151071934765389,-0.015198044059516302
195.40000000000208,15.951717551953326,1.6243220732307355,-0.015359958817465547
196.6000000000021,15.989169691346067,1.6370898766697717,-0.01536014405962316
197.80000000000211,16.025682088831115,1.6466542576148069,-0.015360144012796617
199.00000000000213,16.0628752783022,1.6569223173944405,-0.015360143995341247
200.20000000000215,16.09926077705323,1.6681069518643525,-0.015360143980644558
201.40000000000217,16.135897980538694,1.6787365010564494,-0.015360217837446122
202.60000000000218,16.172720283004082,1.6891221568487347,-0.015369820226244002
203.8000000000022,16.209388047235777,1.700369552545429,-0.016686379727667067
205.00000000000222,16.246031178511767,1.7114530374861832,-0.016679143259509033
206.20000000000223,16.28270046753934,1.7220190684467516,-0.016679829656113476
207.40000000000225,16.31950644422326,1.732139312183389,-0.016679834994851817
208.60000000000227,16.356137586009428,1.743708107710898,-0.01667983504675785
209.80000000000229,16.39285533927552,1.7563029985089718,-0.01667984210962281
211.0000000000023,16.429386589895074,1.7700572422670235,-0.016679901448529044
212.20000000000232,16.466076212707097,1.7805231991218857,-0.01658441219643425
213.40000000000234,16.50284360757695,1.7914351179239152,-0.01798860992228679
214.60000000000235,16.53951532159729,1.8018821715825963,-0.017989900659492797
215.80000000000237,16.57604363679954,1.814514406448154,-0.017989902107111266
217.0000000000024,16.612373903946583,1.8240493262623438,-0.017989904158137282
218.2000000000024,16.649170000000076,1.834850000000021,-0.017990151333928228
219.40000000000242,16.685735861495345,1.845916083135668,-0.017314654109241268
220.60000000000244,16.722177813749457,1.8554886493171001,-0.01700021738485935
221.80000000000246,16.75890384068048,1.865248832292104,-0.018829256864345556
223.00000000000247,16.795095477876934,1.8750999437972762,-0.02086216123718465
224.2000000000025,16.831617060034237,1.883609804012505,-0.01935396362399766
225.4000000000025,16.86838773824015,1.8948203843611098,-0.0193052701545251
226.60000000000252,16.90489005286117,1.9061958377540664,-0.018324426274298755
227.80000000000254,16.941088288725492,1.9167565042220498,-0.01883213240007109
229.00000000000256,16.977215715237463,1.9271371256080863,-0.01963270503680592
230.20000000000258,17.014020657266197,1.9397066857776597,-0.019630100823433416
231.4000000000026,17.050413890383975,1.953217252312436,-0.019630321136510087
232.6000000000026,17.08678110438752,1.9657565484013388,-0.019605971732122196
233.80000000000263,17.123306523081542,1.9789880702394878,-0.022247300017091742
235.00000000000264,17.159821876075437,1.9922918030766572,-0.02226012820446055
236.20000000000266,17.19628910345244,2.0086877429113406,-0.022260293929145192
237.40000000000268,17.23263017516441,2.026742796806152,-0.022279039651145194
238.6000000000027,17.26880822315287,2.0477609311191647,-0.023578465273066396
239.8000000000027,17.305106462412056,2.073788002860011,-0.023579712641418116
241.00000000000273,17.341679288208734,2.102258007896654,-0.023576423500657473
242.20000000000275,17.37804766424918,2.1343180774002146,-0.024456090489069826
243.40000000000276,17.414261245176096,2.1689454787855476,-0.024890285634582288
244.60000000000278,17.45049323317939,2.20459021356149,-0.02488849623143219
245.8000000000028,17.48706490010342,2.241315192628746,-0.02625316901463437
247.0000000000028,17.523587518331876,2.289120739659212,-0.026204281973929877
248.20000000000283,17.559871664272183,2.3571505540073736,-0.027254761016261675
249.40000000000285,17.596275869098285,2.4425849263519983,-0.02743918094333564
250.60000000000286,17.632597738610578,2.5360878940305573,-0.028839165706926906
251.80000000000288,17.668722950282604,2.6209590746924256,-0.027469767828113056
253.0000000000029,17.705504284816442,2.6912808654399645,-0.028841426085543187
254.20000000000292,17.742001966927525,2.728717390947861,-0.029074241476829688
255.40000000000293,17.77825005906248,2.7217614680490714,-0.03015970919233535
256.600000000003,17.81459894717342,2.6710790655576044,-0.03015296627489983
257.80000000000297,17.851078466074956,2.597935558780517,-0.031280207573775254
259.00000000000296,17.887510701918554,2.5213421551372597,-0.03213591198755017
260.200000000003,17.923557320040235,2.4575067084712283,-0.03293118001758444
261.40000000000305,17.960022403466425,2.4033055107764367,-0.03345825192915086
262.60000000000304,17.995943638704542,2.363814285896597,-0.03411103212495492
263.800000000003,18.031965313970165,2.3331636587985343,-0.03510511680165873
265.00000000000307,18.068482419082333,2.307210641487639,-0.03658282638456267
266.2000000000031,18.104466650599505,2.2902407103996048,-0.03823846841236822
267.4000000000031,18.14065752928146,2.2784262539696916,-0.039518771206431325
268.6000000000031,18.176867392481707,2.269120628159929,-0.040293819007500176
269.80000000000314,18.213240784679698,2.2635443173873155,-0.04200398342928491
271.0000000000032,18.2492585289603,2.2628356132941705,-0.044437941008129034
272.2000000000032,18.28539496836586,2.2616375457265665,-0.04585676936535421
273.40000000000316,18.321797441841284,2.262608480939502,-0.04641428813482218
274.6000000000032,18.357782626793966,2.266638097844425,-0.049995412893497626
275.80000000000325,18.394224858016003,2.27031734104016,-0.05168124412869535
277.00000000000324,18.43036153719165,2.2760744073262322,-0.053082167218457155
278.20000000000323,18.46644966304247,2.281093077736187,-0.055756507865534655
279.4000000000033,18.50256180388829,2.287612173438575,-0.058351542687347546
280.6000000000033,18.538718356748124,2.294895606714587,-0.060496555151525744
281.8000000000033,18.57530644031945,2.3022512995191815,-0.06267975372095158
283.0000000000033,18.61131739814207,2.310724811879715,-0.06292297782194822
284.20000000000334,18.647731520820194,2.3178464199284,-0.06489802907014264
285.4000000000034,18.684065035371695,2.325472430917551,-0.06762802586209427
286.6000000000034,18.720329600714884,2.33462499076581,-0.07032351986540286
287.80000000000337,18.756582369794415,2.3430871176743593,-0.07413967200319771
289.0000000000034,18.792742680152237,2.3524089181823338,-0.07748570934227805
290.20000000000346,18.829077620752333,2.3617602797288075,-0.08006010181195933
291.40000000000344,18.865527863717332,2.372204721927575,-0.08374034251154061
292.60000000000343,18.901895345377113,2.3822802476620564,-0.08803845759259232
293.8000000000035,18.93807369867809,2.3937900947900124,-0.09174653687898537
295.0000000000035,18.974261337156392,2.4048797154643475,-0.09507071172451864
296.2000000000035,19.010863540033295,2.4183079928747513,-0.0990909956503323
297.4000000000035,19.047137615302425,2.431127722041221,-0.10328740149717763
298.60000000000355,19.083406052235727,2.4425792907505843,-0.10792373403940436
299.8000000000036,19.11965499887596,2.454503898532279,-0.11214571428797626
301.0000000000036,19.155950731670327,2.467768536873485,-0.11607647356262518
302.20000000000357,19.192568351144313,2.4797076955784165,-0.1222118397843559
303.4000000000036,19.22862868606115,2.492800550982782,-0.12704559213390443
304.60000000000366,19.265171435254747,2.507018331943042,-0.13224837935228395
305.80000000000365,19.301795870646522,2.518105724124517,-0.13839346101843653
307.00000000000364,19.33798816980888,2.5310552007098357,-0.14534696533568292
308.2000000000037,19.374531294852943,2.5453043867130036,-0.1506266582651734
309.40000000000373,19.41082312104899,2.557955161807141,-0.15749062017287851
310.6000000000037,19.447287058103864,2.571092588530876,-0.1653158950583924
311.8000000000037,19.48379280851338,2.5837563699793624,-0.1714677628650918
313.00000000000375,19.520179868883528,2.5963001995072306,-0.17829958556853764
314.2000000000038,19.556592795301366,2.6082271476875256,-0.18642987053506177
315.4000000000038,19.593246783468537,2.618936868513833,-0.1954937599784623
316.6000000000038,19.629858346387508,2.630883054996407,-0.2038301026432756
317.8000000000038,19.666367447605523,2.6438444126176166,-0.21292234078552186
319.00000000000387,19.70274194894294,2.655580090900104,-0.22240196506879784
320.20000000000385,19.7391388895293,2.6656595540802748,-0.23209099236814223
321.40000000000384,19.775971403529166,2.676351336230247,-0.2437008845915143
322.6000000000039,19.81228328796397,2.686603761366378,-0.25270950608631804
323.80000000000393,19.848897970846423,2.695663069881631,-0.263136313749992
325.0000000000039,19.88571383614195,2.7065851945800024,-0.2751120030134473
326.2000000000039,19.92214859337846,2.7163656179979956,-0.28719963503661283
327.40000000000396,19.958862548530757,2.7259440684611924,-0.2984790852806092
328.600000000004,19.99533945036232,2.7365486710482285,-0.30863091087259864
329.800000000004,20.03169995043627,2.7469853763138774,-0.3219182779352714
331.000000000004,20.068237365607903,2.761208799664578,-0.33709593434217355
332.200000000004,20.10494815640489,2.775022516262406,-0.35215505765302835
333.40000000000407,20.141822077235375,2.791799444569812,-0.3671655921825874
334.60000000000406,20.1787445605396,2.8107195510806107,-0.38205171292496276
335.80000000000405,20.21489195370412,2.8292436351467405,-0.39849899498931496
337.0000000000041,20.25171646709616,2.8524361792437944,-0.41508975717175156
338.20000000000414,20.288449716364966,2.8778275306453365,-0.4318626908364487
339.4000000000041,20.325254107647446,2.903731835370949,-0.45032559197198996
340.6000000000041,20.362048950303766,2.9308210172654294,-0.4692154263735886
341.80000000000416,20.39847531866233,2.960002084434982,-0.4898959432777761
343.0000000000042,20.43570982119713,2.9927664100634637,-0.5113549895717213
344.2000000000042,20.472265805707274,3.0213801235032025,-0.5336203996440885
345.4000000000042,20.50922983148922,3.055721696643742,-0.5578918442563428
346.60000000000423,20.545814468115445,3.088682060147649,-0.5826611871733345
347.8000000000043,20.582438746713038,3.124336424208394,-0.6100296883395604
349.00000000000426,20.619637851958004,3.1594927174567515,-0.6385805383591188
350.20000000000425,20.65638448471954,3.19729489859348,-0.6677541286010564
351.4000000000043,20.693328571554087,3.236529807222052,-0.6954152576086261
352.60000000000434,20.72995854177793,3.277611922099964,-0.7257718206122306
353.80000000000433,20.766907020531757,3.3216098659442217,-0.7591182440405819
355.0000000000043,20.804220188951078,3.369689439391897,-0.7951640046629582
356.20000000000437,20.84085655815398,3.4198583672759386,-0.8318765604793295
357.4000000000044,20.87756093974245,3.4692936114091735,-0.8703825688622313
358.6000000000044,20.914654514970287,3.5240116530884293,-0.9123989836879964
359.8000000000044,20.95186311256341,3.5801062350025217,-0.9553791889229153
361.00000000000443,20.988525080419656,3.6341622432500444,-1.000222135225218
362.2000000000045,21.025674250856834,3.6884472019780774,-1.0487234264424417
363.40000000000447,21.062609073060578,3.736798674133804,-1.0974650777762762
364.60000000000446,21.09971729578703,3.7823572883743246,-1.1481787473516807
365.8000000000045,21.136917396700735,3.8202495097877796,-1.2004502759651805
367.00000000000455,21.17384325268941,3.8477760498125027,-1.251938471775126
368.20000000000454,21.211176000371513,3.8704841363078017,-1.3054579011870242
369.4000000000045,21.248471264180367,3.8835936787975855,-1.3608478651822753
370.60000000000457,21.285277366600912,3.8909542245046014,-1.4154908142512204
371.8000000000046,21.32259920641225,3.8882257723124076,-1.4714262593729264
373.0000000000046,21.359544773472884,3.8773120711875575,-1.528161178776891
374.2000000000046,21.396742818444856,3.852299431194777,-1.585336576717733
375.40000000000464,21.433716584394134,3.8130418830837547,-1.6416809540958481
376.6000000000047,21.470698853091154,3.7570905718190057,-1.698575431120858
377.8000000000047,21.50793355852426,3.681911179806849,-1.7548243871103728
379.00000000000466,21.54511473435684,3.589159409574838,-1.8091694176441977
380.2000000000047,21.581783774869766,3.4803690891520795,-1.8609397919757011
381.40000000000475,21.619170309090904,3.355208945718573,-1.9101800309163397
382.60000000000474,21.65630983940682,3.2170187263559504,-1.9529867550703846
383.80000000000473,21.69323737269336,3.0696932350087254,-1.9945120406569719
385.0000000000048,21.73004168440231,2.9207411950840694,-2.031971898195065
386.2000000000048,21.767041065128446,2.773274254086957,-2.066160162153558
387.4000000000048,21.80425410691275,2.6313568461905428,-2.0967969260956596
388.6000000000048,21.84130230936114,2.5007321144336094,-2.1237903778259843
389.80000000000484,21.87769512761245,2.388054458972401,-2.1469109376367563
391.0000000000049,21.914708290276565,2.284696917099462,-2.166959144039029
392.2000000000049,21.951812071350165,2.201269442197593,-2.18549606273605
393.40000000000487,21.98786064788577,2.136070151267855,-2.2015053706622725
394.6000000000049,22.025696383683947,2.0816481982688915,-2.2168531787140484
395.80000000000496,22.062630253961878,2.0417663517655242,-2.230087261780712
397.00000000000495,22.09968562228384,2.012221670073789,-2.2422604685508
398.20000000000493,22.136613070371542,1.9899326586704231,-2.2542421640397725
399.400000000005,22.173867425378965,1.9744045272507085,-2.265986122288065
400.600000000005,22.210754567637704,1.9637855132773376,-2.277329204231178
401.800000000005,22.247858496294093,1.9566825372671288,-2.2882538618653863
403.000000000005,22.28512015067568,1.9548439701986084,-2.2990774230887885
404.20000000000505,22.322139606366044,1.9523734786788787,-2.310061386183545
405.4000000000051,22.359291746806296,1.9537386695146242,-2.3216467980824897
406.6000000000051,22.396392206915735,1.955454067128188,-2.3331642578396776
407.80000000000507,22.43381419791481,1.9566456013732783,-2.3447565181707746
409.0000000000051,22.47144312524687,1.961179202700706,-2.356155409544364
410.20000000000516,22.508387295799405,1.9646286466840779,-2.3666022256905133
411.40000000000515,22.545591085023922,1.9691939875542124,-2.378351111375429
412.60000000000514,22.5830500053209,1.972981536291969,-2.3892973230453203
413.8000000000052,22.620655974311212,1.9790101349983946,-2.4009565264441273
415.00000000000523,22.657744478318016,1.981999271354828,-2.4132568159931793
416.2000000000052,22.695363873428732,1.9876717056245001,-2.4253122366883133
417.4000000000052,22.73275949282791,1.9926806285753282,-2.4369112167250986
418.60000000000525,22.770293014679012,1.9987262163578343,-2.448631750968647
419.8000000000053,22.807481019809096,2.002556628928399,-2.4607143061355385
421.0000000000053,22.844922057056262,2.004416029258307,-2.473731809830083
422.2000000000053,22.882512721748938,2.00977096954108,-2.4867597015172302
423.4000000000053,22.92014371009152,2.015214883342947,-2.500654177132307
424.60000000000537,22.957291688373367,2.019768923426643,-2.514098330341468
425.80000000000535,22.995119454528247,2.0236335262273504,-2.5275144731071597
427.00000000000534,23.032605083190756,2.029162009241307,-2.541349740370508
428.2000000000054,23.070158867059583,2.0343395305560223,-2.556799798551365
429.40000000000543,23.10760495608485,2.041664157724726,-2.5719838154543164
430.6000000000054,23.14556548615167,2.0484140205055485,-2.586870360484594
431.8000000000054,23.183051748901082,2.056548279581251,-2.603265760996406
433.00000000000546,23.220401261450927,2.0596617408084925,-2.6196973317690952
434.2000000000055,23.25819444898626,2.0690966560133415,-2.63682100671341
435.4000000000055,23.2960361534599,2.0743312325243526,-2.6544590867538314
436.6000000000055,23.333850219198983,2.0820323442893596,-2.6711605426358562
437.8000000000055,23.371455193127687,2.0888222429175785,-2.6888773317651564
439.00000000000557,23.40885839504451,2.0969217199457493,-2.706539829633395
440.20000000000556,23.44658099730524,2.1046845361907227,-2.7254713143490035
441.40000000000555,23.484369946434335,2.1108406134685254,-2.7454465743780565
442.6000000000056,23.5222697250719,2.118579401797037,-2.763913515748293
443.80000000000564,23.56009249317481,2.1254803004561635,-2.7828727361489802
445.0000000000056,23.5978122261326,2.130272884484568,-2.802864613600054
446.2000000000056,23.635653684172528,2.138415095707091,-2.8232062024392244
447.40000000000566,23.673482786336347,2.1429286851659914,-2.844502897794615
448.6000000000057,23.711403319640226,2.1461333235728217,-2.864914220928
449.8000000000057,23.74901208004688,2.1523095405721344,-2.8847848844532553
451.0000000000057,23.78706837679019,2.154080900544136,-2.9036081589349596
452.20000000000573,23.824971159666603,2.1566145031277344,-2.9219113276000055
453.4000000000058,23.86267916386739,2.1601442373313504,-2.938843456009362
454.60000000000576,23.90077913676444,2.1603202073771928,-2.9574264500960434
455.80000000000575,23.938529324632082,2.1588369790776563,-2.9736260627320186
457.0000000000058,23.976532169614792,2.1558969988749173,-2.989907035140478
458.20000000000584,24.01427216601304,2.1540884787606127,-3.006707184993996
459.40000000000583,24.052474802871387,2.1477394084703487,-3.021312884180268
460.6000000000058,24.090411070985247,2.141635466608068,-3.0340957274786486
461.80000000000587,24.128561620063177,2.135072127836469,-3.046307721065558
463.0000000000059,24.16613055878512,2.125284139268092,-3.0579476537207877
464.2000000000059,24.203818644398808,2.1141918163775855,-3.0700919566553226
465.4000000000059,24.242139063659213,2.10206913850099,-3.0810183858601468
466.60000000000593,24.28042659119605,2.087477818391539,-3.090851727624547
467.800000000006,24.31868458033405,2.0717443259141417,-3.1012883210480373
469.00000000000597,24.356216824599443,2.057677650613238,-3.1091772140368503
470.20000000000596,24.39455518550427,2.0380002865817937,-3.11807526010387
471.400000000006,24.432483591565266,2.017764083626399,-3.126254279059124
472.60000000000605,24.470638151841673,1.9977453321362526,-3.1345381704747286
473.80000000000604,24.508411288989237,1.9767971759937164,-3.140592344214128
475.000000000006,24.546592052178998,1.9556680674971494,-3.148127529397555
476.20000000000607,24.584898517143348,1.935626708232776,-3.1535579054091936
477.4000000000061,24.62312771778001,1.9157003428721264,-3.1598676950580957
478.6000000000061,24.660998213516763,1.8966356495229837,-3.1646682264577475
479.8000000000061,24.699042350391807,1.8776942586965792,-3.170344052073572
481.00000000000614,24.737336778692615,1.8592233319534677,-3.1752931126595585
482.2000000000062,24.77563960685405,1.8414758904834447,-3.17920507081102
483.4000000000062,24.81374364521544,1.8253056824183571,-3.1825281103862078
484.60000000000616,24.85175011006214,1.8099280149241124,-3.185974342628678
485.8000000000062,24.889991805398342,1.7947542689865754,-3.1896433823312504
487.00000000000625,24.92831125003699,1.782485198515301,-3.1945097786773573
488.20000000000624,24.966576313218972,1.772984888099045,-3.1976999944989752
489.40000000000623,25.00469939501339,1.762335484163888,-3.200336745070546
490.6000000000063,25.04299792996069,1.7538353286268724,-3.202808885225041
491.8000000000063,25.081245664533377,1.745039316685283,-3.205892755516739
493.0000000000063,25.11956081127238,1.7411255413063367,-3.2079787985085004
494.2000000000063,25.157772031567717,1.73411691916492,-3.2101172080470635
495.40000000000634,25.19618089513144,1.7294299877303383,-3.2131016280351035
496.6000000000064,25.234233490965007,1.7265697960709363,-3.214807341283807
497.8000000000064,25.272715845846786,1.7229700840992659,-3.2183042175937686
499.00000000000637,25.310886196272094,1.7216310712370162,-3.2203440727308665
500.2000000000064,25.349296188465793,1.7184150745151188,-3.221756646270257
501.40000000000646,25.387566596301205,1.7176248106440855,-3.2244172721071536
502.60000000000645,25.425678765625488,1.7184561155693268,-3.22525149708732
503.80000000000643,25.464283764719564,1.717618068616749,-3.225935334489065
505.0000000000065,25.502903974196542,1.7162409814633448,-3.227643815724383
506.2000000000065,25.540992942196105,1.7166354530467138,-3.229548423966775
507.4000000000065,25.579417710222454,1.7178065176486959,-3.2303677912412097
508.6000000000065,25.618059205786768,1.7194347054227692,-3.23162928377258
509.80000000000655,25.6565090693105,1.7193974634247058,-3.2332418495800126
511.0000000000066,25.694960162967337,1.719704949116611,-3.234613884204803
512.2000000000066,25.73333417139494,1.7240214639469402,-3.2358948888295433
513.4000000000066,25.771719237745923,1.7253368023840567,-3.2375751424056185
514.6000000000066,25.810569461533962,1.7276581095259136,-3.2389029786893837
515.8000000000067,25.84869115344639,1.7277133513954106,-3.240120364815771
517.0000000000066,25.887436986200633,1.728814430611974,-3.240939504131795
518.2000000000066,25.925806800166246,1.7309035399801855,-3.2416739518040765
519.4000000000067,25.964505268002025,1.7315934930983008,-3.2429004959513343
520.6000000000067,26.002829498889163,1.733393843096808,-3.244186298011642
521.8000000000068,26.04160052886002,1.7365921086222842,-3.2441924626801404
523.0000000000067,26.080187253764667,1.7404822425580369,-3.245593306107366
524.2000000000068,26.11857316071103,1.7429351014894512,-3.2482485014574793
525.4000000000068,26.15730120993261,1.7444089842241282,-3.2494085937839667
526.6000000000067,26.19585181582217,1.7435040548536254,-3.2483616269950684
527.8000000000068,26.2344412201474,1.7466480910251991,-3.249590441506003
529.0000000000068,26.273243966992176,1.7484443217969774,-3.2508878551671794
530.2000000000069,26.311745715749346,1.7507387458747528,-3.252368589702311
531.4000000000069,26.350496334423422,1.7535555103655713,-3.2542725983619385
532.6000000000068,26.389104714742754,1.7540901040427508,-3.25494022669254
533.8000000000069,26.42770800843836,1.7548612796021592,-3.256274797361594
535.0000000000069,26.46648463454744,1.7577471639045894,-3.2553407259712914
536.2000000000069,26.504945734672248,1.759994230080103,-3.256269576519085
537.4000000000069,26.54361136399908,1.7629917553367986,-3.25748172852165
538.600000000007,26.582434297501404,1.765829500758021,-3.258841941910836
539.800000000007,26.62099578760912,1.768112385214552,-3.259859562173353
541.000000000007,26.659920082980108,1.7701533339297757,-3.260588170837985
542.200000000007,26.69874091045751,1.7730921417648622,-3.2608659108278637
543.400000000007,26.737525663586318,1.7757716648596056,-3.262174918338778
544.6000000000071,26.776451646330116,1.7788643687003312,-3.2629197619677104
545.800000000007,26.81501382531416,1.7816802284314779,-3.262931062537044
547.000000000007,26.853866083248068,1.7840139543060518,-3.264228405794098
548.2000000000071,26.892830451626708,1.7860030711010004,-3.2656672468633285
549.4000000000071,26.931562461043953,1.7890684434152067,-3.2656698539375197
550.6000000000072,26.970366299916183,1.791220058940883,-3.2675488239755577
551.8000000000071,27.009136729308608,1.7957251704870414,-3.2682072570069725
553.0000000000072,27.048177454648012,1.7984383384726643,-3.2688172667819395
554.2000000000072,27.08719998003841,1.801250414665139,-3.2701786622926585
555.4000000000071,27.12597109637112,1.8042391426734776,-3.270174190444889
556.6000000000072,27.164699560814288,1.807648274304645,-3.27147759873781
557.8000000000072,27.20372207343631,1.809497779387074,-3.271748911842851
559.0000000000073,27.242507145953358,1.8113979396326692,-3.272150894157038
560.2000000000073,27.2813998121908,1.8172368042279838,-3.2734431579098158
561.4000000000073,27.32039258438147,1.8173426048967172,-3.2745512554866423
562.6000000000073,27.359202120578782,1.8214776490003937,-3.2747795376643722
563.8000000000073,27.398326554712675,1.8242622503531045,-3.2761007912918187
565.0000000000073,27.43694183001765,1.8295853339207826,-3.2760997224326394
566.2000000000073,27.475952885028057,1.8321071435114686,-3.2760009949911137
567.4000000000074,27.51501034318575,1.8353838118985746,-3.2774332068276646
568.6000000000074,27.55395918103691,1.8369231230141694,-3.278777707594018
569.8000000000075,27.59300509926371,1.8412168525736878,-3.2786553754848153
571.0000000000074,27.632077125480436,1.8454940869707637,-3.2800476561714573
572.2000000000074,27.671274961382284,1.8476415655557181,-3.2800278767108906
573.4000000000075,27.71020544197394,1.8521059919554765,-3.2813635986470024
574.6000000000074,27.74835066465076,1.8529991885353145,-3.2813280464600707
575.8000000000075,27.788357663118816,1.8565737259272368,-3.2826522915678247
577.0000000000075,27.82753233465607,1.8606042162971355,-3.283372772534456
578.2000000000075,27.866447636388102,1.8638158532032372,-3.2833411106388057
579.4000000000076,27.90525289650173,1.8671396320944074,-3.2836849963580192
580.6000000000075,27.944503898802626,1.8719679615925315,-3.2846022098153007
581.8000000000076,27.983682624156284,1.873735628825981,-3.2859581303592273
583.0000000000076,28.02258078611874,1.8770180717471778,-3.286127502238618
584.2000000000075,28.061791894861205,1.8813354158158302,-3.287269215820479
585.4000000000076,28.10084177139966,1.8831975891975903,-3.2885900502401544
586.6000000000076,28.139964116781794,1.886706634603033,-3.288600391832358
587.8000000000077,28.179170323618806,1.8882399926247448,-3.2886001833002156
589.0000000000077,28.21838032024296,1.889314828224795,-3.289916133340054
590.2000000000077,28.257850204268244,1.8921636416517322,-3.2912333700947065
591.4000000000077,28.2969858616892,1.895537821580581,-3.2912338574450084
592.6000000000078,28.336354961244023,1.897081143466821,-3.292529132713048
593.8000000000077,28.375144039771474,1.8992999579522063,-3.2925510071419595
595.0000000000077,28.414482822928356,1.9025962591158474,-3.292841119456649
596.2000000000078,28.453775606065985,1.9054711406189717,-3.2938751028074433
597.4000000000078,28.4930809941177,1.908655257526724,-3.2952835877675506
598.6000000000079,28.532442110731072,1.9130153178357598,-3.295176277562962
599.8000000000078,28.571468228312423,1.9186014025229303,-3.296327228379528
601.0000000000078,28.610741757548865,1.921347707282772,-3.296559899101609
602.2000000000079,28.650096560991365,1.926915120594836,-3.2978206337919653
603.4000000000078,28.68936762575596,1.9321067776142073,-3.2991271235891277
604.6000000000079,28.728416332328152,1.9378082946664335,-3.2991299867029635
605.8000000000079,28.768034208485798,1.9413470210699881,-3.29910209488073
607.000000000008,28.80727679271242,1.9453689749610739,-3.300439373909234
608.200000000008,28.846518584689658,1.9520778111706651,-3.3017472465909914
609.4000000000079,28.8860464635888,1.9575682728241048,-3.302901835979977
610.600000000008,28.925529438886052,1.9605176185669921,-3.3032153731039564
611.800000000008,28.964839780436485,1.96672929851276,-3.30451434958783
613.000000000008,29.004375674547184,1.970478755731104,-3.304458930308947
614.200000000008,29.043586357839597,1.9736231570445115,-3.305674993682071
615.400000000008,29.08298630626028,1.9745981335782221,-3.305931576214127
616.6000000000081,29.122350588842345,1.977108442284897,-3.3072648421128537
617.8000000000081,29.16163014612777,1.9818515899375715,-3.309674699281603
619.0000000000081,29.201121095506092,1.9839965969291402,-3.3112693815005274
620.2000000000081,29.240491234265093,1.9860008314436575,-3.312619040371662
621.4000000000082,29.279860342909704,1.99376699105953,-3.314085167268916
622.6000000000081,29.319456808153287,1.9994017499534424,-3.315063977256126
623.8000000000081,29.358843314114935,2.0061631356940133,-3.3153701378516702
625.0000000000082,29.39836006107174,2.01395976463576,-3.316718957162532
626.2000000000082,29.437944391162457,2.0211938407291514,-3.315477313891658
627.4000000000083,29.476837044644963,2.0288849690563833,-3.3166304615656075
628.6000000000082,29.51666559880359,2.036341710752702,-3.3179177125669517
629.8000000000083,29.55612282205523,2.0430521652548292,-3.3181341163717195
631.0000000000083,29.595808518442674,2.0516393587702004,-3.3194348747725475
632.2000000000082,29.635132074146554,2.057995100512115,-3.3194309628610696
633.4000000000083,29.674885100013437,2.065651661139002,-3.3197643584407373
634.6000000000083,29.714496597189513,2.0701607712135757,-3.320425230234041
635.8000000000084,29.753829708054884,2.0772284741310094,-3.3208399881937227
637.0000000000084,29.79316699750165,2.08254853964911,-3.3217312634354004
638.2000000000083,29.83291704504038,2.0886147000492397,-3.3218463724502545
639.4000000000084,29.87219153685715,2.0951951198590373,-3.3220595589518647
640.6000000000084,29.912147482438748,2.098560709882799,-3.3220836095280486
641.8000000000084,29.95144834449401,2.101824705784809,-3.320740238017784
643.0000000000084,29.99105477144681,2.108910591777364,-3.3224298681060964
644.2000000000085,30.030505811635813,2.1139483282365314,-3.324017197216871
645.4000000000085,30.06982139775368,2.1157666875724765,-3.3252403630309333
646.6000000000085,30.10981283163859,2.1199556434417643,-3.3252463643066146
647.8000000000085,30.14917033347088,2.122670033925372,-3.3242500495004386
649.0000000000085,30.18859717264592,2.1298197775823957,-3.3252907930606472
650.2000000000086,30.22838352817758,2.129924525405929,-3.327072956399376
651.4000000000085,30.26771334804385,2.133725417428117,-3.327319062136374
652.6000000000085,30.307325408070618,2.1342770460998413,-3.3284226036282654
653.8000000000086,30.346805982835807,2.1393908707211486,-3.328420065277411
655.0000000000086,30.386452346739926,2.1423967918728484,-3.32842004881973
656.2000000000087,30.426197320259416,2.1448771634634305,-3.3284201834867795
657.4000000000086,30.46602140945471,2.149193188538851,-3.328544742998842
658.6000000000087,30.505526066451,2.1535984091339406,-3.32842784592958
659.8000000000087,30.545046484108,2.157573136649632,-3.329715257463445
661.0000000000086,30.58447973992007,2.1607339624375435,-3.3308157191467673
662.2000000000087,30.62395483883391,2.1629640377598167,-3.3320351623889324
663.4000000000087,30.66378953832407,2.167042953309905,-3.33203989128451
664.6000000000088,30.70362757189648,2.17332259255683,-3.332040010020203
665.8000000000088,30.74349993577844,2.1777294050451608,-3.332061680423676
667.0000000000088,30.782950612662255,2.1824860575341396,-3.3333671672756884
668.2000000000088,30.822525157382177,2.1884898591291506,-3.3333575305236147
669.4000000000088,30.86220662832811,2.1946415378102344,-3.334259651926052
670.6000000000088,30.9018246419625,2.1975486787815965,-3.334668517881092
671.8000000000088,30.9416027129792,2.202996032108504,-3.3343477671731856
673.0000000000089,30.981113639016343,2.206724431059618,-3.3340264340161943
674.2000000000089,31.020858972579376,2.2112138760524442,-3.3344986587575747
675.400000000009,31.060548326121964,2.218401909330263,-3.335009491369147
676.6000000000089,31.10033501635527,2.22281120641022,-3.335010162207309
677.8000000000089,31.13982164949073,2.229032303610812,-3.3350118603289927
679.000000000009,31.179301654184968,2.23476958073637,-3.3363233767831955
680.2000000000089,31.21926745071496,2.238102960077859,-3.336319828697449
681.400000000009,31.259040964055934,2.245059047433537,-3.3363198149016835
682.600000000009,31.29886751692277,2.2485863416132026,-3.3363198150007585
683.800000000009,31.338470820429578,2.2530489868562737,-3.3363198183213667
685.0000000000091,31.37834550633881,2.260128888881547,-3.33632530262929
686.200000000009,31.41817078803145,2.2673969386337958,-3.3360019541428967
687.4000000000091,31.457917347816615,2.273132541627763,-3.3373116724430556
688.6000000000091,31.49767246061095,2.2798552101203273,-3.337531736917775
689.800000000009,31.537491036051776,2.2843515824294918,-3.3386338804015456
691.0000000000091,31.577419480260506,2.2889028122607247,-3.3376411820077525
692.2000000000091,31.61694271954143,2.2958817602657935,-3.3376400196538025
693.4000000000092,31.65677684243426,2.2975716586910595,-3.3376440685512767
694.6000000000092,31.696778156039763,2.3043505762398224,-3.3386492500571423
695.8000000000092,31.736396098116547,2.307482008282384,-3.3386290538004135
697.0000000000092,31.775563444093482,2.313616593562624,-3.3389432069447524
698.2000000000093,31.816012772227005,2.3181384505587497,-3.3389519674287023
699.4000000000092,31.85608097393022,2.32291166153006,-3.3396270619821946
700.6000000000092,31.895604229860165,2.3280030645970067,-3.3400492541180986
701.8000000000093,31.935396796260015,2.3330689516980456,-3.3409214085815213
703.0000000000093,31.975229973612873,2.3379380338483005,-3.3409159900907963
704.2000000000094,32.01511042539845,2.3435977665230165,-3.3399396244998965
705.4000000000093,32.05508089692347,2.345514478411904,-3.339940740032035
706.6000000000093,32.094649413186,2.3531279956367834,-3.340231669366485
707.8000000000094,32.13448129527166,2.358196148532385,-3.3412534134107634
709.0000000000093,32.17435824146097,2.3619238334410793,-3.3412500645310406
710.2000000000094,32.21423421667708,2.3676519440922177,-3.3412757106065545
711.4000000000094,32.253825945100296,2.3731189801209163,-3.342573315076341
712.6000000000095,32.29402866413112,2.3770366568824732,-3.3425700269997334
713.8000000000095,32.33378947034766,2.381533225723964,-3.342570008082922
715.0000000000094,32.37391761210964,2.38948867549738,-3.3425700060041112
716.2000000000095,32.4136475296301,2.3928290922914046,-3.342569570341656
717.4000000000095,32.453662674631744,2.397618283071823,-3.343181943558707
718.6000000000095,32.493468779070085,2.4061705520359333,-3.3428981206852044
719.8000000000095,32.533561016335106,2.410970248455583,-3.3429016666953153
721.0000000000095,32.573591977878685,2.414273197690968,-3.3432819763538473
722.2000000000096,32.61347267923429,2.422266403726091,-3.344220599064771
723.4000000000096,32.65328900044259,2.427275329013824,-3.3442203564121105
724.6000000000096,32.69317984981048,2.4327453766541187,-3.3438736195045067
725.8000000000096,32.73347363598296,2.436776500065153,-3.3452243907201975
727.0000000000097,32.77334391385184,2.441548853253561,-3.3452107274266947
728.2000000000096,32.81328534057156,2.447088516976171,-3.345405431833916
729.4000000000096,32.85327175126173,2.453435858675255,-3.346523633789074
730.6000000000097,32.89324732957042,2.457600725291759,-3.3465199450630787
731.8000000000097,32.933060370974104,2.463523840688019,-3.3465200169420584
733.0000000000098,32.97283296864641,2.4691099255676985,-3.346554755826598
734.2000000000097,33.01311901145965,2.4740053543292775,-3.3478475161657397
735.4000000000098,33.05264562593634,2.4803589704207014,-3.3478400591215647
736.6000000000098,33.09297659709984,2.4862025667685534,-3.3478413965589344
737.8000000000097,33.13302320833787,2.491789276532613,-3.3481800350601802
739.0000000000098,33.172836680189164,2.4955291725988995,-3.3478395183876692
740.2000000000098,33.21294911935982,2.5036944145276356,-3.3478401629796917
741.4000000000099,33.25295322160674,2.5075062064259734,-3.3478502195593767
742.6000000000099,33.292954716340034,2.5117244867642015,-3.349200870974958
743.8000000000098,33.333125380750694,2.5218924971623093,-3.349150445716654
745.0000000000099,33.37280583924033,2.524108713585286,-3.3491501772616505
746.2000000000099,33.41312287025135,2.529133555983755,-3.3491501612850256
747.4000000000099,33.453041664470575,2.5360200005838998,-3.349147300583262
748.6000000000099,33.49305580697391,2.540379176779501,-3.3501231843678037
749.80000000001,33.53317663978136,2.5486395626819256,-3.3504656577609158
751.00000000001,33.573410560322294,2.5557213375168555,-3.351466623760598
752.20000000001,33.61341886403062,2.562172871630671,-3.351778959701606
753.40000000001,33.65361819822075,2.5687603489076887,-3.3517799287883774
754.60000000001,33.693644820907444,2.570832892471761,-3.351780133658969
755.8000000000101,33.73375115176486,2.5789612274625293,-3.3508312223725136
757.00000000001,33.77386238936749,2.5830628775736804,-3.3504697578628644
758.20000000001,33.81364270911454,2.590197603291415,-3.3504250487862692
759.4000000000101,33.85393098931374,2.5958885956141113,-3.3517767206141578
760.6000000000101,33.89430816420782,2.602925055201863,-3.351789976929658
761.8000000000102,33.93428081985574,2.6098680954000466,-3.3518417510157383
763.0000000000101,33.974509579198326,2.6145881062069,-3.350800331343301
764.2000000000102,34.015030542785254,2.6233202482914426,-3.350794945399341
765.4000000000102,34.054840518803736,2.6287427121119777,-3.3519124556961137
766.6000000000101,34.09508880984218,2.6351537416134203,-3.3517864981758674
767.8000000000102,34.135215181110844,2.6432883474101905,-3.3529017008824016
769.0000000000102,34.17528648498815,2.6472108542075317,-3.3530991398549475
770.2000000000103,34.21559803233404,2.657077720596805,-3.3530444791023157
771.4000000000103,34.256077271355224,2.6609870270136504,-3.354412051904188
772.6000000000103,34.29578740985536,2.666241692493674,-3.3544198378613874
773.8000000000103,34.33614840663847,2.675030066834889,-3.3544198758110935
775.0000000000103,34.37655541780735,2.6803100472807384,-3.3544198970667454
776.2000000000103,34.416755343142306,2.684967865532357,-3.354480407789293
777.4000000000103,34.45684501185688,2.6936152717156348,-3.353104518837108
778.6000000000104,34.49711248343707,2.701643018860505,-3.353291013261453
779.8000000000104,34.53717938503854,2.7098504178301592,-3.354422627731445
781.0000000000105,34.57741562417478,2.7143604784131243,-3.354420044342282
782.2000000000104,34.61761750737781,2.720794751636791,-3.3546258194246903
783.4000000000104,34.65823445711339,2.726306169186455,-3.3557312783172657
784.6000000000105,34.698552114187024,2.736170742115987,-3.35573002730134
785.8000000000104,34.73848772028656,2.7430140391174334,-3.3557276201589135
787.0000000000105,34.77906794777631,2.7488477930223065,-3.356962684713431
788.2000000000105,34.81926690869324,2.752933353919334,-3.355739853109645
789.4000000000106,34.859823812413985,2.761345955752703,-3.356097752782105
790.6000000000106,34.89993565351444,2.770016599993905,-3.3563999969685865
791.8000000000105,34.940317355479955,2.775675509264459,-3.35640392364453
793.0000000000106,34.980738143203965,2.7798629352314412,-3.3570354858074594