File: 01_Data/Cotton_Rug/STA/N2/30K_min/Cotton_Rug_STA_N2_30KData_220113_R1.csv
##Temp./Â°C,Time/min,DSC/(mW/mg),Mass loss/mg
49.0,10.54786321898488,-0.9128965054851936,-0.00945500784794806
50.20000000000002,10.742561897346144,-0.774551416668154,-0.011270684099538464
51.400000000000034,10.866118543549847,-0.674391802573845,-0.011422131417275772
52.60000000000005,10.967547171540796,-0.5858985402590756,-0.010470668001041794
53.80000000000007,11.051972215881781,-0.5145855748646424,-0.011548597371668912
55.000000000000085,11.128146833357361,-0.44901439194632753,-0.011598752355431508
56.2000000000001,11.19818019817561,-0.3883094985123775,-0.011484771285790174
57.40000000000012,11.262611769202923,-0.334815068088569,-0.011392419384753438
58.600000000000136,11.325446826053224,-0.283784604699178,-0.011959523004075656
59.80000000000015,11.383680201674705,-0.23542969632764107,-0.011252356073594427
61.00000000000017,11.440745395587738,-0.1912897936048724,-0.011179914143617076
62.20000000000019,11.495007377699643,-0.14973225193175843,-0.012162467021382461
63.400000000000205,11.547579153785987,-0.10980515089580656,-0.012793085620887545
64.60000000000022,11.5991139414865,-0.07194898802110275,-0.011602269351150163
65.80000000000024,11.649738212612247,-0.03573853207616697,-0.012262615327559345
67.00000000000026,11.698890890707686,-4.850120116790032e-06,-0.011288266602051067
68.20000000000027,11.74751711765001,0.03402802174280691,-0.011369570197608425
69.40000000000029,11.794747435355207,0.06543608674409612,-0.012744598470775692
70.6000000000003,11.842168740339874,0.0952213641032522,-0.013033940923157239
71.80000000000032,11.888636340687667,0.12158795851412679,-0.012658932040078064
73.00000000000034,11.93433289813048,0.14536687070302615,-0.013902387883228506
74.20000000000036,11.979604755332458,0.16799848680583143,-0.013298618146725616
75.40000000000038,12.02491041513721,0.1888763257438744,-0.012280704079113747
76.60000000000039,12.069345846343055,0.20916897167858728,-0.012155138745137073
77.80000000000041,12.11354014015128,0.22814064798422895,-0.013686269999349854
79.00000000000043,12.158049077023708,0.24704032409870488,-0.014616244497751119
80.20000000000044,12.20137064335851,0.26519515997980514,-0.013972556036926598
81.40000000000046,12.24458431584581,0.28155608036151447,-0.014106396352278061
82.60000000000048,12.287792361001978,0.3011459606523828,-0.014532040769520194
83.8000000000005,12.33067795863054,0.3180677754807553,-0.015589898530404156
85.00000000000051,12.372917106878283,0.3362870261703735,-0.014495657457074707
86.20000000000053,12.41516605130802,0.35366041760612194,-0.014588418720316909
87.40000000000055,12.457247089027247,0.3701622519796326,-0.014699670595107683
88.60000000000056,12.4989296818586,0.3885084360874401,-0.015103426694073718
89.80000000000058,12.540971544946357,0.4044252941295703,-0.015968390197351745
91.0000000000006,12.582433123681497,0.420571504489206,-0.01601908928850193
92.20000000000061,12.624110382907423,0.43661035183402824,-0.015034005570205622
93.40000000000063,12.665673562907733,0.45233825184122045,-0.01570985379295209
94.60000000000065,12.707003890894232,0.4689358110577128,-0.01611903157965422
95.80000000000067,12.747270154867024,0.4841060732061657,-0.016789924451579452
97.00000000000068,12.788790185003142,0.49898529105948325,-0.016130719397972726
98.2000000000007,12.829455106063293,0.5121900778117134,-0.017541285887226366
99.40000000000072,12.870033300066332,0.5275330552586962,-0.017155752906664823
100.60000000000073,12.911442645490995,0.5416651913319986,-0.017386055147059487
101.80000000000075,12.951825220148818,0.5571156938396363,-0.018676893899021607
103.00000000000077,12.992470722637307,0.5713229209491982,-0.018725825786208183
104.20000000000078,13.032951677059499,0.585694404172978,-0.018789475169060488
105.4000000000008,13.072938873447386,0.5991543581598533,-0.017478350397262865
106.60000000000082,13.113662897960554,0.6129268386321065,-0.018763266374824283
107.80000000000084,13.153844226732579,0.6264963563546945,-0.01877920637596464
109.00000000000085,13.19429633008975,0.6388519205496761,-0.020067407019934702
110.20000000000087,13.234852027937483,0.6531393246014509,-0.019930453060933218
111.40000000000089,13.27507321405195,0.6649976334638257,-0.02006925479925492
112.6000000000009,13.315380589052436,0.6781793340421638,-0.020069878894975357
113.80000000000092,13.355590999280853,0.6898290865654767,-0.020074474135767684
115.00000000000094,13.395827381820755,0.702589959429503,-0.019344174423429727
116.20000000000095,13.436175214553645,0.7138445796549756,-0.020077065860776067
117.40000000000097,13.475731152498515,0.7276099971033549,-0.02008741497561317
118.60000000000099,13.515732596290821,0.7394894679809821,-0.021390198771138458
119.800000000001,13.555624285674234,0.7516637326092555,-0.02139012737506274
121.00000000000102,13.594894055160502,0.7638849781833661,-0.021388260207766407
122.20000000000104,13.634366046456543,0.7751911443848921,-0.020983825068105144
123.40000000000106,13.674063464566629,0.787081590303739,-0.02138393010253825
124.60000000000107,13.713605492676397,0.7985317160434778,-0.02139000096903665
125.80000000000109,13.753276117323843,0.8101491549485694,-0.021407832584519504
127.00000000000111,13.79324111037075,0.821843289909226,-0.022717462970737845
128.20000000000113,13.831919620944818,0.8329517507689549,-0.022711398054497067
129.40000000000114,13.871459116586225,0.8447419204320333,-0.02193180468997724
130.60000000000116,13.91071633524165,0.85502629221379,-0.021907487130734538
131.80000000000118,13.949873132101562,0.8666733628378595,-0.022700755252836657
133.0000000000012,13.98919381130726,0.8795448268071477,-0.02270020306668563
134.2000000000012,14.027972538507653,0.8890196222942917,-0.022700219565090052
135.40000000000123,14.067167075671577,0.902186583381159,-0.02270483603608442
136.60000000000124,14.10598443731406,0.9147927712340087,-0.0214121971667387
137.80000000000126,14.145278324041575,0.9266463010894477,-0.021389613813023622
139.00000000000128,14.18414719258641,0.9392437001154929,-0.02265952761025325
140.2000000000013,14.222984620181794,0.9517544386285639,-0.024286227070218658
141.4000000000013,14.261285479564357,0.9633152536927057,-0.0242404066980777
142.60000000000133,14.300099401139418,0.9775470965742526,-0.024239529085527955
143.80000000000135,14.338717593081418,0.9889964942618279,-0.0242212253834988
145.00000000000136,14.377198742595336,1.0024812420991058,-0.02259138943603567
146.20000000000138,14.415511315231909,1.016591547341161,-0.022589920887429393
147.4000000000014,14.453829801035807,1.0289720889742242,-0.022589697347953575
148.60000000000142,14.492031105161221,1.0406484350780398,-0.022543476253307215
149.80000000000143,14.530255070405955,1.05512065728526,-0.024002877712105963
151.00000000000145,14.568611840397194,1.0672056912944643,-0.024011876493740925
152.20000000000147,14.606933589568591,1.0798480128730088,-0.022562063898214024
153.40000000000148,14.645038089415943,1.0932396826522934,-0.02266934634096085
154.6000000000015,14.683000210641776,1.1058127929814188,-0.023916654948953564
155.80000000000152,14.721019906315359,1.1194098867155864,-0.023910184921528632
157.00000000000153,14.759186362363764,1.1338122684107614,-0.0239101679052931
158.20000000000155,14.797204145072367,1.1466674002312625,-0.02391016800547119
159.40000000000157,14.835414454516767,1.1589258847814794,-0.023910167892585044
160.6000000000016,14.873111027473659,1.1716793859954342,-0.023909954245429965
161.8000000000016,14.91096541275525,1.1848591938455817,-0.024662747543100494
163.00000000000162,14.948570231974479,1.1966161009408287,-0.02390446829944448
164.20000000000164,14.986973647889783,1.2088399742289226,-0.023919894098022976
165.40000000000165,15.024402389870607,1.2223282356571432,-0.023920048650504455
166.60000000000167,15.062363617256473,1.2347264306544488,-0.023920032393252466
167.8000000000017,15.099812360359701,1.2465488567597158,-0.023918044578578268
169.0000000000017,15.137537695830595,1.2602601261897464,-0.024569607711277808
170.20000000000172,15.17510597840386,1.2720695737412335,-0.02522268304725417
171.40000000000174,15.21268638228801,1.2850164141898517,-0.02490894197434379
172.60000000000176,15.250196917216082,1.2983289640052504,-0.024871417609598545
173.80000000000177,15.288061997693095,1.310726533458911,-0.02621817050344255
175.0000000000018,15.325443062308764,1.321941538552745,-0.026220022621641803
176.2000000000018,15.362893667332257,1.3346134825011051,-0.026196509162050408
177.40000000000182,15.400491983361198,1.3447286002323142,-0.02489369799724095
178.60000000000184,15.437606258973808,1.3581689538984376,-0.024899940020393085
179.80000000000186,15.474950083613356,1.3715206257270638,-0.02530286720723751
181.00000000000188,15.51223539648185,1.3828451041749164,-0.026142814889592803
182.2000000000019,15.54959199923447,1.3950436357608074,-0.02764716291226721
183.4000000000019,15.586760695641608,1.4055759747189203,-0.027630456132916148
184.60000000000193,15.624004854684177,1.4165322093978843,-0.02632678164384794
185.80000000000194,15.660718390413397,1.428930043933217,-0.026329986217297652
187.00000000000196,15.697444636748681,1.4422299675065966,-0.026330998666747707
188.20000000000198,15.735017799573638,1.4514395049012982,-0.025639067825882655
189.400000000002,15.771925736831008,1.46383229022903,-0.025341494951610866
190.600000000002,15.808839801444964,1.474281123743887,-0.02658150914863011
191.80000000000203,15.845626247780435,1.4863333571631134,-0.026658408129856426
193.00000000000205,15.882878291647046,1.4975572630293632,-0.026656574436199953
194.20000000000206,15.919109395729864,1.5095226299538966,-0.027986195073895104
195.40000000000208,15.956084080617064,1.5210429302337345,-0.027971122121095426
196.6000000000021,15.992955896251258,1.5315216974697925,-0.02803028463308932
197.80000000000211,16.0295469027065,1.5430108203180943,-0.027089548285125886
199.00000000000213,16.0663697262911,1.5522437259660995,-0.027982850672826576
200.20000000000215,16.1032997115035,1.5638021327829505,-0.027980030680471835
201.40000000000217,16.139633738303313,1.575578365494102,-0.027980925729553352
202.60000000000218,16.17654254743978,1.5856268208107944,-0.02900436300966902
203.8000000000022,16.213138249671786,1.5965041138940814,-0.029323938614430833
205.00000000000222,16.250031507305955,1.6066395526126025,-0.029290357776278864
206.20000000000223,16.28655129603505,1.6176251520463614,-0.029250299558390758
207.40000000000225,16.323415544130086,1.629597862730863,-0.031274030969375755
208.60000000000227,16.359908587084036,1.6382680294433816,-0.0312711670757726
209.80000000000229,16.396628506697596,1.6523029234778395,-0.029933158239212165
211.0000000000023,16.432918781674,1.663453669166081,-0.029949587646905584
212.20000000000232,16.4697862513295,1.676509186671291,-0.029949848014769742
213.40000000000234,16.506377703184203,1.68738423563101,-0.029947980950813413
214.60000000000235,16.542698337838843,1.6974491596596324,-0.0303908014282972
215.80000000000237,16.579430217611222,1.7076942801187807,-0.030610147448863145
217.0000000000024,16.615848192416426,1.7193722173121582,-0.030623969097171244
218.2000000000024,16.652514008562118,1.729576547426811,-0.031967108805705635
219.40000000000242,16.689117351839684,1.7388044039053712,-0.031919890190548195
220.60000000000244,16.725432642801405,1.7479525273668088,-0.03191980815930373
221.80000000000246,16.76210622107005,1.7572171376724972,-0.03188863088643945
223.00000000000247,16.798279057523683,1.7693344951843217,-0.033166582950881374
224.2000000000025,16.834860001543912,1.7806839691821355,-0.03454723125383019
225.4000000000025,16.871067139140045,1.789517690251822,-0.0343432709566458
226.60000000000252,16.907501995382024,1.7996993639375507,-0.03324016103634664
227.80000000000254,16.943787076025277,1.8111830179353228,-0.03323984673930358
229.00000000000256,16.98065609113564,1.8222870763893904,-0.033241419537811456
230.20000000000258,17.016720012719976,1.832693363807923,-0.034142819929830814
231.4000000000026,17.053569475809443,1.8442916433457257,-0.03421870213431166
232.6000000000026,17.089549609894096,1.8571084617417,-0.034219702755839077
233.80000000000263,17.12610772953925,1.8691337839824174,-0.03519677764730167
235.00000000000264,17.162617218594555,1.8818206270664182,-0.03553823162730163
236.20000000000266,17.19886497381127,1.8983472958330014,-0.03553972168193775
237.40000000000268,17.235604613999918,1.916484263656453,-0.035452913311450285
238.6000000000027,17.27173245563771,1.9358064900053529,-0.03684886056859549
239.8000000000027,17.30800650678918,1.960614522829379,-0.03683625273187818
241.00000000000273,17.34454086042164,1.9886501166645618,-0.037204261913878156
242.20000000000275,17.380696308724147,2.0208166353033814,-0.03850227368556336
243.40000000000276,17.41717859550028,2.052809835228627,-0.03844853018188399
244.60000000000278,17.453586195012694,2.0874017575535215,-0.03980436780087526
245.8000000000028,17.489906785355444,2.124041753738821,-0.04046242591683269
247.0000000000028,17.526404320680165,2.1696366898884674,-0.04113278164122036
248.20000000000283,17.562822687786433,2.2365158217434824,-0.04113024533672682
249.40000000000285,17.599162270926218,2.3216447178003663,-0.04112709192399677
250.60000000000286,17.635484264255286,2.4103020694579294,-0.04239869695072951
251.80000000000288,17.67165704003529,2.4917235309928527,-0.04244845543042919
253.0000000000029,17.708222583595028,2.5553395739721956,-0.042964550629166265
254.20000000000292,17.744993923520305,2.593333816589592,-0.043757213864002775
255.40000000000293,17.78110990083309,2.5877034696192323,-0.044833473433742554
256.600000000003,17.81804414954093,2.5325911376793973,-0.04508009357267184
257.80000000000297,17.85446920469903,2.464069906909294,-0.04509161774423287
259.00000000000296,17.890368133397374,2.3951333870327005,-0.0440834811631472
260.200000000003,17.92670903396669,2.332712242986525,-0.04553704058730812
261.40000000000305,17.96323136112472,2.282095330360176,-0.04746892287531024
262.60000000000304,17.999053685614417,2.241369783250747,-0.04985460055823898
263.800000000003,18.035382946604262,2.209830492923717,-0.051510124510555144
265.00000000000307,18.07142910004925,2.1851937804567476,-0.054042034119115456
266.2000000000031,18.107883052490955,2.1674968989366876,-0.05541394211528594
267.4000000000031,18.144030744876893,2.1549033833642652,-0.056884114778975814
268.6000000000031,18.1798811906165,2.1472382451457106,-0.058362377744045624
269.80000000000314,18.216048320274535,2.1421732931579736,-0.058351865966311145
271.0000000000032,18.252383088240027,2.1404231056094942,-0.05960556348691615
272.2000000000032,18.288371674040025,2.141085768146295,-0.06101964814396155
273.40000000000316,18.324661036055417,2.143583417065011,-0.06385261861254277
274.6000000000032,18.360818969954956,2.146173744329266,-0.06540366246036067
275.80000000000325,18.39695303186204,2.1494024264583675,-0.0668921742362274
277.00000000000324,18.43343973083381,2.153083364196965,-0.06837681692354636
278.20000000000323,18.469453865880393,2.160342510129831,-0.07057976236028995
279.4000000000033,18.505810259577437,2.1683607175971424,-0.0727851530589958
280.6000000000033,18.541780273262727,2.1736840565949676,-0.07466070831315541
281.8000000000033,18.57826977726453,2.1805444852546176,-0.07791584467439616
283.0000000000033,18.614527285319767,2.189012441515169,-0.08000366406500525
284.20000000000334,18.65057345877368,2.19672287848935,-0.08165243747018991
285.4000000000034,18.686671500218402,2.20481266180072,-0.08453028880300817
286.6000000000034,18.723137615279185,2.2149017802603557,-0.08725322089508225
287.80000000000337,18.7597298476661,2.2224839520053354,-0.09079090813564772
289.0000000000034,18.795780050013253,2.230768149107124,-0.09470176534849406
290.20000000000346,18.832214659760734,2.239937068080755,-0.09788646426581504
291.40000000000344,18.868456779847442,2.25051763279223,-0.10033199255370429
292.60000000000343,18.904422316015335,2.2605284222365603,-0.10367274980932395
293.8000000000035,18.94078381698506,2.2720858500937156,-0.10788248527679078
295.0000000000035,18.977283921510434,2.282819449153395,-0.11178633982163122
296.2000000000035,19.01398345580933,2.2943267392673548,-0.11535164600103265
297.4000000000035,19.04987624931351,2.3037108596804803,-0.11954614276670572
298.60000000000355,19.086143246020992,2.31644045519281,-0.12443963173095085
299.8000000000036,19.122311480293586,2.3297730224366475,-0.1288201574984531
301.0000000000036,19.159151312835434,2.3402482630720476,-0.13411238220907507
302.20000000000357,19.19512978931753,2.352161019825703,-0.1397267013743888
303.4000000000036,19.231538971294494,2.364655942775006,-0.14508048297532739
304.60000000000366,19.26767977365517,2.3787769860366037,-0.15000308173205745
305.80000000000365,19.303539505551953,2.3914653965510597,-0.15618933971264237
307.00000000000364,19.340932726032335,2.402879036274482,-0.16166739773709882
308.2000000000037,19.377032833159205,2.4164904305913595,-0.16823109508777323
309.40000000000373,19.413331830664724,2.4298048730310104,-0.17605993464431346
310.6000000000037,19.449880883239835,2.443281661872567,-0.18282397403548556
311.8000000000037,19.486086951145904,2.4553464994148593,-0.18821435690341115
313.00000000000375,19.52267030956231,2.4686330429024617,-0.195622206234372
314.2000000000038,19.55896496987844,2.4823390804829133,-0.20165805085722432
315.4000000000038,19.595235091077257,2.493116757786736,-0.20822576431900686
316.6000000000038,19.631670788194803,2.5054683524496855,-0.21891858553357801
317.8000000000038,19.668444439043945,2.5192166312740345,-0.2284678545788883
319.00000000000387,19.70443004895453,2.5287853571696206,-0.2372497880624156
320.20000000000385,19.741433513955492,2.5392265580268165,-0.24589401373987352
321.40000000000384,19.777549702098916,2.551696918088549,-0.25488687598349635
322.6000000000039,19.813999304114187,2.562757111009259,-0.26540522996469784
323.80000000000393,19.849939500662774,2.5735744899565143,-0.2751968100125941
325.0000000000039,19.88676757721613,2.5859157527976167,-0.2868512530712364
326.2000000000039,19.923561119552712,2.5955958283392353,-0.29871842778549773
327.40000000000396,19.96033518395848,2.6089562959043207,-0.3107131585467191
328.600000000004,19.996604417930214,2.6194325627363386,-0.32216763893222744
329.800000000004,20.03319269234248,2.6324327162443706,-0.335136475345017
331.000000000004,20.06966941514775,2.645126131440906,-0.3482394909168667
332.200000000004,20.106220570960275,2.6618578476649004,-0.3617852331109055
333.40000000000407,20.142857637994748,2.678914039474395,-0.3756894894906915
334.60000000000406,20.179363774156805,2.696882076334709,-0.3898439431677825
335.80000000000405,20.21591057187138,2.7190001102202364,-0.405334457427748
337.0000000000041,20.25261569163283,2.739697281138311,-0.4212819595989812
338.20000000000414,20.289281429388566,2.7663340142741157,-0.43840688525971316
339.4000000000041,20.325951542232442,2.7932963691640187,-0.4554500149060776
340.6000000000041,20.362408292504973,2.8217780561541717,-0.47358900435131623
341.80000000000416,20.39901492946338,2.853947616824589,-0.4936733702530791
343.0000000000042,20.43586419437881,2.8861634400888687,-0.5148882302704978
344.2000000000042,20.472306369428704,2.9180277462923727,-0.5363493886842807
345.4000000000042,20.509052027455468,2.9528472833081247,-0.5584713577463059
346.60000000000423,20.545987555235644,2.987590580108706,-0.5814108778106157
347.8000000000043,20.582485385033976,3.0251592657196134,-0.6032037829178183
349.00000000000426,20.61942095883487,3.0662928946145023,-0.629806492183163
350.20000000000425,20.656197227199403,3.1059362727637825,-0.6602946284379718
351.4000000000043,20.69287022097938,3.1496602469665125,-0.6887420588175779
352.60000000000434,20.73009202078029,3.1938987342739686,-0.7187346865658428
353.80000000000433,20.766257143935647,3.2431621448611287,-0.750182958510512
355.0000000000043,20.8030119047603,3.2929917418943515,-0.7820859950388175
356.20000000000437,20.83990577758143,3.3506391335358914,-0.8164963707635571
357.4000000000044,20.87726913260461,3.4098384076964288,-0.8592019746132422
358.6000000000044,20.91437779979649,3.4725713683375345,-0.901605432239271
359.8000000000044,20.951118662267266,3.535424158869036,-0.9429008785465713
361.00000000000443,20.98807309086594,3.6037870876201907,-0.9860969576801022
362.2000000000045,21.024878099464573,3.671708752427367,-1.0305574894746865
363.40000000000447,21.06202297244282,3.7376780827211524,-1.0779860498628135
364.60000000000446,21.098752292424777,3.8015670019844587,-1.1271491560768507
365.8000000000045,21.13593526842155,3.858767567491152,-1.1783428504604414
367.00000000000455,21.172958577728046,3.907665647476339,-1.231465687068778
368.20000000000454,21.210182787687852,3.9511107459743973,-1.2875537424531998
369.4000000000045,21.247291938426788,3.9816735899186773,-1.3442649236971436
370.60000000000457,21.284147387651842,4.003286589619598,-1.401176433900868
371.8000000000046,21.321615937806865,4.016372682895824,-1.4608821208638565
373.0000000000046,21.35823602002588,4.017757745616158,-1.5208224345008339
374.2000000000046,21.395626148690642,4.00558502379228,-1.58060716920575
375.40000000000464,21.432634708803104,3.984373562200813,-1.641142484361854
376.6000000000047,21.469812337999787,3.9465667164154725,-1.6988646258797768
377.8000000000047,21.506608102048798,3.889519557974052,-1.7550875417693792
379.00000000000466,21.543790090533335,3.810108440357898,-1.8106453873257031
380.2000000000047,21.580998965042546,3.714718480921629,-1.8658882563527124
381.40000000000475,21.618055626421288,3.597481681278019,-1.9185160237839898
382.60000000000474,21.65495483971165,3.464998608937341,-1.9662697543208747
383.80000000000473,21.69204390371549,3.3156943725120835,-2.010038383853618
385.0000000000048,21.72900066260732,3.162157849049261,-2.056309152444423
386.2000000000048,21.766097988508296,3.002792250201581,-2.0963625587650196
387.4000000000048,21.802691873270714,2.846032699319356,-2.1312513166805895
388.6000000000048,21.839729720324097,2.6935555629285877,-2.1616289304062852
389.80000000000484,21.876402524367467,2.554802152117836,-2.1893655337344877
391.0000000000049,21.913390648509225,2.4284512191179295,-2.2125111907372546
392.2000000000049,21.950598406857562,2.320756375677502,-2.2328621599288754
393.40000000000487,21.98725878258782,2.231123078915694,-2.2505307104569416
394.6000000000049,22.02418469454275,2.158647619876381,-2.2671719347346575
395.80000000000496,22.06098755638779,2.099377876689327,-2.2814614435676783
397.00000000000495,22.098159245432136,2.0566516509184813,-2.2941856376185816
398.20000000000493,22.1348567682756,2.0229889129368823,-2.3078098107325733
399.400000000005,22.171163223302603,1.9975918326453397,-2.3203538617901076
400.600000000005,22.208965683592492,1.9806245783468521,-2.3319292370633304
401.800000000005,22.24634191208586,1.9697274681004662,-2.3424816347146233
403.000000000005,22.28319577042151,1.9611402722751987,-2.354014178687907
404.20000000000505,22.320526792604586,1.9548447295028049,-2.3654127711987223
405.4000000000051,22.35742956351468,1.9539241141650197,-2.3774644156831695
406.6000000000051,22.394752961483523,1.9535867410783179,-2.389075882084352
407.80000000000507,22.432005155009264,1.9556503127505425,-2.4002699131052916
409.0000000000051,22.469307793920006,1.9584605246098732,-2.4117705785467933
410.20000000000516,22.506645664939086,1.9610918892275584,-2.423208277942183
411.40000000000515,22.544088445022865,1.9643424576646475,-2.4339601279482377
412.60000000000514,22.58144756558226,1.9680981472110637,-2.4455792240372776
413.8000000000052,22.618521110300076,1.9718414739385948,-2.4568935862518195
415.00000000000523,22.655940685057196,1.9793281447055389,-2.469279661379204
416.2000000000052,22.693451643372132,1.9814485824951062,-2.4817367419259497
417.4000000000052,22.73069465358661,1.9889833543629323,-2.493387971367442
418.60000000000525,22.768118058798542,1.992422024544233,-2.5058054588288172
419.8000000000053,22.805364766506464,1.9962724187215188,-2.5192081287967953
421.0000000000053,22.843138686396813,2.002361692502434,-2.532648878976847
422.2000000000053,22.879561690351892,2.009577042663311,-2.5471992597508852
423.4000000000053,22.91819145051448,2.015200333246196,-2.559999085809777
424.60000000000537,22.955727116550857,2.02092634112208,-2.5730862794037743
425.80000000000535,22.99310952134308,2.0256920854408933,-2.586157660930603
427.00000000000534,23.03073297055029,2.031978525260839,-2.6008295105171255
428.2000000000054,23.06831718376754,2.039293635258363,-2.6157032810612018
429.40000000000543,23.106276848176343,2.0449692459768714,-2.631447683069795
430.6000000000054,23.143433331254183,2.05128668420675,-2.6475991606607985
431.8000000000054,23.181217531906956,2.056911328762445,-2.662676468920295
433.00000000000546,23.218579821445072,2.0663083184861493,-2.678241958763025
434.2000000000055,23.256394094291906,2.0739629358978555,-2.695545000053404
435.4000000000055,23.294350736315756,2.0827965446612176,-2.714668489732459
436.6000000000055,23.33179741745267,2.08882129746722,-2.7316340067630756
437.8000000000055,23.369593265384637,2.095522142047666,-2.7486183730269182
439.00000000000557,23.407149321743546,2.1044210527517144,-2.7665552209303335
440.20000000000556,23.44487282407335,2.1141115828422348,-2.7861071939365205
441.40000000000555,23.482904297263,2.120449556958748,-2.8050542311571647
442.6000000000056,23.520281208681777,2.12844869184908,-2.824763321905902
443.80000000000564,23.55869317181649,2.135540654270923,-2.8447526705716957
445.0000000000056,23.5962635873115,2.14007822499567,-2.8639078506558477
446.2000000000056,23.633927998494475,2.146598259826593,-2.8850390733345956
447.40000000000566,23.671675974176985,2.1517634925941156,-2.9050743702599258
448.6000000000057,23.70978523148103,2.1580255298145987,-2.9253027973213666
449.8000000000057,23.747692720734086,2.1628522938290637,-2.9459015359008514
451.0000000000057,23.785401951690044,2.163614745293202,-2.9667323361597546
452.20000000000573,23.823284453674958,2.1672662754050114,-2.983592102604195
453.4000000000058,23.86134862690367,2.16764133932578,-2.9999695918208857
454.60000000000576,23.899286273004634,2.168445530196805,-3.01798193600636
455.80000000000575,23.937566340440256,2.169255712176351,-3.0338908837697773
457.0000000000058,23.975258342111598,2.166674705001242,-3.04947541795213
458.20000000000584,24.01342345936046,2.1642998657872843,-3.065702845798204
459.40000000000583,24.051378244706292,2.1597564789157957,-3.080603804143313
460.6000000000058,24.089073072129153,2.155075299799667,-3.0939240582067304
461.80000000000587,24.127155968605834,2.1464477229130607,-3.106955169042652
463.0000000000059,24.16529679097803,2.137233437251999,-3.1183265458715983
464.2000000000059,24.203357849794262,2.128634114349845,-3.129895662012985
465.4000000000059,24.241368832044373,2.117873888847888,-3.1405038574056308
466.60000000000593,24.27942152577057,2.1054114529108583,-3.150500565496794
467.800000000006,24.317690370811516,2.0904620503707974,-3.1603237797952186
469.00000000000597,24.355712302960168,2.0747394993910153,-3.1699683109457637
470.20000000000596,24.393737232014256,2.0602597643246305,-3.178332075385011
471.400000000006,24.431963002668045,2.041582395912377,-3.1863118114733964
472.60000000000605,24.469661678677202,2.024776294200504,-3.195003275041054
473.80000000000604,24.50769705605121,2.0067414307470073,-3.2011649719438373
475.000000000006,24.546022702958435,1.9864119358777472,-3.2065946878318776
476.20000000000607,24.584304148259537,1.9661246654990687,-3.2134108735381255
477.4000000000061,24.622321896164628,1.949747918215505,-3.219228837848646
478.6000000000061,24.660568160164168,1.9344143988503137,-3.2243275062390104
479.8000000000061,24.698808015557262,1.9145031415086238,-3.2305616088857994
481.00000000000614,24.736785561919806,1.8999773565015055,-3.235043595146793
482.2000000000062,24.774939639247947,1.8842186778678536,-3.238088863046055
483.4000000000062,24.812976411477504,1.8702443250738838,-3.2425540944185993
484.60000000000616,24.851369768408844,1.8590128754652677,-3.246329771056816
485.8000000000062,24.88928602290134,1.8474530770527262,-3.2491423721060935
487.00000000000625,24.927585253751865,1.8378935853301475,-3.2517829462919265
488.20000000000624,24.96582239976262,1.8274744162745244,-3.255655425300069
489.40000000000623,25.00399039666591,1.82021709650423,-3.2587478436208857
490.6000000000063,25.042391732241402,1.8136542987952844,-3.2613535449789266
491.8000000000063,25.08054126706115,1.8103713024792503,-3.2641745927816777
493.0000000000063,25.118940983121483,1.8032302381322893,-3.26735177159947
494.2000000000063,25.157171062374793,1.7983157322321561,-3.268982384950827
495.40000000000634,25.19552596148418,1.795385120539404,-3.271745743105912
496.6000000000064,25.23395979497665,1.7925948768142232,-3.2738551577823456
497.8000000000064,25.272215984628552,1.7933629379438554,-3.275509290907304
499.00000000000637,25.31025487035196,1.7911172523224288,-3.2781082161147843
500.2000000000064,25.349108837659834,1.791763781191302,-3.2813672948654578
501.40000000000646,25.387264879422144,1.7905219144305418,-3.282834409074462
502.60000000000645,25.425881719701245,1.7921958983036808,-3.2841594995631174
503.80000000000643,25.46387856206888,1.7931001342742463,-3.2843551921299956
505.0000000000065,25.502340676871867,1.7922356137929512,-3.2855488684749172
506.2000000000065,25.540675271472367,1.7948710113623236,-3.2868796993219913
507.4000000000065,25.57905166215042,1.7963763881210895,-3.2892159931453513
508.6000000000065,25.617551958652076,1.8003300453980189,-3.2906175892422524
509.80000000000655,25.656277344449933,1.803627317300831,-3.291997743087494
511.0000000000066,25.69456426723688,1.8064231229493868,-3.293469116066352
512.2000000000066,25.733068199585198,1.8079397845435963,-3.2949506584727115
513.4000000000066,25.771495781649296,1.8110776381480063,-3.294859246109122
514.6000000000066,25.810065946206198,1.8120670713141014,-3.2962884181811574
515.8000000000067,25.847742950594174,1.8160160496025533,-3.297745946165937
517.0000000000066,25.8869040002812,1.8181917049942269,-3.298972715517217
518.2000000000066,25.92540252000628,1.8211896136357755,-3.3006569270619406
519.4000000000067,25.96418713301231,1.824655763847218,-3.301327267549209
520.6000000000067,26.002828995318346,1.8269117426573689,-3.3018861301659506
521.8000000000068,26.04131445573788,1.8329119673227978,-3.303226340997835
523.0000000000067,26.0797376005507,1.8346370154399192,-3.305040569982981
524.2000000000068,26.11867764191693,1.8377028335137902,-3.306780098911023
525.4000000000068,26.15700601316836,1.8389071827784456,-3.306744646766286
526.6000000000067,26.195693701078554,1.842656343104043,-3.3084045115129035
527.8000000000068,26.234500378161503,1.8450730042188481,-3.3115265775318177
529.0000000000068,26.272913052574285,1.847096975743194,-3.310031010627303
530.2000000000069,26.31173474331319,1.849967019926943,-3.3100018794493216
531.4000000000069,26.35029508375033,1.8528366702708603,-3.3114373066199554
532.6000000000068,26.389060900666756,1.8573603143091402,-3.3114294076548707
533.8000000000069,26.427993443082087,1.8596279909374305,-3.312588325253729
535.0000000000069,26.46633332215088,1.8634024254310122,-3.312751387178169
536.2000000000069,26.505253677472844,1.8681877756574494,-3.3142278434247734
537.4000000000069,26.54400706361801,1.8685549949076927,-3.3149146365266953
538.600000000007,26.58277339080738,1.8734884292421599,-3.31550245942608
539.800000000007,26.621531215870334,1.8807272752805853,-3.316806798854975
541.000000000007,26.66000000000022,1.882750000000006,-3.3168001720027935
542.200000000007,26.69901664700395,1.8852427396471474,-3.318123999072712
543.400000000007,26.737625308723743,1.890788910510963,-3.319453130887616
544.6000000000071,26.776335279757344,1.893771535724269,-3.319376273381117
545.800000000007,26.815296378477573,1.8976163233010226,-3.3220422003952987
547.000000000007,26.854130031952263,1.9033023314855915,-3.3220572046909913
548.2000000000071,26.892904774111667,1.9055856201488692,-3.3234652119804413
549.4000000000071,26.931363997639885,1.9109787060916692,-3.3224889307227583
550.6000000000072,26.970597695871845,1.9152769520779014,-3.3237102809131094
551.8000000000071,27.00964861234528,1.9200675159304943,-3.3237087641317897
553.0000000000072,27.04844749756412,1.9231330865338494,-3.3250205205629344
554.2000000000072,27.087273238443608,1.9265293962544654,-3.32546533316758
555.4000000000071,27.126311085350306,1.9312431253475826,-3.3263464619040013
556.6000000000072,27.164813385403374,1.9344942612470597,-3.327649204286866
557.8000000000072,27.203908642432456,1.9375071577106526,-3.329029496063518
559.0000000000073,27.242700680270865,1.9436115979174247,-3.329309622728264
560.2000000000073,27.281703763222026,1.946642979869529,-3.330610839568226
561.4000000000073,27.32073957814338,1.9504213055909627,-3.330611688595066
562.6000000000073,27.359488461422252,1.9550297496746332,-3.3329038172720944
563.8000000000073,27.39838007774796,1.959595619561888,-3.332882180671189
565.0000000000073,27.437359009470686,1.9651658974404478,-3.3342343406298975
566.2000000000073,27.476531085790384,1.9679438718062894,-3.3356182764990914
567.4000000000074,27.515377324132082,1.9730965147688322,-3.3355437106578405
568.6000000000074,27.554334791029827,1.9791226360720564,-3.3367795022056246
569.8000000000075,27.593074163036164,1.9819922301784598,-3.336836933960808
571.0000000000074,27.631919756844752,1.9880547280322352,-3.338180300671916
572.2000000000074,27.671437969355615,1.9915353478767668,-3.3382870306844286
573.4000000000075,27.710591723364782,1.997087852231796,-3.339500334186728
574.6000000000074,27.74946462195192,2.0014795118408797,-3.3394992126436907
575.8000000000075,27.788837480762197,2.008344613848852,-3.340783534640363
577.0000000000075,27.82752683301665,2.011981805275757,-3.339840304118857
578.2000000000075,27.86660638180735,2.0168456161071355,-3.339741963076485
579.4000000000076,27.905707673155447,2.0214980712360684,-3.341151269192241
580.6000000000075,27.945078958133607,2.027881171529251,-3.341612053356564
581.8000000000076,27.98362093283898,2.030316983632858,-3.342433874570893
583.0000000000076,28.023176861708833,2.03455515312371,-3.3437762177603263
584.2000000000075,28.06227425493308,2.041493241239935,-3.3437897899055686
585.4000000000076,28.101252847059992,2.0443489779654853,-3.343778710067869
586.6000000000076,28.140459210838358,2.050182841294474,-3.345096186045321
587.8000000000077,28.179466348335982,2.0547553396921168,-3.3457141295490547
589.0000000000077,28.21874025521639,2.060225254285038,-3.346416190058549
590.2000000000077,28.256930548752976,2.062575493324496,-3.347725939072976
591.4000000000077,28.297033122620725,2.069462795705957,-3.348424138078886
592.6000000000078,28.336003722698095,2.0738848077971324,-3.3490503889465204
593.8000000000077,28.37540527487047,2.0791721140196815,-3.3490434482873566
595.0000000000077,28.414676743073073,2.084553220991856,-3.3502982594640107
596.2000000000078,28.45399299357643,2.090752143054897,-3.3502924647913552
597.4000000000078,28.49304112195143,2.094281895493477,-3.3516873215296714
598.6000000000079,28.532386948306527,2.0988082583286154,-3.353043971425701
599.8000000000078,28.57161949676892,2.105014000121041,-3.353008710076404
601.0000000000078,28.610835451034138,2.1118325747934006,-3.3543226908078245
602.2000000000079,28.649802543066563,2.116625384258294,-3.354319139229335
603.4000000000078,28.689360448883825,2.1229337727285396,-3.3556276484692544
604.6000000000079,28.728596567337185,2.130478105436803,-3.356175013029179
605.8000000000079,28.768423562165314,2.137818338888813,-3.3569508986499335
607.000000000008,28.807350921879276,2.142572938904408,-3.356915419569106
608.200000000008,28.846826674870872,2.1476812659629974,-3.3579302120178625
609.4000000000079,28.88657060860537,2.154696995627226,-3.3589541638219114
610.600000000008,28.92564701955589,2.1595287059073693,-3.359334775391448
611.800000000008,28.965131682832478,2.1629882220149113,-3.360591038992526
613.000000000008,29.004357214213265,2.1675126542945113,-3.362005629101986
614.200000000008,29.044061573643848,2.172149030808167,-3.364405565754964
615.400000000008,29.083077211070517,2.1753088567394427,-3.3635475002465185
616.6000000000081,29.122621697400266,2.178675752654537,-3.3640042005057382
617.8000000000081,29.16214841345906,2.1831555046638194,-3.3651166266087986
619.0000000000081,29.20143293427189,2.1898274231321677,-3.3663816708223235
620.2000000000081,29.240849202493084,2.199210070246153,-3.36780449010498
621.4000000000082,29.280164769656885,2.205608806090054,-3.3691216736337624
622.6000000000081,29.319711258180728,2.2128048406648424,-3.370579393535794
623.8000000000081,29.359236624498987,2.22405608149086,-3.371699851299743
625.0000000000082,29.398904386902746,2.228348055213007,-3.372740670862363
626.2000000000082,29.437900986369176,2.2344461897324184,-3.3729984348381117
627.4000000000083,29.47737347417909,2.239676132588092,-3.374310507658172
628.6000000000082,29.51685921918618,2.245771926131129,-3.375709147971922
629.8000000000083,29.556097657123235,2.2532184125331693,-3.3762917508237216
631.0000000000083,29.59566003765571,2.259648084041786,-3.377021494251424
632.2000000000082,29.635092756297908,2.2639509433053155,-3.3772923318380412
633.4000000000083,29.674453489779083,2.271405270563621,-3.378327622444539
634.6000000000083,29.71415693671198,2.2787124024092087,-3.37768711197239
635.8000000000084,29.753633244326256,2.2864200622464095,-3.3789632862585752
637.0000000000084,29.792880489798502,2.295258290256721,-3.3789355637501974
638.2000000000083,29.832283129664727,2.298179975552237,-3.3803085321506456
639.4000000000084,29.87224952882835,2.3060727932312495,-3.3803100303006053
640.6000000000084,29.911473500175912,2.310803182914687,-3.380310312762962
641.8000000000084,29.950891126098835,2.3152281104092416,-3.3803407865921677
643.0000000000084,29.990567129542594,2.322269189703428,-3.3816311512153048
644.2000000000085,30.030097015853592,2.3270030433136215,-3.381665146328772
645.4000000000085,30.069602262671967,2.333295915587286,-3.3822742605812266
646.6000000000085,30.108993097240038,2.337675255777348,-3.382535598557788
647.8000000000085,30.148524551470473,2.3442507773992927,-3.3836017490898533
649.0000000000085,30.18809873763699,2.3474922136496383,-3.3835610074800915
650.2000000000086,30.227655593465855,2.3547308906161653,-3.3849035983684495
651.4000000000085,30.266797496037963,2.3582019482072463,-3.384909768950085
652.6000000000085,30.30611152261069,2.3660779527904814,-3.384911625322178
653.8000000000086,30.345601223587913,2.369038440751048,-3.3854416049574905
655.0000000000086,30.385565803631764,2.378317171049553,-3.3872040779687804
656.2000000000087,30.425073400591526,2.384172138074123,-3.3872216103811095
657.4000000000086,30.464332810185734,2.3895781944506487,-3.3876120467873454
658.6000000000087,30.50413443561373,2.3969327367900366,-3.387407660561828
659.8000000000087,30.543885193682183,2.402056016981098,-3.387221225334312
661.0000000000086,30.583327193080684,2.405085509080372,-3.3872212170341744
662.2000000000087,30.62294608129073,2.4129542710096143,-3.388624960532632
663.4000000000087,30.66283638362366,2.420266856668103,-3.388537584290073
664.6000000000088,30.70280954479135,2.4270191253629725,-3.3898999843965796
665.8000000000088,30.74240282878219,2.435981828311537,-3.3898502624817803
667.0000000000088,30.782176696946536,2.4415556753047634,-3.3898500095083883
668.2000000000088,30.821874343160516,2.447000551735043,-3.3898474977020085
669.4000000000088,30.86155661656353,2.455306705755312,-3.3909568160894263
670.6000000000088,30.90107221887656,2.457527295043731,-3.3911693077400082
671.8000000000088,30.940716985883434,2.462010579889633,-3.390998997050394
673.0000000000089,30.98045048169818,2.4683680856546566,-3.389846561592771
674.2000000000089,31.020098182113422,2.4796542900248877,-3.3898529636888783
675.400000000009,31.059696709384358,2.484973665449772,-3.391157094664646
676.6000000000089,31.099186912472383,2.4889846287365036,-3.3902217803300925
677.8000000000089,31.139022705905848,2.496949490592,-3.38964522742084
679.000000000009,31.178823535730576,2.5036507069785627,-3.3913034843169685
680.2000000000089,31.21824629364863,2.5123354130098594,-3.392101261655869
681.400000000009,31.25786414000422,2.520343756319208,-3.39361998520077
682.600000000009,31.29821179950494,2.5269148896881197,-3.3944513331089863
683.800000000009,31.338018416396952,2.5336175484153136,-3.3944498844606437
685.0000000000091,31.37759209439647,2.539711436789603,-3.3944498738663267
686.200000000009,31.417285368425297,2.5477784357958777,-3.394449431924113
687.4000000000091,31.45711471874915,2.5581192028525606,-3.394365215582977
688.6000000000091,31.496488839589418,2.5632703392516474,-3.3957685530127333
689.800000000009,31.53645324470057,2.5708613516574,-3.3957700340857535
691.0000000000091,31.57622281009118,2.5779260950633605,-3.395769668825329
692.2000000000091,31.61585068415953,2.585600806288296,-3.3967271097037273
693.4000000000092,31.656178375211304,2.5946934938642685,-3.397088256248984
694.6000000000092,31.695567210147203,2.601044798114702,-3.3970720337838376
695.8000000000092,31.73532125028797,2.6086222568668913,-3.3957829189643047
697.0000000000092,31.775137022085033,2.616348496106746,-3.3944627706188797
698.2000000000093,31.815015382664896,2.624210149726564,-3.3955680401736372
699.4000000000092,31.85493245290126,2.631971631316865,-3.396616132489016
700.6000000000092,31.894633371963586,2.6386844357572454,-3.397527888147404
701.8000000000093,31.934386269830785,2.6459097815993657,-3.3972677565822123
703.0000000000093,31.974142015315703,2.654042933528877,-3.398615522623982
704.2000000000094,32.01399443320359,2.663469801064455,-3.3986299158341464
705.4000000000093,32.054012982539334,2.6701521310371197,-3.398629989462619
706.6000000000093,32.09372071268774,2.678514693084886,-3.398629965341354
707.8000000000094,32.13342891377499,2.685585782918632,-3.3986257239989914
709.0000000000093,32.17324725220504,2.6898165441854123,-3.399811034807287
710.2000000000094,32.2131296077312,2.696655092680139,-3.399939957502381
711.4000000000094,32.25330945344297,2.7041309091709076,-3.3999401007607455
712.6000000000095,32.293419792705826,2.710926569072099,-3.3999389030517486
713.8000000000095,32.33330470991533,2.720104341758122,-3.3995827456152856
715.0000000000094,32.37311073933195,2.7278494458167106,-3.399923648617581
716.2000000000095,32.413001640907986,2.737864471504985,-3.399939573791201
717.4000000000095,32.45310349949022,2.7437250343438433,-3.3998974199682657
718.6000000000095,32.49309783243696,2.7499348517936997,-3.402014130793183
719.8000000000095,32.53309898348648,2.7582572929377,-3.401920605842051
721.0000000000095,32.57296379700514,2.7652210168036513,-3.401941268658227
722.2000000000096,32.61311610667814,2.775484809708005,-3.4032371225175755
723.4000000000096,32.6528361003904,2.7820579879865233,-3.403230193808555
724.6000000000096,32.69295988169318,2.7917278738309084,-3.4032301602887136
725.8000000000096,32.733422580477,2.7978470296741134,-3.403230180002967
727.0000000000097,32.77330034873639,2.8056387378401646,-3.4032341836211493
728.2000000000096,32.81363860241079,2.812471890966782,-3.40213956116943
729.4000000000096,32.853541032609456,2.823566818143497,-3.4019116360125494
730.6000000000097,32.89357453625102,2.8304603343939445,-3.4020751169783106
731.8000000000097,32.93345919055983,2.8369121927212513,-3.4032345679889984
733.0000000000098,32.97394609578053,2.847052892832371,-3.403409859941993
734.2000000000097,33.01433329671124,2.854342068103843,-3.4060611994187493
735.4000000000098,33.0543135909443,2.8641218759261133,-3.4089424292369586
736.6000000000098,33.094375134692356,2.873235167287134,-3.410222525574018
737.8000000000097,33.134729735357894,2.8809490542364458,-3.410249733706947
739.0000000000098,33.174642303480255,2.8879639044976457,-3.410238244511123
740.2000000000098,33.21469121302044,2.896537090978916,-3.4088244978242703
741.4000000000099,33.254780960562485,2.903159686141251,-3.4076029700589343
742.6000000000099,33.29485170015053,2.9130353126629513,-3.4076101344002625
743.8000000000098,33.33521562191505,2.9206414094051256,-3.4076119556162157
745.0000000000099,33.3755238944623,2.926617338164592,-3.4063031810601743
746.2000000000099,33.41572828379491,2.9342906835134404,-3.4047644399880275
747.4000000000099,33.45550742769846,2.9441738709481142,-3.404760018051133
748.6000000000099,33.49590284862644,2.951892345764495,-3.4047624690558553
749.80000000001,33.535838481991384,2.962615858667091,-3.406214201935591
751.00000000001,33.576154560618775,2.9731144534413434,-3.406090340318569
752.20000000001,33.61648961206037,2.979782763118507,-3.406418615074203
753.40000000001,33.65683152472667,2.989759299818538,-3.4064199079160398
754.60000000001,33.69699434835738,2.998685547588551,-3.4064198923759004
755.8000000000101,33.7373397938861,3.006063758333436,-3.4064158146969783
757.00000000001,33.77725686423119,3.0172804557600497,-3.407715393679304
758.20000000001,33.81751194400457,3.0237505011616954,-3.4077421626781934
759.4000000000101,33.857987832128195,3.0376499140362667,-3.4090737860730336
760.6000000000101,33.89799206538871,3.044677705209582,-3.4087061324068593
761.8000000000102,33.938596838332614,3.053400296490688,-3.4087208045487447
763.0000000000101,33.97874937792515,3.0622233448331304,-3.4092764465371364
764.2000000000102,34.01903592668015,3.071255358850351,-3.410034322237091
765.4000000000102,34.058995945132786,3.0817839535188565,-3.4093216861218405
766.6000000000101,34.09946731072835,3.0881234978155496,-3.410687672016445
767.8000000000102,34.13954105559099,3.0995741855842005,-3.411997743180937
769.0000000000102,34.17966174353411,3.1059034678511312,-3.411335798442733
770.2000000000103,34.21993161933357,3.117118528900199,-3.4113497784886473
771.4000000000103,34.26003296661019,3.126184504049113,-3.411349855345918
772.6000000000103,34.30017111011807,3.132446039010924,-3.411355331750248
773.8000000000103,34.34053203149906,3.14321409512955,-3.412661028622834
775.0000000000103,34.38078891436036,3.153364011692433,-3.4126599758723044
776.2000000000103,34.42086326577256,3.159819408505815,-3.4126600507703975
777.4000000000103,34.461034144789735,3.1705164593863366,-3.412679421708627
778.6000000000104,34.50102850048432,3.1823233753320275,-3.4111322459153124
779.8000000000104,34.54145177660797,3.1923351823116946,-3.411187380899621
781.0000000000105,34.58188487435483,3.19826031103031,-3.4141471739332054
782.2000000000104,34.62206682307143,3.209587389943785,-3.4152477723987653
783.4000000000104,34.66216433849416,3.221523766294628,-3.416530661463706
784.6000000000105,34.70236325093161,3.229072585749207,-3.4161781421417805
785.8000000000104,34.74261149490888,3.237769342475762,-3.416179926224825
787.0000000000105,34.782806120106905,3.250210629595732,-3.416174385287503
788.2000000000105,34.82301151882094,3.2580697657076496,-3.416767032096873
789.4000000000106,34.86324195069455,3.2690491704670275,-3.417158881548537
790.6000000000106,34.90355060241701,3.278503576723833,-3.415564138204126
791.8000000000105,34.94361657585473,3.2868450698140275,-3.4148616897932644
793.0000000000106,34.98396527974903,3.2988967291108477,-3.4148599673025313