File: 01_Data/EIFS_XPS/STA/N2/30K_min/EIFS_XPS_STA_N2_30KData_230901_R2.csv
##Temp./Â°C,Time/min,DSC/(mW/mg),Mass loss/mg
41.0,10.562621881402361,-2.2906686247004053,-0.004336623945533802
42.100000000000016,10.74938363344144,-2.236638239749843,0.0006771444640150115
43.20000000000003,10.873114707349963,-2.1935378621113384,-0.0023784875105392622
44.30000000000005,10.970828010323597,-2.158984853815246,-0.0011590489390571612
45.40000000000006,11.055582335583146,-2.1253929769901254,-0.0006285210654084494
46.50000000000008,11.129270986930253,-2.096297259252838,-0.0019909226633911814
47.600000000000094,11.196760753915443,-2.069485867770357,-0.0030156813697810314
48.70000000000011,11.25868636931819,-2.0441095739831137,-0.0013710998493703386
49.800000000000125,11.318783931430016,-2.017060003537025,-0.0033782422612431695
50.90000000000014,11.375628825049514,-1.9937580371110595,-0.0014271224396695814
52.000000000000156,11.429758608630747,-1.9694294924721003,-0.0019236654164118683
53.10000000000017,11.481016066250193,-1.947504669704041,-0.0020758669866549617
54.20000000000019,11.531580290858894,-1.9268529331715905,-0.0061219178373033145
55.3000000000002,11.58098251775144,-1.9075512599058757,-0.007980594637400085
56.40000000000022,11.628456734256684,-1.8862552979331866,-0.005012437383975055
57.500000000000234,11.675020954458244,-1.8668202445505764,-0.004073581498678536
58.60000000000025,11.720254959538297,-1.8504993632911402,-0.0055139889471558234
59.700000000000266,11.765325687133101,-1.8302033441743746,-0.0037850289024574657
60.80000000000028,11.809452478101347,-1.8131128930577514,-0.002240772735296215
61.9000000000003,11.853007694757533,-1.797407483305643,-0.001622368812192132
63.00000000000031,11.895384219893778,-1.7807988526264973,-0.0026310182722646402
64.10000000000034,11.93790520320221,-1.7647662912977384,-0.0026187131148196485
65.20000000000034,11.979503019867538,-1.7506580796177402,-0.0035942738645027283
66.30000000000035,12.021277270245541,-1.737980559815392,-0.0029301950072344596
67.40000000000038,12.06212795735773,-1.7212870720840419,-0.003941545593906248
68.5000000000004,12.103099855873928,-1.7068592317728968,-0.006368138480109753
69.6000000000004,12.142716770955907,-1.6936571179266808,-0.005412684314114458
70.70000000000041,12.183319698420759,-1.6832004348297172,-0.005316388909669456
71.80000000000044,12.222745751514026,-1.6698865452064904,-0.0039207972029946525
72.90000000000046,12.262457427902964,-1.6580575930370136,-0.004095752205060421
74.00000000000047,12.30187473953459,-1.6478843872361242,-0.005412886908507275
75.10000000000048,12.341916300858841,-1.6368578488273693,-0.0048039861497746195
76.2000000000005,12.380470493693911,-1.6259014746279414,-0.0035162664044952052
77.30000000000052,12.419615201746296,-1.6178612015507958,-0.0020025949057389525
78.40000000000053,12.457796281188687,-1.6088798241615785,-0.0017612886119864335
79.50000000000054,12.496980238692087,-1.6032244857159232,-0.003170407886305515
80.60000000000056,12.535753880327828,-1.5962488870910527,-0.005186979506389466
81.70000000000059,12.57438576816186,-1.593125517062155,-0.005847467359052949
82.8000000000006,12.612698345862363,-1.5909270709148011,-0.006087066678088782
83.9000000000006,12.650954589880941,-1.584984289182123,-0.004703131725295684
85.00000000000063,12.688428374557999,-1.580063049972519,-0.004290855669462967
86.10000000000065,12.726111921658973,-1.569426379211975,-0.00425811114524155
87.20000000000066,12.763845622277396,-1.5538137360358149,-0.005541939148360875
88.30000000000067,12.801368604696819,-1.5357878778556633,-0.0041883736996570775
89.40000000000069,12.839063096045026,-1.5127009917091325,-0.005609960165313677
90.50000000000071,12.875673278813176,-1.49287091410881,-0.0042881412888893244
91.60000000000072,12.912937078758727,-1.4759146317129073,-0.004130980060773393
92.70000000000073,12.950065159751603,-1.4619810081124927,-0.003106322130687289
93.80000000000075,12.98705036229442,-1.451652955546339,-0.004393687707880289
94.90000000000077,13.024160103712418,-1.4392887340005123,-0.004865439695480145
96.00000000000078,13.060912233733816,-1.4325896599590096,-0.00560617178375189
97.10000000000079,13.097265904352865,-1.424614104619602,-0.007019367100929319
98.20000000000081,13.134690344214667,-1.4215992414279117,-0.007020557179611586
99.30000000000084,13.171665233748264,-1.418799372194062,-0.007762481309605551
100.40000000000084,13.208627978315508,-1.4157766731572325,-0.0060098489881372785
101.50000000000085,13.245285027128919,-1.4137949396166294,-0.006121487653762081
102.60000000000088,13.282655818579736,-1.4145394637984392,-0.00472056101515772
103.7000000000009,13.318950969322621,-1.4194068445319854,-0.0031491323436303453
104.8000000000009,13.355959417277345,-1.4231246174991479,-0.0045095091485438665
105.90000000000092,13.39273699833166,-1.4326720245210456,-0.004490242739592087
107.00000000000094,13.430068522943964,-1.4448386053297064,-0.004489966731493045
108.10000000000096,13.466368936171968,-1.4577538368490912,-0.004399017848780051
109.20000000000097,13.503643010905627,-1.4730418184972867,-0.0031178169057786143
110.30000000000098,13.54019668012077,-1.4861602762556463,-0.003056484040790952
111.400000000001,13.57730075583522,-1.4976467304184518,-0.0033400147408850778
112.50000000000102,13.613619752187915,-1.5036267159040588,-0.0030724593867517136
113.60000000000103,13.650224434791156,-1.5064962499356356,-0.003070156709965133
114.70000000000104,13.68685113246955,-1.50612389852401,-0.0030701598596061253
115.80000000000106,13.722932128302974,-1.4981525630638837,-0.003070619669709451
116.90000000000109,13.759522497167374,-1.492798807939323,-0.003049280080465344
118.0000000000011,13.796090560977252,-1.4938545566826638,-0.0043780044734984536
119.1000000000011,13.831756080492582,-1.4977022369729807,-0.0043871610212424805
120.20000000000113,13.867964389098297,-1.5018507717312968,-0.005763093692328525
121.30000000000115,13.904544460877531,-1.5036379978147634,-0.007252770286278132
122.40000000000116,13.940979899540752,-1.5069948419750125,-0.007240471031065621
123.50000000000117,13.9771430870494,-1.5094983393959212,-0.008328088739607331
124.60000000000119,14.013370907179784,-1.5090116959342121,-0.008488739815335933
125.70000000000121,14.049627978191076,-1.505817256388208,-0.010316525395392961
126.80000000000122,14.085009774995068,-1.498897371084188,-0.012574321212169615
127.90000000000123,14.12033335800618,-1.4873134543172748,-0.013940395333377431
129.00000000000125,14.156267935148046,-1.4740558350509645,-0.013929132764235685
130.10000000000127,14.191633053015217,-1.4619849359766484,-0.013930137384158936
131.2000000000013,14.226888278150987,-1.4435384380288787,-0.013901743505001285
132.3000000000013,14.262571281404753,-1.4279469961501041,-0.012593890899637472
133.4000000000013,14.297683172609895,-1.4099554946839858,-0.013947988901086283
134.50000000000134,14.33259647188834,-1.392612453357917,-0.013628761909450393
135.60000000000133,14.367764301639113,-1.3752831611246463,-0.01349244226605295
136.70000000000135,14.402984188707396,-1.3555450980023587,-0.011494303386483828
137.80000000000138,14.437975465068622,-1.3390816763342483,-0.011078321534733426
138.9000000000014,14.473040801041757,-1.3259329984161776,-0.0110752504996956
140.00000000000142,14.50792494066434,-1.3103580847200793,-0.012432395585319167
141.10000000000142,14.543142165924632,-1.2990711292248422,-0.013592859191650764
142.20000000000144,14.577761914123657,-1.2874931881193803,-0.013643791896281066
143.30000000000146,14.61295053577368,-1.2797002260428865,-0.015038228736157233
144.40000000000146,14.647762148099064,-1.2710862917274057,-0.015009219298822263
145.50000000000148,14.682340084716724,-1.2642261367800594,-0.01600553948148642
146.6000000000015,14.717003116064651,-1.2575194405352734,-0.016692956099531475
147.70000000000152,14.751690858465835,-1.2507154107032463,-0.016690006822932535
148.80000000000155,14.786844342324208,-1.2453311928356088,-0.01668996967492964
149.90000000000154,14.821682806012578,-1.238914973127965,-0.01668997000652883
151.00000000000156,14.856110227486361,-1.2333844384093349,-0.016689968460929627
152.1000000000016,14.890570193212033,-1.2280796039437518,-0.016689939169556745
153.20000000000158,14.925421647769754,-1.222226456162492,-0.016706274275009037
154.3000000000016,14.959379831856534,-1.2175255953512798,-0.017664524225233347
155.40000000000163,14.994246852202153,-1.211782274734036,-0.01935283050804637
156.50000000000165,15.028950538268187,-1.209327087507546,-0.020738566218548637
157.60000000000167,15.062920163091153,-1.2039740123919722,-0.0208101894450472
158.70000000000167,15.097681363108606,-1.200474857218281,-0.019428646539592087
159.8000000000017,15.132277872270143,-1.195946292200799,-0.020836708745086252
160.9000000000017,15.166562941650477,-1.1914205748720006,-0.01971494195596568
162.0000000000017,15.200771229652693,-1.188051075003107,-0.01869834618982047
163.10000000000173,15.235290125893796,-1.1839633714723434,-0.017612313014016667
164.20000000000175,15.269571319921873,-1.1784445950141633,-0.01679024601408985
165.30000000000177,15.303966150849357,-1.1730954129364248,-0.01683205246374264
166.4000000000018,15.33831750679538,-1.169149885011563,-0.018069356023164396
167.5000000000018,15.371833258895498,-1.1656946130675,-0.019429222771373933
168.6000000000018,15.406700621665294,-1.1619229626189058,-0.019335732642567383
169.70000000000184,15.441123003172793,-1.1560931799335563,-0.020847070453869243
170.80000000000183,15.475120488693662,-1.1528164612867688,-0.020836909613533905
171.90000000000185,15.509524494293345,-1.1501062058135485,-0.0195000085717556
173.00000000000188,15.543698315646225,-1.1473972052639834,-0.019530802350121945
174.1000000000019,15.576838406885882,-1.1438541078393931,-0.019529801712899086
175.20000000000192,15.611780012180228,-1.1386015122350213,-0.01952978550580209
176.30000000000192,15.645697456783447,-1.1370076369040396,-0.01953285069684707
177.40000000000194,15.67939673598338,-1.132436053475239,-0.018926436586316875
178.50000000000196,15.71364822884341,-1.1289679878721361,-0.018367726150603225
179.60000000000196,15.747633865541593,-1.1251487594746483,-0.017777396297341763
180.70000000000198,15.78122383021845,-1.1230559847940422,-0.017784794872401477
181.800000000002,15.815408936837565,-1.117496346131985,-0.017053497267735196
182.90000000000202,15.849564919993671,-1.1146733349928792,-0.01645962614741192
184.00000000000205,15.883738355511374,-1.109838476381481,-0.016452005095569433
185.10000000000204,15.917533527816259,-1.1053668298452868,-0.017805064469927245
186.20000000000206,15.950945257516127,-1.1016307956131337,-0.017781640793289366
187.3000000000021,15.983717905810941,-1.0972074581264992,-0.017436946873513826
188.40000000000208,16.01843350731185,-1.0936710279489668,-0.016460708196311735
189.5000000000021,16.052356683008576,-1.0903205692110765,-0.01646049366848512
190.60000000000213,16.08595909419397,-1.086902338900642,-0.017560807224031194
191.70000000000215,16.119363948041034,-1.0826220251499907,-0.01928222850185657
192.80000000000217,16.153071412763296,-1.0788360924855185,-0.019318291068826987
193.90000000000217,16.186909847138537,-1.0758569275514038,-0.01931999520323835
195.0000000000022,16.22054954951017,-1.0695247289730323,-0.0193200565988505
196.1000000000022,16.25391431578015,-1.0667532669555375,-0.019283184124719632
197.2000000000022,16.28783066592509,-1.0641047872657496,-0.020644177434874678
198.30000000000223,16.32117855353332,-1.0602552084132268,-0.01905211159723752
199.40000000000225,16.35499824524579,-1.056854014272741,-0.017848447328170813
200.50000000000227,16.388122606869082,-1.0539748080761053,-0.017779632170773496
201.6000000000023,16.421785455331328,-1.0517235795486761,-0.017777471757375096
202.7000000000023,16.4555191932322,-1.0465719393188269,-0.018290779917927935
203.8000000000023,16.488961688529564,-1.0423497578958856,-0.01909972559234152
204.90000000000234,16.52245281605523,-1.0404728747125915,-0.019113282280248
206.00000000000233,16.55605928438794,-1.0374849854588368,-0.02037190159067226
207.10000000000235,16.589969105926016,-1.0336524466848953,-0.020410172384878855
208.20000000000238,16.623107405516517,-1.0317552968563009,-0.02041139689463467
209.3000000000024,16.656391560347778,-1.0299635191781804,-0.020309184109621903
210.40000000000242,16.690180104639573,-1.0266014202091285,-0.02172965602553134
211.50000000000242,16.723553875320277,-1.0262791188783984,-0.021732522976485313
212.60000000000244,16.757243620174908,-1.0244803928312576,-0.021297120578188
213.70000000000246,16.790624406369528,-1.0229686851837454,-0.020409029236878595
214.80000000000246,16.824110201178037,-1.0201396929677737,-0.020410239337547154
215.90000000000248,16.85753459387774,-1.0193950575754598,-0.020410138405022593
217.0000000000025,16.891127580141116,-1.0189037817571371,-0.02040871093043517
218.10000000000252,16.924366774575553,-1.0180228773318571,-0.020796315308717617
219.20000000000255,16.958094230943367,-1.0141810079538556,-0.021729091927278343
220.30000000000254,16.990642662408636,-1.014035799561094,-0.021729861661686556
221.40000000000256,17.025126754679476,-1.0128381426186377,-0.021729866360508332
222.5000000000026,17.058469391904982,-1.0111552551420504,-0.021729799824342422
223.60000000000258,17.091514881757863,-1.010410108345271,-0.021728358130336023
224.7000000000026,17.125087536759512,-1.009080150034058,-0.020380085929794678
225.80000000000263,17.158331981161997,-1.0080141070801492,-0.019418329387391964
226.90000000000265,17.19181314086913,-1.007105464306084,-0.019420017190515004
228.00000000000267,17.225148257220937,-1.0056914995680621,-0.01942250989526695
229.10000000000267,17.25838516451634,-1.0041395270097107,-0.020783147764376952
230.2000000000027,17.291591833743635,-1.0030285254080176,-0.020738235307261377
231.3000000000027,17.325227171222135,-1.0006545809329757,-0.02074011571503309
232.4000000000027,17.358601577997444,-0.9984067874195967,-0.020736673689290885
233.50000000000273,17.391744421516353,-0.9976132815159658,-0.022150425367707616
234.60000000000275,17.425217486353038,-0.9961802855004176,-0.022116665001517433
235.70000000000277,17.45855751383941,-0.9951480266758856,-0.02350438522875109
236.8000000000028,17.491166610306347,-0.9939784405085406,-0.02349014988730147
237.9000000000028,17.52535704251025,-0.9924244033380583,-0.023486760400344586
239.0000000000028,17.55852243140024,-0.9905257354068202,-0.024013001717317017
240.10000000000284,17.591866038970366,-0.9880279546997329,-0.026399251637985177
241.20000000000283,17.625214169332263,-0.9879208982769646,-0.028990051803488015
242.30000000000285,17.658318495750915,-0.9853465475175156,-0.030309272253687958
243.40000000000288,17.69172252143784,-0.98580232362453,-0.028672982709023742
244.5000000000029,17.725254396280203,-0.9836917299579132,-0.02733838491310525
245.60000000000292,17.758705298850053,-0.9816341940965407,-0.029575809205619752
246.70000000000292,17.791516158478377,-0.9817131474944688,-0.030424954099127266
247.80000000000294,17.824731501871636,-0.9803086775155482,-0.030963984987772974
248.90000000000296,17.858185838252652,-0.9780863420367091,-0.030960108723995017
250.00000000000296,17.891228426895115,-0.9766867389410308,-0.03096013424489774
251.10000000000298,17.92452988303706,-0.9754114552084284,-0.030960249316279054
252.200000000003,17.95806475055478,-0.9750523765958511,-0.03095535874890487
253.30000000000302,17.990910876403472,-0.9736106881540881,-0.032017490249866665
254.40000000000305,18.02458773735505,-0.9700412237661833,-0.03261583155320791
255.50000000000304,18.056840940583136,-0.9689258994417408,-0.033690705222248596
256.6000000000031,18.090030900520528,-0.9683893420097525,-0.033702150451278445
257.7000000000031,18.123838771100885,-0.9666002980978969,-0.03369585923559226
258.8000000000031,18.157456071103358,-0.9649656325149073,-0.03437272221374066
259.9000000000031,18.190833822225045,-0.9628823350096675,-0.03523186348575358
261.0000000000031,18.22350153181106,-0.9623180538171708,-0.03523009072625527
262.10000000000315,18.256904995545938,-0.9606953326060444,-0.03523144826259639
263.2000000000032,18.29029487538625,-0.9606099074117203,-0.0367206966442164
264.30000000000314,18.322627501074503,-0.9594336549105024,-0.03803450865678215
265.40000000000316,18.356595345532636,-0.9574346260362085,-0.039412549402551456
266.5000000000032,18.389939613056896,-0.9575196255945675,-0.03940997374924482
267.6000000000032,18.423187394632926,-0.9564777067685893,-0.03941002344547462
268.70000000000323,18.456447701947408,-0.9558662031404327,-0.039318005830092595
269.80000000000325,18.489758006699866,-0.95621302736173,-0.037870948085642286
270.9000000000033,18.522942437410645,-0.9545757602097954,-0.03645587271515094
272.0000000000033,18.556218589155627,-0.954323017566514,-0.036557698883971756
273.1000000000033,18.589253740458606,-0.9541252187351346,-0.03524453315054643
274.20000000000334,18.62255529267638,-0.9529505485078225,-0.03524095017732787
275.30000000000337,18.655525760086846,-0.9528163071315465,-0.036413918784180765
276.40000000000333,18.68900753788292,-0.9530791754013879,-0.03680327866203381
277.50000000000335,18.722334940992628,-0.9528369828634111,-0.037849813209146266
278.6000000000034,18.75545522471144,-0.9511465706010775,-0.03923448001922347
279.7000000000034,18.78878836969905,-0.9519800080702414,-0.04042771564141123
280.8000000000034,18.82199472175197,-0.9520673981273244,-0.04066450189709592
281.9000000000034,18.855019491510514,-0.9531288400877133,-0.04204412014749481
283.0000000000034,18.88873584536838,-0.952388174189358,-0.04099265854281775
284.10000000000343,18.92184426739569,-0.951328739220985,-0.038654009629804253
285.20000000000346,18.95512398966066,-0.9529604921394179,-0.03875222228678776
286.3000000000035,18.98839502642101,-0.9529095071944389,-0.03875013647690384
287.4000000000035,19.02153195131122,-0.9521100648322233,-0.04038449967738522
288.5000000000035,19.05484765029268,-0.9522988080130459,-0.042924046342365685
289.60000000000355,19.08777616552174,-0.9530678475143195,-0.04358082133752905
290.70000000000357,19.121350476320952,-0.9536999125204385,-0.0422136515322169
291.8000000000036,19.15452612578635,-0.9534225423589561,-0.042249950867858654
292.9000000000036,19.18804690270483,-0.9557523412140574,-0.04092509513163023
294.0000000000036,19.22147837079723,-0.9554709662009827,-0.04082708807857882
295.1000000000036,19.2549214417298,-0.9558840211823929,-0.04164176995362778
296.2000000000036,19.288094242264265,-0.9578847410548905,-0.04388353756471419
297.30000000000365,19.32138673909957,-0.9590907804829525,-0.045018101487829476
298.4000000000037,19.354998986012525,-0.9603828525292735,-0.04362168831627233
299.5000000000037,19.387913413786563,-0.9605428308821625,-0.043690155338824255
300.60000000000366,19.4209782734209,-0.9616662073675221,-0.04368989710027327
301.7000000000037,19.45486756576976,-0.9626776954140971,-0.043689889695526674
302.8000000000037,19.48821830281473,-0.9629801898530154,-0.04368989692777925
303.90000000000373,19.52144571149116,-0.9664118966265445,-0.043690363384560005
305.00000000000375,19.554737057169522,-0.9671258591778289,-0.043606102476865694
306.1000000000038,19.58803984736393,-0.9690639826876412,-0.04512239190555567
307.2000000000038,19.621611555758815,-0.9718908648156955,-0.046408724615298436
308.3000000000038,19.654967910535877,-0.9715468582578948,-0.046732491178388624
309.40000000000384,19.688146728287016,-0.9729722550047903,-0.04774851818815806
310.5000000000038,19.721512349072803,-0.9735303757372163,-0.047924061014923414
311.60000000000383,19.755002812726975,-0.9750674589201695,-0.05039130130387104
312.70000000000385,19.788208048222174,-0.9765929644310346,-0.05184206129552793
313.8000000000039,19.821705439726248,-0.9792056305994051,-0.051928881407425465
314.9000000000039,19.855065865776616,-0.979282810868732,-0.05192331763892577
316.0000000000039,19.888361934887765,-0.9814765416904782,-0.05276251508745755
317.10000000000394,19.921895053513477,-0.9823292736240458,-0.05323834761505708
318.2000000000039,19.954987315289152,-0.9831820089023197,-0.0547848019960826
319.30000000000393,19.98846084168815,-0.9848378498819336,-0.05690068352630595
320.40000000000396,20.022073916221675,-0.9858084760044954,-0.0584498690872195
321.500000000004,20.055657152414216,-0.98755506059538,-0.05841347924356377
322.600000000004,20.088799550948643,-0.9908836879237211,-0.05967754595252295
323.700000000004,20.122333593413888,-0.9916051265534651,-0.059133206528644955
324.80000000000405,20.155851697449055,-0.9938304823083242,-0.05706834911835257
325.90000000000407,20.188623647867676,-0.9949963654646486,-0.05708000981095962
327.0000000000041,20.222850611261766,-0.9986426473529268,-0.05707599034869659
328.10000000000406,20.25617859146685,-1.0003277631627117,-0.05762340589978132
329.2000000000041,20.289415400640586,-1.0026714706098256,-0.0591292778440522
330.3000000000041,20.322955371442976,-1.0052167083912178,-0.06238268723956253
331.4000000000041,20.356692124028225,-1.0073590606638283,-0.06485563737340927
332.50000000000415,20.390424322201643,-1.0097566547583865,-0.06633644920673332
333.6000000000042,20.423715568831398,-1.0116003711878878,-0.06631300082934732
334.7000000000042,20.457409587442932,-1.0135198788371027,-0.06557735377655804
335.80000000000416,20.49088557186734,-1.018056248768467,-0.06498996636584131
336.9000000000042,20.524380330427864,-1.0192661778392045,-0.06499091352492492
338.0000000000042,20.5579527280521,-1.024009696652966,-0.06495237595856329
339.10000000000423,20.591591093501886,-1.0294003194419985,-0.06647286667336116
340.20000000000425,20.625162985456573,-1.0311039383835443,-0.06828935983254247
341.3000000000043,20.658884347394604,-1.0339117960418174,-0.07058042009949927
342.4000000000043,20.69248858216714,-1.0384006529786816,-0.07113882527330251
343.5000000000043,20.72630963339154,-1.0435452834706265,-0.07150265984023374
344.60000000000434,20.759344869825156,-1.0472283985366264,-0.07244928368139769
345.7000000000043,20.793452544422657,-1.0511535205119789,-0.07207376584802994
346.80000000000433,20.827027651162435,-1.0571103510225892,-0.071407321853445
347.90000000000435,20.860712768912645,-1.0612667952331383,-0.0727748788306215
349.0000000000044,20.89452428741818,-1.0651748551564526,-0.07278007175186296
350.1000000000044,20.92854901987683,-1.0702892535759492,-0.07277986943718817
351.2000000000044,20.96206454434074,-1.0750126371148492,-0.07278524574276712
352.30000000000445,20.995989704743522,-1.0803812343554466,-0.07395908599689349
353.4000000000044,21.02954690349602,-1.0858366254266665,-0.07515704252740507
354.50000000000443,21.063429010826027,-1.091049953231643,-0.07663842438520385
355.60000000000446,21.09718662095331,-1.096598601267265,-0.0784386306659064
356.7000000000045,21.130817806200987,-1.1022496587407349,-0.0812350449880963
357.8000000000045,21.164638091143242,-1.1073456161697994,-0.08420145273645918
358.9000000000045,21.19839799037844,-1.1130572195126882,-0.0861011663457667
360.00000000000455,21.23162138992152,-1.1213117334011098,-0.08690013280480491
361.10000000000457,21.26632730511735,-1.1272117225190676,-0.089287263919132
362.2000000000046,21.299849368280885,-1.1354055019516036,-0.09078512473260192
363.30000000000456,21.333765053345314,-1.142049185812398,-0.09231741161935103
364.4000000000046,21.36733725928118,-1.1496144256731742,-0.09323458821331432
365.5000000000046,21.401701713408883,-1.1585124032320189,-0.09384482822638507
366.6000000000046,21.43548385119555,-1.166871948656178,-0.09521574841707947
367.70000000000465,21.469502976948952,-1.1762957344034617,-0.09659158824474945
368.8000000000047,21.503526585278415,-1.1874440174309766,-0.09900906818216715
369.9000000000047,21.537597240101515,-1.1970335198080986,-0.10288846838681787
371.00000000000466,21.571633602791255,-1.2112538343596482,-0.10730118721579096
372.1000000000047,21.60579193475127,-1.2234415632501077,-0.11054866560233112
373.2000000000047,21.639911044375275,-1.2360028440560622,-0.11372277078916637
374.30000000000473,21.673849134977807,-1.2510517564428953,-0.1167330319990394
375.40000000000475,21.70796908265938,-1.2658575734361759,-0.11990388302552857
376.5000000000048,21.741982685251617,-1.2806897746683616,-0.12247931403804246
377.6000000000048,21.77609576569821,-1.2936113694758882,-0.12377824599686216
378.7000000000048,21.80972224417576,-1.3119259993906074,-0.1266924702827441
379.80000000000484,21.844558530775416,-1.3311660481475587,-0.13063364881617145
380.9000000000048,21.878908513815446,-1.3527824935557078,-0.13809497080961153
382.00000000000483,21.913154698115022,-1.3774910877525524,-0.1435574199215015
383.10000000000485,21.947458440219535,-1.4051808983326273,-0.14813517385584696
384.2000000000049,21.981971386799124,-1.4324988971688655,-0.15134561055328843
385.3000000000049,22.016503080408533,-1.4639030643567552,-0.15487681505219353
386.4000000000049,22.05052571733567,-1.4968307657451108,-0.1610177590162274
387.50000000000495,22.084667112361693,-1.5315776697727792,-0.16828403397102054
388.6000000000049,22.119867313658265,-1.5725445888188367,-0.1750793818181151
389.70000000000493,22.154599275585568,-1.6147015795009079,-0.17914239226487982
390.80000000000496,22.188975703386863,-1.6610276894918192,-0.18460712749994013
391.900000000005,22.224062969436943,-1.710359516419747,-0.1935315736250316
393.000000000005,22.258986468721613,-1.7645579359206054,-0.20375324206109235
394.100000000005,22.293770148539142,-1.8219476065174984,-0.21289622823658005
395.20000000000505,22.328212901313453,-1.8803191935889032,-0.22266037102180825
396.30000000000507,22.363839414551652,-1.9537467969389175,-0.23492730409695062
397.4000000000051,22.39910614095744,-2.0292854693585234,-0.24684285344294787
398.50000000000506,22.43414142644883,-2.1025323660199864,-0.25639829120266633
399.6000000000051,22.469515215619058,-2.1936576210663987,-0.2667356817379445
400.7000000000051,22.504856824151126,-2.287085487090147,-0.2802958539685183
401.8000000000051,22.54028887436567,-2.3858131052301603,-0.2935707946235775
402.90000000000515,22.576200622366073,-2.5006469557315283,-0.3120687724228448
404.0000000000052,22.611939274977626,-2.623775698348327,-0.33140592452479467
405.1000000000052,22.6481479731727,-2.7597966930418854,-0.3514592339576641
406.20000000000516,22.684162503707537,-2.8853920177510006,-0.3719999214265739
407.3000000000052,22.71963775865461,-3.0306565639256826,-0.3930100161113437
408.4000000000052,22.756589624503153,-3.1990621681934326,-0.4179434606148895
409.50000000000523,22.793029599997368,-3.373143620670804,-0.44475553574795823
410.60000000000525,22.829829341657543,-3.550533946031185,-0.47359308709559134
411.7000000000053,22.86738838256292,-3.7685950376402118,-0.5055461985683802
412.8000000000053,22.90424603068846,-3.976107459941402,-0.5377735818668539
413.9000000000053,22.94157198419378,-4.20801122917119,-0.5748179437652752
415.00000000000534,22.979307016108685,-4.474982594988595,-0.6169657668824602
416.1000000000053,23.017886448244095,-4.774112133846645,-0.660188512977582
417.20000000000533,23.056139598159948,-5.070021827919323,-0.7109669268655305
418.30000000000535,23.09401883182767,-5.368629212283708,-0.7619170156816115
419.4000000000054,23.13223832345017,-5.671653059696543,-0.8153599679855881
420.5000000000054,23.171201343708717,-5.948124831762086,-0.87420795453769
421.6000000000054,23.209861577660718,-6.276443015292437,-0.9362775835021626
422.70000000000545,23.248909424499917,-6.618307683921971,-1.0060372464513745
423.8000000000054,23.28824770146964,-6.974677498766752,-1.081104385917512
424.90000000000543,23.327713849356506,-7.362689678685611,-1.1639374632296207
426.00000000000546,23.367138639158963,-7.6898157862278955,-1.251697519990107
427.1000000000055,23.406524281215248,-8.07021136241134,-1.3417918833631122
428.2000000000055,23.44573280156167,-8.417532929058178,-1.4335010143500737
429.3000000000055,23.485133388800485,-8.7487069952114,-1.5609326360633329
430.40000000000555,23.524201988815108,-9.078157051011551,-1.6659271417011876
431.50000000000557,23.56311426372067,-9.389659224734299,-1.776277769115861
432.6000000000056,23.60144186819498,-9.644806985977171,-1.8857710929269977
433.70000000000556,23.639489568461364,-9.898446686470677,-1.9993078203198067
434.8000000000056,23.676836061241875,-10.075586451819056,-2.114245314248268
435.9000000000056,23.71278028029247,-10.159487371949648,-2.225827512071901
437.0000000000056,23.748970179361383,-10.219788676040253,-2.341046000553753
438.10000000000565,23.784274138657008,-10.204200145843865,-2.4517052633558483
439.2000000000057,23.81888011956764,-10.140980031236372,-2.561362898949318
440.3000000000057,23.85263652176104,-10.003433159284565,-2.665630309035994
441.40000000000566,23.885386812239517,-9.80868200947318,-2.7701931811411145
442.5000000000057,23.9176995999655,-9.538801358428753,-2.8701729992055514
443.6000000000057,23.94894236950886,-9.219906429416884,-2.9591394729490244
444.70000000000573,23.979255575157616,-8.85813845238813,-3.046180585746167
445.80000000000575,24.0097199818162,-8.443562168747585,-3.1258807947375638
446.9000000000058,24.039706308199868,-7.974981944740384,-3.2058951127673785
448.0000000000058,24.068562333717715,-7.492846018391635,-3.2766764542904268
449.1000000000058,24.09757386619723,-6.966807279476192,-3.3463882008687342
450.20000000000584,24.12618633271968,-6.4273820931920485,-3.4016576519288
451.3000000000058,24.15465869046151,-5.88111401196692,-3.454044705951225
452.40000000000583,24.183006415675017,-5.3338112185604185,-3.505432855583385
453.50000000000585,24.211217766791346,-4.796730311641807,-3.5535205697299808
454.6000000000059,24.239604963044453,-4.276911711728685,-3.5912734943592786
455.7000000000059,24.268322232538374,-3.7715953790196473,-3.625925495245759
456.8000000000059,24.296857533766293,-3.2982922436679387,-3.6587866464874224
457.90000000000595,24.32585629807015,-2.8537850007052845,-3.6878968095547884
459.0000000000059,24.35522261185779,-2.453694514013892,-3.711177137752303
460.10000000000593,24.38511347176607,-2.0806661238029402,-3.73266442842993
461.20000000000596,24.41524134686401,-1.7486458740962316,-3.7512640483725055
462.300000000006,24.446012340770558,-1.4536145566569267,-3.7655296025088973
463.400000000006,24.477010095759898,-1.1933150869580733,-3.777019493897549
464.500000000006,24.508518385521207,-0.9696890954672538,-3.789731455178417
465.60000000000605,24.540142872845124,-0.7807450425742412,-3.8042579627778434
466.70000000000607,24.572116316387138,-0.6150740041031998,-3.813289307062713
467.8000000000061,24.60482999297798,-0.4844741108972573,-3.8187950912678206
468.90000000000606,24.63666593609789,-0.3719682049312084,-3.82574954838357
470.0000000000061,24.67024826086982,-0.27893769014858166,-3.830032464490132
471.1000000000061,24.703569944680215,-0.20353802631793244,-3.832004479921412
472.2000000000061,24.73718036895794,-0.14199555882783238,-3.8348737844201355
473.30000000000615,24.77077329754831,-0.09617340327184568,-3.8372539474584118
474.4000000000062,24.804647398783548,-0.05944873108720271,-3.8404996230939528
475.5000000000062,24.83876280181235,-0.030616444186874488,-3.8476794846888676
476.60000000000616,24.872830882206742,-0.010133248885571624,-3.847920276583872
477.7000000000062,24.906678880329867,0.011722831093549149,-3.8492250532908803
478.8000000000062,24.940904197925178,0.02966234454129761,-3.8507297701394774
479.90000000000623,24.975412884039407,0.04229530885453357,-3.852078667220893
481.00000000000625,25.0095922028967,0.05408912757697736,-3.8523634779636327
482.1000000000063,25.04418805256456,0.06201751988634208,-3.8540328186256856
483.2000000000063,25.07857892665492,0.07190663200717343,-3.8567577948076144
484.3000000000063,25.11286033789301,0.08170717231444338,-3.860130453622789
485.40000000000634,25.147364666919575,0.09176648957906061,-3.861571210372822
486.5000000000063,25.181788880251947,0.1016843074681282,-3.861521450322007
487.60000000000633,25.216767963183113,0.10901893228798375,-3.8628128542728786
488.70000000000636,25.25145289301781,0.11577362774125088,-3.8632940912955442
489.8000000000064,25.286066107299884,0.12121480212941776,-3.8641556100768533
490.9000000000064,25.320547406032258,0.12401567340351703,-3.8641500604175785
492.0000000000064,25.355764677863473,0.1262676787709202,-3.8641500490516143
493.10000000000645,25.39031422448033,0.12765519502063333,-3.864150046421376
494.2000000000064,25.42555149871245,0.12539759880135218,-3.8641534604660683
495.30000000000643,25.46018693853378,0.12018180952731593,-3.863474240631076
496.40000000000646,25.49508255046529,0.1154176351614486,-3.862827172319058
497.5000000000065,25.530162053389994,0.10186413709408287,-3.8628347573305675
498.6000000000065,25.56509579817191,0.0913233084064313,-3.864135974292567
499.7000000000065,25.59964542616901,0.07778538451196157,-3.8641500666825164
500.80000000000655,25.634470292972036,0.06642134411868492,-3.864150011650887
501.90000000000657,25.669523554509382,0.05738503295146252,-3.8641506660870153
503.0000000000066,25.705044728115688,0.04728927299231702,-3.8655605162935602
504.10000000000656,25.7402853852288,0.045252453456062866,-3.865472641181957
505.2000000000066,25.77541648237544,0.04265981363012182,-3.8641046340218703
506.3000000000066,25.810644318505677,0.04243892367239057,-3.8641504903790196
507.4000000000066,25.84592548430021,0.04209808492283797,-3.8621433106271144
508.50000000000665,25.880682447814962,0.042311827392768925,-3.86150621671286
509.6000000000067,25.915846796826784,0.04249473546534802,-3.862845640367604
510.7000000000067,25.951237321850794,0.04414295759194019,-3.8628396815099664
511.80000000000666,25.985965587069494,0.04457856833517701,-3.862766430335114
512.9000000000067,26.02124712525443,0.04550352002410692,-3.862825048751308
514.0000000000067,26.056506630358438,0.046644776976652716,-3.86166987856508
515.1000000000067,26.092250741079134,0.04984323777351092,-3.8615546166605754
516.2000000000068,26.12737984721052,0.05321876870735505,-3.861609310600926
517.3000000000068,26.162995475810703,0.05422841439362034,-3.861536229970576
518.4000000000068,26.198098836617444,0.058088535254153945,-3.8628164926526223
519.5000000000068,26.233633381126563,0.05914373705995612,-3.8634996830185804
520.6000000000068,26.268309184283734,0.06040745317651947,-3.8629349926543646
521.7000000000069,26.304167852569968,0.0669078942686155,-3.8629401752673167
522.8000000000068,26.339436565376154,0.06810022542804041,-3.8629401437055635
523.9000000000069,26.37469970903862,0.07085542266931975,-3.86292719099951
525.0000000000068,26.410284683158533,0.07356523526703602,-3.8615976522468447
526.100000000007,26.44558122581498,0.07213241969193851,-3.859275311735087
527.2000000000069,26.48100856917399,0.07288444061985012,-3.85856042425411
528.300000000007,26.516563125754153,0.07289566381662213,-3.861220161405402
529.4000000000069,26.552099723966844,0.0750368816213985,-3.862332350153269
530.5000000000069,26.58768103051792,0.07361521226994516,-3.86402220101486
531.600000000007,26.62298893162181,0.07250421354084445,-3.8639172894510003
532.700000000007,26.65771333062784,0.07000980847423059,-3.8627092365162836
533.800000000007,26.693738899739998,0.06959932411786052,-3.8612538649634107
534.900000000007,26.729673539924708,0.06622526951831952,-3.85976879358136
536.000000000007,26.765295887958867,0.06561560128629097,-3.860639412618266
537.1000000000071,26.80061221112982,0.06431311396900344,-3.861120334479632
538.2000000000071,26.83614237498667,0.06186860451805284,-3.8623884709277605
539.300000000007,26.871848799243168,0.06027031750268561,-3.865212011754074
540.4000000000071,26.907254734446575,0.057435386022861676,-3.8665131498189504
541.500000000007,26.943158970602774,0.05616435682478149,-3.8652466335687707
542.6000000000072,26.97880558362666,0.053669349770083925,-3.8639115361357885
543.7000000000071,27.014350899640046,0.05114892765057924,-3.8630073951938053
544.8000000000072,27.049869489089282,0.04917515531327476,-3.861518623902187
545.9000000000071,27.085364322932897,0.04562471810864011,-3.8628368279094323
547.0000000000072,27.12117099936087,0.04246018098747795,-3.8628301842090895
548.1000000000072,27.15686251088137,0.040633352311562496,-3.862830164359581
549.2000000000072,27.192271997565697,0.03600765221976304,-3.8628301562532585
550.3000000000072,27.22852126410878,0.03233282407361338,-3.862832311319279
551.4000000000073,27.263947746841588,0.027438543893021458,-3.862386077453481
552.5000000000073,27.299445679176827,0.025444807136535144,-3.8639319988810055
553.6000000000073,27.335610204023336,0.022122156981581223,-3.8639597563125267
554.7000000000073,27.37132403463367,0.018625032029352784,-3.8645323199524353
555.8000000000073,27.407194038810758,0.012597568740772258,-3.8636221535112343
556.9000000000074,27.442886985162428,0.0067805880875621075,-3.86406775114987
558.0000000000074,27.478112327500604,0.002629753536333543,-3.863597830057147
559.1000000000074,27.514038397845066,4.3677787999079815e-05,-3.863563035254354
560.2000000000073,27.550227928375776,-0.00473794605621837,-3.865027905407956
561.3000000000073,27.58615859170055,-0.00906697141816129,-3.8650304110286826
562.4000000000074,27.62220496929527,-0.013318939903501224,-3.8650320747781763
563.5000000000074,27.658155587060016,-0.017637963228524327,-3.8644960994876585
564.6000000000074,27.69409825626786,-0.02199747611798065,-3.864038726080286
565.7000000000074,27.729871198491885,-0.025800831693790213,-3.864040112344367
566.8000000000075,27.76551602825623,-0.028819567243392723,-3.8632397231853446
567.9000000000075,27.801364986789668,-0.03382300753447836,-3.862737268429063
569.0000000000075,27.83761094436537,-0.0350694151839102,-3.864027360634279
570.1000000000075,27.873697649601347,-0.038530468652598605,-3.86403853414857
571.2000000000075,27.90957685749034,-0.04233113960756185,-3.8640629066962053
572.3000000000076,27.9454589892358,-0.04536104331972955,-3.862731367491362
573.4000000000076,27.98158494454911,-0.048175512025123914,-3.8627284941000815
574.5000000000076,28.01766406346973,-0.052771018743796354,-3.8632266559156108
575.6000000000076,28.053551125297574,-0.05639876309788099,-3.86372558327642
576.7000000000077,28.088960758187504,-0.06146704111839394,-3.862819646771771
577.8000000000077,28.125342355328943,-0.06546094605984586,-3.8623992737796753
578.9000000000076,28.1615045873317,-0.06992021254985371,-3.8624000763397133
580.0000000000076,28.197585546139713,-0.07468957304720245,-3.862392805882389
581.1000000000076,28.23292398713193,-0.07782383801235465,-3.8634921713405714
582.2000000000077,28.26999966344351,-0.08498374882221621,-3.8633798485939965
583.3000000000077,28.305943679122297,-0.08572701194037637,-3.8633800401955565
584.4000000000077,28.34190191159537,-0.08953516872939894,-3.8633800499638125
585.5000000000077,28.378142668499304,-0.09487677075298963,-3.8633800500005595
586.6000000000078,28.414138484879803,-0.09937584616459105,-3.863380050000006
587.7000000000078,28.450166296142946,-0.10410620653369024,-3.86338005
588.8000000000078,28.486336043726535,-0.10692195917879334,-3.8633800500000004
589.9000000000078,28.522410764913122,-0.11417581152919694,-3.863380050000017
591.0000000000078,28.558455072208275,-0.11895543395577694,-3.8633800499988147
592.1000000000079,28.594573067627184,-0.12263774436284243,-3.863380049700066
593.2000000000079,28.63069415760685,-0.1254498408519015,-3.863380042092291
594.3000000000079,28.666962924236064,-0.129564268766878,-3.8633833905740005
595.4000000000078,28.703227207270828,-0.13612241594376875,-3.8623853611589056
596.5000000000078,28.739408144212582,-0.1396233447120108,-3.859033799105916
597.6000000000079,28.77530210212388,-0.14651616101073353,-3.85903173040725
598.7000000000079,28.81183716161696,-0.15088728702789303,-3.8613790539444524
599.8000000000079,28.84766149474227,-0.155242675317623,-3.862094047033411
600.9000000000079,28.884317269071374,-0.1599730220385777,-3.863399737431433
602.000000000008,28.920459883812267,-0.1648847322100953,-3.8647236896407406
603.100000000008,28.956261683442126,-0.1703455902229074,-3.8650424299379305
604.200000000008,28.993232813128532,-0.17381909987861066,-3.8661346803649366
605.300000000008,29.029125106382786,-0.18014391925714326,-3.8661235857275145
606.400000000008,29.06463206835845,-0.18420914435962105,-3.8647646493364363
607.5000000000081,29.101915710510315,-0.1905097875293234,-3.8648332670271923
608.6000000000081,29.137948957335006,-0.1973827956713483,-3.8651411949432664
609.7000000000081,29.17441806013738,-0.20568621434794215,-3.8650761982723387
610.8000000000081,29.210629003743925,-0.20757470636952946,-3.866115027856431
611.9000000000082,29.24686748530082,-0.2158512560205317,-3.866795437643097
613.0000000000082,29.283131247593946,-0.21918261063986896,-3.8674358604850676
614.1000000000081,29.319475085038924,-0.22396673158683678,-3.8683838230497596
615.2000000000081,29.355831407779736,-0.23136144820234816,-3.868758975035926
616.3000000000081,29.39230363906994,-0.23636923414073788,-3.86741333821329
617.4000000000082,29.428154781933127,-0.242749793878716,-3.867449799920397
618.5000000000082,29.464559571595892,-0.24805376657196895,-3.867281461252437
619.6000000000082,29.501048681567305,-0.2526950398314837,-3.8667887674973906
620.7000000000082,29.537295818639965,-0.2577033738951525,-3.865686670981765
621.8000000000083,29.573464380589655,-0.26554920722266784,-3.8654724935484017
622.9000000000083,29.60973177186154,-0.26941189379387936,-3.865204303551063
624.0000000000083,29.646268971750068,-0.27229938857268626,-3.8647563781017302
625.1000000000083,29.682646059161613,-0.27559594788772357,-3.866117723747699
626.2000000000083,29.71892062130023,-0.28045107594388896,-3.8661300039019864
627.3000000000084,29.755396149248988,-0.28465457868503447,-3.8661309031410944
628.4000000000084,29.792048094213197,-0.28627616012818163,-3.8662095732557713
629.5000000000084,29.828119272644336,-0.2928422252054366,-3.867439779493336
630.6000000000083,29.864462074342732,-0.29628515590811033,-3.8669079937419664
631.7000000000083,29.900823164458618,-0.2976550085604841,-3.867449717161225
632.8000000000084,29.937338919062935,-0.3034966814725173,-3.8678704913665776
633.9000000000084,29.97381972115582,-0.306698358696641,-3.8700346956712135
635.0000000000084,30.00996707375641,-0.3071179562649416,-3.8705206378201398
636.1000000000084,30.046467268578755,-0.310131847497268,-3.871855188196969
637.2000000000085,30.082775818207455,-0.31414650433913666,-3.869614992116979
638.3000000000085,30.119229857483173,-0.31429055131464884,-3.867591320971818
639.4000000000085,30.15519981311637,-0.3170514705415952,-3.866427586272832
640.5000000000085,30.19175309190675,-0.3199468266497337,-3.8661370742796066
641.6000000000085,30.228045356744754,-0.32237105665790816,-3.864710864584954
642.7000000000086,30.264697207276587,-0.3265202238025191,-3.863407187277685
643.8000000000086,30.30088528512751,-0.32759487032847306,-3.864759005199186
644.9000000000086,30.33751977624334,-0.32975419805149336,-3.8678029264260005
646.0000000000086,30.373834689263028,-0.33315051812965907,-3.8705138191862853
647.1000000000087,30.410328104785595,-0.3361823852157576,-3.870519950674208
648.2000000000087,30.446743490265522,-0.3396590684565916,-3.8705199952262364
649.3000000000086,30.48304261599225,-0.341420752013271,-3.8705199889505395
650.4000000000086,30.51959941374782,-0.34236652743013346,-3.8705201254585306
651.5000000000086,30.556155830880574,-0.3465466000392375,-3.870623631811153
652.6000000000087,30.592520434515997,-0.3495304316420277,-3.8680919144705594
653.7000000000087,30.629128319784257,-0.35065464533989227,-3.8665443777287343
654.8000000000087,30.665422706867744,-0.35442582851790666,-3.867588754773921
655.9000000000087,30.70193481838851,-0.3555040858316126,-3.8696235137457737
657.0000000000088,30.73829865248759,-0.358467047776998,-3.8707747612175427
658.1000000000088,30.77469990705214,-0.36056082879678986,-3.870839099144225
659.2000000000088,30.81135231876712,-0.3646982334819328,-3.8708400319153475
660.3000000000088,30.847631669897943,-0.36788010691567025,-3.870840034335549
661.4000000000088,30.884197015501307,-0.36980995812206446,-3.87084044212324
662.5000000000089,30.920964306234016,-0.37274987835721357,-3.8681116421544397
663.6000000000089,30.95716823237924,-0.3772013048666712,-3.868110933389354
664.7000000000089,30.993735830162294,-0.38109402035489104,-3.8681099903869702
665.8000000000088,31.030130979899127,-0.3841840060956396,-3.8681098640852416
666.9000000000088,31.066575499603495,-0.3892378755449874,-3.8687538470218525
668.0000000000089,31.103209895951473,-0.3908248413830344,-3.8694263244988223
669.1000000000089,31.1396594317045,-0.3962043701696071,-3.870745710504404
670.2000000000089,31.176407371098822,-0.4001469180992229,-3.8694590597137655
671.3000000000089,31.212696337493725,-0.4016164508419888,-3.8680471659039846
672.400000000009,31.249350651176428,-0.405351401394084,-3.8678899493782763
673.500000000009,31.285773025805664,-0.41069559800281846,-3.867901620608294
674.600000000009,31.322393727993163,-0.4124409376825347,-3.8694513801610433
675.700000000009,31.35808397100088,-0.41685111445612505,-3.870870474150872
676.800000000009,31.39538721735357,-0.42167652655637694,-3.872497318179452
677.9000000000091,31.431820930896365,-0.42697420228608507,-3.8725000253975823
679.0000000000091,31.468392890558327,-0.4319865021968203,-3.8725003383858745
680.1000000000091,31.50515384384296,-0.43476359677860293,-3.871628286761541
681.2000000000091,31.54161566286004,-0.4411366708121342,-3.8711752075426977
682.3000000000092,31.578452829717534,-0.44443705118175153,-3.870839231138156
683.4000000000092,31.614707992480028,-0.45004726662222466,-3.870839374595606
684.5000000000091,31.651400774989412,-0.4559606813632095,-3.8692610162655847
685.6000000000091,31.687838003529198,-0.45801627985460697,-3.869307856608449
686.7000000000091,31.724517032015118,-0.46273307372527583,-3.8724535629528987
687.8000000000092,31.761346140652396,-0.4666646628243052,-3.873600394270917
688.9000000000092,31.79766768670475,-0.47177904196309667,-3.8735998181701796
690.0000000000092,31.8343374439128,-0.47563607883649367,-3.873577876702868
691.1000000000092,31.87084109706186,-0.47897679330865045,-3.8722662147369054
692.2000000000093,31.907388199988397,-0.48615848223146174,-3.869765263909289
693.3000000000093,31.944266465448486,-0.49067076014128086,-3.8705026318232574
694.0000000000093,31.967577225433665,-0.49513937738100156,-3.871312494554969