File: 01_Data/EIFS_XPS/STA/N2/30K_min/EIFS_XPS_STA_N2_30KData_230901_R3.csv
##Temp./Â°C,Time/min,DSC/(mW/mg),Mass loss/mg
41.0,10.538835100862444,-2.3057703760741832,0.0036631811732799058
42.100000000000016,10.742843826645982,-2.25923670592379,0.005096205130440623
43.20000000000003,10.870869263410924,-2.2259464956720145,0.002816373379422199
44.30000000000005,10.967071045680667,-2.1987785046277533,0.00436571657724194
45.40000000000006,11.0503461355699,-2.1774280534085633,0.0037841047594056043
46.50000000000008,11.126492007648169,-2.1535859952491005,0.0036742553154378577
47.600000000000094,11.196125717854699,-2.1317329366324596,0.004024831800974571
48.70000000000011,11.259551471422183,-2.1142677160775576,0.0032656752959527857
49.800000000000125,11.318541109619009,-2.0941221868154916,0.004551821833835401
50.90000000000014,11.375761833294808,-2.077445014158581,0.003739767460801957
52.000000000000156,11.430562635153994,-2.0583817415317363,0.0040738595487122
53.10000000000017,11.48290606814214,-2.0430781689776096,0.0041785038575223865
54.20000000000019,11.53144125888374,-2.026499196689331,0.0038700795187058823
55.3000000000002,11.581725990000594,-2.010158536033927,0.0033818061003154654
56.40000000000022,11.630027635026934,-1.996087433726306,0.004342955527097292
57.500000000000234,11.676698444864105,-1.9806024467305978,0.0036015559246553863
58.60000000000025,11.722742304767744,-1.9654513599061576,0.00387471606267642
59.700000000000266,11.767382562155442,-1.951205653965566,0.003508109301785911
60.80000000000028,11.81149214351205,-1.9365391137204089,0.004600121691713088
61.9000000000003,11.854745486873002,-1.9227951458490338,0.004784094420321239
63.00000000000031,11.897446655889649,-1.9104603327469745,0.005126143226727997
64.10000000000034,11.940791599576919,-1.8965548336628595,0.00674905628919209
65.20000000000034,11.982526703898001,-1.8839753183452936,0.005904845641075962
66.30000000000035,12.023712071676632,-1.8718024540621097,0.004693365646023739
67.40000000000038,12.064367401350623,-1.8606434559611789,0.005119719264881972
68.5000000000004,12.105606836947983,-1.851389341513653,0.004502450836645799
69.6000000000004,12.146072298942041,-1.840239338477808,0.004474898260432347
70.70000000000041,12.18524554882651,-1.8311979652527413,0.0049302487880922286
71.80000000000044,12.226935560991679,-1.8183640721835457,0.005055518953064997
72.90000000000046,12.266252735514092,-1.810338738309669,0.004618115636614295
74.00000000000047,12.306108376366451,-1.8004280076959631,0.0040546962761998095
75.10000000000048,12.345096663220716,-1.7930423476439437,0.004585450291724413
76.2000000000005,12.384705316951774,-1.7864193238516808,0.004052799922584782
77.30000000000052,12.423710877863966,-1.7769337162564611,0.004843840544777489
78.40000000000053,12.462556935465312,-1.7714315994788215,0.004776645858899364
79.50000000000054,12.501261585639243,-1.765925782707085,0.004368035699715556
80.60000000000056,12.540116558192958,-1.7606514611705215,0.003689306552014493
81.70000000000059,12.578457708773474,-1.757986962926696,0.0035341850116599183
82.8000000000006,12.617037339722977,-1.7534637263232105,0.0033168929509890255
83.9000000000006,12.655227555726995,-1.7509978258481962,0.0031481938381308083
85.00000000000063,12.693715017282928,-1.7469787030015513,0.003480625371485413
86.10000000000065,12.73120896159575,-1.738858066136362,0.003510462489934252
87.20000000000066,12.76937600168677,-1.7253633339382803,0.0036333578137281997
88.30000000000067,12.805729995359354,-1.708325530665919,0.0026903226013561543
89.40000000000069,12.844207634222162,-1.6894799069593045,0.0035019599240628807
90.50000000000071,12.881182042643816,-1.6681992627259072,0.0022279082275038498
91.60000000000072,12.918474350084633,-1.6520688411985307,0.002297844069895749
92.70000000000073,12.955425206918148,-1.6422911874510162,0.002300829501831636
93.80000000000075,12.992410921024398,-1.627770429517965,0.0023145846896541755
94.90000000000077,13.029589096222928,-1.6189983538925303,0.002296104203376892
96.00000000000078,13.066588033066273,-1.6141812075364252,0.0023029774500602507
97.10000000000079,13.103587461376165,-1.6086465410851989,0.002272243252566586
98.20000000000081,13.140659683503689,-1.602745769263166,0.002431681736986935
99.30000000000084,13.17759634541564,-1.6021573042867572,0.0023100186306979076
100.40000000000084,13.214026357797062,-1.6004745336281845,0.002306235469565099
101.50000000000085,13.251044263072297,-1.6009560837185006,0.002272165077576549
102.60000000000088,13.287934007067065,-1.6040600207442886,0.0023128915320360655
103.7000000000009,13.32444863554236,-1.6081055423034387,0.0018743031905184004
104.8000000000009,13.361495116369788,-1.6153444821797605,0.0022981388112155443
105.90000000000092,13.398302760389864,-1.6240552459823072,0.002299868393936144
107.00000000000094,13.43494987832609,-1.6372156659639174,0.002293623700855729
108.10000000000096,13.472355233860096,-1.6509341805795428,0.0028230970998559535
109.20000000000097,13.50897101588677,-1.6659067879995333,0.0023099057070981033
110.30000000000098,13.546402033525867,-1.6806660603802461,0.00230715555648775
111.400000000001,13.583305705410277,-1.695472021656023,0.0008973899927142703
112.50000000000102,13.61951428039826,-1.7065538005197576,0.0009845009759912315
113.60000000000103,13.656364739702463,-1.7167606200826615,-0.00037564002918388795
114.70000000000104,13.693078213575786,-1.7236095874085473,-0.0003189689704674592
115.80000000000106,13.728960020084813,-1.7306132838035104,0.0009837915346406767
116.90000000000109,13.766525519893765,-1.7342700935447766,0.000989515427900045
118.0000000000011,13.802923271054336,-1.7445927771555323,0.0009901474714792968
119.1000000000011,13.839426844312067,-1.7490312845095195,0.0009964295899487219
120.20000000000113,13.87602877776646,-1.7554467403447105,-0.0009804899316581128
121.30000000000115,13.912326051025568,-1.7622459326248834,-0.0011782462582541342
122.40000000000116,13.948671659074577,-1.7674310448620019,-0.0016505106986604012
123.50000000000117,13.98483634212275,-1.7713763835278657,-0.0017343779028933248
124.60000000000119,14.020884023965642,-1.7717756563205258,-0.002999287650565563
125.70000000000121,14.056795415445517,-1.7680662934893636,-0.004286305148445635
126.80000000000122,14.092665399793573,-1.7625312585109552,-0.004280164822683563
127.90000000000123,14.12861234027437,-1.7510576398740834,-0.004302249757790033
129.00000000000125,14.164038630750598,-1.733472465589328,-0.005277332659178846
130.10000000000127,14.199716635252216,-1.7208417993152598,-0.005976255160697441
131.2000000000013,14.235121083205827,-1.7002218122408075,-0.006592652442162006
132.3000000000013,14.270373989525602,-1.684487594877322,-0.0065888144837153995
133.4000000000013,14.30519085157653,-1.664483408149803,-0.007979424992416106
134.50000000000134,14.340529117169071,-1.643517822946748,-0.007900412161579329
135.60000000000133,14.375755870894595,-1.6235142164153644,-0.00790007046331409
136.70000000000135,14.409949710346028,-1.6067805595683913,-0.007900077190044819
137.80000000000138,14.445346279656077,-1.589073616673486,-0.007900106775393212
138.9000000000014,14.480995912185369,-1.572230990609844,-0.007898022177702302
140.00000000000142,14.515916161677204,-1.560681084592394,-0.008265024073145444
141.10000000000142,14.550936328261265,-1.5475051940717164,-0.008243502674235348
142.20000000000144,14.584944341840545,-1.5368982968684923,-0.008871327218683778
143.30000000000146,14.620761575403986,-1.5242991501492633,-0.008890211060246234
144.40000000000146,14.655374268651384,-1.5176792426718735,-0.008890739160945849
145.50000000000148,14.690297452080513,-1.5095828508359292,-0.008836742992221591
146.6000000000015,14.724640366660836,-1.501640573731028,-0.009554695608747998
147.70000000000152,14.759542294344763,-1.494716669328941,-0.009550047646808224
148.80000000000155,14.794566291015007,-1.4901982776566611,-0.009532801461634044
149.90000000000154,14.82920140384428,-1.485212916915046,-0.008890188086534412
151.00000000000156,14.863966542897966,-1.4791983582440646,-0.008889512816038891
152.1000000000016,14.898361636916365,-1.4755398032279579,-0.008889837964288994
153.20000000000158,14.932958915843345,-1.470102152567382,-0.008889837035924941
154.3000000000016,14.967535390355206,-1.463692248816991,-0.008889836999783185
155.40000000000163,15.002064956652484,-1.4614377790819737,-0.00888983699987067
156.50000000000165,15.036264493863875,-1.457167008884841,-0.008889836853850142
157.60000000000167,15.070813549523754,-1.4520060941573794,-0.008889841100416795
158.70000000000167,15.105411943824835,-1.446089043861254,-0.008890899529823137
159.8000000000017,15.138922178477777,-1.4437515782236385,-0.010011199148020289
160.9000000000017,15.17390883762874,-1.4383739067063044,-0.010207795293442512
162.0000000000017,15.208674905078299,-1.4333365666322395,-0.010216395153554991
163.10000000000173,15.242575694388648,-1.430579013051851,-0.009566324132635806
164.20000000000175,15.27720351444357,-1.4257241905486608,-0.009559764786684966
165.30000000000177,15.311994789778039,-1.421440989120992,-0.009559814336114414
166.4000000000018,15.345009943267238,-1.4162935628676074,-0.009559815438754615
167.5000000000018,15.379564568047098,-1.4125225342373355,-0.009559820217666992
168.6000000000018,15.414372578571543,-1.4076319432873141,-0.00955545036164418
169.70000000000184,15.448360765626521,-1.4042042777104347,-0.010158970746469098
170.80000000000183,15.48281361665874,-1.400437003567845,-0.01054138047887676
171.90000000000185,15.516940691335895,-1.3954008992997726,-0.01054007388186129
173.00000000000188,15.550785306381929,-1.3913452421002468,-0.010535509031187829
174.1000000000019,15.58527514258852,-1.3870219720266763,-0.011707652392813461
175.20000000000192,15.619324405660674,-1.3834954895845606,-0.011850245141144189
176.30000000000192,15.653311758086964,-1.3803932706373834,-0.011849958621237722
177.40000000000194,15.687242200296106,-1.3749889883529247,-0.011849956949890661
178.50000000000196,15.721684384956127,-1.3721640710846694,-0.011849957000194422
179.60000000000196,15.755372160299489,-1.3676914619070195,-0.011849957000001243
180.70000000000198,15.78858067198879,-1.3644882360971073,-0.011849957000169997
181.800000000002,15.823288591343696,-1.3606588313117651,-0.011849957006335732
182.90000000000202,15.856966867513087,-1.3575633471367046,-0.011849955253194544
184.00000000000205,15.89108979696247,-1.351234422689336,-0.01185001129675678
185.10000000000204,15.92480766102785,-1.3475778029311325,-0.01185640123594478
186.20000000000206,15.95889134553294,-1.344585016115062,-0.012563441408145692
187.3000000000021,15.992481356143964,-1.3401798955451294,-0.01250980151048875
188.40000000000208,16.025995627312685,-1.3360096279377696,-0.012509936393692467
189.5000000000021,16.05968093778821,-1.3323048439024483,-0.012509742802835344
190.60000000000213,16.093674712327704,-1.3278097195302152,-0.012653844365895672
191.70000000000215,16.1271280117025,-1.323698255470473,-0.012849454518384373
192.80000000000217,16.160608441943527,-1.3201870012965253,-0.013161213264659466
193.90000000000217,16.1940112423023,-1.3176606008505298,-0.013651795756214558
195.0000000000022,16.22790915266256,-1.313333355638679,-0.013869294895437978
196.1000000000022,16.261893141721174,-1.3095482848747444,-0.012843329954475013
197.2000000000022,16.294918020772826,-1.3050276257604125,-0.0128402248217232
198.30000000000223,16.328887659658065,-1.3025691394682057,-0.012840125725916973
199.40000000000225,16.362165105521044,-1.298421951797809,-0.012840556996159158
200.50000000000227,16.395870413902006,-1.2941169994309454,-0.01425345392041688
201.6000000000023,16.429230242590794,-1.291821007677238,-0.014160727362329872
202.7000000000023,16.463071199111607,-1.2884256787224646,-0.015465074504942944
203.8000000000023,16.496348760152998,-1.2868074084293875,-0.015480007777595617
204.90000000000234,16.530005057440814,-1.2835066701440951,-0.015479858589170892
206.00000000000233,16.563347230762755,-1.2807116353265235,-0.015479856823091165
207.10000000000235,16.59704206091805,-1.2782286816716926,-0.015479915570906666
208.20000000000238,16.62987425036939,-1.276258982057937,-0.01548156759604824
209.3000000000024,16.663951997568642,-1.2734248637729493,-0.016521376711629454
210.40000000000242,16.69769279112724,-1.2715626169221148,-0.016751746076581586
211.50000000000242,16.73056361640597,-1.2704312232140975,-0.017445361988387642
212.60000000000244,16.76431822013282,-1.2680400658616142,-0.01745994287973085
213.70000000000246,16.797502159190984,-1.2674278225743372,-0.017460019920452208
214.80000000000246,16.830824972503933,-1.2655251124653535,-0.017467626343224296
215.90000000000248,16.864559926403356,-1.2650918352027427,-0.01874358972099399
217.0000000000025,16.89797190824963,-1.264036510900566,-0.017910701594745504
218.10000000000252,16.931374195420332,-1.2624196501885803,-0.017779292077650943
219.20000000000255,16.964780219154623,-1.2610442460535678,-0.01777981209644075
220.30000000000254,16.998060748119272,-1.261034765617027,-0.017779787370717504
221.40000000000256,17.031750406459462,-1.2597649450216692,-0.017774700517772857
222.5000000000026,17.064070582986023,-1.2578436769238215,-0.019183834600316363
223.60000000000258,17.098183302396716,-1.2566515682589592,-0.019099598067039647
224.7000000000026,17.13166393977993,-1.2568992381901798,-0.019099701360479227
225.80000000000263,17.164504326765282,-1.2564630407630768,-0.019169564779363935
226.90000000000265,17.198185619796472,-1.2545384359949678,-0.02041513268802575
228.00000000000267,17.231682291714538,-1.252108517324877,-0.02041986574772725
229.10000000000267,17.26512416367921,-1.2513350049695653,-0.020419990004511668
230.2000000000027,17.298381034098536,-1.251983608088901,-0.020419994799548924
231.3000000000027,17.331667292328998,-1.2499309884493197,-0.020420770769191243
232.4000000000027,17.364825107184117,-1.248703362977161,-0.020312710444242654
233.50000000000273,17.39809446573947,-1.2474381711292954,-0.022051379417275196
234.60000000000275,17.43140577072473,-1.2462952285925568,-0.0220599745604364
235.70000000000277,17.46456130135291,-1.2446121464888737,-0.02205992633111986
236.8000000000028,17.497739464043402,-1.2446461115349965,-0.022057477381457247
237.9000000000028,17.53126955597142,-1.2423855290501131,-0.02289760098950344
239.0000000000028,17.56456828110958,-1.2406395449396417,-0.023383102359209484
240.10000000000284,17.597891689135512,-1.2391446880256716,-0.02337992803210165
241.20000000000283,17.631134836343556,-1.238465348835203,-0.023379943967182903
242.30000000000285,17.664157072389894,-1.2346246443516817,-0.02337991285779717
243.40000000000288,17.69758178150711,-1.2349380465490165,-0.02338116748667307
244.5000000000029,17.730790548383727,-1.2337190170079166,-0.024771639265443568
245.60000000000292,17.76419891247507,-1.2319441759537524,-0.025007702663225384
246.70000000000292,17.796881199589055,-1.2305068323069093,-0.025372903463695362
247.80000000000294,17.830569722784496,-1.2298484540919594,-0.026714738204308475
248.90000000000296,17.86362646659998,-1.2282939759023535,-0.026679076704565485
250.00000000000296,17.89701595672376,-1.2266450712133092,-0.026680189294829848
251.10000000000298,17.930124057044704,-1.226109580564506,-0.026682603856712284
252.200000000003,17.963441861818392,-1.2238265076249526,-0.02768050231928454
253.30000000000302,17.99679923544497,-1.222931789231595,-0.027854930557608792
254.40000000000305,18.030025152775494,-1.2214054498311304,-0.026675755878422525
255.50000000000304,18.063056222309935,-1.2210423071495942,-0.027887935392177265
256.6000000000031,18.096472510294156,-1.2201447294865668,-0.02799034801364675
257.7000000000031,18.129497033807915,-1.2181898424010031,-0.02799004797322535
258.8000000000031,18.16255288191466,-1.2165446464159297,-0.02800750792831641
259.9000000000031,18.19557612988714,-1.2158065898714303,-0.029277384269595697
261.0000000000031,18.22904744425784,-1.2154503946364603,-0.029514136919283285
262.10000000000315,18.262111499221547,-1.2133731634436036,-0.03062822449991698
263.2000000000032,18.295387297385776,-1.2127220239624923,-0.03099200602010166
264.30000000000314,18.32824595897833,-1.2108192014846835,-0.03094455102367899
265.40000000000316,18.362133248399285,-1.2113612708972408,-0.03064828265911146
266.5000000000032,18.394921249564764,-1.2102119347798155,-0.030627969473477457
267.6000000000032,18.428260704612022,-1.2096376691511215,-0.030906235449002395
268.70000000000323,18.461337154916844,-1.2100486628797094,-0.03278363646220939
269.80000000000325,18.494628882745058,-1.2098513892813934,-0.03326477904076652
270.9000000000033,18.52822668404096,-1.209256614804783,-0.03378185300665493
272.0000000000033,18.560979846897318,-1.2081717887270513,-0.035562234348156974
273.1000000000033,18.59450372176151,-1.207224641564101,-0.03557006794522666
274.20000000000334,18.627652565536778,-1.207924046713405,-0.03557414963137173
275.30000000000337,18.6608380587053,-1.206615192003563,-0.03415718153291536
276.40000000000333,18.6939755852346,-1.2065697898036378,-0.035608276621116985
277.50000000000335,18.727441002665504,-1.2066406196399289,-0.03649775189085647
278.6000000000034,18.760893826533334,-1.207418695314731,-0.03819687492579371
279.7000000000034,18.79413761140862,-1.2067881257161903,-0.03824094214759288
280.8000000000034,18.827362474646115,-1.2075235529991244,-0.036903343976527836
281.9000000000034,18.860776742547934,-1.206782373470834,-0.03688976274651656
283.0000000000034,18.893562388674844,-1.20698810716568,-0.03688281837633278
284.10000000000343,18.92698167044544,-1.2066557394565463,-0.03824387898831416
285.20000000000346,18.96034268273181,-1.207154440328261,-0.03820310409577532
286.3000000000035,18.993258069675036,-1.2073296059617618,-0.039190328633573746
287.4000000000035,19.027025998513164,-1.2079619471521603,-0.03952164346907905
288.5000000000035,19.059725384923432,-1.2086655272971756,-0.03951994324326735
289.60000000000355,19.092617490203974,-1.2098635242519786,-0.0395212732979231
290.70000000000357,19.126748111745467,-1.2096839758238926,-0.03943249391422876
291.8000000000036,19.16009593575849,-1.2095165386942144,-0.04083927081807959
292.9000000000036,19.193495795034302,-1.2103015424182089,-0.04084016452262196
294.0000000000036,19.226679708317626,-1.2098668438330347,-0.040833685006291365
295.1000000000036,19.260041762654044,-1.2111360202029622,-0.04189553453265349
296.2000000000036,19.293673467810535,-1.2112789524611303,-0.04216075198226621
297.30000000000365,19.326468654250164,-1.2125030084123507,-0.042159894015425525
298.4000000000037,19.36021347178024,-1.2137082694547552,-0.04215192013648705
299.5000000000037,19.393431469049624,-1.214659125339817,-0.04352858583155017
300.60000000000366,19.42697056883839,-1.214859897329346,-0.04365148341920699
301.7000000000037,19.460216683407452,-1.2166386796153963,-0.044793784375640744
302.8000000000037,19.493338554586,-1.2175050527679572,-0.04479140548388072
303.90000000000373,19.52718834745829,-1.219182718341236,-0.04595496747918881
305.00000000000375,19.560401597080823,-1.219878164063439,-0.04610905795839537
306.1000000000038,19.593709346674164,-1.2208104517472584,-0.04611019425063345
307.2000000000038,19.62699456482019,-1.221445245059631,-0.046110163298790585
308.3000000000038,19.660231162506857,-1.2236441331336392,-0.04611040020300505
309.40000000000384,19.693366480210877,-1.224865842560773,-0.046885540911410395
310.5000000000038,19.726805686108236,-1.2251417230605885,-0.047443468287546864
311.60000000000383,19.760189423678412,-1.226525786110943,-0.04876464619141796
312.70000000000385,19.79372010786344,-1.2286134395695336,-0.048736211874886415
313.8000000000039,19.827070398208967,-1.2293926693618933,-0.050099278762633315
314.9000000000039,19.86047262179207,-1.2313522977144558,-0.05005637331695256
316.0000000000039,19.893944449874358,-1.231340168356266,-0.05063634971933384
317.10000000000394,19.927373172990162,-1.23216712252693,-0.05273686995508875
318.2000000000039,19.960809600313585,-1.2326055060354277,-0.052704494660730905
319.30000000000393,19.99405218296771,-1.2347782026251475,-0.05374983107122677
320.40000000000396,20.027898541824673,-1.236690749089155,-0.054035421418258345
321.500000000004,20.061106694288195,-1.2374721830885784,-0.0553355880639641
322.600000000004,20.094364050793605,-1.2383958472908594,-0.05532095655756297
323.700000000004,20.12770503299184,-1.2405147490514297,-0.05654965186154426
324.80000000000405,20.161383598060365,-1.2419684865342986,-0.05534020079536761
325.90000000000407,20.19491227511027,-1.2443490791838514,-0.05535443815671037
327.0000000000041,20.228122904361634,-1.2456230823573466,-0.056643757800875605
328.10000000000406,20.261675952281102,-1.2480801587382022,-0.05664590442848905
329.2000000000041,20.295003169967366,-1.2493652172418772,-0.05803391832420024
330.3000000000041,20.32850256765783,-1.2520790259920402,-0.057959673429503145
331.4000000000041,20.36206429928597,-1.2541531291831016,-0.05795518674441702
332.50000000000415,20.395741304747435,-1.256767393534806,-0.05934807228424788
333.6000000000042,20.42892002038831,-1.2592647859146346,-0.05927908815043503
334.7000000000042,20.46293954050585,-1.2610880659274357,-0.0605719269342746
335.80000000000416,20.496322810291172,-1.2628681208955306,-0.06102259072717153
336.9000000000042,20.52963432338485,-1.2650756758574668,-0.06193875757653311
338.0000000000042,20.563172813043483,-1.268497665496409,-0.06357544436144646
339.10000000000423,20.597088798012845,-1.2728651696491322,-0.06381262174237845
340.20000000000425,20.630576231281736,-1.2756304638815112,-0.06519550285337328
341.3000000000043,20.663208982622134,-1.2776285946017323,-0.06657458471328193
342.4000000000043,20.697180828320242,-1.2828294783840257,-0.06653042289615829
343.5000000000043,20.731174702873766,-1.285898437195878,-0.06792879340170943
344.60000000000434,20.765059812596334,-1.290106984081372,-0.06839223150761997
345.7000000000043,20.79833172873775,-1.2929953922815298,-0.06953219900369634
346.80000000000433,20.83210397863593,-1.2989685922542071,-0.07053899467232272
347.90000000000435,20.865967116677496,-1.3029300605666332,-0.07198483812039713
349.0000000000044,20.89944285720216,-1.3072732299807484,-0.0734429780102217
350.1000000000044,20.933314018986202,-1.3108319664458772,-0.07476762247984636
351.2000000000044,20.966338185624483,-1.3152198128531603,-0.07593432560339775
352.30000000000445,21.000545687761488,-1.3189773591246863,-0.0762864739540352
353.4000000000044,21.03441290121186,-1.3222788311054776,-0.07741337665662318
354.50000000000443,21.068320160563413,-1.3273409831225345,-0.07881350734741721
355.60000000000446,21.101439979483,-1.3314347527201769,-0.08057990096019285
356.7000000000045,21.13503913230896,-1.3363075428842826,-0.0822432497339598
357.8000000000045,21.169104712599623,-1.3428479072167394,-0.08387639869732721
358.9000000000045,21.20332626973254,-1.3496767694074576,-0.0858020342017638
360.00000000000455,21.23642902591138,-1.3539405371293392,-0.0877393932108359
361.10000000000457,21.27124123644213,-1.362371708758549,-0.08965663615258679
362.2000000000046,21.304821599418645,-1.3677787313479883,-0.09131351131154508
363.30000000000456,21.338677880398325,-1.3750958646005513,-0.09360216484612627
364.4000000000046,21.37272632902438,-1.382974442937756,-0.09635214162036077
365.5000000000046,21.406417110106528,-1.3900957563189724,-0.09840339088885619
366.6000000000046,21.440432328976197,-1.3991191245923575,-0.10026039763966965
367.70000000000465,21.47419823966303,-1.4085204564914628,-0.10172888890865339
368.8000000000047,21.508198947028486,-1.419105211514161,-0.10347493505649163
369.9000000000047,21.542653707167826,-1.4295263974313432,-0.1055194530466701
371.00000000000466,21.576591383582517,-1.441616245842728,-0.10834039087996494
372.1000000000047,21.610648039090236,-1.4521650683935825,-0.11137450430281959
373.2000000000047,21.644568778120167,-1.468382523848382,-0.11397626085442303
374.30000000000473,21.678150324676654,-1.480308096890634,-0.11699862963315733
375.40000000000475,21.71286241207941,-1.4962634690782868,-0.12079504654150552
376.5000000000048,21.746830921157006,-1.5115095875989741,-0.1240627335712805
377.6000000000048,21.781160122819713,-1.5305488642201783,-0.12817474407694496
378.7000000000048,21.815167645676258,-1.550812236637775,-0.1315863721834214
379.80000000000484,21.849609362544346,-1.5679531109422227,-0.13542170984306479
380.9000000000048,21.883964416709976,-1.591451522534634,-0.13941713102424114
382.00000000000483,21.91798382866884,-1.6180291817265195,-0.14366231994119794
383.10000000000485,21.95256279911026,-1.645201639443612,-0.1473993504417912
384.2000000000049,21.98693081771855,-1.673694057381108,-0.15196854774525548
385.3000000000049,22.021208572437825,-1.7031094582039874,-0.15707298851580997
386.4000000000049,22.055838981066977,-1.7357727940727066,-0.16328294443882552
387.50000000000495,22.08998494164832,-1.7705480184409235,-0.16881702935869303
388.6000000000049,22.124740872371117,-1.8093835574703505,-0.17604713147117135
389.70000000000493,22.15964161836477,-1.8506258307659853,-0.18218777744629522
390.80000000000496,22.19414566273644,-1.8982140102878475,-0.18868244857472005
391.900000000005,22.229106811293285,-1.9473198821743645,-0.19573747859730073
393.000000000005,22.263825677652136,-1.9985726791833172,-0.20389686574989385
394.100000000005,22.298716622173405,-2.058995320569804,-0.21452165273112422
395.20000000000505,22.33371429553692,-2.118751229507297,-0.2242550393413536
396.30000000000507,22.368579746761043,-2.1837821762921297,-0.23454065008785419
397.4000000000051,22.403680784599057,-2.254632050660307,-0.24533790647264553
398.50000000000506,22.439170000000168,-2.3331600000003734,-0.2567899370000619
399.6000000000051,22.474381940477713,-2.41608441379018,-0.26866936977204947
400.7000000000051,22.509978913159312,-2.5124954197988854,-0.28247129153860406
401.8000000000051,22.545058972026826,-2.6097183323649626,-0.2973085549897263
402.90000000000515,22.58080773256354,-2.7117860589987393,-0.3130983051861356
404.0000000000052,22.61643161245184,-2.8307486005349096,-0.33168828439783793
405.1000000000052,22.652507409791315,-2.9597791625466385,-0.35123805431345945
406.20000000000516,22.688664121723342,-3.098315585012863,-0.3709568639366676
407.3000000000052,22.725018084721103,-3.253798450507139,-0.3931368809350815
408.4000000000052,22.761489729708703,-3.408150784612047,-0.4167817790587063
409.50000000000523,22.79746259053136,-3.573541807522021,-0.4415618826361323
410.60000000000525,22.833874584815284,-3.755263672925712,-0.469092428119279
411.7000000000053,22.871394516518652,-3.9690085028297806,-0.5004615841366769
412.8000000000053,22.90841802883326,-4.181764697430905,-0.5337444892299876
413.9000000000053,22.94595984635752,-4.413313510783396,-0.5709263544908105
415.00000000000534,22.98348452390747,-4.664522113589094,-0.6100666692921464
416.1000000000053,23.02155701289619,-4.96066134721776,-0.6538653996387107
417.20000000000533,23.060031192650598,-5.243546951849465,-0.70024287121417
418.30000000000535,23.098044126213857,-5.541307847058711,-0.7515968163539042
419.4000000000054,23.136799199697904,-5.865383227953835,-0.8077182017742373
420.5000000000054,23.17531076157272,-6.173569967317564,-0.8684495557557175
421.6000000000054,23.213915319129626,-6.515833166160666,-0.9330789342456889
422.70000000000545,23.252860753927404,-6.852220364173623,-1.0025917733442782
423.8000000000054,23.292108616748635,-7.195382565647245,-1.0764203216229
424.90000000000543,23.330768973521938,-7.500718140149393,-1.1546668730913687
426.00000000000546,23.370349661059464,-7.849793029663295,-1.2397864946392616
427.1000000000055,23.409525304868602,-8.21305591086358,-1.3276760325108543
428.2000000000055,23.447725423146473,-8.469142633221962,-1.4184272644771263
429.3000000000055,23.486420130869984,-8.750681111281061,-1.5070118128571086
430.40000000000555,23.525413603816993,-9.07882673740359,-1.6363228369624654
431.50000000000557,23.564347082404417,-9.365059595261718,-1.733564752968746
432.6000000000056,23.602465672676725,-9.62371220333529,-1.8457509575658961
433.70000000000556,23.639741737808695,-9.836294358285201,-1.9567097839841523
434.8000000000056,23.677686302732017,-10.025967082667613,-2.07071898726932
435.9000000000056,23.714019161938573,-10.140749601379262,-2.1810266049650577
437.0000000000056,23.75030235066431,-10.206231082737434,-2.2945145240779063
438.10000000000565,23.785642565600895,-10.218897805191924,-2.406717616389548
439.2000000000057,23.82019147197448,-10.176423474075962,-2.5166246644451125
440.3000000000057,23.854439138135017,-10.088866050456536,-2.622747875400556
441.40000000000566,23.887633090470146,-9.923456178397062,-2.7244510304042775
442.5000000000057,23.92027336801465,-9.698782763412831,-2.8253564803693214
443.6000000000057,23.952015725956638,-9.418916354103457,-2.918047450173135
444.70000000000573,23.983085561643904,-9.08405338206078,-3.0098965146035606
445.80000000000575,24.013449839478202,-8.69057505685604,-3.0947214318369256
446.9000000000058,24.0433216627337,-8.277058633402483,-3.173669073679629
448.0000000000058,24.073076933689382,-7.783975898040278,-3.2467942303604063
449.1000000000058,24.102038545404145,-7.29344003698591,-3.3151422224999942
450.20000000000584,24.13096080486103,-6.770046159221017,-3.368367946846422
451.3000000000058,24.15943180304194,-6.237139059048793,-3.4253303699213493
452.40000000000583,24.187792419172425,-5.693411875038542,-3.4792368067209325
453.50000000000585,24.216168754965057,-5.15103208487592,-3.5233069907484698
454.6000000000059,24.244344791873644,-4.622727769707972,-3.563857577988817
455.7000000000059,24.272960597970187,-4.10425014367892,-3.6018184293059328
456.8000000000059,24.301689136967912,-3.611807410953446,-3.633601505553571
457.90000000000595,24.330607630985075,-3.1497129504878023,-3.6620878371566508
459.0000000000059,24.359655844024207,-2.7266143119470736,-3.688046708964484
460.10000000000593,24.389415388729656,-2.3345171322903626,-3.710945491013514
461.20000000000596,24.41922403799029,-1.9918215242448498,-3.729482497799655
462.300000000006,24.449007742577063,-1.689365680629305,-3.745389668406401
463.400000000006,24.48056719775555,-1.4150242308561365,-3.760524515697184
464.500000000006,24.511711727450283,-1.1815255049456472,-3.7727594854239497
465.60000000000605,24.543202706236,-0.9786284747789922,-3.781632008115507
466.70000000000607,24.575312853098044,-0.806772521396162,-3.79040207031602
467.8000000000061,24.607510156938446,-0.6617237042494524,-3.798369626440023
468.90000000000606,24.640153393141173,-0.5417638563573077,-3.806319658443984
470.0000000000061,24.673243573902116,-0.44202686889065124,-3.810873047765174
471.1000000000061,24.706277879873376,-0.3640070673350993,-3.8142097860248594
472.2000000000061,24.739231841594933,-0.2982558667745721,-3.8185963467414132
473.30000000000615,24.772972598717594,-0.24456340375346786,-3.82149009739905
474.4000000000062,24.80698016024101,-0.20338744209475365,-3.824619778260372
475.5000000000062,24.840383183160494,-0.17091333565468297,-3.827511235531606
476.60000000000616,24.874718737653115,-0.14371988051757476,-3.829445969472973
477.7000000000062,24.90882294041036,-0.12463701731007804,-3.831847438075208
478.8000000000062,24.942954178848858,-0.10452889087232946,-3.8337980774303566
479.90000000000623,24.977265595548392,-0.09449985089580182,-3.8356568331457215
481.00000000000625,25.01181791049978,-0.0825723110090425,-3.8364151549415353
482.1000000000063,25.04602041191413,-0.07312904264000694,-3.837062274311113
483.2000000000063,25.08043140142763,-0.06338509388691782,-3.8385541524886104
484.3000000000063,25.11508102770527,-0.056237175684763115,-3.8385769093453255
485.40000000000634,25.149557134365846,-0.04520308069402206,-3.8400237736738
486.5000000000063,25.184033988076912,-0.036775839303435955,-3.839955951745508
487.60000000000633,25.21901378119044,-0.027010376082761627,-3.8417549317922695
488.70000000000636,25.25271979455277,-0.021742877713275988,-3.842640090790832
489.8000000000064,25.287648808258147,-0.01255283589856192,-3.8426401594014106
490.9000000000064,25.32304641652811,-0.008523392230056598,-3.84263823970868
492.0000000000064,25.357965388729006,-0.005240794980991252,-3.8433275048412807
493.10000000000645,25.39206403438852,-0.002257868507075028,-3.843285901494729
494.2000000000064,25.427466277576286,-0.0036389608505245146,-3.8446417204737267
495.30000000000643,25.46229219580736,-0.004340959432868457,-3.8446102923196497
496.40000000000646,25.497215459816168,-0.005938856681802242,-3.8446098003831453
497.5000000000065,25.532231542311244,-0.015926112317223608,-3.844609817504466
498.6000000000065,25.56742507273667,-0.028673537027269262,-3.84460897040103
499.7000000000065,25.601643840308125,-0.04075354532680793,-3.8444913388697866
500.80000000000655,25.637473567148085,-0.04837628951765373,-3.8432948853518223
501.90000000000657,25.672457098585326,-0.056564454792529265,-3.84329016268652
503.0000000000066,25.70773210051056,-0.06428048761579526,-3.843291275426493
504.10000000000656,25.74268688638906,-0.07213432546920337,-3.843588558629226
505.2000000000066,25.77771456830213,-0.07706264131673303,-3.8446097269768744
506.3000000000066,25.81295078540753,-0.08075110744179197,-3.8438935206121094
507.4000000000066,25.848063693448825,-0.08105290365907973,-3.8432867850969696
508.50000000000665,25.88342081049322,-0.07912527348921125,-3.8442912219145
509.6000000000067,25.918721359748105,-0.07477381316118774,-3.8446100856616483
510.7000000000067,25.953753012922995,-0.07401572994196684,-3.84461047963751
511.80000000000666,25.989105279994824,-0.07311719265976505,-3.844633030137549
512.9000000000067,26.024661755963027,-0.07232910737377192,-3.844941471819936
514.0000000000067,26.059892411572363,-0.06959727165832394,-3.844939813720674
515.1000000000067,26.094951008416324,-0.0686331392893284,-3.8449398038580176
516.2000000000068,26.13058507457243,-0.06637145604466595,-3.8449398039950182
517.3000000000068,26.165845724051497,-0.06471977976343424,-3.844939804743385
518.4000000000068,26.201314428779874,-0.06434180438783915,-3.8449398690368977
519.5000000000068,26.236775146874425,-0.06346886072028518,-3.844932743830836
520.6000000000068,26.272296379520018,-0.05951946723600895,-3.8460440723996827
521.7000000000069,26.30767374609918,-0.059039989518846536,-3.8446138369812224
522.8000000000068,26.34347124239405,-0.05720802227712162,-3.8446123021052188
523.9000000000069,26.37857311790285,-0.05492610488163453,-3.8459240654578224
525.0000000000068,26.414164410269688,-0.053721992538525803,-3.8459305862302555
526.100000000007,26.44976848060584,-0.05271269938912324,-3.8459301547547176
527.2000000000069,26.485220823069067,-0.05134618885299678,-3.8459328682744074
528.300000000007,26.520904632612133,-0.046519152053728835,-3.8455694255894812
529.4000000000069,26.556597921350374,-0.046726646617921926,-3.8456004144802574
530.5000000000069,26.591864908300835,-0.045636143422448094,-3.8456001673733495
531.600000000007,26.627566753353133,-0.04291249319942593,-3.845600163986895
532.700000000007,26.6632581664711,-0.04052664384000922,-3.845600163999659
533.800000000007,26.698744201576893,-0.03767878767377888,-3.845600164
534.900000000007,26.73436857112366,-0.03413829216092852,-3.8456001640000004
536.000000000007,26.770169484007372,-0.03172885309715473,-3.8456001640000004
537.1000000000071,26.805442486286655,-0.02990123460407146,-3.845600164
538.2000000000071,26.84117313104833,-0.02814512054220268,-3.8456001640000004
539.300000000007,26.876952930095854,-0.02791178660121211,-3.845600164
540.4000000000071,26.912870291992572,-0.027692826268756215,-3.8456001639999813
541.500000000007,26.948087539789316,-0.026874111618615727,-3.8456001640006634
542.6000000000072,26.9833861591295,-0.026749149651572268,-3.845600164226604
543.7000000000071,27.01953260740202,-0.02740605385613446,-3.8456001668650215
544.8000000000072,27.055545142953807,-0.02803304008901413,-3.8455977501340777
545.9000000000071,27.09129351392328,-0.029506802046833782,-3.84596057183222
547.0000000000072,27.12689367805134,-0.03069642656077275,-3.84592961968916
548.1000000000072,27.162612726684127,-0.031902110701871635,-3.8459298878770922
549.2000000000072,27.198512298774506,-0.03197264114437722,-3.845929883400154
550.3000000000072,27.23413057417722,-0.03312589907578894,-3.8459258131531557
551.4000000000073,27.269879418356528,-0.0357664165281106,-3.8466330998047153
552.5000000000073,27.305576953897607,-0.03662754921651065,-3.846918270295432
553.6000000000073,27.34163556565675,-0.04185037160543575,-3.8472709612708496
554.7000000000073,27.37757678542603,-0.044775363879174274,-3.8472392774067496
555.8000000000073,27.413059261690776,-0.048015527842444575,-3.847054625705523
556.9000000000074,27.448974178764093,-0.05059185440826457,-3.845930335759872
558.0000000000074,27.48500360809878,-0.053205672984243994,-3.845929952050257
559.1000000000074,27.520704853268203,-0.05786600411322976,-3.8459298914432885
560.2000000000073,27.556148308812745,-0.061250246761585095,-3.845929857009047
561.3000000000073,27.592272089426,-0.06392169878543792,-3.8459259476310703
562.4000000000074,27.627984671605503,-0.06783982086518632,-3.8468191992913465
563.5000000000074,27.66450728685749,-0.06765231248193859,-3.8472408823625246
564.6000000000074,27.700312636144137,-0.07036911548725097,-3.8472401551629853
565.7000000000074,27.73603962895255,-0.0723850673429485,-3.8472401529503286
566.8000000000075,27.771461658951974,-0.07473811220581292,-3.847240152999681
567.9000000000075,27.808160373904222,-0.07635964691142991,-3.8472401530000018
569.0000000000075,27.843368811106313,-0.07971156596934537,-3.8472401530000058
570.1000000000075,27.87961003829796,-0.08327074999146523,-3.847240152998779
571.2000000000075,27.91584368921779,-0.08481204449546187,-3.8472401528447113
572.3000000000076,27.951850784619964,-0.08620077927466119,-3.8472401608898994
573.4000000000076,27.987829825979382,-0.08825600214192185,-3.8472426221150378
574.5000000000076,28.02392060994017,-0.09107354482930317,-3.8469077157535425
575.6000000000076,28.059679818276344,-0.09175974220212059,-3.846243130659176
576.7000000000077,28.095769607181616,-0.09298170570930396,-3.8462605129095864
577.8000000000077,28.131832051447187,-0.09577844983699436,-3.8462271732863
578.9000000000076,28.16773072107642,-0.09912629287277862,-3.8475571313368193
580.0000000000076,28.203717282923588,-0.10165312099382998,-3.8478071280058397
581.1000000000076,28.239899038814464,-0.10395397297021391,-3.848891277554542
582.2000000000077,28.275734696014574,-0.10707234446346625,-3.8488925856685086
583.3000000000077,28.312110164391317,-0.11077400427354048,-3.8475351755594787
584.4000000000077,28.348036338607052,-0.11174802802537713,-3.8475793491830017
585.5000000000077,28.38399198985002,-0.11431387921279229,-3.847579840522217
586.6000000000078,28.41994867025092,-0.11747470297477305,-3.8475867058441557
587.7000000000078,28.456057576767286,-0.12011335987617602,-3.846462759386006
588.8000000000078,28.492363960687157,-0.12412781744470994,-3.846259596163712
589.9000000000078,28.528541480644606,-0.12715850727546502,-3.8462542160298883
591.0000000000078,28.564455377127523,-0.13006174111417168,-3.8472551949576674
592.1000000000079,28.600776189658642,-0.13190051257052635,-3.847580321064803
593.2000000000079,28.63688213724618,-0.1355227032117122,-3.847579849772568
594.3000000000079,28.673031459534837,-0.13631552341237752,-3.8475798312911773
595.4000000000078,28.70910593579647,-0.14072526219020884,-3.8475798856985737
596.5000000000078,28.745092890251954,-0.1436842556753514,-3.8479106175486035
597.6000000000079,28.781333980764817,-0.14493488153431228,-3.848903060595118
598.7000000000079,28.817614858086035,-0.14710530444140701,-3.8488999128405386
599.8000000000079,28.85363779473352,-0.14882719596124455,-3.848899935835599
600.9000000000079,28.88972872983906,-0.15349547851191925,-3.8489003660376646
602.000000000008,28.926208691005836,-0.15586974662502806,-3.848913178433694
603.100000000008,28.96204277479773,-0.1585698292110742,-3.8479308949464337
604.200000000008,28.998471111165873,-0.16083426056884387,-3.847910740498229
605.300000000008,29.034764890446823,-0.16525329572311254,-3.849313951212513
606.400000000008,29.070864104933644,-0.1671123320637162,-3.8492303922507487
607.5000000000081,29.10682811335443,-0.16995829079827243,-3.8492300058466817
608.6000000000081,29.143218260602314,-0.17269938863209064,-3.8492322952244535
609.7000000000081,29.179301685061507,-0.17588986293977815,-3.8488667942932353
610.8000000000081,29.21554426025079,-0.18118447782415922,-3.848899078988118
611.9000000000082,29.251744100824766,-0.18279678696956975,-3.8503066341129233
613.0000000000082,29.28779576772952,-0.18454100884235874,-3.8503299021400306
614.1000000000081,29.32405400369871,-0.1889209683012279,-3.8503300221110894
615.2000000000081,29.360495892078653,-0.1920969938424749,-3.8503300210146105
616.3000000000081,29.39663932157505,-0.19832648364721064,-3.8503300210000218
617.4000000000082,29.43284986949174,-0.2008790301998986,-3.850330021000006
618.5000000000082,29.469235954312676,-0.2043827842811344,-3.8503300210000204
619.6000000000082,29.505408154911272,-0.20710283974343446,-3.8503300209055924
620.7000000000082,29.54164624815708,-0.21111400369626418,-3.8503300115130514
621.8000000000083,29.577844302759296,-0.21314395524979635,-3.850330647336834
622.9000000000083,29.61430384615427,-0.21866887243037927,-3.85060330333522
624.0000000000083,29.6505509065761,-0.21924673590176585,-3.8516406418600773
625.1000000000083,29.6865611047546,-0.22261344136451916,-3.8516158151305997
626.2000000000083,29.722769035655332,-0.22508808884618017,-3.850321226335151
627.3000000000084,29.759331678127275,-0.229164390535361,-3.850319904676724
628.4000000000084,29.795443739616882,-0.22923872432560582,-3.850312509547856
629.5000000000084,29.831924159707633,-0.22939908980272167,-3.851493919758725
630.6000000000083,29.868271412098053,-0.2324524371062429,-3.851639547900394
631.7000000000083,29.904385730838868,-0.23440378012947588,-3.850066801062935
632.8000000000084,29.9408406758351,-0.2337813000153169,-3.8500980078747213
633.9000000000084,29.97689937402972,-0.23416191202814002,-3.8516284688742997
635.0000000000084,30.013391886132972,-0.2367124322117701,-3.8519611313248685
636.1000000000084,30.04989942433211,-0.23750124679427512,-3.851982359675385
637.2000000000085,30.08614016188328,-0.23773637005889442,-3.8526270486155845
638.3000000000085,30.122230894451395,-0.23867569375139905,-3.852564543886051
639.4000000000085,30.15840516058636,-0.2410060293136002,-3.853616305074924
640.5000000000085,30.19475361971068,-0.24143220992061443,-3.85361995146481
641.6000000000085,30.231260166129104,-0.23990200987403865,-3.853624857120462
642.7000000000086,30.267219616906903,-0.24310140055907767,-3.852911085286676
643.8000000000086,30.304062681484957,-0.2417887854306341,-3.852957163011927
644.9000000000086,30.34019565056691,-0.24538108949722268,-3.8537056889526227
646.0000000000086,30.376980417361466,-0.2457469418777842,-3.8542817322066276
647.1000000000087,30.41337057866165,-0.2469192072303198,-3.854280170144893
648.2000000000087,30.44963621202971,-0.24706660710127626,-3.8542801511233655
649.3000000000086,30.486101237193427,-0.24913627414274905,-3.854280152405588
650.4000000000086,30.522555758148677,-0.2516458371640673,-3.8542788626230773
651.5000000000086,30.55900757363734,-0.2504390322334926,-3.8540925133971453
652.6000000000087,30.595284180289127,-0.2530401393138388,-3.8536196946534123
653.7000000000087,30.631889126648026,-0.2561000823466299,-3.8536201315720024
654.8000000000087,30.668239342747444,-0.25540442974760136,-3.85362015088118
655.9000000000087,30.704796613622417,-0.25763517571790506,-3.8536201513697446
657.0000000000088,30.74113485343217,-0.2575156101431093,-3.8536201776562296
658.1000000000088,30.77794994526647,-0.26076407986604744,-3.85361796734803
659.2000000000088,30.81411438105094,-0.26302831390406894,-3.85467170669897
660.3000000000088,30.85075525446076,-0.2626529616301496,-3.8549153399390663
661.4000000000088,30.88738758072273,-0.26401512954914824,-3.8539363930909265
662.5000000000089,30.923952438435055,-0.26588530515593534,-3.8539401723908195
663.6000000000089,30.96012318810898,-0.26460590035600157,-3.853940021570569
664.7000000000089,30.997234732800145,-0.2672265823648142,-3.8539400200026086
665.8000000000088,31.033603036125644,-0.26957079904888737,-3.853940019597281
666.9000000000088,31.07013287878095,-0.2708329554124422,-3.8539399784783486
668.0000000000089,31.10658065061376,-0.27180200902650403,-3.853941290636359
669.1000000000089,31.14304312086288,-0.2735139605384742,-3.853933294381775
670.2000000000089,31.180008671152958,-0.2757276776517892,-3.8549300490005787
671.3000000000089,31.216805514944298,-0.27889274367701555,-3.8549309496195963
672.400000000009,31.25328894329121,-0.2792388613326838,-3.8538762079232938
673.500000000009,31.28985074587757,-0.28039014687532743,-3.85399369873106
674.600000000009,31.326751236121694,-0.2831812340882345,-3.8552695469589735
675.700000000009,31.363137636675333,-0.2860522045985603,-3.855270187012175
676.800000000009,31.39967017440017,-0.28848263866230356,-3.85527019619283
677.9000000000091,31.43647080617616,-0.2914558769045289,-3.855268953749053
679.0000000000091,31.473067132309534,-0.29307466438672786,-3.8550263348826763
680.1000000000091,31.509737288873552,-0.29477765498641806,-3.8546101105757264
681.2000000000091,31.54630266708893,-0.29927033438431333,-3.8546226591048853
682.3000000000092,31.583329409429652,-0.3016207059327454,-3.8555670925696255
683.4000000000092,31.619907347184608,-0.30344191218583333,-3.8555915365353624
684.5000000000091,31.65632590428761,-0.3055476102795666,-3.8551704991531963
685.6000000000091,31.693347401330374,-0.308655812994202,-3.855604284554327
686.7000000000091,31.72998692611283,-0.30869681170415764,-3.8556000396179626
687.8000000000092,31.76666068889391,-0.31160272404319256,-3.8556000595712714
688.9000000000092,31.80359564419598,-0.3145550766637589,-3.8556066227481662
690.0000000000092,31.84018247513123,-0.31860837349496224,-3.8544645165266345
691.1000000000092,31.877427942818656,-0.3198461963810267,-3.854279945931544
692.2000000000093,31.913717040962556,-0.3242091078510105,-3.8542801154043205
693.3000000000093,31.950555419946074,-0.32562411837910016,-3.8542853446161938
694.0000000000093,31.97387719675371,-0.3295649928161995,-3.855690578095989