File: 01_Data/Corian_Countertop/STA/N2/10K_min/Corian_Countertop_STA_N2_10KData_220920_R1.csv
##Temp./Â°C,Time/min,DSC/(mW/mg),Mass loss/mg
51.0,10.873994898948125,-1.5254643742043432,0.015440937361602458
52.20000000000002,11.191802327686647,-1.419385363028843,0.01296421477984211
53.400000000000034,11.452859911612506,-1.341384614994316,0.01573320643908982
54.60000000000005,11.670110835247756,-1.2851197297776826,0.014262796660135635
55.80000000000007,11.864753404496438,-1.2407760072222427,0.014519019954269297
57.000000000000085,12.047957046574128,-1.204281773104352,0.015915411504626498
58.2000000000001,12.22156487809466,-1.1749600391408932,0.015661612497577693
59.40000000000012,12.387092943311597,-1.1501690762935786,0.014408569785287817
60.600000000000136,12.548370100211947,-1.1274708288226878,0.013329353891214701
61.80000000000015,12.70323368288957,-1.1084859895445436,0.01752353929659911
63.00000000000017,12.857698351949034,-1.0888803421645514,0.014259682366168924
64.20000000000019,13.00680537891597,-1.0708522345246676,0.014028572633333347
65.4000000000002,13.153742681783852,-1.056905567662672,0.013548410465330285
66.60000000000022,13.29942394135881,-1.0394649972956147,0.014414500899377458
67.80000000000024,13.441594337771338,-1.0258096935980623,0.014470719318750547
69.00000000000026,13.579779898860792,-1.0121577086628015,0.014593553570124485
70.20000000000027,13.720000000000027,-0.9994499999999943,0.01331334005783269
71.40000000000029,13.857637935426077,-0.984903653543915,0.013247654119588503
72.6000000000003,13.993241288745017,-0.9716876802303281,0.014086102210872475
73.80000000000032,14.128554114120673,-0.9604397413424745,0.014472832198244134
75.00000000000034,14.264643802059496,-0.9469853712692193,0.01449248946741477
76.20000000000036,14.396308697194424,-0.9338439950496142,0.01331104553620932
77.40000000000038,14.527254066668487,-0.9211711724738734,0.011983696948977496
78.60000000000039,14.657678134736088,-0.9094181289171959,0.011864937010178878
79.80000000000041,14.788870066103154,-0.8988600097546967,0.011501573972373613
81.00000000000043,14.915924837289067,-0.8884365357539306,0.011774159752936164
82.20000000000044,15.045651955751984,-0.8781429028175223,0.011600287818562371
83.40000000000046,15.170535967208554,-0.8702133142957857,0.01053949582864444
84.60000000000048,15.298567335014859,-0.8615101815535413,0.010543242093079108
85.8000000000005,15.425986045971012,-0.8512937969054677,0.010650580364197637
87.00000000000051,15.550842926630468,-0.8443174968069315,0.010687946496737766
88.20000000000053,15.673425513373855,-0.8379484891334178,0.012159451253564768
89.40000000000055,15.798748979331895,-0.8289314283273416,0.011865107367857952
90.60000000000056,15.921105452321425,-0.8189452657483557,0.011850200100059105
91.80000000000058,16.0437699414146,-0.8099442441197896,0.009950365204961287
93.0000000000006,16.166204016704647,-0.8026564823589983,0.01052189513290891
94.20000000000061,16.287521652758148,-0.7950887000503192,0.007900918481339225
95.40000000000063,16.40937386351298,-0.7860864347485224,0.007910965079231502
96.60000000000065,16.527996977674015,-0.7777182672442222,0.007909642442815112
97.80000000000067,16.649059443203992,-0.7691678674488527,0.007480991872557574
99.00000000000068,16.765505359562834,-0.7613267012411956,0.007899816951648653
100.2000000000007,16.888287152308106,-0.7536229366547456,0.009221714939775083
101.40000000000072,17.00808152262814,-0.745338420115111,0.007960666257080362
102.60000000000073,17.127744486979342,-0.7369680748959417,0.006618978696687705
103.80000000000075,17.24528955989515,-0.7301478068602355,0.0052698949737362
105.00000000000077,17.364835050704233,-0.7212086221506206,0.004953920145777779
106.20000000000078,17.482448369924402,-0.713786938264205,0.003962747876989248
107.4000000000008,17.599705458969208,-0.706243817400847,0.004376261969020412
108.60000000000082,17.718578533487417,-0.6990639750390804,0.0041763679447965885
109.80000000000084,17.836712951644138,-0.691985324799702,0.0039510853809199276
111.00000000000085,17.95149040338096,-0.683499856646547,0.003960612551384912
112.20000000000087,18.070983853738824,-0.6754323291033387,0.003048731438545893
113.40000000000089,18.188661220595108,-0.6678087043657986,0.0039500115420247894
114.6000000000009,18.304861263934832,-0.66036916864141,0.0038790943390418775
115.80000000000092,18.423541047968357,-0.6513163279249805,0.0023366387859207194
117.00000000000094,18.54019787770605,-0.6449772493944195,0.0009860845008597963
118.20000000000095,18.65735359119109,-0.6378244622235965,1.0561967391353733e-05
119.40000000000097,18.77231855227057,-0.6304857445819292,0.0010871224440016647
120.60000000000099,18.89067115002333,-0.6248529851208631,9.689935530143856e-05
121.800000000001,19.007772519929205,-0.6175668595845094,-0.0026160776588568524
123.00000000000102,19.12455181396177,-0.610504569488476,-0.0026318968048837377
124.20000000000104,19.241794440829267,-0.6047031514578146,-0.0019368664982106765
125.40000000000106,19.35803365070641,-0.5980744622786304,-0.0026188455002706945
126.60000000000107,19.47414556339247,-0.5910494749743332,-0.0013201518641743348
127.80000000000109,19.589248597834654,-0.5856245496971195,-0.0026518623961786503
129.0000000000011,19.70604507300672,-0.579332993934596,-0.002729992010223725
130.20000000000113,19.82239934670965,-0.5735449242328844,-0.005252680034334212
131.40000000000114,19.938953159500226,-0.567961516732908,-0.0049290297932902405
132.60000000000116,20.05389629536317,-0.5619788898207996,-0.00527015745130921
133.80000000000118,20.16838782392111,-0.5570368392675106,-0.00659341355402443
135.0000000000012,20.283297751393373,-0.551226330102693,-0.005929619236925809
136.2000000000012,20.399026009308315,-0.5451813370592288,-0.006893386063705265
137.40000000000123,20.51490568814804,-0.538795642068901,-0.010854738908220085
138.60000000000124,20.630712981264207,-0.5332941012904123,-0.010859955998097526
139.80000000000126,20.74473517250287,-0.5277015197891404,-0.010860020424013683
141.00000000000128,20.860000000000127,-0.5226599999999882,-0.012180320187352045
142.2000000000013,20.975450169412746,-0.5171646891398647,-0.011861238343544578
143.4000000000013,21.090383814433572,-0.509908762078571,-0.011859711651974969
144.60000000000133,21.204706268049772,-0.5032726729139939,-0.01483098390338089
145.80000000000135,21.319582673505884,-0.4977950697861778,-0.015810178100909233
147.00000000000136,21.43313313237681,-0.4912517743364527,-0.014474714451598203
148.20000000000138,21.548658327397554,-0.4840723494566484,-0.015799872906997692
149.4000000000014,21.66139953089277,-0.4796941388956183,-0.017123963473864023
150.60000000000142,21.776810191341607,-0.47185825661369335,-0.017119878888903983
151.80000000000143,21.891611548182624,-0.4655268012858091,-0.01791730976086381
153.00000000000145,22.00628682733685,-0.4581141007320798,-0.019105685045313514
154.20000000000147,22.11949717816261,-0.45119725084866613,-0.021263364386621575
155.40000000000148,22.233430930277592,-0.4431557758773537,-0.02240008633877366
156.6000000000015,22.34805587352885,-0.43654770831648043,-0.02371519946932832
157.80000000000152,22.461995764564897,-0.4289554269959906,-0.025031349274604153
159.00000000000153,22.576208903533782,-0.4217833239588408,-0.026680034916365614
160.20000000000155,22.689792015117433,-0.41439710912508687,-0.027975795857103414
161.40000000000157,22.804251243147178,-0.40743755915408353,-0.027990127421224642
162.6000000000016,22.918332248191973,-0.3978535660398255,-0.028649672718259467
163.8000000000016,23.03219528668505,-0.3924269000231905,-0.03030000576562486
165.00000000000162,23.146064200142764,-0.3832484483381404,-0.031596310287739904
166.20000000000164,23.259905593386428,-0.37610411145651207,-0.03272948412410148
167.40000000000165,23.373725610057246,-0.3675264004247439,-0.0356011779560248
168.60000000000167,23.4874991038708,-0.3600422903485393,-0.03602819557256076
169.8000000000017,23.60222126091024,-0.3513226479588511,-0.03965256728019284
171.0000000000017,23.71478712150516,-0.34397913998895385,-0.04215432832001387
172.20000000000172,23.82921730161514,-0.3346474810312125,-0.04406200531229043
173.40000000000174,23.944756872609602,-0.32634778657092295,-0.047405032992996254
174.60000000000176,24.05896648023776,-0.31928844606496787,-0.05009117376544481
175.80000000000177,24.1722165689932,-0.31104832898580087,-0.05140329045015957
177.0000000000018,24.287301670693996,-0.30254976277477896,-0.05269990123070034
178.2000000000018,24.401055912093,-0.29625960375919114,-0.054022204817302466
179.40000000000182,24.513727710051068,-0.2890922853151795,-0.05794204736692343
180.60000000000184,24.62907228258523,-0.2815063273534951,-0.05954430472418082
181.80000000000186,24.742909586967375,-0.27436098744172965,-0.06187963549183273
183.00000000000188,24.857143983069115,-0.26888761614055345,-0.06593056232188488
184.2000000000019,24.970586638742766,-0.2625050034533983,-0.06986113753566148
185.4000000000019,25.08548261030478,-0.25552206542561323,-0.07015861874264484
186.60000000000193,25.19844863500419,-0.2504986370095396,-0.07315425408631793
187.80000000000194,25.31254068396691,-0.24423598987454623,-0.07672867521228532
189.00000000000196,25.426010668773444,-0.23973150587394992,-0.07936931489374555
190.20000000000198,25.54089859288476,-0.23333373830988377,-0.08199681847512341
191.400000000002,25.654300321850833,-0.22866949357572652,-0.08579438877746348
192.600000000002,25.767739692766824,-0.22258559706313247,-0.08805913858450465
193.80000000000203,25.88080816716601,-0.21607653920344702,-0.08994426334855499
195.00000000000205,25.995362072655276,-0.21115487980564487,-0.0918861007127445
196.20000000000206,26.107724269192158,-0.20588144254902568,-0.09453371475876482
197.40000000000208,26.221965191767833,-0.19894497499232427,-0.09715277769003183
198.6000000000021,26.335537796955524,-0.1913429952070999,-0.09943213961623032
199.80000000000211,26.446927362705637,-0.1867525650985328,-0.10114673127991924
201.00000000000213,26.563569198048775,-0.17913007788449564,-0.10242994746161838
202.20000000000215,26.677493441671512,-0.172757281034146,-0.10373332574511673
203.40000000000217,26.79064926571925,-0.1659622037124384,-0.10509582558512554
204.60000000000218,26.90343901078979,-0.15725626405756815,-0.10636975242359847
205.8000000000022,27.01766265434548,-0.14879946198413638,-0.10903470286052253
207.00000000000222,27.132847364209965,-0.1405831492434184,-0.11350862277476903
208.20000000000223,27.245158559383317,-0.13172322621509602,-0.1138349070245126
209.40000000000225,27.359263539881717,-0.12031291008621676,-0.11650921108072909
210.60000000000227,27.47286170165794,-0.11085681226476914,-0.12096072993496243
211.80000000000229,27.586204109068543,-0.09986366398499066,-0.12217235335237664
213.0000000000023,27.702488530791367,-0.08902089070787055,-0.12481889194204854
214.20000000000232,27.81469622309505,-0.07519441417020398,-0.1262301616620598
215.40000000000234,27.928908238608333,-0.06350263661543577,-0.12747102709680913
216.60000000000235,28.042939761511594,-0.0505481486168593,-0.13008536448692398
217.80000000000237,28.156481105466156,-0.0332868084981125,-0.13276566230251463
219.0000000000024,28.269796989335383,-0.019132009714734294,-0.13403403615037046
220.2000000000024,28.384846921730063,-0.0017172123800507763,-0.13666978046573908
221.40000000000242,28.498422096233966,0.01530143293141712,-0.14068792537731545
222.60000000000244,28.611689282977927,0.032129772837134626,-0.1433970147096555
223.80000000000246,28.72704161891197,0.051992035462324254,-0.14801021235877654
225.00000000000247,28.84047639893281,0.07047734147184963,-0.14996593087493615
226.2000000000025,28.954396023648673,0.08995979365510048,-0.15406979114364994
227.4000000000025,29.0686376881065,0.11059787795286934,-0.15621040195459868
228.60000000000252,29.18095331949785,0.132785046137353,-0.15882479072072364
229.80000000000254,29.297418642802644,0.1548223607969971,-0.1604916021109517
231.00000000000256,29.410660870816958,0.18209795954447458,-0.1675597786971914
232.20000000000258,29.525914998851754,0.20982328326824792,-0.17066557094758839
233.4000000000026,29.63890847806178,0.2404057060652314,-0.17476361119283057
234.6000000000026,29.753802541029252,0.27400427840981656,-0.1791558417530652
235.80000000000263,29.86759095882659,0.31011391214644163,-0.18339010358344598
237.00000000000264,29.981830845356647,0.3501340749834134,-0.18799704876166023
238.20000000000266,30.096207462009946,0.3932045824148644,-0.19353191666613823
239.40000000000268,30.21100401970946,0.4379546092640125,-0.19938930112863495
240.6000000000027,30.32579781399983,0.4873230109784989,-0.2068309661401826
241.8000000000027,30.44069767412155,0.5428073842003804,-0.210179241501542
243.00000000000273,30.552077599243592,0.5948136220891793,-0.21766959694204768
244.20000000000275,30.669628207173893,0.6584872850223947,-0.22384681140112184
245.40000000000276,30.783907732415162,0.72071466420046,-0.231149734408445
246.60000000000278,30.898679834605108,0.7880952758943089,-0.23772359664724751
247.8000000000028,31.01157773901679,0.8575356589816439,-0.2468932977674192
249.0000000000028,31.128495744236723,0.9300797815554954,-0.2563082146988731
250.20000000000283,31.243549872265653,1.006848742547618,-0.2646565631898481
251.40000000000285,31.35907560090122,1.0859884448162784,-0.2717365732977024
252.60000000000286,31.47366478551954,1.1662632943484925,-0.281796075441032
253.80000000000288,31.587860528888072,1.2500771772881694,-0.29339101898559106
255.0000000000029,31.705054657981513,1.3375635413191773,-0.3055668550269157
256.2000000000029,31.819333587228087,1.4255882308590222,-0.3182832215786031
257.40000000000293,31.934461196844595,1.5139142524369245,-0.32994415706780567
258.600000000003,32.050869342707315,1.605689262991554,-0.3440457825193577
259.80000000000297,32.16610710869386,1.7000039672047966,-0.35739143015194674
261.00000000000296,32.28105925180956,1.7903026573422083,-0.36864715918123325
262.200000000003,32.39609383197784,1.884517813649726,-0.3829822046786795
263.40000000000305,32.51144122044155,1.9786112326343441,-0.3988205581851494
264.60000000000304,32.627597941435106,2.0730733921501887,-0.41551483901493436
265.800000000003,32.74267448735541,2.1696422441431555,-0.43062751831996193
267.00000000000307,32.85932564547817,2.2686478783852575,-0.44871717098191644
268.2000000000031,32.974356251716415,2.36859214443456,-0.4677799227929742
269.4000000000031,33.089499101967675,2.46881516098757,-0.48608671203719434
270.6000000000031,33.20272954701159,2.5662213161129364,-0.5056310079809734
271.80000000000314,33.32069194429522,2.6696418676949376,-0.5254636565850048
273.0000000000032,33.436707076098585,2.7687958986275,-0.5459541561636891
274.2000000000032,33.5521672278803,2.869100885717447,-0.5693235501293095
275.40000000000316,33.66734975460501,2.965630444586902,-0.5913624663436701
276.6000000000032,33.78297201296888,3.0583738976885955,-0.6179003013266473
277.80000000000325,33.89884358682049,3.143182558295708,-0.6411755717630725
279.00000000000324,34.01458377594671,3.2178381489409627,-0.6683617553231351
280.20000000000323,34.12999894262497,3.279129575870733,-0.6956998986316392
281.4000000000033,34.24604819509171,3.314874890581413,-0.720064611129053
282.6000000000033,34.36010523735246,3.321145732203687,-0.7487652966655842
283.8000000000033,34.47662235726786,3.280192691079529,-0.7760961617633888
285.0000000000033,34.59149977013636,3.169561797478377,-0.8029667660121143
286.20000000000334,34.70580291970598,2.949689710754475,-0.8289019317765867
287.4000000000034,34.82000099087155,2.576715919666414,-0.8548804599126858
288.6000000000034,34.93125672987428,2.0165006330981674,-0.8757575085453273
289.80000000000337,35.04477402555421,1.4049591150671303,-0.8916089167198202
291.0000000000034,35.15507470713882,0.9769119601075876,-0.9079404356205703
292.20000000000346,35.266222977587944,0.7180785731474459,-0.9237372826766506
293.40000000000344,35.37842967744344,0.5712822460650725,-0.936419954834077
294.60000000000343,35.49027530328565,0.4828061833710895,-0.9503118673352016
295.8000000000035,35.60231066060559,0.42473404572622653,-0.9647476578757548
297.0000000000035,35.71535355921979,0.38261068165706663,-0.9774043616341719
298.2000000000035,35.829044623372056,0.34544434221119263,-0.9897982403227408
299.4000000000035,35.94271394242984,0.3151500998140026,-1.0032483184010474
300.60000000000355,36.05497041230293,0.2849161738485908,-1.0163939921638208
301.8000000000036,36.167856719082636,0.2563005548851351,-1.0265589824145174
303.0000000000036,36.28186625107001,0.2283886790399247,-1.0396727617728856
304.20000000000357,36.397093974362456,0.19950477304210845,-1.0511459479916438
305.4000000000036,36.510261011472124,0.17164243078916655,-1.0601981037287884
306.60000000000366,36.622009297855776,0.1439618869958682,-1.0685436520640228
307.80000000000365,36.73588065820589,0.11790540413167352,-1.0790430770869102
309.00000000000364,36.85377819035959,0.09280478268392585,-1.0886509746190618
310.2000000000037,36.96705885314287,0.07342719463341224,-1.0933602116333718
311.40000000000373,37.08151977077884,0.05277693163090758,-1.1013130398735687
312.6000000000037,37.19534600190448,0.036734476207782286,-1.1072622078104342
313.8000000000037,37.31000094535636,0.02337190292735313,-1.1132889816861322
315.00000000000375,37.42489576534169,0.013017154776011765,-1.1185079956484967
316.2000000000038,37.539014298434054,0.003559784042602901,-1.1249499659185789
317.4000000000038,37.65479684534393,-0.0010329115204479778,-1.1324677530499967
318.6000000000038,37.76836176298472,-0.005965660832360237,-1.138316747255586
319.8000000000038,37.88364842484685,-0.009802154308938243,-1.1426487696924492
321.00000000000387,37.99885480637067,-0.00939327832715542,-1.1474245057812045
322.20000000000385,38.113270050012396,-0.009631864990593608,-1.1563912857700998
323.40000000000384,38.22964999674108,-0.008935336158462237,-1.1623585300308346
324.6000000000039,38.34328497523444,-0.007706925075131224,-1.1676701860851084
325.80000000000393,38.45814016184027,-0.007104823232642295,-1.1719614088241586
327.0000000000039,38.572368476161806,-0.004310665464152674,-1.1777315986430508
328.2000000000039,38.68970636292138,-0.001582331409257133,-1.1846321099813881
329.40000000000396,38.80408459564552,0.00036015386098001026,-1.192275813324616
330.600000000004,38.919409209563,0.0030800854160231432,-1.1975597624502443
331.800000000004,39.03504698775077,0.00571751097541797,-1.2076789326932102
333.000000000004,39.14753974287702,0.006996603707814603,-1.212515612892334
334.200000000004,39.26465014307063,0.00991503422788958,-1.2179080470836512
335.40000000000407,39.38000098698642,0.012670583400128452,-1.2258399014552355
336.60000000000406,39.494525925867656,0.01693304409756049,-1.2338365925749941
337.80000000000405,39.6109907907297,0.019675892520818056,-1.2418933939749768
339.0000000000041,39.72578004248695,0.021283515025126997,-1.2470078110009606
340.20000000000414,39.84238803170883,0.02702655757122481,-1.258420383960849
341.4000000000041,39.95764896754551,0.030009717442856777,-1.2656077694568233
342.6000000000041,40.07330088672094,0.03314864513887456,-1.274034806796383
343.80000000000416,40.18780586884398,0.03677756046870935,-1.2821298742842444
345.0000000000042,40.30319660348653,0.04279308533576983,-1.2907924537569762
346.2000000000042,40.42091628257652,0.04725290802965863,-1.3016421279621309
347.4000000000042,40.536781833968725,0.05136348302407832,-1.3074785269577647
348.60000000000423,40.652469541381784,0.05722159431222938,-1.318250397915472
349.8000000000043,40.76841579392715,0.0630016981017423,-1.3279242400942266
351.00000000000426,40.88334242767868,0.06920792624020086,-1.3369269068518856
352.20000000000425,40.99950584903113,0.07440700699861072,-1.3465785998180686
353.4000000000043,41.115524040458794,0.0783207453822677,-1.3541279258407855
354.60000000000434,41.23236404548051,0.08511075770568036,-1.3642784771310645
355.80000000000433,41.34808728501272,0.09107038307722976,-1.3756845531617534
357.0000000000043,41.464480502384305,0.09701725375685982,-1.3899749743152263
358.20000000000437,41.578815282762186,0.10435188257385197,-1.399960570561201
359.4000000000044,41.6953997054562,0.109043766228522,-1.411410609551928
360.6000000000044,41.81126918421825,0.11906980264455783,-1.4226856035466864
361.8000000000044,41.92817380448163,0.1277266326032253,-1.4344712640909747
363.00000000000443,42.04329373257292,0.13365281850742983,-1.4472047425022803
364.2000000000045,42.1603597009281,0.14112113848312013,-1.4608104100552803
365.40000000000447,42.276925792788134,0.14994483710648848,-1.4741467369847863
366.60000000000446,42.39161086111374,0.15703146198176204,-1.4876761781453363
367.8000000000045,42.50825765866314,0.16443910514511847,-1.502185659423945
369.00000000000455,42.624670308245754,0.17255573330960228,-1.5158597084473913
370.20000000000454,42.741900525761395,0.17898536116752928,-1.5288278462356217
371.4000000000045,42.85781667426448,0.18674955061212284,-1.544632589820623
372.60000000000457,42.973764559192716,0.19427701886502013,-1.5601190351731562
373.8000000000046,43.090000956298056,0.20077997207402826,-1.5747301465153796
375.0000000000046,43.20555206750203,0.2065702193023799,-1.5907673465817993
376.2000000000046,43.32220176573106,0.21216890894698795,-1.6075326070153206
377.40000000000464,43.43969434708474,0.21705474920594242,-1.6244365402603007
378.6000000000047,43.553903326510266,0.22159978281864756,-1.6419613864308755
379.8000000000047,43.67097030571791,0.2241829339323281,-1.6575985243245812
381.00000000000466,43.78673926029538,0.22759287198085973,-1.676582825621912
382.2000000000047,43.90425864733966,0.22888508146957595,-1.691178234106336
383.40000000000475,44.02068916526802,0.22898777949376864,-1.7089707544164519
384.60000000000474,44.13658762158929,0.22964154294897526,-1.7278171527266215
385.80000000000473,44.252971242988366,0.2278725812847516,-1.744327835561411
387.0000000000048,44.369906632609286,0.22483374651958674,-1.7628828645727306
388.2000000000048,44.48613558312863,0.22396806672180838,-1.780655154249358
389.4000000000048,44.602484658608354,0.21804549108782015,-1.7977371464297027
390.6000000000048,44.71869607240442,0.21112499634523973,-1.8153693822937598
391.80000000000484,44.836501555483636,0.20450989840325523,-1.831016369764631
393.0000000000049,44.95215517008338,0.1946954788700124,-1.8474958259059355
394.2000000000049,45.06936344143422,0.183190063337474,-1.8632915159270058
395.40000000000487,45.18576888838694,0.17296184398734143,-1.8808168756205195
396.6000000000049,45.301494589806815,0.16030357321846608,-1.8954973277136284
397.80000000000496,45.41943842926325,0.14799725983370557,-1.9097360285932892
399.00000000000495,45.53521922134013,0.13476928000773697,-1.9243719046463648
400.20000000000493,45.65147689816345,0.11835581223811875,-1.9399336776940874
401.400000000005,45.76805925155116,0.10311907228133196,-1.9534959509648848
402.600000000005,45.88578803962775,0.08620010036272047,-1.9666527341254754
403.800000000005,45.999686067030794,0.06911320057475412,-1.9805613220868823
405.000000000005,46.1181712400527,0.052397502589639634,-1.9918505925326468
406.20000000000505,46.235377313124246,0.0360527487447802,-2.0023115855527838
407.4000000000051,46.351646699022844,0.018518970082259386,-2.0130057831677353
408.6000000000051,46.468444329600494,0.002862310330326174,-2.0245540870086685
409.80000000000507,46.585102333886816,-0.0159526508621451,-2.0350700918320466
411.0000000000051,46.701207728453504,-0.029544168776796206,-2.0421136369337467
412.20000000000516,46.81875725596507,-0.04871316406789465,-2.051848205757322
413.40000000000515,46.93625805829131,-0.06013809334653668,-2.05842636221004
414.60000000000514,47.0512051592581,-0.07675081927004353,-2.067882885952696
415.8000000000052,47.1692503602554,-0.08806478471833362,-2.0740565445998422
417.00000000000523,47.28667642222259,-0.1015202445401064,-2.0808900403074384
418.2000000000052,47.40268357687525,-0.11203550198928257,-2.0858451073335234
419.4000000000052,47.51895923056091,-0.1229505984813146,-2.090654562334988
420.60000000000525,47.63628477186301,-0.1339581096233087,-2.0966419789085826
421.8000000000053,47.75472136148476,-0.14341014490666987,-2.1027524460204887
423.0000000000053,47.871616598060626,-0.15031365763839163,-2.1081495650308093
424.2000000000053,47.98810067368354,-0.160066752577833,-2.1120620699817687
425.4000000000053,48.10524627547451,-0.16882688046802333,-2.1160724322076563
426.60000000000537,48.22114275011479,-0.17442726015932497,-2.11882206692949
427.80000000000535,48.338680064638844,-0.17975524845966626,-2.1220961771239164
429.00000000000534,48.454803792140744,-0.1852420420225257,-2.123776029285696
430.2000000000054,48.571820806359206,-0.19058770378107226,-2.125609019970662
431.40000000000543,48.6889497169401,-0.19417656884915005,-2.128225304592405
432.6000000000054,48.80602631039288,-0.19747674033892074,-2.130154568857094
433.8000000000054,48.923715809278775,-0.20036001410659243,-2.1335305504540694
435.00000000000546,49.04009109286482,-0.20187906592762409,-2.136266572657322
436.2000000000055,49.15698708417502,-0.2047061860705152,-2.1382402476794624
437.4000000000055,49.27428991934421,-0.2038271711418336,-2.139298075079611
438.6000000000055,49.39147545970767,-0.20556913710400776,-2.1423217162390924
439.8000000000055,49.51000090307082,-0.20709000319235688,-2.1428615424119477
441.00000000000557,49.62730892887329,-0.20663643112455898,-2.142850086075665
442.20000000000556,49.74365810489187,-0.20742193273951584,-2.1443611073919464
443.40000000000555,49.861838051952326,-0.20716717588058015,-2.146809771045077
444.6000000000056,49.979212264233965,-0.20587670813438294,-2.149041539513834
445.80000000000564,50.096671050845316,-0.20714620370658057,-2.1494027545157346
447.0000000000056,50.2149132157939,-0.20707187290793694,-2.152051493843463
448.2000000000056,50.332301475026476,-0.20599843974806406,-2.153218272856329
449.40000000000566,50.44990221763463,-0.20410857774215957,-2.156030159710026
450.6000000000057,50.567081334256265,-0.20382812518830903,-2.1573501802773234
451.8000000000057,50.68479942014698,-0.20458038197202208,-2.158712733703032
453.0000000000057,50.802301965960396,-0.20410492830152166,-2.1613052298918554
454.20000000000573,50.92053600547193,-0.204587163531423,-2.1613018891788993
455.4000000000058,51.03851511099729,-0.2033887534252629,-2.163820742183822
456.60000000000576,51.15580815084418,-0.20257602477962208,-2.1653845416383857
457.80000000000575,51.273724639602165,-0.20207400086071572,-2.165591468594527
459.0000000000058,51.391387117766,-0.2013330850486326,-2.166900058786007
460.20000000000584,51.508981223239815,-0.20087367741355583,-2.168210480758325
461.40000000000583,51.62656582780751,-0.19992861994377997,-2.1695300755262643
462.6000000000058,51.74365513037,-0.1994323851814943,-2.170852103849301
463.80000000000587,51.86118034284378,-0.1990981488517317,-2.171835148741077
465.0000000000059,51.97951414203437,-0.198044443593518,-2.1718356977589433
466.2000000000059,52.097430948338946,-0.1974070344651598,-2.1745089898359984
467.4000000000059,52.21494699661935,-0.19567042728893705,-2.177109532892566
468.60000000000593,52.33246611219947,-0.19408417842279657,-2.1771018224351786
469.800000000006,52.45038860064235,-0.19389642236738255,-2.1791139663619465
471.00000000000597,52.569098415753096,-0.19087896803847737,-2.1806476205744456
472.20000000000596,52.686209030726,-0.19087724611466095,-2.1824434707563922
473.400000000006,52.80403105355169,-0.18881913579307316,-2.184533060761725
474.60000000000605,52.92197396385796,-0.1884714471621536,-2.1850245443415717
475.80000000000604,53.039683519190305,-0.1856564016820592,-2.185660178177213
477.000000000006,53.158151925106324,-0.18552337780457745,-2.1883094424480043
478.20000000000607,53.276229233691154,-0.18412149337805747,-2.189619917534759
479.4000000000061,53.3938460001476,-0.18426963115740486,-2.190940266918656
480.6000000000061,53.51129940933891,-0.18317417996892124,-2.1922498792120413
481.8000000000061,53.629643053059105,-0.18144991974876132,-2.192249879310548
483.00000000000614,53.747054394170696,-0.1807490676706425,-2.1935724180637446
484.2000000000062,53.86551866368461,-0.17993414824408857,-2.1955462162476853
485.4000000000062,53.98263886723481,-0.17941977557502622,-2.195560070134655
486.60000000000616,54.100876740934844,-0.18006380667120003,-2.1968686490316136
487.8000000000062,54.21821851255494,-0.17911298641755552,-2.198699757889917
489.00000000000625,54.337056812993126,-0.17856465712950728,-2.202178670900706
490.20000000000624,54.455234360975965,-0.17689661154849298,-2.2034816278832814
491.40000000000623,54.5724671169735,-0.17616212235808393,-2.204769838132738
492.6000000000063,54.69112630304497,-0.17737837446017388,-2.206144395584152
493.8000000000063,54.80918204323445,-0.1761136047040751,-2.205373920327247
495.0000000000063,54.92788922051456,-0.1746275316906574,-2.20608986973991
496.2000000000063,55.04537609314499,-0.17367016620910702,-2.2064597751762354
497.40000000000634,55.16391318375605,-0.1741264888160779,-2.2087670091980844
498.6000000000064,55.28314590318149,-0.17195194776868516,-2.20999232685733
499.8000000000064,55.4003612223023,-0.17292001946187827,-2.211282603115146
501.00000000000637,55.51989983369951,-0.17198697972167054,-2.212669627952285
502.2000000000064,55.63723875549773,-0.170703418043342,-2.213999824305663
503.40000000000646,55.75532770720244,-0.16936383918118014,-2.2152836258301245
504.60000000000645,55.87414530435379,-0.16851249753914477,-2.2166461067258987
505.80000000000643,55.992242658196005,-0.16795044586384159,-2.21894869527722
507.0000000000065,56.11039405826165,-0.16612773962207683,-2.2202758614531017
508.2000000000065,56.22983131102756,-0.16719446895184117,-2.2215701636974625
509.4000000000065,56.3489794204558,-0.16474556225701012,-2.2228853915360958
510.6000000000065,56.466185874006264,-0.1642018589116752,-2.222784299685596
511.80000000000655,56.58438054907021,-0.16609867683363985,-2.2227799003058752
513.0000000000066,56.7031686333825,-0.1647741976730812,-2.22409295209233
514.2000000000066,56.82121433627119,-0.16342587879180326,-2.2263953125980445
515.4000000000066,56.940892297869674,-0.16321598421398423,-2.227718642991304
516.6000000000066,57.058989575201906,-0.16226292687262012,-2.2276607273685203
517.8000000000067,57.17716676677573,-0.16175676726417823,-2.229455609530111
519.0000000000066,57.29635468696216,-0.1617207387300447,-2.231670223704186
520.2000000000066,57.41492139952888,-0.1611133419565003,-2.2316668930825854
521.4000000000067,57.53379465990009,-0.16147049285839737,-2.234359242777585
522.6000000000067,57.65177061507711,-0.1620671670374081,-2.2348083763851214
523.8000000000068,57.77065138316186,-0.16091277303020252,-2.2362808329733634
525.0000000000067,57.88860045651922,-0.16028119988816272,-2.2375756262826907
526.2000000000068,58.00716499776879,-0.16054240467842495,-2.2372811579359313
527.4000000000068,58.12544545461207,-0.16056434080525583,-2.2376261425394937
528.6000000000067,58.24329030208351,-0.16012891041915428,-2.237527292296033
529.8000000000068,58.363174924779315,-0.1610868597737799,-2.240255870660062
531.0000000000068,58.479620554249436,-0.16109520335676508,-2.2421757080684253
532.2000000000069,58.60010583293286,-0.16062327743600893,-2.2435300230459356
533.4000000000069,58.71941237594343,-0.16146409453076443,-2.2451333772496147
534.6000000000068,58.83865086567573,-0.16269410897054443,-2.247480221026345
535.8000000000069,58.95798759601697,-0.1632921928408228,-2.248800172849484
537.0000000000069,59.075386422302245,-0.1634403931599293,-2.2487631131790367
538.2000000000069,59.19405579196961,-0.16436175349759663,-2.249349600920535
539.4000000000069,59.31234819286329,-0.16332987092540263,-2.2507937235541324
540.600000000007,59.43230666220144,-0.16326884763517957,-2.252089959242584
541.800000000007,59.548476662575546,-0.1618466143816815,-2.253404447384192
543.000000000007,59.67010169070971,-0.16048757176480974,-2.25311600321372
544.200000000007,59.788863126357285,-0.158959130510089,-2.2534127947168887
545.400000000007,59.90696410674735,-0.15542487125533744,-2.2560447929239316
546.6000000000071,60.026993300527266,-0.14991577851007082,-2.257358975456513
547.800000000007,60.145888794893544,-0.1479265638567051,-2.258680153347144
549.000000000007,60.264697683675394,-0.14621620490436885,-2.2600248606355064
550.2000000000071,60.383164793636375,-0.14504167839028637,-2.260989851682589
551.4000000000071,60.501638371752705,-0.1444016964983993,-2.2596687158648567
552.6000000000072,60.62029888514594,-0.1443022341050603,-2.258628524259244
553.8000000000071,60.73902608114755,-0.14342918030453636,-2.2646450795961535
555.0000000000072,60.858493535985275,-0.14255787048649973,-2.267019548152085
556.2000000000072,60.97712603443855,-0.14311634640117898,-2.265822131736246
557.4000000000071,61.09526777500494,-0.14214569489646214,-2.2643984708980227
558.6000000000072,61.21419792998283,-0.1419966835035476,-2.2657003113124508
559.8000000000072,61.33291184195421,-0.14345861602178883,-2.2670204016410263
561.0000000000073,61.45183127107765,-0.14429630263611304,-2.265772385572932
562.2000000000073,61.570467482091814,-0.14526032134102798,-2.268330079194108
563.4000000000073,61.690101485349196,-0.14407369582974786,-2.2683300694274298
564.6000000000073,61.808464643110426,-0.1433996811371617,-2.2696456435199726
565.8000000000073,61.927138229511094,-0.14507769045943136,-2.272348473575121
567.0000000000073,62.04671741698103,-0.14545748013282234,-2.2719600863379803
568.2000000000073,62.16563240514736,-0.14673859535099035,-2.2736855744128945
569.4000000000074,62.284143296884075,-0.1475602957498143,-2.276240423283731
570.6000000000074,62.40318422267598,-0.14867736232705114,-2.273627212333818
571.8000000000075,62.52262354734489,-0.15451768217979142,-2.2736098430009717
573.0000000000074,62.64191341553805,-0.15658091737094496,-2.273608094946047
574.2000000000074,62.759474959596886,-0.16036085406194586,-2.2739437707060275
575.4000000000075,62.88083349871888,-0.16411740084993187,-2.2765743847564988
576.6000000000074,63.00020297237196,-0.16846948320598626,-2.2765708191285623
577.8000000000075,63.11876214564983,-0.17191070750939552,-2.2781292893197165
579.0000000000075,63.23924658255931,-0.17610395301842763,-2.279216360203923
580.2000000000075,63.35791552373642,-0.1794872170986435,-2.278876489009382
581.4000000000076,63.47723192162288,-0.18361009122343588,-2.280186578717136
582.6000000000075,63.59696404977655,-0.18606283539334095,-2.280145029916821
583.8000000000076,63.71420553391686,-0.1891921314909205,-2.278868119541965
585.0000000000076,63.83453272880035,-0.19482722899211807,-2.2821349625040828
586.2000000000075,63.95336915069113,-0.19873045720769333,-2.2842347458414767
587.4000000000076,64.07162580257004,-0.2052761082953437,-2.284150071141151
588.6000000000076,64.19304588124348,-0.20946507329498612,-2.283819926932341
589.8000000000077,64.31137118357921,-0.21357792168806553,-2.2849945399922285
591.0000000000077,64.43117617976876,-0.21567391785797754,-2.2864599728222346
592.2000000000077,64.55194288026196,-0.21962293864772814,-2.2851400365385404
593.4000000000077,64.67149342944131,-0.22358421086561492,-2.2839295892836518
594.6000000000078,64.79052661474427,-0.22805362317033515,-2.282828990445328
595.8000000000077,64.90815866851872,-0.2328334354402974,-2.282795210182112
597.0000000000077,65.02922794052901,-0.2374151056364195,-2.2854611670694434
598.2000000000078,65.14882489649492,-0.24350432266872302,-2.288100073809548
599.4000000000078,65.26906652689242,-0.24406770216672755,-2.2894111158256862
600.6000000000079,65.38797725439706,-0.2452596392487904,-2.289412602397401
601.8000000000078,65.50664282300562,-0.2509251227847268,-2.2884784945271206
603.0000000000078,65.62612937032236,-0.2532792577417436,-2.2884108677599153
604.2000000000079,65.74633056742273,-0.25632343900471655,-2.2887601560292348
605.4000000000078,65.86659010850627,-0.2576913114875937,-2.288760176978906
606.6000000000079,65.98422837311513,-0.25811571496418856,-2.2900300576417214
607.8000000000079,66.10332151489203,-0.2600622460301145,-2.290781683436678
609.000000000008,66.22180391901169,-0.26213661589755033,-2.2900856931448335
610.200000000008,66.34302275471894,-0.26110737136513035,-2.2913937173563244
611.4000000000079,66.46187543703711,-0.2620292867061814,-2.2910699020923095
612.600000000008,66.58215588573181,-0.2611564357588647,-2.292186478893356
613.800000000008,66.70199430806717,-0.2597406143850063,-2.2909077224412853
615.000000000008,66.82000000000075,-0.25792000000011417,-2.291071950548066
616.200000000008,66.94099428943804,-0.2565207820432302,-2.2923843844171303
617.400000000008,67.06029670046553,-0.2557260131816271,-2.293710442343613
618.6000000000081,67.18021387477603,-0.2541607237729503,-2.2936998322025337
619.8000000000081,67.29940848358774,-0.25139793121671844,-2.293699781948693
621.0000000000081,67.41812593334916,-0.24888893148829236,-2.292379829628682
622.2000000000081,67.53837352495144,-0.2462939020406996,-2.291074894938248
623.4000000000082,67.6582521277947,-0.2458362365687476,-2.291055653900114
624.6000000000081,67.77681516702799,-0.24367822625221366,-2.2917660790012646
625.8000000000081,67.89607657584337,-0.2403028323506673,-2.2933582087939137
627.0000000000082,68.01605242209915,-0.23847122938919393,-2.292405751425388
628.2000000000082,68.13634102530875,-0.23506753538257297,-2.295028252045897
629.4000000000083,68.25389861199609,-0.23464043398463025,-2.295010393354969
630.6000000000082,68.37498902314294,-0.23274364800077446,-2.2937377517424173
631.8000000000083,68.4946763494198,-0.23219226460453493,-2.295010309489843
633.0000000000083,68.61451855198919,-0.22928095433605478,-2.2950095054182094
634.2000000000082,68.73488083266761,-0.22730793067979171,-2.2954173950542645
635.4000000000083,68.85191232251215,-0.22422280498647462,-2.298970045851123
636.6000000000083,68.97249061612742,-0.2235082195768015,-2.2976501662479083
637.8000000000084,69.09333771192259,-0.220884699082483,-2.2997487224278266
639.0000000000084,69.21221937425004,-0.2190642926708319,-2.300326508976835
640.2000000000083,69.33223775946725,-0.2178584101882949,-2.2965593669225512
641.4000000000084,69.45216869699976,-0.21946406345066574,-2.296560266506359
642.6000000000084,69.57216377489819,-0.2176219965999427,-2.2968869305165414
643.8000000000084,69.69094302405799,-0.2154039576291378,-2.299522653173688
645.0000000000084,69.81000000000076,-0.21679999999993463,-2.2977597058031236
646.2000000000085,69.930279026586,-0.21540787520426738,-2.296440004012281
647.4000000000085,70.05116613624568,-0.21422940552445038,-2.2977517601374897
648.6000000000085,70.17064826338691,-0.2134669437718351,-2.2967516085265136
649.8000000000085,70.29042383463639,-0.2133650746546247,-2.300214323437542
651.0000000000085,70.40897362870174,-0.21326024350612735,-2.299482621478595
652.2000000000086,70.52940150023115,-0.21446604425474464,-2.3008403292086306
653.4000000000085,70.64790585996676,-0.21499493813039805,-2.299520208235835
654.6000000000085,70.76670964933346,-0.21399377610527442,-2.299511883418009
655.8000000000086,70.88939853988835,-0.21513050323954053,-2.2969055703182324
657.0000000000086,71.00704487621842,-0.21570838321977384,-2.2995623743168077
658.2000000000087,71.12895529319559,-0.2171512010069578,-2.2995099060080584
659.4000000000086,71.24877487740709,-0.21591378828926366,-2.2995099107831045
660.6000000000087,71.36806727191528,-0.2176105685403182,-2.300766525233814
661.8000000000087,71.48772805849937,-0.21739469796757843,-2.2998682807833637
663.0000000000086,71.60775452102123,-0.2184961991135848,-2.298577602531204
664.2000000000087,71.72702744562736,-0.21806606653775662,-2.2985264463541624
665.4000000000087,71.84800750659183,-0.21849395743818437,-2.301159310989595
666.6000000000088,71.96778987573911,-0.21803689294178785,-2.3011778074816407
667.8000000000088,72.08676126437246,-0.2164855823577853,-2.3011667208101017
669.0000000000088,72.20742866325516,-0.21706129484446748,-2.2999011036919255
670.2000000000088,72.32662653108123,-0.21691375131554858,-2.2989718569571043
671.4000000000088,72.44672413074194,-0.21843395639327565,-2.2972617233049064
672.6000000000088,72.56716234633669,-0.2195344499991518,-2.296878208780604
673.8000000000088,72.68722100968182,-0.22305593874211924,-2.2979273012077766
675.0000000000089,72.80660697578558,-0.2263631578767093,-2.302425883938517
676.2000000000089,72.9268375406677,-0.2253144473963906,-2.301702325503741
677.400000000009,73.04694486120277,-0.22825274736333148,-2.3011598190558393
678.6000000000089,73.16644176517023,-0.23023463674443367,-2.3011725378834083
679.8000000000089,73.28657013350382,-0.23143495952093765,-2.3038592998042122
681.000000000009,73.40745954930426,-0.2358846891258471,-2.3015117158150664
682.2000000000089,73.52712582998402,-0.23653190599108634,-2.3028084349786972
683.400000000009,73.64766655363212,-0.23998501208926698,-2.3018200517509815
684.600000000009,73.76740908889565,-0.2442167617291011,-2.301542670503554
685.800000000009,73.88618752086765,-0.24699172142999226,-2.3024190349334654
687.0000000000091,74.00660878943037,-0.24714806441600198,-2.302810005520326
688.200000000009,74.12793484946496,-0.2469065578886459,-2.3020863492109553
689.4000000000091,74.24633119076208,-0.24911223389147674,-2.302111824837082
690.6000000000091,74.36860579075442,-0.24848130794899764,-2.3045182692016697
691.800000000009,74.48837501090671,-0.2507017339280584,-2.3030331654468923
693.0000000000091,74.6082275270721,-0.250929840824129,-2.300542985715139
694.2000000000091,74.72748816594826,-0.2530692436711898,-2.300719896627842
695.4000000000092,74.84921074948075,-0.25255267843427576,-2.299396396404204
696.6000000000092,74.96923698194244,-0.2555624996421164,-2.3000090137974194
697.8000000000092,75.08980132371866,-0.25465026154207404,-2.2967701741896605
699.0000000000092,75.20836664391835,-0.25655200819755675,-2.2986081727736236
700.2000000000093,75.32949003329549,-0.2539748074967796,-2.30038948468835
701.4000000000092,75.44990586610076,-0.2538658736313844,-2.3020362395417666
702.6000000000092,75.56942299324902,-0.25593237213852477,-2.3046800947800996
703.8000000000093,75.69090153714626,-0.2572297577431193,-2.305990226275174
705.0000000000093,75.8097890074854,-0.2599438015201117,-2.3037060566218726
706.2000000000094,75.93026418234473,-0.26207134408984517,-2.303373001467403
707.4000000000093,76.0507602006156,-0.26704876203695,-2.3010501182606884
708.6000000000093,76.17058751539315,-0.2711338089905584,-2.302369689347643
709.8000000000094,76.29151367673768,-0.27113195213653163,-2.3010498080592603
711.0000000000093,76.411559038473,-0.2740144124221074,-2.3010499792724657
712.2000000000094,76.53231725713951,-0.2743200278764837,-2.2982295262823675
713.4000000000094,76.65168062495032,-0.27757399400207394,-2.297098954682041
714.6000000000095,76.77178784241345,-0.28011773841342413,-2.297108158729264
715.8000000000095,76.8923538863473,-0.28009370776495296,-2.299740886636208
717.0000000000094,77.01298087679928,-0.279279110065124,-2.301050968489243
718.2000000000095,77.1335955148325,-0.28039968599912984,-2.3037984336076054
719.4000000000095,77.25377561719166,-0.28527897895149645,-2.303785201029656
720.6000000000095,77.37305244633005,-0.2847950418276428,-2.302532250523966
721.8000000000095,77.49427681173003,-0.2879662259918856,-2.3012638232784663
723.0000000000095,77.61477760662682,-0.2875696194626874,-2.2998208377010996
724.2000000000096,77.73550361835576,-0.2877358867982962,-2.302026907569128
725.4000000000096,77.85507311393428,-0.2882709245322802,-2.304712184186912
726.6000000000096,77.97608480953535,-0.29308737498962917,-2.3033677289536922
727.8000000000096,78.09696303371797,-0.29553450809140414,-2.3057437550708038
729.0000000000097,78.21695234999437,-0.29796241494966735,-2.303603507105777
730.2000000000096,78.33771190448779,-0.2943386074775905,-2.3038142075604493
731.4000000000096,78.45749072729723,-0.29396213226129514,-2.3020462692175476
732.6000000000097,78.57855552911968,-0.2926209278561445,-2.30500804466982
733.8000000000097,78.69819105111235,-0.295823855084077,-2.3050009050579474
735.0000000000098,78.81947254368347,-0.29708971985165306,-2.3020903575167244
736.2000000000097,78.93941493804283,-0.29651842022841934,-2.302361780374525
737.4000000000098,79.06018286324657,-0.3011993672424229,-2.3040160715205835
738.6000000000098,79.18095074549122,-0.3017345829708744,-2.30566872769617
739.8000000000097,79.29964483761103,-0.3058995575290807,-2.304236263044868
741.0000000000098,79.42128041716461,-0.3092569325677831,-2.301599705837965
742.2000000000098,79.54136196440967,-0.30742800034935525,-2.302917953324889
743.4000000000099,79.66136383834966,-0.3069429857858316,-2.3003629690673453
744.6000000000099,79.78221971350663,-0.307684004428995,-2.304228861814405
745.8000000000098,79.90236627100127,-0.31115896473768334,-2.3055420900308965
747.0000000000099,80.02284061202408,-0.31340226001770616,-2.306968614903731
748.2000000000099,80.14341801466037,-0.31564363015980246,-2.3074876434857425
749.4000000000099,80.2640380900837,-0.31633972962231416,-2.3062131269681148
750.6000000000099,80.38434180774111,-0.32037193540912845,-2.305550151305102
751.80000000001,80.50443505047258,-0.3212392426814675,-2.3055183435533495
753.00000000001,80.62591573073779,-0.3220280906657237,-2.305550161827255
754.20000000001,80.74591324543499,-0.3202243646545877,-2.3042298496688454
755.40000000001,80.86723660321259,-0.32561194078107375,-2.302913708151465
756.60000000001,80.98859371722533,-0.3280257961454454,-2.3051237325259444
757.8000000000101,81.10959365262464,-0.32905923076555815,-2.306081418923662
759.00000000001,81.23021129739182,-0.33305918891920744,-2.3066603255645135
760.20000000001,81.35084209699076,-0.3361832553964187,-2.30731365783021
761.4000000000101,81.4717389741906,-0.3378098287227035,-2.30708046519883
762.6000000000101,81.59175786176137,-0.33993256511149633,-2.3074000057621546
763.8000000000102,81.71367697003105,-0.3409149959566076,-2.307974664434574
765.0000000000101,81.83428911886351,-0.34351070111868903,-2.3080465221932362
766.2000000000102,81.95477389346061,-0.34786179018198404,-2.305340715547886
767.4000000000102,82.075373802793,-0.3526219754076777,-2.304679985598985
768.6000000000101,82.19554767111549,-0.35620276387526245,-2.3060526037408806
769.8000000000102,82.31639303903779,-0.361433227226484,-2.3059810216634116
771.0000000000102,82.43740948952357,-0.36040044807211546,-2.307294989801235
772.2000000000103,82.55739623768541,-0.36676263005765714,-2.3059900322569966
773.4000000000103,82.677158164724,-0.3701857837235974,-2.3046873594801904
774.6000000000103,82.79702856490009,-0.3771854461601043,-2.3047943285635863
775.8000000000103,82.91736041887047,-0.3779655222676516,-2.3094742964252317
777.0000000000103,83.03986955998094,-0.3835837808034435,-2.3092943253152485
778.2000000000103,83.15967878914671,-0.3912807305638368,-2.3086288844063825
779.4000000000103,83.27945624246263,-0.39299942870682036,-2.3072881555339744
780.6000000000104,83.4005921031815,-0.3986563191646857,-2.3073098926886417
781.8000000000104,83.5218679818546,-0.4018996738528775,-2.3076717249324132
783.0000000000105,83.64192864389874,-0.40458011214646505,-2.308606742403599
784.2000000000104,83.76199627322525,-0.4095002789766689,-2.3086146756111146
785.4000000000104,83.88314496536674,-0.41603370106022197,-2.3089598690697666
786.6000000000105,84.0041435514709,-0.42011782820396915,-2.3089598690000006
787.8000000000104,84.12371848837803,-0.424252558270539,-2.308959868509471
789.0000000000105,84.2426165104965,-0.4274003925392932,-2.309926545166311
790.2000000000105,84.36557006633669,-0.4254722777317813,-2.3085312107164633
791.4000000000106,84.48654562535631,-0.430676031926539,-2.3086377658626485
792.6000000000106,84.60669942580301,-0.43588332240265515,-2.304666544855412
793.8000000000105,84.72808091312145,-0.44077229095830545,-2.306004068086116
795.0000000000106,84.84920127628163,-0.443129884535735,-2.310027895316261
796.0000000000106,84.9489451408754,-0.4502711754060721,-2.3120432829138284