File: 01_Data/Corian_Countertop/STA/N2/10K_min/Corian_Countertop_STA_N2_10KData_220920_R2.csv
##Temp./Â°C,Time/min,DSC/(mW/mg),Mass loss/mg
51.0,10.859705950474893,-1.5225663853616223,0.020425819251546073
52.20000000000002,11.212811564974452,-1.4060238339290094,0.018806693018915688
53.400000000000034,11.469616455136254,-1.327881651896983,0.016567720367119954
54.60000000000005,11.686800587916306,-1.2696511860484399,0.01687643306140263
55.80000000000007,11.880088608694452,-1.2249431145186171,0.01914948571719588
57.000000000000085,12.060386747033684,-1.1892594619799877,0.019599058037100825
58.2000000000001,12.235188943217862,-1.1581177053402307,0.018452818519102188
59.40000000000012,12.397864649763083,-1.1323514902231524,0.019336584106394383
60.600000000000136,12.558353830975948,-1.1098780283487422,0.018762968535166458
61.80000000000015,12.713543700348248,-1.0888436184678254,0.018299028808582918
63.00000000000017,12.864845856449605,-1.0692161035878809,0.01811427165391688
64.20000000000019,13.014396024314367,-1.054045986368001,0.018257928763961928
65.4000000000002,13.161898521493708,-1.0365866514876085,0.018177138076951316
66.60000000000022,13.30799369617564,-1.0198391375108427,0.017040150668542253
67.80000000000024,13.448224195592017,-1.0061798450191386,0.018293769638516366
69.00000000000026,13.590063897278368,-0.9904735868977315,0.016924795252576175
70.20000000000027,13.729059181294389,-0.9751599055056285,0.018253574028939568
71.40000000000029,13.866563877643113,-0.9608894620651722,0.01681664022591356
72.6000000000003,14.001289684754923,-0.9481901167371451,0.01683743438895391
73.80000000000032,14.138081890415005,-0.9344889553804004,0.016797057147044825
75.00000000000034,14.270617327190946,-0.9209469357291024,0.01812753134814482
76.20000000000036,14.403981387846331,-0.9080264744315246,0.017194606795950307
77.40000000000038,14.534063946452768,-0.8959963157680025,0.016790821534849343
78.60000000000039,14.665589213903603,-0.8846283976362103,0.018066144322818722
79.80000000000041,14.794654316201347,-0.8728583883075653,0.016626324868513898
81.00000000000043,14.923799886407055,-0.862297180974804,0.015399926529215513
82.20000000000044,15.04989879747164,-0.8510246501545011,0.015264849382989887
83.40000000000046,15.178251657229916,-0.8430086757247229,0.016580846107498104
84.60000000000048,15.30506171550192,-0.8333462312692879,0.017838582956698268
85.8000000000005,15.429833124470656,-0.8244548229385914,0.01657123948531236
87.00000000000051,15.555005064758303,-0.8163852213286721,0.016563779884811503
88.20000000000053,15.679786180473197,-0.8070055889595983,0.015249136413222786
89.40000000000055,15.803904980828882,-0.7979256526627289,0.012630363844580828
90.60000000000056,15.924688770057081,-0.7889908094746255,0.012480260897270945
91.80000000000058,16.04994732323735,-0.781181068433705,0.013886867146141846
93.0000000000006,16.170837126287097,-0.7711924360597077,0.013940189512145373
94.20000000000061,16.291901698216243,-0.7619340640930934,0.013974619237491659
95.40000000000063,16.412165136217308,-0.7543344655482921,0.01267608446379942
96.60000000000065,16.53358348570596,-0.7456195723770559,0.012618258900381818
97.80000000000067,16.653212160275004,-0.737946284652582,0.011351657097234735
99.00000000000068,16.77317749160359,-0.7295618180697441,0.011331441019308386
100.2000000000007,16.89240520039617,-0.7202744900869106,0.01129979768628786
101.40000000000072,17.012315606795042,-0.7119299051632807,0.011299406682208968
102.60000000000073,17.131127221552852,-0.7057976078614822,0.00999115390155314
103.80000000000075,17.24980933919785,-0.6967494634616893,0.009990013999909841
105.00000000000077,17.367795825196623,-0.6894888476745362,0.008670035436965762
106.20000000000078,17.486890313775277,-0.6820988697446055,0.00999301495211391
107.4000000000008,17.60438291827276,-0.675579245567865,0.008668388974112595
108.60000000000082,17.722248131574304,-0.6667202059477138,0.008755775643515484
109.80000000000084,17.841397547984304,-0.6595368589059436,0.00867079249318703
111.00000000000085,17.95889317965645,-0.6523234107407266,0.008314295008744033
112.20000000000087,18.075159684498118,-0.64351686994588,0.007379213212804103
113.40000000000089,18.192475851004698,-0.6356586487146645,0.007945492028266443
114.6000000000009,18.310197900821297,-0.6268942746508842,0.00736187140460931
115.80000000000092,18.426858907615163,-0.6203337984385939,0.007163552418568031
117.00000000000094,18.544276886603093,-0.6128594398498642,0.005381365961828699
118.20000000000095,18.662190343464484,-0.6062743862535672,0.005380806306743757
119.40000000000097,18.78057013050215,-0.5977059949739782,0.006012172920104142
120.60000000000099,18.896285858520443,-0.5907493390743466,0.004719964697065926
121.800000000001,19.012499726008475,-0.5820670539955616,0.004398630515869861
123.00000000000102,19.12693747187726,-0.5771541008491069,0.004719885869594265
124.20000000000104,19.245115009910794,-0.5710376774186443,0.003399857830582498
125.40000000000106,19.36142551835883,-0.5661356578412579,0.00467450382106982
126.60000000000107,19.47529510066476,-0.5603878032783072,0.0011053405600156552
127.80000000000109,19.59397086198653,-0.5534764315764962,0.001099924515883366
129.0000000000011,19.70946239787229,-0.5475656255345599,0.0014266987682933774
130.20000000000113,19.82556360853686,-0.5431561359449613,0.0014293937849130245
131.40000000000114,19.941096136222868,-0.53644113373506,-0.00020192091858817207
132.60000000000116,20.05680948563328,-0.5308075766656222,-0.0015402512500166665
133.80000000000118,20.17172683114322,-0.5250588055852159,-0.0027384162419892277
135.0000000000012,20.287931309267215,-0.5184506636399068,-0.004186903868037994
136.2000000000012,20.40348829454875,-0.5125891506189245,-0.004170133627913408
137.40000000000123,20.518407869424177,-0.5081544293071824,-0.005491418212761445
138.60000000000124,20.63488450226702,-0.5015692075910241,-0.004844165324477956
139.80000000000126,20.75001233706051,-0.4971827685992788,-0.006066229272738255
141.00000000000128,20.86441693635175,-0.4904389155776165,-0.007190278162163999
142.2000000000013,20.979903177956945,-0.4849183408881535,-0.008591425368898342
143.4000000000013,21.09280193071248,-0.4778026997336079,-0.009769818761308002
144.60000000000133,21.20818153528375,-0.4725202678962596,-0.00944428911715356
145.80000000000135,21.322772244887574,-0.46622901864089666,-0.008752496477847593
147.00000000000136,21.436419341951773,-0.4583813837434741,-0.010126585690498402
148.20000000000138,21.551511601689725,-0.45284775258537996,-0.011410856746964626
149.4000000000014,21.666670501817144,-0.44579919600307905,-0.012737006266201334
150.60000000000142,21.780539937378755,-0.4391717140879538,-0.014050037368225965
151.80000000000143,21.894619697923652,-0.4312856961254862,-0.015041535228450975
153.00000000000145,22.009643236187447,-0.42578885209248135,-0.016359880868651366
154.20000000000147,22.12426844938777,-0.41764574585142594,-0.01636200469060789
155.40000000000148,22.23821210173168,-0.41048991328128964,-0.01794490243918645
156.6000000000015,22.351680059211926,-0.40156400484322574,-0.0193301838657991
157.80000000000152,22.465122800868997,-0.3950593086740876,-0.020270657400340397
159.00000000000153,22.580057253447368,-0.386694406634672,-0.021626243311221316
160.20000000000155,22.694125164090597,-0.3785709045899448,-0.021997901727104363
161.40000000000157,22.807843330648303,-0.3707281240886483,-0.023136371841697034
162.6000000000016,22.921991447416833,-0.3644352395194935,-0.024621117446117502
163.8000000000016,23.03587269617188,-0.355941399881879,-0.02822168275303305
165.00000000000162,23.14906754041101,-0.3489287169980496,-0.02986971396399163
166.20000000000164,23.26473740920002,-0.33970963218629874,-0.031179826629530005
167.40000000000165,23.375679992929133,-0.33186411096382123,-0.031876037668366664
168.60000000000167,23.49304187275825,-0.3235535564263904,-0.03213568999124927
169.8000000000017,23.606820149712192,-0.31464457157986137,-0.03573047991053091
171.0000000000017,23.720422250331758,-0.30780393259642574,-0.039284381250610956
172.20000000000172,23.834255538179004,-0.29898384197001243,-0.040841784390579505
173.40000000000174,23.948565841216368,-0.2905261656929343,-0.04310087478233804
174.60000000000176,24.063538695817613,-0.28102367485911767,-0.04380933958067512
175.80000000000177,24.17768008886666,-0.2734430164866408,-0.0446945904091427
177.0000000000018,24.289834686558148,-0.26682047642356543,-0.046093664763261266
178.2000000000018,24.40265730328194,-0.25803548604485005,-0.05190023548509437
179.40000000000182,24.518442477347037,-0.24808572577665883,-0.05586718677961233
180.60000000000184,24.632415430107276,-0.2420349373569114,-0.05620809849587616
181.80000000000186,24.74589273359309,-0.2360250244642613,-0.058791645525668734
183.00000000000188,24.859645805632148,-0.22991761355220106,-0.0628091703971112
184.2000000000019,24.97416695269091,-0.22329269114013267,-0.06673772880879092
185.4000000000019,25.08443665754039,-0.21684718350050824,-0.06784402118999378
186.60000000000193,25.202032573242427,-0.21048497664209057,-0.07082441260213779
187.80000000000194,25.314877132692118,-0.20609907404786978,-0.07266207795946666
189.00000000000196,25.426859308671382,-0.20056845090926712,-0.07596682052808923
190.20000000000198,25.54208077884526,-0.19418083508871126,-0.07861633150663216
191.400000000002,25.656493748753913,-0.1897359003566148,-0.08000880005099331
192.600000000002,25.770100956530005,-0.1847962423636392,-0.08295808755025291
193.80000000000203,25.88415338552466,-0.1796163432030907,-0.08552195137575325
195.00000000000205,25.99786393269235,-0.1740914422824285,-0.08938623128016676
196.20000000000206,26.110969877489804,-0.16946060619118952,-0.09079065870562619
197.40000000000208,26.22265451546862,-0.16385977842362104,-0.09207270418802338
198.6000000000021,26.33796562653968,-0.15762890927155987,-0.09606029742351652
199.80000000000211,26.45254128226744,-0.15170356507237856,-0.09738036475969292
201.00000000000213,26.56586229091139,-0.14426852023317283,-0.09875969344569446
202.20000000000215,26.67988034952626,-0.1385910761161476,-0.10075426953729583
203.40000000000217,26.7911550332092,-0.13141902327682045,-0.10264281578447942
204.60000000000218,26.90670011003069,-0.12502327343897396,-0.10416499569974036
205.8000000000022,27.02124069901276,-0.11573552015297274,-0.10525039514565115
207.00000000000222,27.132128254266725,-0.10802051245073829,-0.10885352252463898
208.20000000000223,27.248130475189704,-0.09668176858826925,-0.11054985558272845
209.40000000000225,27.362664240083138,-0.08962722950871525,-0.11186894911567258
210.60000000000227,27.4752410625131,-0.07897821597876707,-0.11585768624197446
211.80000000000229,27.589362827581187,-0.0687975172783127,-0.11682917478707733
213.0000000000023,27.703228142268298,-0.0584575735372927,-0.11977649394669587
214.20000000000232,27.81709213144944,-0.04616605891796009,-0.1211036345070231
215.40000000000234,27.93103791946025,-0.03279446010468564,-0.12240858059772997
216.60000000000235,28.044605276533062,-0.02157672668528539,-0.12601239329687797
217.80000000000237,28.15868386350557,-0.008167157734988068,-0.12809972927143543
219.0000000000024,28.271363387249558,0.006358326958114521,-0.13065809810225293
220.2000000000024,28.38577665064513,0.02041993441545831,-0.13272944144659027
221.40000000000242,28.500352774889766,0.038251419425527525,-0.13535062929696107
222.60000000000244,28.613915877101075,0.05381188588293624,-0.13697348601362114
223.80000000000246,28.72917000000026,0.07164948000001212,-0.14095353412331812
225.00000000000247,28.841794001760487,0.0892835852829169,-0.14428369356988924
226.2000000000025,28.955352045920165,0.10668721410928937,-0.14763814890577454
227.4000000000025,29.06917097132193,0.12724011112818656,-0.15162000718008883
228.60000000000252,29.18277308666692,0.1468709802054907,-0.1529165307951259
229.80000000000254,29.297225572078673,0.169268311759958,-0.1557165122428512
231.00000000000256,29.412604881708358,0.192943756889857,-0.16106413398349462
232.20000000000258,29.526079781447578,0.21709305729298,-0.1637087425609436
233.4000000000026,29.640646155725108,0.24547929473294366,-0.1685358938171615
234.6000000000026,29.754768781514912,0.2740705998457075,-0.17345948179472037
235.80000000000263,29.867927304369815,0.30652779880565206,-0.17619456603188555
237.00000000000264,29.982162040653908,0.34251380819321187,-0.18224544196828907
238.20000000000266,30.094970379428627,0.3795053576192253,-0.18390373431515616
239.40000000000268,30.211356401771944,0.42318680298995226,-0.18958594531150563
240.6000000000027,30.325862605715322,0.467367894102885,-0.1968274249106825
241.8000000000027,30.44070359757301,0.516039548216946,-0.20161402651811278
243.00000000000273,30.553715068732213,0.5657620374891086,-0.20787371435847257
244.20000000000275,30.670192067367882,0.62327431612176,-0.2143278473359298
245.40000000000276,30.78362130165288,0.6798566356131496,-0.21996825869351788
246.60000000000278,30.898980799882985,0.741462903265846,-0.22789076494469285
247.8000000000028,31.01408126614087,0.8073442986378151,-0.23543852179056302
249.0000000000028,31.12935769277096,0.8756940119472846,-0.24471684647284864
250.20000000000283,31.244244172543304,0.9461593803255226,-0.2528990646699718
251.40000000000285,31.358112174463212,1.0211773512151205,-0.2611957114722019
252.60000000000286,31.47306713167331,1.0979364268146043,-0.27152823627027
253.80000000000288,31.589079542651785,1.176905878192193,-0.28005066662244804
255.0000000000029,31.700986369658505,1.2560875861496301,-0.2893306281348984
256.2000000000029,31.818128831591135,1.3417578821534157,-0.30129212286053697
257.40000000000293,31.933392074861132,1.426184181011698,-0.3110904280550164
258.600000000003,32.048742826231674,1.5148911032821308,-0.3248139575548321
259.80000000000297,32.163914790248654,1.6002263834079569,-0.33725694397972195
261.00000000000296,32.27896286981671,1.6894521544663599,-0.35160961229397625
262.200000000003,32.39510913753257,1.7804793590876589,-0.36444723845353133
263.40000000000305,32.510072853434146,1.8699218752734217,-0.3800475516144495
264.60000000000304,32.62519583681259,1.9617980667575246,-0.39507518333300107
265.800000000003,32.739740611759274,2.0534314035089434,-0.4085488752333153
267.00000000000307,32.856325651081036,2.1495215930596574,-0.42728390301129826
268.2000000000031,32.97236942039927,2.2468812044331794,-0.4440682077417373
269.4000000000031,33.08686338033366,2.3405029772479313,-0.46248884978925586
270.6000000000031,33.19977960127847,2.4363191345303714,-0.4796624682191011
271.80000000000314,33.316852926874326,2.5363239873492285,-0.4992528937977463
273.0000000000032,33.43242436183035,2.6369287167891455,-0.5204994660562017
274.2000000000032,33.547780200389504,2.735229349934157,-0.5406079742516638
275.40000000000316,33.66408024996627,2.835941532701429,-0.5621636619899539
276.6000000000032,33.77938514861501,2.931940888582457,-0.5890418740401642
277.80000000000325,33.89601127580935,3.0272297380754747,-0.6101988875080919
279.00000000000324,34.01147437175387,3.1094868826395823,-0.6357702476926725
280.20000000000323,34.12614069462261,3.1865390003293697,-0.6618736351981767
281.4000000000033,34.24240676801774,3.2499356695297625,-0.6878708122013979
282.6000000000033,34.35705236514782,3.2921186954867485,-0.7137906909364404
283.8000000000033,34.47266896738471,3.307250945285875,-0.742242880463921
285.0000000000033,34.58782353957214,3.278658014553057,-0.7714175005547395
286.20000000000334,34.70361392162,3.1850308689607916,-0.7965178876003343
287.4000000000034,34.81766362319045,2.999534991727855,-0.822660927294506
288.6000000000034,34.93135129379001,2.6763991942693712,-0.8471350916900007
289.80000000000337,35.04536651671019,2.166821643907115,-0.8713420286477787
291.0000000000034,35.156766882289475,1.570562775862074,-0.8886704920611512
292.20000000000346,35.26846319150477,1.1018037708243382,-0.9063545299093292
293.40000000000344,35.378316604510324,0.8177389126494703,-0.9186981547924771
294.60000000000343,35.49153327201442,0.6464343160380445,-0.932969951240993
295.8000000000035,35.60265896883636,0.5458423061717345,-0.9473858845911223
297.0000000000035,35.71563447392142,0.4769977610668731,-0.9619665577388252
298.2000000000035,35.82944845432369,0.4298573650207608,-0.9765570070820426
299.4000000000035,35.94159396188859,0.3910840120785469,-0.9907245275406837
300.60000000000355,36.054369625675854,0.35554701493838947,-1.0040051093170734
301.8000000000036,36.166365068465126,0.32367220359206816,-1.0151355029550717
303.0000000000036,36.281470195769394,0.29157985245394985,-1.0270025075431541
304.20000000000357,36.39462003267496,0.25992455702863815,-1.038039463513683
305.4000000000036,36.50882403365294,0.22977464291308786,-1.048724716663175
306.60000000000366,36.62267691827681,0.20031542160268664,-1.0591273244064472
307.80000000000365,36.73578357470124,0.17547898686040536,-1.0672153492478977
309.00000000000364,36.850266430170585,0.14864413431488802,-1.0767414286487798
310.2000000000037,36.96398238094317,0.12602844303206046,-1.0838364431156386
311.40000000000373,37.077927956579465,0.10655370454172854,-1.091515699651326
312.6000000000037,37.19132235091396,0.08964090533214157,-1.1002484890153736
313.8000000000037,37.30581512905705,0.07482409092956165,-1.1020315209290263
315.00000000000375,37.41975106911467,0.06285782166551915,-1.1087061753097398
316.2000000000038,37.53435937749765,0.05352444427728498,-1.11629697447822
317.4000000000038,37.64927197445165,0.045946479224742084,-1.120568492355635
318.6000000000038,37.76407464510195,0.04084071127802983,-1.1268924799283697
319.8000000000038,37.87763048437711,0.03812566769192263,-1.1332228823155472
321.00000000000387,37.993116540258164,0.03744524636117543,-1.138499362721125
322.20000000000385,38.10724318832674,0.036290362234491565,-1.145951884482253
323.40000000000384,38.22235876134524,0.035085848378134374,-1.1503199135803701
324.6000000000039,38.337459187649685,0.03560966097310168,-1.1553393112193446
325.80000000000393,38.4525573898467,0.037828841894682046,-1.1635207523128153
327.0000000000039,38.56667587745618,0.037556537050454517,-1.1699313000999219
328.2000000000039,38.68331311438352,0.04090229118184077,-1.176573013245156
329.40000000000396,38.798281341916145,0.042008027279995905,-1.1825402227873196
330.600000000004,38.913385223494025,0.044426229032022965,-1.1901861244156406
331.800000000004,39.028892022858685,0.04779527400992646,-1.1970789999561982
333.000000000004,39.143891131196845,0.050395471183929064,-1.2027398317654314
334.200000000004,39.2594536504838,0.052561053289243494,-1.209701131366666
335.40000000000407,39.37517750954176,0.0553049600338531,-1.2177891188530001
336.60000000000406,39.49084538251651,0.058281388991423745,-1.225307548439631
337.80000000000405,39.606383674718494,0.060729121375862484,-1.232444631703141
339.0000000000041,39.722652048364516,0.06444134836852258,-1.2404407773831472
340.20000000000414,39.83807666405342,0.06912256758724557,-1.2491456719458083
341.4000000000041,39.95282094573485,0.07239261912715404,-1.256352673344019
342.6000000000041,40.06830083758648,0.07737413245444155,-1.2649785343540256
343.80000000000416,40.18475572081152,0.08251242764415145,-1.2711365182921797
345.0000000000042,40.300459762733624,0.0865666514510329,-1.2817730140181811
346.2000000000042,40.41518473188089,0.0900049127869363,-1.2901064174096901
347.4000000000042,40.53034473687089,0.09599705992121163,-1.2985678111162775
348.60000000000423,40.646632912576315,0.10124860870034921,-1.3088643455952544
349.8000000000043,40.76199889015177,0.10583434709948268,-1.3186404679845625
351.00000000000426,40.87828287804529,0.11077710731794986,-1.3279318861044844
352.20000000000425,40.99313429044747,0.11609923512110375,-1.33810795919076
353.4000000000043,41.10848527356861,0.12253166370886967,-1.3481980649746657
354.60000000000434,41.22410062566622,0.12997431312669275,-1.3588335100591302
355.80000000000433,41.3407031643481,0.13315265173246532,-1.37004850379226
357.0000000000043,41.4567162863531,0.13908375891183952,-1.3794562294522845
358.20000000000437,41.57406687760746,0.14701937148585162,-1.3905660990988262
359.4000000000044,41.689367344603106,0.15238269081969102,-1.4023833243576909
360.6000000000044,41.806698185113454,0.15966544354827453,-1.41535710949309
361.8000000000044,41.92324646059351,0.16726726591176957,-1.4297998628283932
363.00000000000443,42.03847153717574,0.17494063717315267,-1.4416124207443461
364.2000000000045,42.154004103806955,0.18271728218115252,-1.4536623349954643
365.40000000000447,42.270410309943806,0.1896513911831868,-1.4686895728256673
366.60000000000446,42.386690949686496,0.19805029013397987,-1.4794147119178458
367.8000000000045,42.50218271300391,0.20565240615143143,-1.4933132701771878
369.00000000000455,42.61945311953027,0.21429312108156798,-1.5085724172525499
370.20000000000454,42.73497299042272,0.22116808545389002,-1.523121083443887
371.4000000000045,42.85190112307434,0.22799844727037635,-1.539395226806302
372.60000000000457,42.96704479972863,0.2358581803318095,-1.55380491167488
373.8000000000046,43.08325276030214,0.24359958473416746,-1.5690528429293096
375.0000000000046,43.19954791592144,0.24743689051926818,-1.5856460137293427
376.2000000000046,43.31587927851192,0.2521159806834755,-1.6036975589018083
377.40000000000464,43.43223422276621,0.256175391336281,-1.6199215438437502
378.6000000000047,43.549438746726196,0.25948599803972694,-1.6372312776215354
379.8000000000047,43.66606607709246,0.26250703948061077,-1.6538934179996838
381.00000000000466,43.781199546778126,0.2643716750480749,-1.6686361151841909
382.2000000000047,43.895852026238344,0.26567081268379233,-1.6863994688170099
383.40000000000475,44.01384917141214,0.2649475392726551,-1.7041358307864094
384.60000000000474,44.1301471477507,0.2631481872225173,-1.7211643362322246
385.80000000000473,44.246630165102935,0.2624388139669941,-1.7388707619941965
387.0000000000048,44.36206923474327,0.25970377597814615,-1.7566126910865836
388.2000000000048,44.48020580517931,0.25514938828991457,-1.773450771752282
389.4000000000048,44.59574437791868,0.2497818550837199,-1.7912122440854072
390.6000000000048,44.71221500102738,0.24196343416483138,-1.808027541858527
391.80000000000484,44.829068235199536,0.2330438978587828,-1.8248106115742266
393.0000000000049,44.94467516935059,0.2252657900428895,-1.8435736128675555
394.2000000000049,45.06177793940253,0.21273449678969197,-1.8588540084337777
395.40000000000487,45.17738480466244,0.20201532026124167,-1.8759449796275738
396.6000000000049,45.29362383328717,0.19186760526671892,-1.8913222452723217
397.80000000000496,45.40981573138763,0.1788991692914358,-1.9058896378880115
399.00000000000495,45.526572042244645,0.1635121250480171,-1.9227421963758884
400.20000000000493,45.64396835798992,0.1476059843164338,-1.9362701985524402
401.400000000005,45.75965541293446,0.1309124697841721,-1.9506944319334467
402.600000000005,45.876517132015266,0.11420565386546677,-1.9636745301131517
403.800000000005,45.993595806566226,0.09879499621924641,-1.9770854144481853
405.000000000005,46.1092731055759,0.0802183906134091,-1.989281575374045
406.20000000000505,46.22616562756168,0.06499447528598283,-2.0007022925372446
407.4000000000051,46.34275887219397,0.046890281613364636,-2.0118004121766853
408.6000000000051,46.458703924364976,0.03077872860507249,-2.022360768898534
409.80000000000507,46.57614345726871,0.013836252026169917,-2.032828033591519
411.0000000000051,46.69213536747919,-0.0011608799706128356,-2.0404799184338662
412.20000000000516,46.808820327024534,-0.018288896757831165,-2.0487731943647765
413.40000000000515,46.925403988448416,-0.0343311421970061,-2.05889813172975
414.60000000000514,47.040138251144,-0.046948645367168744,-2.065387932236942
415.8000000000052,47.157303695931866,-0.05999575876743905,-2.072100578444073
417.00000000000523,47.275362736135904,-0.07386358731249823,-2.0785831075533583
418.2000000000052,47.39340603973962,-0.08477505630675848,-2.084784617082719
419.4000000000052,47.509448063798615,-0.09773102567587706,-2.0891814247677605
420.60000000000525,47.62698861223605,-0.10640410262911171,-2.095070873292522
421.8000000000053,47.744162592978924,-0.11642739409341739,-2.0998571114610423
423.0000000000053,47.86194210293803,-0.12603082902331994,-2.104025014459887
424.2000000000053,47.978173619953026,-0.13382033451361514,-2.1081577336741204
425.4000000000053,48.09556764419337,-0.14182139855289194,-2.1109613266476055
426.60000000000537,48.21116558671391,-0.14719352049366383,-2.1142250604140918
427.80000000000535,48.3275074112902,-0.15355853693476607,-2.1186298879160583
429.00000000000534,48.44698202573212,-0.15852573414404764,-2.122240255561187
430.2000000000054,48.563799005393975,-0.16232631599792707,-2.124929246269298
431.40000000000543,48.68115527560315,-0.1664025348127523,-2.1275755827310574
432.6000000000054,48.79957956758447,-0.1688724584745837,-2.1302380516810997
433.8000000000054,48.91741229523532,-0.17087482637710188,-2.131659417328853
435.00000000000546,49.033783947284824,-0.1740730923888742,-2.13259420434896
436.2000000000055,49.150116079014126,-0.17377112037647738,-2.135321646069948
437.4000000000055,49.26772893538515,-0.1746568023537363,-2.136606327727144
438.6000000000055,49.38448831232578,-0.17539215886309117,-2.140308293424881
439.8000000000055,49.5027060705128,-0.1755071823681721,-2.141873998503196
441.00000000000557,49.61926699290542,-0.17624883688870058,-2.1431955334796955
442.20000000000556,49.7346832863164,-0.1754853780857938,-2.144445197515002
443.40000000000555,49.85447031117404,-0.17695847070232143,-2.1495556691939086
444.6000000000056,49.97244492614519,-0.17585536005091593,-2.149567231965032
445.80000000000564,50.088554989253865,-0.17499961164670552,-2.150878348860563
447.0000000000056,50.2053390768176,-0.17575436477559758,-2.1534988228486913
448.2000000000056,50.323599277032905,-0.1748939069778241,-2.1535232123507813
449.40000000000566,50.440370930443784,-0.17408575105400198,-2.15351031116841
450.6000000000057,50.55834460568921,-0.174789031378837,-2.152117335345025
451.8000000000057,50.67617727513699,-0.17502418729737054,-2.1568256590462855
453.0000000000057,50.79386091861569,-0.17558022084917735,-2.158332294624779
454.20000000000573,50.91118032984437,-0.1739409914128109,-2.158345496308984
455.4000000000058,51.0295930260648,-0.1728102140118144,-2.1596445833545537
456.60000000000576,51.14721076980261,-0.17438558703291934,-2.162246237029909
457.80000000000575,51.26358563710295,-0.17344966084810798,-2.1649269395234287
459.0000000000058,51.384327356589054,-0.174432285402754,-2.163624115243747
460.20000000000584,51.5002511247318,-0.17175476665110367,-2.1662423767186603
461.40000000000583,51.6168793293301,-0.17174548307624574,-2.168540664999261
462.6000000000058,51.73711026133651,-0.16962942870211128,-2.1713226186456884
463.80000000000587,51.854702879338554,-0.17012664647068262,-2.1729129822910602
465.0000000000059,51.97294945314906,-0.16846502113023382,-2.171525058819576
466.2000000000059,52.08946384097678,-0.16805883770413957,-2.1741658243701107
467.4000000000059,52.20738971480065,-0.16674179091348107,-2.1746564654671285
468.60000000000593,52.324050727453326,-0.1641642407773782,-2.1767816328854335
469.800000000006,52.44291449900737,-0.16203331193882822,-2.1781019134270334
471.00000000000597,52.56062562845781,-0.16113691890029144,-2.1794725012119867
472.20000000000596,52.67927583165775,-0.16057823019193676,-2.182056283861362
473.400000000006,52.79610721706044,-0.15814693441263988,-2.1833980774914545
474.60000000000605,52.913298206823804,-0.15673993225803187,-2.1846800642866437
475.80000000000604,53.03201024130726,-0.15569695890405696,-2.1861051958712103
477.000000000006,53.14850404414878,-0.15591109971493938,-2.187317037602683
478.20000000000607,53.26666228547278,-0.15460259610353325,-2.1886619884649265
479.4000000000061,53.38443569768518,-0.1526631461637652,-2.19002826363713
480.6000000000061,53.502718215073216,-0.15129626506617092,-2.19128957191771
481.8000000000061,53.620703832676284,-0.14913155550785667,-2.1920523807673327
483.00000000000614,53.736652919378315,-0.1490576778283661,-2.1955513705496754
484.2000000000062,53.85620486467354,-0.14772616452874088,-2.1955434022458045
485.4000000000062,53.97206344660003,-0.14573242839427764,-2.196871009905305
486.60000000000616,54.0909245064409,-0.14588732088503714,-2.198189783009453
487.8000000000062,54.210706361056815,-0.14468382319655373,-2.1995000245641116
489.00000000000625,54.32688941402061,-0.14524801736133724,-2.2020583586658975
490.20000000000624,54.44554376554568,-0.14317671237016624,-2.2025032010499137
491.40000000000623,54.56349590078206,-0.14060419039693445,-2.203789881452091
492.6000000000063,54.6824699577714,-0.1410441273146613,-2.204795300943376
493.8000000000063,54.79985833230393,-0.13787220504723102,-2.2067496836294294
495.0000000000063,54.91623183402304,-0.13757129185242264,-2.208058721198503
496.2000000000063,55.03549578837911,-0.13657806327805433,-2.209285259960766
497.40000000000634,55.15277867102505,-0.1349280815847208,-2.209389323080939
498.6000000000064,55.27222088008417,-0.13405697933323116,-2.211410100015989
499.8000000000064,55.38997783338068,-0.13188574027678554,-2.2133544014253044
501.00000000000637,55.508521371440864,-0.13266234977310126,-2.2159638213905106
502.2000000000064,55.62621457519805,-0.13200936081326423,-2.214680116994799
503.40000000000646,55.74444067860831,-0.13004013218825025,-2.2164613533586506
504.60000000000645,55.86362636041815,-0.13062660356771003,-2.2173148912802043
505.80000000000643,55.981496323620426,-0.1297031273048181,-2.219986017485766
507.0000000000065,56.09984520413948,-0.1305656879474794,-2.2199298783335655
508.2000000000065,56.218217327452365,-0.12827564300468736,-2.2212566620050977
509.4000000000065,56.337466447076245,-0.12814889498536683,-2.2238811116866164
510.6000000000065,56.45543376877396,-0.12706226897515846,-2.2252005791000107
511.80000000000655,56.57466495981605,-0.1277217607982302,-2.226520180467606
513.0000000000066,56.6927743827078,-0.12713018527035858,-2.2278284409281555
514.2000000000066,56.811633123536666,-0.12720038863328423,-2.229164982472156
515.4000000000066,56.92936400329114,-0.12731764194241652,-2.228994360804906
516.6000000000066,57.04820106330085,-0.12536649790165136,-2.2303583283332413
517.8000000000067,57.16707411554482,-0.12709750503032557,-2.2315665026007676
519.0000000000066,57.28517946371478,-0.12603306073408088,-2.235300181287018
520.2000000000066,57.40398154174424,-0.12626645413543053,-2.235629953215989
521.4000000000067,57.52255350904821,-0.12437378137679402,-2.2359513163509117
522.6000000000067,57.64169342308963,-0.12250188749074334,-2.237270105830839
523.8000000000068,57.760217740678016,-0.12326383953009819,-2.2379566000508575
525.0000000000067,57.87777396412732,-0.12088868494820681,-2.2395808795116325
526.2000000000068,57.99620174196,-0.12250563242461916,-2.242353303658774
527.4000000000068,58.114006642412164,-0.12164687417313641,-2.2449553260168837
528.6000000000067,58.23395336967647,-0.12184418115222978,-2.244450255942822
529.8000000000068,58.352719353795024,-0.12175519359556611,-2.2457865558447074
531.0000000000068,58.471850120985806,-0.12167646027361564,-2.2461121744598675
532.2000000000069,58.590260978646434,-0.12183558601450424,-2.2461550606053327
533.4000000000069,58.708698746568864,-0.1206819194752228,-2.247412120214288
534.6000000000068,58.828390820605755,-0.12090210740230523,-2.250079444196814
535.8000000000069,58.945325794126866,-0.12234292640725603,-2.2500556377854437
537.0000000000069,59.06665991450626,-0.12254231840781876,-2.252753313394196
538.2000000000069,59.18499479274568,-0.12327768023849957,-2.2540762963277983
539.4000000000069,59.303536717083134,-0.12479864433531704,-2.2554446356314943
540.600000000007,59.4233440330418,-0.12609954596886735,-2.255010593446484
541.800000000007,59.54020081143006,-0.1274107749688168,-2.257028770241767
543.000000000007,59.658563052280414,-0.127022776117015,-2.259343672670855
544.200000000007,59.778067441822756,-0.12777095518578027,-2.260650588274478
545.400000000007,59.897318881558114,-0.12667415772368792,-2.2616429252811354
546.6000000000071,60.01620608297362,-0.12628284502051135,-2.2633327506537224
547.800000000007,60.13635792318702,-0.12599343921132605,-2.263429127750272
549.000000000007,60.25516517608871,-0.12065666604641219,-2.2633997552925305
550.2000000000071,60.37326050592006,-0.11479467712813754,-2.266101904165641
551.4000000000071,60.49172237809234,-0.11389818367373439,-2.2686874959443855
552.6000000000072,60.60965561151439,-0.11120723310645543,-2.2674233149100718
553.8000000000071,60.727740605676765,-0.10905668377438313,-2.2673444442245385
555.0000000000072,60.847323291116275,-0.10790769231087836,-2.269910427717563
556.2000000000072,60.966013022200045,-0.10578737589446455,-2.269983930495642
557.4000000000071,61.084028463099244,-0.10663735455942178,-2.271309958261381
558.6000000000072,61.20313138820607,-0.10466982338814781,-2.2726097886976424
559.8000000000072,61.322627573481455,-0.10552699254613353,-2.2752605855132195
561.0000000000073,61.44024201063967,-0.10755990188934472,-2.274018331406818
562.2000000000073,61.55916901131589,-0.11020001781372801,-2.2752599303574454
563.4000000000073,61.678876935032676,-0.10897688064784208,-2.276624145293601
564.6000000000073,61.797619137989074,-0.11315160474890847,-2.2769001913768623
565.8000000000073,61.917388053587665,-0.11150769579670156,-2.2771954173141253
567.0000000000073,62.035781590530405,-0.11242931646395353,-2.2795346895767445
568.2000000000073,62.15399587241385,-0.11418172346634846,-2.279983327980392
569.4000000000074,62.27402955572522,-0.11598862859558177,-2.2808601573401353
570.6000000000074,62.39283392012464,-0.11739535819708982,-2.2808601714359655
571.8000000000075,62.51141788409673,-0.11837289871743326,-2.2821699484708757
573.0000000000074,62.63094936939678,-0.12029846097330715,-2.284809314560488
574.2000000000074,62.748089919420764,-0.12025056523228242,-2.2834803240079617
575.4000000000075,62.86936900621257,-0.12575135192851636,-2.283467829856196
576.6000000000074,62.987652904130535,-0.12876379829687562,-2.2821490229928663
577.8000000000075,63.10579689357434,-0.1337289458702062,-2.2835011030758636
579.0000000000075,63.225704320356726,-0.13696212814862893,-2.2861481683708567
580.2000000000075,63.34565361154176,-0.14179390151509502,-2.287209917901081
581.4000000000076,63.46462496341341,-0.1453683275131346,-2.2869960870300945
582.6000000000075,63.584054089458085,-0.14874313368068343,-2.2887573513105743
583.8000000000076,63.70301326485144,-0.15278877807550406,-2.2874501203162887
585.0000000000076,63.82250224070607,-0.15683134922322298,-2.2877801343917272
586.2000000000075,63.941702078451264,-0.16066395913162154,-2.2890536868638556
587.4000000000076,64.06034085504754,-0.16477884534253315,-2.290400292428606
588.6000000000076,64.18036433244549,-0.16759620706131584,-2.291390035801723
589.8000000000077,64.30074423045636,-0.1700922552493478,-2.290420921950206
591.0000000000077,64.41907587817626,-0.17279386376275707,-2.293037624651147
592.2000000000077,64.53907514904338,-0.1761271485111195,-2.293039915666859
593.4000000000077,64.65750507439003,-0.17954658908483911,-2.2929810091935856
594.6000000000078,64.77730496370218,-0.1833069307542849,-2.293061777894007
595.8000000000077,64.89689637473539,-0.1863781335340214,-2.2930368219972754
597.0000000000077,65.01673684705236,-0.1898099009613568,-2.293040428543911
598.2000000000078,65.13549277868816,-0.19346199608327647,-2.295370976702225
599.4000000000078,65.25587312252398,-0.19566857113036673,-2.295018197968925
600.6000000000079,65.3744775542756,-0.19594286985313009,-2.2956802170715522
601.8000000000078,65.49478848315489,-0.19923248099056118,-2.2956802064551836
603.0000000000078,65.6130319706026,-0.20153052239169733,-2.2969973520075166
604.2000000000079,65.73359243470443,-0.2030154640503641,-2.295667983733355
605.4000000000078,65.85360673688304,-0.20595744082880854,-2.2982861210754266
606.6000000000079,65.97271962713931,-0.2083380584632085,-2.2992649398095724
607.8000000000079,66.09239300276657,-0.21080220889867435,-2.2987768944173403
609.000000000008,66.21150675913344,-0.21114149667726687,-2.2982858778623254
610.200000000008,66.3313810292282,-0.21102178038200597,-2.299569432428367
611.4000000000079,66.45070675693536,-0.2130673516290692,-2.2992999480119574
612.600000000008,66.57103385783105,-0.2136285784642346,-2.2993097958328717
613.800000000008,66.68991504184632,-0.2162023037610289,-2.2992990057575815
615.000000000008,66.80978598545587,-0.21485667480624765,-2.299620266400301
616.200000000008,66.92907599010378,-0.21393603406571546,-2.301929599989492
617.400000000008,67.04815641330377,-0.2148019953571665,-2.3002894480452003
618.6000000000081,67.16840825597649,-0.2131511254011286,-2.300290312877246
619.8000000000081,67.28744007088531,-0.2132453006193315,-2.3016098514862495
621.0000000000081,67.40578499561084,-0.2094569387767969,-2.3016317269852924
622.2000000000081,67.52657827866578,-0.209246292671171,-2.3029301565818274
623.4000000000082,67.64531098596127,-0.20699458928199976,-2.3029301285612336
624.6000000000081,67.76376720864725,-0.20516681218704474,-2.303589938374379
625.8000000000081,67.88390331926108,-0.2032123230928352,-2.3029150829668037
627.0000000000082,68.004052161445,-0.20143212659015655,-2.3042399162371554
628.2000000000082,68.12269455867464,-0.19841722447638374,-2.305617136267781
629.4000000000083,68.24246773194079,-0.1972007332616874,-2.3043100108232304
630.6000000000082,68.35917221033725,-0.19265989525668292,-2.303249924016963
631.8000000000083,68.4788742010085,-0.19294324846474428,-2.3045701802677097
633.0000000000083,68.60137826127621,-0.19115428986581395,-2.304900075664435
634.2000000000082,68.72076653585836,-0.18987203696483018,-2.304900008908906
635.4000000000083,68.84056213865368,-0.1882513026902328,-2.3062200297298032
636.6000000000083,68.96019736379777,-0.18870315764799409,-2.3062073285504923
637.8000000000084,69.07927497684544,-0.19042639639450726,-2.3075303808458187
639.0000000000084,69.19853500744708,-0.19048494373313424,-2.3068775589386803
640.2000000000083,69.31777681988922,-0.1891314667550162,-2.3063283262115815
641.4000000000084,69.43768024790572,-0.18932271555837799,-2.306550325911809
642.6000000000084,69.55753749828213,-0.18758521490575414,-2.307559923527343
643.8000000000084,69.67813504313096,-0.18997129487508727,-2.3052299542110197
645.0000000000084,69.79777819481033,-0.18710671082447072,-2.3052271162267663
646.2000000000085,69.91797714914811,-0.18559995364519694,-2.306541405189557
647.4000000000085,70.03554795949624,-0.18590363133257676,-2.3065398540007456
648.6000000000085,70.1566712258644,-0.18751876053230795,-2.3065398530247676
649.8000000000085,70.27715364775572,-0.18973182841793676,-2.307853161699903
651.0000000000085,70.39583498152297,-0.18868876848264915,-2.307860165998611
652.2000000000086,70.51748515630689,-0.1888209322816938,-2.3078602011408424
653.4000000000085,70.63707156100506,-0.19017470166759065,-2.3082015651498358
654.6000000000085,70.7571752475255,-0.19073796623748676,-2.3091800722217215
655.8000000000086,70.87630543094399,-0.19098571341335285,-2.3091673759870575
657.0000000000086,70.997028668355,-0.18967056454006717,-2.309179219225393
658.2000000000087,71.1162754606603,-0.1897451133895895,-2.3098398197328964
659.4000000000086,71.23625520524989,-0.1920449335666914,-2.3085202240865432
660.6000000000087,71.35502036032076,-0.19293388002735096,-2.3096271380922357
661.8000000000087,71.47744071167995,-0.19213327655929444,-2.309845497726264
663.0000000000086,71.59777278370281,-0.1936002255242869,-2.3090752795956364
664.2000000000087,71.71702310747128,-0.19457314329637412,-2.310804612355974
665.4000000000087,71.83438068097122,-0.19452206731396351,-2.309510045537879
666.6000000000088,71.95547626460448,-0.19443026847647213,-2.311638289949311
667.8000000000088,72.07586163530229,-0.1962024016016655,-2.311822603834301
669.0000000000088,72.19569468118806,-0.19593754978650024,-2.3117796693118913
670.2000000000088,72.3153118114547,-0.19706193833757613,-2.3127969733749514
671.4000000000088,72.43678682991869,-0.19781663830528137,-2.3121401143586144
672.6000000000088,72.55617630119343,-0.19894942869520743,-2.311468122864417
673.8000000000088,72.67761948402818,-0.1980678436823901,-2.3124521823723874
675.0000000000089,72.79720023629959,-0.197859245941135,-2.311162035770382
676.2000000000089,72.91679343269098,-0.19780806099028633,-2.3116171274111466
677.400000000009,73.0375706308867,-0.1997815538227815,-2.312470098122313
678.6000000000089,73.15768249029408,-0.2008378494314458,-2.311426711735189
679.8000000000089,73.27760423532754,-0.2008913242549635,-2.3111257418637443
681.000000000009,73.39775886562781,-0.20455357304390195,-2.3118200442542918
682.2000000000089,73.51798859868546,-0.20567763538841102,-2.311820004002257
683.400000000009,73.63662875024905,-0.2050252546424532,-2.3118448913918765
684.600000000009,73.75710812258268,-0.20497382611806186,-2.313130165908001
685.800000000009,73.87653216693245,-0.20032356267421073,-2.314234501167804
687.0000000000091,73.99678159144699,-0.19833196206824466,-2.3144542515042485
688.200000000009,74.11807350661479,-0.19867667148276097,-2.313103102005714
689.4000000000091,74.23675130803497,-0.19910004163560444,-2.312470086137546
690.6000000000091,74.35665637116016,-0.19710158661870542,-2.312470071951605
691.800000000009,74.47604926329974,-0.19670119589954405,-2.311949975201931
693.0000000000091,74.59583481659455,-0.19689423878934048,-2.313130195287072
694.2000000000091,74.71706338381516,-0.19897998269454265,-2.3133863154075507
695.4000000000092,74.83687315815109,-0.19813192831351353,-2.313459977974481
696.6000000000092,74.95687464757401,-0.19764302125569916,-2.314610554593263
697.8000000000092,75.07719629489628,-0.20064819839673773,-2.3134698849563664
699.0000000000092,75.19822831543365,-0.20211341551021086,-2.31343033870424
700.2000000000093,75.31736778249461,-0.2015609231435862,-2.3157477206705392
701.4000000000092,75.43790511398913,-0.20242169935681006,-2.313471113851247
702.6000000000092,75.55808644961259,-0.20040390402885805,-2.3147829256846384
703.8000000000093,75.67817789542563,-0.20084075748756752,-2.3127856585834237
705.0000000000093,75.79907886230738,-0.2003627592795898,-2.312799967990734
706.2000000000094,75.9201998512537,-0.20238296862322241,-2.3141294362047686
707.4000000000093,76.03988268092154,-0.19915189641567585,-2.315104660031215
708.6000000000093,76.159868719579,-0.1998515017260335,-2.3151101083286116
709.8000000000094,76.28011496149492,-0.19838769313544688,-2.3141166204522396
711.0000000000093,76.40038252639062,-0.19327627712242254,-2.314431267860548
712.2000000000094,76.52155031856844,-0.19397958857121345,-2.314113383903786
713.4000000000094,76.6413061656617,-0.19566001317524004,-2.314138494616059
714.6000000000095,76.76158734661882,-0.19609875968511845,-2.3145477915565973
715.8000000000095,76.8817963796476,-0.19482233018638748,-2.314120092039826
717.0000000000094,77.00057952784239,-0.1930810539838709,-2.3141458959503756
718.2000000000095,77.12195651089735,-0.19749525018888467,-2.3147813253225302
719.4000000000095,77.24303606627538,-0.19710536143119156,-2.314978815812425
720.6000000000095,77.36339706087364,-0.1984379489698493,-2.319600825895237
721.8000000000095,77.48408116006527,-0.19940618141887093,-2.3163762076756367
723.0000000000095,77.60363221161714,-0.20025480352874447,-2.3152192710756627
724.2000000000096,77.72382536317741,-0.20231506095347354,-2.3152201326921045
725.4000000000096,77.84455709248886,-0.20668054877714098,-2.3142298500545144
726.6000000000096,77.96426822837195,-0.20941925663277647,-2.315879247290718
727.8000000000096,78.08521178846838,-0.2109662366055892,-2.3168702521503852
729.0000000000097,78.20475748968616,-0.20995164450642503,-2.316870038069535
730.2000000000096,78.32607534167995,-0.20952329921108473,-2.3168699720002643
731.4000000000096,78.4467050850378,-0.21030483321398696,-2.316871829830159
732.6000000000097,78.56689953112226,-0.20949533930026776,-2.3164992212331934
733.8000000000097,78.68706798332391,-0.2091420680866128,-2.31686011370348
735.0000000000098,78.80717180632229,-0.20911071080404803,-2.316860134267002
736.2000000000097,78.92666813105484,-0.21026561236463928,-2.3124226491025297
737.4000000000098,79.04741160739893,-0.212885142471459,-2.3155500591748943
738.6000000000098,79.16926957822123,-0.21442408291545395,-2.315903163892058
739.8000000000097,79.28917104524379,-0.22070016885976754,-2.315880039904472
741.0000000000098,79.40907068429773,-0.21938481124538306,-2.3171999465155246
742.2000000000098,79.53029603242132,-0.22043857102843434,-2.317199910932005
743.4000000000099,79.65089280746022,-0.22519534240828037,-2.316206839876945
744.6000000000099,79.77112899255643,-0.22853045655805046,-2.317205461616968
745.8000000000098,79.89226898561076,-0.23061122768290807,-2.317144095735178
747.0000000000099,80.01152002177308,-0.2317110413145058,-2.3177178387881834
748.2000000000099,80.13249882012514,-0.23667553055547486,-2.3175193784252692
749.4000000000099,80.25362537915505,-0.23565291834241744,-2.317190016801768
750.6000000000099,80.37416105926135,-0.2403996300377724,-2.3172042869957257
751.80000000001,80.49492339133195,-0.2402866392174368,-2.31751983649707
753.00000000001,80.61528880144174,-0.2398182905779396,-2.3175199199999907
754.20000000001,80.73655610457762,-0.2410983984475409,-2.3175199200000005
755.40000000001,80.85523126025845,-0.24414091600699483,-2.3175199199999934
756.60000000001,80.97746131050876,-0.24510813508998858,-2.3175198858937147
757.8000000000101,81.09865144989288,-0.2454150715297873,-2.318509837620649
759.00000000001,81.21815384892577,-0.24322893952302005,-2.3158767621710648
760.20000000001,81.33948809805341,-0.24771000656507075,-2.3171998271604615
761.4000000000101,81.4596853251089,-0.24846866009006652,-2.315880439082049
762.6000000000101,81.5796687993891,-0.24694768624989757,-2.317568214289401
763.8000000000102,81.70021607732694,-0.25149817350549414,-2.3175301669218342
765.0000000000101,81.81978655947131,-0.253491639748377,-2.316207410973197
766.2000000000102,81.93983005302822,-0.25275247715987037,-2.3168601692160706
767.4000000000102,82.05937692295929,-0.2539593448971718,-2.317520171865997
768.6000000000101,82.17887442437652,-0.2541701348314865,-2.3161881323633446
769.8000000000102,82.29959405792036,-0.2555639266136287,-2.3168747344937732
771.0000000000102,82.41947072134792,-0.2568651518410335,-2.3169878401204778
772.2000000000103,82.54082108996549,-0.25842459788933875,-2.3168698000089547
773.4000000000103,82.66089230086229,-0.2620320652198695,-2.3168683888524013
774.6000000000103,82.78019048177383,-0.2647488615935815,-2.317203232338355
775.8000000000103,82.90094852049734,-0.2684671229341126,-2.3172001120001773
777.0000000000103,83.021926338794,-0.27001071105473323,-2.3172001119999965
778.2000000000103,83.14108098843164,-0.2705931612548668,-2.317200092464817
779.4000000000103,83.26121045442932,-0.27010451232017724,-2.3182049979939614
780.6000000000104,83.38221484368495,-0.2738272262589352,-2.3180430200032625
781.8000000000104,83.50322666481041,-0.27613347839496244,-2.319200881121033
783.0000000000105,83.62478301634962,-0.27972227803540695,-2.3181718348161136
784.2000000000104,83.74530490390082,-0.2820266362896132,-2.3181834370330305
785.4000000000104,83.86525366402364,-0.2861589051074919,-2.3168600590094623
786.6000000000105,83.98626708682067,-0.28967851187702937,-2.318174140087004
787.8000000000104,84.10653215805115,-0.29368104611956813,-2.318180086574729
789.0000000000105,84.22727919835587,-0.29642093162542793,-2.3195388408087534
790.2000000000105,84.34730577811364,-0.29933636137049324,-2.3181715933324294
791.4000000000106,84.46832932679648,-0.303894982459078,-2.3181797845176515
792.6000000000106,84.58938065056921,-0.3097918152328178,-2.3178467560249123
793.8000000000105,84.70926979232279,-0.3147035465304365,-2.31917014800279
795.0000000000106,84.830515117451,-0.3177500904711371,-2.3192042623553526
796.0000000000106,84.9307267349707,-0.3258789548570483,-2.3188500562939103