File: 01_Data/Nylon_Carpet_High_Pile/STA/N2/10K_min/Nylon_Carpet_High_Pile_STA_N2_10KData_220307_R1.csv
##Temp./Â°C,Time/min,DSC/(mW/mg),Mass loss/mg
50.0,10.575065847445524,-1.0886677729255747,-0.025404034899328742
51.20000000000002,10.987925395606132,-0.9616262692595204,-0.017947689073497308
52.400000000000034,11.228362634404037,-0.8841436783280872,-0.014245878823519575
53.60000000000005,11.41947322023394,-0.8274118906888714,-0.013052540301620397
54.80000000000007,11.589600388859933,-0.783275461951749,-0.015298248626354649
56.000000000000085,11.748829824472638,-0.7473198480547756,-0.017558507419019875
57.2000000000001,11.898552415131732,-0.7218550092520202,-0.013478470380809071
58.40000000000012,12.041315172262832,-0.6968462097474291,-0.010727982884338516
59.600000000000136,12.183035092108797,-0.6788558917581121,-0.008656670709298098
60.80000000000015,12.318949427036735,-0.6629224768090836,-0.011321854046967061
62.00000000000017,12.454669686946309,-0.6483727623683994,-0.011025725631410133
63.20000000000019,12.588174906038887,-0.6344291302235993,-0.014444186649724244
64.4000000000002,12.71986229213918,-0.6199232239322664,-0.009813815045935037
65.60000000000022,12.85209371868104,-0.6079821250521189,-0.009663417569581334
66.80000000000024,12.981782741194479,-0.5979427995780324,-0.010389014612710135
68.00000000000026,13.111344591843483,-0.5871701111738364,-0.008208444281166294
69.20000000000027,13.240624464633651,-0.5752952520178115,-0.012145865274700185
70.40000000000029,13.369598159492625,-0.564527249895748,-0.011606463864484162
71.6000000000003,13.497725304134326,-0.5553603281377263,-0.010521565398081911
72.80000000000032,13.624154324059418,-0.5465679708747954,-0.01197985535137569
74.00000000000034,13.749622941084635,-0.5360889666096276,-0.013168340278136625
75.20000000000036,13.876520924909505,-0.5275419950912703,-0.009321533597313802
76.40000000000038,14.003563046393754,-0.5191140906994409,-0.011840577668837504
77.60000000000039,14.127709943601829,-0.5092335480781436,-0.016715982368724625
78.80000000000041,14.252969243504449,-0.49908088542599177,-0.018107206542467225
80.00000000000043,14.37906984464901,-0.490796287977096,-0.017991019041460277
81.20000000000044,14.49917000000005,-0.4823299999999987,-0.014260163051125652
82.40000000000046,14.621848707920135,-0.4740839957681895,-0.015577185796156634
83.60000000000048,14.748329390962576,-0.4663701929535,-0.013874486860999014
84.8000000000005,14.871180925062463,-0.45897080190851053,-0.014149961192029714
86.00000000000051,14.993885855748333,-0.4510886033263929,-0.015434824681262782
87.20000000000053,15.114898148728116,-0.4427173042761819,-0.01793009154531422
88.40000000000055,15.23590668642489,-0.4346103582902044,-0.019381261818470108
89.60000000000056,15.356676715727586,-0.428149862186063,-0.016800138524285302
90.80000000000058,15.476836076194626,-0.4195475774932043,-0.016709630593925162
92.0000000000006,15.59685726460624,-0.41294831823782957,-0.01546004552730551
93.20000000000061,15.717017751500656,-0.4087526185283003,-0.016779893543383828
94.40000000000063,15.834448765631967,-0.40060753284301404,-0.016822064444760088
95.60000000000065,15.955131116621246,-0.3941922638856317,-0.019440662046884327
96.80000000000067,16.073956135638735,-0.3893426535217195,-0.019739662062677965
98.00000000000068,16.192136617316205,-0.383677233429699,-0.019745215968483443
99.2000000000007,16.31095736929122,-0.3779530545221325,-0.017000255657674934
100.40000000000072,16.429834297770075,-0.3722748402016832,-0.01962997169207359
101.60000000000073,16.547737363567506,-0.36910970012676675,-0.023688550232624728
102.80000000000075,16.665433619387024,-0.3651599343449053,-0.02336345464765799
104.00000000000077,16.784419749870125,-0.3601045159827702,-0.023690099752566418
105.20000000000078,16.90244027566987,-0.3563772370337027,-0.02399892539226567
106.4000000000008,17.020839041697588,-0.3515239588830978,-0.01799585938190784
107.60000000000082,17.137824248370393,-0.3494318047914963,-0.017108389545358982
108.80000000000084,17.258215600120376,-0.34319975700027777,-0.018545806568875278
110.00000000000085,17.373913618124313,-0.33874625881973414,-0.022516974305196946
111.20000000000087,17.49233207932518,-0.3324004947619748,-0.02247989688741736
112.40000000000089,17.60981997714272,-0.3269054965249175,-0.020303938505144004
113.6000000000009,17.728290282293692,-0.3230999806738938,-0.018331390561447947
114.80000000000092,17.844937803641017,-0.31839694644032834,-0.01819639079444446
116.00000000000094,17.96263045771224,-0.3124600835190996,-0.01969026708724453
117.20000000000095,18.078895647378342,-0.3069308315661014,-0.021269897250487446
118.40000000000097,18.1972854612699,-0.3016281107675873,-0.021273527622065913
119.60000000000099,18.315612115454158,-0.295275838775684,-0.021579654460455622
120.800000000001,18.431282230347154,-0.2910506128903229,-0.019984102658423097
122.00000000000102,18.550010657758406,-0.28450735351274864,-0.019959962607403625
123.20000000000104,18.665438124170525,-0.2810658307564986,-0.019850486145673862
124.40000000000106,18.782445363836867,-0.2762245163134859,-0.02051316804147696
125.60000000000107,18.899963192713024,-0.27109352936764103,-0.02050978140713866
126.80000000000109,19.016864727311578,-0.26568139667404006,-0.021830149070637184
128.0000000000011,19.133338602736718,-0.259238289010963,-0.023140152142917536
129.20000000000113,19.250255022021165,-0.2544990186938222,-0.024560170616253707
130.40000000000114,19.365545567208148,-0.25005951015278083,-0.023349775082392554
131.60000000000116,19.482600481740807,-0.2427090278219325,-0.024560079088873366
132.80000000000118,19.59775692619286,-0.23887879244047122,-0.02300936159033906
134.0000000000012,19.715019463079912,-0.23362637493508778,-0.024352804713280385
135.2000000000012,19.831518710588476,-0.23113240245874692,-0.022476486002106277
136.40000000000123,19.947385560742582,-0.22450531723321082,-0.022242587207935927
137.60000000000124,20.063241407142907,-0.217886769932781,-0.02541644042095559
138.80000000000126,20.1793700666856,-0.2135810051874978,-0.02611665252965878
140.00000000000128,20.291100119820403,-0.20946525233702504,-0.023490034798268056
141.2000000000013,20.411320912614865,-0.20413966917221596,-0.023470594981278126
142.4000000000013,20.526609154037807,-0.19726726242220108,-0.026687157568296094
143.60000000000133,20.645322191179904,-0.1901190482343757,-0.02883081005071464
144.80000000000135,20.755022775163418,-0.186270676728507,-0.028848847355273044
146.00000000000136,20.874805822351277,-0.1794943830277749,-0.028839224238381256
147.20000000000138,20.991635448695398,-0.17279133013624856,-0.02824620371960407
148.4000000000014,21.10802249013514,-0.1660759094685859,-0.02598598858488721
149.60000000000142,21.223726707358185,-0.15947737034188697,-0.024237962602290608
150.80000000000143,21.339076455847188,-0.15207857931172689,-0.026542523961430753
152.00000000000145,21.455388274843745,-0.1426430418854186,-0.028191750441514785
153.20000000000147,21.570458040439263,-0.13334629224252326,-0.028264690385597646
154.40000000000148,21.686223257278087,-0.12344172201142181,-0.02687248755399274
155.6000000000015,21.801319857495507,-0.11312495826929224,-0.025531369870678056
156.80000000000152,21.91677121736161,-0.09812999424982273,-0.02813561620332905
158.00000000000153,22.031778597105284,-0.08427914871547613,-0.030160762849722467
159.20000000000155,22.147998141758645,-0.07023549688718331,-0.026260863975554827
160.40000000000157,22.262643013488884,-0.05634916868103337,-0.024149523241182358
161.6000000000016,22.377894495271054,-0.04020419279031352,-0.028070800853929434
162.8000000000016,22.49387435643527,-0.025964561779254665,-0.026331649094542442
164.00000000000162,22.608288501168218,-0.013412447082610163,-0.03222684672605336
165.20000000000164,22.723518549934827,-0.00843150413107382,-0.03192432211041041
166.40000000000165,22.839692387206412,-0.012085866932521144,-0.029293120755454538
167.60000000000167,22.955527407699158,-0.024287236606408132,-0.02928248117963861
168.8000000000017,23.069460615574275,-0.038122215749465276,-0.02680531921833129
170.0000000000017,23.1863127353075,-0.05253642502815337,-0.03188842545614179
171.20000000000172,23.30041616071561,-0.06178142161403271,-0.027532561877499973
172.40000000000174,23.415160730584223,-0.0654014535407598,-0.026540063610026365
173.60000000000176,23.531109095180412,-0.06393655155276363,-0.02819586296190213
174.80000000000177,23.64652291601926,-0.06302843774016319,-0.032279952339902884
176.0000000000018,23.760261191096625,-0.05841186973348762,-0.03593049780849267
177.2000000000018,23.876821520931937,-0.05417347282715133,-0.03619004806096804
178.40000000000182,23.99201972726439,-0.048889195836911876,-0.03434790356488193
179.60000000000184,24.106792454189787,-0.04421022099251189,-0.030310320157825643
180.80000000000186,24.22122652546777,-0.038544756400286026,-0.027624963636554867
182.00000000000188,24.336840416323007,-0.03297411731446419,-0.02975676975254693
183.2000000000019,24.451327802731743,-0.028107175904980096,-0.031615588924800875
184.4000000000019,24.564182716173264,-0.023251592825396624,-0.031589730458765786
185.60000000000193,24.68104131073263,-0.01552646666993707,-0.031589909323359144
186.80000000000194,24.79501764842935,-0.0110015100039174,-0.03159553150647376
188.00000000000196,24.908971988875642,-0.005461958484906774,-0.03160230873402359
189.20000000000198,25.024319557524677,-0.0013750223124186396,-0.030062168069965978
190.400000000002,25.13906483794486,0.0060139065096624375,-0.034218565592159855
191.600000000002,25.252290073778088,0.01151828196777249,-0.034206157956510275
192.80000000000203,25.36937641721017,0.015420296609784619,-0.03423230996656823
194.00000000000205,25.483869278383573,0.021109081063272434,-0.03158662507326149
195.20000000000206,25.598138016445088,0.025077061141455814,-0.030199775792753236
196.40000000000208,25.712741684959934,0.03206181345612505,-0.02884409011587774
197.6000000000021,25.82751989429549,0.03848632807270061,-0.03114638540496628
198.80000000000211,25.94218822237543,0.04458892900828363,-0.03366995964774233
200.00000000000213,26.057351970776395,0.049375313044116007,-0.03367535514567166
201.20000000000215,26.171777477642607,0.057566892005944933,-0.03716558662495473
202.40000000000217,26.286364871667544,0.06453550783669115,-0.037180860757339396
203.60000000000218,26.401735867706247,0.07392079453651364,-0.035512617818795
204.8000000000022,26.516567622509474,0.08037859446210224,-0.030268206500323025
206.00000000000222,26.631119531015244,0.08929857446786581,-0.03207499522527879
207.20000000000223,26.746027222890792,0.100075656581328,-0.0326343221726102
208.40000000000225,26.861399505954093,0.10877861539628512,-0.03454735511183582
209.60000000000227,26.975576351155347,0.12233964009954318,-0.03320572710556302
210.80000000000229,27.091915234677305,0.13753404417982765,-0.030491384560478174
212.0000000000023,27.205241181587276,0.15737319042319686,-0.028224001650898778
213.20000000000232,27.320530071371877,0.19034842117168368,-0.027987780848028443
214.40000000000234,27.435805983826693,0.24113070796150896,-0.03701921047612622
215.60000000000235,27.550368641730127,0.32457636661606537,-0.03870157345180214
216.80000000000237,27.666549148752473,0.45055479833850515,-0.036298513987696346
218.0000000000024,27.781291719429742,0.5765586578800898,-0.03340838587032824
219.2000000000024,27.897241376072266,0.6791647671741687,-0.03337798902302325
220.40000000000242,28.01288868679708,0.7325797861536818,-0.03068732983473943
221.60000000000244,28.12790895822422,0.7239224569226802,-0.03477075062316004
222.80000000000246,28.242528300750237,0.6309713015487158,-0.03476384055356352
224.00000000000247,28.358611251458512,0.46562521445707683,-0.032485061563106044
225.2000000000025,28.472741066343907,0.3223751097614836,-0.03477582582104244
226.4000000000025,28.587040262946083,0.23380017236167241,-0.035023500410169106
227.60000000000252,28.70061477666622,0.18857530146411366,-0.03784477085223603
228.80000000000254,28.815165371017688,0.16560595363969216,-0.03664990449968197
230.00000000000256,28.928356576340196,0.15609960960795174,-0.035077478757195024
231.20000000000258,29.042727378372977,0.1504625776785243,-0.038086517462954994
232.4000000000026,29.156270972873138,0.15012497000898373,-0.038047791209582904
233.6000000000026,29.267838759995776,0.15020604770862597,-0.0368066795097306
234.80000000000263,29.38586533498907,0.1516781603652581,-0.04181254967137704
236.00000000000264,29.500094979731262,0.15474935620070948,-0.04315538320775403
237.20000000000266,29.613801269016164,0.15923989742769398,-0.04286926538203595
238.40000000000268,29.72806853832219,0.16164506900829828,-0.040485916643246966
239.6000000000027,29.84308989278441,0.16498933594852602,-0.04014574440451213
240.8000000000027,29.95680732613159,0.16705677334177899,-0.040560965649205194
242.00000000000273,30.071736094441885,0.1695208528134524,-0.03850067178694605
243.20000000000275,30.18639070720296,0.17394040034463862,-0.0430893093533431
244.40000000000276,30.300746219571487,0.17911553542728428,-0.04736957112809037
245.60000000000278,30.414939405692092,0.17913814738811926,-0.04384676270666166
246.8000000000028,30.52917000000028,0.18166000000001847,-0.0428434470588277
248.0000000000028,30.64457278925335,0.1854457019041267,-0.041350040421374246
249.20000000000283,30.757767798888207,0.19011616132542578,-0.04320341563502428
250.40000000000285,30.87354879994253,0.1918803567708921,-0.042267788693217234
251.60000000000286,30.987678839195425,0.19649557542670198,-0.04415831120716085
252.80000000000288,31.102379587000417,0.1980462794277217,-0.0428833931405066
254.0000000000029,31.21632111880542,0.20218984291688483,-0.04288927850176716
255.20000000000292,31.331709929788943,0.20349171381378398,-0.040029438798782735
256.40000000000293,31.446126674431095,0.2046629428313312,-0.04005028648390674
257.600000000003,31.56088419167217,0.21042244643905642,-0.047005062404767095
258.80000000000297,31.675491317562187,0.2131964957266099,-0.04550164004440305
260.00000000000296,31.78917000000033,0.21560000000000606,-0.04550644396956649
261.200000000003,31.904484145646826,0.21813317019033818,-0.04430950864167116
262.40000000000305,32.020032070210405,0.22118144990762217,-0.04420011053771855
263.60000000000304,32.133868554641694,0.22461980935464582,-0.04682609840595209
264.800000000003,32.24889843985074,0.22691595025102013,-0.0455195450012047
266.00000000000307,32.36381770990547,0.2300026367041374,-0.04575754940811194
267.2000000000031,32.47881157660459,0.23184429174908958,-0.04814743079311423
268.4000000000031,32.594362965212504,0.23536800167162314,-0.049480498309867116
269.6000000000031,32.70864677688661,0.23584485018888002,-0.04698543378050335
270.80000000000314,32.823828403003645,0.2390595740878847,-0.04793027990006227
272.0000000000032,32.938188379431395,0.24194320540949527,-0.04825606714512709
273.2000000000032,33.053473453201335,0.24489937669166797,-0.049580001916410765
274.40000000000316,33.16833049169845,0.24885427164469578,-0.051549843708658116
275.6000000000032,33.283925401888354,0.25138253711455005,-0.05155018005038681
276.80000000000325,33.39815383208842,0.25531720525047996,-0.05236759195058749
278.00000000000324,33.51342994482176,0.25605449571308303,-0.051882340798817594
279.20000000000323,33.62769025271383,0.25741438533326594,-0.05056978263629697
280.4000000000033,33.74309113116682,0.26027382155775075,-0.056037961644586964
281.6000000000033,33.85751108414183,0.26516159590844113,-0.0533935925060689
282.8000000000033,33.973020497589154,0.26612701146994144,-0.052032262213749014
284.0000000000033,34.088240978205256,0.2692607096767428,-0.052100701425898954
285.20000000000334,34.20216534751857,0.27288598239417133,-0.05103680583689085
286.4000000000034,34.31770888980801,0.27559687054711735,-0.054749569708667956
287.6000000000034,34.43289655877303,0.27815545817818715,-0.056050971607986444
288.80000000000337,34.547983987534934,0.2807741800457201,-0.05736954819269968
290.0000000000034,34.6631992740014,0.2845977889914533,-0.055392465858327355
291.20000000000346,34.77792086841477,0.2893063264562207,-0.057215030641198705
292.40000000000344,34.89338470609826,0.29315269142308314,-0.0587506146805743
293.60000000000343,35.007718758797154,0.29625207825782596,-0.06017878553795253
294.8000000000035,35.12252544272165,0.2993864471100552,-0.06161706136346812
296.0000000000035,35.23781002812041,0.3041599460710558,-0.06154296517040425
297.2000000000035,35.35315898810969,0.30629349431210523,-0.059226350332739486
298.4000000000035,35.46804570909288,0.3116887935774554,-0.0602111860788197
299.60000000000355,35.584245000058424,0.315603549973914,-0.06287651269394967
300.8000000000036,35.69907260913218,0.32000365244271,-0.06559006145904256
302.0000000000036,35.814287170592934,0.3244027827253526,-0.06460320773910011
303.20000000000357,35.92997501868945,0.329194618270096,-0.064279997430857
304.4000000000036,36.04576025529899,0.33472789877880715,-0.06423320872995086
305.60000000000366,36.160764089245795,0.3395928511607912,-0.06689539827524049
306.80000000000365,36.27603326069002,0.3440322096933126,-0.06939413722883003
308.00000000000364,36.38927131543215,0.3472313312663396,-0.07119850396157812
309.2000000000037,36.50805133281342,0.35110107142885494,-0.07357654766302568
310.40000000000373,36.62343245824182,0.35598364741475014,-0.07612595350301765
311.6000000000037,36.73740500418206,0.3608378366794672,-0.07521061825795616
312.8000000000037,36.85454655609759,0.3650630684400917,-0.07295247037945085
314.00000000000375,36.96962434184984,0.37142458587418314,-0.07780665957497801
315.2000000000038,37.08531545860643,0.376436646240509,-0.08392902928939527
316.4000000000038,37.201501161662165,0.3832871265310874,-0.08495776417346868
317.6000000000038,37.31687222694155,0.39146978166172053,-0.08571240362374244
318.8000000000038,37.43337223467629,0.3969286794938436,-0.0900722779880474
320.00000000000387,37.54832995658295,0.40334554642321574,-0.09017498092459153
321.20000000000385,37.66326394044715,0.4113584826857393,-0.095318966906484
322.40000000000384,37.779354104710336,0.41846735752825087,-0.09829694206085904
323.6000000000039,37.89506858524033,0.42599306123651975,-0.10352577293728071
324.80000000000393,38.0092767391265,0.435536511278374,-0.10464994446563525
326.0000000000039,38.12583846438124,0.44350290015216426,-0.11243709981106198
327.2000000000039,38.241412594857174,0.4519021654746339,-0.11727140432209948
328.40000000000396,38.35764369197844,0.4624758558359913,-0.12128724196251905
329.600000000004,38.47329336045652,0.47008816627835776,-0.1250533055037355
330.800000000004,38.58853565636415,0.47965108552672797,-0.1256402249425541
332.000000000004,38.704177272244436,0.48815080870059596,-0.1349411340804152
333.200000000004,38.820009813162,0.5002667595269247,-0.14350936744269394
334.40000000000407,38.93551882669611,0.5099112916130786,-0.14972142301367386
335.60000000000406,39.05201452378966,0.5211422287738161,-0.15480156700992653
336.80000000000405,39.168562473531665,0.5322925561256946,-0.16468596154800386
338.0000000000041,39.28395927424061,0.5442801790866026,-0.17122569551644373
339.20000000000414,39.400230957638676,0.5551262442847573,-0.17575182600434314
340.4000000000041,39.5174178570042,0.5661273098656614,-0.18583162615356175
341.6000000000041,39.63272460891616,0.5792235106033548,-0.19691249673423927
342.80000000000416,39.748256758182755,0.593545349576388,-0.20513999975676045
344.0000000000042,39.86607998868915,0.6080919332531172,-0.2216160118983801
345.2000000000042,39.983205129147244,0.6233180922853204,-0.22796640537971768
346.4000000000042,40.099654136161256,0.6347679438850448,-0.2375748898170542
347.60000000000423,40.21448510465371,0.651162929702827,-0.24900683520140277
348.8000000000043,40.33147343228512,0.6671903346875429,-0.259175991501682
350.00000000000426,40.44907674183755,0.6820947184389838,-0.27233326464078456
351.20000000000425,40.56435940923657,0.6987114471070531,-0.2864175477870865
352.4000000000043,40.681451740113296,0.7142337404773884,-0.30211223583854174
353.60000000000434,40.79772131396393,0.7296417864024671,-0.3172081428723974
354.80000000000433,40.91464239422771,0.7464068378516556,-0.3316481561004969
356.0000000000043,41.03085931188966,0.7651720680998183,-0.34529924883509056
357.20000000000437,41.147402386915964,0.7805594962261704,-0.3618574810028563
358.4000000000044,41.263441132726975,0.7994182005515742,-0.3822236770279237
359.6000000000044,41.379071012787435,0.8173525719543976,-0.3989386232988976
360.8000000000044,41.49702954523802,0.8365158695583615,-0.42170470804613025
362.00000000000443,41.61226127210318,0.8534820912575414,-0.4379642886897148
363.2000000000045,41.72812578503438,0.8722135672200262,-0.45277482542938996
364.40000000000447,41.84477921142061,0.8905770335418095,-0.4731504455004165
365.60000000000446,41.96018113659233,0.9093217280789216,-0.4956132875141308
366.8000000000045,42.076964381703334,0.9309019322265184,-0.5192858918160406
368.00000000000455,42.19530128813736,0.9538726150503818,-0.5452157995485667
369.20000000000454,42.31094258774827,0.9730960294411893,-0.5668314742790965
370.4000000000045,42.426521505031026,0.9917292494966621,-0.5964258448717383
371.60000000000457,42.5436543159697,1.0149078702833951,-0.6193644922647925
372.8000000000046,42.66018500483789,1.0383272426792518,-0.651230468775605
374.0000000000046,42.77798618350982,1.0601929217284753,-0.6806928823725156
375.2000000000046,42.89446726519006,1.08389836040367,-0.707986599627414
376.40000000000464,43.0117328014834,1.1040561943105525,-0.7371380460686137
377.6000000000047,43.12746270782627,1.1269097152868728,-0.7704534347302006
378.8000000000047,43.2448883845446,1.1485836000120015,-0.8071157942423626
380.00000000000466,43.36228306634082,1.1711451705666374,-0.8404536195945584
381.2000000000047,43.47906483243605,1.19167706749896,-0.8780007495604965
382.40000000000475,43.596579343887406,1.2097941739053564,-0.9186338375199017
383.60000000000474,43.71381710546798,1.2315369152054558,-0.956124540102735
384.80000000000473,43.83149730636504,1.2462687504596444,-0.9931442891547722
386.0000000000048,43.94819960310286,1.2583624526872597,-1.0330881769735463
387.2000000000048,44.065232934716654,1.2715805947433514,-1.0783151389323669
388.4000000000048,44.18245262348757,1.280597802559366,-1.1228739077088679
389.6000000000048,44.29937283322011,1.287701601588172,-1.1709685180932756
390.80000000000484,44.417776387004636,1.290055942868912,-1.2181555767384853
392.0000000000049,44.53503445991819,1.2896922297589801,-1.264749379765008
393.2000000000049,44.6524889102726,1.2852225077168322,-1.3110832146386335
394.40000000000487,44.76927773608887,1.2740883159092844,-1.3573971208171782
395.6000000000049,44.88648574334663,1.2600309416512245,-1.4008208725443345
396.80000000000496,45.003795861645486,1.2375220012017054,-1.4499394877073608
398.00000000000495,45.1218794595594,1.2101842242807228,-1.4995489334084078
399.20000000000493,45.23812866383736,1.1768521661755518,-1.5410850483891818
400.400000000005,45.353245032565226,1.136344189236447,-1.583332794360353
401.600000000005,45.472640996271956,1.0842085204176324,-1.627897049074957
402.800000000005,45.58875958561191,1.027321578181409,-1.6707281281104498
404.000000000005,45.70598594386752,0.963674460647906,-1.7087457065655571
405.20000000000505,45.82246426191241,0.89561013824516,-1.7400714285352938
406.4000000000051,45.938361273604265,0.8257744160623437,-1.7711350656655171
407.6000000000051,46.05522305241114,0.7560591785394986,-1.7978762915891187
408.80000000000507,46.17110136620499,0.6939103256820308,-1.8213741298529094
410.0000000000051,46.287918736730646,0.6364142821383478,-1.8444631331618306
411.20000000000516,46.403604173498394,0.5902215053997361,-1.860658801044773
412.40000000000515,46.520284536500576,0.5517456179774853,-1.8741955627154465
413.60000000000514,46.63742178427067,0.5208673290688413,-1.8881857437294305
414.8000000000052,46.75224098169449,0.5006500341587415,-1.9022420182182667
416.00000000000523,46.87013969175897,0.48465066265905926,-1.9161377081510356
417.2000000000052,46.98822419210489,0.4742379396144805,-1.9274226059084452
418.4000000000052,47.10386391237996,0.46388420873278785,-1.9321478121621665
419.60000000000525,47.22227279979544,0.4583987417986122,-1.9399869431840449
420.8000000000053,47.33888419978872,0.4568099385895875,-1.949525351590629
422.0000000000053,47.45604154058665,0.45339039085107186,-1.9596482407179714
423.2000000000053,47.57356182451263,0.45382459059091124,-1.970168881740868
424.4000000000053,47.69187727505492,0.4538414889261904,-1.9794670001476846
425.60000000000537,47.8088230402974,0.4538210128393127,-1.9821303541040827
426.80000000000535,47.925885621249826,0.45480273555945255,-1.9884967510714677
428.00000000000534,48.04308410334574,0.4552648849266977,-1.9990318392472806
429.2000000000054,48.160964027620246,0.45935159475203513,-2.00816604358587
430.40000000000543,48.278982679818874,0.45866074751048796,-2.0155860139387336
431.6000000000054,48.397275721644625,0.46088337083587316,-2.0236033767011934
432.8000000000054,48.51588012928753,0.46321201912790433,-2.0289490291809678
434.00000000000546,48.63314921997282,0.46795887215283183,-2.0364843056322766
435.2000000000055,48.75091011600005,0.47057565442631466,-2.046996339114343
436.4000000000055,48.868487231682415,0.4737920261605318,-2.055865318955415
437.6000000000055,48.98603616750402,0.47636809894319054,-2.060957998515664
438.8000000000055,49.1035581475894,0.4811793128666794,-2.0680509225571675
440.00000000000557,49.22180483076319,0.4852210724310933,-2.0797261389273753
441.20000000000556,49.33946360793623,0.4890428390217354,-2.090421520956319
442.40000000000555,49.457199151823325,0.4941970918020257,-2.0961133071154894
443.6000000000056,49.57404220433893,0.4960418567887276,-2.1053658671651174
444.80000000000564,49.692293819601566,0.49960866812731125,-2.1124978534161034
446.0000000000056,49.80944839353149,0.501748858790486,-2.1228284823055175
447.2000000000056,49.92693487336121,0.508742683077198,-2.1326952231711997
448.40000000000566,50.04520140107546,0.5104252512554334,-2.1389924901769195
449.6000000000057,50.162874126530596,0.5142142820266173,-2.1431196378985753
450.8000000000057,50.280405889758654,0.5176298108970359,-2.15597095207317
452.0000000000057,50.39822835341831,0.5221594538216207,-2.168820285951057
453.20000000000573,50.51548846804924,0.5253734190977483,-2.1787599004858578
454.4000000000058,50.63526544945414,0.5298818316658821,-2.18730638721654
455.60000000000576,50.752683754149,0.5340144043382606,-2.1980148294729127
456.80000000000575,50.87110216817363,0.5358955999192024,-2.2068199474683414
458.0000000000058,50.989170000000485,0.540510000000049,-2.216430144891106
459.20000000000584,51.10802697143871,0.5447823148123888,-2.229896349999658
460.40000000000583,51.2247944704676,0.5482517125871015,-2.2402996026009
461.6000000000058,51.34319339218844,0.5535777599219984,-2.2515897644881533
462.80000000000587,51.462024165239015,0.55551541944084,-2.263174555625289
464.0000000000059,51.580699758286066,0.5604228502150763,-2.2765521793007784
465.2000000000059,51.698077970404256,0.5629017304432563,-2.2845116062200583
466.4000000000059,51.817417692059614,0.5645688405856681,-2.297137389780456
467.60000000000593,51.93553865472472,0.5666926363213769,-2.3087980908050056
468.800000000006,52.0539293818779,0.5674195873149038,-2.3225390004624407
470.00000000000597,52.172449280562915,0.5685168650170883,-2.334837636756393
471.20000000000596,52.29019028246761,0.5690133271213809,-2.3483437907877365
472.400000000006,52.40864473798802,0.565092443114701,-2.359485502205372
473.60000000000605,52.52692356211597,0.5579301948164415,-2.3704672096860193
474.80000000000604,52.645735920063316,0.5504276567857149,-2.3811557785140325
476.000000000006,52.76293230753603,0.539270836602544,-2.3890506572441526
477.20000000000607,52.88219415914232,0.523265344151872,-2.397238294191889
478.4000000000061,53.0003581037964,0.5073153555872487,-2.412511071677252
479.6000000000061,53.118391532644964,0.4908989294091131,-2.4177121371917982
480.8000000000061,53.23761882556432,0.4721089465267896,-2.4192198339306192
482.00000000000614,53.35499196459336,0.4601106374482761,-2.4257756885608135
483.2000000000062,53.473586674229864,0.44614787830980207,-2.430939953306928
484.4000000000062,53.591906388842574,0.4408526133080635,-2.4317063267173484
485.60000000000616,53.71030298097542,0.43456784592638853,-2.4312012101536804
486.8000000000062,53.829270536881275,0.43109351736972057,-2.4347027765802687
488.00000000000625,53.948806394083924,0.4319420910857343,-2.4364535466797586
489.20000000000624,54.065436864074215,0.4325418128424465,-2.4371568927753766
490.40000000000623,54.18498657999834,0.43907413342646406,-2.4332752860131017
491.6000000000063,54.302111722682156,0.45356511894572354,-2.4381325494626935
492.8000000000063,54.42214981203619,0.4647408558377166,-2.439749132503887
494.0000000000063,54.54022828206222,0.4714827475979208,-2.4397471955907895
495.2000000000063,54.65926717804332,0.4759155769651164,-2.438429824942012
496.40000000000634,54.77751029089476,0.47641417986241547,-2.4371046101470313
497.6000000000064,54.89613023550325,0.47674933146423826,-2.4347258895885053
498.8000000000064,55.014661105137456,0.47688321009728046,-2.440202707128735
500.00000000000637,55.13362569173454,0.4769368029656503,-2.4430397721294295
501.2000000000064,55.252076334466814,0.4747986405660376,-2.44173436748004
502.40000000000646,55.37189457848171,0.4701758398006999,-2.4417063593142787
503.60000000000645,55.49128850658556,0.47051412818573235,-2.4417201999277225
504.80000000000643,55.60955485992474,0.47078407417923085,-2.4403309090418475
506.0000000000065,55.72959444580138,0.47299853446159984,-2.439075395849965
507.2000000000065,55.84866408376168,0.47279236582701695,-2.4387611955201445
508.4000000000065,55.96753444108712,0.47164261849261363,-2.4400798264753005
509.6000000000065,56.08766270941595,0.4702366231102667,-2.440070300947987
510.80000000000655,56.20667477039634,0.4654447177697707,-2.442515954532807
512.0000000000066,56.325331073707495,0.4616104053242884,-2.44205246168333
513.2000000000066,56.44595237068269,0.46289424724366296,-2.442719254865769
514.4000000000066,56.56449194824873,0.4614346340412601,-2.4430401599304803
515.6000000000066,56.683895172880895,0.4664868476680567,-2.444018652678624
516.8000000000067,56.803128578556596,0.4678112178161375,-2.4443366404194387
518.0000000000066,56.922419027311264,0.4692473618570072,-2.4428987813598138
519.2000000000066,57.041490906319424,0.4732631404033425,-2.445338376818696
520.4000000000067,57.16068914095765,0.4751285988576006,-2.4439206963959004
521.6000000000067,57.28012310482884,0.4787626425306873,-2.4412805220960885
522.8000000000068,57.396815588510854,0.4809019633187293,-2.441278368765475
524.0000000000067,57.51948950291511,0.48419215395242665,-2.4412901889646403
525.2000000000068,57.63781663187876,0.4876233050655819,-2.4452529367391223
526.4000000000068,57.75829345904057,0.489175984671122,-2.4465111128659007
527.6000000000067,57.877152862679516,0.49303727698771266,-2.4478600181473427
528.8000000000068,57.996420194639086,0.49690730945948464,-2.4478601076229913
530.0000000000068,58.116207035741226,0.5004758057668595,-2.445231011684497
531.2000000000069,58.234051481846315,0.5018656468539758,-2.4440299698639736
532.4000000000069,58.35391277814754,0.5065432536390934,-2.445263114730643
533.6000000000068,58.47304787240431,0.5066787066966184,-2.445339939521502
534.8000000000069,58.59267786754688,0.5116418245251401,-2.4460814077043707
536.0000000000069,58.71131100640437,0.5161250880674991,-2.44800569865874
537.2000000000069,58.83071990542575,0.5185393262299934,-2.446979991581596
538.4000000000069,58.95052085887656,0.521272980000107,-2.444130723695586
539.600000000007,59.070515052913855,0.5246918952080768,-2.4454489101722903
540.800000000007,59.18992331133268,0.52820315100772,-2.445405357519856
542.000000000007,59.31022437227795,0.5316681237075376,-2.4466842852431854
543.200000000007,59.43018058239434,0.533305012697694,-2.4448213134190624
544.400000000007,59.54980453745688,0.5373535826045449,-2.444492795905386
545.6000000000071,59.66944084363497,0.5390470130153496,-2.4457802114993497
546.800000000007,59.78917105432874,0.543510079196106,-2.4464392784976026
548.000000000007,59.909262304139006,0.5478074448511596,-2.449070053068672
549.2000000000071,60.02895272880471,0.5516772988141548,-2.449401157265763
550.4000000000071,60.14916802260864,0.5566901321258458,-2.4503899202381003
551.6000000000072,60.26965308353964,0.5591072344107549,-2.450027421019053
552.8000000000071,60.388689173559754,0.5608866400880456,-2.4460908982462874
554.0000000000072,60.50891421208111,0.5656998280032957,-2.4464431618772
555.2000000000072,60.628952919185714,0.5710103440234315,-2.4514607846607093
556.4000000000071,60.74829968254513,0.5746410265476624,-2.4518116900315348
557.6000000000072,60.867521081900875,0.5764289880852679,-2.4498375943837942
558.8000000000072,60.988344963254704,0.5833713074302799,-2.4488476908273076
560.0000000000073,61.106801324904254,0.5874768505559368,-2.4524696216011828
561.2000000000073,61.22654068892044,0.5919003834898398,-2.4506229237984707
562.4000000000073,61.346796266918886,0.5957939120594853,-2.4511495831080707
563.6000000000073,61.46644471582596,0.5974182095010228,-2.453635509607377
564.8000000000073,61.58835763550624,0.602549646124409,-2.4531301620740518
566.0000000000073,61.707387246042444,0.6070221668284704,-2.4531996149796678
567.2000000000073,61.827023164020645,0.6115220538849224,-2.450512153882017
568.4000000000074,61.94742786343164,0.6138989305298439,-2.451809968479237
569.6000000000074,62.06709109625617,0.6182713013926255,-2.452470488093686
570.8000000000075,62.185936462772894,0.6231958853980755,-2.449723731546578
572.0000000000074,62.30682745850411,0.6284349564955769,-2.4497300849953776
573.2000000000074,62.42588889678614,0.6300715047547637,-2.4497016035636827
574.4000000000075,62.546605832465495,0.6332175942092901,-2.448640205195968
575.6000000000074,62.6666157516306,0.6388837435717432,-2.4549941460785725
576.8000000000075,62.785954417679676,0.6396824721653779,-2.4564848602067215
578.0000000000075,62.90673933680598,0.6444585907724923,-2.453051030050199
579.2000000000075,63.025430362446095,0.6486263131648642,-2.4489599451950257
580.4000000000076,63.14629759003549,0.6520550019117907,-2.450300595835479
581.6000000000075,63.266429231858645,0.6581345613160965,-2.4556045441902485
582.8000000000076,63.38589502369557,0.6622116491992044,-2.4567135946180474
584.0000000000076,63.50685948309693,0.665095000135337,-2.452925099519941
585.2000000000075,63.62662838983459,0.6725959989091936,-2.462780262717321
586.4000000000076,63.74587101672472,0.6755343440038614,-2.470243449492065
587.6000000000076,63.86590760738334,0.679445360004775,-2.4618252820798827
588.8000000000077,63.98603236720815,0.6861877640974464,-2.463575117950196
590.0000000000077,64.10553539830217,0.6879450569159128,-2.4674013869296942
591.2000000000077,64.22580499868887,0.6959722665211183,-2.465272112681184
592.4000000000077,64.34517283886613,0.6978108054318972,-2.4634488251402695
593.6000000000078,64.46587657412012,0.7043952659134561,-2.4594292975031564
594.8000000000077,64.58633339069273,0.7099359342714295,-2.4635188410464
596.0000000000077,64.70658216355095,0.717002514041924,-2.46506121245214
597.2000000000078,64.8243506635546,0.725063123432114,-2.466285834595535
598.4000000000078,64.94716445184693,0.7317785257377261,-2.467830148990614
599.6000000000079,65.06757990296123,0.7388701740234793,-2.4733033949103205
600.8000000000078,65.18866795701739,0.7485132552230931,-2.4726012689253487
602.0000000000078,65.30845623902727,0.7550688250427753,-2.4719314776312693
603.2000000000079,65.42948820755852,0.7620595557672365,-2.4709146630668517
604.4000000000078,65.55005637145891,0.7711787763902765,-2.4718905971580987
605.6000000000079,65.67084041273421,0.7785159774580284,-2.4720892267694925
606.8000000000079,65.7916454059111,0.7882196298436592,-2.475079049246279
608.000000000008,65.91263961012307,0.7976067505469389,-2.4737495867881076
609.200000000008,66.03326146701943,0.8084842567950423,-2.4724309663477655
610.4000000000079,66.15426770920155,0.8162993634376509,-2.4754116206125456
611.600000000008,66.27614882981479,0.8276605626346424,-2.486639036221921
612.800000000008,66.39612626002159,0.8359119220661625,-2.4844652750770795
614.000000000008,66.5173054499761,0.846411345340349,-2.4803268201595197
615.200000000008,66.63570153632877,0.8595740650017824,-2.4816469151772815
616.400000000008,66.75775210093148,0.8710970489870017,-2.4830180323769246
617.6000000000081,66.87816782983535,0.8842084460739518,-2.4869491644427155
618.8000000000081,66.99926628453137,0.89628948083622,-2.4940280279348417
620.0000000000081,67.1188559615724,0.9083522613649199,-2.4895039917514197
621.2000000000081,67.24048447333978,0.9225420676213886,-2.491296361513242
622.4000000000082,67.36057428265954,0.9338438075331315,-2.489694439339212
623.6000000000081,67.48082969131848,0.9477221193118277,-2.492296240312714
624.8000000000081,67.60231726773448,0.964454798062942,-2.4959958659325836
626.0000000000082,67.72214953810445,0.977786323597724,-2.497864298386265
627.2000000000082,67.84231878149744,0.9894137231257425,-2.5019414678113043
628.4000000000083,67.96321580299589,1.0073635005916368,-2.505539304628216
629.6000000000082,68.08335503229361,1.0226587173267587,-2.507252725050835
630.8000000000083,68.2040593477292,1.0370588141017967,-2.503251034605126
632.0000000000083,68.32430940024831,1.0564182154889203,-2.509480989396776
633.2000000000082,68.44532983971047,1.0709360892775655,-2.5132713345994357
634.4000000000083,68.56557572032582,1.0869001275454349,-2.5133116165846014
635.6000000000083,68.687318635387,1.1014177529502611,-2.5131559050007937
636.8000000000084,68.80733292464602,1.119779087875027,-2.519589389545017
638.0000000000084,68.9274858902244,1.136114534707913,-2.518223783602062
639.2000000000083,69.04832305618683,1.1539309241317839,-2.520392388679916
640.4000000000084,69.16937353237608,1.1749342264453846,-2.529382698816394
641.6000000000084,69.28968944634603,1.192424843254736,-2.5345548165281455
642.8000000000084,69.4116497668,1.2099785243692338,-2.5417327825316747
644.0000000000084,69.53328206612966,1.2286338169809448,-2.5417499080219197
645.2000000000085,69.65454958219736,1.2450246519565653,-2.545039399701691
646.4000000000085,69.776063841474,1.2666143688239506,-2.5458538329743257
647.6000000000085,69.897503323355,1.2855633794059484,-2.5530058916736817
648.8000000000085,70.01957609658983,1.3057523385509786,-2.5566571555139666
650.0000000000085,70.13981230899181,1.326272583501707,-2.5649594823934976
651.2000000000086,70.2609932207888,1.345216318797103,-2.5621263635874687
652.4000000000085,70.38035013759291,1.365787692636099,-2.5619630728149723
653.6000000000085,70.50305872977985,1.390941506992285,-2.571252650501101
654.8000000000086,70.62326943499738,1.4141614475418127,-2.583149988503124
656.0000000000086,70.74394347572542,1.437785692912119,-2.586692491594154
657.2000000000087,70.86367929356379,1.4585860368064119,-2.592918076885276
658.4000000000086,70.98483451548272,1.4805340618190403,-2.5937503365227155
659.6000000000087,71.10589602229898,1.5057261887743971,-2.5987149116206285
660.8000000000087,71.22642197447388,1.5304978305912442,-2.6078923996329726
662.0000000000086,71.34755187565109,1.554861506478707,-2.6107204121920526
663.2000000000087,71.46661355578355,1.5772515966482334,-2.6188690582479177
664.4000000000087,71.58846417113587,1.6006696307073454,-2.623570044626267
665.6000000000088,71.70937113355622,1.6240827503432862,-2.6285280719822026
666.8000000000088,71.8306086487352,1.6475695150787042,-2.6367063363554744
668.0000000000088,71.9515932767685,1.666520234762596,-2.641233462237949
669.2000000000088,72.07147526669802,1.6903882875145844,-2.648352740915708
670.4000000000088,72.19216985175288,1.7112179132281164,-2.6571972012044585
671.6000000000088,72.31295833653262,1.7284288025740364,-2.6666464123458775
672.8000000000088,72.43461031796392,1.7455156117768829,-2.6733851020818316
674.0000000000089,72.55587140001155,1.7607341644895005,-2.6775536065271566
675.2000000000089,72.67816402466259,1.7722306345966032,-2.6833541109306536
676.400000000009,72.7990688909368,1.7876386362857566,-2.693882124601403
677.6000000000089,72.91948662044847,1.7986020102927918,-2.6958547069377055
678.8000000000089,73.04138255158033,1.8133208066499007,-2.7033843784767013
680.000000000009,73.16292319128725,1.8282978420667362,-2.710121560684727
681.2000000000089,73.28376802921915,1.8488505248226967,-2.7166695957715796
682.400000000009,73.40483895955761,1.875293635759764,-2.720761380906122
683.600000000009,73.5251306522218,1.9061978782462157,-2.724239551018753
684.800000000009,73.64686971633759,1.9483659525351398,-2.7410511305135614
686.0000000000091,73.767056801849,1.9887769459928555,-2.747196796397064
687.200000000009,73.8884237913814,2.0376454999463895,-2.7533949401685103
688.4000000000091,74.00990602788885,2.083957993271461,-2.76254569691179
689.6000000000091,74.1309284878177,2.1373825614821027,-2.7758519031936526
690.800000000009,74.25147457888008,2.1851098055114977,-2.7829717577558273
692.0000000000091,74.3731030233193,2.2360110750459783,-2.7923205306686047
693.2000000000091,74.494486904544,2.285064712710213,-2.79853220919812
694.4000000000092,74.61561914512293,2.337272662540287,-2.812662296727477
695.6000000000092,74.73677190364405,2.381893662087039,-2.8201218373442045
696.8000000000092,74.85800205828667,2.4286878344485925,-2.828677693278564
698.0000000000092,74.97978086877029,2.474454109580861,-2.8419616556135785
699.2000000000093,75.10121386897366,2.5203899351192836,-2.8517416535711524
700.4000000000092,75.22218124390156,2.56125409127732,-2.8620374327876705
701.6000000000092,75.34333553720012,2.6063386294335684,-2.876827829856742
702.8000000000093,75.4644754899285,2.6460832304097264,-2.89079841959542
704.0000000000093,75.58621524945103,2.687691050306171,-2.9086280045653394
705.2000000000094,75.70799711841424,2.7204581352754693,-2.9200480822949384
706.4000000000093,75.82955522883928,2.755134679435876,-2.9343846444167867
707.6000000000093,75.95067301497211,2.7820062776716816,-2.9465393505114705
708.8000000000094,76.07191923773013,2.805733711995547,-2.956163374517569
710.0000000000093,76.19252974147304,2.824500897979369,-2.9713069423928067
711.2000000000094,76.31525208921222,2.8347155626735074,-2.9831777304402483
712.4000000000094,76.43542726066292,2.832967350848011,-2.997365015772876
713.6000000000095,76.55706163133964,2.8212024311673263,-3.015229340318634
714.8000000000095,76.67765461387458,2.788287303153584,-3.0244273524527348
716.0000000000094,76.79927171923089,2.736537900107597,-3.036381241801652
717.2000000000095,76.91974526211925,2.65262571787357,-3.0534312531086303
718.4000000000095,77.04139977781503,2.5132247492950666,-3.0670489965012933
719.6000000000095,77.16192236610034,2.2791264413229118,-3.0754064676403416
720.8000000000095,77.28281002137349,1.8421988951921617,-3.084272792175776
722.0000000000095,77.40324963166937,1.3711528487328897,-3.085580148004071
723.2000000000096,77.52388768810667,1.2225363304429728,-3.086809109236354
724.4000000000096,77.64452178750395,1.1772641960417232,-3.0882130488078183
725.6000000000096,77.76465092036031,1.1581572821934913,-3.0882121747034432
726.8000000000096,77.88670611045265,1.1525769792840044,-3.088616197626748
728.0000000000097,78.00741883856861,1.1551642061321832,-3.0882100032385256
729.2000000000096,78.12798397447935,1.154821205897699,-3.088209800000031
730.4000000000096,78.2497660525662,1.1578817925950948,-3.0882098163508083
731.6000000000097,78.37151764216568,1.1593647371987668,-3.0886279358995896
732.8000000000097,78.49262853322018,1.1668361698019798,-3.08524480243355
734.0000000000098,78.61486390762148,1.1670170439498062,-3.0839301174741856
735.2000000000097,78.73659947406858,1.17231201376679,-3.085175240526334
736.4000000000098,78.85849754354558,1.1758360782270023,-3.0906145898633546
737.6000000000098,78.97981914981956,1.184625240716317,-3.089573670439288
738.8000000000097,79.10035668949142,1.1900800205410955,-3.0924455299724887
740.0000000000098,79.22258401086032,1.195107336980156,-3.0894181923634276
741.2000000000098,79.34431647287643,1.2013320907965583,-3.0918394462480885
742.4000000000099,79.46574454461926,1.2064694865965013,-3.091841743873498
743.6000000000099,79.58662201702451,1.2087370811049625,-3.0890897810692355
744.8000000000098,79.7085795077437,1.2148830429207038,-3.090420506864974
746.0000000000099,79.83059798437266,1.2190259247851785,-3.0890898333309544
747.2000000000099,79.95229016751217,1.2251294741844043,-3.090398262333437
748.4000000000099,80.07453944392451,1.2285006575492488,-3.0875083377532295
749.6000000000099,80.19625983802439,1.2335603179805703,-3.0802940074975202
750.80000000001,80.31822359837888,1.2432908442676522,-3.082626506215758
752.00000000001,80.44001988169052,1.246481903065032,-3.093986106660184
753.20000000001,80.56139094299634,1.2540132650044729,-3.0947144600557692
754.40000000001,80.68334972471288,1.2584006181501355,-3.086785993779481
755.60000000001,80.8050417019168,1.2663538988547538,-3.0948980304908282
756.8000000000101,80.92683254507142,1.2686573003036417,-3.0944377991793766
758.00000000001,81.04784403792272,1.2750914008770318,-3.087645416206459
759.20000000001,81.16759691872991,1.280241807269984,-3.0911680495901983
760.4000000000101,81.2904516069212,1.2817806865883181,-3.091976721738328
761.6000000000101,81.41332873297685,1.288326254611247,-3.0937833477029386
762.8000000000102,81.53539963150313,1.2969426761049685,-3.0924910094900095
764.0000000000101,81.65486175370506,1.3003867392682107,-3.092192074280189
765.2000000000102,81.77764584612635,1.3056925036399931,-3.0912484399607254
766.4000000000102,81.89622755857219,1.3124397085198303,-3.0941321850867345
767.6000000000101,82.01812454189522,1.3171974022973578,-3.0941298090651497
768.8000000000102,82.14225251268056,1.3261839675138234,-3.092820326001053
770.0000000000102,82.26286903739849,1.3316248479468413,-3.0911414487570767
771.2000000000103,82.38522978253714,1.3386855347935873,-3.0913853307036794
772.4000000000103,82.50645489586053,1.344306356520684,-3.0933541587228564
773.6000000000103,82.62876564522921,1.3527844183128113,-3.094981713202205
774.8000000000103,82.75028975042066,1.3587903764815468,-3.0932471857526824
776.0000000000103,82.8713834280945,1.365455681665003,-3.0919399290476908
777.2000000000103,82.99315429222005,1.3771679610616179,-3.0919399985209552
778.4000000000103,83.11545789026135,1.3826844209836622,-3.0919852160856216
779.6000000000104,83.23640232906433,1.3914887272248069,-3.0906300341579267
780.8000000000104,83.35906956740035,1.4001002197133343,-3.0919398511119693
782.0000000000105,83.48162024576699,1.4089007388071768,-3.0932258801578962
783.2000000000104,83.60344507061265,1.4169777295954473,-3.095223337187987
784.4000000000104,83.7256689217842,1.4263758873407961,-3.0950117539405158
785.6000000000105,83.84647536734182,1.434096256260991,-3.0946781549389044
786.8000000000104,83.9696608577377,1.4420588770745428,-3.095989698922067
788.0000000000105,84.09123914311728,1.4486629044039534,-3.0949292380559434
789.2000000000105,84.21282323309588,1.459369650691797,-3.09468120802276
790.4000000000106,84.33474100145318,1.4684551514438466,-3.0946866039681438
791.6000000000106,84.4557173281144,1.4732486526552528,-3.094666247956436
792.8000000000105,84.5781377175576,1.485686529423219,-3.0959667402685844
794.0000000000106,84.70027510350876,1.493481007374094,-3.095918222651392
795.2000000000106,84.82149644431686,1.5011760837179455,-3.093331428082729
795.7000000000106,84.87145153738567,1.501037651281686,-3.090798000717154