File: 01_Data/EIFS_Coating/STA/N2/3K_min/EIFS_Coating_STA_N2_3KData_230915_R1.csv
##Temp./Â°C,Time/min,DSC/(mW/mg),Mass loss/mg
40.2,10.9328440951629,-2.3538741557906455,0.05281950115417189
41.60000000000002,11.745014629019876,-2.315162118937697,0.04876145004042787
43.00000000000004,12.333212926006823,-2.2931725249812795,0.04851774554713639
44.40000000000006,12.874453611767505,-2.2860092593358425,0.04983019530713939
45.80000000000008,13.403552666072688,-2.2797654093410795,0.05063136358036324
47.2000000000001,13.903994307824373,-2.271191695598607,0.05204665593153557
48.60000000000012,14.411915048092414,-2.2698599587331887,0.05280186251382091
50.00000000000014,14.906214436599079,-2.2643939711804815,0.05212719893189366
51.40000000000016,15.390000000000054,-2.2575699999999985,0.05478011523750492
52.80000000000018,15.868327592455639,-2.2551304305649125,0.05377901730010315
54.2000000000002,16.345329269859043,-2.2532942445770594,0.055135865912033566
55.60000000000022,16.8215378769202,-2.2494745582714035,0.0560667353880584
57.00000000000024,17.299652391771904,-2.2468463621790935,0.05612367100480675
58.40000000000026,17.755776478386117,-2.242929064649316,0.056067027892058974
59.80000000000028,18.240311709066464,-2.2389692585956005,0.05738885026708651
61.2000000000003,18.699059849284282,-2.2357501125627754,0.0568752030515709
62.60000000000032,19.18021910758198,-2.2322640254892137,0.05708220533133712
64.00000000000034,19.645714738329016,-2.2289719579453973,0.05741007907135298
65.40000000000036,20.111502831996646,-2.2249980056261074,0.05674618831632383
66.80000000000038,20.575336113124532,-2.2208785181389943,0.05740170375311493
68.2000000000004,21.04335972508765,-2.215477925408109,0.05675013500789028
69.60000000000042,21.5047130990938,-2.2094118995768364,0.05543002984956136
71.00000000000044,21.97143416105964,-2.202239420852921,0.05543992497498351
72.40000000000046,22.441602935308858,-2.1928726521562685,0.05445000031942371
73.80000000000048,22.903565527180053,-2.1851284916541465,0.055760070022908614
75.2000000000005,23.37143898727034,-2.1765440364779924,0.0575583815080849
76.60000000000052,23.83331171267534,-2.1685928491416475,0.057080286348940135
78.00000000000054,24.2897763370929,-2.163895402958781,0.05575992999999979
79.40000000000056,24.753140250506316,-2.158628464290571,0.05708350176610644
80.80000000000058,25.21802506705367,-2.1548745614297684,0.05707989504490385
82.2000000000006,25.68040149341384,-2.1485206074650542,0.057735675240079054
83.60000000000062,26.143252713788286,-2.146029014496635,0.05708971232349036
85.00000000000064,26.60241246505676,-2.1405196200853727,0.05850831381931609
86.40000000000066,27.06309751946361,-2.1372894513369807,0.0587381861132279
87.80000000000068,27.52330002672101,-2.1343475369652767,0.05873005480960902
89.2000000000007,27.992656635765158,-2.1289314242822943,0.06138568498600527
90.60000000000072,28.457974548320948,-2.1265646513267162,0.06004007315624715
92.00000000000074,28.91021573407801,-2.123258367247051,0.06005125374107578
93.40000000000076,29.379127869826178,-2.11964242432534,0.05840234110505005
94.80000000000078,29.839915364912056,-2.1155307920480055,0.05872519005581012
96.2000000000008,30.301387053043932,-2.1110324415234776,0.06003972008915426
97.60000000000082,30.762475298854664,-2.1059090421779216,0.059709867069733136
99.00000000000084,31.22065054171753,-2.1001292994855065,0.05939381522299936
100.40000000000086,31.676731088440754,-2.0973642974676574,0.06127789837842457
101.80000000000088,32.13154825815918,-2.0936530147793957,0.0595594869419207
103.2000000000009,32.597533458279,-2.088467826437651,0.05937981499576317
104.60000000000092,33.05220145080919,-2.0866653817979595,0.061394185337694474
106.00000000000094,33.534494299391845,-2.081042604819589,0.061297900738289
107.40000000000096,33.97166129092026,-2.0798434298433275,0.06071073707373831
108.80000000000098,34.43224025491776,-2.0752234452164564,0.05887061138585459
110.200000000001,34.890217273671034,-2.0699685466396165,0.06168990056414092
111.60000000000102,35.34908222124262,-2.06727893394177,0.060913604298543866
113.00000000000104,35.810000000000606,-2.064730000000072,0.06135982010782293
114.40000000000106,36.26489072740353,-2.060541265891601,0.059380564524777135
115.80000000000108,36.722963341127844,-2.056451256997554,0.06069807833066587
117.2000000000011,37.16999999999939,-2.0515299999999117,0.06072929875559652
118.60000000000112,37.638502752747755,-2.047812451021177,0.06200895272699647
120.00000000000114,38.10095565890397,-2.046750294495709,0.06070991844070406
121.40000000000116,38.556570519674494,-2.043043631896375,0.061030159043396814
122.80000000000118,39.01763474544894,-2.0391109099365474,0.06135922227432378
124.2000000000012,39.41420709108764,-2.0350541149743386,0.056714246780351196
125.60000000000122,39.93380726595373,-2.031713417225281,0.05938012831677675
127.00000000000124,40.38629997665464,-2.028898708763559,0.05806980672191475
128.40000000000126,40.847024634607095,-2.0256634585765436,0.060369663722548594
129.80000000000126,41.30476451455821,-2.0213593165481516,0.06136020000000553
131.2000000000013,41.765488105261646,-2.0179324186064496,0.06136009503618922
132.60000000000133,42.228509743776435,-2.015413952640487,0.05904994198003699
134.00000000000134,42.68072606690774,-2.0115463897738217,0.06039180668325361
135.40000000000134,43.13525615278502,-2.0099986033890316,0.05907676997366007
136.80000000000138,43.59193631834133,-2.006089817547888,0.05975475629418536
138.2000000000014,44.04491705546526,-2.005127417107196,0.06201905973078059
139.60000000000142,44.49920384752715,-2.001729411420637,0.05939028541184932
141.00000000000142,44.95479196326219,-1.998874814446478,0.06091405075318246
142.40000000000146,45.40792378310245,-1.9947730038458398,0.06114007343954153
143.8000000000015,45.859735936873506,-1.9909276619131164,0.06080995500011799
145.2000000000015,46.3229195145437,-1.9897964033389457,0.059489954995207484
146.6000000000015,46.77465062203255,-1.985989555583101,0.06114513616049955
148.00000000000153,47.23194605557849,-1.9830508760539016,0.06227704853672744
149.40000000000157,47.6858519087272,-1.983562491846387,0.06047992502297195
150.80000000000157,48.142696349715536,-1.9808357270257138,0.06048887094449551
152.20000000000158,48.591295813369065,-1.978636827278752,0.05817999464520174
153.60000000000161,49.04673185174595,-1.9761779045254213,0.06212858435670032
155.00000000000165,49.49317653877573,-1.9744618928711872,0.05982989499976554
156.40000000000165,49.95753424762774,-1.9712460831009713,0.05982006359432024
157.80000000000166,50.41423022637813,-1.9672753155380684,0.059820069990446534
159.2000000000017,50.86571771273411,-1.967388469030345,0.059820170006249285
160.60000000000173,51.31999645249225,-1.965129849295789,0.0604798149896828
162.00000000000173,51.774713148879876,-1.9614561985976913,0.059819650091311516
163.40000000000174,52.23507505626145,-1.9620217119776653,0.06015025090383652
164.80000000000177,52.68403182402652,-1.958027028762504,0.05983019000003953
166.2000000000018,53.13782498621916,-1.9566052380663193,0.05983018999999867
167.6000000000018,53.59164547877031,-1.9548665264983307,0.06112713926797575
169.00000000000182,54.05125555208926,-1.9527707161873804,0.05886075272892466
170.40000000000185,54.50241772134028,-1.9504854829850462,0.060150034999646884
171.8000000000019,54.955908909456575,-1.9489564820319434,0.06015017926499322
173.2000000000019,55.409146643578865,-1.9475547372408508,0.05949018859267863
174.6000000000019,55.86146571378454,-1.9454253048213055,0.05817390605174122
176.00000000000193,56.31435762455374,-1.9429530679412816,0.05917069431348754
177.40000000000197,56.76859339149585,-1.9381062536871498,0.057840186250471604
178.80000000000197,57.21777214239195,-1.9389717920481502,0.05946464595754364
180.20000000000198,57.67346916320129,-1.9363191121343863,0.05566504931714178
181.600000000002,58.1299966024125,-1.9342500042913469,0.05740011000263312
183.00000000000205,58.586965437716024,-1.9348079574036832,0.05773992999999944
184.40000000000205,59.034574432490075,-1.933327879132572,0.05690396344340343
185.80000000000206,59.49571081767784,-1.9295051641076995,0.057740284628096994
187.2000000000021,59.94876060146001,-1.9273570399312032,0.05774076460363897
188.60000000000213,60.40131786366294,-1.927462580219864,0.056419929999999674
190.00000000000213,60.86000000000075,-1.9240299999999737,0.05627398280589624
191.40000000000214,61.310003370417334,-1.924899896234339,0.05576000499999978
192.80000000000217,61.76044280488111,-1.9238681584441002,0.055495542285125765
194.2000000000022,62.221492748021475,-1.9215087089040057,0.05479883154553633
195.6000000000022,62.67307367718875,-1.9185729522150583,0.05378009230055536
197.00000000000222,63.12756190287124,-1.9152460273063898,0.054770079903690316
198.40000000000225,63.577287358677694,-1.9172550239354134,0.056062932606592675
199.80000000000229,64.03679185319704,-1.9141470000023049,0.054110063182018386
201.2000000000023,64.4895890306922,-1.9127061600059554,0.05342015316717408
202.6000000000023,64.94820899467433,-1.9127840991942437,0.054110133064410704
204.00000000000233,65.40104807654929,-1.910346715457591,0.0527948154269815
205.40000000000236,65.85603924886213,-1.909823593441646,0.05443003043801031
206.80000000000237,66.30709681987655,-1.9093607400121955,0.05450050738644663
208.20000000000238,66.76044037378927,-1.9057490980761909,0.05410422403845683
209.6000000000024,67.21695146614351,-1.9053627888862241,0.05247007999161113
211.00000000000244,67.67101376147313,-1.9046928213017909,0.05279998591072932
212.40000000000245,68.1266920715785,-1.9017447938409047,0.05214008000000181
213.80000000000246,68.5729308116415,-1.9002651365245076,0.05082034778848499
215.2000000000025,69.02727819301981,-1.9021453224543996,0.051490271460579606
216.60000000000252,69.48087537624336,-1.8981044661075814,0.051810219247665934
218.00000000000253,69.93328232422624,-1.8959374506004698,0.049536099113532295
219.40000000000254,70.38746960506256,-1.8965799490085549,0.05699461217624968
220.80000000000257,70.83786861775174,-1.8947085869203844,0.047530756043872024
222.2000000000026,71.28892138884082,-1.8923709292968862,0.05156852232012188
223.6000000000026,71.74392272137601,-1.8933113810307027,0.04894985499999649
225.00000000000261,72.1967684361266,-1.893290030978275,0.04929147304623083
226.40000000000265,72.65166932476113,-1.8918455248314723,0.050930829602783945
227.80000000000268,73.10387673695128,-1.8898551087619568,0.051598016388971324
229.2000000000027,73.55905386906649,-1.8883056985797337,0.04828792356100653
230.6000000000027,74.01106738059258,-1.8893184145173838,0.05019897996753375
232.00000000000273,74.4693206098638,-1.8874188033819366,0.05027007870216771
233.40000000000276,74.9228135195549,-1.8851801129017303,0.050338463292228575
234.80000000000277,75.37582338525682,-1.8853009904485345,0.04927603854912199
236.20000000000277,75.82692367984072,-1.8841831556462225,0.04828992999999926
237.6000000000028,76.28440956750484,-1.8815454000885732,0.048289930000001036
239.00000000000284,76.73767912763608,-1.8814250954017404,0.04745409401277456
240.40000000000285,77.18900805738483,-1.8793786430322228,0.04664331571173275
241.80000000000285,77.64413514752552,-1.8767761225514654,0.046455643873583696
243.2000000000029,78.09565072926758,-1.8758839905593372,0.04730016617310806
244.60000000000292,78.54928367442189,-1.872771026986714,0.047960111915316794
246.00000000000293,79.00528216708605,-1.8741507692323707,0.0459900375176181
247.40000000000293,79.45247419732205,-1.871570337204727,0.04696928175888271
248.80000000000297,79.9100000000006,-1.872130000000101,0.04762629040228106
250.200000000003,80.36684489221788,-1.871425211903241,0.04905315523169218
251.600000000003,80.81869471038642,-1.8689592336894225,0.04468019739702811
253.000000000003,81.27557477138973,-1.8678225181401729,0.04684523317808953
254.40000000000305,81.72637821390408,-1.8668630727785955,0.04457887176151498
255.80000000000308,82.17210140854377,-1.8670851623956302,0.04467011487240402
257.2000000000031,82.63686491758105,-1.864670536931626,0.045317064178218125
258.6000000000031,83.08616357802953,-1.8641258555361784,0.04532996499939124
260.0000000000031,83.54242451605369,-1.8663929642438413,0.04400993571405731
261.40000000000316,83.99617540874011,-1.8646259457643635,0.042690069010929754
262.80000000000314,84.45127298409487,-1.864197772593328,0.04269006426190103
264.2000000000032,84.90018618225113,-1.8630436762653932,0.04375562627919383
265.6000000000032,85.35978774919639,-1.8628305044043039,0.04235053875283512
267.00000000000324,85.81342670227215,-1.8637138291390576,0.041298489998848
268.4000000000033,86.2670296309434,-1.86210998813848,0.04236960612157237
269.80000000000325,86.72109591505794,-1.8608433635230488,0.04367992247406427
271.2000000000033,87.17856333627145,-1.8616067133324932,0.0417098213020024
272.6000000000033,87.63313729308994,-1.859724656278094,0.04200448089188047
274.0000000000033,88.08836017302303,-1.861769338186259,0.04170869660386778
275.40000000000333,88.54228913123414,-1.860811812676887,0.040060002453690124
276.80000000000337,88.99845918830916,-1.8599058672150588,0.041049999978063134
278.2000000000034,89.45491369253995,-1.858408012518892,0.040060022540972184
279.60000000000343,89.90589531123645,-1.8592446264440396,0.03939958577704772
281.0000000000034,90.36355765449913,-1.8596179170492904,0.03939668198574342
282.40000000000344,90.81598033723472,-1.8572417563796508,0.03939541773956279
283.8000000000035,91.27234646121568,-1.8582802318179723,0.03810608800244086
285.20000000000346,91.7242114680744,-1.8567053253893906,0.038412439021944245
286.6000000000035,92.1828929298623,-1.8573020641248952,0.03808598879037195
288.0000000000035,92.63096397109246,-1.8557753055176234,0.03841927543791179
289.40000000000356,93.09443099409599,-1.8569747904408878,0.03413711676682851
290.8000000000036,93.54226185456031,-1.8568610460106223,0.03578033961770366
292.20000000000357,94.00250660935757,-1.8561494818075486,0.0357798099999771
293.6000000000036,94.45832267429205,-1.8550185130186323,0.03416569888617982
295.00000000000364,94.91252479304231,-1.8553403587463788,0.035120574071814126
296.4000000000036,95.37372663633988,-1.8565627861570688,0.03429640211947138
297.80000000000365,95.82832960241885,-1.8557891336865675,0.033800020033564415
299.2000000000037,96.28532045858644,-1.8569453729103316,0.03380001999989801
300.6000000000037,96.74094867730932,-1.8549785029286439,0.03248002611956835
302.00000000000375,97.19801686001527,-1.8543178713762902,0.03182984500001851
303.40000000000373,97.65320426446166,-1.8558808594458163,0.032819738402367626
304.80000000000376,98.11215867515315,-1.8572851418708107,0.030503309618588048
306.2000000000038,98.56632224897682,-1.8548101763634397,0.03183002203085383
307.6000000000038,99.02081968070816,-1.8552688963983195,0.030510828052888073
309.0000000000038,99.47742419418269,-1.8554900780621326,0.0307707781924611
310.40000000000384,99.93265056521037,-1.8562629205984271,0.030180057899402257
311.8000000000039,100.38490820302006,-1.8562910766640006,0.029522357363483742
313.2000000000039,100.84718964961628,-1.8576156038968983,0.028983808160577773
314.6000000000039,101.29982276785756,-1.858894171939597,0.027549992157595682
316.0000000000039,101.75685568673357,-1.8597988573975204,0.028209834999112893
317.40000000000396,102.21497781657862,-1.8612603317622634,0.02623009000150578
318.80000000000393,102.66337345865641,-1.8604507806802806,0.025569937465720116
320.20000000000397,103.12197459103149,-1.8603243502278233,0.024910123694328767
321.600000000004,103.58325919418687,-1.8613170528077685,0.023261209575394126
323.00000000000404,104.04081133562866,-1.8618682446804486,0.023919895000001468
324.40000000000407,104.49794912325034,-1.8626325432508088,0.022602781922922865
325.80000000000405,104.95631283998722,-1.8656868103600885,0.021948197284616278
327.2000000000041,105.4082177738873,-1.8672786852514884,0.023014229453897528
328.6000000000041,105.86800302116863,-1.8699055719026865,0.020265751727683856
330.0000000000041,106.33029933343052,-1.871790157879707,0.0206167460065263
331.4000000000041,106.77179850193777,-1.8719218351481823,0.020630131584035816
332.80000000000416,107.24650986246145,-1.8731903135812886,0.01908699160585403
334.2000000000042,107.70503754287779,-1.8777862091040132,0.016661022610558796
335.60000000000423,108.15921778521763,-1.877912663364131,0.014694811004489772
337.0000000000042,108.61706573313624,-1.8829194072704365,0.014814446460165165
338.40000000000424,109.07549897673722,-1.8872392144810781,0.014050117981756927
339.8000000000043,109.5335779349852,-1.891792038392131,0.012721636981188666
341.20000000000425,109.99440558657388,-1.8986339572164963,0.01229629632113749
342.6000000000043,110.45056791287844,-1.911560112834766,0.010064111416828503
344.0000000000043,110.90681807591183,-1.921816725465931,0.00745980999481155
345.40000000000435,111.37256674142844,-1.9278840824779413,0.0074557326045630035
346.8000000000044,111.83440735749733,-1.930211035123217,0.0041594767854196135
348.20000000000437,112.2933218126211,-1.9342510392156107,0.004754004325235428
349.6000000000044,112.7553839517904,-1.9379142122207607,0.0017773460496117721
351.00000000000443,113.21331513439317,-1.9379989778488218,-0.0014168020527600689
352.4000000000044,113.67463353276918,-1.9422411621908235,-0.0014398841740357327
353.80000000000445,114.12830705698956,-1.9418024323236867,-0.005379733200557624
355.2000000000045,114.59236757872743,-1.9431189000161193,-0.007920265373065227
356.6000000000045,115.04808658710344,-1.9431200176684094,-0.011207732689364036
358.00000000000455,115.50882196143428,-1.9417996947885017,-0.01526989545085744
359.4000000000045,115.96762356810281,-1.941007644799327,-0.0198095712200983
360.80000000000456,116.4276372288204,-1.9408099248275414,-0.023834071543183732
362.2000000000046,116.88143917612462,-1.942426469534563,-0.029122959804608328
363.60000000000457,117.35103201612343,-1.9390209174137754,-0.035690184740261977
365.0000000000046,117.80615771646613,-1.9388306535071342,-0.04095330405837583
366.40000000000464,118.26746486364682,-1.9350322741433206,-0.04987847628624742
367.8000000000047,118.73233235018306,-1.9336861960691833,-0.055114502940347254
369.2000000000047,119.1921755145827,-1.932229686607322,-0.0632472645583313
370.6000000000047,119.65759325538849,-1.9313910098990648,-0.07125375961890157
372.0000000000047,120.11901652653557,-1.9286064702470251,-0.07977969608765312
373.40000000000475,120.57976996739632,-1.9239022003386517,-0.08740190212490484
374.80000000000473,121.0410142124387,-1.9231656544918971,-0.09674657230550343
376.20000000000476,121.50405045701099,-1.9184682567469031,-0.10667326451776882
377.6000000000048,121.95795460541459,-1.9189300888547145,-0.11580315686200882
379.00000000000483,122.4228343971277,-1.916884325223582,-0.12441900381275639
380.40000000000487,122.87857791059831,-1.9132117796886532,-0.13138800449362265
381.80000000000484,123.34585884625656,-1.9120573225752118,-0.13726947798619715
383.2000000000049,123.80857080663682,-1.9082402094811026,-0.1461295855993896
384.6000000000049,124.26746808455837,-1.9069890661927864,-0.1527195923011857
386.0000000000049,124.72856395131824,-1.903432844007235,-0.15895368977116586
387.4000000000049,125.18872362242234,-1.9030791786772223,-0.16437042056837514
388.80000000000496,125.64481290539906,-1.9004384248051858,-0.1646985280032971
390.200000000005,126.10640556416419,-1.9001495361084693,-0.1690892011013867
391.600000000005,126.56798453290831,-1.8995157171367407,-0.17214985521709503
393.000000000005,127.03565853440075,-1.9004901582777787,-0.17347015478492622
394.40000000000504,127.4902889723947,-1.9110106282357804,-0.17345992042330582
395.80000000000507,127.95502022616952,-1.9188993682126938,-0.17510981987556384
397.20000000000505,128.41496194523245,-1.9213814801436133,-0.17643021398381542
398.6000000000051,128.8796635556338,-1.9213853825652438,-0.1780800928566788
400.0000000000051,129.343080979745,-1.9219473871926718,-0.17649937405320548
401.40000000000515,129.8068769937604,-1.9227189800642963,-0.17896008524305085
402.8000000000052,130.26606482909733,-1.920668022303409,-0.17932554639574816
404.20000000000516,130.72655191014195,-1.9253570934724729,-0.1832317172604192
405.6000000000052,131.18873304281865,-1.923787666712581,-0.18256982417327183
407.00000000000523,131.6494313593366,-1.9258799054871147,-0.18455104980828718
408.4000000000052,132.1134835214817,-1.926772558191501,-0.18356246502806606
409.80000000000524,132.57784213270077,-1.9262370125726482,-0.18620116285487054
411.2000000000053,133.0429016121735,-1.927730332793662,-0.18587001252577684
412.6000000000053,133.50401563822714,-1.9311585602340158,-0.1845511464367351
414.00000000000534,133.96598865251474,-1.9299587221356995,-0.18553943561440311
415.4000000000053,134.431008298358,-1.9315127777767962,-0.18586991009964482
416.80000000000535,134.89283843913978,-1.9329294012178075,-0.18751987999999242
418.2000000000054,135.3580385862296,-1.93414267790076,-0.18619988000001442
419.60000000000537,135.81360048223652,-1.9368155555694517,-0.18685959105842365
421.0000000000054,136.28171346875956,-1.934860818880134,-0.18752017999048354
422.40000000000543,136.74575247711954,-1.9375986217896664,-0.19014999154286816
423.80000000000547,137.21070539123437,-1.9405460447706553,-0.18977562560436656
425.2000000000055,137.67290117681915,-1.94195936002295,-0.19015017501352016
426.6000000000055,138.13327688342443,-1.9425640042625916,-0.1924891072204118
428.0000000000055,138.5996540225836,-1.9460298684347173,-0.19312014711514447
429.40000000000555,139.06223423975953,-1.9493923466956407,-0.192789890061265
430.8000000000055,139.53375940466793,-1.9506859053786716,-0.19442953624006076
432.20000000000556,140.00101035424908,-1.9525612769858132,-0.1923688277489881
433.6000000000056,140.46434774922696,-1.9540266478872486,-0.19574996256037958
435.0000000000056,140.92686370557246,-1.9557112892430102,-0.19542857089876842
436.40000000000566,141.39304624276224,-1.9572177370117605,-0.1970676893773673
437.80000000000564,141.85970214826992,-1.9640057005059062,-0.19643794013564708
439.2000000000057,142.32477291819117,-1.9625851844648061,-0.1964213948577309
440.6000000000057,142.78625592732553,-1.9647673110807955,-0.19739971155016
442.0000000000057,143.2524896706238,-1.9650971732928777,-0.1995709966131174
443.4000000000057,143.72061493439003,-1.9676017109798198,-0.2016800158058114
444.80000000000575,144.18492544592226,-1.9677109701436462,-0.20037001252524744
446.2000000000058,144.65197333484605,-1.9691577217571454,-0.20036995866382634
447.6000000000058,145.119647629368,-1.9674237458282138,-0.2019888834096797
449.0000000000058,145.5856793773759,-1.97126076858177,-0.20125532235044563
450.40000000000583,146.04728732288015,-1.9697915483245496,-0.20233982011024354
451.80000000000587,146.5129916618863,-1.971105358194754,-0.20405946821641274
453.20000000000584,146.97853246908187,-1.9688915430654963,-0.2042101300003898
454.6000000000059,147.44109004238436,-1.965129485826109,-0.20454013012716787
456.0000000000059,147.90833009174725,-1.962307035994601,-0.20320989986835647
457.40000000000595,148.37826879351294,-1.9640913199329306,-0.204524187313897
458.800000000006,148.84312639095504,-1.9666483415139429,-0.20518616421725522
460.20000000000596,149.30310593730314,-1.9650304583411438,-0.20481207134299728
461.600000000006,149.77302749883003,-1.9624995534694376,-0.20715877046144016
463.000000000006,150.2355382282853,-1.9647531083024259,-0.20618016999999966
464.400000000006,150.70326699743967,-1.9637622263695467,-0.20716999000000014
465.80000000000604,151.16834589314135,-1.9614275314219685,-0.2071699250106036
467.20000000000607,151.63749043728544,-1.9654388183371114,-0.20983024269632455
468.6000000000061,152.1081052484836,-1.96258607750743,-0.2096290213575056
470.00000000000614,152.58000000000274,-1.9657100000001628,-0.20815981000000017
471.4000000000061,153.04620185985752,-1.9650682410738873,-0.20842649244072176
472.80000000000615,153.51221758734766,-1.9648463369996234,-0.21211053651804068
474.2000000000062,153.97929738255095,-1.967977436710024,-0.21078993530010992
475.60000000000616,154.44497667661437,-1.9692673317750315,-0.20805012317498273
477.0000000000062,154.9126491465409,-1.9722076860954143,-0.21140053703197248
478.40000000000623,155.37880140466268,-1.9757914600272217,-0.21299078835003504
479.80000000000626,155.84917954220506,-1.9763371101363876,-0.21101010513820473
481.2000000000063,156.31386728138446,-1.9785493107647874,-0.21298984914334795
482.6000000000063,156.78290661076036,-1.9836955793989053,-0.21168263926995978
484.0000000000063,157.2494170367787,-1.9841223203048708,-0.21364999979565136
485.40000000000634,157.71932128729264,-1.98902407634621,-0.21298986751038163
486.8000000000063,158.1809056882723,-1.9865730555186019,-0.2133857914684376
488.20000000000636,158.65198595716316,-1.9932863857047345,-0.21330645829875072
489.6000000000064,159.12039000008068,-1.9969161517378893,-0.21331046462051617
491.0000000000064,159.58864355970098,-2.00096322748642,-0.21200017847901087
492.40000000000646,160.057352891248,-2.0033823358162346,-0.2128782257108237
493.80000000000643,160.52566855891786,-2.006097519324848,-0.2149600303273722
495.20000000000647,160.9943312865274,-2.0104077251629042,-0.21429707042230906
496.6000000000065,161.46510769411617,-2.0113064903001994,-0.2146402620210357
498.0000000000065,161.93334254070012,-2.015073363820647,-0.21497020325074567
499.4000000000065,162.40177305837395,-2.0150213956227137,-0.2146399701477324
500.80000000000655,162.8657449714656,-2.0179141238795837,-0.2146399674483761
502.2000000000066,163.33264515354276,-2.01940198751955,-0.2139798012296552
503.6000000000066,163.8035635552044,-2.0230656793383135,-0.21596010849698954
505.0000000000066,164.2724893576328,-2.0248274076980413,-0.2149855429263443
506.4000000000066,164.74055300772977,-2.027239643065633,-0.21693981000119855
507.80000000000666,165.20521489960703,-2.0286676956163263,-0.21630034814806498
509.20000000000664,165.67842885445452,-2.0322553540124932,-0.21495982279891157
510.6000000000067,166.14670452568853,-2.0367671731627333,-0.21857909893966587
512.0000000000067,166.61603619450133,-2.0397264448731383,-0.21661018461517045
513.4000000000067,167.0822434269638,-2.04080094454335,-0.21694040893442912
514.8000000000068,167.55144402056948,-2.0429305811839384,-0.21693985501517776
516.2000000000068,168.0184042281468,-2.045003747258573,-0.21693985554469997
517.6000000000067,168.4913287893412,-2.048862462029796,-0.2166101824735973
519.0000000000068,168.96630063142032,-2.0511782141507306,-0.21730445387024844
520.4000000000068,169.43414274174356,-2.053446841802951,-0.21826008000545816
521.8000000000068,169.90477933863485,-2.056305233675862,-0.21775536887037816
523.2000000000069,170.37275943946787,-2.0571196469081214,-0.21925167739180162
524.600000000007,170.84201855057617,-2.063864235884181,-0.21825888799726112
526.0000000000069,171.30868567556308,-2.0622312253812645,-0.21695043889425403
527.4000000000069,171.7731937321212,-2.0646647480327553,-0.21891014999999303
528.800000000007,172.24457814382941,-2.0673627074313576,-0.22056014951272473
530.200000000007,172.70319621201836,-2.07041800134505,-0.2192385743505727
531.600000000007,173.18203953175924,-2.071417783746652,-0.21974764333504915
533.000000000007,173.65332228783348,-2.074427167711059,-0.22254304283490445
534.400000000007,174.12434652317677,-2.0773422805293618,-0.22121994000736978
535.800000000007,174.59055128999069,-2.082172337255367,-0.22055548030015037
537.2000000000071,175.0672471120964,-2.080101738246549,-0.2217345155547652
538.6000000000071,175.53463386966013,-2.082297428372852,-0.2215499372336187
540.000000000007,176.00553092014349,-2.086410254338533,-0.22154978911523804
541.4000000000071,176.4754135181598,-2.0862216617973863,-0.22221706243779682
542.8000000000071,176.94957737385292,-2.08755132998955,-0.22122193043486105
544.2000000000071,177.41550734676687,-2.089323545109041,-0.22318460353131453
545.6000000000072,177.89071809604548,-2.094555557535053,-0.22286993845172187
547.0000000000073,178.31617492279244,-2.0932165733669956,-0.22320001540043943
548.4000000000073,178.83280580195438,-2.102513210448518,-0.22188001000000002
549.8000000000072,179.2984718003605,-2.1059420383124965,-0.2222100099018851
551.2000000000073,179.76212985857202,-2.106927581670416,-0.22351291084604297
552.6000000000073,180.23113932319865,-2.110735276816867,-0.22253123956994791
554.0000000000073,180.70476870232133,-2.111822743052344,-0.22385431780994747
555.4000000000074,181.17704930962537,-2.1149899533519534,-0.22353613335591227
556.8000000000073,181.65304724120813,-2.119424388544204,-0.22484974813058267
558.2000000000073,182.12283060182787,-2.121547695723816,-0.22352017782293254
559.6000000000074,182.60476072592638,-2.1277781794322563,-0.22583997703249414
561.0000000000074,183.07382824387662,-2.1291136687946897,-0.22584002499999967
562.4000000000074,183.54561687369576,-2.128669572863561,-0.22584002499365363
563.8000000000075,184.0149396734609,-2.133964838893115,-0.2261601357759231
565.2000000000074,184.47570268891602,-2.133335519328821,-0.2274722118599266
566.6000000000075,184.95107075219178,-2.1390956608448737,-0.22879046206380416
568.0000000000075,185.4144512542843,-2.1411707079440148,-0.2251720342497694
569.4000000000075,185.8939769091055,-2.145849331114007,-0.22748016995442244
570.8000000000076,186.36936101265454,-2.149808767343625,-0.2278098399927413
572.2000000000075,186.84600922571096,-2.1567877820099466,-0.22859089895501405
573.6000000000076,187.3132623462869,-2.179801088795354,-0.22813752438946278
575.0000000000076,187.77896431325908,-2.158518039025638,-0.2294601400180296
576.4000000000076,188.25719140157932,-2.159702704548432,-0.23176005528651933
577.8000000000077,188.73000340551675,-2.1632104309768496,-0.2304303632588196
579.2000000000077,189.2067791948683,-2.1628970035388684,-0.23239463198320243
580.6000000000076,189.67977978608457,-2.165086520330606,-0.2337346604837771
582.0000000000077,190.14829821202756,-2.165052209316492,-0.23238306823327148
583.4000000000077,190.61374622370658,-2.1698657397882797,-0.2343999326769617
584.8000000000077,191.0896707826976,-2.1703738322875963,-0.23497453811110525
586.2000000000078,191.5696411676523,-2.1785530553128476,-0.23636984498356872
587.6000000000078,192.04193445048622,-2.1817841868516616,-0.23634659477945696
589.0000000000078,192.51758360405466,-2.1890031679193864,-0.23899485893526506
590.4000000000078,192.9882000011389,-2.197887889046353,-0.2376855285991879
591.8000000000078,193.46555684202409,-2.199439553576266,-0.2396599646477151
593.2000000000079,193.93750360071027,-2.2055713721492016,-0.2386764718287857
594.6000000000079,194.4111479985148,-2.208303750527809,-0.2435259359409674
596.000000000008,194.88451223357967,-2.2122506013909544,-0.246601368287084
597.4000000000079,195.35911772181584,-2.2203479911911153,-0.2439400539671066
598.8000000000079,195.83113927157524,-2.2264916872748186,-0.2455901201542976
600.200000000008,196.30571887790234,-2.232635566866093,-0.2472378639417232
601.600000000008,196.78164608842576,-2.2373576798382464,-0.250859902546515
603.000000000008,197.25502122851032,-2.2438132666008803,-0.2505299787010635
604.400000000008,197.72824647080304,-2.2514684321080876,-0.2525221401288862
605.800000000008,198.20094434915381,-2.257232520202628,-0.252509870104062
607.200000000008,198.67891919382106,-2.2638561592493485,-0.2554780378751689
608.6000000000081,199.15384907712448,-2.2713700583829795,-0.25924949509933226
610.0000000000081,199.62721089247728,-2.276394775976384,-0.2607496308497863
611.4000000000082,200.0961295274651,-2.283499759686916,-0.26370993579671653
612.8000000000081,200.56496562403052,-2.2907603186833074,-0.2650275015047452
614.2000000000081,201.03920533996362,-2.301793914688146,-0.2679903511052699
615.6000000000082,201.51517506628826,-2.3106631694891604,-0.2703000500251047
617.0000000000082,201.9892580442521,-2.3180236235549514,-0.2729301093495402
618.4000000000083,202.46683394384317,-2.3311316880323782,-0.27820003559719897
619.8000000000083,202.93882854947242,-2.342579643796708,-0.2794862565459715
621.2000000000082,203.40900280711574,-2.348556900789565,-0.28478793174879646
622.6000000000083,203.8881540575821,-2.3605755994164817,-0.28907008604133955
624.0000000000083,204.35915804760285,-2.3698066272716076,-0.29105143754172325
625.4000000000083,204.83353659919698,-2.3813077949152266,-0.29633979950500144
626.8000000000084,205.30635386163172,-2.3901665975859987,-0.3015797385829475
628.2000000000083,205.78240071146854,-2.4027558946612695,-0.30817027964425225
629.6000000000083,206.25583548648842,-2.4136439514008874,-0.3114291715500519
631.0000000000084,206.73034369361173,-2.422858197413195,-0.31743600891283874
632.4000000000084,207.2034429477256,-2.435981322274949,-0.32134169263216306
633.8000000000085,207.66937379063245,-2.4509188383336697,-0.3279298960130652
635.2000000000085,208.15471767254078,-2.4621775289687515,-0.3327868400380871
636.6000000000084,208.6272963948435,-2.475044223129957,-0.33928753164479986
638.0000000000085,209.1016566512404,-2.492399770222768,-0.3461126485166939
639.4000000000085,209.57647381190267,-2.501226497513318,-0.3546985378281251
640.8000000000086,210.05284020779894,-2.5193827434876543,-0.36338345827265117
642.2000000000086,210.5289244100841,-2.5336425758390093,-0.3701270478018679
643.6000000000085,211.00800685874168,-2.5476707287295626,-0.3777925208511186
645.0000000000086,211.48678394288316,-2.562966459135404,-0.38897074402146714
646.4000000000086,211.96210126883162,-2.5751605323327764,-0.3976544205055781
647.8000000000086,212.43582145301923,-2.590914661127989,-0.40554367412206327
649.2000000000087,212.91596290970278,-2.6066553132863266,-0.41812955669656615
650.6000000000087,213.38772037408287,-2.6245988550791686,-0.4276154855304122
652.0000000000086,213.86438428522263,-2.64095609186,-0.43862720324870175
653.4000000000087,214.34282525026902,-2.6596702462190502,-0.4511869962216055
654.8000000000087,214.81914110927488,-2.6791047973514157,-0.46231015279151455
656.2000000000088,215.295157817841,-2.699954817228226,-0.4742911243669057
657.6000000000088,215.77127946541535,-2.7170039421632035,-0.48857245101641533
659.0000000000088,216.2455929683829,-2.74192938574474,-0.5008281254248041
660.4000000000088,216.72351187659564,-2.7599124215453466,-0.5145270627996972
661.8000000000088,217.19789604804953,-2.781338937721394,-0.5296502616425864
663.2000000000089,217.67617301302735,-2.803945201807865,-0.5437699044512012
664.6000000000089,218.16378353418457,-2.8269883731860603,-0.5604023123096753
666.0000000000089,218.64619266489717,-2.847051775504343,-0.5773766603317596
667.400000000009,219.1217712680927,-2.8668914595158332,-0.5942025750741737
668.8000000000089,219.59694108972312,-2.888459235015506,-0.611951264329833
670.2000000000089,220.0668707745449,-2.910780746897114,-0.6320928873031617
671.600000000009,220.5437106030565,-2.9363737004525365,-0.6490078942124091
673.000000000009,221.01781363444343,-2.9583280369516385,-0.6670613975775406
674.400000000009,221.50352707595903,-2.9837118042845536,-0.687342703494187
675.800000000009,221.9803691440253,-3.005979899958598,-0.7087828033774013
677.200000000009,222.4613251120891,-3.0290779051305665,-0.7326675802041351
678.6000000000091,222.93429836313314,-3.0533601482135877,-0.7529181577662496
680.0000000000091,223.41128070898722,-3.0765182659289207,-0.7759553726736841
681.4000000000091,223.88860062300168,-3.0995871015454037,-0.8003052364380645
682.8000000000092,224.36613208611257,-3.1198234732425716,-0.8250396368342834
684.2000000000091,224.84633411112569,-3.144327829499359,-0.8501090477226505
685.6000000000092,225.32571459077465,-3.1667792102105263,-0.8748050408235906
687.0000000000092,225.80354241025685,-3.184049761742894,-0.9000415276983658
688.4000000000092,226.281524249527,-3.2016361691244533,-0.9295150493297184
689.8000000000093,226.7486234473437,-3.2169554411842376,-0.9567858210675175
691.2000000000093,227.2282954882735,-3.228275225140908,-0.9837348671294555
692.6000000000092,227.70579091991144,-3.2380943480756876,-1.0110428318510167
694.0000000000093,228.18386026720333,-3.2400636025892418,-1.037591844143316
695.4000000000093,228.6573281045927,-3.2360747594586337,-1.0659787493674595
696.8000000000093,229.13282793884483,-3.221023210799177,-1.094301025763377
698.2000000000094,229.60442098219306,-3.197030969493736,-1.1218256581324915
699.6000000000093,230.08047781965354,-3.159034609725618,-1.1469181197036673
701.0000000000094,230.54708643348462,-3.1016555385167255,-1.1692885855633826
702.4000000000094,231.00915588843193,-3.018291426478191,-1.1916562356849139
703.8000000000094,231.47640586058432,-2.9044097181372086,-1.208695923930403
705.2000000000095,231.94439740169003,-2.7556527749650552,-1.226187267992454
706.6000000000095,232.40735757500806,-2.614569192058622,-1.2347946657596376
708.0000000000095,232.87809636400476,-2.5158403517815757,-1.2390211247652831
709.4000000000095,233.3528176383902,-2.4580847736408846,-1.244299758267235
710.8000000000095,233.8248956369563,-2.4219798645801855,-1.2462466041102442
712.2000000000096,234.30298519836919,-2.4034132753731523,-1.246255660619454
713.6000000000096,234.77811068033918,-2.394699107870434,-1.2479205245890896
715.0000000000095,235.26166219283695,-2.395118562131504,-1.2476303598656013
716.4000000000096,235.74218090325581,-2.392400553777887,-1.2479307996737234
717.8000000000096,236.21069393154002,-2.3975058149968924,-1.2479231645067919
719.2000000000096,236.68656628957555,-2.401912516482762,-1.2485796427589624
720.6000000000097,237.16650719035283,-2.402266862703199,-1.2472598600000007
722.0000000000097,237.6415858455439,-2.407828883412182,-1.24857985945973
723.4000000000098,238.1162505545659,-2.4110550290145487,-1.2505335087666096
724.8000000000097,238.59076270964306,-2.417156488170336,-1.250549885000383
726.2000000000097,239.07043252130208,-2.4183274182874817,-1.2472681790085227
727.6000000000098,239.55408344374058,-2.421214181114572,-1.2509181234661981
729.0000000000098,240.0266819511117,-2.4221122789082514,-1.2495601869076123
730.4000000000099,240.4903921939004,-2.422195880954886,-1.250215020814606
731.8000000000098,240.96698484661334,-2.4224703650619306,-1.2507464020619632
733.2000000000098,241.44999505573475,-2.425190906562399,-1.2498900909606743
734.6000000000099,241.92950236431184,-2.427574486300511,-1.2512888207221442
736.0000000000099,242.4077374935461,-2.4337962777111275,-1.2498899788300264
737.4000000000099,242.88588170847356,-2.4412585777216322,-1.2492311730901355
738.80000000001,243.3650295828884,-2.4475006820153733,-1.2495593456434135
740.2000000000099,243.83418175574704,-2.4469722111229935,-1.2495599304011877
741.6000000000099,244.3165278411282,-2.4474219976353027,-1.2495595309283334
743.00000000001,244.7940572465077,-2.4541206171533188,-1.2495896460508904
744.40000000001,245.27153768623413,-2.458153899276286,-1.2498899299999997
745.8000000000101,245.7438719291069,-2.454676380189392,-1.2485743117571109
747.20000000001,246.22199246670104,-2.4577543678410363,-1.2482499306978014
748.60000000001,246.69774509856336,-2.461254486864807,-1.2508599734615395
750.0000000000101,247.1800000000034,-2.4683399999998854,-1.2512110858986807
751.4000000000101,247.66429516016882,-2.471894020028254,-1.250895436450191
752.8000000000102,248.14270649156333,-2.4739392933921476,-1.2515398276636538
754.2000000000102,248.62275651101663,-2.4723412387643213,-1.2504489054655155
755.6000000000101,249.09348786112918,-2.4733828680859116,-1.2515399001223497
757.0000000000102,249.56688460282615,-2.4693195403130264,-1.2515399005778702
758.4000000000102,250.04671172744347,-2.440604968319462,-1.2512101251028391
759.8000000000102,250.52664900956862,-2.4160271013958243,-1.2508901249999012
761.2000000000103,251.00576596703223,-2.424122745117237,-1.250890226679107
762.6000000000103,251.4818228524959,-2.427226790251905,-1.2504589748913335
764.0000000000102,251.96134598864685,-2.43127440458109,-1.250561973905039
765.4000000000103,252.44079394537349,-2.43498224691937,-1.2525478095264249
766.8000000000103,252.91827100068923,-2.4348784538331403,-1.2512807202908567
768.2000000000104,253.39497700519183,-2.4416256913178116,-1.2525200904558158
769.6000000000104,253.87710071162067,-2.4444951433586297,-1.2521894343454947
771.0000000000103,254.3533948156473,-2.449346236739593,-1.2498930770678016
772.4000000000104,254.82341748643762,-2.449916665659153,-1.2521999752398751
773.8000000000104,255.30434813422116,-2.4528730659009437,-1.2502198411490566
775.2000000000105,255.78195398215829,-2.453873384853511,-1.2518700449863647
776.6000000000105,256.2678830920554,-2.457765251825877,-1.2518700450000018
778.0000000000105,256.74779761699943,-2.4583049313923397,-1.2511765513514135
779.4000000000106,257.22908541499567,-2.457999289949551,-1.2522002017693574
780.8000000000105,257.7008569700258,-2.4610652609783,-1.2515399390635578
782.2000000000105,258.18512349482785,-2.4622199208374678,-1.2519025747905528
783.6000000000106,258.66533246699316,-2.460143790575555,-1.2495561838113023
785.0000000000106,259.14598130616696,-2.4606966560906405,-1.2504782757919446
786.4000000000106,259.61955014452667,-2.463369977823044,-1.2521988747717447
787.8000000000106,260.09921283430475,-2.4679007674280857,-1.251871241077514
789.2000000000106,260.5782238571686,-2.4679479420219947,-1.2538507756270945
790.6000000000107,261.056572599717,-2.4701741036969,-1.2511428304511267
792.0000000000107,261.5304066696355,-2.4716716091275694,-1.2525195997092284
793.4000000000107,262.01307479760044,-2.4731759224480845,-1.254839794860155
794.8000000000108,262.4910035360682,-2.4745544661208694,-1.2512101667342042
796.2000000000107,262.9743103587386,-2.4761435553118982,-1.253189834914215
797.6000000000108,263.4549210754039,-2.4810438273085866,-1.252199910002361
799.0000000000108,263.934956894879,-2.4873012780598276,-1.2548198678191675
800.4000000000108,264.4146793486062,-2.4890817350747083,-1.2538400851743878
801.8000000000109,264.89186172001723,-2.4932977080878977,-1.2548721675349395
803.2000000000108,265.3673603117767,-2.4982806090500396,-1.2535204607514245
804.6000000000108,265.84528215737447,-2.4999677202382573,-1.255159905775713
806.0000000000109,266.32065148027107,-2.5018298838430795,-1.2535131229309129
807.4000000000109,266.8012171422409,-2.5027171089695455,-1.253509832530018
808.8000000000109,267.2848587648353,-2.5068171325717836,-1.252860642792546
810.200000000011,267.7683296589993,-2.513011276973157,-1.2548331269048791
811.6000000000109,268.24396768498406,-2.516252207938581,-1.2522001363504498
813.000000000011,268.7183085630286,-2.519514350957098,-1.25385012994824
814.400000000011,269.19999170712634,-2.5207290558572466,-1.2525304306264986
815.800000000011,269.681688764342,-2.521641391904518,-1.2505341611492868
817.2000000000111,270.159107141487,-2.5252617015492556,-1.2531899500073211
818.600000000011,270.6416324970068,-2.5321762628241182,-1.2534488831039767
820.0000000000111,271.1182282541198,-2.5365666528245363,-1.2535198742964981
821.4000000000111,271.5972226276881,-2.537921460973032,-1.2535202016916944
822.8000000000111,272.081559585064,-2.5391532769158647,-1.2521989981067159
824.2000000000112,272.55508202503296,-2.5388787362378737,-1.2538402174579502
825.6000000000112,273.0316777353671,-2.539342186348267,-1.254499954823455
827.0000000000111,273.51205867956185,-2.544665615888237,-1.2554900195385321
828.4000000000112,273.99646694996363,-2.54815253042833,-1.2554896272083726
829.8000000000112,274.4741424420013,-2.5514229995725115,-1.2534801003798735
831.2000000000112,274.9554217121977,-2.5533778041010717,-1.2542800347989589
832.6000000000113,275.43349455252513,-2.5565591359819955,-1.251896926951011
834.0000000000113,275.9100000000041,-2.5550000000001454,-1.253620169991129
835.4000000000113,276.39570507664865,-2.5572217799105124,-1.2545302431591399
836.8000000000113,276.87679940440603,-2.557740134833629,-1.2545100619565677
838.2000000000113,277.3514456421008,-2.5599547937189873,-1.2548823811013792
839.6000000000114,277.83224720834284,-2.5651988405371347,-1.2521972183882082
841.0000000000114,278.31393259782,-2.5621331780789953,-1.253520065003241
842.4000000000115,278.78721039792083,-2.5710727131301403,-1.252200067277339
843.8000000000114,279.2563886493076,-2.570992330046874,-1.2528987146308013
845.2000000000114,279.7479431140418,-2.572242667882291,-1.2552606566588933
846.6000000000115,280.2275941958558,-2.576156570631056,-1.2531482486189036
848.0000000000115,280.7110881278986,-2.5755570207902605,-1.2538399850000141
849.4000000000115,281.1905220661643,-2.5771996341133767,-1.2541743841254727
850.8000000000116,281.66438242889865,-2.5842925461511226,-1.254168794533205
852.2000000000115,282.1399963826745,-2.588849592387631,-1.2515248260424041
853.6000000000115,282.61670445789554,-2.5949049504416872,-1.2535098098832749
855.0000000000116,283.0956699478504,-2.6000442502136782,-1.2538518008756938
856.4000000000116,283.58146708163514,-2.6060781546220344,-1.2544971642565153
857.8000000000117,284.0600031136299,-2.6069005251489017,-1.2541699550355645
859.2000000000116,284.530944672339,-2.60385043203722,-1.2538503239652732
860.6000000000116,285.015292724331,-2.6109034071391313,-1.2558199246745847
862.0000000000117,285.495853418153,-2.613452086682884,-1.2548402446174332
863.4000000000117,285.98172122366,-2.6200711148904334,-1.2554495792880873
864.8000000000118,286.4500007388645,-2.6262306077389836,-1.2554899249980371
866.2000000000118,286.93633513151735,-2.6305336262844614,-1.2548400742367263
867.6000000000117,287.4172941154612,-2.6388772847450346,-1.2554999297076987
869.0000000000118,287.89606578943204,-2.638796064927235,-1.25417982
870.4000000000118,288.3803209248764,-2.645158977876258,-1.2531898199326492
871.8000000000118,288.86041674861235,-2.6502174432219485,-1.256809937057143
873.2000000000119,289.3397007732681,-2.6531243927571415,-1.254155242371025
874.6000000000118,289.81728036939523,-2.6577668688444795,-1.255489844977336
876.0000000000118,290.27193043407743,-2.657013113908656,-1.254499844867111
877.4000000000119,290.77882366794734,-2.669425445517933,-1.2564475829016963
878.8000000000119,291.25518952157614,-2.670549121143261,-1.255489305337223
880.200000000012,291.7359116853509,-2.6719629748091456,-1.2571408049446933
881.600000000012,292.2113119396764,-2.680455959376839,-1.2558165369450438
883.0000000000119,292.6869539500661,-2.684816630568158,-1.2558198366071474
884.400000000012,293.1593107432599,-2.6948363753831175,-1.2554900404380174
885.800000000012,293.6494593924275,-2.7039519469084397,-1.257126391756791
887.2000000000121,294.1330996258602,-2.709338356692301,-1.256480114990401
888.6000000000121,294.6112362302558,-2.711258293829605,-1.2558201147748616
890.000000000012,295.0943932423473,-2.7168222527475088,-1.2568263073394723
891.4000000000121,295.57113593196823,-2.7239913985761786,-1.2577900350359812
892.8000000000121,296.05034065249555,-2.7269014509487826,-1.2555997028832029
894.0000000000122,296.4615775732136,-2.7319080230458836,-1.255164203974041