File: 01_Data/Vinyl_Tile/STA/N2/10K_min/Vinyl_Tile_STA_N2_10KData_220505_R2.csv
##Temp./Â°C,Time/min,DSC/(mW/mg),Mass loss/mg
50.0,10.4777939392758,-1.2637271583603222,-0.022711530521998036
51.100000000000016,10.939682068815712,-1.1163064018823141,-0.021489450531963605
52.20000000000003,11.176024764721438,-1.0263714129007036,-0.021361421521951307
53.30000000000005,11.363412037365045,-0.9655015211873972,-0.02158923109419497
54.40000000000006,11.526116892119626,-0.915519840138313,-0.020420417213514952
55.50000000000008,11.677236429856853,-0.876008814984668,-0.022145783115706585
56.600000000000094,11.817288403234581,-0.8448863211085742,-0.022233015694574476
57.70000000000011,11.950485608107508,-0.8179156978760974,-0.02122893992937236
58.800000000000125,12.082054585603787,-0.7946659197920699,-0.02180049280685825
59.90000000000014,12.209066422271725,-0.7766052412336595,-0.021231889597090436
61.000000000000156,12.334272909479068,-0.76067525184449,-0.021143412725057154
62.10000000000017,12.457585370914819,-0.7476922707774446,-0.02112367518645275
63.20000000000019,12.579798378808087,-0.7348275403863949,-0.02115421830614217
64.30000000000021,12.699475514610182,-0.7241022670333077,-0.021184642145656518
65.40000000000022,12.820660698709355,-0.7134599185052896,-0.02117638760076357
66.50000000000023,12.940000000000023,-0.7032899999999982,-0.021169817584834938
67.60000000000025,13.057838153676856,-0.6941725801279294,-0.021360274494965914
68.70000000000027,13.174369431309913,-0.6866889225894951,-0.02252601379503183
69.80000000000028,13.29219599751454,-0.6786721751352883,-0.022476095066148893
70.90000000000029,13.412073488009412,-0.667686934257898,-0.022476368006575598
72.00000000000031,13.529145031629659,-0.659453397771093,-0.022997848353913497
73.10000000000034,13.644433926083751,-0.6505640401108459,-0.023840640848960426
74.20000000000034,13.761014647678156,-0.6399564456763569,-0.022426491218942246
75.30000000000035,13.875284681942144,-0.6331593767796049,-0.022439068311014942
76.40000000000038,13.991265054139154,-0.6241722568561674,-0.023837701622842822
77.5000000000004,14.09910458055805,-0.6167010187973315,-0.023630425437857205
78.6000000000004,14.218549127753622,-0.6071013803746068,-0.025119613766833027
79.70000000000041,14.334143605778094,-0.5976912814717891,-0.023810757735619248
80.80000000000044,14.446159786704388,-0.5897396718458524,-0.025127604684318072
81.90000000000046,14.558464261686916,-0.5823530060286819,-0.025117405596430054
83.00000000000047,14.670782048310269,-0.5730765124705561,-0.02511624974712845
84.10000000000048,14.782800724954337,-0.5652611293486356,-0.025128578644567412
85.2000000000005,14.894555189941922,-0.5592305135301089,-0.02484140831752235
86.30000000000052,15.00683783584571,-0.5509514457964135,-0.025120030555221717
87.40000000000053,15.116641964434331,-0.5438273680421448,-0.0251200732009087
88.50000000000054,15.227880519402202,-0.5365186352355438,-0.02684966258977539
89.60000000000056,15.339175640804333,-0.5294230157494182,-0.02643948394049822
90.70000000000059,15.448086664632669,-0.5229146521434542,-0.02780780788166748
91.8000000000006,15.559682729864956,-0.5163004799039254,-0.027798737042551203
92.9000000000006,15.66921456741934,-0.5081972904770125,-0.026453658375253042
94.00000000000063,15.779364903680746,-0.5017178852124289,-0.02774989835160291
95.10000000000065,15.887438256817063,-0.49589635780203,-0.027106368318207785
96.20000000000066,15.996746681933782,-0.4873672984769475,-0.027747816115925694
97.30000000000067,16.105837486818388,-0.4809035364234133,-0.0270898913518538
98.40000000000069,16.21383581268597,-0.47440945962120995,-0.027147357955726648
99.50000000000071,16.32332850152437,-0.46645049870560534,-0.027432643966746717
100.60000000000072,16.432401757238384,-0.45960303367234295,-0.026809618247034983
101.70000000000073,16.540565924995104,-0.45430147542639765,-0.026439508561841407
102.80000000000075,16.648167749718553,-0.447216523533088,-0.027751266618543546
103.90000000000077,16.75734843641002,-0.4398138231336339,-0.02863490779899802
105.00000000000078,16.863502270239476,-0.4320599626839843,-0.027761432395839947
106.10000000000079,16.973495450655243,-0.42689323673127105,-0.02774848555582654
107.20000000000081,17.0812480928453,-0.4201002807178858,-0.028080217442520095
108.30000000000084,17.188880609071887,-0.4126413730393936,-0.028079914528752248
109.40000000000084,17.29609914311782,-0.4051769702790022,-0.02939021301652378
110.50000000000085,17.403588673943066,-0.39782083351181863,-0.029792366560543293
111.60000000000088,17.51129693898585,-0.39255660565777645,-0.029069823759093616
112.7000000000009,17.618957571599243,-0.3839068088336735,-0.03040261756675333
113.8000000000009,17.726835413398206,-0.37799026741972347,-0.029722349630626255
114.90000000000092,17.834612578325185,-0.3727178423066251,-0.029175497665528738
116.00000000000094,17.940581077608186,-0.3680025305664636,-0.028737948413692038
117.10000000000096,18.04920380260781,-0.3611229327022755,-0.029126505216349408
118.20000000000097,18.15647962219341,-0.35416518458963286,-0.030389860357463938
119.30000000000098,18.26345089611952,-0.34734689335155444,-0.030752300815288347
120.400000000001,18.37183158224962,-0.3410588546967696,-0.030390034940716237
121.50000000000102,18.47812796400656,-0.338415393644004,-0.03038997160803536
122.60000000000103,18.584970269978548,-0.33059625656902386,-0.031570379896869394
123.70000000000104,18.692460438775402,-0.32595423533542645,-0.031143539829285416
124.80000000000106,18.799686398835515,-0.32053428883865026,-0.030390057035568407
125.90000000000109,18.906279305397106,-0.31537368030521107,-0.03039005701280706
127.0000000000011,19.012063317503205,-0.31085535269356335,-0.030375080660287157
128.1000000000011,19.119699935393236,-0.3052348674347791,-0.0303806032651881
129.20000000000113,19.226317622479296,-0.3014254041865816,-0.0316998537641382
130.30000000000115,19.3328810896862,-0.2954597562616212,-0.03269065578915509
131.40000000000117,19.44000097203038,-0.29042993004165013,-0.03137001070838741
132.50000000000117,19.54667481112898,-0.28671826057695166,-0.031370051783115915
133.6000000000012,19.652752266722853,-0.2807672777847497,-0.030339101144568836
134.7000000000012,19.76039968556189,-0.27520471098755034,-0.03169985759091709
135.8000000000012,19.864997574359705,-0.2694855315913881,-0.03169704412686514
136.90000000000123,19.97326516287283,-0.26547463768613,-0.03170007723301271
138.00000000000125,20.077382083837552,-0.2601778848579899,-0.03170045120823861
139.10000000000127,20.18447741554141,-0.2545595635785868,-0.032690192892272485
140.2000000000013,20.290493387819943,-0.24846667186395122,-0.0340119241590604
141.3000000000013,20.396833827507358,-0.24383158322089776,-0.03268999385319171
142.4000000000013,20.50341456951458,-0.24006357903213038,-0.0330513936510517
143.50000000000134,20.609717056803696,-0.2343431918341681,-0.033019875017082256
144.60000000000133,20.715491500520756,-0.22839126016050604,-0.03287222837480064
145.70000000000135,20.821961258572802,-0.2237489077503838,-0.034148081997243285
146.80000000000138,20.92652732102132,-0.21780874755117477,-0.03367999134620625
147.9000000000014,21.032217059879315,-0.2133623726399855,-0.03368333579528304
149.00000000000142,21.13916199752056,-0.2085523940899004,-0.032675172277977005
150.10000000000142,21.242739216268482,-0.20298603840731833,-0.034110672137868114
151.20000000000144,21.350189735387374,-0.19875299967412402,-0.03531961624958191
152.30000000000146,21.456378529840084,-0.19392894341463882,-0.03540508527606523
153.40000000000146,21.561625264727056,-0.1895937510075882,-0.03531939287375341
154.50000000000148,21.666690755743353,-0.1840073991739914,-0.03627184640031089
155.6000000000015,21.77288835590382,-0.1783962210387714,-0.034990017933922424
156.70000000000152,21.87913127438704,-0.17465226494164138,-0.03499001300000115
157.80000000000155,21.983918762767985,-0.16918121384542018,-0.034990013011341414
158.90000000000154,22.09045905493988,-0.16235655584269504,-0.034991048027971594
160.00000000000156,22.195270191135574,-0.15745356504013613,-0.035322774832105
161.1000000000016,22.301833717995194,-0.1537252338201135,-0.0353198918891251
162.20000000000158,22.40652246827302,-0.14787104466169998,-0.0353201883407972
163.3000000000016,22.51149029427163,-0.14281479451603524,-0.03615748396814622
164.40000000000163,22.617105248919664,-0.13946161603749116,-0.03664018773150213
165.50000000000165,22.722604395732418,-0.13356724345312967,-0.03664018395868185
166.60000000000167,22.82849035411198,-0.12951731608533806,-0.03794158625148647
167.70000000000167,22.933355226816435,-0.12345391833721966,-0.03794639695504953
168.8000000000017,23.038879611052266,-0.11856359690955988,-0.03665438603785631
169.9000000000017,23.144310102173826,-0.1143368816596281,-0.03763003315868341
171.0000000000017,23.249690076175344,-0.10925409083490739,-0.037630652173817225
172.10000000000173,23.35552018311004,-0.10427102601697381,-0.03796005003985403
173.20000000000175,23.460179977847357,-0.10003201319995146,-0.03780284712330717
174.30000000000177,23.565789035707052,-0.0949924803211196,-0.03959147272519381
175.4000000000018,23.670677851237112,-0.09229079213098634,-0.03858389731358791
176.5000000000018,23.77574857436784,-0.0863726864831474,-0.038619579638910384
177.6000000000018,23.88143418503302,-0.08097203461119815,-0.03992992162628184
178.70000000000184,23.98519519714767,-0.07544603507222986,-0.03993154505043828
179.80000000000183,24.09243803235212,-0.07228573459299316,-0.038617609037643774
180.90000000000185,24.196386036771102,-0.06739308886522592,-0.03861009588908537
182.00000000000188,24.300853584868456,-0.06328812807339834,-0.03904089910874298
183.1000000000019,24.40656671462448,-0.06023823661572701,-0.04124992077298062
184.20000000000192,24.510787182566542,-0.05575199437194585,-0.04124992100184821
185.30000000000192,24.61589044730584,-0.05022234017713452,-0.04125649637198059
186.40000000000194,24.721967312670333,-0.04711534045789107,-0.03993009691134164
187.50000000000196,24.826076281075476,-0.043025425010377046,-0.04263966337165259
188.60000000000196,24.932050548098655,-0.03817794218308777,-0.042544232598758835
189.70000000000198,25.03369256260164,-0.035864561197228036,-0.041282808734521836
190.800000000002,25.14215739320373,-0.03049769481470181,-0.04387992384766104
191.90000000000202,25.2459026802557,-0.025565135883248633,-0.04387992100000293
193.00000000000205,25.350739687331632,-0.022962180232702318,-0.04387992099999316
194.10000000000204,25.456418682835995,-0.01883267828795982,-0.04387993272462731
195.20000000000206,25.56074935675546,-0.015123581039385296,-0.04520312679137417
196.3000000000021,25.66527328623319,-0.0110105995170088,-0.04650090442916133
197.40000000000208,25.770558798332317,-0.006538215572525778,-0.04617914684297997
198.5000000000021,25.875118797882575,-0.0019346566666984613,-0.046179324528694554
199.60000000000213,25.98057863677936,0.0008440624790524388,-0.04749932092386455
200.70000000000215,26.08561059742372,0.004262922614536503,-0.04748936196589826
201.80000000000217,26.188678106943954,0.008768210142741704,-0.04880981865738043
202.90000000000217,26.294503541841852,0.014377966790059198,-0.04883611542273725
204.0000000000022,26.39958694800759,0.017937424339463062,-0.04979984299707363
205.1000000000022,26.504211317981397,0.022628198471423135,-0.05080868071389366
206.2000000000022,26.608209640205292,0.0270006058238566,-0.0507971992757037
207.30000000000223,26.713218700990208,0.03151031838743947,-0.051134386824618794
208.40000000000225,26.818375946571074,0.03367988948648649,-0.05244030821489476
209.50000000000227,26.922355978768934,0.03825903793465635,-0.0527589169223015
210.6000000000023,27.02762885245984,0.04180871028693256,-0.05538026652536976
211.7000000000023,27.13324361085234,0.0460761087661043,-0.055630263298376725
212.8000000000023,27.236818866551104,0.05029538336041291,-0.05670991872627473
213.90000000000234,27.34186391388016,0.0557531535758336,-0.05868049514929341
215.00000000000233,27.447232670012355,0.05968312063677508,-0.06004616967123022
216.10000000000235,27.552098221759547,0.06240541116401541,-0.06065950760507555
217.20000000000238,27.657222167382916,0.0674828027920209,-0.0619957923777239
218.3000000000024,27.762007378233083,0.07214584281777604,-0.06328986985666374
219.40000000000242,27.865848834408926,0.07833144908690653,-0.06597641297140999
220.50000000000242,27.97049315351987,0.08259819447893099,-0.0659298527397536
221.60000000000244,28.076025503915275,0.08439902874573399,-0.06854178577851933
222.70000000000246,28.181017534101045,0.0895424174722315,-0.06992925659338889
223.80000000000246,28.284232883539936,0.09585870554640058,-0.0712025087148831
224.90000000000248,28.390305116273243,0.10056641319985336,-0.0738187107794106
226.0000000000025,28.495435009976372,0.10425334137953161,-0.0751284613059946
227.10000000000252,28.600214257975797,0.10901391002751246,-0.07513873165155749
228.20000000000255,28.70491797725803,0.11351699651616631,-0.07907772188447382
229.30000000000254,28.809909554435976,0.11804993988505966,-0.08106032093438698
230.40000000000256,28.914690281238073,0.12297211164742176,-0.08344693374192991
231.5000000000026,29.01890900451556,0.12646896915808922,-0.08568194011271624
232.60000000000258,29.123085312513417,0.13043695065696848,-0.08828697670022878
233.7000000000026,29.22658662425084,0.13419313712026934,-0.09092002293141421
234.80000000000263,29.331557847708467,0.13887694884170917,-0.0935571234697874
235.90000000000265,29.436613930755907,0.14180695085712336,-0.09618301529904105
237.00000000000267,29.542989251340167,0.1460242902816198,-0.09829551181441243
238.10000000000267,29.64692414588945,0.15098900911344007,-0.10090445533509174
239.2000000000027,29.752636805071823,0.15352257679148862,-0.10497544271683434
240.3000000000027,29.85735986319467,0.15887759525672152,-0.10890747185604965
241.4000000000027,29.96223734536295,0.1630230993513142,-0.11023075435944918
242.50000000000273,30.067622237435426,0.16708413418136983,-0.11442097190281064
243.60000000000275,30.17294428680844,0.17083664046603625,-0.11886046958811303
244.70000000000277,30.277516681782604,0.1755612879244892,-0.12280364721350479
245.8000000000028,30.382469715783092,0.18223685118679128,-0.1270118504258826
246.9000000000028,30.487262126202666,0.18765845870505832,-0.13119536407990795
248.0000000000028,30.592080453265268,0.1917716723060505,-0.13557286454165451
249.10000000000284,30.69820639297339,0.19608624437465544,-0.13837262753451407
250.20000000000283,30.802465133410532,0.19832768518066105,-0.14158466059594543
251.30000000000285,30.907508191563878,0.20642929428487317,-0.14774419064620004
252.40000000000288,31.012293478586628,0.20887900756918754,-0.1544803596166764
253.5000000000029,31.11729477842542,0.21429400712037905,-0.15902245204516063
254.60000000000292,31.221885779705094,0.21716082438745085,-0.16337145174944157
255.70000000000292,31.32673619696688,0.22110526701945585,-0.16953568673793118
256.8000000000029,31.43160471999835,0.22379657063655892,-0.17455140230377797
257.90000000000293,31.53619215737478,0.22806129306261994,-0.18088050434726366
259.00000000000296,31.641620404656702,0.23134904660255745,-0.18555293012792218
260.100000000003,31.74511898094414,0.23585408576666883,-0.1940672572035309
261.200000000003,31.851395955365977,0.23540355033734653,-0.20097659928680445
262.300000000003,31.957015727269543,0.23825847335583072,-0.20620485270029976
263.40000000000305,32.05990046143818,0.24081199768929884,-0.21508504161642472
264.50000000000307,32.16555923005179,0.24443484401848092,-0.22201668170448263
265.6000000000031,32.27181596421554,0.2465210561270616,-0.22883563556501452
266.7000000000031,32.375573404603415,0.2495991953573333,-0.23710291808321093
267.8000000000031,32.48077864597386,0.25172046365510475,-0.24519534944571042
268.9000000000031,32.586518962845275,0.25437937857049453,-0.25395137044686367
270.0000000000031,32.691847026764854,0.2565784782806689,-0.2648276410418293
271.10000000000315,32.79588567876873,0.25909641219427754,-0.272685162113393
272.2000000000032,32.901303032026334,0.26052602902329275,-0.2834862659714905
273.30000000000314,33.006577112158226,0.2627210380694721,-0.2936649144795749
274.40000000000316,33.11205919271882,0.267876289197546,-0.30381049157703055
275.5000000000032,33.21688824931575,0.2739483159623014,-0.31567697667391803
276.6000000000032,33.322419287614885,0.2799124736281744,-0.3294041784338564
277.70000000000323,33.42751955181332,0.2885730474335394,-0.34181517738591616
278.80000000000325,33.53265541517048,0.30115959121492125,-0.355761527571119
279.9000000000033,33.63849007058167,0.31086153384858145,-0.36893922698448245
281.0000000000033,33.74386696471904,0.32520422020976464,-0.3847848923318846
282.1000000000033,33.84883653019603,0.3393274910511811,-0.39904100650743546
283.20000000000334,33.95434437798824,0.3544960221923886,-0.41162300964581133
284.30000000000337,34.05990866604304,0.36814976526721643,-0.4277580888958772
285.40000000000333,34.16506923011734,0.3798187992928924,-0.4433207235173575
286.50000000000335,34.2702096003042,0.3941621843017818,-0.45885036422446523
287.6000000000034,34.376558644388766,0.40803040667680934,-0.47402111615177667
288.7000000000034,34.48173256802405,0.41717374762634724,-0.48765172108800225
289.8000000000034,34.58685214372692,0.4254511784932506,-0.5033341633651705
290.9000000000034,34.69236812390051,0.42938466897018623,-0.5168426951466909
292.0000000000034,34.79690881770083,0.4296033104480618,-0.529847480258963
293.10000000000343,34.90304913721531,0.4305464817253659,-0.5422989386567503
294.20000000000346,35.00806927075641,0.4306409865834923,-0.5554179454335677
295.3000000000035,35.11372862935243,0.4255091755576853,-0.5665582437271168
296.4000000000035,35.218689935323866,0.4193073379398282,-0.5790963626149495
297.5000000000035,35.32484569577585,0.4126624964972055,-0.5873439165310952
298.60000000000355,35.42999899976144,0.4041801130285263,-0.5977328516619127
299.70000000000357,35.5351866129369,0.39571033138177414,-0.6054808874689184
300.8000000000036,35.641180867806824,0.3860151720840711,-0.6140606746536283
301.9000000000036,35.74686952849137,0.3777548794241983,-0.6230756847713801
303.0000000000036,35.851637517553634,0.3689020843665278,-0.6305249769469059
304.1000000000036,35.957114671919534,0.3620753708191403,-0.6373029450169221
305.2000000000036,36.06235626806929,0.35492880122768933,-0.6443031119870315
306.30000000000365,36.16779305009254,0.3496407105452964,-0.6503722721017149
307.4000000000037,36.271782782008685,0.342043463971822,-0.655227644653583
308.5000000000037,36.37758954173149,0.3386108978363454,-0.6605512510328082
309.60000000000366,36.48373895099935,0.33390372820618436,-0.6661521562805683
310.7000000000037,36.58782594133146,0.3274455815433043,-0.6701199974895369
311.8000000000037,36.693849059413054,0.32412108747091495,-0.6748786517661935
312.90000000000373,36.79924891724291,0.321501277166752,-0.6792932770970794
314.00000000000375,36.905250127999096,0.3186573513134656,-0.6826867085628892
315.1000000000038,37.01086758524097,0.3150541247600722,-0.6864855036699615
316.2000000000038,37.115024353474666,0.3133126707224273,-0.6917806074161619
317.3000000000038,37.22082998283542,0.31233783426423245,-0.6958065131514455
318.40000000000384,37.32658684035001,0.30911832891424823,-0.6991957864330947
319.5000000000038,37.432673072254744,0.3056845896521064,-0.7004637559532303
320.60000000000383,37.537738334197584,0.30432082800572907,-0.7057768552865711
321.70000000000385,37.64385893920995,0.30332190674722614,-0.7086793372389466
322.8000000000039,37.74964003660279,0.2993076499244557,-0.7099996269677602
323.9000000000039,37.85482880231469,0.3002638312760708,-0.7139211351824146
325.0000000000039,37.96110740531876,0.29879735567544713,-0.714358509129513
326.10000000000394,38.0671423904804,0.29861580090505874,-0.7194108015920242
327.2000000000039,38.17307585415066,0.2958681557918819,-0.7217677712625279
328.30000000000393,38.278155310723726,0.2958089293925394,-0.7248084041696816
329.40000000000396,38.3847366856487,0.29516625543530506,-0.726064361810538
330.500000000004,38.49030049982004,0.2939276312354771,-0.728749392981082
331.600000000004,38.59524675203106,0.29539652818457196,-0.7300599300825437
332.700000000004,38.70138579689676,0.29313163199281145,-0.7326977245061168
333.80000000000405,38.80843670890606,0.2942006128480287,-0.7340186455043702
334.90000000000407,38.91368550668502,0.2934012182910107,-0.7362870556175647
336.0000000000041,39.01961068859354,0.2924017887950389,-0.737970119852978
337.10000000000406,39.12521924622226,0.29348371234328074,-0.7392736402625455
338.2000000000041,39.231347021527874,0.293833478879404,-0.7406148787110007
339.3000000000041,39.337461047915426,0.2940449668748333,-0.7435829900719115
340.4000000000041,39.443395141774715,0.2941145309680372,-0.7435302871427911
341.50000000000415,39.549082824959854,0.2945385283469498,-0.7461821825798842
342.6000000000042,39.655852924695665,0.2978482565031918,-0.7461899146017084
343.7000000000042,39.761681527107754,0.2973715542877725,-0.7468499042342027
344.80000000000416,39.867208929539835,0.29853792045454236,-0.748170544823691
345.9000000000042,39.972745344862716,0.29965344035164126,-0.7494797888929954
347.0000000000042,40.079899416278806,0.30012424737345117,-0.7494794500345359
348.10000000000423,40.186806127825264,0.3014304980397231,-0.7511200648070653
349.20000000000425,40.29123779712163,0.30520197163605334,-0.752785958290831
350.3000000000043,40.39963665493842,0.3057454650967868,-0.7540900742192074
351.4000000000043,40.504072606295104,0.3091742457310794,-0.7540900468894418
352.5000000000043,40.610880602787105,0.3116397364167262,-0.7554100219855577
353.60000000000434,40.71793008979913,0.3124276955656353,-0.755409906956277
354.7000000000043,40.824362426780546,0.3156222042762669,-0.7567267180218575
355.80000000000433,40.930576402241925,0.3180268806569705,-0.7580578217444707
356.90000000000435,41.037748479454976,0.3185362295830184,-0.7588172539468188
358.0000000000044,41.14377527855768,0.3187712673827194,-0.7593601049496193
359.1000000000044,41.25087187885339,0.32067492141760073,-0.7593601050185317
360.2000000000044,41.35724144713813,0.32077703500293936,-0.7595466157912139
361.30000000000445,41.46407331369737,0.322640072664939,-0.7607095028016717
362.4000000000044,41.57080900494108,0.3225467871554321,-0.7619900827741057
363.50000000000443,41.67740971793892,0.3253219571783873,-0.7619220850514474
364.60000000000446,41.78300170586734,0.329354881247704,-0.7633103097435625
365.7000000000045,41.88999902865118,0.33059999040515,-0.7633096366373948
366.8000000000045,41.99650691834302,0.3345037869961727,-0.7655830671926149
367.9000000000045,42.102162241133335,0.3364675823600835,-0.7642903182866334
369.00000000000455,42.2094867157659,0.3409102582797766,-0.7646198896398566
370.10000000000457,42.31541531445712,0.343986751552504,-0.7672598495583429
371.2000000000046,42.42377810940951,0.34665686567629905,-0.7685816198670223
372.30000000000456,42.52966265227802,0.34819393882461924,-0.7679201745517679
373.4000000000046,42.63712285676013,0.34970478610703976,-0.7672616720705476
374.5000000000046,42.742190917297634,0.35248198166177,-0.7685698558699317
375.6000000000046,42.85054953304386,0.3570004124023755,-0.7696066065498086
376.70000000000465,42.957493183641326,0.36056549323541875,-0.7698900919894842
377.8000000000047,43.06406052443066,0.3632333942152337,-0.7698900918971221
378.9000000000047,43.17130846729394,0.3678501344687445,-0.7712682338620822
380.00000000000466,43.27655027256258,0.36975916285669486,-0.7711599914924396
381.1000000000047,43.384143550398285,0.3728004903780799,-0.7725200713712335
382.2000000000047,43.49076845781771,0.3773579669910561,-0.7725210375327278
383.30000000000473,43.59675684745755,0.37909729163790323,-0.773610596702694
384.40000000000475,43.70332473870887,0.3835213694915925,-0.773835022193484
385.5000000000048,43.80972119025279,0.38499841972012316,-0.7751500472635002
386.6000000000048,43.91645132369538,0.38970578037624143,-0.7751497300862966
387.7000000000048,44.02324204547605,0.39268666428444093,-0.7774610621515325
388.80000000000484,44.13065747970332,0.3940963766564856,-0.778781496636916
389.9000000000048,44.23727823691562,0.3969140246735018,-0.7784424218666937
391.00000000000483,44.34341883005097,0.40277151036836806,-0.7794299157330835
392.10000000000485,44.45111607607896,0.4034478641444829,-0.7797788913734536
393.2000000000049,44.55879519419845,0.40587783719438975,-0.7810808526069022
394.3000000000049,44.66475578730246,0.4104172546257013,-0.7810818598678573
395.4000000000049,44.77221761083937,0.4117222357056914,-0.781069600479869
396.50000000000495,44.8781427383566,0.41512537293540913,-0.783709306494615
397.6000000000049,44.985978982724106,0.41708498063808536,-0.7837095682924464
398.70000000000493,45.09298014325096,0.4194643365637783,-0.7850299113206698
399.80000000000496,45.19929426261165,0.4221364056095356,-0.7863371985604268
400.900000000005,45.30721227481607,0.4235315715384236,-0.786363623179803
402.000000000005,45.415382730222376,0.4267600949676744,-0.7876614680888672
403.100000000005,45.522275583773876,0.4286198103400737,-0.788001223377452
404.20000000000505,45.629604940468475,0.4310309241666663,-0.7902966843444692
405.30000000000507,45.73679960854224,0.4331551189037487,-0.7912917007001434
406.4000000000051,45.8441239729308,0.43518503585897483,-0.7926927526489673
407.50000000000506,45.952512559156354,0.4378913350718401,-0.7925976504681791
408.6000000000051,46.05961205581771,0.4400355350588389,-0.7939100315783141
409.7000000000051,46.16689540208256,0.44306082760099197,-0.7952271050358237
410.8000000000051,46.27503951839848,0.4433784983569934,-0.7962417092756775
411.90000000000515,46.382396859695135,0.44552474642761025,-0.7971984695087135
413.0000000000052,46.48969134453105,0.4471920799460289,-0.7985119343507794
414.1000000000052,46.59767003534979,0.44933903416636917,-0.7998298787463867
415.20000000000516,46.70473133535954,0.44974277128771595,-0.8011520624573247
416.3000000000052,46.813615650339166,0.4528527800709802,-0.8037775584327176
417.4000000000052,46.91916161679877,0.4544758675707318,-0.805109873822321
418.50000000000523,47.0290281826869,0.4581554759320885,-0.8064097530103389
419.60000000000525,47.13623906295772,0.45952695261535853,-0.8077411853564076
420.7000000000053,47.24256953425738,0.4625808151470971,-0.8089763217519899
421.8000000000053,47.350862540840346,0.46526085663876743,-0.8116799191166275
422.9000000000053,47.45858299379517,0.4689378297675725,-0.8129256979597486
424.00000000000534,47.5666697034496,0.4694975858219475,-0.81562859034364
425.1000000000053,47.67417659376408,0.4742760579558938,-0.8169363483809109
426.20000000000533,47.782102778304704,0.47790105919254217,-0.8194160628454452
427.30000000000535,47.888849438482396,0.48241921200109517,-0.8208340711633526
428.4000000000054,47.99620898586172,0.4854306055625909,-0.8236049163244847
429.5000000000054,48.1044580886797,0.48906770856320475,-0.8261627546477643
430.6000000000054,48.21227155180208,0.49188477037194256,-0.828767598742381
431.70000000000545,48.32099448684604,0.4966358645555094,-0.8301536771292377
432.8000000000054,48.42739586717249,0.49984395770651985,-0.8326216993030471
433.90000000000543,48.53589479839173,0.5024144418247717,-0.8354807145002319
435.00000000000546,48.643385426173424,0.5089290436413403,-0.8390760432848814
436.1000000000055,48.750286115504615,0.5105652669501933,-0.8418400427925823
437.2000000000055,48.85850326264834,0.5161194399332977,-0.8434081837033411
438.3000000000055,48.965335442782745,0.5200849696257187,-0.8472028737126553
439.40000000000555,49.07353404421764,0.5244845302955327,-0.8512690186051621
440.50000000000557,49.18127373772962,0.5293165733024253,-0.854000618998195
441.6000000000056,49.28899326957698,0.5331265162662759,-0.8597527411889478
442.70000000000556,49.39687231820493,0.5412242507703352,-0.862469458652039
443.8000000000056,49.50422159332384,0.5454836636596533,-0.8665151441456955
444.9000000000056,49.61230736814457,0.5511455587872832,-0.869053364647363
446.0000000000056,49.7195750486967,0.5573755557037466,-0.8737264305483676
447.10000000000565,49.82769908262334,0.5627065047076357,-0.8782789730563132
448.2000000000057,49.93592558251996,0.5696588561546538,-0.883578350643548
449.3000000000057,50.0441897599774,0.5750078106103076,-0.8883874294612784
450.40000000000566,50.15236993115878,0.5830910901967037,-0.8923625149652059
451.5000000000057,50.259796150716916,0.5892186652417439,-0.8978222599556895
452.6000000000057,50.368658183308355,0.5949323344064276,-0.9016378802397611
453.70000000000573,50.47641254221015,0.6007256749871477,-0.9059766588729596
454.80000000000575,50.584722582409796,0.6079972060712311,-0.9112817387206791
455.9000000000058,50.692288300243675,0.6137227780829655,-0.9168244715789049
457.0000000000058,50.80077874402567,0.621836955899603,-0.9216787673940496
458.1000000000058,50.90865399060591,0.6297985164359137,-0.9257542725142418
459.20000000000584,51.01760548258696,0.6364703096643807,-0.9313072217995257
460.3000000000058,51.12544800020224,0.6417089491862423,-0.9354175448596935
461.40000000000583,51.23457403740579,0.6492365560573837,-0.940113484255408
462.50000000000585,51.34294973039015,0.6531151631603275,-0.9459409820214466
463.6000000000059,51.45083548040035,0.6579164529025301,-0.9493149615269707
464.7000000000059,51.56038179208697,0.6635125072832219,-0.9552454215280473
465.8000000000059,51.66759408519615,0.6709063483038099,-0.9594147790920995
466.90000000000595,51.776298400084535,0.6758527839766229,-0.964141410421532
468.0000000000059,51.885183973460514,0.6828092763466596,-0.9682007616880739
469.10000000000593,51.993610489196534,0.6882154468486531,-0.9749774644035711
470.20000000000596,52.100796299935695,0.6925141089502915,-0.9779768912209268
471.300000000006,52.20924564619713,0.6972781656571054,-0.9802022444997767
472.400000000006,52.31726093961229,0.7006721705180727,-0.9851819447365613
473.500000000006,52.42584009271761,0.7072247654605033,-0.9896422247663361
474.60000000000605,52.533960145645175,0.711918905721421,-0.992564970205728
475.70000000000607,52.6422084022856,0.714100921029556,-0.9963574019711503
476.8000000000061,52.75087564506508,0.7197003880785318,-1.000779808735278
477.90000000000606,52.860492802356745,0.7242184333088381,-1.0028984109065058
479.0000000000061,52.96872584992357,0.7292752011154918,-1.0060623067882006
480.1000000000061,53.077632715324086,0.7336683659797995,-1.0101348971122315
481.2000000000061,53.18634644998452,0.7358336109620877,-1.0116331378119696
482.30000000000615,53.29542428636862,0.7419797655880658,-1.0148002148780626
483.4000000000062,53.403094635972785,0.7468222254371655,-1.018445630637102
484.5000000000062,53.511926386411744,0.7506844235847754,-1.0197569535027111
485.60000000000616,53.62071991004748,0.7583280899229441,-1.024046035766308
486.7000000000062,53.73048949805275,0.762391315640317,-1.025348956573696
487.8000000000062,53.837773242689025,0.7658299222547192,-1.0280884359584168
488.90000000000623,53.947034504785094,0.7691215018351708,-1.0304667474602867
490.00000000000625,54.056014735064615,0.7742262889376907,-1.0320188720095458
491.1000000000063,54.16470453869165,0.7799474630025299,-1.0338380672166694
492.2000000000063,54.27154244596007,0.7859813896249953,-1.036041793368974
493.3000000000063,54.38112686352666,0.7875998494771386,-1.0371095449049523
494.40000000000634,54.489900789587224,0.7888304803094278,-1.0400500855516803
495.5000000000063,54.59875835280118,0.7945755036664427,-1.0422274072193556
496.60000000000633,54.707735064370915,0.7982899714472288,-1.0430113217498165
497.70000000000636,54.81670988943923,0.8017227784514313,-1.0443203426345984
498.8000000000064,54.92622787534448,0.8052832851574345,-1.044904016151197
499.9000000000064,55.03484430111253,0.8083470120433277,-1.0469480894986525
501.0000000000064,55.143117488477245,0.8153643804665204,-1.0479402871733914
502.10000000000645,55.25171688310173,0.8186241765445837,-1.0485987310799785
503.2000000000064,55.35999900770802,0.8213797486015089,-1.050020176832147
504.30000000000643,55.46871626354638,0.825619282666325,-1.0526597015066907
505.40000000000646,55.57641214169799,0.8341973725677401,-1.0530170181095668
506.5000000000065,55.687168057039145,0.838459807367483,-1.055291966667502
507.6000000000065,55.79524070260198,0.8437230573056062,-1.0556272195776866
508.7000000000065,55.90404779250851,0.8499922768527374,-1.0569646424649797
509.80000000000655,56.012959943851556,0.8533008740586194,-1.0584815015907645
510.90000000000657,56.12082507424814,0.8582032486380478,-1.0619775568668386
512.0000000000066,56.23072157761084,0.8638524443886015,-1.0601235773499011
513.1000000000065,56.33835192338259,0.8680065757551443,-1.0614572317726307
514.2000000000066,56.44840935872342,0.8760213963750324,-1.0627501131230277
515.3000000000065,56.55774917853084,0.8810351327691739,-1.0627559325039382
516.4000000000067,56.666161211013026,0.8885598261761314,-1.0663612364197368
517.5000000000066,56.77487224287685,0.9001001850710707,-1.065648737552003
518.6000000000067,56.88438292006408,0.9114853658704581,-1.067989378944671
519.7000000000066,56.99275889795425,0.9244009339239683,-1.0694215229630637
520.8000000000067,57.1015916423703,0.9380692446079972,-1.070650154205251
521.9000000000067,57.21011033701114,0.9506263081146239,-1.0713193943224897
523.0000000000067,57.31989905353188,0.9582512000630187,-1.0736101884659872
524.1000000000067,57.429130471615125,0.96845036612846,-1.075260822234723
525.2000000000068,57.53779342566401,0.9790148058211973,-1.0765939400610658
526.3000000000068,57.647497532809716,0.9847887608995738,-1.0768482864740205
527.4000000000068,57.75724773304127,0.9905183933601581,-1.0794226155656275
528.5000000000068,57.86644331562006,1.0017711001071112,-1.0821699721390545
529.6000000000068,57.97458037146354,1.0084704024304456,-1.0821577440734855
530.7000000000069,58.08394829272109,1.0154890145973345,-1.08601871502401
531.8000000000068,58.194602503808525,1.0242121418635637,-1.0874284776868994
532.9000000000069,58.30283618452779,1.0320045036967997,-1.087417118819225
534.0000000000068,58.412696740551695,1.0395771358874017,-1.08932551562528
535.100000000007,58.52280592595538,1.0472252920797218,-1.0913786668645713
536.2000000000069,58.631126883934144,1.055070291411988,-1.09269645838959
537.300000000007,58.74053765146713,1.0606973693988861,-1.0953275820888089
538.4000000000069,58.850497986930584,1.0660012882925682,-1.0966407849980206
539.5000000000069,58.95957101916544,1.0712020823935484,-1.099276563976216
540.600000000007,59.067788678734416,1.0778998572121012,-1.101393836259661
541.700000000007,59.17833205938727,1.0814367439038661,-1.1011225498265982
542.800000000007,59.28820032410316,1.0859660547413124,-1.1042119945010658
543.900000000007,59.397280775773076,1.0870923902770702,-1.106833569718641
545.000000000007,59.50682635093372,1.0893638024184644,-1.1081598387957046
546.1000000000071,59.61711042341239,1.0905396366488371,-1.1107724909386518
547.2000000000071,59.726273675012536,1.0871931779137791,-1.1121100350433348
548.300000000007,59.83546375959235,1.0920825933066975,-1.1147416085608097
549.4000000000071,59.94546380956057,1.0937483804385848,-1.1164775865343044
550.500000000007,60.05434911773922,1.0973719990204398,-1.117641002989675
551.6000000000072,60.16281858804246,1.1000095447636151,-1.1202758530815733
552.7000000000071,60.273436091296084,1.105388081876598,-1.1212912037964946
553.8000000000072,60.38279600025674,1.1114628617109226,-1.1238686110935627
554.9000000000071,60.49262093310594,1.1153885648761437,-1.1252680379381843
556.0000000000072,60.60225234640534,1.119635193050866,-1.1280947939242258
557.1000000000072,60.71274460459917,1.1250060587785695,-1.130646557986767
558.2000000000072,60.82304339284198,1.1280924139212356,-1.1331372861270776
559.3000000000072,60.932666026888924,1.1332770193153607,-1.133798128002843
560.4000000000073,61.04236457139416,1.1362953354821639,-1.1364609294927956
561.5000000000073,61.152258379454565,1.1424249085793157,-1.13893049155207
562.6000000000073,61.262405336484,1.1452331754952076,-1.1419289435408784
563.7000000000073,61.37234541788653,1.1547286364123088,-1.1432727721744214
564.8000000000073,61.48186354869009,1.162375847987364,-1.1447322704321006
565.9000000000074,61.591580604948454,1.1700155847868703,-1.1479626047541949
567.0000000000074,61.70114241635564,1.179687296627878,-1.1506335763270132
568.1000000000074,61.811071533767304,1.1930095910044647,-1.1532848076950253
569.2000000000073,61.92019847267196,1.2061739184575784,-1.1549061713754263
570.3000000000073,62.029293296415176,1.2176563922710901,-1.1571404796320048
571.4000000000074,62.14030656025758,1.2325087047483319,-1.1591572963895471
572.5000000000074,62.251602430150236,1.2477662399195415,-1.1617980307403042
573.6000000000074,62.361983202490336,1.2618527077452044,-1.1638268514496937
574.7000000000074,62.47186338777666,1.2752358880040875,-1.168021507800753
575.8000000000075,62.58207393573717,1.2909634589892354,-1.1706609970133286
576.9000000000075,62.69190371762807,1.31070824015702,-1.1733735847432234
578.0000000000075,62.802080765186176,1.331490210953136,-1.1771760166167429
579.1000000000075,62.912869377054186,1.3511505112248694,-1.1799887536272373
580.2000000000075,63.0238112598252,1.3712860693674647,-1.1822554976286703
581.3000000000076,63.13306093553325,1.386945018761112,-1.1853731889534154
582.4000000000076,63.24373442917115,1.4036936740234833,-1.1895560517643058
583.5000000000076,63.35325216664621,1.4168461680329743,-1.1939103361674457
584.6000000000076,63.463008334144405,1.4206953536386469,-1.1980394318739793
585.7000000000077,63.57355617860502,1.4161766963855618,-1.1998828741516463
586.8000000000077,63.68441019902769,1.4036776283565804,-1.2039335561956581
587.9000000000076,63.794015189619834,1.3747442019161484,-1.2084232716871974
589.0000000000076,63.904513147195274,1.324800730278469,-1.2121648406168521
590.1000000000076,64.01311204623215,1.2784458421801435,-1.2138300812314924
591.2000000000077,64.12358147823232,1.2381805938846522,-1.2165242470549669
592.3000000000077,64.2328385895534,1.2072292675505842,-1.217850457831477
593.4000000000077,64.3441073560496,1.1869403877683462,-1.2204634472089926
594.5000000000077,64.45348184527884,1.1798518253369454,-1.220418410766773
595.6000000000078,64.5638288156887,1.1743796955906307,-1.2217998062157496
596.7000000000078,64.67272662510553,1.1737950927898129,-1.221711243995768
597.8000000000078,64.7840718974443,1.1716015414278436,-1.2221197801520796
598.9000000000078,64.89510012062797,1.1733533349405787,-1.2234451669997801
600.0000000000078,65.00426735084142,1.1774859257232706,-1.2247514341242791
601.1000000000079,65.11439233214413,1.1829669166016465,-1.225241510479857
602.2000000000079,65.22435640505775,1.1890262803128013,-1.224421049111403
603.3000000000079,65.33442639992778,1.1982163853746624,-1.2270599216598064
604.4000000000078,65.44521485058961,1.2099623592544715,-1.2278572596355692
605.5000000000078,65.55515239061486,1.2249064177209041,-1.227060257200269
606.6000000000079,65.66580547559491,1.2422741935968131,-1.228378762467805
607.7000000000079,65.77641650377163,1.2577745848109818,-1.2297002190319186
608.8000000000079,65.88678487899362,1.2708827231616342,-1.231016910871738
609.9000000000079,65.99799072887981,1.288604065376548,-1.230979642332632
611.000000000008,66.10741144595399,1.3017583884551418,-1.231037257288191
612.100000000008,66.21897571946707,1.316052627978659,-1.232320391193571
613.200000000008,66.32948930280686,1.3292074250791213,-1.2349628113321964
614.300000000008,66.43978104727685,1.3469688800964799,-1.2365999434568726
615.400000000008,66.55055297002438,1.3578654089633706,-1.237254674613983
616.5000000000081,66.66174248281257,1.3705080656103776,-1.2385770479382732
617.6000000000081,66.77173109695107,1.3843455503707098,-1.2406908516298283
618.7000000000081,66.88192713407174,1.4002386220801166,-1.2425689048745956
619.8000000000081,66.992317088088,1.4125302988164885,-1.2431135304472951
620.9000000000082,67.1030722099824,1.427243996064795,-1.2457849534987946
622.0000000000082,67.21314227254554,1.4408045186644824,-1.2471580458481584
623.1000000000081,67.32447045877076,1.4562758726459473,-1.248434996506477
624.2000000000081,67.43416833637421,1.4711859919557897,-1.2524749143130611
625.3000000000081,67.54394634364212,1.4848835222865435,-1.2537099169557506
626.4000000000082,67.65450962475573,1.5019790335124532,-1.2539385782138273
627.5000000000082,67.764605318901,1.5175904739605353,-1.2565744928760103
628.6000000000082,67.874897985075,1.5338773109936286,-1.2590370892707754
629.7000000000082,67.98529812879835,1.5507565761278985,-1.2625219702775654
630.8000000000083,68.0955078105195,1.5659531303991012,-1.2643402469418898
631.9000000000083,68.2071878688094,1.584434061246624,-1.2698723032133805
633.0000000000083,68.31701998865127,1.6009789087491701,-1.2702870042412018
634.1000000000083,68.42775752816868,1.61742942771809,-1.2723662443690267
635.2000000000083,68.53762293728147,1.635381251391815,-1.2758316246617163
636.3000000000084,68.64907275273481,1.6558175852318435,-1.279174663588249
637.4000000000084,68.75913035697565,1.6730536398064346,-1.2821653242116327
638.5000000000084,68.86837604886739,1.6922088697767124,-1.2846674662346143
639.6000000000083,68.9786693220077,1.7103892042651574,-1.2882441068207076
640.7000000000083,69.08938451559223,1.730778533839937,-1.291420027480041
641.8000000000084,69.19959932819901,1.7512226567902456,-1.2974429333715434
642.9000000000084,69.31121230532545,1.7759097562175454,-1.3011726890116337
644.0000000000084,69.42266940079173,1.8003967544773045,-1.3041513477527702
645.1000000000084,69.5333979895838,1.823950884831889,-1.3097162551796981
646.2000000000085,69.64406855370237,1.8462279956086929,-1.3099756521536694
647.3000000000085,69.75490826605922,1.8724235040979795,-1.316172436290611
648.4000000000085,69.86434680523287,1.8989820131794655,-1.320317425539368
649.5000000000085,69.97535683485195,1.9255064810306917,-1.325339374212474
650.6000000000085,70.08482586676199,1.9503524316430212,-1.3295075767327957
651.7000000000086,70.19649694718858,1.977431290903788,-1.3343150320098522
652.8000000000086,70.30655995573858,2.004566112300435,-1.3386022899871364
653.9000000000086,70.41632982046143,2.0328491335264283,-1.3435756794081688
655.0000000000086,70.52839794398017,2.0614831847372233,-1.3486723822088882
656.1000000000087,70.63808823539412,2.088263180542954,-1.3543604100400453
657.2000000000087,70.7493791019202,2.113327568591305,-1.3596001191844769
658.3000000000086,70.86087845670494,2.141667347282556,-1.3624534995931454
659.4000000000086,70.9703143032767,2.1727730060062598,-1.3686547688669513
660.5000000000086,71.08194623941154,2.2042202212800053,-1.3750087947961687
661.6000000000087,71.193530653532,2.235001236429803,-1.3797057175997995
662.7000000000087,71.30316225371764,2.267340827963626,-1.3848546288816488
663.8000000000087,71.41342489272509,2.2987732264710363,-1.3913040203621332
664.9000000000087,71.52572151569395,2.333313610820288,-1.3945011469225692
666.0000000000088,71.63635163222716,2.3687211416998832,-1.4024951452673937
667.1000000000088,71.74635681626563,2.4046062865948543,-1.4080743741776423
668.2000000000088,71.85798298276485,2.4395808057712824,-1.4139682160942169
669.3000000000088,71.96894233329824,2.4795426265264595,-1.4200686869720247
670.4000000000088,72.08074682108165,2.5278998036553064,-1.4262775361613418
671.5000000000089,72.19153744314237,2.572612648253668,-1.4316566729052527
672.6000000000089,72.30083132017481,2.6236641863637717,-1.4401637285368647
673.7000000000089,72.41130900737738,2.6827449873957407,-1.447137815646835
674.8000000000088,72.5243065016412,2.741156826910992,-1.455925399664324
675.9000000000088,72.63557098342912,2.805282335958752,-1.462072272533721
677.0000000000089,72.74577359269213,2.869913504615882,-1.4725048214753529
678.1000000000089,72.85731377844071,2.9455829360316805,-1.481404286099088
679.2000000000089,72.96830755362524,3.025682110923679,-1.4894664268761177
680.3000000000089,73.07987858173209,3.114409450189579,-1.4991893585573437
681.400000000009,73.19161811376328,3.20729628545434,-1.5089627687648157
682.500000000009,73.30300906013224,3.3126106495599856,-1.5192861014174421
683.600000000009,73.41396202563854,3.425669133413535,-1.5306532773825223
684.700000000009,73.5248288688339,3.5531342787262132,-1.5414430833375046
685.800000000009,73.63685909693086,3.6808096469422797,-1.553243658060318
686.9000000000091,73.74853820158509,3.7819564996584956,-1.5669937918063606
688.0000000000091,73.8597785088945,3.8280087582134823,-1.5787828218772755
689.1000000000091,73.97172173305366,3.8323700786830615,-1.5930487180964024
690.2000000000091,74.08304356372714,3.8309138356990697,-1.608135020582253
691.3000000000092,74.19440420341375,3.8420461793078036,-1.6230699688567372
692.4000000000092,74.30558837661317,3.8646447246784046,-1.6383694048908897
693.5000000000091,74.41654210812352,3.898473051251003,-1.6528195163209625
694.6000000000091,74.5280621001136,3.9361670355882756,-1.668142211237984
695.7000000000091,74.63967870982731,3.9767565406727305,-1.6845244269016493
696.8000000000092,74.75140568416404,4.016377041423395,-1.6997426915365295
697.9000000000092,74.8626770224161,4.059675996810208,-1.7160066990436142
699.0000000000092,74.97375737146453,4.095892398862884,-1.7326192366992048
700.1000000000092,75.08425572228346,4.13519786798895,-1.7495440064237906
701.2000000000093,75.19577766528367,4.171387797794457,-1.7669446498753247
702.3000000000093,75.30766529741084,4.20413740461226,-1.7846314987921943
703.4000000000093,75.41794481680559,4.233853994879583,-1.8016595890064524
704.5000000000093,75.52832959324157,4.259377877232797,-1.8187246079662098
705.6000000000093,75.64041085593847,4.279911729156482,-1.837103538688904
706.7000000000094,75.7519728795601,4.29325106189206,-1.8539969468145978
707.8000000000094,75.86309502103526,4.302500685653695,-1.872271805640933
708.9000000000094,75.97453239803279,4.306280454932329,-1.8904894829981789
710.0000000000093,76.0863408502388,4.310877801520443,-1.9069127057083008
711.1000000000093,76.19725950303153,4.304155530890599,-1.9260060662100371
712.2000000000094,76.30837945100087,4.300432120113558,-1.943023080524751
713.3000000000094,76.41989635928276,4.290656333904057,-1.9609509295538023
714.4000000000094,76.53169081989735,4.280607222089401,-1.9774836664730948
715.5000000000094,76.642295203533,4.264681063899781,-1.9937276925764778
716.6000000000095,76.75403902036828,4.243874525636576,-2.0123614744771654
717.7000000000095,76.86496876463521,4.200888650544823,-2.0288309273519873
718.8000000000095,76.97576658289272,4.145252760985736,-2.0447291263436895
719.9000000000095,77.08737466176565,4.049317856093729,-2.0596909750045436
721.0000000000095,77.19818007255623,3.906248450262617,-2.0761664363362726
722.1000000000096,77.30917068846294,3.693929962529796,-2.0895203061112113
723.2000000000096,77.42040871662995,3.3602505382188617,-2.1032752071870595
724.3000000000096,77.53059566742948,2.8541634764389827,-2.110537928756286
725.4000000000096,77.63979618910594,2.074623615438143,-2.118903260311308
726.5000000000097,77.75009802608601,1.8895864337129733,-2.1218805346646388
727.6000000000097,77.85980174095403,1.8669744087686224,-2.1245200198415777
728.7000000000096,77.97093581096063,1.86386726162309,-2.1258429083037997
729.8000000000096,78.08209069994604,1.8702520481056748,-2.1251656872093587
730.9000000000096,78.19327615036966,1.8797555261039576,-2.125483493848842
732.0000000000097,78.30374918634854,1.8885831669574367,-2.1258229607460697
733.1000000000097,78.41662972927574,1.8973313611238813,-2.1258943120730067
734.2000000000097,78.52844761530314,1.9066197550510067,-2.1268198849110833
735.3000000000097,78.6401180493816,1.9148990227375549,-2.126819885059355
736.4000000000098,78.75070147993677,1.924026354405653,-2.1265044745352784
737.5000000000098,78.86200186751434,1.934668627621812,-2.1261499802609585
738.6000000000098,78.97388931143169,1.9433308343044002,-2.1261499711723166
739.7000000000098,79.08618351711804,1.9497532695649265,-2.1264795584733385
740.8000000000098,79.19739932281752,1.9588954170196764,-2.1277860746305537
741.9000000000099,79.3078612026759,1.9696002158692443,-2.1278033013742492
743.0000000000099,79.41957410950756,1.9763249127580287,-2.1277981983323753
744.1000000000099,79.53259589982312,1.9852479610791867,-2.1278103361140706
745.2000000000098,79.64437552774665,1.9953984668171314,-2.126756029583191
746.3000000000098,79.75587097944529,2.005299867455217,-2.1287518326582884
747.4000000000099,79.8678304887159,2.012459815871629,-2.128789828042293
748.0000000000099,79.92896884496416,2.0175686480576855,-2.1287335710632025