File: 01_Data/PE_Foam_Pipe_Insulation/STA/N2/10K_min/PE_Foam_Pipe_Insulation_STA_N2_10KData_220923_R2.csv
##Temp./Â°C,Time/min,DSC/(mW/mg),Mass loss/mg
51.0,10.76300835701429,-1.5626857930369862,-0.02133947944534956
51.80000000000001,11.054620833745252,-1.4419552694562994,-0.044176497711609565
52.60000000000002,11.261730963361758,-1.3569312278957633,-0.06261553635742463
53.400000000000034,11.427463565451498,-1.2900642476432707,-0.07184616535932407
54.200000000000045,11.576822923752493,-1.2332068017689854,-0.08299087057481314
55.00000000000006,11.716565212331108,-1.183453261747364,-0.09202004660313624
55.80000000000007,11.845714725186903,-1.142237542133186,-0.0988246368487443
56.60000000000008,11.96749971200267,-1.105321710284167,-0.10619143875996209
57.40000000000009,12.085591559041465,-1.070061393653729,-0.11108638913873711
58.2000000000001,12.201081358992658,-1.0415179463676556,-0.11623836720838858
59.000000000000114,12.310555596051413,-1.014001541418366,-0.12103003510688196
59.800000000000125,12.424680855243105,-0.9884166482748318,-0.12499957198616703
60.600000000000136,12.529292799276956,-0.9711291884343689,-0.1280618882380802
61.40000000000015,12.634880455876461,-0.9553913492842998,-0.13184040454547155
62.20000000000016,12.734768524948807,-0.9417034447893631,-0.13452035927355904
63.00000000000017,12.837371608329306,-0.9310192112708272,-0.13832425850856556
63.80000000000018,12.938894286477565,-0.921327573665216,-0.1407458560276193
64.6000000000002,13.038549063828725,-0.9115396840166091,-0.14252243250230015
65.4000000000002,13.135779318804897,-0.9023049479168024,-0.14608331624021859
66.20000000000022,13.232717140569632,-0.8910473588397646,-0.14779277726804943
67.00000000000023,13.328961740195757,-0.8826685737012118,-0.15040971124902272
67.80000000000024,13.423927669368618,-0.8696139837385255,-0.15303941945846739
68.60000000000025,13.516270132711842,-0.8609898635552051,-0.15444006244317535
69.40000000000026,13.612256473982374,-0.8487641469896591,-0.15700505188753738
70.20000000000027,13.704576151632285,-0.8385319750638522,-0.15852980721403062
71.00000000000028,13.79409030171328,-0.8275302567147336,-0.1610830938547564
71.8000000000003,13.888701068653349,-0.8134017189111222,-0.1622600200978672
72.6000000000003,13.979123107942055,-0.8028245612551773,-0.1635806194019228
73.40000000000032,14.069772502204707,-0.7893116428662315,-0.1658598233442996
74.20000000000033,14.159008539279673,-0.7765071048073068,-0.16679131396014937
75.00000000000034,14.248138662568328,-0.764631025541054,-0.16883666638338976
75.80000000000035,14.337415557201078,-0.752678501548348,-0.17010782437156852
76.60000000000036,14.426352622815086,-0.7383613436559903,-0.17140344966722898
77.40000000000038,14.513454019784445,-0.7268782532297842,-0.17422428787282593
78.20000000000039,14.600720988294741,-0.7139384542989031,-0.17544517205241683
79.0000000000004,14.686425507546007,-0.6996062905611731,-0.1767787906915253
79.80000000000041,14.774298037903872,-0.6864607520380738,-0.17796197489754711
80.60000000000042,14.860642004261088,-0.6749666740490767,-0.17806930567097987
81.40000000000043,14.945546958722337,-0.6606496027763469,-0.18046999010848208
82.20000000000044,15.032814496064452,-0.6479137881974181,-0.1809009641146698
83.00000000000045,15.114852807670461,-0.6329152624693714,-0.18198232448572144
83.80000000000047,15.201358162680705,-0.6199548625770619,-0.18464205125818078
84.60000000000048,15.285258001512808,-0.6053719176246318,-0.1847222333780096
85.40000000000049,15.370000000000049,-0.5924999999999949,-0.18596999200000042
86.2000000000005,15.453395712082354,-0.5788598147945954,-0.18727587974225085
87.00000000000051,15.536386887756661,-0.5636056870635108,-0.18722099273916237
87.80000000000052,15.620301627094383,-0.5516894354401484,-0.18929555924351116
88.60000000000053,15.703369645784866,-0.538901334621508,-0.19058757962802655
89.40000000000055,15.783342877747055,-0.5261021183646383,-0.19124038863899206
90.20000000000056,15.866988441098691,-0.5092112808979885,-0.19256313230492655
91.00000000000057,15.948727910675391,-0.492682977959673,-0.19258098443128469
91.80000000000058,16.031217549012503,-0.48005305806671006,-0.19388821981378285
92.60000000000059,16.112704755540207,-0.4613728724157679,-0.19519784739278498
93.4000000000006,16.193453964245222,-0.44139963369817253,-0.19650911786246145
94.20000000000061,16.274910026787357,-0.4227948094270047,-0.19789064019422367
95.00000000000063,16.356504286106098,-0.40468259723830863,-0.19774784030440215
95.80000000000064,16.437278579209252,-0.38435186423390905,-0.1991501075721125
96.60000000000065,16.518885843349423,-0.3658369732123752,-0.20048767706862844
97.40000000000066,16.598696081905516,-0.3472221180567768,-0.2004698883177924
98.20000000000067,16.678856915840722,-0.3352444250775205,-0.20177579187193062
99.00000000000068,16.757842121770498,-0.32755134099107985,-0.2031230897256249
99.8000000000007,16.838872316730946,-0.3153326877874702,-0.20444384450585998
100.6000000000007,16.91923401976206,-0.3008937256413133,-0.20442013841150247
101.40000000000072,16.998450382228857,-0.2815703699917347,-0.20442013666436598
102.20000000000073,17.076586021311908,-0.2578679122046802,-0.2043396795203125
103.00000000000074,17.15708785391634,-0.23145389689713985,-0.20573092950671767
103.80000000000075,17.235420283842906,-0.2019736211051207,-0.20705296847242374
104.60000000000076,17.315214387519113,-0.16577473653280556,-0.20845695393370228
105.40000000000077,17.394898902969643,-0.12817849690273797,-0.20836895903820912
106.20000000000078,17.470535823961725,-0.08798245047388235,-0.20969034055114064
107.0000000000008,17.552445613832514,-0.041058560688871294,-0.209876260686896
107.80000000000081,17.63177459235163,0.009362685553471346,-0.21097611834350757
108.60000000000082,17.7116032308238,0.06946197911694661,-0.21232013712867912
109.40000000000083,17.790974686195437,0.13294254112979428,-0.21272559990516637
110.20000000000084,17.870673012126897,0.20337899105586216,-0.21363997066465182
111.00000000000085,17.949017562640666,0.2818509731808045,-0.21458793333074644
111.80000000000086,18.029360159796518,0.36886645393020717,-0.2146342493378275
112.60000000000088,18.107632851783393,0.45857316601232134,-0.21609933216909732
113.40000000000089,18.186255782555747,0.5394532394162959,-0.21628266745622732
114.2000000000009,18.266010213517216,0.5970528738595702,-0.21759033317330173
115.00000000000091,18.34582926332308,0.584772793476322,-0.21886733586761734
115.80000000000092,18.42225741002028,0.4397163743111664,-0.21891004149772522
116.60000000000093,18.50122207491286,0.14198296239758773,-0.21955913432224522
117.40000000000094,18.57901428048066,-0.10097135443568245,-0.21957011748714816
118.20000000000095,18.65501437902455,-0.25866497578476116,-0.21958063979423412
119.00000000000097,18.73276438899989,-0.3606191165242826,-0.22022966100726898
119.80000000000098,18.80932927336224,-0.4256337646974046,-0.2215405853863921
120.60000000000099,18.887865049012913,-0.4675204177795251,-0.22152949221765872
121.400000000001,18.964062177634716,-0.49218118448043807,-0.22253006569977904
122.20000000000101,19.040792296390205,-0.5059697271925072,-0.22253022620187127
123.00000000000102,19.117999100649165,-0.5156110421777387,-0.22286309024310552
123.80000000000103,19.195132682729852,-0.519698034149712,-0.2241804359087463
124.60000000000105,19.27246363456854,-0.5222428199143231,-0.22418003330483602
125.40000000000106,19.34937603383106,-0.5225247713969964,-0.2241841336671589
126.20000000000107,19.427046309249846,-0.5208687217936211,-0.22550003859963885
127.00000000000108,19.50358572426274,-0.5181152942750565,-0.22549976937329344
127.80000000000109,19.580971592256386,-0.5167683858925474,-0.22649108895329778
128.6000000000011,19.657116597006194,-0.5139287840708493,-0.22680974266435255
129.4000000000011,19.733975653856042,-0.5113171851558262,-0.22813787552238524
130.20000000000113,19.811780092150293,-0.5085395240381009,-0.22945010793702295
131.00000000000114,19.888628767341434,-0.5048198603935851,-0.22945006499883952
131.80000000000115,19.965991752949467,-0.5009843196640259,-0.22945007358920486
132.60000000000116,20.043069704832806,-0.4974953460800169,-0.22899609298473536
133.40000000000117,20.11945058584028,-0.4944956672136608,-0.22878998457334168
134.20000000000118,20.196090074266014,-0.4908254845988871,-0.2301181604807292
135.0000000000012,20.27222878422789,-0.4863957535937847,-0.2314222377877988
135.8000000000012,20.34809353338304,-0.4826798918045801,-0.23143085302865493
136.60000000000122,20.426975032634882,-0.48022220909317503,-0.2327403701444063
137.40000000000123,20.502752079589598,-0.4769830829464321,-0.23274015688782188
138.20000000000124,20.580176945794694,-0.4743394845789806,-0.23273993100386725
139.00000000000125,20.657395408268368,-0.46886695250674393,-0.23406040396897493
139.80000000000126,20.73435433111204,-0.4647737220248417,-0.234319895723584
140.60000000000127,20.809364630369874,-0.46300321195488736,-0.23472010185583123
141.40000000000128,20.88584296840249,-0.45867499528637284,-0.23510514902667998
142.2000000000013,20.959536650304006,-0.45528579829314253,-0.2353801504153191
143.0000000000013,21.03520479921101,-0.4509009146246428,-0.23603440042993806
143.80000000000132,21.114535474658854,-0.44835045121009914,-0.236690096268444
144.60000000000133,21.190458375202276,-0.44479755805694005,-0.23668996000419545
145.40000000000134,21.26670620223475,-0.4426511092793348,-0.2366894999740119
146.20000000000135,21.342931866645213,-0.43860899736883646,-0.23800840102823395
147.00000000000136,21.41838288234063,-0.43440896034444104,-0.23801057429486047
147.80000000000138,21.494994716164204,-0.4328150750092981,-0.23867186818100844
148.6000000000014,21.569128735354724,-0.4291237432016935,-0.23866991514469138
149.4000000000014,21.64635894401667,-0.42625017253225056,-0.23935158965592843
150.2000000000014,21.72316602455828,-0.42267697157311757,-0.23957599434080998
151.00000000000142,21.799316742594947,-0.4203251622573854,-0.2406498363625466
151.80000000000143,21.874159764871102,-0.41617202468917586,-0.24065073120811864
152.60000000000144,21.95038681728104,-0.41307549189487425,-0.24196084380506347
153.40000000000146,22.02692090555059,-0.40859112486608545,-0.2419599907721599
154.20000000000147,22.103628115109625,-0.4072485111193361,-0.24196003343700234
155.00000000000148,22.179073411054933,-0.4049087385567695,-0.2432756949326924
155.8000000000015,22.254856064215577,-0.4012495698589797,-0.24327981531361795
156.6000000000015,22.33080476000285,-0.3980229469083814,-0.24327981599998022
157.4000000000015,22.40603543627468,-0.3946542953826786,-0.2432798168492324
158.20000000000152,22.483166892386773,-0.390944247233256,-0.24329602583803225
159.00000000000153,22.55910938188891,-0.387998480529658,-0.24459852844623597
159.80000000000155,22.63578178211017,-0.38480198278910527,-0.24591896786382933
160.60000000000156,22.710831175541678,-0.38153772548398374,-0.2459198689894093
161.40000000000157,22.787702596326053,-0.3779028221273151,-0.2459198689961203
162.20000000000158,22.860359963322086,-0.37521427205863017,-0.24591985553255716
163.0000000000016,22.939070220505634,-0.3719948864458367,-0.24724304097576386
163.8000000000016,23.01447636315824,-0.36756456517684455,-0.24723002625525045
164.60000000000161,23.09037879784143,-0.36569142924822495,-0.24723751750533335
165.40000000000163,23.167531467624656,-0.36456575501517197,-0.24789681355714435
166.20000000000164,23.242712185420086,-0.35828361004431286,-0.2485491665112355
167.00000000000165,23.317816987317517,-0.35552914140416403,-0.24854984703090519
167.80000000000166,23.39387531047497,-0.35200382221367293,-0.24854984700213567
168.60000000000167,23.47144438081703,-0.34913402411003147,-0.2485498814178301
169.40000000000168,23.54631614372841,-0.34661375805703865,-0.2498216155793974
170.2000000000017,23.622748227641143,-0.3435892411079651,-0.24987102363942637
171.0000000000017,23.699187378530112,-0.33916183145722123,-0.251179577783061
171.80000000000172,23.774270116976332,-0.3346453908814728,-0.2511798249546512
172.60000000000173,23.849311654975246,-0.33348036160513,-0.25117982499999997
173.40000000000174,23.924716625476044,-0.33060980811735063,-0.2511798250002565
174.20000000000175,24.00045793736937,-0.3286363191575101,-0.2511798258370616
175.00000000000176,24.07808948608901,-0.32596186061471344,-0.251096261995359
175.80000000000177,24.15397889297532,-0.32360689431264594,-0.2525000308373293
176.60000000000178,24.229798917814545,-0.32209162356377274,-0.2531435801813651
177.4000000000018,24.306830260408507,-0.3176960899682444,-0.25381989180164244
178.2000000000018,24.37930649989029,-0.31581846150652104,-0.25382035078180093
179.00000000000182,24.45760133904894,-0.31170804152491505,-0.2551418818835248
179.80000000000183,24.53344098231714,-0.311143043805529,-0.2546629334295591
180.60000000000184,24.608854899785385,-0.3074001361725018,-0.2541450474483671
181.40000000000185,24.68510382951097,-0.3054561778605343,-0.254150017095781
182.20000000000186,24.76135784060347,-0.3016266190115912,-0.25549876919100084
183.00000000000188,24.836776509981604,-0.3003055970404718,-0.25547016016075985
183.8000000000019,24.911438686816137,-0.29868685542380957,-0.2554701629946654
184.6000000000019,24.98910829700099,-0.2976370118263124,-0.2554702729919745
185.4000000000019,25.064705988444587,-0.2936413773943967,-0.25678608400627306
186.20000000000192,25.140519900573732,-0.2920625256973046,-0.25677991300844233
187.00000000000193,25.216042848835265,-0.28966328176560546,-0.25678499791220805
187.80000000000194,25.292244490962712,-0.2864032354793814,-0.2558000576597475
188.60000000000196,25.368175438780604,-0.2847766840340852,-0.25579981698013426
189.40000000000197,25.442037843327793,-0.2822200571936552,-0.2557995274110206
190.20000000000198,25.518920146466023,-0.2792901932361742,-0.25711118633002317
191.000000000002,25.59525036939137,-0.2770008550756622,-0.25710997014095427
191.800000000002,25.6701886770236,-0.2758631719830661,-0.257109969999816
192.600000000002,25.7467217786624,-0.27283921240498754,-0.2571100283134185
193.40000000000202,25.823026976850276,-0.27102574158410175,-0.25848955322460154
194.20000000000203,25.89830627353464,-0.26793598428458365,-0.25711326810791496
195.00000000000205,25.974502590550486,-0.26530504408655614,-0.25710741765409173
195.80000000000206,26.047198569201154,-0.2625850689966049,-0.2584334462948711
196.60000000000207,26.125975307436512,-0.2617434118273773,-0.2584301981019099
197.40000000000208,26.201075848209996,-0.2569836152118682,-0.2584301980000018
198.2000000000021,26.276778638537067,-0.25675610246621866,-0.25843019800000017
199.0000000000021,26.352568260436808,-0.2543214428509435,-0.2584301980016522
199.80000000000211,26.42962693382089,-0.25281763611196856,-0.2584301910310207
200.60000000000213,26.503897370359137,-0.2497987079905683,-0.25951251311865786
201.40000000000214,26.580200013029533,-0.24666747208317805,-0.2597502796836289
202.20000000000215,26.656117104044515,-0.24560243971137602,-0.2597500405350735
203.00000000000216,26.731315368236242,-0.24317527400305247,-0.26112002002364215
203.80000000000217,26.806770504185916,-0.24127263511283897,-0.2609216015896965
204.60000000000218,26.882708990969945,-0.2384771565426067,-0.2597499961854725
205.4000000000022,26.958562305468163,-0.2348072586574832,-0.2594837528156193
206.2000000000022,27.0347177501322,-0.23244787654145388,-0.25908989984602954
207.00000000000222,27.109820153546117,-0.23058991093610498,-0.25908990900003165
207.80000000000223,27.186335453948093,-0.2275601104397189,-0.2590899090000001
208.60000000000224,27.262826159172047,-0.22483905663005394,-0.25908990900014905
209.40000000000225,27.3375488903371,-0.22284287593043778,-0.25908990656732067
210.20000000000226,27.413718650001456,-0.2207320723805521,-0.25901678505150655
211.00000000000227,27.490182282687826,-0.21776494489484596,-0.26008008434163515
211.80000000000229,27.565456253280733,-0.21682317088827346,-0.2600790162754792
212.6000000000023,27.641548675158486,-0.21319178825396787,-0.25908904065108457
213.4000000000023,27.71644002297581,-0.21157816323443215,-0.25908990910539115
214.20000000000232,27.79265690352941,-0.20865244372947678,-0.25908990900000367
215.00000000000233,27.869737478904455,-0.20551816024191777,-0.25908990900000006
215.80000000000234,27.944920043883798,-0.2034421498745639,-0.25908990900000006
216.60000000000235,28.018691451395668,-0.20250658011450298,-0.25908990900000006
217.40000000000236,28.096661346208624,-0.2001867787949729,-0.259089909
218.20000000000238,28.172248038075626,-0.19771031843510803,-0.2590899089999549
219.0000000000024,28.24948276487218,-0.19491004203231072,-0.2590899092466974
219.8000000000024,28.3232514038666,-0.19413394728401134,-0.25911681340124054
220.6000000000024,28.399719372993143,-0.19101805046506842,-0.25875985461798573
221.40000000000242,28.47553596017249,-0.18870323197482664,-0.2587598520026984
222.20000000000243,28.551101296994904,-0.18612575159772085,-0.25875986193966866
223.00000000000244,28.625029007879373,-0.18407387901933392,-0.2573492871212746
223.80000000000246,28.703396448541444,-0.18108768792612803,-0.2574400207956396
224.60000000000247,28.778965399564544,-0.1794227267031661,-0.2577079291519413
225.40000000000248,28.855097101513646,-0.1766475687832197,-0.2584302249260825
226.2000000000025,28.93092928293438,-0.17612579780837168,-0.25843124899167985
227.0000000000025,29.00711044831937,-0.17360098781301025,-0.2571154716393075
227.8000000000025,29.08309380746558,-0.1724123357539989,-0.2557675335194221
228.60000000000252,29.159360748356008,-0.170163446100652,-0.25579981752803116
229.40000000000254,29.2344115532123,-0.16883620929702353,-0.2558131347175815
230.20000000000255,29.31210624971652,-0.16649538486100557,-0.25448008462516414
231.00000000000256,29.38659411100084,-0.16445380184837965,-0.2544799919931863
231.80000000000257,29.46314811193486,-0.16241145731326642,-0.2544799919999587
232.60000000000258,29.53999906674067,-0.16065000241473365,-0.25447999200034643
233.4000000000026,29.615228011152475,-0.15827728974854238,-0.25450552177345814
234.2000000000026,29.692427709836704,-0.15589104801423093,-0.2534899650529773
235.00000000000261,29.767510448074052,-0.15529319847344802,-0.2531649359270131
235.80000000000263,29.844030231235195,-0.15332810520406168,-0.253160185714693
236.60000000000264,29.920667619665306,-0.15283188602002598,-0.25184068714780466
237.40000000000265,29.995076629569013,-0.1491828684053418,-0.2518406733808496
238.20000000000266,30.071988581848583,-0.14736197633986547,-0.2505315460782236
239.00000000000267,30.1481520142621,-0.14434732506639045,-0.25053018895021006
239.80000000000268,30.224417082112918,-0.14267497098198936,-0.25053042223252153
240.6000000000027,30.299890625753573,-0.14025212105712268,-0.249209335015059
241.4000000000027,30.37633895607595,-0.13814651830468705,-0.2492099600994632
242.20000000000272,30.45210179614218,-0.13602382409529523,-0.24920996100095838
243.00000000000273,30.528514832422335,-0.13507711834540415,-0.24920994662181026
243.80000000000274,30.604072663226976,-0.13326864853094764,-0.24815601512302712
244.60000000000275,30.68009636418642,-0.13088813696093096,-0.24789012481915002
245.40000000000276,30.755665481378035,-0.12912152440797195,-0.24756362279140912
246.20000000000277,30.831544927908595,-0.12770982913718706,-0.24548383501307855
247.00000000000279,30.907995882082332,-0.12594671959717446,-0.24526015631806347
247.8000000000028,30.98487515523948,-0.1253505771611361,-0.24526062587951647
248.6000000000028,31.059251500120972,-0.12320911155352639,-0.24393977219505789
249.40000000000282,31.136742468096713,-0.12284794315244543,-0.2447528389058039
250.20000000000283,31.212589467086264,-0.12149355448573797,-0.24492947449246286
251.00000000000284,31.289377871175173,-0.11989551756156105,-0.24361123495637513
251.80000000000285,31.364261163723416,-0.1172959705286409,-0.242286924879328
252.60000000000286,31.44084549496319,-0.11627966693389695,-0.2409609646176282
253.40000000000288,31.516573972283854,-0.11287653625065905,-0.24097993665815928
254.2000000000029,31.592740922908,-0.1118785957481771,-0.23989112562330028
255.0000000000029,31.669895749991372,-0.11026535681742207,-0.2399918388469914
255.8000000000029,31.744869015857187,-0.10960250550135311,-0.23921190088318472
256.6000000000029,31.821312505574067,-0.10690164698660524,-0.23833984160856342
257.40000000000293,31.89619358491692,-0.10639047458530922,-0.23833984136134678
258.20000000000294,31.97330834768385,-0.10478332523313577,-0.23832454208705037
259.00000000000296,32.048197993475334,-0.10316948726736491,-0.23702006631836275
259.80000000000297,32.12552612424762,-0.10159758446610181,-0.23563202986021117
260.600000000003,32.20085247778682,-0.09952091076315944,-0.2343880850666561
261.400000000003,32.2772187155336,-0.09954926309176837,-0.23439038775998444
262.200000000003,32.353129821755964,-0.09559760534193502,-0.23307155262860546
263.000000000003,32.42904564116931,-0.0931370429422396,-0.23306975552176865
263.800000000003,32.50578277086824,-0.0928096032203697,-0.23173264277949512
264.60000000000304,32.58038213819208,-0.0910188476490185,-0.23174998589663467
265.40000000000305,32.656916823789,-0.0910878778724058,-0.23174998594508542
266.20000000000306,32.733308886778836,-0.08901541252506841,-0.23174848287613226
267.00000000000307,32.81009187853797,-0.0886144086828771,-0.2304399303104612
267.8000000000031,32.88505111698234,-0.08686405505730475,-0.22911894975539002
268.6000000000031,32.9612437314564,-0.08604946805801916,-0.2291201254236968
269.4000000000031,33.03828680191908,-0.0844790880224548,-0.22779778763280475
270.2000000000031,33.11311423900644,-0.08400313959200864,-0.22780102693251802
271.0000000000031,33.189684285334245,-0.08162384130341878,-0.22647967867802657
271.80000000000314,33.267595500801455,-0.08138000893928671,-0.22549346177260732
272.60000000000315,33.34320964252933,-0.07963563718827808,-0.2251782890649129
273.40000000000316,33.41775169194437,-0.07973793507621396,-0.22516980837989017
274.2000000000032,33.494838651809175,-0.07907668982057926,-0.22387475806193344
275.0000000000032,33.57150576695869,-0.07707211060892676,-0.2238499774851257
275.8000000000032,33.64745098110751,-0.07533764789423966,-0.22385000841248076
276.6000000000032,33.72384694325173,-0.07485709131755316,-0.22263758995803726
277.4000000000032,33.79959012850728,-0.07352885755134181,-0.22253166151381987
278.20000000000323,33.87607679518767,-0.07230484192477345,-0.22121001769138995
279.00000000000324,33.951806004503254,-0.0703259131161089,-0.2212099240022422
279.80000000000325,34.029106129702924,-0.07031234551424125,-0.22120992455100122
280.60000000000326,34.1029643531741,-0.06942674210404026,-0.2212445981664928
281.4000000000033,34.17870417192807,-0.06695189527245435,-0.21989184559465474
282.2000000000033,34.25616538516941,-0.06486459588625881,-0.21857967533830086
283.0000000000033,34.3340105668137,-0.06463171230943712,-0.21856952190867893
283.8000000000033,34.41000097402709,-0.06230376987927206,-0.2172601208938338
284.6000000000033,34.48649982470539,-0.062058769914985656,-0.21590054242843484
285.40000000000333,34.56255720804597,-0.06083098360413214,-0.2159398916460894
286.20000000000334,34.6393336962028,-0.05968308994631522,-0.21593989300016656
287.00000000000335,34.715412243578946,-0.057723131930187035,-0.21593991109978902
287.80000000000337,34.79124516154841,-0.05507584621061114,-0.2151858220031311
288.6000000000034,34.86862180149624,-0.05722674720223246,-0.21463013777191975
289.4000000000034,34.94484404594032,-0.053543111083700884,-0.21463018001602555
290.2000000000034,35.0207132960033,-0.05223093507979901,-0.2135868535114897
291.0000000000034,35.09794352179305,-0.05039616161977792,-0.21330991376710517
291.8000000000034,35.17400675514253,-0.04943329219704105,-0.2133099154647153
292.60000000000343,35.25135573977176,-0.04946366226430103,-0.21331555357999052
293.40000000000344,35.32716196304866,-0.047242942366571596,-0.21232001238380935
294.20000000000346,35.40362977485325,-0.04602171557921639,-0.21232014699336776
295.00000000000347,35.480655736281456,-0.04479864247089307,-0.2123201469999878
295.8000000000035,35.55614690479238,-0.045121212392187596,-0.21232014804404517
296.6000000000035,35.63210565843988,-0.04320941477807659,-0.2123373832500624
297.4000000000035,35.709051952722696,-0.041846435123463484,-0.2106648313116958
298.2000000000035,35.78628026001033,-0.0420914779722433,-0.21067993655720244
299.0000000000035,35.862310829777634,-0.03939547048043072,-0.21070112881640574
299.80000000000354,35.93916270329852,-0.037820034570712195,-0.20936007654044553
300.60000000000355,36.014856827839715,-0.03762027770369581,-0.2093609461735117
301.40000000000356,36.09167100514826,-0.036009280966495465,-0.2080411111754478
302.20000000000357,36.16691329894837,-0.03553329115036351,-0.20803988386923317
303.0000000000036,36.24490656982524,-0.032017200734834765,-0.20803988393745032
303.8000000000036,36.322036483227954,-0.030893854649579798,-0.20803902955678044
304.6000000000036,36.39876238437325,-0.029542676029561555,-0.20836980420127596
305.4000000000036,36.47422642329443,-0.028127660420704956,-0.20836871605475948
306.2000000000036,36.551422178091954,-0.028162784888483124,-0.20704773078472546
307.00000000000364,36.62659564438755,-0.025456556840339806,-0.20704998731987412
307.80000000000365,36.704499861079,-0.024957708287746377,-0.2057175558057591
308.60000000000366,36.781720329616,-0.023909020779043787,-0.20572988778891893
309.4000000000037,36.85808441340401,-0.02091252481238707,-0.2057298879983546
310.2000000000037,36.934167080973545,-0.02100594862838223,-0.20572981721551392
311.0000000000037,37.01105187075933,-0.018877166232459212,-0.20439561378457805
311.8000000000037,37.0876127523642,-0.01609121939963073,-0.2044201401762485
312.6000000000037,37.163922744056734,-0.014413407846638039,-0.20442692554722822
313.40000000000373,37.24099395983436,-0.011718263773270692,-0.20342967205224816
314.20000000000374,37.31746501975205,-0.008946033197985412,-0.20342996703587288
315.00000000000375,37.392280012836196,-0.0030751378607125827,-0.203429970965974
315.80000000000376,37.470000909496015,9.467060034192765e-08,-0.2030998913410168
316.6000000000038,37.54701625999464,0.0028500324884816347,-0.20310700971318063
317.4000000000038,37.623542255836185,0.005584680513120337,-0.20178021075180289
318.2000000000038,37.6999990596362,0.008598557980856479,-0.20178008521543273
319.0000000000038,37.77615101329716,0.01121854499983179,-0.20068307946823355
319.8000000000038,37.853648662569626,0.012043547387282484,-0.20045941354591398
320.60000000000383,37.92999903502172,0.014866918544059422,-0.19915010715189277
321.40000000000384,38.005820880710445,0.016555170445729725,-0.19914965966378417
322.20000000000385,38.082282009674394,0.019127268249854303,-0.20046106127757954
323.00000000000387,38.160099123253254,0.02173735144284626,-0.19915023141339552
323.8000000000039,38.23644768112903,0.02416659739240087,-0.19913571507901512
324.6000000000039,38.312714892890334,0.026022949738087605,-0.19782959178838838
325.4000000000039,38.39059227660573,0.028436885546762585,-0.19783042206468213
326.2000000000039,38.467054077936,0.03283958179863594,-0.1965095185843501
327.0000000000039,38.54245329483956,0.033943529597736326,-0.1951940459805988
327.80000000000393,38.61962361544867,0.036069175463755695,-0.19519968078684805
328.60000000000394,38.69656157092744,0.038705732852585446,-0.19387735302747955
329.40000000000396,38.773821477354126,0.04043734072137336,-0.193857616097494
330.20000000000397,38.85009988352485,0.04380216650370579,-0.19255984574458054
331.000000000004,38.92745726751446,0.045920662891668566,-0.19242594117841247
331.800000000004,39.00403158261484,0.04932784943122096,-0.19131036005123575
332.600000000004,39.081203224217326,0.0530429948092357,-0.18988212127830334
333.400000000004,39.157917171254084,0.054277241545607334,-0.1886076073043458
334.200000000004,39.23553044530628,0.05665099394673714,-0.18728929272082623
335.00000000000404,39.31207433541922,0.05913047281666666,-0.18596232654721337
335.80000000000405,39.38900179009153,0.06065311710493373,-0.18466860645483313
336.60000000000406,39.46708557291718,0.06338250805563216,-0.1833691962281333
337.40000000000407,39.5434317286178,0.06608090413219801,-0.18333944584210776
338.2000000000041,39.62017139371565,0.06938663019770551,-0.1820197193753499
339.0000000000041,39.69778650106813,0.07063295925237645,-0.1807869741943734
339.8000000000041,39.772700490975886,0.07396318080270131,-0.1795565987097708
340.6000000000041,39.852137856176064,0.07710855576562906,-0.1780621124943758
341.4000000000041,39.92832199961453,0.07943743220402245,-0.1767527613651752
342.20000000000414,40.00418557564699,0.08032801695463113,-0.17540709053469605
343.00000000000415,40.08325913725613,0.08344373350220953,-0.1741189635911175
343.80000000000416,40.16000091896551,0.08596405595921171,-0.17279995261805314
344.6000000000042,40.23681369763165,0.08881732897175554,-0.17153055457447075
345.4000000000042,40.31480715324069,0.08904026509697426,-0.17013391438077916
346.2000000000042,40.3909496983616,0.09384863495902761,-0.16730384363939943
347.0000000000042,40.46727729706693,0.09618134175755684,-0.1659907774623154
347.8000000000042,40.54589864186346,0.0982215975033755,-0.16473854984308453
348.60000000000423,40.622872993640314,0.09896616941011396,-0.16324182953296915
349.40000000000424,40.698528144782685,0.10138602500363374,-0.16070717115761457
350.20000000000425,40.77484967950557,0.10026777336999992,-0.15942382507805733
351.00000000000426,40.855114636756326,0.09932132369637378,-0.1567137086361843
351.8000000000043,40.93178698890568,0.09967236590119262,-0.15434703042108755
352.6000000000043,41.01018434180685,0.09961353232872014,-0.15282024112957812
353.4000000000043,41.086047591712735,0.09974067095643611,-0.15149745702196074
354.2000000000043,41.163904214846866,0.09934656161559333,-0.1498802423042732
355.0000000000043,41.2409055289854,0.10090165370968172,-0.14743616825801711
355.80000000000433,41.31823672428703,0.10055815250065836,-0.1461305103227979
356.60000000000434,41.395387915377725,0.1004139210497006,-0.14491441167079777
357.40000000000435,41.47267950920566,0.09946204525628996,-0.1421511193522115
358.20000000000437,41.54920674312531,0.09916576579728364,-0.13931444034822796
359.0000000000044,41.62601798330284,0.09871118401335115,-0.13800228642936788
359.8000000000044,41.70483718434395,0.0970415816875234,-0.13565470631379675
360.6000000000044,41.78186584858123,0.09733555345698565,-0.13406413603000897
361.4000000000044,41.859794198430876,0.09605910271585227,-0.13274091112788403
362.2000000000044,41.93687814898335,0.09439684353648348,-0.1301159306902713
363.00000000000443,42.01340574083679,0.09221114764601511,-0.1287399598848299
363.80000000000445,42.09267042724549,0.08986885990493063,-0.12744521601697642
364.60000000000446,42.17041201379788,0.08844745291658723,-0.12614503689505466
365.40000000000447,42.246823720043245,0.08551378924614257,-0.1234743854271765
366.2000000000045,42.324208642696036,0.0828222713720039,-0.12180944338969665
367.0000000000045,42.400605884294265,0.08108251183615639,-0.1195578990111312
367.8000000000045,42.479363112893374,0.07852868978255304,-0.11823229401569085
368.6000000000045,42.55690321923612,0.07667347069130122,-0.11554364039338148
369.4000000000045,42.63419149527371,0.0745470761868683,-0.11560294124627289
370.20000000000454,42.71186835311761,0.07262212710620958,-0.11243248786335623
371.00000000000455,42.789330294638354,0.07236743091937643,-0.11120381513121885
371.80000000000456,42.865455568127366,0.06976710591159595,-0.10992170586068178
372.60000000000457,42.94456417986835,0.06769827182633209,-0.10848636845225938
373.4000000000046,43.021364331444744,0.06613574350580677,-0.10720896867457481
374.2000000000046,43.09935389171338,0.06402407225888,-0.10594048053678834
375.0000000000046,43.17614980314508,0.06319196368712704,-0.10427331241284381
375.8000000000046,43.252902171594094,0.059998348119323024,-0.1021394777363951
376.6000000000046,43.33122556415399,0.05903302812876692,-0.10199000081679462
377.40000000000464,43.40848067482106,0.05601232293794573,-0.10068005071975708
378.20000000000465,43.485751564580916,0.053710595963980326,-0.09934851233251617
379.00000000000466,43.563851045819256,0.05007829734068226,-0.0980049237184995
379.8000000000047,43.64052145625632,0.04770543236112161,-0.0980428114652338
380.6000000000047,43.71777487591957,0.044667034210851136,-0.09625317649097066
381.4000000000047,43.79566358493233,0.04186534737551523,-0.09540015866430905
382.2000000000047,43.87291818992668,0.0390194896917682,-0.0953925006578968
383.0000000000047,43.951460775352615,0.037720212746223926,-0.09408986473442417
383.80000000000473,44.02755894898607,0.035001150441904216,-0.0933335746292295
384.60000000000474,44.10465349169363,0.0330616630852106,-0.09277648563664911
385.40000000000475,44.18353514657155,0.032391498091239306,-0.09144917241325065
386.20000000000476,44.26030841083844,0.03189420328060037,-0.09012754605190465
387.0000000000048,44.33838889309225,0.029257167526890893,-0.08882002402540307
387.8000000000048,44.41567346373232,0.02928488969752878,-0.08881999115618368
388.6000000000048,44.49344785989955,0.02830034912007327,-0.08882512245541185
389.4000000000048,44.570884093469985,0.02791496704582163,-0.08750024077524726
390.2000000000048,44.64781055928177,0.026811600277987232,-0.08635795860873809
391.00000000000483,44.723592285295126,0.027799736407958076,-0.086179950893038
391.80000000000484,44.80361353240805,0.028894619318442973,-0.08617262048956176
392.60000000000485,44.880973186254394,0.0288120089318974,-0.08486878016613758
393.40000000000487,44.95814588226177,0.03161944786816136,-0.08355554603954611
394.2000000000049,45.03538855039223,0.03156949661201386,-0.08223018741956126
395.0000000000049,45.11484404471545,0.03380690375187301,-0.08223842797566147
395.8000000000049,45.191274828485554,0.03527956950626002,-0.08090985082308642
396.6000000000049,45.26990467744932,0.036352974308236696,-0.07959604205630676
397.4000000000049,45.34775955794023,0.037474352847799416,-0.07959026253283115
398.20000000000493,45.42409805576978,0.04043675251001955,-0.07829741533200146
399.00000000000495,45.50332508079866,0.04191263005519072,-0.07685089630350694
399.80000000000496,45.58075929440914,0.042986137965246536,-0.07695587678529874
400.60000000000497,45.658167268341465,0.04412689767389149,-0.07563876329465248
401.400000000005,45.73674757546971,0.046748520685191745,-0.07431788286921209
402.200000000005,45.813643236829115,0.048060277599896964,-0.07300783088745808
403.000000000005,45.88936301328455,0.04951221693192428,-0.07097047774651781
403.800000000005,45.96941392280746,0.052396049597991295,-0.07025991629911818
404.600000000005,46.047088676166254,0.05331513867621801,-0.06895724323927759
405.40000000000504,46.12506983395285,0.056738232561390614,-0.0675762882669911
406.20000000000505,46.20304174582242,0.05986464344896875,-0.06763064073087592
407.00000000000506,46.28099337863548,0.060278849075535115,-0.06498591425366165
407.80000000000507,46.35816488676558,0.06383170060105346,-0.06372646641715458
408.6000000000051,46.43667084315438,0.06690587096534316,-0.06224445405763969
409.4000000000051,46.514658962178714,0.06909984449111974,-0.05979620449529487
410.2000000000051,46.59211014285612,0.07187089715479453,-0.05970116330326534
411.0000000000051,46.67009283214356,0.07435843142704412,-0.05807153650982923
411.8000000000051,46.74830266016801,0.07646957693432843,-0.05576518655035161
412.60000000000514,46.826718791580724,0.07825272498098408,-0.05325764988527444
413.40000000000515,46.90463126961545,0.08212997995775849,-0.05057125606412352
414.20000000000516,46.980515344646754,0.08413745479485546,-0.04894181022056854
415.0000000000052,47.05938920808861,0.08670353998948116,-0.047645710324775804
415.8000000000052,47.13896779512054,0.08940281959331751,-0.04543131937128925
416.6000000000052,47.217251516944884,0.09212186618546547,-0.04220720092383596
417.4000000000052,47.29297397245989,0.09515660854839532,-0.040175555336362585
418.2000000000052,47.37283848674755,0.09854179790350961,-0.038131345361402
419.00000000000523,47.45000000000047,0.1027400000000275,-0.03523993199999532
419.80000000000524,47.52870163961959,0.1085794263998541,-0.03228539578742819
420.60000000000525,47.60614997157233,0.1116893453371603,-0.029269249727256415
421.40000000000526,47.684225269700654,0.11720816924409036,-0.02625462023773049
422.2000000000053,47.76280158782207,0.12306901301132513,-0.023256816968277687
423.0000000000053,47.84039092412566,0.1297092169762274,-0.01876857564180702
423.8000000000053,47.91844844834406,0.13539781205045484,-0.014941908887314904
424.6000000000053,47.99655609110589,0.14163559185002844,-0.01119967574406872
425.4000000000053,48.07412443844947,0.1484042695989905,-0.008057977766836956
426.20000000000533,48.15252799812131,0.1557470780105529,-0.003719601367441233
427.00000000000534,48.23070315282883,0.16004702346862718,-0.0009393001385916408
427.80000000000535,48.309000989628686,0.16909836176650303,0.0038315127137417346
428.60000000000537,48.385965751837254,0.17496221362441042,0.01085884503000662
429.4000000000054,48.463771019308666,0.18059706143210913,0.014625664474002356
430.2000000000054,48.54167223843422,0.18902953597514385,0.019118683706542162
431.0000000000054,48.62040644612645,0.19527623024343563,0.024276989604041954
431.8000000000054,48.69791947324483,0.20329257798472217,0.029462909974895604
432.6000000000054,48.77619084335351,0.21208644967034568,0.03645159176730961
433.40000000000543,48.85460353350745,0.21960209302848047,0.04405844643628806
434.20000000000545,48.932613171254296,0.22957798838315135,0.049726586038002556
435.00000000000546,49.01162139619703,0.23693948084275476,0.05603517017142389
435.80000000000547,49.08798333876261,0.24789641561111042,0.062376797146477855
436.6000000000055,49.16723752942246,0.25933208983181877,0.0699317811029609
437.4000000000055,49.245985210967724,0.26832404720232356,0.0795170799315487
438.2000000000055,49.32400361366501,0.28030369071415706,0.0885742510442758
439.0000000000055,49.402001751616275,0.292246061938431,0.09747842103184222
439.8000000000055,49.48038581325859,0.3039670929875776,0.10631276578250129
440.60000000000554,49.558851590856946,0.31531588927580334,0.11626849647728865
441.40000000000555,49.63675902426152,0.3295109342554179,0.1263202573013211
442.20000000000556,49.71565045249931,0.3417263441759425,0.13685928328858196
443.00000000000557,49.79380161467451,0.35779477095569784,0.14823562293336007
443.8000000000056,49.870423897384946,0.36910832949927674,0.16032624742447896
444.6000000000056,49.95010818700064,0.38326425265957315,0.1730417152936548
445.4000000000056,50.02853393746564,0.39974657746255465,0.18625782890690185
446.2000000000056,50.10756615864137,0.41564754858202335,0.20180351483094575
447.0000000000056,50.185431424283166,0.4302904492414225,0.21532901946374652
447.80000000000564,50.263102630578075,0.4495726344921819,0.232435644140747
448.60000000000565,50.34093122560557,0.46452158879800276,0.24839116332684139
449.40000000000566,50.4199039904171,0.4832792411899326,0.2639059253486978
450.2000000000057,50.49811048231516,0.5024003332955059,0.2827489696245201
451.0000000000057,50.57583649830645,0.5217381561784248,0.3020892928931049
451.8000000000057,50.655361645266915,0.5403795367765402,0.3230263983284256
452.6000000000057,50.73252662434585,0.5605129548789366,0.344128650614583
453.4000000000057,50.811121722191494,0.5829625487707896,0.366841033497188
454.20000000000573,50.88990892678855,0.6061702905838514,0.3902421370960145
455.00000000000574,50.96896812798953,0.6338051054732374,0.4154561290104539
455.80000000000575,51.04780438338014,0.6593974546300713,0.442782497223623
456.60000000000576,51.12482335936921,0.6859253072184923,0.47090752704689887
457.4000000000058,51.2036747544945,0.7115902900212344,0.5019350688363116
458.2000000000058,51.282013036321025,0.7369226856832117,0.5340787592053992
459.0000000000058,51.35982969951576,0.7627394399929819,0.5679505888178767
459.8000000000058,51.43917345503661,0.7894038206697924,0.6032177771686713
460.6000000000058,51.51939234716337,0.8193925577116417,0.641171761910899
461.40000000000583,51.597472573726264,0.8460676222719631,0.6803232187957844
462.20000000000584,51.674278295417736,0.8731652366736643,0.7210931472731351
463.00000000000585,51.75486679115628,0.9026071074396861,0.7638321233298463
463.80000000000587,51.83350394614927,0.9323504945876088,0.8109001647039205
464.6000000000059,51.91255007720885,0.9614961775038793,0.8568673653837623
465.4000000000059,51.99095195700564,0.9907062588847229,0.9074349036815187
466.2000000000059,52.06928207527203,1.0220259081891288,0.9597756270567
467.0000000000059,52.147158392777406,1.0510461188991878,1.0144046338952333
467.8000000000059,52.22551191693454,1.0783484085243655,1.070846226159495
468.60000000000593,52.3053687569302,1.1084267189505335,1.1314174611495529
469.40000000000595,52.38295177990452,1.1361289226916766,1.1928898839446487
470.20000000000596,52.46175810135417,1.160552555290093,1.2576517489157544
471.00000000000597,52.54009680935848,1.1854322948815876,1.3245074094054787
471.800000000006,52.619171483304726,1.207741368987554,1.3948789507994213
472.600000000006,52.69834587672502,1.2308364048576803,1.4674001808262203
473.400000000006,52.776308554486135,1.2492521128240826,1.5414231417919737
474.200000000006,52.855279741284754,1.264557468686551,1.6185013098673877
475.000000000006,52.93437324511522,1.2784884485922408,1.6975062301136503
475.80000000000604,53.012390298835946,1.2857756825459765,1.7778350223436863
476.60000000000605,53.09126352348215,1.2942083575637482,1.8607666879028646
477.40000000000606,53.169622012392665,1.2942649679880756,1.9457525229721946
478.20000000000607,53.24710559443672,1.291346280448833,2.0298132956917745
479.0000000000061,53.32681470442154,1.2824881224475349,2.11885507702909
479.8000000000061,53.40587529352036,1.2731600152342564,2.208668602851398
480.6000000000061,53.48398575933842,1.2561931242481157,2.2974454337615935
481.4000000000061,53.562521704840584,1.2375715666749456,2.3882019946435715
482.2000000000061,53.64033615087484,1.2110344021161226,2.4771922023505266
483.00000000000614,53.71952862858537,1.1787204203701123,2.567850866912986
483.80000000000615,53.79826933772439,1.1397802688806256,2.6577144217698354
484.60000000000616,53.87640940896164,1.0947116478600916,2.7451160883932246
485.4000000000062,53.95531558040956,1.0411940685815353,2.8330316807580243
486.2000000000062,54.03321438932298,0.9810490542614664,2.9158324897943655
487.0000000000062,54.11184872944852,0.9202364101914613,2.9963796425577827
487.8000000000062,54.18934722926809,0.848030412921131,3.0739346969972874
488.6000000000062,54.267666930649774,0.7717194551929327,3.1478550383447645
489.40000000000623,54.347113473643816,0.689778689677614,3.219060534576147
490.20000000000624,54.42528939876854,0.6062269052535452,3.282914623816454
491.00000000000625,54.50334808805375,0.5193805788277072,3.3432895759996
491.80000000000626,54.58180318402815,0.4329378994505474,3.39772651654486
492.6000000000063,54.65950787549771,0.34810116287315207,3.4462261205086206
493.4000000000063,54.7353396140367,0.26996489591611667,3.4879704957845767
494.2000000000063,54.81512290890654,0.19300449357628507,3.5264363935283516
495.0000000000063,54.894050390048555,0.12415956812900106,3.5593097562101406
495.8000000000063,54.97238237604883,0.05863354978630066,3.587886186122347
496.60000000000633,55.05048586702292,0.0007462030448785001,3.611467331206135
497.40000000000634,55.129134070753175,-0.053090618064318466,3.6314870400213364
498.20000000000636,55.20654253963659,-0.100021042159645,3.6481917516483184
499.00000000000637,55.28586979774863,-0.14292851175327498,3.6605515343523543
499.8000000000064,55.36439173637411,-0.18028202944980154,3.672563573025548
500.6000000000064,55.441918271342146,-0.2103436725322041,3.680427502019209
501.4000000000064,55.521728436175884,-0.2400252104405354,3.687040921340909
502.2000000000064,55.599802874863485,-0.26338313584000034,3.6916469671760472
503.0000000000064,55.679111513680766,-0.28262699241587796,3.695735104752877
503.80000000000643,55.75849199363549,-0.2971796372260237,3.6970593165945798
504.60000000000645,55.836350161717455,-0.30954719961838745,3.6999991626359177
505.40000000000646,55.915194726114976,-0.3185702465424793,3.701243450184882
506.20000000000647,55.99381051309911,-0.32236931824165727,3.7026499458692426
507.0000000000065,56.0731244821406,-0.3253571186615174,3.7026499509998443
507.8000000000065,56.151852497267306,-0.3250651104096098,3.7026499506694597
508.6000000000065,56.231525947678286,-0.32479469772004244,3.702638640339402
509.4000000000065,56.308620033702326,-0.3220885809890287,3.702981345880095
510.2000000000065,56.38890348134257,-0.32020292352193713,3.7039697529930806
511.00000000000654,56.46684372922328,-0.3140628794148174,3.7045559072147602
511.80000000000655,56.54548434079769,-0.31281013218508175,3.7046298874488115
512.6000000000065,56.623915324743756,-0.311112269947198,3.704629889999925
513.4000000000066,56.7035888839532,-0.31075070707086155,3.7046298899999988
514.2000000000066,56.7818212795372,-0.3112423475348329,3.704629889999999
515.0000000000066,56.858872632510064,-0.31247438643241976,3.7046298900000005
515.8000000000065,56.93718028950153,-0.3135949347252342,3.7046298900000005
516.6000000000066,57.01877371545703,-0.31546177113826585,3.70462989
517.4000000000067,57.0974503635726,-0.3198525838454923,3.7046298900000045
518.2000000000066,57.17693523499326,-0.32296621448479523,3.7046298901843473
519.0000000000066,57.255855288783884,-0.3272980885350548,3.7046367512844154
519.8000000000067,57.33537489509346,-0.33021483579625355,3.705290118843102
520.6000000000067,57.414579509195946,-0.3362044828874169,3.70529000400283
521.4000000000067,57.49337821269751,-0.3420317825905639,3.705290004
522.2000000000066,57.572876786909326,-0.34493981877813035,3.7052900039999037
523.0000000000067,57.65167872755754,-0.3469598413220719,3.7052900022526765
523.8000000000068,57.73057870836221,-0.3516326701174864,3.7056594224019923
524.6000000000067,57.81060620119686,-0.354288195090564,3.7065896996871777
525.4000000000067,57.88777805959583,-0.3573716503971035,3.7079199847252027
526.2000000000068,57.96886828630642,-0.3600332904025287,3.707919977278889
527.0000000000068,58.047609296384714,-0.36137156673967735,3.707155333667921
527.8000000000068,58.1267870583242,-0.36291576666983993,3.7066001539951863
528.6000000000067,58.205943877850466,-0.36304541815031466,3.7066012539222584
529.4000000000068,58.28587722351163,-0.3667078169656189,3.7079229875867648
530.2000000000069,58.36544271484526,-0.3659349516107713,3.7079199820814495
531.0000000000068,58.44437039531066,-0.36725658334561506,3.707919982000003
531.8000000000068,58.52369605640405,-0.3685953073527878,3.7079199819999995
532.6000000000068,58.60338560730213,-0.36842027606190736,3.707919982012675
533.4000000000069,58.68189402655475,-0.36915755964750774,3.7079202419521486
534.2000000000069,58.76169362064841,-0.36864145361138867,3.708581283420644
535.0000000000068,58.84089346952699,-0.36922110773728994,3.708576912669972
535.8000000000069,58.91745277880857,-0.3693378544089989,3.7092398557329203
536.600000000007,58.99990635961191,-0.3682648120102746,3.709239807000052
537.4000000000069,59.07776198895879,-0.36886501175710984,3.709239806999441
538.2000000000069,59.15803286847341,-0.36805082919462756,3.709239788016736
539.0000000000069,59.236839117197306,-0.3681852536781522,3.709940385515592
539.800000000007,59.31721960481465,-0.3677520895259602,3.709899922022752
540.600000000007,59.39557158886682,-0.36753791016652976,3.709899921000041
541.4000000000069,59.47492558809481,-0.3673374041163161,3.709899920999983
542.200000000007,59.55477496269206,-0.3672370758933348,3.7098999203960497
543.000000000007,59.63349142125611,-0.36622099357758353,3.709881744243772
543.800000000007,59.712423648367526,-0.3686496163260854,3.710559526862367
544.600000000007,59.79089728578824,-0.368195647803854,3.710560034993227
545.400000000007,59.87010277834234,-0.36845932198885367,3.710560035
546.000000000007,59.93064924588128,-0.3677777415997683,3.7105600349999994