File: 01_Data/PE_Foam_Pipe_Insulation/STA/N2/10K_min/PE_Foam_Pipe_STA_N2_10KData_220923_R1.csv
##Temp./Â°C,Time/min,DSC/(mW/mg),Mass loss/mg
51.0,10.741411923731906,-1.5664496581116323,0.003379427917476363
52.100000000000016,11.127555144421555,-1.4075599371241738,0.0017924833620783787
53.20000000000003,11.376632227340556,-1.3041988964249336,0.00044551301299744495
54.30000000000005,11.584902374759404,-1.2247490958007352,0.003417393142880698
55.40000000000006,11.774379476589854,-1.15833596364371,0.003786064394476263
56.50000000000008,11.944971217571256,-1.1060255432070203,0.00027364200439095043
57.600000000000094,12.110551065015517,-1.0565640286278128,0.0038036349204553233
58.70000000000011,12.264560997232802,-1.0164633059972612,0.0038150983062177346
59.800000000000125,12.414529291289238,-0.983518995444731,0.002741225753636556
60.90000000000014,12.560674558235323,-0.959083888424859,0.0011570243512757372
62.000000000000156,12.704229630016913,-0.9393885627027608,-0.00037456068709040835
63.10000000000017,12.840628174725776,-0.9225406705140791,0.004138209159841644
64.20000000000019,12.981345549703581,-0.9081192839602941,0.004947765889875555
65.30000000000021,13.11793719617511,-0.8952982486950317,0.004895911668405084
66.40000000000022,13.251703691881627,-0.8824650774863843,0.004051658197106178
67.50000000000023,13.382072631800593,-0.8680122630188789,0.0064077110874309895
68.60000000000025,13.512951688902739,-0.8532868793996258,0.005055606643050048
69.70000000000027,13.640540154580165,-0.8387118661252817,0.0036045189425539803
70.80000000000028,13.76905207542409,-0.8241644078801003,0.0023994645082154875
71.90000000000029,13.893987579309933,-0.8059485538434927,0.0011173206105130618
73.00000000000031,14.020586076024406,-0.7909187656638212,0.0016311148875622905
74.10000000000034,14.143801011866275,-0.7708503114671986,0.0017633101214080682
75.20000000000034,14.265005753731865,-0.7557540247751178,0.0033547713879205077
76.30000000000035,14.38639865359747,-0.7386336165168376,0.0024148625437963034
77.40000000000038,14.503766655592122,-0.7207531519548818,0.0038279265603380352
78.5000000000004,14.628829986002852,-0.7021222898524444,0.005158924638250184
79.6000000000004,14.747046765329836,-0.6833602373486016,0.006505597669851149
80.70000000000041,14.865944657594095,-0.6663012924456658,0.0025273370097007586
81.80000000000044,14.982863160981646,-0.6484996541347663,0.0012034313347735193
82.90000000000046,15.101233341181956,-0.628758447243251,0.004231305220000259
84.00000000000047,15.21797353111971,-0.612041394746369,0.0036783020917585674
85.10000000000048,15.333904613826853,-0.5933113749806614,0.002862603506122774
86.2000000000005,15.44917000000005,-0.5746099999999918,0.004169998812981746
87.30000000000052,15.56326735680957,-0.5568597785222317,0.002761855733759866
88.40000000000053,15.677108595098034,-0.5370215112037224,0.0041616751743838165
89.50000000000054,15.790220461320429,-0.5181069448248724,0.005501646765408097
90.60000000000056,15.903411181276617,-0.4999834531050749,0.005386315122042795
91.70000000000059,16.01480449617953,-0.47870820932775227,0.005479068282602029
92.8000000000006,16.127743148517432,-0.4520553703650009,0.004808982682173557
93.9000000000006,16.2400894362306,-0.42743561078508446,0.0035916778404745386
95.00000000000063,16.34937538452374,-0.4003086930265018,0.005600915420069796
96.10000000000065,16.46094851708362,-0.37386834865159346,0.007355025843192031
97.20000000000066,16.571418005682716,-0.35112340435108896,0.005997769351565374
98.30000000000067,16.682376014644397,-0.3356984020146379,0.004720013676514867
99.40000000000069,16.79191159829024,-0.3222330951996162,0.002086691393849982
100.50000000000071,16.902105321639855,-0.3013102636845436,0.003620444598170458
101.60000000000072,17.010979445525944,-0.27554161616323425,0.003289248261128641
102.70000000000073,17.12007711083507,-0.2410769911688971,0.0010972710940393426
103.80000000000075,17.229760320245028,-0.19812177391609725,0.0036348950441871253
104.90000000000077,17.338244378513078,-0.1484248153451526,0.0023000664240520052
106.00000000000078,17.44445177991127,-0.09462131524836835,0.002300019522516905
107.10000000000079,17.555837960299254,-0.024279363420429505,0.003632782736306517
108.20000000000081,17.66439434727374,0.052038981981390876,0.004927757221667939
109.30000000000084,17.773845913098956,0.14387425957662128,0.006416321659419744
110.40000000000084,17.881524976345048,0.2481473914179039,0.0061462542935881714
111.50000000000085,17.991122136104796,0.362683646400198,0.005204262711650642
112.60000000000088,18.098837710251622,0.4840196143287606,0.006460628885153419
113.7000000000009,18.209453890703035,0.5769992593383001,0.007789729614869678
114.8000000000009,18.31795971063058,0.5499700515557308,0.006479892931467113
115.90000000000092,18.425274577238937,0.25690092614291216,0.006482839996244216
117.00000000000094,18.532089683010028,-0.10775387786249946,0.006246877062381806
118.10000000000096,18.636750993817728,-0.30859483806704313,0.004829981907523262
119.20000000000097,18.74381477650588,-0.42143839091802926,0.00484181566807429
120.30000000000098,18.848963384145083,-0.4804912087344783,0.006517000614503665
121.400000000001,18.95531365644026,-0.5094168206573924,0.005155154023707809
122.50000000000102,19.05873097959816,-0.5219343349817018,0.005223587285902553
123.60000000000103,19.16704736081927,-0.5280569588772543,0.005821067539818259
124.70000000000104,19.27245553790144,-0.5290716106389247,0.005771043974672985
125.80000000000106,19.377814123706152,-0.5281203502242656,0.007017855523825389
126.90000000000109,19.484147770365876,-0.5247708666066778,0.006467788457936052
128.00000000000108,19.59073782691263,-0.5221365713349048,0.005149353429131587
129.1000000000011,19.69637372025677,-0.5165666982761318,0.0038399982180639114
130.20000000000113,19.80282425342556,-0.5122315329315034,0.003840011205738847
131.30000000000115,19.908093061305074,-0.5081250509460133,0.003512639404987361
132.40000000000117,20.0136047562314,-0.5039038989645087,0.005167055557477873
133.50000000000117,20.119063668063617,-0.5004597981441277,0.005149859538937207
134.6000000000012,20.224380544593544,-0.4971952879278111,0.004887081324898901
135.7000000000012,20.32994636363863,-0.49318716587879297,0.0020962549297962596
136.8000000000012,20.436224915357172,-0.4894902033389217,0.0008705853315928991
137.90000000000123,20.540485502932498,-0.48404348318937207,-0.0004622930413802351
139.00000000000125,20.646265187593393,-0.4788188330902866,0.001978732806061423
140.10000000000127,20.75165560873303,-0.47551674550536494,0.0035925285097491155
141.2000000000013,20.857512943581966,-0.47099055839342246,0.004924034253736664
142.3000000000013,20.961136185529277,-0.46655275985646466,0.0011054626094217923
143.4000000000013,21.06779554143512,-0.4627243327909413,-0.00027692361984499314
144.50000000000134,21.172561083141684,-0.457587668827295,0.0011009041025946686
145.60000000000133,21.27553529643933,-0.45262507419105175,0.0043996054037922505
146.70000000000135,21.382464315691696,-0.4488684304183651,0.005050708182917418
147.80000000000138,21.487448642447273,-0.44438246369285034,0.003742224204810185
148.9000000000014,21.59332652565485,-0.440258054040978,0.003567775742483903
150.00000000000142,21.696746511840402,-0.4353519698548992,0.0024245777771110255
151.10000000000142,21.802669668534374,-0.4308976314742843,0.003406195942379675
152.20000000000144,21.906081921075575,-0.426896770121724,0.0051023980215374465
153.30000000000146,22.011206413385004,-0.4224927707687753,0.006470108220643311
154.40000000000146,22.115588507262657,-0.4168593980555681,0.0050552322843469
155.50000000000148,22.220361685133344,-0.41444922654085026,0.0028573135685734385
156.6000000000015,22.32374860316026,-0.4090809787171441,0.0024101196818708814
157.70000000000152,22.42851640208776,-0.4048619602953075,0.0010908968266694075
158.80000000000155,22.532908023791524,-0.4008717696671182,0.0010864394318543802
159.90000000000154,22.636726322412493,-0.39764312121239564,0.0036944845587933983
161.00000000000156,22.73886091932578,-0.3942611719533848,0.003730157979259907
162.1000000000016,22.847394314890522,-0.390932985374889,0.0037303613639636524
163.20000000000158,22.9510694371962,-0.3851639038638,0.003730319560680151
164.3000000000016,23.055148996822094,-0.38275465837729755,0.003745376960692326
165.40000000000163,23.159661641508,-0.37714801429870837,0.0013837499247015828
166.50000000000165,23.26465975548345,-0.37498644363575606,0.0011294146137679206
167.60000000000167,23.36898016786874,-0.3707585176928068,0.0032419902943230383
168.70000000000167,23.474424430994183,-0.36554288891929043,0.0031794046474447057
169.8000000000017,23.578073306071538,-0.36242284870394237,0.002774271901121672
170.9000000000017,23.6822902694131,-0.35897192560271757,0.0031796273079596205
172.0000000000017,23.78567895177491,-0.35477528520814844,0.0031801515744778186
173.10000000000173,23.891280733825614,-0.35021656650405486,0.0018612000076734248
174.20000000000175,23.996425528376154,-0.3465232068964409,0.0015300563240074894
175.30000000000177,24.100336767964304,-0.344090998921428,0.0015308436277905457
176.4000000000018,24.20479657113306,-0.34051025977844596,0.0018708445085779957
177.5000000000018,24.30966925748711,-0.3367541794144444,0.0005435407845455487
178.6000000000018,24.414702711479602,-0.333265320934449,-0.0007799321128718617
179.70000000000184,24.519488858907494,-0.32770432962313006,-0.0007798619390797512
180.80000000000183,24.620579809671735,-0.32660620311057614,0.0005405789144514728
181.90000000000185,24.727519319015435,-0.323117989392589,0.0018611317239738412
183.00000000000188,24.829539599016115,-0.3211710786180798,0.0015301763384094613
184.1000000000019,24.93535732398343,-0.3184244628441353,0.0005608811308102091
185.20000000000192,25.03935935370615,-0.3152953569536417,0.0015077120239537223
186.30000000000192,25.143765889434587,-0.31262743858668235,0.0008808150305448237
187.40000000000194,25.247497135193754,-0.3110099241491618,0.0021803690367656614
188.50000000000196,25.352085125389127,-0.305494362993859,0.0018601776862050556
189.60000000000196,25.456838318974352,-0.3037031672883661,0.0018621956760949132
190.70000000000198,25.560402800551742,-0.3007018427289727,-0.0006978193751763229
191.800000000002,25.660995179083333,-0.2984561523780128,-0.0007798360139243954
192.90000000000202,25.768011914315487,-0.2958555887624717,-0.000779835999994205
194.00000000000205,25.871929281079186,-0.29364368707293914,-0.0007798350188910064
195.10000000000204,25.97735985899048,-0.2912141973739939,-0.0015314825022541
196.20000000000206,26.07926460960864,-0.28818086481733235,-0.0004399967371542246
197.3000000000021,26.1865223253293,-0.2830567319115025,0.0005520064390118762
198.40000000000208,26.289011624034146,-0.2819414462658368,-0.002412538656522578
199.5000000000021,26.393705889899174,-0.2797677858228142,-0.0024211783295857714
200.60000000000213,26.498758735550037,-0.27544049482279404,-0.00275012808031061
201.70000000000215,26.603360827682543,-0.2727469025197173,-0.004041026916244306
202.80000000000217,26.70682154587556,-0.2712941991738416,-0.0037357055259743532
203.90000000000217,26.811824207119123,-0.2671399620466772,-0.003734571565164657
205.0000000000022,26.9164542072771,-0.2632774526712019,-0.003739839999448158
206.1000000000022,27.02059637877114,-0.26069405635519255,-0.0037364514612061583
207.2000000000022,27.125672478782672,-0.25840479459625304,-0.002420011740273509
208.30000000000223,27.22938796598599,-0.25269744894696816,-0.004719910479671796
209.40000000000225,27.33353956781386,-0.2519493097343201,-0.004733968514146092
210.50000000000227,27.438394792348284,-0.24706462310570765,-0.005710188504213676
211.6000000000023,27.54136216084453,-0.24506124692886205,-0.005710185937148005
212.7000000000023,27.64578462270765,-0.24211881275263228,-0.005744805897965222
213.8000000000023,27.750438048618612,-0.2396180219392228,-0.006033225405228215
214.90000000000234,27.854697123738365,-0.2386098779817493,-0.007360280693327503
216.00000000000233,27.957279868371785,-0.23727604809256247,-0.0073598400922536555
217.10000000000235,28.06302983300666,-0.23550270775580726,-0.007182556356733372
218.20000000000238,28.167555204988282,-0.2350042638815725,-0.0063225347646787
219.3000000000024,28.27170817434077,-0.23062643106050243,-0.006356121257111269
220.40000000000242,28.37504719907506,-0.2279893639307419,-0.01044852402034202
221.50000000000242,28.479079514654526,-0.22494174011048518,-0.011212012664838511
222.60000000000244,28.584281444187045,-0.22358582435632232,-0.011198749223681581
223.70000000000246,28.689459538544366,-0.221460159029326,-0.011546342244479035
224.80000000000246,28.792846708296548,-0.2180447316776656,-0.012871697573627827
225.90000000000248,28.897419879981243,-0.21512498375649072,-0.012850106702063435
227.0000000000025,29.00167030627776,-0.21135041504587815,-0.011851260241580341
228.10000000000252,29.105735398231197,-0.2099039939806351,-0.01218191194042717
229.20000000000255,29.209549907412452,-0.208293854345549,-0.012849344473894853
230.30000000000254,29.314191931932243,-0.20639745025086034,-0.015141748678312084
231.40000000000256,29.418516116074816,-0.20376883401253365,-0.01690754261616423
232.5000000000026,29.5234180182767,-0.20135637687564725,-0.01952929682649973
233.60000000000258,29.624337441794165,-0.1985963535356101,-0.019520036910689598
234.7000000000026,29.732253176577338,-0.19799499747755378,-0.01814688066385184
235.80000000000263,29.83653849166233,-0.19581073041703853,-0.01790026710863568
236.90000000000265,29.93958412065949,-0.1939077296171642,-0.019219844380996776
238.00000000000267,30.04259475520266,-0.1930926332976736,-0.01922441022716015
239.10000000000267,30.148652309149437,-0.18889391725622376,-0.02185628395947603
240.2000000000027,30.25376744034119,-0.18832731314970388,-0.023197856227056945
241.3000000000027,30.35856833769801,-0.1854272167489942,-0.02185125223484441
242.4000000000027,30.462799131800825,-0.18321491449239635,-0.024530539751272507
243.50000000000273,30.56765542151548,-0.1821585482256006,-0.025136129580188182
244.60000000000275,30.671094103173974,-0.17980197501998227,-0.027119954333091556
245.70000000000277,30.775540224498602,-0.1791252140067942,-0.02717478619823588
246.8000000000028,30.879848926885753,-0.17757677831639326,-0.02816708575345217
247.9000000000028,30.9856213539039,-0.1764165231107584,-0.02977325949316434
249.0000000000028,31.09041717577881,-0.17551210313014684,-0.031069879041679016
250.10000000000284,31.193256111032458,-0.17382142558932648,-0.031999235763926936
251.20000000000283,31.298270835978663,-0.17256714303767398,-0.03206487564124849
252.30000000000285,31.40368945454942,-0.17051875435115266,-0.03651971047213687
253.40000000000288,31.50802726059793,-0.16999714543263897,-0.036449952119818274
254.5000000000029,31.6123175869696,-0.16779964638557807,-0.0363693050867786
255.60000000000292,31.71749061080365,-0.1673016463846753,-0.040277174361603496
256.7000000000029,31.822209361167328,-0.1650333137093098,-0.04172019974758978
257.8000000000029,31.925733157241385,-0.16405726691534048,-0.04105981049166729
258.90000000000293,32.03122193822074,-0.16257218276084945,-0.041054301363410595
260.00000000000296,32.13570622366604,-0.16047646477368574,-0.04378158215114958
261.100000000003,32.24059528631477,-0.1606836679327506,-0.04511986789115641
262.200000000003,32.34479736210924,-0.1589497457532172,-0.046484210058437725
263.300000000003,32.450359617711676,-0.15758235325341058,-0.048572799410182554
264.40000000000305,32.554451745983066,-0.1570461754935401,-0.049114489179479026
265.50000000000307,32.659900242133325,-0.15780574862933808,-0.05036104675329245
266.6000000000031,32.765359859225335,-0.15673863983068703,-0.050326395495009724
267.7000000000031,32.869169010316206,-0.15598000781014146,-0.054371742832358905
268.8000000000031,32.97604862132083,-0.15479541924637696,-0.05566039684389423
269.9000000000031,33.08016433465167,-0.1545143636780747,-0.0536895367293031
271.0000000000031,33.18511554657545,-0.1514405064922039,-0.05689426696390365
272.10000000000315,33.28965904843874,-0.150636390415923,-0.05963675372396704
273.2000000000032,33.394821372275715,-0.1472320356755919,-0.05822807921800699
274.30000000000314,33.49981894716247,-0.14783460860564793,-0.05929034040093173
275.40000000000316,33.60570324330088,-0.14576440171512745,-0.05994848011123555
276.5000000000032,33.7088758440495,-0.143534666474879,-0.060934478869114184
277.6000000000032,33.81453099030909,-0.14229378014111815,-0.06353961545221232
278.70000000000323,33.919594747529125,-0.1411248224066429,-0.06523216874257853
279.80000000000325,34.024320943687,-0.1396540908755801,-0.06715068253402645
280.9000000000033,34.129931223454825,-0.13720483363731567,-0.06587546988473969
282.0000000000033,34.23512036025117,-0.13697264581684224,-0.06716724129015272
283.1000000000033,34.33926491909012,-0.13556794319339682,-0.06719038193267668
284.20000000000334,34.4444390619901,-0.13370459413121483,-0.06634867565950708
285.30000000000337,34.549468507859295,-0.1345367248260086,-0.06619985177695176
286.40000000000333,34.65502311875782,-0.1322361087159798,-0.06752007171798535
287.50000000000335,34.75981250921923,-0.1305926262178966,-0.06752195532632133
288.6000000000034,34.86398205216354,-0.1287732952277598,-0.06882371629649597
289.7000000000034,34.968519800647016,-0.12642627605028967,-0.07147392607131797
290.8000000000034,35.07434948022456,-0.12575382867346652,-0.07014946299894964
291.9000000000034,35.17917088640769,-0.1245800323660882,-0.07281069867055878
293.0000000000034,35.28482789852154,-0.12451921156649684,-0.07541724575129205
294.10000000000343,35.38948598074006,-0.12313056620253333,-0.07806133403473048
295.20000000000346,35.49558145487668,-0.12121695942847835,-0.07938103479327197
296.3000000000035,35.59873559955747,-0.1208938204191582,-0.08069568742572564
297.4000000000035,35.70451771175291,-0.11976344563295432,-0.08068545679823069
298.5000000000035,35.81009043703713,-0.11755103636502824,-0.08069001754093108
299.60000000000355,35.9150642148439,-0.11838872208292874,-0.07937008122359135
300.70000000000357,36.02102095094234,-0.11615936547013199,-0.08035632015472816
301.8000000000036,36.12554411479445,-0.11468145001796258,-0.08101984671861961
302.9000000000036,36.22958984928081,-0.11479691879356448,-0.08101982706260591
304.0000000000036,36.334279157036285,-0.1132435758122671,-0.08142003797479491
305.1000000000036,36.44199914401649,-0.11377266630859484,-0.08226688317367792
306.2000000000036,36.547722296191736,-0.11134737204564545,-0.08531141781118956
307.30000000000365,36.65317347119615,-0.11020345860561527,-0.08564125320427607
308.4000000000037,36.75891603629548,-0.10862813697254955,-0.08550749267387614
309.5000000000037,36.86415820179143,-0.10645275116826557,-0.08182186401380909
310.60000000000366,36.969482549463244,-0.1052050042870512,-0.08504851617828901
311.7000000000037,37.075642819021475,-0.10366217756127365,-0.08841494910776104
312.8000000000037,37.18092968294586,-0.1029913127638475,-0.09053858305973339
313.90000000000373,37.2864456175197,-0.10118025029572121,-0.09102041139434958
315.00000000000375,37.392680850965334,-0.10005396614109506,-0.09003712797882502
316.1000000000038,37.49863385668175,-0.09801601210462216,-0.09004207531102804
317.2000000000038,37.60391549257028,-0.0949011918572965,-0.08871002493988733
318.3000000000038,37.709548736881665,-0.09398837770969927,-0.09134321501950415
319.40000000000384,37.81610489467636,-0.09176918898673822,-0.09133990734435571
320.5000000000038,37.92106132245984,-0.09017231079139143,-0.09135576117842747
321.60000000000383,38.02743005003211,-0.08735432260689069,-0.09497706845301224
322.70000000000385,38.13383015929068,-0.0850951055037843,-0.09754902467983051
323.8000000000039,38.23998556915088,-0.08160079005712312,-0.09865569275790209
324.9000000000039,38.34557148949757,-0.0803945068905255,-0.09923976263794998
326.0000000000039,38.449170000000365,-0.07783676999997834,-0.09792983349620332
327.10000000000394,38.55672227556027,-0.07419727580255304,-0.09792007674805436
328.2000000000039,38.66379826559609,-0.07172982100250545,-0.09799601071747022
329.30000000000393,38.76934880314311,-0.06852504767913199,-0.1019971550728882
330.40000000000396,38.87457104852746,-0.0656584928679461,-0.10246972035708968
331.500000000004,38.98128723236808,-0.0631411429435398,-0.10593806504433001
332.600000000004,39.08648876537838,-0.059440429667425014,-0.10567228138199614
333.700000000004,39.191094498415794,-0.05713087595294549,-0.10677697388623031
334.80000000000405,39.29842619600802,-0.05476560290008425,-0.10890971470150967
335.90000000000407,39.40450690409399,-0.050086342949368284,-0.110016253159535
337.0000000000041,39.51020599369662,-0.04820445710329994,-0.11451102453065598
338.10000000000406,39.615473537098815,-0.046089876390912984,-0.11653287080950925
339.2000000000041,39.721480699732936,-0.0426186148030715,-0.116602923538494
340.3000000000041,39.82834342110969,-0.03854669202756138,-0.11879006398149006
341.4000000000041,39.93335003580957,-0.03542461092296047,-0.11944295755997825
342.50000000000415,40.03944427325868,-0.032788548566784884,-0.12296981607026414
343.6000000000042,40.1455449144988,-0.029991849770197997,-0.1263331617266208
344.7000000000042,40.252591664478196,-0.026815961395840453,-0.12740627958047535
345.80000000000416,40.357906751688986,-0.024477723332655067,-0.1314014022473966
346.9000000000042,40.46362320288228,-0.021066937526256352,-0.13060616217964327
348.0000000000042,40.56960179889366,-0.019978881503155264,-0.13301875326323476
349.10000000000423,40.67505568959966,-0.018855586939101956,-0.13576356123024436
350.20000000000425,40.782290496224626,-0.01678401658395479,-0.13876471084026676
351.3000000000043,40.88853894782227,-0.01627031501020069,-0.14176242560388497
352.4000000000043,40.9947269269741,-0.013700655962771317,-0.14813278943775732
353.5000000000043,41.10069370963209,-0.01363990720789744,-0.15200173344051038
354.60000000000434,41.207615333722444,-0.012617770371793322,-0.153924683834739
355.7000000000043,41.313632317243616,-0.010364185383052381,-0.15429168638887436
356.80000000000433,41.41993126645872,-0.012682153007629688,-0.1568668552769985
357.90000000000435,41.52652753718603,-0.01254942829928447,-0.15951529728608982
359.0000000000044,41.63251550141593,-0.011812665064104536,-0.16183352810624463
360.1000000000044,41.7392645186809,-0.0135468829652388,-0.1644586433705455
361.2000000000044,41.844904691650946,-0.014492979961340796,-0.1658617064936565
362.30000000000445,41.951946946471764,-0.017012426742171086,-0.16971379299557698
363.4000000000044,42.05907143649065,-0.016364165630159504,-0.17236618485696553
364.50000000000443,42.16437208473941,-0.018770126343753562,-0.1734403792770567
365.60000000000446,42.27027074996192,-0.022218620170430897,-0.1748444477201101
366.7000000000045,42.3766714261594,-0.023725371216641176,-0.18009632534837738
367.8000000000045,42.48373913499004,-0.02595285783963799,-0.1848274900130571
368.9000000000045,42.58926993871819,-0.027608135350646313,-0.18872016315523465
370.00000000000455,42.69645538677301,-0.030935381711492373,-0.19020333192102257
371.10000000000457,42.80259554023909,-0.03322445675677306,-0.19422939272113027
372.2000000000046,42.908275887359395,-0.036403047576561556,-0.1928384250351951
373.30000000000456,43.015534232661786,-0.040509036802843346,-0.19157653838467104
374.4000000000046,43.122255682847666,-0.043217563016650924,-0.19026248555095915
375.5000000000046,43.22926587995467,-0.046966580818756876,-0.19223731524261556
376.6000000000046,43.335716365706695,-0.05206704041119264,-0.19707124372022244
377.70000000000465,43.44300283408443,-0.057736482856007056,-0.20009076875860954
378.8000000000047,43.54907946638241,-0.06113942334593005,-0.19991977564512053
379.9000000000047,43.65600095074727,-0.06559558267067549,-0.20280286380852086
381.00000000000466,43.76249173705309,-0.0691217318664163,-0.20650509510848813
382.1000000000047,43.8702128661131,-0.07252888593138858,-0.2065609198339473
383.2000000000047,43.97717338915629,-0.07497770729715153,-0.20777036102575064
384.30000000000473,44.084926032334614,-0.07695816048895175,-0.2090301804727508
385.40000000000475,44.19020567393007,-0.07894544051703827,-0.20924784164500698
386.5000000000048,44.296919671045195,-0.07978682582497998,-0.20667460470335453
387.6000000000048,44.404351853514406,-0.08043611552984446,-0.20903511934167307
388.7000000000048,44.51016286498251,-0.08029088546719533,-0.21395153074741824
389.80000000000484,44.61739478575624,-0.07850988293790975,-0.21749714266074083
390.9000000000048,44.72355666120714,-0.0781499637407367,-0.21352616727514695
392.00000000000483,44.83134825111489,-0.07814532687574414,-0.2148503428917321
393.10000000000485,44.93756727620726,-0.07795121328776425,-0.21617223573008149
394.2000000000049,45.04489445619827,-0.07712650154055632,-0.21745910153833226
395.3000000000049,45.15152852947607,-0.07770572238052861,-0.21752822377824854
396.4000000000049,45.2585529392466,-0.07553081506339791,-0.2185150456483509
397.50000000000495,45.36465265186456,-0.07515233278763958,-0.22067274740733467
398.6000000000049,45.472613937983425,-0.07361504186863667,-0.22486100158618028
399.70000000000493,45.57966373699715,-0.07284116075751096,-0.22747636207486188
400.80000000000496,45.68613575510323,-0.07220355809312673,-0.2269900405368559
401.900000000005,45.79159067766176,-0.06999145885300484,-0.22608090374735657
403.000000000005,45.900467009817085,-0.06860924265088222,-0.22879999819979613
404.100000000005,46.007426778040276,-0.0669265867354645,-0.23011148265734027
405.20000000000505,46.11415748685091,-0.06689640148515999,-0.23117010149133455
406.30000000000507,46.221326048777655,-0.06558558677270784,-0.234060769844203
407.4000000000051,46.3286961260937,-0.0631939255661779,-0.23733236862727036
408.50000000000506,46.436101646957006,-0.05881956363929519,-0.23866980521536796
409.6000000000051,46.54255356208373,-0.05821905320812753,-0.2399737319854478
410.7000000000051,46.65097544933746,-0.056837190238888384,-0.2433690901096912
411.8000000000051,46.75780875766485,-0.055088167594611444,-0.24855158928084187
412.90000000000515,46.86498873666512,-0.051820094521029716,-0.2498769602540758
414.0000000000052,46.972191099471814,-0.05049990372693458,-0.2540768497731496
415.1000000000052,47.07916904385973,-0.04662173746889917,-0.25639341444922037
416.20000000000516,47.18586724561258,-0.044096145914066395,-0.2581328618368013
417.3000000000052,47.29265307091473,-0.039624174506629556,-0.26221032480128104
418.4000000000052,47.39862126547983,-0.037094124613518145,-0.26677631086451425
419.50000000000523,47.507745409903386,-0.03375505898275005,-0.26675735264849987
420.60000000000525,47.61501503275171,-0.02946367431991472,-0.2693135779477336
421.7000000000053,47.722617118670996,-0.024406056078110354,-0.27422160924301986
422.8000000000053,47.83019520879124,-0.020222138340191497,-0.2770711257960876
423.9000000000053,47.93691224170072,-0.015224119662264233,-0.2809504145436845
425.00000000000534,48.044252545480646,-0.008925994730687689,-0.28660207277653615
426.1000000000053,48.15151899390411,-0.004124827466083032,-0.2942689529617266
427.20000000000533,48.258552016396195,0.00142262037469745,-0.302428715232657
428.30000000000535,48.36633209433772,0.006159099456862003,-0.30698551976472377
429.4000000000054,48.473546089738605,0.010962915775423788,-0.3135994203724102
430.5000000000054,48.580521415955616,0.016411742025763912,-0.32162396274545735
431.6000000000054,48.68820942563962,0.022052153071698152,-0.3276250302944441
432.70000000000545,48.795333135654474,0.028076314814056497,-0.3359125564002605
433.8000000000054,48.90248993654208,0.03354643636677677,-0.3453208424032792
434.90000000000543,49.010883122429,0.042824378757224675,-0.3546406769169099
436.00000000000546,49.118578248385305,0.0501566498626532,-0.36476192980208255
437.1000000000055,49.22697782134198,0.061314628086990695,-0.3756236156717794
438.2000000000055,49.33360984833593,0.06961246519127698,-0.3843838269548665
439.3000000000055,49.43906261643772,0.07926940330343597,-0.3967474809163978
440.40000000000555,49.548989009244934,0.09061443227111066,-0.40881672392319146
441.50000000000557,49.656161809304905,0.10317952094342361,-0.4247278760556559
442.6000000000056,49.763652943400075,0.1150970956061418,-0.43846757053042307
443.70000000000556,49.872037719728795,0.12800164951804435,-0.45488906168110876
444.8000000000056,49.97917097520457,0.1428400456778498,-0.4752605366400191
445.9000000000056,50.08768169236018,0.15842351883911987,-0.4920974972317729
447.0000000000056,50.19345921863952,0.17424823898005604,-0.5081794940709443
448.10000000000565,50.302245299841246,0.1944800377823396,-0.5313262993032501
449.2000000000057,50.410271123100074,0.21205946306859633,-0.5569298065510297
450.3000000000057,50.517612542998314,0.234321001774724,-0.5803882685900374
451.40000000000566,50.625304231334184,0.25616464608878886,-0.6057066127515345
452.5000000000057,50.733440655789124,0.28132043745005336,-0.6341333611757767
453.6000000000057,50.8406629438857,0.3058672216825095,-0.6651554876390269
454.70000000000573,50.948454866408284,0.33254667864704024,-0.6982191166603231
455.80000000000575,51.05681335359037,0.3616040906909575,-0.7347063646299445
456.9000000000058,51.163223925759226,0.39603012612835164,-0.7692008840813922
458.0000000000058,51.271675052490224,0.4304911892617878,-0.8120397964285058
459.1000000000058,51.38105992761346,0.46347964868414626,-0.8596238921426194
460.20000000000584,51.48859682015487,0.4986529263515542,-0.9051476203844842
461.3000000000058,51.59666619446024,0.5353390138105523,-0.9591851760194134
462.40000000000583,51.70452795200355,0.5733799090675824,-1.0170841041791445
463.50000000000585,51.81278220371351,0.6114664320258271,-1.076441412879762
464.6000000000059,51.92022452694884,0.6513895427107551,-1.1399845000261863
465.7000000000059,52.0271030087651,0.6877272253290345,-1.2047195761639742
466.8000000000059,52.137579925885625,0.7262593772144321,-1.276179895932764
467.90000000000595,52.24576680694581,0.7676128578278171,-1.353293092735138
469.0000000000059,52.353622778811186,0.8079601610887047,-1.431584163641996
470.10000000000593,52.46142831966662,0.8445830655826071,-1.520021961072541
471.20000000000596,52.570782298743985,0.8813593822443502,-1.6108912129389292
472.300000000006,52.6788706726493,0.9146366237852392,-1.706446313754514
473.400000000006,52.78774883406382,0.9415411748397141,-1.809155489028612
474.500000000006,52.89589312399812,0.971861572445935,-1.914132106298167
475.60000000000605,53.00461722502369,0.9966063475304284,-2.0227711206000394
476.70000000000607,53.113359885420714,1.020486075160285,-2.135544479455827
477.8000000000061,53.22106478816951,1.0347127341098292,-2.2561522092242225
478.90000000000606,53.32945840417048,1.0395489538900917,-2.3735956746035827
480.0000000000061,53.43794860136002,1.0407287004138324,-2.4948649359309916
481.1000000000061,53.5463666976432,1.0313854578128325,-2.6229490543549074
482.2000000000061,53.65424943001662,1.0114240746161642,-2.7480420183355974
483.30000000000615,53.76350674399072,0.9788335179288931,-2.8757822081522404
484.4000000000062,53.871647969421446,0.9349260331402476,-3.001375850643933
485.5000000000062,53.979448701317,0.8751566655911976,-3.128033690166213
486.60000000000616,54.086875230783505,0.8115113148652682,-3.2402943741256642
487.7000000000062,54.19398185525861,0.7263482682949771,-3.3546975539129056
488.8000000000062,54.302271452594674,0.6228742078414757,-3.4671113472102495
489.90000000000623,54.41051380242465,0.5107674872429908,-3.5651840709216076
491.00000000000625,54.51701170876572,0.3920265007461441,-3.6526261632689883
492.1000000000063,54.623443305129335,0.2763471838268057,-3.7294153214031383
493.2000000000063,54.728004043123974,0.16299514258894854,-3.793390565729589
494.3000000000063,54.83799824087717,0.05334742045658149,-3.8528502891788916
495.40000000000634,54.94506618261588,-0.04404977299921536,-3.8984034980080335
496.5000000000063,55.05238122159823,-0.13190519555753102,-3.939920546502992
497.60000000000633,55.16003157353176,-0.2167038602218107,-3.9685466082869034
498.70000000000636,55.26808261381528,-0.2932857579965657,-3.989415313914625
499.8000000000064,55.375262442921986,-0.3548510262616112,-4.003120758319657
500.9000000000064,55.483544289630515,-0.4060316417505924,-4.0163604618226145
502.0000000000064,55.591780540563455,-0.44202885726928215,-4.023752580713892
503.10000000000645,55.69927207138463,-0.4718659620519204,-4.028618332619995
504.2000000000064,55.80784364904468,-0.4919248238426123,-4.029259976415229
505.30000000000643,55.914999012559946,-0.5053032201684461,-4.030580147804899
506.40000000000646,56.02371005603225,-0.5131306551474564,-4.02926117475041
507.5000000000065,56.1322399505818,-0.5195047342826232,-4.0279098934277195
508.6000000000065,56.240462826583375,-0.5209584954622086,-4.029273544845156
509.7000000000065,56.347854650790275,-0.5206690571404515,-4.029269789419998
510.80000000000655,56.4566738153336,-0.5180945763730663,-4.030582864864311
511.90000000000657,56.565719173870846,-0.5165254671139591,-4.031899806049615
513.0000000000066,56.67387798083919,-0.5136506881858695,-4.031916469446291
514.1000000000065,56.78276009256385,-0.5127782839900761,-4.034530376971634
515.2000000000066,56.89164095685569,-0.5109770620503647,-4.033209739810625
516.3000000000065,57.00051923920022,-0.5097151798671423,-4.032688085145198
517.4000000000067,57.109355151009574,-0.5099964826956009,-4.031879425629056
518.5000000000066,57.21738877437104,-0.5072291220080373,-4.030470239100435
519.6000000000067,57.32604780802077,-0.5090873761908531,-4.030465383117234
520.7000000000066,57.435431032260304,-0.5123852769377835,-4.030446190604018
521.8000000000067,57.54558122317273,-0.5151960025449329,-4.032769923979139
522.9000000000067,57.653179680971114,-0.5171970075195347,-4.03082343679353
524.0000000000067,57.76219352712797,-0.5195891751268125,-4.027523710680349
525.1000000000067,57.870672401960874,-0.5200055212246878,-4.0275092426565715
526.2000000000068,57.98080991040627,-0.5200524517769589,-4.033018608856247
527.3000000000068,58.088115502120985,-0.5182271260549652,-4.03419982815468
528.4000000000068,58.19886170767346,-0.5165111382761657,-4.034528498222051
529.5000000000068,58.308846826162096,-0.5170698996124501,-4.03583958294357
530.6000000000068,58.41622040144881,-0.5136130884736472,-4.035839819000563
531.7000000000069,58.52616850374142,-0.5107030047012969,-4.035846196368999
532.8000000000068,58.63525516985598,-0.5095681409536381,-4.036500157414673
533.9000000000069,58.744091675256435,-0.5108694541047931,-4.0365100009424975
535.0000000000068,58.85329467559185,-0.5077893984330557,-4.035066150034638
536.100000000007,58.962129626940246,-0.5067248268191255,-4.034012336779729
537.2000000000069,59.07099302627823,-0.5028520191887718,-4.037388597624855
538.300000000007,59.17986807604707,-0.502762710159541,-4.0373769848041885
539.4000000000069,59.288732073302654,-0.5024342625370788,-4.037380019256669
540.5000000000069,59.3986650816084,-0.5014342037923372,-4.034747660543664
541.600000000007,59.506555112438924,-0.5013586111281721,-4.033443541516729
542.700000000007,59.61664515982775,-0.4995651494260304,-4.034750025860087
543.800000000007,59.72590272949179,-0.49934541318375114,-4.034750027999973
544.900000000007,59.83404416168218,-0.502034111016889,-4.034750090395842
546.000000000007,59.941737032034624,-0.5025260343852562,-4.033429387391919
547.1000000000071,60.05345430916657,-0.5010943760385383,-4.0347482416067315
548.2000000000071,60.16174388042125,-0.5006016148575215,-4.0349619180333836
549.300000000007,60.27101688309773,-0.49808848419457713,-4.037379789591169
550.4000000000071,60.377228041500146,-0.49819728535560015,-4.036070029912591
551.500000000007,60.489934191862055,-0.4956860233901739,-4.036069199016607
552.6000000000072,60.59917235249132,-0.49412993614500894,-4.034750032320078
553.7000000000071,60.70806010962142,-0.4933104447788266,-4.034750027248545
554.8000000000072,60.81742454366499,-0.49181613770921573,-4.036087567821374
555.9000000000071,60.92757772566924,-0.49055138165039863,-4.036069854973358
557.0000000000072,61.03299239663921,-0.4904782392866508,-4.034749509275934
558.1000000000072,61.14517531624325,-0.49131185856418147,-4.033774683840539
559.2000000000072,61.25414511354323,-0.49074554703152784,-4.034738191114134
560.3000000000072,61.360938852627044,-0.48848940396104484,-4.034655254114732
561.4000000000073,61.469063290395106,-0.48840501714833806,-4.034749853131115
562.5000000000073,61.58068535750519,-0.4875165741989245,-4.034749673547013
563.6000000000073,61.68882786674911,-0.4881229329261244,-4.036070078702556
564.7000000000073,61.79847780527893,-0.4861348233064957,-4.03607942859275
565.8000000000073,61.90438509046568,-0.4848306951759078,-4.038699791548577
566.9000000000074,62.01624337190968,-0.4834143650843753,-4.03869955899013
568.0000000000074,62.12568480356393,-0.48259303251074503,-4.040019085143431
569.1000000000074,62.234449511023705,-0.4817995345438613,-4.038706417472841
570.2000000000073,62.34246522386966,-0.48031740565624226,-4.037332011946271
571.3000000000073,62.450749418652464,-0.4806523714385007,-4.034742341812758
572.4000000000074,62.55998457514107,-0.48096879832110395,-4.034747473152839
573.5000000000074,62.66917000000075,-0.47991000000002804,-4.035740002435989
574.6000000000074,62.77803262856955,-0.4794101633176904,-4.0360698347640005
575.7000000000074,62.887193501299144,-0.4780650107825287,-4.037111687797856
576.8000000000075,62.99693578587445,-0.4786809615108463,-4.035740001971628
577.9000000000075,63.105097345320225,-0.47657721047728935,-4.035740001999701
579.0000000000075,63.21425126925743,-0.47632856730608114,-4.035740453169473
580.1000000000075,63.32355170127024,-0.4773221024995175,-4.037644005584114
581.2000000000075,63.433014376907906,-0.4755464176382563,-4.038377446440118
582.3000000000076,63.542539217715714,-0.477318112841203,-4.037059703778753
583.4000000000076,63.65124543622387,-0.4773717171158649,-4.034417332500251
584.5000000000076,63.760365196529435,-0.4783276300261755,-4.033452531938928
585.6000000000076,63.8694708796483,-0.4763396476951303,-4.034749838590587
586.7000000000077,63.977209005679704,-0.4782850473873603,-4.037388696070416
587.8000000000077,64.0885152312832,-0.4791630169739554,-4.036097162638073
588.9000000000076,64.1983972436727,-0.4790238669020628,-4.033419518243087
590.0000000000076,64.30819029395002,-0.47894769712112,-4.032110412063682
591.1000000000076,64.41749567818162,-0.47862317041526975,-4.03549095896063
592.2000000000077,64.52648322220294,-0.4787019248081142,-4.036279912593273
593.3000000000077,64.63564205137162,-0.47797978116991285,-4.036263170518346
594.4000000000077,64.74543522829586,-0.4777216622204609,-4.037280272522771
595.5000000000077,64.85513841691807,-0.4777856801561903,-4.035959864159557
596.6000000000078,64.96435393380425,-0.47718238719849626,-4.035960093000123
597.7000000000078,65.07283501154161,-0.4811814268252907,-4.035960093001559
598.8000000000078,65.18376236343784,-0.4798779618800549,-4.035958057317246
599.9000000000078,65.29337127058712,-0.4787552210655747,-4.038784778242626
601.0000000000078,65.40072981252085,-0.47957741136173676,-4.0399100707547495
602.1000000000079,65.51182321989343,-0.47862505633471125,-4.039883780706985
603.2000000000079,65.62201024420943,-0.47870547597625457,-4.039901164515667
604.3000000000079,65.73206375082131,-0.47939425487842124,-4.0376793324529485
605.4000000000078,65.8406102099267,-0.479526967608024,-4.0372700709221245
606.5000000000078,65.94989059290691,-0.4781964516793561,-4.0372700653909686
607.6000000000079,66.0595781732831,-0.4792464735112397,-4.038259393337939
608.7000000000079,66.16775271075304,-0.4782267966491436,-4.038259841572351
609.8000000000079,66.27835990590556,-0.47859413292322334,-4.0372810480898185
610.9000000000079,66.38889790498354,-0.47920582473711515,-4.038594798683632
612.000000000008,66.49780166508161,-0.4791116355106719,-4.037609952294358
613.100000000008,66.60584198030026,-0.4789399467164773,-4.037610812820803
614.200000000008,66.71838706518093,-0.4815474078027169,-4.037956242930284
615.300000000008,66.82748956086077,-0.48257895926257177,-4.040243339383849
616.400000000008,66.93657651928973,-0.4834523956119259,-4.039282506591493
617.5000000000081,67.04752300005268,-0.48622798081173724,-4.037940392179734
618.6000000000081,67.15674096237599,-0.48746961646554726,-4.039259981300576
619.7000000000081,67.26601761883967,-0.48813445765577973,-4.04056876890503
620.8000000000081,67.3759397845523,-0.4903003367001793,-4.037912098524133
621.9000000000082,67.48459553088088,-0.4911333800989789,-4.037939913730096
623.0000000000082,67.59493097444745,-0.49214246503556386,-4.0392492853703565
624.1000000000081,67.70417238705883,-0.49055578831225194,-4.039249988000477
625.2000000000081,67.81429724994331,-0.4906883031967183,-4.039249895007579
626.3000000000081,67.92344453928008,-0.4928867851333931,-4.037930129241221
627.4000000000082,68.03304889346624,-0.4939667487212843,-4.0368677539623326
628.5000000000082,68.14257131268644,-0.4949358558702481,-4.036237388832713
629.6000000000082,68.25218077210235,-0.4964150209967911,-4.03990948585531
630.7000000000082,68.36191921443299,-0.4935541163280321,-4.040236007378108
631.8000000000083,68.4706934278111,-0.49468087442377556,-4.040240173615084
632.9000000000083,68.58014757657189,-0.49589150460123554,-4.038920075675574
634.0000000000083,68.68974942817508,-0.4961674355365098,-4.038920390262172
635.1000000000083,68.79917213384236,-0.4988901128839594,-4.0376016340016205
636.2000000000083,68.90784701567335,-0.4978768356294521,-4.040350174758609
637.3000000000084,69.0168132198216,-0.4999559242862214,-4.0408519694368845
638.4000000000084,69.12734383249591,-0.4991693671094769,-4.042998514066281
639.5000000000084,69.23607899386097,-0.4975329953382993,-4.042978382625997
640.6000000000083,69.34553236293364,-0.4992188649192679,-4.041777236305869
641.7000000000083,69.45528261262274,-0.4999647349433679,-4.040353473438665
642.8000000000084,69.5641696371496,-0.49911624990715375,-4.037440316093854
643.9000000000084,69.67468381988009,-0.5014113441740433,-4.039537255067144
645.0000000000084,69.7834201292923,-0.5018018861704698,-4.043079115565833
646.1000000000084,69.89451189552776,-0.5027915459552514,-4.0430630977672335
647.2000000000085,70.00366829818219,-0.5045221263533832,-4.04187389952068
648.3000000000085,70.11262895872493,-0.504463786125507,-4.040459980970583
649.4000000000085,70.22326052686702,-0.5040117484263341,-4.0404599809991435
650.5000000000085,70.33306757299975,-0.5066363785190506,-4.040461410860641
651.6000000000085,70.44210325303227,-0.5060777794521814,-4.041779781764985
652.7000000000086,70.55230024730425,-0.508110578051128,-4.043088829544457
653.8000000000086,70.66170593574707,-0.5079231685670111,-4.044410227266804
654.9000000000086,70.77186087701135,-0.5085587611430447,-4.047040016751116
656.0000000000086,70.88210849898276,-0.5073452393231456,-4.048031317016954
657.1000000000087,70.99238658690653,-0.5092887744990066,-4.043657399519469
658.2000000000087,71.10171476768234,-0.5081040626498473,-4.039313122825843
659.3000000000086,71.21143833610755,-0.5075179056930694,-4.039050947514852
660.4000000000086,71.3217457932816,-0.507021093343905,-4.039518458433335
661.5000000000086,71.43132334223016,-0.5043868773866248,-4.041312529532541
662.6000000000087,71.54101555078891,-0.5043869283515466,-4.040023505696684
663.7000000000087,71.65020273074609,-0.5032127743088093,-4.0387002587269505
664.8000000000087,71.75725999301906,-0.5042411540820186,-4.040004674339851
665.9000000000087,71.86748937175138,-0.5043834014924853,-4.039689424591418
667.0000000000088,71.9785037955505,-0.5062938268036601,-4.03858981515191
668.1000000000088,72.08877158221689,-0.5093849059793825,-4.038679363977891
669.2000000000088,72.19906932858784,-0.5075439862560234,-4.04122959125956
670.3000000000088,72.30807573387838,-0.5093379216461668,-4.039909855877434
671.4000000000088,72.41692171401765,-0.5139632468364231,-4.0399096914251675
672.5000000000089,72.52821362937866,-0.5123385025801958,-4.042885146706906
673.6000000000089,72.63937801795488,-0.5110070888243512,-4.0418790719857425
674.7000000000089,72.7477714434909,-0.5105793649431405,-4.040570220631337
675.8000000000088,72.85883366280622,-0.5099306153056937,-4.040240221771331
676.9000000000088,72.96833833751205,-0.511005042586288,-4.0389728601718655
678.0000000000089,73.0779966575355,-0.5127998534131661,-4.040816219832129
679.1000000000089,73.18732873639802,-0.5135245283978233,-4.042692956832865
680.2000000000089,73.2985949438278,-0.5129537274113845,-4.041333877750018
681.3000000000089,73.40866364732712,-0.5142399905306005,-4.038699617096388
682.400000000009,73.51842962961369,-0.5135010042565041,-4.039946929696637
683.500000000009,73.62803077177584,-0.5133677096223886,-4.040036122755233
684.600000000009,73.73917222767209,-0.5118801024465581,-4.0400199510823285
685.700000000009,73.84859711857015,-0.5132776862126771,-4.040011181483864
686.800000000009,73.959370491832,-0.5129951736116447,-4.040680280464424
687.9000000000091,74.06938943766458,-0.5113788622285216,-4.041337316277183
689.0000000000091,74.1797900214933,-0.5118043685253104,-4.041978383532114
690.1000000000091,74.2888905058257,-0.5111474991516276,-4.040002258411584
691.2000000000091,74.39980145623234,-0.5118106123217105,-4.038699930348764
692.3000000000092,74.50939263337384,-0.5133994343151345,-4.041383298329038
693.4000000000092,74.61987631713288,-0.5128083683078027,-4.040028792754329
694.5000000000091,74.73078517414345,-0.5173884999544683,-4.039359583026026
695.6000000000091,74.84050494108745,-0.5181890714280311,-4.040439830735373
696.7000000000091,74.95116951056654,-0.5200203748492874,-4.043395505864678
697.8000000000092,75.06120485512584,-0.5213172743125482,-4.044807513249534
698.9000000000092,75.17123733546006,-0.5198209574268239,-4.044284238767
700.0000000000092,75.28208751853886,-0.5210746484838581,-4.0459472724435
701.1000000000092,75.39262839109058,-0.5210559286276247,-4.046130425934028
702.2000000000093,75.5035222707356,-0.5202245621698873,-4.044853643458458
703.3000000000093,75.61310625965076,-0.5220233781280045,-4.043865540966147
704.4000000000093,75.72442503110953,-0.5230016007520314,-4.043714123975318
705.5000000000093,75.83387133097303,-0.5224609888258587,-4.043540133796781
706.6000000000093,75.94520862407458,-0.5247101706256713,-4.041930866034653
707.7000000000094,76.05532282810654,-0.523884185136843,-4.040704009278348
708.8000000000094,76.1661853162868,-0.5265022395332809,-4.0420001150566165
709.9000000000094,76.27504809854618,-0.5282924536760019,-4.041939594151291
711.0000000000093,76.38652441876496,-0.5262972433481934,-4.0393619609082245
712.1000000000093,76.49575419227075,-0.525905714915678,-4.040871404233697
713.2000000000094,76.60661142550957,-0.52811830369287,-4.041155008547906
714.3000000000094,76.71666573724526,-0.529156964838112,-4.043566684300517
715.4000000000094,76.82695927410987,-0.5275320008992771,-4.0461160443342035
716.5000000000094,76.93732237357014,-0.529964217179452,-4.045620126773466
717.6000000000095,77.04651090443384,-0.5329196843482676,-4.0431906326198135
718.7000000000095,77.1570154566278,-0.5361369946033897,-4.042992626772867
719.8000000000095,77.26671183459291,-0.537383853667754,-4.042792875733602
720.9000000000095,77.37847107779955,-0.5386912185083449,-4.041504168930045
722.0000000000095,77.48803302061069,-0.536480357283095,-4.042400942728733
723.1000000000096,77.59773892417178,-0.53434375876057,-4.041631472991359
724.2000000000096,77.70854472312888,-0.5355851188701093,-4.04035038694185
725.3000000000096,77.81917091085973,-0.5321699811239388,-4.041659564367065
726.4000000000096,77.92927074120587,-0.5339889186641853,-4.043431157861313
727.5000000000097,78.03978457561952,-0.5344818477623838,-4.044530089035393
728.6000000000097,78.15063825869942,-0.5365681037619364,-4.044343825325537
729.7000000000096,78.26106954081273,-0.5353912794325775,-4.042172978956411
730.8000000000096,78.37143962382986,-0.5363049565692151,-4.04362445370991
731.9000000000096,78.48118121226545,-0.536588775331908,-4.043739513855202
733.0000000000097,78.5919063670163,-0.534607418834408,-4.037180735575189
734.1000000000097,78.70269311500944,-0.5333764351087491,-4.037489274859369
735.2000000000097,78.81271999249356,-0.5343218160019272,-4.038455088646076
736.3000000000097,78.9226495049069,-0.535490512132397,-4.042435438957175
737.4000000000098,79.03375750541176,-0.5370897254296599,-4.042430067339763
738.5000000000098,79.14421830692291,-0.5396102657770645,-4.041118506912485
739.6000000000098,79.25524921577973,-0.5395246212617215,-4.042809747799209
740.7000000000098,79.36619152877137,-0.5428639062274794,-4.043987417968123
741.8000000000098,79.47578911537016,-0.5455662292732041,-4.040683268992808
742.9000000000099,79.58715823039707,-0.545796557695702,-4.039166127302905
744.0000000000099,79.69753599764955,-0.548427236522715,-4.04068885590795
745.1000000000099,79.80751156475965,-0.552220966923612,-4.0419984700521265
746.2000000000098,79.91778735662142,-0.5489313393849891,-4.039275432660145
747.0000000000099,79.99864516416275,-0.5522664403228076,-4.039385092769854