File: 01_Data/PE_Foam_Pipe_Insulation/STA/N2/10K_min/PE_Foam_Pipe_STA_N2_10KData_220926_R3.csv
##Temp./Â°C,Time/min,DSC/(mW/mg),Mass loss/mg
51.0,10.77917,-1.58107,0.019198451060650434
51.80000000000001,11.06436758925596,-1.4668599839945011,0.014910778746283881
52.60000000000002,11.25596046881028,-1.3864976539002618,0.014423732818212187
53.400000000000034,11.43148201762155,-1.3214022027516055,0.015328863964188422
54.200000000000045,11.579938996908702,-1.264023133734127,0.016269197900729004
55.00000000000006,11.71815076711176,-1.2161991453539331,0.014540129087638576
55.80000000000007,11.848548913316197,-1.1760544805435624,0.013331007391585104
56.60000000000008,11.97164564092767,-1.1371219416814848,0.013580915929122028
57.40000000000009,12.09019020313019,-1.1064682526178675,0.014258071591906507
58.2000000000001,12.203224854261723,-1.0753796624240197,0.016287395893114898
59.000000000000114,12.31575590219275,-1.0479824920393384,0.018754150873814268
59.800000000000125,12.423192237665459,-1.027483268556701,0.018315032296588818
60.600000000000136,12.53100281960714,-1.0074212037877832,0.017994484135400057
61.40000000000015,12.636130521243572,-0.9915017866363883,0.01754144242215272
62.20000000000016,12.739290477884479,-0.9782597195500675,0.018462572761984042
63.00000000000017,12.84023837235425,-0.9680037444246827,0.01712896712331169
63.80000000000018,12.938292496288291,-0.9585480105464251,0.018256874260764278
64.6000000000002,13.040356968410048,-0.9491667771921858,0.017348980990994356
65.4000000000002,13.138058763496046,-0.9393158530059833,0.01604236628959299
66.20000000000022,13.236844289907552,-0.9288610651361715,0.017373727112731885
67.00000000000023,13.332005194491368,-0.9191728884530308,0.01723971431377791
67.80000000000024,13.427015799195157,-0.9095692237577221,0.0175718680136292
68.60000000000025,13.520828064366397,-0.898765034556712,0.016313800534478062
69.40000000000026,13.613253378124133,-0.8872041238922854,0.01646730872645019
70.20000000000027,13.705924095877858,-0.8758463562293506,0.017346176413029823
71.00000000000028,13.797788955327169,-0.8646888225420277,0.016212055508246337
71.8000000000003,13.889170000000034,-0.8534099999999936,0.01690225145950297
72.6000000000003,13.980557296921798,-0.8415550459458969,0.017573303838489984
73.40000000000032,14.070929478111857,-0.8285228235803224,0.018857107950300822
74.20000000000033,14.158088838857596,-0.8171809062814916,0.01817960052483336
75.00000000000034,14.24975409361593,-0.8050810130214288,0.017539849490191273
75.80000000000035,14.337960126457103,-0.7922201719028449,0.01784297608049723
76.60000000000036,14.42583817073365,-0.7802198650957959,0.01823236616954116
77.40000000000038,14.514463684681258,-0.7686202832285698,0.018370665996886082
78.20000000000039,14.60231345707257,-0.7540129262149364,0.01857892964278829
79.0000000000004,14.689285458537814,-0.7412358406855881,0.019559627925139544
79.80000000000041,14.773596206276384,-0.729644267323754,0.020162235628823133
80.60000000000042,14.862770871874476,-0.7159812627897167,0.0196623590093008
81.40000000000043,14.947305564084791,-0.7037611692698892,0.019788537920007343
82.20000000000044,15.034158736757977,-0.6916628234974034,0.01904461094162979
83.00000000000045,15.11906311900619,-0.677509815111014,0.020200837778037162
83.80000000000047,15.202650577938309,-0.664044924355017,0.018982744531247597
84.60000000000048,15.287394172620022,-0.6502307883719506,0.02037106079526918
85.40000000000049,15.370572912933934,-0.6365463860321192,0.020802214890543347
86.2000000000005,15.454888586236573,-0.6249288768821948,0.02030845097936229
87.00000000000051,15.538149315390346,-0.6120487103430614,0.01895096079364844
87.80000000000052,15.622079922549839,-0.5979416063237638,0.020310364988316287
88.60000000000053,15.704934530789858,-0.5838929003171391,0.020326669768336636
89.40000000000055,15.788186865572081,-0.5704562261580913,0.019290674797289853
90.20000000000056,15.869719549249371,-0.5573696579148558,0.02027451646593814
91.00000000000057,15.948920708248362,-0.5397685517475914,0.02029602896627125
91.80000000000058,16.03231307574868,-0.526386717007062,0.020297201094114037
92.60000000000059,16.11487492234999,-0.5090347094000598,0.02040061908782853
93.4000000000006,16.195925026226302,-0.48964512875972405,0.02044080610200627
94.20000000000061,16.275731515168214,-0.4710984519782265,0.02162333338630873
95.00000000000063,16.35760184258971,-0.4512145201831914,0.020304602651560977
95.80000000000064,16.43879480787337,-0.4302908215400787,0.02031761764460338
96.60000000000065,16.517602383494186,-0.4109976569631645,0.021650633323845092
97.40000000000066,16.598857313060112,-0.3947916406039393,0.02032003598783305
98.20000000000067,16.678282551229927,-0.38394520254413367,0.021367156683583133
99.00000000000068,16.759075270923837,-0.375370724542027,0.02030543870727275
99.8000000000007,16.837417118509208,-0.36462960619410306,0.020311500622250733
100.6000000000007,16.918489552838466,-0.34787349886862023,0.021357119965236926
101.40000000000072,16.99867970430941,-0.32934664004034697,0.021639521862999445
102.20000000000073,17.07634866300451,-0.30834270297651467,0.020647957951316798
103.00000000000074,17.156898829004486,-0.2791305118352576,0.01924296292080463
103.80000000000075,17.23315551537321,-0.25047363723150184,0.020319260690212282
104.60000000000076,17.314248893585052,-0.21539191183201734,0.020375601406629862
105.40000000000077,17.39471841060418,-0.1767542023966122,0.020349401907099995
106.20000000000078,17.473404623992806,-0.13447811581087996,0.020717603367987003
107.0000000000008,17.550030410907716,-0.0870810991721147,0.021637911215500516
107.80000000000081,17.632468993736488,-0.028704560629835476,0.020320141239301925
108.60000000000082,17.711602447296368,0.032678391996254885,0.01901454684402193
109.40000000000083,17.79076445301261,0.10025217698399344,0.02031498501097495
110.20000000000084,17.867558830499267,0.17573886407906888,0.020201530671609902
111.00000000000085,17.947377927790093,0.2565047150493225,0.021662273025472523
111.80000000000086,18.027413582120253,0.34485432353016865,0.02197178351455964
112.60000000000088,18.105892092083224,0.43325241876601234,0.02268842940413407
113.40000000000089,18.185906834043873,0.5098694496103193,0.021626485159144337
114.2000000000009,18.26471113843945,0.5469251995514323,0.02254475882656326
115.00000000000091,18.343669346449293,0.5048978552581267,0.022948691978492697
115.80000000000092,18.422081789494463,0.31233896577241255,0.022948033496838605
116.60000000000093,18.49955313253842,0.023870504104401908,0.021652383309625378
117.40000000000094,18.576096203645797,-0.18912312832953979,0.022758263878685625
118.20000000000095,18.654882522212997,-0.3392230917648379,0.022181976068577747
119.00000000000097,18.731053584848222,-0.4275374756264273,0.021639907768953748
119.80000000000098,18.808418237344263,-0.4884793418843508,0.021638645809468393
120.60000000000099,18.885754751259167,-0.5244477535683646,0.022277070524149956
121.400000000001,18.961719539651416,-0.5469665671969934,0.021579054533827247
122.20000000000101,19.03898135283071,-0.5607619244332558,0.02030977729570793
123.00000000000102,19.115080394327073,-0.5668057896451563,0.021617567285512784
123.80000000000103,19.19304627120745,-0.5706928566908717,0.021636744186740664
124.60000000000105,19.26896768378848,-0.5718544705949472,0.021284017055512194
125.40000000000106,19.347362235466875,-0.5722441778414741,0.02027616762178308
126.20000000000107,19.42502376979427,-0.5698039273971872,0.019019374754106977
127.00000000000108,19.501289360186064,-0.5683723454292084,0.01904466612688971
127.80000000000109,19.577232712553545,-0.5651948729181576,0.020265376060040197
128.6000000000011,19.655285401951183,-0.564904259972588,0.023285882301479432
129.4000000000011,19.731306747393113,-0.559192700848145,0.024249578741998512
130.20000000000113,19.806300836905443,-0.5564035897912574,0.02408360430853751
131.00000000000114,19.886408498279987,-0.5544618692452437,0.024267298386114078
131.80000000000115,19.96222041011184,-0.5511016170685744,0.02426342998608888
132.60000000000116,20.03947480347453,-0.5486199073338636,0.023274359969080116
133.40000000000117,20.115418762800324,-0.5434442835029791,0.023298529368566356
134.20000000000118,20.192227253703205,-0.5408063729887036,0.02294866635171111
135.0000000000012,20.267830467069423,-0.5381385881105605,0.0226563118237042
135.8000000000012,20.346279012964253,-0.5338164410638953,0.022949778612052718
136.60000000000122,20.421281864783666,-0.531045163538165,0.022949806251060245
137.40000000000123,20.49765457816756,-0.5262559327847688,0.022944905770680535
138.20000000000124,20.574363631619,-0.5225718514017242,0.022952703620235937
139.00000000000125,20.651940740301097,-0.518174501251245,0.021570714085583198
139.80000000000126,20.728964397119697,-0.5169003079322622,0.022602262246025795
140.60000000000127,20.804909356513445,-0.5140521757676028,0.02294904032852596
141.40000000000128,20.881641760295892,-0.5104265135752054,0.021639509029049542
142.2000000000013,20.95895729673563,-0.5065205245306236,0.021639989204444987
143.0000000000013,21.0335445391321,-0.5028817778474023,0.02163977378465809
143.80000000000132,21.11047794136672,-0.49887203234523836,0.022941633915688264
144.60000000000133,21.18605922882758,-0.4965803856847492,0.022485909214053024
145.40000000000134,21.26108349295578,-0.492997478422433,0.020120227535326052
146.20000000000135,21.339649941660607,-0.48986467621104074,0.021411444413844016
147.00000000000136,21.415560525568544,-0.48759570561052895,0.023884391085439383
147.80000000000138,21.49242479445672,-0.48252939673963485,0.023055336358319245
148.6000000000014,21.567733177669407,-0.478789119733728,0.02273136029574907
149.4000000000014,21.644920847687846,-0.47761609236636576,0.022730533498246608
150.2000000000014,21.72101449040005,-0.47397480343942394,0.023228815391968638
151.00000000000142,21.797011520213267,-0.4709663121886824,0.024041913054539954
151.80000000000143,21.86902815297875,-0.46846121468942875,0.024050130721334106
152.60000000000144,21.948270783118694,-0.46573651377853353,0.02345757121135339
153.40000000000146,22.02415139605805,-0.46293810342753194,0.0243838865746957
154.20000000000147,22.098987567110495,-0.4594182645367599,0.02438008099013622
155.00000000000148,22.176465941715133,-0.4554644216580913,0.0243800366719924
155.8000000000015,22.2534577706968,-0.44999739903876196,0.02405788696623201
156.6000000000015,22.328166629613396,-0.4480538063628191,0.02273032301828959
157.4000000000015,22.403389544783344,-0.44456804705574104,0.022726010809406283
158.20000000000152,22.48075186956528,-0.4410509486518787,0.024053276298008797
159.00000000000153,22.555681289017762,-0.43882385041665317,0.022729910718908286
159.80000000000155,22.632125555860156,-0.43372224925085023,0.023063024719681025
160.60000000000156,22.70831735563145,-0.4312820062309324,0.024040351989495612
161.40000000000157,22.783625129932897,-0.42775485243792577,0.02404381490609353
162.20000000000158,22.85983929295514,-0.42541927389810696,0.022729980200799638
163.0000000000016,22.935980428506284,-0.4215714465170857,0.02272743805714761
163.8000000000016,23.01214142363597,-0.4184940204741631,0.023060031087388744
164.60000000000161,23.08722838368226,-0.41600334802509487,0.023060154504494612
165.40000000000163,23.16365986596776,-0.41348316618579795,0.022736343357850686
166.20000000000164,23.239170000000158,-0.41161999999999765,0.023720099890154778
167.00000000000165,23.316195458685296,-0.4077411361497704,0.023723023419696787
167.80000000000166,23.391912511437358,-0.4030729290721689,0.022401067134182107
168.60000000000167,23.46779006522525,-0.40278958921040636,0.022398750512022225
169.40000000000168,23.542806086019933,-0.3998460468039181,0.024171130484615944
170.2000000000017,23.61967342600551,-0.3973133656707066,0.022729956510044502
171.0000000000017,23.694728168418536,-0.39490889887118874,0.022729958878619172
171.80000000000172,23.771584030488235,-0.3931004447161998,0.023279360168123375
172.60000000000173,23.84650071432573,-0.3907838770275303,0.02403993458771403
173.40000000000174,23.922051859902545,-0.38774361148454517,0.022685769037533277
174.20000000000175,23.996533132558273,-0.3845064480673431,0.021414696127433075
175.00000000000176,24.074368518510877,-0.3829436849086269,0.022691741374820218
175.80000000000177,24.149867894974665,-0.3805039348984467,0.023719649367500928
176.60000000000178,24.227324405886158,-0.3778766500993612,0.02471049706150996
177.4000000000018,24.301973503472034,-0.3754200822410004,0.024682740756106547
178.2000000000018,24.379260139894573,-0.3721986365676961,0.0233862944178016
179.00000000000182,24.452979676400037,-0.36908623877965246,0.02281049752115294
179.80000000000183,24.53153818800456,-0.3677443900923454,0.02141015453962325
180.60000000000184,24.605520458307062,-0.3655230478030288,0.021318407126221572
181.40000000000185,24.682448230368667,-0.3609989274462805,0.02206688615184227
182.20000000000186,24.758407443204856,-0.36040574078067006,0.022729838649356182
183.00000000000188,24.83458274800547,-0.3582217748939026,0.02148933133156561
183.8000000000019,24.909170000000167,-0.3549799999999964,0.022079989861240712
184.6000000000019,24.98617885318515,-0.35389512886515284,0.022659098130203503
185.4000000000019,25.060916403686726,-0.35090841180895355,0.022729954299648192
186.20000000000192,25.137048722962195,-0.3494304662821028,0.022699395016462454
187.00000000000193,25.21355954138765,-0.34699009529473224,0.021739604016577374
187.80000000000194,25.289265480754437,-0.34558670041447676,0.021739927986297758
188.60000000000196,25.365204581646648,-0.3416036669639134,0.021739930383924744
189.40000000000197,25.44099639657273,-0.3391428662185185,0.0218077405631103
190.20000000000198,25.515748404787047,-0.3364512455752598,0.021224463579270214
191.000000000002,25.591764273368174,-0.3328431235791976,0.021409835415295397
191.800000000002,25.667162111369407,-0.332911542003261,0.02140984700020443
192.600000000002,25.743645556123255,-0.33151318587785633,0.020089908348865038
193.40000000000202,25.81907195407389,-0.328137303025515,0.020089847287515283
194.20000000000203,25.894084144452464,-0.3274608821039031,0.02149689872250793
195.00000000000205,25.97091744266451,-0.32477510104423024,0.021410136151768455
195.80000000000206,26.046530597029786,-0.3230369359622242,0.021432678789277126
196.60000000000207,26.12197277419158,-0.3201147856704027,0.019104821761576574
197.40000000000208,26.19821450229442,-0.31705760135167665,0.01910982976266684
198.2000000000021,26.272766595346155,-0.31581503060515315,0.020213348206348236
199.0000000000021,26.34917000000021,-0.31465000000000487,0.01878014568543307
199.80000000000211,26.424750466913128,-0.3117384367294492,0.018780137963035237
200.60000000000213,26.500233243692808,-0.3096974045320564,0.018778730730310222
201.40000000000214,26.576567890460986,-0.30700713717115286,0.017460228973591008
202.20000000000215,26.652513214354652,-0.30484485396009514,0.01746018090613255
203.00000000000216,26.728046247654632,-0.3030009952092976,0.017799645938776365
203.80000000000217,26.804412039186097,-0.30047705045706763,0.017790112193568852
204.60000000000218,26.879940186557118,-0.2992356148062763,0.0177901110000116
205.4000000000022,26.95551579494709,-0.2975790090162457,0.017790110999934328
206.2000000000022,27.030683602176968,-0.2947353639633387,0.017790107990536264
207.00000000000222,27.10551953142925,-0.2929415184259855,0.017819740930794303
207.80000000000223,27.183216416418386,-0.2900641375723729,0.01746135185437847
208.60000000000224,27.25926857175416,-0.2876923761633067,0.01647121570801957
209.40000000000225,27.33431454297311,-0.28702539064980964,0.01647051141620892
210.20000000000226,27.41028113322016,-0.2841287279591123,0.015491609018524422
211.00000000000227,27.48658594619721,-0.2830195433632917,0.015161466607354512
211.80000000000229,27.562237876912672,-0.28070116052345756,0.016480525563704163
212.6000000000023,27.63802209769111,-0.27859710179501357,0.01651196398829846
213.4000000000023,27.71437819467801,-0.2753520276606715,0.01380014101467264
214.20000000000232,27.79019647980759,-0.2739401724236085,0.013840109147055024
215.00000000000233,27.86579872941801,-0.27213639216857016,0.013840111000028799
215.80000000000234,27.939336002936482,-0.27022350822021934,0.013840111000507527
216.60000000000235,28.017602637802653,-0.2663848494606381,0.013840115847447265
217.40000000000236,28.093368902425567,-0.2639109403558115,0.013357053368041605
218.20000000000238,28.16735403831201,-0.2620970818022563,0.01318008642113444
219.0000000000024,28.246247781299278,-0.2603470877513356,0.012836123546859035
219.8000000000024,28.32088924858664,-0.2584464875090856,0.012520161767888283
220.6000000000024,28.397622307110982,-0.2559253312525287,0.012520263534179676
221.40000000000242,28.472731581784217,-0.25646463102656586,0.011202118567154251
222.20000000000243,28.54879114980116,-0.2522676865397892,0.011202126991769035
223.00000000000244,28.62460236015541,-0.25227519297338813,0.008657578435075752
223.80000000000246,28.701027999723856,-0.24974091819112468,0.010889936043677828
224.60000000000247,28.776570644250523,-0.24732435926682378,0.01084436399199884
225.40000000000248,28.85211620661293,-0.24628812988836607,0.009549849636022234
226.2000000000025,28.92617303494126,-0.24385989177050404,0.009527226378684528
227.0000000000025,29.00474443086103,-0.24119694129218533,0.008568720636100924
227.8000000000025,29.079883916467125,-0.23988968250436402,0.008569321537988728
228.60000000000252,29.157454234384833,-0.23758132899862575,0.007909799885449154
229.40000000000254,29.23194726645565,-0.23490422207931946,0.005932550167905504
230.20000000000255,29.307524945140422,-0.2349083113661865,0.005929928031981113
231.00000000000256,29.384597345526714,-0.2328792989360807,0.00592992890820998
231.80000000000257,29.459627162784248,-0.23007315375357001,0.005963443389048972
232.60000000000258,29.53549162198252,-0.22822286150514356,0.006387922316267058
233.4000000000026,29.61196584712344,-0.22713316469534184,0.004226389777515216
234.2000000000026,29.68816564070901,-0.22590166172547924,0.00430612016252141
235.00000000000261,29.76395006936653,-0.22462577542551226,0.0027966012721329925
235.80000000000263,29.840338022482428,-0.22263665758775913,0.0016268876916480934
236.60000000000264,29.916429244007226,-0.22221499494581964,0.0016503029009662384
237.40000000000265,29.99270941944695,-0.21980311802586955,0.0013171980971207198
238.20000000000266,30.068244571371157,-0.21822945751736617,0.0013213910257507955
239.00000000000267,30.14486633369545,-0.21633752957581293,-0.0009020590625303804
239.80000000000268,30.22077913588183,-0.21391237583269979,-0.000946722091436758
240.6000000000027,30.294704824970243,-0.2128529432822361,-0.0023100207860302646
241.4000000000027,30.372903076989086,-0.21192348989375856,-0.0023100370011381877
242.20000000000272,30.449170000000265,-0.21017999999999296,-0.0023100369999928816
243.00000000000273,30.525057603979867,-0.2079951042012379,-0.0034235714471093637
243.80000000000274,30.60115858637677,-0.20602896114535124,-0.003624970541928896
244.60000000000275,30.67705512118891,-0.2050583490666341,-0.004929318908197811
245.40000000000276,30.7535475979426,-0.20373552133644746,-0.006248204297049309
246.20000000000277,30.829374473760218,-0.20232345273938432,-0.006262181392168387
247.00000000000279,30.903398364552622,-0.2001331070606785,-0.007570130724871227
247.8000000000028,30.979833635736735,-0.1990889185161266,-0.007569213654359697
248.6000000000028,31.05829395708426,-0.19703673949592998,-0.01020177246462417
249.40000000000282,31.134017082788716,-0.19587742891047782,-0.010200059841129594
250.20000000000283,31.20956034887253,-0.19485445395084186,-0.008880110471980895
251.00000000000284,31.285744106021006,-0.19176259001614274,-0.0101090838680844
251.80000000000285,31.361917536813824,-0.19135445476011279,-0.011752244337079443
252.60000000000286,31.43822637259086,-0.19072320118775474,-0.012829712138612948
253.40000000000288,31.51504015141653,-0.1882336616333197,-0.012509901101953602
254.2000000000029,31.58936441152904,-0.18641017328843304,-0.012514633558847077
255.0000000000029,31.666445511261458,-0.18402674965250096,-0.014473109195087375
255.8000000000029,31.74269998891874,-0.18425599220342323,-0.01454901760798677
256.6000000000029,31.81916911580395,-0.1813300691924578,-0.016460049455280235
257.40000000000293,31.89471277905154,-0.1801931002083218,-0.016367212542490073
258.20000000000294,31.970882587790083,-0.17890761561339164,-0.017776636713777272
259.00000000000296,32.046985585275834,-0.17724833437334647,-0.020460871175972617
259.80000000000297,32.122904615076756,-0.1754725828366938,-0.020419833166397616
260.600000000003,32.19785503922142,-0.17412953571587692,-0.02041723775679305
261.400000000003,32.27445795163556,-0.1725659905620418,-0.021739400981193757
262.200000000003,32.35113845781913,-0.1712711654863244,-0.021740222905543227
263.000000000003,32.42756962540353,-0.17054244409938157,-0.023048327253192724
263.800000000003,32.50261128452472,-0.16903847647695716,-0.022968487587105013
264.60000000000304,32.57897913362038,-0.16899856844001307,-0.024359071446836467
265.40000000000305,32.65446207953435,-0.16831795373828937,-0.02567949860363461
266.20000000000306,32.729065572045776,-0.16617490048372757,-0.027000370884574743
267.00000000000307,32.8065102389743,-0.16484347850610717,-0.026895217644670844
267.8000000000031,32.88128658170123,-0.1645098024972515,-0.029699321814317337
268.6000000000031,32.95992152920127,-0.1632389877953025,-0.028975595508817342
269.4000000000031,33.033920099706876,-0.1621843682941778,-0.028320081886842985
270.2000000000031,33.10936102311629,-0.1621222653697168,-0.02962721728741302
271.0000000000031,33.187300552163265,-0.15924316985302153,-0.03101565813797702
271.80000000000314,33.26299590901043,-0.15944534041252476,-0.030963107880976892
272.60000000000315,33.33988447191774,-0.15880722657058197,-0.03226988701469047
273.40000000000316,33.41553244653249,-0.1580775063850037,-0.03359291213246607
274.2000000000032,33.49163350523352,-0.15665378761226864,-0.034281170800310345
275.0000000000032,33.56814937915392,-0.15617526347330463,-0.03553955483898452
275.8000000000032,33.64423847018704,-0.15352335051619928,-0.035570122909857727
276.6000000000032,33.72058022897132,-0.15505240456079272,-0.03658531088964878
277.4000000000032,33.79700199943406,-0.15241496148691105,-0.03687603457259048
278.20000000000323,33.87349142555634,-0.15240627133821752,-0.03696341178656759
279.00000000000324,33.94934782902258,-0.15034573160705383,-0.0381999171842935
279.80000000000325,34.02615799433002,-0.14988907340491114,-0.03819989801331758
280.60000000000326,34.102749264331344,-0.14771553831423986,-0.039299458302362034
281.4000000000033,34.17897484261059,-0.1483393674907305,-0.040494878860794614
282.2000000000033,34.25496731726878,-0.14686945327218254,-0.042799906244147756
283.0000000000033,34.3308651642124,-0.14501755917013842,-0.04281837449378667
283.8000000000033,34.407241887490876,-0.14508602991053512,-0.04314021478858443
284.6000000000033,34.483346882806146,-0.1435466606405633,-0.04184100496556553
285.40000000000333,34.56047067590648,-0.14306825506692677,-0.043218143420561184
286.20000000000334,34.63603962857813,-0.14114110987472614,-0.04412010785713427
287.00000000000335,34.71100828083531,-0.14136809377764684,-0.04408482404131009
287.80000000000337,34.788780919043546,-0.139487781589902,-0.04509361981566551
288.6000000000034,34.86510940908077,-0.1385528431452989,-0.04542196233914142
289.4000000000034,34.940814428706695,-0.13644316839421966,-0.04675931578692527
290.2000000000034,35.0181836645692,-0.1365659177156586,-0.048413227966135786
291.0000000000034,35.09414695869573,-0.13521764514035894,-0.0470948419434829
291.8000000000034,35.169644427666626,-0.1349807724413135,-0.04841241160739296
292.60000000000343,35.24658690181659,-0.13339053533368936,-0.048211933947730934
293.40000000000344,35.32270846804104,-0.1338217032480501,-0.047955426074477
294.20000000000346,35.3999676841272,-0.13253386021478147,-0.048740542870016945
295.00000000000347,35.47565529047779,-0.131378893067806,-0.050059775694801356
295.8000000000035,35.55170778026832,-0.12970771029028547,-0.05136223465564349
296.6000000000035,35.62907068061672,-0.12897831029245954,-0.05269318880400675
297.4000000000035,35.70495739248489,-0.1270531228149853,-0.05268945208582565
298.2000000000035,35.781470051527734,-0.12625530982966995,-0.05137014535954609
299.0000000000035,35.85730457871339,-0.1256049968497127,-0.0510424478754028
299.80000000000354,35.93394687933486,-0.12535419111244075,-0.052027897916584465
300.60000000000355,36.010351975349295,-0.12384495913851584,-0.0521169744495249
301.40000000000356,36.08767673384525,-0.12374720605816826,-0.05335000832890646
302.20000000000357,36.16375631164734,-0.12172530032819324,-0.05331930502462434
303.0000000000036,36.24148874530801,-0.12095835471976275,-0.05452632686633807
303.8000000000036,36.317028051270675,-0.12006438457244036,-0.05499985074431191
304.6000000000036,36.39372863223186,-0.11961195164922131,-0.05499984400034208
305.4000000000036,36.47048971682874,-0.11756972913120521,-0.05499984400000013
306.2000000000036,36.54725676032924,-0.11721653330809845,-0.05499984400000191
307.00000000000364,36.62362148513606,-0.1157962369932759,-0.05499984404253855
307.80000000000365,36.70046315937501,-0.11497834558120233,-0.055000278783032375
308.60000000000366,36.777065557873854,-0.11306815009540881,-0.05599075878035764
309.4000000000037,36.853820208076456,-0.11217952519102453,-0.056320322725430305
310.2000000000037,36.931165485315155,-0.10913131491562644,-0.05772961095706641
311.0000000000037,37.0072104756796,-0.10714732829938003,-0.057630047882403446
311.8000000000037,37.084679092573815,-0.10490979609936776,-0.057628228958083394
312.6000000000037,37.162356962724076,-0.10364560873569853,-0.05631780982803125
313.40000000000373,37.237284930895896,-0.1027454630752475,-0.05756768920231847
314.20000000000374,37.31414112503461,-0.10059275274915241,-0.058941379683327355
315.00000000000375,37.39127293760792,-0.09852749289142348,-0.06027761026884937
315.80000000000376,37.46748419346175,-0.09821802491950321,-0.05894829939262802
316.6000000000038,37.54462417135407,-0.09531931540438857,-0.06026998910676262
317.4000000000038,37.621745522438786,-0.09536756198895412,-0.06026999566212954
318.2000000000038,37.69832685932032,-0.09457713465310252,-0.06158555882721606
319.0000000000038,37.77512443755588,-0.09224176144239457,-0.06366348973428693
319.8000000000038,37.849820480074726,-0.0910822141946674,-0.06388991721041304
320.60000000000383,37.92898188783234,-0.08912414090450566,-0.06259057306809801
321.40000000000384,38.0064572907777,-0.0870503459531821,-0.06258012715516736
322.20000000000385,38.08271740134881,-0.08511784099774804,-0.06326003450919382
323.00000000000387,38.15945407199004,-0.08268834539116561,-0.06522320086733213
323.8000000000039,38.23639171381765,-0.07932947985282557,-0.06555807254035306
324.6000000000039,38.31258714872895,-0.07583481381893549,-0.06684980044612221
325.4000000000039,38.38917102493478,-0.07265772889248387,-0.06717991053712513
326.2000000000039,38.466725999759745,-0.07004038775187907,-0.0682197610116404
327.0000000000039,38.54347608500714,-0.06748384811325658,-0.06817086251113036
327.80000000000393,38.61986356263601,-0.06363254473430908,-0.06916179719662541
328.60000000000394,38.697208591013705,-0.06142242390665893,-0.06948970496876328
329.40000000000396,38.7739694404825,-0.05960283014056001,-0.07081460880795554
330.20000000000397,38.85096338172644,-0.056996961013858906,-0.07212016946981059
331.000000000004,38.92791879833777,-0.05342601386945703,-0.07343039333332513
331.800000000004,39.004854582621235,-0.05170398142179351,-0.0734335831571098
332.600000000004,39.08188472672276,-0.04844989382544997,-0.07474995692091913
333.400000000004,39.15886616313845,-0.04730040056700998,-0.07475013750870962
334.200000000004,39.234890538609825,-0.04457075522796104,-0.07531231953889028
335.00000000000404,39.31303067781517,-0.042847940556161895,-0.07736066841782474
335.80000000000405,39.389424622258204,-0.040958421558279286,-0.0786989695507927
336.60000000000406,39.46656860735146,-0.04040526137219533,-0.07875381399769621
337.40000000000407,39.54252707484424,-0.038436575075977,-0.0800298829726489
338.2000000000041,39.62051707309413,-0.035981179169467824,-0.08122049164615941
339.0000000000041,39.69772324782528,-0.03488168024814616,-0.08134779186765773
339.8000000000041,39.774061193722275,-0.03253998515015877,-0.08402833137353216
340.6000000000041,39.851701540698514,-0.03157700469444199,-0.0845469504921037
341.4000000000041,39.928574232839026,-0.030723156012870387,-0.08595529330314022
342.20000000000414,40.005489290912955,-0.029016537951100815,-0.0888125768124235
343.00000000000415,40.08289260534003,-0.02767064984168887,-0.08881866223479884
343.80000000000416,40.160346505804824,-0.025743756120928725,-0.08991133536192297
344.6000000000042,40.23719223729742,-0.0260246593155584,-0.09209982492992408
345.4000000000042,40.315152887020915,-0.024722502932900233,-0.09500206035552639
346.2000000000042,40.39034200612152,-0.022460844684008788,-0.0967350932055302
347.0000000000042,40.46888862499464,-0.022798967757839676,-0.09803256632520574
347.8000000000042,40.54637820879198,-0.020804913055134912,-0.09934910152868293
348.60000000000423,40.622907444040095,-0.020523346906880017,-0.1007160774623288
349.40000000000424,40.70106503630291,-0.020538768250091526,-0.10196686303995373
350.20000000000425,40.77844448458639,-0.018425791056843523,-0.10485792670952421
351.00000000000426,40.855480626732664,-0.017657163619565673,-0.10701070331116247
351.8000000000043,40.93188489499623,-0.016982195413146356,-0.10940030288990599
352.6000000000043,41.00935862193717,-0.015221437998689283,-0.1114464250145053
353.4000000000043,41.087229384078015,-0.015206856169066177,-0.11472804323228303
354.2000000000043,41.164085619044286,-0.012914858743214104,-0.11619547243130945
355.0000000000043,41.240472895363155,-0.013036638801550364,-0.11733405024051757
355.80000000000433,41.31846250444791,-0.01323411370899441,-0.11867073941072892
356.60000000000434,41.396384042424756,-0.013080164090644946,-0.12001046037602237
357.40000000000435,41.47428212770007,-0.013395186350641467,-0.12361544699519245
358.20000000000437,41.551231107860374,-0.013349078781123876,-0.12576172544319775
359.0000000000044,41.628363674648035,-0.014473205691534785,-0.12690523675256404
359.8000000000044,41.70592558375774,-0.014935739869041464,-0.12751430320503854
360.6000000000044,41.78276035255928,-0.015671305626519676,-0.12888019630776482
361.4000000000044,41.86013359549971,-0.01708251545426431,-0.13018820881235094
362.2000000000044,41.938201935882894,-0.018101433246867762,-0.13279044684428953
363.00000000000443,42.01488333356856,-0.01845573365388439,-0.13525719349933985
363.80000000000445,42.09347886463804,-0.020889619550601635,-0.1382429542271888
364.60000000000446,42.170685267984425,-0.020990424503239444,-0.14093276830943768
365.40000000000447,42.248946549551206,-0.022582081090016408,-0.14087462302346498
366.2000000000045,42.32559628991818,-0.02512871588785084,-0.14304237105275197
367.0000000000045,42.40164747833011,-0.025731694831797308,-0.14438389247369132
367.8000000000045,42.480212978542326,-0.02787819487042863,-0.1448852479452123
368.6000000000045,42.55715608963143,-0.030760058790208877,-0.14807396208011214
369.4000000000045,42.632861522095105,-0.030735645991660128,-0.1495152224892733
370.20000000000454,42.712830031223675,-0.03396256834978678,-0.15084063565296146
371.00000000000455,42.78975866397617,-0.0346341468945992,-0.15216307910744886
371.80000000000456,42.86681869297621,-0.037805798672581,-0.15361211016168141
372.60000000000457,42.944955866837596,-0.03953227603783517,-0.15473722394071432
373.4000000000046,43.02174402896348,-0.0408285034238271,-0.15677035217082258
374.2000000000046,43.09976863571411,-0.04261528756545813,-0.15808953357773703
375.0000000000046,43.17658284350928,-0.04439426154900014,-0.15931137418729557
375.8000000000046,43.25538733240584,-0.046402803424652236,-0.1620063867895878
376.6000000000046,43.330831537144334,-0.04889315457106217,-0.1635079603541647
377.40000000000464,43.4100639339191,-0.05106390885982579,-0.16379644278695782
378.20000000000465,43.48735146204753,-0.054461168274628706,-0.16477436697628045
379.00000000000466,43.5651666648973,-0.0569509623644416,-0.1660995757491488
379.8000000000047,43.64221051252218,-0.06235846819114986,-0.16745465921699498
380.6000000000047,43.718781323964556,-0.06483120383638867,-0.16871721387827998
381.4000000000047,43.7970746133617,-0.06664608693511818,-0.17004994479622093
382.2000000000047,43.87437584867089,-0.06927448918217773,-0.16870135433087619
383.0000000000047,43.95131536547076,-0.0716660302257626,-0.17138417772502335
383.80000000000473,44.03044930585057,-0.07500517791074353,-0.1713705719819174
384.60000000000474,44.106216992071836,-0.07397070096772754,-0.17268867173502045
385.40000000000475,44.18545625788865,-0.07669865209831639,-0.17269181918966447
386.20000000000476,44.26016893358137,-0.07588327475981538,-0.17408138572344223
387.0000000000048,44.3400175679943,-0.07442046890237217,-0.17436640108453672
387.8000000000048,44.4165428019103,-0.07635576367709042,-0.1743300175404756
388.6000000000048,44.49462424339298,-0.07612883741529954,-0.174320386485046
389.4000000000048,44.57282583833221,-0.07634770703983079,-0.17685228155779953
390.2000000000048,44.65052232204408,-0.07583829302844382,-0.17828313876094803
391.00000000000483,44.7278163444766,-0.07659437666342453,-0.17982952968858967
391.80000000000484,44.80651512939717,-0.07704766747738598,-0.18091950450809868
392.60000000000485,44.881132659235874,-0.07604435482848587,-0.18059587476659855
393.40000000000487,44.96173516943602,-0.07612734222349858,-0.180600628812158
394.2000000000049,45.03897671135363,-0.07580603667821044,-0.1812508438681193
395.0000000000049,45.1167206291149,-0.07574597744760427,-0.1812495141097612
395.8000000000049,45.194232627193124,-0.07603599519259552,-0.18265663812817223
396.6000000000049,45.27164231373443,-0.07448252950701638,-0.1825698069418107
397.4000000000049,45.350799559458586,-0.07510040979722543,-0.1825677960176142
398.20000000000493,45.42782889158131,-0.0756144351910139,-0.183880218530875
399.00000000000495,45.505719323315766,-0.07538026444820603,-0.18491174362711282
399.80000000000496,45.58377966673063,-0.07454224377328901,-0.1851998515566864
400.60000000000497,45.661868301959046,-0.07302343177608506,-0.18648201354827476
401.400000000005,45.73888060427127,-0.07198299945915118,-0.18783806890537535
402.200000000005,45.81744195437591,-0.06974290696259947,-0.189113251867429
403.000000000005,45.895395047377804,-0.06925065754602408,-0.1918204153630243
403.800000000005,45.973210236594866,-0.06894871886704998,-0.19277826388937402
404.600000000005,46.05049083699091,-0.06963352411831085,-0.1940904125653442
405.40000000000504,46.1298820290291,-0.07134267912424276,-0.19409374810727664
406.20000000000505,46.20660263023929,-0.07051159480043066,-0.196534942718682
407.00000000000506,46.284260782069495,-0.07003056187464902,-0.19810836081274008
407.80000000000507,46.36272006121532,-0.06871030567627898,-0.19937872175865934
408.6000000000051,46.44023519446748,-0.06795681472404973,-0.20067779210675285
409.4000000000051,46.516291183687215,-0.06459589176300679,-0.20248769544870004
410.2000000000051,46.595909449845095,-0.0642701377236912,-0.20622695979634997
411.0000000000051,46.674098510574304,-0.0652651960730815,-0.2063324118060592
411.8000000000051,46.752144597492006,-0.0686928492740538,-0.20902954751176317
412.60000000000514,46.82985408902519,-0.06848403228135422,-0.21105631963928273
413.40000000000515,46.90727453493717,-0.06489692318486226,-0.213007805159092
414.20000000000516,46.982415561254776,-0.06355384003932361,-0.21432106838092757
415.0000000000052,47.063670390262,-0.061562938348989765,-0.21709649004877196
415.8000000000052,47.14043396456001,-0.05856014903054846,-0.21878982627642607
416.6000000000052,47.21955821059208,-0.05669107099383416,-0.21966750208396402
417.4000000000052,47.29717803107536,-0.05202222650950135,-0.22127354311867498
418.2000000000052,47.374668112989895,-0.04998684493247991,-0.22375337820453467
419.00000000000523,47.452784678923884,-0.046212678428425774,-0.22790317103185975
419.80000000000524,47.53050581251155,-0.042881280808508955,-0.22947390734313533
420.60000000000525,47.6088081610333,-0.0385283557644046,-0.23219403726364796
421.40000000000526,47.68682850077181,-0.036366104575271396,-0.23509187766243222
422.2000000000053,47.76430516417825,-0.034526999310160116,-0.23848810035263668
423.0000000000053,47.842441782996254,-0.03030925744294528,-0.24195530050555547
423.8000000000053,47.92002902665291,-0.026449933118200056,-0.24718519433430242
424.6000000000053,47.99906433509133,-0.022957656262921896,-0.2513907479591322
425.4000000000053,48.076788468779505,-0.017671463817959195,-0.2535721377671969
426.20000000000533,48.155791691062376,-0.01487087132405774,-0.25787097180670804
427.00000000000534,48.232751403271166,-0.008190182440881776,-0.26247646034653815
427.80000000000535,48.31146898735752,-0.005410093803101407,-0.2673761778826016
428.60000000000537,48.387831648067554,0.00022933944999681591,-0.2699344877281984
429.4000000000054,48.466805955829045,0.005666376860505106,-0.27404240056551554
430.2000000000054,48.5428704934761,0.009645276864113296,-0.27993595625187506
431.0000000000054,48.62199697695306,0.01702075561429264,-0.2846366020936726
431.8000000000054,48.701741161727675,0.022687606671075583,-0.29229332210809567
432.6000000000054,48.77985038625614,0.029233584508934877,-0.29802446905459856
433.40000000000543,48.856893484518594,0.03486067501431257,-0.304209993283711
434.20000000000545,48.936406520930255,0.041234268482263435,-0.31000742631039513
435.00000000000546,49.013780907234946,0.0477408034843668,-0.31799018154933334
435.80000000000547,49.09306934650826,0.05487005097024537,-0.32390941800235185
436.6000000000055,49.17045888617032,0.06135841699432495,-0.3317361082338244
437.4000000000055,49.24972083230733,0.0699040232843285,-0.3394873649238992
438.2000000000055,49.326698680007446,0.07612250652753291,-0.348854156352298
439.0000000000055,49.40570336625916,0.08190200739691707,-0.356983621592986
439.8000000000055,49.48389880959586,0.09107837491696753,-0.3669768776039555
440.60000000000554,49.56147493477316,0.09905546746145727,-0.3769076933804545
441.40000000000555,49.640114942130495,0.10742602357198464,-0.38720521643486094
442.20000000000556,49.71816821610838,0.11581656043794417,-0.3979689362715919
443.00000000000557,49.79639196962236,0.1263977598403379,-0.4077041944522253
443.8000000000056,49.87462588296105,0.13810021220161608,-0.4197209376547919
444.6000000000056,49.953372096997526,0.14838194431580973,-0.43276383608955404
445.4000000000056,50.031064169272526,0.15878891673119538,-0.44612122763397855
446.2000000000056,50.10962871424242,0.1722207205668429,-0.46017446160233577
447.0000000000056,50.188158869909834,0.18596572375703804,-0.47538283973220263
447.80000000000564,50.267076899959676,0.20159394770037706,-0.48964225551876206
448.60000000000565,50.34454173532543,0.21443506902343729,-0.507211291378638
449.40000000000566,50.42357686337781,0.23092363160120197,-0.5256734398201623
450.2000000000057,50.501579710025396,0.24732246782587966,-0.5431967814713596
451.0000000000057,50.580167436469,0.2642784990340443,-0.5617180101058725
451.8000000000057,50.658605925251514,0.2834650421075589,-0.581229887491189
452.6000000000057,50.737174922634196,0.3038327597945732,-0.60466173641331
453.4000000000057,50.81596078306205,0.3246733187873147,-0.6259608452148395
454.20000000000573,50.89410479236757,0.3504704177254104,-0.6486134544160427
455.00000000000574,50.9714810887581,0.37595546474117375,-0.6755809174275482
455.80000000000575,51.05091091707499,0.40384651942499683,-0.7018581377707482
456.60000000000576,51.131049598611504,0.4359259818510334,-0.7321989222585321
457.4000000000058,51.208680912096554,0.46181759227455976,-0.7631302753178
458.2000000000058,51.28780347239238,0.48910135225570955,-0.796285389661223
459.0000000000058,51.36569930614991,0.5164265036165273,-0.8287388184590108
459.8000000000058,51.44447377556384,0.543830687716065,-0.8652701176050539
460.6000000000058,51.523231002979706,0.5705662155674766,-0.9027579478187575
461.40000000000583,51.60203729253126,0.6040549106737321,-0.9417470533734065
462.20000000000584,51.68115271427828,0.6365430450229665,-0.9833269824825184
463.00000000000585,51.760087279639905,0.6686455395493919,-1.028323113035904
463.80000000000587,51.83609554652805,0.6971318987811176,-1.071434188271326
464.6000000000059,51.91791167205653,0.7304156240332655,-1.1214935399382657
465.4000000000059,51.996744361559585,0.7625715115679752,-1.1712168167485077
466.2000000000059,52.074545172393115,0.7956682304647363,-1.22510849653069
467.0000000000059,52.153545609472985,0.8298721401989853,-1.2806714191102762
467.8000000000059,52.23169470992554,0.8618115934119054,-1.3371918075117608
468.60000000000593,52.3110434680574,0.8956561353784351,-1.3975019219350004
469.40000000000595,52.39006721384436,0.9253681513997278,-1.4599624711949257
470.20000000000596,52.46843851762224,0.9546401660195588,-1.5242342596984297
471.00000000000597,52.54593791238178,0.9804760155529139,-1.5897017671387816
471.800000000006,52.624897213099594,1.0056667600467564,-1.6600200438928563
472.600000000006,52.70358946916754,1.0289929471191626,-1.733108146082781
473.400000000006,52.78252510366467,1.0537749925653477,-1.8077556731785647
474.200000000006,52.86214076644973,1.0720120034850726,-1.88584472838025
475.000000000006,52.940953309830626,1.0887907860796682,-1.9653262526226025
475.80000000000604,53.01908083759808,1.1036820176413977,-2.045365737808673
476.60000000000605,53.09835646143725,1.1120969334924682,-2.1292132525426997
477.40000000000606,53.176453954298395,1.1174862343849696,-2.211062932653098
478.20000000000607,53.25589241440295,1.1167315431585199,-2.2975399957141076
479.0000000000061,53.33437851774403,1.110181131007205,-2.3859077765386463
479.8000000000061,53.41318634398904,1.0981256237741104,-2.473992438942748
480.6000000000061,53.492635271973526,1.0846932488881302,-2.5645844496614916
481.4000000000061,53.57035326808039,1.063974686510551,-2.652993768196137
482.2000000000061,53.64971015901189,1.0398115455799248,-2.743075972722784
483.00000000000614,53.72716725189422,1.0052485387488788,-2.8306417078788693
483.80000000000615,53.80588181993514,0.9637957829805908,-2.9180382641811144
484.60000000000616,53.88496180750638,0.9171768279629355,-3.0057525463170967
485.4000000000062,53.963479764728184,0.8635595315881892,-3.088877410787286
486.2000000000062,54.03983662903956,0.8041051664762442,-3.1699057846395533
487.0000000000062,54.12050125633085,0.736729938892413,-3.2497913221013146
487.8000000000062,54.19866684632598,0.665286233811877,-3.3240763156974054
488.6000000000062,54.27682998931261,0.5872644010439433,-3.3935018929427696
489.40000000000623,54.355839144254816,0.5042888610771731,-3.4624208178454827
490.20000000000624,54.43336181760343,0.4211217792778076,-3.5245603340403178
491.00000000000625,54.511787636731384,0.33721827782562686,-3.5813408503949415
491.80000000000626,54.59003954954242,0.25251953259177823,-3.634420013291858
492.6000000000063,54.66775563053841,0.17242572341678272,-3.678886314685759
493.4000000000063,54.74691567097799,0.09220868202745654,-3.7192521822263473
494.2000000000063,54.824850440774334,0.017633036647379034,-3.755719862374
495.0000000000063,54.90384063986315,-0.0499764889172481,-3.7856064357017023
495.8000000000063,54.98177341370639,-0.11207953552555765,-3.813038724477377
496.60000000000633,55.06020607223998,-0.1664347332277017,-3.8358259670557127
497.40000000000634,55.139078072880935,-0.21910914056682024,-3.8565341247237286
498.20000000000636,55.21574858789662,-0.26740801872454323,-3.871428551880569
499.00000000000637,55.295119461427674,-0.3077474720139482,-3.883015568173845
499.8000000000064,55.37412904081202,-0.3447763663953691,-3.8932658322441007
500.6000000000064,55.45223748787472,-0.37555936804775725,-3.9010135764067213
501.4000000000064,55.52982498979785,-0.40108211378389974,-3.9078909973620575
502.2000000000064,55.609260399258304,-0.42402522457707864,-3.9112348307285036
503.0000000000064,55.68798131200091,-0.44190496765418075,-3.916305863929441
503.80000000000643,55.76647084943095,-0.4548369786528734,-3.919333734816045
504.60000000000645,55.844431123149036,-0.46494005353848106,-3.9190900282636845
505.40000000000646,55.92348783593538,-0.47248103145844234,-3.9204185345805445
506.20000000000647,56.00262604457135,-0.4769005634794919,-3.922944787453547
507.0000000000065,56.08088023841336,-0.47927488353027087,-3.923084495144703
507.8000000000065,56.15925413515166,-0.47851245822977445,-3.9211339092232373
508.6000000000065,56.237731117032475,-0.4761803122590514,-3.9211200980362357
509.4000000000065,56.3169855646059,-0.47468834946198757,-3.921120342067143
510.2000000000065,56.39597403259297,-0.4759054762308457,-3.9221131622071095
511.00000000000654,56.474557775602904,-0.4771270949945545,-3.9224249845307213
511.80000000000655,56.554161781203675,-0.478505498864634,-3.9224802396391913
512.6000000000065,56.63252903671975,-0.4804436228837489,-3.9238555880911967
513.4000000000066,56.71064495524376,-0.48104656218066216,-3.924738729071017
514.2000000000066,56.79148154543234,-0.4831536967878057,-3.9245669103805665
515.0000000000066,56.87000353326581,-0.48409017827039963,-3.9227699963226708
515.8000000000065,56.950177449684396,-0.48592914216427074,-3.9227699091352326
516.6000000000066,57.026760797180785,-0.48490895691428815,-3.9227594855375423
517.4000000000067,57.10680756832757,-0.48636364452135306,-3.924079771100077
518.2000000000066,57.18680013194796,-0.4865743929722028,-3.9240798259985286
519.0000000000066,57.26366887187484,-0.48687864397882763,-3.924079826
519.8000000000067,57.345494953915974,-0.48842326747510334,-3.9240798259880965
520.6000000000067,57.423974828013854,-0.4895248307619389,-3.924079471141977
521.4000000000067,57.50365016742209,-0.48867580584896914,-3.9234178532594988
522.2000000000066,57.58216995741809,-0.4897562726995803,-3.923419825951356
523.0000000000067,57.658751560001576,-0.4906820182627489,-3.923419826035373
523.8000000000068,57.740697352599256,-0.4923295807147418,-3.9234119676599755
524.6000000000067,57.8201283373742,-0.49301739770882097,-3.9221099677987383
525.4000000000067,57.897827132086015,-0.4918063769427453,-3.9210175027120537
526.2000000000068,57.97722972553602,-0.4919616259611969,-3.922099842276089
527.0000000000068,58.057333980371034,-0.4940150512434608,-3.9221014075643
527.8000000000068,58.13446424499966,-0.49586485125359897,-3.9227520790885504
528.6000000000067,58.21651529165692,-0.49503800334083525,-3.924738767324245
529.4000000000068,58.29525019627586,-0.4953951954364606,-3.924739686701716
530.2000000000069,58.375139755065526,-0.49767854120902605,-3.924410787824401
531.0000000000068,58.4541011017137,-0.4990083994583531,-3.924410135868036
531.8000000000068,58.53324131026461,-0.4999217101135063,-3.923415514694192
532.6000000000068,58.61262971512363,-0.5020798642786762,-3.9234201170120184
533.4000000000069,58.69260391904693,-0.5027773619887491,-3.9234200632856475
534.2000000000069,58.770269256083246,-0.5042837465730241,-3.924392785538908
535.0000000000068,58.84959176390265,-0.5042478419436555,-3.925727905420161
535.8000000000069,58.930024601990574,-0.5077392220799402,-3.9230949799634445
536.600000000007,59.00662687652981,-0.5104485981361165,-3.9230901433836207
537.4000000000069,59.088037046664155,-0.5114817248622225,-3.9230901305418415
538.2000000000069,59.167776483919916,-0.5132232855580082,-3.9233494964140503
539.0000000000069,59.24593576656062,-0.5139255466138204,-3.9230900425365833
539.800000000007,59.326617874606214,-0.5150875598602087,-3.9230900360001315
540.600000000007,59.4052819522989,-0.5154303928140852,-3.9230900360000125
541.4000000000069,59.484559234411094,-0.5161821748910713,-3.92309003639925
542.200000000007,59.56375800592849,-0.5176014739360533,-3.923104495370925
543.000000000007,59.64298814705415,-0.5154929906800693,-3.925070355032423
543.800000000007,59.72252303257095,-0.5160500365989716,-3.9250699653290244
544.600000000007,59.80104040599156,-0.5148718615655727,-3.9242504977443007
545.400000000007,59.879804139051195,-0.5159933499246033,-3.9237517950878646
546.000000000007,59.93936198820362,-0.5156084815203028,-3.9247391690702558