File: 01_Data/EIFS_Mesh/STA/N2/3K_min/EIFS_Mesh_STA_N2_3KData_230907_R1.csv
##Temp./Â°C,Time/min,DSC/(mW/mg),Mass loss/mg
41.0,11.272792596778483,-2.360943070229174,0.002677625235751435
42.100000000000016,11.840580711953326,-2.3415076737592653,0.003951205269420832
43.20000000000003,12.309170000000018,-2.3329999999999997,0.00394860705658262
44.30000000000005,12.74128555736905,-2.32730740503728,0.0032864604357780713
45.40000000000006,13.159170000000056,-2.32409,0.0026300164021351158
46.50000000000008,13.577669281573788,-2.320612805911431,0.003157596050752609
47.600000000000094,13.97873471713251,-2.318231146733681,0.0021976573929580745
48.70000000000011,14.367154665607027,-2.315851794934139,0.0022974105730471095
49.800000000000125,14.765376119092911,-2.3133169926295873,0.002636733608563091
50.90000000000014,15.148533207454097,-2.3104123021354117,0.00231006402651035
52.000000000000156,15.538534326683902,-2.3096668084223655,0.0009818044448048902
53.10000000000017,15.953623578752286,-2.3062514569583286,0.0009938626388512617
54.20000000000019,16.296333872924183,-2.3035473777712876,1.45599190926049e-07
55.3000000000002,16.66742911393511,-2.3020041675577785,0.0003124915462260347
56.40000000000022,17.041795233591127,-2.301229792910145,0.0012016195091257842
57.500000000000234,17.411088102905715,-2.2997846714944505,0.00019238101429097654
58.60000000000025,17.792174703250343,-2.297014096418357,0.00032999665304611625
59.700000000000266,18.149862237781463,-2.2948387483266237,-0.0003306798885458484
60.80000000000028,18.530948349256203,-2.292639092460903,-0.0009814998015715837
61.9000000000003,18.91237871652024,-2.2905104226171753,-0.0008803890240041135
63.00000000000031,19.270483326400825,-2.28842382145018,-0.002001045782410671
64.10000000000034,19.640393172339643,-2.2870370079957287,-0.002200395564130986
65.20000000000034,20.00406593095127,-2.2844446573547117,-0.0031675112383311443
66.30000000000035,20.376868104162902,-2.2811034676754027,-0.0031800305675848684
67.40000000000038,20.744580930098977,-2.2784171767394574,-0.004240126594035498
68.5000000000004,21.10736948466067,-2.275640182678106,-0.004839932207589381
69.6000000000004,21.47561338546258,-2.2719281725661986,-0.004596486955367851
70.70000000000041,21.837667545615197,-2.2686710884065002,-0.004276047943744921
71.80000000000044,22.207883058998306,-2.26587838687231,-0.004819457496600954
72.90000000000046,22.569164762764775,-2.2622699498615493,-0.005361771366194645
74.00000000000047,22.93738339850192,-2.261523587645217,-0.0065857382652509955
75.10000000000048,23.305518884386366,-2.2603103468369743,-0.00638315283444868
76.2000000000005,23.6694470737153,-2.2570522112329097,-0.0064798320046235425
77.30000000000052,24.033682434944723,-2.2540494938725875,-0.0067353708765227616
78.40000000000053,24.40261423231609,-2.252232783121451,-0.007799963999999271
79.50000000000054,24.775734101680293,-2.248753896452737,-0.008119410525087911
80.60000000000056,25.140848697481697,-2.245989114223046,-0.008450116942139818
81.70000000000059,25.505525972911173,-2.2443008860812883,-0.008193288280419875
82.8000000000006,25.869511809786303,-2.2410340047562003,-0.0067272449123003675
83.9000000000006,26.23414566250328,-2.2388301213530615,-0.009675313701917876
85.00000000000063,26.598247023096,-2.2356845853997673,-0.008131081138914809
86.10000000000065,26.963058857123478,-2.234515473705231,-0.009439997466384575
87.20000000000066,27.324735119842668,-2.230581906122492,-0.01142922027321358
88.30000000000067,27.68917000000013,-2.228679999999991,-0.012062891091524808
89.40000000000069,28.051502624982533,-2.226607755797777,-0.010757612583694787
90.50000000000071,28.418839646312364,-2.2240039728913357,-0.012399994867048125
91.60000000000072,28.785310479604952,-2.2208376294883467,-0.013719826375470312
92.70000000000073,29.147649442221898,-2.2172792281110048,-0.013261297067092226
93.80000000000075,29.50415142671131,-2.215306953502587,-0.012302543890923445
94.90000000000077,29.85852062616943,-2.21228717569391,-0.01230000953709931
96.00000000000078,30.23797015148982,-2.209915260723403,-0.014928166699842649
97.10000000000079,30.602367497885417,-2.2084654472575402,-0.014599489493718476
98.20000000000081,30.965754117420484,-2.2073452666506856,-0.015332310537761185
99.30000000000084,31.324859297922764,-2.204941921322454,-0.014269281013298496
100.40000000000084,31.689751514805202,-2.2009093519746004,-0.014281192534796094
101.50000000000085,32.04992925303538,-2.19975516763116,-0.014914448710318329
102.60000000000088,32.41037971606804,-2.1956611644466033,-0.014907205642742838
103.7000000000009,32.77095968948945,-2.1930423646255095,-0.015589840004656352
104.8000000000009,33.13300930645452,-2.18956382789309,-0.015502573352452753
105.90000000000092,33.492526416819025,-2.1884923129998834,-0.01691054843518769
107.00000000000094,33.85874621438538,-2.186838195257601,-0.016580335084225073
108.10000000000096,34.21790163134636,-2.1834437066871786,-0.016632814036831256
109.20000000000097,34.58163299430013,-2.1808292718879057,-0.017239971907397234
110.30000000000098,34.93643866801146,-2.1772477864366473,-0.01826223376989322
111.400000000001,35.297127295862786,-2.173624207018145,-0.0172296141456445
112.50000000000102,35.66036470724213,-2.171848612747637,-0.01821974377169866
113.60000000000103,36.02104205593701,-2.168714814880895,-0.018219840000002208
114.70000000000104,36.379568223179724,-2.167433741039384,-0.018243697348846233
115.80000000000106,36.743525003979734,-2.1654223796311762,-0.018560136000015603
116.90000000000109,37.101921062161345,-2.163142292683438,-0.01822994802822997
118.0000000000011,37.465649596602645,-2.1611745359763725,-0.019550151877574695
119.1000000000011,37.82176600124848,-2.158853206736046,-0.02092600151511137
120.20000000000113,38.175070656047815,-2.157203928534969,-0.019869835015615234
121.30000000000115,38.54731667371638,-2.155177535374824,-0.019539922050995973
122.40000000000116,38.90429688578871,-2.152353155828614,-0.019540003999998667
123.50000000000117,39.26813990126932,-2.1501041632354108,-0.020840666446526157
124.60000000000119,39.62949158613261,-2.148002698386829,-0.019540136323852764
125.70000000000121,39.9885394066957,-2.1465420107705864,-0.020532675017740143
126.80000000000122,40.35590179045348,-2.144146238478007,-0.020199874510681948
127.90000000000123,40.709581658844044,-2.1413831450453626,-0.02019987694345904
129.00000000000125,41.06800894846593,-2.139352984677455,-0.02184987199986299
130.10000000000127,41.42956009623853,-2.1368496401865076,-0.021849871881151284
131.2000000000013,41.79159769638863,-2.135454734738173,-0.020800006647102798
132.3000000000013,42.146539621994044,-2.133606255383228,-0.022116698254557754
133.4000000000013,42.50771576445875,-2.131132292977922,-0.0226429407378288
134.50000000000134,42.85963332952599,-2.1295758651481007,-0.022279620902542874
135.60000000000133,43.22545410843195,-2.1261279747521855,-0.02098732205405085
136.70000000000135,43.58185809396442,-2.125006238255217,-0.021298223980557918
137.80000000000138,43.94220698369099,-2.1230981294364364,-0.024285284656942352
138.9000000000014,44.30271160260908,-2.1226116828739583,-0.02261990399995728
140.00000000000142,44.660170409632514,-2.118930623674357,-0.021960168828787374
141.10000000000142,45.014437672342936,-2.1186361089103456,-0.0232801650329435
142.20000000000144,45.37585133160702,-2.116819203536515,-0.02328052863241936
143.30000000000146,45.735106267094665,-2.116282283522575,-0.021960115260514446
144.40000000000146,46.09601963975902,-2.114026752208785,-0.02328168749941195
145.50000000000148,46.45081513281284,-2.1107399383279555,-0.022259622211427743
146.6000000000015,46.811043866933616,-2.1111148288926826,-0.024602305010637426
147.70000000000152,47.16651724006714,-2.108631929815648,-0.024590538782687688
148.80000000000155,47.518704827011895,-2.1069097332159554,-0.023269904001170794
149.90000000000154,47.879252998421926,-2.105242885419089,-0.02525133696827142
151.00000000000156,48.24271074735997,-2.1037339289667942,-0.02525003600000275
152.1000000000016,48.599165545249626,-2.1014899646577576,-0.024920168000001297
153.20000000000158,48.95304336851551,-2.0999857354091427,-0.02492016800000041
154.3000000000016,49.31155132753712,-2.0988111387698876,-0.024920162091095044
155.40000000000163,49.66864785276195,-2.098421285208988,-0.025579041245791245
156.50000000000165,50.02528852081301,-2.0967590998268473,-0.02690425065310542
157.60000000000167,50.39089009463123,-2.095090100320561,-0.026900199493578913
158.70000000000167,50.735894197077755,-2.0948899796154272,-0.02690003725464507
159.8000000000017,51.09889878407793,-2.094060001207191,-0.026900052370489203
160.9000000000017,51.45724560629526,-2.0909230122665488,-0.026240575813905043
162.0000000000017,51.813855163731965,-2.091334388295966,-0.02630143095596127
163.10000000000173,52.17579111270956,-2.090847661616835,-0.02659644805854189
164.20000000000175,52.53215657705774,-2.0918223845166874,-0.026566143113269547
165.30000000000177,52.885759634844625,-2.0884327649674224,-0.026499971415848478
166.4000000000018,53.24636102870149,-2.087547840035939,-0.027889904993014802
167.5000000000018,53.608717866301134,-2.086765040759547,-0.02689990439459322
168.6000000000018,53.96738871612617,-2.0854907900688047,-0.027560043447318883
169.70000000000184,54.31917000000075,-2.084160000000023,-0.02789003600000184
170.80000000000183,54.67844851157669,-2.0845958723720184,-0.02789003512071897
171.90000000000185,55.0329332823722,-2.0800102979236734,-0.027220174531222163
173.00000000000188,55.38943833245182,-2.079902534181164,-0.028870041888735543
174.1000000000019,55.740666393168354,-2.07766771603488,-0.027551250276230732
175.20000000000192,56.097294212759444,-2.0759994502972376,-0.02789942500498377
176.30000000000192,56.453128804034975,-2.076142862289597,-0.027550031483976944
177.40000000000194,56.81151550573422,-2.0762178484038114,-0.029199904000000387
178.50000000000196,57.16820598906618,-2.0743634662518664,-0.0291999039999995
179.60000000000196,57.53152662097954,-2.0735965589600056,-0.029199904119797893
180.70000000000198,57.888130088493064,-2.0728286434927536,-0.02817369500080691
181.800000000002,58.23896529598328,-2.071577307363818,-0.029529903882066222
182.90000000000202,58.59999082646069,-2.0698384413773847,-0.030901916621704828
184.00000000000205,58.951299643421585,-2.0699072640052822,-0.03095771312224249
185.10000000000204,59.31070493208695,-2.0691695734144226,-0.030520035999993755
186.20000000000206,59.66672730228785,-2.0665165339011966,-0.03052003561410599
187.3000000000021,60.02408498853404,-2.0673065972871347,-0.03019003600154324
188.40000000000208,60.384911658869925,-2.0651482008245976,-0.03051993797418895
189.5000000000021,60.741438416010894,-2.064856090116923,-0.030189874101316683
190.60000000000213,61.09415988117639,-2.0647471442636056,-0.030179928842654302
191.70000000000215,61.452683399473095,-2.0617885791283257,-0.031180168000001007
192.80000000000217,61.812278126773855,-2.060775393181315,-0.02986016688520632
193.90000000000217,62.16815625656063,-2.0600698128513204,-0.031179598809646603
195.0000000000022,62.52558810263031,-2.0606430253939787,-0.029531146819290033
196.1000000000022,62.87797482199815,-2.0594017011308097,-0.03085589599257199
197.2000000000022,63.23800482479898,-2.0563886325476504,-0.031368926776680794
198.30000000000223,63.60186399944919,-2.0562175641313356,-0.03150990400000664
199.40000000000225,63.95204068293783,-2.0551371941945913,-0.030519864831646704
200.50000000000227,64.30890800765347,-2.0539758292972308,-0.03258480429167676
201.6000000000023,64.67315957427864,-2.0526604931352272,-0.032171318113795255
202.7000000000023,65.02190923990517,-2.0528922898818704,-0.03315016799998993
203.8000000000023,65.3781047839476,-2.05163131684272,-0.033152825995163226
204.90000000000234,65.73230053482926,-2.0519224616133016,-0.03282016799999976
206.00000000000233,66.08365578422679,-2.0514015885817036,-0.032820168214610757
207.10000000000235,66.44534610013262,-2.051192741959467,-0.03483773817915514
208.20000000000238,66.79499308138719,-2.0511530171615364,-0.03248990396601048
209.3000000000024,67.15629807120612,-2.049765451003116,-0.0324899744237821
210.40000000000242,67.4460524532014,-2.0509937664775473,-0.03479997804849999
211.50000000000242,67.85596475989017,-2.048696577744411,-0.03480016799998209
212.60000000000244,68.21979189771717,-2.04737870756308,-0.035130168000002904
213.70000000000246,68.57531413221517,-2.0485847905498895,-0.03513016799749602
214.80000000000246,68.93593509004761,-2.0480952036187583,-0.03447600450632882
215.90000000000248,69.29045256932234,-2.0467460952353353,-0.035286351787366055
217.0000000000025,69.63803389526475,-2.0457186348608,-0.035130164766878025
218.10000000000252,70.00283710549282,-2.0454972719965987,-0.03513016806059133
219.20000000000255,70.35623386097004,-2.0453628075999757,-0.03546016762302129
220.30000000000254,70.71204139800997,-2.0454421809971715,-0.035128494218399364
221.40000000000256,71.0677525655604,-2.044325772597738,-0.03611966815740164
222.5000000000026,71.42785301676973,-2.043946208255005,-0.03581271836645161
223.60000000000258,71.78326371625656,-2.0430539022192065,-0.0346387727321007
224.7000000000026,72.1429090854888,-2.042810589454345,-0.03549850407084332
225.80000000000263,72.4938197329775,-2.0425414210561947,-0.036716410117538345
226.90000000000265,72.85143303710545,-2.042798955885217,-0.037953380536235315
228.00000000000267,73.2082996402197,-2.039977610906468,-0.03792514360062693
229.10000000000267,73.56523709092725,-2.040534179118729,-0.038529965828693946
230.2000000000027,73.92484874303148,-2.0398335824443556,-0.03721994601171641
231.3000000000027,74.27954953299954,-2.040177606594646,-0.03592103162969895
232.4000000000027,74.63699260941777,-2.0397198900833966,-0.03719556807689006
233.50000000000273,74.99439798707594,-2.0369659089378676,-0.03788007999963616
234.60000000000275,75.34556406486514,-2.0377862851199215,-0.03930004902764228
235.70000000000277,75.70372501713096,-2.037261349901973,-0.03930004799792375
236.8000000000028,76.05046925993294,-2.0367651865255723,-0.039315416254077196
237.9000000000028,76.41180590981972,-2.0357836612978413,-0.03929818295596599
239.0000000000028,76.76224614459225,-2.036524004367013,-0.03996018000000001
240.10000000000284,77.11596218235702,-2.034893914865714,-0.03996017990409095
241.20000000000283,77.47519726463602,-2.0344773428446175,-0.041276872446281754
242.30000000000285,77.82917000000083,-2.034980000000024,-0.04227035951776381
243.40000000000288,78.18782582105143,-2.0346297382075216,-0.043294264054847265
244.5000000000029,78.54380708988788,-2.033811955897667,-0.040496712105186905
245.60000000000292,78.90219402200863,-2.0323517389658243,-0.043149827999999335
246.70000000000292,79.25334834021182,-2.0312426948249733,-0.04314983141897866
247.80000000000294,79.61313841129669,-2.030910701375311,-0.04412916679318979
248.90000000000296,79.9659235921602,-2.0310895153298274,-0.04347998210064441
250.00000000000296,80.32251681585134,-2.031320799712459,-0.04379821957573293
251.10000000000298,80.67999689109196,-2.030894428625005,-0.04379992798437504
252.200000000003,81.03643226137213,-2.032460488711649,-0.04444240645163777
253.30000000000302,81.38917000000103,-2.0328900000000156,-0.04512019199999928
254.40000000000305,81.7502531748178,-2.0316030111775953,-0.04512019199998507
255.50000000000304,82.10538756088332,-2.030806535545174,-0.045120191999998394
256.6000000000031,82.45813307183239,-2.030535312946613,-0.04512019673453738
257.7000000000031,82.81208148606319,-2.0296902040656284,-0.045120192034952655
258.8000000000031,83.17157323447813,-2.0286033130261973,-0.045120191094466744
259.9000000000031,83.52608229830619,-2.0298151579004595,-0.04743005901262487
261.0000000000031,83.88387702122992,-2.0295159369327656,-0.04544633923993002
262.10000000000315,84.23771878258374,-2.029613121177367,-0.048018839082102804
263.2000000000032,84.59416818205105,-2.031062071127534,-0.04875002254312166
264.30000000000314,84.94446247693823,-2.0299197346159676,-0.049950428876258446
265.40000000000316,85.30453430672677,-2.0300811147566256,-0.04973992741274724
266.5000000000032,85.66174627571054,-2.0302485780571096,-0.048419966352577504
267.6000000000032,86.0180491065165,-2.030195630873789,-0.04973226261100905
268.70000000000323,86.37366270469602,-2.031003319610611,-0.04948896327472374
269.80000000000325,86.72775456496589,-2.029311630002073,-0.050720028048403254
270.9000000000033,87.08855130678376,-2.0300125528965594,-0.050720038034745674
272.0000000000033,87.4467942517687,-2.0303938858742754,-0.0512127044592976
273.1000000000033,87.80369820743594,-2.0295052621279153,-0.05108490771762808
274.20000000000334,88.1626273087416,-2.030715490803713,-0.052478507274278385
275.30000000000337,88.52116727552412,-2.031223340377242,-0.05379985200000004
276.40000000000333,88.88462610142308,-2.0310611443783633,-0.05379979629848952
277.50000000000335,89.24169878629525,-2.0325492984060696,-0.055432974346131925
278.6000000000034,89.59850843689392,-2.0334644839131792,-0.054120897917135924
279.7000000000034,89.95411573071496,-2.03338576705996,-0.05411982369653767
280.8000000000034,90.31296006090106,-2.033156568393033,-0.05677098719067075
281.9000000000034,90.66686113453288,-2.0342497512357753,-0.05678829084210557
283.0000000000034,91.02457820181628,-2.032328658954454,-0.05837087230692761
284.10000000000343,91.38048866782728,-2.033488806270173,-0.06088991184816983
285.20000000000346,91.74337473320422,-2.032830497169835,-0.05949925334791706
286.3000000000035,92.1005719339544,-2.0334660744215802,-0.059836873084812225
287.4000000000035,92.46202881586235,-2.0342825048675057,-0.06385106618703862
288.5000000000035,92.81402023129446,-2.0356288880198634,-0.06251182485631235
289.60000000000355,93.17416370238564,-2.0356532409978287,-0.06247000794292212
290.70000000000357,93.53028525618491,-2.038595602595257,-0.06312980693092074
291.8000000000036,93.88585329190946,-2.0399314014236825,-0.06309746826542684
292.9000000000036,94.24129464810909,-2.0410433610939966,-0.0653788352003315
294.0000000000036,94.60289080778234,-2.043375652487554,-0.06676485326269432
295.1000000000036,94.95901618505238,-2.0434340603391727,-0.06872982882706191
296.2000000000036,95.31955997096598,-2.046285561468219,-0.07136053680343579
297.30000000000365,95.6807132466854,-2.0468020124256388,-0.07004006921687234
298.4000000000037,96.0382341264729,-2.0504767923060756,-0.0723499520150237
299.5000000000037,96.39545432087864,-2.050457945134191,-0.07436257587901007
300.60000000000366,96.75579710897945,-2.052788682131541,-0.07530926148796002
301.7000000000037,97.11472239445044,-2.055207176167991,-0.07596923192404326
302.8000000000037,97.4666157292906,-2.0583746271763084,-0.07892129140594051
303.90000000000373,97.82004078774621,-2.062476804733104,-0.08024988000002375
305.00000000000375,98.18782776649728,-2.066754345397358,-0.0802498799239717
306.1000000000038,98.54414740036337,-2.0701651199618585,-0.08161246232011177
307.2000000000038,98.9019172590259,-2.07286094558588,-0.08419991631687473
308.3000000000038,99.26106372705344,-2.076322552482134,-0.08749029507414585
309.40000000000384,99.6201507587467,-2.0785310827032615,-0.08946997476692031
310.5000000000038,99.9766272593359,-2.0829161007472594,-0.09277224398519612
311.60000000000383,100.33590397009479,-2.084675760764397,-0.0944290491180233
312.70000000000385,100.69423346412555,-2.085616630048628,-0.09737544301505086
313.8000000000039,101.05051530915365,-2.086241973166032,-0.09968155063667972
314.9000000000039,101.40708360972725,-2.087397201498354,-0.10132708586113415
316.0000000000039,101.76953215130264,-2.085564603923095,-0.10629146512094634
317.10000000000394,102.12004402712854,-2.087945852648584,-0.11021982716709067
318.2000000000039,102.48821465989485,-2.0877371636229585,-0.1129035390503983
319.30000000000393,102.8431103689753,-2.0884682030709807,-0.11724616115644837
320.40000000000396,103.19788382871722,-2.0867420922353817,-0.11854734701305825
321.500000000004,103.5579844678679,-2.086458742593144,-0.12284995371382124
322.600000000004,103.91527374131316,-2.086226512818332,-0.1254956002265466
323.700000000004,104.27385459174845,-2.0875359230885127,-0.1304462648948701
324.80000000000405,104.63449764307917,-2.085549889619528,-0.13431172687538107
325.90000000000407,104.99667328634857,-2.0875039069473242,-0.1380000053571071
327.0000000000041,105.35806322197904,-2.08591075676953,-0.14315948005534196
328.10000000000406,105.71284426876335,-2.085008447123825,-0.14600995220785906
329.2000000000041,106.07508808836421,-2.083368037576397,-0.1486452108480747
330.3000000000041,106.43232555625612,-2.0830430167547673,-0.15260062231248694
331.4000000000041,106.79213147413714,-2.0816057367228553,-0.15555983887080016
332.50000000000415,107.14917000000155,-2.0811799999999128,-0.15819803368659446
333.6000000000042,107.50913480572109,-2.081114781982211,-0.16149681546074834
334.7000000000042,107.87030030782749,-2.0794478354611337,-0.16542656710741888
335.80000000000416,108.23267939291418,-2.076759023873815,-0.16840927303715603
336.9000000000042,108.58886917180742,-2.075596582153066,-0.16942448691530076
338.0000000000042,108.94917000000112,-2.0740600000000056,-0.17202987605989728
339.10000000000423,109.30883137422146,-2.07049809561947,-0.1766393960488002
340.20000000000425,109.67055134929048,-2.070547215869217,-0.17665118726828855
341.3000000000043,110.02953262208449,-2.071842580969742,-0.17829003910534924
342.4000000000043,110.3915179174571,-2.067505795613508,-0.17967638232674954
343.5000000000043,110.74955581126915,-2.066987818805513,-0.18228501359284843
344.60000000000434,111.10806798572486,-2.065793605421141,-0.18486120186331512
345.7000000000043,111.46827506040998,-2.0664067676439175,-0.18421065626881816
346.80000000000433,111.82740800618598,-2.0645941387359215,-0.1855301746640028
347.90000000000435,112.18883640112935,-2.065410036258739,-0.1861890262914141
349.0000000000044,112.54611922854575,-2.0665719563264675,-0.18948496634976175
350.1000000000044,112.90896100611509,-2.0680538702302265,-0.19047957821868522
351.2000000000044,113.26866072231405,-2.0678705769608836,-0.1921198789605829
352.30000000000445,113.63249909820202,-2.0681670256326963,-0.1934398402660551
353.4000000000044,113.98924736197455,-2.069111013934552,-0.19367435520976972
354.50000000000443,114.34853531378269,-2.068117896607287,-0.19387997999807371
355.60000000000446,114.70882819433042,-2.070137195289513,-0.19629629363396006
356.7000000000045,115.07104435022367,-2.070311303708387,-0.1978339552886963
357.8000000000045,115.43241573823586,-2.0713594046811648,-0.1971797098746193
358.9000000000045,115.78803506046677,-2.0733428232345625,-0.19719553753814534
360.00000000000455,116.1516113172862,-2.0731795781779527,-0.19909071547683066
361.10000000000457,116.50548789483608,-2.074550554920138,-0.20122689688897877
362.2000000000046,116.87435829304823,-2.074620488920497,-0.2021057270652089
363.30000000000456,117.23507678760168,-2.0753627573248954,-0.20212024581507304
364.4000000000046,117.5995155266453,-2.0763968636086396,-0.2034290427814951
365.5000000000046,117.96350787504343,-2.075024201983928,-0.20473950570113786
366.6000000000046,118.3257022286135,-2.077941537236641,-0.20643387256824575
367.70000000000465,118.69252961100841,-2.078366735031546,-0.20786263021030793
368.8000000000047,119.05008000418036,-2.0789415003507377,-0.2070499159937449
369.9000000000047,119.40679046055122,-2.0825618031346957,-0.20673004625200253
371.00000000000466,119.76783836879073,-2.0832062919541476,-0.20739023712429372
372.1000000000047,120.12236956916298,-2.082402383975533,-0.20870014800045666
373.2000000000047,120.48989782535594,-2.0842213120301674,-0.2109863279927886
374.30000000000473,120.84285171736215,-2.088055450317318,-0.21166012787324462
375.40000000000475,121.21511482829551,-2.0884346406730763,-0.2109974631274958
376.5000000000048,121.57329098113007,-2.0881533996289066,-0.2110154016871424
377.6000000000048,121.93642947678217,-2.0906205511327407,-0.21199950326107775
378.7000000000048,122.29873219493172,-2.0925525097577107,-0.21330851350924274
379.80000000000484,122.6616680832581,-2.0929041298833817,-0.21467913127158234
380.9000000000048,123.02374535311402,-2.0951389601316084,-0.21594998417786915
382.00000000000483,123.38572744055693,-2.0960756644955945,-0.21628011600000097
383.10000000000485,123.74719213340846,-2.0989521206322275,-0.21923981988498653
384.2000000000049,124.10837164155774,-2.099114670270589,-0.21957010981836245
385.3000000000049,124.46996685785119,-2.0985386253863205,-0.2208803585416348
386.4000000000049,124.82828384371975,-2.101602465571333,-0.22088978977445528
387.50000000000495,125.18593645741204,-2.103714193322593,-0.22319024229408457
388.6000000000049,125.5537033415537,-2.1029978536871607,-0.22319018400034274
389.70000000000493,125.9157144591172,-2.105888472942722,-0.2245221961008217
390.80000000000496,126.27630258951085,-2.1065212683058956,-0.2254999200020653
391.900000000005,126.64372298511906,-2.111016120195698,-0.22681446253366033
393.000000000005,127.00664770234906,-2.1095399419122396,-0.2287652997430789
394.100000000005,127.36817176799639,-2.1096192172361112,-0.22903146228196647
395.20000000000505,127.73176931965563,-2.1094890614467277,-0.2291201519999948
396.30000000000507,128.09498252845364,-2.1108077030300114,-0.23044003709717042
397.4000000000051,128.45293737031952,-2.113050172440682,-0.23044221611044646
398.50000000000506,128.82148225789012,-2.112391407975368,-0.2327401699811089
399.6000000000051,129.1845364132064,-2.1150957801939247,-0.23439011999999915
400.7000000000051,129.54716270895892,-2.11462465822789,-0.23438518266712283
401.8000000000051,129.9078156030787,-2.115755959638719,-0.2370356889353653
402.90000000000515,130.26756594784385,-2.1159941828762925,-0.2376804436912643
404.0000000000052,130.63084436625192,-2.117008867960569,-0.23800995780524126
405.1000000000052,130.99240548021314,-2.119113839874165,-0.23830867248497478
406.20000000000516,131.35302567730818,-2.1200410915779084,-0.2393569800691866
407.3000000000052,131.71740182196848,-2.123343418755972,-0.2399899476180689
408.4000000000052,132.07887390022762,-2.1234507173227106,-0.23932993031500605
409.50000000000523,132.4391700000022,-2.1241099999999866,-0.24328348374650766
410.60000000000525,132.80428904937304,-2.125160666522285,-0.24748306310960855
411.7000000000053,133.16510875535886,-2.128050784427626,-0.2449300560000589
412.8000000000053,133.5295231360559,-2.127824088325663,-0.24658018800027381
413.9000000000053,133.89685597242476,-2.1294756216190036,-0.24690015390628917
415.00000000000534,134.26220221980486,-2.1323760010562953,-0.24789002274378635
416.1000000000053,134.60589744874255,-2.1331219206730014,-0.2505299227829041
417.20000000000533,134.98916736508156,-2.133159985830347,-0.25316054625537676
418.30000000000535,135.3546597096139,-2.1338442444252026,-0.25381997813205004
419.4000000000054,135.71846454522847,-2.132933868510496,-0.25381942316061057
420.5000000000054,136.07917000000208,-2.1343399999998662,-0.25547012393794954
421.6000000000054,136.4428815863157,-2.1379255077095545,-0.25678009200237106
422.70000000000545,136.80833228124908,-2.1394793423830594,-0.25743995651884743
423.8000000000054,137.17152923270203,-2.139139106371605,-0.25972765553833943
424.90000000000543,137.53386345238187,-2.141246243177801,-0.26238014738023274
426.00000000000546,137.90230193065597,-2.142087405413998,-0.2627112760981154
427.1000000000055,138.26387149037663,-2.142060149728996,-0.2625789297078227
428.2000000000055,138.6313648942828,-2.1447284439330647,-0.2640131908907657
429.3000000000055,138.99007660396003,-2.1464630633727304,-0.26666002605627215
430.40000000000555,139.35443144802338,-2.1480926758944414,-0.2693006173874499
431.50000000000557,139.7206071187898,-2.1498909326709796,-0.2719300171884753
432.6000000000056,140.08034086137383,-2.150896517171936,-0.2732499066473282
433.70000000000556,140.45689210323116,-2.153359428444206,-0.2748999633175888
434.8000000000056,140.82453289723014,-2.1553032954829043,-0.2775294692022796
435.9000000000056,141.1870426948641,-2.15570206927531,-0.2795106108335954
437.0000000000056,141.55009982570797,-2.1564323931193083,-0.27918265585172497
438.10000000000565,141.91118847148795,-2.1578102405620245,-0.2804875872845569
439.2000000000057,142.27889236249374,-2.159677084553689,-0.2824444117878131
440.3000000000057,142.640243603195,-2.160149095416242,-0.2864204924583831
441.40000000000566,142.99978630050376,-2.1602774336539703,-0.2870798688168801
442.5000000000057,143.3649649767547,-2.163103886949671,-0.28829974387389834
443.6000000000057,143.72990103486558,-2.1649671218037865,-0.2896100276711602
444.70000000000573,144.09457201227704,-2.1676361911369,-0.2923085437725228
445.80000000000575,144.45569223056606,-2.1674746469999024,-0.2953544871449423
446.9000000000058,144.8262008208517,-2.168087852345288,-0.2952098045926137
448.0000000000058,145.18630691276408,-2.1699523536309813,-0.30080735784557433
449.1000000000058,145.54975210664983,-2.1711672758730614,-0.2982898391282123
450.20000000000584,145.91321065335387,-2.1725404537156723,-0.3009098038718152
451.3000000000058,146.2829730125058,-2.173450061175279,-0.30354993538860287
452.40000000000583,146.64666152792,-2.1739890366608075,-0.3042100235368368
453.50000000000585,147.01808495392686,-2.1746832792964623,-0.3045400381635779
454.6000000000059,147.38371463370672,-2.1768573638529713,-0.30583200666525157
455.7000000000059,147.74693884210433,-2.1774215737949167,-0.30751001587839255
456.8000000000059,148.11185539702998,-2.1779813221853583,-0.3084999247372817
457.90000000000595,148.47312912958208,-2.1798926175909084,-0.309810212977367
459.0000000000059,148.8375927994149,-2.1821768554059298,-0.3104698719958119
460.10000000000593,149.20546671511497,-2.18451596391577,-0.3124501360007166
461.20000000000596,149.56454972185793,-2.1887334450659153,-0.31244341598286995
462.300000000006,149.933643396179,-2.1929125784611037,-0.3133786876654594
463.400000000006,150.29747297199503,-2.193186107745818,-0.3149789146794282
464.500000000006,150.66243189871838,-2.196900386489363,-0.3139826784650772
465.60000000000605,151.02949558551907,-2.2006013186424123,-0.31529983999588573
466.70000000000607,151.3968021151635,-2.20389163483622,-0.316289839999945
467.8000000000061,151.76196955241318,-2.2057676045747976,-0.3171422857556956
468.90000000000606,152.1315719130197,-2.2069196621369485,-0.31760984000003667
470.0000000000061,152.49320706206578,-2.2060797023809013,-0.3182721098351342
471.1000000000061,152.85998409565508,-2.2084295930173177,-0.31924993995180184
472.2000000000061,153.22386347575588,-2.2078810262805915,-0.3192493511108774
473.30000000000615,153.5891798311361,-2.2074693546428663,-0.3192499541129137
474.4000000000062,153.95320919637578,-2.20863533191307,-0.32056482393516417
475.5000000000062,154.31952391055228,-2.2053345209910686,-0.32188985355877175
476.60000000000616,154.68318004686478,-2.2012283485730157,-0.3229645209506655
477.7000000000062,155.05062937897335,-2.198639096154609,-0.3232552942751803
478.8000000000062,155.41947480324538,-2.1938587944567116,-0.3218900476687314
479.90000000000623,155.789587444874,-2.1928858044276933,-0.3245214665455234
481.00000000000625,156.1526766785095,-2.1907198003258608,-0.3232017852294815
482.1000000000063,156.5219622948681,-2.1894482771025867,-0.32417035936490723
483.2000000000063,156.88660449729713,-2.1887767408580454,-0.3245199088121713
484.3000000000063,157.25202366521137,-2.1910004564348387,-0.3258594477289356
485.40000000000634,157.61800112108364,-2.192738122123818,-0.32515384397732694
486.5000000000063,157.9856115021687,-2.1958249195768365,-0.32696742103406873
487.60000000000633,158.34916627336594,-2.1978198665107387,-0.3255099079999968
488.70000000000636,158.7147013807544,-2.202588254287078,-0.32681940317468117
489.8000000000064,159.07724485475975,-2.2040693985575763,-0.32551693537391735
490.9000000000064,159.44135799734522,-2.206687957381065,-0.3267726524251686
492.0000000000064,159.8098551459489,-2.2113827573701648,-0.3282117583278903
493.10000000000645,160.18009226408924,-2.2144052723061343,-0.32737048961171933
494.2000000000064,160.54288538894207,-2.2197543596724056,-0.3273700425432873
495.30000000000643,160.90213525411588,-2.2231273118155546,-0.32704989198651413
496.40000000000646,161.28134875017275,-2.223675501653167,-0.32892441823712737
497.5000000000065,161.64486491528467,-2.2293307625540915,-0.32857635405871033
498.6000000000065,162.00916606270994,-2.232179789673333,-0.3299030168204191
499.7000000000065,162.37384679727066,-2.2343498662522903,-0.3298990090178955
500.80000000000655,162.74557561733553,-2.236911234341055,-0.3308900085623425
501.90000000000657,163.11198863807024,-2.2399001878721205,-0.33023014000026185
503.0000000000066,163.48161408891718,-2.243678902737544,-0.330255282669778
504.10000000000656,163.84948437232174,-2.244891056852814,-0.3308798440000005
505.2000000000066,164.21832144640436,-2.248360164709135,-0.3299248204144227
506.3000000000066,164.5848333079761,-2.2511210626330995,-0.3305591742023255
507.4000000000066,164.9523345437754,-2.2558028873739207,-0.33048561694767464
508.50000000000665,165.31984616598527,-2.257787027314966,-0.32989984399999894
509.6000000000067,165.68971101810288,-2.261643598153061,-0.32989526173820805
510.7000000000067,166.0578217891473,-2.2628155567019737,-0.3318798439998951
511.80000000000666,166.42586605627503,-2.265181994648825,-0.3312213393818739
512.9000000000067,166.7961740899862,-2.26858541163528,-0.33285995087770237
514.0000000000067,167.16099602755313,-2.272665902242294,-0.33107021036974515
515.1000000000067,167.5264278094251,-2.2748606686063786,-0.33287010799999894
516.2000000000068,167.89266562742938,-2.276405637093767,-0.3330781346675309
517.3000000000068,168.2610234487435,-2.2780484846224294,-0.33282872889665693
518.4000000000068,168.62518460535247,-2.2819964982096193,-0.332969203575729
519.5000000000068,168.9955614641311,-2.288667085586408,-0.33429007625719054
520.6000000000068,169.3679950078139,-2.2879636971422697,-0.3343086504477375
521.7000000000069,169.73437694085052,-2.2914156422782286,-0.3349529325762153
522.8000000000068,170.10271210446385,-2.292701059601674,-0.33735180850037594
523.9000000000069,170.47276834324282,-2.2934179718767393,-0.3351718403954713
525.0000000000068,170.83875913822007,-2.296313986231514,-0.33650714407335247
526.100000000007,171.2037616231304,-2.298405378452775,-0.33582992300798553
527.2000000000069,171.56503742080184,-2.3006957646352024,-0.3345099484760321
528.300000000007,171.9376891063062,-2.304446134793913,-0.33616016608953947
529.4000000000069,172.30976295641204,-2.3060325450931054,-0.334840076008033
530.5000000000069,172.67766336393495,-2.309078646069088,-0.3354998001404983
531.600000000007,173.04801798178454,-2.310928464673144,-0.3371493988490655
532.700000000007,173.42291115084402,-2.3144014224296097,-0.3358300759632593
533.800000000007,173.78166199169357,-2.316300738292804,-0.33583135423021027
534.900000000007,174.14875791322413,-2.3186085466751383,-0.33615994400000027
536.000000000007,174.51017817796054,-2.321991069409004,-0.33763611592700515
537.1000000000071,174.87720526598858,-2.325311044319542,-0.33988989236933786
538.2000000000071,175.24559947734426,-2.327685175081577,-0.3380782906405795
539.300000000007,175.61131707639666,-2.330012773322609,-0.33861592380485606
540.4000000000071,175.9784185317734,-2.331879971931307,-0.34121629250392127
541.500000000007,176.34797487577723,-2.33652123090949,-0.3304490532841071
542.6000000000072,176.71895907112585,-2.338621603442908,-0.3379148155652243
543.7000000000071,177.08880658107094,-2.340778437440006,-0.33791013199706876
544.8000000000072,177.4491340210693,-2.343862664478525,-0.33856987421834495
545.9000000000071,177.83009471885106,-2.3467292496732517,-0.33867993353023573
547.0000000000072,178.19778917450725,-2.3492136812869866,-0.3403184196034883
548.1000000000072,178.56984351182314,-2.352274517642636,-0.33974683067242983
549.2000000000072,178.94311780967388,-2.3537210672807616,-0.3386067803697923
550.3000000000072,179.31317862043545,-2.356171903501303,-0.3395314491797716
551.4000000000073,179.67916609353435,-2.357370008756516,-0.3381398680015355
552.5000000000073,180.04917000000307,-2.360050000000027,-0.3381374432125708
553.6000000000073,180.41586420170304,-2.3616253383587784,-0.3394574970364701
554.7000000000073,180.78881323454522,-2.364412511655042,-0.34077004593441407
555.8000000000073,181.1651980812293,-2.3689726553461714,-0.3401105950447283
556.9000000000074,181.52916273571657,-2.370320403865544,-0.33977966558309003
558.0000000000074,181.89810687525673,-2.3732765352865233,-0.3401238902494854
559.1000000000074,182.26844375685477,-2.3764838409936853,-0.34043983831327873
560.2000000000073,182.63685456141428,-2.3794352523817186,-0.34077009834249194
561.3000000000073,183.00569960024205,-2.3838202430043025,-0.3391198352895244
562.4000000000074,183.37680805421564,-2.3858055974804246,-0.34050324926434783
563.5000000000074,183.74804697806974,-2.389593042765825,-0.3392159085001367
564.6000000000074,184.1184682813569,-2.394118347086909,-0.3404401000000008
565.7000000000074,184.48974556298077,-2.395985577161317,-0.33980016318527806
566.8000000000075,184.8586609027379,-2.3987233891540654,-0.34060425179227805
567.9000000000075,185.21946515138598,-2.3998507263522826,-0.3404398290135582
569.0000000000075,185.5857819757735,-2.402370179817262,-0.34179682768978603
570.1000000000075,185.95994435132684,-2.407511819261132,-0.3420899756721587
571.2000000000075,186.32916561929986,-2.4103098322165897,-0.34208946813489494
572.3000000000076,186.69875009119556,-2.4125360423724773,-0.34241996799999974
573.4000000000076,187.06630530400147,-2.4152695101854653,-0.34263142720421147
574.5000000000076,187.43234695923417,-2.416058312663931,-0.3417599680006287
575.6000000000076,187.80733229659617,-2.421912373391113,-0.34208996801598524
576.7000000000077,188.17957253876952,-2.422006665220659,-0.3401114611790961
577.8000000000077,188.5485702815284,-2.42330962679743,-0.34274895979937803
578.9000000000076,188.9126383278166,-2.4269825368301285,-0.34143032137772433
580.0000000000076,189.28234744532418,-2.4307100331272817,-0.3420898362826579
581.1000000000076,189.65464658213037,-2.4326979891424565,-0.34119219964175906
582.2000000000077,190.02394740241232,-2.436741003498151,-0.34241983600488
583.3000000000077,190.39274283339782,-2.4425386700596152,-0.34076995579699343
584.4000000000077,190.76162914460744,-2.447729122913916,-0.34208996798296765
585.5000000000077,191.13564047048166,-2.448344931247614,-0.34209018635658905
586.6000000000078,191.50485127300038,-2.4538331217806824,-0.3417137702283388
587.7000000000078,191.87029603545577,-2.4579153787093353,-0.34143170129926803
588.8000000000078,192.24456836664595,-2.4573537035153827,-0.3404400834362029
589.9000000000078,192.61670362100932,-2.4616284734146014,-0.3401102123504596
591.0000000000078,192.98541672281476,-2.465558412167256,-0.33912967418386897
592.1000000000079,193.3536876274656,-2.471225598879905,-0.3401100680013993
593.2000000000079,193.7188199678717,-2.4734393981143725,-0.3387996623613052
594.3000000000079,194.09217949138562,-2.4759252755391077,-0.3410900675794033
595.4000000000078,194.46747624102574,-2.478145310716353,-0.3394598082944249
596.5000000000078,194.83828715357936,-2.4814157340570095,-0.3407697983182598
597.6000000000079,195.21467115702796,-2.4843965101709404,-0.3407678084175827
598.7000000000079,195.5787148810066,-2.488049254890721,-0.34174993596726466
599.8000000000079,195.95026515008297,-2.490463912094921,-0.3410899359999999
600.9000000000079,196.32114365563277,-2.494920615820863,-0.3410899359999999
602.000000000008,196.68839905840926,-2.4987332204975687,-0.3424097818722953
603.100000000008,197.05621451238693,-2.5018813040536436,-0.34269955060584545
604.200000000008,197.42489280830995,-2.504224113373461,-0.3420799359977602
605.300000000008,197.79752236524027,-2.5094112627302207,-0.34174993056612646
606.400000000008,198.16945856105977,-2.512446481654005,-0.3424100640360086
607.5000000000081,198.53980771663103,-2.515155625297886,-0.3411000680001002
608.6000000000081,198.91466865597337,-2.516963525248472,-0.3424084153817626
609.7000000000081,199.28203790549205,-2.5202831965241663,-0.3417600680020465
610.8000000000081,199.65165363253377,-2.5235363443770127,-0.34176270844568224
611.9000000000082,200.01841440543464,-2.527984624701738,-0.34239992315624246
613.0000000000082,200.38886300359133,-2.5307147674354256,-0.341099934242993
614.1000000000081,200.76206321882844,-2.536383230313068,-0.3419356438370351
615.2000000000081,201.12851965809745,-2.539717215650588,-0.34105314375845364
616.3000000000081,201.5053244740136,-2.5441906552147513,-0.34166298345844703
617.4000000000082,201.87576077385035,-2.545337980924987,-0.3413198041062242
618.5000000000082,202.25109603379474,-2.546849202039073,-0.3429762120710014
619.6000000000082,202.6222771847916,-2.55150257362159,-0.34132156246507916
620.7000000000082,202.99361391104392,-2.553430115919582,-0.34264006811749237
621.8000000000083,203.36312258980746,-2.5563065701148178,-0.3412087477482393
622.9000000000083,203.73275458459548,-2.5599448707010297,-0.34186723853102974
624.0000000000083,204.10679335123,-2.5630612448551338,-0.3408076309132393
625.1000000000083,204.47790156201253,-2.5633677592491386,-0.34086343066577784
626.2000000000083,204.84879431758364,-2.567416025454263,-0.34319006800002194
627.3000000000084,205.21743020136623,-2.5729803189944285,-0.34319006153492815
628.4000000000084,205.59160261760752,-2.5742142956852936,-0.34285532844627786
629.5000000000084,205.96087209734347,-2.5753862920400654,-0.34154058930767617
630.6000000000083,206.33362015855118,-2.5795352964863616,-0.3431900679815141
631.7000000000083,206.70563081267585,-2.5824241349498456,-0.34187006800689534
632.8000000000084,207.07217233873007,-2.585879569140866,-0.34187006842221024
633.9000000000084,207.446671028497,-2.5876272211728955,-0.34154397769600475
635.0000000000084,207.8201360290119,-2.592346405545162,-0.3418599029264824
636.1000000000084,208.19244046156027,-2.595662952678019,-0.34086990436839804
637.2000000000085,208.56442394124593,-2.5985321320825516,-0.34284989454476644
638.3000000000085,208.93212540171155,-2.602968262353495,-0.34317732485128083
639.4000000000085,209.30320760492336,-2.607585034689652,-0.34218943757811804
640.5000000000085,209.67453900939694,-2.607861334106456,-0.34264000430589636
641.6000000000085,210.04675632733503,-2.613418037312955,-0.34284990399693216
642.7000000000086,210.41726960365443,-2.6154981431015725,-0.3428499040000008
643.8000000000086,210.79224743398578,-2.6185205969363694,-0.341539151865919
644.9000000000086,211.16990992937963,-2.6224023201932387,-0.34153990492928443
646.0000000000086,211.54272453939836,-2.626297999382724,-0.3422072499295523
647.1000000000087,211.9095329578072,-2.6318258390861446,-0.3422000675453294
648.2000000000087,212.2733568473241,-2.6330544993460436,-0.34220003442718694
649.3000000000086,212.64310640834572,-2.638474966285748,-0.3459352980361299
650.4000000000086,213.01840508621032,-2.6415069029136915,-0.34208990401217365
651.5000000000086,213.37955265400728,-2.646048862249254,-0.3434470999769723
652.6000000000087,213.76137944576774,-2.6477015724714223,-0.34274461773823495
653.7000000000087,214.13681740216097,-2.654145497913661,-0.3444366003641641
654.8000000000087,214.5112785115404,-2.6570043650639548,-0.34398829328314484
655.9000000000087,214.88264749473942,-2.6600793343034304,-0.3430801680001654
657.0000000000088,215.2545725442441,-2.661953047387916,-0.34505058744616246
658.1000000000088,215.62767097737753,-2.664652693340279,-0.34317246532079126
659.2000000000088,215.996910386658,-2.6713244761117707,-0.3445094055742768
660.3000000000088,216.36959776197662,-2.6732913927649355,-0.3447301663420217
661.4000000000088,216.7444480525048,-2.6749140216414946,-0.34342275856647353
662.5000000000089,217.1178987207015,-2.6809226512211866,-0.3434101679999997
663.6000000000089,217.48529393308291,-2.6845261477012876,-0.34439997596559335
664.7000000000089,217.8512872982355,-2.6884512133892935,-0.3443848403973808
665.8000000000088,218.22012380846513,-2.693966688063477,-0.34373340733484126
666.9000000000088,218.59140438740502,-2.6976018528356795,-0.3438176621687634
668.0000000000089,218.96338269126753,-2.7017198988354427,-0.3437316336436229
669.1000000000089,219.3388299888763,-2.705357599971446,-0.3450475557751904
670.2000000000089,219.7169998029988,-2.7089624747526204,-0.34414793325815474
671.3000000000089,220.09484440585396,-2.7140167179667496,-0.34570987186297897
672.400000000009,220.4651008727822,-2.7183530013350463,-0.34724877797838394
673.500000000009,220.83527120361964,-2.7230853566703628,-0.3470416480823384
674.600000000009,221.21003777477637,-2.726380431441765,-0.34436552263369036
675.700000000009,221.57916678044896,-2.7297201017636006,-0.34768987746256697
676.800000000009,221.94754259765895,-2.7330490021803535,-0.3473591420702986
677.9000000000091,222.32501158306187,-2.739010548739874,-0.34735986321790024
679.0000000000091,222.6983486604773,-2.7422197767687027,-0.3477011040112403
680.1000000000091,223.0701970461074,-2.7480048087904536,-0.3470299820749756
681.2000000000091,223.44332441635032,-2.751637504637884,-0.3463600425104243
682.3000000000092,223.81427489879746,-2.75416717869355,-0.3483216296416436
683.4000000000092,224.18269971908325,-2.7587761679196925,-0.34734871253677424
684.5000000000091,224.55655394582965,-2.763976876747304,-0.34722561517766115
685.6000000000091,224.93219551060668,-2.7671400639871258,-0.34818785732017066
686.7000000000091,225.30604731341793,-2.7701992909286846,-0.34910062263154007
687.8000000000092,225.6829305017952,-2.7745373298436804,-0.3463699751040732
688.9000000000092,226.05175084203017,-2.777945293904486,-0.3456696423922465
690.0000000000092,226.4245766327071,-2.7823422669351614,-0.35003358267336004
691.1000000000092,226.78954867572793,-2.7868278344408637,-0.34867010351728744
692.2000000000093,227.17126018435775,-2.7919887541693407,-0.34798405031508395
693.3000000000093,227.5412938590635,-2.7935015723227763,-0.3469125435444176
694.4000000000093,227.91732389125826,-2.7986639549828887,-0.348700846693895
695.5000000000093,228.29297072224438,-2.802260960352564,-0.34833983999999996
696.6000000000093,228.665881082997,-2.807782148776194,-0.348339839566556
697.7000000000094,229.03989180660741,-2.8086279147961655,-0.3496601646549711
698.8000000000094,229.40871823574992,-2.813250092927984,-0.3483079232110571
699.9000000000094,229.78495377364698,-2.8196435283253587,-0.34867998845165404
701.0000000000093,230.1602049623598,-2.820402997771632,-0.3490085382100121
702.1000000000093,230.5361873838574,-2.8230333508491814,-0.34831056963239915
703.2000000000094,230.9040276075409,-2.8263518123426565,-0.3499899732380021
704.3000000000094,231.26769208719617,-2.8279561083091522,-0.3499991746720368
705.4000000000094,231.64134685858966,-2.836720197026745,-0.34868012136838544
706.5000000000094,232.01996210993283,-2.8398367232003574,-0.3483398079987534
707.6000000000095,232.3917117142759,-2.8443568711022373,-0.3493299405799397
708.7000000000095,232.76376938911574,-2.8476419611971475,-0.34932954860524124
709.8000000000095,233.13807444986458,-2.8513586904765322,-0.3512247598967182
710.9000000000095,233.51255084218707,-2.8588451266323713,-0.3490107254777164
712.0000000000095,233.88345596723423,-2.859654735224773,-0.35127070060602117
713.1000000000096,234.2580933200548,-2.865390168698677,-0.3519700721304102
714.2000000000096,234.63298838189476,-2.869164129292595,-0.3509808059996238
715.3000000000096,235.00568115533528,-2.8742915518051686,-0.350573708293624
716.4000000000096,235.37887560535341,-2.8783420391668635,-0.3509798975745273
717.5000000000097,235.75158241691508,-2.8786421615088873,-0.35262540633489614
718.6000000000097,236.12684999768553,-2.8850171238570694,-0.35194154290775304
719.7000000000096,236.50132633302186,-2.8886861438782,-0.35162980752925943
720.8000000000096,236.87076537772012,-2.8848669074918325,-0.3532801719951646
721.9000000000096,237.2372192477145,-2.803701790462192,-0.3513180235495441
723.0000000000097,237.60534668052586,-2.808247337582835,-0.3519599731100693
724.1000000000097,237.9767576297508,-2.8124173000056727,-0.3529469564696952
725.2000000000097,238.35127338020072,-2.817457443712551,-0.3532798457091557
726.3000000000097,238.7233378791861,-2.8218190258367,-0.3532800250274364
727.4000000000098,239.09531229190014,-2.823978990094045,-0.35394017152693014
728.5000000000098,239.46655306836303,-2.8277252403807904,-0.35426990885842313
729.6000000000098,239.852020357745,-2.8329427978049946,-0.3536200353034107
730.7000000000098,240.2211264887808,-2.839856637605491,-0.3538698950298893
731.8000000000098,240.5923043428855,-2.841673555099202,-0.3569101610633565
732.9000000000099,240.96050904370279,-2.849416776866734,-0.35393041937704117
734.0000000000099,241.3337813678637,-2.854726135561468,-0.3550294512897594
735.1000000000099,241.70744335500285,-2.8572307223985636,-0.3561458075547703
736.2000000000098,242.08281137686174,-2.865236995275474,-0.35636084792621414
737.3000000000098,242.4588031740718,-2.869474828808227,-0.35526002269796164
738.4000000000099,242.82952460487223,-2.8737196206939806,-0.3562362167802906
739.5000000000099,243.2095937366921,-2.8780019133443475,-0.35492989056725
740.6000000000099,243.58340213621784,-2.883631271567539,-0.3549300117668328
741.7000000000099,243.95506239016032,-2.8885982654120768,-0.355920008
742.80000000001,244.32786822019239,-2.894572050773509,-0.3562229209769314
743.90000000001,244.69866828411674,-2.899407538326791,-0.35724013999969184
745.00000000001,245.0684177751863,-2.903380986234418,-0.35724013996024206
746.10000000001,245.44207059001522,-2.9087648199236344,-0.356504285287377
747.20000000001,245.81859285984544,-2.9163392182056,-0.35691008637029764
748.3000000000101,246.19917359186667,-2.918220220236502,-0.35658000788634103
749.00000000001,246.43657502691013,-2.922979544760126,-0.3578998759951526