File: 01_Data/Memory_Foam_Carpet_Pad/STA/N2/10K_min/Memory_Foam_Carpet_Pad_STA_N2_10KData_221013_R3.csv
##Temp./Â°C,Time/min,DSC/(mW/mg),Mass loss/mg
51.0,10.804742564569308,-1.6056244722893265,0.013685377881731853
52.000000000000014,11.126005184352188,-1.4885347553531116,0.013261173212262278
53.00000000000003,11.360335598163486,-1.4033933824489278,0.015507067320131185
54.00000000000004,11.551961578660489,-1.3440641532453093,0.013984033887207481
55.00000000000006,11.724820339604358,-1.2946979492095003,0.014755047530927712
56.00000000000007,11.884318987646726,-1.2567683077402556,0.014126735096075649
57.000000000000085,12.03697072652147,-1.2209577721665024,0.013689157512929206
58.0000000000001,12.179123473500999,-1.1938147843582199,0.012355101796179824
59.000000000000114,12.31861593730275,-1.1695552933715443,0.014075136413214118
60.00000000000013,12.455080108686818,-1.1490497995108153,0.013111895923577421
61.00000000000014,12.587592967799244,-1.1290904179137498,0.014224424349492892
62.000000000000156,12.715103941493506,-1.113077520397884,0.013117886355179742
63.00000000000017,12.84205643081873,-1.098905343053737,0.015707971698494916
64.00000000000018,12.96760617235105,-1.0844102678596554,0.014205594666156784
65.0000000000002,13.08892099042121,-1.0698870347582763,0.014056337934534646
66.00000000000021,13.211467912617227,-1.0558971838348892,0.014327322684303923
67.00000000000023,13.330984089792414,-1.0439118723035548,0.013440582894105546
68.00000000000024,13.450116243089962,-1.0338641862600153,0.01323249279142047
69.00000000000026,13.566565579246218,-1.0219002233577519,0.015147850855811384
70.00000000000027,13.68354327005725,-1.012677813448923,0.016453379748576857
71.00000000000028,13.798758032112449,-1.0014999704163505,0.016719025023139267
72.0000000000003,13.91343249708247,-0.9909325961545752,0.015870526291149822
73.00000000000031,14.026085760148092,-0.9801374437633191,0.015011120919955268
74.00000000000033,14.138610521652726,-0.9703674703212232,0.015479818218556929
75.00000000000034,14.249631445523427,-0.960277011546776,0.016104132688154138
76.00000000000036,14.355866226979714,-0.9507785195570748,0.01540528759977633
77.00000000000037,14.47023954044809,-0.9420872956847227,0.015480449139077201
78.00000000000038,14.57978088562656,-0.932720532041972,0.016134474596970705
79.0000000000004,14.687448528657574,-0.9241469197033197,0.01659916344687673
80.00000000000041,14.79636924590371,-0.9169201282151608,0.015511828610665468
81.00000000000043,14.903310444143258,-0.9093629887160515,0.01613901591743261
82.00000000000044,15.009210562405526,-0.8996709745646584,0.016799596049551724
83.00000000000045,15.116047611741699,-0.8911286740258876,0.016801164767513477
84.00000000000047,15.221568667660922,-0.8844145521185678,0.015439869995846678
85.00000000000048,15.328026322382934,-0.8753714465557556,0.016798381315934918
86.0000000000005,15.43209639094476,-0.8684655368362812,0.016782287910897864
87.00000000000051,15.53530411476515,-0.8622499259985691,0.015542163740244419
88.00000000000053,15.63954531743928,-0.8548782415962837,0.01547397974820619
89.00000000000054,15.741857233696111,-0.847484259888703,0.015480110792822188
90.00000000000055,15.846274461572683,-0.8406486602052157,0.015793169748372193
91.00000000000057,15.94695431098145,-0.8323476817921469,0.015340937985769187
92.00000000000058,16.050000000000065,-0.8250899999999932,0.015411930706608956
93.0000000000006,16.152014154982176,-0.8171578337841515,0.0167524773262544
94.00000000000061,16.25320770190797,-0.8117594567329026,0.01574945985102527
95.00000000000063,16.354851754220768,-0.8054842427823223,0.01676691684804421
96.00000000000064,16.45516225959008,-0.7990489403839466,0.01678994658461974
97.00000000000065,16.5553532784873,-0.7911766902162399,0.015551356514218462
98.00000000000067,16.652129340216828,-0.7854535060314303,0.016458452224716424
99.00000000000068,16.75574509739996,-0.7779817555120615,0.016075690289817146
100.0000000000007,16.855050145267306,-0.7728783656550051,0.01678995521843163
101.00000000000071,16.955241053865823,-0.7670824565317997,0.015851926896854884
102.00000000000072,17.052421511425276,-0.7617934438395146,0.016792902146055333
103.00000000000074,17.151500150182116,-0.754045644756736,0.016800114854988557
104.00000000000075,17.24947308663302,-0.7497054227811633,0.016415214190724114
105.00000000000077,17.34829087741989,-0.7421734381625528,0.015447146635921172
106.00000000000078,17.447616955222397,-0.737213267652602,0.015418741111522749
107.0000000000008,17.54657420814409,-0.7308569710955759,0.016800449699441167
108.00000000000081,17.64403663905221,-0.7256281107350308,0.016708412749928847
109.00000000000082,17.74292962615546,-0.7189601868658343,0.016781094543547148
110.00000000000084,17.84103091450103,-0.7147717808078448,0.01678983325474359
111.00000000000085,17.938996833942518,-0.7093308361405508,0.01810257255966441
112.00000000000087,18.036709754630326,-0.7025926254136587,0.016846965914309564
113.00000000000088,18.13445245761398,-0.6976676524048082,0.018120633155940702
114.0000000000009,18.22888790558848,-0.692914417963457,0.018344670211424052
115.00000000000091,18.32991607983255,-0.6876661618891162,0.018110038614548074
116.00000000000092,18.428142508149925,-0.6826328679332727,0.01812811437415629
117.00000000000094,18.52478722992585,-0.6776900449264094,0.018123493704157667
118.00000000000095,18.623100843040703,-0.6718256271879545,0.01942990447545956
119.00000000000097,18.719884959695282,-0.6652616818386258,0.018108271834824663
120.00000000000098,18.81850183127035,-0.6600736374342611,0.01808991917494218
121.000000000001,18.915250217835663,-0.6543338192120327,0.017721345495594676
122.00000000000101,19.0137338563124,-0.6490029696782669,0.018112936544423697
123.00000000000102,19.111683871780976,-0.643147150203333,0.01941630996926058
124.00000000000104,19.204501158737756,-0.6367780062523574,0.01809965193858254
125.00000000000105,19.30456035748496,-0.6315626772687061,0.018108323379292912
126.00000000000107,19.401292227733663,-0.6308201898696182,0.019414489063349194
127.00000000000108,19.49889493544208,-0.6305565195674857,0.018109965258948257
128.00000000000108,19.594852184200555,-0.6331028382506254,0.018001933834732142
129.0000000000011,19.691955839994993,-0.6306154516603845,0.018114663753012294
130.00000000000114,19.788729427551793,-0.6288757434677411,0.01675960274429844
131.00000000000114,19.88548453110951,-0.626010307310378,0.01774288934893864
132.00000000000114,19.981745415376178,-0.6229496918890733,0.01877872495174593
133.00000000000117,20.078333797735144,-0.6188831557809334,0.018770088756336456
134.0000000000012,20.17376621959329,-0.6160936231513318,0.01846061531832177
135.0000000000012,20.270756803263417,-0.6115252747092822,0.018439897122080495
136.0000000000012,20.36627636902783,-0.6080232086662725,0.0187212620514714
137.00000000000122,20.461574406447788,-0.6043417352305361,0.0190953902607518
138.00000000000125,20.557335490787075,-0.5998910794413214,0.01999839898055278
139.00000000000125,20.65408390806256,-0.5954816630056698,0.01877059116017854
140.00000000000125,20.750097947018645,-0.5929277257807368,0.017456420661102534
141.00000000000128,20.845803247587078,-0.5896152434982456,0.01745035818780316
142.0000000000013,20.941782575777875,-0.5851040001124811,0.016138844792365603
143.0000000000013,21.035987664616908,-0.5816562347343961,0.017460954756788105
144.0000000000013,21.133390607857226,-0.5776795332227617,0.017456863343014994
145.00000000000134,21.227480113777695,-0.575694116337283,0.017450174769309434
146.00000000000136,21.3237632091531,-0.5705737696241732,0.018772185723475943
147.00000000000136,21.41924751682293,-0.5670318819263303,0.017447059489783534
148.00000000000136,21.515304612979858,-0.5632574065832202,0.016791053674378276
149.0000000000014,21.610822361159208,-0.5590689705225179,0.016782450724562636
150.00000000000142,21.70468532760298,-0.5562967665879573,0.0161398787732443
151.00000000000142,21.800349603373135,-0.5523152836033652,0.017459094586833146
152.00000000000142,21.895145538541122,-0.5484099999463234,0.01706971761390097
153.00000000000145,21.991079236250336,-0.5471121877184565,0.0161400824719502
154.00000000000148,22.087820209544446,-0.5407355988910021,0.016877468582889854
155.00000000000148,22.181998335969407,-0.5387728319473871,0.016130197660451984
156.00000000000148,22.277163198539764,-0.5361018048876449,0.016130198931970874
157.0000000000015,22.37302016712491,-0.5308744817381122,0.016226401415575964
158.00000000000153,22.467910656636974,-0.5277161555692714,0.016129787690640995
159.00000000000153,22.563136721654192,-0.523600577500804,0.01729990538711057
160.00000000000153,22.658874384434238,-0.5214885526304492,0.017399683064224902
161.00000000000156,22.75355340519254,-0.5176897554237365,0.015748750937940592
162.0000000000016,22.849910964281815,-0.5141122538074673,0.014820106296194346
163.0000000000016,22.944645434145407,-0.5106798965501872,0.01472753164022933
164.0000000000016,23.039629961155605,-0.5073341450426953,0.014825260909022475
165.00000000000162,23.13348392868923,-0.5026894538599402,0.016130145916931404
166.00000000000165,23.230707732750076,-0.49961914692380865,0.014855655914297827
167.00000000000165,23.325366366527746,-0.497094224686497,0.016123827959957815
168.00000000000165,23.419191718336783,-0.4928592826328265,0.014819737197320215
169.00000000000168,23.514367533796076,-0.49006673443486365,0.013832379283288176
170.0000000000017,23.610000000000163,-0.4868100000000093,0.015151478344963998
171.0000000000017,23.70523891019897,-0.4841667674528129,0.01382972254892767
172.0000000000017,23.8006379448917,-0.48074596447150525,0.013829855867740548
173.00000000000173,23.896319933071542,-0.4767835023231664,0.013380573602506551
174.00000000000176,23.990293415678185,-0.4740068954316979,0.013829952072401674
175.00000000000176,24.08594767321829,-0.4719167888727936,0.015145027825473
176.00000000000176,24.180620739407114,-0.4685310588109881,0.013829885603081848
177.0000000000018,24.276147448970647,-0.46525444995917753,0.012591834316125983
178.00000000000182,24.370971085399265,-0.4645389492153967,0.011860082423756246
179.00000000000182,24.466010971417983,-0.4611304882965489,0.013169047876959716
180.00000000000182,24.559023862083635,-0.45769385183187494,0.012503351931336226
181.00000000000185,24.65341347462929,-0.45459685905030667,0.012510014043232154
182.00000000000188,24.751269809723496,-0.45229143646541076,0.01250911874413152
183.00000000000188,24.845244751123374,-0.4482217575648864,0.011190065261755144
184.00000000000188,24.940828911105637,-0.44757762961240316,0.011177542610166569
185.0000000000019,25.036167773512474,-0.44437647597259233,0.009870034671811467
186.00000000000193,25.130545097547177,-0.4400790285062116,0.009855722499917619
187.00000000000193,25.225495297531936,-0.439489171185333,0.011190106351998352
188.00000000000193,25.32009560703191,-0.4364123410671892,0.0111901061008286
189.00000000000196,25.414232839883738,-0.43283182467253994,0.011019639582491081
190.000000000002,25.509514792540582,-0.4313385162796207,0.008850629142772348
191.000000000002,25.605166642124402,-0.42806399857251354,0.008876377502256894
192.000000000002,25.69930729334872,-0.4239340506954147,0.008891206357711567
193.00000000000202,25.793800422224688,-0.4234953345167293,0.007899913663511171
194.00000000000205,25.88864193873851,-0.4196665400078367,0.006907053884671832
195.00000000000205,25.982544941405514,-0.41760588018561995,0.0069100600228013676
196.00000000000205,26.079280843317047,-0.4154213398498373,0.006910059999999163
197.00000000000207,26.172742062765433,-0.4121605186984835,0.006904335859677424
198.0000000000021,26.26807841932012,-0.4079103377192647,0.005257821079307057
199.0000000000021,26.36334645981069,-0.40702241959456137,0.005184834718066966
200.0000000000021,26.45854730039016,-0.4040140353810752,0.00460001475646532
201.00000000000213,26.55199798822861,-0.3999927380356064,0.004576103879697868
202.00000000000216,26.647896583114427,-0.3979305418656243,0.001985506573784157
203.00000000000216,26.739637948984413,-0.39501538578063944,0.0005660275120140668
204.00000000000216,26.837020539871563,-0.39219260539251977,0.000698761010706761
205.0000000000022,26.931291153652754,-0.3895255257705644,-0.0006629323379945262
206.00000000000222,27.02671116974285,-0.3861824001312616,-0.000660144973263499
207.00000000000222,27.12141156119877,-0.38305607586518775,-0.0006601449996148645
208.00000000000222,27.215301984759012,-0.3797673502868222,-0.0006601567152424437
209.00000000000225,27.310000000000212,-0.37696999999999475,-0.0033024533809413725
210.00000000000227,27.406082082917607,-0.3737729428863901,-0.0026417908416922486
211.00000000000227,27.500000000000245,-0.37240000000000206,-0.0026398397017199926
212.00000000000227,27.595365524571513,-0.36638732287735765,-0.0049578963228942285
213.0000000000023,27.689615906495554,-0.36478365536202656,-0.005279927820497576
214.00000000000233,27.784903567274057,-0.3622552821087355,-0.005279928434516634
215.00000000000233,27.879032737942225,-0.3593426942447826,-0.006531404996424683
216.00000000000233,27.97471469746767,-0.35654901578211495,-0.006589994523555021
217.00000000000236,28.068892399240006,-0.35300331806420115,-0.006611484772406584
218.0000000000024,28.1630956020066,-0.34970717142326035,-0.009219905369976189
219.0000000000024,28.258269924090804,-0.3453971071910405,-0.010542231928987178
220.0000000000024,28.35350814346086,-0.34232880802619825,-0.012498717099917123
221.00000000000242,28.44893444513476,-0.3388778631098751,-0.013833614289251894
222.00000000000244,28.5434072539272,-0.33720266751290645,-0.015150738969222033
223.00000000000244,28.638232371208645,-0.33373243218173226,-0.014489682668912707
224.00000000000244,28.733853007433126,-0.32971844739903733,-0.01581794592828878
225.00000000000247,28.828323754947668,-0.32843897360187535,-0.017014097107058035
226.0000000000025,28.923583808921737,-0.3244126486917754,-0.017790185056534735
227.0000000000025,29.017712261468816,-0.321957225212585,-0.01909453249947246
228.0000000000025,29.113994858708015,-0.3191600529890884,-0.02042579117741994
229.00000000000253,29.2086601497982,-0.31491267455010363,-0.022414966269187264
230.00000000000256,29.303136337768372,-0.31136555383225206,-0.02504773345301503
231.00000000000256,29.397651934293286,-0.3068529513059178,-0.02634305599994846
232.00000000000256,29.493305800351532,-0.30352648800870263,-0.027669134993841382
233.0000000000026,29.5873218282691,-0.29811155310102433,-0.03029775814471458
234.00000000000261,29.682689493822732,-0.2942901592653935,-0.0312588631125319
235.00000000000261,29.77774979033216,-0.28989768696058654,-0.03230698000670307
236.00000000000261,29.873279185300696,-0.28642182855252407,-0.03359748969240295
237.00000000000264,29.969140159637114,-0.28217382272859337,-0.036235454848216
238.00000000000267,30.06342748472597,-0.27658265377763314,-0.038867299188193094
239.00000000000267,30.15874957462152,-0.271307703417469,-0.04017966639542392
240.00000000000267,30.253447612345802,-0.26679253690900434,-0.04149767656226855
241.0000000000027,30.3484599876205,-0.26136855453347596,-0.04407611996767491
242.00000000000273,30.44352519377553,-0.2558358243024476,-0.04678089686566711
243.00000000000273,30.53954041991082,-0.24902001606170268,-0.04950880465399621
244.00000000000273,30.634086093275503,-0.24289043533437696,-0.0508801575744644
245.00000000000276,30.729818735660913,-0.23630556702391942,-0.05346130180527453
246.00000000000279,30.824488054760426,-0.2295331044779318,-0.05611028799642126
247.00000000000279,30.920084830086832,-0.22283091440345068,-0.060059989882953246
248.00000000000279,31.01482630835275,-0.21672421901512956,-0.06305714892185232
249.0000000000028,31.109912687379456,-0.20742725354924774,-0.06587143873883905
250.00000000000284,31.205803985014228,-0.20170348065901714,-0.0710277418574905
251.00000000000284,31.301565197551877,-0.1931979445519353,-0.07236388915190695
252.00000000000284,31.396199215499138,-0.18465429175401094,-0.07597160825475457
253.00000000000287,31.490886251405357,-0.1761448346747202,-0.08055745886270671
254.0000000000029,31.586085315024327,-0.167619094165912,-0.08620472590381345
255.0000000000029,31.682185130161233,-0.1595395095140705,-0.08867954623075613
256.0000000000029,31.777115768712324,-0.1496032346976715,-0.09330882964988607
257.00000000000296,31.87270621115475,-0.14097653580690084,-0.09774851628039327
258.00000000000296,31.967348341699488,-0.13102947780093221,-0.10222314135857591
259.00000000000296,32.062116294387366,-0.11986332245216648,-0.10657313937957724
260.00000000000296,32.15849829562474,-0.11020929116135857,-0.11080954916031471
261.00000000000296,32.253414601180054,-0.09987650841072312,-0.11750013598343223
262.000000000003,32.3486494481758,-0.08731692624868248,-0.12340122423469957
263.000000000003,32.44427986303726,-0.07505464901341151,-0.12984211190120787
264.000000000003,32.540094306896364,-0.062401873229919455,-0.13548193092362393
265.00000000000307,32.635007062677005,-0.05112871157928765,-0.14301542340919804
266.00000000000307,32.73039608630848,-0.037364404808357864,-0.1496506746778219
267.00000000000307,32.825127957295514,-0.023354343370210463,-0.15614013310177777
268.00000000000307,32.92139533891608,-0.009696081854048152,-0.16328605630000448
269.00000000000307,33.01708288515092,0.005469275244029142,-0.1718927734429614
270.0000000000031,33.11279572098988,0.017858949683258,-0.17944284016117873
271.0000000000031,33.20762816158294,0.035634495994093796,-0.1866777803413977
272.0000000000031,33.30383103809662,0.05035390832181659,-0.19714172761208237
273.0000000000032,33.39969936425597,0.06755603395004946,-0.20549842137697372
274.0000000000032,33.49517778826714,0.08609138006940599,-0.21530487734667236
275.0000000000032,33.59094994303166,0.10203914249444056,-0.2268995948862349
276.0000000000032,33.686433189895766,0.11977844338062082,-0.23614283566038763
277.0000000000032,33.78230222362125,0.1397631738003723,-0.2477191376108019
278.00000000000324,33.878538262043634,0.1582034672898821,-0.2586396178433894
279.00000000000324,33.97437986973129,0.17526332104198722,-0.27141650857705235
280.00000000000324,34.07041748527791,0.19331011858422953,-0.2846302457323735
281.0000000000033,34.165813208006135,0.21268223159054941,-0.29660471731087323
282.0000000000033,34.26198280645109,0.2333283449039588,-0.30950634348060824
283.0000000000033,34.3570844586561,0.25031281078880246,-0.322201787846792
284.0000000000033,34.45356882887704,0.271381516378506,-0.3368563649742353
285.0000000000033,34.55009242463243,0.2872451973153288,-0.3521497394893802
286.00000000000335,34.64492265374871,0.3076289078137879,-0.36785402586099014
287.00000000000335,34.74107869485583,0.32538188520916655,-0.38290121665164856
288.00000000000335,34.837730876014405,0.34206823301908473,-0.3976459834422639
289.0000000000034,34.93284502100526,0.3562883796102178,-0.41225836139203675
290.0000000000034,35.029896832823155,0.3664014700636133,-0.42891660235968754
291.0000000000034,35.12437523534156,0.37473602665126615,-0.44702520043225036
292.0000000000034,35.22103431655365,0.3819119165279957,-0.4642426042164267
293.0000000000034,35.31385358813394,0.38472889436257746,-0.47982912906782227
294.00000000000347,35.412173207559874,0.38698100574410604,-0.49678565069016933
295.00000000000347,35.505901488690874,0.38681437496133525,-0.513875141487782
296.00000000000347,35.60282740364225,0.38373259591664904,-0.5306525447144779
297.0000000000035,35.699725717235,0.3810257479110164,-0.5484363017264342
298.0000000000035,35.79512798991736,0.3733937905216983,-0.5651443290540596
299.0000000000035,35.891471284641405,0.36492515518695867,-0.5825229035281705
300.0000000000035,35.986693929025435,0.3519288629419285,-0.601481061673522
301.0000000000035,36.07961403412795,0.33696266939791125,-0.6185709008398907
302.0000000000036,36.17804728347649,0.31875863707155466,-0.6364094540084051
303.0000000000036,36.27436783905482,0.2985702980547146,-0.6539945938165395
304.0000000000036,36.3706296975122,0.27636043437101787,-0.671878838737535
305.00000000000364,36.46583658089091,0.2503483127060547,-0.6880974960686919
306.00000000000364,36.56260173272092,0.22689284147144076,-0.7041258837074582
307.00000000000364,36.65714030290301,0.2029941996959236,-0.7199322197102376
308.00000000000364,36.753344772721654,0.17964836611368853,-0.7361650484053288
309.00000000000364,36.84968206049787,0.15544157053943092,-0.7505463179978058
310.0000000000037,36.943355090273116,0.1332417503393911,-0.766263141516625
311.0000000000037,37.04028191298361,0.10954061777913147,-0.7799502392139708
312.0000000000037,37.135772775182524,0.08877436995578047,-0.7931251400204657
313.00000000000375,37.231636322100094,0.06884720477415714,-0.8065710923087743
314.00000000000375,37.32547763892125,0.0492223613736307,-0.8216541632423948
315.00000000000375,37.42377868047934,0.03335928333922785,-0.8341064200742361
316.00000000000375,37.51865254550927,0.0135633735970352,-0.8462199013742486
317.00000000000375,37.615666643992014,-0.0001138845350138876,-0.8584632685731917
318.0000000000038,37.71059392536438,-0.01537866871488953,-0.8702500551009966
319.0000000000038,37.80674408769464,-0.028464135498880456,-0.8827197565559781
320.0000000000038,37.902734521843826,-0.04190173873541892,-0.8950486346247408
321.00000000000387,37.99956861597275,-0.05341335409883678,-0.9057712950516366
322.00000000000387,38.09505857830516,-0.06531701846255121,-0.9165799017921348
323.00000000000387,38.1913812631035,-0.0763319241513055,-0.9284790571232335
324.00000000000387,38.287269982041714,-0.08686819843650684,-0.9407054705992293
325.00000000000387,38.38345609112078,-0.09546555270597396,-0.9523821058837956
326.0000000000039,38.47902949297633,-0.10478545086226601,-0.9634444006017366
327.0000000000039,38.576528819666024,-0.11214803565992157,-0.9748375907946194
328.0000000000039,38.672816872184335,-0.11914948424349858,-0.9862617587017262
329.000000000004,38.76902005894985,-0.12642868571679533,-0.9971510103201262
330.000000000004,38.86633333896437,-0.13167522400970044,-1.0087849661247925
331.000000000004,38.96244852218571,-0.13991283170087063,-1.0207175594374958
332.000000000004,39.05849489978559,-0.14449895267955332,-1.0326108256220614
333.000000000004,39.15442496783239,-0.14950020428039215,-1.044833965812023
334.00000000000404,39.25094866445304,-0.15477015701235486,-1.0558494281622806
335.00000000000404,39.34660294008722,-0.16093522603787286,-1.0680453539308488
336.00000000000404,39.443651521715324,-0.1647177038161062,-1.083089744381466
337.0000000000041,39.539909986874896,-0.16947385995196745,-1.0953037755578139
338.0000000000041,39.636917350397944,-0.17501625509718863,-1.108022829327357
339.0000000000041,39.7329788986072,-0.17962514190145737,-1.1205720303255884
340.0000000000041,39.82920447484159,-0.18429394117942008,-1.13506556460773
341.0000000000041,39.92573618467374,-0.1879215619301037,-1.1476382611628635
342.00000000000415,40.02345189771827,-0.19129662668907774,-1.162599807862851
343.00000000000415,40.11924999917463,-0.19812874865630345,-1.1769203989477788
344.00000000000415,40.21637596282881,-0.2040508496316595,-1.1913915986806765
345.0000000000042,40.31287691033015,-0.20829282645643227,-1.2053863146648789
346.0000000000042,40.40982355865536,-0.21449605802030472,-1.220095345272659
347.0000000000042,40.505369585016915,-0.22191482570385732,-1.2344901962720494
348.0000000000042,40.60217613738982,-0.22926496157773096,-1.2491583842519844
349.0000000000042,40.69968458866048,-0.23489629707944865,-1.2658845421011224
350.00000000000426,40.795692894345834,-0.24243854247322522,-1.2809792263955466
351.00000000000426,40.891695795331145,-0.2471046695162668,-1.2990027316949804
352.00000000000426,40.988977653486344,-0.25609750775100926,-1.3153236010485707
353.0000000000043,41.08523884028055,-0.2607662577585149,-1.3315899714992518
354.0000000000043,41.18186943406674,-0.26525650361712844,-1.3496276568516477
355.0000000000043,41.279037859819425,-0.26969129922042767,-1.36756116651335
356.0000000000043,41.375106037173715,-0.274126576621126,-1.38631572472848
357.0000000000043,41.471575016881026,-0.27509669550701504,-1.4050432802314625
358.0000000000044,41.56840389993702,-0.2762146265535281,-1.4248169842094196
359.0000000000044,41.665341828836624,-0.2768512951593242,-1.4439198625130847
360.0000000000044,41.761160011973836,-0.2761818765046357,-1.462922129165824
361.00000000000443,41.85887019656872,-0.27509159772677333,-1.4851027753221815
362.00000000000443,41.95562352915341,-0.2748915725366999,-1.5056479867067276
363.00000000000443,42.05241031404004,-0.2713961125005913,-1.528378992384154
364.00000000000443,42.14836244356409,-0.2698157158158601,-1.5491873039027384
365.00000000000443,42.24585775289782,-0.2655489748412247,-1.5711433135287627
366.0000000000045,42.34022940335074,-0.2619923906134911,-1.5935759260946636
367.0000000000045,42.4400000000004,-0.25830999999998483,-1.6194096757072565
368.0000000000045,42.536042999771425,-0.254545101472947,-1.641775885365682
369.00000000000455,42.633639181737394,-0.24874830934432976,-1.668089423178741
370.00000000000455,42.73123335467495,-0.24348909253751697,-1.6926391335021456
371.00000000000455,42.82816289464064,-0.2363360045857444,-1.7189495692597863
372.00000000000455,42.92497418644916,-0.22948597504284715,-1.7446792793541372
373.00000000000455,43.02230000837264,-0.22271389015839646,-1.7718077672007122
374.0000000000046,43.11990484071403,-0.2161277936270049,-1.7998780793960716
375.0000000000046,43.216604671204955,-0.20834588167293921,-1.828780296721121
376.0000000000046,43.3143333143539,-0.201527207924861,-1.858287349346063
377.00000000000466,43.41081532828143,-0.19376029671871536,-1.8874400140370695
378.00000000000466,43.508089077203934,-0.18343201785964677,-1.9204428501703843
379.00000000000466,43.604826209521846,-0.17706928252801887,-1.9502654236179815
380.00000000000466,43.70238544403966,-0.1688217305148366,-1.9831208430553993
381.00000000000466,43.79942051010761,-0.1625605189766823,-2.0157840832849434
382.0000000000047,43.89717373107791,-0.15507419427717084,-2.050544103108418
383.0000000000047,43.99418006001088,-0.14672068568502644,-2.0872315607281617
384.0000000000047,44.092180954731994,-0.14141517840523055,-2.1226709633260046
385.0000000000048,44.18847906204463,-0.13326132756859546,-2.1605280987806648
386.0000000000048,44.28585038645926,-0.13078287834712443,-2.197488521178573
387.0000000000048,44.383277718745155,-0.12546764137152536,-2.237038870808636
388.0000000000048,44.4804981425586,-0.12044961703917828,-2.2754109624854872
389.0000000000048,44.576748631902646,-0.11837031480131248,-2.31360615072211
390.00000000000483,44.675671695116414,-0.11505208040800108,-2.354996574286959
391.00000000000483,44.7726526915656,-0.11469710224744517,-2.3951767915921147
392.00000000000483,44.86885346870406,-0.11525112661384897,-2.4375386333603677
393.0000000000049,44.96641453133651,-0.11688610723389106,-2.478527797637987
394.0000000000049,45.06418600237092,-0.1202171194687721,-2.5203575828919735
395.0000000000049,45.1611216932563,-0.12469526761587173,-2.5603204375051547
396.0000000000049,45.25814188611627,-0.13101904209132414,-2.6007022068096655
397.0000000000049,45.354877686021425,-0.13782793427780968,-2.6437931190320088
398.00000000000495,45.452546799334684,-0.14599706747221186,-2.683880719322017
399.00000000000495,45.550468867394756,-0.15601901068411037,-2.7228061031552975
400.00000000000495,45.64734148596169,-0.1647598938908142,-2.762307140549691
401.000000000005,45.744303010188105,-0.17559567329694822,-2.801366975577987
402.000000000005,45.84296027191312,-0.18798348606928622,-2.838582934906371
403.000000000005,45.9397029808318,-0.20074006598028804,-2.876537574814889
404.000000000005,46.03743964534253,-0.21363064920067848,-2.9128541110790547
405.000000000005,46.135767628118536,-0.22951226941307368,-2.947390698278686
406.00000000000506,46.2334411289373,-0.241091220015452,-2.9808654439670956
407.00000000000506,46.330309110503286,-0.2551816889792505,-3.0112768736549613
408.00000000000506,46.427754427138446,-0.2715265534367521,-3.0414311688597255
409.0000000000051,46.525859915298916,-0.2819089749743724,-3.070042657887989
410.0000000000051,46.622507100586205,-0.2948986576025301,-3.0999957521976738
411.0000000000051,46.720391452983186,-0.310082541105877,-3.124735443010495
412.0000000000051,46.81787644343368,-0.32256037324546605,-3.148720905596357
413.0000000000051,46.916549700295015,-0.3360433096111357,-3.1740208652473068
414.0000000000052,47.013121517791106,-0.34744421064698267,-3.1968563540391974
415.0000000000052,47.11086669022177,-0.35795535281085494,-3.218201366273896
416.0000000000052,47.209161132256654,-0.3677448950825018,-3.2377759801713304
417.00000000000523,47.30699573136636,-0.37803092840124286,-3.2554615268179425
418.00000000000523,47.40472308384761,-0.3869203868184523,-3.2725730548370673
419.00000000000523,47.50209471630578,-0.3977193076759661,-3.290421311423473
420.00000000000523,47.600214044167515,-0.4025270203073202,-3.304933133715001
421.00000000000523,47.69767913902664,-0.4108898898197925,-3.3182742716108606
422.0000000000053,47.79519753176247,-0.4166327878498785,-3.3295722528452685
423.0000000000053,47.8923570278089,-0.4199901399245051,-3.340754723710326
424.0000000000053,47.991179978797526,-0.42572041383093123,-3.3506277073008475
425.00000000000534,48.08817183219855,-0.4289842400171326,-3.361002088486873
426.00000000000534,48.1855223495745,-0.43436814445745464,-3.369869690848068
427.00000000000534,48.28283166705013,-0.4358231662430329,-3.3788459150513654
428.00000000000534,48.38042870942045,-0.43851546420515203,-3.3860675638605455
429.00000000000534,48.47837687912621,-0.44102949897921584,-3.392760071105798
430.0000000000054,48.57698632806062,-0.4428451178564565,-3.399989331415075
431.0000000000054,48.67176347263665,-0.44400667316002207,-3.405470010244035
432.0000000000054,48.77132745483491,-0.4458357496465605,-3.4109994717685055
433.00000000000546,48.869517658782904,-0.44560541050177566,-3.415656631577521
434.00000000000546,48.96741339892988,-0.4460302646186446,-3.42167700287267
435.00000000000546,49.064949622188244,-0.44628956425675465,-3.4248427729058926
436.00000000000546,49.162016778792044,-0.447006621654063,-3.4291858165788494
437.00000000000546,49.25970860672939,-0.4457535216386742,-3.4331138448763925
438.0000000000055,49.356383557810894,-0.4465924563177318,-3.4376377954510144
439.0000000000055,49.4557227320089,-0.4434123225433994,-3.4408894040775992
440.0000000000055,49.552784573260496,-0.4437188076514863,-3.442068241146709
441.00000000000557,49.65060445642035,-0.4433275510853495,-3.4463614488518575
442.00000000000557,49.74897978300092,-0.4418418644074521,-3.4497302033488735
443.00000000000557,49.84646003174088,-0.44166911105107254,-3.453017208027467
444.00000000000557,49.94423070683549,-0.44242720436293625,-3.4546948239958275
445.00000000000557,50.04180279832563,-0.43939430182187583,-3.458197831732581
446.0000000000056,50.139600383271805,-0.43903309839530696,-3.4585304953849096
447.0000000000056,50.23801614308015,-0.43998114704019725,-3.4610433766323307
448.0000000000056,50.335822846308155,-0.43743907940750926,-3.4627816703282974
449.0000000000057,50.433598083479865,-0.4367658431602926,-3.465379775606867
450.0000000000057,50.53193733999059,-0.4348964549118649,-3.4680377163673626
451.0000000000057,50.63000000000058,-0.4338299999999873,-3.4706900370000033
452.0000000000057,50.72689472322206,-0.4324289692182071,-3.472406745667487
453.0000000000057,50.825846363814655,-0.4307198891883925,-3.4753008127268687
454.00000000000574,50.92327326545681,-0.42996572620580664,-3.477539223152875
455.00000000000574,51.02146581259314,-0.4282679436646493,-3.4806303924214412
456.00000000000574,51.118870546622894,-0.42524773370710445,-3.4818711908688074
457.0000000000058,51.214973674947565,-0.4248145803822633,-3.4855652856013144
458.0000000000058,51.315180893413,-0.42240691214404597,-3.488142490899719
459.0000000000058,51.41375919430384,-0.42097644595865996,-3.4895029583112214
460.0000000000058,51.51159283459415,-0.4184880847596717,-3.492206019132002
461.0000000000058,51.60691816846964,-0.41712732892868953,-3.494521411647705
462.00000000000585,51.70833582737987,-0.41499346596676284,-3.4983815939692797
463.00000000000585,51.80637704205969,-0.413294512873335,-3.4989895727198004
464.00000000000585,51.90567511428136,-0.41332356536158166,-3.503188901372334
465.0000000000059,52.00272915210362,-0.4107820257187975,-3.5083560936091613
466.0000000000059,52.10148413208824,-0.4093852044142307,-3.510564869922092
467.0000000000059,52.199534180499825,-0.4083918784196232,-3.5138917710005257
468.0000000000059,52.29731082046028,-0.4078375283285045,-3.515992363428184
469.0000000000059,52.39566541688135,-0.40459523276081866,-3.518517806879552
470.00000000000597,52.49391896660091,-0.40485093372143394,-3.524249425842276
471.00000000000597,52.59213848671728,-0.40464284343403056,-3.5266212526784932
472.00000000000597,52.690281486830536,-0.40220705043101,-3.529642307908267
473.000000000006,52.789344075006916,-0.40234862485211575,-3.5337584249472775
474.000000000006,52.88710790184275,-0.4027790446216838,-3.536529948542581
475.000000000006,52.98654678073496,-0.40228345987871217,-3.54082476682061
476.000000000006,53.08434718901148,-0.4025280073433002,-3.543585011033552
477.000000000006,53.18375251000126,-0.40271225332532096,-3.546039075773709
478.0000000000061,53.282623556634725,-0.4039242989547598,-3.547979276078708
479.0000000000061,53.38134344432562,-0.40237452249792005,-3.5508873500512603
480.0000000000061,53.48000000000063,-0.40537999999997953,-3.555167467969711
481.00000000000614,53.579056222508996,-0.4048933268304279,-3.559109967948518
482.00000000000614,53.677327645549454,-0.4062317505701259,-3.560506765782292
483.00000000000614,53.775864535236195,-0.40850361129862617,-3.5635903037375796
484.00000000000614,53.874727288071476,-0.40788759708837197,-3.5662319959677813
485.00000000000614,53.97463739678971,-0.4104006657315711,-3.5674976937379057
486.0000000000062,54.07191160451093,-0.4098425379452101,-3.569942647922722
487.0000000000062,54.17174363660205,-0.4110868479236653,-3.571386132167615
488.0000000000062,54.270202789313,-0.4121220514421282,-3.573219732363457
489.00000000000625,54.36899266483614,-0.4133628253192284,-3.5751167281658116
490.00000000000625,54.46847759717267,-0.4143365205273088,-3.5768413999112285
491.00000000000625,54.567316172894714,-0.4144267662318474,-3.578160287665421
492.00000000000625,54.66479351078909,-0.4139857986595806,-3.5794867743850443
493.00000000000625,54.76431898827161,-0.41456463485980705,-3.5807843245130537
494.0000000000063,54.86243723375683,-0.415261697647585,-3.5811180734080086
495.0000000000063,54.961101890155575,-0.41196226887931486,-3.582438486415204
496.0000000000063,55.05960154683814,-0.41069355510296707,-3.5847385841728316
497.00000000000637,55.15933818879131,-0.4082345346405244,-3.5863869062559655
498.00000000000637,55.256807169462114,-0.4065063800803261,-3.586391338234192
499.00000000000637,55.355801619361245,-0.4029730091706312,-3.5863957589109825
500.00000000000637,55.4540523798356,-0.40051028394726396,-3.587710340239227
501.00000000000637,55.553226825075114,-0.40094319025846187,-3.587710040428177
502.0000000000064,55.65201228498163,-0.3980210462540641,-3.589036980568779
503.0000000000064,55.750875151637466,-0.39546296634449124,-3.589008545753057
504.0000000000064,55.85000000000063,-0.3930100000000053,-3.5890301867832965
505.0000000000065,55.94841186868266,-0.3932611892851992,-3.5893508415993987
506.0000000000065,56.04734378944013,-0.39153041282508505,-3.590679886410869
507.0000000000065,56.14548147770609,-0.39005828765568884,-3.5906707668997035
508.0000000000065,56.24523963848792,-0.38929423073102937,-3.5913482111375488
509.0000000000065,56.344894437934904,-0.38862388085982663,-3.591670736880662
510.00000000000654,56.44315715881545,-0.3872059197379083,-3.5929945108690857
511.00000000000654,56.54198973402244,-0.3870321544455943,-3.5921490710912893
512.0000000000066,56.6412268441028,-0.3859750648383048,-3.5933169370446034
513.0000000000066,56.74028003901618,-0.3847602567804216,-3.594655808908053
514.0000000000066,56.83906197960271,-0.38382888877035054,-3.596590378387434
515.0000000000066,56.938527196470915,-0.3810974009358209,-3.5959525039535514
516.0000000000066,57.03618769963196,-0.38063974939189643,-3.5972719681174192
517.0000000000066,57.13655426147928,-0.3785668882852294,-3.5985900498759107
518.0000000000066,57.23307512957612,-0.37914229915039643,-3.5985912063396164
519.0000000000066,57.33370282445232,-0.3774836669809289,-3.598556770249278
520.0000000000066,57.43349540998214,-0.3759369267519445,-3.5986042407730596
521.0000000000067,57.531869229500224,-0.37715624341003406,-3.599988896949019
522.0000000000067,57.628772839067864,-0.37578279292091676,-3.5998994425029722
523.0000000000067,57.730881469770196,-0.3769808274742289,-3.5995689442776793
524.0000000000067,57.8290643147095,-0.37721085815500816,-3.600889872549362
525.0000000000067,57.92846650045771,-0.3753676449902208,-3.6008842167527737
526.0000000000068,58.027250929285394,-0.3753470510371974,-3.602206430420404
527.0000000000068,58.12619194557912,-0.3751796858444366,-3.6045458795593195
528.0000000000068,58.225137376292764,-0.37483219115890154,-3.603519579811
529.0000000000068,58.324783718552084,-0.3740634042029312,-3.6043549235893493
530.0000000000068,58.42387394170545,-0.3740968186978345,-3.606266506214344
531.0000000000068,58.52292833004475,-0.3744700442070121,-3.606854490513729
532.0000000000068,58.6206804745259,-0.374127690335777,-3.6074823381320895
533.0000000000068,58.7219716222054,-0.37502069259053983,-3.607799643373282
534.0000000000068,58.821195036717256,-0.3730361430581979,-3.609119397460015
535.0000000000068,58.919588419273246,-0.3756688304636348,-3.6091199680004733
536.0000000000068,59.01950507458696,-0.3753280122280504,-3.6091199637964753
537.0000000000069,59.119036698872144,-0.37365294088629264,-3.610437480048726
538.0000000000069,59.21750762053638,-0.3727921613433958,-3.6104400615375836
539.0000000000069,59.317091970783025,-0.3753343964654939,-3.61182520262025
540.0000000000069,59.415524751098495,-0.37207894461833,-3.6114269942208908
541.0000000000069,59.51527484285836,-0.372350252538979,-3.611747656013154
542.000000000007,59.614238712160436,-0.3731440764040519,-3.6114276819415982
543.000000000007,59.71398488097546,-0.37229373582510855,-3.611419809712943
544.000000000007,59.812734810296234,-0.36829038549885745,-3.6114160021621213
545.000000000007,59.91341643513476,-0.3638380883681113,-3.6127398989187647
546.000000000007,60.01202713048323,-0.36200434983796115,-3.6129047874095415
547.000000000007,60.111016362034164,-0.36035087820032646,-3.6137551075192107
548.000000000007,60.211173126386,-0.3595660655170627,-3.614052733839882
549.000000000007,60.30979854566877,-0.3589923139703862,-3.6143900286325583
550.000000000007,60.40936572708272,-0.35734082589951566,-3.614390009391562
551.000000000007,60.509387767093386,-0.355993211277426,-3.6162574039497093
552.000000000007,60.60775102360301,-0.3547689061092531,-3.617019332497551
553.0000000000072,60.705257819513015,-0.3552448404093545,-3.6156999134777146
554.0000000000072,60.80614526074025,-0.3529154793527306,-3.617265264802411
555.0000000000072,60.90592482127357,-0.34937673100522953,-3.618315470235158
556.0000000000072,61.005140813690275,-0.3483067941046903,-3.618298949778177
557.0000000000072,61.10406468620366,-0.34791060681247077,-3.618339943988549
558.0000000000073,61.203241436062136,-0.3457039679559,-3.6183362459564745
559.0000000000073,61.30308610185685,-0.34433872981850544,-3.6186801326643923
560.0000000000073,61.40218476666774,-0.3450408759114344,-3.618627330788722
561.0000000000073,61.50178017888626,-0.34466791517953793,-3.6191827592288273
562.0000000000073,61.600930837541384,-0.3461560119097773,-3.620029893690942
563.0000000000073,61.70017943666829,-0.3452596173844174,-3.6209801720547605
564.0000000000073,61.800439756828816,-0.3463325630039397,-3.620980171933194
565.0000000000073,61.89838348279765,-0.3470971162490911,-3.621272752010407
566.0000000000073,61.99889601449987,-0.34697932961632144,-3.6226255821371423
567.0000000000073,62.09810248264316,-0.3483209043009289,-3.622629885987924
568.0000000000074,62.19741309625412,-0.3490559181241308,-3.622629886
569.0000000000074,62.296996467351384,-0.35333459230221087,-3.6226298859996837
570.0000000000074,62.39636308626053,-0.35589611718517833,-3.6226297409968673
571.0000000000074,62.496529890684556,-0.35640961944015376,-3.6227042724097607
572.0000000000074,62.596064885336475,-0.35962128389217357,-3.6219669556423124
573.0000000000074,62.694458860897456,-0.3607101639696213,-3.6232801367555427
574.0000000000074,62.795333663008535,-0.3603807860625979,-3.623280044986255
575.0000000000075,62.894654697726935,-0.3623786727821245,-3.623272874211246
576.0000000000075,62.99444793076404,-0.36364552283102297,-3.6255974023065867
577.0000000000075,63.09422880785146,-0.36660553614273794,-3.625590300864148
578.0000000000075,63.19348905346593,-0.36693704145025646,-3.6253386785276946
579.0000000000075,63.29261223705964,-0.36791719871396916,-3.6252644826399156
580.0000000000075,63.39252244354346,-0.36922163321145796,-3.6255898154194712
581.0000000000075,63.49120261769464,-0.3705431240210967,-3.6273659216716077
582.0000000000075,63.59117994185391,-0.37145702128407104,-3.6269101070311383
583.0000000000075,63.69087812058475,-0.37304012246541846,-3.6269098707011054
584.0000000000076,63.790359163290866,-0.37314969699525125,-3.62821998459997
585.0000000000076,63.89032581055791,-0.372626128606218,-3.6282200055024485
586.0000000000076,63.99111429555647,-0.3718742001826939,-3.6285866201787615
587.0000000000076,64.08880358588293,-0.37373411449945576,-3.6302001156969146
588.0000000000076,64.18938428220432,-0.373167868985127,-3.6315206310288897
589.0000000000076,64.2890907664004,-0.3736115312337172,-3.6302001007051303
590.0000000000076,64.38837529153083,-0.3754169371646465,-3.6302001741312457
591.0000000000077,64.48667805697119,-0.37275192793650047,-3.6315165458209124
592.0000000000077,64.58793217088393,-0.3761689343326058,-3.631509837003878
593.0000000000077,64.68908844854376,-0.3772080071766732,-3.6315092222758323
594.0000000000077,64.78842813801278,-0.3800464173750739,-3.631519574350504
595.0000000000077,64.88760315521986,-0.3824335948931475,-3.631519929002038
596.0000000000077,64.98808943384743,-0.38420804337778997,-3.6315211909168146
597.0000000000077,65.08799457292045,-0.38316856457309767,-3.632840041305249
598.0000000000077,65.1874297766362,-0.3869329334159584,-3.6328400210000535
599.0000000000077,65.28705999548744,-0.39039140268531936,-3.6328400210018543
600.0000000000078,65.38704994843037,-0.39309498885887423,-3.6328408806149977
601.0000000000078,65.48665483307724,-0.3961035608096266,-3.6348001902954987
602.0000000000078,65.58678568968102,-0.3970638586775706,-3.6354701800704663
603.0000000000078,65.68739511933525,-0.39756570654764184,-3.635431545247166
604.0000000000078,65.78673066879853,-0.39798568931252637,-3.6367898683977544
605.0000000000078,65.88589138532743,-0.39952632746718664,-3.6373646945540314
606.0000000000078,65.9860791041679,-0.39986186824957803,-3.6381099690954843
607.000000000008,66.08663474469257,-0.40257309012949327,-3.6387588577762684
608.000000000008,66.1858313826782,-0.40296392253295765,-3.6377466513912307
609.000000000008,66.28458367031278,-0.4019574552646573,-3.6381130875907135
610.000000000008,66.38567097423847,-0.4027069955752767,-3.639442332898816
611.000000000008,66.4865059059405,-0.40107425188555623,-3.6381028826076918
612.000000000008,66.5859198286822,-0.4042670376994326,-3.63942010326628
613.000000000008,66.68543489641092,-0.40114807870049196,-3.6397556622073104
614.000000000008,66.78632691512608,-0.4023457989531148,-3.639750013459565
615.000000000008,66.88545982160228,-0.40451652978474356,-3.639419684852842
616.0000000000081,66.98552197878355,-0.4021902903384812,-3.640089007735941
617.0000000000081,67.08592778543911,-0.40127769782775735,-3.6407399000231893
618.0000000000081,67.18601788538271,-0.40016859671161936,-3.6407389375873778
619.0000000000081,67.28607494253083,-0.4010263706698532,-3.642059907984647
620.0000000000081,67.38502566257368,-0.402160951869692,-3.642059996346699
621.0000000000081,67.4859820130325,-0.4017746044476116,-3.642615313696764
622.0000000000081,67.58602264016857,-0.40089879262181594,-3.643421730860815
623.0000000000082,67.685730695811,-0.399674137740185,-3.6446878521969466
624.0000000000082,67.78610280540077,-0.3983418687328834,-3.6446901798876183
625.0000000000082,67.88556749957365,-0.39901646826564,-3.645996337251799
626.0000000000082,67.98643663264318,-0.3986960071415188,-3.6450198563695193
627.0000000000082,68.08591528084946,-0.3979744242532302,-3.645020881345406
628.0000000000082,68.18415693534483,-0.39659722288158433,-3.6462747828565827
629.0000000000082,68.2865817253881,-0.39494339484937346,-3.646011683928566
630.0000000000082,68.3850925884113,-0.39422219190097874,-3.6473200637220655
631.0000000000082,68.48700451380925,-0.3904038352865985,-3.648625224020897
632.0000000000083,68.58670852135016,-0.38688835979848446,-3.6486433780182557
633.0000000000083,68.68716830013776,-0.3866398429624377,-3.6473270452982876
634.0000000000083,68.78677394518918,-0.38456952590465615,-3.648649658015823
635.0000000000083,68.88665875714997,-0.38117295187074807,-3.649971744778626
636.0000000000083,68.98802098786224,-0.37848934643386095,-3.6512799630290016
637.0000000000083,69.08676633250116,-0.3757737246919137,-3.6512799388595423
638.0000000000083,69.18729643891662,-0.3709061100775166,-3.653249510952021
639.0000000000084,69.2876960061171,-0.3692626974194902,-3.653252531351526
640.0000000000084,69.38608274790577,-0.3644101388313656,-3.6545702443103574
641.0000000000084,69.48722091698411,-0.36053090147741923,-3.6545635876567975
642.0000000000084,69.58709584781747,-0.35594327174802615,-3.6546801525416805
643.0000000000084,69.68724146881318,-0.35577272057600917,-3.655890115430099
644.0000000000084,69.78784697936673,-0.3499216950733915,-3.6572471640285587
645.0000000000084,69.8883167427257,-0.3454409678921497,-3.657736195825379
646.0000000000084,69.98827669297567,-0.34242399979481125,-3.658530074884887