File: 01_Data/Memory_Foam_Carpet_Pad/STA/N2/10K_min/Memory_Foam_Carpet_Pad_STA_N2_10KData_221006_R2.csv
##Temp./Â°C,Time/min,DSC/(mW/mg),Mass loss/mg
51.0,10.592177968986315,-1.7167661652637614,0.01450703270913234
52.000000000000014,11.032156169767964,-1.5781826386689752,0.01947816230485966
53.00000000000003,11.28830963831571,-1.4889966985394738,0.018973844711287935
54.00000000000004,11.490252765814212,-1.4243192427932119,0.01846140840976407
55.00000000000006,11.667830510789809,-1.3731626879326408,0.019129942030011726
56.00000000000007,11.833762422183778,-1.3317873970060472,0.0184822629520065
57.000000000000085,11.985674224076474,-1.2991220153902538,0.019643483491921465
58.0000000000001,12.131346741178465,-1.2711943136242878,0.019126675961973927
59.000000000000114,12.272174200877382,-1.245415378775447,0.018867585597100778
60.00000000000013,12.409058678693023,-1.2248189508444505,0.018272760234108176
61.00000000000014,12.540844847885012,-1.2062563618312923,0.019514223282733667
62.000000000000156,12.669770978780413,-1.1892706791930931,0.01921959749295965
63.00000000000017,12.797524219486988,-1.172619965081024,0.019276994332482644
64.00000000000018,12.924133153249514,-1.160073217046306,0.0208435387836321
65.0000000000002,13.048600602772563,-1.1463338389950926,0.018165081665615368
66.00000000000021,13.17102474311676,-1.1329025649427047,0.020072833965111947
67.00000000000023,13.291121487247896,-1.1230374421296694,0.019422586954430887
68.00000000000024,13.411664788344988,-1.1102467537871072,0.01946536812900046
69.00000000000026,13.527617182127274,-1.0991014644642498,0.020862533228191094
70.00000000000027,13.64419524200396,-1.0871344769878803,0.020843079262696573
71.00000000000028,13.757298876576943,-1.076536342919227,0.021099858986440623
72.0000000000003,13.874680543904974,-1.0671046173701266,0.02144600177489986
73.00000000000031,13.987887101934657,-1.056743259796672,0.022103337789891153
74.00000000000033,14.098972651549069,-1.048430079643683,0.020874101873031403
75.00000000000034,14.209848689644483,-1.0382257648966429,0.020860617224760514
76.00000000000036,14.324246192660956,-1.0273482346802445,0.022229812498574475
77.00000000000037,14.434882435745427,-1.0187172391946024,0.02076771860230897
78.00000000000038,14.539370362420074,-1.009470310351957,0.021491687218142097
79.0000000000004,14.651658798603648,-1.0015912684525388,0.022664934112736734
80.00000000000041,14.75956847134455,-0.9926162257612827,0.02206065412600422
81.00000000000043,14.867296243548493,-0.9837955487676379,0.02338271317951479
82.00000000000044,14.974484699912404,-0.9747379009844015,0.023268980186090804
83.00000000000045,15.081260586000369,-0.9669837290604015,0.022165814144353924
84.00000000000047,15.187442929803746,-0.959614544508025,0.021925716045253285
85.00000000000048,15.292959015162264,-0.952148016348035,0.02358529960264244
86.0000000000005,15.398096300330096,-0.9438071881769923,0.02338559326117995
87.00000000000051,15.502296765402546,-0.9363147919254615,0.022907249303114607
88.00000000000053,15.605050968900034,-0.9300560061260472,0.023379713954327475
89.00000000000054,15.708683704380164,-0.9241511760525167,0.023444379624641076
90.00000000000055,15.811598263933003,-0.9146785877673834,0.023388830418997753
91.00000000000057,15.915479327401794,-0.9086445041729367,0.02266721141144057
92.00000000000058,16.01653225571397,-0.9017947074737377,0.02243204365464191
93.0000000000006,16.11858363108735,-0.8937088265140428,0.023410937997206283
94.00000000000061,16.21991117116696,-0.8878624883819769,0.02305616629885643
95.00000000000063,16.320506197769237,-0.8793347143611396,0.022235660503084453
96.00000000000064,16.42249705561214,-0.8745496456606937,0.02206679994576044
97.00000000000065,16.52327297651478,-0.8661682992377555,0.023366575197908634
98.00000000000067,16.62326318556088,-0.8577358297375803,0.02341453131561133
99.00000000000068,16.723411283332364,-0.8526270166598525,0.023397729907791653
100.0000000000007,16.822691800892613,-0.8472274025061788,0.022078679141658508
101.00000000000071,16.92228985385465,-0.8421660086028369,0.023380881054299696
102.00000000000072,17.02219809470653,-0.8357125544753007,0.02459077355217998
103.00000000000074,17.12043299203821,-0.831870289275729,0.02339017348131689
104.00000000000075,17.2190620817182,-0.8234642727678392,0.023380062596614515
105.00000000000077,17.317648240138123,-0.8192534586589744,0.02355175952938149
106.00000000000078,17.41777527998074,-0.8139282178867853,0.024698301523951027
107.0000000000008,17.5154077900673,-0.807333470786953,0.02475193944266474
108.00000000000081,17.612291942959388,-0.8007229899655431,0.023389568528586313
109.00000000000082,17.711138782796645,-0.7952988882321779,0.023380194282048627
110.00000000000084,17.809115548024774,-0.7893812558683816,0.02302179743949706
111.00000000000085,17.907660156347454,-0.7853355617606289,0.023380969503109306
112.00000000000087,18.006484474457455,-0.7772251965542574,0.024677224319402224
113.00000000000088,18.104396227213847,-0.7712109651435701,0.023992608414842742
114.0000000000009,18.20125478062368,-0.7669445174259478,0.022102728161398577
115.00000000000091,18.300657731474175,-0.7617009265408331,0.023379912595496766
116.00000000000092,18.397133072663323,-0.7555698458098647,0.02349642403943797
117.00000000000094,18.494760007941853,-0.7515295316600492,0.0233871174249769
118.00000000000095,18.593654866299033,-0.7449719370702345,0.022287474428591025
119.00000000000097,18.688393498953754,-0.7390730879199527,0.023380123416933074
120.00000000000098,18.788408610051263,-0.7358475988499017,0.022901180750622085
121.000000000001,18.887260426570286,-0.7312934682032103,0.022398491680630794
122.00000000000101,18.983962102793253,-0.7267650128441187,0.023752203794285
123.00000000000102,19.080380259011175,-0.7224980368271702,0.02339050759517347
124.00000000000104,19.178907240515578,-0.7201537866355143,0.023380239416761484
125.00000000000105,19.2754855971587,-0.718334549495162,0.02469697406709548
126.00000000000107,19.372417538831066,-0.7144332426057717,0.02338997606432036
127.00000000000108,19.470274395433073,-0.7120517777778417,0.0237211898474472
128.00000000000108,19.56625535072186,-0.7086660269289333,0.025011760228266677
129.0000000000011,19.663302893515567,-0.7059806036335565,0.025029207499130735
130.00000000000114,19.75959745631709,-0.7009782644394511,0.02332174263057185
131.00000000000114,19.856724150956037,-0.6957619265169162,0.024704793290520666
132.00000000000114,19.95210600497051,-0.6924102402306951,0.02518654865219716
133.00000000000117,20.0502094202581,-0.6890617621401189,0.02469999581633875
134.0000000000012,20.145573305867224,-0.684854223196759,0.023390088247178475
135.0000000000012,20.240984406970995,-0.6816564951335154,0.024761723920958545
136.0000000000012,20.338247594508072,-0.6776869532048284,0.023390066939383836
137.00000000000122,20.43395872539354,-0.6735377966712872,0.02469982480058519
138.00000000000125,20.528113752484263,-0.6694592674224593,0.023250332644604743
139.00000000000125,20.626706945785365,-0.665970213215985,0.022702907503904246
140.00000000000125,20.723239258700403,-0.6620380554074773,0.024046279832925066
141.00000000000128,20.81865818606586,-0.6576082087873302,0.024040024303299656
142.0000000000013,20.91515122518195,-0.6555301644359156,0.02437443471070999
143.0000000000013,21.00912662371801,-0.6502573346243203,0.023610511280457658
144.0000000000013,21.104876769633343,-0.646474563336262,0.02343337715662308
145.00000000000134,21.201049855613682,-0.6430836476283227,0.024764169163060235
146.00000000000136,21.296817669510606,-0.6384241913189249,0.02469818115182898
147.00000000000136,21.393164381541997,-0.6341500089445438,0.024698660940640327
148.00000000000136,21.487798060674024,-0.6308390347512031,0.023382298864600415
149.0000000000014,21.58414959274419,-0.6264039578388717,0.02340517075827986
150.00000000000142,21.67854681256586,-0.6210128093067199,0.023380026475775306
151.00000000000142,21.775183598873827,-0.6182887248442182,0.023872233332787207
152.00000000000142,21.87027048791995,-0.6149424671259741,0.023389916496795227
153.00000000000145,21.967784806682147,-0.6088059197065672,0.022084831499851187
154.00000000000148,22.062404051179385,-0.605395492782336,0.02338025310337999
155.00000000000148,22.158533459737715,-0.6031020668320547,0.023379976010123205
156.00000000000148,22.254159314135926,-0.5990781162945388,0.023386329193445743
157.0000000000015,22.349082510023393,-0.5936880041753636,0.02305024665536992
158.00000000000153,22.445265258714706,-0.5904946936038578,0.021752960660379905
159.00000000000153,22.54072321073543,-0.5866005714380595,0.021731382190433024
160.00000000000153,22.63561150593896,-0.5825600691555866,0.022080276995105397
161.00000000000156,22.731113169948706,-0.5777443932237203,0.02207004619559161
162.0000000000016,22.825513861141303,-0.5751953047183958,0.02207017599914085
163.0000000000016,22.921939147679915,-0.571095596445859,0.023438759220948846
164.0000000000016,23.015866841771743,-0.5671479614791318,0.022069727947173767
165.00000000000162,23.113010127914006,-0.5645255610577454,0.022070070002456532
166.00000000000165,23.207587577063496,-0.5597900871927319,0.022073617018475655
167.00000000000165,23.30210494031762,-0.5568507302656526,0.01944132699662582
168.00000000000165,23.39805241024257,-0.5535213730317148,0.020742459281976267
169.00000000000168,23.494401208400365,-0.5485498022882775,0.022042977603854652
170.0000000000017,23.588424384582616,-0.5445049097922281,0.020740120146860885
171.0000000000017,23.68105822282286,-0.5410771082809336,0.020756663374839057
172.0000000000017,23.77901184466822,-0.5380408019471162,0.020844137650640082
173.00000000000173,23.87397353317479,-0.5337349970603165,0.020750010007180908
174.00000000000176,23.966603043411247,-0.5307718315398022,0.020086866635964817
175.00000000000176,24.06342761033954,-0.5271882232765396,0.020090019714393392
176.00000000000176,24.159380512489307,-0.5243913343689266,0.019513928785239276
177.0000000000018,24.2549119031109,-0.5213232978983904,0.020324719682228487
178.00000000000182,24.348717959688834,-0.5169373515937734,0.019100135226383763
179.00000000000182,24.44414023119334,-0.5129923916700282,0.0194323535612293
180.00000000000182,24.538824981687153,-0.5113867399797336,0.019429909059021533
181.00000000000185,24.634316597302092,-0.5082204056727716,0.018120942231468096
182.00000000000188,24.729015226038406,-0.504570613785462,0.01806490371897551
183.00000000000188,24.82354100369589,-0.5017684920342447,0.018119800966603705
184.00000000000188,24.918159576785023,-0.49891072413060056,0.018119804364142844
185.0000000000019,25.01206202296016,-0.4957903239683739,0.016796354604492247
186.00000000000193,25.108011271546864,-0.4933313486507776,0.0171245850213535
187.00000000000193,25.203520415934342,-0.4892263074535111,0.016830311924182162
188.00000000000193,25.298367693166966,-0.48613814522997034,0.01668220294108158
189.00000000000196,25.393105319351086,-0.4834059682198992,0.016684348373495528
190.000000000002,25.48918070357818,-0.47863997669206343,0.015479816365945975
191.000000000002,25.583445958858874,-0.4775423103459447,0.014153386778237298
192.000000000002,25.678552394093742,-0.47373604193461744,0.015477634241418237
193.00000000000202,25.773432491928187,-0.4705334236036924,0.015402645449003938
194.00000000000205,25.866593936274317,-0.4686257069863029,0.013509863780593268
195.00000000000205,25.96367320613346,-0.46591347006213696,0.012850274598368294
196.00000000000205,26.058883597615715,-0.46241752019307747,0.012190013778930364
197.00000000000207,26.153095977281588,-0.45942891279369796,0.01152296760914373
198.0000000000021,26.248748623202204,-0.45669184609944125,0.011529941280776335
199.0000000000021,26.343084417425356,-0.4546170542770078,0.01020920827829741
200.0000000000021,26.439211477484783,-0.45053058519746364,0.010212512336073676
201.00000000000213,26.533163009065895,-0.44656318679015544,0.008880816320339324
202.00000000000216,26.62819526814358,-0.44212816090937845,0.007392376721328642
203.00000000000216,26.722296702119166,-0.43860474665545907,0.006260021268861937
204.00000000000216,26.818091425179865,-0.43543460533330985,0.0062600200006759366
205.0000000000022,26.91409387579254,-0.4323592582455988,0.006260344581022537
206.00000000000222,27.008916364419857,-0.4288382553012756,0.004940013873620419
207.00000000000222,27.103709401339092,-0.4241461777579697,0.004934531767477601
208.00000000000222,27.197845142024047,-0.42109013357802605,0.0036200988200052464
209.00000000000225,27.292796948462506,-0.4175999608986514,0.00362036730231452
210.00000000000227,27.387753810127045,-0.4157793472534902,0.0022215487310353055
211.00000000000227,27.482518811974057,-0.41189793105927125,0.0009900245701928156
212.00000000000227,27.57803755629996,-0.40814698517224274,0.0010251088174242362
213.0000000000023,27.67291204448561,-0.4042062234314039,-0.00035942718253645367
214.00000000000233,27.76780636460996,-0.39925997209522435,-0.0029791553610074573
215.00000000000233,27.86158926097626,-0.3969682664089644,-0.002970115606172108
216.00000000000233,27.956908288491945,-0.3920176074304142,-0.004295886235536006
217.00000000000236,28.052637856378485,-0.38701574472764727,-0.00429098594373345
218.0000000000024,28.147227277227167,-0.3835874512090399,-0.005666869815446507
219.0000000000024,28.24284596418396,-0.37974481463057186,-0.006910828949693748
220.0000000000024,28.337346527657708,-0.37482751024037286,-0.008229896967344885
221.00000000000242,28.43293433959468,-0.37273159914066223,-0.009252117784743774
222.00000000000244,28.526906424741465,-0.36959962207538793,-0.010209128994884686
223.00000000000244,28.621799618505218,-0.3659949386193072,-0.01186001948394777
224.00000000000244,28.717435422575473,-0.3619981768051527,-0.011816094753486883
225.00000000000247,28.813434680533483,-0.35685932638825346,-0.013178334748716214
226.0000000000025,28.90704887604637,-0.3554434936735481,-0.016248662743181264
227.0000000000025,29.001211135139545,-0.349714573280173,-0.01756999409117732
228.0000000000025,29.09759138364027,-0.3456397826232356,-0.018816948703451075
229.00000000000253,29.191985421148416,-0.341375838707827,-0.018187429904612973
230.00000000000256,29.287101074301386,-0.33657466914374345,-0.021882179107531652
231.00000000000256,29.379638348715822,-0.33396973678849384,-0.02216667689892038
232.00000000000256,29.476671163030176,-0.3264799727769966,-0.023518210728068034
233.0000000000026,29.572353777407137,-0.3208192061152686,-0.027138389840931865
234.00000000000261,29.666582786791217,-0.3176425407907794,-0.02710416944064198
235.00000000000261,29.76199593095962,-0.31314621415820715,-0.029267806246313643
236.00000000000261,29.857003208713362,-0.30748905631077694,-0.0302245458373811
237.00000000000264,29.952213879106946,-0.3009802128845632,-0.03408370815168871
238.00000000000267,30.04671408865512,-0.29550940505626133,-0.035452713994241325
239.00000000000267,30.141245805461462,-0.2889928604201111,-0.03667012251405177
240.00000000000267,30.23657813806044,-0.283543406399926,-0.03933272624328099
241.0000000000027,30.331887343436232,-0.2774382726650265,-0.04198133923542979
242.00000000000273,30.42690250371444,-0.271511312904766,-0.04392516628584797
243.00000000000273,30.52250842833738,-0.2643561584796171,-0.04540956209489444
244.00000000000273,30.617109178657152,-0.2570872489818249,-0.04932197982959696
245.00000000000276,30.712444619850313,-0.25121083666114663,-0.051485398606872845
246.00000000000279,30.80778975042009,-0.24381093060150938,-0.054201050398413386
247.00000000000279,30.903105672990083,-0.23513298415378728,-0.056782421894945756
248.00000000000279,30.99833204070135,-0.22640250577548296,-0.06155833373609054
249.0000000000028,31.09354821756214,-0.2207469929791262,-0.06403138335777214
250.00000000000284,31.18862131323788,-0.2094579425912397,-0.06742680831558845
251.00000000000284,31.284058094920077,-0.20206447995197496,-0.07074716700402028
252.00000000000284,31.37971243414966,-0.1952944711096599,-0.07378422155084907
253.00000000000287,31.474791092935273,-0.18497511530120986,-0.0766190277951746
254.0000000000029,31.569712814107447,-0.17745703502658725,-0.0794796239513822
255.0000000000029,31.665207960693106,-0.16818053971476243,-0.0852462792816504
256.0000000000029,31.760347899985245,-0.1589091653022469,-0.09071765392274767
257.00000000000296,31.856076629269825,-0.14746024042581862,-0.09453351778783814
258.00000000000296,31.952021652030115,-0.1376498085707802,-0.10053346784527006
259.00000000000296,32.04748547930757,-0.1252430462266649,-0.10488612773415884
260.00000000000296,32.143481536188744,-0.11323860191189061,-0.10943216380878606
261.00000000000296,32.23711976361657,-0.10428364710399435,-0.11416858519371953
262.000000000003,32.3310696967831,-0.09361285193166939,-0.1204255911640808
263.000000000003,32.427527186495624,-0.07893420590849062,-0.12703214740888757
264.000000000003,32.52177533226713,-0.06687394772089432,-0.1331081713773825
265.00000000000307,32.619181895498194,-0.0531438175425567,-0.1387971998496127
266.00000000000307,32.71419631076983,-0.039657665829692344,-0.14554989030007626
267.00000000000307,32.81066149982856,-0.025941588355779227,-0.151906283738378
268.00000000000307,32.90565432031847,-0.009169407657799078,-0.15988393253193678
269.00000000000307,33.00129594164334,0.003978460128229493,-0.1678541235233415
270.0000000000031,33.09688014538376,0.021594023265240504,-0.17550707226209505
271.0000000000031,33.192688336504744,0.038452835224180325,-0.18374158565956078
272.0000000000031,33.286553293339736,0.05490357747956881,-0.19170055157965393
273.0000000000032,33.38351017660082,0.07199120118363014,-0.20184585474540784
274.0000000000032,33.47829016483061,0.08972046718948087,-0.21103332557681576
275.0000000000032,33.57464597466446,0.1062918392493699,-0.22095901910802063
276.0000000000032,33.67064400299613,0.12367219385989084,-0.23101550294751272
277.0000000000032,33.76663971344029,0.1442765697302841,-0.24062010491735153
278.00000000000324,33.86141177258703,0.16410006455543294,-0.2537376910130602
279.00000000000324,33.95732424062647,0.18225837874529702,-0.26426770997967663
280.00000000000324,34.05230092579292,0.20062974395910166,-0.27649913844768337
281.0000000000033,34.148567834902416,0.22228713978594833,-0.2883903194134785
282.0000000000033,34.24395656270164,0.2411584288359958,-0.30133334664570866
283.0000000000033,34.34083861470319,0.26051756784086,-0.31464014334247503
284.0000000000033,34.43640066327347,0.27938384076998896,-0.3281543125643229
285.0000000000033,34.530796779454974,0.29972660535127793,-0.3424875203375497
286.00000000000335,34.62830493279675,0.3174442310455257,-0.35704491736557875
287.00000000000335,34.72378504706889,0.33647201143591876,-0.37141293180942325
288.00000000000335,34.81950683380839,0.3524046703148967,-0.38556792466392453
289.0000000000034,34.91558610573859,0.37009793772247773,-0.40162695123044934
290.0000000000034,35.009086252981966,0.38406860629807327,-0.41802777364888666
291.0000000000034,35.10708057534556,0.3919055821422701,-0.4341784135019462
292.0000000000034,35.20227275063997,0.3974543699901515,-0.4493290019975982
293.0000000000034,35.29921719849946,0.4014665987841384,-0.4658663631684212
294.00000000000347,35.39430521536321,0.39827927609124814,-0.48153965783622477
295.00000000000347,35.489414329145134,0.3980006074841035,-0.49779329507030834
296.00000000000347,35.58464374562278,0.3968523019349618,-0.5157371141972895
297.0000000000035,35.679785544598666,0.39252077616476544,-0.534062222370022
298.0000000000035,35.77493456676075,0.3867685316027266,-0.550461471099426
299.0000000000035,35.872166771066254,0.37795406147174243,-0.5675614596869218
300.0000000000035,35.96898960781442,0.3669698795164661,-0.5842779957804303
301.0000000000035,36.06527446927843,0.3538493771639376,-0.6016291594724215
302.0000000000036,36.1611055772745,0.33797376330047224,-0.6187694518300013
303.0000000000036,36.256800801597024,0.31902559995553853,-0.6357443023751004
304.0000000000036,36.351839185785316,0.297620097296862,-0.6523152929826863
305.00000000000364,36.44831447319985,0.27561732772525965,-0.668880133032776
306.00000000000364,36.5443300144935,0.2534585675169833,-0.6854119202453348
307.00000000000364,36.640469034694604,0.22992002038252699,-0.6995791800632891
308.00000000000364,36.735908919206956,0.2070237494387763,-0.7166405267596287
309.00000000000364,36.83225595188658,0.18550009010257185,-0.7305131493386239
310.0000000000037,36.928310765174786,0.16434416967754698,-0.7453824540959775
311.0000000000037,37.02282581602365,0.1438256798884881,-0.7586574996893627
312.0000000000037,37.11916960578888,0.12475997677327155,-0.7743874347147486
313.00000000000375,37.21535462506162,0.1065706755183359,-0.7846341219865418
314.00000000000375,37.31046213227136,0.08766907297722715,-0.7978506941672308
315.00000000000375,37.40754676588852,0.07092350175250307,-0.8123597283795299
316.00000000000375,37.503020832377324,0.0547171057897971,-0.8237315960276979
317.00000000000375,37.59802956053029,0.0394931800442824,-0.8351004418417194
318.0000000000038,37.69456365960671,0.02376044418663335,-0.8478869718314512
319.0000000000038,37.79087515737864,0.013406534180153314,-0.8591736488190675
320.0000000000038,37.88617259348324,-0.0006682134325431757,-0.8707150945784892
321.00000000000387,37.98321956267544,-0.011686838299253365,-0.8835072196112073
322.00000000000387,38.07723086836411,-0.021665648312054163,-0.8945292185016971
323.00000000000387,38.173584871504794,-0.028917802456917056,-0.9079125465003863
324.00000000000387,38.271318112302666,-0.037833000839329715,-0.9162651725446991
325.00000000000387,38.368387891958626,-0.04494817766753209,-0.9277682758361419
326.0000000000039,38.46469814367938,-0.05188926617329596,-0.9409895266507946
327.0000000000039,38.5615198353595,-0.05738397461870162,-0.9527347543136768
328.0000000000039,38.65758135548885,-0.06235078024277052,-0.9634707395866284
329.000000000004,38.75443612464868,-0.06585823482811641,-0.9736209057260647
330.000000000004,38.8501983524722,-0.07092487215901287,-0.9866432216244014
331.000000000004,38.947909570477464,-0.07407220956726732,-0.9979889060273455
332.000000000004,39.04418286818626,-0.07762161671536486,-1.0097839024503839
333.000000000004,39.14078473024808,-0.08067209352274293,-1.0211147051119203
334.00000000000404,39.23693088246612,-0.08336683794365558,-1.0333363182591504
335.00000000000404,39.33303725578275,-0.08518893291850713,-1.045814755516608
336.00000000000404,39.42966364675453,-0.09104110537975993,-1.0579965463104108
337.0000000000041,39.52694529274973,-0.09332775786869603,-1.0711876939062597
338.0000000000041,39.624185577969435,-0.09452268435077008,-1.0839688088669255
339.0000000000041,39.72000000000042,-0.09822280000003121,-1.0956582278669464
340.0000000000041,39.81729585195175,-0.10040250551285854,-1.1099095977579467
341.0000000000041,39.91297207084143,-0.10516741328076669,-1.122682281583272
342.00000000000415,40.010874925113654,-0.1088557427525289,-1.1375433041941014
343.00000000000415,40.106689482670944,-0.11255136434058302,-1.151495420146626
344.00000000000415,40.203851289861504,-0.11879334706466134,-1.1656544097171437
345.0000000000042,40.30042465288803,-0.12177101407549339,-1.1789020446523475
346.0000000000042,40.39868592834309,-0.12636456824323908,-1.1947563831703811
347.0000000000042,40.49529304557471,-0.13294649799925112,-1.2091093770084123
348.0000000000042,40.59206626620811,-0.1403071776005763,-1.2231006331240093
349.0000000000042,40.689206275857615,-0.14657195481588714,-1.2375641634130918
350.00000000000426,40.78596634261008,-0.15291815861885572,-1.2535908940466873
351.00000000000426,40.881202358236926,-0.15684787085558272,-1.2695545310463587
352.00000000000426,40.979911780246894,-0.16273721336190475,-1.286427241609437
353.0000000000043,41.07755832570594,-0.17050932356254653,-1.3021612612116829
354.0000000000043,41.17340771193707,-0.1747758379940697,-1.3196462584278712
355.0000000000043,41.27049364891267,-0.17961600718582207,-1.3363880884951693
356.0000000000043,41.36862304136793,-0.18371678837113417,-1.3538776302724371
357.0000000000043,41.46559157029491,-0.1868072361592462,-1.3712002458824237
358.0000000000044,41.56182986241823,-0.19017856655312296,-1.3895904535253631
359.0000000000044,41.65915788070177,-0.19164419781526565,-1.4089488100101124
360.0000000000044,41.75579183927067,-0.19249159630459395,-1.4279819284159188
361.00000000000443,41.853000623875566,-0.19244981581902182,-1.449967261319899
362.00000000000443,41.949627927832765,-0.19310217871838034,-1.470134426355917
363.00000000000443,42.046625530364956,-0.19113700246369714,-1.4888441713838274
364.00000000000443,42.14391782204648,-0.1891843483444657,-1.509432010755492
365.00000000000443,42.240533989736065,-0.18647621389102279,-1.5340254333949042
366.0000000000045,42.33827256287917,-0.1814474649336671,-1.5546355139685422
367.0000000000045,42.43494057093454,-0.17666547268995092,-1.5792279429039273
368.0000000000045,42.53214536637879,-0.1720069932459048,-1.602284957427098
369.00000000000455,42.62915101206684,-0.1657742728067365,-1.6246606099996286
370.00000000000455,42.725885721500056,-0.1604505692480912,-1.6497418033314943
371.00000000000455,42.82266852104102,-0.15347606258527127,-1.674067585398697
372.00000000000455,42.9192537843875,-0.14846777585485404,-1.6994679153647216
373.00000000000455,43.017300906567904,-0.1407574144676289,-1.7263485380450825
374.0000000000046,43.1148266563071,-0.13283222300071323,-1.7548532160850976
375.0000000000046,43.21132461645055,-0.12656237145169552,-1.7812217853639014
376.0000000000046,43.30853887935812,-0.11837239993274522,-1.8109479070622574
377.00000000000466,43.406323159325915,-0.11031014587785412,-1.841450008458232
378.00000000000466,43.50276710934164,-0.10333834794850429,-1.8709935972882143
379.00000000000466,43.601012075029246,-0.09618289669954956,-1.9028631067842814
380.00000000000466,43.69783892057765,-0.08885414784371003,-1.933367692840552
381.00000000000466,43.79310403074136,-0.08167397593324961,-1.9669196661188297
382.0000000000047,43.89364373478573,-0.07493063418289495,-2.000487762790661
383.0000000000047,43.99069481265478,-0.06630512052292774,-2.0344779591709883
384.0000000000047,44.08726998638846,-0.05960896436881988,-2.069458407481495
385.0000000000048,44.184522619377184,-0.05440153867942394,-2.104634330030355
386.0000000000048,44.2831674803569,-0.04836157150795942,-2.142941394609698
387.0000000000048,44.380096157149424,-0.04421047313759409,-2.1799957980291973
388.0000000000048,44.477976006551664,-0.0406911048709591,-2.218084288753554
389.0000000000048,44.576058004105704,-0.03697719122152031,-2.2563904524903466
390.00000000000483,44.67282413129406,-0.035757919996539385,-2.295361446067299
391.00000000000483,44.76959852768523,-0.03580508598505358,-2.3336152517850843
392.00000000000483,44.8667807749811,-0.035880818830337294,-2.3721653259429294
393.0000000000049,44.96451123618817,-0.038446901792058015,-2.415499587658994
394.0000000000049,45.06283581112355,-0.04243410251014512,-2.4538335474128212
395.0000000000049,45.16000000000052,-0.04524800000000772,-2.495149942000224
396.0000000000049,45.25482766066772,-0.05196296916150299,-2.532525956498068
397.0000000000049,45.354590162897644,-0.05910027657687824,-2.57435255969709
398.00000000000495,45.45208826853798,-0.06609023194818998,-2.6142130417594567
399.00000000000495,45.54943118815626,-0.07589395601423708,-2.652404397515701
400.00000000000495,45.64673392443043,-0.08679326689813728,-2.6908335240012335
401.000000000005,45.744648686841664,-0.09527506100738795,-2.727552660934232
402.000000000005,45.84246060335084,-0.10757168639555702,-2.7656008555030054
403.000000000005,45.94073652499934,-0.12084850436669246,-2.8010620875599193
404.000000000005,46.037926334081625,-0.13297840695551688,-2.8370541455031733
405.000000000005,46.13523432822106,-0.1461747822070089,-2.870519069725794
406.00000000000506,46.232786964013535,-0.15991682595491574,-2.903134336376069
407.00000000000506,46.33000000000049,-0.17371000000005715,-2.9331800253649596
408.00000000000506,46.42819540520301,-0.18653927869578688,-2.962765488369528
409.0000000000051,46.52639521940219,-0.20068712938450595,-2.9934938153561244
410.0000000000051,46.623511354920225,-0.21485382765336922,-3.020103937980802
411.0000000000051,46.72072604626959,-0.22734767412361379,-3.046771117995745
412.0000000000051,46.81883539867938,-0.24347099400536681,-3.0697979552275854
413.0000000000051,46.91648496488924,-0.2557329569780947,-3.0950655605004656
414.0000000000052,47.01409694984835,-0.2672071169637042,-3.1170440913333826
415.0000000000052,47.11128524779455,-0.27933569733957675,-3.1384933089401965
416.0000000000052,47.21059414134345,-0.2909716558076349,-3.1589221460285057
417.00000000000523,47.306921350850295,-0.3031856715296607,-3.1757233705086314
418.00000000000523,47.40542853983016,-0.31134867583180387,-3.1938471752711015
419.00000000000523,47.50288468233468,-0.321665877981589,-3.210382360780673
420.00000000000523,47.60147647215478,-0.33114808505391463,-3.2254761159292635
421.00000000000523,47.698951922594624,-0.3419762560197239,-3.2385664971090486
422.0000000000053,47.79699332531045,-0.34713659766989585,-3.250868303791536
423.0000000000053,47.895957576529796,-0.3540085452356542,-3.2633967631026413
424.0000000000053,47.99381435374568,-0.36012598586424743,-3.273985389630701
425.00000000000534,48.090427611688824,-0.36531379987857066,-3.283848890972701
426.00000000000534,48.18912767409249,-0.3702849727026135,-3.2929595696745206
427.00000000000534,48.286793113488564,-0.3745437541475355,-3.301191208323427
428.00000000000534,48.384375532032614,-0.37811827553648725,-3.309990091212063
429.00000000000534,48.48288381837891,-0.38243948705521713,-3.314969994276842
430.0000000000054,48.579595359015975,-0.3846642189369843,-3.3220370594011324
431.0000000000054,48.67889780194395,-0.3868345295169578,-3.3277501000465
432.0000000000054,48.77724183533569,-0.3894948698161831,-3.334075827416991
433.00000000000546,48.875066953064476,-0.3925414466416737,-3.33842995880702
434.00000000000546,48.973532458264565,-0.39386484095683827,-3.3446511235279255
435.00000000000546,49.06978585872013,-0.39367757539169546,-3.3499275453422652
436.00000000000546,49.168380799683455,-0.3935224541771928,-3.3529105339685374
437.00000000000546,49.266121448557506,-0.3962878166289397,-3.35698794751837
438.0000000000055,49.3631006724908,-0.3966562696397071,-3.360023292806939
439.0000000000055,49.46168396241135,-0.39733802297353854,-3.362829181330855
440.0000000000055,49.559902262139516,-0.39608579830778995,-3.3682535445720756
441.00000000000557,49.65775259578093,-0.3964039345117371,-3.371078389684826
442.00000000000557,49.756130319852396,-0.39514447645238976,-3.3737489212604665
443.00000000000557,49.853855679057524,-0.3955692307882619,-3.376448041978934
444.00000000000557,49.95242874767297,-0.3931275880995927,-3.379507682297602
445.00000000000557,50.05019821430848,-0.39383889455859805,-3.379669971001483
446.0000000000056,50.14760885816167,-0.3913579238318435,-3.382685279505366
447.0000000000056,50.245264230065125,-0.3898894648495215,-3.3862597893075597
448.0000000000056,50.343623777194274,-0.3901429905912678,-3.388957441662601
449.0000000000057,50.4418804842379,-0.3873358654555965,-3.3916062884773917
450.0000000000057,50.54029855997148,-0.38549525397766743,-3.3915305766517294
451.0000000000057,50.63969685293273,-0.383434049352774,-3.3954776982374817
452.0000000000057,50.7365051740213,-0.38190276517463234,-3.3974060696232935
453.0000000000057,50.83667223886995,-0.380152094651289,-3.400860538852335
454.00000000000574,50.93424515590811,-0.3778386088578864,-3.4035994599860953
455.00000000000574,51.03274895799233,-0.3756225999778488,-3.404827261920351
456.00000000000574,51.13058161986037,-0.3744460005060654,-3.406085896346931
457.0000000000058,51.229251286492804,-0.37347867861443185,-3.4100603994798164
458.0000000000058,51.32699437785663,-0.3713528408216975,-3.412708535145686
459.0000000000058,51.4255986519982,-0.36846329595756555,-3.4141071009369175
460.0000000000058,51.522788862412995,-0.3658156210469321,-3.416779179604607
461.0000000000058,51.62209073412091,-0.36574457450846026,-3.42013751269981
462.00000000000585,51.72095077967142,-0.36347241531141,-3.4234598620998966
463.00000000000585,51.81853464976155,-0.3639585042509957,-3.427226041127056
464.00000000000585,51.9145179981427,-0.36147767606018694,-3.4300162349803403
465.0000000000059,52.015851617647215,-0.3604584361521716,-3.4326397466477876
466.0000000000059,52.112989633921565,-0.3585529717129538,-3.435314057150561
467.0000000000059,52.21223299796409,-0.35717504204505024,-3.438173241144722
468.0000000000059,52.31164459469108,-0.35512445887422694,-3.442306465702587
469.0000000000059,52.409809947193274,-0.35325286801084665,-3.444976794158189
470.00000000000597,52.507238506267214,-0.3518486539481387,-3.4465597683734113
471.00000000000597,52.60663921422752,-0.3510038000818271,-3.4508533618400485
472.00000000000597,52.704900222462854,-0.34914729813304385,-3.454241697258059
473.000000000006,52.80326179128359,-0.3498411762003186,-3.4567967772292008
474.000000000006,52.90259103761271,-0.34908526169403575,-3.460423927021143
475.000000000006,53.001318154077985,-0.3472375463787911,-3.4634562695944062
476.000000000006,53.09910140329901,-0.3484296253251165,-3.4678141505194233
477.000000000006,53.197920913188696,-0.3481457562429337,-3.4704688221081605
478.0000000000061,53.296707226550346,-0.3475139464238721,-3.473842849727073
479.0000000000061,53.394893462815524,-0.34811975406998263,-3.476979156041129
480.0000000000061,53.49402402783355,-0.34796680504949656,-3.479648831334361
481.00000000000614,53.59227952824133,-0.3487826272167445,-3.4826268314608333
482.00000000000614,53.69127826578495,-0.35016141956236274,-3.486796660536113
483.00000000000614,53.78877456870664,-0.35053539448608223,-3.4900267351675964
484.00000000000614,53.88790950053865,-0.35205520147183583,-3.4927540520003095
485.00000000000614,53.9872651595543,-0.35249522429964875,-3.4943324770383595
486.0000000000062,54.08566500901007,-0.35493778909511675,-3.4957120043381416
487.0000000000062,54.18373230575635,-0.3557605429413283,-3.499443565720382
488.0000000000062,54.28339318115727,-0.3567773419790077,-3.5015893805438427
489.00000000000625,54.38113154969247,-0.3566186062011761,-3.503289472534082
490.00000000000625,54.479571285857496,-0.3589398749682936,-3.505243091654737
491.00000000000625,54.57817329568691,-0.35942755191014986,-3.506573637141671
492.00000000000625,54.678704539090376,-0.36015790991803576,-3.5072406238711817
493.00000000000625,54.77627059462485,-0.359081260395832,-3.5085677456176505
494.0000000000063,54.87535906892243,-0.35956520416090176,-3.5098727293904095
495.0000000000063,54.97360506566008,-0.3593725879079562,-3.511190108556797
496.0000000000063,55.07290717662773,-0.3586462328821169,-3.5125546718535423
497.00000000000637,55.171305528449416,-0.3571081887016273,-3.5138189671809505
498.00000000000637,55.27176599820387,-0.3568396846196156,-3.513820159212467
499.00000000000637,55.370832411650696,-0.35511979726705745,-3.5151401186373183
500.00000000000637,55.46958544129373,-0.35483311534347917,-3.516460435491866
501.00000000000637,55.56832286400445,-0.3542348835487431,-3.515149437970709
502.0000000000064,55.66675346761905,-0.3516768403721725,-3.51718229400571
503.0000000000064,55.76548075102361,-0.3525570898437919,-3.517132273747201
504.0000000000064,55.86479788165329,-0.35141163355408633,-3.5184301842034826
505.0000000000065,55.9637154775013,-0.3502288123626732,-3.5198307753828777
506.0000000000065,56.062176576397945,-0.3496168733974345,-3.519098752839226
507.0000000000065,56.161981991830224,-0.3508618271034371,-3.5204257246854627
508.0000000000065,56.26130071507216,-0.34878660249190246,-3.5203102344426025
509.0000000000065,56.36053353665602,-0.3494406419269063,-3.5217945436075713
510.00000000000654,56.45909334976998,-0.3475471568392145,-3.521741561264672
511.00000000000654,56.55751455005732,-0.34619922583888146,-3.5229488689136006
512.0000000000066,56.65687170890467,-0.3453049537170459,-3.524403930356918
513.0000000000066,56.75560341278284,-0.345482933966807,-3.5243698160947745
514.0000000000066,56.855253793445534,-0.34521001202240137,-3.524370694176578
515.0000000000066,56.95451090779185,-0.344055894288248,-3.5256906237195698
516.0000000000066,57.05220082326637,-0.34235830052508515,-3.5276609384176387
517.0000000000066,57.152290567800016,-0.3425035208795186,-3.5276600100104534
518.0000000000066,57.25177858835295,-0.34069046652168516,-3.527665740060041
519.0000000000066,57.34990595475618,-0.3405460194032164,-3.527989654802706
520.0000000000066,57.45020712947139,-0.3388032027785123,-3.5293099467671336
521.0000000000067,57.550000000000665,-0.33659999999998497,-3.52930996000043
522.0000000000067,57.64875174309254,-0.3356189504838669,-3.5293270165641553
523.0000000000067,57.74779164490202,-0.33593273987926026,-3.5319405890813984
524.0000000000067,57.84530410656294,-0.3339430813449226,-3.5306310954245976
525.0000000000067,57.94470520047818,-0.33383877166324555,-3.531940378943076
526.0000000000068,58.043375508108326,-0.33364878311363916,-3.5322328714469204
527.0000000000068,58.14334661127541,-0.33285957882175793,-3.533259924637993
528.0000000000068,58.242261448295224,-0.33134855729302476,-3.534580526917609
529.0000000000068,58.34226495560486,-0.3318178620910667,-3.5335896083490157
530.0000000000068,58.44166548745807,-0.33096244773899675,-3.533590103965889
531.0000000000068,58.5407513714809,-0.32893867745350214,-3.53358272583008
532.0000000000068,58.6383742665019,-0.3268303062678237,-3.5349099967756223
533.0000000000068,58.73885740232227,-0.32686931676336495,-3.5362127225134365
534.0000000000068,58.83754019974952,-0.32532991811261397,-3.5355721179665016
535.0000000000068,58.93750039582076,-0.3261434106274751,-3.536882388108336
536.0000000000068,59.036990788619526,-0.3262718881609975,-3.5368820947300357
537.0000000000069,59.13612674681556,-0.32552077400541224,-3.5368799540463045
538.0000000000069,59.23506346109107,-0.32273652368741457,-3.536900631628562
539.0000000000069,59.33429477017989,-0.32251986558153795,-3.537433070506583
540.0000000000069,59.43378683487795,-0.3231440346471035,-3.5383109429204356
541.0000000000069,59.5337688686198,-0.3222913201551618,-3.539519243826276
542.000000000007,59.63271735017676,-0.32238116250093796,-3.5395170672673424
543.000000000007,59.73225945406248,-0.3216021049676487,-3.5395117679602484
544.000000000007,59.83133700517653,-0.3234443979654216,-3.539509806643447
545.000000000007,59.93094780622851,-0.3212489295757128,-3.5408306108899974
546.000000000007,60.03067489196224,-0.3197397582324462,-3.54215007566898
547.000000000007,60.128879699101695,-0.31964170710049483,-3.541473693907088
548.000000000007,60.22961106375106,-0.31872038586648255,-3.5421499111821086
549.000000000007,60.328465095164596,-0.3181561264873958,-3.542149997999301
550.000000000007,60.42793271566362,-0.31596665489621034,-3.5421499979954807
551.000000000007,60.52750286557749,-0.3163831830977818,-3.542147060886047
552.000000000007,60.62735221250716,-0.3163204889435726,-3.5434697761653573
553.0000000000072,60.727342263405845,-0.3117662110434418,-3.542065655789133
554.0000000000072,60.82578291689113,-0.3103104126728833,-3.544782070962339
555.0000000000072,60.925244261835026,-0.3088469314603364,-3.544593843411269
556.0000000000072,61.02424637035597,-0.3068815469814524,-3.54543984817815
557.0000000000072,61.12336029784897,-0.30493623902446215,-3.5454398479999982
558.0000000000073,61.220932003999245,-0.30404716084864297,-3.545439847754814
559.0000000000073,61.32213029802742,-0.30296555453143303,-3.5461449082381176
560.0000000000073,61.4223908687989,-0.30008442944949576,-3.545468729506697
561.0000000000073,61.520582252953545,-0.2982927704536128,-3.546103347151783
562.0000000000073,61.62042792809952,-0.2967381779353989,-3.5461100191902
563.0000000000073,61.720190309659195,-0.2937413479674658,-3.5474249590764404
564.0000000000073,61.819456978170685,-0.2928305581371157,-3.548740092184686
565.0000000000073,61.91840111174287,-0.2933375216095942,-3.547216446342021
566.0000000000073,62.01843131879998,-0.2907952366097004,-3.5471077355859775
567.0000000000073,62.1180771879728,-0.29072157132737575,-3.5480794430581843
568.0000000000074,62.21762204176171,-0.2891982465669119,-3.549399756235041
569.0000000000074,62.3163280987015,-0.28653274488539165,-3.5493998200120744
570.0000000000074,62.416609310142064,-0.28433111098249353,-3.549406938403524
571.0000000000074,62.51527234414038,-0.28238398750561355,-3.5496722195849113
572.0000000000074,62.614038296692094,-0.28223279024036974,-3.5507313702562673
573.0000000000074,62.713394852509516,-0.28090232280201727,-3.5493753571383406
574.0000000000074,62.81428626566433,-0.2810530000257661,-3.5513583187992923
575.0000000000075,62.913711191931235,-0.2803285640493689,-3.5522150402899264
576.0000000000075,63.01306201871318,-0.276664306459076,-3.5523599666994308
577.0000000000075,63.11224378225539,-0.2782136381079577,-3.551020202200028
578.0000000000075,63.21258368308357,-0.2774839436820189,-3.55173182629137
579.0000000000075,63.312230222010996,-0.2765302860246209,-3.5539905413674515
580.0000000000075,63.4118506975384,-0.27648857546632155,-3.5539861653380522
581.0000000000075,63.51148912854199,-0.27690725988664333,-3.554009866079354
582.0000000000075,63.61147006973054,-0.2764667944781614,-3.552687943629716
583.0000000000075,63.7102999633721,-0.27757459982847765,-3.5526898639949556
584.0000000000076,63.80927045101221,-0.2786040512960837,-3.5526898642322577
585.0000000000076,63.908952673231326,-0.2800638208684208,-3.554027798047933
586.0000000000076,64.00935744795434,-0.2811580372824966,-3.5540101580226624
587.0000000000076,64.10824671219524,-0.27958847934873,-3.5540112530039987
588.0000000000076,64.20859427644646,-0.28223146373778574,-3.555340032320869
589.0000000000076,64.30792207411606,-0.2817369213398183,-3.5539957704587652
590.0000000000076,64.40853419513753,-0.2827730616650179,-3.5559766645983237
591.0000000000077,64.50738181475874,-0.2815783228866342,-3.5559802435264936
592.0000000000077,64.60709371184072,-0.281271115146582,-3.555382935689101
593.0000000000077,64.7072461844122,-0.2822944537201226,-3.5566401023508427
594.0000000000077,64.80550247617107,-0.2832563703279492,-3.556640008000274
595.0000000000077,64.9067143100899,-0.2831822063507849,-3.5566400087005343
596.0000000000077,65.00267592967168,-0.28580274619098167,-3.557967098002065
597.0000000000077,65.10527930788334,-0.2853275157124167,-3.556670049929103
598.0000000000077,65.20504445804306,-0.2854598302965065,-3.557906646536575
599.0000000000077,65.3045218225863,-0.2864369815716153,-3.559266828726064
600.0000000000078,65.4038139691077,-0.28793796404389616,-3.5579599441257135
601.0000000000078,65.50360136499744,-0.2867292265201135,-3.557952774961949
602.0000000000078,65.60265506538244,-0.28976921040675646,-3.560593455763734
603.0000000000078,65.70330069748434,-0.2887918353680709,-3.558651102173305
604.0000000000078,65.80262334064011,-0.28943540637405474,-3.559975433397812
605.0000000000078,65.90283329689335,-0.28982455264838153,-3.561251470099139
606.0000000000078,66.00092536944823,-0.29105383875403523,-3.5599402341937787
607.000000000008,66.10104665723966,-0.29002889650099706,-3.5612601118948644
608.000000000008,66.20124458945511,-0.2919378368382478,-3.562625227140204
609.000000000008,66.3011266494452,-0.29166894614536504,-3.561910158456032
610.000000000008,66.40009177716938,-0.29083600448164765,-3.56191015151344
611.000000000008,66.50046422787995,-0.2911633796695582,-3.56157864923623
612.000000000008,66.59945624144986,-0.291463759966206,-3.562576250285092
613.000000000008,66.69883100614271,-0.290196218215439,-3.5625700520156016
614.000000000008,66.7988987678906,-0.2923484258915992,-3.5625666627272903
615.000000000008,66.89867626434355,-0.29161418590251337,-3.563889949583033
616.0000000000081,66.99814765279405,-0.2894845690832837,-3.563843282279563
617.0000000000081,67.09793080027252,-0.29004020385234164,-3.565212640116818
618.0000000000081,67.19775243910462,-0.2882657309598876,-3.5648700007292815
619.0000000000081,67.29705957395487,-0.28888987578957426,-3.5658384877219307
620.0000000000081,67.39709284113388,-0.2884793902007963,-3.5661979609518584
621.0000000000081,67.49664925770989,-0.2892052162074557,-3.566447196246741
622.0000000000081,67.59583539911607,-0.28656924521529303,-3.5665201959164308
623.0000000000082,67.69598254816185,-0.2848137216456132,-3.5665198715106587
624.0000000000082,67.79545889299085,-0.28463328475611294,-3.5678391479969536
625.0000000000082,67.89498966287262,-0.2844299993166269,-3.5668502181635575
626.0000000000082,67.99488819405947,-0.28388051838677986,-3.5667505534645705
627.0000000000082,68.09384081819081,-0.28103406923517776,-3.5678500987846244
628.0000000000082,68.1932117685154,-0.2783673676345787,-3.569176642296252
629.0000000000082,68.29269990604038,-0.2766428591737968,-3.5690675854675056
630.0000000000082,68.39297473794329,-0.27324535751214996,-3.5704601349685614
631.0000000000082,68.49244774411659,-0.27155240637173633,-3.5706926921557867
632.0000000000083,68.59216558887788,-0.26876703233966315,-3.5704798462618155
633.0000000000083,68.69140735540584,-0.2637228024946248,-3.570483763830968
634.0000000000083,68.79049983852104,-0.25908714432064306,-3.5717899152742216
635.0000000000083,68.89043874257574,-0.257144820167888,-3.573107153133311
636.0000000000083,68.99113598825943,-0.2511942457571053,-3.571790191951329
637.0000000000083,69.08864210335683,-0.2476236022185448,-3.57310692809593
638.0000000000083,69.19039598908418,-0.24157438214784396,-3.573110017075444
639.0000000000084,69.29099661092529,-0.2351086350211906,-3.575089792526194
640.0000000000084,69.39052599506006,-0.23068712496081129,-3.576399460593571
641.0000000000084,69.4901827797836,-0.22279601891735815,-3.5777197802498995
642.0000000000084,69.59036403752901,-0.2178367765452722,-3.5764014037084997
643.0000000000084,69.69019846947043,-0.210589900777101,-3.5777178098475506
644.0000000000084,69.78950736735504,-0.20539652891923066,-3.5790401353630354
645.0000000000084,69.89022058118888,-0.19964456136704242,-3.57904512596636
646.0000000000084,69.98979202351428,-0.19367431846975378,-3.5809956495106556