File: 01_Data/Nylon_Carpet_High_Pile/STA/N2/30K_min/Nylon_Carpet_High_Pile_STA_N2_30KData_220308_R1.csv
##Temp./Â°C,Time/min,DSC/(mW/mg),Mass loss/mg
49.0,10.367651306436825,-1.130709237440172,-0.0015737162804967397
50.20000000000002,10.674621273298477,-0.9391255168827195,-0.0012799665585108144
51.400000000000034,10.816959966340377,-0.8087084043430971,-0.003037465269710271
52.60000000000005,10.92517069475976,-0.7030847395799595,-0.0027242711880877124
53.80000000000007,11.01506280299391,-0.6152364124566782,-0.0019419664209077148
55.000000000000085,11.093913366641136,-0.5365573865694124,-0.0022155110704527026
56.2000000000001,11.165943628409146,-0.46538951917196025,-0.001894400121554174
57.40000000000012,11.233155855503764,-0.40125688002844,-0.0009097213165571993
58.600000000000136,11.29614208337914,-0.34138697510756544,-0.001303226671856006
59.80000000000015,11.355643302166417,-0.2861157076081324,-0.001110684227254577
61.00000000000017,11.412789418277374,-0.23294954553669014,-0.0025269315368388057
62.20000000000019,11.468119709044721,-0.18405404278049434,-0.002377992889605718
63.400000000000205,11.519958510158398,-0.1379653942533269,-0.0018806784604343818
64.60000000000022,11.572202878812519,-0.0950255663456896,-0.0028849617631028224
65.80000000000024,11.62304854537604,-0.05311959288365079,-0.003336182637260876
67.00000000000026,11.672311060506347,-0.013293877624366589,-0.0028381536364987525
68.20000000000027,11.720686071567243,0.024200595439857968,-0.001934685760548227
69.40000000000029,11.7684394932448,0.06264235783735274,-0.0013208161077336023
70.6000000000003,11.815670554055393,0.09885479468307444,-0.0021341620037982345
71.80000000000032,11.861791376693215,0.13168459279799322,-0.002257717251960667
73.00000000000034,11.906257186315749,0.16312903268563636,-0.0016065856064630957
74.20000000000036,11.952879638366849,0.1958053881322879,-0.0019891875776796297
75.40000000000038,11.997926512769954,0.22537165031397863,-0.001489935149184607
76.60000000000039,12.042366165435332,0.2538238189760057,-0.0019703950375014045
77.80000000000041,12.086251741110328,0.2809727843468281,-0.002476836620647571
79.00000000000043,12.130452007706685,0.3066678392725803,-0.002074718081917837
80.20000000000044,12.174144806145982,0.33190845764304994,-0.0032718363082175905
81.40000000000046,12.217429460334596,0.3581283467533819,-0.0032786401462643333
82.60000000000048,12.260493970843454,0.3814590771847584,-0.003703733248530572
83.8000000000005,12.303382229364106,0.4050412579953195,-0.0036537763699837633
85.00000000000051,12.345405644628082,0.4283240556008909,-0.003224120124890817
86.20000000000053,12.387191736623148,0.4495700522489808,-0.0037063384621491835
87.40000000000055,12.429577311821896,0.4726716147254066,-0.0037228606427586186
88.60000000000056,12.471392151826967,0.49406189238367043,-0.003754025953798479
89.80000000000058,12.513060509523253,0.5136067090840392,-0.003832634400370072
91.0000000000006,12.554089069340387,0.5346587181466368,-0.004093142065505706
92.20000000000061,12.595928990167362,0.5547860227901089,-0.004581896624797466
93.40000000000063,12.637118584369142,0.575201466424018,-0.005147001785480221
94.60000000000065,12.677807916830327,0.5944851286890221,-0.005135343333004361
95.80000000000067,12.718961690452968,0.6122577256881829,-0.0040697033564089935
97.00000000000068,12.759643945933162,0.6285953802648396,-0.005149892064256978
98.2000000000007,12.800792935065395,0.6479103610607002,-0.005142594905803044
99.40000000000072,12.841328312823498,0.6614906234245944,-0.005160067617860253
100.60000000000073,12.882002031487563,0.6754463357412949,-0.004669927100085403
101.80000000000075,12.922662908751464,0.6876841058543495,-0.005148730382464439
103.00000000000077,12.963015738673368,0.6999868645290478,-0.0037722896127636574
104.20000000000078,13.00357141183344,0.7107399747309194,-0.005151264860641547
105.4000000000008,13.044152139552118,0.7186687318537895,-0.00632954129927521
106.60000000000082,13.084616126031152,0.7294881568081405,-0.006469613809674701
107.80000000000084,13.125249967380345,0.7372479345342816,-0.007511158746440039
109.00000000000085,13.165272485466142,0.747343069118727,-0.006505007641059102
110.20000000000087,13.205648073804815,0.7561258959897602,-0.007748219367917475
111.40000000000089,13.244852174525441,0.763759753196762,-0.006470572307887945
112.6000000000009,13.286006847846188,0.7749292993033537,-0.006865423364280421
113.80000000000092,13.326380927017341,0.7822392920008205,-0.007774193945034202
115.00000000000094,13.366437299020259,0.7931496332866531,-0.007775729131079601
116.20000000000095,13.406055748895776,0.8023063482113895,-0.00969507105547196
117.40000000000097,13.446245208954682,0.8139997230791711,-0.00976012046480923
118.60000000000099,13.486206022847504,0.8228053047188983,-0.009760137442891281
119.800000000001,13.52623248937493,0.8342982101058688,-0.009761604249618916
121.00000000000102,13.566112414708524,0.8437615159765991,-0.00980069440861886
122.20000000000104,13.605802679188884,0.8553404533247857,-0.00976006461515544
123.40000000000106,13.645702404659842,0.8641269036079797,-0.009760050005099608
124.60000000000107,13.685370692492585,0.875179570607378,-0.009760048763438611
125.80000000000109,13.724867600910306,0.8859033116943773,-0.009756180682239712
127.00000000000111,13.764405675647712,0.8973258006608632,-0.00877695200521389
128.20000000000113,13.803758507866272,0.9106118215344816,-0.008783659683688327
129.40000000000114,13.843001663795274,0.9205422519730456,-0.010089704464219196
130.60000000000116,13.882411870817045,0.9345613379387148,-0.010089907756842376
131.80000000000118,13.921448980996312,0.944754678249493,-0.010089908057382413
133.0000000000012,13.960557216229605,0.956767494135787,-0.010090011529034548
134.2000000000012,13.999649787435938,0.969296443442948,-0.010032706330020957
135.40000000000123,14.038707475742907,0.9813805545345545,-0.011080447709774344
136.60000000000124,14.077404413304007,0.9925242168968071,-0.011080181090473928
137.80000000000126,14.116442966888226,1.006123977552432,-0.01108018096683061
139.00000000000128,14.155074705618478,1.0202882044959207,-0.011080130291938772
140.2000000000013,14.193861359999252,1.033689366872015,-0.011040160354863549
141.4000000000013,14.232571330060575,1.046322507145386,-0.011601182965796042
142.60000000000133,14.270451381592501,1.0606610028378487,-0.011739804585733982
143.80000000000135,14.309538237358227,1.0757162502359852,-0.011460468651093514
145.00000000000136,14.34787595914553,1.0896334760326662,-0.011080167826056364
146.20000000000138,14.386538272403882,1.1058427217805555,-0.011080093996217233
147.4000000000014,14.42469043942891,1.1211855290314392,-0.011080094750699487
148.60000000000142,14.463222559265944,1.1397059077856364,-0.011079467315925573
149.80000000000143,14.501308847701463,1.1571844764369863,-0.012401897863389966
151.00000000000145,14.539290002587295,1.1777148435445735,-0.012390100658223435
152.20000000000147,14.577643779625399,1.1975430698694403,-0.012390366668100228
153.40000000000148,14.615699168399138,1.2240774854350855,-0.013644618395563857
154.6000000000015,14.6534568913957,1.249761947551905,-0.013710031226798147
155.80000000000152,14.691861360638963,1.2778775968300173,-0.013710093993599681
157.00000000000153,14.729605414439362,1.3033017183106494,-0.013710094000010109
158.20000000000155,14.767465251519525,1.3344980941783704,-0.013710094009272922
159.40000000000157,14.805848743061578,1.3649502600830528,-0.013710107749727474
160.6000000000016,14.843204610182745,1.3948915997661961,-0.013702708793702723
161.8000000000016,14.881307587228548,1.4214939713321468,-0.014699237052828718
163.00000000000162,14.919045897350424,1.4432704646995982,-0.01470009357860258
164.20000000000164,14.956804240035737,1.4575263860749308,-0.014700094000033026
165.40000000000165,14.994560587583353,1.4584166050100906,-0.014700094000001052
166.60000000000167,15.032326957883607,1.4503741051586982,-0.01470009399999972
167.8000000000017,15.070128301660793,1.4390659115649103,-0.014700093999998831
169.0000000000017,15.107965298531079,1.4260011129132084,-0.01470009399999972
170.20000000000172,15.14528546787658,1.413973235363088,-0.014700094000000608
171.40000000000174,15.18312767138749,1.404669613774423,-0.014700094000000608
172.60000000000176,15.220275663703639,1.4005196842334577,-0.01470009400000416
173.80000000000177,15.258071413651829,1.4009300294559928,-0.014700094001992792
175.0000000000018,15.295472786679886,1.4027766325067177,-0.01470008057253569
176.2000000000018,15.332809910240139,1.4042235126532583,-0.01468049025737539
177.40000000000182,15.36994358845563,1.408733518514602,-0.015019958835199798
178.60000000000184,15.407355233637933,1.4171443151440377,-0.015020093766605402
179.80000000000186,15.444658395999145,1.4240188668331089,-0.01502009399997739
181.00000000000188,15.481756170058931,1.4315131598765958,-0.01502009400000004
182.2000000000019,15.518994338883669,1.4413094138212137,-0.015020093999999595
183.4000000000019,15.555974434039113,1.4507630030582959,-0.01502009400000004
184.60000000000193,15.593134012006782,1.4630623524060526,-0.015020094000000483
185.80000000000194,15.630196786304976,1.474120422956518,-0.01502009399987747
187.00000000000196,15.667082435295642,1.4839086321965913,-0.015020092558755582
188.20000000000198,15.703871985110775,1.498962731729431,-0.01501968472873294
189.400000000002,15.74080145335312,1.510107981962886,-0.016380886007922868
190.600000000002,15.777758078797106,1.5238508581011436,-0.017510823809999465
191.80000000000203,15.814886054629529,1.536094154076515,-0.017660123410101924
193.00000000000205,15.851566900518971,1.549984072912576,-0.01766018104999789
194.20000000000206,15.888260781621067,1.5651209653539366,-0.017660179157713785
195.40000000000208,15.925019190648722,1.5798175846421945,-0.017657960199912726
196.6000000000021,15.961710853053466,1.5963316132470589,-0.016330781032118935
197.80000000000211,15.998507849097953,1.6112965121912082,-0.016338263893179494
199.00000000000213,16.035328687365347,1.6297344702308185,-0.01767731510032622
200.20000000000215,16.071949532698188,1.6457334937238866,-0.01766019950178155
201.40000000000217,16.108746445843952,1.6664037092863373,-0.017660180990354046
202.60000000000218,16.14551483794086,1.6849368795434558,-0.017660181018160692
203.8000000000022,16.181969860641274,1.705758297286258,-0.01766022145249524
205.00000000000222,16.21891853481781,1.7316904873798857,-0.017628884306906567
206.20000000000223,16.255354257815615,1.7545520925193827,-0.018968993777450205
207.40000000000225,16.291932307719545,1.7855743240296602,-0.01897005059478607
208.60000000000227,16.328621597403707,1.8207470669312915,-0.018970050000511218
209.80000000000229,16.365222480122632,1.8618138929777022,-0.018970050000000516
211.0000000000023,16.402093000497775,1.917692062291305,-0.018970050000001404
212.20000000000232,16.438235532700634,1.9880036880580827,-0.01897004999980867
213.40000000000234,16.47514253089431,2.0923506498740823,-0.018970049705128833
214.60000000000235,16.51186049914371,2.225807307617296,-0.018970400046132152
215.80000000000237,16.548231315407655,2.3837387342898757,-0.02008484671231736
217.0000000000024,16.585109927379445,2.5707482494053275,-0.02029017276843037
218.2000000000024,16.621736514431934,2.764049553109099,-0.0202901358149159
219.40000000000242,16.657420465224142,2.9436020700323398,-0.020288577609870462
220.60000000000244,16.695223999763684,3.08963895386351,-0.021650328155758736
221.80000000000246,16.732027644573417,3.1477989049004917,-0.021610421098103405
223.00000000000247,16.768919973897088,3.0834625889625946,-0.022768635581333907
224.2000000000025,16.805410794360693,2.9111605540523575,-0.021904155168642525
225.4000000000025,16.842393040722285,2.712532448389618,-0.021051647014115105
226.60000000000252,16.878622836915696,2.5430971122866315,-0.020290195457946414
227.80000000000254,16.915382699834254,2.4021382323084284,-0.0208112387946211
229.00000000000256,16.95134096547877,2.294078690948763,-0.0216096265702439
230.20000000000258,16.987742927942765,2.2049698149572863,-0.02160983091491886
231.4000000000026,17.023960535589413,2.1381569475953235,-0.02160983099324376
232.6000000000026,17.060354747118385,2.0856606908245237,-0.021609828659524766
233.80000000000263,17.09629880453164,2.045943890993357,-0.02162111212594997
235.00000000000264,17.132791476306082,2.0177151268566282,-0.024282229681765966
236.20000000000266,17.1688987643123,1.9919808549432056,-0.024240047009957966
237.40000000000268,17.20472859372872,1.9767498253270832,-0.02423976989305432
238.6000000000027,17.24109772889669,1.9652506801471237,-0.02311559352695225
239.8000000000027,17.276624616801058,1.9580060196844802,-0.023030141228929324
241.00000000000273,17.31355286090129,1.9522633468603698,-0.02424007648117099
242.20000000000275,17.34957969775342,1.949247845456092,-0.024240180774735887
243.40000000000276,17.385730215978825,1.949401539439494,-0.02424007590327326
244.60000000000278,17.422301654377282,1.9496190581106438,-0.024496757754883358
245.8000000000028,17.4581300652799,1.9498105680537463,-0.024900347281037405
247.0000000000028,17.493780212663104,1.9516135313454979,-0.02490730371419758
248.20000000000283,17.530533624304688,1.9548487215600217,-0.026875466160221073
249.40000000000285,17.566790595287145,1.9584103266488646,-0.02687988072667391
250.60000000000286,17.603033882812277,1.9629866535295417,-0.026879873777642338
251.80000000000288,17.638908106191487,1.9670745947155752,-0.026880933036713017
253.0000000000029,17.6751936863035,1.9725748424301626,-0.0258828104725759
254.20000000000292,17.711047753052302,1.9773432564409417,-0.02590510930139045
255.40000000000293,17.747365438701497,1.9814092718610383,-0.02720184233720868
256.600000000003,17.783493956230725,1.9862603562041943,-0.02720013136114785
257.80000000000297,17.819817807603055,1.9927090294075864,-0.02720013600031157
259.00000000000296,17.8555630942049,1.9968286884569477,-0.027200135998298958
260.200000000003,17.891691978232046,2.001163232236955,-0.027200137590264628
261.40000000000305,17.927771439158622,2.006599582035685,-0.02720164926266344
262.60000000000304,17.963986644213303,2.0100042382447096,-0.028531210194730594
263.800000000003,18.000383893191824,2.0156950330242682,-0.028795624679217813
265.00000000000307,18.036534467085843,2.0211133385571856,-0.029822586064883083
266.2000000000031,18.07243121562151,2.024762513366693,-0.03049000771303456
267.4000000000031,18.108354081069187,2.0308192387426787,-0.030490092085694087
268.6000000000031,18.144553100805844,2.0359967434539428,-0.0304898178589581
269.80000000000314,18.18077661537463,2.0399252843372166,-0.031246937639676897
271.0000000000032,18.216722043409597,2.044847178488879,-0.030473766575011663
272.2000000000032,18.25283554860456,2.050888527515263,-0.030490182229004237
273.40000000000316,18.288995175675048,2.053673758641583,-0.03049001739003243
274.6000000000032,18.325356831353183,2.0588595396858556,-0.03095815528761303
275.80000000000325,18.3613385310297,2.063181012541619,-0.03313128357472639
277.00000000000324,18.397456418216294,2.0678155757702794,-0.033129871297396196
278.20000000000323,18.433636925766944,2.0715277541392774,-0.033129873008451494
279.4000000000033,18.469678947245963,2.076164018585241,-0.033129801214498045
280.6000000000033,18.505954037899176,2.0804749226837638,-0.033398901759465804
281.8000000000033,18.54193016245043,2.0846323002211267,-0.03443975062230464
283.0000000000033,18.578019066567492,2.088599149141772,-0.034440135172468356
284.20000000000334,18.614517284436097,2.093913504843061,-0.03444004170279458
285.4000000000034,18.65049823663217,2.097367560031233,-0.03475589222766162
286.6000000000034,18.686977766911152,2.1017346562142105,-0.03575986464115699
287.80000000000337,18.72327604664725,2.1060256225813494,-0.0358228762213626
289.0000000000034,18.75889154747739,2.1093070500943134,-0.035099873874751
290.20000000000346,18.795182753843445,2.112938745390633,-0.03522063638441475
291.40000000000344,18.831362468808557,2.1161556433021738,-0.03641932062930442
292.60000000000343,18.867727296030314,2.1210193143754106,-0.036415344386595994
293.8000000000035,18.903842458295358,2.122935064434927,-0.03772636916461458
295.0000000000035,18.939880212966315,2.1253911856129983,-0.037730221121585306
296.2000000000035,18.97601661001678,2.13140571684187,-0.0389087827287371
297.4000000000035,19.012207338070247,2.1349061726515526,-0.03905229347305772
298.60000000000355,19.048423478123762,2.136465209844018,-0.040426893781456474
299.8000000000036,19.08471133212641,2.1382367671040625,-0.041680942266648646
301.0000000000036,19.121061565227368,2.140546394067415,-0.04166692335918887
302.20000000000357,19.157237797459445,2.1426725684837273,-0.043003120767034275
303.4000000000036,19.193565403080758,2.1462216905446563,-0.043004464318944
304.60000000000366,19.22954800045344,2.1489775002750315,-0.04302466552508255
305.80000000000365,19.2659052220182,2.15345363321263,-0.04332996178676263
307.00000000000364,19.3020857097334,2.1545832730452688,-0.04332976281429257
308.2000000000037,19.338246069651372,2.157066508575337,-0.043764402617501474
309.40000000000373,19.374250398752075,2.159583943263582,-0.04553984224862262
310.6000000000037,19.41066829222672,2.1628025772368025,-0.045634951606303265
311.8000000000037,19.446552923376505,2.1646666714654486,-0.046950471015721806
313.00000000000375,19.48289217223907,2.1699379664237597,-0.046949879152777374
314.2000000000038,19.51934922727595,2.169780168390099,-0.04694986156415748
315.4000000000038,19.555658877690554,2.1725548154689127,-0.046911609041645264
316.6000000000038,19.592032959885593,2.1752929006082096,-0.04827212509134249
317.8000000000038,19.62850631289443,2.177609827882512,-0.04963217783745577
319.00000000000387,19.6646425749599,2.183220108245206,-0.049575778990081254
320.20000000000385,19.7012272583414,2.188348797836284,-0.05088946761170288
321.40000000000384,19.737570748697564,2.1933084414448993,-0.05126793940973151
322.6000000000039,19.7741858479952,2.1965447399109124,-0.05221002355622151
323.80000000000393,19.810542505461033,2.203793713854408,-0.05344800048562215
325.0000000000039,19.846700871786204,2.2099894619223783,-0.053529495660119775
326.2000000000039,19.88307335935546,2.2156687893369704,-0.05496424525362187
327.40000000000396,19.919718882355866,2.2226472443063043,-0.05605009693628782
328.600000000004,19.955970518574034,2.2323498241276853,-0.0576249936926323
329.800000000004,19.992464593985524,2.241023230687072,-0.05913049445376206
331.000000000004,20.028924265841816,2.250044660227092,-0.06082240871228439
332.200000000004,20.065595728912175,2.258961992305972,-0.0625478133214421
333.40000000000407,20.101999679249015,2.2699473002884747,-0.06378517419514029
334.60000000000406,20.138425809731164,2.279150123562441,-0.06525797651452336
335.80000000000405,20.174902123259056,2.2924199453396077,-0.06783379316027638
337.0000000000041,20.211617918635675,2.302957415087005,-0.06957300231652219
338.20000000000414,20.248476667975112,2.3140844783300487,-0.07152470266079591
339.4000000000041,20.285068426505713,2.3245888031834068,-0.07446114971329054
340.6000000000041,20.321706306744527,2.3381054618537225,-0.07635145030562862
341.80000000000416,20.358171141167087,2.3513524929049545,-0.080018924495592
343.0000000000042,20.394775442974193,2.3644245647575377,-0.08473328606678043
344.2000000000042,20.43151237237504,2.377512549831099,-0.08776112763684951
345.4000000000042,20.468132973825895,2.3910486403507742,-0.09094292010553895
346.60000000000423,20.50497648951122,2.4081495531103005,-0.09433250493022705
347.8000000000043,20.54180621271362,2.422506931176842,-0.09698607626949984
349.00000000000426,20.5786794773893,2.438528631199589,-0.10045743542456664
350.20000000000425,20.615427723131184,2.4561758224125128,-0.10472137971166573
351.4000000000043,20.65215655525165,2.472111224954207,-0.10842556365629497
352.60000000000434,20.689320911651123,2.489738064130035,-0.1123686113386344
353.80000000000433,20.7257668816422,2.5086923595274264,-0.11695136181176524
355.0000000000043,20.762656015151578,2.5267771607060174,-0.12243462589708942
356.20000000000437,20.799268554241596,2.549282136586526,-0.12707302583247415
357.4000000000044,20.83615643442202,2.5686299340944356,-0.13224335201551218
358.6000000000044,20.8734255399018,2.5915881707184503,-0.13732987489680282
359.8000000000044,20.91025189727635,2.612893354862121,-0.14297394035885258
361.00000000000443,20.946950671417838,2.634211601988956,-0.1491211953546574
362.2000000000045,20.98404008698995,2.65879746556985,-0.15565348869798568
363.40000000000447,21.020609827688233,2.685631807268063,-0.16197518152302282
364.60000000000446,21.05753797691938,2.7113244449045113,-0.16907669064811204
365.8000000000045,21.094517641597328,2.738486085973055,-0.17640402717097547
367.00000000000455,21.131371888745022,2.766322529810889,-0.18443015580105104
368.20000000000454,21.16859880516052,2.7936657731767274,-0.19307978702480977
369.4000000000045,21.20583899338243,2.8235559092551954,-0.20094107698877695
370.60000000000457,21.24261822996908,2.8514437544063074,-0.21044846232183678
371.8000000000046,21.279687840013995,2.881886812741609,-0.22027556448954755
373.0000000000046,21.316745206733664,2.910046843151507,-0.22986591185372074
374.2000000000046,21.35351461265454,2.9418019900167263,-0.2402603356535189
375.40000000000464,21.390904729408685,2.973040796002121,-0.25143951450660484
376.6000000000047,21.427918691591504,3.0044906024519364,-0.262828994927395
377.8000000000047,21.46497488734652,3.0362099707083825,-0.2739113021758892
379.00000000000466,21.502013555067947,3.069719557133922,-0.284921333583839
380.2000000000047,21.53929162200542,3.1020636375730293,-0.29712686017606593
381.40000000000475,21.576069728874305,3.13459615286359,-0.3102084425142726
382.60000000000474,21.61339539017843,3.1711267676870554,-0.32370464269091936
383.80000000000473,21.65075337034412,3.203130676530188,-0.3373375947807009
385.0000000000048,21.688037775251885,3.240101162981481,-0.3507650154684203
386.2000000000048,21.72524104509442,3.2767949712307094,-0.36622059296777376
387.4000000000048,21.761792512157776,3.314015125473846,-0.38132147171051356
388.6000000000048,21.79967500556636,3.3546154286153023,-0.3975810560429598
389.80000000000484,21.83689983657808,3.3940338666239125,-0.4136784011217385
391.0000000000049,21.873979037360368,3.437193420085038,-0.4310402897438479
392.2000000000049,21.911387036011984,3.4797091076194313,-0.4484852949927438
393.40000000000487,21.94894945557581,3.523471618298036,-0.4670324486525108
394.6000000000049,21.986230437368878,3.5697695141604044,-0.4852467066109716
395.80000000000496,22.023472263877146,3.615958041172996,-0.5043991820070342
397.00000000000495,22.06055467618394,3.665967661478161,-0.5253823467838288
398.20000000000493,22.098065458294453,3.716914039977585,-0.5470082490242301
399.400000000005,22.13536657445564,3.7671298348435736,-0.5690292659422864
400.600000000005,22.17286821034738,3.822820822678698,-0.5915687702649377
401.800000000005,22.21027252742469,3.8752087229629244,-0.6156876330261114
403.000000000005,22.247768547252704,3.9306292178784257,-0.6400060124590241
404.20000000000505,22.28535216376205,3.986545852736283,-0.666604569176477
405.4000000000051,22.322996973137517,4.043222183741804,-0.6942742917042657
406.6000000000051,22.360436369364642,4.09739904007993,-0.7228401823871207
407.80000000000507,22.39802119884031,4.152233268540598,-0.7524759962357099
409.0000000000051,22.435549296350338,4.207725408556506,-0.7825919965619237
410.20000000000516,22.47296058491324,4.259017631713562,-0.8136725861617751
411.40000000000515,22.510718995830196,4.311181241589918,-0.8463955184931113
412.60000000000514,22.5479200623137,4.359969106570027,-0.88014107226142
413.8000000000052,22.58562122470692,4.4058277294105554,-0.9159591508339049
415.00000000000523,22.623398247659996,4.448235426230156,-0.9526394829402247
416.2000000000052,22.660992064162365,4.485121299823824,-0.9902593683400389
417.4000000000052,22.69869358817166,4.520283526359368,-1.0287455996155948
418.60000000000525,22.736207216224347,4.547032810285359,-1.068782220690291
419.8000000000053,22.774004303573125,4.568221494341442,-1.1100851858687881
421.0000000000053,22.81166381976119,4.581828690484095,-1.1514556329748498
422.2000000000053,22.849187149835075,4.585775431007871,-1.1932431740760325
423.4000000000053,22.886823655537786,4.5833135590476966,-1.2364500841732196
424.60000000000537,22.924211718835046,4.568905193226567,-1.2808711079568451
425.80000000000535,22.96220107072669,4.5429692214188,-1.3259544047947989
427.00000000000534,22.999812968991378,4.502619661118886,-1.3699684274997685
428.2000000000054,23.037513739414813,4.44984504889165,-1.4148567255234061
429.40000000000543,23.074963114916855,4.382593435181369,-1.4572103069436984
430.6000000000054,23.11275039776905,4.301818239484695,-1.5015753444658988
431.8000000000054,23.15022762606599,4.201801504900081,-1.5457959717975478
433.00000000000546,23.187719738213314,4.084198512112638,-1.5870419509267282
434.2000000000055,23.225617417977716,3.9476676664659607,-1.6268502085819923
435.4000000000055,23.263132370525106,3.798889841660949,-1.6651521942298668
436.6000000000055,23.300384829198695,3.635236552356929,-1.7009265914258966
437.8000000000055,23.33813906747583,3.460784757597172,-1.7345744544065682
439.00000000000557,23.375789935912962,3.2836248622602775,-1.7659829893425565
440.20000000000556,23.412786061164663,3.11013622058461,-1.7934190207169172
441.40000000000555,23.450277414352488,2.9387875508590247,-1.8190733100558862
442.6000000000056,23.488038999248765,2.778535205709033,-1.8413757927535377
443.80000000000564,23.52537066681771,2.635851386388386,-1.8605314158142163
445.0000000000056,23.562937904020476,2.5122664964928574,-1.8785530664355785
446.2000000000056,23.60040602448063,2.40908054991779,-1.893775998664526
447.40000000000566,23.637948975074373,2.3190104555474838,-1.9074864545799168
448.6000000000057,23.675386915981207,2.245117972306382,-1.9201314697715235
449.8000000000057,23.713045165599457,2.1860439406646477,-1.9330212669105646
451.0000000000057,23.750538457462635,2.1373969131102895,-1.943378028198307
452.20000000000573,23.787934082944496,2.096712690297679,-1.9531633499354386
453.4000000000058,23.825681719050188,2.0635099756850526,-1.9635315658520878
454.60000000000576,23.863599129858166,2.0371572873962553,-1.9737159002273954
455.80000000000575,23.901252197271024,2.0167343955550097,-1.9821074965180852
457.0000000000058,23.939220640426704,1.9990858668975418,-1.991811095011241
458.20000000000584,23.976565905660337,1.9861039314172488,-2.000285528411797
459.40000000000583,24.014585168789058,1.9760321546034603,-2.00873916049209
460.6000000000058,24.05236065344413,1.9654063706126172,-2.0173479757785744
461.80000000000587,24.09005568298792,1.9591494882810472,-2.025748147139282
463.0000000000059,24.127938357954076,1.9547243169134456,-2.033370947369577
464.2000000000059,24.166191251441745,1.9510875712407947,-2.0429913749217983
465.4000000000059,24.203608348163346,1.9465199032818379,-2.0516643042882645
466.60000000000593,24.24132706682182,1.9459088994576266,-2.059803880003501
467.800000000006,24.27917491605084,1.9430911451431359,-2.0683862668201467
469.00000000000597,24.317435239100647,1.941106833052091,-2.077702135221666
470.20000000000596,24.355333792658502,1.9403515722247404,-2.085641225091629
471.400000000006,24.39310326721865,1.9382091850410632,-2.0947672646168143
472.60000000000605,24.431386608680754,1.9417797946936919,-2.1027518693231864
473.80000000000604,24.469429693335844,1.9396007492205147,-2.11202432896847
475.000000000006,24.50767403829888,1.9391424000166884,-2.1195132584255694
476.20000000000607,24.545503993413956,1.9397552900414008,-2.127434933170947
477.4000000000061,24.583724912608936,1.9391674145394358,-2.1358194130009878
478.6000000000061,24.621633089269615,1.9404790776430345,-2.145351596865915
479.8000000000061,24.66000030278563,1.9380100325951595,-2.1545692219438197
481.00000000000614,24.69839551682077,1.9382449913182624,-2.161476412836719
482.2000000000062,24.736180709486174,1.9388405087377887,-2.171047591214413
483.4000000000062,24.77457619473794,1.9386973151497868,-2.1807557760688874
484.60000000000616,24.81305221933009,1.9369344100586081,-2.1899231914348354
485.8000000000062,24.850901497718535,1.9336183062988503,-2.1983504366965447
487.00000000000625,24.889515712096202,1.9321834031785574,-2.207459917840452
488.20000000000624,24.927650057560626,1.9291304700450316,-2.2168531415907538
489.40000000000623,24.965676762549776,1.9281525738420466,-2.225923515144486
490.6000000000063,25.00384515466308,1.9206453935068768,-2.235802390968895
491.8000000000063,25.042209639964884,1.9159932633664118,-2.245769275667291
493.0000000000063,25.08081842515018,1.9082611404416685,-2.2550654738883895
494.2000000000063,25.118565917176145,1.8987245640581487,-2.2653065194413737
495.40000000000634,25.157197721002962,1.8871381660399302,-2.2747248869605317
496.6000000000064,25.195260224598332,1.8739341152278426,-2.283120297907604
497.8000000000064,25.233580744467556,1.8504525783663468,-2.2910457913369147
499.00000000000637,25.272212681737088,1.8267633580508913,-2.2997550125929993
500.2000000000064,25.310560988352734,1.8010648211765616,-2.307507080726542
501.40000000000646,25.349030719094078,1.7664997774236242,-2.3157352320180795
502.60000000000645,25.38725926257338,1.7305930245304868,-2.3218968548349688
503.80000000000643,25.425527392764863,1.6959972810824135,-2.3276541321785693
505.0000000000065,25.46403700122602,1.65458761188739,-2.333346827672808
506.2000000000065,25.502484028319525,1.6200310298903384,-2.3369243591682913
507.4000000000065,25.54106384872856,1.5874438344921147,-2.3404365835799332
508.6000000000065,25.57956538643409,1.5581215541598725,-2.3442003519447008
509.80000000000655,25.617745591317846,1.5314801568697998,-2.3453742191058495
511.0000000000066,25.656593961408067,1.5088401359464059,-2.34576818189136
512.2000000000066,25.69496837383459,1.4908126551503913,-2.3470508146185063
513.4000000000066,25.73380019575539,1.4732319203676516,-2.348270053068351
514.6000000000066,25.77206850930566,1.4642641866134603,-2.3495515936984512
515.8000000000067,25.810646794169298,1.4571131428937498,-2.349599175321231
517.0000000000066,25.84922932904987,1.451996403050919,-2.35024382176755
518.2000000000066,25.888019204153053,1.4462424215767822,-2.350901559599847
519.4000000000067,25.92620993862879,1.4414536557822961,-2.350888047168727
520.6000000000067,25.96515325339962,1.441009691311454,-2.3532032809599848
521.8000000000068,26.003632429106943,1.4382919464033577,-2.353210161456124
523.0000000000067,26.042148280583323,1.4358850744554192,-2.3532101660243034
524.2000000000068,26.081086025227922,1.434952457371225,-2.3532101621340606
525.4000000000068,26.119744865396324,1.436487958761988,-2.3529300124840713
526.6000000000067,26.15800139927143,1.4382907046080076,-2.3528802315078354
527.8000000000068,26.196890682302787,1.4395116598435072,-2.353001246054071
529.0000000000068,26.23541945234827,1.4439775436851219,-2.3541896954394153
530.2000000000069,26.273900488104537,1.4542650130762118,-2.354189985503929
531.4000000000069,26.312328378021682,1.4613745473523532,-2.3547509955700603
532.6000000000068,26.351147733264973,1.470939802859465,-2.3551800567012524
533.8000000000069,26.38982625217846,1.4763947771182149,-2.3551459288526075
535.0000000000069,26.428398131972227,1.4824585614423578,-2.3555102921769064
536.2000000000069,26.466836663630634,1.4906021314692015,-2.3555101220817916
537.4000000000069,26.50599315850228,1.4953079178368478,-2.3555095137182933
538.600000000007,26.54449584663497,1.4967295160342502,-2.3568442614066503
539.800000000007,26.58326444761338,1.5035756299980236,-2.356829602697405
541.000000000007,26.62176428608636,1.5045018820987017,-2.357692716861904
542.200000000007,26.66064077891346,1.5013483359457358,-2.358138636148399
543.400000000007,26.699615159453423,1.4994558137577272,-2.3574802408852373
544.6000000000071,26.738201529467933,1.4940388704387744,-2.357480078991789
545.800000000007,26.777038668131727,1.4914822852369323,-2.357480078000772
547.000000000007,26.816093540412393,1.4885521762038063,-2.357480078006869
548.2000000000071,26.855175577928428,1.4848777446779733,-2.3574800914894505
549.4000000000071,26.894076957322127,1.483954295453471,-2.3574932836578046
550.6000000000072,26.93311386093077,1.481953002719561,-2.3584694091374843
551.8000000000071,26.971591403943535,1.4821379459270894,-2.35880180738991
553.0000000000072,27.01064668118177,1.4791564363670038,-2.358805477410887
554.2000000000072,27.04991675748035,1.4783920079438475,-2.3601056132313323
555.4000000000071,27.088845063365817,1.4751521014131752,-2.360110032424483
556.6000000000072,27.127895907510418,1.47284894053119,-2.36011003399949
557.8000000000072,27.166936128801495,1.4720794390345882,-2.360110033992283
559.0000000000073,27.205829420461768,1.4680481025832766,-2.3601100886589386
560.2000000000073,27.245056345773904,1.4625410535452201,-2.3605978259748452
561.4000000000073,27.283833394621695,1.4623446062344996,-2.3611096607180873
562.6000000000073,27.323290018710107,1.4564684966482062,-2.361429405782358
563.8000000000073,27.36222782327044,1.4561237849498359,-2.361871705853675
565.0000000000073,27.401336925438134,1.4554822592401067,-2.363756223439654
566.2000000000073,27.440234877618924,1.4522311006040203,-2.362737169123213
567.4000000000074,27.479764511901408,1.4506900119174988,-2.3627498061163292
568.6000000000074,27.518520917740613,1.4507992038827613,-2.3627534322602046
569.8000000000075,27.557595019276373,1.4518509215340965,-2.361443164359552
571.0000000000074,27.59718478471141,1.4544609689352532,-2.3613828068508007
572.2000000000074,27.636266100380343,1.455281879072921,-2.3627390921372378
573.4000000000075,27.675489356727365,1.454880625488447,-2.362797137330746
574.6000000000074,27.714675371901638,1.4551752464135452,-2.36405990352784
575.8000000000075,27.75390941420717,1.4539721420662488,-2.364070375489624
577.0000000000075,27.793165600037682,1.4559443422809752,-2.3634000102948507
578.2000000000075,27.832215911535684,1.455052568028296,-2.3635787902295453
579.4000000000076,27.871520453502747,1.4581118313923491,-2.364060073793396
580.6000000000075,27.911251648503125,1.4598675700454637,-2.364241228132469
581.8000000000076,27.950595570152224,1.463242023153589,-2.365379675482188
583.0000000000076,27.98952689238382,1.4648325980539787,-2.3653808688068936
584.2000000000075,28.029035074417493,1.4682451150549767,-2.3667422716042577
585.4000000000076,28.068313738360725,1.4718274793436419,-2.3666898970793335
586.6000000000076,28.107652145305646,1.47284196851135,-2.366689880038666
587.8000000000077,28.14680358513149,1.4767748644502408,-2.3666898905350724
589.0000000000077,28.186480033560272,1.479502109023619,-2.36766801530837
590.2000000000077,28.225611031666286,1.4842274008313991,-2.367686385322879
591.4000000000077,28.26514487609673,1.488118907135451,-2.3680097261727733
592.6000000000078,28.30456846509098,1.4936131183826167,-2.368414758161971
593.8000000000077,28.34370459265057,1.4960431050718377,-2.3693302636454887
595.0000000000077,28.38332683584709,1.502178802630836,-2.369330158131815
596.2000000000078,28.422555090371127,1.505239575150389,-2.3686113862124634
597.4000000000078,28.46175078387391,1.5100787808541452,-2.3696930187103558
598.6000000000079,28.501137411015723,1.5161446153393197,-2.3696498367748275
599.8000000000078,28.541106697926907,1.521137839522764,-2.370450443340178
601.0000000000078,28.580032302030457,1.526001708286059,-2.3709700087458843
602.2000000000079,28.61939268049075,1.5333890704397726,-2.370941459365285
603.4000000000078,28.659077477139245,1.5342606831477166,-2.3722899380031754
604.6000000000079,28.69887290586542,1.5425963690657312,-2.3726612675406082
605.8000000000079,28.73739091724516,1.5476477234966688,-2.3729490390865724
607.000000000008,28.7771049887947,1.5519912686103585,-2.3742742375549493
608.200000000008,28.8172592691201,1.5584183115380361,-2.374259996280522
609.4000000000079,28.856869725555345,1.5631685889776892,-2.3743790289690048
610.600000000008,28.896493082794063,1.5686367933338432,-2.3752476025619997
611.800000000008,28.935658323757302,1.571919718555838,-2.375250099485143
613.000000000008,28.97552323648991,1.5757532489395136,-2.375403563024567
614.200000000008,29.01531366912478,1.5841837830345948,-2.376560199786385
615.400000000008,29.054674688927882,1.5882092546025757,-2.376559919272988
616.6000000000081,29.094327795513856,1.59605946676752,-2.3765545324212325
617.8000000000081,29.134244315101807,1.6021599521098056,-2.3778806401134047
619.0000000000081,29.17373329302219,1.6082820711280754,-2.376874934358597
620.2000000000081,29.21352986395148,1.6155561017910693,-2.3782191701233524
621.4000000000082,29.253155774577987,1.618021023094646,-2.3782200965477402
622.6000000000081,29.292775387065433,1.6261342375886834,-2.378222399838283
623.8000000000081,29.332182252030556,1.633615377619756,-2.3795284072744414
625.0000000000082,29.37177937780972,1.6383817047514446,-2.379529863909058
626.2000000000082,29.41167036813738,1.6465024203013496,-2.380362878930871
627.4000000000083,29.451123496293828,1.6549971620882804,-2.3808500300616537
628.6000000000082,29.491093718583606,1.662684979845011,-2.381624693159094
629.8000000000083,29.530781421474657,1.6695167250100043,-2.3821743965106776
631.0000000000083,29.570451426608212,1.6800970906784227,-2.3834833449202772
632.2000000000082,29.61021338655071,1.6875967217792414,-2.3841616164618853
633.4000000000083,29.649734097667974,1.6988001283096046,-2.384800209449966
634.6000000000083,29.689801650132253,1.7077701671578422,-2.3848979778444357
635.8000000000084,29.729040621058015,1.7206267773591701,-2.386110257918963
637.0000000000084,29.76885841010491,1.7336426007159451,-2.387483560903675
638.2000000000083,29.808650210636433,1.7464611250985824,-2.3874279907419624
639.4000000000084,29.848260121804138,1.7637468286399494,-2.388736420866143
640.6000000000084,29.888009099793432,1.7793428298680476,-2.388755485508206
641.8000000000084,29.92798748805844,1.7943535277298341,-2.3900680437524615
643.0000000000084,29.967582637433406,1.811866868252797,-2.3914930258895586
644.2000000000085,30.007420800570976,1.8301591370087424,-2.3914929463578485
645.4000000000085,30.04696434124201,1.8507981661802513,-2.3928007796941815
646.6000000000085,30.086979583396147,1.8675950498835245,-2.3941248727945177
647.8000000000085,30.1264984611534,1.8891432907662242,-2.3941120812513184
649.0000000000085,30.166226233372257,1.9066221801588064,-2.3954439715346307
650.2000000000086,30.2062764242202,1.9291048678148734,-2.395375332296982
651.4000000000085,30.246106162853465,1.9537426608146893,-2.396756175281041
652.6000000000085,30.285581380777746,1.9733415558708554,-2.3981412694440856
653.8000000000086,30.325404707463264,2.0013817792865454,-2.3994733240472117
655.0000000000086,30.365522227734864,2.024372536662996,-2.4014323730103637
656.2000000000087,30.405251439899445,2.0494807535515434,-2.4031999501827004
657.4000000000086,30.444821679432202,2.079611619926609,-2.404071603513377
658.6000000000087,30.485054291156438,2.107815965101359,-2.4066721757996734
659.8000000000087,30.524580346027648,2.1374835736963016,-2.408083378106473
661.0000000000086,30.564192144709562,2.1673416069435416,-2.409357619338693
662.2000000000087,30.604295652650723,2.199583732778848,-2.4109000469881723
663.4000000000087,30.644048881584773,2.2334647493119015,-2.4123825773656185
664.6000000000088,30.68361351145631,2.27259634198657,-2.414817893017558
665.8000000000088,30.723434301778422,2.305552791854941,-2.417230669740978
667.0000000000088,30.763181642120784,2.342964630081578,-2.418890792073842
668.2000000000088,30.802746269564818,2.381254625041939,-2.422281026861307
669.4000000000088,30.841922443652194,2.420040911984013,-2.424100851573508
670.6000000000088,30.88256240497582,2.459198912179427,-2.4269095754729584
671.8000000000088,30.922117910601894,2.502583773487806,-2.4273740388822054
673.0000000000089,30.961794350781652,2.54155444349539,-2.431052361991441
674.2000000000089,31.00168888093817,2.5832922775505693,-2.4339424900482047
675.400000000009,31.041558702496275,2.6273010119785036,-2.4364130326224718
676.6000000000089,31.08060846463104,2.6688502592878196,-2.4391448796712534
677.8000000000089,31.121098384035683,2.713793311172513,-2.441748168731831
679.000000000009,31.16085251930824,2.7577469212324863,-2.4451606896003852
680.2000000000089,31.200840869712746,2.803519148749627,-2.4478370235410547
681.400000000009,31.24066246355748,2.852079061789676,-2.4509375006060345
682.600000000009,31.280497912909464,2.898520737279803,-2.454320025201989
683.800000000009,31.320234390518223,2.945077192443135,-2.4579805070006073
685.0000000000091,31.360370951217412,2.9911686257097734,-2.4611386654596767
686.200000000009,31.399606073659065,3.036359388783428,-2.46496111315129
687.4000000000091,31.439795203697308,3.0831805367163025,-2.468689727697442
688.6000000000091,31.479692678717782,3.1298954686979488,-2.473180477015963
689.800000000009,31.51934359741807,3.1718533193058875,-2.4779815695467624
691.0000000000091,31.55929412921536,3.2166354658681553,-2.481930478970378
692.2000000000091,31.59912688343229,3.2620462074171566,-2.4864582912046282
693.4000000000092,31.639104143841703,3.3081459522988554,-2.4889149585869075
694.6000000000092,31.67896330026898,3.356548910205764,-2.4928714349560117
695.8000000000092,31.71905685801792,3.406022400438202,-2.4974453017544276
697.0000000000092,31.758956179567555,3.4512678555767526,-2.502527372205073
698.2000000000093,31.799115846937955,3.498355542343983,-2.507976301812767
699.4000000000092,31.83868142325772,3.5439806803897054,-2.512706794918215
700.6000000000092,31.878930052908704,3.59237797559154,-2.5174106415633934
701.8000000000093,31.919049476688397,3.640457231809972,-2.5217573554126935
703.0000000000093,31.958863266893236,3.6851696733025543,-2.5261675064698017
704.2000000000094,31.998641244242236,3.733551243044541,-2.534201570881926
705.4000000000093,32.038983065264595,3.7773827392577135,-2.539603451519538
706.6000000000093,32.078958201880695,3.823354317841857,-2.544706385074006
707.8000000000094,32.11906597016773,3.8704631807744754,-2.5493699930323306
709.0000000000093,32.15907729337008,3.9153750554206344,-2.5545031487870835
710.2000000000094,32.19908975808242,3.958947696429038,-2.5605340917861676
711.4000000000094,32.238898238079656,3.999722770604794,-2.567558258224431
712.6000000000095,32.27908606073981,4.043471004309993,-2.5730437778838526
713.8000000000095,32.31857161876583,4.08578589509626,-2.5783431520350284
715.0000000000094,32.3593191649927,4.130829390012499,-2.584239547823546
716.2000000000095,32.399597678265195,4.172145955793409,-2.5912268018509366
717.4000000000095,32.43959415036197,4.216785013235741,-2.5980798708208415
718.6000000000095,32.47963956444295,4.258631377037382,-2.603476279875828
719.8000000000095,32.52000033597195,4.305610581310177,-2.610420030834121
721.0000000000095,32.560033579068545,4.356860196015145,-2.617553436781305
722.2000000000096,32.60003471410734,4.415399738736488,-2.6232680131402764
723.4000000000096,32.64034174794119,4.482119277550358,-2.629561013105218
724.6000000000096,32.68043054490778,4.559055140029281,-2.636250314978126
725.8000000000096,32.720470494917535,4.6482419799257535,-2.6429945416075045
727.0000000000097,32.76057230597888,4.7494885766429675,-2.65130914095044
728.2000000000096,32.80090997381243,4.859445807622016,-2.6589347875784832
729.4000000000096,32.841496847137876,4.981343127000768,-2.6674559745016575
730.6000000000097,32.881660629819585,5.105911407580761,-2.6747688780668613
731.8000000000097,32.92152978361665,5.233385470779997,-2.682283956945887
733.0000000000098,32.96183458096036,5.3639890661966385,-2.691228559545075
734.2000000000097,33.0020939775963,5.496383816275754,-2.700395135334605
735.4000000000098,33.04260076144622,5.624697899185246,-2.711463582239025
736.6000000000098,33.0820389161985,5.750087412139671,-2.7216951822522955
737.8000000000097,33.12286565118307,5.874847788067028,-2.731010664887613
739.0000000000098,33.16324555131805,5.997629097983291,-2.7408973150891986
740.2000000000098,33.203536275398555,6.113113801879203,-2.7523835063061597
741.4000000000099,33.243543582880775,6.226032567216437,-2.7631989024664305
742.6000000000099,33.284107478678024,6.336425156399646,-2.775066511670186
743.8000000000098,33.324561847369374,6.439589829257258,-2.787180634425857
745.0000000000099,33.36462391864665,6.535675981197308,-2.7989903042373867
746.2000000000099,33.4051774651119,6.623059994201743,-2.811973212431577
747.4000000000099,33.44516608689975,6.705467930365488,-2.8240153142720392
748.6000000000099,33.485301606626585,6.7804277172573295,-2.83632954207288
749.80000000001,33.52543451063871,6.8433745699987165,-2.8482000863503485
751.00000000001,33.56592102077687,6.8974910512269165,-2.8616326719323557
752.20000000001,33.606260256946044,6.930075504283112,-2.874728371518021
753.40000000001,33.6460464818518,6.952420407555145,-2.887266460289096
754.60000000001,33.68630662395239,6.945870468547497,-2.900299070435758
755.8000000000101,33.72653469287073,6.915915473228197,-2.914092600368675
757.00000000001,33.766971406938914,6.851129386070842,-2.9276141463105896
758.20000000001,33.8067395458925,6.74187029088322,-2.94037186225098
759.4000000000101,33.847341278514556,6.567005233762253,-2.9520578572675684
760.6000000000101,33.88722519951234,6.3118989912998025,-2.964079243126678
761.8000000000102,33.927365338266966,5.936386758948601,-2.9749786963238805
763.0000000000101,33.96755006218443,5.393778715602588,-2.984970024213045
764.2000000000102,34.007549959675984,4.456123048916395,-2.9937890382747523
765.4000000000102,34.047199297768124,3.5099403451271582,-2.9987593425415873
766.6000000000101,34.087001986193265,2.922492516000131,-3.0017744522020138
767.8000000000102,34.12683589335415,2.5750988885384234,-3.0031072609936347
769.0000000000102,34.16653582410416,2.36956175044305,-3.0031000016758638
770.2000000000103,34.206536215759655,2.2460866914109836,-3.0044103758581313
771.4000000000103,34.246802465489715,2.169413133805329,-3.0040786389464276
772.6000000000103,34.28677424471113,2.123372209865501,-3.004100888669559
773.8000000000103,34.326899095008606,2.0936630586329494,-3.0030927103317264
775.0000000000103,34.36710595471998,2.0730222767358346,-3.003089434532112
776.2000000000103,34.40746569055489,2.0607695671066706,-3.0044015628364606
777.4000000000103,34.44787757614242,2.053680569900307,-3.004409915151374
778.6000000000104,34.48802032021798,2.04863519278751,-3.0044099189988027
779.8000000000104,34.52855178904084,2.0464602850303435,-3.0044099188146856
781.0000000000105,34.56903640897718,2.0455055348824636,-3.0044061087933036
782.2000000000104,34.6092804722036,2.0472103689313954,-3.003090036086942
783.4000000000104,34.64966179987656,2.05228860191696,-3.0030757284764946
784.6000000000105,34.689910598272185,2.0547802928826626,-3.0044111371913402
785.8000000000104,34.73019464651483,2.061962824629511,-3.0044100062900942
787.0000000000105,34.77074145564306,2.0663655762632565,-3.004409736633879
788.2000000000105,34.81072158152693,2.0716394095828314,-3.0055275257102316
789.4000000000106,34.85122327083134,2.077152882358343,-3.0057198279295694
790.6000000000106,34.89166366035802,2.081982906394832,-3.0057198749869527
791.8000000000105,34.93209290255555,2.0915489326643604,-3.0057198749999965
793.0000000000106,34.972672474347725,2.0979358065357023,-3.0057198750000005