File: 01_Data/Nylon_Carpet_High_Pile/STA/N2/30K_min/Nylon_Carpet_High_Pile_STA_N2_30KData_220309_R3.csv
##Temp./Â°C,Time/min,DSC/(mW/mg),Mass loss/mg
49.0,10.42,-1.1007,-0.0035872338309612672
50.20000000000002,10.683402283262145,-0.9210802628050098,-0.0024562986546254884
51.400000000000034,10.82243367326294,-0.7928745218390496,-0.0038793283747833307
52.60000000000005,10.9305294856821,-0.6871160967167338,-0.006684674221819176
53.80000000000007,11.019443610637468,-0.5980410414854349,-0.005104922089745223
55.000000000000085,11.098403388677044,-0.5204137577825937,-0.005048181434271104
56.2000000000001,11.171266953393387,-0.44881243030809825,-0.003888492956794387
57.40000000000012,11.238863505493084,-0.38194065026391777,-0.004100371433141348
58.600000000000136,11.300997315648818,-0.3215316352970786,-0.0049151563401830245
59.80000000000015,11.35848002344024,-0.2673815997289027,-0.004797735982481566
61.00000000000017,11.417118462840747,-0.21124536936092272,-0.004795586113520933
62.20000000000019,11.472603009213334,-0.16102739612049768,-0.005055573209728159
63.400000000000205,11.52583901078854,-0.11392649807692391,-0.0053371882986832375
64.60000000000022,11.577598040671644,-0.06790836448252267,-0.0046376936415502
65.80000000000024,11.628031157682361,-0.025666212612043496,-0.00632161716978219
67.00000000000026,11.677482173809398,0.015281687906289379,-0.0054520528069059715
68.20000000000027,11.7256984769561,0.053319909341303075,-0.005450026354742565
69.40000000000029,11.77374568679367,0.09287926200451146,-0.006329066467819278
70.6000000000003,11.820496111790117,0.12794776813543202,-0.006902747905124684
71.80000000000032,11.867621913226971,0.1643673736364169,-0.005892067970195036
73.00000000000034,11.912980703729497,0.19581018680753673,-0.005056778224033387
74.20000000000036,11.958502898531254,0.22777995200982312,-0.005636715068941811
75.40000000000038,12.00316539476504,0.25834272264047886,-0.005888514786881238
76.60000000000039,12.04837961428087,0.2891145100974101,-0.006952241766092548
77.80000000000041,12.091858940776632,0.31624799005673004,-0.005596358870862517
79.00000000000043,12.136159837812519,0.34254167938510044,-0.005369574880330408
80.20000000000044,12.179924604207189,0.3679942647542553,-0.005590301805062925
81.40000000000046,12.222485614989672,0.3951635522618662,-0.005088763820414677
82.60000000000048,12.266018848967745,0.4196868536664667,-0.005990232042930366
83.8000000000005,12.30824041690796,0.44430723298471175,-0.00567353743235488
85.00000000000051,12.351045249608738,0.4680446410325918,-0.006327603857673836
86.20000000000053,12.393188250526444,0.4928048069354515,-0.007131412332283205
87.40000000000055,12.434970371979563,0.5142907761908575,-0.007101379277195896
88.60000000000056,12.476854457537419,0.5361151483535449,-0.0074444281105350285
89.80000000000058,12.518414147985675,0.5579002872445666,-0.008549899625296842
91.0000000000006,12.560171635753674,0.5800332835911078,-0.008557415126391188
92.20000000000061,12.601861925132447,0.600678147289573,-0.007419474971666062
93.40000000000063,12.642518746773925,0.621860735254434,-0.008550169974153476
94.60000000000065,12.684203527486245,0.6426370297043602,-0.007198074607885019
95.80000000000067,12.724873700717387,0.6618412361794304,-0.008638378417030523
97.00000000000068,12.765714853949508,0.6801307758856333,-0.008769724163919967
98.2000000000007,12.806195848290743,0.6991720068319187,-0.009034884731849768
99.40000000000072,12.847301688411648,0.715013991134619,-0.008769787310356936
100.60000000000073,12.887836494217186,0.7305717330885454,-0.009665327047990946
101.80000000000075,12.928468697095168,0.7440393970220539,-0.010081557416188325
103.00000000000077,12.969039056832045,0.757273373026,-0.008771238771248413
104.20000000000078,13.009660084612996,0.7685591039900845,-0.0100660130485406
105.4000000000008,13.049834457872517,0.779907106531448,-0.00875647398884416
106.60000000000082,13.090560547158008,0.7903451808488242,-0.008759408268846247
107.80000000000084,13.130898080381927,0.799440722300855,-0.008941414237982226
109.00000000000085,13.171268898432963,0.8101364489047351,-0.008768395864930056
110.20000000000087,13.211357843359488,0.8207874777079144,-0.01007422704340133
111.40000000000089,13.251220798754872,0.8292383113270184,-0.009318122461884126
112.6000000000009,13.291944323544532,0.8390933140895435,-0.010080007927339985
113.80000000000092,13.332097774823369,0.8508617930372476,-0.010079924026247244
115.00000000000094,13.371384074500115,0.8614484976007456,-0.010079923569892735
116.20000000000095,13.412288585406909,0.8718378975216933,-0.010078717951916616
117.40000000000097,13.4521102111805,0.8812675989381479,-0.010906462700495556
118.60000000000099,13.492426471866427,0.8929457719513693,-0.009530746130719248
119.800000000001,13.532289340676762,0.9044743760251052,-0.010067301264054862
121.00000000000102,13.572263082467664,0.9144638819053851,-0.011397751367238307
122.20000000000104,13.61164371569009,0.9272141016794124,-0.012721177640549808
123.40000000000106,13.651653999605188,0.9389156752557222,-0.012719956214337635
124.60000000000107,13.69155257848532,0.9499496001013904,-0.012719955990354137
125.80000000000109,13.730529629204726,0.9622789028896417,-0.012719934181885328
127.00000000000111,13.770191673749261,0.97393781512964,-0.013068167100477535
128.20000000000113,13.80944698718607,0.9866180009973483,-0.014039913598906661
129.40000000000114,13.848928546152923,0.9987847176567245,-0.014046915123674175
130.60000000000116,13.88845900478897,1.0113298514179057,-0.01206780295155152
131.80000000000118,13.927369170480693,1.0223495340403341,-0.012060090067210094
133.0000000000012,13.966568600126688,1.0348041801428107,-0.012063901571720326
134.2000000000012,14.005747607312218,1.0484422837830487,-0.013375579700502183
135.40000000000123,14.045039860052235,1.062332872747077,-0.013380086405798686
136.60000000000124,14.083492623790116,1.0759824208553703,-0.013380855273699588
137.80000000000126,14.122233112394259,1.0876985361668232,-0.014713541204551372
139.00000000000128,14.161186574699071,1.1033499281039305,-0.01469010342282795
140.2000000000013,14.2001266592641,1.117297769933513,-0.014690088007510038
141.4000000000013,14.238531393493673,1.1314168076287292,-0.014690088000001822
142.60000000000133,14.276996303666873,1.145696433122182,-0.014690087999999157
143.80000000000135,14.31559968054699,1.161734437020496,-0.014690087999924106
145.00000000000136,14.354132881604892,1.1768521346719996,-0.014690087924420947
146.20000000000138,14.391894692021317,1.1903258949505031,-0.014690294224305234
147.4000000000014,14.430581748537312,1.2101740675549253,-0.013570331051519169
148.60000000000142,14.468870473117915,1.2267267068075924,-0.014687460794220897
149.80000000000143,14.507239121508752,1.247061121893176,-0.014689822184256851
151.00000000000145,14.544832035616,1.2680406072790673,-0.014689836684226076
152.20000000000147,14.583497112843661,1.2919562750625688,-0.0146830074821227
153.40000000000148,14.621587673941905,1.3168313543285586,-0.01601076029186599
154.6000000000015,14.659736544913768,1.344293812871377,-0.01600982450863553
155.80000000000152,14.69753032428533,1.3743970208666387,-0.016009824015512653
157.00000000000153,14.735677570816378,1.4040290772073178,-0.01600972698687153
158.20000000000155,14.773615545794645,1.434617150019231,-0.01667546720933588
159.40000000000157,14.811675918361571,1.469359590124039,-0.016989785535124646
160.6000000000016,14.849680321729473,1.500558127009672,-0.016989682090995384
161.8000000000016,14.88727666314627,1.5288466767585398,-0.0173385722650945
163.00000000000162,14.925415386034274,1.5534252798592039,-0.019081613522697882
164.20000000000164,14.963194897972363,1.5664878482153952,-0.01907720001865698
165.40000000000165,15.001140086557383,1.5695100760866938,-0.017764757038881918
166.60000000000167,15.038593245714452,1.5607958382519949,-0.016962688601309228
167.8000000000017,15.076371245866497,1.5464551247918539,-0.015136618087437714
169.0000000000017,15.113841062198313,1.531867152115702,-0.015129626712961919
170.20000000000172,15.15165127097956,1.5196497270810934,-0.015854379489876003
171.40000000000174,15.189258763057945,1.510594829081433,-0.01645004208200218
172.60000000000176,15.226894302337527,1.502975708443048,-0.01644987392433883
173.80000000000177,15.264106834461918,1.5005007324967068,-0.017221266438172567
175.0000000000018,15.301666547411326,1.5011399980826163,-0.017429885388744015
176.2000000000018,15.338796518617874,1.5042132087198032,-0.017429956034753946
177.40000000000182,15.37641589111624,1.5075508507018605,-0.01742995750397114
178.60000000000184,15.413552574073828,1.5140452480879991,-0.017435077989751413
179.80000000000186,15.450942953397576,1.5226725206656009,-0.018748454508756396
181.00000000000188,15.487925241281257,1.5301166403681326,-0.018766215014098364
182.2000000000019,15.525070674415069,1.5403763132546233,-0.017429015643811052
183.4000000000019,15.562434385150935,1.5508175089070662,-0.01742995669463676
184.60000000000193,15.599673628880481,1.561146207676612,-0.017429956000606595
185.80000000000194,15.636542342771577,1.5741546621364297,-0.017429955998963464
187.00000000000196,15.673517162761096,1.5872215617644363,-0.01742994966328615
188.20000000000198,15.710465686585879,1.5988912564005882,-0.017428520596884045
189.400000000002,15.747272762910825,1.6105834420788216,-0.01876760210459949
190.600000000002,15.78411614317764,1.6251738451400453,-0.01907996704342141
191.80000000000203,15.821334569220722,1.6405049687965785,-0.019084829626413224
193.00000000000205,15.85802688115517,1.654972858663707,-0.02038723005429155
194.20000000000206,15.894651961680927,1.6695097373981964,-0.019071190112468273
195.40000000000208,15.931653827321977,1.683927918046717,-0.019080309504167836
196.6000000000021,15.96849023744132,1.700738265140604,-0.019942534472371598
197.80000000000211,16.005332676542903,1.7163643679750118,-0.0203900655031215
199.00000000000213,16.04214075220257,1.7331604412643247,-0.018979642575844835
200.20000000000215,16.07857177637061,1.749748011949315,-0.017662568107961185
201.40000000000217,16.11565641243976,1.769626434242186,-0.01766016626206568
202.60000000000218,16.152368979325548,1.7881536811518361,-0.017661373906486588
203.8000000000022,16.18868754831004,1.8102959618306809,-0.016363632923709126
205.00000000000222,16.22545519886749,1.8356933416785994,-0.01762424887872882
206.20000000000223,16.2622882462045,1.8621753581089036,-0.017650101275178187
207.40000000000225,16.299113799965053,1.8898952354545295,-0.017653597462414794
208.60000000000227,16.335464872429366,1.9223112624583159,-0.018964399807706478
209.80000000000229,16.372265461108785,1.9606977234150835,-0.01998926277628099
211.0000000000023,16.409037713083222,2.0141901331122436,-0.02029032466777103
212.20000000000232,16.445502141593728,2.085832017455501,-0.02117757645827556
213.40000000000234,16.48225453865176,2.1861241865402814,-0.022922881438725895
214.60000000000235,16.518596119721238,2.3145904070568615,-0.02291987520530725
215.80000000000237,16.555261347633078,2.465606245153119,-0.022919868003263844
217.0000000000024,16.592105095193848,2.6449664824366055,-0.022919858286530204
218.2000000000024,16.629023003142475,2.828970530996418,-0.022909170291509184
219.40000000000242,16.66542548840415,3.001838617672434,-0.025747087574479632
220.60000000000244,16.7024119538627,3.1341350581199587,-0.02706601473285053
221.80000000000246,16.7392478087387,3.19016105621533,-0.02473591102849948
223.00000000000247,16.77605621886902,3.1502694287957653,-0.023460098650586847
224.2000000000025,16.813140797510485,3.019413836919509,-0.0234598362488736
225.4000000000025,16.84978721358118,2.848662030473524,-0.02345983599975998
226.60000000000252,16.886207486086942,2.683050561395984,-0.02345983600067658
227.80000000000254,16.922490474077684,2.5443182152580466,-0.02345983982956401
229.00000000000256,16.959039715348215,2.4264853616056548,-0.023457309464241405
230.20000000000258,16.99538722529813,2.3367502097133777,-0.024766131130660618
231.4000000000026,17.031013362483638,2.266159490858584,-0.024780114030618527
232.6000000000026,17.067845664324352,2.2113262702551926,-0.02478010000540909
233.80000000000263,17.104086693527538,2.169347426644419,-0.024780100011998485
235.00000000000264,17.140377177486386,2.136035285398598,-0.02478010306194456
236.20000000000266,17.176423521600977,2.111787691907654,-0.02475818496414206
237.40000000000268,17.212842877158813,2.0955926934066325,-0.02608942734582609
238.6000000000027,17.249254450238844,2.0823019311274726,-0.026090066111601473
239.8000000000027,17.285238426087982,2.075032651220916,-0.026090068001088262
241.00000000000273,17.321817408034605,2.0682749733616324,-0.026090068000048205
242.20000000000275,17.357825851541623,2.0641878358494115,-0.0260900679290339
243.40000000000276,17.39424997537602,2.0621388829850535,-0.026090017832502976
244.60000000000278,17.43045212634724,2.0621554413535814,-0.026283593615989087
245.8000000000028,17.466511136604836,2.0637909974677267,-0.027424653684265277
247.0000000000028,17.503006564731713,2.0648292375085258,-0.02872828659066551
248.20000000000283,17.539547754067698,2.0681987132598856,-0.02872993105727728
249.40000000000285,17.575742295008688,2.0718817071050695,-0.028729936003127676
250.60000000000286,17.612026936558525,2.075783408366359,-0.0287299362039386
251.80000000000288,17.648115039996622,2.0802397873571863,-0.02872950489515258
253.0000000000029,17.6844776334061,2.0846047920603796,-0.027844461548331534
254.20000000000292,17.719917519122077,2.0896569266824403,-0.02872973834592152
255.40000000000293,17.756840169957172,2.0934484003968867,-0.029799253348866017
256.600000000003,17.79311547290816,2.098464464419691,-0.030040177265663992
257.80000000000297,17.829517934803622,2.103966396846888,-0.02995154187054494
259.00000000000296,17.865549658863625,2.108627096643532,-0.02872930487344849
260.200000000003,17.90192838664054,2.113281386722729,-0.028727012160584486
261.40000000000305,17.93801941425715,2.119712370195772,-0.029748641829278277
262.60000000000304,17.97441089360338,2.1244104361019844,-0.02972016844780434
263.800000000003,18.01083942645319,2.1287960225611626,-0.02972016813623668
265.00000000000307,18.047231055117162,2.1333245618096726,-0.029720227927806597
266.2000000000031,18.083358230321128,2.139129136352814,-0.030382394735607665
267.4000000000031,18.119411045039506,2.143092100067375,-0.031039976993242124
268.6000000000031,18.155952740873918,2.1495939232160204,-0.03104003584642756
269.80000000000314,18.19207461831084,2.154535835396472,-0.03104003563077873
271.0000000000032,18.22837113158487,2.159650279234789,-0.03103935954031911
272.2000000000032,18.26465363610217,2.165493506592735,-0.032307811929930264
273.40000000000316,18.300484382595105,2.1691367812496436,-0.03230549665170912
274.6000000000032,18.337098963003637,2.1737965156272603,-0.03366606621646806
275.80000000000325,18.373394867527754,2.1776257947922257,-0.03497930111645342
277.00000000000324,18.409477953168537,2.1822314842524677,-0.034979886932492654
278.20000000000323,18.446029479257767,2.1863244318198505,-0.0349798714090519
279.4000000000033,18.482357632246778,2.191893620025356,-0.034980899680001176
280.6000000000033,18.51855565821474,2.1960319176672853,-0.036319994754869356
281.8000000000033,18.55491684621661,2.200793982063952,-0.03629802219197664
283.0000000000033,18.59121169587013,2.2046787584958363,-0.03765479567109642
284.20000000000334,18.62750798299416,2.209805084195906,-0.036304128593226626
285.4000000000034,18.663616133145542,2.2126291093554347,-0.03630016341781639
286.6000000000034,18.699764772579083,2.2177433097449177,-0.03629593790917296
287.80000000000337,18.736475588919955,2.2227348413797237,-0.037611354885513926
289.0000000000034,18.772684585609802,2.226172157319394,-0.03761010370078388
290.20000000000346,18.809223324688713,2.229922133228108,-0.03761010399421005
291.40000000000344,18.8454066931295,2.231920759220183,-0.03761010822841504
292.60000000000343,18.88176234072368,2.2369973497167845,-0.03761731890745734
293.8000000000035,18.918313496869125,2.2396327865244463,-0.038922809699531324
295.0000000000035,18.95434194793263,2.2428652859960803,-0.03892362682561101
296.2000000000035,18.990739000423115,2.2438372484399713,-0.04024260508948396
297.4000000000035,19.027145592413245,2.248464443630664,-0.04176559401892321
298.60000000000355,19.063843452737085,2.2539989499730435,-0.04378938509058816
299.8000000000036,19.100000301506512,2.255940117127002,-0.04495986389811213
301.0000000000036,19.13666105858121,2.259233738561487,-0.044959864495243806
302.20000000000357,19.17311135973492,2.261438766037588,-0.04495986499806959
303.4000000000036,19.209069871195943,2.263673943332685,-0.044971282269319346
304.60000000000366,19.245724757981233,2.268254229363295,-0.04594859281601105
305.80000000000365,19.282207544285466,2.267495147924925,-0.04594979156017631
307.00000000000364,19.318556510505616,2.2717840910295806,-0.045953947308548404
308.2000000000037,19.355135693192107,2.2746406906184697,-0.04464080754251709
309.40000000000373,19.391401834713903,2.2762783607904127,-0.04463979245911043
310.6000000000037,19.427591374450444,2.2804378192426844,-0.04561994993858409
311.8000000000037,19.46399596997024,2.2830644919920866,-0.046613378399122496
313.00000000000375,19.500888221727926,2.2859321148904193,-0.047600168312837976
314.2000000000038,19.536805221110544,2.290186083157144,-0.04760002061087443
315.4000000000038,19.573330308393828,2.292240028878306,-0.047600001239212375
316.6000000000038,19.6102831294131,2.2953309803869115,-0.04891220698049725
317.8000000000038,19.646546974577078,2.299262428253635,-0.05022411884907152
319.00000000000387,19.6831107430355,2.3027913838239416,-0.05022978993051197
320.20000000000385,19.719660451674095,2.309071883024707,-0.05022433826696604
321.40000000000384,19.756088644632776,2.314265180571541,-0.05154278043316518
322.6000000000039,19.79280880046733,2.3199139242701916,-0.05283292099405301
323.80000000000393,19.829270739381972,2.325894946101912,-0.052858911910857564
325.0000000000039,19.86577892463174,2.333190830730485,-0.05416194322832446
326.2000000000039,19.90221581317237,2.34053477269347,-0.05510964796007567
327.40000000000396,19.938648911159078,2.3466717493243894,-0.05598026300402337
328.600000000004,19.975471127004734,2.357403180057093,-0.05694875566581459
329.800000000004,20.012059279678525,2.366376368705459,-0.05936338802159247
331.000000000004,20.04842855169725,2.3747553393534573,-0.06149790593446758
332.200000000004,20.085142350601725,2.3860334288204474,-0.0629904572434663
333.40000000000407,20.121694847691295,2.3955585412377234,-0.06497027995605409
334.60000000000406,20.15808414952657,2.406816729072588,-0.06646210339663794
335.80000000000405,20.19485743912775,2.4185757867655338,-0.06794077005191435
337.0000000000041,20.231480136314797,2.43067495797541,-0.06996167486950045
338.20000000000414,20.26827602766526,2.4426275628292085,-0.07302330464551288
339.4000000000041,20.304688965286463,2.4546054254358505,-0.07516221766807218
340.6000000000041,20.34146015398521,2.4662812413080473,-0.07686748231372897
341.80000000000416,20.37839721448907,2.481156499228137,-0.0792226709536501
343.0000000000042,20.41508293693142,2.492802434660226,-0.08169362277753978
344.2000000000042,20.452019796173577,2.5083613696340974,-0.08566816580731418
345.4000000000042,20.48869022423202,2.5233288916196805,-0.0892412977902084
346.60000000000423,20.52537972067722,2.53695913651533,-0.0913921924249892
347.8000000000043,20.562114271437878,2.5519925011610725,-0.09462821421267176
349.00000000000426,20.598734420056864,2.5671598181480455,-0.09834295898781953
350.20000000000425,20.63573216810646,2.5841427296784745,-0.10179410594956995
351.4000000000043,20.67224689822133,2.602589604899873,-0.10610178933072589
352.60000000000434,20.70922834677968,2.619266094618859,-0.11234860052194362
353.80000000000433,20.74604156231745,2.637671992070755,-0.11663972881317175
355.0000000000043,20.782654675178335,2.6558487655538716,-0.1203092280252136
356.20000000000437,20.81962387975672,2.6748566432955134,-0.12543004865546648
357.4000000000044,20.85651565014294,2.6957961173702136,-0.12944299157318273
358.6000000000044,20.89324028597116,2.7181733173369302,-0.13523146615094017
359.8000000000044,20.93040578666366,2.738503576353326,-0.14067373952743623
361.00000000000443,20.96722112896646,2.7620609959062037,-0.14642229428986253
362.2000000000045,21.004128413621462,2.7862236702078036,-0.15252561902984718
363.40000000000447,21.040928374315403,2.8098044035779184,-0.15770879085170764
364.60000000000446,21.077937936813985,2.8344532585172515,-0.16472465738230158
365.8000000000045,21.114756034597345,2.8598745712552516,-0.17244721304189436
367.00000000000455,21.151783713400146,2.8861075072504443,-0.18061042863327215
368.20000000000454,21.188865045277595,2.914931548866833,-0.1889089585573731
369.4000000000045,21.225843477176326,2.94221964489004,-0.1960074035211603
370.60000000000457,21.26286433030575,2.9703685965103195,-0.20556936266548842
371.8000000000046,21.29977572450526,3.000039976813054,-0.2159150921823545
373.0000000000046,21.336906035402745,3.0261203876963494,-0.22452213746698213
374.2000000000046,21.373611149636545,3.0573735373519053,-0.2339320907343745
375.40000000000464,21.41106711411464,3.0859342920454003,-0.24451729284483603
376.6000000000047,21.448189299178836,3.117719502587481,-0.25499267281712035
377.8000000000047,21.485534309815435,3.1479802274148705,-0.2661951941098968
379.00000000000466,21.52239336334245,3.1799268413497295,-0.2761962224170267
380.2000000000047,21.559506863363904,3.2107160492362574,-0.2879682845085574
381.40000000000475,21.59687458239992,3.2448792996721436,-0.3011535900221567
382.60000000000474,21.63390892285533,3.276553621265995,-0.31399466618133953
383.80000000000473,21.671461766343473,3.3101565051230413,-0.32788594846012353
385.0000000000048,21.708338190709004,3.347943000008502,-0.3408207293987058
386.2000000000048,21.74572812633861,3.3815363858358625,-0.3541453273381454
387.4000000000048,21.782924788892522,3.4189831256624177,-0.3692675051156753
388.6000000000048,21.81977870040869,3.4568204418024706,-0.38551652016530635
389.80000000000484,21.85738577825541,3.496193285828334,-0.4011422389279984
391.0000000000049,21.894414903697847,3.5380422676280765,-0.41685189527690936
392.2000000000049,21.9318059056012,3.5793558603308844,-0.433881121230558
393.40000000000487,21.96913211946829,3.6260839514742664,-0.45163553133441736
394.6000000000049,22.00648370686269,3.6698611952455003,-0.46870570286990354
395.80000000000496,22.043842715796305,3.717161522660456,-0.48770771885720965
397.00000000000495,22.081129856821597,3.7645489911727226,-0.5077310179015013
398.20000000000493,22.117736527065688,3.8133273407628483,-0.5277852246296124
399.400000000005,22.1559053360477,3.8636012734056258,-0.5492700528231778
400.600000000005,22.193041436332205,3.9157013484705434,-0.5712809756135235
401.800000000005,22.23080989733579,3.967467161936936,-0.5945889840062284
403.000000000005,22.268260874979273,4.019594666423649,-0.6191738967798295
404.20000000000505,22.305703571644912,4.074141921248427,-0.644315643562873
405.4000000000051,22.343143368530917,4.128417428865956,-0.6695597505908712
406.6000000000051,22.380698785830393,4.1818605145590375,-0.6965736855301761
407.80000000000507,22.417859402352722,4.234010355095053,-0.725123475311702
409.0000000000051,22.45556201144315,4.286906766549858,-0.7539081255903737
410.20000000000516,22.492939066231084,4.338818678785972,-0.7825353075491632
411.40000000000515,22.530778195968168,4.387046018306194,-0.8128881154676018
412.60000000000514,22.568564426611225,4.435022495845631,-0.8458925849188503
413.8000000000052,22.605783377954463,4.480910256253654,-0.8792755565565882
415.00000000000523,22.6435364801324,4.523960318999235,-0.9147990523698546
416.2000000000052,22.681049237967986,4.565201372350604,-0.9516806259850106
417.4000000000052,22.71852774684802,4.600294184035771,-0.9880505392004317
418.60000000000525,22.75623046270833,4.629746528159526,-1.027104855807802
419.8000000000053,22.793991371037883,4.656390421102731,-1.067937222978049
421.0000000000053,22.83157255713421,4.674693370343495,-1.1081785876370605
422.2000000000053,22.86909256162242,4.687746288786426,-1.148724819293336
423.4000000000053,22.906328665414286,4.6905921936667525,-1.1899310243651202
424.60000000000537,22.944279185995867,4.683807521186407,-1.2324480618642601
425.80000000000535,22.982030382469038,4.66846008048088,-1.2755558480154523
427.00000000000534,23.019558998178965,4.640451414648772,-1.3198734760160469
428.2000000000054,23.05768031758408,4.598936361690002,-1.3634324607299462
429.40000000000543,23.09485913543421,4.548821763951215,-1.406235658318582
430.6000000000054,23.132602911163488,4.481317718812056,-1.4495474526282557
431.8000000000054,23.169939489224298,4.398863901266796,-1.491658100734035
433.00000000000546,23.207925271169767,4.301629746934639,-1.5347377865876863
434.2000000000055,23.245338841597224,4.188548822970469,-1.5754652801093671
435.4000000000055,23.282529063642922,4.060902982474572,-1.6150799238111238
436.6000000000055,23.31966783758795,3.919859352676178,-1.6529799095260884
437.8000000000055,23.35822399895423,3.7612728455313444,-1.6892506145533703
439.00000000000557,23.395655330343185,3.5961753467627733,-1.7224740153511116
440.20000000000556,23.433174563562833,3.4284759045255107,-1.7526612485814246
441.40000000000555,23.47073489981927,3.2592775189587937,-1.7804804393650553
442.6000000000056,23.50787962896312,3.097846951457572,-1.8035698389171793
443.80000000000564,23.545489769692743,2.943755529915044,-1.825847957147857
445.0000000000056,23.582956855070726,2.804476642628868,-1.8458076382840263
446.2000000000056,23.620151286838144,2.6826174472401187,-1.8627534016686358
447.40000000000566,23.65741704448702,2.5762817236158457,-1.8769876939960595
448.6000000000057,23.69523549607967,2.4862233402250338,-1.890989858971802
449.8000000000057,23.732705620722438,2.414957359724612,-1.9046092898474178
451.0000000000057,23.770125111379997,2.3540379922859653,-1.9153624479794766
452.20000000000573,23.807937290221798,2.3035740763569477,-1.9278220788461473
453.4000000000058,23.845425013692076,2.265627250731972,-1.9382638089498747
454.60000000000576,23.883062966811494,2.2329299275652432,-1.9478781635233453
455.80000000000575,23.920902160688353,2.2060596972536732,-1.958478319692099
457.0000000000058,23.95845576560129,2.1857327370671853,-1.9680530810176682
458.20000000000584,23.996295401804698,2.1714155195181193,-1.977382348464107
459.40000000000583,24.033894639016157,2.157095928049395,-1.986762473158817
460.6000000000058,24.071797094788963,2.1459833071743737,-1.9957182733337533
461.80000000000587,24.109452946762662,2.1387446132569363,-2.004311063625509
463.0000000000059,24.147429365675453,2.13147610422782,-2.0136857065133453
464.2000000000059,24.185268468925944,2.130779034518847,-2.022199856204474
465.4000000000059,24.223309297052946,2.12499471761311,-2.030765426184635
466.60000000000593,24.261261493910474,2.124883760619302,-2.040019023665624
467.800000000006,24.299068856806805,2.1221057775079863,-2.048501791979418
469.00000000000597,24.33695025760147,2.121917285583535,-2.0570836623662623
470.20000000000596,24.375132264264685,2.121819704052289,-2.0662512815332787
471.400000000006,24.412960961146315,2.1217391920525923,-2.0744965522604044
472.60000000000605,24.45132100873524,2.121403330037608,-2.0839080550207294
473.80000000000604,24.489345938841055,2.121256970155021,-2.0955639416180474
475.000000000006,24.52740856591704,2.1223822912657564,-2.103249573722982
476.20000000000607,24.565281697290484,2.1232359428262884,-2.113784769324397
477.4000000000061,24.603421162243052,2.122771954188529,-2.1228877292509156
478.6000000000061,24.641582015005465,2.1229881214482864,-2.1312660745352243
479.8000000000061,24.679872966074136,2.122970833318246,-2.139940499488863
481.00000000000614,24.717764999214264,2.1215234373843503,-2.1495455157895123
482.2000000000062,24.75601644732258,2.1221754053947266,-2.15959421924696
483.4000000000062,24.794388364273633,2.1220944045570436,-2.169853785752143
484.60000000000616,24.832508431497907,2.119328813160493,-2.178721762125304
485.8000000000062,24.870607933242926,2.1176967423289037,-2.188173985436943
487.00000000000625,24.909207260285356,2.114034032818482,-2.1980710876034184
488.20000000000624,24.947430267699122,2.109657462350464,-2.2064625391938097
489.40000000000623,24.985803774571874,2.1066700329123025,-2.2192758172085303
490.6000000000063,25.023875719628997,2.100966185604041,-2.231011132269209
491.8000000000063,25.062144686957495,2.0945653893593805,-2.2412725395106694
493.0000000000063,25.10031451690232,2.0838373433766666,-2.2506122952469494
494.2000000000063,25.138839824766166,2.07382584110021,-2.2610793985567286
495.40000000000634,25.17721667731231,2.063335734143512,-2.270325150179647
496.6000000000064,25.215356240428072,2.048350437470624,-2.2798924540242913
497.8000000000064,25.253788780823548,2.0300963842983464,-2.2892551770178393
499.00000000000637,25.29232356108928,2.005559767860477,-2.298886122596328
500.2000000000064,25.330694966801353,1.9790348509450022,-2.3077935555428515
501.40000000000646,25.3684668768237,1.946428002336594,-2.3165284816155753
502.60000000000645,25.40749490055296,1.9099791774423935,-2.3252894366634247
503.80000000000643,25.44543684194828,1.8703490480676268,-2.3322832105193396
505.0000000000065,25.484146767288106,1.829258576224695,-2.339055488493673
506.2000000000065,25.52235236318747,1.7880961754220508,-2.344516918271589
507.4000000000065,25.560983269099708,1.7514724206966237,-2.34882663107798
508.6000000000065,25.599271203041415,1.7171676992730869,-2.351031436719607
509.80000000000655,25.63789181695729,1.684400799483652,-2.3545527665945363
511.0000000000066,25.67639868445571,1.6592574252710957,-2.3562758663627315
512.2000000000066,25.714919398372455,1.6364274846326978,-2.3575075733408264
513.4000000000066,25.753460899738027,1.6176450598199206,-2.35864769522027
514.6000000000066,25.7920038010311,1.6023413369889967,-2.359114173493167
515.8000000000067,25.82949330933433,1.592501404108618,-2.3591200026908057
517.0000000000066,25.868982728379187,1.5845134836641872,-2.359119880729729
518.2000000000066,25.907031178934314,1.5786865112470974,-2.361101176853478
519.4000000000067,25.946054653778177,1.5759937545314273,-2.3617503868308676
520.6000000000067,25.984772364767565,1.5728824187646548,-2.363098703870169
521.8000000000068,26.023613939620198,1.5699056525213249,-2.363070157275569
523.0000000000067,26.061959614358525,1.5701216019942306,-2.3630701400060805
524.2000000000068,26.100557409608463,1.5704597350291993,-2.363070140000028
525.4000000000068,26.13844834228834,1.5714369089743583,-2.3630701398986824
526.6000000000067,26.177892283353376,1.5698869436495846,-2.3630698195749513
527.8000000000068,26.216786848004336,1.574784139729712,-2.363964163422644
529.0000000000068,26.2551046268392,1.5824726522726396,-2.3640502162590087
530.2000000000069,26.293746913018296,1.5936024133970683,-2.364376747012968
531.4000000000069,26.332458418753106,1.6035808196969774,-2.364380132816572
532.6000000000068,26.370786919829474,1.6117594654371805,-2.36453567043354
533.8000000000069,26.40933456926542,1.6194001253930614,-2.365699628355686
535.0000000000069,26.44831083360335,1.6296719540743918,-2.3656999758704575
536.2000000000069,26.4869693862989,1.6327690715562064,-2.365699968743443
537.4000000000069,26.525872123404234,1.6396086788587823,-2.365962210104989
538.600000000007,26.564440409015166,1.6399529206327692,-2.3666587591708317
539.800000000007,26.60305284958335,1.6409051737032285,-2.3670200121827714
541.000000000007,26.642045959280146,1.6333352971727644,-2.367019857402309
542.200000000007,26.680894090459848,1.6290389252150568,-2.3670356794214453
543.400000000007,26.719765452476114,1.6248701688239522,-2.368321518527827
544.6000000000071,26.758718806351617,1.6235675325427616,-2.36965045042321
545.800000000007,26.797041440474732,1.621901498899271,-2.369649812345445
547.000000000007,26.83623224566924,1.6219634946771977,-2.3696495802691535
548.2000000000071,26.875376557869036,1.6204726610565034,-2.3723676705649357
549.4000000000071,26.91403706204601,1.6210355975802833,-2.3722899404453908
550.6000000000072,26.952826586913954,1.6206139768095533,-2.3712807721401727
551.8000000000071,26.991699555429665,1.621831227307221,-2.370032656749419
553.0000000000072,27.03072117173052,1.6212442387210895,-2.368809369721741
554.2000000000072,27.069460189622454,1.6170667358578856,-2.3683411112464006
555.4000000000071,27.108771310341375,1.6162667608794645,-2.368626861572305
556.6000000000072,27.147101756169505,1.6138545514939764,-2.3683300468405504
557.8000000000072,27.186537161089156,1.6122535209066433,-2.368797390774654
559.0000000000073,27.225591344032075,1.6085603393028773,-2.3696496676339898
560.2000000000073,27.264404616501604,1.6050322772834307,-2.370966559100375
561.4000000000073,27.30338790914871,1.6072402839888495,-2.3709600549856926
562.6000000000073,27.342345390654405,1.6042970615959895,-2.3709697398687473
563.8000000000073,27.38159532318701,1.60405437313931,-2.372302441636794
565.0000000000073,27.420494683526897,1.606686545534405,-2.373626971955746
566.2000000000073,27.459506351395202,1.605360701614178,-2.3735999216286707
567.4000000000074,27.497739804498504,1.6063101931064419,-2.373599798101795
568.6000000000074,27.537499174288577,1.6053786756614143,-2.3743488723577713
569.8000000000075,27.576476676871003,1.604552049042952,-2.37491760538076
571.0000000000074,27.615643617938083,1.6089511968274688,-2.373602540758732
572.2000000000074,27.65442462050782,1.6129870852360892,-2.373600177329487
573.4000000000075,27.693876805304264,1.6145586411101407,-2.373600176000715
574.6000000000074,27.732712963917884,1.6150580892328337,-2.3736001757377956
575.8000000000075,27.772097280336983,1.6167571901764337,-2.3735990858044236
577.0000000000075,27.81092959520851,1.6185834015216503,-2.374858791893473
578.2000000000075,27.8503419873861,1.6204283506256374,-2.373930145314723
579.4000000000076,27.889245021691387,1.6263750819703497,-2.3739289580500627
580.6000000000075,27.92849479328128,1.627409427449343,-2.375269408940513
581.8000000000076,27.967633833200484,1.631502633788551,-2.3762407027638717
583.0000000000076,28.006933526593727,1.6320982652476763,-2.376230017377593
584.2000000000075,28.045870662193206,1.6362881209461508,-2.376227655898138
585.4000000000076,28.085274720547165,1.642074543216747,-2.3775446869504657
586.6000000000076,28.12430214743687,1.6428567631126931,-2.377549876757863
587.8000000000077,28.163689435899784,1.6462894900992997,-2.3775498799986163
589.0000000000077,28.202639297001543,1.6495073431732294,-2.377549880108172
590.2000000000077,28.24223107580701,1.6537099535816076,-2.377550109910755
591.4000000000077,28.281155079943314,1.6584698276475833,-2.378620757843262
592.6000000000078,28.320713423225097,1.6623638817891546,-2.3788600150784305
593.8000000000077,28.360064308783784,1.6674392175687291,-2.3785034367191704
595.0000000000077,28.3994177177679,1.6703559705397832,-2.3788121224621595
596.2000000000078,28.438649198400547,1.6763074300164438,-2.3798500036493566
597.4000000000078,28.477915595855507,1.6791636715723894,-2.380069702724422
598.6000000000079,28.517206927132978,1.6837861550921975,-2.3824795788515574
599.8000000000078,28.556797094582524,1.6890663494901472,-2.382480079980452
601.0000000000078,28.5959321842025,1.6930180830881487,-2.382480165659239
602.2000000000079,28.63551455277126,1.6979779527539893,-2.3812333845709817
603.4000000000078,28.674087726272685,1.7028069739266827,-2.382211156420089
604.6000000000079,28.71402291136185,1.707807782824565,-2.3824788026638624
605.8000000000079,28.753816594160572,1.7106119044656638,-2.3814854963293968
607.000000000008,28.792945075056878,1.7173364567542924,-2.3828138836178443
608.200000000008,28.832403370773367,1.7207322863948715,-2.3828198104398757
609.4000000000079,28.87182678802401,1.7253138726838924,-2.3828198191484264
610.600000000008,28.91120447946949,1.730184010155319,-2.3828295181264987
611.800000000008,28.950720975065515,1.7354658249903396,-2.383434026181461
613.000000000008,28.990267432426588,1.7390193939478276,-2.3854411223357945
614.200000000008,29.029553095786305,1.7474347178243614,-2.385439122570344
615.400000000008,29.06911173624648,1.7521957881864754,-2.3867782316603354
616.6000000000081,29.108530846873897,1.754925646712374,-2.3867600539090277
617.8000000000081,29.147986885717284,1.7596196648454978,-2.3867599409992026
619.0000000000081,29.187659315234935,1.76701290745834,-2.387541824075863
620.2000000000081,29.226904190613364,1.772057334268091,-2.388080212183476
621.4000000000082,29.266422239233506,1.7764704415467942,-2.3893912745297996
622.6000000000081,29.305861864497135,1.7826233804713045,-2.3893898860254414
623.8000000000081,29.345193227391647,1.7861410028359854,-2.389390724627943
625.0000000000082,29.384947700467542,1.7930490578893785,-2.3907378178884415
626.2000000000082,29.424308407557653,1.799351554366928,-2.3907101565946496
627.4000000000083,29.46399046961737,1.8064818159511074,-2.390695011548944
628.6000000000082,29.503190348224376,1.8127922801065302,-2.392020999525031
629.8000000000083,29.542722141292128,1.8174246597628407,-2.3930208619888056
631.0000000000083,29.582310572736024,1.8255004290186185,-2.3932997467482364
632.2000000000082,29.62160890198008,1.831597438963959,-2.394658187723871
633.4000000000083,29.661618404522724,1.8390852998759124,-2.397093654973577
634.6000000000083,29.700980042244392,1.8508421981981893,-2.397259275964256
635.8000000000084,29.740736772710108,1.8574916262605115,-2.397286783457444
637.0000000000084,29.780256663349327,1.8692824219773716,-2.3972900815258193
638.2000000000083,29.819679372820893,1.8783085165765558,-2.397294056275678
639.4000000000084,29.85923948742289,1.8918822703248264,-2.398610746209876
640.6000000000084,29.899238862286456,1.9056541663513173,-2.399162374280412
641.8000000000084,29.93829990537771,1.920795778706091,-2.400565890218452
643.0000000000084,29.977405529968316,1.9345817805803465,-2.4019013330979897
644.2000000000085,30.017841901320672,1.9518947939535107,-2.4020735979250576
645.4000000000085,30.057120222318556,1.9687605251293887,-2.403210803268249
646.6000000000085,30.097085944551786,1.984034352017184,-2.4045788917337445
647.8000000000085,30.136696854858908,2.0018999054142457,-2.404542809982096
649.0000000000085,30.176270335754765,2.0220388456746377,-2.4045403003278167
650.2000000000086,30.215988590335986,2.04067401634298,-2.405945387974087
651.4000000000085,30.255824802708304,2.0621152268720473,-2.4073594318198275
652.6000000000085,30.295333476888842,2.0848421956046472,-2.4064833318461036
653.8000000000086,30.33527695827657,2.108821744984879,-2.4073986195000154
655.0000000000086,30.375013862242714,2.13010084767386,-2.4078642931908916
656.2000000000087,30.414685128343844,2.1554114773195865,-2.408895000641169
657.4000000000086,30.454233668416393,2.1794073414161494,-2.411384940694391
658.6000000000087,30.49414777733443,2.209237269493242,-2.413651883486901
659.8000000000087,30.533874699264572,2.236268974417198,-2.415951855554818
661.0000000000086,30.5737592263252,2.2660879195320027,-2.4173653795073466
662.2000000000087,30.613196438607382,2.295599394226181,-2.4188991455875306
663.4000000000087,30.65336415522924,2.326045394601344,-2.420220018654387
664.6000000000088,30.692964432092932,2.360697380633395,-2.421741881907578
665.8000000000088,30.73263571763942,2.3936765608361315,-2.4240557981933644
667.0000000000088,30.772286617643125,2.43022618678322,-2.4267131253615224
668.2000000000088,30.812266848675556,2.466341467107183,-2.428262894251856
669.4000000000088,30.85178595079127,2.503812211727891,-2.4299683616161767
670.6000000000088,30.891804870735207,2.5422395213264033,-2.432125059273628
671.8000000000088,30.931312916712795,2.580461587594541,-2.43425767217056
673.0000000000089,30.97123739024563,2.6203264785010147,-2.434858706532452
674.2000000000089,31.011011871074114,2.66299401520333,-2.437844029765798
675.400000000009,31.050666628256216,2.7012237221654307,-2.4409965454318674
676.6000000000089,31.09010445727508,2.7435730507222296,-2.4437895019794604
677.8000000000089,31.12999246533999,2.782681943034916,-2.446717653039567
679.000000000009,31.170322181130576,2.8251356719678884,-2.451214265410097
680.2000000000089,31.209511697306798,2.8667304068064143,-2.4540055699579457
681.400000000009,31.249572446428207,2.914440463201608,-2.4562038253780747
682.600000000009,31.289214311564827,2.9556902953297604,-2.4597726162008913
683.800000000009,31.328783863909425,3.0026449760730802,-2.4617330822307726
685.0000000000091,31.36853789344474,3.0461665746087014,-2.464565579677388
686.200000000009,31.40859524315831,3.0921067186584246,-2.4671616163008796
687.4000000000091,31.448407306627335,3.137409706893932,-2.470237453572928
688.6000000000091,31.487915124552703,3.1837919259643654,-2.4740447434371786
689.800000000009,31.527805040160008,3.22710532626573,-2.4776524094527996
691.0000000000091,31.567582212742877,3.270189500700689,-2.482029850530167
692.2000000000091,31.607404290237934,3.3151877634856417,-2.486629913617966
693.4000000000092,31.647307148971063,3.3589113371881947,-2.4897380613170323
694.6000000000092,31.686957094077414,3.4036852722276487,-2.4927794516679436
695.8000000000092,31.72683184465176,3.4509658194120716,-2.497574739576508
697.0000000000092,31.766862937564984,3.494345591040691,-2.501969326055089
698.2000000000093,31.806669659333295,3.541869537900296,-2.5063198468066092
699.4000000000092,31.84630392010318,3.5851414687874,-2.511449124946645
700.6000000000092,31.886247183239156,3.635015696095307,-2.516478667263503
701.8000000000093,31.92607088753865,3.6793729600564453,-2.520843732939552
703.0000000000093,31.965931988754956,3.7242565769052653,-2.524948854872986
704.2000000000094,32.005817399568244,3.7706724147358246,-2.5291423229114836
705.4000000000093,32.04561455051076,3.819700625938525,-2.533428353022144
706.6000000000093,32.0856197293187,3.865429779522697,-2.5390007541654604
707.8000000000094,32.12567985462564,3.9092593240998954,-2.546697805287409
709.0000000000093,32.165600162482455,3.9573702749436888,-2.55187075497179
710.2000000000094,32.205554996579764,4.002874377137087,-2.5578207068063477
711.4000000000094,32.24541704202672,4.046276685973887,-2.5630550424269027
712.6000000000095,32.28516837374842,4.090761158954471,-2.568760843159891
713.8000000000095,32.325320487870925,4.1379133899854095,-2.574320665739894
715.0000000000094,32.36541868250344,4.185113281711212,-2.578146383536886
716.2000000000095,32.4054543948233,4.2311691695419915,-2.5849417159614476
717.4000000000095,32.445278825256764,4.276333963642837,-2.5906914136900543
718.6000000000095,32.485296078687426,4.3258607057427465,-2.5966354639950113
719.8000000000095,32.5253507870551,4.37601948291434,-2.603448557272209
721.0000000000095,32.56518668699377,4.427068003475926,-2.6096276601628388
722.2000000000096,32.605536378194344,4.4858150831754875,-2.6165635447723123
723.4000000000096,32.64568461224894,4.54747892925057,-2.623058178986929
724.6000000000096,32.685452367265874,4.613124577743871,-2.6298695346482455
725.8000000000096,32.72566345116771,4.691554019612082,-2.63695929539018
727.0000000000097,32.765744005129775,4.778065421338301,-2.644116607090141
728.2000000000096,32.80555839351356,4.869196746316438,-2.6514192490606057
729.4000000000096,32.846064970323084,4.97019896851228,-2.657519416890913
730.6000000000097,32.885863324578565,5.07387710974947,-2.665161595434423
731.8000000000097,32.926159077003085,5.189379949064438,-2.673187147098744
733.0000000000098,32.96629588392934,5.303259170623045,-2.6816990227413537
734.2000000000097,33.00635087291206,5.425551893086589,-2.6908525248618456
735.4000000000098,33.046604352642596,5.543596692794007,-2.6979292836299162
736.6000000000098,33.08676953656439,5.662577374054243,-2.707620232829957
737.8000000000097,33.12687128677446,5.778806451728468,-2.7159781344281217
739.0000000000098,33.167324877832066,5.894793587693251,-2.7251989425783565
740.2000000000098,33.2076028818244,6.007477929262912,-2.7353671752931468
741.4000000000099,33.24767517080536,6.116599769353785,-2.745899664013657
742.6000000000099,33.288039624417884,6.222492678046406,-2.756014924871855
743.8000000000098,33.3283030019637,6.32893183048942,-2.767383502257887
745.0000000000099,33.368619358546226,6.428831598207504,-2.7784990719368023
746.2000000000099,33.40912670490744,6.524061790238461,-2.7901100401143233
747.4000000000099,33.44934082885646,6.6123860485297845,-2.8013599868088015
748.6000000000099,33.489706618519676,6.697825960763001,-2.8141054364569946
749.80000000001,33.5301773013818,6.77630288230308,-2.8267516569942384
751.00000000001,33.57032556869226,6.8455375949712955,-2.8397631530530303
752.20000000001,33.61047909810207,6.905633643818093,-2.8521287916155855
753.40000000001,33.650948306483535,6.956864480094043,-2.8664325655526457
754.60000000001,33.69135358627753,6.993313343873791,-2.878890669151316
755.8000000000101,33.73143306077893,7.012885786146443,-2.890490235212087
757.00000000001,33.77188956088449,7.01511355711114,-2.9033101926367237
758.20000000001,33.81215273369543,6.995243148151398,-2.9164074462795155
759.4000000000101,33.852118251179945,6.942650248131061,-2.928442723219346
760.6000000000101,33.892467854725254,6.856078311569062,-2.9408548534567376
761.8000000000102,33.93278410532542,6.722792927811982,-2.953327704679041
763.0000000000101,33.97300120957207,6.525164559718652,-2.9647149341152144
764.2000000000102,34.013158915562315,6.248787684855939,-2.975514353018906
765.4000000000102,34.05332930799985,5.857937841794279,-2.986090187543394
766.6000000000101,34.093431137268084,5.291946259983107,-2.9945618061832717
767.8000000000102,34.13322927745127,4.386094590393538,-3.002866847694793
769.0000000000102,34.17309544139087,3.5387249252225095,-3.0079236958154167
770.2000000000103,34.212822723300434,3.013582029402243,-3.0106048888047345
771.4000000000103,34.25254677705477,2.7049608529239464,-3.0111000167950133
772.6000000000103,34.29304099773873,2.512179847209945,-3.0110999447490174
773.8000000000103,34.332868233692885,2.400170849837143,-3.011192605137565
775.0000000000103,34.3729498155043,2.3347593455529934,-3.012089854826088
776.2000000000103,34.41308764923592,2.287347786505383,-3.012089883706188
777.4000000000103,34.4535560328929,2.258327137533789,-3.011424920715647
778.6000000000104,34.49366798212135,2.238413745394438,-3.0114312647728907
779.8000000000104,34.53396618122075,2.231400456961488,-3.0101018441530383
781.0000000000105,34.574261916548714,2.224756179041321,-3.009454702621495
782.2000000000104,34.61479322905202,2.2202139925904723,-3.0108368015833067
783.4000000000104,34.654892996491185,2.2193602506379677,-3.0125673060436697
784.6000000000105,34.69528460724167,2.218023724021163,-3.0125230354359616
785.8000000000104,34.735700652416426,2.2179690712976443,-3.0138343824294225
787.0000000000105,34.77614516006303,2.221213105254946,-3.013840043533374
788.2000000000105,34.81640495002216,2.2259351983156095,-3.0138444642228532
789.4000000000106,34.856451643480774,2.2304598718972874,-3.014833768623442
790.6000000000106,34.89708093752394,2.2335055229154186,-3.0148300453447545
791.8000000000105,34.937212064707055,2.2405481852769666,-3.0148300440004894
793.0000000000106,34.97758016143541,2.2449176046713526,-3.014830044