File: 01_Data/Nylon_Carpet_High_Pile/STA/N2/30K_min/Nylon_Carpet_High_Pile_STA_N2_30KData_220309_R2.csv
##Temp./Â°C,Time/min,DSC/(mW/mg),Mass loss/mg
49.0,10.345735380937846,-1.1308480339996143,0.002602372127405772
50.20000000000002,10.671696050611832,-0.929351025400688,0.0010397037391518538
51.400000000000034,10.815584988644046,-0.7978699722984017,0.0012590728868007162
52.60000000000005,10.92332690404253,-0.6917402315650574,0.0011996772897147068
53.80000000000007,11.013518095706731,-0.5999277577142011,0.0006737911042677958
55.000000000000085,11.093685250307548,-0.5161829124799355,0.0006947932146288416
56.2000000000001,11.16660611298582,-0.44374671758004763,0.0019889662467185154
57.40000000000012,11.232656672944394,-0.3765455792052092,0.0008971254918530569
58.600000000000136,11.29599097080624,-0.3142289092692298,0.0010197931022872808
59.80000000000015,11.355738778857033,-0.2547868595405643,0.002054169802061079
61.00000000000017,11.412229798882658,-0.20190399156854144,0.0007249236669322201
62.20000000000019,11.467308662451114,-0.14906903175187505,0.0018627129591464175
63.400000000000205,11.52012449587071,-0.10158766809623726,0.0014759652504747756
64.60000000000022,11.572302570248633,-0.055799624859126845,0.001959592827280421
65.80000000000024,11.622743018116322,-0.010389001787409386,0.0022490320070520653
67.00000000000026,11.672147519769371,0.03154973936309509,0.0020494152110805963
68.20000000000027,11.720744695909271,0.06973222773405696,0.00246556071548909
69.40000000000029,11.76850220102578,0.10839523733759245,0.0034191791866304833
70.6000000000003,11.815322085071928,0.14531728700247293,0.0023044342752824853
71.80000000000032,11.861496845024831,0.18034500212967716,0.001360335921277489
73.00000000000034,11.907822902681643,0.21653645529836082,0.002034170568440352
74.20000000000036,11.953149800023528,0.2479880371962016,0.0008056813082806258
75.40000000000038,11.997542926186373,0.2784046624887508,0.0002573188825096828
76.60000000000039,12.042563024021888,0.3080574570001058,0.0011829254379152054
77.80000000000041,12.08623990355883,0.3348271421101074,-0.0003479770732277565
79.00000000000043,12.130869536512561,0.3623550801088789,0.0006092694810617694
80.20000000000044,12.173845977062003,0.3874165918332608,0.0013035045900027242
81.40000000000046,12.217276923222459,0.4140761181120191,0.001412192497022069
82.60000000000048,12.260613837732617,0.4388344529248458,0.0016418678920357976
83.8000000000005,12.303364843987584,0.4634270194028269,0.0015022556417414457
85.00000000000051,12.345471741295192,0.48665952821386527,0.0015293317693667596
86.20000000000053,12.387754161091959,0.5095736964197517,0.0011995240740247937
87.40000000000055,12.429725355468511,0.531420007095139,0.00033411680066475213
88.60000000000056,12.471187443398609,0.5524860845185965,0.0008757256578659778
89.80000000000058,12.512750550078398,0.5744884603208474,0.0012910377372605808
91.0000000000006,12.554279400478142,0.595494495296243,1.603588428311653e-05
92.20000000000061,12.595874476742683,0.6152223354348144,-0.00026342645370158735
93.40000000000063,12.637383537306164,0.6367555892219513,-1.917448032795477e-06
94.60000000000065,12.678354801707439,0.6556836175427221,-0.00012093815864133717
95.80000000000067,12.719474943571065,0.675704824337235,-8.631529925562376e-05
97.00000000000068,12.760705162460841,0.6946504798554275,-0.00010983357093374835
98.2000000000007,12.801297364127702,0.7104407796860731,-0.00011986003048924943
99.40000000000072,12.84202845378432,0.7273700329247282,0.00040243314758914295
100.60000000000073,12.882975514794293,0.7438029982635841,5.653590181742274e-05
101.80000000000075,12.923479404190111,0.7583510577853825,-0.00011512955888548504
103.00000000000077,12.96407190797738,0.7704650493434393,-0.0014798786165255429
104.20000000000078,13.004863117373962,0.781433981718004,-0.001435269495021707
105.4000000000008,13.045209301650942,0.7934725906962051,-0.0007370989305730546
106.60000000000082,13.085339061218896,0.803606077697027,-0.0014296707543204334
107.80000000000084,13.125915529122677,0.813580315441497,-0.0014299612655892524
109.00000000000085,13.166638315659025,0.824244639704402,-0.001962616254560956
110.20000000000087,13.207008318125848,0.8344471329994332,-0.002750024604255774
111.40000000000089,13.24670350738003,0.8431407621734631,-0.0027499099190806398
112.6000000000009,13.286960689460487,0.8530417242310973,-0.0017557168701305415
113.80000000000092,13.327437995405086,0.8634988718317271,-0.0030728952099541296
115.00000000000094,13.367440688822317,0.8751908001688209,-0.0030698939179218954
116.20000000000095,13.407932311006892,0.8876710873040348,-0.0027259997344795117
117.40000000000097,13.447652339856758,0.8984204718986752,-0.0040597961487467416
118.60000000000099,13.487914185437699,0.9088300732849987,-0.0037028847387090558
119.800000000001,13.527912838761093,0.9203194987338136,-0.0030650175118895895
121.00000000000102,13.567329580349016,0.9335155615255497,-0.0040587982151700785
122.20000000000104,13.607441086617621,0.9439739029123129,-0.004060014084928731
123.40000000000106,13.647240251142534,0.954985201042478,-0.004068416698185029
124.60000000000107,13.686869500020796,0.9677084520413196,-0.0034021702907343077
125.80000000000109,13.72614777553099,0.9782812710012627,-0.004089750425187777
127.00000000000111,13.766060939956771,0.9900809646216131,-0.004389507057253272
128.20000000000113,13.805185669841762,1.0023412420481854,-0.0044061018714107725
129.40000000000114,13.844835737456606,1.0144358339553017,-0.005387339107196354
130.60000000000116,13.884002759933315,1.0273421400550278,-0.005709706737258902
131.80000000000118,13.923033441799372,1.0402663558415528,-0.005710139941617065
133.0000000000012,13.962327403252042,1.0515499192009936,-0.005710149499100314
134.2000000000012,14.001517886404196,1.0655055677721528,-0.005724721489713591
135.40000000000123,14.040159589451106,1.079248590081601,-0.005379896327903033
136.60000000000124,14.079229144367018,1.091685346108268,-0.005379822452927119
137.80000000000126,14.118007099361314,1.1070983854502974,-0.005692537985083845
139.00000000000128,14.15729662120726,1.1179093750341593,-0.005370079140270434
140.2000000000013,14.195735120123064,1.1331178686432712,-0.005369824440311977
141.4000000000013,14.234331524898058,1.1483379537994631,-0.0053512336571373
142.60000000000133,14.272887771930483,1.1626142096407068,-0.0066910564011415374
143.80000000000135,14.311296633977744,1.1780130612933177,-0.00668983029124437
145.00000000000136,14.349519174356535,1.1934385694979976,-0.0066898189272399655
146.20000000000138,14.387780933188662,1.2094893978092933,-0.006677882710677707
147.4000000000014,14.426435042732722,1.2286751938022682,-0.007351824460648082
148.60000000000142,14.464562058322837,1.2460887829928813,-0.007410473718337585
149.80000000000143,14.50309691161906,1.2671234094590889,-0.008678709842440124
151.00000000000145,14.541055988792055,1.2893868698185333,-0.008669887226304684
152.20000000000147,14.579364956571677,1.310769643410672,-0.008669875009348793
153.40000000000148,14.617539736037285,1.3380253747766497,-0.008669897785042568
154.6000000000015,14.655279558595218,1.3658073109183844,-0.008708121316170825
155.80000000000152,14.693675619959452,1.3951706851006325,-0.007680098676678959
157.00000000000153,14.731918021916336,1.4269471680029666,-0.007680002047239842
158.20000000000155,14.769853578083467,1.4597403943324487,-0.007671248410484388
159.40000000000157,14.807775196666837,1.4942770758004662,-0.007350697124755445
160.6000000000016,14.845485661837746,1.5279329770103436,-0.007350179680601254
161.8000000000016,14.883135943379212,1.5572104672216547,-0.007350174353533134
163.00000000000162,14.921365341669645,1.5800877126500075,-0.007331244549879656
164.20000000000164,14.95913615591914,1.5983416435454496,-0.008660870255520425
165.40000000000165,14.996895081183528,1.6014413040791848,-0.008632983332060196
166.60000000000167,15.034549560137856,1.5951313783831678,-0.009319473278418311
167.8000000000017,15.072502070224404,1.5810653110514712,-0.009319830150342767
169.0000000000017,15.110430541438465,1.5641515298953055,-0.009319830000186435
170.20000000000172,15.147894816911599,1.5504050752775718,-0.009319829999998142
171.40000000000174,15.185753127745285,1.541627462829071,-0.009319829999999474
172.60000000000176,15.223023537926304,1.5353862158781497,-0.009319834482356626
173.80000000000177,15.260765954159682,1.5315529162420831,-0.009325981868592681
175.0000000000018,15.298413112947967,1.5327983227617081,-0.010637133115437347
176.2000000000018,15.335639917135648,1.5364972692747967,-0.01063982491545623
177.40000000000182,15.372410967520466,1.5412788069358139,-0.010639828904565718
178.60000000000184,15.410367937939506,1.546905411065746,-0.010635185733163244
179.80000000000186,15.447489519347762,1.5532743273668428,-0.011312102012968506
181.00000000000188,15.484825816153279,1.5614592997219137,-0.009980498679988514
182.2000000000019,15.521608909071526,1.572330897331723,-0.009979876861989645
183.4000000000019,15.559053946439345,1.5829200681573696,-0.009979874994909821
184.60000000000193,15.596090432015794,1.593001269257604,-0.009979923970294458
185.80000000000194,15.633485008070533,1.6049689506167941,-0.010017863718259967
187.00000000000196,15.67033029971748,1.6177826547487706,-0.010309972637661424
188.20000000000198,15.707278390572721,1.62813486396649,-0.010309875060643847
189.400000000002,15.743922558060374,1.6403160048674672,-0.01030987497342073
190.600000000002,15.781127268524768,1.6532493045460952,-0.010309851139457038
191.80000000000203,15.818071454029576,1.6688469473455108,-0.010484700139907766
193.00000000000205,15.854994707144224,1.6821057557734933,-0.011300429000944412
194.20000000000206,15.891707243747858,1.6966007138254673,-0.011300139774649054
195.40000000000208,15.928494872503908,1.7135443804498196,-0.01130013983751521
196.6000000000021,15.965739927645801,1.7290655820172394,-0.011300286952031335
197.80000000000211,16.00201924192246,1.7454512933455395,-0.010390386981439015
199.00000000000213,16.039295976484468,1.7631763927576887,-0.00998000571047486
200.20000000000215,16.07578399002569,1.7809944770725892,-0.01067621271130692
201.40000000000217,16.112617401249725,1.8007358091237242,-0.011243470653469867
202.60000000000218,16.149316569922732,1.8197055792800707,-0.012284480366866468
203.8000000000022,16.186136186605346,1.8422000007283315,-0.010972007276829121
205.00000000000222,16.223248362987828,1.8674207960073224,-0.010970133185017605
206.20000000000223,16.25984517533289,1.8929729059534803,-0.01097013999872587
207.40000000000225,16.296413454419245,1.9230522726561399,-0.010970140350318403
208.60000000000227,16.333092374226613,1.9560601155525035,-0.010970169099616456
209.80000000000229,16.369596092080133,1.999263887198636,-0.012036938467059333
211.0000000000023,16.40560940466272,2.0504581427428303,-0.012276479481104108
212.20000000000232,16.442951670792745,2.1230087491268494,-0.010745070765387332
213.40000000000234,16.47965195630555,2.22320443666995,-0.010743975465028033
214.60000000000235,16.516562334216044,2.3579709632544064,-0.010947728346122787
215.80000000000237,16.553072822783225,2.5141108325820944,-0.012275820971151319
217.0000000000024,16.589693172944322,2.6911327212484464,-0.012279938934516732
218.2000000000024,16.626729320159836,2.8761459151340554,-0.01227996196964476
219.40000000000242,16.663543213115425,3.048897360474553,-0.012291432775770605
220.60000000000244,16.699632718774865,3.1838909578753385,-0.014571074630903347
221.80000000000246,16.737171010830455,3.250875096570352,-0.014920215168563455
223.00000000000247,16.774359272852806,3.2096794087014886,-0.014920049259520507
224.2000000000025,16.810656424368602,3.0686149100920947,-0.014921855128820383
225.4000000000025,16.84747098948433,2.882705991470474,-0.01358973091944593
226.60000000000252,16.883942526104043,2.7107614838583927,-0.013599973728076531
227.80000000000254,16.9211058807706,2.5660628575995346,-0.013594740534979
229.00000000000256,16.957309996467767,2.451481459147204,-0.014915583002004684
230.20000000000258,16.993916043365665,2.361909437194933,-0.014920049815359437
231.4000000000026,17.030152264503258,2.2929823782267884,-0.014916732765776874
232.6000000000026,17.066757332021425,2.238877054149217,-0.01623888824558728
233.80000000000263,17.102846078895826,2.199463114354075,-0.0162401617397947
235.00000000000264,17.13866744152358,2.167678733020431,-0.01623999569140988
236.20000000000266,17.175144082878845,2.145098466453423,-0.016569064808781064
237.40000000000268,17.211262047559526,2.127983550766877,-0.01690211466197855
238.6000000000027,17.2476941210215,2.1146474885689557,-0.015830841359615988
239.8000000000027,17.284036609173036,2.108450501708971,-0.01557669076032786
241.00000000000273,17.320091768651917,2.103600464588537,-0.017118715156906106
242.20000000000275,17.356401392204496,2.1007269577132988,-0.018446654211089264
243.40000000000276,17.392727621330536,2.0987779004745133,-0.018822304333707685
244.60000000000278,17.429114468007757,2.0996653436387063,-0.018430938867774582
245.8000000000028,17.465270373237107,2.100747784441327,-0.01955143994371511
247.0000000000028,17.501360743514486,2.1046511384540727,-0.019750544543077897
248.20000000000283,17.537573764552363,2.107720384239891,-0.018716400674299027
249.40000000000285,17.57393409339166,2.111677612940617,-0.018760184530810964
250.60000000000286,17.609933998506264,2.1154985494880387,-0.01876019502937032
251.80000000000288,17.645962920394464,2.119042906608816,-0.01876019499982995
253.0000000000029,17.682189015821532,2.1246870269068707,-0.01876019535944451
254.20000000000292,17.718416217381396,2.127510239541796,-0.018760086181148328
255.40000000000293,17.754628968399214,2.134595126700351,-0.020731371200200854
256.600000000003,17.79090003604911,2.1399800141256002,-0.020729868592776146
257.80000000000297,17.826882963361744,2.145015841609079,-0.020727102921889173
259.00000000000296,17.86302881626781,2.1480816164473278,-0.022043479703230506
260.200000000003,17.899342737880673,2.15602628372971,-0.022040015155270876
261.40000000000305,17.93519540031874,2.1612674254651005,-0.02136282163398384
262.60000000000304,17.971524878273375,2.1640400196876164,-0.02137026649629048
263.800000000003,18.00756499230518,2.170939928263135,-0.022711032159598243
265.00000000000307,18.04401033425328,2.173897154052015,-0.022710193555967262
266.2000000000031,18.079999697969196,2.179699934909408,-0.0227101950000006
267.4000000000031,18.116239488997156,2.1848726822840097,-0.022710195019768786
268.6000000000031,18.152274946457254,2.1897459251314433,-0.022710182891632957
269.80000000000314,18.18867459867751,2.194829051731721,-0.022684348465094484
271.0000000000032,18.22467212683956,2.2027216123866107,-0.024032309912828342
272.2000000000032,18.261128389955257,2.20556657192275,-0.024030024636449543
273.40000000000316,18.297267160689767,2.2110736927966803,-0.024746773966600077
274.6000000000032,18.3333869684552,2.21521257135403,-0.02534009075548349
275.80000000000325,18.369919861106176,2.2211429345834195,-0.026545975995058146
277.00000000000324,18.4057758300202,2.2243958121597354,-0.026660219835252352
278.20000000000323,18.442154921281485,2.2303235336061316,-0.02666019503639694
279.4000000000033,18.47797886751857,2.23446160344491,-0.026660194905792967
280.6000000000033,18.514343059374387,2.238827103030551,-0.02666011478883279
281.8000000000033,18.550909992818035,2.243282657400583,-0.027027519165855995
283.0000000000033,18.586823628804005,2.2468295539931593,-0.027979919252868246
284.20000000000334,18.623368403978823,2.250638676495526,-0.027979917490330575
285.4000000000034,18.659389789101162,2.256989009637665,-0.027969557926696087
286.6000000000034,18.695631508817975,2.2573337068701735,-0.029402196819074522
287.80000000000337,18.731989896721522,2.2640875086974455,-0.02939678751630792
289.0000000000034,18.76838518233825,2.2677049607453434,-0.030707427168824797
290.20000000000346,18.8047650074652,2.27158408847222,-0.030720014789693995
291.40000000000344,18.84130595843804,2.2753025931366566,-0.030718440888274134
292.60000000000343,18.87742404301275,2.27851532657506,-0.032068880349279016
293.8000000000035,18.91369506462165,2.282427175805439,-0.03202983052991959
295.0000000000035,18.94968835321407,2.284670295905164,-0.03202983039362062
296.2000000000035,18.986301575070826,2.2872645957708917,-0.032028561350434526
297.4000000000035,19.02257088534374,2.2910200099205564,-0.033014805478457365
298.60000000000355,19.058524761931235,2.2972682484566405,-0.033018115417026817
299.8000000000036,19.095221736641474,2.2962680888412588,-0.03335195812729408
301.0000000000036,19.13136009336122,2.2991683183950617,-0.033350968683535154
302.20000000000357,19.167491793551065,2.302177591359061,-0.03469806923633323
303.4000000000036,19.204194237860698,2.3053805280139685,-0.03466996440547154
304.60000000000366,19.240421368345213,2.3063320534041716,-0.03467126412353361
305.80000000000365,19.276839675350303,2.307967455287298,-0.036178154986762134
307.00000000000364,19.313243362296543,2.3107138274608734,-0.03751835404019799
308.2000000000037,19.349481369199307,2.3141072356833803,-0.037503883900412927
309.40000000000373,19.385713358633247,2.3185999979898226,-0.03882824694572706
310.6000000000037,19.422521932942253,2.321938373491033,-0.03883019240399532
311.8000000000037,19.458884059679658,2.3220532421294586,-0.03879509971772199
313.00000000000375,19.495258639505728,2.324060032291745,-0.040148878125832343
314.2000000000038,19.531626276674825,2.326714774606546,-0.040150148384942685
315.4000000000038,19.568054371292682,2.3286386245313992,-0.04124753820136151
316.6000000000038,19.60438469387943,2.334671768711784,-0.04141227592571761
317.8000000000038,19.640953758257197,2.3403817676827483,-0.042779520722793674
319.00000000000387,19.67752176670801,2.3443842519139273,-0.04278015253088485
320.20000000000385,19.713607188800424,2.3476319607825213,-0.04278130639998734
321.40000000000384,19.750205778237234,2.353955349196826,-0.04408867215704326
322.6000000000039,19.786761614919488,2.3604486824696176,-0.044102220388623437
323.80000000000393,19.823119074510462,2.364902385617264,-0.04666027357654823
325.0000000000039,19.85956524838574,2.3732093535271486,-0.047013578884000484
326.2000000000039,19.896171437291752,2.380216103776546,-0.04682329112883066
327.40000000000396,19.933070382008978,2.3885028467238882,-0.04816542739920715
328.600000000004,19.969201514436147,2.3980380620834567,-0.04986381716002697
329.800000000004,20.005922353066875,2.4072409631952345,-0.051193937721838
331.000000000004,20.042691839157474,2.4173415817892585,-0.051849517462196015
332.200000000004,20.078982913113077,2.427539718772825,-0.05329961086279322
333.40000000000407,20.115725237373958,2.436229151968552,-0.054910947054866543
334.60000000000406,20.15238028641778,2.4486118310581277,-0.05635351396786925
335.80000000000405,20.188793692505698,2.4608546327189624,-0.05806123956283882
337.0000000000041,20.225168705601376,2.4741350290017596,-0.06104452011258088
338.20000000000414,20.262216932762573,2.485642299274255,-0.0631322821956557
339.4000000000041,20.298646978623125,2.4970815522306755,-0.06602209296358819
340.6000000000041,20.33523493200815,2.513529618871185,-0.06762896495544313
341.80000000000416,20.371998537981394,2.5251810370643,-0.07047464079637544
343.0000000000042,20.408829844754507,2.5397401327276556,-0.07353052501218116
344.2000000000042,20.445522364865187,2.5547676261056544,-0.07699893471527508
345.4000000000042,20.48197139514477,2.568484264286669,-0.07897008402393046
346.60000000000423,20.518652462757316,2.5834428601717545,-0.0825927640469768
347.8000000000043,20.55544282499176,2.6012351215633953,-0.08683970228457882
349.00000000000426,20.59208993213638,2.616176890231102,-0.0909442283442381
350.20000000000425,20.628806896931724,2.6322645555385056,-0.09343441946434439
351.4000000000043,20.665668501695922,2.6497433997816193,-0.0965629830455863
352.60000000000434,20.70245554940335,2.6700469536114553,-0.10046792254465764
353.80000000000433,20.73956716583127,2.689455167453004,-0.10577813190891572
355.0000000000043,20.77620115145049,2.7077472692758056,-0.11058216027713774
356.20000000000437,20.812811370644642,2.727232775548499,-0.11608762211755996
357.4000000000044,20.849503089799725,2.7493000956317206,-0.1202655318442063
358.6000000000044,20.886426770589143,2.7713072058062354,-0.12502529275219443
359.8000000000044,20.92329859152529,2.794274562768539,-0.1304608711884696
361.00000000000443,20.96012891905121,2.8166777510998986,-0.13669776174754622
362.2000000000045,20.997301170804196,2.839959539965136,-0.14230494640232072
363.40000000000447,21.03406988039492,2.865202083259366,-0.14754626563293316
364.60000000000446,21.07074315420199,2.891364563973925,-0.15778019438874713
365.8000000000045,21.107068712998444,2.9178861695208917,-0.16604338906414773
367.00000000000455,21.144640455663232,2.9448210207765877,-0.1740764995115387
368.20000000000454,21.18171570796362,2.9718618779798547,-0.1820447641756462
369.4000000000045,21.21876357922354,3.0005000293717043,-0.19049708290525436
370.60000000000457,21.255692788440037,3.0298464717286624,-0.1994222527070555
371.8000000000046,21.291991064989716,3.0596894244786244,-0.20792019764807312
373.0000000000046,21.329981304187392,3.0898473150355716,-0.21722367782558738
374.2000000000046,21.367069586361808,3.1206879495842945,-0.22672777934825472
375.40000000000464,21.404117255400962,3.150850738551125,-0.23945885945331202
376.6000000000047,21.44123522976399,3.1814715776671045,-0.2504648381270602
377.8000000000047,21.47825060769103,3.2136487422547213,-0.26169677094723953
379.00000000000466,21.515330903649293,3.243870445902579,-0.27150566656206987
380.2000000000047,21.552433409496945,3.2776724362860463,-0.28274875219937323
381.40000000000475,21.58975622170326,3.3127358009181296,-0.2957493377697813
382.60000000000474,21.62670155135993,3.3465120185557087,-0.30889076200433596
383.80000000000473,21.66403889604974,3.382306257971472,-0.3220626557023114
385.0000000000048,21.701215600816713,3.4164024036261362,-0.33508557430524233
386.2000000000048,21.7387397678341,3.452459799523968,-0.349054418839426
387.4000000000048,21.775748909039,3.4908181733488877,-0.3654419755272871
388.6000000000048,21.813233564640175,3.530811830861579,-0.3814840739530543
389.80000000000484,21.850434677836134,3.5703332131475336,-0.3980272055323919
391.0000000000049,21.887955855532297,3.61218277329005,-0.41475713491642896
392.2000000000049,21.925177197516614,3.6553463508118087,-0.4316751637101435
393.40000000000487,21.962352668989812,3.699448457295791,-0.45040035981335613
394.6000000000049,21.999999689598788,3.7475996550184507,-0.46911990612774446
395.80000000000496,22.037291736910888,3.7963666861644034,-0.48842965717098696
397.00000000000495,22.074602252963402,3.8433205532363033,-0.5086638680192634
398.20000000000493,22.111823446441647,3.894151569406857,-0.5294934588260309
399.400000000005,22.149392476789306,3.946068993969038,-0.5531781955596018
400.600000000005,22.187103285146183,3.9985944698341744,-0.5768637706923632
401.800000000005,22.22461657110287,4.055111566915687,-0.599944718063635
403.000000000005,22.261903424135095,4.107427527132047,-0.6231428345995891
404.20000000000505,22.299453994952405,4.16386859949765,-0.6484438301335604
405.4000000000051,22.3367515457002,4.217591435041418,-0.676310016956617
406.6000000000051,22.37419496100008,4.272949774946186,-0.7050638532460649
407.80000000000507,22.412000778734505,4.325279867522019,-0.733249693962696
409.0000000000051,22.449524924528202,4.378709429938037,-0.7615390891649376
410.20000000000516,22.487196459441996,4.429065635380295,-0.7931959226370435
411.40000000000515,22.524476192362048,4.476952112486966,-0.8262950429922737
412.60000000000514,22.562153321667633,4.525491782689496,-0.8599071993722598
413.8000000000052,22.59953630726976,4.570751516216087,-0.8934679702728192
415.00000000000523,22.637041616101335,4.612947565595596,-0.9280499575749999
416.2000000000052,22.674784402382876,4.651340181266578,-0.963901731240731
417.4000000000052,22.712423342383865,4.6823755387845525,-1.0017473046180463
418.60000000000525,22.750014993240104,4.713055204112217,-1.041493070302915
419.8000000000053,22.787484348649855,4.7357740513871915,-1.0823672771236108
421.0000000000053,22.825263697909108,4.751437451336766,-1.1236590183654256
422.2000000000053,22.862782593608184,4.760094343252065,-1.1633439725535943
423.4000000000053,22.900193350938103,4.7593596706937795,-1.2036966806658929
424.60000000000537,22.938108285582622,4.750259744665558,-1.2469244821887822
425.80000000000535,22.97571099269211,4.730826301602295,-1.2920577973965521
427.00000000000534,23.013425258833404,4.695760424412204,-1.3359767370485822
428.2000000000054,23.051129037829753,4.651748617599177,-1.3786666065765614
429.40000000000543,23.08851378229176,4.594383016640469,-1.4212795487970897
430.6000000000054,23.12620460254932,4.520253118654586,-1.4644714127277982
431.8000000000054,23.163619160224727,4.432405626903568,-1.5092548903157543
433.00000000000546,23.201426655212604,4.3246650362672625,-1.5527526095498096
434.2000000000055,23.239050620746955,4.204352313026856,-1.59280843207776
435.4000000000055,23.27640186171862,4.067524755142969,-1.6305315061835057
436.6000000000055,23.31436669411521,3.9143010428883764,-1.6667494746153784
437.8000000000055,23.351681744993986,3.7536567446931413,-1.7007524764653787
439.00000000000557,23.3892783642877,3.583659182133486,-1.7349305888889108
440.20000000000556,23.42663983601649,3.410892408598084,-1.7650473382148233
441.40000000000555,23.464430957715045,3.239802354533892,-1.7913215761085515
442.6000000000056,23.501430519911143,3.0812409131022434,-1.8151878814630216
443.80000000000564,23.539062048737264,2.9315056898291045,-1.836307648590226
445.0000000000056,23.5764613428441,2.7994366554494197,-1.8540873629058496
446.2000000000056,23.61391874689243,2.6843552321840756,-1.8710243330533105
447.40000000000566,23.651588690535384,2.585254286661492,-1.886793272309812
448.6000000000057,23.689069071784864,2.5044077121596473,-1.9004114733892497
449.8000000000057,23.726516057600456,2.4353629785697835,-1.9123313391621357
451.0000000000057,23.764158359576065,2.3797263534170248,-1.9253357696955264
452.20000000000573,23.802008378695312,2.3329622857105834,-1.9368672512779375
453.4000000000058,23.839543685194798,2.2965958326560587,-1.9476700546266175
454.60000000000576,23.87682287623432,2.267737471150499,-1.9571044906114372
455.80000000000575,23.914896944325655,2.244130549006132,-1.9666463536613477
457.0000000000058,23.952543062442793,2.226604534665612,-1.9774709716594223
458.20000000000584,23.990473576528593,2.211634137186701,-1.9866298391228965
459.40000000000583,24.02816453606888,2.199797726300289,-1.9959226521728428
460.6000000000058,24.06595360613752,2.191388270761757,-2.005409957442709
461.80000000000587,24.10374065565253,2.1858071167583573,-2.013976527209148
463.0000000000059,24.141309962727938,2.181214911229921,-2.022822276884389
464.2000000000059,24.179181858193175,2.17623945187467,-2.031984104321482
465.4000000000059,24.217191125684703,2.174473193336765,-2.041026435049494
466.60000000000593,24.25505937347633,2.1733249514178308,-2.050025553494004
467.800000000006,24.293140372224798,2.1735589372353683,-2.060081584358627
469.00000000000597,24.331012031270554,2.1740552717136032,-2.0684940957048576
470.20000000000596,24.368951548012834,2.174717170671447,-2.076739254049934
471.400000000006,24.407031381276195,2.1762231642247487,-2.0859909106588397
472.60000000000605,24.444887527659777,2.174072143097547,-2.0954166799474327
473.80000000000604,24.483289713747432,2.1778644558686255,-2.105965735147114
475.000000000006,24.521194726620987,2.1793369136435663,-2.115214938470743
476.20000000000607,24.55903058464739,2.1799351874726853,-2.1244486793086397
477.4000000000061,24.597340062390064,2.1801522741732025,-2.1336946651051782
478.6000000000061,24.635457391135564,2.1808042310012667,-2.1434482282019838
479.8000000000061,24.67365529436153,2.1803356817382795,-2.153554756066077
481.00000000000614,24.71159579041579,2.1810448487281837,-2.162994340853227
482.2000000000062,24.749892731384982,2.1815883279149295,-2.1731608233237782
483.4000000000062,24.788045000987328,2.181814077288865,-2.183044122044226
484.60000000000616,24.82632218700402,2.180927765105232,-2.1935124451466534
485.8000000000062,24.864359048052822,2.1758239725422848,-2.202589522872278
487.00000000000625,24.902723348201622,2.174381428625814,-2.211755775571763
488.20000000000624,24.940838804887473,2.172634492936328,-2.226479725964971
489.40000000000623,24.978942152603743,2.1654659222584867,-2.2377435462962496
490.6000000000063,25.01717923877952,2.1623118489326205,-2.2475351967288386
491.8000000000063,25.055655759999436,2.1556571790227728,-2.2580463802162147
493.0000000000063,25.093986920685065,2.148454007797456,-2.2676151564577927
494.2000000000063,25.132191225722572,2.136619335783664,-2.2778251678333405
495.40000000000634,25.170549114223398,2.1225810002530827,-2.2882130625675927
496.6000000000064,25.20892345843995,2.1065045585011672,-2.2992301375937108
497.8000000000064,25.247154936022923,2.0879665354978325,-2.3093372459279173
499.00000000000637,25.285917663089894,2.065512439516949,-2.3192102008761823
500.2000000000064,25.323877278164396,2.0351933792846495,-2.328188914906383
501.40000000000646,25.362393939310948,2.0007834836726697,-2.3372223058396058
502.60000000000645,25.400595933715618,1.96537627688992,-2.3452850067407525
503.80000000000643,25.43914695612163,1.9219847635802958,-2.3513980189235406
505.0000000000065,25.477408457763058,1.881223108971888,-2.3576933543852077
506.2000000000065,25.51574145950646,1.8368922749643066,-2.3637634320996455
507.4000000000065,25.553888451139052,1.7961321258156495,-2.368682967116004
508.6000000000065,25.592461595840515,1.7596856894506336,-2.372049244222813
509.80000000000655,25.631060493456697,1.7262645758146362,-2.3753315908308688
511.0000000000066,25.66845573039546,1.6979693802203468,-2.378168959943145
512.2000000000066,25.707786651676734,1.672189016271139,-2.3791995428783634
513.4000000000066,25.7460325592567,1.6554194208174526,-2.3800864853264097
514.6000000000066,25.784415281894734,1.6396939810515974,-2.3814008924586227
515.8000000000067,25.822995690399825,1.6303115089689078,-2.3828593331402077
517.0000000000066,25.861497133488054,1.622028499821053,-2.383919858615768
518.2000000000066,25.90043319015746,1.6137705018699435,-2.3841399140893524
519.4000000000067,25.93875555448303,1.6079510234397505,-2.384140011389641
520.6000000000067,25.9772272983428,1.6048319085719016,-2.38344348683099
521.8000000000068,26.01593730644417,1.6045290771463643,-2.382176617037235
523.0000000000067,26.054320379566544,1.602745152374336,-2.382170078186211
524.2000000000068,26.0931717982915,1.6003367747314474,-2.382476993425783
525.4000000000068,26.131422646651462,1.6016365519451166,-2.383478372126644
526.6000000000067,26.17018780526411,1.6021126960317236,-2.38481908287232
527.8000000000068,26.208701436432836,1.6058522058604645,-2.3848000483579437
529.0000000000068,26.24769888214494,1.6047469299587585,-2.384864036070265
530.2000000000069,26.286087314144062,1.6129545853471825,-2.3861198077549384
531.4000000000069,26.324223349765184,1.6239781566779796,-2.3862652268623137
532.6000000000068,26.363574283025564,1.6337123646987943,-2.386087492004052
533.8000000000069,26.40202037813903,1.639865620817493,-2.3855792121012698
535.0000000000069,26.440834103203176,1.6483082079019422,-2.385129893115714
536.2000000000069,26.479645354932437,1.6532133561338163,-2.3851298399891574
537.4000000000069,26.517965711827042,1.6614130248390357,-2.3851298399999736
538.600000000007,26.557037986102564,1.667487219742888,-2.3851298400000003
539.800000000007,26.595383647885356,1.6688831573231024,-2.385129840000089
541.000000000007,26.634221961321682,1.6690494441649286,-2.3851298400941863
542.200000000007,26.67306243491845,1.6642750623949523,-2.3851297814398613
543.400000000007,26.71187328450207,1.659267295854774,-2.386350097206624
544.6000000000071,26.75080488072863,1.6551129841150614,-2.3864400040136804
545.800000000007,26.78978728383695,1.6537358822572106,-2.3864438116270916
547.000000000007,26.828472390554346,1.6524509612396114,-2.3890875787242485
548.2000000000071,26.867511505313832,1.6497973186985335,-2.3890801490357387
549.4000000000071,26.90660736416898,1.6495744456084613,-2.3890801446914813
550.6000000000072,26.944998446666506,1.6490048492872393,-2.389079789956086
551.8000000000071,26.98443202882775,1.6478311645835453,-2.3877489627637267
553.0000000000072,27.02313948468506,1.6505475623732861,-2.38776015989511
554.2000000000072,27.06194052859292,1.649795191016838,-2.3877601450123978
555.4000000000071,27.10099279926347,1.6459013947775027,-2.3877601449998886
556.6000000000072,27.140000654167206,1.644370010984564,-2.387760144999829
557.8000000000072,27.179134888234252,1.6442893454629819,-2.3877606042258828
559.0000000000073,27.21785959040085,1.641620417281174,-2.3893481470336755
560.2000000000073,27.25668880962488,1.6391825422402186,-2.390596945157455
561.4000000000073,27.296027337832808,1.6372775748196198,-2.3906100645556227
562.6000000000073,27.33497412751664,1.634500341001125,-2.39061006999833
563.8000000000073,27.373922798033668,1.637382308517835,-2.3906100699999993
565.0000000000073,27.413361004160762,1.6348399471623787,-2.3906100699999993
566.2000000000073,27.452446756250396,1.6349637993712498,-2.3906100702321016
567.4000000000074,27.49120617142254,1.6329492065696092,-2.390611142049724
568.6000000000074,27.530445001003677,1.634820388513201,-2.3919854049951805
569.8000000000075,27.56965736555234,1.6357993227070973,-2.391270231854759
571.0000000000074,27.608589367083532,1.6389245492629405,-2.391270160133073
572.2000000000074,27.64765703698198,1.6412310260396497,-2.391270159932195
573.4000000000075,27.68697116210248,1.6423742532243697,-2.39127010903607
574.6000000000074,27.72611571060315,1.6431744103389194,-2.3909346798921343
575.8000000000075,27.764311006914692,1.6431148997075697,-2.390945954882546
577.0000000000075,27.804676819377384,1.6465940336799951,-2.391601752567772
578.2000000000075,27.84382711048621,1.645283454026913,-2.3915958373055433
579.4000000000076,27.882991656407228,1.6490882753963263,-2.3928960998578392
580.6000000000075,27.922306411537217,1.6508804953150136,-2.3929108415665112
581.8000000000076,27.96169656426538,1.6560610114075696,-2.3942273319475964
583.0000000000076,28.000630786655368,1.6578396083688163,-2.3967688528457165
584.2000000000075,28.039676247084827,1.6617252398201587,-2.39641179469942
585.4000000000076,28.07908598365314,1.664409886853333,-2.3940244205288472
586.6000000000076,28.118403949556274,1.6683585003222638,-2.393899881686835
587.8000000000077,28.1574681878525,1.6705942433782541,-2.3938995391774
589.0000000000077,28.1963426250127,1.676074402656494,-2.3932219205756247
590.2000000000077,28.235875039526203,1.680517668152964,-2.393238930626517
591.4000000000077,28.27532461370467,1.6850112133045028,-2.3945787806024743
592.6000000000078,28.314218394946895,1.6889737391770878,-2.394559944643539
593.8000000000077,28.35355083604259,1.6933417621341678,-2.3945599400005104
595.0000000000077,28.393038361851254,1.6995870965371533,-2.3945599399923587
596.2000000000078,28.43225777765244,1.7037953303302937,-2.394559914648741
597.4000000000078,28.471433934037805,1.707450814286811,-2.3944912245395225
598.6000000000079,28.510802706382197,1.7123429281391789,-2.3968503232406357
599.8000000000078,28.550107930526742,1.7168874671234355,-2.396860150151921
601.0000000000078,28.589231066821934,1.7250297767321774,-2.3968600543231195
602.2000000000079,28.628824122495384,1.7276239852987725,-2.3972130758212478
603.4000000000078,28.66805372639939,1.7312425941463785,-2.398728660810524
604.6000000000079,28.70766985980269,1.7355053537854999,-2.3985043849280085
605.8000000000079,28.74653891054849,1.7431043219727695,-2.396968777999838
607.000000000008,28.786048977237044,1.7471554112543253,-2.3956590256802435
608.200000000008,28.824628623844184,1.751974799488668,-2.3968921122310594
609.4000000000079,28.864860054935576,1.75653840329658,-2.3983000382577098
610.600000000008,28.904485861454976,1.7640761061532106,-2.3982898399032546
611.800000000008,28.94378920956281,1.7717139827530357,-2.3989905850571294
613.000000000008,28.983090966500132,1.775452955131878,-2.3996002565490593
614.200000000008,29.022260855517963,1.779997280796434,-2.3996001546901518
615.400000000008,29.061720153415436,1.7867075764889946,-2.399599428259269
616.6000000000081,29.101452516583624,1.7932617996059284,-2.4009390615020285
617.8000000000081,29.141006597503544,1.7966256559685359,-2.4009198251701265
619.0000000000081,29.180100845780213,1.8020659451657648,-2.40125857003635
620.2000000000081,29.219402669188934,1.8085142638265697,-2.402230004905397
621.4000000000082,29.25892481214525,1.8172103090385987,-2.4022300649564174
622.6000000000081,29.298410747218885,1.822884329859639,-2.4022300665676157
623.8000000000081,29.338107255718647,1.8277585805693555,-2.402234887525318
625.0000000000082,29.377710327433693,1.8366932086433332,-2.4035468110180913
626.2000000000082,29.417098195805426,1.8430050539500367,-2.4035465518671844
627.4000000000083,29.456610775470274,1.8492585611088346,-2.404857310780283
628.6000000000082,29.495921631105738,1.8575390082561951,-2.404869763849578
629.8000000000083,29.535710344229177,1.8637779907253011,-2.405428095424567
631.0000000000083,29.575403167415608,1.8712289524277428,-2.406180167799961
632.2000000000082,29.61499027618431,1.882461880164702,-2.406180065038994
633.4000000000083,29.65480130193672,1.8918505509810442,-2.406180067399056
634.6000000000083,29.694281098135047,1.9007021233894617,-2.4061837497037035
635.8000000000084,29.73379422295444,1.9107099578545679,-2.407501423305879
637.0000000000084,29.773330000000286,1.9232800000000965,-2.4075001549999975
638.2000000000083,29.812955925176187,1.9355034342494521,-2.4088191527812652
639.4000000000084,29.8525390110641,1.951292575043902,-2.410127583153243
640.6000000000084,29.89203911500432,1.9624388763164031,-2.411469793744314
641.8000000000084,29.931769224468646,1.9796834560581487,-2.413009671178954
643.0000000000084,29.971332135740457,1.994410709833138,-2.4144307773717033
644.2000000000085,30.01104269040314,2.0124178730900746,-2.4156684975021934
645.4000000000085,30.05055822754007,2.0295214451545727,-2.4158664794862212
646.6000000000085,30.090171784956073,2.048987788335776,-2.417044769224753
647.8000000000085,30.12994121287226,2.0674485613450804,-2.4184429563400287
649.0000000000085,30.16964651658209,2.088506964258168,-2.4189375833937214
650.2000000000086,30.209015844173216,2.1085611215117366,-2.4198875246377654
651.4000000000085,30.248991102902057,2.128564000165184,-2.419887474924608
652.6000000000085,30.2886693641121,2.1529364959235395,-2.421219214817249
653.8000000000086,30.328528144640767,2.1757686580721183,-2.422575947229361
655.0000000000086,30.36792215638819,2.20078327282197,-2.4238713058502057
656.2000000000087,30.407629838315803,2.2231379919663956,-2.426073046251216
657.4000000000086,30.44723310677063,2.2524030411885967,-2.4282944164188938
658.6000000000087,30.48670139836644,2.2785289847845553,-2.428239961969407
659.8000000000087,30.526834688874814,2.309114657592718,-2.429657755070461
661.0000000000086,30.566702048695095,2.338567027179553,-2.4310899638118224
662.2000000000087,30.60627413402871,2.3682327001625776,-2.4325125331647497
663.4000000000087,30.645000010942496,2.401208847827408,-2.433942930862433
664.6000000000088,30.685670059658754,2.4359190366851804,-2.4356262712284877
665.8000000000088,30.72537063719694,2.4715459703809968,-2.4382105054062944
667.0000000000088,30.764934247765456,2.5054417257159196,-2.4402578755121325
668.2000000000088,30.804762398594498,2.5437875090555253,-2.4432838357712807
669.4000000000088,30.8446479843922,2.578214267402,-2.445075306530282
670.6000000000088,30.884015596417456,2.61832068537248,-2.446830626712645
671.8000000000088,30.924020925321933,2.655210996065496,-2.449929617210054
673.0000000000089,30.96345705135331,2.694792334976204,-2.4532868728517707
674.2000000000089,31.003424166473433,2.7349284197651054,-2.455484623691979
675.400000000009,31.04297651494154,2.7756641419992705,-2.457754779871567
676.6000000000089,31.082611508472553,2.8132937174677157,-2.4585726385502156
677.8000000000089,31.12236219838275,2.854843404786876,-2.462404041562861
679.000000000009,31.16212400189104,2.899202250282355,-2.4662000078248845
680.2000000000089,31.20195976620161,2.9424053760417457,-2.4688810812946604
681.400000000009,31.241597817010128,2.987945604832967,-2.4716679921458615
682.600000000009,31.281346835475794,3.0286081154269238,-2.4750112049787227
683.800000000009,31.321555007798548,3.0747039132160308,-2.479309140737082
685.0000000000091,31.36114207491364,3.121817818343949,-2.482805958368587
686.200000000009,31.401060677205205,3.163716968929199,-2.4849659589501885
687.4000000000091,31.44056274211663,3.2051034360909796,-2.4887312868427633
688.6000000000091,31.48054091494733,3.250009941694723,-2.490643381778242
689.800000000009,31.52046713451659,3.291961653689138,-2.4942808086141444
691.0000000000091,31.560130632487276,3.339072207337685,-2.496908930033684
692.2000000000091,31.60016163054593,3.3840513922118856,-2.500861554158802
693.4000000000092,31.640231135862958,3.429548750753565,-2.5053459496085715
694.6000000000092,31.67929982716822,3.4713897382836603,-2.5102527645719057
695.8000000000092,31.720000322253696,3.5169403820349414,-2.5144400568465897
697.0000000000092,31.759901269808246,3.564047276162884,-2.5188227108185903
698.2000000000093,31.79952732976861,3.608569336257326,-2.5232178518212334
699.4000000000092,31.83993225304057,3.6577563668429285,-2.528809022831854
700.6000000000092,31.87961066532108,3.7032212434392724,-2.5332760184326806
701.8000000000093,31.919375278036668,3.7486590390482766,-2.537754598056855
703.0000000000093,31.959386396657113,3.795048257187737,-2.543520499586038
704.2000000000094,31.999649642704806,3.842925608383756,-2.5486493807077113
705.4000000000093,32.039400567266895,3.890133032891158,-2.553444452227607
706.6000000000093,32.07953428828983,3.9387299212639766,-2.559120171431357
707.8000000000094,32.1194806893082,3.9844604626273834,-2.563583474192608
709.0000000000093,32.1595277793639,4.032698143077164,-2.5698723628332827
710.2000000000094,32.19939633091039,4.075452266070039,-2.574067727683806
711.4000000000094,32.23977193437353,4.1244229988492345,-2.578457749730026
712.6000000000095,32.27948627741341,4.170561934529009,-2.5844913068928146
713.8000000000095,32.31954867713634,4.215519250868296,-2.590249175759406
715.0000000000094,32.359470542268554,4.264618855855159,-2.5967333376905506
716.2000000000095,32.39963250219971,4.310405015466804,-2.602808184657016
717.4000000000095,32.439692580724106,4.359308669285495,-2.6099024470302012
718.6000000000095,32.47973230903362,4.408691807967337,-2.61434436791932
719.8000000000095,32.52013615926429,4.461870587455288,-2.620429588509776
721.0000000000095,32.560350829939985,4.517168375103896,-2.6264697710152003
722.2000000000096,32.60009818153736,4.572696982743546,-2.632801702240797
723.4000000000096,32.6405363490199,4.64262290417891,-2.6393627170751808
724.6000000000096,32.68026939000756,4.716157191849994,-2.645551953036071
725.8000000000096,32.72051207338199,4.798895726063971,-2.6522288866031287
727.0000000000097,32.760533085722656,4.890720015215293,-2.659305301465591
728.2000000000096,32.80083455361786,4.990962559227137,-2.6666078575932732
729.4000000000096,32.84104018883348,5.100556604486403,-2.6741760835568575
730.6000000000097,32.88119880860051,5.2164502339064835,-2.681753404374626
731.8000000000097,32.92120971172534,5.331572707109062,-2.6896801297262547
733.0000000000098,32.96144910322526,5.455781456446865,-2.698916151889425
734.2000000000097,33.001801569148704,5.580086322760478,-2.707345865745591
735.4000000000098,33.04199235818238,5.702092389357617,-2.7173650018004283
736.6000000000098,33.082101196185135,5.8217121094998525,-2.727382976490838
737.8000000000097,33.12245596039652,5.943469619634791,-2.737219609348555
739.0000000000098,33.16268544798357,6.062590629306127,-2.7469542564426863
740.2000000000098,33.20307093525427,6.17480680658368,-2.757303576942477
741.4000000000099,33.24329048988936,6.288093748057613,-2.7676959410178155
742.6000000000099,33.28344554759497,6.396246374161015,-2.778125661122252
743.8000000000098,33.32391727823454,6.501224421833261,-2.789610251148509
745.0000000000099,33.36411399997161,6.602000920237151,-2.8013694899586836
746.2000000000099,33.40478885280637,6.695943897967487,-2.812682959788398
747.4000000000099,33.44508815967328,6.788414548448728,-2.8250006342830414
748.6000000000099,33.484925043602146,6.869350982083399,-2.8363870689879804
749.80000000001,33.5256973669207,6.9469209505485585,-2.8487300654380543
751.00000000001,33.56626073542512,7.0146494125692636,-2.862260715088277
752.20000000001,33.60627037174859,7.07203464895329,-2.8744284007902285
753.40000000001,33.646836744830445,7.114401921786206,-2.8865268431246536
754.60000000001,33.68718806558354,7.1403468919618085,-2.8980836167415225
755.8000000000101,33.72749353086701,7.148571078001389,-2.911028694682179
757.00000000001,33.76756440630598,7.1294565328114805,-2.9233357450871935
758.20000000001,33.807978256759,7.078398702426034,-2.936191078927216
759.4000000000101,33.84833654684987,6.985146314667913,-2.9503859937113073
760.6000000000101,33.88780373407724,6.839904804309602,-2.95987730174531
761.8000000000102,33.929061594407266,6.612490425063072,-2.972173679113048
763.0000000000101,33.969369728318675,6.289371065641503,-2.9864743508839933
764.2000000000102,34.009230762109596,5.846525230963578,-2.996429977428226
765.4000000000102,34.04916021652696,5.145604828251774,-3.0062418542292164
766.6000000000101,34.0894632443632,4.101993851869748,-3.014317272112401
767.8000000000102,34.129188344635565,3.368190289480383,-3.018193253813056
769.0000000000102,34.16882130782779,2.932677019992318,-3.0187287746515477
770.2000000000103,34.20887399238758,2.6728074831651174,-3.0199896980062104
771.4000000000103,34.24902141476212,2.5132722061376698,-3.0199900991006317
772.6000000000103,34.28908006010939,2.4186804380032347,-3.020157809409864
773.8000000000103,34.32958307378028,2.358431698362733,-3.0213001441359557
775.0000000000103,34.36947636524349,2.3251767507676617,-3.021299870093329
776.2000000000103,34.40980272590011,2.2981758050547203,-3.0212998726187377
777.4000000000103,34.450250593085855,2.284167329228446,-3.0213122657992133
778.6000000000104,34.49044054164076,2.2744904343974968,-3.0203201454024495
779.8000000000104,34.530638804360464,2.268648518208838,-3.0199683380372946
781.0000000000105,34.571082150161004,2.26403881022188,-3.0199898613089067
782.2000000000104,34.61137509881988,2.2641456316840203,-3.0199898699950376
783.4000000000104,34.651838725060934,2.2675711279018533,-3.0199898688390525
784.6000000000105,34.69199188213701,2.2683529306859453,-3.0199869833262323
785.8000000000104,34.73258885597365,2.2718939451619637,-3.0213070204996715
787.0000000000105,34.77268817544252,2.2766518999101817,-3.0213099590782155
788.2000000000105,34.81323331167715,2.2805134642912406,-3.021309958272038
789.4000000000106,34.85332934628819,2.2856698847740886,-3.021309927288574
790.6000000000106,34.89379048985615,2.292324186378293,-3.0226202629056393
791.8000000000105,34.93414119997318,2.295608286073303,-3.022620181506299
793.0000000000106,34.97434774462161,2.3027996201265797,-3.022637882448119