File: 01_Data/Basswood_Panel/STA/N2/3K_min/Basswood_Panel_STA_N2_3KData_220314_R1.csv
##Temp./Â°C,Time/min,DSC/(mW/mg),Mass loss/mg
51.0,11.266456787632398,-1.0911359750005254,-0.06100737644198784
52.100000000000016,11.802908628274777,-1.0482062984076603,-0.06429499235650615
53.20000000000003,12.253971543159336,-1.0280307814882097,-0.06306932250830899
54.30000000000005,12.680429174401219,-1.0160401684698857,-0.0655434660154075
55.40000000000006,13.093146579777724,-1.0076218223295266,-0.0657310250333043
56.50000000000008,13.303298647416131,-1.0092341659272805,-0.06700994399803628
57.600000000000094,13.90170073746855,-0.9939953948730009,-0.0683203894985942
58.70000000000011,14.298683074235802,-0.9878609146921986,-0.06963707594105761
59.800000000000125,14.682810745125913,-0.9815370898756935,-0.07096011643974842
60.90000000000014,15.06406973106884,-0.9748656657123155,-0.0716071033986041
62.000000000000156,15.445287919908619,-0.9717480936403948,-0.07381098340491077
63.10000000000017,15.824006607762325,-0.9662595839493497,-0.07359020763589053
64.20000000000019,16.200827943608534,-0.960832885772153,-0.07458014699548388
65.30000000000021,16.568531155790645,-0.9571154692637754,-0.07491568976264062
66.40000000000022,16.948855365492044,-0.9548719900948135,-0.07588806764025069
67.50000000000023,17.328044990045765,-0.9501972355807123,-0.08181614525194814
68.60000000000025,17.6981828136434,-0.9465941840034392,-0.08247187159149316
69.70000000000027,18.063090417292116,-0.943101073317715,-0.08050034530931649
70.80000000000028,18.43884834134698,-0.9411876501294992,-0.08274799356085083
71.90000000000029,18.809399337895357,-0.936298930480457,-0.08039608014946831
73.00000000000031,19.18160658718679,-0.9349806583642185,-0.08379394566287335
74.10000000000034,19.54779625859,-0.9326243169689055,-0.08446616053248679
75.20000000000034,19.92123025646736,-0.9280388110898024,-0.08530731540683378
76.30000000000035,20.285155950957495,-0.9259085008677718,-0.08510434226995756
77.40000000000038,20.65034997546173,-0.9236662407693684,-0.08771625786071846
78.5000000000004,21.01800202680167,-0.9219752990592219,-0.08839915955937672
79.6000000000004,21.390978796748225,-0.9201443964524841,-0.08848002622678486
80.70000000000041,21.75664203127243,-0.9150960297007492,-0.08698693579401207
81.80000000000044,22.12453398159348,-0.9133014724588298,-0.0879611356603105
82.90000000000046,22.4898701671261,-0.9088320745014928,-0.08938774129433957
84.00000000000047,22.84608539602956,-0.90704288685832,-0.08907299936122293
85.10000000000048,23.21413546750715,-0.9023477346399459,-0.09023078308020649
86.2000000000005,23.58050622265085,-0.9030188887897982,-0.09111853141682902
87.30000000000052,23.95440299232375,-0.9011076356016277,-0.0916375733192738
88.40000000000053,24.316430734737498,-0.8967195720622358,-0.09169293627922581
89.50000000000054,24.68214368704555,-0.8935145617472464,-0.09201983820200743
90.60000000000056,25.049929224131873,-0.8909501777867072,-0.09298170919322324
91.70000000000059,25.418364729008395,-0.8848559037366459,-0.09432923078726851
92.8000000000006,25.781456220867575,-0.8828922549869026,-0.09366023059718875
93.9000000000006,26.146115408911506,-0.8783938992002154,-0.09305134308666085
95.00000000000063,26.510220371315523,-0.8753349795545634,-0.09436164837985084
96.10000000000065,26.874078916453872,-0.8709983745791342,-0.09432117661084849
97.20000000000066,27.236745809110975,-0.8693860395186567,-0.0956400683128864
98.30000000000067,27.60407330430765,-0.8652737398141956,-0.0949733183697492
99.40000000000069,27.967637783450336,-0.8640607282555496,-0.09621239422046024
100.50000000000071,28.332500000000373,-0.8591099999999825,-0.09596006045761118
101.60000000000072,28.698047153215835,-0.8559207944353986,-0.0982699999490797
102.70000000000073,29.06837267983605,-0.8517146935927602,-0.09786320450796193
103.80000000000075,29.43213582183785,-0.8491922019558837,-0.09960201447975603
104.90000000000077,29.797457751778964,-0.8443507344135311,-0.09875401869138667
106.00000000000078,30.161639522752036,-0.8381326557318629,-0.09846298646275686
107.10000000000079,30.52943679896208,-0.8356072434611613,-0.09860273222434834
108.20000000000081,30.886021402523784,-0.8340990088054298,-0.09829029350461216
109.30000000000084,31.255611791971894,-0.8293057722831317,-0.0995345321342187
110.40000000000084,31.615830000000287,-0.8280299999999996,-0.09863301340043451
111.50000000000085,31.974876937686354,-0.8206655507801068,-0.09919667313293301
112.60000000000088,32.337006640916165,-0.8177427687450579,-0.09925988080814774
113.7000000000009,32.699170000000315,-0.8137900000000061,-0.09992014678391703
114.8000000000009,33.05901442229891,-0.8093972154322926,-0.10128200670453325
115.90000000000092,33.42243229736126,-0.8087141152859673,-0.10248633426873743
117.00000000000094,33.78815869679453,-0.8047412755652243,-0.10151517831923274
118.10000000000096,34.15052632690793,-0.8033473139441585,-0.10319980789005223
119.20000000000097,34.521179695747946,-0.7965282967602785,-0.10417704390149973
120.30000000000098,34.87937766502095,-0.79071220974685,-0.10188972644480376
121.400000000001,35.240436260008835,-0.7865639480286712,-0.10434440302779624
122.50000000000102,35.601932586215895,-0.7836104891526577,-0.10385983602628723
123.60000000000103,35.963324111716325,-0.781042145826553,-0.10378576369678827
124.70000000000104,36.32139257147354,-0.7788214013353533,-0.10692120287873408
125.80000000000106,36.68607560844989,-0.7752087499432104,-0.10550951197394287
126.90000000000109,37.04637226187786,-0.7728164266390631,-0.10485275516668446
128.00000000000108,37.4106390392974,-0.7686861287748931,-0.10620904570578515
129.1000000000011,37.772243441333714,-0.7657580188961717,-0.10656168411618028
130.20000000000113,38.1286350244545,-0.7599778017082313,-0.10748986400027549
131.30000000000115,38.49003404604773,-0.7588076770434615,-0.10650111014344255
132.40000000000117,38.853438375851006,-0.756940049545668,-0.1078315407425019
133.50000000000117,39.218532883387844,-0.7516756172792536,-0.10808604486663143
134.6000000000012,39.58099286160132,-0.7477439862385503,-0.10847426533021975
135.7000000000012,39.943248934320344,-0.7449089903519687,-0.108799927999772
136.8000000000012,40.304125754605444,-0.7422306128248447,-0.10945829194130008
137.90000000000123,40.661030742160875,-0.7385051061639292,-0.10930516422987235
139.00000000000125,41.028060270656376,-0.735034656890015,-0.1101102168927266
140.10000000000127,41.39053530361829,-0.730838494130552,-0.11038950256528901
141.2000000000013,41.74768116979339,-0.726611918472911,-0.11041333013357812
142.3000000000013,42.1067888011936,-0.7238257649578312,-0.11076951938416757
143.4000000000013,42.468288420796995,-0.7221946687219755,-0.11230980253320322
144.50000000000134,42.82783032909195,-0.7182023005490984,-0.11329790600889478
145.60000000000133,43.19173852272945,-0.7145361297644331,-0.11198811435873512
146.70000000000135,43.55162571128478,-0.7113886458327185,-0.11284801736665262
147.80000000000138,43.9132789617742,-0.7069207164688476,-0.11429566947673653
148.9000000000014,44.27136575382249,-0.7053595742766722,-0.11363095158695025
150.00000000000142,44.6314539144067,-0.7021944506168645,-0.11427152362101056
151.10000000000142,44.9897308163531,-0.6967759643144119,-0.11645647373079315
152.20000000000144,45.35323109723452,-0.6965687124273198,-0.11614020733838082
153.30000000000146,45.71296706112588,-0.6897404124572465,-0.11602420611974784
154.40000000000146,46.06998305825797,-0.6849234375601183,-0.11669298556080143
155.50000000000148,46.426938610317386,-0.6820290196809909,-0.11617190331328464
156.6000000000015,46.78690249748313,-0.680114969179205,-0.11637109556961489
157.70000000000152,47.145153644162484,-0.675401056878369,-0.11504107225521842
158.80000000000155,47.50971811437613,-0.6733144949260973,-0.11735748831002235
159.90000000000154,47.86148463371741,-0.6692886112844475,-0.1177373788842031
161.00000000000156,48.22306772514384,-0.6636053718880012,-0.11798320285703623
162.1000000000016,48.57951320562095,-0.6628907374848012,-0.11966615577999917
163.20000000000158,48.938582009829446,-0.6594509382117387,-0.11982669910925914
164.3000000000016,49.303677024741305,-0.6564893820553248,-0.11866156789850635
165.40000000000163,49.66052905278535,-0.6514436796552651,-0.12103279680054824
166.50000000000165,50.02359219189647,-0.6469508764574676,-0.11998631943724103
167.60000000000167,50.381348795349346,-0.644101142596599,-0.11998005999999961
168.70000000000167,50.739461465194445,-0.639081537304386,-0.12130617859294146
169.8000000000017,51.092775196426864,-0.6354630682113713,-0.12130114820909421
170.9000000000017,51.45526558804498,-0.6329849112115432,-0.1226107371642926
172.0000000000017,51.81205601937691,-0.6298889833928546,-0.12283577340059981
173.10000000000173,52.1738396751425,-0.6248570530056844,-0.12315828527151274
174.20000000000175,52.53115156171462,-0.6215987939186963,-0.12474820064799141
175.30000000000177,52.88812318871181,-0.618239970101625,-0.1259099679283473
176.4000000000018,53.25136051175398,-0.6144594164990455,-0.1255800313280968
177.5000000000018,53.61099764987778,-0.611335561315366,-0.1282097772266133
178.6000000000018,53.97275573353049,-0.6057156130519173,-0.12820983686667198
179.70000000000184,54.326960143153656,-0.6019445875204765,-0.13012410512271133
180.80000000000183,54.69030597005231,-0.5970759602516473,-0.1305223538923861
181.90000000000185,55.03889690994625,-0.593477716795429,-0.13010157650956522
183.00000000000188,55.39862120766089,-0.5897653243206986,-0.13215765184955552
184.1000000000019,55.755698088012394,-0.5847318077606221,-0.1331500799430656
185.20000000000192,56.11348129403235,-0.583214926511441,-0.13309931870180725
186.30000000000192,56.47185944052081,-0.5790685178315835,-0.13449681621255394
187.40000000000194,56.824737356704546,-0.5749212193717218,-0.13643225937636316
188.50000000000196,57.180392241310045,-0.5718936471318623,-0.13578034456356658
189.60000000000196,57.54457381235314,-0.5698831019216164,-0.13839586514327173
190.70000000000198,57.90349413086882,-0.5661738766487362,-0.1384128138725531
191.800000000002,58.248211637139,-0.5630674627533024,-0.14073490186150872
192.90000000000202,58.61697408759465,-0.5587358382459858,-0.1433565828292549
194.00000000000205,58.97284425945641,-0.5563558857044754,-0.14280751231802657
195.10000000000204,59.33423657959693,-0.5517802367623389,-0.14564882917398947
196.20000000000206,59.69204161005443,-0.5473480021422429,-0.1459854750629046
197.3000000000021,60.04747696321047,-0.5432332328948274,-0.14791346170517494
198.40000000000208,60.40289527969135,-0.5410735448206851,-0.15058267787732715
199.5000000000021,60.76221946087169,-0.5362199294026638,-0.1526237483450883
200.60000000000213,61.117582712888876,-0.5307915418817256,-0.15454007607983034
201.70000000000215,61.47762965806763,-0.5264807214257053,-0.1557105927272482
202.80000000000217,61.831768400097516,-0.5228229990889064,-0.15750233693746596
203.90000000000217,62.187491324324505,-0.5212417302163075,-0.16059861021853417
205.0000000000022,62.546009382146494,-0.519857690685186,-0.1621042209438901
206.1000000000022,62.90602731125378,-0.5170821527560322,-0.16395126186172115
207.2000000000022,63.268330578016524,-0.5119831443549528,-0.16671005708882003
208.30000000000223,63.62371156156202,-0.5075259372449633,-0.17023744393572215
209.40000000000225,63.98250341780446,-0.5048299004438531,-0.17215406406747258
210.50000000000227,64.33342832259525,-0.49985009143921294,-0.1738920484638946
211.6000000000023,64.68722374236232,-0.496233964477663,-0.17704388683362682
212.7000000000023,65.04643527134088,-0.495820265264545,-0.17981465549186915
213.8000000000023,65.40425108874255,-0.49608415929399297,-0.18252662476204629
214.90000000000234,65.76463712178212,-0.49153130372612375,-0.18478169090003593
216.00000000000233,66.12158342032748,-0.48574028976730005,-0.1870965525788879
217.10000000000235,66.47703688557463,-0.48348337591939444,-0.18987630525342958
218.20000000000238,66.8338004183826,-0.47991530917705766,-0.19369943907292253
219.3000000000024,67.18891815241433,-0.47612135608237344,-0.19619542220063835
220.40000000000242,67.55009128768103,-0.47334100681158997,-0.20027409198943324
221.50000000000242,67.90532937506981,-0.47039900419211894,-0.20290281651217557
222.60000000000244,68.25957585059359,-0.47049918069154184,-0.20487950548014622
223.70000000000246,68.6181202610431,-0.46718196973412596,-0.20883182627654762
224.80000000000246,68.97728116474867,-0.46324859574839056,-0.2132270089378796
225.90000000000248,69.33286005954177,-0.46144230719358026,-0.2170600587360676
227.0000000000025,69.69379606263547,-0.45844972345505774,-0.21944135376843388
228.10000000000252,70.05226515770948,-0.4531301615425295,-0.22295224682561932
229.20000000000255,70.4113005512167,-0.45074548949404125,-0.22745513407921747
230.30000000000254,70.76653980690617,-0.4482473458096741,-0.23153234787091925
231.40000000000256,71.12294445400427,-0.4445552580846742,-0.23515499510469873
232.5000000000026,71.47570010390427,-0.44566829180178574,-0.24072628419022113
233.60000000000258,71.83350724493128,-0.44512818582182617,-0.24538810015111245
234.7000000000026,72.19113372128606,-0.44297195036152354,-0.24827252655892362
235.80000000000263,72.54822755140653,-0.4394980920789458,-0.2532015842104287
236.90000000000265,72.90597600872653,-0.4375917262112123,-0.25786268460880013
238.00000000000267,73.26192211333651,-0.43490710466815097,-0.2631085436915468
239.10000000000267,73.62077266239177,-0.42970038937154104,-0.26978068817512435
240.2000000000027,73.97750502572711,-0.426713240018381,-0.2748312205010395
241.3000000000027,74.32956341030558,-0.4227309428180618,-0.28021440162190414
242.4000000000027,74.68896332413246,-0.41853589153628007,-0.2857079981456785
243.50000000000273,75.04312674623182,-0.4166175724777049,-0.2931630398893055
244.60000000000275,75.40360609974718,-0.4120056925165104,-0.29961531955140375
245.70000000000277,75.76252203631546,-0.4109222107381529,-0.3056429803346443
246.8000000000028,76.11622145902685,-0.408069876312086,-0.31349633895343887
247.9000000000028,76.47247702318644,-0.40576481301168044,-0.31984032587827693
249.0000000000028,76.83460576196524,-0.3993582141180294,-0.328238747121103
250.10000000000284,77.188248617268,-0.39698073885089297,-0.3360677337172455
251.20000000000283,77.53251718994824,-0.3931802947130852,-0.3433285214379418
252.30000000000285,77.89812252068546,-0.3876075794412719,-0.35367481125255784
253.40000000000288,78.25449929312012,-0.3865159604957321,-0.36209245639688925
254.5000000000029,78.61165755611609,-0.38457907517795537,-0.37422497058005266
255.60000000000292,78.96973794268747,-0.38023437544068134,-0.38332001241841906
256.7000000000029,79.32908773741015,-0.377794902422578,-0.3950208535121553
257.8000000000029,79.6834570252537,-0.37527927484725787,-0.4049579765278768
258.90000000000293,80.04219665014197,-0.3712307028630679,-0.4174597079480393
260.00000000000296,80.39968815916902,-0.3665568850724612,-0.42963597004906173
261.100000000003,80.75317903709163,-0.3639556219421456,-0.44369705905779133
262.200000000003,81.10562764618103,-0.3591762863209786,-0.45601567813979793
263.300000000003,81.46201863674347,-0.3575079512842647,-0.4707943321815793
264.40000000000305,81.81724459586502,-0.35527041515676927,-0.4862610092156361
265.50000000000307,82.17994390542701,-0.3518275361292278,-0.4996850752392503
266.6000000000031,82.53627321117239,-0.3506750407351173,-0.5173984055501566
267.7000000000031,82.89134635782011,-0.34864266566387336,-0.5330008396033641
268.8000000000031,83.25321015453773,-0.34425762971349966,-0.5515226357525389
269.9000000000031,83.61095742935616,-0.34199837671640604,-0.5679508054588096
271.0000000000031,83.96779554817446,-0.33838819382585844,-0.5848096684067112
272.10000000000315,84.32510200690713,-0.3361292408338958,-0.6057410720176013
273.2000000000032,84.67966668801142,-0.33279186521096094,-0.6252937168111745
274.30000000000314,85.03683887572575,-0.3311687617831701,-0.6407471107836487
275.40000000000316,85.39225466832588,-0.32793717594104743,-0.6618488688315556
276.5000000000032,85.7491700000011,-0.326360000000041,-0.6824600920000683
277.6000000000032,86.10717915100786,-0.3243533890145136,-0.7018379102024044
278.70000000000323,86.46478569284317,-0.3220185859344675,-0.724694168083488
279.80000000000325,86.82575063501285,-0.3197523599856695,-0.7453915163544829
280.9000000000033,87.1806049084415,-0.3140690034254778,-0.7658787318646465
282.0000000000033,87.53360604529098,-0.3106840718864287,-0.7862908343069348
283.1000000000033,87.89097440390786,-0.30656217384096496,-0.8092568561427989
284.20000000000334,88.24553346163043,-0.30598079281177953,-0.8299745893920241
285.30000000000337,88.60280684626322,-0.30236886484370623,-0.8512864531213697
286.40000000000333,88.96074173763866,-0.2963609715191425,-0.8747737287515394
287.50000000000335,89.32092592983486,-0.2955532634834294,-0.8974491571262817
288.6000000000034,89.67747405574947,-0.29543568711591356,-0.9177048096882454
289.7000000000034,90.0362089015981,-0.294303884368962,-0.9410395286641919
290.8000000000034,90.39781740498782,-0.2873382531798841,-0.9633018912722711
291.9000000000034,90.75621512377383,-0.2811763506817762,-0.9843515418032771
293.0000000000034,91.1097261940595,-0.2768073575007784,-1.0080888362166807
294.10000000000343,91.46024412634223,-0.2730103951445208,-1.0299399254239892
295.20000000000346,91.82328357108837,-0.269539545590967,-1.0500438423161684
296.3000000000035,92.18108361612994,-0.26677591129130035,-1.0740195123325704
297.4000000000035,92.54005716459477,-0.2604841744527332,-1.0954550673264483
298.5000000000035,92.89605070828097,-0.25530848947534934,-1.119883582169265
299.60000000000355,93.25303246654005,-0.24971144086156358,-1.1427255005918866
300.70000000000357,93.61101343251863,-0.24683704593147404,-1.1642415498039025
301.8000000000036,93.96163383045246,-0.24135840276616494,-1.1864528639816094
302.9000000000036,94.32898877526513,-0.23583261835653851,-1.2117391183005153
304.0000000000036,94.68764963089086,-0.2304919770170556,-1.2356117016429073
305.1000000000036,95.05091318253471,-0.22341744806280694,-1.2609464113039168
306.2000000000036,95.40504475669314,-0.2179684627261694,-1.2858641053664406
307.30000000000365,95.76149572432047,-0.21363503818134497,-1.310047033038778
308.4000000000037,96.12333842433225,-0.20660828291146993,-1.3360978315572338
309.5000000000037,96.47882889867226,-0.2013436408161502,-1.3628969915320575
310.60000000000366,96.83629297995924,-0.1944870777135779,-1.3886185128896384
311.7000000000037,97.19625403531991,-0.18814238523115584,-1.4167816972638931
312.8000000000037,97.55331978837516,-0.18209270069316924,-1.4436126725319873
313.90000000000373,97.91301036401089,-0.17507902682267323,-1.4728379456657237
315.00000000000375,98.27186047348104,-0.16687312975784213,-1.5026381490796745
316.1000000000038,98.62749306003546,-0.1615968869046001,-1.5321415597038999
317.2000000000038,98.98626650459613,-0.15459751897221596,-1.5659190827373681
318.3000000000038,99.34689268615855,-0.14799909208683962,-1.5979948293423973
319.40000000000384,99.71187644843248,-0.1391742387842299,-1.6297312616368838
320.5000000000038,100.07167462025916,-0.13169368948844246,-1.6650917776742715
321.60000000000383,100.42708542444852,-0.12419247448439803,-1.699985325338873
322.70000000000385,100.7848918631193,-0.1147546502452907,-1.7368179399778274
323.8000000000039,101.14483738795349,-0.10896477252930303,-1.7743018840440623
324.9000000000039,101.5069027065924,-0.10373090523602713,-1.8142970979994528
326.0000000000039,101.86418018158083,-0.09472130583197663,-1.8530586217988776
327.10000000000394,102.22741260719182,-0.08664753353926613,-1.8967735642017058
328.2000000000039,102.58752391085316,-0.07987076895504985,-1.938037928446735
329.30000000000393,102.94731294636301,-0.07164337534032697,-1.9819793903817318
330.40000000000396,103.30970154591756,-0.0661735963028667,-2.028336424559717
331.500000000004,103.66684981260155,-0.05768801656284146,-2.074167701496406
332.600000000004,104.02266768608223,-0.050926727378676394,-2.1217049626629123
333.700000000004,104.38167652245505,-0.04555153159842819,-2.169587818553294
334.80000000000405,104.74390841324829,-0.04021959459096835,-2.2183830064005217
335.90000000000407,105.09566786448973,-0.03623361748276681,-2.2697294723025934
337.0000000000041,105.45808469635539,-0.03397817350764164,-2.320817316600592
338.10000000000406,105.81910443476396,-0.032908508245315535,-2.372260278119183
339.2000000000041,106.1788747691568,-0.03162915901888431,-2.4233980242076094
340.3000000000041,106.53117782848693,-0.032919529618135546,-2.4748778646474543
341.4000000000041,106.89880707208158,-0.03469187264240296,-2.526231014823723
342.50000000000415,107.26056072607815,-0.03783042847920836,-2.57566253608584
343.6000000000042,107.62271496558259,-0.04511708505707491,-2.6263593351037766
344.7000000000042,107.98059383551897,-0.05124812908191472,-2.6727119432016124
345.80000000000416,108.33944633547532,-0.059957696322739625,-2.717823641329793
346.9000000000042,108.69880745456302,-0.07160313573179047,-2.7620431934299994
348.0000000000042,109.05745378828249,-0.0819256082048113,-2.7992046720369883
349.10000000000423,109.41458338923613,-0.09722049204193187,-2.8346727150944586
350.20000000000425,109.7737432170369,-0.1123885818267212,-2.867986411409314
351.3000000000043,110.13644774504779,-0.12769118121654002,-2.8976422019399046
352.4000000000043,110.49451506969153,-0.1428960519370819,-2.922669234564408
353.5000000000043,110.8549020862011,-0.15595674878055085,-2.9448528282070052
354.60000000000434,111.21774715646511,-0.16860194440775747,-2.9628762162846702
355.7000000000043,111.57724069494238,-0.17763176290013946,-2.978403781143248
356.80000000000433,111.93684372184754,-0.18278935460199372,-2.9896262374542966
357.90000000000435,112.29751392408777,-0.1877274482000518,-3.0002758208267735
359.0000000000044,112.65045533282704,-0.18870567096362778,-3.0084657420417202
360.1000000000044,113.00930345714737,-0.19008973356659611,-3.013746636794539
361.2000000000044,113.37289804854572,-0.18925947264390452,-3.0209201527208713
362.30000000000445,113.73517501034378,-0.18780863478751936,-3.027162633955233
363.4000000000044,114.09709087399763,-0.1874264826544686,-3.0328096306099734
364.50000000000443,114.4538644449501,-0.18334703481443085,-3.038047570508949
365.60000000000446,114.81672494363968,-0.1788387590690066,-3.042018804113998
366.7000000000045,115.175870343591,-0.17837592214710646,-3.0485636336478255
367.8000000000045,115.5379084865861,-0.17517057630045413,-3.052541279510785
368.9000000000045,115.89974182002115,-0.17345045430218323,-3.0564889549371226
370.00000000000455,116.26535561795374,-0.1702511034739497,-3.0604620742050574
371.10000000000457,116.62451155983038,-0.16918031891612442,-3.064728760715597
372.2000000000046,116.98352151020617,-0.1653963085429899,-3.0690493728663526
373.30000000000456,117.34659015213848,-0.16182115205490194,-3.072943533092822
374.4000000000046,117.70496262681667,-0.1593699614250702,-3.075572639304517
375.5000000000046,118.06686057499353,-0.15513474270170985,-3.08084006545916
376.6000000000046,118.42938239400607,-0.15710842860303015,-3.083553093645687
377.70000000000465,118.79265124244688,-0.1548532841985675,-3.0887517567657428
378.8000000000047,119.15324784345863,-0.15032750417919302,-3.09255342319205
379.9000000000047,119.51647655991023,-0.14692458429920413,-3.0956667857207645
381.00000000000466,119.88390101207023,-0.14465247026760514,-3.098292325465953
382.1000000000047,120.2428465610511,-0.14267294508992967,-3.1032295964193874
383.2000000000047,120.59955344381405,-0.14003089925637147,-3.107181447351788
384.30000000000473,120.95992252105817,-0.13635909627043427,-3.1108342858518405
385.40000000000475,121.32208035052139,-0.13404877618122993,-3.1137567335855043
386.5000000000048,121.6800511651029,-0.13028484170269938,-3.1177107354364364
387.6000000000048,122.0443714174041,-0.12878377491378212,-3.120220970537143
388.7000000000048,122.40046035208253,-0.12502890062436187,-3.123000685685036
389.80000000000484,122.76494334773993,-0.12251337109539989,-3.125609367200492
390.9000000000048,123.13072134165931,-0.12145490561471954,-3.132174936954578
392.00000000000483,123.48978463726259,-0.11787243921733286,-3.1338156325051565
393.10000000000485,123.85636807556305,-0.1152011040717255,-3.1380098276862407
394.2000000000049,124.2189165198365,-0.11186512514080298,-3.141542254854549
395.3000000000049,124.58379875205905,-0.10855975792292696,-3.145789163586758
396.4000000000049,124.94254047066225,-0.10623732960144114,-3.149086271004479
397.50000000000495,125.30190328641469,-0.1006774888060539,-3.149285828314524
398.6000000000049,125.66899306318506,-0.09755390987754883,-3.1556469413517236
399.70000000000493,126.02957295909154,-0.09467415817008049,-3.157203754200719
400.80000000000496,126.39112237997978,-0.09187748532307285,-3.1618100630915644
401.900000000005,126.75407366586612,-0.08774018328732042,-3.164100627357721
403.000000000005,127.11583000000181,-0.08507400000005205,-3.1694357090161205
404.100000000005,127.47748958039486,-0.0817379154825706,-3.171345764057767
405.20000000000505,127.84015294873626,-0.0799374475444012,-3.175306816027889
406.30000000000507,128.20318238417582,-0.0752270075389885,-3.176661270737021
407.4000000000051,128.56791247882452,-0.07272018829997871,-3.179252721150048
408.50000000000506,128.93405060692123,-0.06768846991636315,-3.1841642645233477
409.6000000000051,129.29202705342425,-0.06357305283810238,-3.185378697616911
410.7000000000051,129.65642341083344,-0.061250457218236465,-3.1893935378917133
411.8000000000051,130.02206198845772,-0.056106674868391986,-3.1932721054998723
412.90000000000515,130.38012003706467,-0.05210128618801444,-3.194700979842672
414.0000000000052,130.74591644263103,-0.049247901730944475,-3.198636886721285
415.1000000000052,131.1020233807979,-0.045079765580541165,-3.2022803980886128
416.20000000000516,131.46467889855614,-0.04212555684310384,-3.2042519380238295
417.3000000000052,131.82820972862348,-0.03883723564413535,-3.205531034135371
418.4000000000052,132.18906472602487,-0.03248629492886011,-3.2075079093679024
419.50000000000523,132.54819187221636,-0.027366819421578197,-3.2107734113023083
420.60000000000525,132.90722418725719,-0.02698727929765614,-3.2134984153870874
421.7000000000053,133.26956204349108,-0.022186517978474558,-3.2155366347137453
422.8000000000053,133.63364265194247,-0.018891470459305035,-3.219300223002462
423.9000000000053,133.9981144537632,-0.014261415591153095,-3.2210326545041807
425.00000000000534,134.36547876876037,-0.01068792787456226,-3.2226002060684893
426.1000000000053,134.72652832901755,-0.006003449705255495,-3.227651081184353
427.20000000000533,135.08654531948628,-0.003990834811967748,-3.23026114439095
428.30000000000535,135.45551200105822,0.00028976827659862696,-3.2302413065255062
429.4000000000054,135.81542555225857,0.005596729312566678,-3.2351617632253085
430.5000000000054,136.17732463147905,0.008358804447454026,-3.2357890957164024
431.6000000000054,136.54421692691227,0.014321890061462757,-3.2371595659620116
432.70000000000545,136.91269619085497,0.01714606249379907,-3.2397838829459973
433.8000000000054,137.27343123417413,0.021077333893650144,-3.2417711470134973
434.90000000000543,137.6411767609763,0.025339828075253184,-3.243079946643671
436.00000000000546,138.00318733403427,0.028365259657443985,-3.245068217125604
437.1000000000055,138.36646759661923,0.03304714115774323,-3.2465895042784587
438.2000000000055,138.72884578728772,0.0373569956818116,-3.2480165309465705
439.3000000000055,139.09385354140798,0.04021259627862678,-3.252954874328924
440.40000000000555,139.4566744255325,0.04593185972401537,-3.2516460550356387
441.50000000000557,139.82211307674208,0.04894679509919298,-3.2552580265015085
442.6000000000056,140.18097847191115,0.05321934652048809,-3.2565439214767897
443.70000000000556,140.542730003013,0.058829129561137894,-3.2592002549503816
444.8000000000056,140.90850912253444,0.06315514913010863,-3.2591612749771013
445.9000000000056,141.2758198878777,0.06597774122725301,-3.262467710327904
447.0000000000056,141.63890179231956,0.07084472967507247,-3.264787089947976
448.10000000000565,142.00033130889875,0.07410978430262692,-3.265771074136783
449.2000000000057,142.36739125879205,0.07876130766099111,-3.2661945894897775
450.3000000000057,142.7327998555016,0.0831172359665323,-3.2687383008105595
451.40000000000566,143.098852804217,0.08811283228068542,-3.2707350214397115
452.5000000000057,143.4624615223405,0.0942567583826471,-3.272148011412541
453.6000000000057,143.82749544712783,0.10120125844256177,-3.273316581601693
454.70000000000573,144.1928715186325,0.10671523567477402,-3.2769495231607118
455.80000000000575,144.5588641954328,0.11193398330672666,-3.2756402402377285
456.9000000000058,144.92503178010855,0.11722728465983887,-3.278278418744436
458.0000000000058,145.28535145110993,0.11861711377345859,-3.279347832722181
459.1000000000058,145.6499034838369,0.12217104710360932,-3.2809137050595285
460.20000000000584,146.0095019881516,0.12643565938320436,-3.2828505672350765
461.3000000000058,146.3743806129985,0.130589464948523,-3.2848675587671896
462.40000000000583,146.73649290121125,0.13628972683876575,-3.2855278460190567
463.50000000000585,147.10383575146142,0.14299385506029705,-3.2868476932336916
464.6000000000059,147.46659698973343,0.14654911243886112,-3.2881484321825716
465.7000000000059,147.83411157021558,0.15338749899121384,-3.2884951319772764
466.8000000000059,148.19852744397065,0.1552975068667297,-3.290655886421329
467.90000000000595,148.5612946983682,0.15732342549237446,-3.290679706541194
469.0000000000059,148.93208859778602,0.16235052358494173,-3.2920006125196113
470.10000000000593,149.2930069752915,0.1634759464069513,-3.2943035410116632
471.20000000000596,149.6643955144968,0.16799624469697505,-3.2956199610730317
472.300000000006,150.03135303997595,0.16867540875578693,-3.296278581282502
473.400000000006,150.3956721663982,0.17042971780049435,-3.2972622892648853
474.500000000006,150.76670041721354,0.17180085690236255,-3.297811794280746
475.60000000000605,151.13281979224166,0.17066075335049063,-3.2991250177177944
476.70000000000607,151.49555342966232,0.17122513911960285,-3.300440036017629
477.8000000000061,151.85920453067703,0.17264688886457655,-3.3016904626894714
478.90000000000606,152.2178441746155,0.1768525733102817,-3.30201720938873
480.0000000000061,152.58194774262702,0.18252246188260204,-3.303290230430714
481.1000000000061,152.94615341439538,0.1853906781751072,-3.3046198568341643
482.2000000000061,153.31311145683605,0.18535879499281083,-3.3072400642182034
483.30000000000615,153.68632519803893,0.18536236469784598,-3.3072498872286213
484.4000000000062,154.05471329570545,0.18820784841277466,-3.308574232839751
485.5000000000062,154.42134341405531,0.18994946415111863,-3.308898030672053
486.60000000000616,154.78368542979513,0.1920654070266604,-3.3102100750264727
487.7000000000062,155.1488286904449,0.19359537780995092,-3.3102095053389466
488.8000000000062,155.51308504225125,0.19722010878684093,-3.312512818651746
489.90000000000623,155.87901896606286,0.19722895838561624,-3.3115211555147717
491.00000000000625,156.24988203622308,0.20126634153492698,-3.3131645922535315
492.1000000000063,156.61618281188615,0.2043627244360295,-3.3134836794137374
493.2000000000063,156.9834698072568,0.20672502947302177,-3.315469884598035
494.3000000000063,157.3511730251785,0.21041711854769415,-3.3167890620368397
495.40000000000634,157.7165987293913,0.21107233664345934,-3.3167877332753375
496.5000000000063,158.07842985722044,0.2147206400352208,-3.317779836067973
497.60000000000633,158.43878807588482,0.21982320687499335,-3.3187654634879897
498.70000000000636,158.80411244278736,0.22434085175215868,-3.320740079480167
499.8000000000064,159.17023200587562,0.22696660378618236,-3.3194200528125393
500.9000000000064,159.539260562312,0.2307943621754304,-3.322049922935783
502.0000000000064,159.89952284681925,0.23366349072697318,-3.3223266914592053
503.10000000000645,160.27057377635117,0.23897788689308924,-3.3231726881682113
504.2000000000064,160.63850643929615,0.24114666232346416,-3.324690003931021
505.30000000000643,160.99325349306235,0.24562064191191946,-3.3246899802250165
506.40000000000646,161.36873557828434,0.2500539855252008,-3.3253402662954827
507.5000000000065,161.73142758089458,0.2534058045278711,-3.326990945486221
508.6000000000065,162.10295776951097,0.25838033905019353,-3.3289727012891954
509.7000000000065,162.47075143809107,0.26200810874916003,-3.328310967236307
510.80000000000655,162.84087175385372,0.2679003636632053,-3.3289864070474504
511.90000000000657,163.20685301296345,0.27209247722087965,-3.3302793741259444
513.0000000000066,163.57205767254803,0.27467967130594545,-3.3327074038083517
514.1000000000065,163.93754855915574,0.27798037215849414,-3.333239547563551
515.2000000000066,164.30383465272,0.28324443938666805,-3.332529685724112
516.3000000000065,164.66677847464283,0.28855151454082534,-3.3329100296678007
517.4000000000067,165.03600002522555,0.29214060460214886,-3.3342426694888263
518.5000000000066,165.4033271851501,0.2954601142625135,-3.3352869709474326
519.6000000000067,165.77082539671338,0.29837266979879745,-3.3363215501630403
520.7000000000066,166.13804514105797,0.3058458599718774,-3.336838017841289
521.8000000000067,166.5054824737865,0.3090342277855098,-3.3388290477041958
522.9000000000067,166.87476432311178,0.31315308904077005,-3.338170108
524.0000000000067,167.24263079665045,0.31850978239093314,-3.3395992185297256
525.1000000000067,167.6095783990706,0.32250181313249565,-3.3392197758534916
526.2000000000068,167.96923732309423,0.32647379094714624,-3.339795401084683
527.3000000000068,168.3408109669654,0.32977849595684555,-3.34131130580801
528.4000000000068,168.7079258188362,0.3347156100583328,-3.342739824171548
529.5000000000068,169.07399896043216,0.3388751187785335,-3.3427776315887563
530.6000000000068,169.4444579797308,0.3433790333031841,-3.344099952367458
531.7000000000069,169.81284291856403,0.34608249379757067,-3.3454319819813367
532.8000000000068,170.17920262352945,0.35449799635029755,-3.3454121938948833
533.9000000000069,170.54655103778668,0.3584418328229461,-3.3467286248895927
535.0000000000068,170.9094890167068,0.36298732534211403,-3.34573676227332
536.100000000007,171.2837756629098,0.36631154229081264,-3.34837039060699
537.2000000000069,171.6513034927929,0.37115770027478395,-3.3490300313136334
538.300000000007,172.0228602101435,0.3738501340799653,-3.3503889899318353
539.4000000000069,172.3872095258982,0.3783300147833694,-3.3516392109568596
540.5000000000069,172.7528179414922,0.38455167690447145,-3.3523301786856385
541.600000000007,173.11961905486064,0.3891631954994337,-3.350967371973198
542.700000000007,173.48838704794835,0.3942499777447489,-3.353314293516283
543.800000000007,173.85141601821562,0.3983463351631318,-3.353318558387765
544.900000000007,174.22034630870223,0.400740617300629,-3.353724006383871
546.000000000007,174.58628989031712,0.40617844891850485,-3.3552904590916994
547.1000000000071,174.95308717900133,0.41290707755256034,-3.3546864189611156
548.2000000000071,175.31975308723364,0.4142955214745627,-3.355949847059257
549.300000000007,175.6925202833972,0.42086994151081114,-3.3565941499323513
550.4000000000071,176.05744196125605,0.42486616314354725,-3.357590120627502
551.500000000007,176.42470305166609,0.4289018111052968,-3.3598922640366347
552.6000000000072,176.79114175434802,0.4352197781184964,-3.3598966527692746
553.7000000000071,177.1569680968325,0.4378001036836838,-3.3608791251226595
554.8000000000072,177.52655665738155,0.44239807261626535,-3.3608899990211603
555.9000000000071,177.89669592233003,0.4455669690262119,-3.3612199884477274
557.0000000000072,178.26873547629597,0.4518000613042989,-3.362520593666594
558.1000000000072,178.63882833304666,0.45772557656197577,-3.363380375133695
559.2000000000072,179.00537938960483,0.4611458832514553,-3.362849978618133
560.3000000000072,179.3750365164945,0.4646247253044288,-3.3628118532727846
561.4000000000073,179.74328526763753,0.47004325986280776,-3.3654732393880122
562.5000000000073,180.10824317157574,0.4755484384089093,-3.3641698508679
563.6000000000073,180.4737790159443,0.47765553181655307,-3.364793616401613
564.7000000000073,180.84167789923504,0.4839915061844508,-3.3654901079997948
565.8000000000073,181.21034128513097,0.4884426367950852,-3.36779035354364
566.9000000000074,181.57827418602096,0.49411555390534945,-3.3677869764749255
568.0000000000074,181.944868544705,0.49786416648109133,-3.36812057942377
569.1000000000074,182.31701898357423,0.5037169682607814,-3.3697347827578383
570.2000000000073,182.68438528113538,0.507956615694993,-3.3694413215976895
571.3000000000073,183.05120570079748,0.5151633357088482,-3.3694400155059485
572.4000000000074,183.42556596944243,0.5199861308974739,-3.3701194931259373
573.5000000000074,183.7968966308366,0.5235837419343662,-3.3700973031658332
574.6000000000074,184.165527539841,0.5253308520654881,-3.370589465594499
575.7000000000074,184.5316932000844,0.5325877800855958,-3.3704201240020417
576.8000000000075,184.899801054372,0.539954399594791,-3.370420099166286
577.9000000000075,185.27116034580908,0.5426795636653495,-3.372877753464767
579.0000000000075,185.64065280976615,0.5495559776388366,-3.3730650012670895
580.1000000000075,186.00705099514522,0.5551429028666474,-3.373920504781685
581.2000000000075,186.37804878914324,0.5578450625624878,-3.371897838889103
582.3000000000076,186.74602910233926,0.56343214500251,-3.3743131886179496
583.4000000000076,187.11835881755997,0.5680572348804503,-3.3747000363404824
584.5000000000076,187.48287650924638,0.5723443573189556,-3.3746999871472765
585.6000000000076,187.84438577405123,0.5779282484320019,-3.3750296513755185
586.7000000000077,188.2198014982279,0.5817602797681698,-3.375380610778929
587.8000000000077,188.5812252168824,0.5880707580478852,-3.3756884640629963
588.9000000000076,188.95496316308422,0.592167379451346,-3.3766052872788714
590.0000000000076,189.32089464205845,0.5978626248795711,-3.376663711373938
591.1000000000076,189.69426874197956,0.606002820481011,-3.3773303209447096
592.2000000000077,190.06392553531794,0.6087065734750743,-3.38052195749402
593.3000000000077,190.4349794551223,0.6125085833232286,-3.3782266647528667
594.4000000000077,190.8093496722442,0.6179317016941429,-3.3799044147560298
595.5000000000077,191.1814352640054,0.6216537011833565,-3.379630061904295
596.6000000000078,191.55177652768586,0.6280016698695198,-3.3795989734605563
597.7000000000078,191.92032268106223,0.6306483844146299,-3.3806896758382257
598.8000000000078,192.28997181238114,0.636975255511496,-3.380877361259785
599.9000000000078,192.658164455998,0.64337677647955,-3.3819784148744327
601.0000000000078,193.02693542123598,0.6489590937427734,-3.381944594051702
602.1000000000079,193.3934652871388,0.6533076503019987,-3.3805968651055336
603.2000000000079,193.76379084767478,0.6583573475423448,-3.383260087985933
604.3000000000079,194.1318427717951,0.6617681101724351,-3.3826002189056137
605.4000000000078,194.50436892830515,0.6676819183341228,-3.38391976545838
606.5000000000078,194.87269569977516,0.672804218445097,-3.3837271304812493
607.6000000000079,195.24032119049946,0.6776806854247412,-3.3847999714844965
608.7000000000079,195.61500942760117,0.682574281960403,-3.3848001751549965
609.8000000000079,195.98653585624237,0.6882522641490125,-3.3854596458093265
610.9000000000079,196.35599843074417,0.6941177561374826,-3.384959216723851
612.000000000008,196.72641588036302,0.6992893674832943,-3.3861435240221107
613.100000000008,197.08959187735442,0.7040863086484268,-3.3874302052541374
614.200000000008,197.4624269956287,0.7082798230932451,-3.3867701999912208
615.300000000008,197.83060305474805,0.7154530658950886,-3.3874299305455597
616.400000000008,198.20286876585888,0.7202816043049539,-3.386770296814479
617.5000000000081,198.57748485214123,0.7235948998944711,-3.38841018887798
618.6000000000081,198.94500159632554,0.732189671219772,-3.3872358322384772
619.7000000000081,199.31908509284838,0.7376980096818718,-3.385719917038459
620.8000000000081,199.6866520212844,0.7409793676469215,-3.3881165430252267
621.9000000000082,200.05257849371944,0.7449199839788216,-3.3894274817104177
623.0000000000082,200.42359861921472,0.7526690408245248,-3.388967828830438
624.1000000000081,200.79148692044134,0.7593950709902783,-3.3894003261363514
625.2000000000081,201.16373421671554,0.7658837491595523,-3.3900478268603815
626.3000000000081,201.53321920168474,0.7697465006707958,-3.3916999613939844
627.4000000000082,201.90159641693415,0.7775774669479685,-3.3913715614987034
628.5000000000082,202.28007460566567,0.783790009468655,-3.3897304633672047
629.6000000000082,202.64849409318717,0.7873758240181522,-3.3910431878005696
630.7000000000082,203.01270491346267,0.7927122920129172,-3.3913824563867045
631.8000000000083,203.3813581245892,0.8000041704605786,-3.3923609295568378
632.9000000000083,203.74625830266538,0.8071132728846239,-3.392663378128831
634.0000000000083,204.11985183094853,0.8091165439660293,-3.393115347969491
635.1000000000083,204.49133208209432,0.8125426705779997,-3.3926756540218843
636.2000000000083,204.86287430288348,0.8183703974962625,-3.3940002479567575
637.3000000000084,205.22887396423337,0.823394365593192,-3.3928837510678553
638.4000000000084,205.60445167256321,0.8306174893917052,-3.3949895970948436
639.5000000000084,205.97562948558345,0.8367830643988885,-3.396310121886953
640.6000000000083,206.35215330066026,0.8392908305370579,-3.396310123998504
641.7000000000083,206.72035612933564,0.8446614135351479,-3.3972755792184675
642.8000000000084,207.09345958482385,0.8501696630160012,-3.396969803247708
643.9000000000084,207.46446247431666,0.8577970545046906,-3.3976054754812455
645.0000000000084,207.83641318129574,0.8609323866053534,-3.397955382366149
646.1000000000084,208.20589417577304,0.8668766724090721,-3.3979690018667013
647.2000000000085,208.5760638232113,0.8733342541674272,-3.3986202018454303
648.3000000000085,208.94580488354669,0.8773504942946724,-3.396871938077188
649.4000000000085,209.31851239675012,0.8842948621287758,-3.3982906833253503
650.5000000000085,209.6931412017416,0.8909686930055526,-3.400014097504735
651.6000000000085,210.06583712539506,0.897529565239371,-3.3976298300208816
652.7000000000086,210.43566003022968,0.9024929973229062,-3.397127922212844
653.8000000000086,210.80534870786823,0.9071482938978929,-3.398939850147774
654.9000000000086,211.16426805249117,0.9141627857888993,-3.3985712455187014
656.0000000000086,211.54885729239936,0.9200269593994318,-3.3986202478406007
657.1000000000087,211.91948494970282,0.9246827627834383,-3.3999297481965707
658.2000000000087,212.30470283969137,0.9325555162504137,-3.3992788239193383
659.3000000000086,212.67829651879154,0.9373332328918107,-3.39958816645691
660.4000000000086,213.0507517892396,0.9447634856222339,-3.3982883501707377
661.5000000000086,213.420356742529,0.9482152570703971,-3.4002084046515546
662.6000000000087,213.7917340618967,0.9529378517718494,-3.4001501491866
663.7000000000087,214.15882967918193,0.9602035980805886,-3.4004783720188696
664.8000000000087,214.5298457569057,0.965834743009671,-3.4004875320496524
665.9000000000087,214.89916378240878,0.9749892646198359,-3.399500047640104
667.0000000000088,215.2700783947187,0.9818229333445057,-3.4014581825695833
668.1000000000088,215.6396222750175,0.988434372566114,-3.4006647170109634
669.2000000000088,216.01546289277428,0.9969672359762547,-3.398390204484094
670.3000000000088,216.38699452506415,1.0025358499831751,-3.399709955387999
671.4000000000088,216.74566127134392,1.0102915718843413,-3.400355663739934
672.5000000000089,217.1258013561896,1.0155354398172471,-3.4013601585469013
673.6000000000089,217.4980474938405,1.0193956821188674,-3.4000402141531567
674.7000000000089,217.86549027640208,1.0276979822025312,-3.401350041338244
675.8000000000088,218.2400271171776,1.036196718101369,-3.4000278384497107
676.9000000000088,218.60771891782412,1.0444168844011148,-3.399127878297171
678.0000000000089,218.9789170897456,1.0514700950814146,-3.3998188633220625
679.1000000000089,219.35017764294,1.0597364568513397,-3.4000723313688814
680.2000000000089,219.7220711308518,1.0691014075946785,-3.4015956599971546
681.3000000000089,220.0924454366196,1.0762058517007256,-3.399479270901406
682.400000000009,220.46464227307584,1.0810650483243318,-3.3995117303952154
683.500000000009,220.84018118975985,1.0908164557375275,-3.3979109045748337
684.600000000009,221.207615132965,1.0988339428235199,-3.397730004272039
685.700000000009,221.58151137833,1.1082221833206571,-3.4036634705675017
686.800000000009,221.94659405662566,1.1130781948883413,-3.399366372119739
687.9000000000091,222.3252923357363,1.1195981134132098,-3.3970685365426774
689.0000000000091,222.6973961040747,1.129066816120993,-3.411371689744685
690.1000000000091,223.06663252063433,1.138656064215671,-3.403101303384583
691.2000000000091,223.43148173118735,1.1443773680123965,-3.400803155149474
692.3000000000092,223.80828341004653,1.1513399466374103,-3.400817494901635
693.4000000000092,224.1781421253072,1.1590445372547415,-3.4011298296845824
694.5000000000091,224.54990372199907,1.164151243308223,-3.401789807279183
695.6000000000091,224.91692464811993,1.1729087874401873,-3.4008110121220616
696.7000000000091,225.2918687942045,1.1797842414750979,-3.4014700104061486
697.8000000000092,225.66547481510776,1.1867754006546911,-3.402125566562275
698.9000000000092,226.03899900463622,1.1958865744256422,-3.402119572086206
700.0000000000092,226.4106422017865,1.201751705046125,-3.402456352490405
701.1000000000092,226.78701805893337,1.2070203935004398,-3.402450393657212
702.2000000000093,227.1635100881325,1.215430232340697,-3.4040234966545455
703.3000000000093,227.5363035678901,1.2233093957662455,-3.4037745554093455
704.4000000000093,227.90124458707993,1.2329622054352878,-3.4032566419278223
705.5000000000093,228.2710847498359,1.239924461676409,-3.4040925833926132
706.6000000000093,228.63860170026194,1.2480887881277953,-3.4040382376730722
707.7000000000094,229.01307951642244,1.255177132527255,-3.404750092457842
708.8000000000094,229.38283240430263,1.2620743633278688,-3.404430159994988
709.9000000000094,229.75559566512138,1.2705029876021117,-3.404734543006206
711.0000000000093,230.13218993191856,1.2787032463833856,-3.404355972783165
712.1000000000093,230.50031688410255,1.2857786380652798,-3.407050112548796
713.2000000000094,230.87860301397419,1.2890436723620935,-3.407720100072334
714.3000000000094,231.24917358756858,1.2983699573113627,-3.4077207875677935
715.4000000000094,231.61871248118754,1.3045297344622413,-3.4080584038959625
716.5000000000094,231.9862355788912,1.3127407866257843,-3.4073801999974678
717.6000000000095,232.35999641301646,1.3198113592815772,-3.4086284255584904
718.7000000000095,232.73318296452575,1.3230666896865415,-3.408381122709947
719.8000000000095,233.10841140724474,1.330590387637948,-3.4084054912837662
720.9000000000095,233.47418507037204,1.3384052458275593,-3.4083801033964223
722.0000000000095,233.8427883050644,1.34644228676029,-3.40969993599534
723.1000000000096,234.21291418602948,1.3527395039359553,-3.411007449406339
724.2000000000096,234.57063836682616,1.3615693636773245,-3.4100388793002576
725.3000000000096,234.95852388224606,1.36883677486479,-3.411016556990614
726.4000000000096,235.3283634887042,1.3753610605899507,-3.4110099080369594
727.5000000000097,235.70288645711884,1.3829721325795026,-3.411669902226463
728.6000000000097,236.07639991661608,1.3898943840302853,-3.41198930795707
729.7000000000096,236.4504421284385,1.397566052961344,-3.411352998566705
730.8000000000096,236.8253414854721,1.4024905962641727,-3.4133101847477856
731.9000000000096,237.20283634026507,1.4130525924210642,-3.4139645227521815
733.0000000000097,237.57064699808427,1.416900105752293,-3.413239961608898
734.1000000000097,237.94236345409797,1.4250079249221739,-3.413967272961511
735.2000000000097,238.31407740654302,1.43098735447043,-3.4146301496790747
736.3000000000097,238.68700286123456,1.4360444205634597,-3.4139698632148825
737.4000000000098,239.05641857091481,1.4471635378429504,-3.416618669151555
738.5000000000098,239.4338038608053,1.454098118490192,-3.415285325001161
739.6000000000098,239.80233442738344,1.4598207927589348,-3.4162307695603404
740.7000000000098,240.17337960510355,1.4651862195815548,-3.416922618309472
741.8000000000098,240.54486336252955,1.4703157233695512,-3.416600578813576
742.9000000000099,240.9184259929976,1.4767275872042038,-3.4179667090155155
744.0000000000099,241.29043107193468,1.485110359368947,-3.417797019829587
745.1000000000099,241.66446717954295,1.494846195533363,-3.417589859984724
746.2000000000098,242.04102824913414,1.500067933175434,-3.4189745873977166
747.3000000000098,242.4137589119763,1.504003194024908,-3.4182400630028487
748.4000000000099,242.78953540549867,1.5142348009970599,-3.4199698209503104
749.5000000000099,243.15819946215768,1.5188591420193363,-3.4179379202330438
749.90000000001,243.29065451788833,1.5198278381316972,-3.4195595306016062