File: 01_Data/EIFS_Mesh/STA/N2/30K_min/EIFS_Mesh_STA_N2_30KData_230908_R2.csv
##Temp./Â°C,Time/min,DSC/(mW/mg),Mass loss/mg
41.0,10.57637844904236,-2.2962855990751954,0.025326411578022956
42.100000000000016,10.759702617219897,-2.2574393237898263,0.026033794813279165
43.20000000000003,10.881093119797901,-2.2263754241054485,0.024598882014958967
44.30000000000005,10.97561403759381,-2.202825632593975,0.025799554392834878
45.40000000000006,11.056929578707745,-2.1805009790147865,0.02398718398584787
46.50000000000008,11.133706530199097,-2.1574796469570763,0.024092228923053405
47.600000000000094,11.202237165889445,-2.1388876478830046,0.025544515044773952
48.70000000000011,11.265159272362787,-2.1196700603043617,0.026065111380026096
49.800000000000125,11.324122287781904,-2.102074971479309,0.02454351905462815
50.90000000000014,11.380414453523699,-2.0858702601930603,0.024599417310086302
52.000000000000156,11.435392705410504,-2.0686890275732788,0.02426920273581512
53.10000000000017,11.487173629192053,-2.0526285647660605,0.02436333434191873
54.20000000000019,11.537676587750719,-2.038222572456919,0.024322477256627728
55.3000000000002,11.58647302837443,-2.023425358891351,0.024842839336134404
56.40000000000022,11.63415898720931,-2.010315383929436,0.024062357674283774
57.500000000000234,11.680567750923483,-1.9977392934166711,0.02302524304914666
58.60000000000025,11.726560677862691,-1.98664867883329,0.023433679756863057
59.700000000000266,11.771343432822208,-1.9765867817932552,0.023923127007162925
60.80000000000028,11.81610298464627,-1.9669000077303975,0.02601923513526483
61.9000000000003,11.859202509952938,-1.9564818665618597,0.0248898687003809
63.00000000000031,11.902209277407016,-1.9487230655632526,0.023848508797128076
64.10000000000034,11.944544545349785,-1.9411562270594354,0.02442196487864745
65.20000000000034,11.98627619735794,-1.9346848272044799,0.02212569377935658
66.30000000000035,12.027673237422892,-1.9280025742819265,0.022879403946829413
67.40000000000038,12.069295698327831,-1.9225578720138448,0.02356474116876317
68.5000000000004,12.109927311773914,-1.9178199613557898,0.02314921670190717
69.6000000000004,12.150548121175953,-1.9132225244908805,0.023565511869277245
70.70000000000041,12.190895011075916,-1.9081988732822093,0.02305305363690735
71.80000000000044,12.230907406358064,-1.9026843528401196,0.022603347445953048
72.90000000000046,12.270632419615879,-1.899844145737021,0.02225813282159983
74.00000000000047,12.310493399999078,-1.8967659552221172,0.021972594439599646
75.10000000000048,12.349859053380225,-1.8912708953068051,0.021854865700176695
76.2000000000005,12.389572119936465,-1.8901406039747002,0.021534449105525155
77.30000000000052,12.427915096441891,-1.8852383785724587,0.02154022261796662
78.40000000000053,12.468082215407058,-1.8836916857407702,0.021095889783130595
79.50000000000054,12.506167158729342,-1.8803644867757616,0.020334351559675667
80.60000000000056,12.544793034084863,-1.877587399377263,0.020006730809556394
81.70000000000059,12.583338917104768,-1.8728530723598988,0.018681168026534856
82.8000000000006,12.62226941979905,-1.8703456953883557,0.018157952242227715
83.9000000000006,12.660141899029467,-1.8643189558111182,0.018764712907814562
85.00000000000063,12.698515775719324,-1.860013130016676,0.01875107044496005
86.10000000000065,12.736534162615069,-1.8552789444590327,0.01801058874167083
87.20000000000066,12.773992399862646,-1.849862263630028,0.017449849642557247
88.30000000000067,12.811905805368259,-1.846795813855338,0.017448421896060218
89.40000000000069,12.84930306295444,-1.8407115061792698,0.01744916329698576
90.50000000000071,12.887062809222948,-1.834385632235656,0.0166523004021073
91.60000000000072,12.924240714183643,-1.8290713495770998,0.01616884821296516
92.70000000000073,12.961150068538613,-1.8231088882519324,0.01586479656075568
93.80000000000075,12.998534851218066,-1.8182825577079662,0.016137534704129486
94.90000000000077,13.035843862375916,-1.8106983978426583,0.014815810115885064
96.00000000000078,13.072667287139435,-1.8050216373518806,0.014824539030196426
97.10000000000079,13.109489043982862,-1.7977383874885136,0.0135101225470029
98.20000000000081,13.146514749562439,-1.7900899371672747,0.014651834840980094
99.30000000000084,13.183693958670904,-1.784246218218325,0.013381513661373745
100.40000000000084,13.220573767161273,-1.7782584877404346,0.013489664554859893
101.50000000000085,13.256966119101152,-1.769120231765598,0.013492828005875701
102.60000000000088,13.292984243297258,-1.7637999174879955,0.012496299831701307
103.7000000000009,13.330199181779351,-1.755837410193581,0.012175599317074237
104.8000000000009,13.366692124529319,-1.7502511136130436,0.01087880578480771
105.90000000000092,13.40314799360387,-1.742399617411247,0.010909171157285513
107.00000000000094,13.439637250936613,-1.73476313487311,0.011805083692310703
108.10000000000096,13.476420386207288,-1.7276136056389746,0.010531181894553931
109.20000000000097,13.512531672822748,-1.7207426174635865,0.010530010098793952
110.30000000000098,13.549176712529375,-1.713607064947716,0.010530000011427454
111.400000000001,13.585287519114766,-1.7056945462186635,0.010530028075597997
112.50000000000102,13.621909603435771,-1.6988792308788425,0.01053324011432899
113.60000000000103,13.658141437630764,-1.6927763956387594,0.00919996024623071
114.70000000000104,13.694218965489968,-1.6836924637573965,0.009207823299814955
115.80000000000106,13.730591742357912,-1.6775139795754244,0.007821828831286126
116.90000000000109,13.76697361381007,-1.6689588263822341,0.007900913502713713
118.0000000000011,13.803428585768529,-1.6627186727882906,0.007900009743718961
119.1000000000011,13.839178457602532,-1.6549358682783595,0.007900000303087573
120.20000000000113,13.875236793887796,-1.6461655281357876,0.007900339742834106
121.30000000000115,13.911406361262525,-1.6407723321051841,0.007917695757820198
122.40000000000116,13.947450512361263,-1.6337550958373148,0.007246118354191644
123.50000000000117,13.98337788846452,-1.6268192905971488,0.007224618709423147
124.60000000000119,14.019098585069464,-1.6195821341095407,0.006580755407025407
125.70000000000121,14.055233567170578,-1.6120251098384464,0.006583111060974645
126.80000000000122,14.090705105763524,-1.6052880002345735,0.005855962449269114
127.90000000000123,14.126977212784997,-1.5979726392241589,0.004055180556936655
129.00000000000125,14.16154681990722,-1.592886623504342,0.003941031946409268
130.10000000000127,14.197973028844594,-1.5842481414942047,0.00393999320008831
131.2000000000013,14.233371896141751,-1.5770221604601597,0.003939999893994184
132.3000000000013,14.268830349777694,-1.5697709830561253,0.003940000002212507
133.4000000000013,14.30463867913347,-1.5619830811992481,0.003940001512398261
134.50000000000134,14.339495436994076,-1.55363137228701,0.003939995135563201
135.60000000000133,14.374792664314018,-1.5446106557379538,0.00392317189531699
136.70000000000135,14.409805379390159,-1.5406904648320676,0.0025912688104199333
137.80000000000138,14.444888022238807,-1.531917240022598,0.0026207318141358016
138.9000000000014,14.480498620672568,-1.523498178326665,0.0026200051512725864
140.00000000000142,14.515724867381905,-1.5172403241042174,0.0026181679131811464
141.10000000000142,14.550418885255576,-1.5094477203013847,0.0025939265687346946
142.20000000000144,14.585727156886,-1.501154075589564,0.0013116329840050511
143.30000000000146,14.620456532997197,-1.4957311751242814,0.0013110548886352547
144.40000000000146,14.655197187496015,-1.4868709260570125,0.0023756326031323383
145.50000000000148,14.68977724617667,-1.4820269556504888,0.0026201327175954248
146.6000000000015,14.724830718694976,-1.4724605837837392,0.002620018221144882
147.70000000000152,14.759483031181142,-1.464386685826179,0.0026199999684441977
148.80000000000155,14.794224176052465,-1.4577536516403162,0.002620000002456102
149.90000000000154,14.82904549850533,-1.4506112931557422,0.002619999818164409
151.00000000000156,14.863229851966349,-1.4436115425632112,0.002619969019267643
152.1000000000016,14.897863684870787,-1.4381967275541623,0.002622834400632712
153.20000000000158,14.932804092782956,-1.4307428554212187,0.0015490995412870134
154.3000000000016,14.96659175355417,-1.423423993206081,1.3699862098093263e-06
155.40000000000163,15.00183549814566,-1.416094417522823,5.837135219621814e-08
156.50000000000165,15.036261125207902,-1.410742461830217,-4.2198466942977575e-10
157.60000000000167,15.070806905700728,-1.4062157556484998,-4.345857007592713e-12
158.70000000000167,15.104869459975037,-1.399217213394758,7.935874180020619e-12
159.8000000000017,15.13975158032907,-1.391757049885297,2.6979662948178884e-10
160.9000000000017,15.17404179361819,-1.3862892771923316,-7.728830642150797e-08
162.0000000000017,15.208148992452427,-1.3807863507130431,3.1191776894701206e-07
163.10000000000173,15.242648855775624,-1.3761504500991126,-0.0012926551988368118
164.20000000000175,15.275875766263134,-1.3683641824832693,-0.001320117757245498
165.30000000000177,15.31103587284951,-1.363152782749671,-0.0013200093087348819
166.4000000000018,15.34547112229204,-1.359508467873163,-0.0013193393920452046
167.5000000000018,15.3788080455601,-1.3543419654177684,-0.001288653115667504
168.6000000000018,15.414011865411846,-1.3503539351704885,-0.0009876115674121166
169.70000000000184,15.448066273461016,-1.344558841541851,-0.0011816501100971877
170.80000000000183,15.482337087133478,-1.3407364620663522,-0.002316142474667604
171.90000000000185,15.51641847637828,-1.334744732513821,-0.0023099062396076953
173.00000000000188,15.550521616749721,-1.330183548456921,-0.0023099998011950618
174.1000000000019,15.58459087626122,-1.3267658683845562,-0.0023100000110467533
175.20000000000192,15.6186189240611,-1.3215228816397415,-0.002310000072698326
176.30000000000192,15.652787789025739,-1.3175645188626117,-0.002310013217978746
177.40000000000194,15.686811673243474,-1.313848514034542,-0.00230880118661414
178.50000000000196,15.720862393147145,-1.3093652486784386,-0.0026930868418446607
179.60000000000196,15.754214976794335,-1.305384857870227,-0.0046782991172578114
180.70000000000198,15.788802907872373,-1.3004822171727903,-0.00462059007924287
181.800000000002,15.8225156475829,-1.2977083346273122,-0.004691186994079555
182.90000000000202,15.856157174021131,-1.2943560208858533,-0.004955082972207148
184.00000000000205,15.890147090087476,-1.2893415872765237,-0.003653734436659839
185.10000000000204,15.92419229553001,-1.2870023737586447,-0.003629645262197556
186.20000000000206,15.957795687031064,-1.283531295827288,-0.003630031395521538
187.3000000000021,15.991489622121568,-1.2793249091941312,-0.004360609942440696
188.40000000000208,16.025101310537806,-1.2758959162623176,-0.004954477005507663
189.5000000000021,16.058316546142173,-1.271861966868716,-0.004949434270358655
190.60000000000213,16.092200629517947,-1.269787371173679,-0.004645675560153162
191.70000000000215,16.12593681315266,-1.2652564789923662,-0.004954338958334414
192.80000000000217,16.159845895154863,-1.2625576599263755,-0.004950788478859103
193.90000000000217,16.193054158582495,-1.2607516346399772,-0.004850046988063017
195.0000000000022,16.22705990007863,-1.2571428500711825,-0.006268571331296879
196.1000000000022,16.260752455649815,-1.2536359718722343,-0.00621950624231804
197.2000000000022,16.29397275653452,-1.2512545632598273,-0.0052730762292396705
198.30000000000223,16.327524893837097,-1.2481894150762842,-0.005280072057214369
199.40000000000225,16.361237815627103,-1.2437319858768574,-0.005280008195034824
200.50000000000227,16.3947102948883,-1.2413502271182884,-0.005278456334077308
201.6000000000023,16.427790147568295,-1.239016336237207,-0.005517765287816889
202.7000000000023,16.461732344453882,-1.2356059365456251,-0.00599066910363355
203.8000000000023,16.494970136143383,-1.2323108842399193,-0.004919190963732056
204.90000000000234,16.528266286729945,-1.2311153010856224,-0.005619356421474375
206.00000000000233,16.561732901425515,-1.2277195169607142,-0.005609836005209257
207.10000000000235,16.595120009965214,-1.2259952259558369,-0.0056206105754035285
208.20000000000238,16.628688860048424,-1.2221227736163365,-0.006611703922873247
209.3000000000024,16.662372703948364,-1.220652735962606,-0.006599733643896766
210.40000000000242,16.695531779214814,-1.2174893155851638,-0.006599731042186807
211.50000000000242,16.728522507447337,-1.2156910151816231,-0.006609569616321753
212.60000000000244,16.76209135871779,-1.2126063560578186,-0.007948491197264929
213.70000000000246,16.79564477571193,-1.210022593331959,-0.008220917319694987
214.80000000000246,16.82903253273438,-1.2072723723742183,-0.008239264099481058
215.90000000000248,16.862489780050186,-1.2073135011818068,-0.008240011158668459
217.0000000000025,16.895407884405078,-1.2049727654122364,-0.008240000737904651
218.10000000000252,16.92943744501439,-1.200336793377688,-0.008240296000954217
219.20000000000255,16.961786162238905,-1.1997294546571315,-0.008211361123202199
220.30000000000254,16.99511765045737,-1.1982160040381384,-0.007244448995031405
221.40000000000256,17.02925814453609,-1.1954145178197702,-0.00852143727046073
222.5000000000026,17.06295259773857,-1.1949166049417477,-0.008568072450800823
223.60000000000258,17.095976047336897,-1.1934332289202816,-0.00856955513246982
224.7000000000026,17.129297548748134,-1.1899561351071828,-0.008579031647195645
225.80000000000263,17.162289480869774,-1.1878749270096884,-0.009898071391437835
226.90000000000265,17.195675870232563,-1.186735114368576,-0.00986685884691596
228.00000000000267,17.22920317351064,-1.186487230351498,-0.01055483929917278
229.10000000000267,17.262610640616725,-1.1835438248065184,-0.010547960818906965
230.2000000000027,17.295685503648183,-1.181382671300431,-0.010857321430774558
231.3000000000027,17.329046092881875,-1.1807738891889672,-0.01121140203521076
232.4000000000027,17.362357674348004,-1.1792274297820255,-0.011209962982627442
233.50000000000273,17.395417616989118,-1.177876670296901,-0.011210901770501103
234.60000000000275,17.429104272197492,-1.175098716965979,-0.011187872055706816
235.70000000000277,17.462083843071664,-1.1747098032823249,-0.0125589894680731
236.8000000000028,17.495451093094452,-1.1740884952405464,-0.011187064132799573
237.9000000000028,17.528416972509373,-1.172497556755735,-0.011199789367108526
239.0000000000028,17.561793590065466,-1.170632336363728,-0.011200004733335156
240.10000000000284,17.594983289022366,-1.1698744568857027,-0.011200000641077512
241.20000000000283,17.628272688226296,-1.169263914490949,-0.011199973320219936
242.30000000000285,17.661617275997376,-1.1679115319050872,-0.011197767027477656
243.40000000000288,17.694785264234554,-1.1656360310820255,-0.011638654704423157
244.5000000000029,17.728175155387113,-1.166331145127351,-0.012519368159693123
245.60000000000292,17.76106103327693,-1.1649130400107983,-0.012520021076618093
246.70000000000292,17.794155913343307,-1.1627408622547122,-0.012514383859141276
247.80000000000294,17.827674438722706,-1.1631215003252735,-0.013281173725181894
248.90000000000296,17.860442794862703,-1.1615114581846928,-0.013840115710201495
250.00000000000296,17.894015085374477,-1.1605661284005144,-0.01384009581441692
251.10000000000298,17.92683530184394,-1.1596893864107907,-0.013833276367860137
252.200000000003,17.960183776193034,-1.158281274144576,-0.015157285805369902
253.30000000000302,17.99310561107888,-1.1579996169327489,-0.015160497576997223
254.40000000000305,18.026491338179063,-1.1579546174003137,-0.015159993177790376
255.50000000000304,18.059673171903523,-1.157185900235695,-0.015160000010538965
256.6000000000031,18.092253524107583,-1.1557445475141506,-0.01516000002366713
257.7000000000031,18.126055513278065,-1.1562091032409445,-0.015159997347659271
258.8000000000031,18.159119100151237,-1.1555260973520491,-0.015160056992662874
259.9000000000031,18.192384424917012,-1.1551461746910754,-0.015176115677924429
261.0000000000031,18.225568613603183,-1.154870359028419,-0.01644776457496544
262.10000000000315,18.2583622196662,-1.1559906554151176,-0.016470154150770355
263.2000000000032,18.292077640641413,-1.1546441501383384,-0.01647000212129779
264.30000000000314,18.32498586727094,-1.154443183308815,-0.016469998626013727
265.40000000000316,18.35802886889703,-1.1540571527720898,-0.016470053618842684
266.5000000000032,18.391496981498126,-1.1548293239277274,-0.016473800452349252
267.6000000000032,18.42437704573148,-1.1543952722784518,-0.017481990068127118
268.70000000000323,18.457824154911684,-1.1524833470089053,-0.01779164533951949
269.80000000000325,18.49101661194798,-1.153055994559201,-0.017792624747837493
270.9000000000033,18.52428159127669,-1.1523804549855428,-0.018794681586336903
272.0000000000033,18.55733955859902,-1.1527109881229691,-0.01911202594689687
273.1000000000033,18.590302746777436,-1.1526231643732117,-0.019081494762537954
274.20000000000334,18.623386714347628,-1.1522628678227238,-0.01780711898059728
275.30000000000337,18.656791387110545,-1.151306927563959,-0.017790017271996472
276.40000000000333,18.69000030112723,-1.151119994177149,-0.01778999726665287
277.50000000000335,18.72317997542653,-1.151244579750948,-0.017756228821865783
278.6000000000034,18.75628416742561,-1.150960427239865,-0.019143153683669034
279.7000000000034,18.78961006932866,-1.1513814071186401,-0.019135272754197352
280.8000000000034,18.823109347962696,-1.1506592331557552,-0.021045973237467486
281.9000000000034,18.855875945839426,-1.1500562767308977,-0.021745532372507093
283.0000000000034,18.888987529316395,-1.1501733295056937,-0.021739978611345023
284.10000000000343,18.922501659440705,-1.1490211409648912,-0.021739981114225593
285.20000000000346,18.955095214229125,-1.1480407081444333,-0.021741945409447627
286.3000000000035,18.988327892737168,-1.1480916435763553,-0.021671536478721887
287.4000000000035,19.022069971922843,-1.1478507720114044,-0.023058391153184754
288.5000000000035,19.05522054976189,-1.1478771113313466,-0.023060035562795456
289.60000000000355,19.088300024343436,-1.1470435710374214,-0.023060006061355054
290.70000000000357,19.12171704538586,-1.146226516903809,-0.023060703565538798
291.8000000000036,19.154488520801237,-1.1458317727730432,-0.022980926155768966
292.9000000000036,19.18834137222246,-1.146047038904237,-0.023338303635008995
294.0000000000036,19.221625240017627,-1.145664248236734,-0.023391718167873776
295.1000000000036,19.25481053230565,-1.1453048362048426,-0.02330471531524747
296.2000000000036,19.28772621911188,-1.1461537411629266,-0.024712611099651838
297.30000000000365,19.32127564865855,-1.1459460974085103,-0.024710018503252495
298.4000000000037,19.354631631336726,-1.145867621183125,-0.024709999453411235
299.5000000000037,19.387986022203368,-1.146503531823612,-0.02471000057574768
300.60000000000366,19.421218152254358,-1.1443791960468126,-0.024710028649781446
301.7000000000037,19.454526983531697,-1.1463070411092997,-0.02470410648752841
302.8000000000037,19.48794003583461,-1.145288138321842,-0.02549061989588486
303.90000000000373,19.520913028130483,-1.1468784241747105,-0.02602051340948952
305.00000000000375,19.554246779506247,-1.146767392956017,-0.025936571159195676
306.1000000000038,19.587737966107035,-1.1481720722511817,-0.027343680011184812
307.2000000000038,19.620887998090748,-1.1485981680562432,-0.02734003084286618
308.3000000000038,19.65433418086259,-1.149479900126422,-0.027336765528531703
309.40000000000384,19.68760098544348,-1.150531491519539,-0.027805439010318178
310.5000000000038,19.72075133769382,-1.1518838599981256,-0.02866145882834159
311.60000000000383,19.754111467388284,-1.1545967343913839,-0.028659930877607653
312.70000000000385,19.7875680380879,-1.1542663691897042,-0.02866011509400801
313.8000000000039,19.82088776811743,-1.1563777045640897,-0.02866424493885722
314.9000000000039,19.854405796845256,-1.1596391607675955,-0.02995383634430704
316.0000000000039,19.887504988785228,-1.1604083192722041,-0.030142815131643186
317.10000000000394,19.921123874261877,-1.1621771753932002,-0.031294057054281676
318.2000000000039,19.954463266168332,-1.1654431538283094,-0.031249238802696144
319.30000000000393,19.987834200763906,-1.1680766221547172,-0.032635193579143795
320.40000000000396,20.021151158231895,-1.1706156350043362,-0.032612917950231246
321.500000000004,20.054343068105275,-1.1732665528265576,-0.03361828858317839
322.600000000004,20.08797580441868,-1.1755659005111128,-0.033948086663571964
323.700000000004,20.121344302367483,-1.1776359119850033,-0.035010950784335026
324.80000000000405,20.154915118128663,-1.1825204018245317,-0.03498844244210719
325.90000000000407,20.187748006632432,-1.1846046957435468,-0.03622995553803765
327.0000000000041,20.221853154493513,-1.1876507239700318,-0.03623880008759972
328.10000000000406,20.255465180756897,-1.190700856670981,-0.03764679390040371
329.2000000000041,20.288949834087322,-1.193071273112432,-0.03754614313625115
330.3000000000041,20.322284001437843,-1.1991326112476601,-0.038697046307419214
331.4000000000041,20.355688083907108,-1.2026629234433188,-0.03895366621565843
332.50000000000415,20.388961753745463,-1.2063072822623482,-0.04018615110195034
333.6000000000042,20.422998630224953,-1.2088951171057007,-0.041608912038686885
334.7000000000042,20.456544204971813,-1.2154546093714396,-0.04152235555251238
335.80000000000416,20.49012274395431,-1.2190139803963898,-0.042823252634491826
336.9000000000042,20.523413973783896,-1.224838413393388,-0.04384770294907936
338.0000000000042,20.557070644419397,-1.227614396711846,-0.044728206267980575
339.10000000000423,20.590756403956114,-1.2338993089909902,-0.04533208580796755
340.20000000000425,20.624413580875036,-1.237631525036364,-0.04571292539024707
341.3000000000043,20.65810148105704,-1.2426956507923403,-0.046915618361729194
342.4000000000043,20.69195519028535,-1.2473277934224103,-0.0485192907776395
343.5000000000043,20.72540183496956,-1.2519667272938877,-0.04976467546191454
344.60000000000434,20.759006945293013,-1.2550695673445393,-0.051382714233421556
345.7000000000043,20.792585242104316,-1.258794481000914,-0.05292910356572422
346.80000000000433,20.82648658328766,-1.2624340442988202,-0.05444933512205408
347.90000000000435,20.860153752750502,-1.2648803370235029,-0.0558814126735343
349.0000000000044,20.89350821512167,-1.2674805947217187,-0.05771939374133117
350.1000000000044,20.92722193986259,-1.2690374128313253,-0.06041874161546712
351.2000000000044,20.960976499173576,-1.269347960612572,-0.06219785604697181
352.30000000000445,20.99488293921058,-1.2702531040321892,-0.06374296620329734
353.4000000000044,21.028711207289753,-1.2697962145177712,-0.06532416354302839
354.50000000000443,21.06198342641068,-1.2681529778053677,-0.06743462209521267
355.60000000000446,21.095540672030797,-1.2652451511855487,-0.07040835119275624
356.7000000000045,21.129049559668175,-1.2637345189102114,-0.07238774568327644
357.8000000000045,21.162711863558577,-1.260012421902531,-0.07578366011838922
358.9000000000045,21.196456034113645,-1.2534314155751012,-0.0783780989670051
360.00000000000455,21.230244334497673,-1.2499235759437075,-0.07972914712433221
361.10000000000457,21.264524759602715,-1.2426998509365357,-0.08201407864618648
362.2000000000046,21.297692442483566,-1.2374603843837544,-0.08405262263640756
363.30000000000456,21.33122595246574,-1.2320362492779353,-0.08672943228349839
364.4000000000046,21.365383315816068,-1.2265070014342918,-0.0894575810239413
365.5000000000046,21.39905171759791,-1.2186975494965062,-0.09267143535022404
366.6000000000046,21.432619221891986,-1.2136207053709294,-0.09584847763932114
367.70000000000465,21.46646662417388,-1.2089531926313766,-0.09859645291078722
368.8000000000047,21.499969112053105,-1.2038132484601956,-0.10089665044563301
369.9000000000047,21.534244050158943,-1.1983944431817275,-0.1040463460654224
371.00000000000466,21.56784585452551,-1.1947654506232896,-0.10753395536746213
372.1000000000047,21.60167895957593,-1.1927383991650213,-0.11070993464100942
373.2000000000047,21.635577151870358,-1.1885124456148872,-0.11380378032506577
374.30000000000473,21.66966102963928,-1.186118109297619,-0.11581473869716419
375.40000000000475,21.703430395341442,-1.1833586251197847,-0.11896031179997024
376.5000000000048,21.737412028318218,-1.1837976058234954,-0.12111714223053172
377.6000000000048,21.771090034656396,-1.1826659689020704,-0.12320398888586626
378.7000000000048,21.805070524501197,-1.1815532883470043,-0.12611737894345865
379.80000000000484,21.838919296943907,-1.1814002969039394,-0.12778900387451353
380.9000000000048,21.87291666250713,-1.1824370431623874,-0.12963318455953265
382.00000000000483,21.90722914553467,-1.1824363062937282,-0.1325323870742432
383.10000000000485,21.941209368777297,-1.1831752372689381,-0.1344398023941884
384.2000000000049,21.975286912409924,-1.1843867089355364,-0.1358878891259767
385.3000000000049,22.008688069544448,-1.1871862769520898,-0.13776937723468885
386.4000000000049,22.043144591287056,-1.18835439239825,-0.14019840705333309
387.50000000000495,22.07707900618782,-1.188635071517378,-0.14154431082576124
388.6000000000049,22.111409137481292,-1.1891740445453842,-0.1431438228104458
389.70000000000493,22.145153469680324,-1.1918387616558,-0.14471750121176896
390.80000000000496,22.17895249510669,-1.1937365966485447,-0.14465299613571903
391.900000000005,22.21389886692492,-1.1964538177499564,-0.14629481688188672
393.000000000005,22.2478438799392,-1.1989891960008783,-0.14745811837985645
394.100000000005,22.281718208959468,-1.200490730942684,-0.14909683785865502
395.20000000000505,22.31611463730321,-1.203786723726649,-0.15040826386102424
396.30000000000507,22.350469928473995,-1.2072952554556355,-0.15235446119991192
397.4000000000051,22.384555755163237,-1.2084588570146315,-0.15561734034853503
398.50000000000506,22.418670069593375,-1.212334193884182,-0.15624180856025083
399.6000000000051,22.452865541025187,-1.2157484440733368,-0.15733265767271032
400.7000000000051,22.48704396348483,-1.2176904691938775,-0.15801858526819235
401.8000000000051,22.521168998386422,-1.2232604591970462,-0.15867906043197832
402.90000000000515,22.555780921977323,-1.227301305050161,-0.1601133902248777
404.0000000000052,22.589852157924714,-1.2294416085047644,-0.1615014293421284
405.1000000000052,22.624121317841208,-1.2315176840605528,-0.16141793047040132
406.20000000000516,22.65836020906051,-1.235708314598781,-0.16284050037179032
407.3000000000052,22.69289919255647,-1.2408697147747116,-0.16410935335648835
408.4000000000052,22.72698750987677,-1.2446337497388849,-0.16566797568906155
409.50000000000523,22.76127326276074,-1.2494792471224863,-0.167089154983719
410.60000000000525,22.795922546669765,-1.256865907647563,-0.16849231315945712
411.7000000000053,22.830227291061927,-1.2579547282712487,-0.1684263099261596
412.8000000000053,22.86461132460255,-1.2616277561111946,-0.16877279484580665
413.9000000000053,22.899043123078236,-1.2657249571796612,-0.16899632487751814
415.00000000000534,22.933156654190938,-1.272355651295947,-0.170082052650808
416.1000000000053,22.96788438382425,-1.2768048225025268,-0.1714749992229616
417.20000000000533,23.00206790616655,-1.2800731215000933,-0.17289302822364183
418.30000000000535,23.036694718102495,-1.284761001978714,-0.17407102257288765
419.4000000000054,23.071125516497364,-1.2895614877860697,-0.17559030417392174
420.5000000000054,23.105687035533304,-1.2958646945449097,-0.17854605845192895
421.6000000000054,23.13983361933078,-1.3002900297817597,-0.17993015117998645
422.70000000000545,23.174706563451082,-1.3040317593793052,-0.17996566243339673
423.8000000000054,23.209152499056948,-1.3081064089104328,-0.18136569760836085
424.90000000000543,23.24363912961985,-1.3158493821033643,-0.18186547501006922
426.00000000000546,23.278260642133304,-1.3199941530091532,-0.18305423423686706
427.1000000000055,23.312785246490463,-1.3237839470223822,-0.18324165290242433
428.2000000000055,23.347302021695533,-1.3293247088540598,-0.18439149156051515
429.3000000000055,23.381935707732055,-1.334892593221802,-0.18737537261243897
430.40000000000555,23.41647976886557,-1.3401304778746084,-0.18900867112442876
431.50000000000557,23.45099385094809,-1.346781549359435,-0.190482800952251
432.6000000000056,23.48590942234875,-1.350209751353809,-0.191893421550287
433.70000000000556,23.52035628162056,-1.3559743506140638,-0.19323816952713146
434.8000000000056,23.555306628763407,-1.3612551288957258,-0.1935528786820795
435.9000000000056,23.59003231871099,-1.3681375207851003,-0.1949804564200308
437.0000000000056,23.624217316774462,-1.374069716163041,-0.1965246185252565
438.10000000000565,23.659343597048842,-1.3796896878239118,-0.19831522700800885
439.2000000000057,23.693822243900232,-1.3851807249081047,-0.20036591911641732
440.3000000000057,23.72869495748658,-1.3904781801038602,-0.20198099375749035
441.40000000000566,23.76353495407005,-1.393854105426153,-0.20409441613284685
442.5000000000057,23.79828700551439,-1.3960640954031864,-0.20651581048167023
443.6000000000057,23.832774055643807,-1.3945827548679002,-0.2077940350619354
444.70000000000573,23.867432771501512,-1.3926539483800233,-0.20932288945810118
445.80000000000575,23.90207166657437,-1.391556385209512,-0.21105998662651126
446.9000000000058,23.93672478698095,-1.3889497073302595,-0.21346525418866946
448.0000000000058,23.971652371312693,-1.3861902699983943,-0.21567226355158997
449.1000000000058,24.00618846141396,-1.3828465354423642,-0.21757588456986277
450.20000000000584,24.041006342283573,-1.376762025688947,-0.21923567226955143
451.3000000000058,24.075791176983326,-1.3740623653628492,-0.22022519180196198
452.40000000000583,24.11056645577008,-1.3688081971281818,-0.220989567218993
453.50000000000585,24.145106608147273,-1.3641958801116356,-0.22237686301997694
454.6000000000059,24.180254825727296,-1.3606104098061447,-0.22363907549991735
455.7000000000059,24.214773851228202,-1.3577025364590267,-0.22529600092538615
456.8000000000059,24.249777304796975,-1.3569265698545172,-0.22779458106523265
457.90000000000595,24.284841166893855,-1.3575226805661693,-0.228691074296687
459.0000000000059,24.31927215967234,-1.35807205152913,-0.2295374205731795
460.10000000000593,24.354430221069915,-1.357239055308751,-0.22970307852669425
461.20000000000596,24.38936831672153,-1.3587497807195135,-0.2309715443956155
462.300000000006,24.42398926019754,-1.3583533098123581,-0.23221001229360638
463.400000000006,24.45922612554966,-1.3589435665780778,-0.23384068441634476
464.500000000006,24.49391743571176,-1.3608467446649404,-0.2351324053966053
465.60000000000605,24.52924039412883,-1.3619758627583434,-0.23671641444757086
466.70000000000607,24.56393527127178,-1.3646433119527477,-0.23802975384829672
467.8000000000061,24.599012268408412,-1.3664133509982495,-0.23956549941419736
468.90000000000606,24.633776328255696,-1.367293326649778,-0.2409184429247091
470.0000000000061,24.668857481623906,-1.370592974886644,-0.24363061385789342
471.1000000000061,24.703675394408748,-1.3705988232910578,-0.24541761600963374
472.2000000000061,24.738672976857153,-1.3737584396329154,-0.2469094499155684
473.30000000000615,24.77362203959681,-1.3779119149175163,-0.24814841197405624
474.4000000000062,24.80866577535646,-1.3795741317574175,-0.249485882043742
475.5000000000062,24.843829658044704,-1.3814136189386694,-0.25134533147127813
476.60000000000616,24.878606736847733,-1.3836279777213938,-0.253775663418228
477.7000000000062,24.91357909818721,-1.3867611219668659,-0.2553260853271482
478.8000000000062,24.94885890420645,-1.389052175491331,-0.2559214679614743
479.90000000000623,24.984011647692167,-1.3899600849899547,-0.2581022119340628
481.00000000000625,25.01891197564276,-1.3925172213399368,-0.26012481323091396
482.1000000000063,25.053808740486847,-1.3948694864483768,-0.26125147690049255
483.2000000000063,25.089017276047247,-1.3976646361014264,-0.26321787571024835
484.3000000000063,25.12443792630091,-1.3995382099925846,-0.2639363436671345
485.40000000000634,25.159021870944454,-1.4016145257610526,-0.26423778707314627
486.5000000000063,25.194116388429556,-1.4017982950999244,-0.2659664695744133
487.60000000000633,25.22902673161462,-1.4030477868482636,-0.26788436634672763
488.70000000000636,25.26459153634938,-1.4046475161681389,-0.2694783837966397
489.8000000000064,25.299771485933906,-1.406182307782206,-0.27312756599663013
490.9000000000064,25.334872541178175,-1.4073801151162075,-0.27492493198486434
492.0000000000064,25.369904966211838,-1.4076893857871986,-0.2761022956528407
493.10000000000645,25.40497042182812,-1.4092234809848836,-0.2772318329732988
494.2000000000064,25.43987081205412,-1.4082229078343007,-0.27808931739260156
495.30000000000643,25.475373297311567,-1.4079266394063759,-0.2793869403039624
496.40000000000646,25.510542131910675,-1.4074552689252182,-0.28093080544889926
497.5000000000065,25.54489024772399,-1.4072552113761425,-0.2826578595161511
498.6000000000065,25.58074443942224,-1.406536361700236,-0.28285005332089996
499.7000000000065,25.615823507827393,-1.406435940426818,-0.28312582788251284
500.80000000000655,25.651164088758474,-1.407434749168713,-0.28411102812840383
501.90000000000657,25.686220854620746,-1.4061703346386445,-0.2854401016561914
503.0000000000066,25.721072255356415,-1.4080782776954062,-0.2867398957420604
504.10000000000656,25.75665550224318,-1.4077120475899667,-0.2880859470985837
505.2000000000066,25.79164781756214,-1.4079581435813318,-0.2894107765303251
506.3000000000066,25.826568822420718,-1.4076751020165348,-0.2905688158504405
507.4000000000066,25.862257944011784,-1.4081547030097463,-0.29069733714108814
508.50000000000665,25.897697967215233,-1.4067937285130772,-0.2920540089773236
509.6000000000067,25.932727074697482,-1.406884363284098,-0.29215157406939696
510.7000000000067,25.96821028283807,-1.4097574759961393,-0.2933453394601848
511.80000000000666,26.00320452041124,-1.40856131007445,-0.2933499210068775
512.9000000000067,26.038635888472637,-1.4086503321320358,-0.29335059398534913
514.0000000000067,26.073934178292742,-1.4106874295159264,-0.29354038050621245
515.1000000000067,26.109161899953804,-1.4103173062098597,-0.2942831780957116
516.2000000000068,26.144613059376375,-1.4089637102155628,-0.29367125287521745
517.3000000000068,26.179480143077793,-1.4102587983831825,-0.294626984840221
518.4000000000068,26.215534210187883,-1.4108668418550907,-0.295000705041208
519.5000000000068,26.250643804688973,-1.4118725446642526,-0.2949992672844206
520.6000000000068,26.2861327195906,-1.411456345867935,-0.2955860821125458
521.7000000000069,26.32153386015919,-1.4129744111254283,-0.29631046621371926
522.8000000000068,26.356788085627567,-1.412263982080123,-0.2963099882167364
523.9000000000069,26.392353046122395,-1.413361644883642,-0.29630967655633844
525.0000000000068,26.428040902018054,-1.4153017186693126,-0.296507005072292
526.100000000007,26.463070304785315,-1.418455260200818,-0.29763646170171976
527.2000000000069,26.49864200132539,-1.4273925478469316,-0.29762996843603284
528.300000000007,26.53414771805441,-1.4361180359371533,-0.29762999936437584
529.4000000000069,26.56944743336605,-1.445343916331657,-0.2976299993113001
530.5000000000069,26.605066945110185,-1.4510809597879761,-0.2976295735452221
531.600000000007,26.640443087350807,-1.4571710574000418,-0.2979988576269119
532.700000000007,26.676155265639913,-1.4619847982817762,-0.2989555598548179
533.800000000007,26.711475932069444,-1.463982484014096,-0.29895002271952453
534.900000000007,26.746925847620265,-1.4692996170934118,-0.29895000027591667
536.000000000007,26.782724253707915,-1.4746002311509792,-0.2989500777957135
537.1000000000071,26.818283884808086,-1.4785695535395305,-0.29894466109941975
538.2000000000071,26.853731898048416,-1.4830475201313862,-0.30016700193870705
539.300000000007,26.889280365281923,-1.4859505939708597,-0.30027005027615816
540.4000000000071,26.924701856924685,-1.4893542629141152,-0.3002700018273061
541.500000000007,26.96050807000429,-1.49135297076593,-0.3002700000028864
542.6000000000072,26.996074304715492,-1.4923150398048806,-0.30026999999985016
543.7000000000071,27.03173142459109,-1.4947210262246318,-0.30026999999999804
544.8000000000072,27.066854533086758,-1.4961797460949686,-0.3002700000002352
545.9000000000071,27.1029090348285,-1.497402078966357,-0.30027000002861914
547.0000000000072,27.13862511229211,-1.5003254244293711,-0.30026999849889124
548.1000000000072,27.174153322057006,-1.5010576153374353,-0.30026959739090353
549.2000000000072,27.20975397975328,-1.5041948462869617,-0.3002733490513232
550.3000000000072,27.24511898852751,-1.5078207444887308,-0.3016163811823964
551.4000000000073,27.28169918147312,-1.5084179102348325,-0.30124786350424104
552.5000000000073,27.31693255451297,-1.5097961793689074,-0.3012479896299962
553.6000000000073,27.352709731980784,-1.514194834038055,-0.29992616677557127
554.7000000000073,27.3884986055091,-1.5166861195159518,-0.29992914683394645
555.8000000000073,27.423709807787297,-1.5205527691578138,-0.30032301665530525
556.9000000000074,27.460132841749772,-1.5246615116751594,-0.3012532652830613
558.0000000000074,27.496110711954024,-1.5274866332096226,-0.30125264800582396
559.1000000000074,27.53122591132319,-1.5306559909734379,-0.3002684812182279
560.2000000000073,27.56726162391402,-1.5293411483984694,-0.2999310962814352
561.3000000000073,27.603595939136788,-1.530756710963505,-0.3002345862536404
562.4000000000074,27.63941849066817,-1.5307156183163682,-0.30123944545010506
563.5000000000074,27.67500611372872,-1.5328725922293918,-0.30157483678314856
564.6000000000074,27.711135799204023,-1.5333886699107613,-0.3015796155519399
565.7000000000074,27.747009162757596,-1.5329589225269658,-0.30159568861027886
566.8000000000075,27.78273946178622,-1.5337627538383534,-0.30255296032946033
567.9000000000075,27.81827896496205,-1.533244032797101,-0.30353967629187784
569.0000000000075,27.854529481598334,-1.5334766021344715,-0.30355971239889534
570.1000000000075,27.890295375675166,-1.53280355098523,-0.30355999943010437
571.2000000000075,27.926289790741443,-1.531894687610659,-0.3035600263359175
572.3000000000076,27.962284462700058,-1.5318319601705976,-0.30356570814035777
573.4000000000076,27.99788576243831,-1.5311793062589547,-0.30256452404923584
574.5000000000076,28.034057224147315,-1.5285431810230652,-0.3022396261671987
575.6000000000076,28.07003345827843,-1.5282874098347303,-0.3022399978636394
576.7000000000077,28.106177846131615,-1.5284004062249508,-0.3022400000204759
577.8000000000077,28.14192102874616,-1.5295653920618846,-0.3022400000000247
578.9000000000076,28.17801941364059,-1.5296557357733565,-0.30223999994036443
580.0000000000076,28.214188381516465,-1.5302680157483082,-0.30223999848079774
581.1000000000076,28.250484173795233,-1.5328158094616502,-0.3022403003276257
582.2000000000077,28.286430720690003,-1.5339960072060816,-0.3022272798730672
583.3000000000077,28.322376311565492,-1.538071663112766,-0.30190746191127404
584.4000000000077,28.358408896571937,-1.5398561065392513,-0.30191006582580915
585.5000000000077,28.394586399371775,-1.5422984577251726,-0.3019239398429838
586.6000000000078,28.4304145707376,-1.5454781962534108,-0.3032314335700632
587.7000000000078,28.466315834848952,-1.55011924333684,-0.3032192933136977
588.8000000000078,28.502665830048915,-1.5520866926123036,-0.3032199953414154
589.9000000000078,28.53809903095726,-1.5575741940385681,-0.30322000003401106
591.0000000000078,28.575179857074154,-1.5636219778992024,-0.3032199999883014
592.1000000000079,28.611016976873035,-1.5711953636473561,-0.3032199995480176
593.2000000000079,28.647242158650112,-1.5740071717002229,-0.30322012130814
594.3000000000079,28.683545685939364,-1.5821960264871293,-0.30323794386713576
595.4000000000078,28.719433807126386,-1.5880171810055814,-0.3045258107496598
596.5000000000078,28.755659193077275,-1.5949669959674972,-0.303892333534558
597.6000000000079,28.791836944171692,-1.6000628586062042,-0.3037603031032905
598.7000000000079,28.82790285748591,-1.6076779086953368,-0.302544034838224
599.8000000000079,28.864501761954536,-1.6159974937275257,-0.30510507356848304
600.9000000000079,28.90050512541434,-1.6238937123649644,-0.30519991215583087
602.000000000008,28.936906652988547,-1.6314940792958699,-0.30520022686141735
603.100000000008,28.973108728592585,-1.640074546422084,-0.30524570705169696
604.200000000008,29.009277454195434,-1.6495499215252565,-0.30296864115696653
605.300000000008,29.045577639077255,-1.6585828935743903,-0.30258267484621637
606.400000000008,29.081628957800906,-1.6686414364757174,-0.30392784518432236
607.5000000000081,29.117841479191572,-1.6756948265342742,-0.3038895317767025
608.6000000000081,29.15407752784167,-1.6859628877034918,-0.3038900033130769
609.7000000000081,29.19050714023092,-1.6938577401490473,-0.3038901901163147
610.8000000000081,29.226572382762082,-1.702600152336217,-0.3037776833640149
611.9000000000082,29.262810728266302,-1.7106388286916738,-0.3048874304534248
613.0000000000082,29.299206475407843,-1.7169965530815243,-0.30487997898085606
614.1000000000081,29.335592207191162,-1.7257949841325484,-0.3048799842793679
615.2000000000081,29.371682010357695,-1.7358499032196892,-0.3048780353319449
616.3000000000081,29.40810980930015,-1.7460659930764006,-0.30358421747156816
617.4000000000082,29.44405344235203,-1.7548356460203474,-0.3035615147083601
618.5000000000082,29.48090151635711,-1.7640398751839508,-0.3035596270188612
619.6000000000082,29.516504895484413,-1.774744847956953,-0.30378537105199843
620.7000000000082,29.55349324417561,-1.7808707856656605,-0.304786956523698
621.8000000000083,29.590098412441545,-1.7919560988358698,-0.30620535772271085
622.9000000000083,29.626449085413448,-1.8033550760854604,-0.30619867684096347
624.0000000000083,29.662747296532004,-1.8124369354385443,-0.3061992821726722
625.1000000000083,29.699129608710727,-1.8217188081820719,-0.3061700239968501
626.2000000000083,29.735483849377804,-1.8311331825955666,-0.30488794299227084
627.3000000000084,29.771402927188657,-1.8378881616877785,-0.30488007188566346
628.4000000000084,29.808059046760672,-1.8449442048832279,-0.30487999995485726
629.5000000000084,29.84412898883006,-1.854523802923145,-0.3048799999951308
630.6000000000083,29.88021137278765,-1.8639344455006732,-0.3048799999999625
631.7000000000083,29.917300416966185,-1.8730267915728136,-0.30488000000025295
632.8000000000084,29.95377240682401,-1.875892511211323,-0.3048800000394447
633.9000000000084,29.98996656574433,-1.8824846010345362,-0.3048800000574299
635.0000000000084,30.02659170362563,-1.891133361491164,-0.3048794928644143
636.1000000000084,30.062896970585857,-1.8977300998740227,-0.3054936882868313
637.2000000000085,30.09950525514729,-1.9000048652433046,-0.3060415584506533
638.3000000000085,30.135876819793893,-1.9059433448098713,-0.3044811871009765
639.4000000000085,30.17219722527382,-1.9106603788359626,-0.3042212293013846
640.5000000000085,30.208551993373646,-1.9143516718217475,-0.304220490593357
641.6000000000085,30.245206734430397,-1.919956417553006,-0.3053757802889079
642.7000000000086,30.28149049885745,-1.9229009539760613,-0.30553823773092903
643.8000000000086,30.31780178618683,-1.9276894146986523,-0.3055400479410775
644.9000000000086,30.354463940694185,-1.930764760387788,-0.30552806329429893
646.0000000000086,30.390749417017663,-1.9333493675040032,-0.30416606387058964
647.1000000000087,30.427218086568423,-1.9372464640460512,-0.3042117086372951
648.2000000000087,30.46380033583251,-1.941627531995027,-0.3055038977989799
649.3000000000086,30.50036453000474,-1.9448792033592415,-0.3055299726401399
650.4000000000086,30.536749110548115,-1.9483355756553336,-0.3055300017095113
651.5000000000086,30.573153891848783,-1.9502629309044992,-0.3055300000134662
652.6000000000087,30.609445605454738,-1.9545601375332862,-0.3055300000008878
653.7000000000087,30.645991305209524,-1.9582815635994617,-0.3055300005594561
654.8000000000087,30.68275264795661,-1.959673270779504,-0.305530060630947
655.9000000000087,30.71862556235794,-1.9636593379336718,-0.305526254377948
657.0000000000088,30.755592306671698,-1.9682490310674372,-0.3068291084515926
658.1000000000088,30.792339093879363,-1.9701443421069178,-0.30684987773436223
659.2000000000088,30.828585042657725,-1.9727651230444314,-0.30685000180377653
660.3000000000088,30.865160720089577,-1.9774639933532863,-0.30684996351442173
661.4000000000088,30.901765652406574,-1.98243853557531,-0.30675077356233293
662.5000000000089,30.93830597968618,-1.9875991467467742,-0.30552307638143317
663.6000000000089,30.974997696475473,-1.9902032095214959,-0.3055300123006006
664.7000000000089,31.01143176835181,-1.9941197010325122,-0.30553052594348395
665.8000000000088,31.048092116159797,-1.999620826180548,-0.3055899612456505
666.9000000000088,31.08465520357492,-2.0027334177841474,-0.3061883232141738
668.0000000000089,31.12081773490585,-2.0053767782522964,-0.30618997285721283
669.1000000000089,31.157638708713737,-2.00901125870193,-0.30618997434145045
670.2000000000089,31.194247097063663,-2.0139484303812107,-0.3061851399615665
671.3000000000089,31.23058810682619,-2.017848564739414,-0.30748762530618823
672.400000000009,31.266992597390907,-2.0223064171773597,-0.3061585902902304
673.500000000009,31.303656053562694,-2.0277615641728404,-0.30620019101258
674.600000000009,31.340234891388814,-2.0314720338632917,-0.3062000039621444
675.700000000009,31.376863243887637,-2.0365971493845016,-0.3062000000212888
676.800000000009,31.41338978673188,-2.0404825165123657,-0.30619999999991965
677.9000000000091,31.450033741573257,-2.0416997549540103,-0.3061999999999965
679.0000000000091,31.486598592909587,-2.0473532525902427,-0.3061999999999996
680.1000000000091,31.522331733839216,-2.050196523811494,-0.30620000000012837
681.2000000000091,31.5596355248511,-2.0551588997663295,-0.3061999999971614
682.3000000000092,31.59637478175861,-2.0579758894941316,-0.3061999974130254
683.4000000000092,31.63287914436879,-2.0635916304362025,-0.30619969631647814
684.5000000000091,31.669647768873187,-2.0694775136287946,-0.30650107497829726
685.6000000000091,31.706206310702953,-2.0740207393868317,-0.3075244890520952
686.7000000000091,31.742516263972373,-2.0782202509648076,-0.3075550574241852
687.8000000000092,31.779373290743504,-2.0812332138695258,-0.3062134087513577
688.9000000000092,31.815712658687197,-2.0873658876087497,-0.3062000312831561
690.0000000000092,31.85241411829981,-2.089854697164442,-0.30619999949478327
691.1000000000092,31.889065240834594,-2.093107390874411,-0.30619999999332537
692.2000000000093,31.92567398865831,-2.0959601147444236,-0.30619999998757885
693.3000000000093,31.96233542801221,-2.1005017732467444,-0.30619999886766225
694.4000000000093,31.999180875395588,-2.106593898246969,-0.30620004989375404
695.5000000000093,32.03560895683217,-2.110737096608697,-0.3062242534366706
696.6000000000093,32.07223710700985,-2.1152962393890835,-0.30751799103713795
697.7000000000094,32.10900407319243,-2.117946379300912,-0.3075083683134725
698.8000000000094,32.1450346508838,-2.1212267781497407,-0.3074468470254237
699.9000000000094,32.18235126847348,-2.127979441839755,-0.30619087590061955
701.0000000000093,32.218666152744504,-2.13207809609396,-0.3061900104134363
702.1000000000093,32.25571632107712,-2.135756424244168,-0.30619000008530195
703.2000000000094,32.29231972400571,-2.1414849158536087,-0.30619000500441773
704.3000000000094,32.329052456267554,-2.143900843881748,-0.30618973960693374
705.4000000000094,32.365728803224634,-2.1477745316064736,-0.3071337270505192
706.5000000000094,32.40249861814666,-2.14956625601472,-0.30750823169156627
707.6000000000095,32.43953203867075,-2.1532066835551196,-0.30751000288626473
708.7000000000095,32.47598314104975,-2.158464865048572,-0.3075100005189948
709.8000000000095,32.51260077073298,-2.1625428148690746,-0.3075100351431628
710.9000000000095,32.54960943925873,-2.166142246178047,-0.3075091845125546
712.0000000000095,32.5864997246808,-2.1692948090120474,-0.30866286404616305
713.1000000000096,32.62302739207798,-2.1734047243094263,-0.30882897038442225
714.2000000000096,32.659702964150945,-2.1785786995415104,-0.3088300009601599
715.3000000000096,32.696794595152205,-2.183903530954488,-0.3088299958199632
716.4000000000096,32.733395727269944,-2.1901978344243322,-0.30883037471696584
717.5000000000097,32.770398907911336,-2.194726183928962,-0.30788537425087403
718.6000000000097,32.80695372569309,-2.1971981870463013,-0.3075118051624983
719.7000000000096,32.843801457241675,-2.2013547301429472,-0.3075099982072924
720.8000000000096,32.880819968982514,-2.2029765885127226,-0.307509999848135
721.9000000000096,32.91735371283384,-2.2064853315415753,-0.30751000017222463
723.0000000000097,32.95423292916434,-2.2110974401347874,-0.3075100300916942
724.1000000000097,32.991148822817806,-2.2135784550243316,-0.3075115273543547
725.2000000000097,33.02821305488629,-2.217778043176055,-0.3081328510733803
726.3000000000097,33.06493420482361,-2.2247089870866,-0.3081671240778472
727.4000000000098,33.10171437132112,-2.225346532189882,-0.3068831778147829
728.5000000000098,33.138557302522,-2.2292415668810155,-0.3068600784235045
729.6000000000098,33.1752346876624,-2.2329794987012463,-0.306832552017668
730.7000000000098,33.21226534862129,-2.2378308351994067,-0.3075044361569379
731.8000000000098,33.24920748690806,-2.2433558050858524,-0.3075097911740179
732.9000000000099,33.286113540257666,-2.2471247272373143,-0.307489717181225
734.0000000000099,33.32306557022107,-2.252279813409983,-0.30653725453445846
735.1000000000099,33.36003444067344,-2.2569325109546936,-0.3071796913571334
736.2000000000098,33.39678669139911,-2.260926864426313,-0.3071802442632454
737.3000000000098,33.43367446282263,-2.2648658112925526,-0.30718007380404844
738.4000000000099,33.470698939426725,-2.2677595728647795,-0.30718236604883575
739.5000000000099,33.50782632959126,-2.270381035403943,-0.3078695530952107
740.6000000000099,33.54492067189116,-2.273087409636218,-0.3078432042528818
741.7000000000099,33.581708905011006,-2.2791015525987475,-0.30750812118094295
742.80000000001,33.61853281865939,-2.279015614688796,-0.3075099876258194
743.90000000001,33.65552018268119,-2.2840142669249945,-0.30750999996137507
744.00000000001,33.658802858346014,-2.284851100690565,-0.3075099999216331