File: 01_Data/EIFS_Mesh/STA/N2/30K_min/EIFS_Mesh_STA_N2_30KData_230906_R1.csv
##Temp./Â°C,Time/min,DSC/(mW/mg),Mass loss/mg
41.0,10.569398041146709,-2.2508391358986026,0.0020455809738271213
42.100000000000016,10.756674920571978,-2.2080278303438847,0.0030483700088268506
43.20000000000003,10.879872413357562,-2.1738177918457064,0.00491013708357535
44.30000000000005,10.975841735217166,-2.1443724346190076,0.003615769043216588
45.40000000000006,11.059525400050294,-2.119989456346117,0.002265257618826233
46.50000000000008,11.133977664106137,-2.0947455621321387,0.003030038079670838
47.600000000000094,11.201722325123693,-2.073647513596674,0.0034707547056047616
48.70000000000011,11.264414569577404,-2.051141864296478,0.002409662871246887
49.800000000000125,11.323802659083807,-2.0316273177246065,0.0033712183931751127
50.90000000000014,11.380584788946615,-2.0115855173346926,0.0025238719712668
52.000000000000156,11.432742800182794,-1.9950578828302779,0.002980390926641263
53.10000000000017,11.486184355206463,-1.976483119467311,0.004262663910072462
54.20000000000019,11.537836772230555,-1.9588586583355412,0.0041279412269563664
55.3000000000002,11.586621681563294,-1.94191115839421,0.0033441957746882522
56.40000000000022,11.634332164367974,-1.9296014805118955,0.001310504941538504
57.500000000000234,11.68130567559607,-1.914194525337309,0.0015804383028825697
58.60000000000025,11.72667833559794,-1.901841158209415,0.003059209138866592
59.700000000000266,11.771136990854277,-1.8882685721447352,0.0030204607100667857
60.80000000000028,11.816247248922922,-1.8760894855386958,0.0022565054703909126
61.9000000000003,11.859725970161255,-1.8657883010822236,0.003396965075346259
63.00000000000031,11.902200676786794,-1.857437390159271,0.0037662943158540685
64.10000000000034,11.943711574044379,-1.8485639442883668,0.0017144801707784652
65.20000000000034,11.98684738434922,-1.8376694035791077,0.0016324425844009838
66.30000000000035,12.028374824784528,-1.8313559895234512,0.0012957148391246065
67.40000000000038,12.069554825605726,-1.824086475525852,0.0017310613592798063
68.5000000000004,12.110450863335197,-1.817333898377355,0.001457720395919182
69.6000000000004,12.150888964835644,-1.810145885975244,0.0011847414754138086
70.70000000000041,12.191550382327078,-1.8060346987303453,0.0013481434703903616
71.80000000000044,12.231521962077414,-1.7994551178903462,0.0011051702624955695
72.90000000000046,12.27157878619547,-1.7936762689137982,-0.00014067854826560477
74.00000000000047,12.311170151307438,-1.7898453697065237,-0.00033015946588133005
75.10000000000048,12.350618094938469,-1.7835736954507253,-0.00019031802835645095
76.2000000000005,12.389705344232421,-1.778281143796271,-0.0019123714141784376
77.30000000000052,12.428775033119818,-1.7734484059367295,-0.002312191547469311
78.40000000000053,12.467462752781183,-1.7684600080814157,-0.0036049678130023466
79.50000000000054,12.507028246533125,-1.7637011902193631,-0.002158559857764253
80.60000000000056,12.544501682820789,-1.7580435052563481,-0.002386698518231256
81.70000000000059,12.58301334688798,-1.7527480760604286,-0.002547476740075716
82.8000000000006,12.62206405132129,-1.7446176369927247,-0.003721428792810677
83.9000000000006,12.660706077529056,-1.7402180789873232,-0.0045981533210470715
85.00000000000063,12.698880062201113,-1.7333914283677117,-0.004832465244939854
86.10000000000065,12.736576287771166,-1.7265005287172928,-0.00505314788332889
87.20000000000066,12.774281410534165,-1.7204809615053118,-0.006345315072713298
88.30000000000067,12.81219840859943,-1.714004573806777,-0.005079795537252352
89.40000000000069,12.849699619667035,-1.7064457126262114,-0.006388131239306816
90.50000000000071,12.887396763048,-1.7003137361361889,-0.007753415179880818
91.60000000000072,12.924793584242762,-1.6923551322233819,-0.007631872410780893
92.70000000000073,12.96186641816657,-1.6850391706716585,-0.009007704817986628
93.80000000000075,12.99841058515088,-1.6781052413071829,-0.009044256090682268
94.90000000000077,13.03518873736492,-1.6681162400834217,-0.00770292837683062
96.00000000000078,13.072551054203405,-1.6603018028798562,-0.0090416028472049
97.10000000000079,13.109654736461719,-1.6507090894046796,-0.009959121051826614
98.20000000000081,13.146036000438196,-1.6437208329375865,-0.010319127995884969
99.30000000000084,13.182418868065223,-1.6351315467703094,-0.011124002286545753
100.40000000000084,13.219871903339225,-1.6271274653454748,-0.010320377199111164
101.50000000000085,13.256537594638164,-1.6180790672176901,-0.010319991670265871
102.60000000000088,13.29303644072034,-1.6096410867124848,-0.010320091724824287
103.7000000000009,13.3298713414083,-1.603354493731824,-0.010338420792564307
104.8000000000009,13.366475019448862,-1.5937146939163704,-0.011640306561762515
105.90000000000092,13.40257160784691,-1.5847209688105344,-0.011632404339765756
107.00000000000094,13.439222315351795,-1.5760890387365554,-0.012933384473083898
108.10000000000096,13.475506890145102,-1.567349822145184,-0.012962416125454013
109.20000000000097,13.510895876972251,-1.5587425702740887,-0.014313410927653258
110.30000000000098,13.54750756170482,-1.5497524699076313,-0.014275750071549353
111.400000000001,13.58493427795816,-1.5396792694651495,-0.015148277093119944
112.50000000000102,13.621237295974405,-1.53280834723667,-0.015590196564773784
113.60000000000103,13.658190264601338,-1.524382388118415,-0.015589338803937203
114.70000000000104,13.694548450807446,-1.5163432127209593,-0.0158360294667359
115.80000000000106,13.730479212441205,-1.5065482599814093,-0.015222456799139472
116.90000000000109,13.766800085805045,-1.4994412380565998,-0.0149287531394382
118.0000000000011,13.803136973731188,-1.4901703844862635,-0.015591478269720405
119.1000000000011,13.839024284922047,-1.4805364611665024,-0.016902808959814664
120.20000000000113,13.87549416531009,-1.4729834047631643,-0.01745375570736396
121.30000000000115,13.91126776582253,-1.4630756511277399,-0.018192351788117733
122.40000000000116,13.947323154218964,-1.454366540650329,-0.019545624557284036
123.50000000000117,13.983278306615631,-1.4452869364325098,-0.019552933760987656
124.60000000000119,14.019097358869796,-1.4378187907686968,-0.018948981444881774
125.70000000000121,14.0548459685403,-1.427637538584541,-0.018558874194169128
126.80000000000122,14.090504147632407,-1.4198754773481659,-0.018560086154400857
127.90000000000123,14.125996061663916,-1.4129143786230094,-0.018560088100269212
129.00000000000125,14.161950006353386,-1.4034573622874813,-0.018560087991234653
130.10000000000127,14.197482903271256,-1.3952905904938953,-0.01856008843480339
131.2000000000013,14.232723504102136,-1.3865309019544023,-0.018560198043283904
132.3000000000013,14.268077227311078,-1.3792575868094414,-0.01856092516519059
133.4000000000013,14.304273624055304,-1.3703198070625489,-0.020728695457902013
134.50000000000134,14.339081578568182,-1.3615632153467914,-0.021189595825078733
135.60000000000133,14.37475624946229,-1.3518766990366382,-0.021189997223760138
136.70000000000135,14.409808282854272,-1.3426910761881723,-0.021191757142728918
137.80000000000138,14.444866382095348,-1.3338797522356556,-0.02207128216310128
138.9000000000014,14.479628188238209,-1.3259613247364257,-0.02215617109779444
140.00000000000142,14.514823462658025,-1.3168734806001543,-0.02250847593784755
141.10000000000142,14.549673251380355,-1.3099472778195593,-0.022490286713101604
142.20000000000144,14.58447876229014,-1.2996338614119407,-0.023508504701239552
143.30000000000146,14.619621867294363,-1.2919808958835182,-0.023500200013343076
144.40000000000146,14.65442769183228,-1.2821477498576122,-0.023495408731058376
145.50000000000148,14.68925416958265,-1.2740080753162244,-0.024231629422734713
146.6000000000015,14.723751191643608,-1.2651560808444915,-0.024159331072797663
147.70000000000152,14.75891422591792,-1.2563409160892647,-0.024160502995909106
148.80000000000155,14.79336935589076,-1.2484233090590477,-0.02426044960027607
149.90000000000154,14.828027227006618,-1.2390579980757066,-0.024490818457677754
151.00000000000156,14.86252169821157,-1.23111674508818,-0.02448819823329007
152.1000000000016,14.89717648709028,-1.2229432075372952,-0.024818437098385715
153.20000000000158,14.93152269295087,-1.2146869453920042,-0.025147116664639313
154.3000000000016,14.966029103321862,-1.2064960285852195,-0.02614591034092051
155.40000000000163,15.000281455938064,-1.1978283647318455,-0.026795244355634296
156.50000000000165,15.03468982994808,-1.1899017304232042,-0.026789882741899085
157.60000000000167,15.068206733621958,-1.18253562537589,-0.026789927569105032
158.70000000000167,15.102948752093802,-1.1749337259739778,-0.02678992801654445
159.8000000000017,15.137741798705582,-1.1681930172406905,-0.026789927231044786
160.9000000000017,15.172356606118544,-1.1602640845222174,-0.026789848027423346
162.0000000000017,15.206584089480604,-1.154368034098041,-0.026798671825288167
163.10000000000173,15.240908336868538,-1.1475910589336238,-0.02711611348187759
164.20000000000175,15.275187030295367,-1.1397797035622441,-0.027120147407162953
165.30000000000177,15.309468742363062,-1.1326535806773315,-0.027119999610281553
166.4000000000018,15.34377602214702,-1.1260104768106967,-0.02712209415171518
167.5000000000018,15.377838873483686,-1.1191003857323225,-0.026849758156741288
168.6000000000018,15.411816466592995,-1.1154098722585255,-0.02679048646894433
169.70000000000184,15.446335997529834,-1.1075088177443317,-0.026789920986737492
170.80000000000183,15.479710193705955,-1.1020587855054018,-0.02679090222884284
171.90000000000185,15.514441887390428,-1.0959426402435666,-0.02672756356380379
173.00000000000188,15.548898850753607,-1.090828885305043,-0.02879478156016635
174.1000000000019,15.582630646776737,-1.0844914768906089,-0.028770611492335618
175.20000000000192,15.61683592420598,-1.079331824054593,-0.02877019327840813
176.30000000000192,15.650737690315413,-1.0741164544336859,-0.028770199990874268
177.40000000000194,15.684784553893488,-1.0691694649139614,-0.028770200002544932
178.50000000000196,15.718688953676152,-1.0641323176286732,-0.02877019993951002
179.60000000000196,15.752763665432719,-1.0583197946596063,-0.028770189685211278
180.70000000000198,15.78670953554686,-1.0542471881330673,-0.028771116594862534
181.800000000002,15.82061039448699,-1.0496261840540617,-0.028790614705568096
182.90000000000202,15.854077582861619,-1.044916669394049,-0.03007583083232568
184.00000000000205,15.887918756879882,-1.0408378227153452,-0.03009017539886738
185.10000000000204,15.921800089068153,-1.0367186429622812,-0.03009009955392461
186.20000000000206,15.955325559258458,-1.031664362267794,-0.03008584005572512
187.3000000000021,15.989015600935495,-1.0276840248535666,-0.03068539105930146
188.40000000000208,16.02308512492273,-1.023081047459362,-0.03108150539067367
189.5000000000021,16.05655601526557,-1.020150119647287,-0.031093604576022393
190.60000000000213,16.090657750757778,-1.0159584132646025,-0.03043904793896779
191.70000000000215,16.123674533191515,-1.0113259006848516,-0.03041978479723717
192.80000000000217,16.157337727124517,-1.0075045705848642,-0.030417360020364548
193.90000000000217,16.190972187323872,-1.0019892269341824,-0.030766839960883807
195.0000000000022,16.2244592853889,-1.0008949795509514,-0.030749222406021737
196.1000000000022,16.2579846678137,-0.9957386308480515,-0.03074561165393952
197.2000000000022,16.291401912574234,-0.9913967169995639,-0.03141978407377177
198.30000000000223,16.3252926507487,-0.9871484294677061,-0.032056758740031555
199.40000000000225,16.358898020005622,-0.9851252455050457,-0.03339016421228891
200.50000000000227,16.39244375413743,-0.9805904631188691,-0.0333705569995697
201.6000000000023,16.425278316879865,-0.9783479111762069,-0.033370100260699864
202.7000000000023,16.459238906913686,-0.9720549255131234,-0.033370107370289226
203.8000000000023,16.492527127524692,-0.9717249146073956,-0.033370131070247666
204.90000000000234,16.52605009638433,-0.9673246279789124,-0.033372698745883334
206.00000000000233,16.559168650630625,-0.9651260850065968,-0.032824268886952446
207.10000000000235,16.592968011414186,-0.9611370003818684,-0.03206040993745596
208.20000000000238,16.626344658890257,-0.9575476893813598,-0.03205363916216797
209.3000000000024,16.659729239006495,-0.9547745997856967,-0.03343561694956332
210.40000000000242,16.693054802317366,-0.9512786893714302,-0.03350812906671585
211.50000000000242,16.726779828208763,-0.9487936886549084,-0.03467981994805669
212.60000000000244,16.759940240353263,-0.9466898851484509,-0.03468997896067627
213.70000000000246,16.793348927888797,-0.942561572726972,-0.03468956819125246
214.80000000000246,16.826994509012682,-0.9406131645222742,-0.034831370134765116
215.90000000000248,16.860031299290107,-0.9388176421837965,-0.03600996343011076
217.0000000000025,16.89367211840665,-0.9346458926595796,-0.03600970797876357
218.10000000000252,16.92691400483721,-0.9318289673960439,-0.036009845591174816
219.20000000000255,16.96021731815091,-0.9283546148046589,-0.036009843995108426
220.30000000000254,16.993457563661778,-0.9283509903040875,-0.03600985108054289
221.40000000000256,17.027181626530062,-0.9258266730415953,-0.036009376974854845
222.5000000000026,17.05956226919621,-0.9228021420353912,-0.03601655631785228
223.60000000000258,17.092893360575946,-0.9209762638607649,-0.03733460672702815
224.7000000000026,17.126458298031142,-0.9182416245136611,-0.03733004476421087
225.80000000000263,17.15996957728416,-0.9151112286499703,-0.03733011600899072
226.90000000000265,17.19354227968449,-0.9131969313770443,-0.03733011420753929
228.00000000000267,17.22669777534515,-0.9115318916212743,-0.037330249975100926
229.10000000000267,17.25994171901665,-0.908215237402356,-0.03732986672314009
230.2000000000027,17.293231614889613,-0.9077354704876062,-0.0385146267810752
231.3000000000027,17.32663902307924,-0.9051429752021737,-0.038640177846444246
232.4000000000027,17.359670730539367,-0.9026833780498145,-0.03863979799964845
233.50000000000273,17.393059310339996,-0.9019730540895186,-0.03857908361189377
234.60000000000275,17.426093431186768,-0.9012500766068368,-0.039874720883890546
235.70000000000277,17.459518239378852,-0.8988097424011602,-0.04128284966750906
236.8000000000028,17.492273709213084,-0.8974585044176013,-0.04128017648592319
237.9000000000028,17.52587995959174,-0.8962705354569493,-0.04128038360893438
239.0000000000028,17.559147617193492,-0.894154134758822,-0.0412696587024457
240.10000000000284,17.592709193024756,-0.8940259848930632,-0.03992922041849667
241.20000000000283,17.62565162806507,-0.8932192358802884,-0.039908186347106245
242.30000000000285,17.658944182486948,-0.8897982894777086,-0.04129004237229461
243.40000000000288,17.691941523620727,-0.8891302209100247,-0.04128023492713773
244.5000000000029,17.724187778147364,-0.8882022010667592,-0.0412800179887185
245.60000000000292,17.758721313299542,-0.8855428378836945,-0.041280062854409216
246.70000000000292,17.791632151838634,-0.8854081753323881,-0.04128451893965934
247.80000000000294,17.824933312093805,-0.8837196933754187,-0.04232837176965809
248.90000000000296,17.85825768437488,-0.8822208695415523,-0.04259142502699209
250.00000000000296,17.89171412234692,-0.8817492241658348,-0.04259184265345439
251.10000000000298,17.924645043774888,-0.8814128172256975,-0.04229399917270715
252.200000000003,17.957785366164885,-0.8806335549709163,-0.04193789915960888
253.30000000000302,17.991090122001694,-0.8781522358014936,-0.04194017319834131
254.40000000000305,18.024211035919837,-0.8776989549793994,-0.0419344971816864
255.50000000000304,18.05731535233541,-0.877379983870872,-0.042656802785077996
256.6000000000031,18.09033537396268,-0.8768071793824724,-0.043250009476957896
257.7000000000031,18.123960609439692,-0.8762086799733022,-0.043250013739441595
258.8000000000031,18.15701137891173,-0.8758366777833337,-0.04324394746723259
259.9000000000031,18.190030180417555,-0.8734291689590254,-0.04456952777213585
261.0000000000031,18.22308503773634,-0.8731931316958067,-0.04452207662285668
262.10000000000315,18.256514917609362,-0.8727468887303418,-0.0459009804867998
263.2000000000032,18.289243121561718,-0.8717768496299266,-0.047161780498006234
264.30000000000314,18.321948372440104,-0.8709565841527525,-0.0472085178285373
265.40000000000316,18.355250903898988,-0.8717571218310544,-0.047217671194554
266.5000000000032,18.388852689013504,-0.8705242870309955,-0.04636025575358582
267.6000000000032,18.421873376111687,-0.8713407764176624,-0.04700876273482013
268.70000000000323,18.455685146200786,-0.8699667494205319,-0.04721050017706929
269.80000000000325,18.48851652849826,-0.8693498441362885,-0.047209967877675396
270.9000000000033,18.521591629963684,-0.8682841299664106,-0.047211378532867165
272.0000000000033,18.554737902089343,-0.8682432888725362,-0.04693289006401491
273.1000000000033,18.58796360172842,-0.8676533712461385,-0.04719610423076226
274.20000000000334,18.62121554217128,-0.8677858374913834,-0.04721026410649509
275.30000000000337,18.654288073456158,-0.8669446731090138,-0.04789620432130892
276.40000000000333,18.687578568306723,-0.8655471306700668,-0.049890564386620095
277.50000000000335,18.720587978279294,-0.8644062872659689,-0.04984022908133978
278.6000000000034,18.754040990672564,-0.8644714432437645,-0.04980312425737443
279.7000000000034,18.78702934912935,-0.8639174486882729,-0.05119201962683473
280.8000000000034,18.82046199139945,-0.8623040345906121,-0.051159912129274066
281.9000000000034,18.85330491679336,-0.8611486378768918,-0.051159838847140815
283.0000000000034,18.885944970401482,-0.860793385919608,-0.05115983109565736
284.10000000000343,18.919417381365008,-0.8615451142470784,-0.05116011227160078
285.20000000000346,18.95295067373487,-0.860067634386597,-0.05123540416402328
286.3000000000035,18.98639916401601,-0.8587773794847862,-0.05149182646093342
287.4000000000035,19.01891655899332,-0.8598378327130147,-0.05150011933281773
288.5000000000035,19.052934118381774,-0.8574658740352941,-0.051501167659444125
289.60000000000355,19.08610350159468,-0.8555585847913743,-0.051407009475596954
290.70000000000357,19.119406064511466,-0.8561699622318341,-0.05280949911623445
291.8000000000036,19.152721199878417,-0.8553347963220014,-0.053685931313332436
292.9000000000036,19.185826831050434,-0.8548599101726188,-0.05523775201951553
294.0000000000036,19.219270411881702,-0.8542173685777819,-0.05544060745312418
295.1000000000036,19.252545578385043,-0.8545633467464812,-0.05544017232361931
296.2000000000036,19.285548038952143,-0.8539204515440153,-0.05544015593292251
297.30000000000365,19.319215946212452,-0.8542952860494336,-0.05544015006995595
298.4000000000037,19.352124822571277,-0.8540218541266381,-0.055439023964382717
299.5000000000037,19.385415811322545,-0.8532843155604015,-0.05555324083536117
300.60000000000366,19.41867137074016,-0.85420799965837,-0.05573906756900193
301.7000000000037,19.451885880946712,-0.8533512574990525,-0.05578001764651663
302.8000000000037,19.485355036768237,-0.8531395138027209,-0.055696151824419005
303.90000000000373,19.51878148145948,-0.8550864726776206,-0.05706738197480732
305.00000000000375,19.55199259981303,-0.8548045277379704,-0.05838782999748071
306.1000000000038,19.585280593912472,-0.8545413337170137,-0.05840043914137594
307.2000000000038,19.61874585092034,-0.8560772558153065,-0.05840040899993948
308.3000000000038,19.652232805784365,-0.8560984843971313,-0.05835519933640798
309.40000000000384,19.685248755296833,-0.8568943397674734,-0.058732408409323256
310.5000000000038,19.718797206527853,-0.8577334212967764,-0.05874009729534624
311.60000000000383,19.752069740825043,-0.8584706695041023,-0.05874044500272646
312.70000000000385,19.78532351344007,-0.859885141762907,-0.058690498945719316
313.8000000000039,19.81889537386847,-0.8602657710059334,-0.060071361154766745
314.9000000000039,19.851943236776158,-0.8613503807644235,-0.06004010059980125
316.0000000000039,19.885596609151687,-0.8641127672075958,-0.06142619985230935
317.10000000000394,19.919127947135436,-0.8673771438300848,-0.06138027250579059
318.2000000000039,19.952742432680566,-0.8688572917876575,-0.0627865132992187
319.30000000000393,19.985728570754173,-0.8696677341742965,-0.06268816680480649
320.40000000000396,20.019170925702014,-0.8718143099283331,-0.06269576292958368
321.500000000004,20.053133045027483,-0.8756658295491045,-0.06406092472833746
322.600000000004,20.086275177473816,-0.8773540019593054,-0.06400448307083595
323.700000000004,20.11990959556776,-0.8803578495072368,-0.06533158581865228
324.80000000000405,20.153062407691944,-0.8835349154369057,-0.0652960850299813
325.90000000000407,20.186848906185144,-0.8856429315088842,-0.06668107543393376
327.0000000000041,20.21943965689429,-0.8904467907717974,-0.06693532946641945
328.10000000000406,20.253057983110796,-0.893361688708603,-0.06796855278217162
329.2000000000041,20.287364159737752,-0.8962265509592997,-0.06787089094264998
330.3000000000041,20.32060588763677,-0.9001586009440403,-0.06927970091833346
331.4000000000041,20.353954189468727,-0.9049553356026397,-0.07003536517555897
332.50000000000415,20.388078289255482,-0.9098470025755898,-0.07193262412490586
333.6000000000042,20.421405291829164,-0.9144188780930356,-0.07237051348505164
334.7000000000042,20.455146284560914,-0.9207199277880427,-0.073507979597502
335.80000000000416,20.488568812611277,-0.9241557949140263,-0.07446230048674662
336.9000000000042,20.522446486235253,-0.9291401850532115,-0.07447256048067974
338.0000000000042,20.55607172079149,-0.9332893766009541,-0.07590840124917131
339.10000000000423,20.589701646693225,-0.9376302924464213,-0.07650472318641954
340.20000000000425,20.62289126735515,-0.9430013670925191,-0.07731634170236168
341.3000000000043,20.65696921698208,-0.9464993227686243,-0.07851029876277993
342.4000000000043,20.690809747287513,-0.9503178752352923,-0.07992252269027311
343.5000000000043,20.72378292691782,-0.9545749252987555,-0.08138114992913525
344.60000000000434,20.757795347351923,-0.9578453137354621,-0.0828823456308001
345.7000000000043,20.791574376825263,-0.9609460288248545,-0.08447217171794152
346.80000000000433,20.82550814518398,-0.9665739051603043,-0.08611583098632014
347.90000000000435,20.85917385910107,-0.9688852030017534,-0.08806594041225724
349.0000000000044,20.892760825554127,-0.9711412105965403,-0.09079446204811248
350.1000000000044,20.926383000029862,-0.9713468248435713,-0.09316957714310226
351.2000000000044,20.960398616098544,-0.9722902192135809,-0.09496723015528241
352.30000000000445,20.993882823710283,-0.9730903165228968,-0.09736004446930124
353.4000000000044,21.027515146189117,-0.9731948823869389,-0.09991802202931988
354.50000000000443,21.06153939166533,-0.9710316240396014,-0.10227308583262795
355.60000000000446,21.094781872093407,-0.9670681024228247,-0.10501269608032082
356.7000000000045,21.12866591189638,-0.9647670257332899,-0.10583182522963819
357.8000000000045,21.162792903851805,-0.9613307585900279,-0.1088302613866774
358.9000000000045,21.196079739583485,-0.9577081170980696,-0.11127128282058552
360.00000000000455,21.229447117011908,-0.9512649549467564,-0.11389450666783896
361.10000000000457,21.26354714727721,-0.9468149790520293,-0.11679074657318322
362.2000000000046,21.297633259903744,-0.9379510778515499,-0.12047628894135753
363.30000000000456,21.33127375070104,-0.9345432960652102,-0.123241382055705
364.4000000000046,21.364711775935444,-0.9288353751812499,-0.1254118997052296
365.5000000000046,21.39851504525563,-0.9218925029823264,-0.12841007279914063
366.6000000000046,21.432386983902145,-0.916351302237682,-0.13068533818788453
367.70000000000465,21.466172582907735,-0.9129219797765115,-0.13410417153759635
368.8000000000047,21.49987566868883,-0.9087125575280975,-0.1356809511125281
369.9000000000047,21.53391521853666,-0.9035646527679658,-0.13965905376643617
371.00000000000466,21.567638190902805,-0.8975768033190717,-0.1426716384855351
372.1000000000047,21.601698333467755,-0.8966677743677144,-0.14480014352816983
373.2000000000047,21.635608150888235,-0.8940250661096826,-0.14727514294069488
374.30000000000473,21.669391037968783,-0.891518628818013,-0.1509167489368335
375.40000000000475,21.702856446561782,-0.8900396547362907,-0.15375958885775454
376.5000000000048,21.73695637451716,-0.8878222147881735,-0.1561877733446324
377.6000000000048,21.770992949857597,-0.8883617169814716,-0.15824383213229165
378.7000000000048,21.804828500591835,-0.8881540749640039,-0.16115908710928561
379.80000000000484,21.839274341909086,-0.8879227217620976,-0.16356726151461443
380.9000000000048,21.873433139014942,-0.8884265821466788,-0.1640048276339341
382.00000000000483,21.907337015460175,-0.8887137415522387,-0.16585304694771796
383.10000000000485,21.9412105273461,-0.8888335482720605,-0.16833029782184683
384.2000000000049,21.975222595819638,-0.8885088295561373,-0.17096504949937108
385.3000000000049,22.009568733072882,-0.8901812109925337,-0.17311727200664073
386.4000000000049,22.04355600155213,-0.889839987215364,-0.17468234929813464
387.50000000000495,22.077391175063795,-0.8891070701771362,-0.17682189915710023
388.6000000000049,22.11175184798656,-0.8896319026716003,-0.1787970182936367
389.70000000000493,22.14579489954987,-0.8895951305336368,-0.1795964956384295
390.80000000000496,22.17972131449943,-0.892076440442181,-0.1811160348384071
391.900000000005,22.21424909463169,-0.8937459508244796,-0.18234407312714884
393.000000000005,22.24817576016409,-0.8928311767207647,-0.18362524080684572
394.100000000005,22.28247592625369,-0.895084465872705,-0.1858963714512436
395.20000000000505,22.31667068953743,-0.8971239014181204,-0.1875627865702838
396.30000000000507,22.350744355788848,-0.8991941098764796,-0.18788767025326214
397.4000000000051,22.3849823128643,-0.901328857988444,-0.18911752032343276
398.50000000000506,22.419099819017738,-0.9052520011435372,-0.18994875101107933
399.6000000000051,22.453586694975012,-0.9065950696782894,-0.19093334575170573
400.7000000000051,22.487584179903745,-0.908963441050945,-0.1925340466208212
401.8000000000051,22.521932502718833,-0.9100835916558511,-0.19380979939073217
402.90000000000515,22.55552593066717,-0.9144863363885212,-0.1956429881958499
404.0000000000052,22.58990683110958,-0.9174876789704498,-0.19640004568490754
405.1000000000052,22.624949290416218,-0.9204360881066028,-0.1977061985474058
406.20000000000516,22.65905614624744,-0.9240947962658933,-0.19780488936125673
407.3000000000052,22.69339125702825,-0.9283186796458656,-0.19913073993246622
408.4000000000052,22.72794829020694,-0.9308104925915595,-0.19994589658194695
409.50000000000523,22.762057948897304,-0.9355381412108391,-0.20064041661168375
410.60000000000525,22.796686570812337,-0.9380092334790837,-0.20199052614967528
411.7000000000053,22.83084583623926,-0.9420121534846585,-0.2033093368081289
412.8000000000053,22.86542009329737,-0.9471755561878404,-0.20427844407429996
413.9000000000053,22.899115961234916,-0.9508220043302517,-0.20500188448678447
415.00000000000534,22.934254508383358,-0.9535512948133968,-0.20632817627886135
416.1000000000053,22.96860518899549,-0.9577600302407904,-0.2076098726145421
417.20000000000533,23.00275452873014,-0.9632006058179302,-0.20892129949096327
418.30000000000535,23.0374803957602,-0.9668497816971536,-0.2096621959837992
419.4000000000054,23.071924737318792,-0.9704901025089709,-0.2102112572482615
420.5000000000054,23.10641011708652,-0.9735033857371441,-0.2128813846384605
421.6000000000054,23.1409792321477,-0.9790682130410432,-0.2143223309341642
422.70000000000545,23.175540523353146,-0.9847108574230855,-0.21468898941293757
423.8000000000054,23.209461120515527,-0.9874424061622787,-0.21438223712465643
424.90000000000543,23.244082039800873,-0.9931332181245,-0.21575369901241492
426.00000000000546,23.27895396144553,-0.9980156796224543,-0.21723186640092385
427.1000000000055,23.313271124642938,-1.0004922526332436,-0.21892763572583895
428.2000000000055,23.347795666994827,-1.0066211937281615,-0.22040243412357974
429.3000000000055,23.382493352266614,-1.0110917127898822,-0.221656187532691
430.40000000000555,23.417300892005404,-1.017110798148567,-0.22276644744924656
431.50000000000557,23.4516383016049,-1.0228587711804837,-0.22419036493836053
432.6000000000056,23.48648458540461,-1.0280758653953448,-0.22550938098652384
433.70000000000556,23.52099218130983,-1.0332227385658213,-0.22701921656947288
434.8000000000056,23.55573059564499,-1.0397162776057647,-0.2285033990612364
435.9000000000056,23.5902484999989,-1.0457702424201027,-0.2310076652387414
437.0000000000056,23.624819851908434,-1.051820910367452,-0.2327568016333159
438.10000000000565,23.659458611713774,-1.0551387753429338,-0.2338948368197009
439.2000000000057,23.694558497368867,-1.0580686905920247,-0.23640622195435945
440.3000000000057,23.729418022855036,-1.0603878449979178,-0.2381423755565657
441.40000000000566,23.763867828877444,-1.0612182251109408,-0.23957984422119027
442.5000000000057,23.79856225088614,-1.0614045027982846,-0.24256474706217546
443.6000000000057,23.833542229562838,-1.0613469316954662,-0.24458356068069032
444.70000000000573,23.868076861651918,-1.060040110941919,-0.24587236604924367
445.80000000000575,23.902759044935426,-1.055279058539779,-0.2475959100588061
446.9000000000058,23.937597195474293,-1.0509834446849398,-0.24924660460303683
448.0000000000058,23.97235614394331,-1.0472824885914138,-0.25090970831022164
449.1000000000058,24.007034253870145,-1.0436873523075825,-0.25306380991226307
450.20000000000584,24.041689454485837,-1.0410631088353774,-0.2543092418470585
451.3000000000058,24.076392661475566,-1.035927162802949,-0.25509283593956766
452.40000000000583,24.111112139617372,-1.0301577509065007,-0.25783161925000364
453.50000000000585,24.14600831153603,-1.0283483222882335,-0.2592347410189024
454.6000000000059,24.18025649396144,-1.0252173835148366,-0.26005877619466977
455.7000000000059,24.215113250577176,-1.023208119422599,-0.2608526047621944
456.8000000000059,24.24977978360658,-1.0217511927963971,-0.2622812030924928
457.90000000000595,24.284820326295062,-1.022462962944617,-0.26394621724322676
459.0000000000059,24.31928198144224,-1.0231123163251328,-0.26521479154732575
460.10000000000593,24.35446206839715,-1.0212653063195318,-0.2663530638619376
461.20000000000596,24.389617320602234,-1.0227202250907117,-0.26827912439697954
462.300000000006,24.424205582737184,-1.0231470608742042,-0.2690761677323392
463.400000000006,24.459234868810526,-1.0240475453603322,-0.26990232705537975
464.500000000006,24.494167202154554,-1.0251887595741236,-0.271150550422667
465.60000000000605,24.529041536393233,-1.0270565710564088,-0.2723431269579786
466.70000000000607,24.56387443170139,-1.0280524525779149,-0.2737031125842404
467.8000000000061,24.59879987200451,-1.0301357493674348,-0.27528160774280686
468.90000000000606,24.633747464135006,-1.0313889387312494,-0.27704612789470584
470.0000000000061,24.66875859295138,-1.032546645600922,-0.2783044940809165
471.1000000000061,24.70411844718744,-1.0346916402095525,-0.27967029775232044
472.2000000000061,24.739233095492317,-1.0371268648236587,-0.2810460586438217
473.30000000000615,24.77419359350454,-1.0396798009742647,-0.2816715158302183
474.4000000000062,24.809453007277703,-1.0410219105766738,-0.2833438881047319
475.5000000000062,24.84422116950586,-1.0439463084117087,-0.28485651664872647
476.60000000000616,24.879275934923776,-1.0464877254316662,-0.28634201924529945
477.7000000000062,24.914380840571322,-1.0480728528360914,-0.2879764634940658
478.8000000000062,24.949641631346683,-1.0499813735002537,-0.29023835574519596
479.90000000000623,24.984641189336777,-1.0513980350366756,-0.29274477010338185
481.00000000000625,25.01970346756855,-1.0529866196430206,-0.29464669714988956
482.1000000000063,25.054806301262527,-1.056853366223308,-0.29634005974471034
483.2000000000063,25.090159373204273,-1.0586045566431865,-0.2977305876689069
484.3000000000063,25.125069919534237,-1.061089555709054,-0.2992974286910606
485.40000000000634,25.16016043526349,-1.0621086012844627,-0.3008127217818384
486.5000000000063,25.195030699319275,-1.0642576201389284,-0.3025644036341011
487.60000000000633,25.230637367032536,-1.064135021580456,-0.30460760949438725
488.70000000000636,25.265658391590904,-1.0655830727084736,-0.3068863255224672
489.8000000000064,25.300913557724027,-1.065826335240086,-0.3082957731987359
490.9000000000064,25.335716636399614,-1.0669040378022763,-0.3094324535258983
492.0000000000064,25.371115643525663,-1.065287289010065,-0.31045027905683
493.10000000000645,25.405418846126164,-1.0657518383692692,-0.3115329071660269
494.2000000000064,25.441333796829465,-1.066390535976731,-0.31244314429477305
495.30000000000643,25.476763513792214,-1.0648123625967052,-0.3139528934110114
496.40000000000646,25.511691633134582,-1.0647903590463346,-0.3155470321398628
497.5000000000065,25.547003862624493,-1.0609163346478434,-0.31735334573807883
498.6000000000065,25.582208540033026,-1.0630302903864985,-0.3182744280075158
499.7000000000065,25.617341910800704,-1.0604370734490296,-0.3195925038003482
500.80000000000655,25.65198454909877,-1.060429748652327,-0.32089699039509556
501.90000000000657,25.68806778489074,-1.058455468077491,-0.32225641787854054
503.0000000000066,25.723184552407226,-1.057518296956007,-0.3221568838599791
504.10000000000656,25.75852791536267,-1.05860338465473,-0.3235311376918837
505.2000000000066,25.793975741641013,-1.0557495112810513,-0.32345617418241757
506.3000000000066,25.828949972369173,-1.0558188664831896,-0.32485173040983284
507.4000000000066,25.864264632478836,-1.055986454318031,-0.325627542301115
508.50000000000665,25.89936432587299,-1.0563984147851742,-0.3263141402454308
509.6000000000067,25.935094863906315,-1.0572370173275516,-0.32676615179917334
510.7000000000067,25.97009838844812,-1.0566979203063602,-0.32782006947101205
511.80000000000666,26.005160034163747,-1.0568978333924646,-0.3280909072018794
512.9000000000067,26.0404376970597,-1.057307565388621,-0.32913096359023664
514.0000000000067,26.076432736031173,-1.0572175459844717,-0.3291301243222797
515.1000000000067,26.111618481224173,-1.0568851692528751,-0.3291369211549511
516.2000000000068,26.146746841740537,-1.0569128747057583,-0.33043147974436016
517.3000000000068,26.182520823315745,-1.0581819845840528,-0.33102995851511885
518.4000000000068,26.217778368852137,-1.0577317322841824,-0.331773590504731
519.5000000000068,26.25298169753019,-1.0570784270223768,-0.33190299447154414
520.6000000000068,26.288609475476385,-1.0567687517713833,-0.333076193016169
521.7000000000069,26.32380051461161,-1.0574225351047095,-0.33307992088120475
522.8000000000068,26.359383360367865,-1.0566615806558095,-0.3330799962641966
523.9000000000069,26.394780890849532,-1.0579723912818961,-0.33308005848496647
525.0000000000068,26.430124883688364,-1.0579834959941306,-0.3330802835618645
526.100000000007,26.46571450607617,-1.0608593147885728,-0.33418494813930355
527.2000000000069,26.501172158921698,-1.0681634955697124,-0.3343993002672141
528.300000000007,26.536787919953653,-1.076608388555024,-0.3343998635145313
529.4000000000069,26.57228695978951,-1.0843501190031486,-0.3343968420013925
530.5000000000069,26.60768749366525,-1.091775557301489,-0.33474857913642
531.600000000007,26.64306592678604,-1.0950939366162862,-0.33506055148050296
532.700000000007,26.678470890965578,-1.1006625295558008,-0.33506009191430985
533.800000000007,26.71406703534397,-1.1036253171780732,-0.3350601356894525
534.900000000007,26.749473599861542,-1.107135826882541,-0.33506010864338576
536.000000000007,26.785100324180576,-1.109190508457639,-0.335060701397369
537.1000000000071,26.820499020913456,-1.1128835585747083,-0.3345341047210706
538.2000000000071,26.85624643629557,-1.1155732081872003,-0.3344002668502255
539.300000000007,26.891483096208574,-1.1185335339314926,-0.3343966396721756
540.4000000000071,26.927576100925172,-1.1218083162163306,-0.33516650180313645
541.500000000007,26.96308520334217,-1.1246058136154857,-0.3357241391832315
542.6000000000072,26.9988627496141,-1.124571478888621,-0.3369588375352661
543.7000000000071,27.033509324467726,-1.1235048985630576,-0.3370380943540625
544.8000000000072,27.06921704134051,-1.1228446443315223,-0.3370400228349566
545.9000000000071,27.105273225395166,-1.1236744516346144,-0.3370397195763335
547.0000000000072,27.141210710654537,-1.1218556852360884,-0.33676989702784077
548.1000000000072,27.17675110682105,-1.1212094394250482,-0.3357238315694291
549.2000000000072,27.21243218866535,-1.1233551342208306,-0.3367462117337876
550.3000000000072,27.24826044274329,-1.1252855249397598,-0.3370361719563384
551.4000000000073,27.28406579006529,-1.1264708971042006,-0.3383326798801112
552.5000000000073,27.31950279283298,-1.1271989056418388,-0.33835002913106615
553.6000000000073,27.355326239705427,-1.126790730234544,-0.3383501902812682
554.7000000000073,27.391305628791418,-1.1278832703863348,-0.3383546589826909
555.8000000000073,27.42699623338719,-1.128486119969436,-0.33767618104605557
556.9000000000074,27.46186989485102,-1.1286023804774,-0.33769165082169295
558.0000000000074,27.498616177731204,-1.1265981252751442,-0.33765884530502754
559.1000000000074,27.53439922707806,-1.1264472744029639,-0.3389956210172791
560.2000000000073,27.570063915254877,-1.1277353881915673,-0.33901004117279276
561.3000000000073,27.6061400828845,-1.1268380217941611,-0.33901004509858534
562.4000000000074,27.641859712218896,-1.1270021037094962,-0.3390100440055823
563.5000000000074,27.677650304515936,-1.1243675878293162,-0.33901004402535495
564.6000000000074,27.713171376549,-1.1252272755502013,-0.3390100478477831
565.7000000000074,27.749259707884804,-1.1231987639055914,-0.33900992973421307
566.8000000000075,27.784829669027282,-1.1244917619510526,-0.338952961406485
567.9000000000075,27.82141739394995,-1.1246422482146048,-0.34032070657154634
569.0000000000075,27.856850996161935,-1.1203385363919935,-0.340323371254581
570.1000000000075,27.892735809074175,-1.1209748410405103,-0.3414940761588636
571.2000000000075,27.928866946516163,-1.121763123652238,-0.34165031947035107
572.3000000000076,27.964717754870584,-1.1213121729493252,-0.3416501872615205
573.4000000000076,28.00062672562519,-1.1210852898897699,-0.3416501840055983
574.5000000000076,28.036487068780886,-1.1204477230251622,-0.341650183999767
575.6000000000076,28.07267704283903,-1.1206912256757458,-0.34165018399999836
576.7000000000077,28.10857475351282,-1.1207979204508614,-0.341650184000001
577.8000000000077,28.144628991238765,-1.1208500127115886,-0.3416501840002475
578.9000000000076,28.180595305615956,-1.1219527866871921,-0.3416501840052888
580.0000000000076,28.216736464427107,-1.1228418453508378,-0.34165018130418856
581.1000000000076,28.252839367410015,-1.121806172121231,-0.3416498816297695
582.2000000000077,28.288222898816684,-1.1260275129126613,-0.34167315490340533
583.3000000000077,28.324610218084242,-1.1263959706745394,-0.34296491120223793
584.4000000000077,28.36089481433295,-1.1268859515944778,-0.3429599845608049
585.5000000000077,28.396710987142086,-1.1330000841588141,-0.3429601183278148
586.6000000000078,28.432978347987476,-1.1381288543025927,-0.3425174387327168
587.7000000000078,28.469244160762905,-1.1407851628092864,-0.342301216027332
588.8000000000078,28.50533211764476,-1.144300891507704,-0.3422999372471103
589.9000000000078,28.541112510939197,-1.1494362292986129,-0.34229954881879365
591.0000000000078,28.577483714411994,-1.1574496338580968,-0.3425271662458269
592.1000000000079,28.613716865143054,-1.159562623978582,-0.3430490964953017
593.2000000000079,28.649732136319635,-1.1666825178614135,-0.3436136271264427
594.3000000000079,28.68592977357178,-1.170652360233051,-0.3429687110111965
595.4000000000078,28.722281921082185,-1.176699053455408,-0.34264752834079326
596.5000000000078,28.75807519581038,-1.1848233350455681,-0.34263987419179553
597.6000000000079,28.794664293359496,-1.191860894472242,-0.34263981985062797
598.7000000000079,28.830653037172624,-1.2002650044450554,-0.3426398199950982
599.8000000000079,28.866915909997473,-1.206597139143051,-0.3426398201197891
600.9000000000079,28.90311682667304,-1.2128959278909248,-0.3426398351746105
602.000000000008,28.93940769472595,-1.2216436009392826,-0.34263942679025794
603.100000000008,28.975510863025686,-1.2275727132256116,-0.34337071109528106
604.200000000008,29.01150629804862,-1.237500262275286,-0.3436286659823842
605.300000000008,29.04814445376418,-1.2448461831912772,-0.34351884149448564
606.400000000008,29.084385071096243,-1.251378932951628,-0.34329988039983306
607.5000000000081,29.1209891560049,-1.2597689654299518,-0.34330001423785816
608.6000000000081,29.157175840795155,-1.2673697652778466,-0.34330002312359964
609.7000000000081,29.19350277461987,-1.2747999608822747,-0.34329989205178
610.8000000000081,29.229966181869823,-1.2817324569262147,-0.34329896139399985
611.9000000000082,29.266251799789927,-1.2897350524536848,-0.3435207866390275
613.0000000000082,29.302105499475086,-1.2997151426714604,-0.34264127316990844
614.1000000000081,29.33884791279563,-1.3057776393018221,-0.3426401129834553
615.2000000000081,29.375129219596587,-1.312567414060518,-0.3426400906436555
616.3000000000081,29.411345949840104,-1.3207014531216517,-0.34264001754970996
617.4000000000082,29.447804404695255,-1.3287153184691214,-0.3426532678544447
618.5000000000082,29.484076176537133,-1.3348836115591225,-0.34400842410139365
619.6000000000082,29.52046186587438,-1.3423657714449837,-0.3438915902460935
620.7000000000082,29.557135763307734,-1.3500380186940968,-0.34462502084090874
621.8000000000083,29.593473996574446,-1.357150486031184,-0.34461995948044155
622.9000000000083,29.629538222142045,-1.3662941510367206,-0.34462045997908186
624.0000000000083,29.66607325023311,-1.373165610067236,-0.3446721351340507
625.1000000000083,29.70224550444488,-1.3819894617209552,-0.3432985553925336
626.2000000000083,29.7390739264967,-1.3906094783632257,-0.34329991687992933
627.3000000000084,29.77538434549171,-1.3977675422929945,-0.34329737321555287
628.4000000000084,29.811858176312885,-1.4047599162855635,-0.3436581300034547
629.5000000000084,29.84794456779417,-1.410729795766766,-0.34362974302699456
630.6000000000083,29.884524106581015,-1.4177572778967853,-0.3436300245449395
631.7000000000083,29.920910570149054,-1.424854595878515,-0.34363002799158604
632.8000000000084,29.957126910070382,-1.429257856313473,-0.34363002803291876
633.9000000000084,29.993813325830654,-1.4354425601346437,-0.34363003321414043
635.0000000000084,30.030233322380198,-1.4404637803706122,-0.3436300766654776
636.1000000000084,30.066795037055428,-1.4463372889126203,-0.3435661156401091
637.2000000000085,30.102529243484213,-1.448984887470141,-0.3442687170641143
638.3000000000085,30.138956675727393,-1.4553716660120413,-0.3446085344538279
639.4000000000085,30.175948863337112,-1.4592505342063795,-0.34463606156535764
640.5000000000085,30.21199045835282,-1.461068109998023,-0.3459354315089693
641.6000000000085,30.247728544738855,-1.4647523281888903,-0.34592993968540675
642.7000000000086,30.284753244104007,-1.4693265438558187,-0.3459299860212228
643.8000000000086,30.321272472317045,-1.4707280464059318,-0.3459334904051139
644.9000000000086,30.357940935692458,-1.4747598581338106,-0.34505881598314847
646.0000000000086,30.393995931545977,-1.4773431839965845,-0.3449401488739512
647.1000000000087,30.430606197526153,-1.4802751777904841,-0.34493999637479344
648.2000000000087,30.466743765990387,-1.4810989531929666,-0.34493999983987456
649.3000000000086,30.503453477267037,-1.483630711346768,-0.3449399991320612
650.4000000000086,30.539489446455846,-1.4868738339045926,-0.344941878924129
651.5000000000086,30.576028676905135,-1.4885097240612064,-0.3452001625617611
652.6000000000087,30.612767615797143,-1.4902524436049882,-0.3469018961699324
653.7000000000087,30.649216983785095,-1.4931509205972442,-0.3475809208705929
654.8000000000087,30.68531251848352,-1.496904573618956,-0.34670995337016386
655.9000000000087,30.72236896569502,-1.499887396427597,-0.34625933524468433
657.0000000000088,30.758801702477186,-1.5023223729692439,-0.34625985042303054
658.1000000000088,30.795375565194615,-1.503776331644767,-0.3462598679119888
659.2000000000088,30.83161678943433,-1.5058711384620318,-0.34625986800075603
660.3000000000088,30.86804535072839,-1.5086443624559487,-0.3462598680002231
661.4000000000088,30.904681738919813,-1.5128787248390687,-0.34625986804708964
662.5000000000089,30.941086033544625,-1.5169755281375528,-0.34625986995371516
663.6000000000089,30.977476332890713,-1.5189698643321021,-0.3462593956737847
664.7000000000089,31.013751863738626,-1.5210817842574473,-0.3461859857419256
665.8000000000088,31.05050302875371,-1.5253686932396466,-0.34764337758480446
666.9000000000088,31.087052575914857,-1.5293799676802728,-0.34659564208568616
668.0000000000089,31.123370675712742,-1.5297318668874629,-0.3462503008374411
669.1000000000089,31.160169211761517,-1.53308325454495,-0.3462606015781571
670.2000000000089,31.196436165947475,-1.536814383728965,-0.34626014885070155
671.3000000000089,31.232901764895207,-1.5435339961326213,-0.3462607057178171
672.400000000009,31.26959863093748,-1.547450501708266,-0.3462518336204212
673.500000000009,31.306256623293717,-1.5497202046048628,-0.3471987075215828
674.600000000009,31.342521477408116,-1.5520457712405271,-0.34691476235597296
675.700000000009,31.37931244971979,-1.5563535757813136,-0.34652020715190623
676.800000000009,31.415910362010283,-1.5593226251487793,-0.34626116729076806
677.9000000000091,31.452223802424175,-1.563538251816045,-0.3462599002804789
679.0000000000091,31.488944260999226,-1.5679446209207717,-0.34625990789201255
680.1000000000091,31.52486775608994,-1.5699238802143938,-0.34625990799944173
681.2000000000091,31.561612090478622,-1.5716231115477126,-0.3462599080000066
682.3000000000092,31.5986367651509,-1.576707052698406,-0.34625990799957895
683.4000000000092,31.635392302566842,-1.5799946333728063,-0.34625990787459093
684.5000000000091,31.672031283822385,-1.5833727654311947,-0.3462598977852491
685.6000000000091,31.708513134368435,-1.584067103476446,-0.3462607641854163
686.7000000000091,31.74516780262647,-1.588877154968119,-0.34660246034031106
687.8000000000092,31.781700993216784,-1.5902400953996951,-0.3469190900202612
688.9000000000092,31.818415345734074,-1.5950998791926316,-0.3469204001671966
690.0000000000092,31.855150765946448,-1.598177416487881,-0.34705596490615953
691.1000000000092,31.891846835500665,-1.6013973100599128,-0.34758162165729756
692.2000000000093,31.928109583808048,-1.604856466514054,-0.3475801384792918
693.3000000000093,31.964861234577157,-1.606304182692597,-0.34757365958876374
694.4000000000093,32.00177840308284,-1.6102594723867796,-0.3487006955905265
695.5000000000093,32.0382566762231,-1.6127433783995602,-0.3489001720165188
696.6000000000093,32.07486294593578,-1.6155079740797114,-0.3488998353543167
697.7000000000094,32.11169588789487,-1.6216262413956937,-0.3489451018815126
698.8000000000094,32.148367533161746,-1.6260352363726536,-0.347068130503946
699.9000000000094,32.18509669018578,-1.6294371077343417,-0.3462585741846751
701.0000000000093,32.22178613844389,-1.6346598592303039,-0.3463919191669187
702.1000000000093,32.25837850591155,-1.6379524729528712,-0.3475793536655547
703.2000000000094,32.29522171948167,-1.6399674038210426,-0.34757372102932527
704.3000000000094,32.331606140383734,-1.6428312441309243,-0.3486833372337599
705.4000000000094,32.36868186951456,-1.646963057496405,-0.34890008849285925
706.5000000000094,32.404763149423594,-1.6516124487585184,-0.3488999118206242
707.6000000000095,32.442029707410754,-1.654881402572311,-0.34890071039907955
708.7000000000095,32.47857811056626,-1.657324362050745,-0.34819571153499984
709.8000000000095,32.51572705110664,-1.6621092048294686,-0.3479107939566952
710.9000000000095,32.55243529481496,-1.6648229037096118,-0.34790990952696843
712.0000000000095,32.58906731044348,-1.6685681961129493,-0.34790991567283847
713.1000000000096,32.6259497519576,-1.6702368375779615,-0.34790989674879613
714.2000000000096,32.662830722233345,-1.6751500292366717,-0.347911385554585
715.3000000000096,32.699454386779074,-1.6768863998560777,-0.34755046928180766
716.4000000000096,32.736098970731604,-1.6782215745073514,-0.347602802307704
717.5000000000097,32.77293148400686,-1.6830029735916539,-0.34889697614789217
718.6000000000097,32.810000673936756,-1.6875500830627337,-0.3474931617832522
719.7000000000096,32.84692131619716,-1.6909621547184175,-0.3475696467762792
720.8000000000096,32.88368666572243,-1.693637678904704,-0.347570861447005
721.9000000000096,32.92081285555281,-1.697058240383004,-0.3477029261132589
723.0000000000097,32.95751611041826,-1.6998293730775675,-0.3502096724007635
724.1000000000097,32.99419873246183,-1.7021775101415506,-0.35020408852517493
725.2000000000097,33.03121144837784,-1.7075083857245223,-0.3488846339325171
726.3000000000097,33.068105640641605,-1.7100628770438318,-0.3488899152029732
727.4000000000098,33.10492852484997,-1.7148227055164904,-0.34888995600842154
728.5000000000098,33.141787011858725,-1.7168466897532861,-0.348889956011321
729.6000000000098,33.17879148711078,-1.7212142468861642,-0.34888995523613575
730.7000000000098,33.21563217104743,-1.7244915660477456,-0.3488896952485794
731.8000000000098,33.25255260117649,-1.7281521654814822,-0.34886444710123854
732.9000000000099,33.288853606575245,-1.729978159095729,-0.35021945575990365
734.0000000000099,33.32603506813908,-1.7332185832453137,-0.35021047266242533
735.1000000000099,33.3632058786932,-1.7350065986048966,-0.3497447574416883
736.2000000000098,33.39945004246821,-1.7387459316804579,-0.34925804657704607
737.3000000000098,33.436442897438475,-1.741628185913348,-0.34889777273373346
738.4000000000099,33.474145767524995,-1.7443916188420114,-0.34882418693182915
739.5000000000099,33.51113231141135,-1.7467661258823113,-0.3502090526475903
740.6000000000099,33.54813398126285,-1.7475023211099572,-0.3502100211354642
741.7000000000099,33.584812919157685,-1.7497643303908916,-0.3502094570280714
742.80000000001,33.621866221562,-1.7529039872947043,-0.34880854000665096
743.90000000001,33.65896396740016,-1.7547196271770775,-0.34888944967364255
744.00000000001,33.662310794206995,-1.7553571467642701,-0.348889565034737