File: 01_Data/EIFS_Mesh/STA/N2/30K_min/EIFS_Mesh_STA_N2_30KData_230908_R3.csv
##Temp./Â°C,Time/min,DSC/(mW/mg),Mass loss/mg
41.0,10.606893549487372,-2.307541209476656,0.003762202473931886
42.100000000000016,10.777256208891636,-2.272145414960402,0.0029232622436734523
43.20000000000003,10.893815555431821,-2.2453006215317908,0.0010718874608293127
44.30000000000005,10.989306715826539,-2.2209149622126887,0.002806214814473851
45.40000000000006,11.07032234442754,-2.1983199686814934,0.003511482719186887
46.50000000000008,11.14340944330176,-2.1783546949820365,0.0026374559304955802
47.600000000000094,11.210614968360217,-2.158731407455182,0.0025592663514890646
48.70000000000011,11.272382943674687,-2.141444992298254,0.0021029696077263793
49.800000000000125,11.33164868278398,-2.1219892426293,0.0010042705372739213
50.90000000000014,11.387679919522942,-2.1063777588508867,0.0013691292003223943
52.000000000000156,11.442045183367249,-2.088067034359097,0.0017717936198087259
53.10000000000017,11.493959220047575,-2.0726511046225777,0.0015707279356522719
54.20000000000019,11.543958224917054,-2.058939032474331,0.0019356630834881372
55.3000000000002,11.592738921720654,-2.0443786059403157,0.0011206858087247085
56.40000000000022,11.640914279514686,-2.0324125385625305,0.0001673312484604672
57.500000000000234,11.687236892087864,-2.017069187576637,4.263687430450247e-05
58.60000000000025,11.732862486367807,-2.0071692578237457,-0.0002945506514855367
59.700000000000266,11.777300677164755,-1.9971362707417664,0.0008972650275467231
60.80000000000028,11.820747849654817,-1.9869278208321572,0.00011907386682441512
61.9000000000003,11.86551451905352,-1.9777550115541154,0.001253647759981824
63.00000000000031,11.907446081671965,-1.9688259619610993,0.0004096047850743467
64.10000000000034,11.950305233291465,-1.9616517405295324,0.0012385673039414513
65.20000000000034,11.992353863760403,-1.9543405027085519,-0.000533710215147476
66.30000000000035,12.033798890452086,-1.9491414651041543,0.00026132941089196393
67.40000000000038,12.074977849053711,-1.944761969477687,-0.0008249253126693112
68.5000000000004,12.1156612866489,-1.9389127129894534,-0.0009166271878897625
69.6000000000004,12.15599363989169,-1.9335893014727275,-0.0020665966160149374
70.70000000000041,12.196522294434885,-1.9315494107519542,-0.0013551586187641185
71.80000000000044,12.236888822309067,-1.9259556447255406,-0.00039182649296787275
72.90000000000046,12.276119185550327,-1.9242190645910602,-0.00020066338264879136
74.00000000000047,12.316255705618332,-1.9194398132492367,-0.0022112513122252153
75.10000000000048,12.355521956928722,-1.9161569008056873,-0.0018286618171829971
76.2000000000005,12.394995675780782,-1.912422797218417,-0.0012694187199704388
77.30000000000052,12.433947135562033,-1.9082691686641937,-0.003877284301166739
78.40000000000053,12.472420033699002,-1.9044900476296733,-0.0040970675749956165
79.50000000000054,12.511361827951935,-1.90126251710457,-0.004087753929163718
80.60000000000056,12.55018509086974,-1.897888966247395,-0.004289491640604659
81.70000000000059,12.588290401091319,-1.893826003185757,-0.005819512122337223
82.8000000000006,12.626020459137868,-1.8885315074644156,-0.0067648185006663475
83.9000000000006,12.664958759756828,-1.8828610139415345,-0.005839306317893644
85.00000000000063,12.703083204690065,-1.8802574054530818,-0.006499367133648182
86.10000000000065,12.740883530590464,-1.8735586265866602,-0.006523485595728573
87.20000000000066,12.779036883204888,-1.869490744262308,-0.006268532730293153
88.30000000000067,12.816646611613042,-1.8635954051634875,-0.007143713878322355
89.40000000000069,12.854437101607646,-1.85824277425808,-0.007384139397392353
90.50000000000071,12.89085855057099,-1.849833811721349,-0.007148836072990772
91.60000000000072,12.928769339694128,-1.843781114295489,-0.008461762169301501
92.70000000000073,12.965901201954939,-1.8380654936313445,-0.007065019239354431
93.80000000000075,13.002950532376909,-1.8319697333534282,-0.008436755702963872
94.90000000000077,13.040584063263863,-1.8237109379341598,-0.008458420640109932
96.00000000000078,13.077364215168512,-1.8177512747976017,-0.0097435005893578
97.10000000000079,13.113984642194254,-1.8106264427809982,-0.010655349128067648
98.20000000000081,13.150776884727962,-1.8029934026672543,-0.01109016416587183
99.30000000000084,13.187542059340664,-1.7952416089471555,-0.011095031379260156
100.40000000000084,13.223693201480343,-1.7893312214148418,-0.012015656699043031
101.50000000000085,13.261064933917368,-1.782702061426284,-0.011062992964891993
102.60000000000088,13.297633710380989,-1.7748024440406445,-0.011712908842427705
103.7000000000009,13.333775448340074,-1.7660052848565615,-0.012421399057835458
104.8000000000009,13.370646703930213,-1.7596263737547497,-0.013686630955845214
105.90000000000092,13.407061905728442,-1.7521099334917651,-0.01372855683766927
107.00000000000094,13.443582408633933,-1.7444555553518026,-0.013729893539708549
108.10000000000096,13.480032697000212,-1.7360230648442108,-0.013741428183718263
109.20000000000097,13.516594361830753,-1.7280732590771857,-0.015061624879519453
110.30000000000098,13.552960279535325,-1.720972309349557,-0.014154606107764423
111.400000000001,13.589092509289577,-1.714190751683828,-0.015037177248713451
112.50000000000102,13.625838063240712,-1.7059920166515432,-0.01504963293110606
113.60000000000103,13.662137116400507,-1.6986579590085957,-0.016414797417541482
114.70000000000104,13.698627259320677,-1.6907213481052712,-0.016358662673540803
115.80000000000106,13.734822450814288,-1.6827751059237221,-0.01635996670614448
116.90000000000109,13.770902434835685,-1.6761320222415947,-0.0163599752590895
118.0000000000011,13.806857360419407,-1.6681056147254911,-0.016360176290390882
119.1000000000011,13.842763582607475,-1.660648702056964,-0.01640341568630932
120.20000000000113,13.87901487725817,-1.6539660904452926,-0.018013388828832078
121.30000000000115,13.915633372501812,-1.6464492539536528,-0.01839160548723129
122.40000000000116,13.951366971957967,-1.6380371914969798,-0.01975409945934814
123.50000000000117,13.98720633966381,-1.6307386386767555,-0.02032222738968592
124.60000000000119,14.023225679729562,-1.6236123479779996,-0.02029121482154439
125.70000000000121,14.059070501539873,-1.6159726742577771,-0.019004528904922324
126.80000000000122,14.094890752733782,-1.6068254069969024,-0.01899972922813209
127.90000000000123,14.130556779671423,-1.6000415597939592,-0.01930880914700417
129.00000000000125,14.16659028440295,-1.5910281208665218,-0.020325868686359883
130.10000000000127,14.202192742926202,-1.5848381312344433,-0.020319996661640083
131.2000000000013,14.236952254910907,-1.5775595329091179,-0.020319975009599922
132.3000000000013,14.272140872478463,-1.567423542471573,-0.02031975664374608
133.4000000000013,14.308230682254564,-1.5623080286948632,-0.020342278486085164
134.50000000000134,14.343699881783708,-1.5530378160216893,-0.021636823330724475
135.60000000000133,14.379105583798166,-1.5447370818367727,-0.022888863739084275
136.70000000000135,14.414516403238412,-1.536264555471962,-0.022943626556708896
137.80000000000138,14.448463438584213,-1.5275302202829497,-0.024299483213796602
138.9000000000014,14.484778082340314,-1.521132215688338,-0.02427070304374146
140.00000000000142,14.52003199592321,-1.5125486392162923,-0.024270130676836477
141.10000000000142,14.554632095581225,-1.5048617445694805,-0.024267071568171428
142.20000000000144,14.589452249899809,-1.4974569223851553,-0.02486416887178411
143.30000000000146,14.62500309680331,-1.4875134155134813,-0.023833972097719425
144.40000000000146,14.659370309038053,-1.4809366447422883,-0.02394023755183161
145.50000000000148,14.694130519211697,-1.4722963366803394,-0.02394751858096633
146.6000000000015,14.72905668024021,-1.4643244149916717,-0.024280582598783962
147.70000000000152,14.763764965205684,-1.4564187975770377,-0.02425722739072489
148.80000000000155,14.798409756076342,-1.4485160246885354,-0.025279813753315672
149.90000000000154,14.83322301968565,-1.4412994376757067,-0.025484013893387836
151.00000000000156,14.867640765483303,-1.4349273359998707,-0.026578532929494525
152.1000000000016,14.901915691672693,-1.42629850438912,-0.02657974440364974
153.20000000000158,14.936549538004803,-1.4183204206928914,-0.026586522470725793
154.3000000000016,14.97153503846322,-1.4113329715869658,-0.025274014197279815
155.40000000000163,15.005931503205133,-1.4046983197516938,-0.025260322442318905
156.50000000000165,15.040030942069087,-1.3969963639336047,-0.025256116813335172
157.60000000000167,15.074554052723427,-1.3892546984365077,-0.02656529126157503
158.70000000000167,15.109002187682858,-1.382688992923601,-0.026579870144156637
159.8000000000017,15.143284179833774,-1.3767199968928125,-0.026580241620003164
160.9000000000017,15.177727547879865,-1.3693003054958248,-0.02654995413910255
162.0000000000017,15.211942189628537,-1.362553844105664,-0.02691209582427634
163.10000000000173,15.246222286733168,-1.3554206944167106,-0.026910066772090513
164.20000000000175,15.28012738760809,-1.3507425540759277,-0.026909927523790067
165.30000000000177,15.314669395548007,-1.3435556897992738,-0.02738249272041937
166.4000000000018,15.348644137016743,-1.3396951357701519,-0.02952539094517448
167.5000000000018,15.383242224476035,-1.3337505025025906,-0.029514345540943676
168.6000000000018,15.417115280205289,-1.3256295224642065,-0.028240056580060457
169.70000000000184,15.45152862232589,-1.3200736814810947,-0.028920904319841068
170.80000000000183,15.485498548863509,-1.3149816196758901,-0.029559714124933745
171.90000000000185,15.519939817816034,-1.308912427188756,-0.029540132239758154
173.00000000000188,15.55393714319415,-1.304525492574441,-0.029540141601808845
174.1000000000019,15.588049631467035,-1.3008718190147355,-0.029540143941214847
175.20000000000192,15.621984985501246,-1.2956182137228067,-0.029540136685155538
176.30000000000192,15.655846563475812,-1.2912479207241316,-0.02954112566939182
177.40000000000194,15.689907632542582,-1.2860976555631005,-0.02957343860112438
178.50000000000196,15.723348984092237,-1.2807293545321334,-0.030846195486195604
179.60000000000196,15.757409610448512,-1.278269257898177,-0.03086022455981796
180.70000000000198,15.791492713695831,-1.2724698634348408,-0.03086014556740091
181.800000000002,15.825179175792847,-1.268270979202732,-0.030860092536431072
182.90000000000202,15.859245923444668,-1.2642483687809156,-0.03086126155765001
184.00000000000205,15.892883882570828,-1.259256775384543,-0.032256269355566136
185.10000000000204,15.926779113346287,-1.2558924970972072,-0.032168865914573797
186.20000000000206,15.960410146115958,-1.2525150801731262,-0.03216996017673912
187.3000000000021,15.994223222671645,-1.2475295307165462,-0.03216987895027934
188.40000000000208,16.027892522745404,-1.244544518922498,-0.03217423065117142
189.5000000000021,16.060687238060243,-1.242621762652417,-0.03317927035940693
190.60000000000213,16.09512024484527,-1.2389136960756664,-0.033159227996657936
191.70000000000215,16.128446751280066,-1.2345877269841192,-0.033160201183400684
192.80000000000217,16.1621980546697,-1.2295710178939456,-0.03318132044653188
193.90000000000217,16.194800694246798,-1.2271598240650454,-0.03283547521737917
195.0000000000022,16.228260120245267,-1.2245459397299314,-0.03283019625539163
196.1000000000022,16.262759805939197,-1.2213024483920583,-0.032830187688262846
197.2000000000022,16.295552800596564,-1.216318568061846,-0.032830036357351045
198.30000000000223,16.329446296076743,-1.2154186059404521,-0.032825377864829974
199.40000000000225,16.36299570490997,-1.2120666358217331,-0.03313020781251419
200.50000000000227,16.39639196793301,-1.2111476727466726,-0.03370755838413997
201.6000000000023,16.42978819483263,-1.205987164837131,-0.034482804509425424
202.7000000000023,16.46356917161258,-1.2028088685636074,-0.034480055547466026
203.8000000000023,16.49679369257319,-1.200389194359529,-0.03448012854072635
204.90000000000234,16.53012198133276,-1.1986739318716355,-0.03448012820508506
206.00000000000233,16.563526206666396,-1.1956893285860537,-0.03447975725517738
207.10000000000235,16.59662828477473,-1.1932616751822458,-0.034507684692303364
208.20000000000238,16.630623576354765,-1.1919475398141097,-0.035461063082980804
209.3000000000024,16.663390619147386,-1.1877378047744613,-0.03547093778454924
210.40000000000242,16.697147784603615,-1.1863639088923388,-0.03543629775690027
211.50000000000242,16.73036917330645,-1.1839911552271039,-0.035800405602361085
212.60000000000244,16.76357681045129,-1.181971576011989,-0.03579676306600055
213.70000000000246,16.79698696795821,-1.1776616709026158,-0.03624925555758152
214.80000000000246,16.8304916174788,-1.1749341688372303,-0.036790442744819796
215.90000000000248,16.863837393376137,-1.1732427264701437,-0.03679009571194225
217.0000000000025,16.8970863234569,-1.171966421152255,-0.0367901203733334
218.10000000000252,16.93033620531934,-1.1689407854218512,-0.0367901430383486
219.20000000000255,16.963934433198368,-1.1679916065360576,-0.03678767887904577
220.30000000000254,16.99731297997976,-1.1652453412376578,-0.03709986923052844
221.40000000000256,17.0304965191314,-1.1636415407792768,-0.0370799233932515
222.5000000000026,17.063656731653396,-1.1617763942210726,-0.03769633243787274
223.60000000000258,17.097023695478796,-1.1591776302677776,-0.038423396828137335
224.7000000000026,17.130060737063133,-1.1566736688787074,-0.038430020758244865
225.80000000000263,17.16360136510544,-1.1559657945110406,-0.03843077039714027
226.90000000000265,17.196824370173022,-1.15334918330731,-0.03838121839785691
228.00000000000267,17.230182477361005,-1.150837891297803,-0.03973842498651914
229.10000000000267,17.263201861036194,-1.148998839853783,-0.03974014007244353
230.2000000000027,17.296409866647966,-1.1479278255581697,-0.039740874245311364
231.3000000000027,17.329969872462577,-1.1463829127669316,-0.03973896937318555
232.4000000000027,17.36314770750956,-1.1448869394931183,-0.04104595058331251
233.50000000000273,17.39588968116494,-1.1427056820153547,-0.041060275909019506
234.60000000000275,17.42965038437712,-1.1421535792073754,-0.04106003978238215
235.70000000000277,17.46295772572733,-1.1402718509808478,-0.04105602304416234
236.8000000000028,17.496191825031428,-1.1397905225252567,-0.040492634302421227
237.9000000000028,17.529722442925493,-1.1380826378835063,-0.04047929790421678
239.0000000000028,17.56266972699099,-1.1361412397553508,-0.041707547595305705
240.10000000000284,17.59615429666156,-1.1356616644675621,-0.04182496515834133
241.20000000000283,17.62930501262105,-1.1346380955842679,-0.04303674849697359
242.30000000000285,17.66242350767336,-1.1326166256575352,-0.04304599217550953
243.40000000000288,17.695975764296293,-1.1320263592938846,-0.042242165457269554
244.5000000000029,17.728374838616144,-1.131005263071243,-0.0417195229089482
245.60000000000292,17.762194598583687,-1.1297008512991027,-0.04171994130628276
246.70000000000292,17.795221441361242,-1.1276978339498949,-0.041719930607583944
247.80000000000294,17.828425237007785,-1.1270411529251454,-0.04171990360347344
248.90000000000296,17.86179228907518,-1.125498532315759,-0.041717331784607126
250.00000000000296,17.89519070185089,-1.1254150307241106,-0.04223084589705728
251.10000000000298,17.928330675702497,-1.124716451731649,-0.04270644861756523
252.200000000003,17.961058432849033,-1.123503869306933,-0.04408626005031735
253.30000000000302,17.994085660836173,-1.123524709154805,-0.04438938020125427
254.40000000000305,18.027730536573475,-1.1213300351446538,-0.044359812377436025
255.50000000000304,18.060598082816192,-1.11947308481801,-0.04436009577371003
256.6000000000031,18.09339580579168,-1.1196128141963302,-0.04435985456193725
257.7000000000031,18.127246708931064,-1.1184236321638839,-0.044377588095403375
258.8000000000031,18.16036013950917,-1.1181295111806244,-0.045004683258608846
259.9000000000031,18.193466667596518,-1.118466973267319,-0.045695841442890295
261.0000000000031,18.226765677959275,-1.1154445168405573,-0.045671252105292215
262.10000000000315,18.260029793135462,-1.1161993631660365,-0.04567161882778814
263.2000000000032,18.292732406392584,-1.116319206715742,-0.046988284711283246
264.30000000000314,18.325955137563568,-1.1160218415294676,-0.04699010803202208
265.40000000000316,18.359301695185746,-1.1145434346745766,-0.04699007991152948
266.5000000000032,18.392378179474793,-1.1153874829871824,-0.04699007994741988
267.6000000000032,18.425503461230612,-1.114117827947071,-0.046990085187660124
268.70000000000323,18.45895223677002,-1.1143477791131207,-0.04698993990836042
269.80000000000325,18.491869027324906,-1.1137494629570266,-0.04697003347101525
270.9000000000033,18.525003750429047,-1.1134900993490984,-0.048387006074659844
272.0000000000033,18.55832197542539,-1.1137164920922877,-0.047978463169601415
273.1000000000033,18.591350712147772,-1.1122189627085959,-0.04797968930276664
274.20000000000334,18.624880229103155,-1.111475078219868,-0.04805242392195064
275.30000000000337,18.65759789831065,-1.112399888041822,-0.04928980498046753
276.40000000000333,18.691244183587,-1.1118563720414325,-0.04929994323587161
277.50000000000335,18.724012238845493,-1.110160131201214,-0.04930001130220729
278.6000000000034,18.757214677126193,-1.1095150608347302,-0.04930106409514057
279.7000000000034,18.79072628075089,-1.1078690244266667,-0.049258087852753096
280.8000000000034,18.823865953699208,-1.1072697366677002,-0.051920669276161124
281.9000000000034,18.856845590307717,-1.107988802393795,-0.051929800677791516
283.0000000000034,18.890450428169764,-1.1060786472641082,-0.051927021694978315
284.10000000000343,18.923538074728775,-1.1048348200756217,-0.05224968364990579
285.20000000000346,18.956762668521947,-1.1051417501708942,-0.05225974364078034
286.3000000000035,18.989969771840293,-1.1039408942494893,-0.052260674283746145
287.4000000000035,19.023295813665708,-1.1032416129479905,-0.05322191694024481
288.5000000000035,19.056626896178354,-1.1026464328742873,-0.05324571001343115
289.60000000000355,19.089879137282004,-1.1023747594322502,-0.054572106154301636
290.70000000000357,19.123024382195855,-1.1009496164931507,-0.05457066754939843
291.8000000000036,19.156037440741144,-1.0988266248795728,-0.05457015377153329
292.9000000000036,19.189302384861534,-1.0997529720770813,-0.05456814559124323
294.0000000000036,19.222990061292702,-1.0987634946099751,-0.054922778489248536
295.1000000000036,19.256149600123777,-1.0990225390029251,-0.055915198905889696
296.2000000000036,19.289326806439277,-1.097557304459444,-0.05720705408112092
297.30000000000365,19.322779177295665,-1.0971006183359846,-0.057209819196141876
298.4000000000037,19.355892256575338,-1.0968766253048254,-0.05720993153394449
299.5000000000037,19.388583886987814,-1.0974395138976698,-0.05721001267467907
300.60000000000366,19.421990837691197,-1.0974621377606588,-0.05722205484876097
301.7000000000037,19.456240110482984,-1.0985487003045376,-0.058499659932699455
302.8000000000037,19.48921295366559,-1.0985680126835007,-0.05846093074252856
303.90000000000373,19.522843138197622,-1.0975685184420099,-0.05786600360081806
305.00000000000375,19.55603943461957,-1.0976201987676173,-0.05785988152732102
306.1000000000038,19.589133805849883,-1.098565340619131,-0.058120311301215644
307.2000000000038,19.622814842609035,-1.098883473118061,-0.05918723643276369
308.3000000000038,19.656409882452422,-1.099640004515455,-0.059181571852493065
309.40000000000384,19.6897860585082,-1.1012532689278545,-0.05916858799700497
310.5000000000038,19.722984298881844,-1.101299191331977,-0.06049817974264382
311.60000000000383,19.75641341055555,-1.1004132641744933,-0.06050023729140985
312.70000000000385,19.789753871372287,-1.1018502316295447,-0.06049916171248304
313.8000000000039,19.823146451803087,-1.1027016346744751,-0.06178572783424885
314.9000000000039,19.85619625032579,-1.1054229881878788,-0.06181029222399026
316.0000000000039,19.89000000000012,-1.1069199999999966,-0.061809904336438404
317.10000000000394,19.92283975818754,-1.1069705957760687,-0.061754377983686215
318.2000000000039,19.95620436897151,-1.1102737135825527,-0.06313811203485864
319.30000000000393,19.990283830501976,-1.11223613560517,-0.06376890713852923
320.40000000000396,20.02371675304018,-1.1147387198371221,-0.0651597103883561
321.500000000004,20.05733727687393,-1.1172954540432878,-0.06510455616840849
322.600000000004,20.090797266755526,-1.1187412530870708,-0.06641926814473775
323.700000000004,20.12420869734789,-1.121700124552172,-0.0664305032299386
324.80000000000405,20.157749182028496,-1.1249903925356834,-0.066430831736501
325.90000000000407,20.191249457203625,-1.128022055088386,-0.0664757282073345
327.0000000000041,20.224707393592254,-1.1308167769733906,-0.06772875268821155
328.10000000000406,20.258155236743814,-1.1339302705998384,-0.0676633987923303
329.2000000000041,20.29191282821618,-1.135746171711186,-0.06905847085966998
330.3000000000041,20.32535958865495,-1.1402172855456423,-0.06913584598473488
331.4000000000041,20.358462055862795,-1.1441509336659543,-0.07036973209599706
332.50000000000415,20.392638042675422,-1.1509368057468186,-0.07118434518798589
333.6000000000042,20.426067474737184,-1.155697719824638,-0.07235426112312204
334.7000000000042,20.45956829850317,-1.1596138239387648,-0.07317442091192561
335.80000000000416,20.492929773732893,-1.1647818495226072,-0.07499613560823981
336.9000000000042,20.52675843463102,-1.1693363586565784,-0.07543666705308771
338.0000000000042,20.56048928871976,-1.175114005723851,-0.07536427719206706
339.10000000000423,20.594005023239383,-1.1781315953208795,-0.07687793453412972
340.20000000000425,20.627373930160335,-1.1847030108614165,-0.0779046141745896
341.3000000000043,20.661155207778037,-1.188021945307572,-0.07930078973395771
342.4000000000043,20.69487536290016,-1.1932450111776745,-0.08182106676655243
343.5000000000043,20.728287945314708,-1.19625514119662,-0.08319728471057752
344.60000000000434,20.762189632126464,-1.2004717208381444,-0.08391172748048747
345.7000000000043,20.79606432116253,-1.2042583937807978,-0.08599339533964567
346.80000000000433,20.82987827926419,-1.2070695892530479,-0.08815586036341516
347.90000000000435,20.8632962483204,-1.209883058702483,-0.08968236662266271
349.0000000000044,20.897116884203886,-1.2121275001066265,-0.09072952391899225
350.1000000000044,20.93075579319706,-1.212605262164335,-0.09183786973692953
351.2000000000044,20.964678034197178,-1.213066505452243,-0.09384725355709467
352.30000000000445,20.997851329915527,-1.2127538562346658,-0.09635785420842558
353.4000000000044,21.031660019016652,-1.2126174115209603,-0.09829055066486259
354.50000000000443,21.06551387755008,-1.2112812262939232,-0.10042201868199818
355.60000000000446,21.09916672318688,-1.2084958192390753,-0.10205806301626241
356.7000000000045,21.132726953556073,-1.2046183073451115,-0.10465715645564844
357.8000000000045,21.166865518982142,-1.198893326805807,-0.10714937133356095
358.9000000000045,21.20033143151453,-1.1946665510168313,-0.10903946065406966
360.00000000000455,21.23390502014104,-1.1892803574705029,-0.11257885063897977
361.10000000000457,21.267838328153108,-1.1828520308330421,-0.1152508247583377
362.2000000000046,21.301637520368708,-1.1780329587685912,-0.11810340241336226
363.30000000000456,21.335507777974673,-1.1712537967015573,-0.12180902509393388
364.4000000000046,21.3691907400543,-1.1643238516964034,-0.12490609736661629
365.5000000000046,21.40284147815734,-1.1584016577881122,-0.1265815002733346
366.6000000000046,21.436647794710925,-1.1521848631319325,-0.12918938616839037
367.70000000000465,21.47052559256077,-1.1453836269654318,-0.13233563671078752
368.8000000000047,21.504243652317918,-1.139335421914348,-0.13519624365040972
369.9000000000047,21.53830123066208,-1.1365366118491314,-0.13769034162614213
371.00000000000466,21.572124512247502,-1.1303588522050152,-0.14225221499399066
372.1000000000047,21.605806611124407,-1.1278002713896513,-0.14461262626809024
373.2000000000047,21.639847973355884,-1.1252480259032844,-0.14711186179548674
374.30000000000473,21.673260041818242,-1.1209143911200612,-0.14933851151271682
375.40000000000475,21.70752769044721,-1.1192019321722038,-0.15218840004632783
376.5000000000048,21.741472572052437,-1.1179033959458269,-0.15292083515956545
377.6000000000048,21.77544189361443,-1.1164870083104348,-0.15603452031125897
378.7000000000048,21.809073421888602,-1.1162050349946748,-0.1583848935654868
379.80000000000484,21.842775110971292,-1.1149385082822245,-0.16124804755517097
380.9000000000048,21.877519603044274,-1.1148827966352466,-0.16407643340525846
382.00000000000483,21.911122307846153,-1.114588552929811,-0.1657872680218344
383.10000000000485,21.945460356938305,-1.1155273398587349,-0.1672942141952749
384.2000000000049,21.979116847207287,-1.115066714129416,-0.16874228276887315
385.3000000000049,22.013340867919148,-1.1150846375832215,-0.1701826467436569
386.4000000000049,22.047267978944152,-1.1163428752569735,-0.17156112034139248
387.50000000000495,22.08130146018951,-1.116160470774973,-0.17315546847651353
388.6000000000049,22.115461208660424,-1.1182051695003323,-0.17515103381736052
389.70000000000493,22.149338951803806,-1.117961405656914,-0.17702817350937794
390.80000000000496,22.183600893528766,-1.1197085075464175,-0.17854604310950828
391.900000000005,22.21777364566109,-1.1214031252327112,-0.17951543096358735
393.000000000005,22.25182961232788,-1.1231924213812199,-0.1802597565274069
394.100000000005,22.2859126166625,-1.12535944637208,-0.1817070155501077
395.20000000000505,22.32015382092316,-1.1267702363739602,-0.1825783888404824
396.30000000000507,22.354180900205836,-1.1294675478687477,-0.18398893199901334
397.4000000000051,22.388074610769614,-1.131526398882669,-0.18615179838220186
398.50000000000506,22.42260712447611,-1.1348913394811966,-0.18722523595874785
399.6000000000051,22.456517093782153,-1.1370100469706108,-0.18784577829549942
400.7000000000051,22.491002618957392,-1.1389526479358643,-0.18946265766830628
401.8000000000051,22.52517121370663,-1.141707998265146,-0.19183325243696592
402.90000000000515,22.559180293912988,-1.1460092208808477,-0.19271162243477846
404.0000000000052,22.59363338842699,-1.148718510668221,-0.19392592483506066
405.1000000000052,22.627843645597153,-1.1511634430232323,-0.1953271170726123
406.20000000000516,22.662069301878613,-1.1542277899693032,-0.19656756524371444
407.3000000000052,22.696478512681864,-1.1579014506114655,-0.19783198592163487
408.4000000000052,22.730758860895016,-1.1612581358398872,-0.19856278653244264
409.50000000000523,22.764884391359104,-1.1655533973367813,-0.1992194218803114
410.60000000000525,22.79936010724361,-1.168159262224526,-0.2004678085100422
411.7000000000053,22.833597466797777,-1.1721796599315686,-0.2007794946731205
412.8000000000053,22.86802346695233,-1.1763926655247239,-0.2017841537239522
413.9000000000053,22.902532230963793,-1.1795018353349132,-0.2030601682661648
415.00000000000534,22.936605484556736,-1.18370421480272,-0.2045959991896411
416.1000000000053,22.971192507898575,-1.1877921334418535,-0.20597496265536597
417.20000000000533,23.005512143424088,-1.1915140452232675,-0.2070490547820052
418.30000000000535,23.039846922466243,-1.1936609762650439,-0.20727931589896942
419.4000000000054,23.074229901406188,-1.1990168510532178,-0.2085036948921246
420.5000000000054,23.10858834929096,-1.202366081801565,-0.20912626802970324
421.6000000000054,23.14338910004121,-1.2059768288351471,-0.21086806763443366
422.70000000000545,23.177589462796647,-1.210365859953687,-0.21299025503760882
423.8000000000054,23.21224403896828,-1.2150993024925758,-0.214177767583426
424.90000000000543,23.24651532836476,-1.2175236600910717,-0.21562048968385783
426.00000000000546,23.281507543121695,-1.2239978579529947,-0.2169837810821602
427.1000000000055,23.315461103626802,-1.229025884351939,-0.2172535794013868
428.2000000000055,23.350187781595686,-1.2331384079286642,-0.21849768564920202
429.3000000000055,23.384914012963602,-1.238719385861838,-0.21970245831324942
430.40000000000555,23.419413639394207,-1.244253348638986,-0.2205672260115663
431.50000000000557,23.45397967716698,-1.250738324371912,-0.2218886538644993
432.6000000000056,23.48841615422551,-1.256071159554492,-0.22328380469984177
433.70000000000556,23.523409507119084,-1.260703956175539,-0.22506941534577907
434.8000000000056,23.557666213663797,-1.266266930171404,-0.22667244033533196
435.9000000000056,23.59271339996902,-1.2725425499640268,-0.22823134386449828
437.0000000000056,23.627103756423764,-1.278508656230165,-0.2296632971293655
438.10000000000565,23.661819220671422,-1.284900864223342,-0.2312236225237596
439.2000000000057,23.696729677020535,-1.2892738618506132,-0.23263071222114506
440.3000000000057,23.731302568549907,-1.292193590262836,-0.23437082831102174
441.40000000000566,23.766157996789342,-1.293794554610734,-0.23602825566088503
442.5000000000057,23.80023788499656,-1.295383769213333,-0.23820101619153444
443.6000000000057,23.83511123970794,-1.2938529688260911,-0.24163370098050718
444.70000000000573,23.86999967983682,-1.2897600588556062,-0.2434999665762252
445.80000000000575,23.90434438940065,-1.2874546739837558,-0.24516208122017602
446.9000000000058,23.93892838163901,-1.2832528347017553,-0.24677641085931734
448.0000000000058,23.973755690239468,-1.2794803746724952,-0.24827135867044348
449.1000000000058,24.008381587149756,-1.2751437962395182,-0.24968290957677475
450.20000000000584,24.043382046261424,-1.2691023511231703,-0.25102774242364534
451.3000000000058,24.077697081893383,-1.264300545511062,-0.25263704953476784
452.40000000000583,24.112603631334945,-1.2611587009518137,-0.25391041556324767
453.50000000000585,24.14722243615524,-1.257415647726693,-0.255347152798445
454.6000000000059,24.182124072249586,-1.2535731519799116,-0.2568425825443641
455.7000000000059,24.216914857213904,-1.251933337410697,-0.25830919087961446
456.8000000000059,24.25096228933928,-1.2519736214530242,-0.25967924265442877
457.90000000000595,24.2863698011158,-1.2498701042748235,-0.2602447273929962
459.0000000000059,24.321225274326725,-1.2504751016072915,-0.26111510303596885
460.10000000000593,24.35608959846526,-1.249889379392806,-0.2622612637560793
461.20000000000596,24.39083278705797,-1.250582044142286,-0.26394649618130916
462.300000000006,24.42584242417487,-1.2510659228641408,-0.2653492137551874
463.400000000006,24.460670970847886,-1.2517616363605675,-0.266691992967528
464.500000000006,24.495594285785355,-1.2539375385877405,-0.2680176945024342
465.60000000000605,24.53056649526907,-1.2548077959604127,-0.27071906079748187
466.70000000000607,24.565301423042737,-1.2570565508042,-0.27167393364036574
467.8000000000061,24.599873068369394,-1.258271172312717,-0.27357098610540076
468.90000000000606,24.634760759262676,-1.2610065730473614,-0.273807473639077
470.0000000000061,24.669968454179767,-1.2620086593714672,-0.275340709240401
471.1000000000061,24.70537213642984,-1.2633582641970285,-0.276764821419599
472.2000000000061,24.74025873329086,-1.267664895153251,-0.2795080021495582
473.30000000000615,24.77530141672593,-1.2687401312635034,-0.2807070819146129
474.4000000000062,24.80990209319114,-1.2697361219588588,-0.2824669534488442
475.5000000000062,24.84506820484713,-1.273113007591716,-0.2823447406418218
476.60000000000616,24.88006425182627,-1.2746907687414648,-0.28422963842283533
477.7000000000062,24.91487034819087,-1.276923997032209,-0.285779979672792
478.8000000000062,24.94955615148504,-1.279172347432083,-0.2872041808998156
479.90000000000623,24.984390612686198,-1.2826084685918748,-0.28968718600927046
481.00000000000625,25.019898882164178,-1.283230613263119,-0.29158784501926327
482.1000000000063,25.055237774500945,-1.286146709601184,-0.2932660553600579
483.2000000000063,25.090064911868232,-1.2882326614452013,-0.29477643433144296
484.3000000000063,25.125422760242138,-1.2885798776102415,-0.2962659662540319
485.40000000000634,25.160281904151024,-1.2920803591470442,-0.2974221718364807
486.5000000000063,25.19530224576707,-1.2945789497470088,-0.29778788351655683
487.60000000000633,25.230439216125703,-1.2940098207137678,-0.2993007441949498
488.70000000000636,25.265772692229852,-1.295576069531846,-0.30147079627189166
489.8000000000064,25.300799469524712,-1.2965513744059813,-0.3040408224253537
490.9000000000064,25.335549535826814,-1.296912909064728,-0.30561911145025444
492.0000000000064,25.371332514401352,-1.2963080147509871,-0.3062988209132431
493.10000000000645,25.40605300207951,-1.2962138407054562,-0.3074198950067695
494.2000000000064,25.441372989959035,-1.2958815937168833,-0.30837394109172944
495.30000000000643,25.476326486862465,-1.295900837887921,-0.31135202014592656
496.40000000000646,25.511767856881008,-1.2937811060473747,-0.3125170944432383
497.5000000000065,25.54678735319602,-1.2946643385611858,-0.3138241996340012
498.6000000000065,25.581940314097697,-1.293807467289711,-0.31456190646344595
499.7000000000065,25.616994706120533,-1.2937097385596383,-0.3159609657858842
500.80000000000655,25.65234055799888,-1.2924713908707848,-0.3173879616348172
501.90000000000657,25.6873740075856,-1.2907851531406218,-0.3173902849782415
503.0000000000066,25.722697946692954,-1.2912665680366269,-0.3174105719786051
504.10000000000656,25.757958919060247,-1.2916656109200626,-0.31870148171077917
505.2000000000066,25.792773396758886,-1.2908452487410753,-0.32005950789300375
506.3000000000066,25.82875267286269,-1.2911754593108187,-0.3205779281426091
507.4000000000066,25.863306015124675,-1.2899366966695274,-0.3217979604591128
508.50000000000665,25.898772073272788,-1.2899791532077403,-0.32397541173889444
509.6000000000067,25.93421812903609,-1.2906016791458004,-0.3239806609547595
510.7000000000067,25.969593017143378,-1.2909072812252687,-0.32396613937103513
511.80000000000666,26.005026670736015,-1.2907530377411196,-0.32400507333511497
512.9000000000067,26.040292805148663,-1.2910476058902525,-0.32396995807200524
514.0000000000067,26.07570108701765,-1.2904521790995396,-0.3239635505881444
515.1000000000067,26.11081794973446,-1.2904885629088712,-0.32502452252474123
516.2000000000068,26.146417797508633,-1.292161950192892,-0.3252831820758395
517.3000000000068,26.18177678309754,-1.2926977375626996,-0.3265907661308636
518.4000000000068,26.217161855639002,-1.2937565313226247,-0.32661007927528685
519.5000000000068,26.25183293487359,-1.2943199527452562,-0.32660980495367165
520.6000000000068,26.287840622106373,-1.2951595344337425,-0.32660992652984167
521.7000000000069,26.32298154939719,-1.2945171324635332,-0.32662672674252136
522.8000000000068,26.358244976167782,-1.2960908470822106,-0.3276342311195539
523.9000000000069,26.393944630911214,-1.296131602587214,-0.3276005578075063
525.0000000000068,26.42936345006675,-1.2983888779051864,-0.32760004340304993
526.100000000007,26.46471148570789,-1.3041521465054458,-0.3276083447382745
527.2000000000069,26.499999678219147,-1.3140799155997873,-0.32792997180939354
528.300000000007,26.535660020003483,-1.3234932398115813,-0.32792366068420575
529.4000000000069,26.570995884532078,-1.3282582165610803,-0.328983738951373
530.5000000000069,26.60662671014395,-1.3360371392798032,-0.3294610085507399
531.600000000007,26.642181299139228,-1.3397743045994581,-0.33023457370886833
532.700000000007,26.677649011955136,-1.3455329532087572,-0.3302301694790186
533.800000000007,26.71328850833994,-1.349189500950271,-0.33023074977624045
534.900000000007,26.748373322943134,-1.3529677684410581,-0.3302350151221387
536.000000000007,26.78382997083076,-1.3578622315583546,-0.33075216665214624
537.1000000000071,26.819833908219362,-1.3621468712318892,-0.33187957148928504
538.2000000000071,26.855397035483893,-1.366141762918599,-0.33187988702519133
539.300000000007,26.89069298762539,-1.3690821772319213,-0.33187995360785694
540.4000000000071,26.926423731615447,-1.3710763916657374,-0.3318799744154659
541.500000000007,26.962060970227455,-1.3719653805950691,-0.3318837117026656
542.6000000000072,26.997365884443514,-1.3718943547640576,-0.3312574371838033
543.7000000000071,27.033053951076262,-1.3722238262644204,-0.3312213107104922
544.8000000000072,27.068334023768305,-1.371565112540785,-0.3312171301486595
545.9000000000071,27.104494564188265,-1.3712756196236182,-0.3322362862024759
547.0000000000072,27.14009612235185,-1.3755003250103306,-0.3325400608887392
548.1000000000072,27.175262905229264,-1.377256947293053,-0.3325401373993748
549.2000000000072,27.21075916517618,-1.378810708467114,-0.33254011092244573
550.3000000000072,27.247290235681014,-1.3817460584959063,-0.33254061891034903
551.4000000000073,27.282905001998984,-1.3827267196866697,-0.33276671226589505
552.5000000000073,27.318568098144148,-1.3835842700812375,-0.33386098996039015
553.6000000000073,27.354062894819858,-1.3858982851124027,-0.3338600615154279
554.7000000000073,27.389934669109266,-1.3891787354681275,-0.33386011968423945
555.8000000000073,27.425631793718,-1.3938560034977203,-0.3338601199019178
556.9000000000074,27.461279454907363,-1.3961345870970803,-0.33386010530295884
558.0000000000074,27.496985447372825,-1.3969047364486062,-0.33386053861385223
559.1000000000074,27.533203985792987,-1.400554685301387,-0.33317604103597764
560.2000000000073,27.568648221574705,-1.40077520276609,-0.3328718045376635
561.3000000000073,27.604975136907147,-1.3998628040679884,-0.3342836995427301
562.4000000000074,27.640705675422648,-1.3998075060863582,-0.3341900800085069
563.5000000000074,27.676336396480075,-1.3992318079026946,-0.33418988101051195
564.6000000000074,27.7123274789999,-1.3966978436934043,-0.3341898879727161
565.7000000000074,27.748359681663295,-1.395012359289599,-0.33418988670691663
566.8000000000075,27.783887201513586,-1.3952326087767262,-0.3341896109971736
567.9000000000075,27.819999340162486,-1.3925100169975766,-0.3341899190726352
569.0000000000075,27.85566328448978,-1.3916003178760574,-0.33501118290132537
570.1000000000075,27.89154548722903,-1.3862266619301036,-0.336123605079238
571.2000000000075,27.92748350091542,-1.3848090378076472,-0.3368391637624586
572.3000000000076,27.96328734226946,-1.3825061556565963,-0.3368216824891057
573.4000000000076,27.999499510189512,-1.3810849629299584,-0.3367942472120715
574.5000000000076,28.035267310791188,-1.3797323636112027,-0.3381385872347282
575.6000000000076,28.070992792626445,-1.3802328007465339,-0.3381416804513453
576.7000000000077,28.106976823459608,-1.3787517756345047,-0.3367656135290571
577.8000000000077,28.142921941495434,-1.3794722074842234,-0.3368200693697685
578.9000000000076,28.17915814108601,-1.380318179052082,-0.33684510668823675
580.0000000000076,28.21513852327301,-1.3827270283623783,-0.3354951118738869
581.1000000000076,28.251088016938557,-1.384863509717107,-0.33550053700396854
582.2000000000077,28.286985643699992,-1.3864230957939732,-0.3365718231355608
583.3000000000077,28.323170434451185,-1.3884969206258808,-0.3368181459550974
584.4000000000077,28.359185477812964,-1.3936811503764157,-0.33681987686028636
585.5000000000077,28.3951676011011,-1.398334856506297,-0.336819872184162
586.6000000000078,28.431264848723803,-1.4042908796519633,-0.3368198745885169
587.7000000000078,28.467071800559033,-1.4056333951158533,-0.336819868483071
588.8000000000078,28.502822486326682,-1.4110263933906873,-0.33678325885908533
589.9000000000078,28.53964792848119,-1.4153133756659981,-0.337151723321202
591.0000000000078,28.575647677253027,-1.4233242165093403,-0.33714985072561543
592.1000000000079,28.611876571564107,-1.4279673161353503,-0.3371498742123662
593.2000000000079,28.648101457527474,-1.4318261949300917,-0.3371495977821719
594.3000000000079,28.684226385512147,-1.4378309551240283,-0.3370935393766401
595.4000000000078,28.720294998756774,-1.4458455542268676,-0.3378109691965676
596.5000000000078,28.75649713296379,-1.4514312559060447,-0.33781008936743717
597.6000000000079,28.79258922166942,-1.4564600448023204,-0.33781015354143884
598.7000000000079,28.828652853865943,-1.4644859546951057,-0.3378101543256089
599.8000000000079,28.865262390581925,-1.4722389813384475,-0.33781025338861426
600.9000000000079,28.9010087842767,-1.4818928543211014,-0.33781382372640145
602.000000000008,28.937408433762865,-1.489215520844068,-0.3385088510371479
603.100000000008,28.973549010348584,-1.4980061606700001,-0.33847028703615
604.200000000008,29.009736071323715,-1.5072332236152675,-0.3384590916487098
605.300000000008,29.04610375674024,-1.5152039809326767,-0.3371551431788591
606.400000000008,29.08235383269589,-1.52291426992997,-0.3384991015520731
607.5000000000081,29.11840516742939,-1.5295517226342001,-0.33978555278835065
608.6000000000081,29.15461022816959,-1.536546383315741,-0.33977709034051884
609.7000000000081,29.191466500235958,-1.5447640287400626,-0.3384168812143131
610.8000000000081,29.227445918837336,-1.550745809161563,-0.33786534643639543
611.9000000000082,29.26359177287964,-1.5595592650059906,-0.33780995594225516
613.0000000000082,29.30003150272586,-1.5652042754703197,-0.3378092719233794
614.1000000000081,29.336123759063614,-1.5753625691582134,-0.3374780539565343
615.2000000000081,29.37179177753747,-1.5829915617264763,-0.3374799704797202
616.3000000000081,29.408231558979836,-1.5918503554273076,-0.33747998007928004
617.4000000000082,29.44517091232777,-1.5991975733951123,-0.33747998000103463
618.5000000000082,29.481739159355858,-1.6077922939786946,-0.3374799799953685
619.6000000000082,29.517848979309555,-1.6181140099414146,-0.3374799805857953
620.7000000000082,29.55415750460964,-1.628139194715744,-0.3374800845806476
621.8000000000083,29.59056499483924,-1.6361034560430627,-0.3374825288809702
622.9000000000083,29.626977707373566,-1.643806617118441,-0.3387651459493406
624.0000000000083,29.6634346137816,-1.6534677342293669,-0.3387900647173381
625.1000000000083,29.699737114431926,-1.6625353229946989,-0.3387901961124662
626.2000000000083,29.73608829847295,-1.6679664070828377,-0.3387901960120634
627.3000000000084,29.7721178728752,-1.6785583740061985,-0.3387901961504083
628.4000000000084,29.80856246516804,-1.6868823949057519,-0.3387901835071423
629.5000000000084,29.844616606457162,-1.6927556152570093,-0.338787065363368
630.6000000000083,29.881245265653508,-1.6992692843795707,-0.33955464621934883
631.7000000000083,29.91762756906656,-1.706288770942255,-0.34011172825229385
632.8000000000084,29.95407062706289,-1.7149544324554862,-0.34010998432379846
633.9000000000084,29.99010368373692,-1.7178193373035793,-0.34010996400509663
635.0000000000084,30.02660186691801,-1.7227395240806047,-0.34010996580356023
636.1000000000084,30.063114210738473,-1.7301502390761458,-0.3401101941340916
637.2000000000085,30.099293616131476,-1.7348082982895743,-0.3401031790386866
638.3000000000085,30.135534039879705,-1.737716767700725,-0.33946726366208013
639.4000000000085,30.172476718341407,-1.7417752271096947,-0.3394501657707476
640.5000000000085,30.20874655739739,-1.7448363142464918,-0.3394501113919639
641.6000000000085,30.24510465522294,-1.7474874997272078,-0.3394407435457678
642.7000000000086,30.28136546203264,-1.750930693971898,-0.33913049318289135
643.8000000000086,30.31777771413826,-1.7563137959425148,-0.3391197214892081
644.9000000000086,30.353976314268635,-1.7583752110923256,-0.3398625138329936
646.0000000000086,30.390503083901926,-1.7596603067769059,-0.34030039234620046
647.1000000000087,30.426724598425633,-1.7627178241072237,-0.33945057375719934
648.2000000000087,30.46322242892623,-1.7655199667590815,-0.3394319989727279
649.3000000000086,30.499369946977748,-1.7671451068670834,-0.340450705321067
650.4000000000086,30.535998556575105,-1.7710296178295482,-0.3397758002612785
651.5000000000086,30.572458219054703,-1.7743574216367235,-0.33977992295872506
652.6000000000087,30.60910405547788,-1.77501906732518,-0.3397808230885584
653.7000000000087,30.644909858039036,-1.7796972030940823,-0.3402412968171884
654.8000000000087,30.681510583099215,-1.7826779319049362,-0.3411004566945195
655.9000000000087,30.71795790018218,-1.7839548535553147,-0.34109974733996173
657.0000000000088,30.754445798668456,-1.7904320774493625,-0.3410145941783438
658.1000000000088,30.790823450337864,-1.793048669562808,-0.3417509575762554
659.2000000000088,30.826744416852968,-1.7968530720945761,-0.3411099936937081
660.3000000000088,30.86383409639493,-1.7992676567573305,-0.34110987205415233
661.4000000000088,30.900410930198696,-1.8035181108987988,-0.34110990070357383
662.5000000000089,30.9367325619419,-1.8081803860542587,-0.34110762441847475
663.6000000000089,30.973321124523892,-1.8124237658462752,-0.339692357135708
664.7000000000089,31.009804408885337,-1.8165384038900254,-0.3397901914518364
665.8000000000088,31.046237707192187,-1.8195566972625086,-0.33979013680636116
666.9000000000088,31.082803592223417,-1.8233656944910814,-0.3397901103251999
668.0000000000089,31.119377017762012,-1.8272676762790223,-0.3397907345912383
669.1000000000089,31.155772624531487,-1.8319290575680458,-0.3403435031935791
670.2000000000089,31.192272339682237,-1.8361487875354807,-0.34111037822831847
671.3000000000089,31.22903149058645,-1.8413541358262968,-0.3411098961898138
672.400000000009,31.265337343353295,-1.8426223667101989,-0.34110989876600994
673.500000000009,31.30213406286679,-1.845830470795378,-0.3411100038691659
674.600000000009,31.33861990801106,-1.848280137499468,-0.3411101168181654
675.700000000009,31.37524591294704,-1.8529874290752761,-0.34115313039195305
676.800000000009,31.41199397025376,-1.8567613614007836,-0.34142894115816613
677.9000000000091,31.44838399467014,-1.8626823978392713,-0.34143557455257323
679.0000000000091,31.485092388719508,-1.864490248660263,-0.3401442282329534
680.1000000000091,31.521619722763653,-1.8703911784871767,-0.34012028226894353
681.2000000000091,31.55837158408512,-1.8725456625295906,-0.34008412023844903
682.3000000000092,31.59508094858861,-1.8777052089773547,-0.3414164296136475
683.4000000000092,31.63127871330094,-1.8796788128564013,-0.34143169262733997
684.5000000000091,31.668022854129163,-1.8840629643914162,-0.3411051183979703
685.6000000000091,31.704791035552315,-1.8860094942839187,-0.3411005546355965
686.7000000000091,31.741688708603917,-1.891008952177234,-0.3411001115507184
687.8000000000092,31.777873089721133,-1.8929971437484363,-0.34110026890741807
688.9000000000092,31.81484147396236,-1.898204151329126,-0.3401446383287179
690.0000000000092,31.85132582850546,-1.9016860275411727,-0.33984032235667216
691.1000000000092,31.888123513974406,-1.9050926019704162,-0.34076789153450937
692.2000000000093,31.924737711121544,-1.9096156857141777,-0.3406374134090937
693.3000000000093,31.961569846944094,-1.9134280571399898,-0.3424195016805487
694.4000000000093,31.998456368532874,-1.9179814072718648,-0.3424210454408865
695.5000000000093,32.03494664822372,-1.9198845717258533,-0.34150490798071065
696.6000000000093,32.071056435127694,-1.9214846640917096,-0.34143024265032906
697.7000000000094,32.108615428702294,-1.9255384682472316,-0.34142594457562936
698.8000000000094,32.144865605576314,-1.9290047191526478,-0.34272798034549057
699.9000000000094,32.18190176172627,-1.9339857115415118,-0.34274993792972985
701.0000000000093,32.21888880133633,-1.9391473438623323,-0.34275004883493176
702.1000000000093,32.25544611785236,-1.9414757566930356,-0.3427502195015615
703.2000000000094,32.29244679073011,-1.9443976133071146,-0.3427684982325796
704.3000000000094,32.32896888236638,-1.9481180687996809,-0.3424208971149141
705.4000000000094,32.36572923227926,-1.951464984260737,-0.34242059729949226
706.5000000000094,32.402544472527104,-1.9554116713586638,-0.34248003984944964
707.6000000000095,32.438828475254965,-1.9589954974123072,-0.34109902686215543
708.7000000000095,32.47627130952815,-1.9604391223223876,-0.34110001974607895
709.8000000000095,32.513346070502905,-1.9658166588937054,-0.3411000238161739
710.9000000000095,32.54986650636309,-1.969502177825189,-0.3411000108329776
712.0000000000095,32.58677664351094,-1.9732383319587394,-0.3424852834461798
713.1000000000096,32.623660926963716,-1.9761157478410378,-0.34241309517005103
714.2000000000096,32.660618260895866,-1.9808847987462412,-0.3424492794572789
715.3000000000096,32.69744056200307,-1.9814564023097154,-0.34241939407352673
716.4000000000096,32.73417098298917,-1.9875332208496959,-0.3424198119489903
717.5000000000097,32.771190980585466,-1.9907090687879438,-0.3424198159687579
718.6000000000097,32.80799465892749,-1.9962296650251043,-0.3424198206501696
719.7000000000096,32.84480377967482,-2.0002322914967743,-0.3424206593889414
720.8000000000096,32.8817256943063,-2.0032803098230545,-0.34246851003454504
721.9000000000096,32.918910507229334,-2.006645475221977,-0.3451156578389729
723.0000000000097,32.95556393260853,-2.011526704283035,-0.34400566583481096
724.1000000000097,32.99230440596602,-2.0131885796990083,-0.3436069842755862
725.2000000000097,33.02933604115732,-2.017275011991498,-0.34231730560334617
726.3000000000097,33.06584264009617,-2.0223791156180404,-0.34231014363901435
727.4000000000098,33.102844702617354,-2.0259513749524474,-0.3423100325617807
728.5000000000098,33.13979987309759,-2.0294081759622236,-0.3423100323844137
729.6000000000098,33.17665824569497,-2.034609787188394,-0.3423109905203434
730.7000000000098,33.21374886283445,-2.036959110209764,-0.34247905779806276
731.8000000000098,33.2507006422165,-2.0411710143194246,-0.3423127017340599
732.9000000000099,33.28735825732075,-2.04337289758455,-0.34231079471112524
734.0000000000099,33.32429218760897,-2.04843694281487,-0.34231030089766845
735.1000000000099,33.36100151076676,-2.051511882255748,-0.3423121961691562
736.2000000000098,33.39842160646876,-2.0571578681661133,-0.3436362514051132
737.3000000000098,33.435252952049815,-2.0602061552847046,-0.34517457629137915
738.4000000000099,33.472324900203695,-2.0632434461538485,-0.3450950822594181
739.5000000000099,33.50939365579069,-2.0674634347754064,-0.34348681855649454
740.6000000000099,33.54623530993541,-2.0706671076141987,-0.3420914897821663
741.7000000000099,33.583232458200676,-2.07360257506747,-0.3414384428287498
742.80000000001,33.62037223345645,-2.076442731079698,-0.342089086370704
743.90000000001,33.657069880186235,-2.080067332747244,-0.3420899679254301
744.00000000001,33.66043375747566,-2.080459642298209,-0.34208996113656465