File: 01_Data/EIFS_Mesh/STA/N2/10K_min/EIFS_Mesh_STA_N2_10KData_230206_R1.csv
##Temp./Â°C,Time/min,DSC/(mW/mg),Mass loss/mg
50.0,10.850288863745037,-1.8662404957259415,-0.008300146870517722
51.100000000000016,11.16660118611569,-1.755449986927508,-0.007890045244562494
52.20000000000003,11.402084298810504,-1.6725024232585306,-0.006774637112783921
53.30000000000005,11.602613228798809,-1.609145648169099,-0.008690977061141414
54.40000000000006,11.78228794107172,-1.5582164764609465,-0.009658149162868224
55.50000000000008,11.944776052539678,-1.5163379737353775,-0.006416136868387046
56.600000000000094,12.10600555556016,-1.4824344228649566,-0.006021967869694667
57.70000000000011,12.255979924805747,-1.452523753939808,-0.006118790938416829
58.800000000000125,12.404747191930252,-1.4249909665289269,-0.004828765236390087
59.90000000000014,12.54398582331687,-1.4028995080733266,-0.007053954848574406
61.000000000000156,12.685549747597182,-1.3805822918287793,-0.007315720896288624
62.10000000000017,12.823409642421,-1.3600493883652849,-0.010863635708996622
63.20000000000019,12.957914674809366,-1.3441860645672195,-0.006386296993767804
64.30000000000021,13.091068614738198,-1.3284283212711356,-0.00735515276589549
65.40000000000022,13.221903166793316,-1.3132518460021936,-0.008819466021526168
66.50000000000023,13.351308382341013,-1.2958899473841723,-0.009098442429546605
67.60000000000025,13.478871342224576,-1.2840965286461385,-0.008985271140913742
68.70000000000027,13.604126628356687,-1.2710459656643092,-0.007360953672555848
69.80000000000028,13.730043984825512,-1.2572461747001826,-0.008605630028576172
70.90000000000029,13.85351008195939,-1.2426995104721983,-0.008493954997422115
72.00000000000031,13.978084751062292,-1.2308768295248833,-0.00997950808858361
73.10000000000034,14.099748942739481,-1.2188866263245643,-0.00656990102256394
74.20000000000034,14.221926194487917,-1.205137659096573,-0.003025155525671952
75.30000000000035,14.337670841131509,-1.1955752525427856,-0.008658108023839706
76.40000000000038,14.460920269088092,-1.1801840637482033,-0.011304562095735271
77.5000000000004,14.577986604611398,-1.1687247281411604,-0.013863874929083586
78.6000000000004,14.696146104241262,-1.1580515158491955,-0.011243597524127846
79.70000000000041,14.812726006652966,-1.1466235585777977,-0.009877074259617036
80.80000000000044,14.928257922084844,-1.1361485516980079,-0.011223039954475045
81.90000000000046,15.045166978992171,-1.127909599276274,-0.012627352289149574
83.00000000000047,15.158629620695805,-1.1188414701512732,-0.012630597941011068
84.10000000000048,15.275796058016681,-1.1084439705422484,-0.011164903191360764
85.2000000000005,15.387449300320043,-1.0993511520966677,-0.011865176104749242
86.30000000000052,15.50059740141576,-1.0902240947903157,-0.013864532114403971
87.40000000000053,15.614388739363994,-1.0832074247832182,-0.015327979065521191
88.50000000000054,15.725917810446223,-1.0732925976243815,-0.013683003531208549
89.60000000000056,15.837167500757886,-1.0653830712636403,-0.013940099334478262
90.70000000000059,15.947358688106364,-1.0573346608548602,-0.013940162040955162
91.8000000000006,16.057800117751626,-1.0513296791108466,-0.013957614175566846
92.9000000000006,16.167317214564566,-1.0422207296910715,-0.013968183805703305
94.00000000000063,16.278724495259674,-1.0375534438243363,-0.015282215062414561
95.10000000000065,16.386936035197472,-1.029076914330499,-0.013818627244094994
96.20000000000066,16.49812215492299,-1.022300519838359,-0.015149407327367026
97.30000000000067,16.604226685732435,-1.0152592917412773,-0.015924970277341632
98.40000000000069,16.711731096349528,-1.0077919887915843,-0.017045190411412392
99.50000000000071,16.82210785028256,-1.0021879172948829,-0.01898617589256979
100.60000000000072,16.92807637489392,-0.9950572231634773,-0.016216284437836403
101.70000000000073,17.0376672677945,-0.9877877772767425,-0.01328187505641365
102.80000000000075,17.144334080434827,-0.9831137981435334,-0.014789702142643524
103.90000000000077,17.251337418387443,-0.9752719655120945,-0.017450728528815684
105.00000000000078,17.358160359636372,-0.969824333303686,-0.017872026594674573
106.10000000000079,17.466586885602695,-0.9671817274471493,-0.01645991050722362
107.20000000000081,17.57281280843336,-0.9610174001208596,-0.01923290938912947
108.30000000000084,17.680109386886112,-0.9552229548958396,-0.02145569879886633
109.40000000000084,17.786965046095922,-0.9486554458981965,-0.025020212815124676
110.50000000000085,17.893284480709724,-0.9428070055427333,-0.024751152428332812
111.60000000000088,17.999272537661746,-0.9386139322155596,-0.022057915168931075
112.7000000000009,18.1057630246717,-0.9354914951294799,-0.020748601633833186
113.8000000000009,18.211616262154593,-0.9314350349857612,-0.02005601562760484
114.90000000000092,18.315564612650643,-0.9262538110816306,-0.020813394457661172
116.00000000000094,18.4240657767861,-0.9199942360998334,-0.019425069346427737
117.10000000000096,18.530270972616037,-0.915715794074716,-0.019430171642652816
118.20000000000097,18.636834525796566,-0.9122479688174867,-0.01953405984068457
119.30000000000098,18.743080790810538,-0.9071582535033144,-0.020774007840175468
120.400000000001,18.84736366724706,-0.9023373456875935,-0.022069095471954903
121.50000000000102,18.954928558210675,-0.8977453851363785,-0.022066108431501252
122.60000000000103,19.059746821451515,-0.8931167707167468,-0.02478339528775031
123.70000000000104,19.16626718112639,-0.8882405503684003,-0.024703211740086495
124.80000000000106,19.271937061396383,-0.8835129573967293,-0.02231559780253667
125.90000000000109,19.37692658882749,-0.879689803070139,-0.02337877423376966
127.0000000000011,19.483359762638752,-0.8748222720314167,-0.02491452511869241
128.1000000000011,19.58723459327231,-0.8704448675727617,-0.021145354263307325
129.20000000000113,19.69227690891905,-0.8663088254150081,-0.02119166808159445
130.30000000000115,19.797162134918445,-0.8623171092080556,-0.01887999954518893
131.40000000000117,19.90277163993788,-0.8580329869861888,-0.02173822609842002
132.50000000000117,20.00714760307653,-0.8530040617771029,-0.022731035382308473
133.6000000000012,20.11243433276459,-0.8488562255998874,-0.025673160270427875
134.7000000000012,20.216208250518395,-0.843112262501134,-0.024207779022442644
135.8000000000012,20.320920358650923,-0.8387216978402816,-0.02426089168475709
136.90000000000123,20.426631996481255,-0.8341705289078752,-0.02424914612152973
138.00000000000125,20.530579385028872,-0.8295337220750413,-0.02558222980512692
139.10000000000127,20.634342849291137,-0.8254457489342263,-0.025954586458178497
140.2000000000013,20.73932331828687,-0.8217785831062738,-0.02426063083125518
141.3000000000013,20.84326525812642,-0.8168166317455945,-0.025682953626239957
142.4000000000013,20.948136021308837,-0.8117976923225899,-0.02691312417161118
143.50000000000134,21.051813223795115,-0.8077785750708804,-0.02700982791118589
144.60000000000133,21.155802810849327,-0.8027241704875727,-0.024592444191265272
145.70000000000135,21.25918697606748,-0.799390489467883,-0.02908082647188248
146.80000000000138,21.362685282281024,-0.7937687297397279,-0.02811131666587041
147.9000000000014,21.46731471603319,-0.7900757443772541,-0.028089275634034294
149.00000000000142,21.570331290380047,-0.7860419937675893,-0.025199573156463373
150.10000000000142,21.675797830446324,-0.7817535988217599,-0.024826421874809323
151.20000000000144,21.776579284987555,-0.7765232186721043,-0.024804264615575278
152.30000000000146,21.882366486287744,-0.7740638690112516,-0.025944239819255976
153.40000000000146,21.9866000689912,-0.7686172523992695,-0.027890267181727157
154.50000000000148,22.08982311222924,-0.7643773202102804,-0.02920983934396082
155.6000000000015,22.194137604671663,-0.7593526331498508,-0.029179548566984792
156.70000000000152,22.29753440287646,-0.7558466105555413,-0.021904517423879888
157.80000000000155,22.40204887729647,-0.7516704296976621,-0.022491409599956214
158.90000000000154,22.50567191331024,-0.7480531312839949,-0.02415307283102397
160.00000000000156,22.609811207775437,-0.7434015313214991,-0.028762530040946643
161.1000000000016,22.71352701802571,-0.7383441029186758,-0.028757097185969194
162.20000000000158,22.816404515744733,-0.733334952335739,-0.028655884569206425
163.3000000000016,22.920257254647403,-0.7281268907769625,-0.029073233873480042
164.40000000000163,23.02357709844472,-0.7238352918276879,-0.02901033594075475
165.50000000000165,23.126773469748667,-0.7209426833420737,-0.027780107901647977
166.60000000000167,23.23082884982165,-0.7150199053439806,-0.027780107950740707
167.70000000000167,23.334469970381004,-0.7128592967610129,-0.028847893354707832
168.8000000000017,23.439232299054577,-0.7089438524795609,-0.028100224475786195
169.9000000000017,23.541560486476584,-0.7045834529858211,-0.028099924999859027
171.0000000000017,23.645498080819213,-0.7000526187479169,-0.02875582233397722
172.10000000000173,23.748676213667945,-0.6972168339792405,-0.030679214594476978
173.20000000000175,23.850830000000137,-0.6928799999999888,-0.028100448108602016
174.30000000000177,23.95549329428497,-0.6892045126494099,-0.029452839704937173
175.4000000000018,24.059837987197376,-0.6855098722660079,-0.031414563419200014
176.5000000000018,24.16414064451968,-0.6807432385780017,-0.031183551851742486
177.6000000000018,24.267043197921815,-0.6767569411571073,-0.03322154355719498
178.70000000000184,24.370220004263267,-0.6727987125426202,-0.03163558338234296
179.80000000000183,24.47380436401595,-0.6689356096443655,-0.031204191573370288
180.90000000000185,24.57549668325217,-0.6659207648410523,-0.03174232709115943
182.00000000000188,24.67966063052905,-0.662573802411737,-0.032289395151710476
183.1000000000019,24.782820122639492,-0.6589902551641524,-0.031681071690485396
184.20000000000192,24.886416510855764,-0.6558752004617421,-0.028769414747787714
185.30000000000192,24.990542748956216,-0.6531554023741393,-0.031591833699009086
186.40000000000194,25.09147166804987,-0.650367735073327,-0.033770851005677116
187.50000000000196,25.196604758714663,-0.6467331204144703,-0.03151370875779813
188.60000000000196,25.299939944361125,-0.6433459692515974,-0.03293167526751395
189.70000000000198,25.404028551453624,-0.6390865056173666,-0.03556872190755067
190.800000000002,25.507442028763034,-0.6365677095060456,-0.03426705517593298
191.90000000000202,25.611010902320857,-0.6332242630135948,-0.03162001330406783
193.00000000000205,25.71354302184219,-0.6301214847096778,-0.03160442566472632
194.10000000000204,25.817154126808713,-0.6246124306470288,-0.03161756735896404
195.20000000000206,25.92039227842436,-0.6225775537583135,-0.03524308538420806
196.3000000000021,26.024119120042506,-0.617560101593528,-0.032567388243651685
197.40000000000208,26.127513183748423,-0.6151220945424822,-0.03127959123080126
198.5000000000021,26.23072889319251,-0.6113057045709512,-0.03002320658528479
199.60000000000213,26.33467104598267,-0.6088331266691079,-0.0298295479519326
200.70000000000215,26.438371262273243,-0.603720820628857,-0.0355969764877857
201.80000000000217,26.540372516097893,-0.6011987309048519,-0.035468585556048815
202.90000000000217,26.644443818021028,-0.5969651200249444,-0.034323338393395186
204.0000000000022,26.747454086492507,-0.5926067709897068,-0.03520550202752615
205.1000000000022,26.851521954573297,-0.5901199576770063,-0.0367834807460965
206.2000000000022,26.95519903686524,-0.5859074852382891,-0.03637317298895448
207.30000000000223,27.05836237594568,-0.5838344182503319,-0.03532500970396146
208.40000000000225,27.161294425541897,-0.5813417755813542,-0.03524005114966
209.50000000000227,27.265632232559053,-0.5768981860907167,-0.03524005099991978
210.6000000000023,27.3690089745061,-0.5737577873713995,-0.03524001997910231
211.7000000000023,27.471816646521248,-0.5704432161906543,-0.032869072157768464
212.8000000000023,27.576395493619703,-0.5671317910380809,-0.031581790913760344
213.90000000000234,27.67944740873152,-0.5636109620155056,-0.03292494065437834
215.00000000000233,27.782903825605143,-0.5588204636107149,-0.04039248453649913
216.10000000000235,27.884617768995415,-0.5552901148179207,-0.03962378095682029
217.20000000000238,27.98958152752816,-0.5534310684093491,-0.03743876207372576
218.3000000000024,28.09156236246839,-0.5516008504423158,-0.034886502791095175
219.40000000000242,28.19632041495694,-0.5470067556652235,-0.038253701455389866
220.50000000000242,28.300923859988025,-0.5420484219307549,-0.04116994297890697
221.60000000000244,28.403742701165477,-0.5401089544939475,-0.03985004424943783
222.70000000000246,28.50713563113955,-0.536719089621054,-0.04016486934893626
223.80000000000246,28.611013224357343,-0.5340392185763951,-0.04017057519541556
224.90000000000248,28.714048192745793,-0.5315093252671601,-0.04017974164059446
226.0000000000025,28.816959697024508,-0.5296853615064767,-0.037290277502981084
227.10000000000252,28.92276948029957,-0.5262756001289454,-0.03856795617441966
228.20000000000255,29.024494802746208,-0.5231260778645478,-0.037329802873963924
229.30000000000254,29.129849064638197,-0.5186165288675378,-0.040164511387297264
230.40000000000256,29.232491931655375,-0.5161093528946374,-0.041500195886201574
231.5000000000026,29.336721641264415,-0.5118306366599114,-0.04281053060161133
232.60000000000258,29.44104372407288,-0.5086778872952843,-0.0400681907780287
233.7000000000026,29.543810747951298,-0.506766714008736,-0.04006523152234953
234.80000000000263,29.648072403960256,-0.5022126188055853,-0.041389785169920756
235.90000000000265,29.752031660977536,-0.5009255737562912,-0.03875197071116787
237.00000000000267,29.854532501132148,-0.4971246878494829,-0.03874996067073866
238.10000000000267,29.959602286508364,-0.4946932114116013,-0.040057648521383715
239.2000000000027,30.063296436287924,-0.49074695767037946,-0.0400719661859581
240.3000000000027,30.167216928415957,-0.48769071053557533,-0.04006977068352224
241.4000000000027,30.270738961458918,-0.48599268126470774,-0.04137983892642172
242.50000000000273,30.37534817362701,-0.48296920512218205,-0.04399990438790846
243.60000000000275,30.47928972999197,-0.47897881582979007,-0.044035330688672936
244.70000000000277,30.58386443698679,-0.4777557418675897,-0.044694759676630724
245.8000000000028,30.687801780842108,-0.47510210997481533,-0.04495685380671599
246.9000000000028,30.791442673006625,-0.4728833161063067,-0.043966949620199536
248.0000000000028,30.894125840117372,-0.4697875813419636,-0.043335034057152555
249.10000000000284,30.999139975440606,-0.46751986512945454,-0.042049596457442995
250.20000000000283,31.103899445392308,-0.46334975167233483,-0.04270015553509854
251.30000000000285,31.207093982395076,-0.4625897602174236,-0.044019653058646746
252.40000000000288,31.312118617640763,-0.4600831086972612,-0.044019477940242524
253.5000000000029,31.417073154497643,-0.45692863400665407,-0.0440214730063655
254.60000000000292,31.52105687022321,-0.4532297276545012,-0.04678063550814349
255.70000000000292,31.625391432124953,-0.450596894124544,-0.0481554844925518
256.8000000000029,31.729783654539997,-0.449144945646345,-0.04676996261723909
257.90000000000293,31.834514873943515,-0.4473658638691455,-0.04644765999001432
259.00000000000296,31.937622871106807,-0.4422443281443681,-0.04615765834354857
260.100000000003,32.04253124471213,-0.4390589933199828,-0.04775598671178605
261.200000000003,32.145232552410555,-0.43709525077942907,-0.04775924704762291
262.300000000003,32.250136802988536,-0.43369515925597313,-0.047813735565517046
263.40000000000305,32.354891463395674,-0.4307081705728227,-0.049047098539381384
264.50000000000307,32.45825546212863,-0.42865377533811233,-0.04884883761076608
265.6000000000031,32.56258756883377,-0.426504711997135,-0.04753025725933835
266.7000000000031,32.66727188651349,-0.42324701277541726,-0.04883670801740392
267.8000000000031,32.77132343079295,-0.4206167231093479,-0.05039228927277506
268.9000000000031,32.87548918917163,-0.41874056080371364,-0.05179307711095493
270.0000000000031,32.97985387882406,-0.4174602637497307,-0.04751701610235415
271.10000000000315,33.08327843881063,-0.4142102160572615,-0.0450638372080876
272.2000000000032,33.18783373334685,-0.41320480956485217,-0.04892029471155146
273.30000000000314,33.29210139323405,-0.4094023583034193,-0.053799674270305076
274.40000000000316,33.39618866433208,-0.4072414988842992,-0.0544876651092836
275.5000000000032,33.50120902296427,-0.4055376803876585,-0.0500591207740273
276.6000000000032,33.60518846916977,-0.4004999939296177,-0.05391036080438649
277.70000000000323,33.70940503843023,-0.40053783929575776,-0.052252306762314404
278.80000000000325,33.81413463367214,-0.3982173297556674,-0.050710715721183686
279.9000000000033,33.91890621611399,-0.39701604395234974,-0.05335030929572149
281.0000000000033,34.02363906845206,-0.39458832005252237,-0.05301766295228072
282.1000000000033,34.12800988596952,-0.39169413609787684,-0.05494988944229462
283.20000000000334,34.23356702740868,-0.3887184125817352,-0.05466045445126522
284.30000000000337,34.337752980379896,-0.3870961089687005,-0.054662843778496395
285.40000000000333,34.44293513200738,-0.38341635831651816,-0.05959932049596306
286.50000000000335,34.5470989345273,-0.3798932356057891,-0.05747945135890209
287.6000000000034,34.65123757044307,-0.37919032954940796,-0.05543963494574555
288.7000000000034,34.757223292979596,-0.37561215332501213,-0.05687365337222383
289.8000000000034,34.86178771004048,-0.3742061574523876,-0.05728384519310925
290.9000000000034,34.9652260558995,-0.37087699827351667,-0.05278969155288582
292.0000000000034,35.07073448990364,-0.3679606110374909,-0.05268983036147201
293.10000000000343,35.17497691128761,-0.36463140255693427,-0.0540102946112877
294.20000000000346,35.277459217782045,-0.36204888094349974,-0.054003462195139296
295.3000000000035,35.38471926110152,-0.3579151524013729,-0.05946221327235479
296.4000000000035,35.48982209206178,-0.3550374898329721,-0.060589922660441164
297.5000000000035,35.593730066318756,-0.35051132067047075,-0.059136096040934394
298.60000000000355,35.699224215686186,-0.34968578064566236,-0.057200044391785276
299.70000000000357,35.8035905570909,-0.3458673003430121,-0.059827195359575924
300.8000000000036,35.90795764911931,-0.34269785595978075,-0.061798967185616505
301.9000000000036,36.0129406936407,-0.33970075192061955,-0.06046847387850551
303.0000000000036,36.1172482806689,-0.3385187013857706,-0.06246348422652881
304.1000000000036,36.22290985295444,-0.3339107591854081,-0.06407603887706248
305.2000000000036,36.326642666426366,-0.3317290967256663,-0.061496493516869144
306.30000000000365,36.43173049377922,-0.32911988977470963,-0.060267968160126806
307.4000000000037,36.53678517152474,-0.3250800986772925,-0.06300130894470968
308.5000000000037,36.641841140608335,-0.320829911893235,-0.064556003181508
309.60000000000366,36.74609688300312,-0.317787335102235,-0.06442877159752403
310.7000000000037,36.851988065268756,-0.3159606666536698,-0.06841563135034123
311.8000000000037,36.956582556427605,-0.31105260942371354,-0.06806437072245641
312.90000000000373,37.06232875515971,-0.3068107152322516,-0.06806089367546919
314.00000000000375,37.16786467501546,-0.3051822292621556,-0.06937977568124776
315.1000000000038,37.27285496382683,-0.3000734334179587,-0.06806025081226208
316.2000000000038,37.37777011610813,-0.2943864516396404,-0.06804990242135345
317.3000000000038,37.48224734124648,-0.29018958746094775,-0.0693479458922508
318.40000000000384,37.58882798962034,-0.2864979672394273,-0.07202119630958137
319.5000000000038,37.693093257612745,-0.28057079339556407,-0.07417735327866604
320.60000000000383,37.79849230557447,-0.27512685206483267,-0.07531855367006202
321.70000000000385,37.903144508544905,-0.26766718593842653,-0.07786060282202945
322.8000000000039,38.008754754403014,-0.2637827107549454,-0.07872005972959295
323.9000000000039,38.114081931888,-0.25631173865484935,-0.07742243827807638
325.0000000000039,38.21917666331143,-0.2501927777651212,-0.07822652753108983
326.10000000000394,38.324964317684056,-0.24415777244050998,-0.08139746383133195
327.2000000000039,38.42954095774198,-0.23839484227177493,-0.08364834540739219
328.30000000000393,38.53454390407702,-0.23252016128874206,-0.08663370651495139
329.40000000000396,38.640385836704006,-0.2246367738791737,-0.08793387986401324
330.500000000004,38.744082787463014,-0.22083374683644005,-0.08924813211712124
331.600000000004,38.850141599285315,-0.2157608577230138,-0.09057018188244292
332.700000000004,38.95500624620708,-0.2109690883353538,-0.09311428381711462
333.80000000000405,39.0614264546368,-0.20614133611299576,-0.09584013222042387
334.90000000000407,39.166963340619176,-0.20186100305111343,-0.09841275972811037
336.0000000000041,39.271953748772006,-0.19769034574307642,-0.10199318678092828
337.10000000000406,39.378058327749464,-0.19393897913990255,-0.10340994145056559
338.2000000000041,39.48242102594295,-0.19316601615414797,-0.10604877828920678
339.3000000000041,39.58970104886494,-0.19276231893417636,-0.11055203439733541
340.4000000000041,39.69412807075623,-0.1921101610969612,-0.11026627038453274
341.50000000000415,39.79968530668637,-0.19211825992856849,-0.11228265644707625
342.6000000000042,39.90573797737006,-0.19085458297355412,-0.11913357902135369
343.7000000000042,40.01186388885169,-0.1914244676603617,-0.11903754294759361
344.80000000000416,40.1164620256062,-0.19231569859075703,-0.1203199741765375
345.9000000000042,40.220728203931266,-0.1949867830716885,-0.12228976100019473
347.0000000000042,40.3276943263518,-0.1960354997741367,-0.1295071893483244
348.10000000000423,40.4337909054788,-0.1964954161910468,-0.13105970147588408
349.20000000000425,40.539692528079264,-0.2003673860098351,-0.13361324568164878
350.3000000000043,40.64489408560103,-0.20080133752282633,-0.13890698810841373
351.4000000000043,40.75212986436334,-0.20261445564277195,-0.1415478549863538
352.5000000000043,40.857211926509414,-0.2048554975397405,-0.1421369263078054
353.60000000000434,40.96292910487189,-0.20828451632917583,-0.14532360376139675
354.7000000000043,41.06948033285572,-0.2081384683988347,-0.1501686569511005
355.80000000000433,41.174137905914364,-0.20958224336856393,-0.15259991451438637
356.90000000000435,41.28120489752524,-0.20973502605955094,-0.15527138161000353
358.0000000000044,41.386838070634134,-0.2104126162179721,-0.1552340195997708
359.1000000000044,41.49343498189924,-0.2096777776915547,-0.15385827186232248
360.2000000000044,41.59886094097527,-0.20819310168477714,-0.16581835651556354
361.30000000000445,41.703384066533154,-0.20571938863662895,-0.16863394613922766
362.4000000000044,41.807762550606135,-0.20534135674301185,-0.1692895575061799
363.50000000000443,41.91742107425071,-0.20420728711995517,-0.1703550942931633
364.60000000000446,42.023448995878816,-0.20569237419776532,-0.17323471273033686
365.7000000000045,42.12947067318375,-0.2059663803569309,-0.17322996202125074
366.8000000000045,42.23577095211924,-0.2061647470453047,-0.17315353290322566
367.9000000000045,42.342623149855235,-0.20536708231206868,-0.1732239028221101
369.00000000000455,42.448319196062954,-0.20489797216485495,-0.17693058856593158
370.10000000000457,42.55393912953767,-0.2037761704282896,-0.1803749485106385
371.2000000000046,42.66062570332003,-0.20254320841810422,-0.1829782260738959
372.30000000000456,42.76654772640058,-0.20185429026184357,-0.18421609681827977
373.4000000000046,42.87326430070138,-0.20009823061296234,-0.18421088208389902
374.5000000000046,42.97897994337224,-0.19942174066257587,-0.18584638146378873
375.6000000000046,43.08622180434524,-0.19826002704095508,-0.18522017222298626
376.70000000000465,43.19204612633557,-0.19221352919884743,-0.18796100925570602
377.8000000000047,43.298097098727105,-0.18626124402707062,-0.18893112791315847
378.9000000000047,43.40543860204506,-0.18265374560870032,-0.1899425881905028
380.00000000000466,43.510281348861945,-0.1810717860585328,-0.1915704332472168
381.1000000000047,43.616671873938806,-0.17816576614947957,-0.18927990645263693
382.2000000000047,43.72306123758712,-0.17525385023261053,-0.1879201955367713
383.30000000000473,43.82992401582877,-0.1737719215777664,-0.18892973886650433
384.40000000000475,43.93631031495484,-0.17072421512526212,-0.19190136649353207
385.5000000000048,44.042317643044946,-0.16954533564826432,-0.19613500446319465
386.6000000000048,44.14979896939346,-0.1681825894053262,-0.198731777449904
387.7000000000048,44.25643722927716,-0.1666288331224595,-0.19744231696033232
388.80000000000484,44.36138337997116,-0.16395495667573876,-0.1979766465937236
389.9000000000048,44.469358976081494,-0.16287142160955065,-0.20134216301724406
391.00000000000483,44.575356477261884,-0.16042188468637253,-0.19980365622155505
392.10000000000485,44.68231510306176,-0.15852731443679963,-0.1973899028924242
393.2000000000049,44.78848887622712,-0.15588272485713453,-0.1986119281822356
394.3000000000049,44.89579848712405,-0.15360747401533173,-0.20151400788007567
395.4000000000049,45.00352731857913,-0.15090586529835495,-0.20562055129902568
396.50000000000495,45.10933296647275,-0.149617215928588,-0.20420073078526935
397.6000000000049,45.21655190061019,-0.14551930215709152,-0.20419971814560434
398.70000000000493,45.32277898085396,-0.14121926306268767,-0.20638066334289018
399.80000000000496,45.43034213810644,-0.1399440204714839,-0.20792092907057258
400.900000000005,45.53363743568718,-0.1370325807741945,-0.21174660410445423
402.000000000005,45.64349945388431,-0.13459742444290967,-0.2117700283722317
403.100000000005,45.75111449527942,-0.13095155502969902,-0.21561634938702445
404.20000000000505,45.8575532980478,-0.1273630129774956,-0.21599665415352476
405.30000000000507,45.964759944064646,-0.12372972870659583,-0.21726579212842312
406.4000000000051,46.071325621239694,-0.11859005704004873,-0.2157918209698515
407.50000000000506,46.17871075447608,-0.1164382393184861,-0.213406711011924
408.6000000000051,46.285850842072634,-0.11071945873866554,-0.2155834034194286
409.7000000000051,46.39321334519763,-0.10843559607415597,-0.22202233535370608
410.8000000000051,46.50063992937747,-0.10491041037513564,-0.22316321960749574
411.90000000000515,46.606456204147754,-0.10111361534735125,-0.2227347197170637
413.0000000000052,46.71432969567225,-0.097215640366423,-0.22499333175796465
414.1000000000052,46.821368072199604,-0.09489551382599053,-0.2278534164467887
415.20000000000516,46.92907504013292,-0.0923829936050043,-0.23021072661118946
416.3000000000052,47.03676419697301,-0.09216513786268281,-0.23152985669138593
417.4000000000052,47.14374794461876,-0.09063191669876657,-0.2325243138518962
418.50000000000523,47.25091601486837,-0.0913711699919759,-0.23351783803544013
419.60000000000525,47.35755564486789,-0.09208118559010592,-0.23966381142784332
420.7000000000053,47.46548159745094,-0.09485460548948152,-0.2383870937639312
421.8000000000053,47.57420980787704,-0.09594027500204372,-0.24042602102238986
422.9000000000053,47.680529487176116,-0.09915177699061622,-0.2424951568117346
424.00000000000534,47.78790908326249,-0.1004831469338947,-0.24117143134531416
425.1000000000053,47.89558842770965,-0.10265154891640316,-0.23854481754135026
426.20000000000533,48.00336191613327,-0.1031422133696198,-0.23848839727495585
427.30000000000535,48.111120617670466,-0.10404373696837145,-0.24120116573503658
428.4000000000054,48.21866745176949,-0.1056234417513481,-0.243660127979191
429.5000000000054,48.32623482592815,-0.10436242076415156,-0.24645820397131857
430.6000000000054,48.43436933227558,-0.10662443821519325,-0.24644335691085217
431.70000000000545,48.542117789784164,-0.1083201754270357,-0.2478989661431661
432.8000000000054,48.651039633804864,-0.10816341705526224,-0.24843981231366508
433.90000000000543,48.75829669770066,-0.10697356316197038,-0.2524586515465117
435.00000000000546,48.86615851509306,-0.10699243865595595,-0.2539556180341216
436.1000000000055,48.97234895708409,-0.10501470517244013,-0.2527277717213021
437.2000000000055,49.081222604644616,-0.1019484303548973,-0.25140684377467926
438.3000000000055,49.18903140409137,-0.09852492695153975,-0.2514209892430266
439.40000000000555,49.296783447437285,-0.09828782648177603,-0.25422584202658793
440.50000000000557,49.4043632882886,-0.09506783792007217,-0.25699993814938127
441.6000000000056,49.51213515565294,-0.09385733606689635,-0.256862899951944
442.70000000000556,49.61863312499256,-0.08942546764351066,-0.25541855804173075
443.8000000000056,49.72590846656574,-0.087403367098484,-0.26104108818910454
444.9000000000056,49.833136778525976,-0.08373054582957754,-0.26224938352010874
446.0000000000056,49.9418533062179,-0.08019512134115399,-0.26544999580030115
447.10000000000565,50.04783830362484,-0.07982158963386585,-0.26282183056804653
448.2000000000057,50.15740868950774,-0.07565938561887146,-0.2648874247211528
449.3000000000057,50.264869226456085,-0.0747150554141703,-0.2654383993778686
450.40000000000566,50.37236439322069,-0.0717748912707505,-0.2684249163051269
451.5000000000057,50.47977204212539,-0.06939601520837489,-0.2715680756127017
452.6000000000057,50.58786409095398,-0.06505231089247754,-0.2739084841682824
453.70000000000573,50.69528416566376,-0.0628109284172865,-0.27530877997945913
454.80000000000575,50.80251174885045,-0.060218492688877044,-0.2762397475802447
455.9000000000058,50.91063487001644,-0.05644520370878997,-0.27938984773144515
457.0000000000058,51.01837534729064,-0.054941402170549734,-0.2793899612346369
458.1000000000058,51.12651928199464,-0.05212306330013435,-0.28070173884922855
459.20000000000584,51.233465013220204,-0.04900990969912773,-0.2828111829241915
460.3000000000058,51.34178390227062,-0.04801147281810678,-0.2841010974675231
461.40000000000583,51.449743391981976,-0.045409729875345126,-0.28128276692577625
462.50000000000585,51.556763860465985,-0.04521921887721764,-0.28642331712113567
463.6000000000059,51.665501134438,-0.04376231397106467,-0.2918117745734583
464.7000000000059,51.772743751342304,-0.041964944217044324,-0.29377617572759807
465.8000000000059,51.88064114247382,-0.03936834051361317,-0.2976123074656529
466.90000000000595,51.9891666387742,-0.03755948236541755,-0.2940124208404167
468.0000000000059,52.09749048796203,-0.03743774149204024,-0.29659003328411826
469.10000000000593,52.20534991182007,-0.03494015084171145,-0.2994899001963751
470.20000000000596,52.312857973923876,-0.034027669458160006,-0.29670422592423806
471.300000000006,52.420926332277695,-0.032735131450655305,-0.2983550226877183
472.400000000006,52.52874586685718,-0.030967092909190565,-0.3046984628568734
473.500000000006,52.636531976003454,-0.031288139175335315,-0.3087730167545599
474.60000000000605,52.74467108421541,-0.027263308614265326,-0.30628668218152644
475.70000000000607,52.85221049473959,-0.02830490751177965,-0.3049896244847785
476.8000000000061,52.961199667656224,-0.026975121881949993,-0.3062903656258458
477.90000000000606,53.069205836673554,-0.024978390515235822,-0.308932017944771
479.0000000000061,53.177652582056204,-0.02404239517257194,-0.31058890923754134
480.1000000000061,53.28514323086364,-0.022706894724053194,-0.31156017899872523
481.2000000000061,53.393756507012874,-0.02197179844168744,-0.31420717533053955
482.30000000000615,53.50150163161628,-0.022866564175485646,-0.31684489305679975
483.4000000000062,53.60934689715801,-0.021395072598154558,-0.3141359089445803
484.5000000000062,53.71711689615399,-0.0069594585998482205,-0.3100219174642236
485.60000000000616,53.825550045686306,0.0013575504658800877,-0.3115235466012214
486.7000000000062,53.93403088281411,0.008569213300765483,-0.3157354685545859
487.8000000000062,54.0411376396733,0.010037599645906158,-0.31837244990770186
488.90000000000623,54.150730569097114,0.006224723224301677,-0.31562995508193215
490.00000000000625,54.25901586840257,0.0035872919282770597,-0.314327621774269
491.1000000000063,54.36735930885753,-0.0007059537041946545,-0.31955796657447566
492.2000000000063,54.47528947806863,-0.0029325316836263586,-0.3208755900288476
493.3000000000063,54.584544533742225,-0.008784884914579441,-0.3185986758827699
494.40000000000634,54.69221894842262,-0.012735755533142046,-0.3159775933505582
495.5000000000063,54.799063947163276,-0.01693313660399629,-0.3118904861493337
496.60000000000633,54.90899101001472,-0.022812413490952466,-0.3185151154043586
497.70000000000636,55.018070443921204,-0.026821891112149686,-0.31770552514088246
498.8000000000064,55.12687935716331,-0.030849758164386936,-0.3231511132908098
499.9000000000064,55.23612983037723,-0.036519350923382106,-0.32198786786248634
501.0000000000064,55.342683964500054,-0.04004900980167812,-0.3218791052147423
502.10000000000645,55.453598145264436,-0.042025827774784405,-0.3232160365464547
503.2000000000064,55.56124805854517,-0.04294245738314604,-0.32487540033324036
504.30000000000643,55.670178341601336,-0.04740746174520168,-0.32323321550697814
505.40000000000646,55.77772612095921,-0.049937185966869836,-0.3246325480551753
506.5000000000065,55.88707588603632,-0.05251138980225374,-0.32497050629394275
507.6000000000065,55.994188204674124,-0.05594657218357134,-0.32232246722618507
508.7000000000065,56.103536549985485,-0.05856648779990433,-0.3228818484798541
509.80000000000655,56.211442510708245,-0.06154788253179512,-0.32153507292991534
510.90000000000657,56.321227445719856,-0.06478911988141076,-0.3215631443110203
512.0000000000066,56.43052073437322,-0.06749468655344311,-0.32419003032981486
513.1000000000065,56.540080694070596,-0.06866123135726705,-0.32682152646186147
514.2000000000066,56.64883338134268,-0.07037645077056476,-0.3268299890057009
515.3000000000065,56.75577619744686,-0.07170749553515317,-0.32682998952775755
516.4000000000067,56.8652407399719,-0.07202598508427585,-0.32536376645117704
517.5000000000066,56.9744178159012,-0.07503149188975658,-0.32198952998160957
518.6000000000067,57.08386461217343,-0.07546275224102036,-0.32379373795764943
519.7000000000066,57.192533211709275,-0.07478548231555214,-0.3265994282146245
520.8000000000067,57.30171796797634,-0.07597024948609776,-0.3253007599004083
521.9000000000067,57.41117891703916,-0.07783519121462613,-0.3265998387861573
523.0000000000067,57.519853041717674,-0.07842882436719911,-0.32659990690065
524.1000000000067,57.62745204420954,-0.0786663473646813,-0.3252507902232171
525.2000000000068,57.7374501323282,-0.07899211239651234,-0.32396990698177897
526.3000000000068,57.8442886869028,-0.0780182181226429,-0.3239061709724598
527.4000000000068,57.95625634090327,-0.07821248863945314,-0.3263802270446594
528.5000000000068,58.06231834703448,-0.07879547765442761,-0.3250749994335327
529.6000000000068,58.17346066726479,-0.07638305836190418,-0.32505990588029876
530.7000000000069,58.282200779443954,-0.07645518630315933,-0.32635017596784444
531.8000000000068,58.39218040774105,-0.07216860488448189,-0.32643330739805565
532.9000000000069,58.500828049098175,-0.07122073486092698,-0.329349951537647
534.0000000000068,58.60974114174042,-0.0717801940501298,-0.3264644524552316
535.100000000007,58.71800912242269,-0.07133163224619991,-0.3253899185485509
536.2000000000069,58.82786518321714,-0.06926057787027697,-0.32407704614428745
537.300000000007,58.93731422280514,-0.06524127645249807,-0.3240802075561624
538.4000000000069,59.04569186259964,-0.06171793938807374,-0.3261090808836129
539.5000000000069,59.15602455260398,-0.05819021319747886,-0.3261682539138806
540.600000000007,59.26217535892496,-0.0571380576737996,-0.32891030837576496
541.700000000007,59.373968596080054,-0.054246406860841374,-0.32890994734397827
542.800000000007,59.48289619935942,-0.053127004906905216,-0.3303367570002922
543.900000000007,59.59250928088502,-0.05107726252325649,-0.3315842016717716
545.000000000007,59.70223704047623,-0.04858096861324673,-0.33153990208055495
546.1000000000071,59.81170092341343,-0.04648040238197288,-0.3330773171586521
547.2000000000071,59.92000178176035,-0.0441210718331037,-0.3349822700355545
548.300000000007,60.02973840502696,-0.04211243071687179,-0.3340473481677053
549.4000000000071,60.13985840813642,-0.039513604631965925,-0.3300722379761396
550.500000000007,60.248486737618265,-0.03797120806344709,-0.32770985722750856
551.6000000000072,60.35773713589078,-0.03607593139191967,-0.3273796954128212
552.7000000000071,60.46600065994414,-0.0327008390741425,-0.3273798596533477
553.8000000000072,60.57419716699797,-0.02913648318914862,-0.32748250834051396
554.9000000000071,60.68406648470698,-0.025608769940422264,-0.3290402419207519
556.0000000000072,60.79346441773816,-0.023569648622289573,-0.33165994835080514
557.1000000000072,60.902153457001305,-0.020708888686623687,-0.33165995764907574
558.2000000000072,61.0119410633325,-0.01957066140259452,-0.3322672409778482
559.3000000000072,61.12104646273685,-0.017207033689704138,-0.33330984818934706
560.4000000000073,61.2291454937968,-0.014104661993783142,-0.3355878781751307
561.5000000000073,61.33950758230371,-0.01362779078026307,-0.33696334671783257
562.6000000000073,61.44708499694326,-0.00980955598748919,-0.3356960247806984
563.7000000000073,61.55812482506021,-0.00897740898045783,-0.33309142690070503
564.8000000000073,61.6674559464974,-0.00424195894241947,-0.3320998273059961
565.9000000000074,61.77460054980485,-0.00501085455200844,-0.3334146087676517
567.0000000000074,61.886868352328484,-0.0017090798449542572,-0.3307803845084307
568.1000000000074,61.99584366904203,0.0004966070239286013,-0.3307801809998958
569.2000000000073,62.10552500212476,0.0012460350794539074,-0.3307801811249056
570.3000000000073,62.215115948796885,0.0038938213832109647,-0.3293787243848958
571.4000000000074,62.324348126563244,0.005610527075178765,-0.3309637625633157
572.5000000000074,62.43388884530332,0.0076132235667244275,-0.3347120505576604
573.6000000000074,62.543909450781186,0.011233148881418702,-0.3348402661329133
574.7000000000074,62.652988273077334,0.013551871520645162,-0.33169728716355396
575.8000000000075,62.763421748783266,0.015546241218770794,-0.33176001238533015
576.9000000000075,62.872133082862206,0.019060365183246816,-0.33175999000015377
578.0000000000075,62.981522202771274,0.018563730826541627,-0.331759686309943
579.1000000000075,63.09140081840286,0.02310333092562564,-0.3345427563001646
580.2000000000075,63.20210866696548,0.023838528373586822,-0.33651222827945126
581.3000000000076,63.311437616018196,0.02551188930202314,-0.33384862041785945
582.4000000000076,63.421259666013114,0.026932265068854242,-0.3312346228035419
583.5000000000076,63.53092512004523,0.02981697774864751,-0.3311399151063523
584.6000000000076,63.639363403897825,0.03163721721694556,-0.33253079035973965
585.7000000000077,63.7499315561944,0.03562431544643471,-0.33252659792714345
586.8000000000077,63.85915603163631,0.0371851012436559,-0.33384923019315194
587.9000000000076,63.969380040564445,0.03876659535884507,-0.331220282547251
589.0000000000076,64.079440720154,0.04130827785502857,-0.33055966680906756
590.1000000000076,64.18798708201044,0.04520870330485386,-0.3372210864756551
591.2000000000077,64.29866832030828,0.04625686465563473,-0.34188760511855776
592.3000000000077,64.4093867040047,0.04796049910916049,-0.3359337333198811
593.4000000000077,64.51946540311305,0.05100184180037801,-0.3315889741759568
594.5000000000077,64.6289874795171,0.05333014064936587,-0.33232191160915736
595.6000000000078,64.73951435347577,0.055824002481494384,-0.3323083052063618
596.7000000000078,64.84790831929492,0.05787857053992972,-0.33372175686944505
597.8000000000078,64.95884703180796,0.06377943456192468,-0.33383586691293665
598.9000000000078,65.06938423588176,0.06564062146864053,-0.33628475866288143
600.0000000000078,65.17760519159674,0.06890664475340424,-0.3326762954259239
601.1000000000079,65.28909731641544,0.07028950769373372,-0.3303298690926786
602.2000000000079,65.3985906992443,0.07306114451709385,-0.3316409439296528
603.3000000000079,65.50944177006578,0.0747765975253719,-0.3349563284506809
604.4000000000078,65.61950914950829,0.078313419599697,-0.33572034030999554
605.5000000000078,65.72976129477482,0.08036978032036388,-0.33858783204189535
606.6000000000079,65.8396227530958,0.08375648935915725,-0.33999027594940134
607.7000000000079,65.9501945075094,0.08621754071388264,-0.3351228308702501
608.8000000000079,66.06062739102802,0.09015883161625873,-0.3300209955235749
609.9000000000079,66.17093072880928,0.0924726753505254,-0.3260930428918303
611.000000000008,66.27987387037071,0.09560529038937134,-0.3260913472315474
612.100000000008,66.39134219095627,0.09959027477126146,-0.3313615505942593
613.200000000008,66.50175378151513,0.10242811896377198,-0.3367305863995744
614.300000000008,66.61225638924027,0.10699494601204218,-0.33451051304254875
615.400000000008,66.72298340662769,0.11173723227304401,-0.33717145875144805
616.5000000000081,66.83428392159233,0.11499896344056915,-0.3371398958397185
617.6000000000081,66.94357037224067,0.11865614989476451,-0.3377046698135153
618.7000000000081,67.0534460070311,0.12412962064909036,-0.3355076868770599
619.8000000000081,67.1640489946644,0.12745329126931487,-0.33654798430563915
620.9000000000082,67.27490738461337,0.12952923515090747,-0.3372597501013397
622.0000000000082,67.3849041649049,0.1331476949068501,-0.33594584350502465
623.1000000000081,67.4948823813175,0.13532936882104374,-0.33375388162209907
624.2000000000081,67.6044637878539,0.1354774541462085,-0.33724333814872276
625.3000000000081,67.7154748861332,0.13894987000299328,-0.33362905880732185
626.4000000000082,67.82530046470063,0.14284933226411886,-0.3349551487283611
627.5000000000082,67.93611454281906,0.14404211668374592,-0.3359396330153612
628.6000000000082,68.04614131451171,0.1480385372884614,-0.33754339801728017
629.7000000000082,68.15693458278989,0.14895157437423448,-0.33899525093400085
630.8000000000083,68.26741449267378,0.15140110409203947,-0.3355911007178465
631.9000000000083,68.37799002207386,0.1529724891708775,-0.3317672731216983
633.0000000000083,68.48793653175136,0.1548938031786215,-0.33175999102605136
634.1000000000083,68.59960866599543,0.1576033527107427,-0.33307992012972987
635.2000000000083,68.70943997095306,0.15946081197329443,-0.3349377128163633
636.3000000000084,68.82001154604062,0.1612982272822799,-0.3383528795173625
637.4000000000084,68.92821191549758,0.16183937584029204,-0.337059057694693
638.5000000000084,69.03959551233399,0.16326548412118894,-0.3322911500708372
639.6000000000083,69.15000018038317,0.1631174738669237,-0.3299000320896113
640.7000000000083,69.26103921551729,0.16653094268768265,-0.3325530042298528
641.8000000000084,69.37053267636746,0.16762465672046664,-0.33253051796666666
642.9000000000084,69.48029165293848,0.16838267813757613,-0.33518825068842073
644.0000000000084,69.59178180809262,0.1696354052296507,-0.3365077856705261
645.1000000000084,69.70103604257493,0.17110756227874063,-0.3325267626587718
646.2000000000085,69.81013103731546,0.17383474860733208,-0.3351813374956061
647.3000000000085,69.92194441519503,0.1778827976896662,-0.33598872872447894
648.4000000000085,70.03197578153137,0.18118525539105057,-0.33439992832091914
649.5000000000085,70.14238199948204,0.17962545197129715,-0.3361725378101008
650.6000000000085,70.25237737094893,0.181654535473713,-0.3373663436041294
651.7000000000086,70.36260644257887,0.18283368139133027,-0.3319343031610167
652.8000000000086,70.4729414831792,0.18539732306247844,-0.3316876273073057
653.9000000000086,70.58346773500809,0.1870367304306586,-0.3332234473004192
655.0000000000086,70.69351407199076,0.18968091928492128,-0.33480222537907256
656.1000000000087,70.8039123419049,0.19104705152249965,-0.3361497736236321
657.2000000000087,70.91327688918368,0.19262077380775233,-0.33909710411862237
658.3000000000086,71.02411766468737,0.19224092491987638,-0.3436200938785148
659.4000000000086,71.13391054755733,0.19569033110352432,-0.34033791518880596
660.5000000000086,71.2444063244996,0.19645182151118146,-0.33328659609523426
661.6000000000087,71.35504271102916,0.19731989138886447,-0.33332919977326814
662.7000000000087,71.46567984801683,0.19840227228337545,-0.33462046001106094
663.8000000000087,71.57620882485853,0.2015619561262756,-0.3330671279095023
664.9000000000087,71.68597713600498,0.2032569741757428,-0.334895151698384
666.0000000000088,71.79599037103269,0.2051252502434276,-0.3334133024508654
667.1000000000088,71.90648925088392,0.20586991600048635,-0.332534654997505
668.2000000000088,72.01661057396745,0.20775162042621975,-0.33390076594497486
669.3000000000088,72.12725161735062,0.21227478711300937,-0.33647941765710554
670.4000000000088,72.23763710569555,0.21547874166334954,-0.33550013988567784
671.5000000000089,72.3473386903781,0.21632104122650156,-0.3367682289985643
672.6000000000089,72.45781049826381,0.2169296724342935,-0.3381400147701008
673.7000000000089,72.5660209256882,0.22035416591039733,-0.3383836581409607
674.8000000000088,72.67902223930051,0.21955847293138708,-0.33549968911654515
675.9000000000088,72.78993298046376,0.22176559970425935,-0.3383907705620075
677.0000000000089,72.89960091392328,0.22280856568985774,-0.3384603121054668
678.1000000000089,73.0093813984975,0.22357450900352127,-0.33582553664302006
679.2000000000089,73.12071434839852,0.22437769297990443,-0.3358307627482029
680.3000000000089,73.23003005829747,0.22556310566303894,-0.33582903930066976
681.400000000009,73.34216048661258,0.2269787172335821,-0.3370427443820354
682.500000000009,73.45268311231025,0.2281881709231076,-0.33550098063133404
683.600000000009,73.56337030485476,0.2293334904546468,-0.33370485660864
684.700000000009,73.67324219088636,0.231709486520576,-0.33395935375230357
685.800000000009,73.78480244138892,0.2333700435294424,-0.3384920691372608
686.9000000000091,73.89471383345077,0.2345093655273095,-0.346932975063452
688.0000000000091,74.0055384192159,0.23583747625803228,-0.3423163595582426
689.1000000000091,74.11590949825697,0.23708048123435532,-0.3341097592533071
690.2000000000091,74.22652024310295,0.2391963358050113,-0.32997133643274656
691.3000000000092,74.3379709758926,0.23929333780379147,-0.3317637979661936
692.4000000000092,74.44784119259232,0.23761018260435823,-0.3362867850761564
693.5000000000091,74.55878576603378,0.24378128720575432,-0.33462003399036977
694.6000000000091,74.66937353683628,0.2429476305751731,-0.3347363482825667
695.7000000000091,74.77979934409362,0.24625628346198195,-0.3361957585696511
696.8000000000092,74.88980275412979,0.24626646133502653,-0.33530529543119725
697.9000000000092,74.9999099148372,0.2488499552212004,-0.3367992519500618
699.0000000000092,75.1114199425002,0.25019914627855155,-0.3362052864922993
700.1000000000092,75.22153647034413,0.25048550396222896,-0.33614085574224184
701.2000000000093,75.3319593087934,0.2532476395520008,-0.3361501289906177
702.3000000000093,75.44385675361734,0.2522360459119102,-0.3374516979662574
703.4000000000093,75.55360583198897,0.2529712424564411,-0.33365595355230315
704.5000000000093,75.66521079523288,0.2574421572142587,-0.3333032046438431
705.6000000000093,75.77628875945678,0.2575741127567947,-0.33924286667590575
706.7000000000094,75.88737487106107,0.25867030002128566,-0.3399791181311369
707.8000000000094,75.9981176833992,0.2575596896769358,-0.34132357699598836
708.9000000000094,76.10973369752463,0.26072791462505485,-0.34253780065944595
710.0000000000093,76.22053242577798,0.2635089258433765,-0.3365007741611872
711.1000000000093,76.33143911536676,0.2660307883321425,-0.33682049338395004
712.2000000000094,76.4421726437155,0.2667962470098156,-0.33899635241616943
713.3000000000094,76.55296323251861,0.2648988577679095,-0.3380179755292323
714.4000000000094,76.66365222369345,0.26515725541674784,-0.33531307994188264
715.5000000000094,76.77235371326228,0.26615263872089606,-0.3342055352241373
716.6000000000095,76.88464270002676,0.2695007048524067,-0.3383391746614026
717.7000000000095,76.99522435508581,0.2714783533416846,-0.3357205409843331
718.8000000000095,77.10578604627516,0.27437387397028024,-0.33433690272516037
719.9000000000095,77.21604253403352,0.2744200237137391,-0.3343827316520249
721.0000000000095,77.32645265098652,0.2757953516394389,-0.33591792770439577
722.1000000000096,77.4368517292999,0.2814848889265864,-0.33461425425410507
723.2000000000096,77.54782789587003,0.28190003162698707,-0.3359293732447801
724.3000000000096,77.65869423851105,0.28219359159134255,-0.33886871765348614
725.4000000000096,77.76948880836898,0.2889155638108266,-0.3415003606082956
726.5000000000097,77.88032109031813,0.29135656083969697,-0.3419046966406305
727.6000000000097,77.99055559340921,0.29373375984453404,-0.33856994439618004
728.7000000000096,78.10161921333669,0.29452894783349487,-0.3395148841603741
729.8000000000096,78.21306147003223,0.2969407286328916,-0.3390891402011067
730.9000000000096,78.32381764510866,0.2952756729717839,-0.34078556292782114
732.0000000000097,78.43433983885443,0.2947024796418206,-0.34275005322723073
733.1000000000097,78.54560039330173,0.2961331305723665,-0.34004814319439935
734.2000000000097,78.65650164799214,0.29687622035692807,-0.34142798456001033
735.3000000000097,78.76727990678651,0.2988682193486303,-0.3394368440062743
736.4000000000098,78.87827942910764,0.3017760824383455,-0.3374145756620677
737.5000000000098,78.98743762362525,0.3013240286443934,-0.33856980940908166
738.6000000000098,79.10035256310688,0.3038336284518353,-0.3385696636113802
739.7000000000098,79.2114359331358,0.3052254250687798,-0.3412008828142583
740.8000000000098,79.32204445330157,0.30608371051220995,-0.34244522891696416
741.9000000000099,79.43296238452571,0.3069098460392891,-0.3381318232087467
743.0000000000099,79.54352894601907,0.30714389116152097,-0.34078815861948364
744.1000000000099,79.65502537379639,0.3092001785237074,-0.34207491380944566
745.2000000000098,79.76646973270941,0.3089293765360824,-0.34081713603169694
746.3000000000098,79.87733402603294,0.30826258861432965,-0.33977826274212175
746.9000000000099,79.93677918457867,0.3087568283905687,-0.3410999436417095