File: 01_Data/EIFS_Mesh/STA/N2/10K_min/EIFS_Mesh_STA_N2_10KData_230207_R3.csv
##Temp./Â°C,Time/min,DSC/(mW/mg),Mass loss/mg
50.0,10.834997879722637,-1.8580931953756172,0.009400225363042303
50.90000000000001,11.111858117382823,-1.759785020864275,0.00903215365843213
51.800000000000026,11.315222413614432,-1.6878711778465916,0.007502471014418255
52.70000000000004,11.488230287733003,-1.6315128222092194,0.007127073058748046
53.60000000000005,11.640654496106656,-1.5874734212437422,0.006839184096098627
54.500000000000064,11.788130509814556,-1.5468929580531945,0.007434691322829146
55.40000000000008,11.926136897360706,-1.513237857838445,0.006838918312126019
56.30000000000009,12.055565355014421,-1.4846664170430262,0.005756874500124631
57.2000000000001,12.182202409794302,-1.458028305739821,0.006631853412526034
58.100000000000115,12.29884676385728,-1.4375168432587495,0.006839398144149023
59.00000000000013,12.423179498949736,-1.4141838440207535,0.006608672967033158
59.90000000000014,12.539731958156942,-1.3961718807168517,0.005378736547569041
60.80000000000015,12.654557780337738,-1.3808515707063995,0.004109230652609597
61.700000000000166,12.767832141869146,-1.3654936735786636,0.005640470729177061
62.60000000000018,12.879737449554222,-1.3506146794310103,0.004616117588248869
63.50000000000019,12.98869066752324,-1.3362218847227145,0.004374284433653841
64.4000000000002,13.098045982933826,-1.3227684544639882,0.004302533071924408
65.30000000000021,13.204487343974193,-1.3117639507686978,0.0045179820949536875
66.20000000000023,13.310596982694893,-1.2983986641620875,0.003708413538555
67.10000000000025,13.416581724375973,-1.2860153561202887,0.004319634853752419
68.00000000000026,13.520951463693786,-1.274933860749695,0.004062075358801209
68.90000000000026,13.62400624868147,-1.2627025430722154,0.003061739959419718
69.80000000000028,13.721630136784398,-1.2527024485224691,0.004387619328440451
70.7000000000003,13.826333284871088,-1.2424911010314048,0.0037712456723753007
71.6000000000003,13.927796502620357,-1.2304354677832807,0.0030641941146116736
72.50000000000031,14.028588549350985,-1.220961541391,0.004198439315837632
73.40000000000033,14.127871483104762,-1.2109748928544837,0.003093111655184444
74.30000000000035,14.226349300444838,-1.200934011588461,0.003082363318573478
75.20000000000036,14.322905319007763,-1.1911682836175956,0.004298415927767252
76.10000000000036,14.422137979135645,-1.181074395989341,0.003074238805558238
77.00000000000038,14.519139542916909,-1.1732409975762494,0.0022683080969221336
77.9000000000004,14.61688822886307,-1.1627342683670974,0.003089113788697695
78.80000000000041,14.712463064735642,-1.152394215448582,0.0030658427326510918
79.70000000000041,14.80550904511629,-1.1437779529216157,0.0030712493659059703
80.60000000000043,14.90266489870312,-1.1333185942138535,0.002842704321030176
81.50000000000045,14.998130363932322,-1.1274009174513584,0.001831351849166829
82.40000000000046,15.091606915492147,-1.1195712829642852,0.001683804181747739
83.30000000000047,15.185710736301548,-1.111672535210664,0.0005161004545586323
84.20000000000049,15.278446054720238,-1.104188563646359,0.0011797336257641788
85.1000000000005,15.370830000000055,-1.096299999999994,0.0017527794677363318
86.00000000000051,15.463145656752195,-1.090264793372177,0.0015364372092419032
86.90000000000052,15.555730477065614,-1.0852960903277709,0.0018526170788240037
87.80000000000054,15.647746448208768,-1.076913893271042,0.00042853471404313837
88.70000000000056,15.737029623882496,-1.0701118480257923,0.0004309784838589792
89.60000000000056,15.830633534831964,-1.0645840097673667,0.00043134069364736405
90.50000000000057,15.920724339146936,-1.0577149002789754,0.0004257029965373249
91.40000000000059,16.01154430048709,-1.0495927186820238,0.0017651160474363436
92.30000000000061,16.102171662867065,-1.0448911025358483,0.002049478343804978
93.20000000000061,16.190925468154475,-1.039149838059303,0.00041703732137232663
94.10000000000062,16.280014766147556,-1.0330348501588427,0.00040377845413352986
95.00000000000064,16.371593362243207,-1.0251333854566858,-0.00026734340319034544
95.90000000000066,16.460399715403007,-1.0188028744092776,0.00043033087736343845
96.80000000000067,16.549013107705807,-1.0140026445961983,-0.0008956828762505253
97.70000000000067,16.637199504953436,-1.0093353773795324,-0.0008802995161429905
98.60000000000069,16.727127784132353,-1.0026026063770896,-0.0008855117716546346
99.50000000000071,16.81362063208206,-0.9982743798161297,-0.0021994466215611297
100.40000000000072,16.90222616929328,-0.9912584230372872,-0.0008872536599406899
101.30000000000072,16.990921799443335,-0.9859822283364139,-0.002117093598529074
102.20000000000074,17.079475509534735,-0.9831868794774444,-0.0021967365158177543
103.10000000000076,17.166071935470708,-0.9776499660627829,-0.002192087774672835
104.00000000000077,17.25233580510568,-0.9718173883482972,-0.002215692139794889
104.90000000000077,17.3436234400993,-0.9676314814781973,-0.0025474770271207703
105.8000000000008,17.43024085324716,-0.963395491732935,-0.00220582008190906
106.70000000000081,17.518460171253793,-0.9599540515373505,-0.001770054991427017
107.60000000000082,17.60512797969645,-0.9555407569058894,-0.0009089768794705577
108.50000000000082,17.69275369915692,-0.9497783096369433,-0.002200037535006416
109.40000000000084,17.77970934893002,-0.9444617401019451,-0.0022028156626126005
110.30000000000086,17.86684609869857,-0.9399841967201754,-0.003498596586095637
111.20000000000087,17.95513689901894,-0.9369599718025411,-0.0028478294531266712
112.10000000000088,18.042130087796263,-0.9324698210952065,-0.002557521778243199
113.0000000000009,18.128883666009397,-0.9292546898176607,-0.0035229451225164965
113.90000000000092,18.21370364134246,-0.9252847979094898,-0.0022035925768397746
114.80000000000092,18.302891385088,-0.9206755845879386,-0.003519951911063579
115.70000000000093,18.38956952613789,-0.9176028016339695,-0.004838606902199061
116.60000000000095,18.476466387759945,-0.9126818248012901,-0.0035203971991943916
117.50000000000097,18.566008885119743,-0.9096344030647019,-0.0036220191400664348
118.40000000000097,18.65102543732511,-0.9048815340354781,-0.003529875192855414
119.30000000000098,18.73775430572452,-0.9020620182265696,-0.004844976047762017
120.200000000001,18.82452794397356,-0.8981427047855352,-0.003622192666607127
121.10000000000102,18.90980174567309,-0.8930536970606001,-0.0035265352074098644
122.00000000000102,18.998559552085684,-0.8892736318525337,-0.004847505299974131
122.90000000000103,19.083484719150476,-0.8854938817259191,-0.005964073139447024
123.80000000000105,19.17120637530079,-0.8820933477465208,-0.004839851693844821
124.70000000000107,19.256688394461307,-0.8786186786910848,-0.006242255351970094
125.60000000000107,19.343927723275854,-0.8746938339683775,-0.004839698286164484
126.50000000000108,19.429985429294565,-0.8721218129833268,-0.00615305503441288
127.4000000000011,19.51625313385154,-0.8687364812235753,-0.006150129833319085
128.30000000000112,19.602581089637894,-0.8647209876630221,-0.006159302400159383
129.20000000000113,19.687608829175105,-0.8609055899624397,-0.006160009964659707
130.10000000000113,19.77484938414746,-0.8555049531071116,-0.006165861027300323
131.00000000000114,19.860013746663068,-0.8525813063337875,-0.004839639886801805
131.90000000000117,19.94646481735929,-0.8492722970143024,-0.005850538081669576
132.80000000000118,20.033135197343892,-0.8445414758225093,-0.005988037536943658
133.70000000000118,20.119108752918557,-0.8406790579944883,-0.006161856035435953
134.60000000000122,20.203311350671424,-0.8364703264033204,-0.006131940435762928
135.50000000000122,20.28863825240367,-0.832028962912775,-0.0074682559124266135
136.40000000000123,20.375814350008557,-0.8283681564140472,-0.006149927031620983
137.30000000000123,20.461302401832818,-0.8248821270875991,-0.006148707180210877
138.20000000000124,20.545218817126354,-0.8213749709424765,-0.0061631597713649455
139.10000000000127,20.632495417971988,-0.8167802535777521,-0.004840011149982004
140.00000000000128,20.714438972270738,-0.8129338810492821,-0.005706064043581094
140.90000000000128,20.80262204371411,-0.8086264686012674,-0.00616002337620003
141.80000000000132,20.887512473418102,-0.8060414976097661,-0.00622383801357973
142.70000000000132,20.972499079603697,-0.8016727687345542,-0.0059372644592947665
143.60000000000133,21.057547903101014,-0.7984734784804693,-0.0061884555604905245
144.50000000000134,21.143579261933688,-0.7943908444435224,-0.006150089546242299
145.40000000000134,21.2276705644041,-0.7921722879329843,-0.006150034433717089
146.30000000000138,21.31460397501666,-0.787556445218497,-0.004849381938814901
147.20000000000138,21.398618245853083,-0.7843987334388741,-0.006204139658219532
148.1000000000014,21.48388350222371,-0.7799741642469641,-0.007487908064383042
149.00000000000142,21.568781878337518,-0.7773567465630994,-0.006109637748092922
149.90000000000143,21.653709515438507,-0.7707393501888528,-0.006159229310585879
150.80000000000143,21.737974936736254,-0.769602726309972,-0.007469270486917701
151.70000000000144,21.82164661529022,-0.7649026522678144,-0.0074698035302516175
152.60000000000144,21.907756819282334,-0.7630290665809951,-0.007547828212172369
153.50000000000148,21.994223875966924,-0.7578146430872454,-0.007470042934133225
154.40000000000148,22.078633796347834,-0.7537810767974277,-0.008344948820591114
155.3000000000015,22.1633988784364,-0.7502918043371576,-0.008768610960005141
156.20000000000152,22.248028372101114,-0.7474616563347085,-0.007645281024857731
157.10000000000153,22.33226390881173,-0.743663073011475,-0.008789973032583553
158.00000000000153,22.417559043093018,-0.7400856952668468,-0.008751896629423328
158.90000000000154,22.501991567270384,-0.7371056760859498,-0.009449832121522839
159.80000000000155,22.586811949249874,-0.7322639144094634,-0.008764425636946349
160.70000000000158,22.67101350716129,-0.7284721220184839,-0.00812127345160718
161.6000000000016,22.756583341941916,-0.7250498496002127,-0.008666416809354871
162.5000000000016,22.841402817180086,-0.7201869097096499,-0.010244769501650097
163.40000000000163,22.926388858783984,-0.7172674189659972,-0.010109992058102257
164.30000000000163,23.011353418616654,-0.7141546638094399,-0.008750533134683991
165.20000000000164,23.095376666186556,-0.710800185190005,-0.009449732027361435
166.10000000000164,23.180655284100816,-0.7066555323400877,-0.009449818000319077
167.00000000000165,23.264610432281334,-0.7038005514749124,-0.009449818002480903
167.90000000000168,23.349483726391284,-0.7007654465618205,-0.00944988584399109
168.8000000000017,23.434797399761113,-0.6973548811392337,-0.009506966307074372
169.7000000000017,23.518815632414963,-0.6938075694237632,-0.010773244010831462
170.60000000000173,23.60436125448813,-0.6895558654266217,-0.011426866472259434
171.50000000000173,23.689441350751387,-0.6875807345062307,-0.011420052013083826
172.40000000000174,23.774515359000986,-0.6834090772717543,-0.01141998837101088
173.30000000000175,23.858066226553422,-0.6805723963764237,-0.010433283379220448
174.20000000000175,23.943330554211958,-0.6768587195968565,-0.011819615311986276
175.10000000000178,24.029041572500876,-0.6745147381678915,-0.011759976021791019
176.0000000000018,24.113479988597398,-0.6714586494628858,-0.011760003469690972
176.9000000000018,24.19808883713778,-0.6665335368015407,-0.012420894026509366
177.80000000000183,24.28303644505453,-0.6649746127907186,-0.013108669164181741
178.70000000000184,24.367389716378376,-0.6624919753871767,-0.012750468265172898
179.60000000000184,24.45225076528418,-0.6592476983602819,-0.012654041781686054
180.50000000000185,24.537872334287695,-0.6539759470011146,-0.012740167944553349
181.40000000000185,24.62273990742721,-0.6509639559347572,-0.012740167999939267
182.3000000000019,24.706879291119627,-0.6493690752711005,-0.012740164508761254
183.2000000000019,24.793177603648015,-0.6465341471580264,-0.013782648014324828
184.1000000000019,24.87664584372195,-0.6436232433675446,-0.013720985413966602
185.00000000000193,24.96083000000019,-0.6399999999999967,-0.013070004268670665
185.90000000000194,25.04656767362328,-0.6375668563885059,-0.013070664828207512
186.80000000000194,25.129660773543783,-0.6343830789225897,-0.014096716840189316
187.70000000000195,25.215352475028762,-0.6317095856951542,-0.012766169344310185
188.60000000000196,25.29970811607443,-0.627584319440929,-0.014059639195143525
189.500000000002,25.384743661129008,-0.6237529853968711,-0.012693480893646303
190.400000000002,25.468614016680043,-0.6205019525836801,-0.012750115180091726
191.300000000002,25.55454838336196,-0.6174651072327517,-0.012751787233174383
192.20000000000203,25.63921175768404,-0.6144514267915332,-0.014060193810434107
193.10000000000204,25.72168334810788,-0.6120631260310891,-0.014060114057323325
194.00000000000205,25.807742496628315,-0.6092169557262642,-0.01387229424606673
194.90000000000205,25.89284934480268,-0.6066380509530028,-0.014059956799209239
195.80000000000206,25.975777755822936,-0.6040231429719299,-0.014059947588580535
196.7000000000021,26.06119071544116,-0.6018128233835407,-0.014063615652135653
197.6000000000021,26.145658737512537,-0.5986541720673586,-0.012740254473689205
198.5000000000021,26.230287520894493,-0.5948262979132676,-0.013768285543535264
199.40000000000214,26.315079736556424,-0.5929117475653825,-0.013730185275188767
200.30000000000214,26.398808463419734,-0.5899471700845211,-0.01376524302707871
201.20000000000215,26.48409462276852,-0.5863570468111134,-0.013900216771515872
202.10000000000215,26.568007462087703,-0.5829834917014349,-0.013410178869036393
203.00000000000216,26.651408955268533,-0.5820519069276504,-0.014065441153209512
203.9000000000022,26.73699794950786,-0.5783003114059507,-0.012750041980355675
204.8000000000022,26.820533711780516,-0.5758193343645525,-0.014048285345573674
205.7000000000022,26.905941412844136,-0.572675469476036,-0.0140598957978888
206.60000000000224,26.990828776829225,-0.568950103115615,-0.014058326050725434
207.50000000000225,27.07499982908419,-0.566128596099748,-0.014060193478280247
208.40000000000225,27.1594937736948,-0.5634670551937231,-0.01406013000110562
209.30000000000226,27.24445963677482,-0.5612565470683527,-0.014060130696050166
210.20000000000226,27.32848724084372,-0.5585917666571784,-0.014057533850837522
211.1000000000023,27.413801564317907,-0.5561423231066458,-0.014389255202516438
212.0000000000023,27.497803217050915,-0.5516720777557357,-0.014388837077966343
212.9000000000023,27.58244706822943,-0.5490984093546918,-0.01570105799485244
213.80000000000234,27.666925718225205,-0.546461614638805,-0.015369806825836996
214.70000000000235,27.7509247440152,-0.5437933214735112,-0.014084446667124162
215.60000000000235,27.835654857826178,-0.5410099929288937,-0.015205347306180172
216.50000000000236,27.920919605427805,-0.5380844968943654,-0.014384069062959526
217.40000000000236,28.005253902088633,-0.5336160228344471,-0.014059743194947849
218.3000000000024,28.090162761333787,-0.5317684534153555,-0.014698549654595716
219.2000000000024,28.175179443949286,-0.5283043416868414,-0.015049849480384125
220.1000000000024,28.259625281044666,-0.5258709766485388,-0.015049843999406676
221.00000000000244,28.34458973362796,-0.5234523405966206,-0.015049927416272979
221.90000000000245,28.427961346516263,-0.5229528950294722,-0.013745805670302147
222.80000000000246,28.51291050741342,-0.5204904633388111,-0.013730077888338243
223.70000000000246,28.59832630222664,-0.5175831637367719,-0.013729736909900758
224.60000000000247,28.681885061316542,-0.5149046671902782,-0.014060278069692345
225.5000000000025,28.76853125657166,-0.5123066915172805,-0.015437356956672588
226.4000000000025,28.853387926797698,-0.5105781928077489,-0.015380216585353601
227.3000000000025,28.93720411841329,-0.5087292634782323,-0.014065021565689229
228.20000000000255,29.022783123948308,-0.5063427336029286,-0.015050475532772722
229.10000000000255,29.108337149239237,-0.5033046903149773,-0.01667675276883429
230.00000000000256,29.19017609771133,-0.5005022569619226,-0.016428352760372356
230.90000000000256,29.277431547486916,-0.4980455617360758,-0.015379927257952453
231.80000000000257,29.362372334075328,-0.49594650477526986,-0.016482074662736323
232.7000000000026,29.446383948970116,-0.49295872855599177,-0.016700077165672234
233.6000000000026,29.531881739304765,-0.4907179840756939,-0.018122873841230458
234.50000000000261,29.617555871878114,-0.4877189539731435,-0.016690450618891184
235.40000000000265,29.70203443044964,-0.486528740236893,-0.016689876941360815
236.30000000000265,29.785940205415155,-0.4838353873475489,-0.018007199653238715
237.20000000000266,29.871632358383675,-0.48209924808432536,-0.01800991014534148
238.10000000000267,29.95696538853908,-0.4821645827827971,-0.01800991000000174
239.00000000000267,30.042367637504885,-0.4778034984197178,-0.018009909988008665
239.9000000000027,30.125938860029915,-0.47659670750807037,-0.018009488730584167
240.8000000000027,30.21238377716547,-0.47555878193267526,-0.019330252403149117
241.70000000000272,30.29801366808588,-0.4715920805091536,-0.01800995245702186
242.60000000000275,30.380348850501157,-0.4685015440633985,-0.018025296928830592
243.50000000000276,30.467758433227612,-0.466035510084825,-0.01932991758090985
244.40000000000276,30.553772262439793,-0.4635178414689299,-0.01938618561328287
245.30000000000277,30.63752391449556,-0.4602129518604473,-0.020649930596922328
246.20000000000277,30.72373769888578,-0.4598844371903918,-0.02184465746874409
247.1000000000028,30.807221308478024,-0.45678284165165056,-0.020147964673037144
248.0000000000028,30.89416742111617,-0.45496162512339955,-0.019989908908114806
248.90000000000282,30.9795535047478,-0.45465057369565354,-0.01998837060299774
249.80000000000285,31.064100699782912,-0.45189839026860057,-0.021644902373669783
250.70000000000286,31.149925608027104,-0.4491197309780125,-0.021639951994940176
251.60000000000286,31.235970911893606,-0.4481360861257684,-0.021639873675659338
252.50000000000287,31.321346184284458,-0.4443936871028308,-0.021629045112049994
253.40000000000288,31.405650136695826,-0.4430822432015743,-0.021630186002041363
254.3000000000029,31.492285697760476,-0.43985702492665535,-0.0216302170739886
255.20000000000292,31.576126053773407,-0.43788921416595666,-0.024394964331444502
256.1000000000029,31.66175998008619,-0.43490198219060905,-0.02526358511263238
257.00000000000296,31.746945712766546,-0.43281873648088864,-0.025164004746404345
257.90000000000293,31.833249469424967,-0.4311090673760552,-0.025171474627692092
258.80000000000297,31.918457026487772,-0.42814479157630103,-0.025525093825094824
259.700000000003,32.003247828384495,-0.4263106242872223,-0.025919604169892807
260.600000000003,32.08932186888682,-0.4230385931085626,-0.026569699916279
261.500000000003,32.174656793651785,-0.42174634534847405,-0.026569909967638417
262.40000000000305,32.25860061074405,-0.42004775666040944,-0.02656990999999831
263.300000000003,32.34555585913427,-0.41765919638716553,-0.026569909999999197
264.20000000000306,32.430356254474994,-0.41595437743099334,-0.02656990999999831
265.1000000000031,32.51612079906641,-0.41265897340854707,-0.026569909999999197
266.00000000000307,32.6017141488544,-0.4120336059730252,-0.026569910000187047
266.90000000000305,32.687512287403486,-0.4082700167439175,-0.02656996330587269
267.8000000000031,32.77175436600796,-0.40767691422731894,-0.026902138835260825
268.7000000000031,32.858362923058294,-0.40479199219240874,-0.02689991002137626
269.6000000000031,32.94254298301012,-0.4025929952187481,-0.026899908179222276
270.5000000000031,33.028594551007444,-0.4002847529973236,-0.026852457693493204
271.40000000000316,33.11380367562934,-0.3999839513989569,-0.027889900236623966
272.30000000000314,33.19900054858384,-0.3975464366570839,-0.027889927572869677
273.2000000000032,33.28479990538449,-0.39394938935216617,-0.02875232640888914
274.1000000000032,33.36950567422348,-0.3925650268944023,-0.029209909166587167
275.0000000000032,33.45595357403518,-0.3899891033171191,-0.02789949351083454
275.9000000000032,33.54228354994013,-0.3865026591036676,-0.029216006470967226
276.80000000000325,33.627020975734325,-0.38399297653080666,-0.03053034484269146
277.70000000000323,33.71294785678427,-0.38079848106712744,-0.02938359594774509
278.60000000000326,33.796501875932655,-0.38143746734117634,-0.029214974896942802
279.5000000000033,33.883267396131764,-0.3795243778030298,-0.027889968059592096
280.4000000000033,33.968331388621316,-0.37818207074172827,-0.027889661905694307
281.30000000000325,34.05433269107089,-0.37585404736590594,-0.02921141301767527
282.2000000000033,34.139111087776016,-0.3744205356284837,-0.0305299485093542
283.1000000000033,34.22527121904377,-0.3718880906816452,-0.030529909421871615
284.0000000000033,34.311139870175225,-0.36908506640159006,-0.030523947470122437
284.90000000000333,34.39742720671154,-0.3688886503752226,-0.029837033098254473
285.80000000000337,34.48135268187528,-0.36637229540901756,-0.031186652531517645
286.70000000000334,34.56878125359016,-0.3644606054761976,-0.03256954255284317
287.6000000000034,34.6536743562959,-0.36203259125893716,-0.029819176025977168
288.5000000000034,34.74034602441184,-0.36065033512279654,-0.032510371316078146
289.4000000000034,34.82619815948433,-0.35790151837834805,-0.033934831712037816
290.3000000000034,34.9119907178588,-0.3558233939600403,-0.03327521427735114
291.20000000000346,34.99633937416798,-0.354008597510483,-0.031203408326898163
292.10000000000343,35.08326771628579,-0.35189169665026265,-0.03249994250717547
293.00000000000347,35.168006276883105,-0.34996175519386385,-0.03258659878040371
293.9000000000035,35.25431468226721,-0.346704309419598,-0.032510091756584814
294.8000000000035,35.341022504598406,-0.3438444773267442,-0.03250800696478473
295.70000000000346,35.42534425909746,-0.3407435311610221,-0.033820309593980635
296.6000000000035,35.51211952340899,-0.33888872974260026,-0.03273251789211784
297.5000000000035,35.59550285957038,-0.33705112091417516,-0.03249514711897472
298.4000000000035,35.68265307875515,-0.3336890484574395,-0.033833045370269765
299.30000000000354,35.76838704927234,-0.3333348850281785,-0.03481219732186025
300.20000000000357,35.85446696611347,-0.32948547698417946,-0.034809847374442704
301.10000000000355,35.93899208803723,-0.32677365864390995,-0.0354098977943047
302.0000000000036,36.02602662773838,-0.3244557932243662,-0.03747451529889734
302.9000000000036,36.10983783476903,-0.32215039573890164,-0.03743996185236176
303.8000000000036,36.19803411936869,-0.31920330685580234,-0.037430305706407374
304.7000000000036,36.283763203244966,-0.3158292136033511,-0.038429991458211354
305.60000000000366,36.369965085034,-0.3150228702623427,-0.03842996199997728
306.50000000000364,36.45632948189993,-0.3113116316065095,-0.038430005383997656
307.4000000000037,36.54146583765539,-0.3089928356585652,-0.03876060988783303
308.30000000000365,36.62800529324147,-0.304117159334857,-0.04008354662003022
309.2000000000037,36.71356197162127,-0.30229712544290216,-0.04008013068109362
310.1000000000037,36.79939675640081,-0.29768069371536204,-0.04008796250507718
311.0000000000037,36.88533499994424,-0.2968784317073272,-0.041145311335454515
311.90000000000373,36.97092867621992,-0.2927952002266416,-0.0423883144027104
312.8000000000037,37.05746083394525,-0.28954974888963014,-0.042713431234524535
313.70000000000374,37.1426926410237,-0.28626487741402784,-0.042720309171746074
314.6000000000038,37.230278719998026,-0.2837759711662927,-0.04371189987402646
315.50000000000375,37.31578728399472,-0.2815182350457787,-0.045019945680048856
316.4000000000038,37.40123539923815,-0.279047156448051,-0.04501998416392183
317.3000000000038,37.48789542625456,-0.2747089423711382,-0.04533533232032161
318.2000000000038,37.57474197948765,-0.27123082755185035,-0.04534995552555143
319.10000000000383,37.660829089217486,-0.268070062209272,-0.046339870716528786
320.00000000000387,37.74647880962424,-0.264653781810072,-0.04799050660705095
320.90000000000384,37.833741290703934,-0.2628564708503916,-0.04866091535644124
321.8000000000039,37.919096562263654,-0.25770657243796957,-0.04915025804624751
322.70000000000385,38.006735884252365,-0.2541487115915097,-0.04995999572792176
323.6000000000039,38.092229251612906,-0.25149261058002054,-0.04995071095982384
324.5000000000039,38.17701521439035,-0.2481377547966056,-0.05257801152690922
325.4000000000039,38.26427246623323,-0.24601029905493446,-0.05512040195023493
326.30000000000393,38.35049248495232,-0.24337584046405858,-0.05652911526642068
327.2000000000039,38.434528871528975,-0.24208439177250204,-0.05773998301043237
328.10000000000394,38.52263617023072,-0.23948746906246351,-0.05785998640201662
329.000000000004,38.60991826899138,-0.2391705853400713,-0.05811626202505149
329.90000000000396,38.69551746338723,-0.2370036994366772,-0.06059666114055906
330.800000000004,38.782457050743695,-0.2339631192885998,-0.0632248943134126
331.700000000004,38.868371380848586,-0.23140219019248348,-0.0658603704842986
332.600000000004,38.95434721292248,-0.2313000808663355,-0.0658654936490568
333.50000000000404,39.0404684338218,-0.2302022377443133,-0.06719237060234162
334.40000000000407,39.12744562877393,-0.22822759907601395,-0.06947816214513436
335.30000000000405,39.21339368764109,-0.22758591051424387,-0.0711360569590882
336.2000000000041,39.30020274703469,-0.22659617222081577,-0.07246783383182587
337.10000000000406,39.38662392889031,-0.2267939719212621,-0.07404010393157279
338.0000000000041,39.47357106925801,-0.22570744799744374,-0.07848481353565262
338.9000000000041,39.560034908923825,-0.2251222462150422,-0.07998519439135254
339.8000000000041,39.645895485471264,-0.22491395491634156,-0.08101429456641096
340.70000000000414,39.73246836195556,-0.22432615931755293,-0.08589597123367287
341.6000000000041,39.81853694913248,-0.22622627867509476,-0.08814386859213519
342.50000000000415,39.905299472594024,-0.2255072183849403,-0.09068641678052902
343.4000000000042,39.992105553086844,-0.2262112353205135,-0.09347563500381195
344.30000000000416,40.07967966189801,-0.2267794113407195,-0.09606968178802733
345.2000000000042,40.1626782524972,-0.22749950872504943,-0.09698503304346584
346.10000000000423,40.25173387959084,-0.2289578362323905,-0.10039602105991108
347.0000000000042,40.33871524836087,-0.22734878028200634,-0.10163428544002917
347.90000000000424,40.4229856553854,-0.22797113963556367,-0.10426731951867696
348.8000000000043,40.51116260641943,-0.22554040041309178,-0.10695551281796511
349.70000000000425,40.598826662018,-0.22712693124225808,-0.11132316737359016
350.6000000000043,40.685495983645815,-0.22602268310344706,-0.1141702686941577
351.50000000000426,40.77252775327114,-0.2264580865014039,-0.11547101055380837
352.4000000000043,40.85873787604725,-0.22603355248896537,-0.11680461246259632
353.30000000000433,40.94596477626397,-0.22359206473585794,-0.12066592316561797
354.2000000000043,41.03275093061182,-0.22314075796423954,-0.1220879091121283
355.10000000000434,41.116817949630246,-0.222937249503501,-0.12352036303854552
356.0000000000043,41.205917793839696,-0.22106275486307977,-0.12588550899345652
356.90000000000435,41.292311910262256,-0.2196170474381407,-0.12883521136835618
357.8000000000044,41.37940488107079,-0.21895537526590467,-0.1313611119502207
358.70000000000437,41.46565823641374,-0.22006672141978584,-0.13276706504025437
359.6000000000044,41.55321970175199,-0.21702724732068596,-0.13534914191464997
360.50000000000443,41.6405372978536,-0.21748854285998387,-0.13667573885214157
361.4000000000044,41.72649667556157,-0.21473568859174003,-0.13854337919351067
362.30000000000445,41.81334574086544,-0.2146685344383423,-0.1406449604284754
363.2000000000045,41.90032708377566,-0.21296830248201545,-0.14196063310849327
364.10000000000446,41.98754049807647,-0.21108125813577544,-0.1432808355848354
365.0000000000045,42.07398646558803,-0.20897310543903844,-0.14727030494965287
365.90000000000447,42.16148819092988,-0.20674794587931933,-0.14827183251759157
366.8000000000045,42.24821429294387,-0.20589598897186287,-0.14850016383025144
367.70000000000454,42.33481706616233,-0.20628133128781367,-0.14986671835164156
368.6000000000045,42.4220990836903,-0.2051937118693238,-0.15118018765813845
369.50000000000455,42.50958444562685,-0.20399134653020634,-0.15173826528068401
370.4000000000045,42.596460590537625,-0.20155475253512364,-0.15251783991629253
371.30000000000456,42.68186794401677,-0.20087333714609476,-0.15587873664343688
372.2000000000046,42.76996466417251,-0.1985893433256479,-0.15772067410785606
373.10000000000457,42.85731338231576,-0.19680246804943663,-0.15908015446064017
374.0000000000046,42.94363297352057,-0.194341761018102,-0.15900090020811586
374.90000000000464,43.03092687985586,-0.19184666785348997,-0.16171026673735156
375.8000000000046,43.117602510758346,-0.18925521291357864,-0.16305813524606538
376.70000000000465,43.20395097901684,-0.18644967783684022,-0.16200509465584245
377.6000000000047,43.2928237602772,-0.18606981148307922,-0.1634214842478281
378.50000000000466,43.37942715797692,-0.18359001325719124,-0.16337009699014526
379.4000000000047,43.46625276658929,-0.1817287998163076,-0.16526502342750105
380.3000000000047,43.5539832894308,-0.17896855619389399,-0.16567016966373194
381.2000000000047,43.64170275003423,-0.17817008334250523,-0.16633258298028153
382.10000000000474,43.72760281993365,-0.17698896156187519,-0.16633312677974033
383.0000000000047,43.81584304276286,-0.17524761057239335,-0.16762792450781205
383.90000000000475,43.90324058239203,-0.17236628161966147,-0.16763997792897944
384.80000000000473,43.990624620342025,-0.1719121636673861,-0.16763855587292342
385.70000000000476,44.07731420220794,-0.1710149176421542,-0.170259454192772
386.6000000000048,44.16496640002599,-0.16673546846647477,-0.17038652525800035
387.5000000000048,44.25224776293296,-0.1658656752662327,-0.17233351214876036
388.4000000000048,44.3396570406785,-0.1657103162936174,-0.17159003122994232
389.30000000000484,44.426197337698554,-0.1624600654376414,-0.17267026932420304
390.2000000000048,44.51454812147321,-0.16140134344396856,-0.17288413874103803
391.10000000000485,44.60123053694201,-0.15917713266115466,-0.1742299689938802
392.0000000000049,44.68965126658802,-0.1575961385932493,-0.17422996400012147
392.90000000000487,44.776461943625456,-0.15436048569601774,-0.17422996440616956
393.8000000000049,44.862570234339216,-0.15293275901407688,-0.17473036948528664
394.7000000000049,44.9509365550027,-0.1503972703889905,-0.17621014559187032
395.6000000000049,45.03840428731878,-0.14768902775184117,-0.1775201857886235
396.50000000000495,45.125410021861,-0.14541098948516334,-0.1762095445340135
397.4000000000049,45.21307962708326,-0.1449716438482916,-0.17638598964859042
398.30000000000496,45.297685817599444,-0.1423648560544005,-0.17883711379390066
399.20000000000493,45.38799652206086,-0.13911318259293692,-0.18016035153475363
400.10000000000497,45.475070968208364,-0.13819164302627931,-0.18145461892020354
401.000000000005,45.56354859972059,-0.1356965605538855,-0.1814928233264963
401.900000000005,45.64998532133432,-0.1344783188229347,-0.18278852550583125
402.800000000005,45.73722697617672,-0.13136998757058976,-0.18410938285784084
403.70000000000505,45.82703138344666,-0.1277692327348223,-0.18543034215906795
404.600000000005,45.9139495998075,-0.12638569294999658,-0.18543046305915034
405.50000000000506,46.00201940709069,-0.1245453120002476,-0.18408082074620324
406.4000000000051,46.08951307066225,-0.12064935540598756,-0.18603919717081974
407.30000000000507,46.17775179525349,-0.11878539101750615,-0.18706343234616662
408.2000000000051,46.265944570151426,-0.11576623987128025,-0.18845918430384945
409.1000000000051,46.353022398283585,-0.11393964577306444,-0.1880520603443574
410.0000000000051,46.43974480410383,-0.11142440154598351,-0.19093530699374472
410.90000000000515,46.5287324217,-0.10933558719137117,-0.19331972877005832
411.8000000000051,46.616423952799416,-0.10622383480758972,-0.19386145894060913
412.70000000000516,46.70335267088434,-0.10429567461022701,-0.19465142720334994
413.60000000000514,46.791221577778295,-0.10596943811992184,-0.19596961270676205
414.5000000000052,46.87947807929579,-0.10440859531375084,-0.19861473102220462
415.4000000000052,46.966387756020346,-0.1033072383876468,-0.2000047940325369
416.3000000000052,47.055036867344704,-0.10250108245317088,-0.1999173030321395
417.2000000000052,47.14198031295741,-0.1029170947219524,-0.2002613617146629
418.10000000000525,47.23082904105811,-0.10071007414068693,-0.20289011061675177
419.00000000000523,47.31497604803783,-0.10093523740733776,-0.20365075639105834
419.90000000000526,47.40447421934923,-0.10242425330556665,-0.20545347477191855
420.8000000000053,47.49378518681494,-0.10256924515677919,-0.20686140247065854
421.7000000000053,47.580925530682435,-0.1027917230845403,-0.20815019547212632
422.6000000000053,47.668875316382696,-0.10453710735802912,-0.2081016653870158
423.5000000000053,47.75793310124541,-0.10430987592305184,-0.2094641130915429
424.4000000000053,47.84411976055612,-0.10475595123196692,-0.21081040975266152
425.30000000000535,47.932633250191365,-0.10553658074456444,-0.21291760382596792
426.20000000000533,48.020608132090466,-0.10493928329694446,-0.2134200138229847
427.10000000000537,48.10864066396755,-0.10338020491366731,-0.2134200122785268
428.00000000000534,48.19641442043635,-0.10356892841812035,-0.21482483554927523
428.9000000000054,48.28462821642521,-0.1020562043447751,-0.2160576071873468
429.8000000000054,48.371889699706955,-0.10048784157794792,-0.21605994967095832
430.7000000000054,48.460413115916,-0.09951431216637523,-0.21738629060511538
431.6000000000054,48.54833800326896,-0.09906120922775406,-0.21782977893498767
432.50000000000546,48.63571286287034,-0.09698929625553146,-0.2186858054597316
433.40000000000543,48.72345818344601,-0.09397882570585263,-0.2200075898705407
434.30000000000547,48.81146172998252,-0.09390493612315307,-0.22133024818975144
435.2000000000055,48.900084754713625,-0.09282378035388461,-0.22133017001768351
436.1000000000055,48.98747411719855,-0.09112090922867147,-0.22263075353670336
437.0000000000055,49.07556516760776,-0.09042923866326619,-0.22468849231880483
437.9000000000055,49.16462590167527,-0.08975738316529011,-0.22496399469722883
438.8000000000055,49.252436163649705,-0.0880795343430154,-0.22594016221112767
439.70000000000556,49.340356671293605,-0.08639412052777955,-0.22593155060371473
440.60000000000554,49.427591203885484,-0.08417334970864924,-0.22758886964883196
441.50000000000557,49.5163096060659,-0.08288489891438895,-0.2276152559946909
442.40000000000555,49.60491241269949,-0.0822750790449425,-0.23029504063532702
443.3000000000056,49.693616984331804,-0.08234567394831588,-0.23223049944913265
444.2000000000056,49.78206455009211,-0.07897596442360748,-0.23330228914325346
445.1000000000056,49.869642266954834,-0.07814624957444484,-0.23329958119243566
446.0000000000056,49.95777082277081,-0.07603751576327641,-0.23460722573088066
446.90000000000566,50.0464639968883,-0.07377218502990489,-0.23595179950240475
447.80000000000564,50.13402548746191,-0.07318407308907397,-0.23659023007425883
448.7000000000057,50.22278906659309,-0.07071663822519356,-0.2379106121761838
449.6000000000057,50.31082898841933,-0.06877580071271334,-0.23821018466805244
450.5000000000057,50.39780678641343,-0.06708174566321726,-0.2418925492716606
451.4000000000057,50.487382342654065,-0.06589743400373485,-0.24317497318033876
452.3000000000057,50.57670793860863,-0.06346708185549008,-0.2431811483645916
453.20000000000573,50.664109210572455,-0.06337997331152131,-0.24316552931332414
454.10000000000576,50.752660668035986,-0.06066031676135454,-0.24268748444111754
455.00000000000574,50.84122621783909,-0.0601080727037796,-0.24584063675740486
455.9000000000058,50.93023653554743,-0.05604156927558773,-0.24745960516513232
456.80000000000575,51.018319196497266,-0.05437977600753951,-0.24879576809657866
457.7000000000058,51.10742068011612,-0.05390136874367747,-0.2500947004191163
458.6000000000058,51.19348690988557,-0.051637986637567676,-0.25140967636774025
459.5000000000058,51.2830720469951,-0.050256944695842826,-0.25270457794867607
460.40000000000583,51.37131290996538,-0.04745822439001158,-0.2544127314428817
461.30000000000587,51.45995083134678,-0.04610364236619953,-0.2563584572028592
462.20000000000584,51.54979904348842,-0.04567448983002562,-0.2563549317540259
463.1000000000059,51.637028626294835,-0.04259370098905942,-0.25762204288358426
464.0000000000059,51.72571605262113,-0.042100049105671965,-0.2594397336936298
464.9000000000059,51.81448395402729,-0.0400298726499486,-0.2615286868267601
465.8000000000059,51.90235516736042,-0.039294180910703774,-0.2629392244746418
466.7000000000059,51.9911357916667,-0.037911467698088994,-0.26426950282920725
467.60000000000593,52.079213932356545,-0.03580388744932058,-0.2668999442979918
468.50000000000597,52.16815186628115,-0.03509338275911198,-0.26731914814843183
469.40000000000595,52.25725251720233,-0.03524672867041936,-0.26814470931014434
470.300000000006,52.34490873942057,-0.033099313957441645,-0.26914049029732867
471.20000000000596,52.43329668806561,-0.031182047348108168,-0.27216552530259497
472.100000000006,52.52172899026877,-0.030173056817118352,-0.27214970878572897
473.000000000006,52.610217723184306,-0.02670936296319698,-0.27480501560074666
473.900000000006,52.698924189642455,-0.023626631811987292,-0.2749943256872238
474.80000000000604,52.78500984423063,-0.023719876758350997,-0.2749220642639272
475.70000000000607,52.876028379333896,-0.024771853737098923,-0.2747716558300102
476.60000000000605,52.96364717611426,-0.02363874938183057,-0.27885990391084725
477.5000000000061,53.050830000000666,-0.02303302000000066,-0.28018012178591434
478.4000000000061,53.140725599771436,-0.020706045722081373,-0.2814982497128802
479.3000000000061,53.22808840162408,-0.01913299089788923,-0.2814956916118856
480.2000000000061,53.31769571302309,-0.0181838862392233,-0.28413135876679574
481.1000000000061,53.405341347366786,-0.01745192662004162,-0.28413746504611614
482.00000000000614,53.49475071112485,-0.014162226135829134,-0.2841303223548044
482.9000000000062,53.58239233210823,-0.01525015687227152,-0.2855933149472052
483.80000000000615,53.6715761212705,-0.01344129590185196,-0.2864300585876767
484.7000000000062,53.75955353731736,-0.014644987204044274,-0.2876642562971057
485.60000000000616,53.84815553138383,-0.012938608631369057,-0.28775734477809056
486.5000000000062,53.935955680938896,-0.013444675060917075,-0.2867647332044365
487.40000000000623,54.023411597176235,-0.014102078107298624,-0.28808026023063826
488.3000000000062,54.11360452751537,-0.01366341043489018,-0.2893868083094975
489.20000000000624,54.202817844773776,-0.011982679318051286,-0.29072018865738425
490.1000000000063,54.288784042471704,-0.011661527611845862,-0.29072015721002664
491.00000000000625,54.37907886718918,-0.011292620725952343,-0.29205806094911857
491.9000000000063,54.468133634721845,-0.012010500698222064,-0.29202987566012384
492.8000000000063,54.555925772165686,-0.011750576263302252,-0.29202957149050723
493.7000000000063,54.645411759449026,-0.010328364990015671,-0.29103988178272777
494.60000000000633,54.73347004664305,-0.008736245550620367,-0.2923656067074658
495.5000000000063,54.82252306996722,-0.008248214076808692,-0.2933483986569052
496.40000000000634,54.91208042054792,-0.0062007998189237004,-0.2933502251564537
497.3000000000064,54.99971594437262,-0.00199552454718458,-0.2946527925013678
498.20000000000636,55.08824654097667,0.004117668477015026,-0.29235980471427503
499.1000000000064,55.17695671117029,0.006768001347138852,-0.2935352477481219
500.00000000000637,55.26551647533137,0.008390358643486896,-0.2936798257662656
500.9000000000064,55.35435471888419,0.010025711663678492,-0.29436888494479696
501.80000000000643,55.44113226657279,0.008658989429444632,-0.29498992840570315
502.7000000000064,55.53268572071136,0.008166251089282926,-0.2949899280175807
503.60000000000645,55.62133941615035,0.0072154109949297066,-0.2949893901862617
504.5000000000065,55.71005582745217,0.006573488771501073,-0.2963100671253418
505.40000000000646,55.798619735810796,0.004527722129589046,-0.2963100914589196
506.3000000000065,55.88662166232596,0.00398961524138805,-0.29755523861832245
507.2000000000065,55.97597590059848,0.0009269257130672028,-0.2966396847576296
508.1000000000065,56.06546971226617,-0.00025973346691567306,-0.2966398590263464
509.00000000000654,56.153814150807555,-0.0017147642729622172,-0.2962732410207929
509.9000000000065,56.24322686976164,-0.003099568899303222,-0.29762982035774677
510.80000000000655,56.33274129710052,-0.004190530837717294,-0.297629820000179
511.7000000000066,56.420642939350756,-0.006543790462519581,-0.29763008067177443
512.6000000000065,56.510167046831754,-0.010235663700206838,-0.29630910470779037
513.5000000000066,56.599732085060765,-0.01142209510252968,-0.2989497972865922
514.4000000000066,56.6879546978801,-0.012453097912085159,-0.2992530935248574
515.3000000000065,56.77648964176856,-0.01506028730875152,-0.2979600483683864
516.2000000000066,56.865366280421206,-0.01775826626533051,-0.29796003069417054
517.1000000000066,56.95603827844477,-0.018430139888786654,-0.2978516240608129
518.0000000000066,57.044573637903405,-0.01980209771540078,-0.2989507425005371
518.9000000000067,57.133541004411434,-0.020753223130892305,-0.3012201266768382
519.8000000000067,57.22263697978559,-0.021969335271847266,-0.29908769369013033
520.7000000000066,57.31244641885628,-0.02417698584813612,-0.298619828414338
521.6000000000067,57.4020136100034,-0.023259007088069814,-0.2982694407778368
522.5000000000067,57.49008839321317,-0.023737303140718785,-0.298290190648804
523.4000000000067,57.57935517895353,-0.025646142283497927,-0.2989542961138132
524.3000000000068,57.66993965741479,-0.02719708093585855,-0.3008806830556967
525.2000000000068,57.75981441374498,-0.02851667684816085,-0.3009199563424647
526.1000000000067,57.84921101276619,-0.029441847884017425,-0.30090455581199604
527.0000000000068,57.938463849064,-0.03234979014577695,-0.30224027668992015
527.9000000000068,58.02784352350221,-0.033814841286704644,-0.30224503154221916
528.8000000000068,58.11700481475541,-0.03521246537249373,-0.30126003513460775
529.7000000000069,58.20644302790013,-0.035863872424180696,-0.30126012400650737
530.6000000000068,58.29531190001124,-0.03882526463101792,-0.30125445851096266
531.5000000000068,58.38361620113687,-0.039256389683219865,-0.30389067146095083
532.4000000000069,58.474014918184075,-0.03908799706975734,-0.30388992182724195
533.3000000000069,58.56321145379752,-0.0406704169655345,-0.3025699489818452
534.2000000000069,58.65010543393957,-0.040284445003002434,-0.30391078378752523
535.100000000007,58.74222248893587,-0.04037852197462203,-0.30299972859170454
536.0000000000069,58.831481205224144,-0.04027172687530111,-0.302239997427443
536.9000000000069,58.920618927854235,-0.04034705654922005,-0.30223996599977276
537.800000000007,59.00889768759215,-0.04101049308588584,-0.302239966031864
538.7000000000069,59.099095924870255,-0.03816000226370621,-0.30223480176752693
539.600000000007,59.18856125433585,-0.039892322085757013,-0.30158822763450077
540.500000000007,59.27681701974061,-0.036705733115831723,-0.3019095624800472
541.4000000000069,59.36692414958358,-0.03533636951093752,-0.3045277315500998
542.300000000007,59.45624405542404,-0.03388553127826285,-0.30363636620979007
543.200000000007,59.54537061074734,-0.033781084457556114,-0.30322999846086773
544.100000000007,59.635361869823655,-0.03282678787036124,-0.3019379419879078
545.000000000007,59.72387299102875,-0.031147038745595358,-0.30191003104123215
545.900000000007,59.81455965229163,-0.03043433789608467,-0.303899298570649
546.800000000007,59.90300544369029,-0.028018615180196788,-0.30389017596099865
547.7000000000071,59.992770218415096,-0.024944072734597,-0.3038901759898933
548.6000000000071,60.08167229443844,-0.023892903057831108,-0.30389184454717766
549.500000000007,60.17180856554386,-0.021498253815558276,-0.3025700726511604
550.4000000000071,60.2611283475213,-0.020188464436183357,-0.3039034357072037
551.3000000000071,60.35136178171638,-0.016933295854438247,-0.30521115373516716
552.2000000000071,60.439154502707126,-0.014073407182899369,-0.3060576242632238
553.1000000000072,60.5298621101466,-0.012831775066877115,-0.30653215388911725
554.0000000000072,60.61879417046962,-0.010926045149508744,-0.3039378929565828
554.9000000000071,60.70905128807523,-0.007639293001115971,-0.30516539142150023
555.8000000000072,60.79849414710808,-0.00847748646259137,-0.30520993674732155
556.7000000000072,60.88793445618457,-0.004690736483712116,-0.3052099343592265
557.6000000000072,60.97708484011932,-0.0028144612698273066,-0.3038806125581397
558.5000000000073,61.06663034421942,-0.0011122423470384755,-0.30488080667322626
559.4000000000073,61.155894335207705,0.0028172915906139085,-0.3051189239323371
560.3000000000072,61.2453361195493,0.003845660565986351,-0.3065198251217933
561.2000000000073,61.335150508552836,0.0060342651443324935,-0.3058665800393996
562.1000000000073,61.425326909563545,0.00719002379481682,-0.3052137101254724
563.0000000000073,61.513812006458004,0.011148943234987165,-0.3052060642671095
563.9000000000073,61.60314286342642,0.011758286787309207,-0.3051917290317028
564.8000000000073,61.693527075449396,0.013168246858902336,-0.30389047581588846
565.7000000000073,61.78227577733509,0.014590270390371154,-0.30520395895366637
566.6000000000073,61.87281449026798,0.01615851404267838,-0.3038897922291568
567.5000000000074,61.9614201924962,0.01646288041453111,-0.3038898261534766
568.4000000000074,62.051125737934626,0.01983128630582194,-0.30389224313869123
569.3000000000073,62.14083097131457,0.02062330303516701,-0.30421982011942816
570.2000000000074,62.2311319519469,0.02168662109545648,-0.304472205217142
571.1000000000074,62.319793119084636,0.023924023526860703,-0.304219994477287
572.0000000000074,62.40912210380912,0.025906164668902696,-0.3042197642908757
572.9000000000075,62.499848893144765,0.026679376119892614,-0.3055402574770838
573.8000000000075,62.58891681042098,0.026688994590291133,-0.30554019115528597
574.7000000000074,62.678740480268225,0.02903340883959961,-0.30421852816524364
575.6000000000074,62.76925332516876,0.029567512945152235,-0.3015778349476874
576.5000000000075,62.85956452062208,0.029977469408748243,-0.3042323078238858
577.4000000000075,62.94835637562059,0.03290701616296273,-0.3055402695493732
578.3000000000075,63.0382962619757,0.03614589374121903,-0.30685860199873183
579.2000000000075,63.128967046309604,0.035006671024598236,-0.30685997725483816
580.1000000000075,63.21829308552971,0.037117160195133586,-0.3055368717521949
581.0000000000075,63.306397889774566,0.03770477890683228,-0.3068583820786581
581.9000000000076,63.39916430367166,0.03997301171808509,-0.30553995577715254
582.8000000000076,63.48830044766433,0.04081989482089598,-0.30553659426036806
583.7000000000075,63.57829445613728,0.042147375530512426,-0.30619990915012485
584.6000000000076,63.66896733439492,0.04490750330982598,-0.3061999262313577
585.5000000000076,63.75764622327738,0.0449893537538612,-0.30679127330478906
586.4000000000076,63.84863333170218,0.04745383208225702,-0.30677515631713526
587.3000000000077,63.93773699390937,0.04806810015303263,-0.3081688580057529
588.2000000000077,64.02692092283054,0.05058057844165325,-0.30551246751454064
589.1000000000076,64.11820630763079,0.05328845798546566,-0.3070592244251831
590.0000000000077,64.20842250046867,0.054283365811117104,-0.30758131934459687
590.9000000000077,64.2987440059787,0.056849336178649165,-0.3071800468476047
591.8000000000077,64.3882514281341,0.05849222773606564,-0.306826854489064
592.7000000000077,64.47818919528594,0.06201688121414302,-0.30647711863378335
593.6000000000078,64.56819463054023,0.06496325219200065,-0.3075098143145558
594.5000000000077,64.65844550166402,0.06486113368458087,-0.3063679966403501
595.4000000000077,64.74735365161823,0.06980016758855762,-0.3075106091512052
596.3000000000078,64.8384824606913,0.07140485074984579,-0.30750993243894786
597.0000000000077,64.90783704324618,0.07283664790052785,-0.3061592603446477