File: 01_Data/Polyester_Carpet_High_Pile/STA/N2/3K_min/Polyester_Carpet_High_Pile_STA_N2_3KData_230926_R1.csv
##Temp./Â°C,Time/min,DSC/(mW/mg),Mass loss/mg
51.0,11.367182290667824,-2.353358550910512,-0.03133303221864914
52.100000000000016,11.879842545068906,-2.340729774028318,-0.031279874293415055
53.20000000000003,12.323761086106677,-2.3358196601354484,-0.032599880323017416
54.30000000000005,12.770256998280797,-2.3296706624882577,-0.03383172959943881
55.40000000000006,13.16833456779646,-2.3278228708431175,-0.03257217743888141
56.50000000000008,13.585538600414857,-2.3231809202344027,-0.03364480893005428
57.600000000000094,13.977356834732065,-2.322067669498954,-0.035230027418267085
58.70000000000011,14.361922742997416,-2.319126518838191,-0.03655197609248351
59.800000000000125,14.743838651411663,-2.3160022833872116,-0.0351900946018846
60.90000000000014,15.12604775387648,-2.3137465212146653,-0.037868839788508524
62.000000000000156,15.505246088439863,-2.3111563691011128,-0.03814228053141466
63.10000000000017,15.873679488565088,-2.3088015948041134,-0.038200336218712216
64.20000000000019,16.251098878673442,-2.3066553750046865,-0.03918986926303791
65.30000000000021,16.620727837466557,-2.3047426872758243,-0.03918998888977221
66.40000000000022,16.99297053411224,-2.30192988176746,-0.03920503247023621
67.50000000000023,17.360858851586528,-2.301742406833893,-0.0401766541903239
68.60000000000025,17.726487596006727,-2.298758054973128,-0.04084009959770629
69.70000000000027,18.09587669237948,-2.2954772178879455,-0.04049986501290359
70.80000000000028,18.46139150668537,-2.2927260796351407,-0.04182995511863119
71.90000000000029,18.831665769724523,-2.2917288736591304,-0.04084019624715385
73.00000000000031,19.179934503484226,-2.2871587517795495,-0.045548620476017376
74.10000000000034,19.56382338253244,-2.2853233738733074,-0.04239311281347202
75.20000000000034,19.92738119241737,-2.2839874553557142,-0.043689145980084554
76.30000000000035,20.299170000000128,-2.2801299999999824,-0.04276961730730022
77.40000000000038,20.669170000000154,-2.2776400000000327,-0.04369019999556034
78.5000000000004,21.030950266495584,-2.274468293775112,-0.04468005031651234
79.6000000000004,21.394958936729562,-2.27038613093533,-0.04466951761425708
80.70000000000041,21.759410525111935,-2.2691252120043273,-0.04532998906419561
81.80000000000044,22.124236053357397,-2.2667312134181805,-0.04500103253780807
82.90000000000046,22.490093877971766,-2.2649888892806658,-0.04435000547311141
84.00000000000047,22.85824228069402,-2.2615879647865103,-0.04664944709036423
85.10000000000048,23.222731961135825,-2.2598867897205515,-0.045330302252654775
86.2000000000005,23.584894917426865,-2.2576733658505708,-0.04632014499985093
87.30000000000052,23.946052826407062,-2.2546795223093254,-0.046454135095792104
88.40000000000053,24.30984778650859,-2.2510897200639235,-0.04732738965386485
89.50000000000054,24.67687829120608,-2.2487078161834164,-0.04846781837356051
90.60000000000056,25.039170000000077,-2.2464500000000065,-0.048299924999999355
91.70000000000059,25.40165501968978,-2.2462953210392316,-0.04908040103682065
92.8000000000006,25.770411534298052,-2.241871759313688,-0.04759426675570655
93.9000000000006,26.136140863842186,-2.240140745242955,-0.049189521438194994
95.00000000000063,26.489507152034385,-2.2400807280435573,-0.04806691417606501
96.10000000000065,26.85783805370344,-2.2395916067010537,-0.04851998151603887
97.20000000000066,27.223509061329608,-2.236815536177944,-0.04950955721454697
98.30000000000067,27.57831684607284,-2.2352916190257455,-0.05114999136400922
99.40000000000069,27.954714715833628,-2.232224926955381,-0.04983981437405394
100.50000000000071,28.310930933250248,-2.2310376303140966,-0.04981998361531126
101.60000000000072,28.670769051163372,-2.22915735973086,-0.05297284351308651
102.70000000000073,29.035320198114746,-2.228807954870443,-0.04885372775312202
103.80000000000075,29.396951906234786,-2.226258785451466,-0.0487652900089488
104.90000000000077,29.761133113973365,-2.225464990082558,-0.05116854337912047
106.00000000000078,30.122737707231387,-2.223382351503184,-0.049738172183260154
107.10000000000079,30.48406634903222,-2.2212216967167695,-0.05280325713454026
108.20000000000081,30.84617095206849,-2.219038805517667,-0.051820060085929764
109.30000000000084,31.20890798031483,-2.216784489564561,-0.05115542350106628
110.40000000000084,31.57023047189738,-2.215563105482277,-0.05017009000431383
111.50000000000085,31.93636410440775,-2.2127016227328644,-0.051810014335795795
112.60000000000088,32.292878102394866,-2.2121251450773776,-0.05181019498966766
113.7000000000009,32.65793738081031,-2.2111776525139697,-0.050829982302059484
114.8000000000009,33.01577856488665,-2.209170917717595,-0.052146073821184746
115.90000000000092,33.373043498785044,-2.2057371734220355,-0.051133313791857926
117.00000000000094,33.72263385022982,-2.2056998379338904,-0.049834465760722146
118.10000000000096,34.094373096860856,-2.2047297648215554,-0.052158361195906444
119.20000000000097,34.45058794585617,-2.2033129173269077,-0.05214005804821564
120.30000000000098,34.8163819528366,-2.2023983844222066,-0.051788458648368785
121.400000000001,35.17978667428504,-2.199627702176601,-0.05181260217983574
122.50000000000102,35.532716032726455,-2.1982190955607126,-0.051933197319479873
123.60000000000103,35.903991796062776,-2.198198380490294,-0.05192989776876411
124.70000000000104,36.263550907844426,-2.196925935440219,-0.05257998318595414
125.80000000000106,36.62368978229836,-2.1945908791552675,-0.05591427227470014
126.90000000000109,36.96963001408995,-2.193593779450369,-0.05133566396419642
128.00000000000108,37.33758160015494,-2.1904156927722793,-0.0513651753293054
129.1000000000011,37.69728373502156,-2.1889550351122864,-0.05268980892142672
130.20000000000113,38.05082076914382,-2.1898736460106676,-0.052755868116316496
131.30000000000115,38.41742430941472,-2.1887277586889184,-0.05269412153189501
132.40000000000117,38.778761640021024,-2.188166738531759,-0.053350117551083986
133.50000000000117,39.138259523459304,-2.1865552820511773,-0.054330968347231945
134.6000000000012,39.48877723602177,-2.1822950388274327,-0.054662451489284614
135.7000000000012,39.85172039165049,-2.1825225299205804,-0.05335132948009935
136.8000000000012,40.21023715184438,-2.1785676583055276,-0.05334928054712096
137.90000000000123,40.56716371148779,-2.17785655306396,-0.052359880340810516
139.00000000000125,40.92393087072649,-2.178300712842576,-0.053681413614771856
140.10000000000127,41.287451141478805,-2.1776093827792447,-0.05203051434118322
141.2000000000013,41.644601866686415,-2.1747721210102506,-0.0540098778651692
142.3000000000013,42.00488264129364,-2.175039991790188,-0.05302066741246758
143.4000000000013,42.365510013490194,-2.174548941079242,-0.053665468560415874
144.50000000000134,42.71846726779194,-2.173842832129485,-0.054989880861432194
145.60000000000133,43.079903305272694,-2.172657678860263,-0.05498988006783989
146.70000000000135,43.43816464430275,-2.169167372228079,-0.0553199988818478
147.80000000000138,43.789813380988974,-2.169050826454652,-0.054336953617224015
148.9000000000014,44.15374947467322,-2.1680372876901415,-0.055654979502441915
150.00000000000142,44.51247880824746,-2.169554376949567,-0.05766171680533905
151.10000000000142,44.86788361911592,-2.1686549024219217,-0.05632012333781633
152.20000000000144,45.22941678852943,-2.166901972482346,-0.05499981001813259
153.30000000000146,45.583276643817726,-2.166166288276868,-0.055989838823796045
154.40000000000146,45.94324078921766,-2.1667893759152004,-0.05631988502314256
155.50000000000148,46.29835612087399,-2.1669933411752846,-0.056644176705217486
156.6000000000015,46.653420780242485,-2.16788515903159,-0.05538006179411292
157.70000000000152,47.01126960452639,-2.166282909506797,-0.0546698394458871
158.80000000000155,47.362120320495855,-2.169125640222036,-0.055080313684507054
159.90000000000154,47.72728236299848,-2.1684524036494772,-0.05597967706789042
161.00000000000156,48.08341685454559,-2.170519354002343,-0.055302925790752244
162.1000000000016,48.43724189573196,-2.1746574117512454,-0.055559454645964124
163.20000000000158,48.79599078976144,-2.177041285236044,-0.05566006999996498
164.3000000000016,49.15705287986388,-2.1781187726772346,-0.05631872960534423
165.40000000000163,49.511035552801886,-2.181274616331287,-0.0563199194750994
166.50000000000165,49.872520333489454,-2.180419969386524,-0.05563114616363363
167.60000000000167,50.227598797957484,-2.1794419308576316,-0.05664982366763294
168.70000000000167,50.57740730136865,-2.1728056887521876,-0.056005589742119
169.8000000000017,50.93713349792976,-2.164859171521773,-0.055989951643116154
170.9000000000017,51.294007331826066,-2.156232046934401,-0.05663819157056693
172.0000000000017,51.64956225171121,-2.1516552102713757,-0.05598987504454289
173.10000000000173,52.00158175536893,-2.1468172825709044,-0.054669704709386924
174.20000000000175,52.3575505516957,-2.144846039822035,-0.05533236127978691
175.30000000000177,52.71551378850705,-2.144390754120638,-0.05433977196761619
176.4000000000018,53.078203991984154,-2.13910612330865,-0.0553098215361536
177.5000000000018,53.42681000813404,-2.140686219427246,-0.055649904868700695
178.6000000000018,53.78640579811073,-2.140315216316067,-0.05655622688731787
179.70000000000184,54.14358797569299,-2.139104415895993,-0.05696990495787446
180.80000000000183,54.499170000000696,-2.1358900000000314,-0.054999805087125875
181.90000000000185,54.85656314555866,-2.1383154840785457,-0.05564982998548906
183.00000000000188,55.21025658130892,-2.1384657213300513,-0.056970661530002076
184.1000000000019,55.56787562407771,-2.137662784143659,-0.05558316891484827
185.20000000000192,55.924789755856246,-2.137886147593065,-0.05762433121105426
186.30000000000192,56.280960081161695,-2.135014435818309,-0.055330163651533315
187.40000000000194,56.63767931909739,-2.135085739171383,-0.056975504417307477
188.50000000000196,56.996774851034274,-2.1339889631451214,-0.05565929442202844
189.60000000000196,57.346201399737005,-2.1335102407397204,-0.054065557441895784
190.70000000000198,57.70768928608642,-2.1343892272241636,-0.05632013499999644
191.800000000002,58.0642046804534,-2.1341404602728686,-0.05632013489434806
192.90000000000202,58.42012924526086,-2.1329412643103423,-0.05599006000000051
194.00000000000205,58.77544459254513,-2.1332127738541886,-0.05598889584588029
195.10000000000204,59.13226676085725,-2.1319581264719627,-0.056001726449056655
196.20000000000206,59.48429043547203,-2.1315179014052963,-0.056320058769463
197.3000000000021,59.84446971436902,-2.1321388631725515,-0.0552829226677356
198.40000000000208,60.19990260180496,-2.130053706079033,-0.0546698204663425
199.5000000000021,60.5563192050065,-2.1297741208461036,-0.057310129237140295
200.60000000000213,60.91236363324625,-2.1278476540766262,-0.05565849118606403
201.70000000000215,61.269170000000805,-2.1285499999999966,-0.055329834999969574
202.80000000000217,61.62557315453789,-2.1278457766591465,-0.05769519010945334
203.90000000000217,61.98458627072191,-2.127691490270212,-0.05500018855373057
205.0000000000022,62.342723750359085,-2.1264286424309957,-0.05631754935205313
206.1000000000022,62.69816419678692,-2.125383649552117,-0.055000898795348085
207.2000000000022,63.051380729340245,-2.123976280735032,-0.053406496482399035
208.30000000000223,63.415724090297736,-2.1229453642367693,-0.05477790605177191
209.40000000000225,63.76690618682806,-2.1240453742595338,-0.057409909988295205
210.50000000000227,64.12481905318948,-2.1245482000266778,-0.0583281953239525
211.6000000000023,64.47971475987111,-2.1250902675284835,-0.055990090087445044
212.7000000000023,64.83520066159359,-2.123336432728403,-0.05729863679913905
213.8000000000023,65.19225122433978,-2.1207731644542918,-0.05662489303223639
214.90000000000234,65.54814777211601,-2.1206911766750194,-0.05664000887210152
216.00000000000233,65.90322903897855,-2.1200996859982997,-0.05795990999999967
217.10000000000235,66.25678230878064,-2.1216607051000462,-0.0566606918131356
218.20000000000238,66.61277849106632,-2.119758855707609,-0.05716624535599113
219.3000000000024,66.96786512573391,-2.1185293895172572,-0.05861991522662846
220.40000000000242,67.32356393972894,-2.119862353744207,-0.05760518418153726
221.50000000000242,67.68234452130328,-2.119646458545175,-0.05814424557289266
222.60000000000244,68.03356025836023,-2.121231175869576,-0.058950059985472425
223.70000000000246,68.38992689709924,-2.120923455331183,-0.05798957379735059
224.80000000000246,68.74155641782735,-2.12286169373757,-0.05993998505731568
225.90000000000248,69.10643431072945,-2.121817726889962,-0.059391443214644735
227.0000000000025,69.46024753230732,-2.122495400524483,-0.05928013500383811
228.10000000000252,69.8156931595532,-2.1205780876966975,-0.05961020987459209
229.20000000000255,70.17277701436852,-2.1209864185643563,-0.05939012536702171
230.30000000000254,70.52563756668994,-2.1218578155397774,-0.059390128820245636
231.40000000000256,70.88548000180185,-2.1212793238861822,-0.06004998073583767
232.5000000000026,71.23772010075945,-2.122680985239179,-0.06004987870202383
233.60000000000258,71.59681808615566,-2.1232204127778,-0.06239282130907009
234.7000000000026,71.96029729301212,-2.12355708130256,-0.06026358646534735
235.80000000000263,72.3102264037402,-2.125956983315408,-0.06103845793237994
236.90000000000265,72.66717527303337,-2.127375483475126,-0.06105225914560597
238.00000000000267,73.02799134531364,-2.129821906210291,-0.06257265515316623
239.10000000000267,73.38259804712371,-2.1281946406853436,-0.06189469013992799
240.2000000000027,73.7408686169974,-2.1309133929535267,-0.06157538230601256
241.3000000000027,74.0991700000014,-2.1334500000000305,-0.061249978493654655
242.4000000000027,74.45253474901214,-2.136755011550087,-0.06136015092264824
243.50000000000273,74.81108538906979,-2.1401616598281086,-0.0618108855192494
244.60000000000275,75.16866994179466,-2.1456522496327755,-0.06333992706803615
245.70000000000277,75.52399918199815,-2.1519390017309936,-0.060041030101598114
246.8000000000028,75.87760764276386,-2.1600905917925632,-0.06301979289975357
247.9000000000028,76.23539837853745,-2.1721986530663075,-0.06377956127892359
249.0000000000028,76.59917000000124,-2.1926200000000047,-0.06212980878380048
250.10000000000284,76.95613300521913,-2.2190331216880557,-0.0634489650958181
251.20000000000283,77.32040337995106,-2.23413483184757,-0.06410986542984043
252.30000000000285,77.67558017232336,-2.227436443049151,-0.06411101887354098
253.40000000000288,78.03063187623115,-2.204105967298733,-0.0651353732120481
254.5000000000029,78.38232659634924,-2.1767099075323078,-0.06378058897731975
255.60000000000292,78.73307840831357,-2.158837332648893,-0.06501423110392457
256.7000000000029,79.0832241730337,-2.145485362129,-0.06480556306572316
257.8000000000029,79.44358610980854,-2.135896078157964,-0.0657600700000005
258.90000000000293,79.80001700350441,-2.12970355236672,-0.06674141436716896
260.00000000000296,80.15569961236463,-2.1260939171853455,-0.06696637324620802
261.100000000003,80.51593211594768,-2.1233805195141238,-0.06707009499985883
262.200000000003,80.87027785817925,-2.121250896471178,-0.06641009141296061
263.300000000003,81.22407593132742,-2.1199742117914204,-0.06718001547882091
264.40000000000305,81.57860222334583,-2.118998993144345,-0.06717991504656773
265.50000000000307,81.93449113701416,-2.119262363244422,-0.0691588714040563
266.6000000000031,82.28731647232767,-2.1197783232523384,-0.06920441725947146
267.7000000000031,82.64177967321251,-2.1186881040844145,-0.06916005879484644
268.8000000000031,82.99775567163475,-2.1195575016804726,-0.06900605638357993
269.9000000000031,83.35712961940386,-2.119262579939224,-0.07342060256868255
271.0000000000031,83.717826514837,-2.119696575230666,-0.06852270189389431
272.10000000000315,84.07272310375737,-2.1191082038632563,-0.07212216548450678
273.2000000000032,84.43252014395112,-2.1194749359074865,-0.07092001499999778
274.30000000000314,84.81774406674145,-2.1237343436181053,-0.07190993087168884
275.40000000000316,85.14781100644416,-2.1207843468587435,-0.073548323875539
276.5000000000032,85.50632824821531,-2.121638627297304,-0.07157018989307451
277.6000000000032,85.8668868223429,-2.124226916171953,-0.07333125546501806
278.70000000000323,86.21919852506848,-2.1210514490543746,-0.07322247824687
279.80000000000325,86.5684817022649,-2.1237489981219397,-0.07289000778960508
280.9000000000033,86.92345058757921,-2.124180961314764,-0.07322835247437842
282.0000000000033,87.28169083902702,-2.12476837447557,-0.0745455899527343
283.1000000000033,87.6393852078801,-2.1262199004401063,-0.07486605750045872
284.20000000000334,88.00376349732058,-2.1276663098274264,-0.07408350790593587
285.30000000000337,88.36139878245679,-2.1289115744424496,-0.07464985245823375
286.40000000000333,88.71441460174988,-2.129784219002564,-0.07695535852240587
287.50000000000335,89.07414143393211,-2.1287628595592984,-0.0762891530051566
288.6000000000034,89.43331115417487,-2.132600016431813,-0.07892992310295632
289.7000000000034,89.78842025685897,-2.132679289770753,-0.07921817434464185
290.8000000000034,90.14337315756539,-2.134614700490859,-0.08112843500011868
291.9000000000034,90.50483506203815,-2.1351414432153892,-0.08090009289150712
293.0000000000034,90.86348173443864,-2.138734904559265,-0.0812299203746627
294.10000000000343,91.22445929523106,-2.14126119288415,-0.083497225339773
295.20000000000346,91.57789179553819,-2.144411111972886,-0.08585010716672015
296.3000000000035,91.93698110790845,-2.146100678274417,-0.08585010509563196
297.4000000000035,92.29368171157239,-2.1506737794648774,-0.0865620647853933
298.5000000000035,92.64882289662945,-2.154392520932679,-0.08815018896005977
299.60000000000355,93.00751584555702,-2.1588868345881695,-0.0907899674237469
300.70000000000357,93.36584486384673,-2.1625508029827425,-0.09078666353147424
301.8000000000036,93.72314055215249,-2.1690071594023714,-0.09209979238538812
302.9000000000036,94.08197987866546,-2.1709058082043744,-0.09605982503155053
304.0000000000036,94.43119574395062,-2.1746594370594665,-0.09976177564722333
305.1000000000036,94.80007257446786,-2.1793122967467062,-0.10099976269863209
306.2000000000036,95.15560881364182,-2.182908658529077,-0.10263045253543801
307.30000000000365,95.51235495671068,-2.18568343443049,-0.1039599199934802
308.4000000000037,95.86917350200444,-2.186890545019607,-0.10792214780263887
309.5000000000037,96.2230229813445,-2.1873839373078563,-0.11634140247962055
310.60000000000366,96.58230408989839,-2.1873310453282477,-0.1158837237519359
311.7000000000037,96.94192948890668,-2.1892654639156612,-0.1166089028054138
312.8000000000037,97.29730373145648,-2.1878806658944265,-0.12200349020613599
313.90000000000373,97.65568651411043,-2.1881996159478616,-0.12459958726112985
315.00000000000375,98.01434447298081,-2.1860286896841665,-0.12857140768297093
316.1000000000038,98.37002724040178,-2.183428318506977,-0.13248819028167214
317.2000000000038,98.72478026838368,-2.1808022279920896,-0.13513392735782181
318.3000000000038,99.08797432068236,-2.180663776454041,-0.14041005077098978
319.40000000000384,99.44540151739326,-2.1795578410823477,-0.1452566315662871
320.5000000000038,99.80528820276974,-2.17771783835503,-0.15062530486855463
321.60000000000383,100.1679058719715,-2.176513479611691,-0.1558939980341445
322.70000000000385,100.52714260872162,-2.17525716526746,-0.16085528053434794
323.8000000000039,100.8870934953315,-2.173068724474523,-0.16477096195270446
324.9000000000039,101.24620443098485,-2.1691929649632913,-0.1687508163593341
326.0000000000039,101.60517870328299,-2.1655486314992283,-0.17498072530728148
327.10000000000394,101.96454838293859,-2.1647279164669295,-0.17927279966012843
328.2000000000039,102.32508475857824,-2.164115127853299,-0.18452712905648205
329.30000000000393,102.68285896247232,-2.1618863983153345,-0.18880973826070457
330.40000000000396,103.04548309321144,-2.1580017138268133,-0.19684210474349229
331.500000000004,103.3995585940979,-2.158573849152174,-0.20048699147796434
332.600000000004,103.7519311868286,-2.1561885237568807,-0.20668798944687872
333.700000000004,104.1163904677174,-2.1536339288348225,-0.21329546549180467
334.80000000000405,104.48202031198622,-2.1508683098870582,-0.2185161772015216
335.90000000000407,104.83639565337982,-2.150148116485948,-0.22251397638573422
337.0000000000041,105.1924887422961,-2.1490668982559016,-0.22845004932359458
338.10000000000406,105.55601337208857,-2.151499330361991,-0.23372092991944404
339.2000000000041,105.91816194700556,-2.151636092724109,-0.23900641117677468
340.3000000000041,106.2793773424881,-2.152435719514405,-0.24451622337369772
341.4000000000041,106.64101241191398,-2.155666430713763,-0.2500802770331991
342.50000000000415,106.99879177245553,-2.1557894324084397,-0.2586753498109271
343.6000000000042,107.35640748653088,-2.1531462992128647,-0.26322387626960797
344.7000000000042,107.71456583567756,-2.1549622350216713,-0.2673167745631684
345.80000000000416,108.07562168177782,-2.1555275934968483,-0.2706425865843798
346.9000000000042,108.43473387384103,-2.154938680065767,-0.27752142954739023
348.0000000000042,108.7949420275137,-2.1579122700041915,-0.2827929167828902
349.10000000000423,109.15640031594236,-2.1592243203104613,-0.2885017224792956
350.20000000000425,109.51738536678248,-2.158466807252617,-0.29608030076220615
351.3000000000043,109.878878904248,-2.1617146131481038,-0.29969990227637755
352.4000000000043,110.2398183718209,-2.15885979139411,-0.30595884940737506
353.5000000000043,110.5967536256031,-2.1587492052630877,-0.31012071399316543
354.60000000000434,110.95654872807683,-2.1599608267237604,-0.31640531536179095
355.7000000000043,111.30721531449406,-2.159941659047434,-0.32254086151825057
356.80000000000433,111.6732763284966,-2.1596963703647463,-0.3277302883235591
357.90000000000435,112.02820104531341,-2.1612138003600756,-0.3343900137352458
359.0000000000044,112.39216592996469,-2.1625447099694846,-0.3409236375514353
360.1000000000044,112.7536301260006,-2.16317350101892,-0.3435727633624617
361.2000000000044,113.11493272092757,-2.1642355908063453,-0.35197185154397737
362.30000000000445,113.4794694368876,-2.1652805086121343,-0.35855001747646087
363.4000000000044,113.8391737719256,-2.166549661960926,-0.3664876515186615
364.50000000000443,114.1984685013121,-2.166010310912047,-0.3703614727418416
365.60000000000446,114.56016797843378,-2.168197904105185,-0.3784076159288925
366.7000000000045,114.91641522639782,-2.168515707809437,-0.38422370234527836
367.8000000000045,115.27630693001461,-2.1726503861795585,-0.3948490870280925
368.9000000000045,115.64485808951474,-2.171620878543776,-0.3977437906701189
370.00000000000455,116.00557989307953,-2.1724118679563853,-0.4082549218357152
371.10000000000457,116.36657206112203,-2.1744533980196388,-0.41420587212388504
372.2000000000046,116.72565236079451,-2.175904408626959,-0.4235151541879718
373.30000000000456,117.082077638879,-2.176459467637907,-0.4320629827659621
374.4000000000046,117.45191273646913,-2.1784797731827985,-0.44018359426988507
375.5000000000046,117.8108222183893,-2.1808523017845918,-0.4510358912844836
376.6000000000046,118.17567902163495,-2.1802067920625743,-0.4596729954152239
377.70000000000465,118.53468046018877,-2.181457827436766,-0.46928094471665327
378.8000000000047,118.89882466279678,-2.1846145819795213,-0.4785260084777967
379.9000000000047,119.25826401452596,-2.18607974168727,-0.4891977545905486
381.00000000000466,119.6222134028284,-2.1887920514331296,-0.5014071771201976
382.1000000000047,119.98403768134095,-2.1906554571709456,-0.5120203493130133
383.2000000000047,120.34321078743291,-2.1953878782302234,-0.5241823397364249
384.30000000000473,120.70713062531107,-2.1957332616465672,-0.5367836896958527
385.40000000000475,121.06668220166846,-2.1971370675077213,-0.5494677947701301
386.5000000000048,121.42059002289244,-2.2008543347388114,-0.5597721740329491
387.6000000000048,121.78890205811179,-2.2011622068084176,-0.5766315324151003
388.7000000000048,122.14521106675515,-2.20510578631594,-0.5904628827550318
389.80000000000484,122.513058839104,-2.208918927107509,-0.6058670758530478
390.9000000000048,122.87760441209598,-2.2154542729891467,-0.6197130680409808
392.00000000000483,123.2424912737761,-2.217341954288244,-0.6369688452557765
393.10000000000485,123.60334681186107,-2.220796683235022,-0.653166751621927
394.2000000000049,123.96190393603935,-2.2234890983264664,-0.671223681384252
395.3000000000049,124.33091957783273,-2.228543742134617,-0.6884119229715613
396.4000000000049,124.6887858196335,-2.231309917205786,-0.7074436741211945
397.50000000000495,125.05120613289242,-2.2355246364338974,-0.7280278891992018
398.6000000000049,125.41326877310104,-2.2375725423787594,-0.749854544408433
399.70000000000493,125.7826115936286,-2.2427573294053955,-0.768845172340757
400.80000000000496,126.14299029332312,-2.247006269824528,-0.7932150291108542
401.900000000005,126.49974677664028,-2.2485823374234615,-0.8150454738799704
403.000000000005,126.87307518154924,-2.252964003788001,-0.8389158939774499
404.100000000005,127.23111219213723,-2.2559749107574483,-0.8634849683711678
405.20000000000505,127.59326063,-2.258939712930492,-0.8881879636261325
406.30000000000507,127.95642330935691,-2.264154044928609,-0.9141950693572065
407.4000000000051,128.31054828636974,-2.265599623434277,-0.9424886440791562
408.50000000000506,128.6814613842335,-2.2715501426172855,-0.9699007396857349
409.6000000000051,129.0455324728827,-2.2736587852441543,-0.9987840763376665
410.7000000000051,129.40819613995453,-2.275740642047262,-1.0281516696237931
411.8000000000051,129.7691735209474,-2.2800000418095916,-1.0573201890803454
412.90000000000515,130.1341264743888,-2.281021132376761,-1.0900867262798504
414.0000000000052,130.49917000000104,-2.2831699999999926,-1.1186799550000086
415.1000000000052,130.86057957837238,-2.2819700410409482,-1.149046003662241
416.20000000000516,131.22074858403295,-2.284418190765274,-1.178584436655012
417.3000000000052,131.5864814898507,-2.2828150438275183,-1.2054265855109478
418.4000000000052,131.94453505066483,-2.283233609515584,-1.233765695247535
419.50000000000523,132.29234000467042,-2.282876659501697,-1.2597584946407863
420.60000000000525,132.6696357835128,-2.2812863557836844,-1.2826766426359586
421.7000000000053,133.0348824334392,-2.2805316390302983,-1.306703213595593
422.8000000000053,133.4025686912287,-2.276479460977402,-1.3293441726188813
423.9000000000053,133.76971520506856,-2.2753378666519066,-1.346927173201598
425.00000000000534,134.1325838368955,-2.2699979569100863,-1.3637319691604706
426.1000000000053,134.4977589050249,-2.2672089882171487,-1.3784102969679601
427.20000000000533,134.8553954431172,-2.2642182407529066,-1.3946944523395106
428.30000000000535,135.22142435520144,-2.262354553197029,-1.4075199854563998
429.4000000000054,135.58684008477098,-2.2588507517569716,-1.4189834264078542
430.5000000000054,135.9471834528287,-2.2579773051935734,-1.4312602035513198
431.6000000000054,136.30850149886868,-2.255136349427818,-1.4431459900612311
432.70000000000545,136.66879201314208,-2.2567182905883,-1.4552792768001712
433.8000000000054,137.03330917288412,-2.256189900311832,-1.4661776191121532
434.90000000000543,137.39528065531601,-2.2578295464628995,-1.4786684830795718
436.00000000000546,137.76553725230931,-2.2603691802937265,-1.4898672569719653
437.1000000000055,138.13236158845555,-2.261289805470877,-1.5022116243625838
438.2000000000055,138.49726370127027,-2.263639033973222,-1.5146126014114945
439.3000000000055,138.86111170023813,-2.2631887305661826,-1.5261698984991
440.40000000000555,139.22417369850916,-2.2642961638307333,-1.5422991762639566
441.50000000000557,139.58992983510444,-2.265303253390634,-1.5543399495667214
442.6000000000056,139.9501371752735,-2.2683479631541945,-1.5649824437542987
443.70000000000556,140.31641119651997,-2.2682964079360395,-1.5796057848029865
444.8000000000056,140.68288908941207,-2.2713892431707405,-1.5953671278883035
445.9000000000056,141.0488307266115,-2.273193068519611,-1.6101978446794143
447.0000000000056,141.40744515188098,-2.2769641531906246,-1.6268684070264263
448.10000000000565,141.7781545087546,-2.277277566259133,-1.6413640131409197
449.2000000000057,142.1383492036169,-2.278970712827079,-1.6643678036498666
450.3000000000057,142.50444821269036,-2.2778006121635648,-1.6750530911731762
451.40000000000566,142.87483059417494,-2.2775079391224575,-1.6925490940595749
452.5000000000057,143.24388710766664,-2.274038799278593,-1.70720103822483
453.6000000000057,143.60960441662365,-2.2711096374647943,-1.719197569913511
454.70000000000573,143.97620444402327,-2.265871659319414,-1.7289008289201084
455.80000000000575,144.3425847834193,-2.2591829441120113,-1.7355674015886473
456.9000000000058,144.70638316771544,-2.2499552919402723,-1.7421322381502717
458.0000000000058,145.07094444958852,-2.2454438802753733,-1.7473199567923396
459.1000000000058,145.43157999386435,-2.240167883346503,-1.7500608198367535
460.20000000000584,145.79410004957396,-2.2379028226884548,-1.7537209551980384
461.3000000000058,146.16121216970726,-2.2396556673275527,-1.7564657832183066
462.40000000000583,146.5283646385878,-2.2385892335202704,-1.7590598499974575
463.50000000000585,146.88934268375027,-2.2408031130928587,-1.7603816618124069
464.6000000000059,147.25977495566806,-2.261647255784357,-1.7611392377942927
465.7000000000059,147.626234395922,-2.2695504360913388,-1.7626907423725102
466.8000000000059,147.98632605786307,-2.269918823434595,-1.765285125272198
467.90000000000595,148.35882336936453,-2.2738597493063883,-1.7666308409107239
469.0000000000059,148.7266789577983,-2.2725456566601085,-1.767096830267315
470.10000000000593,149.0952679606148,-2.273084540906311,-1.7683008933383686
471.20000000000596,149.45835808741194,-2.2761509657248036,-1.7709094315156966
472.300000000006,149.82682721877794,-2.276634192818937,-1.7706875292324593
473.400000000006,150.19013592291373,-2.280050879834402,-1.7706005065348873
474.500000000006,150.5571027574653,-2.2811645376317355,-1.7735508635545436
475.60000000000605,150.92087706499714,-2.2833050548971756,-1.773645661336014
476.70000000000607,151.28547327789735,-2.286856826709003,-1.7771710746757328
477.8000000000061,151.65300839719976,-2.2888847081179,-1.777499967376234
478.90000000000606,152.01954243687234,-2.2922518145657698,-1.7774998472270247
480.0000000000061,152.38825187755157,-2.2929865481308185,-1.7807753159957849
481.1000000000061,152.75941277468738,-2.2945950038283214,-1.780129820513908
482.2000000000061,153.12134313315153,-2.299521373582094,-1.7812441660557616
483.30000000000615,153.4879253198472,-2.300657216404579,-1.7839398809201628
484.4000000000062,153.85483382137085,-2.3055735195792315,-1.7837266935123943
485.5000000000062,154.2257267560282,-2.304917564616947,-1.7864999250162343
486.60000000000616,154.58674936938942,-2.3076674737376317,-1.7873511913960454
487.7000000000062,154.9506074811048,-2.311111602329409,-1.7887941942713952
488.8000000000062,155.30881082575115,-2.3129724962465765,-1.7900103517497987
489.90000000000623,155.6876870583437,-2.316703080054556,-1.7887691195731943
491.00000000000625,156.0529172195753,-2.316584549879708,-1.7923201817137113
492.1000000000063,156.42105854489074,-2.3157224131069842,-1.7990481704333643
493.2000000000063,156.7851115455796,-2.320627404959791,-1.7897595617145927
494.3000000000063,157.14726524261744,-2.3243579827073346,-1.789481495583345
495.40000000000634,157.52140438713562,-2.3247472804276073,-1.7975893568931127
496.5000000000063,157.8895705388369,-2.3280962142748107,-1.7989564362251644
497.60000000000633,158.25651117971142,-2.3286876566199197,-1.7988237553663966
498.70000000000636,158.62730889742105,-2.331546698031872,-1.8012121214485477
499.8000000000064,158.9958797797055,-2.3348993268844263,-1.80220005547246
500.9000000000064,159.36552017147872,-2.3365009182786878,-1.8045010913077055
502.0000000000064,159.7329772168696,-2.3383222318246744,-1.8071399798126548
503.10000000000645,160.105987544192,-2.342172959205382,-1.8074717421394588
504.2000000000064,160.47796759070374,-2.3427417345702946,-1.8073977494795264
505.30000000000643,160.84117009859065,-2.3431215600940516,-1.8098500075802737
506.40000000000646,161.210226973894,-2.3466725130473787,-1.8139602380788786
507.5000000000065,161.5759993549202,-2.3524003487807787,-1.8139500161913977
508.6000000000065,161.9380000876077,-2.3540101684971626,-1.8159392312874694
509.7000000000065,162.30763139634476,-2.3579700729144,-1.8152700455414692
510.80000000000655,162.67529134586445,-2.3608268173835505,-1.8177827356261105
511.90000000000657,163.04308391629718,-2.366999825073377,-1.8185607601255311
513.0000000000066,163.41287694786143,-2.3707851586264073,-1.8208942180640983
514.1000000000065,163.781362979568,-2.3781657480405616,-1.8232799666738604
515.2000000000066,164.14916684020505,-2.379839445594831,-1.8237204960842868
516.3000000000065,164.51809924835447,-2.3873395012385394,-1.8265699398144486
517.4000000000067,164.88945842514138,-2.3937229688678974,-1.8282214275448987
518.5000000000066,165.2547917425803,-2.400306669824177,-1.8295398049946927
519.6000000000067,165.62194692047194,-2.4066547981233324,-1.8321698765426948
520.7000000000066,165.98655858777556,-2.4111376450452715,-1.8338891350526385
521.8000000000067,166.356637463133,-2.4156633904619134,-1.8359915270494813
522.9000000000067,166.72770531338145,-2.4237144986353663,-1.8376026087386026
524.0000000000067,167.09296878040675,-2.425830263369582,-1.8400912659856932
525.1000000000067,167.4665442086487,-2.4254191568531906,-1.8412823144955128
526.2000000000068,167.8287709908799,-2.4255837561928386,-1.8449026034953042
527.3000000000068,168.2073594792526,-2.4273717399006287,-1.8475399498232998
528.4000000000068,168.56418255711344,-2.4240118529292096,-1.8514921113169738
529.5000000000068,168.9326940965893,-2.4228495496733604,-1.8531399865409344
530.6000000000068,169.2939669488391,-2.4252039171016984,-1.8552149011691563
531.7000000000069,169.6657575564486,-2.4270364911190296,-1.8577099030959685
532.8000000000068,170.03577908358267,-2.4282541941774234,-1.8622351742503969
533.9000000000069,170.40362462278492,-2.429372952417794,-1.8661997392377279
535.0000000000068,170.7744829698721,-2.430092961901082,-1.8701442575795064
536.100000000007,171.14111964662277,-2.4311924000639453,-1.875200892302432
537.2000000000069,171.51510623014713,-2.4321912512334007,-1.8782801814188281
538.300000000007,171.88538930559872,-2.4318186100183485,-1.8841493886190062
539.4000000000069,172.2537438489691,-2.4347193910402387,-1.888524345613583
540.5000000000069,172.62809449923319,-2.4374213828452187,-1.8918821427224453
541.600000000007,172.9976576287578,-2.4369260541424773,-1.8969365364125368
542.700000000007,173.36787418832333,-2.438325205558737,-1.9040900999559152
543.800000000007,173.73327438943252,-2.439321418731544,-1.9085782819270798
544.900000000007,174.10205548256556,-2.4378494363230203,-1.916004974356008
546.000000000007,174.46831351670338,-2.4401204177225857,-1.922960683418553
547.1000000000071,174.83102351097497,-2.4416251231694868,-1.9308297057197206
548.2000000000071,175.20274170585245,-2.440631118311195,-1.9368766538788464
549.300000000007,175.5730658502344,-2.438613485580541,-1.9454931646822335
550.4000000000071,175.9397726308744,-2.437179027297742,-1.9534842158770038
551.500000000007,176.3106704043006,-2.4372883643981256,-1.964902840696951
552.6000000000072,176.67745179521526,-2.4331995013882097,-1.971705098053576
553.7000000000071,177.04855934388084,-2.4327528847727296,-1.9818268358283482
554.8000000000072,177.41264448052777,-2.430196883383126,-1.992837995873825
555.9000000000071,177.78716308526225,-2.4310329025989885,-2.0014735914016692
557.0000000000072,178.15692295276796,-2.4300226547618657,-2.01078416694669
558.1000000000072,178.52997394458998,-2.431921815734564,-2.020676462844604
559.2000000000072,178.8998963220851,-2.4358282692060396,-2.0317590374727055
560.3000000000072,179.2693816055349,-2.4346700302461572,-2.0407556789132273
561.4000000000073,179.6318316933892,-2.435020756610681,-2.05361456054578
562.5000000000073,180.0062138845354,-2.438485483255579,-2.0631838142838768
563.6000000000073,180.37457110105996,-2.439931228133486,-2.074315013407366
564.7000000000073,180.7446428607488,-2.442933607292053,-2.0862133901694064
565.8000000000073,181.11173703480193,-2.446473927463609,-2.0954767708684896
566.9000000000074,181.48133067557347,-2.450504712596734,-2.1072262543927742
568.0000000000074,181.85080693835485,-2.449969450570285,-2.1183389863950075
569.1000000000074,182.2180317428653,-2.4520631690007955,-2.1271031216094016
570.2000000000073,182.57877617159457,-2.4523439414089645,-2.1370412906472884
571.3000000000073,182.95385547504193,-2.4530705886014053,-2.1491623515873974
572.4000000000074,183.32014684171745,-2.4574658201376707,-2.15834197575578
573.5000000000074,183.68609097964736,-2.458199929806918,-2.1663439367879747
574.6000000000074,184.06148660680063,-2.4601362669285853,-2.173213779851026
575.7000000000074,184.4291659148169,-2.4702993936328226,-2.180620041398725
576.8000000000075,184.80215567342614,-2.5062462702833015,-2.183238537606294
577.9000000000075,185.17321520355176,-2.5338161114281252,-2.185889810079191
579.0000000000075,185.54339837848042,-2.551237930407229,-2.187869985985085
580.1000000000075,185.90682287933325,-2.5580762666414505,-2.188190152310647
581.2000000000075,186.28112610591336,-2.5510996218873743,-2.188193742946212
582.3000000000076,186.6464273342413,-2.547819154225232,-2.190827436896425
583.4000000000076,187.01416118588511,-2.54389389911989,-2.192149970695122
584.5000000000076,187.38700695120014,-2.5426567593236333,-2.191841568030977
585.6000000000076,187.7538949849592,-2.5374789031966363,-2.1947899889273774
586.7000000000077,188.1255717153616,-2.5351098591258925,-2.195120504008777
587.8000000000077,188.49499209760552,-2.5309888356168844,-2.196212041227762
588.9000000000076,188.86829848068913,-2.525845114713747,-2.197530273741961
590.0000000000076,189.23864546906705,-2.5230368770259552,-2.198186793144134
591.1000000000076,189.60553517766667,-2.5190476172243264,-2.202436668757148
592.2000000000077,189.97425205877627,-2.5179131093619587,-2.2018102251532135
593.3000000000077,190.34536092095172,-2.51294726410323,-2.2041199095127144
594.4000000000077,190.7180324644142,-2.512457023722526,-2.2056561159425008
595.5000000000077,191.08381930255564,-2.507364196376087,-2.2073000681691965
596.6000000000078,191.45147063935795,-2.508395070299681,-2.209278827582968
597.7000000000078,191.8183169377171,-2.504844325193324,-2.2099398829629466
598.8000000000078,192.1908371570066,-2.5047131111806884,-2.212569989999982
599.9000000000078,192.56527824199875,-2.5090861521392256,-2.215199215049738
601.0000000000078,192.93799963426213,-2.5106872066941923,-2.2165281926980973
602.1000000000079,193.3081917165681,-2.514923545283047,-2.2204385443210763
603.2000000000079,193.67590075841895,-2.5232113798363933,-2.221790111313165
604.3000000000079,194.0477607992587,-2.528872500406982,-2.2244300099180454
605.4000000000078,194.42022729286435,-2.5352328315931865,-2.2260699359106475
606.5000000000078,194.79639332542254,-2.543447297484861,-2.228668621030433
607.6000000000079,195.17391493568712,-2.5496668435539505,-2.2313404913440547
608.7000000000079,195.54281429244855,-2.55522441947459,-2.235305392867849
609.8000000000079,195.911186935929,-2.5662019221600567,-2.237299581719957
610.9000000000079,196.27802869318253,-2.5722932788877437,-2.240240122431577
612.000000000008,196.6501496793422,-2.5826752748070714,-2.243554024429775
613.100000000008,197.01374513954502,-2.5907233659986275,-2.246489944955352
614.200000000008,197.38525207434697,-2.6012752306968943,-2.2507642230307647
615.300000000008,197.75230643995474,-2.6072529076599493,-2.2534085418700567
616.400000000008,198.11974333842096,-2.617513623696419,-2.2567488855763003
617.5000000000081,198.49121859419708,-2.6283993511729244,-2.260851632783482
618.6000000000081,198.86812873475253,-2.6394260484935663,-2.2652596422889926
619.7000000000081,199.2445337500625,-2.6519830303060496,-2.270200576227216
620.8000000000081,199.61280673179678,-2.6614301995444447,-2.274803560616186
621.9000000000082,199.98916332644234,-2.6768991521413956,-2.278109997798163
623.0000000000082,200.36067090771755,-2.683085193570563,-2.287452351625479
624.1000000000081,200.73015681005907,-2.693282369630565,-2.2885167403756923
625.2000000000081,201.10148161000035,-2.7020797565877825,-2.2941576594527535
626.3000000000081,201.46634519984798,-2.6664191968893594,-2.299027258269911
627.4000000000082,201.8353683467593,-2.6676151622541435,-2.30367278929336
628.5000000000082,202.2069735525398,-2.680252767797578,-2.311355469034873
629.6000000000082,202.57993912230378,-2.693214814175463,-2.3155491863205473
630.7000000000082,202.95399560863268,-2.7062241036384305,-2.320728342022367
631.8000000000083,203.32405744114223,-2.7207734206843934,-2.3269673946987623
632.9000000000083,203.69916199692213,-2.734620236117283,-2.333660310668101
634.0000000000083,204.07116940470738,-2.747167952156505,-2.339606863813402
635.1000000000083,204.44532875524578,-2.7647788246584537,-2.347472155258493
636.2000000000083,204.81668035927842,-2.77579467418754,-2.3540595549069185
637.3000000000084,205.18766055922933,-2.788801480151143,-2.3619907840463816
638.4000000000084,205.55725771297023,-2.804499738164421,-2.369992832124404
639.5000000000084,205.9326845607217,-2.820442369728449,-2.3769155709079888
640.6000000000083,206.30258666426354,-2.8341555961592646,-2.3837409847881696
641.7000000000083,206.67375046482388,-2.8488983555116043,-2.392770729404668
642.8000000000084,207.0391719351634,-2.863360295161564,-2.401619945602298
643.9000000000084,207.41389738201752,-2.8756194163095614,-2.4098137497040564
645.0000000000084,207.7844114084348,-2.891183842266676,-2.416120361972726
646.1000000000084,208.16086527677237,-2.905260958645526,-2.425508730230721
647.2000000000085,208.53530584388423,-2.9176189070404766,-2.434996579404939
648.3000000000085,208.90860841427397,-2.9311990039288762,-2.443770386207043
649.4000000000085,209.28418271651717,-2.94717024120985,-2.452968334975016
650.5000000000085,209.6544862124775,-2.9617411839281793,-2.4628695621024943
651.6000000000085,210.0291788957033,-2.9786315888164587,-2.472328344473203
652.7000000000086,210.39916656972616,-2.9917899888353046,-2.4802297968112006
653.8000000000086,210.77299713920627,-3.00795838960492,-2.48971645857338
654.9000000000086,211.14992313349248,-3.025667146471158,-2.5009234832921488
656.0000000000086,211.52035072377663,-3.0420128287799297,-2.5103402137935067
657.1000000000087,211.88917623169874,-3.0625200773853476,-2.521069874029767
658.2000000000087,212.26554077152755,-3.0824587390115306,-2.531823583468134
659.3000000000086,212.63955133792132,-3.100993314716408,-2.543153948868317
660.4000000000086,213.01125622154265,-3.114604676668285,-2.552355481962867
661.5000000000086,213.38442257395073,-3.1294137605905807,-2.564231307997643
662.6000000000087,213.7560683461405,-3.1455163942783444,-2.5753584770186437
663.7000000000087,214.12799238449588,-3.16155072737814,-2.588919249940004
664.8000000000087,214.4986426215674,-3.174913160889706,-2.600401404706469
665.9000000000087,214.8757470033423,-3.189472182921676,-2.6141736040900083
667.0000000000088,215.2477847688865,-3.198558821899326,-2.623986771965678
668.1000000000088,215.62082631865127,-3.2120212452176213,-2.638054142704126
669.2000000000088,215.99916677183072,-3.2194599836290934,-2.6511498148917045
670.3000000000088,216.37315084588454,-3.2231945208169726,-2.6619925728338414
671.4000000000088,216.74864290429514,-3.2274116372975152,-2.6749787274115757
672.5000000000089,217.11770414119013,-3.2284561244553616,-2.691665828194789
673.6000000000089,217.4921853663214,-3.2296853422273353,-2.701405079381913
674.7000000000089,217.86133106876503,-3.226895683861215,-2.712742520622152
675.8000000000088,218.2325222913695,-3.222838151988583,-2.7268802506433643
676.9000000000088,218.60500020881028,-3.2235912639967514,-2.738449213590843
678.0000000000089,218.9725721599001,-3.2213045558896174,-2.750916880853997
679.1000000000089,219.3471409048249,-3.2219388913903613,-2.760704185439401
680.2000000000089,219.71916684493863,-3.2142996450203847,-2.7731199362620096
681.3000000000089,220.0994548111917,-3.208404787443387,-2.7852191464456144
682.400000000009,220.47265375640774,-3.1927896947783547,-2.7975627496952393
683.500000000009,220.84563520230373,-3.1714078149929277,-2.8060532685112887
684.600000000009,221.21138506956817,-3.1448680942893996,-2.818095049753251
685.700000000009,221.5823941296603,-3.1010165308698348,-2.827736309988433
686.800000000009,221.94575045251332,-3.0262698070092378,-2.8368959947416514
687.9000000000091,222.3062033024392,-2.8768849946021606,-2.8437385789668257
689.0000000000091,222.66265854668612,-2.757059645823581,-2.8450721007140567
690.1000000000091,223.0300078509957,-2.742156762019606,-2.8450301736059442
691.2000000000091,223.40214809822893,-2.7373440975356926,-2.846351198667065
692.3000000000092,223.7700860873993,-2.7375239569458962,-2.8466799400270815
693.4000000000092,224.1488218441143,-2.740101370900353,-2.8456897136071797
694.5000000000091,224.51917000000174,-2.7393899999990268,-2.8473046976337617
695.6000000000091,224.88594994774596,-2.743917985292047,-2.8481098049646425
696.7000000000091,225.25621557602776,-2.744642813359224,-2.847772209534054
697.8000000000092,225.6334759735901,-2.7504488974197154,-2.848759701999439
698.9000000000092,226.00764085667274,-2.758049144480588,-2.8481142655262395
700.0000000000092,226.37679233943635,-2.761608353592604,-2.8497600412827016
701.1000000000092,226.75574554877673,-2.7655602784795756,-2.8496499999744653
702.2000000000093,227.12504870082896,-2.7686830374678704,-2.851086939265814
703.3000000000093,227.4950113966114,-2.7724953537270145,-2.849969283014914
704.4000000000093,227.87359019646567,-2.776387731955987,-2.849969844973719
705.5000000000093,228.2446860381813,-2.783125271012369,-2.850960069999609
706.6000000000093,228.6177216479967,-2.784529473387929,-2.850999459949021
707.7000000000094,228.9924258604607,-2.789170249644866,-2.8522800342300534
708.8000000000094,229.37029151779055,-2.7933940798387926,-2.85239004195222
709.9000000000094,229.74123238801425,-2.7973983574406374,-2.8534308332544702
711.0000000000093,230.1131755955429,-2.7982001289049836,-2.8530477541960453
712.1000000000093,230.49048767423514,-2.802123803654195,-2.854027892473553
713.2000000000094,230.86097530524572,-2.8032248902238646,-2.852709959606143
714.3000000000094,231.23524644015092,-2.8125152729276786,-2.853370109914069
715.4000000000094,231.6068074479592,-2.8168344669468075,-2.8563401479694615
716.5000000000094,231.9798077458077,-2.8218379758379997,-2.8553450618367675
717.6000000000095,232.35377141497816,-2.826070088566101,-2.855870027976149
718.7000000000095,232.72653735632025,-2.832940169335169,-2.855679956547499
719.8000000000095,233.094039836552,-2.8366946499815753,-2.8569899999940698
720.9000000000095,233.4673301836299,-2.841046724440721,-2.855679975311702
722.0000000000095,233.84132719785228,-2.8426957614195514,-2.856999893401775
723.1000000000096,234.21476943135764,-2.8460035247216915,-2.85822318847214
724.2000000000096,234.58823134365082,-2.8524970950223505,-2.8576594093879173
725.3000000000096,234.96136602543916,-2.856963328830469,-2.8593101650060397
726.4000000000096,235.33539118093344,-2.859935242889916,-2.8604090995533413
727.5000000000097,235.70524288926143,-2.8630730322883915,-2.8589754228783733
728.6000000000097,236.083891976421,-2.868861533550357,-2.859960557964
729.7000000000096,236.45954743728487,-2.8748196570338433,-2.861249647708803
730.8000000000096,236.83334364389262,-2.87589099082925,-2.861611212307679
731.9000000000096,237.20643302888251,-2.8805984538580063,-2.8625930589412762
733.0000000000097,237.5800927513867,-2.883280378029416,-2.863259923887984
734.1000000000097,237.94829563223902,-2.8850490333818746,-2.863759854747501
735.2000000000097,238.32850993307514,-2.8905483375746974,-2.862269070292672
736.3000000000097,238.70476786829005,-2.8952407594877836,-2.8645702015968624
737.4000000000098,239.07204867952518,-2.89744658933705,-2.8655606376373823
738.5000000000098,239.44738287491006,-2.902495919575198,-2.865560132477467
739.6000000000098,239.81624078956744,-2.906359692158411,-2.865890095000391
740.7000000000098,240.19036443611645,-2.906736040496402,-2.865889998183126
741.8000000000098,240.5660853416528,-2.9135246657629996,-2.866220064735095
742.9000000000099,240.94244347214303,-2.9151489801115416,-2.8662162688700836
744.0000000000099,241.3137722186104,-2.9194269702524416,-2.8675427357643857
745.1000000000099,241.68846389980988,-2.9232824865268165,-2.867927344720491
746.2000000000098,242.06620289418092,-2.926221846386474,-2.8688599621910216
747.3000000000098,242.43773555294888,-2.9283720379209623,-2.8701699550494437
748.4000000000099,242.81156156903526,-2.930450502543058,-2.868200106844478
749.0000000000099,243.0175316391633,-2.932615970258846,-2.869520210256626