File: 01_Data/Cardboard/STA/N2/30K_min/Cardboard_STA_N2_30KData_230922_R3.csv
##Temp./Â°C,Time/min,DSC/(mW/mg),Mass loss/mg
41.0,10.550414357626128,-2.367671433893466,-0.034095640648922565
42.100000000000016,10.74652505869371,-2.3382512387595797,-0.03547629169630051
43.20000000000003,10.872650325788724,-2.3172723986465797,-0.03742259056758046
44.30000000000005,10.969214151136041,-2.299507361180177,-0.03907882631599913
45.40000000000006,11.053255458579326,-2.2856712469506766,-0.037025802447505196
46.50000000000008,11.12745525577678,-2.2700408794835156,-0.038740652400162556
47.600000000000094,11.195839000316715,-2.257010776834956,-0.0376110223137176
48.70000000000011,11.259351760533686,-2.2432083087452543,-0.03957527004902506
49.800000000000125,11.3188212208605,-2.2305251262626324,-0.039449217668789505
50.90000000000014,11.375814422723218,-2.2187178722402936,-0.03995818441060095
52.000000000000156,11.42985588679378,-2.2106481110477714,-0.03995116984484204
53.10000000000017,11.482178698255627,-2.2002358813506766,-0.041031136808798774
54.20000000000019,11.532970193091343,-2.190421770841625,-0.041200128633057
55.3000000000002,11.580949418964027,-2.1828254643880505,-0.04087164649599195
56.40000000000022,11.62962603120437,-2.175774103304123,-0.04006999679375056
57.500000000000234,11.676308387206594,-2.1719482341596255,-0.041075073251968686
58.60000000000025,11.72221020809462,-2.1641000444486305,-0.04171832341879522
59.700000000000266,11.76717665467293,-2.1608549155583887,-0.042334163386212875
60.80000000000028,11.811644650235397,-2.1556813625594566,-0.04344599854075737
61.9000000000003,11.854766013064014,-2.1530219622279447,-0.041929076176277835
63.00000000000031,11.898041666775779,-2.150715356379353,-0.04202754078802462
64.10000000000034,11.940829008331503,-2.1493314923333067,-0.04279463420961305
65.20000000000034,11.982599390592114,-2.149109431008938,-0.04462251954118779
66.30000000000035,12.024033746342358,-2.1482977681794253,-0.04691328305705911
67.40000000000038,12.065085781604111,-2.1481909122884275,-0.0461446249779911
68.5000000000004,12.106322258290987,-2.1496654551582774,-0.045578321010631306
69.6000000000004,12.14722362996318,-2.1511744307858955,-0.047734401774220725
70.70000000000041,12.187295394080715,-2.1554310056673582,-0.04932204011092001
71.80000000000044,12.227570147062057,-2.156847516716475,-0.0506129054036486
72.90000000000046,12.267720059048118,-2.1596855329244695,-0.051820362723789426
74.00000000000047,12.306656438962104,-2.1651191505674845,-0.05200375783414657
75.10000000000048,12.346963735976791,-2.1700340374444393,-0.05334664632563202
76.2000000000005,12.386726005881265,-2.1740957304510355,-0.05441022057947542
77.30000000000052,12.426064393418367,-2.1788760845938846,-0.054860535722998094
78.40000000000053,12.464927749067767,-2.1826266215799808,-0.05640335127338503
79.50000000000054,12.503627694019611,-2.1899882326328517,-0.056334181501700886
80.60000000000056,12.542949797943782,-2.1954962236205438,-0.05633664670764693
81.70000000000059,12.581274991415633,-2.1995467774617063,-0.056215363885197434
82.8000000000006,12.620070000099881,-2.203656504820192,-0.05631825064399498
83.9000000000006,12.658240912918172,-2.2089791824044633,-0.056488959101105074
85.00000000000063,12.696428597527621,-2.212432938476928,-0.05631863299728668
86.10000000000065,12.734553673209309,-2.2168651139211044,-0.05748368651529612
87.20000000000066,12.772799065787154,-2.2196776682853847,-0.06042640927896503
88.30000000000067,12.810104324398903,-2.2238540763645904,-0.06046676220282565
89.40000000000069,12.848258600629519,-2.225868431246482,-0.061814696531130586
90.50000000000071,12.885243537765342,-2.227184052031158,-0.06443127600491083
91.60000000000072,12.923021612112757,-2.228750434623963,-0.06436852170433127
92.70000000000073,12.960357190224071,-2.228630005620038,-0.06707596670909721
93.80000000000075,12.997565338527101,-2.2290246162020564,-0.06706943077862082
94.90000000000077,13.034889852435056,-2.2279240662360995,-0.06934166170629297
96.00000000000078,13.07172869035408,-2.2244947563762576,-0.06971326200632122
97.10000000000079,13.108874608427223,-2.2232919789248964,-0.0723481260739649
98.20000000000081,13.145414729317219,-2.220731926685302,-0.0723458519058604
99.30000000000084,13.182266493266406,-2.214783377194211,-0.0748507442578017
100.40000000000084,13.219419722440005,-2.2084885049080865,-0.07497888349989124
101.50000000000085,13.256169892206533,-2.2032533777338514,-0.0762156115000816
102.60000000000088,13.292599118547455,-2.1962336683765233,-0.07729200906344502
103.7000000000009,13.329397609141433,-2.187235028584675,-0.0772960777192031
104.8000000000009,13.365992354713521,-2.179593440543168,-0.07857302043173053
105.90000000000092,13.401771468506203,-2.170022431168864,-0.07938856172371267
107.00000000000094,13.438402761543488,-2.1581325180365747,-0.08026429677220648
108.10000000000096,13.474145691891502,-2.1486398069273234,-0.0816560425993802
109.20000000000097,13.510769722193345,-2.1380899286326205,-0.08157089103535897
110.30000000000098,13.54766355543709,-2.1256102819707134,-0.08354486652457505
111.400000000001,13.583988240117186,-2.114287440499856,-0.08420963330172748
112.50000000000102,13.620462554372553,-2.100546395502523,-0.08421121622617855
113.60000000000103,13.656218700242498,-2.0848123127787943,-0.08550826698416669
114.70000000000104,13.692506870666323,-2.072129415291042,-0.08772737981178524
115.80000000000106,13.728482968824899,-2.057612199273964,-0.08817206930374955
116.90000000000109,13.764708815431923,-2.0428648779250818,-0.08947784247391954
118.0000000000011,13.800782943134092,-2.0280076753362657,-0.08945842130151194
119.1000000000011,13.83653115932858,-2.0142647977836368,-0.09080605427420041
120.20000000000113,13.87247782716702,-2.000632165317271,-0.09165401798158745
121.30000000000115,13.908413418387395,-1.9855381003716464,-0.09211085216879367
122.40000000000116,13.944484577958224,-1.9692342688076587,-0.09206655977180933
123.50000000000117,13.980062415364932,-1.955751306140562,-0.0934295636318705
124.60000000000119,14.015819217549184,-1.9376237762891415,-0.09345814993837287
125.70000000000121,14.051530089218343,-1.9251876291097405,-0.09474463738653416
126.80000000000122,14.086892006840126,-1.9106915050548083,-0.09473713605193756
127.90000000000123,14.122745700938207,-1.8949305102808807,-0.09604688596334743
129.00000000000125,14.158117773229572,-1.8844860526103453,-0.09608206133621522
130.10000000000127,14.193743792845174,-1.8689329178064369,-0.09702143966801113
131.2000000000013,14.22840669058985,-1.8576120072067324,-0.09704646767993763
132.3000000000013,14.264085049257524,-1.844407663720718,-0.09840678720789553
133.4000000000013,14.299416443208782,-1.8320593937415057,-0.0983730089305368
134.50000000000134,14.334756134681609,-1.8194363339034194,-0.09708509570071522
135.60000000000133,14.36990783038799,-1.8094102837950259,-0.09706015747627772
136.70000000000135,14.405079035842725,-1.7972223793751791,-0.09571355967461503
137.80000000000138,14.440374234389497,-1.7880758086056123,-0.09605056202372886
138.9000000000014,14.475008147862109,-1.7771987538537752,-0.09619121169095646
140.00000000000142,14.510222313717392,-1.7651459472081843,-0.09749723918694109
141.10000000000142,14.545206955742486,-1.757568538883898,-0.09878694642613706
142.20000000000144,14.580272917500345,-1.7480433931899868,-0.09879965466343688
143.30000000000146,14.614187681290588,-1.7395563213238818,-0.10020758004908314
144.40000000000146,14.649842818094507,-1.7296209213082934,-0.10012003459831575
145.50000000000148,14.684861206249844,-1.7220559169810987,-0.10012006972289678
146.6000000000015,14.719316799845409,-1.7172237050466475,-0.10012008420198892
147.70000000000152,14.75395468509501,-1.7101460430802682,-0.10012282945585893
148.80000000000155,14.788442195176787,-1.703755808545466,-0.09959253491792053
149.90000000000154,14.823265452955331,-1.6968945567335487,-0.10001741068911496
151.00000000000156,14.857555880311873,-1.692234658184948,-0.10011834912165263
152.1000000000016,14.892519135583873,-1.6875738850180455,-0.10012044437843493
153.20000000000158,14.926871396746696,-1.6825685810761102,-0.10009448748675887
154.3000000000016,14.961503067701699,-1.6761426804077388,-0.09880565885131887
155.40000000000163,14.995146078005734,-1.672992922796091,-0.09880997464777508
156.50000000000165,15.03075592685357,-1.6692424487445643,-0.09880987024387355
157.60000000000167,15.064557484836458,-1.6645942183213218,-0.09880986989795204
158.70000000000167,15.099142437138347,-1.660184315288935,-0.09880987234860861
159.8000000000017,15.133750795472428,-1.6573402402096429,-0.09881065696913982
160.9000000000017,15.168256961086747,-1.6549823368992935,-0.09999063186332702
162.0000000000017,15.20223132411516,-1.6538221061788154,-0.10011913332691824
163.10000000000173,15.236767826197891,-1.6488970216761802,-0.1004535848357424
164.20000000000175,15.271025990671363,-1.6454996698581992,-0.10143934814995248
165.30000000000177,15.305532230896247,-1.6426756168569394,-0.10144067117153321
166.4000000000018,15.339790356663281,-1.6393600136077024,-0.10112734654561217
167.5000000000018,15.373838157136682,-1.6389354068149595,-0.10012321313628192
168.6000000000018,15.407831234136818,-1.6380503029987237,-0.10013156936040879
169.70000000000184,15.442562770658903,-1.6352733716588546,-0.10032937924791918
170.80000000000183,15.476600070813605,-1.6344794662169342,-0.10143858253613036
171.90000000000185,15.511077577455382,-1.6321835762620958,-0.10144017943121764
173.00000000000188,15.545035199109646,-1.6296102148803338,-0.10144018622301054
174.1000000000019,15.579003891266062,-1.6284535657498247,-0.10144018599918558
175.20000000000192,15.613065186108445,-1.6271222168942563,-0.10144018599997562
176.30000000000192,15.647138206345234,-1.6249301057110002,-0.10144018600001559
177.40000000000194,15.681351601872525,-1.6256699481083725,-0.10144018599924332
178.50000000000196,15.71550109667142,-1.6232980086225763,-0.10144018589689008
179.60000000000196,15.749340888245785,-1.6221278387984766,-0.10144019619501732
180.70000000000198,15.78356438345779,-1.6213011319036772,-0.10144035644725857
181.800000000002,15.817513903685997,-1.6202524011598407,-0.10221725557896555
182.90000000000202,15.85130141919099,-1.619258361539341,-0.10276321190107884
184.00000000000205,15.885053484773632,-1.6170335906583968,-0.102760211971479
185.10000000000204,15.919047351275946,-1.6180537195631977,-0.10276019125173619
186.20000000000206,15.952871697540978,-1.617339264431129,-0.10276009599375335
187.3000000000021,15.98671351808943,-1.615041280501321,-0.10272126341043641
188.40000000000208,16.020504755849934,-1.614485158296348,-0.10183717645641188
189.5000000000021,16.054275446804233,-1.614983141387171,-0.10274515098068049
190.60000000000213,16.088102065815836,-1.6125561097899281,-0.10276020072249548
191.70000000000215,16.121562550599428,-1.6147169608428291,-0.10276188989701218
192.80000000000217,16.15507798355716,-1.613184685205522,-0.10411354929448091
193.90000000000217,16.188713176417018,-1.6125132632678658,-0.10407933932803903
195.0000000000022,16.222565166029533,-1.6119946576546347,-0.10428065472450765
196.1000000000022,16.256029967259455,-1.611540591071947,-0.10539842581615
197.2000000000022,16.28955602866393,-1.6106962430110099,-0.10539997326037343
198.30000000000223,16.322446149620596,-1.6103010455654918,-0.10540003476620408
199.40000000000225,16.35678622991801,-1.6090850888831825,-0.1053931650720683
200.50000000000227,16.39026849578781,-1.608678093433696,-0.10641224325912679
201.6000000000023,16.4239525397563,-1.608520067587828,-0.10672033881321896
202.7000000000023,16.45749638710319,-1.607279245591386,-0.1067200244612434
203.8000000000023,16.491218997153872,-1.6080185322941247,-0.10672771872208786
204.90000000000234,16.524440650147874,-1.6072139038918942,-0.10639773327595003
206.00000000000233,16.55781358470757,-1.6074597754253064,-0.10648316328655616
207.10000000000235,16.591449131650325,-1.6095745062092917,-0.10539494046318998
208.20000000000238,16.624964711481468,-1.6064014851099317,-0.10540010877083406
209.3000000000024,16.65825996217195,-1.607272532758135,-0.10539976181799604
210.40000000000242,16.69182765966344,-1.6074039548803236,-0.10538037677527035
211.50000000000242,16.725152409388862,-1.6067530499175262,-0.10676664103852707
212.60000000000244,16.758718166398737,-1.6062345551308277,-0.10671961964555221
213.70000000000246,16.791647695784263,-1.6075501404320809,-0.10671985846068699
214.80000000000246,16.8253204781521,-1.606516912807914,-0.10671986208980533
215.90000000000248,16.858690492036715,-1.6069256961702254,-0.10671986199732197
217.0000000000025,16.892330599898383,-1.6060217395143095,-0.10671986167468406
218.10000000000252,16.92524313773644,-1.6051929401903142,-0.10671989803684179
219.20000000000255,16.95916552012481,-1.6048047103179697,-0.10671904214819827
220.30000000000254,16.992742948306468,-1.6054530868374797,-0.10800294852207992
221.40000000000256,17.02547876534848,-1.6047255607020376,-0.10802359343851498
222.5000000000026,17.059127263613963,-1.60362263540459,-0.10894261372424774
223.60000000000258,17.092557004341923,-1.605052192341049,-0.10935058288498345
224.7000000000026,17.125700374831784,-1.6044079582702002,-0.10935005893525629
225.80000000000263,17.15900780639509,-1.6035133873199265,-0.10935012616813156
226.90000000000265,17.192117719013957,-1.6027614977445694,-0.10935967632806998
228.00000000000267,17.224893206803088,-1.6025036607817558,-0.110584367400405
229.10000000000267,17.25882004126195,-1.6007594572440185,-0.11068417986626455
230.2000000000027,17.292236061056865,-1.6010093245084105,-0.1119987834249323
231.3000000000027,17.32516160676589,-1.601137380459475,-0.1119372174555644
232.4000000000027,17.358429006656564,-1.6000415648202917,-0.11331531916131965
233.50000000000273,17.39155225129964,-1.5991293028477667,-0.11330035247177861
234.60000000000275,17.425140878440924,-1.599084975777837,-0.1132996875708896
235.70000000000277,17.458313308011373,-1.5994046534549433,-0.11332016727564298
236.8000000000028,17.491341955378534,-1.5976499314765358,-0.11462302931281876
237.9000000000028,17.52440064476507,-1.5973380785030666,-0.11461573047907248
239.0000000000028,17.557984332292136,-1.595608605941211,-0.1149375023299446
240.10000000000284,17.591108393305745,-1.5971045785443954,-0.11494526863429222
241.20000000000283,17.624191088083705,-1.5963802084007674,-0.1157206435179039
242.30000000000285,17.657552018144823,-1.595575025362882,-0.1162700193233488
243.40000000000288,17.69081340939985,-1.5929561840391089,-0.11698756375588548
244.5000000000029,17.72400015477041,-1.5916517594317656,-0.11758562705204278
245.60000000000292,17.757076755822926,-1.590211121909391,-0.11767484097290293
246.70000000000292,17.790391050956696,-1.5893045189103339,-0.11888747904220409
247.80000000000294,17.823356160556713,-1.5869655047075342,-0.12064940930053814
248.90000000000296,17.856662667422814,-1.5865328509860213,-0.12196740547317919
250.00000000000296,17.889718915667366,-1.58542278736989,-0.12339045664675474
251.10000000000298,17.923068181946235,-1.5830189812179452,-0.12340727658326411
252.200000000003,17.956199006494867,-1.583290467066169,-0.1246754147788236
253.30000000000302,17.98918577967632,-1.5817721843363834,-0.12530304112169954
254.40000000000305,18.02277831891003,-1.5822591522529261,-0.12626226020803344
255.50000000000304,18.055541220976906,-1.5798672577225579,-0.12812792434960585
256.6000000000031,18.08867797588986,-1.5804258834141591,-0.12995514843074396
257.7000000000031,18.1219343735818,-1.5799666281792157,-0.13137139948772525
258.8000000000031,18.154993391291896,-1.578030630902343,-0.1329297479158349
259.9000000000031,18.188253822436018,-1.5796289963820451,-0.13468325755674648
261.0000000000031,18.22114807357117,-1.5757199032313496,-0.1343805344043112
262.10000000000315,18.254537741925176,-1.5737979341498993,-0.1350456046125137
263.2000000000032,18.287620269958186,-1.573939773606248,-0.139681923733332
264.30000000000314,18.3205382654885,-1.5733741471366895,-0.14197682564702063
265.40000000000316,18.353869994504734,-1.5711028018288884,-0.14394685172911892
266.5000000000032,18.386848298632064,-1.5697898529042336,-0.14586330948560544
267.6000000000032,18.41950869024017,-1.569409920906165,-0.14837892067915526
268.70000000000323,18.452183505239223,-1.5684359599757252,-0.150992366966205
269.80000000000325,18.486030234055256,-1.5674532710174216,-0.15313363859486673
270.9000000000033,18.51943644100343,-1.565903541196228,-0.15451644283448074
272.0000000000033,18.552653278984018,-1.5651482846523008,-0.1572367758091251
273.1000000000033,18.585609538527905,-1.5645957035819569,-0.1605263019803127
274.20000000000334,18.618124050186402,-1.5628960993719767,-0.16229595000966013
275.30000000000337,18.650986382838582,-1.5626991741772507,-0.16304953402511657
276.40000000000333,18.684995377773348,-1.5614132267570546,-0.1666345863687244
277.50000000000335,18.717909660373266,-1.5604268153430558,-0.1694550910912036
278.6000000000034,18.750972736201547,-1.5600166526085495,-0.17352474929643869
279.7000000000034,18.78430120659139,-1.558453495029994,-0.17730042695623682
280.8000000000034,18.817478220952957,-1.559103984959463,-0.17954162071002644
281.9000000000034,18.85058878413522,-1.5584360853159487,-0.18388709755621502
283.0000000000034,18.883817453813702,-1.5565731386460577,-0.189316156508482
284.10000000000343,18.916783400604707,-1.5573871515435167,-0.19310887213251338
285.20000000000346,18.950310058028517,-1.5546390325314614,-0.19902705024713052
286.3000000000035,18.98337745554928,-1.5556908052499614,-0.2031730734424766
287.4000000000035,19.01644133520703,-1.556541373857156,-0.20762867302586585
288.5000000000035,19.049969268557774,-1.5546317977384514,-0.21264471535688
289.60000000000355,19.08290049244842,-1.5538650953090882,-0.21788514297968176
290.70000000000357,19.116221569154167,-1.5542968173361884,-0.2229096205144887
291.8000000000036,19.149298463169366,-1.5536357082336902,-0.2267047497855308
292.9000000000036,19.182737920461904,-1.5521011811583987,-0.23279080960150722
294.0000000000036,19.21606073673445,-1.5535705300552152,-0.2392609393264622
295.1000000000036,19.249327467184425,-1.5557039990980706,-0.2444502586856463
296.2000000000036,19.282618907374754,-1.5546670527755806,-0.25253367101000146
297.30000000000365,19.315869396392102,-1.5544071026276995,-0.25987293252674615
298.4000000000037,19.349303166588424,-1.5559929659399483,-0.2662686028623864
299.5000000000037,19.38214297577901,-1.5546136689145489,-0.27389804322388134
300.60000000000366,19.415695823772012,-1.5558480636992542,-0.2791456652812281
301.7000000000037,19.44918885799172,-1.5578593256668645,-0.2834435079631006
302.8000000000037,19.48206172439252,-1.5581889042229908,-0.29109334764230965
303.90000000000373,19.51564928538045,-1.5594073357090972,-0.30450139317726066
305.00000000000375,19.549070198612764,-1.5608093617043626,-0.3153765393736161
306.1000000000038,19.582641916930463,-1.5630650255404623,-0.3247225307794963
307.2000000000038,19.615604780558968,-1.5656080235025212,-0.33442606025536703
308.3000000000038,19.649183420279922,-1.5683155188821873,-0.3430462352830852
309.40000000000384,19.682468305136968,-1.5707237919976529,-0.3527004398660889
310.5000000000038,19.715859362804512,-1.5772943978763787,-0.3633326599925568
311.60000000000383,19.749542976596697,-1.5780557188902988,-0.37390236832219514
312.70000000000385,19.782526044412382,-1.5834694664583282,-0.38458198086441175
313.8000000000039,19.81609948335514,-1.5874012927080916,-0.39711691798455595
314.9000000000039,19.849273295855784,-1.592108923285458,-0.4099783149366001
316.0000000000039,19.882961846256848,-1.5967589785368501,-0.4234911109439614
317.10000000000394,19.916261098101995,-1.6032804512630923,-0.4361472938868305
318.2000000000039,19.95006072230129,-1.608146370715366,-0.44915969355360597
319.30000000000393,19.983546168480846,-1.6134718164470292,-0.46434462143269606
320.40000000000396,20.016986286720932,-1.6200444182308134,-0.4785523942574095
321.500000000004,20.050179293258786,-1.6240168255272758,-0.4928944051968034
322.600000000004,20.083940489193623,-1.6306754141024815,-0.506875126261392
323.700000000004,20.117403560271566,-1.638200660050469,-0.5211188697113034
324.80000000000405,20.150950514211594,-1.6458226951305976,-0.535178931358562
325.90000000000407,20.184212658526807,-1.651407124908762,-0.5516817411191939
327.0000000000041,20.218028915387357,-1.659597188633768,-0.5688525219825284
328.10000000000406,20.251608835895823,-1.6670023443994142,-0.5857890466155675
329.2000000000041,20.28501967490087,-1.6736420955051208,-0.6032050222398446
330.3000000000041,20.31869441759389,-1.6813552677500008,-0.6208924227560293
331.4000000000041,20.35235632193699,-1.6895998919289188,-0.6398804888001437
332.50000000000415,20.385742096974706,-1.6959599140667185,-0.6590508741176984
333.6000000000042,20.4196235471113,-1.7055487292886546,-0.678285337755105
334.7000000000042,20.453582554102105,-1.7128758202571834,-0.699616973737085
335.80000000000416,20.48706942363444,-1.7209417453828497,-0.7201452528380847
336.9000000000042,20.520700686093072,-1.7295082052622615,-0.7393058584937919
338.0000000000042,20.55452029967543,-1.7396446600185678,-0.7580892508070596
339.10000000000423,20.58822303070552,-1.7468330052490626,-0.7828333477065952
340.20000000000425,20.621661044539692,-1.7580047500834282,-0.8076324447785628
341.3000000000043,20.655454208183823,-1.7697438287407343,-0.8314124205915698
342.4000000000043,20.68924576006355,-1.7787877217499426,-0.8560631373485168
343.5000000000043,20.723198931055588,-1.791143595377655,-0.8805140203543225
344.60000000000434,20.756638239147627,-1.8032383764339546,-0.9047138147532063
345.7000000000043,20.790563565859202,-1.8155287056840963,-0.9300747683947197
346.80000000000433,20.82424165864185,-1.829959074038493,-0.9564242859608605
347.90000000000435,20.85850639633014,-1.8449492515766432,-0.984660670746925
349.0000000000044,20.8922329851454,-1.859092510894757,-1.0133314361502297
350.1000000000044,20.926188277090308,-1.8740949430472968,-1.041494136364029
351.2000000000044,20.959408453821307,-1.8892381388359698,-1.0688430327868406
352.30000000000445,20.994139612186803,-1.9083736302397267,-1.1013243239149317
353.4000000000044,21.027834901062402,-1.9259918922195858,-1.1318090239795526
354.50000000000443,21.06171636791047,-1.945513864314051,-1.1640029296026926
355.60000000000446,21.095967469102924,-1.9656694812425972,-1.1978336112169852
356.7000000000045,21.130124031186586,-1.9863004503927213,-1.2325412208211626
357.8000000000045,21.164266347893015,-2.0074344740620598,-1.2667310224568213
358.9000000000045,21.19806810053167,-2.030522339014817,-1.3009470401729084
360.00000000000455,21.232174363210888,-2.055107833448717,-1.3371134814558063
361.10000000000457,21.2662130950021,-2.0775231487465913,-1.374240361496772
362.2000000000046,21.30051059605631,-2.102971108201892,-1.4129528179794408
363.30000000000456,21.334760820605673,-2.1261617546209877,-1.453376422473137
364.4000000000046,21.36902472481385,-2.150174369364509,-1.4930532383788844
365.5000000000046,21.40297290688353,-2.1738973787933755,-1.532530084048143
366.6000000000046,21.43735920268809,-2.1960243976564335,-1.5739165838509215
367.70000000000465,21.47152278415183,-2.2189647298435724,-1.6163744219124037
368.8000000000047,21.505799407413996,-2.239869440898468,-1.6599795526942551
369.9000000000047,21.539841224434536,-2.2583497749814985,-1.7044391237307424
371.00000000000466,21.5740287231243,-2.2739745137242564,-1.7512718287871718
372.1000000000047,21.608122448084384,-2.2845799453928226,-1.7979399593847893
373.2000000000047,21.64233358858417,-2.291600812393202,-1.8405768138395011
374.30000000000473,21.676022284562546,-2.295425987341011,-1.883583435715952
375.40000000000475,21.710369116752084,-2.293135631923157,-1.9346041638037192
376.5000000000048,21.744169138937632,-2.2817319877624556,-1.9834131038423775
377.6000000000048,21.77778875260598,-2.2666373653272487,-2.0303632080717575
378.7000000000048,21.811702257394842,-2.2408024574460974,-2.0781354756943795
379.80000000000484,21.845064883663593,-2.2091103703802863,-2.12168992121001
380.9000000000048,21.878707734684994,-2.168244961615595,-2.1634703819890806
382.00000000000483,21.912169635276594,-2.122192060267734,-2.2060448542481077
383.10000000000485,21.945590322821435,-2.0636785404983664,-2.247078355663149
384.2000000000049,21.979011762791462,-2.0025002522534665,-2.2862277463386143
385.3000000000049,22.01247319998518,-1.9345578493874522,-2.3251691577413443
386.4000000000049,22.04501656487604,-1.8631780495763428,-2.3584993880222753
387.50000000000495,22.078346689354404,-1.7868730250414,-2.3887521889268433
388.6000000000049,22.11125653931694,-1.7108429126894407,-2.417967516176866
389.70000000000493,22.14458935007125,-1.6350169995830541,-2.4461424211872576
390.80000000000496,22.177475789036663,-1.5582429080578415,-2.471916424673123
391.900000000005,22.21070717281546,-1.48559442660802,-2.4948179331489837
393.000000000005,22.243988907189035,-1.4145056165343537,-2.5136364835646208
394.100000000005,22.277184844786095,-1.3481972285964106,-2.5323251269312936
395.20000000000505,22.310449536450182,-1.2856026133670573,-2.548721453219998
396.30000000000507,22.343742907763215,-1.2266726637472831,-2.5633222732482945
397.4000000000051,22.377287179384272,-1.1686095400287657,-2.5766130679117243
398.50000000000506,22.410670943233434,-1.1167160498806576,-2.587703995951463
399.6000000000051,22.44401673672814,-1.0668095807759979,-2.597183906608489
400.7000000000051,22.477899490889488,-1.0199156418848176,-2.6071801821919953
401.8000000000051,22.51111314453399,-0.9771596559155942,-2.6160442279546925
402.90000000000515,22.544296561395672,-0.9397895853551265,-2.6233170143829074
404.0000000000052,22.57871232057502,-0.9047350413962996,-2.6300176849053614
405.1000000000052,22.61245772833107,-0.8748798663863345,-2.6347788241842593
406.20000000000516,22.646335365863493,-0.8474280285135894,-2.6404006799717203
407.3000000000052,22.680241853359764,-0.8256662571533828,-2.6447122838135186
408.4000000000052,22.714468740613928,-0.8049958266640675,-2.6487545304944318
409.50000000000523,22.74837666787059,-0.7902487872567493,-2.6526241140705102
410.60000000000525,22.782396211534618,-0.772127667544555,-2.655297506050485
411.7000000000053,22.816635527951075,-0.7594369344689477,-2.658800950012698
412.8000000000053,22.85062906179862,-0.75322916126538,-2.6622052549798836
413.9000000000053,22.884646845119903,-0.7418706005219569,-2.664716426656165
415.00000000000534,22.918934393967156,-0.7340330613953698,-2.668479601979334
416.1000000000053,22.95322290407209,-0.7264457014880027,-2.671659065274896
417.20000000000533,22.98754713240922,-0.7194905015989793,-2.6750278925826745
418.30000000000535,23.02177741357025,-0.7129280395270015,-2.6779425883068444
419.4000000000054,23.056217877685544,-0.707943444653714,-2.681090128533543
420.5000000000054,23.090602315293246,-0.7041677313552637,-2.6854895750995604
421.6000000000054,23.12495385574838,-0.6968786201585703,-2.6876956882968446
422.70000000000545,23.159350272030363,-0.6942782702668582,-2.69084200937625
423.8000000000054,23.19363416293568,-0.6909931054652055,-2.6940359932767883
424.90000000000543,23.227837788229827,-0.6860143053117336,-2.696440149765041
426.00000000000546,23.262275740505466,-0.6818399322114946,-2.700183135379403
427.1000000000055,23.296707918710723,-0.6774506564584041,-2.7037504777101056
428.2000000000055,23.331020366408605,-0.6759975714018014,-2.7067519533236406
429.3000000000055,23.365558379713384,-0.6730536839714314,-2.709244624528513
430.40000000000555,23.399872836005773,-0.6705561483230311,-2.7125192753989067
431.50000000000557,23.434465557762124,-0.6705269378129689,-2.715397663154709
432.6000000000056,23.46926766729354,-0.668014168977924,-2.7181020542460206
433.70000000000556,23.503489886540674,-0.6652517762592991,-2.7208041410364388
434.8000000000056,23.538018727576763,-0.6664819307310088,-2.72390218635417
435.9000000000056,23.572974646461734,-0.6672488499283212,-2.727824758207024
437.0000000000056,23.607331629379097,-0.666415953701094,-2.729013331046252
438.10000000000565,23.641830998079453,-0.6656383669118257,-2.73254114679437
439.2000000000057,23.676263956325833,-0.66660800407827,-2.735106606567319
440.3000000000057,23.711109724508304,-0.666773065407359,-2.738388593930563
441.40000000000566,23.745699482155175,-0.6692196510075268,-2.7405348919914143
442.5000000000057,23.780315338232043,-0.6710652406187193,-2.7439443153974032
443.6000000000057,23.815097526839473,-0.6731273294798672,-2.745649763087628
444.70000000000573,23.849711507944296,-0.675056181712569,-2.74774178608373
445.80000000000575,23.88440591671905,-0.6797697273036462,-2.750415667908603
446.9000000000058,23.91909154007782,-0.6822724407340544,-2.753195241593357
448.0000000000058,23.95392094698959,-0.6835322721553895,-2.7566167969486366
449.1000000000058,23.988697596013253,-0.6881816377930858,-2.76077398728654
450.20000000000584,24.023529518162583,-0.6937017092522225,-2.7638624688505624
451.3000000000058,24.058153132495534,-0.6992661648946578,-2.7668898431547846
452.40000000000583,24.09304167451805,-0.7052608780688319,-2.768917327026495
453.50000000000585,24.127972265199645,-0.7111676549372689,-2.771587502701847
454.6000000000059,24.1627260291488,-0.7175365721633775,-2.772761142751185
455.7000000000059,24.19772124569568,-0.7222111244700954,-2.774960259311478
456.8000000000059,24.23218429057089,-0.728332708531209,-2.778493134696805
457.90000000000595,24.26726236358795,-0.7387354489599677,-2.7802765537183527
459.0000000000059,24.302407773499798,-0.7419649116720634,-2.782860601028733
460.10000000000593,24.337050317597818,-0.7484037951418192,-2.7854091638048035
461.20000000000596,24.37204983137193,-0.756239942254361,-2.787725007389141
462.300000000006,24.40717430828801,-0.7619888937793462,-2.789988022873662
463.400000000006,24.441985995633566,-0.7705283998159402,-2.792003343070206
464.500000000006,24.476770089878286,-0.7762016661740737,-2.793773065869471
465.60000000000605,24.511889280111795,-0.7843250673111424,-2.794929442385088
466.70000000000607,24.546793314198325,-0.7906025877731309,-2.796732770515682
467.8000000000061,24.58181396419848,-0.7967002604354805,-2.799164728186165
468.90000000000606,24.61677028232138,-0.8048991066714348,-2.80200371000508
470.0000000000061,24.65195063190028,-0.8131320311848771,-2.8036917302336715
471.1000000000061,24.68681989680646,-0.8203787808748327,-2.8064714518912766
472.2000000000061,24.722009204475007,-0.8278818131776626,-2.8084477928688596
473.30000000000615,24.757127327248725,-0.8340942052174494,-2.810751906261743
474.4000000000062,24.792189512980467,-0.8400091628309851,-2.8131003680168556
475.5000000000062,24.82730927281045,-0.8478485559287384,-2.8148183652356003
476.60000000000616,24.86256296316604,-0.8534355946665895,-2.81853513074031
477.7000000000062,24.897158743544324,-0.8590106410864973,-2.820264786026879
478.8000000000062,24.932733684233625,-0.8667397896797007,-2.8230217050427413
479.90000000000623,24.9681067191041,-0.8748451030289347,-2.8241354792600797
481.00000000000625,25.003054845592082,-0.8791911628205571,-2.824890070179442
482.1000000000063,25.038331625098376,-0.8852841853858944,-2.826670384433764
483.2000000000063,25.07367774935781,-0.8925143611081902,-2.828167831604425
484.3000000000063,25.1088832380409,-0.9000948659731832,-2.8293838248709458
485.40000000000634,25.144102380970104,-0.905080521285038,-2.8325145945680865
486.5000000000063,25.178990560899763,-0.9146584791846996,-2.8353732671133565
487.60000000000633,25.214322327220007,-0.9179885421421823,-2.836626449726621
488.70000000000636,25.249617966004728,-0.9228601516005139,-2.8388884246587507
489.8000000000064,25.284896440856752,-0.929571841367177,-2.8402154365302272
490.9000000000064,25.320312903598424,-0.935477172795978,-2.840204380844208
492.0000000000064,25.355349641531514,-0.9401533768244231,-2.84163142210471
493.10000000000645,25.3906646539113,-0.9461750795199487,-2.8434379203760116
494.2000000000064,25.425403622572908,-0.9520834985766738,-2.844590345027724
495.30000000000643,25.461167225613984,-0.9562834973175136,-2.846745226053029
496.40000000000646,25.496665480812354,-0.9609410218833869,-2.84820874528348
497.5000000000065,25.532411229568446,-0.9653558046484226,-2.849453823267992
498.6000000000065,25.567221667540856,-0.9713124370516171,-2.850714691311948
499.7000000000065,25.602173650972233,-0.9753025376988228,-2.851908797033463
500.80000000000655,25.63798927678868,-0.9811901200544612,-2.8547751001047743
501.90000000000657,25.67348003966324,-0.9856172365461703,-2.8566017498601464
503.0000000000066,25.7087876769857,-0.9898512470019399,-2.8581112593010958
504.10000000000656,25.743988837978407,-0.994776058742136,-2.859357977780949
505.2000000000066,25.77961376297229,-0.9995252927714076,-2.860859637543711
506.3000000000066,25.814756653550564,-1.003445754108035,-2.8622837519446356
507.4000000000066,25.850162873374384,-1.0083695510520434,-2.8638077698609488
508.50000000000665,25.88558016596979,-1.0136051177295804,-2.865080830410651
509.6000000000067,25.92089439990452,-1.016167942698114,-2.8651609956046062
510.7000000000067,25.95658305065454,-1.0218320456706458,-2.8664557514383167
511.80000000000666,25.991611415999788,-1.0224850293345236,-2.8678655115602485
512.9000000000067,26.027393701638836,-1.0292672432735481,-2.869214551178243
514.0000000000067,26.062844230144997,-1.0327139904874076,-2.870081565508829
515.1000000000067,26.098277389396962,-1.0373681813389042,-2.870441356577171
516.2000000000068,26.133728140725943,-1.0402218077767533,-2.8719733346700793
517.3000000000068,26.169264981008034,-1.044082859312173,-2.8740483698657906
518.4000000000068,26.204420500868466,-1.0484131570008575,-2.8762916377904584
519.5000000000068,26.240031147636653,-1.0486576671602603,-2.876431706928214
520.6000000000068,26.27556207084311,-1.0559149124758713,-2.877725770677004
521.7000000000069,26.31126881036998,-1.0607604994022188,-2.8790700059395293
522.8000000000068,26.34646645094472,-1.0620619735853192,-2.8801801214042793
523.9000000000069,26.381977573424543,-1.0643419273761467,-2.881231528924917
525.0000000000068,26.417494273428495,-1.0690464437121006,-2.883023503673898
526.100000000007,26.453175412388504,-1.0755943231083855,-2.8839184930652624
527.2000000000069,26.48863764977485,-1.07724760204533,-2.88521172929578
528.300000000007,26.52430318869758,-1.08404379546128,-2.886311354278398
529.4000000000069,26.560097759851644,-1.084971127286648,-2.8867834946407047
530.5000000000069,26.595499382456097,-1.0918558437467631,-2.886699754403823
531.600000000007,26.63099260099928,-1.0968396824382638,-2.888054090318742
532.700000000007,26.666607478675658,-1.1005962618550034,-2.8894951950009062
533.800000000007,26.701502152091454,-1.108845640454209,-2.89147276097027
534.900000000007,26.737728006227357,-1.1184797948624097,-2.893143373185001
536.000000000007,26.773183423152787,-1.1263563894352735,-2.8937763602671036
537.1000000000071,26.808937755499368,-1.1344500094024765,-2.895012070546949
538.2000000000071,26.844615450349128,-1.1426780078050736,-2.8956807171064263
539.300000000007,26.879693331425777,-1.1504482982224793,-2.8970688888898084
540.4000000000071,26.915675735234068,-1.157672731743091,-2.8983342726067804
541.500000000007,26.951425614432555,-1.1655889441704677,-2.898393136412728
542.6000000000072,26.987129547871767,-1.1714871125769846,-2.8984783991120047
543.7000000000071,27.023076644906105,-1.178782133964791,-2.898387702119109
544.8000000000072,27.058442854340687,-1.1839775182937493,-2.8989042701638894
545.9000000000071,27.094479360265744,-1.188476455718495,-2.900122725857471
547.0000000000072,27.13000000000023,-1.194000000000041,-2.90255581368433
548.1000000000072,27.165458714588322,-1.1982080579046803,-2.904007739530507
549.2000000000072,27.20102640583433,-1.202177067368841,-2.9043117410956887
550.3000000000072,27.236910270286668,-1.2087396603560894,-2.905628448352716
551.4000000000073,27.272791033845103,-1.2151339197890778,-2.9071092582356712
552.5000000000073,27.308615524642608,-1.21888030605222,-2.908363851308091
553.6000000000073,27.34415119496007,-1.224220446238312,-2.909695169567163
554.7000000000073,27.37996727403987,-1.2295884839044495,-2.9108005196898814
555.8000000000073,27.41575682017868,-1.2353888109615492,-2.912119580526735
556.9000000000074,27.45147891226063,-1.239829430481114,-2.912107701837451
558.0000000000074,27.487227939081322,-1.2474654766378526,-2.913475225936611
559.1000000000074,27.522933201099015,-1.2520781091119098,-2.9149630422966806
560.2000000000073,27.558604977144984,-1.2578717774954313,-2.9149150632744054
561.3000000000073,27.594304130712118,-1.2605523721386969,-2.9149072179670923
562.4000000000074,27.630560692492548,-1.2643711806439584,-2.9163098897968522
563.5000000000074,27.666194398855968,-1.2681523549765195,-2.9175926170816004
564.6000000000074,27.702312149292226,-1.2716616473956066,-2.918915803371838
565.7000000000074,27.73800245177657,-1.27626336476484,-2.9208578603135864
566.8000000000075,27.7731076357082,-1.2812655663277166,-2.920614662478731
567.9000000000075,27.80963863915674,-1.2813112443257728,-2.919358538988405
569.0000000000075,27.845462683774816,-1.2870098491963555,-2.920981477058869
570.1000000000075,27.88131159403275,-1.28877180981203,-2.922604270407205
571.2000000000075,27.917229065070156,-1.2910563445991459,-2.9239702813387978
572.3000000000076,27.95283169889824,-1.2912823882542428,-2.924868197878352
573.4000000000076,27.989075660957052,-1.2929255920396723,-2.9252908616448883
574.5000000000076,28.02510033995531,-1.2934588415495003,-2.9255588040774203
575.6000000000076,28.060740925705332,-1.2947050663826956,-2.926584991277579
576.7000000000077,28.09662772508838,-1.2997969673399272,-2.927279972486926
577.8000000000077,28.132798418237034,-1.3006458415363007,-2.927270645554576
578.9000000000076,28.168604411947527,-1.3032577023470828,-2.9272378642440104
580.0000000000076,28.204710664317865,-1.3059802285924629,-2.9286779632172264
581.1000000000076,28.240598870668776,-1.3091117792988267,-2.929737498954333
582.2000000000077,28.276481664672318,-1.3113406669621448,-2.929923320806561
583.3000000000077,28.312496546354446,-1.3133003518890463,-2.9313373100469025
584.4000000000077,28.34865225014048,-1.3143134768615128,-2.9320387149756293
585.5000000000077,28.38475431160924,-1.3183065202663529,-2.931991411979818
586.6000000000078,28.42091791823542,-1.320537450591267,-2.9334713907808387
587.7000000000078,28.4567848928656,-1.3240421621618186,-2.93446596705395
588.8000000000078,28.49286489870126,-1.326938991385242,-2.9356117080091826
589.9000000000078,28.529082675579634,-1.3303205871484287,-2.9360289922176968
591.0000000000078,28.565022517478965,-1.3334366813856915,-2.9373462572056814
592.1000000000079,28.60113065571619,-1.3373550659290872,-2.937357551895592
593.2000000000079,28.63730597490926,-1.338935782302702,-2.93660841450342
594.3000000000079,28.67355484964468,-1.3441298201408316,-2.93738435984731
595.4000000000078,28.709605210837033,-1.3471896245171897,-2.9386769626812677
596.5000000000078,28.745424118858878,-1.3488324271271201,-2.9392024825443333
597.6000000000079,28.78174108863643,-1.3541403264798804,-2.940009457185596
598.7000000000079,28.817818189458414,-1.3576319384548416,-2.941307699863052
599.8000000000079,28.85398841144445,-1.3624371296132198,-2.941277240307029
600.9000000000079,28.890367634277833,-1.363503963209425,-2.9426370671711464
602.000000000008,28.926275692815263,-1.3669623360114118,-2.942631976891715
603.100000000008,28.962813851644686,-1.3709653015953374,-2.9439369713458876
604.200000000008,28.99860569005125,-1.3750191989269012,-2.9451782557351365
605.300000000008,29.035004424748607,-1.376146967599535,-2.945269284490887
606.400000000008,29.071596187804793,-1.3793290325699459,-2.9453309309022186
607.5000000000081,29.1074542024911,-1.3865170134867224,-2.946583199162969
608.6000000000081,29.143734618522387,-1.389155044157717,-2.946592931022338
609.7000000000081,29.17999966701867,-1.3919499367096932,-2.9475812485033934
610.8000000000081,29.216199651161894,-1.3958903282577588,-2.9475885796788885
611.9000000000082,29.252424028635343,-1.4016464041738685,-2.9479148534265587
613.0000000000082,29.288314247321335,-1.4044556122621972,-2.948934614316026
614.1000000000081,29.32504206328899,-1.4119406412908997,-2.9491664762646863
615.2000000000081,29.360912872197776,-1.4128439071507095,-2.9502115144125582
616.3000000000081,29.397463347447584,-1.4152134536794938,-2.9502328116537315
617.4000000000082,29.433606387543172,-1.422758442319194,-2.951534821898375
618.5000000000082,29.46974230971561,-1.4260211387862198,-2.952966871050067
619.6000000000082,29.506292583607575,-1.4305454659942367,-2.9543214835158484
620.7000000000082,29.54271856548247,-1.437738374649146,-2.95567395461699
621.8000000000083,29.579145158867668,-1.4412921331602413,-2.9565029515863133
622.9000000000083,29.614767808256534,-1.4474602684149858,-2.9569727403338244
624.0000000000083,29.651709207121012,-1.4532861998817468,-2.955923336025327
625.1000000000083,29.688295946754835,-1.4580883436717404,-2.9561242934880463
626.2000000000083,29.724401448455055,-1.464076545815982,-2.957253128000864
627.3000000000084,29.76096843287493,-1.4709051820076862,-2.9561910872875004
628.4000000000084,29.7973585408581,-1.4771729244898701,-2.9576021949708418
629.5000000000084,29.833789672880332,-1.4845114435108007,-2.9578841893620402
630.6000000000083,29.870302568956827,-1.4918881934065678,-2.9590090002478173
631.7000000000083,29.906452925424702,-1.4977253470414824,-2.961365968029147
632.8000000000084,29.94308431863296,-1.5019292442743581,-2.9613007125576285
633.9000000000084,29.979506118674145,-1.5102342605708827,-2.9613001995670496
635.0000000000084,30.01554106780413,-1.516103933381422,-2.9613273311752177
636.1000000000084,30.052001661200794,-1.521241908550977,-2.962624863491877
637.2000000000085,30.088786355754543,-1.5290607164895107,-2.962316545620678
638.3000000000085,30.124591491155307,-1.5337686801592834,-2.9635384266379465
639.4000000000085,30.161546741784758,-1.5380627415752053,-2.96359457611723
640.5000000000085,30.197778211981355,-1.5443135722964219,-2.9649424879102444
641.6000000000085,30.23441607454519,-1.5497843846802841,-2.9649201850677365
642.7000000000086,30.27078250172311,-1.555263096803103,-2.9649218381817355
643.8000000000086,30.307342043262064,-1.5610145247717298,-2.9661220364353937
644.9000000000086,30.343819631498352,-1.5690709375227547,-2.9662405103879435
646.0000000000086,30.380163689438536,-1.5763500283298513,-2.9662497599852395
647.1000000000087,30.416462782160693,-1.583168876379619,-2.967666903495647
648.2000000000087,30.453285294968175,-1.5895748006140864,-2.967670003149133
649.3000000000086,30.48945890548054,-1.5996852192185638,-2.9676736634687364
650.4000000000086,30.52578934543245,-1.607010024323889,-2.9708138025437627
651.5000000000086,30.562660567393575,-1.6178046255591465,-2.972282076888524
652.6000000000087,30.599211770026887,-1.625261094845279,-2.97359470944866
653.7000000000087,30.635971135759434,-1.6350628335459954,-2.9748597285876266
654.8000000000087,30.672339844356916,-1.6431794182278936,-2.974909773374132
655.9000000000087,30.7087408760218,-1.653230006608053,-2.97490992343064
657.0000000000088,30.745328270406517,-1.6633211122644347,-2.974902859127863
658.1000000000088,30.781986003766885,-1.67532719523146,-2.9759915452060097
659.2000000000088,30.81826379212516,-1.684157009121725,-2.9762410658826077
660.3000000000088,30.854867181886046,-1.6945347953995273,-2.976230134115113
661.4000000000088,30.891593430828284,-1.7057320419228557,-2.9762391785047644
662.5000000000089,30.928159781576205,-1.714984474462776,-2.9775402030204527
663.6000000000089,30.964406764741028,-1.7259744071279886,-2.977509618520793
664.7000000000089,31.001045589961524,-1.7369191462099378,-2.977550655926772
665.8000000000088,31.037953869083395,-1.7470766843437062,-2.9783291811597614
666.9000000000088,31.074110934956625,-1.7595111025105696,-2.978881359020031
668.0000000000089,31.11091252956071,-1.771889416279038,-2.9801832887345876
669.1000000000089,31.14724631152357,-1.7851698627235772,-2.9803289779078534
670.2000000000089,31.1838099854809,-1.793134466965206,-2.981502034563186
671.3000000000089,31.2207140069133,-1.8034191759736986,-2.9825376773587755
672.400000000009,31.257083327634103,-1.8113720409632506,-2.9828103258894814
673.500000000009,31.29376247365913,-1.8230951839270628,-2.9828171257803975
674.600000000009,31.330370650173734,-1.8348200237115129,-2.981511708199989
675.700000000009,31.36713456142086,-1.844517254314197,-2.982689615403208
676.800000000009,31.40360303158143,-1.85220391551752,-2.983517459671866
677.9000000000091,31.44033222454914,-1.864038397179709,-2.9841410236775077
679.0000000000091,31.476738913723608,-1.8705473927474519,-2.985456515408954
680.1000000000091,31.51352214265375,-1.8765420601300389,-2.9868378017510606
681.2000000000091,31.550169592114266,-1.8833410982809349,-2.989723684577166
682.3000000000092,31.58661256431182,-1.8900174823716127,-2.9911769670016666
683.4000000000092,31.623058493437316,-1.8944035283539598,-2.992231140022752
684.5000000000091,31.659675217177725,-1.8998623886270343,-2.9908304426034946
685.6000000000091,31.696453760683582,-1.90331800782947,-2.9911800911620583
686.7000000000091,31.733064168855048,-1.9039629684482033,-2.992664959601619
687.8000000000092,31.7696308189687,-1.9062751858102946,-2.994025564808527
688.9000000000092,31.80669016383373,-1.9058017474173372,-2.9940446026015968
690.0000000000092,31.842914579189646,-1.9056934527546892,-2.99534417218442
691.1000000000092,31.87950065924752,-1.9030602889703208,-2.9959488710704036
692.2000000000093,31.916155864148422,-1.8991298347553465,-2.9966660651317527
693.3000000000093,31.95267487755687,-1.8977058360341212,-2.998000910713389
694.4000000000093,31.98938336366884,-1.8886167293454605,-2.9966467303307485
695.5000000000093,32.02595688580232,-1.8813787307533505,-2.99792428417879
696.6000000000093,32.06201433409783,-1.874709896165776,-2.99910036341591
697.7000000000094,32.098258873119505,-1.8659689000842408,-2.999291069710646
698.8000000000094,32.13584444165286,-1.8538208779620253,-2.999607593699842
699.9000000000094,32.17212198092014,-1.8448921008571126,-3.000599604693284
701.0000000000093,32.20894827233273,-1.8353298347605682,-3.001938580377442
702.1000000000093,32.24515970572227,-1.8241037100864492,-3.002801991129389
703.2000000000094,32.28207260657745,-1.8120424864720157,-3.003235048094209
704.3000000000094,32.3188112217411,-1.8007365734762206,-3.004096968030561
705.4000000000094,32.35535437834666,-1.7970202130354154,-3.006449837537165
706.5000000000094,32.391949075743774,-1.7922239748993762,-3.007110345939618
707.6000000000095,32.42852790559318,-1.7900423629837299,-3.0056539783145526
708.7000000000095,32.46527966976311,-1.7889832025828711,-3.0043410533552413
709.8000000000095,32.5021382458082,-1.7898714763832826,-3.0043298260465177
710.9000000000095,32.53891061872508,-1.7932460719139036,-3.0043386004362738
712.0000000000095,32.57560088698417,-1.7952363620250158,-3.004975188215474
713.1000000000096,32.61212877163341,-1.798227320645905,-3.0049934189125613
714.2000000000096,32.648865826395046,-1.7997383813319932,-3.005058285962514
715.3000000000096,32.685605975868896,-1.8059704820518059,-3.0076304784088292
716.4000000000096,32.72270694212281,-1.8057608108085224,-3.006535402622978
717.5000000000097,32.75911044753766,-1.81045170866793,-3.006307323834645
718.6000000000097,32.79610876427286,-1.8139878245981913,-3.0075926009399705
719.7000000000096,32.83288316432171,-1.8181380826253453,-3.0087982558434447
720.8000000000096,32.8696929595926,-1.8237698100784474,-3.0089444851977865
721.9000000000096,32.906586176000864,-1.8275068702390362,-3.010263654733449
723.0000000000097,32.94348266281107,-1.831637752903846,-3.010256837957547
724.1000000000097,32.98026154819697,-1.8318985839490323,-3.0109304510813732
725.2000000000097,33.01715239855592,-1.8384598439175008,-3.01091923781057
726.3000000000097,33.05418568828656,-1.8442410004337402,-3.0109202284256718
727.4000000000098,33.09095337354092,-1.845617505068652,-3.010929569434628
728.5000000000098,33.12773986313661,-1.849464760567667,-3.009579418350178
729.6000000000098,33.16395814233872,-1.8524857671636965,-3.0095998687296404
730.7000000000098,33.201757528266654,-1.8568538675080934,-3.0096007558326714
731.8000000000098,33.23826943306176,-1.8605055460387891,-3.0095248838891435
732.9000000000099,33.275183988196666,-1.8668952868492634,-3.0106946244789055
734.0000000000099,33.312453877935006,-1.8708357791395158,-3.0110808681148558
735.1000000000099,33.3490952595187,-1.873532219783952,-3.012592158538325
736.2000000000098,33.38642004516915,-1.8761710654974002,-3.01390036712979
737.3000000000098,33.4228038636526,-1.882124600045146,-3.0152936778218455
738.4000000000099,33.46006691117673,-1.8841604740929982,-3.0152100260428703
739.5000000000099,33.497101283967204,-1.8925274691520368,-3.0151240962566743
740.6000000000099,33.533646109726,-1.897365991133767,-3.0150696608609007
741.7000000000099,33.57079064205061,-1.9008080748618954,-3.01651895909103
742.80000000001,33.60779082967185,-1.90533601690711,-3.016474495316227
743.90000000001,33.64467277064613,-1.9083095759787012,-3.017826707115097
744.00000000001,33.647900476838906,-1.909108562151737,-3.0178343914401