File: 01_Data/Cardboard/STA/N2/30K_min/Cardboard_STA_N2_30KData_230920_R1.csv
##Temp./Â°C,Time/min,DSC/(mW/mg),Mass loss/mg
28.200000000000003,15.453145724847174,-2.3458792605833625,-0.031538250214071084
29.30000000000002,15.71017062120304,-2.3066846065388846,-0.0410602038046175
30.400000000000034,15.850465114755808,-2.288533671463977,-0.039903423353425005
31.50000000000005,15.95228405800374,-2.2752284851814624,-0.0368349001422823
32.600000000000065,16.041093217072156,-2.2634665606105275,-0.0398278430078598
33.70000000000008,16.117733807271506,-2.2566426398384474,-0.04045094810676453
34.8000000000001,16.186569449546987,-2.2461231357876184,-0.04130658886812455
35.90000000000011,16.25159213344482,-2.237870166434646,-0.04042443653736871
37.00000000000013,16.31176487302797,-2.2309400360453773,-0.040563710210512305
38.10000000000014,16.37026393989778,-2.2231771267875704,-0.04055320662640849
39.20000000000016,16.425230360417064,-2.216071582199112,-0.041622932412369806
40.300000000000175,16.47801872084853,-2.208428063935241,-0.04193576372560592
41.40000000000019,16.528921326581198,-2.202983587446,-0.042084713585055944
42.500000000000206,16.578334762148103,-2.1988166644051814,-0.043603462299484974
43.60000000000022,16.627763862008205,-2.1948024916898343,-0.04361240646782516
44.70000000000024,16.674966685180397,-2.189525130062789,-0.04482622693859817
45.80000000000025,16.72271698912988,-2.1872678311668348,-0.045205978897215005
46.90000000000027,16.767493307813712,-2.185176218329474,-0.045861144596268666
48.000000000000284,16.813059358700666,-2.184075768247241,-0.04519359235374587
49.1000000000003,16.856857510398264,-2.183029047466376,-0.04599024946655739
50.200000000000315,16.901272920021924,-2.1819683469066398,-0.04703577920449664
51.30000000000033,16.94431964667899,-2.184468761380602,-0.04825861289301958
52.40000000000035,16.98784704857274,-2.186498020557918,-0.0473556818887495
53.50000000000036,17.030196484213334,-2.189034655967897,-0.04903856414207031
54.60000000000038,17.07179807939807,-2.191548428067771,-0.04772284137157534
55.700000000000394,17.113770733433906,-2.19455877253253,-0.04959879020632396
56.80000000000041,17.155310622422416,-2.201286774320576,-0.053806922136219626
57.900000000000425,17.196702862213865,-2.2076025844449934,-0.05397628456675374
59.00000000000044,17.23714375954535,-2.212045455904611,-0.053531007405904774
60.100000000000456,17.278216656016674,-2.2193873695585697,-0.053683694682214345
61.20000000000047,17.31795826960571,-2.2273299894551553,-0.05504711559309605
62.30000000000049,17.358559536743726,-2.23797050648967,-0.05704736699203661
63.4000000000005,17.399309622883848,-2.2472161091147864,-0.05768803273268741
64.50000000000051,17.438726255540036,-2.256933622351306,-0.059237123859309015
65.60000000000053,17.477921699262467,-2.2679155754255107,-0.060149725378773944
66.70000000000056,17.51734777222834,-2.27746580841407,-0.061590230736863205
67.80000000000057,17.55633066250434,-2.2865923018036414,-0.06307314009194265
68.90000000000057,17.596123845537054,-2.298796844449979,-0.06455303034959226
70.0000000000006,17.63566129508956,-2.3086499346528333,-0.06582078804018465
71.10000000000062,17.674652518102413,-2.3197556076309738,-0.06718124725189423
72.20000000000063,17.713793678021407,-2.332654252773736,-0.0675680107297234
73.30000000000064,17.752284917464287,-2.344058148749726,-0.06859989121673671
74.40000000000066,17.791155119096228,-2.3547916270403983,-0.07110253451777471
75.50000000000068,17.830288203275423,-2.362148683411723,-0.07251606549782963
76.60000000000069,17.86935326713335,-2.3725517707105563,-0.07397692087658925
77.7000000000007,17.908023455353636,-2.382692690449921,-0.07583436457683934
78.80000000000072,17.946479715297052,-2.39081685557859,-0.07806359452372114
79.90000000000074,17.98428873852506,-2.399480405365276,-0.08012698796919882
81.00000000000075,18.0229324518084,-2.405753215277172,-0.08169419638085529
82.10000000000076,18.060984400332373,-2.4119610263207627,-0.08308658280659831
83.20000000000078,18.099512919408266,-2.417109125362321,-0.08477328239959547
84.30000000000081,18.137215829491968,-2.4221435044288637,-0.0872868999887988
85.40000000000082,18.175229261783972,-2.4250551209821087,-0.08869984382232055
86.50000000000082,18.2126878595417,-2.429129391501114,-0.09012068031803366
87.60000000000085,18.250525633709188,-2.430675786287274,-0.09171676166529519
88.70000000000087,18.288205393652053,-2.4286910005032087,-0.09436045830315187
89.80000000000088,18.324828259684626,-2.427720492010183,-0.09617165242251247
90.90000000000089,18.36279057970792,-2.4240761689468857,-0.09802802835999191
92.00000000000091,18.399556743554637,-2.422372391535587,-0.10137808876039678
93.10000000000093,18.43642210763232,-2.4153714173896046,-0.10365312066209764
94.20000000000094,18.473493293011327,-2.4091545101487397,-0.10504934542518951
95.30000000000095,18.51053172976558,-2.40238802216242,-0.10763175281015736
96.40000000000097,18.547088386803605,-2.3921214777411435,-0.1096856983836294
97.500000000001,18.58421764011156,-2.3828005577799583,-0.11176063608890408
98.600000000001,18.62059383344965,-2.3723710516563488,-0.11208486329449396
99.70000000000101,18.657118808928747,-2.3610418792556467,-0.11344763919959755
100.80000000000103,18.693500180290023,-2.3484951666279463,-0.1161974002877244
101.90000000000106,18.729592727718472,-2.3349293955302626,-0.11745799896509412
103.00000000000107,18.766182387629822,-2.3178623321128016,-0.11952389917738682
104.10000000000107,18.80221787002624,-2.3026036640932506,-0.1202655980848264
105.2000000000011,18.837688894195434,-2.286224785447776,-0.1214318222057873
106.30000000000112,18.87436908584458,-2.266718256926293,-0.12285602708357457
107.40000000000113,18.910033078869997,-2.2486216945787842,-0.12426989352189421
108.50000000000114,18.9462404539654,-2.2297966372452356,-0.12540798373337925
109.60000000000116,18.98223582651175,-2.210092587706946,-0.12664467414968605
110.70000000000118,19.018340617826237,-2.190248845367561,-0.12823601109270033
111.80000000000119,19.05481325969729,-2.169130489258035,-0.12822225551839805
112.9000000000012,19.09081618055644,-2.1478094986441234,-0.13007963145658064
114.00000000000122,19.12654871839886,-2.128720603471425,-0.1325776984486886
115.10000000000124,19.162653255812153,-2.1062650163063545,-0.1330942784426723
116.20000000000125,19.19799096406187,-2.084603713873975,-0.1338509589036878
117.30000000000126,19.233743577011563,-2.063082558944131,-0.1351491050164415
118.40000000000128,19.269438471877873,-2.0404683232031435,-0.13514083816280653
119.50000000000131,19.30487203479076,-2.02097990511028,-0.13596230942429965
120.60000000000132,19.340712336217614,-1.9998820671576067,-0.1377584834086658
121.70000000000132,19.375987399316823,-1.9782785725911236,-0.13777244019447998
122.80000000000135,19.41149641245931,-1.956669419736372,-0.1389772438231791
123.90000000000137,19.446985424022962,-1.9364719871462104,-0.14040740022505682
125.00000000000138,19.481370081190178,-1.9166592787423256,-0.14040930520835637
126.10000000000139,19.51762958658562,-1.8943879723936357,-0.14177883515317946
127.20000000000141,19.552128360500724,-1.8763120587469837,-0.14173044690561065
128.30000000000143,19.588253765996054,-1.8575050353599472,-0.14172460570815515
129.40000000000146,19.623497481592597,-1.839319377111558,-0.14293464039179726
130.50000000000145,19.65849220938933,-1.8219274292109244,-0.1430399665249955
131.60000000000147,19.693486669737847,-1.8050108734187489,-0.14304059421627757
132.7000000000015,19.72838347823882,-1.789580929616313,-0.14407499918491995
133.8000000000015,19.763608194189302,-1.773282687031503,-0.1457799602774119
134.9000000000015,19.7981383671035,-1.756935738033435,-0.14567945858358033
136.00000000000153,19.833034448837918,-1.7441408653039092,-0.14568008315211367
137.10000000000156,19.86798465657656,-1.7297660975322033,-0.14567993734116857
138.20000000000158,19.902909484798673,-1.715457005382583,-0.14565830811117397
139.30000000000157,19.937541891397114,-1.7039868938956295,-0.14600746098742956
140.4000000000016,19.972274877875304,-1.6894714860897724,-0.14612712052879662
141.50000000000162,20.006987384272083,-1.6804823599244991,-0.1473290171141235
142.60000000000161,20.04173276668263,-1.6664058081028963,-0.14733013604434753
143.70000000000164,20.07629109291833,-1.656154296156927,-0.14733014012348056
144.80000000000166,20.111118810271876,-1.6455024604122404,-0.14733014000020184
145.90000000000168,20.14557129836265,-1.636285677460646,-0.14733013999998557
147.0000000000017,20.18018588747183,-1.6267732081757613,-0.14733014000000288
148.1000000000017,20.214674817730828,-1.6190282205354614,-0.14733014000283262
149.20000000000172,20.249129002430998,-1.6100533259821255,-0.14733013987854848
150.30000000000175,20.283702752232543,-1.6061377724779953,-0.14733012012730917
151.40000000000174,20.317992011695175,-1.5977336149202916,-0.1473319685332597
152.50000000000176,20.351529286857556,-1.5913478798798362,-0.1474501710814109
153.60000000000178,20.3861049730987,-1.5856104660191674,-0.14864024268906828
154.7000000000018,20.420877476093498,-1.5803590704447341,-0.14825254584394632
155.80000000000183,20.45526147355823,-1.5747584354276314,-0.14764611687175044
156.90000000000182,20.489594852008217,-1.5687109919928965,-0.14764999549968483
158.00000000000185,20.52388427817116,-1.563129877791032,-0.14764989278483887
159.10000000000187,20.557921946369653,-1.5583207687623661,-0.14765737387486233
160.20000000000186,20.59227864656889,-1.5562183595796704,-0.1465819619180868
161.3000000000019,20.626309386405293,-1.5517746368758092,-0.14666172812204747
162.4000000000019,20.660694027006244,-1.5458771151854915,-0.1466578918881205
163.50000000000193,20.694839996718795,-1.5428370802602365,-0.1476650002282307
164.60000000000196,20.729124115768066,-1.5400695594522147,-0.14825928607171512
165.70000000000195,20.76330285519172,-1.5353288416280977,-0.1489741221219658
166.80000000000197,20.797941892373032,-1.5327134764145536,-0.14908517948743594
167.900000000002,20.831758979973834,-1.5302177023405752,-0.1502914178282455
169.000000000002,20.865613259351193,-1.5255305195908235,-0.1502899034928573
170.100000000002,20.89978931149328,-1.5248360515238437,-0.15029457639318133
171.20000000000203,20.933878015131278,-1.522782395913531,-0.1491509312359196
172.30000000000206,20.96799284331915,-1.5204279449437352,-0.14896970672822052
173.40000000000208,21.00187351510508,-1.5169486720467324,-0.14896957100006114
174.50000000000207,21.035670490315916,-1.5153620343246723,-0.14904164304754186
175.6000000000021,21.069936800710725,-1.5135886004164507,-0.14831023878102512
176.70000000000212,21.103815328747224,-1.511154230555954,-0.14831014008567056
177.80000000000211,21.137914533028926,-1.506786994525345,-0.14831004603779796
178.90000000000214,21.171928476068757,-1.5068752918118313,-0.14830999016862112
180.00000000000216,21.205690007145694,-1.5042479784585667,-0.14826013967063645
181.10000000000218,21.23939242011563,-1.5030284000334422,-0.14896014921069733
182.2000000000022,21.27330785173908,-1.5002270694817346,-0.14896999722432147
183.3000000000022,21.307110983123426,-1.5024578879448525,-0.1489700417481341
184.40000000000222,21.34083114547063,-1.4995759210770778,-0.14897003998991964
185.50000000000225,21.374525347991753,-1.4968811096530017,-0.1489700399998548
186.60000000000224,21.408258937785448,-1.4960880594900487,-0.1489700399988929
187.70000000000226,21.44224941856528,-1.4949321358912007,-0.14897004002742875
188.80000000000229,21.47575806615107,-1.4944154484656296,-0.1489700454906968
189.9000000000023,21.509595550827513,-1.4928390570627847,-0.148969488846042
191.00000000000233,21.542836072399567,-1.4912642292567968,-0.14898330574439678
192.10000000000232,21.576432169297167,-1.4896914554242997,-0.1483107217498767
193.20000000000235,21.610088566474047,-1.489092072595517,-0.14930739669315507
194.30000000000237,21.643805671776587,-1.4868142794689556,-0.1496304683824352
195.40000000000236,21.67727944341011,-1.4850778270578562,-0.14962982371171174
196.5000000000024,21.710184715899214,-1.4845344184721645,-0.14962983040997013
197.6000000000024,21.744288612773452,-1.4838939243481544,-0.14962983890060455
198.70000000000243,21.777730658080344,-1.4829435692300088,-0.14962629258738858
199.80000000000246,21.8115932469941,-1.4805069874367283,-0.15098860394825042
200.90000000000245,21.844731060360505,-1.4805963513023659,-0.15094432830161741
202.00000000000247,21.878637679188945,-1.4790643547076225,-0.15229725675203643
203.1000000000025,21.91209463981717,-1.4775315534020939,-0.15227048889080042
204.2000000000025,21.945431203524713,-1.477541205647653,-0.15227152455772996
205.3000000000025,21.9785956591548,-1.476650397125399,-0.15085993608953796
206.40000000000254,22.012211861729092,-1.4762222800951335,-0.15095058550981255
207.50000000000256,22.045535063907845,-1.4768131028450442,-0.15095003887274272
208.60000000000258,22.079178930571235,-1.4758571497489563,-0.15094995286872948
209.70000000000258,22.112448153601246,-1.4752616713052817,-0.15095242343844983
210.8000000000026,22.146213546468093,-1.4727111004548923,-0.1519930440424706
211.90000000000262,22.179243382595168,-1.4732417487148912,-0.1519389150369599
213.00000000000261,22.21264726927261,-1.4715339691861147,-0.1519467656209179
214.10000000000264,22.246058353217794,-1.4717407426590616,-0.1531169770739762
215.20000000000266,22.279431247485515,-1.4723430479193116,-0.15336026986300277
216.30000000000268,22.31290206984372,-1.4700102780476185,-0.15333204560578473
217.4000000000027,22.346223071845,-1.470702801866332,-0.15472009789692054
218.5000000000027,22.379405488517794,-1.4707730135913804,-0.15467995974769044
219.60000000000272,22.413001471702543,-1.4681765264402569,-0.15467982047845164
220.70000000000275,22.44615212479173,-1.4662501443482685,-0.15477689041444087
221.80000000000274,22.479311094203435,-1.4674343914251458,-0.15599666814705015
222.90000000000276,22.512597268263956,-1.4657155922846283,-0.15599967776283297
224.00000000000279,22.54544789567517,-1.4660420631216673,-0.1559859423691181
225.1000000000028,22.579661567663656,-1.46484909483331,-0.15473943214908026
226.20000000000283,22.612623590873657,-1.4645381931073649,-0.15468071019100194
227.30000000000283,22.645916053236544,-1.4632490592587428,-0.1545220906974123
228.40000000000285,22.679217813468846,-1.4610696863152564,-0.1573253441721434
229.50000000000287,22.712314053901235,-1.4623300205106937,-0.15732005893933776
230.60000000000286,22.745445166371805,-1.459438134251621,-0.15732130611200335
231.7000000000029,22.779095330743047,-1.45750513495127,-0.15856886798728942
232.8000000000029,22.81209856235526,-1.4574408182612546,-0.1586344014403065
233.90000000000293,22.845474980846177,-1.4570214235898313,-0.15971496784452155
235.00000000000296,22.87837307158161,-1.4533989256568052,-0.15995115079493427
236.10000000000295,22.911307419884945,-1.4535691821449734,-0.16040647133282793
237.20000000000297,22.94483753855444,-1.451505348126343,-0.1612767220097564
238.300000000003,22.977838779826612,-1.4490252065592268,-0.1612333640328325
239.400000000003,23.01069016305628,-1.4459927636363163,-0.16166228187730747
240.500000000003,23.044531787821562,-1.4443405509379905,-0.1615984122832148
241.60000000000304,23.077583388091316,-1.4428177634165908,-0.16295933295787446
242.70000000000306,23.110607821187145,-1.443438018236534,-0.16293205344872197
243.80000000000308,23.143851070501654,-1.4409346748980527,-0.1642136711989428
244.90000000000308,23.17704772925981,-1.438814311368047,-0.164637125285223
246.0000000000031,23.210336645128574,-1.4370446436342403,-0.16566250980525954
247.10000000000312,23.243323053192547,-1.4336198487442091,-0.1669419578654776
248.20000000000312,23.276291413188115,-1.4325572333195828,-0.16736302171459227
249.30000000000314,23.30948917820844,-1.4302767385214574,-0.16796947642391746
250.40000000000316,23.342515113229148,-1.4297648891109576,-0.16928419567481923
251.50000000000318,23.376095152044858,-1.4269002689701635,-0.16961497819460503
252.6000000000032,23.408771177494643,-1.4253407027715281,-0.1709290347713992
253.7000000000032,23.441995001959757,-1.4237210897982788,-0.17278813469641774
254.80000000000322,23.475168542042738,-1.4216355632324635,-0.17362865345405432
255.90000000000325,23.508056097368407,-1.421016362705548,-0.17502283079753145
257.00000000000324,23.541384422790856,-1.4209294946312039,-0.17646222462164918
258.10000000000326,23.574618747099517,-1.4191565139996187,-0.178030895268944
259.2000000000033,23.60726789982816,-1.4179687638966467,-0.17970828169493824
260.3000000000033,23.640186991657963,-1.4177323808274938,-0.18124873380523
261.40000000000333,23.673443450772982,-1.4156510493067063,-0.18249844205191934
262.5000000000033,23.70664536676887,-1.4126180701810742,-0.18411105131883598
263.6000000000033,23.739068932877903,-1.413328934393412,-0.18610420677705708
264.70000000000334,23.772013053740103,-1.4110439012425429,-0.18860078713423256
265.80000000000337,23.80548227614892,-1.4097263327598468,-0.1902912268720165
266.9000000000034,23.83895872191766,-1.4074363076960092,-0.19187253407580984
268.0000000000034,23.871471446504746,-1.4080764128018126,-0.1944813224739823
269.10000000000343,23.90506066853511,-1.405333241228918,-0.19674143448961745
270.20000000000346,23.938366138109284,-1.403626420146836,-0.20016781947261464
271.3000000000035,23.971142186057968,-1.4029648698497612,-0.20193055585613662
272.4000000000035,24.004464102093756,-1.402242057290256,-0.20348739779381209
273.5000000000035,24.03761937409984,-1.4024789619552722,-0.20619351450706347
274.6000000000035,24.0700319243852,-1.4009272182772123,-0.2092540167537078
275.7000000000035,24.103763340673357,-1.3999670529847867,-0.21341178203529276
276.80000000000354,24.13689888759436,-1.3989251665746048,-0.21660671549730726
277.90000000000356,24.169939695559442,-1.3976487310805075,-0.21905475221024107
279.0000000000036,24.203203636366013,-1.3946384252354183,-0.2223126059693481
280.10000000000355,24.235997886632493,-1.3952332706612496,-0.22631646639188618
281.20000000000357,24.26926615974954,-1.395151212691769,-0.22993481450537256
282.3000000000036,24.30245576638113,-1.394750017755193,-0.2340253310524072
283.4000000000036,24.335778595772847,-1.3944509992887608,-0.23920241678158982
284.50000000000364,24.36866087246898,-1.3936769989132434,-0.24336125312112777
285.60000000000366,24.40213240619072,-1.3921787379314627,-0.2488477899904158
286.7000000000037,24.434957891942638,-1.3913855145509766,-0.25426336247146875
287.8000000000037,24.46824348767027,-1.3920902846717569,-0.2590807379662152
288.90000000000373,24.501299296260513,-1.390880829110435,-0.2648079011902529
290.00000000000375,24.53432420942685,-1.3912076169919665,-0.2695232433454038
291.1000000000037,24.567668188977876,-1.391086549690294,-0.27424750479212356
292.20000000000374,24.600677734334703,-1.3895688773577475,-0.2806690293473153
293.30000000000376,24.633861157807896,-1.390861417155599,-0.2884551424854065
294.4000000000038,24.666994343416782,-1.3897486575056321,-0.2943464201978463
295.5000000000038,24.700565667465128,-1.3890863089321328,-0.2996279760104916
296.60000000000383,24.733527544607792,-1.390177152485574,-0.30688252005998384
297.70000000000385,24.76668589152683,-1.3892835522936389,-0.3134453770651944
298.8000000000038,24.8001477334581,-1.3898175578536702,-0.32267935179866436
299.90000000000384,24.833252262776302,-1.3890136012212584,-0.3304816053879449
301.00000000000387,24.866366176599698,-1.392305877083177,-0.33889678783400434
302.1000000000039,24.899553112693965,-1.3914493257598977,-0.34908593950131017
303.2000000000039,24.932770122004175,-1.3928891800419467,-0.35713097571254426
304.30000000000393,24.966272592418868,-1.3935023518197724,-0.3656292005433106
305.40000000000396,24.999435598993497,-1.3952743106874481,-0.375392286310694
306.500000000004,25.03203377992408,-1.3988346025241392,-0.38567458054499815
307.600000000004,25.066099534841392,-1.401047468076956,-0.39660204953855205
308.70000000000397,25.09910147898671,-1.4022255590150923,-0.4073023778495921
309.800000000004,25.132632890067867,-1.4064903732275238,-0.4174010071497065
310.900000000004,25.166043180740523,-1.4079490301149367,-0.4284963687962504
312.00000000000404,25.198964781833997,-1.4114407398292241,-0.44020784439630667
313.10000000000406,25.23256059890315,-1.4151415835119134,-0.4516680586227553
314.2000000000041,25.26622827084711,-1.4188520539530831,-0.46490394657738454
315.3000000000041,25.29875028799394,-1.4220656606632733,-0.4786789542900749
316.40000000000407,25.332816242089457,-1.4267694950863874,-0.4922774597586428
317.5000000000041,25.366152068937534,-1.4322355640418647,-0.5062567667427329
318.6000000000041,25.398888512738786,-1.4369725592229374,-0.5191599031501357
319.70000000000414,25.43302056001957,-1.443095079277719,-0.5342448396740451
320.80000000000416,25.466465115839746,-1.4475008581973665,-0.5500275434153936
321.9000000000042,25.499212985348017,-1.4523199758883625,-0.5651905456324795
323.0000000000042,25.533351277381065,-1.458112860638039,-0.5820359733680687
324.10000000000423,25.56672357592508,-1.464725459157955,-0.5976449685346537
325.20000000000425,25.600092706878247,-1.4706928541740796,-0.6141760817163879
326.3000000000042,25.633737493886848,-1.476855140192288,-0.6323897658678934
327.40000000000424,25.66720496310324,-1.483739088899512,-0.6516956950451975
328.50000000000426,25.700825961840312,-1.4889770010367411,-0.6705695939356167
329.6000000000043,25.734282431068,-1.496778379679246,-0.6884565825514763
330.7000000000043,25.76711826746975,-1.5045465021702566,-0.7074705695769214
331.80000000000433,25.800517101314682,-1.5102819487175303,-0.7278408728798214
332.90000000000435,25.83412677872437,-1.518417869603528,-0.7493404810384652
334.0000000000043,25.868116612507592,-1.5250285638632928,-0.7703458542543151
335.10000000000434,25.9012070989653,-1.5339536896727757,-0.7918551476659248
336.20000000000437,25.935153280258756,-1.5424738982862842,-0.8135579188466551
337.3000000000044,25.968704456066096,-1.5504576902111744,-0.8356655369525492
338.4000000000044,26.002267700871478,-1.5588442320226876,-0.8599171415127413
339.50000000000443,26.036148721093245,-1.5679083710661392,-0.8846126724731187
340.60000000000446,26.069939754576676,-1.5769630529245156,-0.9098437462216937
341.7000000000045,26.103405080067944,-1.5864917946036552,-0.9353520479749795
342.8000000000045,26.137250165571853,-1.599915305876823,-0.9612690667800172
343.90000000000447,26.17074566207648,-1.6084733810075649,-0.9869969629800472
345.0000000000045,26.204649820717535,-1.6186498576542185,-1.0137837915135286
346.1000000000045,26.23909941009195,-1.63072592750233,-1.0423039831731713
347.20000000000454,26.27272422219029,-1.6443603309006383,-1.071203643520584
348.30000000000456,26.30690414941466,-1.659365660111592,-1.1017761328281992
349.4000000000046,26.34037616692378,-1.6717776283494006,-1.1322061621080275
350.5000000000046,26.374639169279295,-1.687186679975968,-1.1617506646788738
351.60000000000457,26.408328340664585,-1.704243761401414,-1.1911953096209875
352.7000000000046,26.442557196949572,-1.7196177530604153,-1.2249802677823403
353.8000000000046,26.476393570129282,-1.7369495888151796,-1.2590283819915853
354.90000000000464,26.51021835380355,-1.758320013915936,-1.2936583701342612
356.00000000000466,26.544396792488634,-1.776780003788702,-1.3309001990910692
357.1000000000047,26.577613620094443,-1.796115630553158,-1.3668276652030262
358.2000000000047,26.61144531794598,-1.8148515730507393,-1.4037662268816846
359.30000000000473,26.64583164395685,-1.8394933346885354,-1.4413229050220764
360.40000000000475,26.6802830680152,-1.8610616473316406,-1.4806344023111269
361.5000000000047,26.71440728620331,-1.8824722049640208,-1.5211568301449918
362.60000000000474,26.748674819895307,-1.9052435606691644,-1.5627005438309993
363.70000000000476,26.782853425611524,-1.9269113275570053,-1.6066172894640043
364.8000000000048,26.816895261203776,-1.9504473572862857,-1.6491797029900854
365.9000000000048,26.851158883726665,-1.9715431762045994,-1.6914403617010092
367.00000000000483,26.88512102345885,-1.9940852428120224,-1.73422718269171
368.10000000000485,26.91928446191794,-2.0133589697554317,-1.7804765367028432
369.2000000000048,26.953401415899023,-2.032786222361685,-1.8282047520834928
370.30000000000484,26.98746281297226,-2.047157744351903,-1.8776392124890098
371.40000000000487,27.02154314435961,-2.059622055179588,-1.9273954979742998
372.5000000000049,27.055590245239117,-2.067937004034443,-1.9752315555100433
373.6000000000049,27.089725619129936,-2.072228934643068,-2.0219657039574956
374.70000000000493,27.123639334309654,-2.069812046350096,-2.070668433318885
375.80000000000496,27.15762392037724,-2.062153079463977,-2.120367146006502
376.900000000005,27.19140484564833,-2.0513707827672216,-2.17050300297396
378.000000000005,27.225056946168163,-2.029325654557041,-2.2213746533187884
379.10000000000497,27.258438801024667,-2.001399651110347,-2.2701951762414376
380.200000000005,27.291994981033074,-1.9673171462200096,-2.3148122695655697
381.300000000005,27.325804274987117,-1.9239972679542343,-2.360432379333446
382.40000000000504,27.358882801002114,-1.8748180143678281,-2.404671129918153
383.50000000000506,27.39217493562994,-1.8166397275356996,-2.4480849314670037
384.6000000000051,27.425329633661434,-1.7526008163891094,-2.4902488573907786
385.7000000000051,27.45868655746756,-1.6831678580103377,-2.527798308555166
386.80000000000507,27.491522821823363,-1.6130025959500514,-2.5605835419479375
387.9000000000051,27.524764611947088,-1.541062753916102,-2.5940711624182127
389.0000000000051,27.55779420899936,-1.4680844749025401,-2.6250758746093124
390.10000000000514,27.590974074296167,-1.3926851714622992,-2.6532249725444212
391.20000000000516,27.624128663836878,-1.3210593847967196,-2.6788835049042956
392.3000000000052,27.657228592150418,-1.2527438186980275,-2.7008552396720638
393.4000000000052,27.690431971384953,-1.1876903235199336,-2.7198416183193603
394.50000000000523,27.723765062179243,-1.1247175961527751,-2.738512445236651
395.60000000000525,27.757202990916312,-1.0650447781257164,-2.7556019344361644
396.7000000000052,27.79024236834997,-1.0083659351145038,-2.7700189178559675
397.80000000000524,27.823466792288574,-0.9548602081821019,-2.7838016243289854
398.90000000000526,27.85694825729484,-0.9030564784210902,-2.7955202653002575
400.0000000000053,27.89027431517877,-0.8561083850915793,-2.8056164865109334
401.1000000000053,27.923941692356326,-0.8107670375206043,-2.815453703346476
402.20000000000533,27.95756830186972,-0.7700013874558679,-2.8228713765495748
403.30000000000535,27.991437444411215,-0.7299422309057455,-2.8306203498766895
404.4000000000053,28.02456094298748,-0.6983017634470836,-2.836083634498426
405.50000000000534,28.058268170326237,-0.667541218867334,-2.841813019971454
406.60000000000537,28.092557929022277,-0.6414139150454004,-2.8480023871365248
407.7000000000054,28.125940220643415,-0.6193322354047667,-2.8522435045618355
408.8000000000054,28.159813865971863,-0.6000014910343079,-2.8567611236477077
409.90000000000543,28.193707713314744,-0.5838015479870273,-2.861345956159375
411.00000000000546,28.227817994209513,-0.5704063276410622,-2.8634497674770607
412.1000000000055,28.261914563956427,-0.5577003746389734,-2.867563254151343
413.2000000000055,28.295926581863252,-0.5485205154477493,-2.8718467915992685
414.30000000000547,28.329812290840902,-0.5385753708966158,-2.8758705745680153
415.4000000000055,28.364563524364367,-0.5304473590790896,-2.8787969673539493
416.5000000000055,28.3985695534404,-0.5234001734082846,-2.881278306930293
417.60000000000554,28.432691047593565,-0.5167032296543875,-2.8845505212241354
418.70000000000556,28.467077003533728,-0.5095653254729984,-2.8871185774503205
419.8000000000056,28.501271499956243,-0.5048753522068489,-2.8918116589365797
420.9000000000056,28.535018873781134,-0.5006000833129776,-2.8950565250123628
422.00000000000557,28.5694756242737,-0.4947871580754407,-2.897493946145785
423.1000000000056,28.60412714873058,-0.4917727503632973,-2.8997220199067497
424.2000000000056,28.63831555940926,-0.4872690880632929,-2.9029359866916744
425.30000000000564,28.672649582311013,-0.4831289410554355,-2.9078481670186016
426.40000000000566,28.706946251261233,-0.47890940381634095,-2.910821492164052
427.5000000000057,28.74126647785208,-0.4749636960036876,-2.913939343848474
428.6000000000057,28.774943605944415,-0.47299130803508455,-2.9171825289161086
429.70000000000573,28.81025799007237,-0.4692089267276449,-2.9204758391438257
430.80000000000575,28.844392373788377,-0.466784912785523,-2.9232799714148445
431.9000000000057,28.878742568700503,-0.4653257473429643,-2.9263423929516112
433.00000000000574,28.913533104460807,-0.4606978388706804,-2.9301767507758756
434.10000000000576,28.947816600392457,-0.46101979440754276,-2.933465822901813
435.2000000000058,28.981720882021357,-0.46027560507353593,-2.9353834560820697
436.3000000000058,29.016881350872918,-0.4587962837178823,-2.939628337186666
437.40000000000583,29.05142123636196,-0.45695824409023394,-2.9433111438301935
438.50000000000585,29.086045733825028,-0.45944758167328037,-2.9461621858397034
439.6000000000058,29.120523021222578,-0.45730064847076635,-2.949589194605153
440.70000000000584,29.15503339798909,-0.4601530286618741,-2.952729225294644
441.80000000000587,29.189814376537885,-0.46109825247383207,-2.954910686827215
442.9000000000059,29.22433602325831,-0.4622291892292547,-2.9582496505552043
444.0000000000059,29.25910533690904,-0.46594772648126026,-2.961186625202475
445.10000000000593,29.293561013205377,-0.4679947210673221,-2.9632196301213236
446.20000000000596,29.328321177445197,-0.47128213639989114,-2.9661454192566685
447.300000000006,29.36232170168114,-0.47261876214642673,-2.968870502053801
448.400000000006,29.397674258604656,-0.4785165934193785,-2.971845657594533
449.50000000000597,29.432201533074345,-0.4813095557489786,-2.974336684096701
450.600000000006,29.467092063882905,-0.48323804414757043,-2.977404462874526
451.700000000006,29.50159691443984,-0.48986815467988776,-2.9792184088766946
452.80000000000604,29.536334021201938,-0.49378885463991995,-2.9821796849795996
453.90000000000606,29.57083261815978,-0.4977578553763477,-2.9851214593269972
455.0000000000061,29.605966458184106,-0.5049372995597282,-2.989368144547334
456.1000000000061,29.640725525790486,-0.509458734939711,-2.9923222826816507
457.20000000000607,29.675029104359183,-0.5146778049448213,-2.994692801379514
458.3000000000061,29.7098015807031,-0.5209820103520156,-2.9963346271262434
459.4000000000061,29.74493407140991,-0.5290748463679019,-2.9971113942203385
460.50000000000614,29.78015782029623,-0.5331255024297687,-2.9999454484567947
461.60000000000616,29.814985485075418,-0.5401651076088714,-3.002356498480623
462.7000000000062,29.849840133760498,-0.5472676755074946,-3.0067325516807433
463.8000000000062,29.884528972162023,-0.553829228650362,-3.0085707642140767
464.90000000000623,29.919595232663834,-0.5605523945506592,-3.011518420406549
466.00000000000625,29.95465613029786,-0.5679220450786385,-3.01366567975217
467.1000000000062,29.989454778560088,-0.5743968975063072,-3.0159105290531465
468.20000000000624,30.024033772409947,-0.5813138452443388,-3.018496114409139
469.30000000000626,30.0590985385371,-0.5880650285828911,-3.019919893570605
470.4000000000063,30.094055769146802,-0.5939578390170395,-3.021367497686004
471.5000000000063,30.129206927068246,-0.6000975187073869,-3.023794896622112
472.60000000000633,30.16339272699088,-0.6081124004016637,-3.0262459786029043
473.70000000000636,30.1988235129828,-0.6134696084245929,-3.027919529929571
474.8000000000063,30.23391629905813,-0.6222882282978438,-3.0300190904875124
475.90000000000634,30.2688279612818,-0.6261889237672369,-3.032809591434757
477.00000000000637,30.303998661270626,-0.6302961503944523,-3.034858913989969
478.1000000000064,30.339042742147438,-0.6385853121149699,-3.0360044953033816
479.2000000000064,30.373962795045106,-0.6460573485629246,-3.0375698188819875
480.30000000000643,30.408826136124027,-0.6505427173891991,-3.040565058272589
481.40000000000646,30.44379959816998,-0.6569477419343476,-3.0422384222152914
482.5000000000065,30.479018589145802,-0.6630613269711167,-3.0436986390294303
483.6000000000065,30.514309189962155,-0.6676004142951978,-3.0455754852579533
484.70000000000647,30.549111372058746,-0.673107321648271,-3.0468764249960603
485.8000000000065,30.584067906012866,-0.678766113087263,-3.0487528525640366
486.9000000000065,30.619308246068183,-0.6835073482866896,-3.0516006773520474
488.00000000000654,30.654558800135113,-0.6899845463252656,-3.053102175538858
489.10000000000656,30.689159587373176,-0.6946168851361991,-3.0546453982407114
490.2000000000066,30.72445698953653,-0.6989697970406973,-3.0554489491007746
491.3000000000066,30.75970858966508,-0.7027592111295351,-3.0570061296723594
492.40000000000657,30.794789736327907,-0.7092939212321349,-3.0590174615855403
493.5000000000066,30.829968577125875,-0.7134848867505931,-3.0611868530824697
494.6000000000066,30.865108832401262,-0.7181505552541626,-3.0628071673664943
495.70000000000664,30.90003119866054,-0.7232019661314129,-3.0653261159059637
496.80000000000666,30.935525926490115,-0.7267870812348204,-3.0665846940625032
497.9000000000067,30.9706471276499,-0.7306218866023931,-3.068577982406378
499.0000000000067,31.005683634999105,-0.7372379156534753,-3.070660226083417
500.10000000000673,31.040874806425563,-0.7421950705732832,-3.0718433999056405
501.20000000000675,31.076280377750212,-0.7463440002988115,-3.073349545925037
502.3000000000067,31.111195316580794,-0.7483432559376798,-3.0747977747219224
503.40000000000674,31.146775986296063,-0.75330028193547,-3.0761087968358214
504.50000000000676,31.181870441214674,-0.756043284421541,-3.0779056754829153
505.6000000000068,31.21717319341989,-0.7612554924557607,-3.0783799833485856
506.7000000000068,31.252486064950542,-0.7644295627046266,-3.079269096432112
507.80000000000683,31.28734672609077,-0.7704841774998873,-3.080780603703246
508.90000000000686,31.32268747183602,-0.772478398373506,-3.0833236911523128
510.0000000000068,31.358587516850854,-0.7765829462152765,-3.084676347621497
511.10000000000684,31.393619913139762,-0.7804732513102088,-3.0864982628445903
512.2000000000069,31.428907351284618,-0.7838952707748833,-3.087656803989184
513.3000000000069,31.464083608063515,-0.785401350163672,-3.089014217792731
514.4000000000069,31.49960067922637,-0.7886489240286483,-3.0899236014718334
515.5000000000069,31.534931496143518,-0.7945355385016022,-3.091354373941846
516.600000000007,31.570063491261113,-0.7989435396523613,-3.0920799200275084
517.700000000007,31.605858862830864,-0.8007207792355776,-3.0936752233871125
518.800000000007,31.64099984486164,-0.8049847666799069,-3.0949774301518405
519.9000000000069,31.67634152699637,-0.8075308541361307,-3.096493356506378
521.000000000007,31.711862115639562,-0.8120712019717341,-3.098410740676223
522.100000000007,31.747308744036566,-0.8157249943275812,-3.098550735911572
523.2000000000071,31.782672089679473,-0.8194473501692404,-3.099866442121505
524.300000000007,31.81821616497462,-0.8235402102885669,-3.1011626431042565
525.4000000000071,31.853684265381474,-0.8252389054736109,-3.1026696766271487
526.500000000007,31.8892266743918,-0.831914440754743,-3.1041386890828493
527.6000000000071,31.924536458918926,-0.8336027374373854,-3.1055273945446977
528.7000000000071,31.960512442511565,-0.8377938274641232,-3.1069606693522793
529.8000000000071,31.995790300618854,-0.8420915641027531,-3.1083326247341083
530.9000000000071,32.03147006005576,-0.846158685990809,-3.108392175381697
532.0000000000072,32.06649734035933,-0.8501978556661779,-3.109600818063151
533.1000000000072,32.1023651146808,-0.8568342992996701,-3.1107499183795335
534.2000000000072,32.13798964910808,-0.8638731286119731,-3.111722068322357
535.3000000000072,32.17355879896514,-0.8703687540819004,-3.113004950215063
536.4000000000073,32.209219520402485,-0.8807741732217055,-3.114371734028778
537.5000000000073,32.2448207741599,-0.8861908443286303,-3.115461274700559
538.6000000000072,32.28062042068277,-0.894109688933219,-3.1169745264382036
539.7000000000073,32.31576063330353,-0.9020799479493933,-3.118300580103039
540.8000000000072,32.35170015287911,-0.909499948494324,-3.119638469539634
541.9000000000073,32.387459579914335,-0.9154476603988652,-3.11955694784156
543.0000000000073,32.423122572325966,-0.9222661887090441,-3.121136527328198
544.1000000000073,32.45860999814147,-0.9264259862589276,-3.1225484784801667
545.2000000000073,32.49447502439477,-0.931962906980133,-3.1238507443778225
546.3000000000073,32.53053689721498,-0.9360765043565163,-3.124585460913295
547.4000000000074,32.56601916682027,-0.940907745180435,-3.1251533522500354
548.5000000000074,32.60172862521876,-0.9446873491938705,-3.1263530349362854
549.6000000000074,32.637430483648444,-0.950161386909686,-3.126647183554318
550.7000000000074,32.673465977641314,-0.9549166162484038,-3.126564702642434
551.8000000000075,32.708973922998446,-0.959530174621101,-3.1279502726255637
552.9000000000075,32.74453183675996,-0.9619732463406218,-3.1289840725832647
554.0000000000075,32.7805953423727,-0.9665752470933084,-3.130603946241429
555.1000000000075,32.81640745141727,-0.9733744254734267,-3.1319911579322044
556.2000000000075,32.85226562043611,-0.9782380876122001,-3.1333016418750956
557.3000000000076,32.88787056702152,-0.9818083812831695,-3.1346427471302185
558.4000000000076,32.92388389646754,-0.9866810467077191,-3.1347903235311168
559.5000000000075,32.9594502271087,-0.989733178619528,-3.136057404838747
560.6000000000075,32.994700256922805,-0.9935353302762091,-3.135664665765938
561.7000000000075,33.0305772339119,-0.996391115738251,-3.1370934367618917
562.8000000000076,33.06711746492086,-0.9982712194516387,-3.137576531645202
563.9000000000076,33.10285337944221,-1.0024229336940353,-3.13832300989043
565.0000000000076,33.13891267564106,-1.0058914153927248,-3.1392729243454944
566.1000000000076,33.1746295329807,-1.010070085450834,-3.1404629435034566
567.2000000000077,33.210391797457994,-1.0134865011512408,-3.1417643828640793
568.3000000000077,33.24659335541861,-1.0174665653997594,-3.1416717101309075
569.4000000000077,33.28235535844523,-1.0187213143131482,-3.1430436032679587
570.5000000000077,33.31857896528037,-1.0234284092215846,-3.1445250680570997
571.6000000000078,33.354297509364315,-1.0264328602522266,-3.145298153347738
572.7000000000078,33.39048510381177,-1.0281683718938508,-3.1458297388373753
573.8000000000078,33.42630658574626,-1.0312087578437235,-3.1468307681249272
574.9000000000078,33.46239335387158,-1.0334351700155446,-3.1477326530739074
576.0000000000077,33.49823350960949,-1.0360434715421356,-3.148584008042824
577.1000000000078,33.534401240626494,-1.0394694136504745,-3.1499953448303244
578.2000000000078,33.57031536731483,-1.0423869340807097,-3.149568325712657
579.3000000000078,33.60610781346164,-1.0461606941586035,-3.1507065671321275
580.4000000000078,33.64233225481938,-1.0473409481414817,-3.150900476873103
581.5000000000078,33.67825065159345,-1.049400038376674,-3.15219639306109
582.6000000000079,33.71450673283399,-1.0502441575284833,-3.1530074647068176
583.7000000000079,33.75051480792743,-1.0530234542145407,-3.1535607536728265
584.8000000000079,33.78649262278824,-1.0565214127637526,-3.1547518018324268
585.9000000000079,33.822431134351376,-1.059222275007374,-3.1549934209118162
587.000000000008,33.858543115489276,-1.0623475150776607,-3.155167744573172
588.100000000008,33.895050176931605,-1.065131584402834,-3.156276408911359
589.200000000008,33.93086591745949,-1.0668787640364779,-3.157656492896663
590.300000000008,33.96723143682568,-1.0687681624703402,-3.1580713428661493
591.400000000008,34.00309149732123,-1.0709866554958059,-3.159255622798324
592.5000000000081,34.0395819926257,-1.07429683727767,-3.160536521830407
593.6000000000081,34.07553903511657,-1.0772510044310541,-3.1605510210419965
594.700000000008,34.11172308411741,-1.0798225090937577,-3.161935648131826
595.800000000008,34.14799417649481,-1.082643452005996,-3.1618693590683487
596.900000000008,34.184245317827106,-1.0879465277427753,-3.1618701171132955
598.0000000000081,34.22050214528039,-1.0887911778168846,-3.1618715811874005
599.1000000000081,34.256395133977975,-1.0918721679387204,-3.1632764132713618
600.2000000000081,34.29270916188537,-1.0929607562825652,-3.1645867159536825
601.3000000000081,34.32915463777505,-1.0984062854239016,-3.1658743157083586
602.4000000000082,34.365252169508345,-1.1017457433302136,-3.165952395229213
603.5000000000082,34.40127021975617,-1.1062737510379899,-3.1672536345602538
604.6000000000082,34.43777711488753,-1.108276077268746,-3.1669293828045175
605.7000000000082,34.47438804079979,-1.110299742081149,-3.168276455566474
606.8000000000083,34.51049259624634,-1.1134199980384187,-3.1669277214866325
607.9000000000083,34.546547324302566,-1.1142205101225602,-3.1682128106338476
609.0000000000083,34.58299190767303,-1.1194054397198507,-3.168238231937348
610.1000000000083,34.6192708957097,-1.1217752873794447,-3.169525392164992
611.2000000000082,34.65554142757501,-1.125399785267147,-3.169495327126174
612.3000000000083,34.69215030493144,-1.127315105610867,-3.1708578033958936
613.4000000000083,34.72845567900246,-1.1340270838759245,-3.1708661658459323
614.5000000000083,34.76474809129282,-1.1359027188498731,-3.1721621799755684
615.6000000000083,34.80086736110338,-1.1394425602120286,-3.172921843058983
616.7000000000083,34.837229834057005,-1.142291864046709,-3.1735042380851888
617.8000000000084,34.873895725866824,-1.1488287590352824,-3.173780379278214
618.9000000000084,34.90993267289547,-1.1506964095684327,-3.1758115255764916
620.0000000000084,34.94630504898173,-1.1560670128022121,-3.17590558318406
621.1000000000084,34.98293380462474,-1.1617662676541536,-3.1744671744628348
622.2000000000085,35.019449551976955,-1.165068141290584,-3.176421409688946
623.3000000000085,35.05563476180565,-1.1697261816766562,-3.1789011746815414
624.4000000000085,35.0922274468621,-1.1752141237190064,-3.179324957530886
625.5000000000085,35.128473592359036,-1.1805393429598474,-3.1794575122562705
626.6000000000085,35.16450198776323,-1.1860678079201412,-3.1792743266178407
627.7000000000086,35.20133816851181,-1.1921224743375884,-3.1806312748215797
628.8000000000086,35.23759442454889,-1.200219408103456,-3.1806398363573334
629.9000000000085,35.273889914200865,-1.2024639595385158,-3.181380625858511
631.0000000000085,35.310564743878125,-1.207353498091649,-3.181631111001472
632.1000000000085,35.346688679615966,-1.2146467322226504,-3.180944562290177
633.2000000000086,35.383423147290344,-1.2226567008883027,-3.1819662742678507
634.3000000000086,35.4201008863482,-1.2238977539990679,-3.1832730891720105
635.4000000000086,35.456325211136544,-1.2325538312165383,-3.1832703385816297
636.5000000000086,35.49296527221129,-1.2385397538308731,-3.183402195764073
637.6000000000087,35.5294108390581,-1.2424578063619423,-3.1845905962644405
638.7000000000087,35.56574413562857,-1.2483073376361415,-3.183306927728383
639.8000000000087,35.602311330502054,-1.2540157040447215,-3.184554599064874
640.9000000000087,35.63811521062148,-1.2587979085911025,-3.1862824294299514
642.0000000000088,35.67532384246196,-1.2654938139378697,-3.1875947204539865
643.1000000000088,35.71180029225706,-1.2736657438038415,-3.188668276712411
644.2000000000088,35.747841380017995,-1.2777742994688228,-3.188778229552509
645.3000000000088,35.78510852582226,-1.2850986201572383,-3.1901400735980454
646.4000000000087,35.821198720573605,-1.2930869841346446,-3.1915022501823422
647.5000000000088,35.857978909373685,-1.29950064638035,-3.1915838463010875
648.6000000000088,35.894740478619326,-1.3086134046792106,-3.1902029393220515
649.7000000000088,35.93137491229848,-1.316726235289247,-3.190646078544188
650.8000000000088,35.967804132146725,-1.3252356056075674,-3.1915126141476255
651.9000000000088,36.004628854056584,-1.3327143883353307,-3.1923757603771596
653.0000000000089,36.04057174475515,-1.3452975827471068,-3.1929590911320833
654.1000000000089,36.07782382560708,-1.3520765060917799,-3.1942530056024205
655.2000000000089,36.114618094832885,-1.3650710755028972,-3.1942571379642435
656.3000000000089,36.15062281758085,-1.374592925703912,-3.1949721235964192
657.400000000009,36.18773044328548,-1.3848638458741827,-3.1955714126930985
658.500000000009,36.22459094789864,-1.3960168883767765,-3.1954838198211712
659.600000000009,36.261276587724865,-1.4050741725352578,-3.196889276202093
660.700000000009,36.298022080338754,-1.41911691130996,-3.198060458339134
661.800000000009,36.334414452512526,-1.4277061277029026,-3.198162179521971
662.9000000000091,36.37107080742629,-1.4370988719543552,-3.199522596073365
664.0000000000091,36.40776394231751,-1.4488925691852235,-3.199529581814795
665.100000000009,36.44449656765926,-1.4617935474958197,-3.200725260619717
666.200000000009,36.48129851838905,-1.472282847229955,-3.1999617403425944
667.300000000009,36.517924595126736,-1.4823886369443542,-3.2019484151575384
668.4000000000091,36.55468862392716,-1.495746912054613,-3.2037078073990557
669.5000000000091,36.591458375763054,-1.5059151045647194,-3.2050603604196186
670.6000000000091,36.62793297382571,-1.5171509317115888,-3.2041296345127783
671.7000000000091,36.664708149007254,-1.5284244396624729,-3.205349252083381
672.8000000000092,36.70116592140631,-1.5429287978077417,-3.2064190373403787
673.9000000000092,36.73777041092849,-1.5497442303917681,-3.2050247516758095
675.0000000000092,36.77445302884229,-1.5600026164601117,-3.2064295209324767
676.1000000000092,36.81093159787387,-1.5699412136354731,-3.2063211458595524
677.2000000000093,36.84757194190831,-1.5794053030982533,-3.2076764353479197
678.3000000000093,36.88356925554717,-1.590674482117828,-3.207951851429006
679.4000000000093,36.920741061757994,-1.5984890140567054,-3.209465623870888
680.5000000000093,36.95752518729042,-1.604619461327114,-3.210420208341639
681.6000000000092,36.99420216695218,-1.6133180748380445,-3.2117270333481347
682.7000000000093,37.0310985458223,-1.6203586735068252,-3.213065256685746
683.8000000000093,37.067522029783106,-1.6261995433780265,-3.214403198992085
684.9000000000093,37.10428263806005,-1.6306882149233832,-3.2156779109963565
686.0000000000093,37.140882111603936,-1.6352382664169887,-3.215839983783965
687.1000000000093,37.17765023898508,-1.6376841339479367,-3.2161511152606677
688.2000000000094,37.213734592369505,-1.6400292456218537,-3.216422631839192
689.3000000000094,37.25138018222265,-1.638204196150769,-3.217415876141586
690.4000000000094,37.2879507490284,-1.6375586251656726,-3.2187164521416443
691.5000000000094,37.324498419699566,-1.635158792194077,-3.219748864128463
692.6000000000095,37.36118126492195,-1.6300294551754442,-3.220054386589954
693.7000000000095,37.39774844648009,-1.6262035864424407,-3.221371393296555
694.8000000000095,37.43428526146948,-1.6218813325995238,-3.222728283884808
695.9000000000095,37.471170924547536,-1.6145595712135046,-3.2226594742664334
697.0000000000095,37.5076655063827,-1.6078234192234337,-3.2240028083897028
698.1000000000096,37.54411803599394,-1.6015498676581987,-3.2240502143732206
699.2000000000096,37.58068510181238,-1.5909585493919505,-3.224998143213781
700.3000000000095,37.61731441224867,-1.5842435173033367,-3.2263610644621092
701.4000000000095,37.654285039875944,-1.5738520905363278,-3.226299628486274
702.5000000000095,37.69071041373243,-1.5626737475007528,-3.2260470569315727
703.6000000000096,37.72755811729368,-1.556036937856506,-3.2263115456699127
704.7000000000096,37.76378526824488,-1.5474186422009901,-3.2265008047689476
705.8000000000096,37.80063800955823,-1.5431791885974695,-3.227631215200864
706.9000000000096,37.83760754565258,-1.5398791140392745,-3.227631618399177
708.0000000000097,37.8738574055343,-1.541527323829204,-3.227968853566629
709.1000000000097,37.910743254656836,-1.5447513865813265,-3.2289537817953904
710.2000000000097,37.94741733446347,-1.5449026248314262,-3.2302534771729174
711.3000000000097,37.98433814979114,-1.5489529144353686,-3.2302646004994164
712.4000000000098,38.02092221187002,-1.5502310197314375,-3.231305766719693
713.5000000000098,38.057340316658504,-1.55567395477252,-3.2302541174866413
714.6000000000098,38.09413789336837,-1.5592875866683076,-3.2303114642386745
715.7000000000098,38.131383731794514,-1.5641676872299801,-3.231584491538478
716.8000000000097,38.168429037630666,-1.570276684758374,-3.2315800591174564
717.9000000000098,38.204777455076986,-1.5737248110244446,-3.231580198961807
719.0000000000098,38.24190789018084,-1.5758863277363722,-3.2315901384942576
720.1000000000098,38.27848204836444,-1.582604217725033,-3.2328920251139532
721.2000000000098,38.31471766469747,-1.5861794134215546,-3.232892220973678
722.3000000000098,38.35177689801161,-1.5920209782504295,-3.233905448481262
723.4000000000099,38.38876011112877,-1.5984717413367662,-3.2328934631345283
724.5000000000099,38.42555402323587,-1.5992704800668531,-3.233984024324548
725.6000000000099,38.462523030202945,-1.6070338962487223,-3.2342091132909387
726.7000000000099,38.49862846270736,-1.6108577296673519,-3.2342106627298897
727.80000000001,38.53617063616208,-1.6166684658954904,-3.2345466652915125
728.90000000001,38.5728293444367,-1.6235452806893367,-3.2356442569793704
730.00000000001,38.61020216358862,-1.6256638374801857,-3.235640121776282
731.10000000001,38.646994945060975,-1.6345034021358549,-3.2356417056872253
732.20000000001,38.68397946738298,-1.6361595912363474,-3.2370584090353707
733.3000000000101,38.72074929118501,-1.6433243969667113,-3.2369649997169514
734.4000000000101,38.75800044934275,-1.6477868584100024,-3.238322469026914
735.50000000001,38.794946956623065,-1.6535590128525723,-3.2369722729551045
736.60000000001,38.832068923996694,-1.657323352518749,-3.236958314818466
737.70000000001,38.868950080325355,-1.6627085821159864,-3.238289108935188
738.8000000000101,38.90633617284518,-1.6704226732031129,-3.2382704378511167
739.9000000000101,38.94293024038329,-1.6748785616857305,-3.238269704701131
741.0000000000101,38.98030145804259,-1.6821884965542333,-3.238631460595422
742.1000000000101,39.01735380626795,-1.6845595553718546,-3.2383098382445263
743.2000000000102,39.05423796377922,-1.6901217385147196,-3.23827995461546
744.0000000000102,39.081157725928264,-1.6924338749873495,-3.2382798524717975