File: 01_Data/Cardboard/STA/N2/30K_min/Cardboard_STA_N2_30KData_230921_R2.csv
##Temp./Â°C,Time/min,DSC/(mW/mg),Mass loss/mg
41.0,10.527643172727956,-2.3739213332747506,-0.017333941184503487
42.100000000000016,10.736947726372076,-2.3488563994096827,-0.016906647340506176
43.20000000000003,10.863322712493657,-2.331914118108326,-0.017772035615087667
44.30000000000005,10.963841894083028,-2.318678519069726,-0.018165645626098126
45.40000000000006,11.048773742372756,-2.3054948257949897,-0.018816266113562463
46.50000000000008,11.124246965014336,-2.292768654072169,-0.01768264276664988
47.600000000000094,11.192371156137407,-2.2811830783597937,-0.017907278143036276
48.70000000000011,11.255767584929073,-2.272151016892582,-0.018116731056972313
49.800000000000125,11.315634309131642,-2.2625211280396686,-0.018932283261652305
50.90000000000014,11.373267045493643,-2.253494895800875,-0.01949817053814762
52.000000000000156,11.42735244725541,-2.244440522600678,-0.01851333446743908
53.10000000000017,11.479875831872475,-2.2345383500245903,-0.020301275171096478
54.20000000000019,11.530505090602734,-2.227941224289785,-0.019773523206575216
55.3000000000002,11.579520595519877,-2.219163411686617,-0.020552636714426864
56.40000000000022,11.627528743715782,-2.215079064030895,-0.02030551903073219
57.500000000000234,11.674634646495166,-2.20915941745767,-0.01987622251631027
58.60000000000025,11.719992846687955,-2.205213627040114,-0.022088584243132647
59.700000000000266,11.765621079053503,-2.200745118224968,-0.022443588250471436
60.80000000000028,11.809718040897707,-2.199283896892133,-0.023111458089297265
61.9000000000003,11.853051548894781,-2.1960074182721563,-0.023012596090245196
63.00000000000031,11.896455484353892,-2.19530947992583,-0.02356922203069578
64.10000000000034,11.938257157785642,-2.1946122581289873,-0.02336183745182252
65.20000000000034,11.980575841067079,-2.1949866213512577,-0.023593824419780862
66.30000000000035,12.022436218207005,-2.195021711222784,-0.023291200580731086
67.40000000000038,12.063461222784795,-2.1948182674737513,-0.024519819838011436
68.5000000000004,12.104416749213351,-2.196372711769432,-0.025575349170868567
69.6000000000004,12.145423166215854,-2.198475914122945,-0.026701854897440036
70.70000000000041,12.18491622446556,-2.199895328102005,-0.026821363829855116
71.80000000000044,12.225705527378077,-2.204604831830045,-0.026771137166454295
72.90000000000046,12.26547816848119,-2.20822837970853,-0.02680120558120036
74.00000000000047,12.30553236658675,-2.2130365745744327,-0.028630689067098203
75.10000000000048,12.34472224845026,-2.217145645600996,-0.02951950286775684
76.2000000000005,12.384399737496096,-2.223061355357521,-0.02915794372422864
77.30000000000052,12.423791025752445,-2.228693217692747,-0.03044141351805063
78.40000000000053,12.462962407137745,-2.2365948093685746,-0.030997488354326475
79.50000000000054,12.501814928827656,-2.2416949989444763,-0.03291303693473946
80.60000000000056,12.540755075715282,-2.2481013197546336,-0.03453743513066598
81.70000000000059,12.579566629287456,-2.255240972541538,-0.03315060185166718
82.8000000000006,12.61826423748665,-2.2621406611126518,-0.033335940495609506
83.9000000000006,12.65640566409179,-2.2666628748282793,-0.03447017982362155
85.00000000000063,12.694630919634553,-2.2729038335111826,-0.03442736745983144
86.10000000000065,12.73288736866902,-2.2797932679859803,-0.035777419886343864
87.20000000000066,12.771276195668701,-2.2850896116112804,-0.03678531735757584
88.30000000000067,12.808901131778061,-2.2909605805109887,-0.03706953127617796
89.40000000000069,12.846681579526157,-2.297090005805497,-0.03973281482279356
90.50000000000071,12.883826306265684,-2.2997591757152196,-0.039741589191237825
91.60000000000072,12.921594904225397,-2.301977024349964,-0.04116617918678189
92.70000000000073,12.959268447032787,-2.3057883850918763,-0.0414764653531523
93.80000000000075,12.996355799790582,-2.3064687451506307,-0.04267591876971899
94.90000000000077,13.033059964660074,-2.3091765232790706,-0.04386175968034367
96.00000000000078,13.069663976551237,-2.3100947737235855,-0.0451448726265391
97.10000000000079,13.107735010620974,-2.310753637797566,-0.04643272755328187
98.20000000000081,13.144534724444524,-2.3090015307278806,-0.04772743419218051
99.30000000000084,13.18131638173351,-2.3073005325898333,-0.04989762835795242
100.40000000000084,13.21818136684626,-2.3041930199052016,-0.05039114687416024
101.50000000000085,13.255040395010791,-2.3015170194669756,-0.05069931260029703
102.60000000000088,13.291145871698502,-2.2966442225866137,-0.05301382833613122
103.7000000000009,13.328268334735329,-2.291207190784062,-0.0530392148161587
104.8000000000009,13.364687736917308,-2.286011295950193,-0.05438662632587565
105.90000000000092,13.401614186200252,-2.280120919127154,-0.05568095290285591
107.00000000000094,13.437693024067062,-2.270651495428445,-0.05563643681866992
108.10000000000096,13.474254677128776,-2.261164790026853,-0.0569783604406342
109.20000000000097,13.510804424456406,-2.2538080368097226,-0.05699049542686341
110.30000000000098,13.546717769346508,-2.245561365856496,-0.05693941876099329
111.400000000001,13.582879096683333,-2.2345819324729614,-0.059691928949440864
112.50000000000102,13.61923459953919,-2.2235992512420975,-0.05994593068810339
113.60000000000103,13.655331157136835,-2.2123393447150597,-0.060944485281064775
114.70000000000104,13.691825532289357,-2.2009110039071937,-0.06358885566125583
115.80000000000106,13.727958407400141,-2.1883474175609403,-0.06356994807955108
116.90000000000109,13.763775666323275,-2.1759687951121616,-0.06403767211848521
118.0000000000011,13.799873436250762,-2.1625751967207507,-0.06621170817639843
119.1000000000011,13.835911433218197,-2.1484224569742967,-0.06620352572403077
120.20000000000113,13.87183785063814,-2.1357124290855496,-0.0673659625756442
121.30000000000115,13.908020021990948,-2.1231933843055613,-0.06752020825674876
122.40000000000116,13.943526266491972,-2.1089894656117063,-0.06751971556909186
123.50000000000117,13.979504185974402,-2.0940222148054515,-0.06818448418221035
124.60000000000119,14.014759805823449,-2.0808471362904424,-0.06952146182868457
125.70000000000121,14.050975218356479,-2.067790266245831,-0.0695006876263431
126.80000000000122,14.086076054761302,-2.0546109570532627,-0.0694279742515409
127.90000000000123,14.121827825270937,-2.0419702109726394,-0.07016512199176406
129.00000000000125,14.157333176337898,-2.02882176091523,-0.07015849892282722
130.10000000000127,14.192573299363794,-2.0147655949679066,-0.0706362937020284
131.2000000000013,14.227833450680786,-2.0011704759188746,-0.07077480404231684
132.3000000000013,14.263732202049084,-1.990799242725381,-0.07150212230092068
133.4000000000013,14.298645891145675,-1.9793788126960616,-0.07279766880102878
134.50000000000134,14.334510509830137,-1.967771152294551,-0.07279136802417963
135.60000000000133,14.36942884703034,-1.9575878981661747,-0.07390033504528803
136.70000000000135,14.40448910858424,-1.9455263416507704,-0.07541801497712575
137.80000000000138,14.439557181761987,-1.9346057989926628,-0.07543018235613097
138.9000000000014,14.474330545170302,-1.9257683182090937,-0.07543018320969974
140.00000000000142,14.509389318666798,-1.915064522590709,-0.07543018269139434
141.10000000000142,14.544267741578246,-1.9075869893314827,-0.07543022072272443
142.20000000000144,14.57930027670192,-1.8951310048955503,-0.07542299320800483
143.30000000000146,14.614269847001522,-1.8879019793335419,-0.07475398627734808
144.40000000000146,14.649170322973502,-1.879599894067176,-0.07477051062200468
145.50000000000148,14.683800103959634,-1.8733725060359456,-0.0747777767619815
146.6000000000015,14.718762452640402,-1.8663552993139887,-0.07344315345898877
147.70000000000152,14.753300506974567,-1.859324202577534,-0.07344940402223443
148.80000000000155,14.788231019647714,-1.8537873499942683,-0.07344367629551796
149.90000000000154,14.822850403850548,-1.8488656252985425,-0.07480912696168618
151.00000000000156,14.857391175302528,-1.8425548478234774,-0.07609021434560592
152.1000000000016,14.891910329175323,-1.8388964457331027,-0.07609017523119999
153.20000000000158,14.92603420757034,-1.8344743909574859,-0.07609018185708516
154.3000000000016,14.961084780166805,-1.8295947345116486,-0.07609018433339099
155.40000000000163,14.995758600352305,-1.8270359961650617,-0.07609179128902932
156.50000000000165,15.02964055813235,-1.824774324822741,-0.07730856637974792
157.60000000000167,15.06429445049241,-1.8188661700740874,-0.07740827518129834
158.70000000000167,15.098904607777063,-1.816731353405204,-0.07741020071669746
159.8000000000017,15.132936723241961,-1.8147037429200874,-0.07741018214674922
160.9000000000017,15.167862073233422,-1.811859157046459,-0.07741018199745175
162.0000000000017,15.201814741305723,-1.8106790351735473,-0.0774101819999915
163.10000000000173,15.236332942415519,-1.8091596216155423,-0.07741018200000171
164.20000000000175,15.270394279998943,-1.8055689635948802,-0.07741018199999594
165.30000000000177,15.30453776791163,-1.8054642243273524,-0.07741018200099248
166.4000000000018,15.339010310652647,-1.8022589125401882,-0.07741018199654803
167.5000000000018,15.373707171802616,-1.8018436423305622,-0.07741017280832008
168.6000000000018,15.407374898375094,-1.7996398338798825,-0.07741058591048366
169.70000000000184,15.441992563691983,-1.7988357956863041,-0.07679822838298778
170.80000000000183,15.476450858205535,-1.7972310777145377,-0.0763966927679367
171.90000000000185,15.510529518984741,-1.7951520830257492,-0.07706855097379828
173.00000000000188,15.544632777677158,-1.7941059855387214,-0.07736536517591075
174.1000000000019,15.578397238176983,-1.7946236328149046,-0.07838831699864279
175.20000000000192,15.61300875592389,-1.7928153421608122,-0.07839011349253244
176.30000000000192,15.646322736691342,-1.7927417417749911,-0.0783901827769764
177.40000000000194,15.680976194832999,-1.7919392403564047,-0.07839018200534387
178.50000000000196,15.715032961755202,-1.791162658611612,-0.07839018199988246
179.60000000000196,15.748953906961786,-1.792468776947761,-0.07839018200000059
180.70000000000198,15.781837586947153,-1.7910264299658663,-0.0783901819999997
181.800000000002,15.81641978256607,-1.7898227861926412,-0.07839018200000192
182.90000000000202,15.85076746542228,-1.7899329034950597,-0.0783901819999917
184.00000000000205,15.884769993889233,-1.7899554262958315,-0.07839018198945968
185.10000000000204,15.917870052384586,-1.7908427500992932,-0.0783901826448048
186.20000000000206,15.951887481732172,-1.7895632531489492,-0.07839021901064269
187.3000000000021,15.985985242244308,-1.7893135386128474,-0.07838344866708002
188.40000000000208,16.019744759556062,-1.7886992753734279,-0.07776127788589449
189.5000000000021,16.05324547044192,-1.7881140982528385,-0.077737509820901
190.60000000000213,16.086965571630202,-1.7889495316126338,-0.07821207840489874
191.70000000000215,16.120613962789765,-1.7887767069485847,-0.07905266109238385
192.80000000000217,16.154327039816636,-1.788391142619054,-0.07905003305209357
193.90000000000217,16.187543327071282,-1.7882975453792869,-0.07905010475918184
195.0000000000022,16.221697672890006,-1.7885458016881972,-0.07905015022195894
196.1000000000022,16.255076877129056,-1.7895995625132426,-0.07900411628075421
197.2000000000022,16.28873226411735,-1.7895175180669876,-0.0800375786907872
198.30000000000223,16.322406134355465,-1.7895915596311829,-0.08003015324813978
199.40000000000225,16.355012021631616,-1.790792778935937,-0.0800300973125827
200.50000000000227,16.389231445325567,-1.7901734263692357,-0.0800300990107985
201.6000000000023,16.422592926159478,-1.7892908741073226,-0.08003009901921398
202.7000000000023,16.455649530207925,-1.7917443191104474,-0.08003009748584455
203.8000000000023,16.48977673510705,-1.790569477339243,-0.0800300711344617
204.90000000000234,16.52338420451625,-1.7895116408847103,-0.0800417724015281
206.00000000000233,16.55664274329691,-1.7895390782330447,-0.0812407152428154
207.10000000000235,16.590167515514707,-1.7903711217916534,-0.08134947533599401
208.20000000000238,16.62324634298808,-1.7913955544914546,-0.08135000972482143
209.3000000000024,16.65704414645195,-1.7891377480189994,-0.08134998565941398
210.40000000000242,16.690291554981993,-1.7891775290756005,-0.08134973495812226
211.50000000000242,16.72386056758167,-1.7914871962776822,-0.08144010057587092
212.60000000000244,16.757233717881736,-1.791546100251006,-0.08234137789681828
213.70000000000246,16.79044409961508,-1.7915974915794566,-0.08266418814926091
214.80000000000246,16.823850854682387,-1.7913913030893982,-0.08267017269442967
215.90000000000248,16.857430598779402,-1.7913000128554506,-0.08266452764770182
217.0000000000025,16.89071955011561,-1.791331096340529,-0.08377620966758759
218.10000000000252,16.92411743983372,-1.790734691522308,-0.08399049161174466
219.20000000000255,16.95739540249035,-1.7937098633677524,-0.08399017884499616
220.30000000000254,16.990692051034934,-1.7932819089364644,-0.08399756420952365
221.40000000000256,17.0240916268629,-1.7921149551416753,-0.08455619932187863
222.5000000000026,17.057463376188053,-1.792551376485234,-0.08465107138742667
223.60000000000258,17.090689834686767,-1.7918295540272189,-0.08465009391611344
224.7000000000026,17.124189212726623,-1.7928479913716895,-0.0846500615659056
225.80000000000263,17.157261597223147,-1.792171867051697,-0.08465135917815836
226.90000000000265,17.190712627057735,-1.7930583443194872,-0.08603780459723742
228.00000000000267,17.223907004385556,-1.7897281112506946,-0.08596828926408584
229.10000000000267,17.257510931915895,-1.7909645495337663,-0.08596514846687509
230.2000000000027,17.29042381979517,-1.7918191374952868,-0.08705212548308028
231.3000000000027,17.323461623501426,-1.7919332190215267,-0.0872873627427575
232.4000000000027,17.35701007846252,-1.7915038529318095,-0.08776879336299093
233.50000000000273,17.390614136914138,-1.7907757197035714,-0.0886023501650306
234.60000000000275,17.423468487525877,-1.7916726555821445,-0.08860013024030966
235.70000000000277,17.45672644632391,-1.7927772211401243,-0.08860019590314439
236.8000000000028,17.489591360448802,-1.7927437858478867,-0.08860025560317375
237.9000000000028,17.52219299049403,-1.7916535661030613,-0.08857209672475941
239.0000000000028,17.55635626523764,-1.7918084135151746,-0.0900813546974435
240.10000000000284,17.589502199842922,-1.791893763007674,-0.09191921603987963
241.20000000000283,17.622536952301257,-1.7906138124003044,-0.09315790859809603
242.30000000000285,17.65581220640688,-1.7911606011887713,-0.0945348910904058
243.40000000000288,17.688991472228587,-1.7905998675335093,-0.09452972617509392
244.5000000000029,17.722415135232445,-1.78991659931949,-0.09545436011777841
245.60000000000292,17.755641615964453,-1.7901229431796812,-0.0958802292719092
246.70000000000292,17.788559136946905,-1.7893530561028546,-0.0971678967408538
247.80000000000294,17.821716967781715,-1.789491804902098,-0.0971246059957771
248.90000000000296,17.854842441585443,-1.7901033985246753,-0.09849508600600965
250.00000000000296,17.888129351221416,-1.7917777577401095,-0.0984964401175299
251.10000000000298,17.921054457735583,-1.790992964281744,-0.09996265839883378
252.200000000003,17.954245296976925,-1.7908461091097425,-0.10102653260380245
253.30000000000302,17.98683892044593,-1.7898600994389566,-0.10256297266998082
254.40000000000305,18.020926421508353,-1.7885960258239808,-0.10401720040872409
255.50000000000304,18.05383834358634,-1.7896014022923332,-0.10430007794711704
256.6000000000031,18.086721649100884,-1.787790627310163,-0.10433104105920687
257.7000000000031,18.119956118513937,-1.7895772845068583,-0.10591974232927193
258.8000000000031,18.152920836105793,-1.7880751634842769,-0.10928694651738446
259.9000000000031,18.18635541637191,-1.7885179064938288,-0.1120526387923837
261.0000000000031,18.219618323779088,-1.7884089432464823,-0.11357273921864497
262.10000000000315,18.252157920165754,-1.7872998259657829,-0.11417381494844303
263.2000000000032,18.28572731991837,-1.7878512373702384,-0.11538764398054768
264.30000000000314,18.318837598339307,-1.7874276280913144,-0.11692084023417415
265.40000000000316,18.352033463762393,-1.7868520686052602,-0.11933089895084947
266.5000000000032,18.384964505288487,-1.7876448310278026,-0.12302579992076801
267.6000000000032,18.41775268210711,-1.7866120303161563,-0.12502193930172956
268.70000000000323,18.450849428863314,-1.7865936555634352,-0.12795928476524976
269.80000000000325,18.48438114553243,-1.7865074789277455,-0.12972970815819806
270.9000000000033,18.51756234866476,-1.784868549947883,-0.13229694447647145
272.0000000000033,18.55048895031138,-1.7850151426913359,-0.1348940200403752
273.1000000000033,18.583785057815476,-1.7853069808289572,-0.1370497221006448
274.20000000000334,18.616630723785978,-1.786213570700754,-0.14014020009887318
275.30000000000337,18.649859178533227,-1.7850148897958253,-0.14347924581464344
276.40000000000333,18.68311050535143,-1.7840884177323446,-0.14736460461992396
277.50000000000335,18.715874986784875,-1.7841460723269211,-0.15007678134764202
278.6000000000034,18.749290293552786,-1.783869053063586,-0.1531740943426101
279.7000000000034,18.78246351794756,-1.7844293811553844,-0.15629950050330788
280.8000000000034,18.815641499588963,-1.7829573264282987,-0.16028572757044435
281.9000000000034,18.84878030446697,-1.7823946830452826,-0.164761617961783
283.0000000000034,18.88186685529739,-1.7816751891547613,-0.16703912001645937
284.10000000000343,18.91523091150859,-1.78244233828313,-0.169205648896122
285.20000000000346,18.948288417852858,-1.782597120520974,-0.17532137060729047
286.3000000000035,18.981260678058238,-1.7832796089327128,-0.1822115011686618
287.4000000000035,19.0145562925448,-1.783731147355597,-0.1860082113215471
288.5000000000035,19.04767218779557,-1.784363230266747,-0.19085775642610336
289.60000000000355,19.080897416404717,-1.7841760551348782,-0.19632944571564126
290.70000000000357,19.114392864944662,-1.7830340843493395,-0.20314705382472997
291.8000000000036,19.147668577589585,-1.7848191777047675,-0.20823707779946732
292.9000000000036,19.180661789751127,-1.78482322759047,-0.2138553246053867
294.0000000000036,19.213340473236485,-1.7849435749332685,-0.22066512376985692
295.1000000000036,19.247179031147752,-1.7842900580526286,-0.22686232004664664
296.2000000000036,19.280678731294056,-1.7861732175562743,-0.23330410487279396
297.30000000000365,19.313854358064695,-1.7898054626547424,-0.24008841815392845
298.4000000000037,19.347003066219447,-1.788644682455114,-0.24480769798707902
299.5000000000037,19.380277426191885,-1.7883836155254043,-0.25236581641787703
300.60000000000366,19.4132870801772,-1.7899103696032541,-0.26305784060953163
301.7000000000037,19.446663458159378,-1.7898802443341175,-0.2726429463803046
302.8000000000037,19.480235963491374,-1.7931570437486177,-0.2807081119778716
303.90000000000373,19.513292385389505,-1.7943612836900633,-0.28905653079842786
305.00000000000375,19.54667994015902,-1.7962528008967884,-0.29800832171556424
306.1000000000038,19.580100160475986,-1.7991389095678774,-0.3074176905724699
307.2000000000038,19.61320626748181,-1.8017081124463046,-0.3172283174026611
308.3000000000038,19.64674312158519,-1.8048081381956764,-0.3264759453096291
309.40000000000384,19.67973690691482,-1.8085405758520392,-0.3365195778714005
310.5000000000038,19.71330351635505,-1.8129665314474952,-0.3474159777298813
311.60000000000383,19.746717771461743,-1.8172061333405134,-0.36116054866827385
312.70000000000385,19.780028834019927,-1.8207840823962134,-0.3725274738691917
313.8000000000039,19.813834931607783,-1.826102082804213,-0.38421783393162956
314.9000000000039,19.847350575182357,-1.8307197337379784,-0.397275793974349
316.0000000000039,19.880403921475015,-1.8366782683172078,-0.4100943837401698
317.10000000000394,19.91416443135408,-1.8416530265836915,-0.42358046342276
318.2000000000039,19.947425496575974,-1.8484754817303104,-0.4375613565764409
319.30000000000393,19.980792988586632,-1.8534960182409979,-0.4509120979673309
320.40000000000396,20.01419971714501,-1.8595067885773189,-0.46479341543265074
321.500000000004,20.047449180910945,-1.8665231475954898,-0.47954835985264577
322.600000000004,20.08116633385236,-1.8733505792066227,-0.49474144238289997
323.700000000004,20.114767761785366,-1.8798643487400453,-0.5121180716899478
324.80000000000405,20.14808571007007,-1.8856718245619555,-0.5291346261323073
325.90000000000407,20.18112038989035,-1.8931609964207439,-0.5449191134611895
327.0000000000041,20.21521478504464,-1.8995053694334831,-0.5609508173476065
328.10000000000406,20.24859717525272,-1.905805108833315,-0.5773481501144255
329.2000000000041,20.282323788991132,-1.9146093763501035,-0.5961321783746603
330.3000000000041,20.315748218157808,-1.9215338389896874,-0.6153431857231353
331.4000000000041,20.349477756925502,-1.930453598106785,-0.634069888256235
332.50000000000415,20.38278042843228,-1.9370581708756527,-0.6521313209348585
333.6000000000042,20.416519780353845,-1.9449724741171608,-0.6725161247221081
334.7000000000042,20.45046737692729,-1.9545166440410329,-0.6932984000701468
335.80000000000416,20.48382484230699,-1.9631383579656256,-0.7139177138715778
336.9000000000042,20.517784152787648,-1.9716562468950483,-0.7362396910246836
338.0000000000042,20.551441904887707,-1.9805463289996725,-0.7598383027695186
339.10000000000423,20.58492790877773,-1.9894327155856057,-0.783105083340927
340.20000000000425,20.618114981956502,-1.9982951812935181,-0.8050913064474234
341.3000000000043,20.652304286368242,-2.0101366216801657,-0.8301467150334791
342.4000000000043,20.686039983559514,-2.019413721947825,-0.85469951844604
343.5000000000043,20.719994969941713,-2.030973036908862,-0.8795527977532256
344.60000000000434,20.753339793405207,-2.044508734930428,-0.9062570589678987
345.7000000000043,20.787271273607338,-2.0566523629515765,-0.9340153303374827
346.80000000000433,20.82113607649782,-2.0704917617339498,-0.960073633077454
347.90000000000435,20.854879601025406,-2.0835882686765266,-0.9862848443705197
349.0000000000044,20.888736663369272,-2.097390644435883,-1.0155615207483222
350.1000000000044,20.922936311567728,-2.1144889849226507,-1.0462776778053073
351.2000000000044,20.956575886549643,-2.1295604394714744,-1.0774362394975423
352.30000000000445,20.99078758666997,-2.1477744761684416,-1.10924383103587
353.4000000000044,21.02457382877524,-2.166948592109899,-1.139982089539258
354.50000000000443,21.0586996747785,-2.1830525085568997,-1.1715082459981514
355.60000000000446,21.092595719741567,-2.2052632715565954,-1.2052715754552192
356.7000000000045,21.126627011037296,-2.2247020174313166,-1.239815717324524
357.8000000000045,21.160604627622497,-2.245068708836569,-1.2750682055964795
358.9000000000045,21.194433152367964,-2.2688522262504995,-1.3123573960391997
360.00000000000455,21.228551118496142,-2.289581110287417,-1.350506675801805
361.10000000000457,21.262984939135354,-2.3144100217533974,-1.3878991870960027
362.2000000000046,21.297081010421,-2.337367154862447,-1.4253887296884553
363.30000000000456,21.330959849897443,-2.3601850799155164,-1.4640660271572061
364.4000000000046,21.365107703046643,-2.3835674359682875,-1.5048669648791524
365.5000000000046,21.399472935141695,-2.406834258575159,-1.547930378150114
366.6000000000046,21.43351184156261,-2.428677726044821,-1.5917618511545784
367.70000000000465,21.467802041715636,-2.4485469740579786,-1.6359243457944102
368.8000000000047,21.50166075784496,-2.4668620401989054,-1.679611528031808
369.9000000000047,21.53576307677734,-2.4852119484545065,-1.7240642162683564
371.00000000000466,21.569853709613124,-2.499283118218351,-1.769605333589538
372.1000000000047,21.603934328761248,-2.5095836622616825,-1.8150480815841545
373.2000000000047,21.638102147155042,-2.515825870201105,-1.8631399576473386
374.30000000000473,21.671709308598842,-2.516683831098384,-1.9124439724156992
375.40000000000475,21.706055539994246,-2.5133604363623685,-1.9612772078410665
376.5000000000048,21.739905879286106,-2.5024852397833395,-2.0058712770162126
377.6000000000048,21.7737125308148,-2.486154933374096,-2.0525601161108256
378.7000000000048,21.807251059103123,-2.4611600855895155,-2.098792800166599
379.80000000000484,21.840854875312935,-2.429673379766129,-2.145110497716916
380.9000000000048,21.874499866175604,-2.3874702551237337,-2.1914382181051453
382.00000000000483,21.907863976084375,-2.3407546777745574,-2.236364368868262
383.10000000000485,21.941598065538184,-2.285315803826165,-2.2774663719705193
384.2000000000049,21.974891385225035,-2.224147131471084,-2.316376993488829
385.3000000000049,22.008008672388307,-2.158243448165572,-2.3529739502884013
386.4000000000049,22.041345545356766,-2.087154666149203,-2.3884246926530883
387.50000000000495,22.073853337910162,-2.0159148703428893,-2.420725277717561
388.6000000000049,22.10700756217823,-1.9417772096384116,-2.451260558933175
389.70000000000493,22.14032166128892,-1.8692154341997043,-2.4785541128195265
390.80000000000496,22.173732688702525,-1.7949234362190951,-2.5054260806838564
391.900000000005,22.206916437323613,-1.724423479032267,-2.5283344548844218
393.000000000005,22.240127380118153,-1.6575022468332041,-2.5501948657401368
394.100000000005,22.273754660288514,-1.5936566498580869,-2.5696186506425978
395.20000000000505,22.307066760250045,-1.5317648621648714,-2.5862382897475387
396.30000000000507,22.340320019728097,-1.4723710540713326,-2.5999112671442632
397.4000000000051,22.373559385965926,-1.4175731613236624,-2.613496685769509
398.50000000000506,22.407285228954084,-1.3643467740961772,-2.6265686702804008
399.6000000000051,22.44069750155647,-1.3150438287971846,-2.637823575967528
400.7000000000051,22.474285028617263,-1.2674467365356072,-2.6473392453074567
401.8000000000051,22.507829408023746,-1.227658273392802,-2.654799257065037
402.90000000000515,22.541442448027365,-1.1861036897531876,-2.662602253810821
404.0000000000052,22.575357426224034,-1.1534132084830286,-2.6701163097713874
405.1000000000052,22.608901264167883,-1.1219323132735726,-2.675933600081387
406.20000000000516,22.642607992131687,-1.0951342656913892,-2.6802969404202344
407.3000000000052,22.676593627585422,-1.0707588363406497,-2.6860151125847747
408.4000000000052,22.710754400861067,-1.0501960479534365,-2.689987335942113
409.50000000000523,22.744236172673123,-1.0351319084051434,-2.6939161278308474
410.60000000000525,22.778072472432832,-1.0199657201891317,-2.697926505392131
411.7000000000053,22.812345685359144,-1.0065346439965848,-2.7010055771971007
412.8000000000053,22.8469972685538,-0.9966665648282041,-2.7041229252560663
413.9000000000053,22.88084823946773,-0.9871804028582255,-2.7072361449159943
415.00000000000534,22.915216287903593,-0.9808348880874279,-2.7098507727934567
416.1000000000053,22.94926370506504,-0.9720994834196033,-2.713651708118134
417.20000000000533,22.983679332259193,-0.965600233887209,-2.7172931525186264
418.30000000000535,23.01806773682288,-0.9601735211746332,-2.720533444020286
419.4000000000054,23.052170748075934,-0.9526409476472749,-2.724082770136337
420.5000000000054,23.08662179260952,-0.9500071970247944,-2.7271397559894583
421.6000000000054,23.12090948640166,-0.9442020887297163,-2.730265910006378
422.70000000000545,23.15480265493731,-0.9379833451870158,-2.7333766756498328
423.8000000000054,23.189785949426096,-0.9365936361120863,-2.7372889186880913
424.90000000000543,23.223956290022688,-0.9333052082277631,-2.7405918236914015
426.00000000000546,23.258696613139648,-0.93119557342953,-2.74453693634706
427.1000000000055,23.293017831280316,-0.9293042973298711,-2.7469462497103594
428.2000000000055,23.3272994041349,-0.9260175366923545,-2.74836895963918
429.3000000000055,23.361746129879375,-0.9239165577578454,-2.7513270127751177
430.40000000000555,23.396117061622014,-0.9215074731216266,-2.7548659131829822
431.50000000000557,23.429844184097355,-0.9207911992965202,-2.7583758178989535
432.6000000000056,23.46506359707484,-0.9187464313647754,-2.7613055724578297
433.70000000000556,23.499828269163768,-0.9187378381927261,-2.7640974712707047
434.8000000000056,23.534268984263495,-0.9172622278597793,-2.767928766063696
435.9000000000056,23.5688179822912,-0.9163470604567178,-2.7707668762611792
437.0000000000056,23.603223434703565,-0.9181545759860275,-2.771818214990879
438.10000000000565,23.637846723706634,-0.9185059101080757,-2.7744105061478166
439.2000000000057,23.672323836350596,-0.9212625774341355,-2.778735799066731
440.3000000000057,23.707085533328623,-0.9224409328574479,-2.7809097172848993
441.40000000000566,23.74185466855393,-0.9231203254361126,-2.7844484075689384
442.5000000000057,23.776314751774603,-0.9259146232787584,-2.7876806967278287
443.6000000000057,23.81088521294137,-0.9293213844469019,-2.7909055816457418
444.70000000000573,23.845622189433787,-0.9324944280439675,-2.7937842546775693
445.80000000000575,23.88015490403394,-0.9362888414309827,-2.7956053271933587
446.9000000000058,23.915272595219786,-0.9388909701956912,-2.7991619849623133
448.0000000000058,23.9497989560734,-0.9439014442811138,-2.80216457375856
449.1000000000058,23.984564640858252,-0.9488430690582313,-2.8046740533263717
450.20000000000584,24.01926674310592,-0.9539126748024922,-2.8079421936578335
451.3000000000058,24.054093656671068,-0.9585117437556177,-2.8102069534943945
452.40000000000583,24.088876478538857,-0.9669517903956388,-2.812283223588927
453.50000000000585,24.12387000928665,-0.9700028927003435,-2.8149024538141263
454.6000000000059,24.158501600423655,-0.9768715955769052,-2.8176351643354716
455.7000000000059,24.19345942056472,-0.9848016793824418,-2.8189987510073387
456.8000000000059,24.22812207816141,-0.9902366720065032,-2.8218921126458527
457.90000000000595,24.263315540900873,-0.9985667348057874,-2.824075924665819
459.0000000000059,24.298086374867374,-1.003632073915108,-2.826787398873586
460.10000000000593,24.33307089027377,-1.0131312084293846,-2.829433409397545
461.20000000000596,24.367478806409466,-1.0221730392835522,-2.832004662445116
462.300000000006,24.40288241514073,-1.027313369370292,-2.83450686252345
463.400000000006,24.43820474228756,-1.0357715195841886,-2.8362148837306975
464.500000000006,24.47292258584336,-1.0437517436778836,-2.83924960192721
465.60000000000605,24.50792583908702,-1.051370094233031,-2.841644072661606
466.70000000000607,24.543067487016224,-1.0581615445584878,-2.8447422700465106
467.8000000000061,24.578000838961323,-1.065163336855152,-2.847097223213418
468.90000000000606,24.612975736057326,-1.0741776504494682,-2.8499266978057145
470.0000000000061,24.648122586857422,-1.080214688344525,-2.8516700982269074
471.1000000000061,24.683071557118687,-1.089785352776953,-2.8519002759903485
472.2000000000061,24.718047346557952,-1.0969098976682392,-2.8528374875854237
473.30000000000615,24.753357054472154,-1.1053450632259445,-2.8553059738198074
474.4000000000062,24.788515772876295,-1.1110206524974244,-2.859103599079978
475.5000000000062,24.823504402076576,-1.120387684910465,-2.8617329269546894
476.60000000000616,24.85859303209847,-1.1276293228333314,-2.8633428562303243
477.7000000000062,24.893730220908424,-1.1341615951849242,-2.8660179840553974
478.8000000000062,24.92907521397563,-1.1427735435335922,-2.8686386020526258
479.90000000000623,24.96398831071717,-1.1491463454389523,-2.870065095779957
481.00000000000625,24.999401015253884,-1.1562893090511905,-2.8729320879091507
482.1000000000063,25.034398599131254,-1.1632234082983999,-2.874197499727812
483.2000000000063,25.069808160120086,-1.1694164304833707,-2.874839819529372
484.3000000000063,25.105131497565786,-1.1761864191033733,-2.8761778585710744
485.40000000000634,25.13999538529426,-1.1839867840522724,-2.8785969645336738
486.5000000000063,25.175614349276103,-1.1887992175629332,-2.8806237724014077
487.60000000000633,25.210687767052914,-1.1961238237336296,-2.881827428646784
488.70000000000636,25.246181578139026,-1.203051698107077,-2.8833781654402704
489.8000000000064,25.281189765573167,-1.2079943739298011,-2.885039501709103
490.9000000000064,25.316332353143128,-1.2139293031540836,-2.886831303296412
492.0000000000064,25.351725241605628,-1.220461934530893,-2.8886524262165434
493.10000000000645,25.387004208182336,-1.22490492313327,-2.891246111895602
494.2000000000064,25.422210332312602,-1.2325650549344451,-2.8930066329829147
495.30000000000643,25.457580862268756,-1.2366441679214644,-2.8938221964963793
496.40000000000646,25.492708779562772,-1.241221100775954,-2.8959340389524093
497.5000000000065,25.52813863938892,-1.2476173614042905,-2.8975755042578903
498.6000000000065,25.563294950855365,-1.2520085568783066,-2.8983935413363624
499.7000000000065,25.59910594403648,-1.2546827348263334,-2.898276528130725
500.80000000000655,25.634063806286157,-1.2609313281524794,-2.89973577284922
501.90000000000657,25.669463887800493,-1.2680150257406841,-2.9016077984145587
503.0000000000066,25.704951887062734,-1.272421311924768,-2.9029973377722684
504.10000000000656,25.74027179642571,-1.2773407126745144,-2.9044384309980114
505.2000000000066,25.77523659052371,-1.2816392581313167,-2.9065128132855778
506.3000000000066,25.811330223209165,-1.2868772042126928,-2.9073845660723716
507.4000000000066,25.846246978863835,-1.2929453489196587,-2.9085619519192907
508.50000000000665,25.881731639097758,-1.296623100142956,-2.911463357125706
509.6000000000067,25.917161459722454,-1.3019145637931349,-2.912745666105724
510.7000000000067,25.952861565810927,-1.3047042061755942,-2.9140113635367166
511.80000000000666,25.987917188323657,-1.3087860737903736,-2.9152477357161386
512.9000000000067,26.023487933582917,-1.3158303462571233,-2.9160532959531302
514.0000000000067,26.058816778630035,-1.3199100604799068,-2.9167874460104866
515.1000000000067,26.09423036929836,-1.323425474226206,-2.9184084622750817
516.2000000000068,26.129466828331676,-1.3296128895384363,-2.9201142987541306
517.3000000000068,26.16457081754806,-1.333345329921589,-2.9226496153808204
518.4000000000068,26.200502007216503,-1.3380147389957513,-2.9240534889099905
519.5000000000068,26.236143419942685,-1.341562100459116,-2.9256301215963774
520.6000000000068,26.27139284518956,-1.3461347877407468,-2.9256235709951914
521.7000000000069,26.305817095294138,-1.3502101132179303,-2.9278579683181567
522.8000000000068,26.34225122616811,-1.3547617366751115,-2.930211062972093
523.9000000000069,26.377810725342528,-1.3579571648756212,-2.931073919168747
525.0000000000068,26.4131949700546,-1.3631851115138776,-2.932451521502607
526.100000000007,26.448594190378515,-1.3670735904418234,-2.933371258577219
527.2000000000069,26.48418398265435,-1.3692724066753177,-2.9347831032887055
528.300000000007,26.519770430866448,-1.376544956860495,-2.9358313652589296
529.4000000000069,26.55512863444429,-1.378306474886777,-2.9357281389757337
530.5000000000069,26.59098857565499,-1.3839614463251282,-2.9368168067860063
531.600000000007,26.626606922756505,-1.389446303028639,-2.9371833108989773
532.700000000007,26.661923572227064,-1.3924983178099934,-2.938628302189412
533.800000000007,26.697576923648832,-1.3995823430187515,-2.9394087683543404
534.900000000007,26.73332762494541,-1.4038926465862351,-2.9402307232805986
536.000000000007,26.76848618753147,-1.407587645058254,-2.942354821726378
537.1000000000071,26.80422906465642,-1.4152173691133658,-2.944616227184367
538.2000000000071,26.839774687892152,-1.4212500003276305,-2.9447097852965345
539.300000000007,26.875612406545006,-1.4300140383278934,-2.9460478330511117
540.4000000000071,26.910892100426096,-1.435871264171595,-2.9474293176548194
541.500000000007,26.94618226378987,-1.4454214672721493,-2.9477651087401853
542.6000000000072,26.98240772939574,-1.4495512840551914,-2.949049000014147
543.7000000000071,27.017853597322894,-1.4582538798640994,-2.9501085851056033
544.8000000000072,27.053661341344796,-1.4650067956250306,-2.9514717404560704
545.9000000000071,27.089073128374004,-1.4693818593969574,-2.9514215349804824
547.0000000000072,27.125092859667454,-1.4755004466939916,-2.952771001526285
548.1000000000072,27.160349598787448,-1.4815870418965604,-2.9540526659267274
549.2000000000072,27.196219066825932,-1.487271804153427,-2.9540717201488187
550.3000000000072,27.232144367785512,-1.4914030997917727,-2.9553940532547367
551.4000000000073,27.267597803019097,-1.4974744811858625,-2.956741882482995
552.5000000000073,27.303144626555746,-1.5036470966181015,-2.95671953459214
553.6000000000073,27.339202829730937,-1.5106432914917247,-2.9575170988713113
554.7000000000073,27.374841804702193,-1.514958911717039,-2.9594339575004254
555.8000000000073,27.410607622649533,-1.5199741798415471,-2.9598925306557575
556.9000000000074,27.446445714125286,-1.5256063195548277,-2.9608847311272335
558.0000000000074,27.48209386967479,-1.5338892068726215,-2.962950521300086
559.1000000000074,27.518052162863864,-1.5390285032707878,-2.963725056222013
560.2000000000073,27.553501468751495,-1.5458674581951308,-2.9650377867609894
561.3000000000073,27.589497852338198,-1.5502137236204092,-2.965037870084178
562.4000000000074,27.62517134054163,-1.5558848721462464,-2.964861944982899
563.5000000000074,27.66078648115384,-1.5595840446105995,-2.9651026411068675
564.6000000000074,27.69685637810938,-1.5664695871528433,-2.96637552627589
565.7000000000074,27.732884401633296,-1.5693967213417348,-2.9676803692769615
566.8000000000075,27.76842376622933,-1.5735145811757854,-2.968942859460469
567.9000000000075,27.804246322424262,-1.5787960688547944,-2.9698165219335007
569.0000000000075,27.84013356864348,-1.5822755615062423,-2.9716276355620037
570.1000000000075,27.8764949755398,-1.5857174800389608,-2.9728185941367093
571.2000000000075,27.912218197734052,-1.591290862686653,-2.9735690980631784
572.3000000000076,27.947541406352983,-1.5951369210553357,-2.974249644231862
573.4000000000076,27.983790484137348,-1.5994303778271337,-2.975275363425816
574.5000000000076,28.019744800740188,-1.6023772772407283,-2.975573656077996
575.6000000000076,28.05567081500153,-1.6050947873370838,-2.975478829802154
576.7000000000077,28.091536191910112,-1.6059006800042284,-2.9771074160188986
577.8000000000077,28.127663200881106,-1.6102049099352753,-2.978370412679147
578.9000000000076,28.16335338031196,-1.6156600634630147,-2.9784257560929572
580.0000000000076,28.19956064575761,-1.6170132029425803,-2.9791228248917614
581.1000000000076,28.23583056562255,-1.6225998034204963,-2.979754150470907
582.2000000000077,28.27162639147153,-1.6246782769824777,-2.981155186950465
583.3000000000077,28.30764203685665,-1.6284035124643288,-2.9810643292750885
584.4000000000077,28.34353678784383,-1.6291065054174347,-2.9823664601427513
585.5000000000077,28.37982448801718,-1.6346649043263335,-2.9837193029054707
586.6000000000078,28.41589928283507,-1.6355809042486182,-2.983692480757637
587.7000000000078,28.45177305693335,-1.6411845550225077,-2.9848632754322093
588.8000000000078,28.487693190277998,-1.6429934591740043,-2.9850211725992306
589.9000000000078,28.523845547996952,-1.6476590260342325,-2.986433613658394
591.0000000000078,28.55977434893662,-1.653871011521601,-2.987679075158414
592.1000000000079,28.59604576240612,-1.6549908903841966,-2.987780633901987
593.2000000000079,28.632289529854663,-1.6595347518527628,-2.988976222450389
594.3000000000079,28.66811323530919,-1.6626976822881356,-2.9889663475834096
595.4000000000078,28.704491491897354,-1.665451964871093,-2.9902280231587186
596.5000000000078,28.740734970172564,-1.6705653057712322,-2.9902823191929873
597.6000000000079,28.776673820163197,-1.6730862614898057,-2.9893794206004127
598.7000000000079,28.81302731434006,-1.6767548424408247,-2.99029509810258
599.8000000000079,28.84889842533262,-1.6787811995933883,-2.991607050396218
600.9000000000079,28.8851271864779,-1.6839207029006056,-2.992916316647677
602.000000000008,28.921286237557204,-1.6881605901163468,-2.994217762971552
603.100000000008,28.957416241348056,-1.690659383611363,-2.994753329998269
604.200000000008,28.993782087477857,-1.6970349137928735,-2.9955579937889403
605.300000000008,29.029849362722164,-1.699709672504181,-2.996603721074421
606.400000000008,29.06605193043127,-1.7028744712105603,-2.9968799183045265
607.5000000000081,29.10216157004881,-1.7098134552021282,-2.9968235644583285
608.6000000000081,29.138356186217536,-1.713469855345069,-2.9983080054341715
609.7000000000081,29.17445096044043,-1.7177909822026418,-2.9987830983832593
610.8000000000081,29.211069850091015,-1.7205494188370127,-2.998436389988419
611.9000000000082,29.246353995778147,-1.7265196459329362,-2.9996181696173605
613.0000000000082,29.28271726652806,-1.7323108002786065,-2.9995781613786194
614.1000000000081,29.319962699654127,-1.7350440455373284,-3.0009345294514773
615.2000000000081,29.35589500066437,-1.7384899346380154,-3.0009541845541525
616.3000000000081,29.392721801207568,-1.7458570490899954,-3.002301193774669
617.4000000000082,29.42794596852509,-1.7500858621884248,-3.0028065202078107
618.5000000000082,29.46521451671133,-1.7566166480486165,-3.0035728672777715
619.6000000000082,29.501395100863494,-1.7628531494890656,-3.0041180463746113
620.7000000000082,29.53775096382705,-1.7664027468425887,-3.004887300648338
621.8000000000083,29.574057989055397,-1.771501400479551,-3.006136813729238
622.9000000000083,29.610641926652026,-1.7798042051948164,-3.0066616172517455
624.0000000000083,29.646695345164677,-1.7870554950595097,-3.007524719304059
625.1000000000083,29.683105230567147,-1.7915755474201522,-3.007846730245734
626.2000000000083,29.719683126775926,-1.7977071194281278,-3.008522571179072
627.3000000000084,29.756202972970776,-1.8066594312151973,-3.008177494594536
628.4000000000084,29.792357865519715,-1.8124089247284385,-3.0081813873347842
629.5000000000084,29.828717157248082,-1.818946968332218,-3.009473052625882
630.6000000000083,29.86556668784516,-1.8263276613933224,-3.0094919648212417
631.7000000000083,29.9015608417626,-1.832584359205963,-3.0106464753379956
632.8000000000084,29.937898888379905,-1.839188904990425,-3.010804901636002
633.9000000000084,29.974558723335484,-1.8442952715131848,-3.0115299340412065
635.0000000000084,30.010549818257456,-1.8498529276337774,-3.0114682091675484
636.1000000000084,30.04709258351983,-1.8573525673017808,-3.0121175859722493
637.2000000000085,30.084049362246684,-1.8632847034166558,-3.0121318151494645
638.3000000000085,30.1202014448968,-1.8716529195453722,-3.0121980989270165
639.4000000000085,30.156950907060867,-1.8780840231185794,-3.013547619179144
640.5000000000085,30.19325298288554,-1.8840766447073223,-3.0138652268546133
641.6000000000085,30.229542712225456,-1.8897841945877034,-3.0142114760451486
642.7000000000086,30.266221820384363,-1.8952183539319918,-3.0154116170168836
643.8000000000086,30.3024026355536,-1.9026324459970194,-3.0168503367372663
644.9000000000086,30.339431851639507,-1.9126087916969186,-3.0168658990832604
646.0000000000086,30.37573636811721,-1.9171409976395883,-3.018168410155612
647.1000000000087,30.412340979670052,-1.9273083213747784,-3.0188156793769427
648.2000000000087,30.448640010286297,-1.9352191054658865,-3.0194923375933653
649.3000000000086,30.485196961458495,-1.944544186843544,-3.019430833037518
650.4000000000086,30.521515504907633,-1.9539342963728354,-3.0196628041744003
651.5000000000086,30.558350216591297,-1.9630117456869238,-3.0207998027946386
652.6000000000087,30.594858271368697,-1.9734655653170916,-3.0207575581739032
653.7000000000087,30.63135356780572,-1.9819667331251842,-3.0221073073735036
654.8000000000087,30.668040031069104,-1.990589525634014,-3.022105708090604
655.9000000000087,30.70429066003464,-2.0017107639097445,-3.0227923236047953
657.0000000000088,30.74090645097758,-2.0152569673246488,-3.023421427275364
658.1000000000088,30.77757629943156,-2.0250617178896286,-3.0232898509902286
659.2000000000088,30.8140486116839,-2.0378793482734228,-3.0234028712796146
660.3000000000088,30.85095058713533,-2.048478459452934,-3.026078688279906
661.4000000000088,30.88680035768691,-2.0611004580441525,-3.0260619446594985
662.5000000000089,30.923686372270463,-2.072080797939118,-3.0273876891634113
663.6000000000089,30.960320276641962,-2.0833501413660884,-3.0287135993268235
664.7000000000089,30.997180440456486,-2.098389595217182,-3.0289109684316333
665.8000000000088,31.033635747582547,-2.1087476802145866,-3.0287349294810766
666.9000000000088,31.070209328138162,-2.1242926449936967,-3.02945626663116
668.0000000000089,31.106782059490634,-2.1354070183964837,-3.0299840361730968
669.1000000000089,31.143185352553235,-2.147209058726838,-3.031338038704444
670.2000000000089,31.18009624561642,-2.15920485954555,-3.0314122723388977
671.3000000000089,31.216848987047566,-2.1749767202405303,-3.0326691642984347
672.400000000009,31.2536702992727,-2.1872666858422876,-3.032723062088597
673.500000000009,31.29010251028537,-2.197417860172975,-3.033981900834487
674.600000000009,31.326520009955473,-2.2092583478983063,-3.0347087136767517
675.700000000009,31.363604382324123,-2.2218920936424906,-3.0353758679373355
676.800000000009,31.40029802514128,-2.2339302101854326,-3.0352738407485127
677.9000000000091,31.43695213500552,-2.245389103179764,-3.036758370866658
679.0000000000091,31.47351636874228,-2.255933006116185,-3.0382023077813374
680.1000000000091,31.510063402508457,-2.2633345357123518,-3.039208727039901
681.2000000000091,31.54692661801075,-2.274896695993412,-3.039463345052035
682.3000000000092,31.583533652602743,-2.2825723685310417,-3.0407588883827588
683.4000000000092,31.620184980043415,-2.289424645833724,-3.041850250550444
684.5000000000091,31.656720575888553,-2.296237499370864,-3.0421022324726072
685.6000000000091,31.69323978986058,-2.3051672408721937,-3.0435096936253005
686.7000000000091,31.73004979623272,-2.308584998616557,-3.04447844321087
687.8000000000092,31.76663407305432,-2.3106897325297133,-3.045948508638425
688.9000000000092,31.803166849160274,-2.3130079266476957,-3.046202102499848
690.0000000000092,31.839858626594413,-2.315059045656796,-3.047482334971354
691.1000000000092,31.876821375953742,-2.314103735266384,-3.04747416367911
692.2000000000093,31.912917158903667,-2.3151824418571234,-3.0486789073885423
693.3000000000093,31.949984150878752,-2.3111839169035218,-3.049533928846535
694.4000000000093,31.986338205942342,-2.3050295612508576,-3.05092854480075
695.5000000000093,32.02315118280074,-2.3021595162806783,-3.0523916804649764
696.6000000000093,32.059646094867745,-2.29678121288318,-3.0521357265666764
697.7000000000094,32.09618670485698,-2.288467346227189,-3.053332781185522
698.8000000000094,32.13300149069729,-2.2808369147003695,-3.0533205972096997
699.9000000000094,32.16939803451203,-2.2737832211504063,-3.0546205285540795
701.0000000000093,32.20606136926997,-2.2624381720322706,-3.0550228003510034
702.1000000000093,32.242951947715106,-2.2499490657692127,-3.055933935990224
703.2000000000094,32.2794999650486,-2.242836675656346,-3.055931346085594
704.3000000000094,32.315883539626626,-2.2299484218888015,-3.0572240155144184
705.4000000000094,32.35270750275093,-2.219546048498208,-3.057250138836528
706.5000000000094,32.38927259270635,-2.212467220725407,-3.057243612042545
707.6000000000095,32.426061363517135,-2.206236794898152,-3.0581125263782925
708.7000000000095,32.4628219609018,-2.2072441343161873,-3.0582670694024032
709.8000000000095,32.499672395594786,-2.205859092904429,-3.0582375378104687
710.9000000000095,32.53636763518485,-2.207359920684647,-3.058233416328202
712.0000000000095,32.57262794364454,-2.2097044097181575,-3.0594298343633644
713.1000000000096,32.60976710493953,-2.2119380532496296,-3.0595497795578446
714.2000000000096,32.64669521807673,-2.217263378802668,-3.0595515494867738
715.3000000000096,32.68338058947416,-2.2220199520285915,-3.0599300350644465
716.4000000000096,32.72038420428771,-2.2265428871325494,-3.060870379261104
717.5000000000097,32.75741955920984,-2.228130234750359,-3.060869767380346
718.6000000000097,32.79418517417496,-2.234000710888289,-3.060779417820813
719.7000000000096,32.830837562496036,-2.2410353685649427,-3.0621885277067733
720.8000000000096,32.86800314045656,-2.243660730556488,-3.0621874230687727
721.9000000000096,32.904186261394464,-2.253208758877924,-3.0631557354427503
723.0000000000097,32.94173868237304,-2.2569376887904236,-3.062208730233278
724.1000000000097,32.97841960316622,-2.262616489033916,-3.0634836543372117
725.2000000000097,33.01509681354939,-2.264347265167268,-3.063509023367775
726.3000000000097,33.05236081265851,-2.2743281751402113,-3.0635098291509157
727.4000000000098,33.08867530248528,-2.274620001161589,-3.0635098249919652
728.5000000000098,33.12632133664584,-2.279035357650309,-3.0635033755648156
729.6000000000098,33.16291351892334,-2.284562208439509,-3.0647168664536846
730.7000000000098,33.2000335252803,-2.2903871332178087,-3.0648299595842694
731.8000000000098,33.23700844969809,-2.2954212209365625,-3.0650120638073033
732.9000000000099,33.273689397017456,-2.299719682418463,-3.066150540423877
734.0000000000099,33.310384534916345,-2.304583267440075,-3.0672276650852526
735.1000000000099,33.34740901726632,-2.3088587256141224,-3.0674701414319765
736.2000000000098,33.38368954884886,-2.314852153080607,-3.0674699049268117
737.3000000000098,33.42149880952504,-2.3196186884455128,-3.067473843512037
738.4000000000099,33.45865249274613,-2.3268409752644668,-3.0667498419797936
739.5000000000099,33.495326626052275,-2.329347551238393,-3.0681569788805283
740.6000000000099,33.532536320887864,-2.334979896194196,-3.0677787106594403
741.7000000000099,33.56930575931504,-2.3402837532266623,-3.06778787283063
742.80000000001,33.60640226126063,-2.344572792839755,-3.069086589802749
743.90000000001,33.64270768746142,-2.3484291832530984,-3.0687798537872193
744.00000000001,33.6459894001263,-2.3486452865981953,-3.0687809471580256